[META]
version=2.0
spawnOnBlockType=2
spawnSunlight=True
spawnDarkness=True
spawnWater=False
spawnLava=False
underFill=False
randomRotation=True
dig=True
tree=False
branch=False
needsFoundation=True
rarity=100
collisionPercentage=20
spawnElevationMin=0
spawnElevationMax=200
spawnInBiome=Custom
[DATA]
10,-6,-8:17.12
10,-5,-8:17.12
11,-5,-8:17.12
9,-7,-7:17.12
12,-6,-7:17.12
10,-5,-7:17.12
11,-5,-7:17.12
9,-3,-7:17.12
11,-3,-7:17.12
9,-7,-6:17.12
10,-7,-6:17.12
8,-6,-6:17.12
10,-6,-6:17.12
12,-6,-6:17.12
9,-5,-6:17.12
10,-5,-6:17.12
11,-5,-6:17.12
12,-5,-6:17.12
8,-4,-6:17.12
12,-4,-6:17.12
11,-3,-6:17.12
9,-7,-5:17.12
11,-7,-5:17.12
9,-6,-5:17.12
10,-6,-5:17.12
11,-6,-5:17.12
12,-6,-5:17.12
9,-5,-5:17.12
10,-5,-5:17.12
11,-5,-5:17.12
10,-4,-5:17.12
10,-3,-5:17.12
11,-3,-5:17.12
10,-7,-4:17.12
11,-7,-4:17.12
12,-7,-4:17.12
8,-6,-4:17.12
9,-6,-4:17.12
10,-6,-4:17.12
11,-6,-4:17.12
12,-6,-4:17.12
8,-5,-4:17.12
9,-5,-4:17.12
10,-5,-4:17.12
11,-5,-4:17.12
12,-5,-4:17.12
13,-5,-4:17.12
9,-4,-4:17.12
10,-4,-4:17.12
11,-4,-4:17.12
13,-4,-4:17.12
9,-3,-4:17.12
10,-3,-4:17.12
11,-3,-4:17.12
11,-2,-4:17.12
10,-7,-3:17.12
9,-6,-3:17.12
10,-6,-3:17.12
11,-6,-3:17.12
9,-5,-3:17.12
10,-5,-3:17.12
11,-5,-3:17.12
12,-5,-3:17.12
8,-4,-3:17.12
9,-4,-3:17.12
11,-4,-3:17.12
12,-4,-3:17.12
10,-3,-3:17.12
11,-3,-3:17.12
12,-3,-3:17.12
13,-3,-3:17.12
10,-2,-3:17.12
11,-2,-3:17.12
12,-2,-3:17.12
13,-2,-3:17.12
9,-7,-2:17.12
10,-7,-2:17.12
11,-7,-2:17.12
12,-7,-2:17.12
13,-7,-2:17.12
8,-6,-2:17.12
9,-6,-2:17.12
12,-6,-2:17.12
13,-6,-2:17.12
8,-5,-2:17.12
10,-5,-2:17.12
13,-5,-2:17.12
14,-5,-2:17.12
8,-4,-2:17.12
10,-4,-2:17.12
11,-4,-2:17.12
12,-4,-2:17.12
13,-4,-2:17.12
14,-4,-2:17.12
8,-3,-2:17.12
9,-3,-2:17.12
10,-3,-2:17.12
12,-3,-2:17.12
13,-3,-2:17.12
9,-2,-2:17.12
10,-2,-2:17.12
11,-2,-2:17.12
12,-2,-2:17.12
9,-7,-1:17.12
10,-7,-1:17.12
11,-7,-1:17.12
12,-7,-1:17.12
9,-6,-1:17.12
12,-6,-1:17.12
13,-6,-1:17.12
8,-5,-1:17.12
13,-5,-1:17.12
8,-4,-1:17.12
9,-4,-1:17.12
13,-4,-1:17.12
12,-3,-1:17.12
9,-2,-1:17.12
10,-2,-1:17.12
11,-2,-1:17.12
12,-2,-1:17.12
10,-7,0:17.12
11,-7,0:17.12
9,-6,0:17.12
10,-6,0:17.12
11,-6,0:17.12
12,-6,0:17.12
9,-5,0:17.12
13,-5,0:17.12
9,-4,0:17.12
13,-4,0:17.12
9,-3,0:17.12
10,-3,0:17.12
11,-3,0:17.12
12,-3,0:17.12
11,-7,1:17.12
9,-6,1:17.12
10,-6,1:17.12
11,-6,1:17.12
12,-6,1:17.12
9,-5,1:17.12
13,-5,1:17.12
9,-4,1:17.12
12,-4,1:17.12
13,-4,1:17.12
9,-3,1:17.12
10,-3,1:17.12
11,-3,1:17.12
12,-3,1:17.12
7,-12,2:18.6
8,-12,2:18.6
9,-12,2:18.6
10,-12,2:18.6
11,-12,2:18.6
12,-12,2:18.6
13,-12,2:18.6
14,-12,2:18.6
15,-12,2:18.6
6,-11,2:18.14
16,-11,2:18.14
16,-10,2:18.14
4,-9,2:18.6
5,-9,2:18.14
17,-9,2:18.14
18,-9,2:18.6
3,-8,2:18.6
4,-8,2:18.6
7,-8,2:18.14
17,-8,2:18.14
18,-8,2:18.6
3,-7,2:18.6
4,-7,2:18.6
7,-7,2:18.14
11,-7,2:17.12
18,-7,2:18.6
19,-7,2:18.6
2,-6,2:18.6
3,-6,2:18.6
9,-6,2:17.12
10,-6,2:17.12
11,-6,2:17.12
12,-6,2:17.12
18,-6,2:18.6
19,-6,2:18.6
9,-5,2:17.12
12,-5,2:17.12
13,-5,2:17.12
19,-5,2:18.6
9,-4,2:17.12
12,-4,2:17.12
19,-4,2:18.6
3,-3,2:18.6
9,-3,2:17.12
10,-3,2:17.12
11,-3,2:17.12
12,-3,2:17.12
13,-3,2:17.12
18,-3,2:18.6
19,-3,2:18.6
3,-2,2:18.6
4,-2,2:18.6
11,-2,2:17.12
4,-1,2:18.6
17,-1,2:18.6
18,-1,2:18.6
4,0,2:18.6
5,0,2:18.6
17,0,2:18.6
5,1,2:18.6
16,1,2:18.6
6,2,2:18.14
15,2,2:18.6
16,2,2:18.6
7,3,2:18.6
8,3,2:18.6
9,3,2:18.6
10,3,2:18.6
11,3,2:18.6
12,3,2:18.6
13,3,2:18.6
7,-12,3:18.6
8,-12,3:18.6
9,-12,3:18.6
10,-12,3:18.6
11,-12,3:18.6
12,-12,3:18.6
13,-12,3:18.6
14,-12,3:18.6
6,-11,3:18.14
7,-11,3:18.14
8,-11,3:18.14
9,-11,3:18.14
10,-11,3:18.14
11,-11,3:18.14
12,-11,3:18.14
13,-11,3:18.14
14,-11,3:18.14
15,-11,3:18.14
5,-10,3:18.14
6,-10,3:18.14
7,-10,3:18.14
15,-10,3:18.14
16,-10,3:18.14
5,-9,3:18.14
6,-9,3:18.14
8,-9,3:18.14
9,-9,3:18.14
10,-9,3:18.14
11,-9,3:18.14
12,-9,3:18.14
13,-9,3:18.14
15,-9,3:18.14
16,-9,3:18.14
4,-8,3:18.6
5,-8,3:18.14
6,-8,3:18.14
7,-8,3:18.14
8,-8,3:18.14
13,-8,3:18.14
14,-8,3:18.14
16,-8,3:18.14
17,-8,3:18.6
3,-7,3:18.6
4,-7,3:18.6
5,-7,3:18.14
7,-7,3:18.14
8,-7,3:18.14
14,-7,3:18.14
17,-7,3:18.6
18,-7,3:18.6
3,-6,3:18.6
4,-6,3:18.6
5,-6,3:18.14
6,-6,3:18.14
7,-6,3:18.14
9,-6,3:17.12
10,-6,3:17.12
11,-6,3:17.12
12,-6,3:17.12
15,-6,3:18.14
17,-6,3:18.6
18,-6,3:18.6
19,-6,3:18.6
3,-5,3:18.6
4,-5,3:18.6
6,-5,3:18.14
9,-5,3:17.12
12,-5,3:17.12
13,-5,3:17.12
15,-5,3:18.14
18,-5,3:18.6
19,-5,3:18.6
3,-4,3:18.6
4,-4,3:18.6
6,-4,3:18.14
9,-4,3:17.12
12,-4,3:17.12
15,-4,3:18.14
18,-4,3:18.6
19,-4,3:18.6
3,-3,3:18.6
4,-3,3:18.6
6,-3,3:18.14
7,-3,3:18.14
10,-3,3:17.12
11,-3,3:17.12
12,-3,3:17.12
14,-3,3:18.14
15,-3,3:18.14
17,-3,3:18.6
18,-3,3:18.6
4,-2,3:18.6
5,-2,3:18.6
7,-2,3:18.14
8,-2,3:18.14
11,-2,3:17.12
14,-2,3:18.14
16,-2,3:18.6
17,-2,3:18.6
4,-1,3:18.6
5,-1,3:18.6
6,-1,3:18.14
8,-1,3:18.14
10,-1,3:18.14
11,-1,3:18.14
12,-1,3:18.14
13,-1,3:18.14
14,-1,3:18.14
16,-1,3:18.6
17,-1,3:18.6
5,0,3:18.6
6,0,3:18.14
9,0,3:18.14
10,0,3:18.14
11,0,3:18.14
12,0,3:18.14
13,0,3:18.14
15,0,3:18.6
16,0,3:18.6
6,1,3:18.14
7,1,3:18.14
14,1,3:18.14
15,1,3:18.6
16,1,3:18.6
6,2,3:18.14
7,2,3:18.14
8,2,3:18.14
9,2,3:18.14
10,2,3:18.14
11,2,3:18.14
12,2,3:18.14
13,2,3:18.14
14,2,3:18.14
15,2,3:18.6
8,-11,4:18.14
9,-11,4:18.14
10,-11,4:18.14
11,-11,4:18.14
12,-11,4:18.14
13,-11,4:18.14
14,-11,4:18.14
7,-10,4:18.14
8,-10,4:18.14
9,-10,4:18.14
10,-10,4:18.14
11,-10,4:18.14
12,-10,4:18.14
13,-10,4:18.14
14,-10,4:18.14
6,-9,4:18.14
7,-9,4:18.14
9,-9,4:18.14
10,-9,4:18.14
11,-9,4:18.14
12,-9,4:18.14
14,-9,4:18.14
15,-9,4:18.14
5,-8,4:18.6
6,-8,4:18.14
7,-8,4:18.14
8,-8,4:18.14
9,-8,4:18.14
10,-8,4:18.14
11,-8,4:18.14
12,-8,4:18.14
13,-8,4:18.14
15,-8,4:18.14
16,-8,4:18.6
5,-7,4:18.6
6,-7,4:18.14
7,-7,4:18.14
8,-7,4:18.14
13,-7,4:18.14
14,-7,4:18.14
15,-7,4:18.14
16,-7,4:18.6
4,-6,4:18.6
5,-6,4:18.6
6,-6,4:18.14
7,-6,4:18.14
8,-6,4:18.14
10,-6,4:17.12
11,-6,4:17.12
12,-6,4:17.12
14,-6,4:18.14
16,-6,4:18.6
17,-6,4:18.6
4,-5,4:18.6
5,-5,4:18.6
6,-5,4:18.14
7,-5,4:18.14
9,-5,4:17.12
12,-5,4:17.12
13,-5,4:17.12
14,-5,4:18.14
15,-5,4:18.14
17,-5,4:18.6
4,-4,4:18.6
5,-4,4:18.6
7,-4,4:18.14
9,-4,4:17.12
12,-4,4:17.12
15,-4,4:18.14
16,-4,4:18.6
17,-4,4:18.6
5,-3,4:18.6
6,-3,4:18.14
7,-3,4:18.14
8,-3,4:18.14
10,-3,4:17.12
11,-3,4:17.12
12,-3,4:17.12
14,-3,4:18.14
16,-3,4:18.6
17,-3,4:18.6
5,-2,4:18.6
6,-2,4:18.14
8,-2,4:18.14
13,-2,4:18.14
14,-2,4:18.14
15,-2,4:18.6
16,-2,4:18.6
6,-1,4:18.14
7,-1,4:18.14
8,-1,4:18.14
10,-1,4:18.14
11,-1,4:18.14
12,-1,4:18.14
13,-1,4:18.14
14,-1,4:18.14
15,-1,4:18.6
6,0,4:18.14
7,0,4:18.14
8,0,4:18.14
9,0,4:18.14
10,0,4:18.14
11,0,4:18.14
12,0,4:18.14
13,0,4:18.14
14,0,4:18.14
15,0,4:18.6
7,1,4:18.14
8,1,4:18.14
9,1,4:18.14
10,1,4:18.14
11,1,4:18.14
12,1,4:18.14
13,1,4:18.14
14,1,4:18.14
8,-11,5:18.14
9,-11,5:18.14
10,-11,5:18.14
11,-11,5:18.14
12,-11,5:18.14
13,-11,5:18.14
6,-10,5:18.14
7,-10,5:18.14
15,-10,5:18.14
6,-9,5:18.14
8,-9,5:18.14
9,-9,5:18.14
10,-9,5:18.14
11,-9,5:18.14
12,-9,5:18.14
13,-9,5:18.14
14,-9,5:18.14
15,-9,5:18.14
16,-9,5:18.6
5,-8,5:18.6
6,-8,5:18.14
7,-8,5:18.14
8,-8,5:18.14
9,-8,5:18.14
10,-8,5:18.14
11,-8,5:18.14
12,-8,5:18.14
13,-8,5:18.14
14,-8,5:18.14
16,-8,5:18.6
4,-7,5:18.6
5,-7,5:18.6
6,-7,5:18.14
7,-7,5:18.14
9,-7,5:18.14
12,-7,5:18.14
13,-7,5:18.14
14,-7,5:18.14
15,-7,5:18.14
16,-7,5:18.6
17,-7,5:18.6
4,-6,5:18.6
5,-6,5:18.6
6,-6,5:18.14
7,-6,5:18.14
8,-6,5:18.14
10,-6,5:17.12
11,-6,5:17.12
12,-6,5:17.12
13,-6,5:18.14
14,-6,5:18.14
15,-6,5:18.14
17,-6,5:18.6
2,-5,5:18.6
4,-5,5:18.6
5,-5,5:18.6
6,-5,5:18.14
7,-5,5:18.14
8,-5,5:18.14
9,-5,5:17.12
10,-5,5:18.14
11,-5,5:18.14
12,-5,5:17.12
14,-5,5:18.14
15,-5,5:18.14
4,-4,5:18.6
5,-4,5:18.6
6,-4,5:18.14
7,-4,5:18.14
8,-4,5:18.14
9,-4,5:17.12
11,-4,5:18.14
12,-4,5:17.12
13,-4,5:18.14
15,-4,5:18.14
16,-4,5:18.6
17,-4,5:18.6
4,-3,5:18.6
5,-3,5:18.6
6,-3,5:18.14
7,-3,5:18.14
8,-3,5:18.14
10,-3,5:17.12
11,-3,5:17.12
12,-3,5:17.12
13,-3,5:18.14
14,-3,5:18.14
15,-3,5:18.14
17,-3,5:18.6
5,-2,5:18.6
7,-2,5:18.14
8,-2,5:18.14
9,-2,5:18.14
10,-2,5:18.14
11,-2,5:18.14
12,-2,5:18.14
13,-2,5:18.14
14,-2,5:18.14
15,-2,5:18.6
16,-2,5:18.6
5,-1,5:18.6
6,-1,5:18.14
7,-1,5:18.14
8,-1,5:18.14
10,-1,5:18.14
11,-1,5:18.14
12,-1,5:18.14
13,-1,5:18.14
14,-1,5:18.14
16,-1,5:18.6
6,0,5:18.14
8,0,5:18.14
9,0,5:18.14
10,0,5:18.14
11,0,5:18.14
12,0,5:18.14
13,0,5:18.14
14,0,5:18.14
15,0,5:18.6
7,1,5:18.14
8,1,5:18.14
9,1,5:18.14
10,1,5:18.14
11,1,5:18.14
12,1,5:18.14
13,1,5:18.14
15,1,5:18.6
9,2,5:18.6
10,2,5:18.6
12,2,5:18.6
8,-11,6:18.14
9,-11,6:18.14
10,-11,6:18.14
11,-11,6:18.14
12,-11,6:18.14
13,-11,6:18.14
14,-11,6:18.14
7,-10,6:18.14
8,-10,6:18.14
9,-10,6:18.14
10,-10,6:18.14
11,-10,6:18.14
12,-10,6:18.14
13,-10,6:18.14
14,-10,6:18.14
6,-9,6:18.14
7,-9,6:18.14
14,-9,6:18.14
15,-9,6:18.14
5,-8,6:18.6
6,-8,6:18.14
8,-8,6:18.14
9,-8,6:18.14
10,-8,6:18.14
11,-8,6:18.14
12,-8,6:18.14
13,-8,6:18.14
15,-8,6:18.14
16,-8,6:18.6
5,-7,6:18.6
6,-7,6:18.14
7,-7,6:18.14
8,-7,6:18.14
9,-7,6:18.14
10,-7,6:18.14
11,-7,6:18.14
12,-7,6:18.14
13,-7,6:18.14
14,-7,6:18.14
16,-7,6:18.6
4,-6,6:18.6
5,-6,6:18.6
6,-6,6:18.14
7,-6,6:18.14
9,-6,6:18.14
10,-6,6:17.12
11,-6,6:17.12
12,-6,6:17.12
13,-6,6:18.14
14,-6,6:18.14
16,-6,6:18.6
17,-6,6:18.6
3,-5,6:18.6
4,-5,6:18.6
5,-5,6:18.6
6,-5,6:18.14
7,-5,6:18.14
8,-5,6:18.14
9,-5,6:17.12
10,-5,6:18.14
11,-5,6:18.14
12,-5,6:17.12
13,-5,6:18.14
14,-5,6:18.14
15,-5,6:18.14
17,-5,6:18.6
4,-4,6:18.6
5,-4,6:18.6
7,-4,6:18.14
8,-4,6:18.14
9,-4,6:17.12
11,-4,6:18.14
12,-4,6:17.12
13,-4,6:18.14
16,-4,6:18.6
17,-4,6:18.6
5,-3,6:18.6
7,-3,6:18.14
8,-3,6:18.14
9,-3,6:18.14
10,-3,6:17.12
11,-3,6:17.12
12,-3,6:18.14
13,-3,6:18.14
14,-3,6:18.14
16,-3,6:18.6
17,-3,6:18.6
5,-2,6:18.6
6,-2,6:18.14
8,-2,6:18.14
9,-2,6:18.14
10,-2,6:18.14
11,-2,6:18.14
12,-2,6:18.14
13,-2,6:18.14
15,-2,6:18.6
16,-2,6:18.6
6,-1,6:18.14
7,-1,6:18.14
10,-1,6:18.14
11,-1,6:18.14
12,-1,6:18.14
13,-1,6:18.14
14,-1,6:18.14
15,-1,6:18.6
7,0,6:18.14
14,0,6:18.14
15,0,6:18.6
7,1,6:18.14
8,1,6:18.14
9,1,6:18.14
10,1,6:18.14
11,1,6:18.14
12,1,6:18.14
13,1,6:18.14
14,1,6:18.14
8,-10,7:18.14
9,-10,7:18.14
10,-10,7:18.14
11,-10,7:18.14
12,-10,7:18.14
13,-10,7:18.14
14,-10,7:18.14
7,-9,7:18.14
8,-9,7:18.14
9,-9,7:18.14
10,-9,7:18.14
11,-9,7:18.14
12,-9,7:18.14
13,-9,7:18.14
14,-9,7:18.14
6,-8,7:18.14
7,-8,7:18.14
14,-8,7:18.14
15,-8,7:18.6
5,-7,7:18.6
6,-7,7:18.14
7,-7,7:18.14
9,-7,7:18.14
10,-7,7:18.14
11,-7,7:18.14
12,-7,7:18.14
15,-7,7:18.6
5,-6,7:18.6
6,-6,7:18.14
9,-6,7:18.14
10,-6,7:17.12
11,-6,7:17.12
12,-6,7:18.14
13,-6,7:18.14
15,-6,7:18.6
16,-6,7:18.6
4,-5,7:18.6
5,-5,7:18.6
6,-5,7:18.14
7,-5,7:18.14
8,-5,7:18.14
9,-5,7:18.14
10,-5,7:18.14
11,-5,7:18.14
12,-5,7:17.12
13,-5,7:18.14
5,-4,7:18.6
6,-4,7:18.14
8,-4,7:18.14
9,-4,7:18.14
10,-4,7:17.12
11,-4,7:18.14
12,-4,7:18.14
13,-4,7:18.14
16,-4,7:18.6
6,-3,7:18.14
9,-3,7:18.14
10,-3,7:18.14
11,-3,7:18.14
12,-3,7:18.14
13,-3,7:18.14
15,-3,7:18.6
16,-3,7:18.6
6,-2,7:18.14
7,-2,7:18.14
10,-2,7:18.14
11,-2,7:18.14
12,-2,7:18.14
13,-2,7:18.14
14,-2,7:18.14
15,-2,7:18.6
7,-1,7:18.14
8,-1,7:18.14
14,-1,7:18.14
15,-1,7:18.6
7,0,7:18.14
8,0,7:18.14
9,0,7:18.14
10,0,7:18.14
11,0,7:18.14
12,0,7:18.14
13,0,7:18.14
14,0,7:18.14
15,0,7:18.6
9,1,7:18.14
10,1,7:18.14
11,1,7:18.14
12,1,7:18.14
8,-10,8:18.14
9,-10,8:18.14
10,-10,8:18.14
11,-10,8:18.14
12,-10,8:18.14
13,-10,8:18.14
7,-9,8:18.14
8,-9,8:18.14
9,-9,8:18.14
10,-9,8:18.14
11,-9,8:18.14
12,-9,8:18.14
13,-9,8:18.14
14,-9,8:18.14
7,-8,8:18.14
8,-8,8:18.14
13,-8,8:18.14
14,-8,8:18.14
15,-8,8:18.6
6,-7,8:18.14
7,-7,8:18.14
8,-7,8:18.14
14,-7,8:18.14
15,-7,8:18.6
5,-6,8:18.6
6,-6,8:18.14
7,-6,8:18.14
10,-6,8:18.14
11,-6,8:18.14
12,-6,8:17.12
14,-6,8:18.14
15,-6,8:18.6
16,-6,8:18.6
5,-5,8:18.6
6,-5,8:18.14
9,-5,8:18.14
10,-5,8:18.14
11,-5,8:18.14
12,-5,8:18.14
15,-5,8:18.6
5,-4,8:18.6
6,-4,8:18.14
7,-4,8:18.14
9,-4,8:17.12
10,-4,8:18.14
11,-4,8:18.14
12,-4,8:17.12
15,-4,8:18.6
16,-4,8:18.6
6,-3,8:18.14
7,-3,8:18.14
10,-3,8:17.12
11,-3,8:17.12
12,-3,8:18.14
14,-3,8:18.14
15,-3,8:18.6
16,-3,8:18.6
6,-2,8:18.14
7,-2,8:18.14
8,-2,8:18.14
13,-2,8:18.14
14,-2,8:18.14
15,-2,8:18.6
7,-1,8:18.14
8,-1,8:18.14
10,-1,8:18.14
11,-1,8:18.14
12,-1,8:18.14
13,-1,8:18.14
14,-1,8:18.14
15,-1,8:18.6
7,0,8:18.14
8,0,8:18.14
9,0,8:18.14
10,0,8:18.14
11,0,8:18.14
12,0,8:18.14
13,0,8:18.14
14,0,8:18.14
8,-9,9:18.14
9,-9,9:18.14
10,-9,9:18.14
11,-9,9:18.14
12,-9,9:18.14
13,-9,9:18.14
8,-8,9:18.14
9,-8,9:18.14
10,-8,9:18.14
11,-8,9:18.14
12,-8,9:18.14
13,-8,9:18.14
14,-8,9:18.14
7,-7,9:18.14
8,-7,9:18.14
13,-7,9:18.14
14,-7,9:18.14
6,-6,9:18.14
7,-6,9:18.14
8,-6,9:18.14
10,-6,9:17.12
11,-6,9:17.12
12,-6,9:17.12
14,-6,9:18.14
15,-6,9:18.6
6,-5,9:18.14
7,-5,9:18.14
8,-5,9:18.14
9,-5,9:18.14
10,-5,9:18.14
11,-5,9:18.14
12,-5,9:17.12
14,-5,9:18.14
15,-5,9:18.6
6,-4,9:18.14
7,-4,9:18.14
9,-4,9:17.12
10,-4,9:18.14
11,-4,9:18.14
12,-4,9:17.12
15,-4,9:18.6
6,-3,9:18.14
7,-3,9:18.14
8,-3,9:18.14
10,-3,9:17.12
11,-3,9:17.12
12,-3,9:18.14
13,-3,9:18.14
14,-3,9:18.14
15,-3,9:18.6
7,-2,9:18.14
8,-2,9:18.14
9,-2,9:18.14
10,-2,9:18.14
11,-2,9:18.14
12,-2,9:18.14
13,-2,9:18.14
14,-2,9:18.14
8,-1,9:18.14
10,-1,9:18.14
11,-1,9:18.14
12,-1,9:18.14
13,-1,9:18.14
14,-1,9:18.14
9,0,9:18.14
10,-9,10:18.14
11,-9,10:18.14
7,-8,10:18.14
8,-8,10:18.14
9,-8,10:18.14
10,-8,10:18.14
11,-8,10:18.14
12,-8,10:18.14
13,-8,10:18.14
14,-8,10:18.14
7,-7,10:18.14
8,-7,10:18.14
9,-7,10:18.14
10,-7,10:18.14
11,-7,10:18.14
12,-7,10:18.14
13,-7,10:18.14
14,-7,10:18.14
15,-7,10:18.6
7,-6,10:18.14
8,-6,10:18.14
9,-6,10:18.14
10,-6,10:17.12
11,-6,10:17.12
12,-6,10:17.12
13,-6,10:18.14
14,-6,10:18.14
15,-6,10:18.6
7,-5,10:18.14
8,-5,10:18.14
9,-5,10:18.14
10,-5,10:18.14
11,-5,10:18.14
12,-5,10:17.12
13,-5,10:18.14
14,-5,10:18.14
15,-5,10:18.6
7,-4,10:18.14
8,-4,10:18.14
9,-4,10:17.12
10,-4,10:17.12
11,-4,10:18.14
12,-4,10:17.12
13,-4,10:18.14
7,-3,10:18.14
8,-3,10:18.14
9,-3,10:18.14
10,-3,10:17.12
11,-3,10:17.12
12,-3,10:18.14
13,-3,10:18.14
14,-3,10:18.14
8,-2,10:18.14
9,-2,10:18.14
10,-2,10:18.14
11,-2,10:18.14
12,-2,10:18.14
13,-2,10:18.14
14,-2,10:18.14
10,-1,10:18.14
11,-1,10:18.14
12,-1,10:18.14
13,-1,10:18.14
10,0,10:18.14
11,0,10:18.14
9,-8,11:18.14
10,-8,11:18.14
11,-8,11:18.14
12,-8,11:18.14
7,-7,11:18.14
8,-7,11:18.14
9,-7,11:18.14
10,-7,11:18.14
11,-7,11:18.14
12,-7,11:18.14
13,-7,11:18.14
14,-7,11:18.14
7,-6,11:18.14
8,-6,11:18.14
9,-6,11:18.14
10,-6,11:17.12
11,-6,11:17.12
12,-6,11:18.14
13,-6,11:18.14
14,-6,11:18.14
5,-5,11:18.6
6,-5,11:18.14
7,-5,11:18.14
8,-5,11:18.14
9,-5,11:18.14
10,-5,11:17.12
11,-5,11:18.14
12,-5,11:17.12
13,-5,11:18.14
14,-5,11:18.14
8,-4,11:18.14
9,-4,11:18.14
10,-4,11:17.12
11,-4,11:18.14
12,-4,11:17.12
13,-4,11:18.14
8,-3,11:18.14
9,-3,11:18.14
10,-3,11:18.14
11,-3,11:18.14
12,-3,11:18.14
13,-3,11:18.14
9,-2,11:18.14
10,-2,11:18.14
11,-2,11:18.14
12,-2,11:18.14
13,-2,11:18.14
10,-1,11:18.14
11,-1,11:18.14
12,-1,11:18.14
10,-9,12:18.14
11,-9,12:18.14
9,-8,12:18.14
10,-8,12:18.14
11,-8,12:18.14
12,-8,12:18.14
13,-8,12:18.14
7,-7,12:18.14
8,-7,12:18.14
9,-7,12:18.14
10,-7,12:18.14
11,-7,12:18.14
12,-7,12:18.14
13,-7,12:18.14
14,-7,12:18.14
7,-6,12:18.14
8,-6,12:18.14
9,-6,12:18.14
10,-6,12:18.14
11,-6,12:18.14
12,-6,12:18.14
13,-6,12:18.14
14,-6,12:18.14
6,-5,12:18.14
7,-5,12:18.14
8,-5,12:18.14
9,-5,12:18.14
10,-5,12:18.14
11,-5,12:18.14
12,-5,12:18.14
13,-5,12:18.14
14,-5,12:18.14
7,-4,12:18.14
8,-4,12:18.14
9,-4,12:18.14
10,-4,12:18.14
11,-4,12:18.14
12,-4,12:18.14
13,-4,12:18.14
7,-3,12:18.14
9,-3,12:18.14
10,-3,12:18.14
11,-3,12:18.14
12,-3,12:18.14
13,-3,12:18.14
14,-3,12:18.14
8,-2,12:18.14
9,-2,12:18.14
10,-2,12:18.14
11,-2,12:18.14
12,-2,12:18.14
13,-2,12:18.14
14,-2,12:18.14
10,-1,12:18.14
11,-1,12:18.14
12,-1,12:18.14
10,-8,13:18.14
11,-8,13:18.14
12,-8,13:18.14
8,-7,13:18.14
9,-7,13:18.14
10,-7,13:18.14
12,-7,13:18.14
13,-7,13:18.14
8,-6,13:18.14
9,-6,13:18.14
10,-6,13:18.14
11,-6,13:18.14
12,-6,13:18.14
13,-6,13:18.14
14,-6,13:18.14
5,-5,13:18.6
6,-5,13:18.14
7,-5,13:18.14
8,-5,13:18.14
9,-5,13:18.14
10,-5,13:18.14
11,-5,13:18.14
12,-5,13:18.14
13,-5,13:18.14
14,-5,13:18.14
8,-4,13:18.14
9,-4,13:18.14
10,-4,13:18.14
11,-4,13:18.14
12,-4,13:18.14
13,-4,13:18.14
7,-3,13:18.14
8,-3,13:18.14
9,-3,13:18.14
10,-3,13:18.14
11,-3,13:18.14
12,-3,13:18.14
13,-3,13:18.14
14,-3,13:18.14
9,-2,13:18.14
10,-2,13:18.14
11,-2,13:18.14
12,-2,13:18.14
13,-2,13:18.14
14,-2,13:18.14
11,-1,13:18.14
11,-8,14:18.14
9,-7,14:18.14
10,-7,14:18.14
11,-7,14:18.14
12,-7,14:18.14
8,-6,14:18.14
9,-6,14:18.14
11,-6,14:17.12
12,-6,14:18.14
13,-6,14:18.14
8,-5,14:18.14
10,-5,14:18.14
11,-5,14:18.14
13,-5,14:18.14
8,-4,14:18.14
11,-4,14:18.14
13,-4,14:18.14
8,-3,14:18.14
9,-3,14:18.14
10,-3,14:18.14
12,-3,14:18.14
13,-3,14:18.14
10,-2,14:18.14
11,-2,14:18.14
12,-2,14:18.14
13,-2,14:18.14
14,-2,14:18.14
11,-8,15:18.14
9,-7,15:18.14
10,-7,15:18.14
11,-7,15:18.14
12,-7,15:18.14
13,-7,15:18.14
8,-6,15:18.14
9,-6,15:18.14
10,-6,15:18.14
11,-6,15:18.14
12,-6,15:18.14
13,-6,15:18.14
8,-5,15:18.14
9,-5,15:18.14
11,-5,15:17.12
12,-5,15:18.14
13,-5,15:18.14
14,-5,15:18.14
8,-4,15:18.14
9,-4,15:18.14
11,-4,15:17.12
12,-4,15:18.14
13,-4,15:18.14
8,-3,15:18.14
9,-3,15:18.14
10,-3,15:18.14
11,-3,15:18.14
12,-3,15:18.14
13,-3,15:18.14
9,-2,15:18.14
10,-2,15:18.14
11,-2,15:18.14
12,-2,15:18.14
13,-2,15:18.14
9,-7,16:18.6
10,-7,16:18.6
11,-7,16:18.6
12,-7,16:18.6
8,-6,16:18.6
9,-6,16:18.6
10,-6,16:18.6
11,-6,16:18.6
12,-6,16:18.6
13,-6,16:18.6
8,-5,16:18.6
9,-5,16:18.6
11,-5,16:17.12
12,-5,16:18.6
13,-5,16:18.6
8,-4,16:18.6
9,-4,16:18.6
10,-4,16:18.6
11,-4,16:17.12
12,-4,16:18.6
13,-4,16:18.6
9,-3,16:18.6
10,-3,16:18.6
11,-3,16:18.6
12,-3,16:18.6
13,-3,16:18.6
9,-2,16:18.6
10,-2,16:18.6
11,-2,16:18.6
12,-2,16:18.6
10,-7,17:18.6
11,-7,17:18.6
9,-6,17:18.6
10,-6,17:18.6
11,-6,17:18.6
12,-6,17:18.6
9,-5,17:18.6
10,-5,17:18.6
11,-5,17:18.6
12,-5,17:18.6
13,-5,17:18.6
9,-4,17:18.6
10,-4,17:18.6
11,-4,17:18.6
12,-4,17:18.6
13,-4,17:18.6
9,-3,17:18.6
10,-3,17:18.6
11,-3,17:18.6
12,-3,17:18.6
9,-6,18:18.6
10,-6,18:18.6
11,-6,18:18.6
12,-6,18:18.6
9,-5,18:18.6
10,-5,18:18.6
11,-5,18:17.0
12,-5,18:18.6
13,-5,18:18.6
9,-4,18:18.6
10,-4,18:18.6
11,-4,18:17.0
12,-4,18:18.6
9,-3,18:18.6
10,-3,18:18.6
11,-3,18:18.6
12,-3,18:18.6
9,-6,19:18.6
10,-6,19:18.6
11,-6,19:18.6
12,-6,19:18.6
9,-5,19:18.6
10,-5,19:18.6
11,-5,19:18.6
12,-5,19:18.6
9,-4,19:18.6
10,-4,19:18.6
11,-4,19:18.6
12,-4,19:18.6
9,-3,19:18.6
10,-3,19:18.6
11,-3,19:18.6
12,-3,19:18.6
10,-6,20:18.6
11,-6,20:18.6
10,-5,20:18.6
11,-5,20:18.6
12,-5,20:18.6
10,-4,20:18.6
11,-4,20:18.6
12,-4,20:18.6
11,-6,21:18.6
10,-5,21:18.6
11,-5,21:18.6
12,-5,21:18.6
10,-4,21:18.6
11,-4,21:18.6
12,-4,21:18.6
10,-5,22:18.6
11,-5,22:18.6
10,-4,22:18.6
11,-4,22:18.6
10,-5,23:18.6
11,-5,23:18.6
10,-4,23:18.6
11,-4,23:18.6
11,-5,24:17.0
11,-4,24:17.0
