[META]
version=2.0
spawnOnBlockType=2
spawnSunlight=True
spawnDarkness=True
spawnWater=False
spawnLava=False
underFill=False
randomRotation=True
dig=True
tree=False
branch=False
needsFoundation=True
rarity=100
collisionPercentage=20
spawnElevationMin=0
spawnElevationMax=200
spawnInBiome=Custom
[DATA]
-3,0,-8:17.12
-2,0,-8:17.12
2,4,-8:17.12
-8,5,-8:17.12
-5,5,-8:17.12
-4,5,-8:17.12
-1,-1,-7:17.12
-3,0,-7:17.12
-2,0,-7:17.12
-1,0,-7:17.12
0,3,-7:17.12
1,3,-7:17.12
-9,4,-7:17.12
-8,4,-7:17.12
-7,4,-7:17.12
-5,4,-7:17.12
-4,4,-7:17.12
1,4,-7:17.12
2,4,-7:17.12
-8,5,-7:17.12
-7,5,-7:17.12
-5,5,-7:17.12
1,5,-7:17.12
-8,6,-7:17.12
-5,6,-7:17.12
-2,8,-7:17.12
-4,-1,-6:17.12
-2,-1,-6:17.12
-3,0,-6:17.12
-2,0,-6:17.12
-4,1,-6:17.12
-3,1,-6:17.12
-5,4,-6:17.12
0,4,-6:17.12
1,4,-6:17.12
2,4,-6:17.12
3,4,-6:17.12
-9,5,-6:17.12
-8,5,-6:17.12
-6,5,-6:17.12
-5,5,-6:17.12
-4,5,-6:17.12
-3,5,-6:17.12
1,5,-6:17.12
2,5,-6:17.12
-1,7,-6:17.12
0,7,-6:17.12
-1,8,-6:17.12
-2,9,-6:17.12
-1,9,-6:17.12
0,9,-6:17.12
-4,-1,-5:17.12
-3,-1,-5:17.12
-4,0,-5:17.12
-3,0,-5:17.12
-2,0,-5:17.12
-5,1,-5:17.12
-3,1,-5:17.12
-8,3,-5:17.12
-7,3,-5:17.12
-5,3,-5:17.12
1,3,-5:17.12
2,3,-5:17.12
-9,4,-5:17.12
-8,4,-5:17.12
-7,4,-5:17.12
-6,4,-5:17.12
-4,4,-5:17.12
1,4,-5:17.12
2,4,-5:17.12
3,4,-5:17.12
-9,5,-5:17.12
-8,5,-5:17.12
-6,5,-5:17.12
-5,5,-5:17.12
-4,5,-5:17.12
1,5,-5:17.12
-8,6,-5:17.12
-4,6,-5:17.12
-2,7,-5:17.12
-1,7,-5:17.12
0,7,-5:17.12
-2,8,-5:17.12
-1,8,-5:17.12
-1,9,-5:17.12
-2,-1,-4:17.12
-4,0,-4:17.12
-3,0,-4:17.12
-2,0,-4:17.12
-5,1,-4:17.12
-4,1,-4:17.12
-3,1,-4:17.12
-2,1,-4:17.12
-5,2,-4:17.12
-4,2,-4:17.12
-3,2,-4:17.12
-8,3,-4:17.12
-5,3,-4:17.12
2,3,-4:17.12
-9,4,-4:17.12
-8,4,-4:17.12
-7,4,-4:17.12
-6,4,-4:17.12
-5,4,-4:17.12
-4,4,-4:17.12
1,4,-4:17.12
2,4,-4:17.12
3,4,-4:17.12
-8,5,-4:17.12
-7,5,-4:17.12
-6,5,-4:17.12
-5,5,-4:17.12
-4,5,-4:17.12
1,5,-4:17.12
2,5,-4:17.12
3,5,-4:17.12
-5,6,-4:17.12
-2,7,-4:17.12
-1,7,-4:17.12
0,7,-4:17.12
0,8,-4:17.12
-4,1,-3:17.12
-3,1,-3:17.12
-4,2,-3:17.12
-3,2,-3:17.12
-2,2,-3:17.12
-7,3,-3:17.12
-5,3,-3:17.12
-4,3,-3:17.12
2,3,-3:17.12
-9,4,-3:17.12
-8,4,-3:17.12
-7,4,-3:17.12
-6,4,-3:17.12
-5,4,-3:17.12
-4,4,-3:17.12
1,4,-3:17.12
2,4,-3:17.12
3,4,-3:17.12
-8,5,-3:17.12
-7,5,-3:17.12
-6,5,-3:17.12
-5,5,-3:17.12
1,5,-3:17.12
2,5,-3:17.12
-2,6,-3:17.12
-1,6,-3:17.12
2,6,-3:17.12
-2,7,-3:17.12
-1,7,-3:17.12
0,7,-3:17.12
-2,8,-3:17.12
-1,8,-3:17.12
0,8,-3:17.12
-5,1,-2:17.12
-4,1,-2:17.12
-3,1,-2:17.12
-6,2,-2:17.12
-5,2,-2:17.12
-4,2,-2:17.12
-3,2,-2:17.12
-9,3,-2:17.12
-8,3,-2:17.12
-7,3,-2:17.12
-6,3,-2:17.12
-5,3,-2:17.12
-4,3,-2:17.12
-3,3,-2:17.12
-2,3,-2:17.12
0,3,-2:17.12
1,3,-2:17.12
2,3,-2:17.12
3,3,-2:17.12
-9,4,-2:17.12
-8,4,-2:17.12
-7,4,-2:17.12
-6,4,-2:17.12
-5,4,-2:17.12
-4,4,-2:17.12
-3,4,-2:17.12
-2,4,-2:17.12
-1,4,-2:17.12
0,4,-2:17.12
1,4,-2:17.12
2,4,-2:17.12
3,4,-2:17.12
-9,5,-2:17.12
-8,5,-2:17.12
-7,5,-2:17.12
-6,5,-2:17.12
-5,5,-2:17.12
-4,5,-2:17.12
-3,5,-2:17.12
-2,5,-2:17.12
0,5,-2:17.12
1,5,-2:17.12
2,5,-2:17.12
3,5,-2:17.12
-8,6,-2:17.12
-7,6,-2:17.12
-5,6,-2:17.12
-4,6,-2:17.12
-3,6,-2:17.12
-1,6,-2:17.12
0,6,-2:17.12
1,6,-2:17.12
2,6,-2:17.12
3,6,-2:17.12
-2,7,-2:17.12
-1,7,-2:17.12
0,7,-2:17.12
-2,8,-2:17.12
-1,8,-2:17.12
0,8,-2:17.12
-6,2,-1:17.12
-5,2,-1:17.12
-4,2,-1:17.12
-3,2,-1:17.12
-9,3,-1:17.12
-8,3,-1:17.12
-6,3,-1:17.12
-5,3,-1:17.12
-3,3,-1:17.12
0,3,-1:17.12
1,3,-1:17.12
2,3,-1:17.12
3,3,-1:17.12
-9,4,-1:17.12
-8,4,-1:17.12
-7,4,-1:17.12
-6,4,-1:17.12
-5,4,-1:17.12
-2,4,-1:17.12
0,4,-1:17.12
3,4,-1:17.12
-8,5,-1:17.12
-6,5,-1:17.12
-5,5,-1:17.12
-4,5,-1:17.12
-3,5,-1:17.12
0,5,-1:17.12
2,5,-1:17.12
3,5,-1:17.12
-4,6,-1:17.12
-3,6,-1:17.12
-2,6,-1:17.12
-1,6,-1:17.12
0,6,-1:17.12
1,6,-1:17.12
2,6,-1:17.12
3,6,-1:17.12
-2,7,-1:17.12
-1,7,-1:17.12
0,7,-1:17.12
-2,8,-1:17.12
-1,8,-1:17.12
0,8,-1:17.12
-5,2,0:17.12
-4,2,0:17.12
-3,2,0:17.12
-9,3,0:17.12
-8,3,0:17.12
-6,3,0:17.12
-3,3,0:17.12
0,3,0:17.12
1,3,0:17.12
2,3,0:17.12
3,3,0:17.12
-9,4,0:17.12
-8,4,0:17.12
-6,4,0:17.12
-2,4,0:17.12
0,4,0:17.12
3,4,0:17.12
-6,5,0:17.12
-5,5,0:17.12
-4,5,0:17.12
-3,5,0:17.12
0,5,0:17.12
3,5,0:17.12
-4,6,0:17.12
-3,6,0:17.12
-2,6,0:17.12
-1,6,0:17.12
0,6,0:17.12
1,6,0:17.12
2,6,0:17.12
-2,7,0:17.12
-1,7,0:17.12
0,7,0:17.12
-2,8,0:17.12
-1,8,0:17.12
-5,2,1:17.12
-4,2,1:17.12
-3,2,1:17.12
-9,3,1:17.12
-8,3,1:17.12
-6,3,1:17.12
-5,3,1:17.12
-3,3,1:17.12
0,3,1:17.12
1,3,1:17.12
2,3,1:17.12
-9,4,1:17.12
-8,4,1:17.12
-6,4,1:17.12
-2,4,1:17.12
0,4,1:17.12
2,4,1:17.12
3,4,1:17.12
-5,5,1:17.12
-3,5,1:17.12
-2,5,1:17.12
0,5,1:17.12
2,5,1:17.12
3,5,1:17.12
-4,6,1:17.12
-3,6,1:17.12
0,6,1:17.12
1,6,1:17.12
2,6,1:17.12
-2,7,1:17.12
-1,7,1:17.12
-2,8,1:17.12
-1,8,1:17.12
-4,2,2:17.12
-10,3,2:18.14
-9,3,2:17.12
-5,3,2:17.12
-4,3,2:17.12
-3,3,2:17.12
0,3,2:17.12
1,3,2:17.12
2,3,2:17.12
-10,4,2:18.14
-9,4,2:17.12
-8,4,2:17.12
-7,4,2:18.14
-6,4,2:17.12
-2,4,2:17.12
0,4,2:17.12
2,4,2:17.12
-8,5,2:18.14
-5,5,2:17.12
-3,5,2:17.12
-2,5,2:17.12
0,5,2:17.12
2,5,2:17.12
-4,6,2:17.12
-3,6,2:17.12
1,6,2:17.12
2,6,2:17.12
-2,7,2:17.12
-1,7,2:17.12
-2,8,2:17.12
-9,2,3:18.14
-9,3,3:17.12
-5,3,3:17.12
-4,3,3:17.12
-3,3,3:17.12
0,3,3:17.12
1,3,3:17.12
2,3,3:17.12
-11,4,3:18.12
-10,4,3:18.14
-9,4,3:17.12
-8,4,3:17.12
-7,4,3:18.14
-6,4,3:17.12
-5,4,3:17.12
-3,4,3:17.12
-2,4,3:17.12
0,4,3:17.12
2,4,3:17.12
-10,5,3:18.12
-9,5,3:18.12
-8,5,3:18.14
-7,5,3:18.14
-5,5,3:17.12
-3,5,3:17.12
-2,5,3:17.12
0,5,3:17.12
1,5,3:17.12
2,5,3:17.12
-8,6,3:18.14
-4,6,3:17.12
-3,6,3:17.12
-2,7,3:17.12
-1,7,3:17.12
-2,8,3:17.12
-9,2,4:18.14
-11,3,4:18.12
-10,3,4:18.12
-9,3,4:18.12
-8,3,4:18.12
-5,3,4:17.12
-4,3,4:17.12
-3,3,4:17.12
0,3,4:17.12
1,3,4:17.12
-11,4,4:18.12
-10,4,4:18.12
-9,4,4:17.12
-8,4,4:18.14
-7,4,4:18.14
-5,4,4:17.12
-3,4,4:17.12
-2,4,4:17.12
0,4,4:17.12
2,4,4:17.12
-10,5,4:18.12
-9,5,4:18.12
-7,5,4:18.14
-6,5,4:18.14
-5,5,4:17.12
-3,5,4:17.12
-2,5,4:17.12
0,5,4:17.12
1,5,4:17.12
2,5,4:17.12
-8,6,4:18.14
-4,6,4:17.12
-3,6,4:17.12
-3,7,4:18.14
-2,7,4:18.14
-1,7,4:17.12
0,7,4:18.14
-3,8,4:18.14
-2,8,4:18.14
-1,8,4:18.14
-8,2,5:18.12
-7,2,5:18.12
-9,3,5:18.12
-8,3,5:18.12
-7,3,5:18.12
-6,3,5:18.12
-5,3,5:17.12
-4,3,5:17.12
-3,3,5:17.12
1,3,5:17.12
-9,4,5:18.12
-8,4,5:18.14
-7,4,5:18.14
-6,4,5:18.12
-5,4,5:17.12
-3,4,5:17.12
0,4,5:17.12
2,4,5:17.12
-9,5,5:18.12
-8,5,5:18.14
-7,5,5:18.14
-6,5,5:18.12
-5,5,5:17.12
-4,5,5:17.12
-3,5,5:17.12
0,5,5:17.12
1,5,5:17.12
2,5,5:17.12
-8,6,5:18.12
-7,6,5:18.12
-6,6,5:18.12
-5,6,5:18.12
-4,6,5:17.12
-3,6,5:18.12
-2,6,5:18.12
-7,7,5:18.12
-4,7,5:18.12
-3,7,5:18.12
-2,7,5:18.12
-1,7,5:18.14
0,7,5:18.14
1,7,5:18.14
-4,8,5:18.12
-3,8,5:18.12
-2,8,5:18.12
-1,8,5:18.12
0,8,5:18.14
-3,9,5:18.12
-2,9,5:18.12
-8,3,6:18.12
-7,3,6:18.12
-5,3,6:17.12
-4,3,6:17.12
-3,3,6:17.12
1,3,6:17.12
-9,4,6:18.12
-8,4,6:18.12
-7,4,6:18.12
-6,4,6:18.12
-5,4,6:17.12
-4,4,6:18.12
-3,4,6:17.12
0,4,6:17.12
1,4,6:17.12
2,4,6:17.12
-9,5,6:18.12
-8,5,6:18.12
-7,5,6:18.12
-6,5,6:18.12
-5,5,6:17.12
-4,5,6:17.12
-3,5,6:17.12
-1,5,6:18.12
0,5,6:17.12
1,5,6:17.12
2,5,6:17.12
-7,6,6:18.12
-2,6,6:18.12
-1,6,6:18.14
0,6,6:18.14
1,6,6:18.12
2,6,6:18.12
-3,7,6:18.12
-2,7,6:18.12
-1,7,6:18.14
0,7,6:18.14
1,7,6:18.14
2,7,6:18.12
-3,8,6:18.12
-2,8,6:18.12
-1,8,6:18.14
0,8,6:18.14
1,8,6:18.14
2,8,6:18.12
-1,9,6:18.12
0,9,6:18.12
1,9,6:18.12
0,12,6:18.12
1,-5,7:18.4
0,-4,7:18.4
0,-3,7:18.4
-1,-2,7:18.4
5,-1,7:18.12
4,0,7:18.12
5,0,7:18.12
3,1,7:18.12
4,1,7:18.12
3,2,7:18.12
-5,3,7:17.12
-4,3,7:17.12
-3,3,7:17.12
2,3,7:18.12
3,3,7:18.12
-8,4,7:18.12
-7,4,7:18.12
-6,4,7:18.12
-5,4,7:17.12
-4,4,7:18.12
-3,4,7:17.12
-2,4,7:18.12
-1,4,7:18.12
0,4,7:17.12
1,4,7:17.12
2,4,7:17.12
-5,5,7:17.12
-4,5,7:17.12
-3,5,7:17.12
0,5,7:17.12
1,5,7:17.12
2,5,7:18.12
-2,6,7:18.12
-1,6,7:18.12
0,6,7:18.12
1,6,7:18.12
2,6,7:18.12
3,6,7:18.12
-2,7,7:18.12
-1,7,7:18.12
0,7,7:18.12
1,7,7:18.12
2,7,7:18.12
3,7,7:18.12
-2,8,7:18.12
-1,8,7:18.12
0,8,7:18.12
1,8,7:18.12
4,8,7:18.12
-2,9,7:18.12
4,9,7:18.12
-1,10,7:18.12
4,10,7:18.4
-1,11,7:18.12
5,11,7:18.4
0,12,7:18.12
0,13,7:18.4
6,13,7:18.4
1,15,7:18.4
2,16,7:18.4
2,-7,8:18.4
1,-5,8:18.4
0,-4,8:18.4
7,-4,8:18.4
0,-3,8:18.4
6,-3,8:18.4
7,-3,8:18.4
-1,-2,8:18.4
6,-2,8:18.4
-2,-1,8:18.12
-1,-1,8:18.12
5,-1,8:18.12
-2,0,8:18.12
4,0,8:18.12
5,0,8:18.12
-3,1,8:18.12
3,1,8:18.12
4,1,8:18.12
-4,2,8:18.12
-3,2,8:18.12
3,2,8:18.12
-14,3,8:18.4
-13,3,8:18.12
-12,3,8:18.12
-11,3,8:18.12
-10,3,8:18.12
-6,3,8:18.12
-5,3,8:17.12
-4,3,8:18.12
-3,3,8:17.12
2,3,8:18.12
3,3,8:18.12
-6,4,8:18.12
-5,4,8:17.12
-4,4,8:18.12
-3,4,8:17.12
-2,4,8:18.12
-1,4,8:18.12
0,4,8:18.12
1,4,8:17.12
2,4,8:17.12
-5,5,8:17.12
-4,5,8:18.12
-3,5,8:17.12
1,5,8:17.12
2,5,8:18.12
-3,6,8:18.12
2,6,8:18.12
3,6,8:18.12
-3,7,8:18.12
3,7,8:18.12
-2,8,8:18.12
4,8,8:18.12
-2,9,8:18.12
4,9,8:18.12
-1,10,8:18.12
5,10,8:18.4
-1,11,8:18.12
5,11,8:18.4
0,12,8:18.4
6,12,8:18.4
0,13,8:18.4
6,13,8:18.4
1,14,8:18.4
1,15,8:18.4
3,-8,9:18.4
2,-7,9:18.4
1,-6,9:18.4
2,-6,9:18.4
1,-5,9:18.4
0,-4,9:18.4
0,-3,9:18.4
6,-3,9:18.4
7,-3,9:18.4
-1,-2,9:18.4
6,-2,9:18.4
-2,-1,9:18.12
-1,-1,9:18.12
5,-1,9:18.12
-2,0,9:18.12
-3,1,9:18.12
3,1,9:18.12
4,1,9:18.12
-18,2,9:18.4
-17,2,9:18.4
-4,2,9:18.12
-3,2,9:18.12
3,2,9:18.12
-15,3,9:18.4
-14,3,9:18.4
-13,3,9:18.4
-12,3,9:18.4
-11,3,9:18.4
-10,3,9:18.4
-9,3,9:18.12
-8,3,9:18.12
-7,3,9:18.12
-6,3,9:18.12
-5,3,9:17.12
-4,3,9:18.12
2,3,9:18.12
3,3,9:18.12
-8,4,9:18.12
-7,4,9:18.12
-6,4,9:18.12
-5,4,9:17.12
-4,4,9:18.12
-3,4,9:17.12
-2,4,9:18.12
-1,4,9:18.12
0,4,9:18.12
1,4,9:17.12
2,4,9:17.12
-5,5,9:17.12
-4,5,9:17.12
-3,5,9:17.12
1,5,9:17.12
2,5,9:18.12
-3,6,9:18.12
3,6,9:18.12
-3,7,9:18.12
3,7,9:18.12
-2,8,9:18.12
4,8,9:18.12
-2,9,9:18.12
4,9,9:18.12
-1,10,9:18.12
4,10,9:18.4
5,10,9:18.4
-1,11,9:18.4
5,11,9:18.4
0,12,9:18.4
6,12,9:18.4
0,13,9:18.4
6,13,9:18.4
1,-5,10:18.4
0,-4,10:18.4
0,-3,10:18.4
7,-3,10:18.4
-1,-2,10:18.4
6,-2,10:18.4
-5,-1,10:18.12
-2,-1,10:18.12
5,-1,10:18.12
-5,0,10:18.12
-2,0,10:18.12
4,0,10:18.12
5,0,10:18.12
-6,1,10:18.12
-5,1,10:18.12
-3,1,10:18.12
3,1,10:18.12
4,1,10:18.12
-18,2,10:18.4
-17,2,10:18.4
-16,2,10:18.4
-6,2,10:18.12
3,2,10:18.12
-16,3,10:18.4
-15,3,10:18.4
-13,3,10:18.4
-12,3,10:18.4
-11,3,10:18.4
-10,3,10:18.4
-9,3,10:18.12
-8,3,10:18.12
-7,3,10:18.12
-6,3,10:18.12
-5,3,10:17.12
-4,3,10:17.12
2,3,10:18.12
3,3,10:18.12
-8,4,10:18.12
-7,4,10:18.12
-6,4,10:18.12
-5,4,10:17.12
-4,4,10:18.12
-3,4,10:17.12
-2,4,10:18.12
-1,4,10:18.12
0,4,10:18.12
1,4,10:17.12
2,4,10:18.12
-7,5,10:18.12
-6,5,10:18.12
-4,5,10:17.12
1,5,10:17.12
2,5,10:18.12
-7,6,10:18.12
-6,6,10:18.12
-3,6,10:18.12
2,6,10:18.12
3,6,10:18.12
-6,7,10:18.12
-3,7,10:18.12
3,7,10:18.12
-2,8,10:18.12
4,8,10:18.12
-5,9,10:18.12
-2,9,10:18.12
4,9,10:18.12
-1,10,10:18.4
4,10,10:18.4
5,10,10:18.4
-1,11,10:18.4
5,11,10:18.4
-1,12,10:18.4
0,12,10:18.4
6,12,10:18.4
0,13,10:18.4
6,13,10:18.4
1,14,10:18.4
1,15,10:18.4
3,-8,11:18.4
2,-7,11:18.4
1,-6,11:18.4
2,-6,11:18.4
1,-5,11:18.4
-2,-4,11:18.4
-1,-4,11:18.4
0,-4,11:18.4
1,-4,11:18.4
2,-4,11:18.4
3,-4,11:18.4
4,-4,11:18.4
5,-4,11:18.4
6,-4,11:18.4
7,-4,11:18.4
-3,-3,11:18.4
-2,-3,11:18.4
-1,-3,11:18.4
0,-3,11:18.4
1,-3,11:18.4
2,-3,11:18.4
3,-3,11:18.4
4,-3,11:18.4
5,-3,11:18.4
6,-3,11:18.4
7,-3,11:18.4
8,-3,11:18.4
-4,-2,11:18.4
-3,-2,11:18.4
-2,-2,11:18.4
-1,-2,11:18.4
0,-2,11:18.4
2,-2,11:18.4
3,-2,11:18.4
4,-2,11:18.4
5,-2,11:18.4
6,-2,11:18.4
7,-2,11:18.4
8,-2,11:18.4
9,-2,11:18.4
-4,-1,11:18.12
-3,-1,11:18.12
-2,-1,11:18.12
-1,-1,11:18.12
0,-1,11:18.12
1,-1,11:18.12
2,-1,11:18.4
3,-1,11:18.4
5,-1,11:18.4
6,-1,11:18.4
7,-1,11:18.4
8,-1,11:18.4
9,-1,11:18.4
-5,0,11:18.12
-4,0,11:18.12
-3,0,11:18.12
-2,0,11:18.12
-1,0,11:18.12
0,0,11:18.12
4,0,11:18.12
5,0,11:18.12
6,0,11:18.12
7,0,11:18.4
8,0,11:18.4
9,0,11:18.4
10,0,11:18.4
-5,1,11:18.12
-4,1,11:18.12
-3,1,11:18.12
-2,1,11:18.12
-1,1,11:18.12
4,1,11:18.12
7,1,11:18.4
11,1,11:18.4
-16,2,11:18.4
-6,2,11:18.12
-5,2,11:18.12
-4,2,11:18.12
-3,2,11:18.12
-2,2,11:18.12
-1,2,11:18.12
3,2,11:18.12
8,2,11:18.4
9,2,11:18.4
10,2,11:18.4
11,2,11:18.4
-15,3,11:18.4
-14,3,11:18.4
-13,3,11:18.4
-12,3,11:18.4
-11,3,11:18.4
-10,3,11:18.4
-9,3,11:18.12
-8,3,11:18.12
-7,3,11:18.12
-6,3,11:18.12
-5,3,11:18.12
-4,3,11:18.12
-3,3,11:18.12
-2,3,11:18.12
2,3,11:18.12
3,3,11:18.12
9,3,11:18.4
10,3,11:18.4
11,3,11:18.4
-7,4,11:18.12
-6,4,11:18.12
-5,4,11:18.12
-4,4,11:18.12
-2,4,11:18.12
-1,4,11:18.12
1,4,11:17.12
2,4,11:18.12
11,4,11:18.4
-6,5,11:18.12
-5,5,11:18.12
-4,5,11:18.12
-3,5,11:18.12
-2,5,11:18.12
1,5,11:17.12
2,5,11:18.12
-6,6,11:18.12
-5,6,11:18.12
-4,6,11:18.12
-3,6,11:18.12
-2,6,11:18.12
3,6,11:18.12
10,6,11:18.4
11,6,11:18.4
-6,7,11:18.12
-5,7,11:18.12
-4,7,11:18.12
-3,7,11:18.12
-2,7,11:18.12
-1,7,11:18.12
3,7,11:18.12
9,7,11:18.4
10,7,11:18.4
11,7,11:18.4
-5,8,11:18.12
-4,8,11:18.12
-3,8,11:18.12
-2,8,11:18.12
-1,8,11:18.12
4,8,11:18.12
7,8,11:18.4
8,8,11:18.4
9,8,11:18.4
10,8,11:18.4
-5,9,11:18.12
-4,9,11:18.12
-3,9,11:18.12
-2,9,11:18.12
-1,9,11:18.12
0,9,11:18.12
1,9,11:18.12
2,9,11:18.12
4,9,11:18.12
6,9,11:18.4
7,9,11:18.4
8,9,11:18.4
9,9,11:18.4
10,9,11:18.4
-4,10,11:18.4
-3,10,11:18.4
-2,10,11:18.4
-1,10,11:18.4
0,10,11:18.4
1,10,11:18.4
2,10,11:18.4
3,10,11:18.4
4,10,11:18.4
5,10,11:18.4
6,10,11:18.4
7,10,11:18.4
8,10,11:18.4
9,10,11:18.4
-4,11,11:18.4
-3,11,11:18.4
-2,11,11:18.4
-1,11,11:18.4
0,11,11:18.4
1,11,11:18.4
2,11,11:18.4
3,11,11:18.4
4,11,11:18.4
5,11,11:18.4
6,11,11:18.4
7,11,11:18.4
8,11,11:18.4
-3,12,11:18.4
-2,12,11:18.4
-1,12,11:18.4
0,12,11:18.4
1,12,11:18.4
2,12,11:18.4
3,12,11:18.4
4,12,11:18.4
5,12,11:18.4
6,12,11:18.4
7,12,11:18.4
-1,13,11:18.4
0,13,11:18.4
1,13,11:18.4
2,13,11:18.4
3,13,11:18.4
4,13,11:18.4
5,13,11:18.4
6,13,11:18.4
7,13,11:18.4
0,14,11:18.4
1,14,11:18.4
1,15,11:18.4
3,-8,12:18.4
2,-7,12:18.4
1,-6,12:18.4
2,-6,12:18.4
1,-5,12:18.4
0,-4,12:18.4
-1,-3,12:18.4
0,-3,12:18.4
1,-3,12:18.4
2,-3,12:18.4
-2,-2,12:18.4
-1,-2,12:18.4
0,-2,12:18.4
2,-2,12:18.4
3,-2,12:18.4
4,-2,12:18.4
5,-2,12:18.4
6,-2,12:18.4
7,-2,12:18.4
-2,-1,12:18.12
-1,-1,12:18.12
0,-1,12:18.12
1,-1,12:18.12
2,-1,12:18.4
3,-1,12:18.4
5,-1,12:18.4
6,-1,12:18.4
7,-1,12:18.4
8,-1,12:18.4
-3,0,12:18.12
-2,0,12:18.12
-1,0,12:18.12
0,0,12:18.12
1,0,12:18.12
2,0,12:18.12
3,0,12:18.12
4,0,12:18.12
5,0,12:18.12
6,0,12:18.12
7,0,12:18.4
8,0,12:18.4
-3,1,12:18.12
-2,1,12:18.12
-1,1,12:18.12
0,1,12:18.12
1,1,12:18.12
2,1,12:18.12
3,1,12:18.12
4,1,12:18.12
5,1,12:18.12
6,1,12:18.12
7,1,12:18.4
8,1,12:18.4
9,1,12:18.4
-18,2,12:18.4
-17,2,12:18.4
-16,2,12:18.4
-15,2,12:18.4
-14,2,12:18.4
-4,2,12:18.12
-3,2,12:18.12
-2,2,12:18.12
-1,2,12:18.12
0,2,12:18.12
1,2,12:18.12
2,2,12:18.12
3,2,12:18.12
6,2,12:18.12
7,2,12:18.4
8,2,12:18.4
9,2,12:18.4
10,2,12:18.4
-14,3,12:18.4
-13,3,12:18.4
-12,3,12:18.4
-11,3,12:18.4
-10,3,12:18.4
-9,3,12:18.12
-8,3,12:18.12
-6,3,12:18.12
-5,3,12:17.12
-4,3,12:18.12
-3,3,12:18.12
-1,3,12:18.12
0,3,12:18.12
1,3,12:18.12
2,3,12:18.12
3,3,12:18.12
4,3,12:18.12
5,3,12:18.12
6,3,12:18.12
7,3,12:18.4
8,3,12:18.4
9,3,12:18.4
10,3,12:18.4
11,3,12:18.4
-6,4,12:18.12
-5,4,12:18.12
-4,4,12:18.12
-2,4,12:18.12
-1,4,12:18.12
0,4,12:18.12
1,4,12:18.12
2,4,12:18.12
3,4,12:18.12
4,4,12:18.12
5,4,12:18.12
6,4,12:18.12
7,4,12:18.4
8,4,12:18.4
9,4,12:18.4
10,4,12:18.4
11,4,12:18.4
-4,5,12:18.12
-3,5,12:18.12
-1,5,12:18.12
0,5,12:18.12
1,5,12:18.12
2,5,12:18.12
3,5,12:18.12
4,5,12:18.12
5,5,12:18.12
6,5,12:18.12
7,5,12:18.4
8,5,12:18.4
9,5,12:18.4
10,5,12:18.4
11,5,12:18.4
12,5,12:18.4
-4,6,12:18.12
-3,6,12:18.12
-1,6,12:18.12
0,6,12:18.12
1,6,12:18.12
2,6,12:18.12
3,6,12:18.12
4,6,12:18.12
5,6,12:18.12
6,6,12:18.12
7,6,12:18.4
8,6,12:18.4
9,6,12:18.4
10,6,12:18.4
11,6,12:18.4
12,6,12:18.4
-4,7,12:18.12
-3,7,12:18.12
-2,7,12:18.12
-1,7,12:18.12
0,7,12:18.12
1,7,12:18.12
2,7,12:18.12
3,7,12:18.12
4,7,12:18.12
5,7,12:18.12
6,7,12:18.12
7,7,12:18.4
8,7,12:18.4
9,7,12:18.4
10,7,12:18.4
-3,8,12:18.12
-2,8,12:18.12
-1,8,12:18.12
0,8,12:18.12
1,8,12:18.12
2,8,12:18.12
4,8,12:18.12
5,8,12:18.12
6,8,12:18.12
7,8,12:18.4
8,8,12:18.4
9,8,12:18.4
-3,9,12:18.12
-2,9,12:18.12
-1,9,12:18.12
0,9,12:18.12
1,9,12:18.12
2,9,12:18.12
3,9,12:18.12
4,9,12:18.12
5,9,12:18.12
6,9,12:18.4
7,9,12:18.4
8,9,12:18.4
-3,10,12:18.4
-2,10,12:18.4
-1,10,12:18.4
0,10,12:18.4
1,10,12:18.4
2,10,12:18.4
3,10,12:18.4
4,10,12:18.4
5,10,12:18.4
6,10,12:18.4
7,10,12:18.4
-2,11,12:18.4
-1,11,12:18.4
0,11,12:18.4
1,11,12:18.4
2,11,12:18.4
3,11,12:18.4
4,11,12:18.4
5,11,12:18.4
6,11,12:18.4
-1,12,12:18.4
0,12,12:18.4
2,12,12:18.4
3,12,12:18.4
4,12,12:18.4
5,12,12:18.4
-2,13,12:18.4
-1,13,12:18.4
0,13,12:18.4
1,13,12:18.4
2,13,12:18.4
-7,14,12:18.4
-6,14,12:18.4
-5,14,12:18.4
-4,14,12:18.4
-3,14,12:18.4
-2,14,12:18.4
-1,14,12:18.4
0,14,12:18.4
1,14,12:18.4
2,14,12:18.4
-1,15,12:18.4
0,15,12:18.4
1,15,12:18.4
-5,-9,13:18.4
-4,-9,13:18.4
-3,-9,13:18.4
-2,-9,13:18.4
-1,-9,13:18.4
-2,-8,13:18.4
-1,-8,13:18.4
0,-8,13:18.4
1,-8,13:18.4
2,-8,13:18.4
3,-8,13:18.4
-1,-7,13:18.4
0,-7,13:18.4
1,-7,13:18.4
2,-7,13:18.4
3,-7,13:18.4
1,-6,13:18.4
2,-6,13:18.4
3,-6,13:18.4
4,-6,13:18.4
-14,-5,13:18.4
1,-5,13:18.4
2,-5,13:18.4
3,-5,13:18.4
4,-5,13:18.4
5,-5,13:18.4
0,-4,13:18.4
2,-4,13:18.4
3,-4,13:18.4
4,-4,13:18.4
5,-4,13:18.4
-15,-3,13:18.4
-1,-3,13:18.4
0,-3,13:18.4
2,-3,13:18.4
3,-3,13:18.4
4,-3,13:18.4
5,-3,13:18.4
-16,-2,13:18.4
-15,-2,13:18.4
-1,-2,13:18.4
3,-2,13:18.4
4,-2,13:18.4
5,-2,13:18.4
6,-2,13:18.4
-16,-1,13:18.4
-15,-1,13:18.4
-2,-1,13:18.12
-1,-1,13:18.12
0,-1,13:18.12
3,-1,13:18.4
5,-1,13:18.4
6,-1,13:18.4
-17,0,13:18.4
-16,0,13:18.4
-15,0,13:18.4
-2,0,13:18.12
-1,0,13:18.12
0,0,13:18.12
1,0,13:18.12
2,0,13:18.12
3,0,13:18.12
4,0,13:18.12
5,0,13:18.12
6,0,13:18.12
7,0,13:18.4
-18,1,13:18.4
-17,1,13:18.4
-16,1,13:18.4
-15,1,13:18.4
-3,1,13:18.12
-1,1,13:18.12
0,1,13:18.12
1,1,13:18.12
2,1,13:18.12
3,1,13:18.12
4,1,13:18.12
5,1,13:18.12
6,1,13:18.12
7,1,13:18.4
-18,2,13:18.4
-17,2,13:18.4
-16,2,13:18.4
-15,2,13:18.4
-14,2,13:18.4
-2,2,13:18.12
-1,2,13:18.12
0,2,13:18.12
3,2,13:18.12
4,2,13:18.12
5,2,13:18.12
6,2,13:18.12
7,2,13:18.4
-18,3,13:18.4
-17,3,13:18.4
-16,3,13:18.4
-15,3,13:18.4
-13,3,13:18.4
-12,3,13:18.4
-11,3,13:18.4
-10,3,13:18.4
-9,3,13:18.12
-8,3,13:18.12
-7,3,13:18.12
-6,3,13:18.12
-5,3,13:18.12
-4,3,13:18.12
-2,3,13:18.12
-1,3,13:18.12
2,3,13:18.12
6,3,13:18.12
7,3,13:18.4
8,3,13:18.4
-17,4,13:18.4
-16,4,13:18.4
-15,4,13:18.4
-14,4,13:18.4
-5,4,13:18.12
-4,4,13:18.12
-2,4,13:18.12
-1,4,13:18.12
0,4,13:18.12
1,4,13:18.12
2,4,13:18.12
3,4,13:18.12
4,4,13:18.12
5,4,13:18.12
6,4,13:18.12
7,4,13:18.4
8,4,13:18.4
9,4,13:18.4
-17,5,13:18.4
-16,5,13:18.4
-15,5,13:18.4
-14,5,13:18.4
-2,5,13:18.12
-1,5,13:18.12
2,5,13:18.12
3,5,13:18.12
4,5,13:18.12
5,5,13:18.12
6,5,13:18.12
7,5,13:18.4
8,5,13:18.4
9,5,13:18.4
-16,6,13:18.4
-15,6,13:18.4
-14,6,13:18.4
-13,6,13:18.4
-3,6,13:18.12
-2,6,13:18.12
-1,6,13:18.12
2,6,13:18.12
3,6,13:18.12
4,6,13:18.12
5,6,13:18.12
6,6,13:18.12
7,6,13:18.4
8,6,13:18.4
-16,7,13:18.4
-15,7,13:18.4
-14,7,13:18.4
-13,7,13:18.4
-12,7,13:18.4
-3,7,13:18.12
-2,7,13:18.12
-1,7,13:18.12
0,7,13:18.12
1,7,13:18.12
2,7,13:18.12
3,7,13:18.12
4,7,13:18.12
5,7,13:18.12
6,7,13:18.12
7,7,13:18.4
-15,8,13:18.4
-14,8,13:18.4
-13,8,13:18.4
-12,8,13:18.4
-2,8,13:18.12
-1,8,13:18.12
0,8,13:18.12
1,8,13:18.12
2,8,13:18.12
4,8,13:18.12
5,8,13:18.12
6,8,13:18.12
-15,9,13:18.4
-14,9,13:18.4
-13,9,13:18.4
-12,9,13:18.4
-11,9,13:18.4
-3,9,13:18.12
-2,9,13:18.12
-1,9,13:18.12
0,9,13:18.12
1,9,13:18.12
2,9,13:18.12
3,9,13:18.12
4,9,13:18.12
5,9,13:18.12
-14,10,13:18.4
-13,10,13:18.4
-12,10,13:18.4
-11,10,13:18.4
-9,10,13:18.4
-8,10,13:18.4
-7,10,13:18.4
-6,10,13:18.4
-5,10,13:18.4
-4,10,13:18.4
-3,10,13:18.4
-2,10,13:18.4
-1,10,13:18.4
0,10,13:18.4
1,10,13:18.4
2,10,13:18.4
3,10,13:18.4
4,10,13:18.4
-14,11,13:18.4
-13,11,13:18.4
-12,11,13:18.4
-11,11,13:18.4
-10,11,13:18.4
-9,11,13:18.4
-8,11,13:18.4
-7,11,13:18.4
-6,11,13:18.4
-5,11,13:18.4
-4,11,13:18.4
-3,11,13:18.4
-2,11,13:18.4
-1,11,13:18.4
0,11,13:18.4
1,11,13:18.4
2,11,13:18.4
3,11,13:18.4
4,11,13:18.4
5,11,13:18.4
-13,12,13:18.4
-12,12,13:18.4
-11,12,13:18.4
-10,12,13:18.4
-9,12,13:18.4
-8,12,13:18.4
-7,12,13:18.4
-6,12,13:18.4
-5,12,13:18.4
-4,12,13:18.4
-3,12,13:18.4
-2,12,13:18.4
-1,12,13:18.4
0,12,13:18.4
1,12,13:18.4
2,12,13:18.4
-12,13,13:18.4
-11,13,13:18.4
-10,13,13:18.4
-9,13,13:18.4
-8,13,13:18.4
-7,13,13:18.4
-6,13,13:18.4
-5,13,13:18.4
-4,13,13:18.4
-3,13,13:18.4
-2,13,13:18.4
-1,13,13:18.4
0,13,13:18.4
1,13,13:18.4
-10,14,13:18.4
-9,14,13:18.4
-8,14,13:18.4
-7,14,13:18.4
-6,14,13:18.4
-5,14,13:18.4
-4,14,13:18.4
-3,14,13:18.4
-2,14,13:18.4
-1,14,13:18.4
0,14,13:18.4
-10,-9,14:18.4
-9,-9,14:18.4
-8,-9,14:18.4
-7,-9,14:18.4
-6,-9,14:18.4
-5,-9,14:18.4
-4,-9,14:18.4
-11,-8,14:18.4
-10,-8,14:18.4
-9,-8,14:18.4
-8,-8,14:18.4
-7,-8,14:18.4
-6,-8,14:18.4
-5,-8,14:18.4
-4,-8,14:18.4
-3,-8,14:18.4
-2,-8,14:18.4
-1,-8,14:18.4
0,-8,14:18.4
-12,-7,14:18.4
-11,-7,14:18.4
-10,-7,14:18.4
-9,-7,14:18.4
-8,-7,14:18.4
-7,-7,14:18.4
-6,-7,14:18.4
-5,-7,14:18.4
-4,-7,14:18.4
-3,-7,14:18.4
-2,-7,14:18.4
-1,-7,14:18.4
0,-7,14:18.4
1,-7,14:18.4
2,-7,14:18.4
-13,-6,14:18.4
-12,-6,14:18.4
-11,-6,14:18.4
-10,-6,14:18.4
-9,-6,14:18.4
-8,-6,14:18.4
-7,-6,14:18.4
-6,-6,14:18.4
-5,-6,14:18.4
-4,-6,14:18.4
-3,-6,14:18.4
-2,-6,14:18.4
-1,-6,14:18.4
0,-6,14:18.4
1,-6,14:18.4
2,-6,14:18.4
3,-6,14:18.4
-14,-5,14:18.4
-13,-5,14:18.4
-12,-5,14:18.4
-11,-5,14:18.4
-10,-5,14:18.4
-9,-5,14:18.4
-8,-5,14:18.4
-7,-5,14:18.4
-6,-5,14:18.4
-5,-5,14:18.4
-4,-5,14:18.4
-3,-5,14:18.4
-2,-5,14:18.4
-1,-5,14:18.4
0,-5,14:18.4
1,-5,14:18.4
2,-5,14:18.4
3,-5,14:18.4
-14,-4,14:18.4
-13,-4,14:18.4
-12,-4,14:18.4
-11,-4,14:18.4
-10,-4,14:18.4
-9,-4,14:18.4
-8,-4,14:18.4
-7,-4,14:18.4
-6,-4,14:18.4
-5,-4,14:18.4
-4,-4,14:18.4
-3,-4,14:18.4
-2,-4,14:18.4
-1,-4,14:18.4
0,-4,14:18.4
1,-4,14:18.4
2,-4,14:18.4
3,-4,14:18.4
-14,-3,14:18.4
-13,-3,14:18.4
-12,-3,14:18.4
-11,-3,14:18.4
-10,-3,14:18.4
-9,-3,14:18.4
-8,-3,14:18.4
-7,-3,14:18.4
-6,-3,14:18.4
-5,-3,14:18.4
-4,-3,14:18.4
-3,-3,14:18.4
-2,-3,14:18.4
-1,-3,14:18.4
0,-3,14:18.4
1,-3,14:18.4
2,-3,14:18.4
3,-3,14:18.4
4,-3,14:18.4
-15,-2,14:18.4
-14,-2,14:18.4
-13,-2,14:18.4
-12,-2,14:18.4
-11,-2,14:18.4
-10,-2,14:18.4
-9,-2,14:18.4
-8,-2,14:18.4
-6,-2,14:18.4
-5,-2,14:18.4
-4,-2,14:18.4
-3,-2,14:18.4
-2,-2,14:18.4
-1,-2,14:18.4
0,-2,14:18.4
2,-2,14:18.4
3,-2,14:18.4
4,-2,14:18.4
-15,-1,14:18.4
-14,-1,14:18.4
-13,-1,14:18.4
-12,-1,14:18.4
-11,-1,14:18.4
-10,-1,14:18.4
-9,-1,14:18.12
-8,-1,14:18.12
-4,-1,14:18.12
-3,-1,14:18.12
-2,-1,14:18.12
-1,-1,14:18.12
0,-1,14:18.12
1,-1,14:18.4
2,-1,14:18.4
3,-1,14:18.4
5,-1,14:18.4
-16,0,14:18.4
-15,0,14:18.4
-14,0,14:18.4
-13,0,14:18.4
-12,0,14:18.4
-11,0,14:18.4
-10,0,14:18.4
-8,0,14:18.12
-3,0,14:18.12
-2,0,14:18.12
-1,0,14:18.12
0,0,14:18.12
1,0,14:18.12
2,0,14:18.12
3,0,14:18.12
4,0,14:18.12
5,0,14:18.12
-16,1,14:18.4
-15,1,14:18.4
-14,1,14:18.4
-13,1,14:18.4
-12,1,14:18.4
-11,1,14:18.4
-10,1,14:18.4
-9,1,14:18.12
-8,1,14:18.12
-3,1,14:18.12
-2,1,14:18.12
-1,1,14:18.12
0,1,14:18.12
1,1,14:18.12
2,1,14:18.12
3,1,14:18.12
4,1,14:18.12
5,1,14:18.12
-17,2,14:18.4
-16,2,14:18.4
-15,2,14:18.4
-14,2,14:18.4
-13,2,14:18.4
-12,2,14:18.4
-11,2,14:18.4
-10,2,14:18.4
-9,2,14:18.12
-8,2,14:18.12
-4,2,14:18.12
-2,2,14:18.12
-1,2,14:18.12
0,2,14:18.12
1,2,14:18.12
2,2,14:18.12
3,2,14:18.12
4,2,14:18.12
5,2,14:18.12
6,2,14:18.4
-16,3,14:18.4
-15,3,14:18.4
-14,3,14:18.4
-13,3,14:18.4
-12,3,14:18.4
-11,3,14:18.4
-10,3,14:18.4
-9,3,14:18.12
-8,3,14:18.12
-7,3,14:18.12
-5,3,14:18.12
-4,3,14:18.12
-1,3,14:18.12
0,3,14:18.12
1,3,14:18.12
2,3,14:18.12
3,3,14:18.12
4,3,14:18.12
5,3,14:18.12
6,3,14:18.4
7,3,14:18.4
-16,4,14:18.4
-15,4,14:18.4
-14,4,14:18.4
-13,4,14:18.4
-12,4,14:18.4
-11,4,14:18.4
-10,4,14:18.4
-9,4,14:18.12
-8,4,14:18.12
-5,4,14:18.12
-4,4,14:18.12
-2,4,14:18.12
-1,4,14:18.12
0,4,14:18.12
1,4,14:18.12
2,4,14:18.12
4,4,14:18.12
5,4,14:18.12
6,4,14:18.4
7,4,14:18.4
-15,5,14:18.4
-14,5,14:18.4
-13,5,14:18.4
-12,5,14:18.4
-11,5,14:18.4
-10,5,14:18.4
-9,5,14:18.12
-8,5,14:18.12
-7,5,14:18.12
-5,5,14:18.12
-4,5,14:18.12
-3,5,14:18.12
-2,5,14:18.12
-1,5,14:18.12
0,5,14:18.12
1,5,14:18.12
2,5,14:18.12
3,5,14:18.12
4,5,14:18.12
5,5,14:18.12
6,5,14:18.4
7,5,14:18.4
8,5,14:18.4
-15,6,14:18.4
-14,6,14:18.4
-13,6,14:18.4
-12,6,14:18.4
-11,6,14:18.4
-10,6,14:18.4
-9,6,14:18.12
-8,6,14:18.12
-7,6,14:18.12
-6,6,14:18.12
-5,6,14:18.12
-4,6,14:18.12
-3,6,14:18.12
-2,6,14:18.12
-1,6,14:18.12
0,6,14:18.12
1,6,14:18.12
2,6,14:18.12
3,6,14:18.12
4,6,14:18.12
5,6,14:18.12
9,6,14:18.4
-14,7,14:18.4
-13,7,14:18.4
-12,7,14:18.4
-11,7,14:18.4
-10,7,14:18.4
-9,7,14:18.12
-8,7,14:18.12
-7,7,14:18.12
-6,7,14:18.12
-5,7,14:18.12
-4,7,14:18.12
-3,7,14:18.12
-2,7,14:18.12
-1,7,14:18.12
0,7,14:18.12
1,7,14:18.12
2,7,14:18.12
3,7,14:18.12
4,7,14:18.12
-13,8,14:18.4
-12,8,14:18.4
-11,8,14:18.4
-10,8,14:18.4
-9,8,14:18.12
-8,8,14:18.12
-7,8,14:18.12
-5,8,14:18.12
-4,8,14:18.12
-3,8,14:18.12
-2,8,14:18.12
-1,8,14:18.12
1,8,14:18.12
2,8,14:18.12
-13,9,14:18.4
-12,9,14:18.4
-11,9,14:18.4
-10,9,14:18.4
-9,9,14:18.4
-8,9,14:18.12
-7,9,14:18.12
-6,9,14:18.12
-5,9,14:18.12
-4,9,14:18.12
-3,9,14:18.12
-2,9,14:18.12
0,9,14:18.12
1,9,14:18.12
2,9,14:18.12
3,9,14:18.12
-12,10,14:18.4
-11,10,14:18.4
-10,10,14:18.4
-9,10,14:18.4
-8,10,14:18.4
-7,10,14:18.4
-6,10,14:18.4
-3,10,14:18.4
-2,10,14:18.4
-1,10,14:18.4
0,10,14:18.4
1,10,14:18.4
3,10,14:18.4
4,10,14:18.4
-12,11,14:18.4
-11,11,14:18.4
-10,11,14:18.4
-9,11,14:18.4
-8,11,14:18.4
-7,11,14:18.4
-6,11,14:18.4
-5,11,14:18.4
-4,11,14:18.4
-3,11,14:18.4
-2,11,14:18.4
-1,11,14:18.4
0,11,14:18.4
4,11,14:18.4
-11,12,14:18.4
-10,12,14:18.4
-9,12,14:18.4
-8,12,14:18.4
-7,12,14:18.4
-6,12,14:18.4
-5,12,14:18.4
-4,12,14:18.4
-3,12,14:18.4
-2,12,14:18.4
-1,12,14:18.4
0,12,14:18.4
0,13,14:18.4
-10,-7,15:18.4
-9,-7,15:18.4
-8,-7,15:18.4
-7,-7,15:18.4
-10,-6,15:18.4
-9,-6,15:18.4
-8,-6,15:18.4
-7,-6,15:18.4
-6,-6,15:18.4
-5,-6,15:18.4
-4,-6,15:18.4
-3,-6,15:18.4
2,-6,15:18.4
-11,-5,15:18.4
-10,-5,15:18.4
-9,-5,15:18.4
-8,-5,15:18.4
-7,-5,15:18.4
-6,-5,15:18.4
-5,-5,15:18.4
-4,-5,15:18.4
-3,-5,15:18.4
-2,-5,15:18.4
-1,-5,15:18.4
0,-5,15:18.4
1,-5,15:18.4
2,-5,15:18.4
-11,-4,15:18.4
-10,-4,15:18.4
-9,-4,15:18.4
-6,-4,15:18.4
-5,-4,15:18.4
-4,-4,15:18.4
-3,-4,15:18.4
-2,-4,15:18.4
-1,-4,15:18.4
0,-4,15:18.4
1,-4,15:18.4
-12,-3,15:18.4
-11,-3,15:18.4
-10,-3,15:18.4
-9,-3,15:18.4
-2,-3,15:18.4
-1,-3,15:18.4
0,-3,15:18.4
1,-3,15:18.4
-12,-2,15:18.4
-11,-2,15:18.4
-10,-2,15:18.4
-7,-2,15:18.4
-6,-2,15:18.4
-1,-2,15:18.4
0,-2,15:18.4
2,-2,15:18.4
-13,-1,15:18.4
-12,-1,15:18.4
-11,-1,15:18.4
-10,-1,15:18.4
-7,-1,15:18.12
-6,-1,15:18.12
-5,-1,15:18.12
-4,-1,15:18.12
-2,-1,15:18.12
-1,-1,15:18.12
0,-1,15:18.4
1,-1,15:18.4
2,-1,15:18.4
-13,0,15:18.4
-12,0,15:18.4
-11,0,15:18.4
-8,0,15:18.12
-7,0,15:18.12
-6,0,15:18.12
-5,0,15:18.12
-4,0,15:18.12
-3,0,15:18.12
-2,0,15:18.12
0,0,15:18.12
1,0,15:18.12
2,0,15:18.12
3,0,15:18.12
5,0,15:18.12
-14,1,15:18.4
-13,1,15:18.4
-12,1,15:18.4
-11,1,15:18.4
-8,1,15:18.12
-7,1,15:18.12
-6,1,15:18.12
-5,1,15:18.12
-4,1,15:18.12
-3,1,15:18.12
-2,1,15:18.12
1,1,15:18.12
2,1,15:18.12
3,1,15:18.12
4,1,15:18.12
-15,2,15:18.4
-14,2,15:18.4
-13,2,15:18.4
-12,2,15:18.4
-8,2,15:18.12
-7,2,15:18.12
-6,2,15:18.12
-5,2,15:18.12
-4,2,15:18.12
-3,2,15:18.12
-2,2,15:18.12
1,2,15:18.12
2,2,15:18.12
3,2,15:18.12
4,2,15:18.12
-14,3,15:18.4
-13,3,15:18.4
-12,3,15:18.4
-11,3,15:18.4
-10,3,15:18.4
-9,3,15:18.12
-8,3,15:18.12
-7,3,15:18.12
-6,3,15:18.12
-5,3,15:18.12
-4,3,15:18.12
-3,3,15:18.12
-2,3,15:18.12
1,3,15:18.12
2,3,15:18.12
3,3,15:18.12
4,3,15:18.12
-13,4,15:18.4
-12,4,15:18.4
-11,4,15:18.4
-7,4,15:18.12
-6,4,15:18.12
-5,4,15:18.12
-4,4,15:18.12
-2,4,15:18.12
-1,4,15:18.12
0,4,15:18.12
1,4,15:18.12
2,4,15:18.12
3,4,15:18.12
4,4,15:18.12
-13,5,15:18.4
-12,5,15:18.4
-11,5,15:18.4
-10,5,15:18.4
-7,5,15:18.12
-6,5,15:18.12
-5,5,15:18.12
-4,5,15:18.12
1,5,15:18.12
2,5,15:18.12
3,5,15:18.12
4,5,15:18.12
5,5,15:18.12
6,5,15:18.4
7,5,15:18.4
8,5,15:18.4
-12,6,15:18.4
-11,6,15:18.4
-10,6,15:18.4
-3,6,15:18.12
0,6,15:18.12
1,6,15:18.12
2,6,15:18.12
3,6,15:18.12
8,6,15:18.4
9,6,15:18.4
-12,7,15:18.4
-11,7,15:18.4
-10,7,15:18.4
-9,7,15:18.12
-3,7,15:18.12
-1,7,15:18.12
0,7,15:18.12
1,7,15:18.12
2,7,15:18.12
-11,8,15:18.4
-10,8,15:18.4
-9,8,15:18.4
-2,8,15:18.12
-1,8,15:18.12
0,8,15:18.12
1,8,15:18.12
2,8,15:18.12
-10,9,15:18.4
-9,9,15:18.4
-8,9,15:18.4
-7,9,15:18.4
-6,9,15:18.4
-5,9,15:18.4
-4,9,15:18.4
-3,9,15:18.12
-2,9,15:18.12
-1,9,15:18.12
0,9,15:18.12
2,9,15:18.12
3,9,15:18.12
-10,10,15:18.4
-9,10,15:18.4
-8,10,15:18.4
-7,10,15:18.4
-6,10,15:18.4
-5,10,15:18.4
-4,10,15:18.4
-3,10,15:18.4
-2,10,15:18.4
-1,10,15:18.4
3,10,15:18.4
-1,11,15:18.4
-1,12,15:18.4
0,12,15:18.4
0,13,15:18.4
2,-5,16:18.4
-8,-4,16:18.4
-7,-4,16:18.4
-6,-4,16:18.4
-5,-4,16:18.4
1,-4,16:18.4
-9,-3,16:18.4
-8,-3,16:18.4
-7,-3,16:18.4
-6,-3,16:18.4
-5,-3,16:18.4
-4,-3,16:18.4
-3,-3,16:18.4
-2,-3,16:18.4
-1,-3,16:18.4
0,-3,16:18.4
1,-3,16:18.4
-9,-2,16:18.4
-8,-2,16:18.4
-7,-2,16:18.4
-6,-2,16:18.4
-5,-2,16:18.4
-4,-2,16:18.4
-3,-2,16:18.4
-2,-2,16:18.4
-1,-2,16:18.4
0,-2,16:18.4
2,-2,16:18.4
-10,-1,16:18.4
-9,-1,16:18.12
-8,-1,16:18.12
-7,-1,16:18.12
-5,-1,16:18.12
-4,-1,16:18.12
-3,-1,16:18.12
-2,-1,16:18.12
-1,-1,16:18.12
0,-1,16:18.4
1,-1,16:18.4
2,-1,16:18.4
3,-1,16:18.4
-10,0,16:18.4
-8,0,16:18.12
-2,0,16:18.12
-1,0,16:18.12
0,0,16:18.4
-11,1,16:18.4
-10,1,16:18.4
-9,1,16:18.12
-8,1,16:18.12
-3,1,16:18.12
-1,1,16:18.12
0,1,16:18.4
1,1,16:18.4
4,1,16:18.4
-15,2,16:18.4
-14,2,16:18.4
-13,2,16:18.4
-12,2,16:18.4
-11,2,16:18.4
-10,2,16:18.4
-9,2,16:18.12
-4,2,16:18.12
-3,2,16:18.12
-1,2,16:18.12
0,2,16:18.4
1,2,16:18.4
-11,3,16:18.4
-10,3,16:18.4
-9,3,16:18.12
-8,3,16:18.12
-7,3,16:18.12
-6,3,16:18.12
-5,3,16:18.12
-4,3,16:18.12
0,3,16:18.4
1,3,16:18.4
2,3,16:18.4
-11,4,16:18.4
-10,4,16:18.4
-9,4,16:18.12
-5,4,16:18.12
-4,4,16:18.12
0,4,16:18.4
1,4,16:18.4
2,4,16:18.4
3,4,16:18.4
4,4,16:18.4
-10,5,16:18.4
-9,5,16:18.12
-8,5,16:18.12
-4,5,16:18.12
-1,5,16:18.12
0,5,16:18.4
1,5,16:18.4
4,5,16:18.4
5,5,16:18.4
7,5,16:18.4
8,5,16:18.4
-10,6,16:18.4
-9,6,16:18.12
-8,6,16:18.12
-7,6,16:18.12
-3,6,16:18.12
-2,6,16:18.12
-1,6,16:18.12
0,6,16:18.4
7,6,16:18.4
8,6,16:18.4
9,6,16:18.4
-9,7,16:18.12
-8,7,16:18.12
-7,7,16:18.12
-6,7,16:18.12
-5,7,16:18.12
-4,7,16:18.12
-3,7,16:18.12
-2,7,16:18.12
-1,7,16:18.12
0,7,16:18.4
-9,8,16:18.4
-8,8,16:18.4
-7,8,16:18.4
-5,8,16:18.4
-4,8,16:18.4
-3,8,16:18.4
-2,8,16:18.4
-1,8,16:18.4
-10,9,16:18.4
-2,9,16:18.4
-3,10,16:18.4
-1,10,16:18.4
-1,11,16:18.4
0,12,16:18.4
2,-4,17:18.4
1,-3,17:18.4
-7,-2,17:18.4
0,-2,17:18.4
-7,-1,17:18.4
-6,-1,17:18.4
-5,-1,17:18.4
-4,-1,17:18.4
-1,-1,17:18.4
0,-1,17:18.4
1,-1,17:18.4
2,-1,17:18.4
3,-1,17:18.4
5,-1,17:18.4
-7,0,17:18.4
-6,0,17:18.4
-5,0,17:18.4
-4,0,17:18.4
-3,0,17:18.4
-2,0,17:18.4
-1,0,17:18.4
0,0,17:18.4
1,0,17:18.4
2,0,17:18.4
3,0,17:18.4
4,0,17:18.4
5,0,17:18.4
6,0,17:18.4
-8,1,17:18.4
-7,1,17:18.4
-6,1,17:18.4
-5,1,17:18.4
-4,1,17:18.4
-3,1,17:18.4
-2,1,17:18.4
-1,1,17:18.4
0,1,17:18.4
1,1,17:18.4
2,1,17:18.4
3,1,17:18.4
4,1,17:18.4
5,1,17:18.4
6,1,17:18.4
7,1,17:18.4
-13,2,17:18.4
-12,2,17:18.4
-8,2,17:18.4
-7,2,17:18.4
-6,2,17:18.4
-4,2,17:18.4
-3,2,17:18.4
-2,2,17:18.4
-1,2,17:18.4
0,2,17:18.4
1,2,17:18.4
2,2,17:18.4
3,2,17:18.4
4,2,17:18.4
5,2,17:18.4
6,2,17:18.4
7,2,17:18.4
8,2,17:18.4
-11,3,17:18.4
-10,3,17:18.4
-9,3,17:18.4
-8,3,17:18.4
-7,3,17:18.4
-6,3,17:18.4
-5,3,17:18.4
-4,3,17:18.4
-3,3,17:18.4
-2,3,17:18.4
-1,3,17:18.4
0,3,17:18.4
1,3,17:18.4
2,3,17:18.4
3,3,17:18.4
4,3,17:18.4
5,3,17:18.4
6,3,17:18.4
7,3,17:18.4
8,3,17:18.4
-8,4,17:18.4
-7,4,17:18.4
-6,4,17:18.4
-5,4,17:18.4
-4,4,17:18.4
-2,4,17:18.4
-1,4,17:18.4
0,4,17:18.4
1,4,17:18.4
2,4,17:18.4
3,4,17:18.4
4,4,17:18.4
5,4,17:18.4
6,4,17:18.4
7,4,17:18.4
8,4,17:18.4
-8,5,17:18.4
-7,5,17:18.4
-6,5,17:18.4
-5,5,17:18.4
-4,5,17:18.4
-3,5,17:18.4
-2,5,17:18.4
-1,5,17:18.4
0,5,17:18.4
1,5,17:18.4
3,5,17:18.4
4,5,17:18.4
5,5,17:18.4
6,5,17:18.4
7,5,17:18.4
8,5,17:18.4
-7,6,17:18.4
-6,6,17:18.4
-5,6,17:18.4
-4,6,17:18.4
-3,6,17:18.4
-2,6,17:18.4
-1,6,17:18.4
0,6,17:18.4
1,6,17:18.4
4,6,17:18.4
5,6,17:18.4
6,6,17:18.4
9,6,17:18.4
-8,7,17:18.4
-4,7,17:18.4
-3,7,17:18.4
-2,7,17:18.4
-1,7,17:18.4
0,7,17:18.4
1,7,17:18.4
2,7,17:18.4
4,7,17:18.4
5,7,17:18.4
6,7,17:18.4
7,7,17:18.4
8,7,17:18.4
-9,8,17:18.4
-4,8,17:18.4
-3,8,17:18.4
-2,8,17:18.4
-1,8,17:18.4
0,8,17:18.4
1,8,17:18.4
2,8,17:18.4
4,8,17:18.4
5,8,17:18.4
6,8,17:18.4
7,8,17:18.4
-10,9,17:18.4
-3,9,17:18.4
-2,9,17:18.4
-1,9,17:18.4
0,9,17:18.4
1,9,17:18.4
2,9,17:18.4
3,9,17:18.4
4,9,17:18.4
5,9,17:18.4
6,9,17:18.4
-11,10,17:18.4
-10,10,17:18.4
-3,10,17:18.4
-2,10,17:18.4
-1,10,17:18.4
0,10,17:18.4
1,10,17:18.4
2,10,17:18.4
3,10,17:18.4
4,10,17:18.4
5,10,17:18.4
-11,11,17:18.4
-1,11,17:18.4
1,11,17:18.4
2,11,17:18.4
3,11,17:18.4
4,11,17:18.4
0,12,17:18.4
-8,-6,18:18.4
-7,-4,18:18.4
-7,-3,18:18.4
-7,-2,18:18.4
0,-2,18:18.4
-6,-1,18:18.4
0,-1,18:18.4
-6,0,18:18.4
-1,0,18:18.4
0,0,18:18.4
1,0,18:18.4
-6,1,18:18.4
-5,1,18:18.4
-2,1,18:18.4
-1,1,18:18.4
0,1,18:18.4
1,1,18:18.4
2,1,18:18.4
3,1,18:18.4
4,1,18:18.4
5,1,18:18.4
-5,2,18:18.4
-4,2,18:18.4
-3,2,18:18.4
-2,2,18:18.4
-1,2,18:18.4
0,2,18:18.4
1,2,18:18.4
2,2,18:18.4
3,2,18:18.4
4,2,18:18.4
5,2,18:18.4
-11,3,18:18.4
-10,3,18:18.4
-9,3,18:18.4
-8,3,18:18.4
-7,3,18:18.4
-6,3,18:18.4
-5,3,18:18.4
-4,3,18:18.4
-3,3,18:18.4
-2,3,18:18.4
-1,3,18:18.4
0,3,18:18.4
1,3,18:18.4
2,3,18:18.4
3,3,18:18.4
4,3,18:18.4
5,3,18:18.4
6,3,18:18.4
-6,4,18:18.4
-5,4,18:18.4
-4,4,18:18.4
-2,4,18:18.4
-1,4,18:18.4
0,4,18:18.4
1,4,18:18.4
2,4,18:18.4
3,4,18:18.4
4,4,18:18.4
5,4,18:18.4
6,4,18:18.4
-6,5,18:18.4
-5,5,18:18.4
-4,5,18:18.4
-3,5,18:18.4
-2,5,18:18.4
-1,5,18:18.4
0,5,18:18.4
1,5,18:18.4
2,5,18:18.4
3,5,18:18.4
4,5,18:18.4
5,5,18:18.4
6,5,18:18.4
7,5,18:18.4
-7,6,18:18.4
-3,6,18:18.4
-2,6,18:18.4
-1,6,18:18.4
0,6,18:18.4
1,6,18:18.4
2,6,18:18.4
3,6,18:18.4
4,6,18:18.4
5,6,18:18.4
6,6,18:18.4
7,6,18:18.4
-8,7,18:18.4
-3,7,18:18.4
-2,7,18:18.4
-1,7,18:18.4
0,7,18:18.4
1,7,18:18.4
2,7,18:18.4
3,7,18:18.4
4,7,18:18.4
5,7,18:18.4
6,7,18:18.4
-9,8,18:18.4
-2,8,18:18.4
-1,8,18:18.4
0,8,18:18.4
1,8,18:18.4
2,8,18:18.4
4,8,18:18.4
5,8,18:18.4
-10,9,18:18.4
-2,9,18:18.4
0,9,18:18.4
1,9,18:18.4
2,9,18:18.4
3,9,18:18.4
4,9,18:18.4
-11,10,18:18.4
-1,10,18:18.4
3,10,18:18.4
4,10,18:18.4
-7,-5,19:18.4
-7,-4,19:18.4
-7,-3,19:18.4
-7,-2,19:18.4
-6,-1,19:18.4
0,-1,19:18.4
1,-1,19:18.4
-6,0,19:18.4
0,0,19:18.4
-6,1,19:18.4
1,1,19:18.4
-5,2,19:18.4
1,2,19:18.4
3,2,19:18.4
-11,3,19:18.4
-10,3,19:18.4
-9,3,19:18.4
-8,3,19:18.4
-7,3,19:18.4
-5,3,19:18.4
-4,3,19:18.4
0,3,19:18.4
1,3,19:18.4
2,3,19:18.4
3,3,19:18.4
-5,4,19:18.4
-4,4,19:18.4
-2,4,19:18.4
-1,4,19:18.4
0,4,19:18.4
1,4,19:18.4
2,4,19:18.4
3,4,19:18.4
4,4,19:18.4
-6,5,19:18.4
0,5,19:18.4
1,5,19:18.4
2,5,19:18.4
3,5,19:18.4
4,5,19:18.4
5,5,19:18.4
6,5,19:18.4
-7,6,19:18.4
-1,6,19:18.4
0,6,19:18.4
1,6,19:18.4
2,6,19:18.4
3,6,19:18.4
-8,7,19:18.4
-3,7,19:18.4
-2,7,19:18.4
-1,7,19:18.4
2,7,19:18.4
3,7,19:18.4
-9,8,19:18.4
-2,8,19:18.4
-10,9,19:18.4
-2,9,19:18.4
-11,10,19:18.4
-10,10,19:18.4
-2,10,19:18.4
-1,10,19:18.4
-7,-6,20:18.4
-7,-5,20:18.4
-7,-4,20:18.4
-7,-3,20:18.4
-7,-2,20:18.4
-6,-1,20:18.4
-6,0,20:18.4
-6,1,20:18.4
1,1,20:18.4
3,1,20:18.4
4,1,20:18.4
-5,2,20:18.4
1,2,20:18.4
3,2,20:18.4
-5,3,20:18.4
-4,3,20:18.4
2,3,20:18.4
-6,4,20:18.4
-5,4,20:18.4
-4,4,20:18.4
-2,4,20:18.4
-1,4,20:18.4
0,4,20:18.4
1,4,20:18.4
2,4,20:18.4
3,4,20:18.4
-12,5,20:18.4
-6,5,20:18.4
0,5,20:18.4
1,5,20:18.4
3,5,20:18.4
4,5,20:18.4
5,5,20:18.4
-12,6,20:18.4
-7,6,20:18.4
-1,6,20:18.4
2,6,20:18.4
-12,7,20:18.4
-11,7,20:18.4
-8,7,20:18.4
2,7,20:18.4
3,7,20:18.4
-11,8,20:18.4
-9,8,20:18.4
-11,9,20:18.4
-10,9,20:18.4
3,9,20:18.4
-11,10,20:18.4
-10,10,20:18.4
-9,10,20:18.4
-8,10,20:18.4
-8,11,20:18.4
-7,11,20:18.4
-7,-6,21:18.4
-6,-6,21:18.4
-5,-6,21:18.4
-8,-5,21:18.4
-7,-5,21:18.4
-6,-5,21:18.4
-5,-5,21:18.4
-4,-5,21:18.4
-3,-5,21:18.4
-2,-5,21:18.4
-1,-5,21:18.4
0,-5,21:18.4
-9,-4,21:18.4
-8,-4,21:18.4
-7,-4,21:18.4
-6,-4,21:18.4
-5,-4,21:18.4
-4,-4,21:18.4
-3,-4,21:18.4
-2,-4,21:18.4
-1,-4,21:18.4
0,-4,21:18.4
-10,-3,21:18.4
-9,-3,21:18.4
-8,-3,21:18.4
-7,-3,21:18.4
-6,-3,21:18.4
-5,-3,21:18.4
-4,-3,21:18.4
-3,-3,21:18.4
-11,-2,21:18.4
-10,-2,21:18.4
-9,-2,21:18.4
-8,-2,21:18.4
-7,-2,21:18.4
-6,-2,21:18.4
3,-2,21:18.4
-12,-1,21:18.4
-11,-1,21:18.4
-10,-1,21:18.4
-9,-1,21:18.4
-8,-1,21:18.4
-7,-1,21:18.4
-6,-1,21:18.4
2,-1,21:18.4
3,-1,21:18.4
-12,0,21:18.4
-11,0,21:18.4
-10,0,21:18.4
-8,0,21:18.4
-6,0,21:18.4
1,0,21:18.4
2,0,21:18.4
3,0,21:18.4
4,0,21:18.4
-13,1,21:18.4
-12,1,21:18.4
-11,1,21:18.4
-10,1,21:18.4
-9,1,21:18.4
-6,1,21:18.4
-1,1,21:18.4
0,1,21:18.4
1,1,21:18.4
2,1,21:18.4
3,1,21:18.4
4,1,21:18.4
-13,2,21:18.4
-12,2,21:18.4
-11,2,21:18.4
-10,2,21:18.4
-9,2,21:18.4
-5,2,21:18.4
-2,2,21:18.4
-1,2,21:18.4
0,2,21:18.4
1,2,21:18.4
2,2,21:18.4
3,2,21:18.4
4,2,21:18.4
5,2,21:18.4
-13,3,21:18.4
-12,3,21:18.4
-11,3,21:18.4
-10,3,21:18.4
-9,3,21:18.4
-5,3,21:18.4
-4,3,21:18.4
-3,3,21:18.4
-2,3,21:18.4
-1,3,21:18.4
0,3,21:18.4
1,3,21:18.4
2,3,21:18.4
3,3,21:18.4
4,3,21:18.4
5,3,21:18.4
-12,4,21:18.4
-11,4,21:18.4
-10,4,21:18.4
-9,4,21:18.4
-8,4,21:18.4
-5,4,21:18.4
-4,4,21:18.4
-2,4,21:18.4
-1,4,21:18.4
0,4,21:18.4
1,4,21:18.4
2,4,21:18.4
3,4,21:18.4
4,4,21:18.4
5,4,21:18.4
6,4,21:18.4
-12,5,21:18.4
-11,5,21:18.4
-10,5,21:18.4
-9,5,21:18.4
-8,5,21:18.4
-7,5,21:18.4
-6,5,21:18.4
-3,5,21:18.4
-2,5,21:18.4
-1,5,21:18.4
0,5,21:18.4
1,5,21:18.4
2,5,21:18.4
3,5,21:18.4
4,5,21:18.4
5,5,21:18.4
6,5,21:18.4
-12,6,21:18.4
-11,6,21:18.4
-10,6,21:18.4
-9,6,21:18.4
-8,6,21:18.4
-7,6,21:18.4
-6,6,21:18.4
-3,6,21:18.4
-2,6,21:18.4
-1,6,21:18.4
0,6,21:18.4
1,6,21:18.4
2,6,21:18.4
3,6,21:18.4
4,6,21:18.4
5,6,21:18.4
6,6,21:18.4
-11,7,21:18.4
-10,7,21:18.4
-9,7,21:18.4
-8,7,21:18.4
-7,7,21:18.4
-6,7,21:18.4
-5,7,21:18.4
-4,7,21:18.4
-2,7,21:18.4
-1,7,21:18.4
0,7,21:18.4
1,7,21:18.4
2,7,21:18.4
3,7,21:18.4
4,7,21:18.4
5,7,21:18.4
-11,8,21:18.4
-10,8,21:18.4
-9,8,21:18.4
-8,8,21:18.4
-7,8,21:18.4
-5,8,21:18.4
-4,8,21:18.4
-3,8,21:18.4
-2,8,21:18.4
-1,8,21:18.4
0,8,21:18.4
1,8,21:18.4
2,8,21:18.4
4,8,21:18.4
-10,9,21:18.4
-9,9,21:18.4
-8,9,21:18.4
-7,9,21:18.4
-6,9,21:18.4
-5,9,21:18.4
-4,9,21:18.4
-3,9,21:18.4
-2,9,21:18.4
-1,9,21:18.4
0,9,21:18.4
1,9,21:18.4
2,9,21:18.4
3,9,21:18.4
4,9,21:18.4
-9,10,21:18.4
-8,10,21:18.4
-7,10,21:18.4
-6,10,21:18.4
-5,10,21:18.4
-4,10,21:18.4
-3,10,21:18.4
-2,10,21:18.4
-1,10,21:18.4
0,10,21:18.4
-6,11,21:18.4
-5,11,21:18.4
-4,11,21:18.4
-3,11,21:18.4
-2,11,21:18.4
-1,11,21:18.4
-7,-4,22:18.4
-6,-4,22:18.4
-5,-4,22:18.4
-4,-4,22:18.4
-3,-4,22:18.4
-2,-4,22:18.4
-1,-4,22:18.4
0,-4,22:18.4
1,-4,22:18.4
-8,-3,22:18.4
-7,-3,22:18.4
-6,-3,22:18.4
-5,-3,22:18.4
-4,-3,22:18.4
-3,-3,22:18.4
-2,-3,22:18.4
-1,-3,22:18.4
0,-3,22:18.4
1,-3,22:18.4
2,-3,22:18.4
-9,-2,22:18.4
-8,-2,22:18.4
-7,-2,22:18.4
-6,-2,22:18.4
-5,-2,22:18.4
-4,-2,22:18.4
-3,-2,22:18.4
-2,-2,22:18.4
-1,-2,22:18.4
0,-2,22:18.4
2,-2,22:18.4
-10,-1,22:18.4
-9,-1,22:18.4
-8,-1,22:18.4
-7,-1,22:18.4
-6,-1,22:18.4
-5,-1,22:18.4
-4,-1,22:18.4
-3,-1,22:18.4
-2,-1,22:18.4
-1,-1,22:18.4
0,-1,22:18.4
1,-1,22:18.4
2,-1,22:18.4
-11,0,22:18.4
-10,0,22:18.4
-8,0,22:18.4
-7,0,22:18.4
-6,0,22:18.4
-5,0,22:18.4
-4,0,22:18.4
-3,0,22:18.4
-2,0,22:18.4
-1,0,22:18.4
0,0,22:18.4
1,0,22:18.4
2,0,22:18.4
-11,1,22:18.4
-10,1,22:18.4
-9,1,22:18.4
-8,1,22:18.4
-7,1,22:18.4
-6,1,22:18.4
-5,1,22:18.4
-4,1,22:18.4
-3,1,22:18.4
-2,1,22:18.4
-1,1,22:18.4
0,1,22:18.4
1,1,22:18.4
2,1,22:18.4
3,1,22:18.4
-11,2,22:18.4
-10,2,22:18.4
-9,2,22:18.4
-8,2,22:18.4
-7,2,22:18.4
-6,2,22:18.4
-5,2,22:18.4
-4,2,22:18.4
-3,2,22:18.4
-2,2,22:18.4
-1,2,22:18.4
0,2,22:18.4
1,2,22:18.4
2,2,22:18.4
3,2,22:18.4
4,2,22:18.4
-11,3,22:18.4
-10,3,22:18.4
-9,3,22:18.4
-8,3,22:18.4
-7,3,22:18.4
-6,3,22:18.4
-5,3,22:18.4
-4,3,22:18.4
-3,3,22:18.4
-2,3,22:18.4
-1,3,22:18.4
0,3,22:18.4
1,3,22:18.4
2,3,22:18.4
3,3,22:18.4
4,3,22:18.4
5,3,22:18.4
-10,4,22:18.4
-9,4,22:18.4
-8,4,22:18.4
-7,4,22:18.4
-6,4,22:18.4
-5,4,22:18.4
-4,4,22:18.4
-2,4,22:18.4
-1,4,22:18.4
0,4,22:18.4
1,4,22:18.4
2,4,22:18.4
3,4,22:18.4
4,4,22:18.4
5,4,22:18.4
-10,5,22:18.4
-9,5,22:18.4
-8,5,22:18.4
-7,5,22:18.4
-6,5,22:18.4
-5,5,22:18.4
-4,5,22:18.4
-3,5,22:18.4
-2,5,22:18.4
-1,5,22:18.4
0,5,22:18.4
1,5,22:18.4
2,5,22:18.4
3,5,22:18.4
4,5,22:18.4
5,5,22:18.4
6,5,22:18.4
-10,6,22:18.4
-9,6,22:18.4
-8,6,22:18.4
-7,6,22:18.4
-6,6,22:18.4
-5,6,22:18.4
-4,6,22:18.4
-3,6,22:18.4
-2,6,22:18.4
-1,6,22:18.4
0,6,22:18.4
1,6,22:18.4
2,6,22:18.4
3,6,22:18.4
4,6,22:18.4
5,6,22:18.4
-9,7,22:18.4
-8,7,22:18.4
-7,7,22:18.4
-6,7,22:18.4
-5,7,22:18.4
-4,7,22:18.4
-3,7,22:18.4
-2,7,22:18.4
-1,7,22:18.4
0,7,22:18.4
1,7,22:18.4
2,7,22:18.4
3,7,22:18.4
4,7,22:18.4
-9,8,22:18.4
-8,8,22:18.4
-7,8,22:18.4
-5,8,22:18.4
-4,8,22:18.4
-3,8,22:18.4
-2,8,22:18.4
-1,8,22:18.4
0,8,22:18.4
1,8,22:18.4
2,8,22:18.4
-10,9,22:18.4
-6,9,22:18.4
-5,9,22:18.4
-4,9,22:18.4
-3,9,22:18.4
-2,9,22:18.4
-1,9,22:18.4
-3,10,22:18.4
-2,10,22:18.4
-7,-4,23:18.4
-7,-3,23:18.4
-6,-3,23:18.4
-6,-2,23:18.4
-5,-2,23:18.4
-4,-2,23:18.4
-3,-2,23:18.4
-2,-2,23:18.4
-7,-1,23:18.4
-6,-1,23:18.4
-5,-1,23:18.4
-4,-1,23:18.4
-3,-1,23:18.4
-2,-1,23:18.4
-1,-1,23:18.4
0,-1,23:18.4
-8,0,23:18.4
-7,0,23:18.4
-6,0,23:18.4
-5,0,23:18.4
-4,0,23:18.4
-3,0,23:18.4
-2,0,23:18.4
-1,0,23:18.4
0,0,23:18.4
-8,1,23:18.4
-7,1,23:18.4
-6,1,23:18.4
-5,1,23:18.4
-4,1,23:18.4
-3,1,23:18.4
-2,1,23:18.4
-1,1,23:18.4
0,1,23:18.4
-9,2,23:18.4
-8,2,23:18.4
-7,2,23:18.4
-5,2,23:18.4
-2,2,23:18.4
-1,2,23:18.4
0,2,23:18.4
3,2,23:18.4
-9,3,23:18.4
-8,3,23:18.4
-7,3,23:18.4
-5,3,23:18.4
-2,3,23:18.4
-1,3,23:18.4
0,3,23:18.4
2,3,23:18.4
3,3,23:18.4
-8,4,23:18.4
-7,4,23:18.4
-6,4,23:18.4
-5,4,23:18.4
-4,4,23:18.4
-2,4,23:18.4
-1,4,23:18.4
0,4,23:18.4
1,4,23:18.4
2,4,23:18.4
-8,5,23:18.4
-7,5,23:18.4
-6,5,23:18.4
-3,5,23:18.4
-2,5,23:18.4
-1,5,23:18.4
0,5,23:18.4
1,5,23:18.4
2,5,23:18.4
3,5,23:18.4
-8,6,23:18.4
-7,6,23:18.4
-6,6,23:18.4
-5,6,23:18.4
-4,6,23:18.4
-3,6,23:18.4
-2,6,23:18.4
-1,6,23:18.4
1,6,23:18.4
2,6,23:18.4
-8,7,23:18.4
-6,7,23:18.4
-5,7,23:18.4
-4,7,23:18.4
-3,7,23:18.4
-2,7,23:18.4
2,7,23:18.4
-9,8,23:18.4
-3,8,23:18.4
-6,-2,24:18.4
-6,-1,24:18.4
-1,-1,24:18.4
-6,0,24:18.4
-2,0,24:18.4
-1,0,24:18.4
-6,1,24:18.4
-5,1,24:18.4
-4,1,24:18.4
-3,1,24:18.4
-2,1,24:18.4
-6,2,24:18.4
-5,2,24:18.4
-4,2,24:18.4
-3,2,24:18.4
-2,2,24:18.4
-7,3,24:18.4
-6,3,24:18.4
-5,3,24:18.4
-4,3,24:18.4
-3,3,24:18.4
-2,3,24:18.4
-7,4,24:18.4
-6,4,24:18.4
-5,4,24:18.4
-4,4,24:18.4
-2,4,24:18.4
-1,4,24:18.4
-6,5,24:18.4
-5,5,24:18.4
-4,5,24:18.4
-3,5,24:18.4
-1,5,24:18.4
0,5,24:18.4
1,5,24:18.4
-7,6,24:18.4
-3,6,24:18.4
-8,7,24:18.4
-2,7,24:18.4
-9,8,24:18.4
-2,8,24:18.4
-1,9,24:18.4
-1,10,24:18.4
0,-2,25:18.4
-6,-1,25:18.4
-1,-1,25:18.4
-6,0,25:18.4
-2,0,25:18.4
-1,0,25:18.4
-5,1,25:18.4
-2,1,25:18.4
-5,2,25:18.4
-3,2,25:18.4
-11,3,25:18.4
-10,3,25:18.4
-9,3,25:18.4
-8,3,25:18.4
-3,3,25:18.4
-7,4,25:18.4
-6,4,25:18.4
-5,4,25:18.4
-4,4,25:18.4
-6,5,25:18.4
-3,5,25:18.4
-2,5,25:18.4
-1,5,25:18.4
0,5,25:18.4
-7,6,25:18.4
-3,6,25:18.4
-8,7,25:18.4
-2,7,25:18.4
-2,8,25:18.4
-1,9,25:18.4
-1,-1,26:18.4
-2,0,26:18.4
-1,0,26:18.4
-2,1,26:18.4
-3,2,26:18.4
-10,3,26:18.4
-9,3,26:18.4
-8,3,26:18.4
-3,3,26:18.4
-7,4,26:18.4
-6,4,26:18.4
-5,4,26:18.4
-4,4,26:18.4
-3,5,26:18.4
-3,6,26:18.4
1,6,26:18.4
-2,7,26:18.4
0,7,26:18.4
-2,8,26:18.4
-1,8,26:18.4
0,8,26:18.4
-5,9,26:18.4
-4,9,26:18.4
-3,9,26:18.4
-2,9,26:18.4
-1,9,26:18.4
-7,-2,27:18.4
-6,-2,27:18.4
-5,-2,27:18.4
-4,-2,27:18.4
-3,-2,27:18.4
-2,-2,27:18.4
-1,-2,27:18.4
0,-2,27:18.4
-8,-1,27:18.4
-7,-1,27:18.4
-6,-1,27:18.4
-5,-1,27:18.4
-4,-1,27:18.4
-3,-1,27:18.4
-2,-1,27:18.4
-1,-1,27:18.4
0,-1,27:18.4
-8,0,27:18.4
-7,0,27:18.4
-6,0,27:18.4
-5,0,27:18.4
-4,0,27:18.4
-3,0,27:18.4
-2,0,27:18.4
-1,0,27:18.4
0,0,27:18.4
1,0,27:18.4
-9,1,27:18.4
-8,1,27:18.4
-7,1,27:18.4
-6,1,27:18.4
-5,1,27:18.4
-4,1,27:18.4
-3,1,27:18.4
-2,1,27:18.4
-1,1,27:18.4
0,1,27:18.4
1,1,27:18.4
-10,2,27:18.4
-9,2,27:18.4
-8,2,27:18.4
-7,2,27:18.4
-6,2,27:18.4
-3,2,27:18.4
-2,2,27:18.4
-1,2,27:18.4
0,2,27:18.4
1,2,27:18.4
2,2,27:18.4
-11,3,27:18.4
-10,3,27:18.4
-9,3,27:18.4
-8,3,27:18.4
-7,3,27:18.4
-6,3,27:18.4
-4,3,27:18.4
-3,3,27:18.4
-2,3,27:18.4
-1,3,27:18.4
0,3,27:18.4
1,3,27:18.4
2,3,27:18.4
-10,4,27:18.4
-9,4,27:18.4
-8,4,27:18.4
-7,4,27:18.4
-6,4,27:18.4
-5,4,27:18.4
-4,4,27:18.4
-2,4,27:18.4
-1,4,27:18.4
0,4,27:18.4
1,4,27:18.4
2,4,27:18.4
-10,5,27:18.4
-9,5,27:18.4
-8,5,27:18.4
-7,5,27:18.4
-6,5,27:18.4
-5,5,27:18.4
-4,5,27:18.4
-3,5,27:18.4
-2,5,27:18.4
-1,5,27:18.4
0,5,27:18.4
1,5,27:18.4
2,5,27:18.4
-9,6,27:18.4
-8,6,27:18.4
-7,6,27:18.4
-6,6,27:18.4
-5,6,27:18.4
-4,6,27:18.4
-3,6,27:18.4
-2,6,27:18.4
-1,6,27:18.4
0,6,27:18.4
1,6,27:18.4
-9,7,27:18.4
-8,7,27:18.4
-7,7,27:18.4
-6,7,27:18.4
-5,7,27:18.4
-4,7,27:18.4
-3,7,27:18.4
-2,7,27:18.4
-1,7,27:18.4
0,7,27:18.4
-8,8,27:18.4
-7,8,27:18.4
-5,8,27:18.4
-4,8,27:18.4
-3,8,27:18.4
-2,8,27:18.4
-1,8,27:18.4
-7,9,27:18.4
-6,9,27:18.4
-5,9,27:18.4
-4,9,27:18.4
-3,9,27:18.4
-2,9,27:18.4
-7,-1,28:18.4
-6,-1,28:18.4
-5,-1,28:18.4
-4,-1,28:18.4
-3,-1,28:18.4
-1,-1,28:18.4
-7,0,28:18.4
-6,0,28:18.4
-5,0,28:18.4
-4,0,28:18.4
-3,0,28:18.4
-2,0,28:18.4
-1,0,28:18.4
-8,1,28:18.4
-7,1,28:18.4
-6,1,28:18.4
-5,1,28:18.4
-4,1,28:18.4
-3,1,28:18.4
-2,1,28:18.4
-1,1,28:18.4
-8,2,28:18.4
-7,2,28:18.4
-6,2,28:18.4
-5,2,28:18.4
-4,2,28:18.4
-3,2,28:18.4
-2,2,28:18.4
-1,2,28:18.4
-9,3,28:18.4
-8,3,28:18.4
-7,3,28:18.4
-6,3,28:18.4
-5,3,28:18.4
-4,3,28:18.4
-3,3,28:18.4
-2,3,28:18.4
-1,3,28:18.4
0,3,28:18.4
-8,4,28:18.4
-7,4,28:18.4
-6,4,28:18.4
-5,4,28:18.4
-4,4,28:18.4
-2,4,28:18.4
-1,4,28:18.4
0,4,28:18.4
-8,5,28:18.4
-7,5,28:18.4
-6,5,28:18.4
-5,5,28:18.4
-4,5,28:18.4
-3,5,28:18.4
-2,5,28:18.4
-1,5,28:18.4
-7,6,28:18.4
-6,6,28:18.4
-5,6,28:18.4
-4,6,28:18.4
-3,6,28:18.4
-2,6,28:18.4
-6,7,28:18.4
-5,7,28:18.4
-4,7,28:18.4
-3,7,28:18.4
-2,7,28:18.4
-2,8,28:18.4
-1,0,29:18.4
-2,1,29:18.4
-1,1,29:18.4
-5,2,29:18.4
-4,2,29:18.4
-3,2,29:18.4
-2,2,29:18.4
-8,3,29:18.4
-7,3,29:18.4
-6,3,29:18.4
-5,3,29:18.4
-4,3,29:18.4
-3,3,29:18.4
-2,3,29:18.4
-6,4,29:18.4
-5,4,29:18.4
-4,4,29:18.4
-2,4,29:18.4
-5,5,29:18.4
-4,5,29:18.4
-3,5,29:18.4
-3,6,29:18.4
-2,7,29:18.4
-2,8,29:18.4
-2,2,30:18.4
-7,3,30:18.4
-6,4,30:18.4
