[META]
version=2.0
spawnOnBlockType=2
spawnSunlight=True
spawnDarkness=True
spawnWater=False
spawnLava=False
underFill=False
randomRotation=True
dig=True
tree=False
branch=False
needsFoundation=True
rarity=100
collisionPercentage=20
spawnElevationMin=0
spawnElevationMax=200
spawnInBiome=Custom
[DATA]
30,-25,-8:17.12
24,-24,-8:17.12
29,-24,-8:17.12
26,-23,-8:17.12
30,-23,-8:17.12
22,-22,-8:17.12
25,-22,-8:17.12
22,-21,-8:17.12
23,-21,-8:17.12
24,-21,-8:17.12
23,-20,-8:17.12
29,-17,-8:17.12
28,-16,-8:17.12
32,-13,-8:17.12
32,-12,-8:17.12
25,-25,-7:17.12
28,-25,-7:17.12
29,-25,-7:17.12
30,-25,-7:17.12
24,-24,-7:17.12
27,-24,-7:17.12
28,-24,-7:17.12
29,-24,-7:17.12
30,-24,-7:17.12
32,-24,-7:17.12
23,-23,-7:17.12
25,-23,-7:17.12
26,-23,-7:17.12
27,-23,-7:17.12
29,-23,-7:17.12
30,-23,-7:17.12
31,-23,-7:17.12
24,-22,-7:17.12
25,-22,-7:17.12
26,-22,-7:17.12
27,-22,-7:17.12
21,-21,-7:17.12
23,-21,-7:17.12
25,-21,-7:17.12
23,-20,-7:17.12
23,-19,-7:17.12
24,-19,-7:17.12
27,-19,-7:17.12
28,-19,-7:17.12
29,-19,-7:17.12
22,-17,-7:17.12
26,-17,-7:17.12
27,-17,-7:17.12
28,-17,-7:17.12
30,-17,-7:17.12
22,-16,-7:17.12
24,-16,-7:17.12
26,-16,-7:17.12
30,-16,-7:17.12
21,-15,-7:17.12
23,-15,-7:17.12
33,-15,-7:17.12
24,-14,-7:17.12
31,-14,-7:17.12
23,-13,-7:17.12
25,-13,-7:17.12
28,-13,-7:17.12
30,-13,-7:17.12
31,-13,-7:17.12
32,-13,-7:17.12
34,-13,-7:17.12
24,-12,-7:17.12
28,-12,-7:17.12
30,-12,-7:17.12
27,-11,-7:17.12
26,-10,-7:17.12
27,-10,-7:17.12
30,-26,-6:17.12
31,-26,-6:17.12
24,-25,-6:17.12
25,-25,-6:17.12
24,-24,-6:17.12
25,-24,-6:17.12
28,-24,-6:17.12
29,-24,-6:17.12
30,-24,-6:17.12
31,-24,-6:17.12
32,-24,-6:17.12
22,-23,-6:17.12
23,-23,-6:17.12
24,-23,-6:17.12
25,-23,-6:17.12
26,-23,-6:17.12
27,-23,-6:17.12
28,-23,-6:17.12
29,-23,-6:17.12
31,-23,-6:17.12
22,-22,-6:17.12
23,-22,-6:17.12
24,-22,-6:17.12
25,-22,-6:17.12
29,-22,-6:17.12
30,-22,-6:17.12
31,-22,-6:17.12
32,-22,-6:17.12
22,-21,-6:17.12
23,-21,-6:17.12
24,-21,-6:17.12
25,-21,-6:17.12
26,-21,-6:17.12
27,-21,-6:17.12
28,-21,-6:17.12
29,-21,-6:17.12
31,-21,-6:17.12
32,-21,-6:17.12
21,-20,-6:17.12
23,-20,-6:17.12
24,-20,-6:17.12
25,-20,-6:17.12
29,-20,-6:17.12
30,-20,-6:17.12
31,-20,-6:17.12
33,-20,-6:17.12
22,-19,-6:17.12
24,-19,-6:17.12
28,-19,-6:17.12
29,-19,-6:17.12
31,-19,-6:17.12
21,-18,-6:17.12
22,-18,-6:17.12
23,-18,-6:17.12
26,-18,-6:17.12
29,-18,-6:17.12
31,-18,-6:17.12
32,-18,-6:17.12
33,-18,-6:17.12
21,-17,-6:17.12
22,-17,-6:17.12
23,-17,-6:17.12
28,-17,-6:17.12
20,-16,-6:17.12
22,-16,-6:17.12
24,-16,-6:17.12
28,-16,-6:17.12
29,-16,-6:17.12
32,-16,-6:17.12
21,-15,-6:17.12
23,-15,-6:17.12
24,-15,-6:17.12
25,-15,-6:17.12
28,-15,-6:17.12
32,-15,-6:17.12
22,-14,-6:17.12
25,-14,-6:17.12
26,-14,-6:17.12
30,-14,-6:17.12
31,-14,-6:17.12
32,-14,-6:17.12
33,-14,-6:17.12
34,-14,-6:17.12
22,-13,-6:17.12
24,-13,-6:17.12
25,-13,-6:17.12
26,-13,-6:17.12
27,-13,-6:17.12
28,-13,-6:17.12
29,-13,-6:17.12
30,-13,-6:17.12
32,-13,-6:17.12
33,-13,-6:17.12
34,-13,-6:17.12
24,-12,-6:17.12
26,-12,-6:17.12
27,-12,-6:17.12
28,-12,-6:17.12
29,-12,-6:17.12
30,-12,-6:17.12
31,-12,-6:17.12
34,-12,-6:17.12
25,-11,-6:17.12
27,-11,-6:17.12
28,-11,-6:17.12
29,-11,-6:17.12
31,-11,-6:17.12
32,-11,-6:17.12
33,-11,-6:17.12
26,-10,-6:17.12
27,-10,-6:17.12
29,-10,-6:17.12
25,-9,-6:17.12
27,-9,-6:17.12
28,-9,-6:17.12
29,-26,-5:17.12
30,-26,-5:17.12
27,-25,-5:17.12
28,-25,-5:17.12
29,-25,-5:17.12
31,-25,-5:17.12
25,-24,-5:17.12
26,-24,-5:17.12
27,-24,-5:17.12
28,-24,-5:17.12
29,-24,-5:17.12
30,-24,-5:17.12
31,-24,-5:17.12
32,-24,-5:17.12
25,-23,-5:17.12
26,-23,-5:17.12
27,-23,-5:17.12
28,-23,-5:17.12
29,-23,-5:17.12
30,-23,-5:17.12
32,-23,-5:17.12
34,-23,-5:17.12
22,-22,-5:17.12
23,-22,-5:17.12
25,-22,-5:17.12
26,-22,-5:17.12
27,-22,-5:17.12
28,-22,-5:17.12
29,-22,-5:17.12
30,-22,-5:17.12
31,-22,-5:17.12
32,-22,-5:17.12
33,-22,-5:17.12
21,-21,-5:17.12
22,-21,-5:17.12
23,-21,-5:17.12
24,-21,-5:17.12
25,-21,-5:17.12
26,-21,-5:17.12
27,-21,-5:17.12
28,-21,-5:17.12
30,-21,-5:17.12
31,-21,-5:17.12
32,-21,-5:17.12
33,-21,-5:17.12
20,-20,-5:17.12
22,-20,-5:17.12
23,-20,-5:17.12
24,-20,-5:17.12
25,-20,-5:17.12
28,-20,-5:17.12
30,-20,-5:17.12
31,-20,-5:17.12
32,-20,-5:17.12
33,-20,-5:17.12
34,-20,-5:17.12
19,-19,-5:17.12
21,-19,-5:17.12
22,-19,-5:17.12
23,-19,-5:17.12
24,-19,-5:17.12
29,-19,-5:17.12
30,-19,-5:17.12
31,-19,-5:17.12
32,-19,-5:17.12
19,-18,-5:17.12
20,-18,-5:17.12
21,-18,-5:17.12
24,-18,-5:17.12
25,-18,-5:17.12
27,-18,-5:17.12
28,-18,-5:17.12
29,-18,-5:17.12
30,-18,-5:17.12
32,-18,-5:17.12
34,-18,-5:17.12
21,-17,-5:17.12
22,-17,-5:17.12
23,-17,-5:17.12
24,-17,-5:17.12
25,-17,-5:17.12
27,-17,-5:17.12
28,-17,-5:17.12
30,-17,-5:17.12
31,-17,-5:17.12
32,-17,-5:17.12
33,-17,-5:17.12
34,-17,-5:17.12
21,-16,-5:17.12
22,-16,-5:17.12
23,-16,-5:17.12
24,-16,-5:17.12
26,-16,-5:17.12
28,-16,-5:17.12
33,-16,-5:17.12
34,-16,-5:17.12
35,-16,-5:17.12
20,-15,-5:17.12
21,-15,-5:17.12
22,-15,-5:17.12
23,-15,-5:17.12
24,-15,-5:17.12
25,-15,-5:17.12
28,-15,-5:17.12
31,-15,-5:17.12
33,-15,-5:17.12
34,-15,-5:17.12
22,-14,-5:17.12
23,-14,-5:17.12
24,-14,-5:17.12
26,-14,-5:17.12
27,-14,-5:17.12
28,-14,-5:17.12
29,-14,-5:17.12
30,-14,-5:17.12
31,-14,-5:17.12
33,-14,-5:17.12
34,-14,-5:17.12
35,-14,-5:17.12
36,-14,-5:17.12
22,-13,-5:17.12
23,-13,-5:17.12
24,-13,-5:17.12
25,-13,-5:17.12
26,-13,-5:17.12
27,-13,-5:17.12
28,-13,-5:17.12
29,-13,-5:17.12
30,-13,-5:17.12
32,-13,-5:17.12
34,-13,-5:17.12
23,-12,-5:17.12
24,-12,-5:17.12
25,-12,-5:17.12
26,-12,-5:17.12
27,-12,-5:17.12
28,-12,-5:17.12
29,-12,-5:17.12
30,-12,-5:17.12
31,-12,-5:17.12
32,-12,-5:17.12
33,-12,-5:17.12
24,-11,-5:17.12
26,-11,-5:17.12
27,-11,-5:17.12
28,-11,-5:17.12
29,-11,-5:17.12
30,-11,-5:17.12
31,-11,-5:17.12
32,-11,-5:17.12
33,-11,-5:17.12
25,-10,-5:17.12
26,-10,-5:17.12
27,-10,-5:17.12
28,-10,-5:17.12
29,-10,-5:17.12
25,-9,-5:17.12
26,-9,-5:17.12
27,-9,-5:17.12
27,-8,-5:17.12
26,-25,-4:17.12
27,-25,-4:17.12
28,-25,-4:17.12
29,-25,-4:17.12
25,-24,-4:17.12
26,-24,-4:17.12
27,-24,-4:17.12
29,-24,-4:17.12
30,-24,-4:17.12
31,-24,-4:17.12
32,-24,-4:17.12
23,-23,-4:17.12
25,-23,-4:17.12
26,-23,-4:17.12
27,-23,-4:17.12
28,-23,-4:17.12
29,-23,-4:17.12
30,-23,-4:17.12
31,-23,-4:17.12
33,-23,-4:17.12
34,-23,-4:17.12
23,-22,-4:17.12
24,-22,-4:17.12
25,-22,-4:17.12
26,-22,-4:17.12
27,-22,-4:17.12
28,-22,-4:17.12
30,-22,-4:17.12
31,-22,-4:17.12
32,-22,-4:17.12
33,-22,-4:17.12
34,-22,-4:17.12
22,-21,-4:17.12
23,-21,-4:17.12
24,-21,-4:17.12
25,-21,-4:17.12
26,-21,-4:17.12
28,-21,-4:17.12
29,-21,-4:17.12
30,-21,-4:17.12
31,-21,-4:17.12
32,-21,-4:17.12
21,-20,-4:17.12
22,-20,-4:17.12
23,-20,-4:17.12
24,-20,-4:17.12
25,-20,-4:17.12
26,-20,-4:17.12
27,-20,-4:17.12
28,-20,-4:17.12
29,-20,-4:17.12
30,-20,-4:17.12
31,-20,-4:17.12
32,-20,-4:17.12
33,-20,-4:17.12
19,-19,-4:17.12
20,-19,-4:17.12
22,-19,-4:17.12
23,-19,-4:17.12
24,-19,-4:17.12
27,-19,-4:17.12
28,-19,-4:17.12
29,-19,-4:17.12
30,-19,-4:17.12
31,-19,-4:17.12
32,-19,-4:17.12
33,-19,-4:17.12
34,-19,-4:17.12
19,-18,-4:17.12
21,-18,-4:17.12
22,-18,-4:17.12
23,-18,-4:17.12
24,-18,-4:17.12
28,-18,-4:17.12
29,-18,-4:17.12
30,-18,-4:17.12
31,-18,-4:17.12
32,-18,-4:17.12
33,-18,-4:17.12
34,-18,-4:17.12
19,-17,-4:17.12
20,-17,-4:17.12
21,-17,-4:17.12
22,-17,-4:17.12
23,-17,-4:17.12
24,-17,-4:17.12
28,-17,-4:17.12
29,-17,-4:17.12
30,-17,-4:17.12
31,-17,-4:17.12
33,-17,-4:17.12
34,-17,-4:17.12
35,-17,-4:17.12
20,-16,-4:17.12
22,-16,-4:17.12
23,-16,-4:17.12
24,-16,-4:17.12
28,-16,-4:17.12
31,-16,-4:17.12
32,-16,-4:17.12
33,-16,-4:17.12
34,-16,-4:17.12
35,-16,-4:17.12
20,-15,-4:17.12
21,-15,-4:17.12
23,-15,-4:17.12
25,-15,-4:17.12
29,-15,-4:17.12
32,-15,-4:17.12
33,-15,-4:17.12
35,-15,-4:17.12
22,-14,-4:17.12
23,-14,-4:17.12
24,-14,-4:17.12
25,-14,-4:17.12
26,-14,-4:17.12
27,-14,-4:17.12
28,-14,-4:17.12
29,-14,-4:17.12
31,-14,-4:17.12
32,-14,-4:17.12
33,-14,-4:17.12
34,-14,-4:17.12
35,-14,-4:17.12
36,-14,-4:17.12
22,-13,-4:17.12
24,-13,-4:17.12
26,-13,-4:17.12
27,-13,-4:17.12
28,-13,-4:17.12
29,-13,-4:17.12
30,-13,-4:17.12
31,-13,-4:17.12
32,-13,-4:17.12
33,-13,-4:17.12
34,-13,-4:17.12
35,-13,-4:17.12
36,-13,-4:17.12
21,-12,-4:17.12
22,-12,-4:17.12
23,-12,-4:17.12
24,-12,-4:17.12
25,-12,-4:17.12
26,-12,-4:17.12
27,-12,-4:17.12
28,-12,-4:17.12
29,-12,-4:17.12
30,-12,-4:17.12
31,-12,-4:17.12
32,-12,-4:17.12
33,-12,-4:17.12
34,-12,-4:17.12
35,-12,-4:17.12
22,-11,-4:17.12
23,-11,-4:17.12
24,-11,-4:17.12
25,-11,-4:17.12
26,-11,-4:17.12
28,-11,-4:17.12
29,-11,-4:17.12
30,-11,-4:17.12
32,-11,-4:17.12
28,-10,-4:17.12
29,-10,-4:17.12
27,-9,-4:17.12
28,-8,-4:17.12
28,-24,-3:17.12
29,-24,-3:17.12
31,-24,-3:17.12
32,-24,-3:17.12
25,-23,-3:17.12
26,-23,-3:17.12
27,-23,-3:17.12
28,-23,-3:17.12
30,-23,-3:17.12
25,-22,-3:17.12
26,-22,-3:17.12
27,-22,-3:17.12
28,-22,-3:17.12
29,-22,-3:17.12
30,-22,-3:17.12
31,-22,-3:17.12
32,-22,-3:17.12
33,-22,-3:17.12
22,-21,-3:17.12
23,-21,-3:17.12
25,-21,-3:17.12
28,-21,-3:17.12
29,-21,-3:17.12
30,-21,-3:17.12
31,-21,-3:17.12
32,-21,-3:17.12
21,-20,-3:17.12
22,-20,-3:17.12
23,-20,-3:17.12
25,-20,-3:17.12
30,-20,-3:17.12
31,-20,-3:17.12
32,-20,-3:17.12
19,-19,-3:17.12
23,-19,-3:17.12
25,-19,-3:17.12
27,-19,-3:17.12
28,-19,-3:17.12
29,-19,-3:17.12
30,-19,-3:17.12
23,-18,-3:17.12
24,-18,-3:17.12
25,-18,-3:17.12
27,-18,-3:17.12
28,-18,-3:17.12
30,-18,-3:17.12
32,-18,-3:17.12
34,-18,-3:17.12
20,-17,-3:17.12
24,-17,-3:17.12
28,-17,-3:17.12
29,-17,-3:17.12
30,-17,-3:17.12
32,-17,-3:17.12
20,-16,-3:17.12
21,-16,-3:17.12
23,-16,-3:17.12
24,-16,-3:17.12
28,-16,-3:17.12
29,-16,-3:17.12
30,-16,-3:17.12
31,-16,-3:17.12
33,-16,-3:17.12
35,-16,-3:17.12
25,-15,-3:17.12
28,-15,-3:17.12
32,-15,-3:17.12
33,-15,-3:17.12
34,-15,-3:17.12
20,-14,-3:17.12
21,-14,-3:17.12
22,-14,-3:17.12
23,-14,-3:17.12
24,-14,-3:17.12
25,-14,-3:17.12
30,-14,-3:17.12
31,-14,-3:17.12
32,-14,-3:17.12
33,-14,-3:17.12
36,-14,-3:17.12
22,-13,-3:17.12
23,-13,-3:17.12
24,-13,-3:17.12
26,-13,-3:17.12
27,-13,-3:17.12
28,-13,-3:17.12
29,-13,-3:17.12
30,-13,-3:17.12
31,-13,-3:17.12
32,-13,-3:17.12
33,-13,-3:17.12
22,-12,-3:17.12
23,-12,-3:17.12
24,-12,-3:17.12
25,-12,-3:17.12
26,-12,-3:17.12
28,-12,-3:17.12
29,-12,-3:17.12
32,-12,-3:17.12
34,-12,-3:17.12
22,-11,-3:17.12
23,-11,-3:17.12
25,-11,-3:17.12
26,-11,-3:17.12
27,-11,-3:17.12
28,-11,-3:17.12
29,-11,-3:17.12
27,-10,-3:17.12
28,-10,-3:17.12
29,-10,-3:17.12
26,-9,-3:17.12
27,-9,-3:17.12
28,-9,-3:17.12
23,-25,-2:17.12
30,-25,-2:17.12
31,-25,-2:17.12
22,-24,-2:17.12
23,-24,-2:17.12
24,-24,-2:17.12
25,-24,-2:17.12
26,-24,-2:17.12
27,-24,-2:17.12
28,-24,-2:17.12
29,-24,-2:17.12
30,-24,-2:17.12
31,-24,-2:17.12
32,-24,-2:17.12
33,-24,-2:17.12
22,-23,-2:17.12
33,-23,-2:17.12
34,-23,-2:17.12
35,-23,-2:17.12
22,-22,-2:17.12
32,-22,-2:17.12
34,-22,-2:17.12
35,-22,-2:17.12
22,-21,-2:17.12
25,-21,-2:17.12
29,-21,-2:17.12
30,-21,-2:17.12
31,-21,-2:17.12
32,-21,-2:17.12
34,-21,-2:17.12
21,-20,-2:17.12
23,-20,-2:17.12
24,-20,-2:17.12
25,-20,-2:17.12
28,-20,-2:17.12
30,-20,-2:17.12
31,-20,-2:17.12
32,-20,-2:17.12
33,-20,-2:17.12
34,-20,-2:17.12
20,-19,-2:17.12
21,-19,-2:17.12
22,-19,-2:17.12
23,-19,-2:17.12
27,-19,-2:17.12
28,-19,-2:17.12
29,-19,-2:17.12
31,-19,-2:17.12
32,-19,-2:17.12
34,-19,-2:17.12
19,-18,-2:17.12
20,-18,-2:17.12
21,-18,-2:17.12
22,-18,-2:17.12
27,-18,-2:17.12
28,-18,-2:17.12
29,-18,-2:17.12
31,-18,-2:17.12
32,-18,-2:17.12
34,-18,-2:17.12
18,-17,-2:17.12
19,-17,-2:17.12
20,-17,-2:17.12
21,-17,-2:17.12
22,-17,-2:17.12
23,-17,-2:17.12
24,-17,-2:17.12
25,-17,-2:17.12
26,-17,-2:17.12
27,-17,-2:17.12
28,-17,-2:17.12
29,-17,-2:17.12
30,-17,-2:17.12
31,-17,-2:17.12
32,-17,-2:17.12
33,-17,-2:17.12
34,-17,-2:17.12
19,-16,-2:17.12
20,-16,-2:17.12
30,-16,-2:17.12
33,-16,-2:17.12
34,-16,-2:17.12
35,-16,-2:17.12
20,-15,-2:17.12
21,-15,-2:17.12
27,-15,-2:17.12
28,-15,-2:17.12
29,-15,-2:17.12
35,-15,-2:17.12
21,-14,-2:17.12
22,-14,-2:17.12
28,-14,-2:17.12
32,-14,-2:17.12
34,-14,-2:17.12
35,-14,-2:17.12
21,-13,-2:17.12
22,-13,-2:17.12
23,-13,-2:17.12
28,-13,-2:17.12
29,-13,-2:17.12
31,-13,-2:17.12
34,-13,-2:17.12
35,-13,-2:17.12
36,-13,-2:17.12
21,-12,-2:17.12
22,-12,-2:17.12
23,-12,-2:17.12
27,-12,-2:17.12
28,-12,-2:17.12
29,-12,-2:17.12
30,-12,-2:17.12
31,-12,-2:17.12
32,-12,-2:17.12
33,-12,-2:17.12
34,-12,-2:17.12
35,-12,-2:17.12
36,-12,-2:17.12
21,-11,-2:17.12
22,-11,-2:17.12
23,-11,-2:17.12
28,-11,-2:17.12
29,-11,-2:17.12
30,-11,-2:17.12
22,-10,-2:17.12
23,-10,-2:17.12
24,-10,-2:17.12
25,-10,-2:17.12
26,-10,-2:17.12
27,-10,-2:17.12
28,-10,-2:17.12
26,-9,-2:17.12
28,-26,-1:18.12
29,-26,-1:18.12
30,-26,-1:18.12
31,-26,-1:18.12
32,-26,-1:18.12
33,-26,-1:18.12
27,-25,-1:18.12
28,-25,-1:18.12
29,-25,-1:18.12
30,-25,-1:18.12
31,-25,-1:18.12
32,-25,-1:18.12
33,-25,-1:18.12
22,-24,-1:17.12
23,-24,-1:17.12
24,-24,-1:17.12
25,-24,-1:17.12
26,-24,-1:17.12
27,-24,-1:17.12
28,-24,-1:17.12
29,-24,-1:17.12
30,-24,-1:17.12
31,-24,-1:18.12
32,-24,-1:17.12
22,-23,-1:17.12
33,-23,-1:17.12
34,-23,-1:17.12
22,-22,-1:17.12
34,-22,-1:17.12
22,-21,-1:17.12
34,-21,-1:17.12
21,-20,-1:17.12
34,-20,-1:17.12
20,-19,-1:17.12
21,-19,-1:17.12
28,-19,-1:17.12
29,-19,-1:17.12
30,-19,-1:17.12
34,-19,-1:17.12
19,-18,-1:17.12
20,-18,-1:17.12
29,-18,-1:17.12
30,-18,-1:17.12
34,-18,-1:17.12
19,-17,-1:17.12
26,-17,-1:17.12
27,-17,-1:17.12
28,-17,-1:17.12
29,-17,-1:17.12
30,-17,-1:17.12
34,-17,-1:17.12
20,-16,-1:17.12
29,-16,-1:17.12
20,-15,-1:17.12
29,-15,-1:17.12
34,-15,-1:17.12
21,-14,-1:17.12
22,-14,-1:17.12
35,-14,-1:18.12
21,-13,-1:17.12
22,-13,-1:17.12
23,-13,-1:17.12
35,-13,-1:17.12
23,-12,-1:17.12
24,-12,-1:17.12
29,-12,-1:17.12
30,-12,-1:17.12
31,-12,-1:17.12
32,-12,-1:17.12
33,-12,-1:17.12
34,-12,-1:17.12
35,-12,-1:17.12
23,-11,-1:17.12
24,-11,-1:17.12
25,-11,-1:17.12
26,-11,-1:17.12
27,-11,-1:17.12
28,-11,-1:17.12
29,-11,-1:18.12
30,-11,-1:18.12
31,-11,-1:17.12
32,-11,-1:18.12
33,-11,-1:18.12
25,-10,-1:17.12
26,-10,-1:17.12
27,-10,-1:17.12
28,-10,-1:18.12
29,-10,-1:18.12
30,-10,-1:18.12
31,-10,-1:18.12
32,-10,-1:18.12
29,-9,-1:18.12
30,-9,-1:18.12
31,-9,-1:18.12
29,-8,-1:18.12
30,-8,-1:18.12
31,-8,-1:18.12
29,-26,0:18.12
30,-26,0:18.12
31,-26,0:18.12
27,-25,0:18.12
28,-25,0:18.12
29,-25,0:18.12
30,-25,0:18.12
31,-25,0:18.12
32,-25,0:18.12
33,-25,0:18.12
22,-24,0:17.12
23,-24,0:17.12
24,-24,0:17.12
25,-24,0:17.12
26,-24,0:17.12
27,-24,0:17.12
28,-24,0:17.12
29,-24,0:17.12
30,-24,0:17.12
31,-24,0:17.12
32,-24,0:17.12
22,-23,0:17.12
27,-23,0:17.12
32,-23,0:17.12
33,-23,0:17.12
34,-23,0:17.12
22,-22,0:17.12
34,-22,0:17.12
22,-21,0:17.12
34,-21,0:17.12
36,-21,0:18.12
21,-20,0:17.12
22,-20,0:17.12
34,-20,0:17.12
36,-20,0:18.12
21,-19,0:17.12
33,-19,0:17.12
34,-19,0:17.12
35,-19,0:18.12
36,-19,0:18.12
20,-18,0:17.12
33,-18,0:17.12
34,-18,0:17.12
35,-18,0:18.12
36,-18,0:18.12
18,-17,0:18.12
19,-17,0:17.12
20,-17,0:17.12
28,-17,0:17.12
34,-17,0:17.12
35,-17,0:18.12
36,-17,0:18.12
37,-17,0:18.12
18,-16,0:18.12
19,-16,0:18.12
20,-16,0:17.12
29,-16,0:17.12
34,-16,0:18.12
35,-16,0:18.12
36,-16,0:18.12
18,-15,0:18.12
19,-15,0:18.12
20,-15,0:18.12
21,-15,0:17.12
34,-15,0:17.12
35,-15,0:18.12
36,-15,0:18.12
21,-14,0:18.12
22,-14,0:17.12
34,-14,0:17.12
35,-14,0:18.12
36,-14,0:18.12
37,-14,0:18.12
18,-13,0:18.12
20,-13,0:18.12
21,-13,0:18.12
22,-13,0:18.12
23,-13,0:17.12
24,-13,0:17.12
32,-13,0:17.12
33,-13,0:17.12
34,-13,0:17.12
35,-13,0:18.12
36,-13,0:18.12
37,-13,0:18.12
18,-12,0:18.12
19,-12,0:18.12
20,-12,0:18.12
21,-12,0:18.12
23,-12,0:18.12
24,-12,0:17.12
25,-12,0:17.12
26,-12,0:17.12
28,-12,0:17.12
29,-12,0:17.12
30,-12,0:17.12
31,-12,0:17.12
32,-12,0:17.12
37,-12,0:18.12
21,-11,0:18.12
22,-11,0:18.12
23,-11,0:18.12
24,-11,0:18.12
25,-11,0:17.12
26,-11,0:17.12
27,-11,0:17.12
28,-11,0:17.12
29,-11,0:18.12
30,-11,0:17.12
31,-11,0:17.12
32,-11,0:18.12
21,-10,0:18.12
22,-10,0:18.12
23,-10,0:18.12
24,-10,0:18.12
25,-10,0:18.12
28,-10,0:18.12
29,-10,0:18.12
30,-10,0:18.12
31,-10,0:18.12
28,-9,0:18.12
29,-9,0:18.12
30,-9,0:18.12
30,-8,0:18.12
31,-8,0:18.12
30,-26,1:18.12
29,-25,1:18.12
30,-25,1:18.12
31,-25,1:18.12
23,-24,1:17.12
24,-24,1:17.12
27,-24,1:17.12
28,-24,1:17.12
29,-24,1:17.12
30,-24,1:17.12
31,-24,1:18.12
22,-23,1:17.12
23,-23,1:17.12
24,-23,1:17.12
25,-23,1:17.12
26,-23,1:17.12
31,-23,1:17.12
32,-23,1:17.12
33,-23,1:17.12
22,-22,1:17.12
23,-22,1:17.12
33,-22,1:17.12
34,-22,1:17.12
22,-21,1:17.12
33,-21,1:17.12
34,-21,1:17.12
22,-20,1:17.12
33,-20,1:17.12
21,-19,1:17.12
22,-19,1:17.12
33,-19,1:17.12
35,-19,1:18.12
36,-19,1:18.12
20,-18,1:17.12
21,-18,1:17.12
33,-18,1:17.12
34,-18,1:17.12
35,-18,1:18.12
36,-18,1:18.12
20,-17,1:17.12
21,-17,1:17.12
34,-17,1:17.12
35,-17,1:18.12
36,-17,1:18.12
37,-17,1:18.12
17,-16,1:18.12
20,-16,1:17.12
21,-16,1:17.12
34,-16,1:17.12
35,-16,1:18.12
36,-16,1:18.12
18,-15,1:18.12
19,-15,1:18.12
20,-15,1:18.12
21,-15,1:17.12
34,-15,1:17.12
35,-15,1:18.12
18,-14,1:18.12
20,-14,1:18.12
21,-14,1:17.12
22,-14,1:17.12
23,-14,1:17.12
34,-14,1:17.12
35,-14,1:18.12
36,-14,1:18.12
18,-13,1:18.12
19,-13,1:18.12
20,-13,1:18.12
21,-13,1:18.12
23,-13,1:17.12
24,-13,1:17.12
31,-13,1:17.12
32,-13,1:17.12
33,-13,1:17.12
34,-13,1:17.12
36,-13,1:18.12
18,-12,1:18.12
19,-12,1:18.12
20,-12,1:18.12
21,-12,1:18.12
25,-12,1:17.12
26,-12,1:17.12
27,-12,1:17.12
28,-12,1:17.12
29,-12,1:17.12
30,-12,1:17.12
21,-11,1:18.12
22,-11,1:18.12
23,-11,1:18.12
24,-11,1:18.12
27,-11,1:17.12
29,-11,1:17.12
30,-11,1:17.12
24,-10,1:18.12
25,-10,1:18.12
29,-10,1:18.12
30,-10,1:18.12
28,-9,1:18.12
29,-9,1:18.12
26,-24,2:17.12
27,-24,2:17.12
28,-24,2:17.12
29,-24,2:17.12
24,-23,2:17.12
25,-23,2:17.12
26,-23,2:17.12
29,-23,2:17.12
30,-23,2:17.12
31,-23,2:17.12
23,-22,2:17.12
24,-22,2:17.12
31,-22,2:17.12
32,-22,2:17.12
33,-22,2:17.12
22,-21,2:17.12
23,-21,2:17.12
33,-21,2:17.12
22,-20,2:17.12
33,-20,2:17.12
22,-19,2:17.12
33,-19,2:17.12
21,-18,2:17.12
22,-18,2:17.12
33,-18,2:17.12
34,-18,2:17.12
21,-17,2:17.12
22,-17,2:17.12
33,-17,2:17.12
34,-17,2:17.12
17,-16,2:18.12
18,-16,2:18.12
21,-16,2:17.12
22,-16,2:17.12
33,-16,2:17.12
34,-16,2:17.12
18,-15,2:18.12
19,-15,2:18.12
20,-15,2:18.12
21,-15,2:18.12
22,-15,2:17.12
33,-15,2:17.12
19,-14,2:18.12
20,-14,2:18.12
22,-14,2:17.12
23,-14,2:17.12
32,-14,2:17.12
33,-14,2:17.12
18,-13,2:18.12
19,-13,2:18.12
20,-13,2:18.12
21,-13,2:18.12
23,-13,2:17.12
24,-13,2:17.12
25,-13,2:17.12
30,-13,2:17.12
31,-13,2:17.12
32,-13,2:17.12
18,-12,2:18.12
21,-12,2:18.12
25,-12,2:17.12
26,-12,2:17.12
27,-12,2:17.12
28,-12,2:17.12
29,-12,2:17.12
30,-12,2:17.12
22,-11,2:18.12
24,-11,2:18.12
28,-11,2:17.12
29,-11,2:17.12
27,-10,2:17.12
28,-10,2:17.12
27,-9,2:17.12
27,-8,2:17.12
27,-7,2:17.12
28,-6,2:17.12
28,-5,2:17.12
26,-24,3:17.12
27,-24,3:17.12
28,-24,3:17.12
29,-24,3:17.12
24,-23,3:17.12
25,-23,3:17.12
26,-23,3:17.12
29,-23,3:17.12
30,-23,3:17.12
31,-23,3:17.12
23,-22,3:17.12
24,-22,3:17.12
31,-22,3:17.12
32,-22,3:17.12
22,-21,3:17.12
33,-21,3:17.12
22,-20,3:17.12
33,-20,3:17.12
22,-19,3:17.12
33,-19,3:17.12
22,-18,3:17.12
33,-18,3:17.12
22,-17,3:17.12
33,-17,3:17.12
18,-16,3:18.12
22,-16,3:17.12
33,-16,3:17.12
22,-15,3:17.12
32,-15,3:17.12
33,-15,3:17.12
19,-14,3:18.12
22,-14,3:17.12
31,-14,3:17.12
32,-14,3:17.12
18,-13,3:18.12
23,-13,3:17.12
29,-13,3:17.12
30,-13,3:17.12
31,-13,3:17.12
24,-12,3:17.12
25,-12,3:17.12
26,-12,3:17.12
27,-12,3:17.12
28,-12,3:17.12
29,-12,3:17.12
26,-11,3:18.12
27,-11,3:18.12
28,-11,3:18.12
24,-10,3:18.12
25,-10,3:18.12
26,-10,3:18.12
27,-10,3:18.12
28,-10,3:18.12
29,-10,3:18.12
23,-9,3:18.12
24,-9,3:18.12
25,-9,3:18.12
27,-9,3:18.12
28,-9,3:18.12
29,-9,3:18.12
30,-9,3:18.12
23,-8,3:18.12
24,-8,3:18.12
25,-8,3:18.12
26,-8,3:18.12
27,-8,3:18.12
28,-8,3:18.12
29,-8,3:18.12
30,-8,3:18.12
23,-7,3:18.12
24,-7,3:18.12
25,-7,3:18.12
26,-7,3:18.12
27,-7,3:17.12
29,-7,3:18.12
30,-7,3:18.12
23,-6,3:18.12
24,-6,3:18.12
25,-6,3:17.12
26,-6,3:18.12
27,-6,3:18.12
28,-6,3:18.12
29,-6,3:18.12
30,-6,3:18.12
22,-5,3:18.12
23,-5,3:18.12
24,-5,3:18.12
26,-5,3:18.12
28,-5,3:17.12
29,-5,3:18.12
23,-4,3:18.12
24,-4,3:18.12
25,-4,3:18.12
26,-4,3:18.12
27,-4,3:18.12
28,-4,3:18.12
29,-4,3:18.12
24,-3,3:18.12
25,-3,3:18.12
26,-3,3:18.12
27,-3,3:18.12
26,-24,4:17.12
27,-24,4:17.12
28,-24,4:17.12
24,-23,4:17.12
25,-23,4:17.12
26,-23,4:17.12
29,-23,4:17.12
30,-23,4:17.12
31,-23,4:17.12
23,-22,4:17.12
24,-22,4:17.12
31,-22,4:17.12
32,-22,4:17.12
22,-21,4:17.12
32,-21,4:17.12
33,-21,4:17.12
22,-20,4:17.12
33,-20,4:17.12
22,-19,4:17.12
33,-19,4:17.12
22,-18,4:17.12
33,-18,4:17.12
21,-17,4:17.12
22,-17,4:17.12
33,-17,4:17.12
21,-16,4:17.12
22,-16,4:17.12
32,-16,4:17.12
33,-16,4:17.12
21,-15,4:17.12
32,-15,4:17.12
21,-14,4:17.12
22,-14,4:17.12
30,-14,4:17.12
31,-14,4:17.12
23,-13,4:17.12
24,-13,4:17.12
28,-13,4:17.12
29,-13,4:17.12
30,-13,4:17.12
24,-12,4:17.12
25,-12,4:17.12
26,-12,4:17.12
27,-12,4:17.12
27,-11,4:18.12
25,-10,4:18.12
26,-10,4:18.12
27,-10,4:18.12
28,-10,4:18.12
24,-9,4:18.12
25,-9,4:18.12
26,-9,4:18.12
27,-9,4:18.12
28,-9,4:18.12
29,-9,4:18.12
30,-9,4:18.12
24,-8,4:18.12
25,-8,4:18.12
26,-8,4:18.12
27,-8,4:18.12
28,-8,4:18.12
29,-8,4:18.12
23,-7,4:18.12
24,-7,4:18.12
25,-7,4:18.12
26,-7,4:18.12
27,-7,4:18.12
28,-7,4:18.12
29,-7,4:18.12
23,-6,4:18.12
24,-6,4:18.12
25,-6,4:18.12
26,-6,4:18.12
27,-6,4:18.12
28,-6,4:18.12
29,-6,4:18.12
23,-5,4:18.12
24,-5,4:18.12
25,-5,4:18.12
26,-5,4:18.12
27,-5,4:18.12
28,-5,4:18.12
29,-5,4:18.12
24,-4,4:18.12
25,-4,4:18.12
26,-4,4:18.12
27,-4,4:18.12
25,-3,4:18.12
27,-24,5:17.12
28,-24,5:17.12
25,-23,5:17.12
26,-23,5:17.12
29,-23,5:17.12
30,-23,5:17.12
23,-22,5:17.12
24,-22,5:17.12
25,-22,5:17.12
31,-22,5:17.12
32,-22,5:17.12
22,-21,5:17.12
23,-21,5:17.12
32,-21,5:17.12
22,-20,5:17.12
32,-20,5:17.12
33,-20,5:17.12
22,-19,5:17.12
33,-19,5:17.12
21,-18,5:17.12
33,-18,5:17.12
21,-17,5:17.12
22,-17,5:17.12
33,-17,5:17.12
20,-16,5:17.12
21,-16,5:17.12
22,-16,5:17.12
32,-16,5:17.12
33,-16,5:17.12
19,-15,5:17.12
20,-15,5:17.12
30,-15,5:17.12
31,-15,5:17.12
32,-15,5:17.12
19,-14,5:17.12
20,-14,5:17.12
21,-14,5:17.12
28,-14,5:17.12
29,-14,5:17.12
30,-14,5:17.12
31,-14,5:17.12
19,-13,5:17.12
20,-13,5:17.12
21,-13,5:17.12
22,-13,5:17.12
23,-13,5:17.12
24,-13,5:17.12
27,-13,5:17.12
28,-13,5:17.12
29,-13,5:17.12
24,-12,5:17.12
25,-12,5:17.12
26,-12,5:17.12
27,-12,5:17.12
25,-8,5:18.12
26,-8,5:18.12
27,-8,5:18.12
28,-8,5:18.12
25,-7,5:18.12
26,-7,5:18.12
27,-7,5:18.12
25,-6,5:18.12
26,-6,5:18.12
27,-6,5:18.12
24,-5,5:18.12
26,-5,5:17.12
22,-4,5:18.12
24,-4,5:18.12
25,-4,5:18.12
26,-4,5:17.12
27,-4,5:17.12
28,-4,5:18.12
24,-3,5:17.12
25,-3,5:17.12
26,-3,5:18.12
23,-2,5:17.12
23,-1,5:18.12
27,-24,6:17.12
28,-24,6:17.12
26,-23,6:17.12
28,-23,6:17.12
29,-23,6:17.12
30,-23,6:17.12
24,-22,6:17.12
25,-22,6:17.12
30,-22,6:17.12
31,-22,6:17.12
22,-21,6:17.12
23,-21,6:17.12
24,-21,6:17.12
25,-21,6:17.12
31,-21,6:17.12
21,-20,6:17.12
22,-20,6:17.12
30,-20,6:17.12
31,-20,6:17.12
32,-20,6:17.12
21,-19,6:17.12
31,-19,6:17.12
32,-19,6:17.12
33,-19,6:17.12
21,-18,6:17.12
22,-18,6:17.12
23,-18,6:17.12
33,-18,6:17.12
22,-17,6:17.12
23,-17,6:17.12
24,-17,6:17.12
25,-17,6:17.12
32,-17,6:17.12
33,-17,6:17.12
22,-16,6:17.12
23,-16,6:17.12
24,-16,6:17.12
25,-16,6:17.12
27,-16,6:17.12
28,-16,6:17.12
29,-16,6:17.12
30,-16,6:17.12
31,-16,6:17.12
32,-16,6:17.12
19,-15,6:17.12
20,-15,6:17.12
21,-15,6:17.12
22,-15,6:17.12
23,-15,6:17.12
24,-15,6:17.12
25,-15,6:17.12
27,-15,6:17.12
28,-15,6:17.12
29,-15,6:17.12
30,-15,6:17.12
31,-15,6:17.12
18,-14,6:17.12
19,-14,6:17.12
20,-14,6:17.12
21,-14,6:17.12
22,-14,6:17.12
23,-14,6:17.12
24,-14,6:17.12
25,-14,6:17.12
27,-14,6:17.12
28,-14,6:17.12
18,-13,6:17.12
19,-13,6:17.12
20,-13,6:17.12
21,-13,6:17.12
22,-13,6:17.12
25,-13,6:17.12
27,-13,6:17.12
25,-12,6:17.12
26,-12,6:17.12
27,-12,6:17.12
23,-6,6:18.12
24,-6,6:18.12
25,-6,6:18.12
26,-6,6:18.12
27,-6,6:18.12
22,-5,6:18.12
23,-5,6:18.12
24,-5,6:18.12
25,-5,6:18.12
26,-5,6:18.12
27,-5,6:18.12
22,-4,6:18.12
23,-4,6:18.12
24,-4,6:18.12
25,-4,6:18.12
26,-4,6:18.12
27,-4,6:18.12
22,-3,6:18.12
23,-3,6:18.12
24,-3,6:18.12
25,-3,6:18.12
26,-3,6:18.12
27,-3,6:18.12
28,-3,6:18.12
23,-2,6:18.12
24,-2,6:18.12
25,-2,6:18.12
26,-2,6:18.12
27,-2,6:18.12
28,-2,6:18.12
24,-1,6:18.12
25,-1,6:18.12
26,-1,6:18.12
27,-1,6:18.12
25,0,6:18.12
31,-26,7:18.12
22,-25,7:17.12
23,-25,7:17.12
23,-24,7:17.12
27,-24,7:17.12
28,-24,7:17.12
26,-23,7:17.12
27,-23,7:17.12
28,-23,7:17.12
29,-23,7:17.12
30,-23,7:17.12
25,-22,7:17.12
26,-22,7:17.12
30,-22,7:17.12
24,-21,7:17.12
25,-21,7:17.12
26,-21,7:17.12
30,-21,7:17.12
20,-20,7:17.12
21,-20,7:17.12
22,-20,7:17.12
23,-20,7:17.12
24,-20,7:17.12
25,-20,7:17.12
26,-20,7:17.12
27,-20,7:17.12
29,-20,7:17.12
30,-20,7:17.12
20,-19,7:17.12
21,-19,7:17.12
23,-19,7:17.12
24,-19,7:17.12
25,-19,7:17.12
26,-19,7:17.12
27,-19,7:17.12
28,-19,7:17.12
29,-19,7:17.12
30,-19,7:17.12
31,-19,7:17.12
32,-19,7:17.12
33,-19,7:17.12
15,-18,7:18.12
16,-18,7:18.12
17,-18,7:18.12
21,-18,7:17.12
22,-18,7:17.12
23,-18,7:17.12
24,-18,7:17.12
25,-18,7:17.12
26,-18,7:17.12
27,-18,7:17.12
28,-18,7:17.12
29,-18,7:17.12
30,-18,7:17.12
31,-18,7:17.12
33,-18,7:17.12
14,-17,7:18.12
15,-17,7:18.12
16,-17,7:18.12
17,-17,7:18.12
18,-17,7:18.12
19,-17,7:18.12
20,-17,7:18.12
23,-17,7:17.12
24,-17,7:17.12
25,-17,7:17.12
26,-17,7:17.12
27,-17,7:17.12
28,-17,7:17.12
29,-17,7:17.12
30,-17,7:17.12
31,-17,7:17.12
32,-17,7:17.12
33,-17,7:17.12
13,-16,7:18.12
14,-16,7:18.12
15,-16,7:18.12
18,-16,7:18.12
19,-16,7:18.12
20,-16,7:18.12
21,-16,7:18.12
22,-16,7:17.12
23,-16,7:17.12
24,-16,7:17.12
26,-16,7:17.12
27,-16,7:17.12
28,-16,7:17.12
29,-16,7:17.12
30,-16,7:17.12
12,-15,7:18.12
13,-15,7:18.12
14,-15,7:18.12
15,-15,7:18.12
16,-15,7:18.12
20,-15,7:18.12
21,-15,7:18.12
25,-15,7:17.12
26,-15,7:17.12
27,-15,7:17.12
28,-15,7:17.12
12,-14,7:18.4
13,-14,7:18.12
15,-14,7:18.12
16,-14,7:18.12
17,-14,7:18.12
18,-14,7:17.12
19,-14,7:17.12
20,-14,7:18.12
21,-14,7:18.12
22,-14,7:18.12
25,-14,7:17.12
26,-14,7:17.12
27,-14,7:17.12
12,-13,7:18.4
13,-13,7:18.12
17,-13,7:17.12
18,-13,7:17.12
19,-13,7:17.12
20,-13,7:18.12
21,-13,7:18.12
22,-13,7:18.12
23,-13,7:18.12
25,-13,7:17.12
26,-13,7:17.12
27,-13,7:17.12
12,-12,7:18.4
13,-12,7:18.12
18,-12,7:18.12
20,-12,7:18.12
21,-12,7:18.12
23,-12,7:18.12
25,-12,7:17.12
26,-12,7:17.12
27,-12,7:17.12
12,-11,7:18.4
13,-11,7:18.12
14,-11,7:18.12
18,-11,7:18.12
20,-11,7:18.12
21,-11,7:18.12
22,-11,7:18.12
13,-10,7:18.12
14,-10,7:18.12
15,-10,7:18.12
16,-10,7:18.12
18,-10,7:18.12
19,-10,7:18.12
20,-10,7:18.12
21,-10,7:18.12
13,-9,7:18.12
14,-9,7:18.12
15,-9,7:18.12
16,-9,7:18.12
17,-9,7:18.12
18,-9,7:18.12
19,-9,7:18.12
20,-9,7:18.12
17,-8,7:18.12
18,-8,7:18.12
19,-8,7:18.12
24,-5,7:18.12
25,-5,7:18.12
26,-5,7:18.12
24,-4,7:18.12
25,-4,7:18.12
26,-4,7:18.12
24,-3,7:18.12
25,-3,7:18.12
26,-3,7:18.12
25,-2,7:18.12
16,-29,8:18.12
30,-27,8:18.12
31,-26,8:18.12
18,-25,8:18.12
19,-25,8:18.12
21,-25,8:17.12
22,-25,8:17.12
23,-25,8:17.12
28,-25,8:17.12
29,-25,8:17.12
30,-25,8:17.12
22,-24,8:17.12
23,-24,8:17.12
24,-24,8:17.12
27,-24,8:17.12
28,-24,8:17.12
29,-24,8:17.12
30,-24,8:17.12
23,-23,8:17.12
24,-23,8:17.12
25,-23,8:18.12
27,-23,8:17.12
29,-23,8:17.12
24,-22,8:17.12
25,-22,8:17.12
26,-22,8:17.12
27,-22,8:17.12
29,-22,8:17.12
19,-21,8:17.12
20,-21,8:17.12
24,-21,8:17.12
25,-21,8:17.12
26,-21,8:17.12
27,-21,8:17.12
28,-21,8:17.12
29,-21,8:17.12
18,-20,8:17.12
19,-20,8:17.12
20,-20,8:17.12
21,-20,8:17.12
22,-20,8:17.12
25,-20,8:17.12
26,-20,8:17.12
27,-20,8:17.12
28,-20,8:17.12
29,-20,8:17.12
30,-20,8:17.12
32,-20,8:17.12
33,-20,8:17.12
34,-20,8:17.12
20,-19,8:17.12
21,-19,8:17.12
22,-19,8:17.12
23,-19,8:17.12
26,-19,8:17.12
27,-19,8:17.12
28,-19,8:17.12
29,-19,8:17.12
30,-19,8:17.12
31,-19,8:17.12
32,-19,8:17.12
34,-19,8:17.12
21,-18,8:17.12
22,-18,8:17.12
23,-18,8:17.12
30,-18,8:17.12
31,-18,8:17.12
32,-18,8:17.12
33,-18,8:17.12
15,-17,8:18.12
16,-17,8:18.12
17,-17,8:18.12
18,-17,8:18.12
22,-17,8:17.12
23,-17,8:17.12
31,-17,8:17.12
32,-17,8:17.12
14,-16,8:18.12
15,-16,8:18.12
16,-16,8:18.12
17,-16,8:18.12
18,-16,8:18.12
19,-16,8:18.12
20,-16,8:18.12
21,-16,8:18.12
22,-16,8:17.12
23,-16,8:17.12
13,-15,8:18.12
14,-15,8:18.12
15,-15,8:18.12
16,-15,8:18.12
17,-15,8:18.12
18,-15,8:18.12
19,-15,8:18.12
20,-15,8:18.12
21,-15,8:18.12
28,-15,8:17.12
29,-15,8:17.12
12,-14,8:18.4
13,-14,8:18.12
14,-14,8:18.12
15,-14,8:18.12
16,-14,8:18.12
17,-14,8:18.12
18,-14,8:18.12
19,-14,8:18.12
20,-14,8:18.12
21,-14,8:18.12
28,-14,8:17.12
29,-14,8:17.12
13,-13,8:18.12
14,-13,8:18.12
15,-13,8:18.12
16,-13,8:18.12
17,-13,8:17.12
18,-13,8:17.12
19,-13,8:18.12
20,-13,8:18.12
21,-13,8:18.12
26,-13,8:17.12
27,-13,8:17.12
13,-12,8:18.12
14,-12,8:18.12
15,-12,8:18.12
16,-12,8:18.12
17,-12,8:18.12
18,-12,8:18.12
19,-12,8:18.12
20,-12,8:18.12
21,-12,8:18.12
25,-12,8:17.12
26,-12,8:17.12
27,-12,8:17.12
13,-11,8:18.12
14,-11,8:18.12
15,-11,8:18.12
17,-11,8:18.12
18,-11,8:18.12
19,-11,8:18.12
20,-11,8:18.12
21,-11,8:18.12
26,-11,8:17.12
27,-11,8:17.12
14,-10,8:18.12
15,-10,8:18.12
16,-10,8:18.12
17,-10,8:18.12
18,-10,8:18.12
19,-10,8:18.12
20,-10,8:18.12
16,-9,8:18.12
17,-9,8:18.12
18,-9,8:18.12
19,-9,8:18.12
19,-8,8:18.12
18,-30,9:18.4
19,-30,9:18.4
16,-29,9:18.12
17,-29,9:18.12
18,-29,9:18.12
19,-29,9:18.12
20,-29,9:18.12
21,-29,9:18.12
15,-28,9:18.4
16,-28,9:18.12
17,-28,9:18.12
18,-28,9:18.12
19,-28,9:18.12
20,-28,9:18.12
21,-28,9:18.12
22,-28,9:18.12
23,-28,9:18.12
14,-27,9:18.12
15,-27,9:18.12
16,-27,9:18.12
17,-27,9:18.12
18,-27,9:18.12
19,-27,9:18.12
20,-27,9:18.12
21,-27,9:18.12
22,-27,9:18.12
23,-27,9:18.12
24,-27,9:18.12
13,-26,9:18.4
14,-26,9:18.12
15,-26,9:18.12
16,-26,9:18.12
17,-26,9:18.12
18,-26,9:18.12
19,-26,9:18.12
20,-26,9:18.12
21,-26,9:18.12
22,-26,9:18.12
23,-26,9:18.12
24,-26,9:18.12
28,-26,9:17.12
29,-26,9:17.12
30,-26,9:17.12
13,-25,9:18.4
14,-25,9:18.12
15,-25,9:18.12
16,-25,9:18.12
17,-25,9:18.12
18,-25,9:18.12
19,-25,9:18.12
21,-25,9:17.12
22,-25,9:18.12
23,-25,9:18.12
24,-25,9:18.12
28,-25,9:17.12
30,-25,9:17.12
13,-24,9:18.12
14,-24,9:18.12
15,-24,9:18.12
16,-24,9:18.12
22,-24,9:18.12
23,-24,9:18.12
24,-24,9:18.12
25,-24,9:18.12
27,-24,9:17.12
28,-24,9:17.12
29,-24,9:17.12
13,-23,9:18.12
14,-23,9:18.12
15,-23,9:18.12
16,-23,9:18.12
22,-23,9:18.12
23,-23,9:18.12
24,-23,9:18.12
25,-23,9:18.12
27,-23,9:17.12
28,-23,9:17.12
29,-23,9:17.12
13,-22,9:18.12
14,-22,9:18.12
15,-22,9:18.12
16,-22,9:18.12
19,-22,9:17.12
20,-22,9:17.12
21,-22,9:18.12
22,-22,9:18.12
23,-22,9:18.12
24,-22,9:18.12
25,-22,9:18.12
27,-22,9:17.12
28,-22,9:17.12
29,-22,9:17.12
13,-21,9:18.12
14,-21,9:18.12
15,-21,9:18.12
16,-21,9:18.12
17,-21,9:18.12
18,-21,9:18.12
19,-21,9:17.12
20,-21,9:17.12
21,-21,9:18.12
22,-21,9:18.12
23,-21,9:18.12
24,-21,9:18.12
25,-21,9:18.12
14,-20,9:18.12
15,-20,9:18.12
16,-20,9:18.12
17,-20,9:18.12
18,-20,9:17.12
19,-20,9:17.12
20,-20,9:17.12
21,-20,9:18.12
22,-20,9:18.12
23,-20,9:18.12
24,-20,9:18.12
29,-20,9:17.12
30,-20,9:17.12
33,-20,9:17.12
34,-20,9:17.12
35,-20,9:17.12
14,-19,9:18.12
15,-19,9:18.12
16,-19,9:18.12
17,-19,9:18.12
18,-19,9:18.12
19,-19,9:18.12
20,-19,9:18.12
21,-19,9:18.12
22,-19,9:18.12
23,-19,9:18.12
29,-19,9:17.12
32,-19,9:17.12
33,-19,9:17.12
34,-19,9:17.12
16,-18,9:18.12
17,-18,9:18.12
18,-18,9:18.12
19,-18,9:18.12
20,-18,9:18.12
21,-18,9:18.12
26,-18,9:18.12
27,-18,9:18.12
28,-18,9:18.12
29,-18,9:18.12
30,-18,9:18.12
31,-18,9:18.12
32,-18,9:17.12
33,-18,9:17.12
34,-18,9:17.12
16,-17,9:18.12
20,-17,9:18.12
22,-17,9:18.12
23,-17,9:18.12
30,-17,9:18.12
31,-17,9:18.12
32,-17,9:18.12
33,-17,9:18.12
16,-16,9:18.12
17,-16,9:18.12
21,-16,9:17.12
22,-16,9:17.12
33,-16,9:18.12
15,-15,9:18.12
16,-15,9:18.12
17,-15,9:18.12
18,-15,9:18.12
19,-15,9:18.12
20,-15,9:18.12
21,-15,9:18.12
28,-15,9:17.12
29,-15,9:17.12
33,-15,9:18.12
34,-15,9:18.12
13,-14,9:18.12
14,-14,9:18.12
15,-14,9:18.12
16,-14,9:18.12
18,-14,9:18.12
19,-14,9:18.12
20,-14,9:18.12
28,-14,9:17.12
29,-14,9:18.12
34,-14,9:18.12
14,-13,9:18.12
15,-13,9:18.12
16,-13,9:18.12
17,-13,9:17.12
18,-13,9:18.12
19,-13,9:18.12
20,-13,9:18.12
26,-13,9:17.12
30,-13,9:18.12
34,-13,9:18.12
15,-12,9:18.12
16,-12,9:18.12
17,-12,9:17.12
18,-12,9:18.12
19,-12,9:18.12
20,-12,9:18.12
21,-12,9:18.12
26,-12,9:17.12
27,-12,9:17.12
31,-12,9:18.12
34,-12,9:18.12
15,-11,9:18.12
17,-11,9:18.12
18,-11,9:18.12
19,-11,9:18.12
26,-11,9:17.12
27,-11,9:17.12
34,-11,9:18.12
14,-10,9:18.12
15,-10,9:18.12
18,-10,9:18.12
19,-10,9:18.12
27,-10,9:18.12
35,-10,9:18.12
19,-9,9:18.12
26,-9,9:18.12
35,-9,9:18.4
19,-8,9:18.12
26,-8,9:18.12
34,-7,9:18.4
20,-6,9:18.12
33,-6,9:18.4
34,-6,9:18.4
20,-5,9:18.12
32,-5,9:18.4
33,-5,9:18.4
32,-4,9:18.4
22,-3,9:18.12
23,-3,9:18.12
25,-3,9:18.12
31,-3,9:18.12
26,-2,9:18.12
27,-2,9:18.12
28,-2,9:18.12
29,-2,9:18.12
30,-2,9:18.12
32,-31,10:18.12
18,-29,10:18.12
34,-29,10:18.12
17,-28,10:18.12
18,-28,10:18.12
19,-28,10:18.12
20,-28,10:18.12
16,-27,10:18.12
17,-27,10:18.12
18,-27,10:18.12
19,-27,10:18.12
20,-27,10:18.12
21,-27,10:18.12
22,-27,10:18.12
23,-27,10:18.12
15,-26,10:18.12
16,-26,10:18.12
17,-26,10:18.12
18,-26,10:18.12
19,-26,10:18.12
20,-26,10:18.12
21,-26,10:18.12
22,-26,10:18.12
23,-26,10:18.12
29,-26,10:17.12
30,-26,10:17.12
31,-26,10:18.12
32,-26,10:18.12
13,-25,10:18.4
14,-25,10:18.12
15,-25,10:18.12
16,-25,10:18.12
17,-25,10:18.12
18,-25,10:18.12
19,-25,10:18.12
20,-25,10:17.12
21,-25,10:18.12
22,-25,10:18.12
23,-25,10:18.12
28,-25,10:17.12
29,-25,10:17.12
30,-25,10:17.12
14,-24,10:18.12
15,-24,10:18.12
16,-24,10:18.12
17,-24,10:18.12
18,-24,10:18.12
19,-24,10:18.12
21,-24,10:18.12
22,-24,10:18.12
23,-24,10:18.12
14,-23,10:18.12
15,-23,10:18.12
16,-23,10:18.12
17,-23,10:18.12
18,-23,10:18.12
19,-23,10:18.12
20,-23,10:18.12
22,-23,10:18.12
23,-23,10:18.12
15,-22,10:18.12
16,-22,10:18.12
17,-22,10:18.12
18,-22,10:18.12
19,-22,10:17.12
20,-22,10:18.12
21,-22,10:18.12
22,-22,10:18.12
23,-22,10:18.12
24,-22,10:18.12
15,-21,10:18.12
16,-21,10:18.12
17,-21,10:18.12
18,-21,10:18.12
19,-21,10:18.12
20,-21,10:18.12
21,-21,10:18.12
22,-21,10:18.12
23,-21,10:18.12
24,-21,10:18.12
30,-21,10:17.12
15,-20,10:18.12
16,-20,10:18.12
17,-20,10:18.12
18,-20,10:18.12
19,-20,10:18.12
20,-20,10:18.12
21,-20,10:18.12
22,-20,10:18.12
29,-20,10:17.12
30,-20,10:17.12
34,-20,10:17.12
35,-20,10:17.12
16,-19,10:17.12
17,-19,10:17.12
18,-19,10:18.12
19,-19,10:18.12
20,-19,10:18.12
21,-19,10:18.12
34,-19,10:17.12
35,-19,10:17.12
20,-18,10:18.12
24,-18,10:18.12
25,-18,10:18.12
26,-18,10:18.12
27,-18,10:18.12
36,-18,10:18.12
23,-17,10:18.12
24,-17,10:18.12
25,-17,10:18.12
26,-17,10:18.12
27,-17,10:18.12
28,-17,10:18.12
29,-17,10:18.12
30,-17,10:18.12
31,-17,10:18.12
36,-17,10:18.12
37,-17,10:18.12
16,-16,10:18.12
21,-16,10:17.12
22,-16,10:17.12
23,-16,10:18.12
24,-16,10:18.12
25,-16,10:18.12
26,-16,10:18.12
27,-16,10:18.12
28,-16,10:18.12
29,-16,10:18.12
30,-16,10:18.12
31,-16,10:18.12
32,-16,10:18.12
37,-16,10:18.12
17,-15,10:18.12
21,-15,10:18.12
22,-15,10:18.12
23,-15,10:18.12
24,-15,10:18.12
26,-15,10:18.12
27,-15,10:18.12
28,-15,10:18.12
29,-15,10:18.12
30,-15,10:18.12
31,-15,10:18.12
32,-15,10:18.12
33,-15,10:18.12
14,-14,10:18.12
16,-14,10:18.12
17,-14,10:18.12
18,-14,10:18.12
19,-14,10:18.12
20,-14,10:18.12
21,-14,10:18.12
22,-14,10:18.12
23,-14,10:18.12
28,-14,10:17.12
29,-14,10:18.12
30,-14,10:18.12
31,-14,10:18.12
32,-14,10:18.12
33,-14,10:18.12
15,-13,10:18.12
16,-13,10:18.12
17,-13,10:18.12
18,-13,10:18.12
19,-13,10:18.12
20,-13,10:18.12
21,-13,10:18.12
22,-13,10:18.12
30,-13,10:18.12
31,-13,10:18.12
32,-13,10:18.12
33,-13,10:18.12
16,-12,10:18.12
17,-12,10:18.12
18,-12,10:18.12
19,-12,10:18.12
20,-12,10:18.12
21,-12,10:18.12
26,-12,10:17.12
27,-12,10:17.12
31,-12,10:18.12
32,-12,10:18.12
33,-12,10:18.12
34,-12,10:18.12
15,-11,10:18.12
18,-11,10:18.12
19,-11,10:18.12
20,-11,10:18.12
21,-11,10:18.12
26,-11,10:17.12
27,-11,10:17.12
31,-11,10:18.12
32,-11,10:18.12
33,-11,10:18.12
34,-11,10:18.12
19,-10,10:18.12
20,-10,10:18.12
21,-10,10:18.12
26,-10,10:17.12
27,-10,10:17.12
32,-10,10:18.12
33,-10,10:18.12
34,-10,10:18.4
19,-9,10:18.12
20,-9,10:18.12
21,-9,10:18.12
22,-9,10:18.12
26,-9,10:18.12
32,-9,10:18.4
33,-9,10:18.4
34,-9,10:18.4
35,-9,10:18.4
20,-8,10:18.12
21,-8,10:18.12
22,-8,10:18.12
26,-8,10:18.12
31,-8,10:18.12
32,-8,10:18.4
33,-8,10:18.4
34,-8,10:18.4
35,-8,10:18.4
20,-7,10:18.4
21,-7,10:18.4
22,-7,10:18.12
26,-7,10:18.12
30,-7,10:18.12
31,-7,10:18.12
32,-7,10:18.4
33,-7,10:18.4
34,-7,10:18.4
20,-6,10:18.4
21,-6,10:18.4
22,-6,10:18.12
23,-6,10:18.12
24,-6,10:18.12
26,-6,10:18.12
29,-6,10:18.12
30,-6,10:18.12
31,-6,10:18.12
32,-6,10:18.4
33,-6,10:18.4
21,-5,10:18.4
22,-5,10:18.4
23,-5,10:18.12
24,-5,10:18.12
25,-5,10:18.12
26,-5,10:18.12
27,-5,10:18.12
28,-5,10:18.12
29,-5,10:18.12
30,-5,10:18.12
31,-5,10:18.12
32,-5,10:18.4
21,-4,10:18.4
22,-4,10:18.4
23,-4,10:18.4
24,-4,10:18.4
25,-4,10:18.4
26,-4,10:18.4
27,-4,10:18.4
28,-4,10:18.4
29,-4,10:18.4
30,-4,10:18.4
23,-3,10:18.4
24,-3,10:18.4
25,-3,10:18.4
26,-3,10:18.4
27,-3,10:18.4
28,-3,10:18.4
29,-3,10:18.4
30,-3,10:18.4
28,-2,10:18.4
29,-2,10:18.4
31,-30,11:18.12
32,-30,11:18.12
33,-30,11:18.12
34,-30,11:18.12
35,-30,11:18.12
36,-30,11:18.12
30,-29,11:18.12
31,-29,11:18.12
32,-29,11:18.12
33,-29,11:18.12
34,-29,11:18.12
35,-29,11:18.12
36,-29,11:18.12
37,-29,11:18.12
18,-28,11:18.12
26,-28,11:18.12
27,-28,11:18.12
28,-28,11:18.12
29,-28,11:18.12
30,-28,11:18.12
31,-28,11:18.12
35,-28,11:18.12
36,-28,11:18.12
37,-28,11:18.12
18,-27,11:18.12
23,-27,11:18.12
25,-27,11:18.12
26,-27,11:18.12
30,-27,11:17.12
36,-27,11:18.12
37,-27,11:18.12
38,-27,11:18.12
17,-26,11:18.12
18,-26,11:18.12
19,-26,11:18.12
20,-26,11:18.12
21,-26,11:18.12
22,-26,11:18.12
25,-26,11:18.12
26,-26,11:18.12
29,-26,11:17.12
30,-26,11:17.12
31,-26,11:17.12
32,-26,11:18.12
33,-26,11:18.12
34,-26,11:18.12
35,-26,11:18.12
37,-26,11:18.12
38,-26,11:18.12
14,-25,11:18.12
15,-25,11:18.12
16,-25,11:18.12
17,-25,11:18.12
18,-25,11:18.12
19,-25,11:18.12
21,-25,11:18.12
25,-25,11:18.12
26,-25,11:18.12
30,-25,11:18.12
38,-25,11:18.12
39,-25,11:18.12
15,-24,11:18.12
16,-24,11:18.12
17,-24,11:18.12
21,-24,11:18.12
22,-24,11:18.12
24,-24,11:18.12
25,-24,11:18.12
30,-24,11:18.12
39,-24,11:18.12
40,-24,11:18.12
14,-23,11:18.12
15,-23,11:18.12
16,-23,11:18.12
17,-23,11:18.12
18,-23,11:17.12
19,-23,11:17.12
22,-23,11:18.12
23,-23,11:18.12
24,-23,11:18.12
25,-23,11:18.12
40,-23,11:18.12
16,-22,11:18.12
17,-22,11:18.12
18,-22,11:18.12
19,-22,11:17.12
20,-22,11:18.12
21,-22,11:18.12
22,-22,11:18.12
23,-22,11:18.12
24,-22,11:18.12
40,-22,11:18.12
16,-21,11:18.12
17,-21,11:18.12
18,-21,11:18.12
19,-21,11:18.12
20,-21,11:18.12
21,-21,11:18.12
23,-21,11:18.12
24,-21,11:18.12
30,-21,11:17.12
35,-21,11:17.12
39,-21,11:18.12
40,-21,11:18.12
15,-20,11:18.12
16,-20,11:17.12
17,-20,11:18.12
19,-20,11:18.12
20,-20,11:18.12
23,-20,11:18.12
24,-20,11:18.12
30,-20,11:17.12
34,-20,11:17.12
35,-20,11:17.12
39,-20,11:18.12
16,-19,11:17.12
17,-19,11:18.12
20,-19,11:18.12
24,-19,11:18.12
25,-19,11:18.12
34,-19,11:17.12
35,-19,11:17.12
38,-19,11:18.12
39,-19,11:18.12
24,-18,11:18.12
25,-18,11:18.12
26,-18,11:18.12
35,-18,11:18.12
36,-18,11:18.12
38,-18,11:18.12
39,-18,11:18.12
25,-17,11:18.12
26,-17,11:18.12
27,-17,11:18.12
36,-17,11:18.12
37,-17,11:18.12
38,-17,11:18.12
39,-17,11:18.12
21,-16,11:17.12
22,-16,11:17.12
24,-16,11:18.12
25,-16,11:18.12
26,-16,11:18.12
27,-16,11:18.12
28,-16,11:18.12
29,-16,11:18.12
37,-16,11:18.12
38,-16,11:18.12
39,-16,11:18.12
23,-15,11:18.12
24,-15,11:18.12
25,-15,11:18.12
26,-15,11:18.12
27,-15,11:18.12
28,-15,11:18.12
29,-15,11:18.12
30,-15,11:18.12
31,-15,11:18.12
35,-15,11:18.12
36,-15,11:18.12
37,-15,11:18.12
38,-15,11:18.12
22,-14,11:18.12
23,-14,11:18.12
24,-14,11:18.12
25,-14,11:18.12
26,-14,11:18.12
27,-14,11:18.12
28,-14,11:18.12
29,-14,11:18.12
30,-14,11:18.12
31,-14,11:18.12
32,-14,11:18.12
33,-14,11:18.12
34,-14,11:18.12
35,-14,11:18.12
36,-14,11:18.12
37,-14,11:18.12
17,-13,11:18.12
18,-13,11:18.12
21,-13,11:18.12
22,-13,11:18.12
23,-13,11:18.12
24,-13,11:18.12
25,-13,11:18.12
26,-13,11:18.12
27,-13,11:18.12
28,-13,11:18.12
29,-13,11:18.12
30,-13,11:18.12
31,-13,11:18.12
32,-13,11:18.12
17,-12,11:18.12
19,-12,11:18.12
20,-12,11:18.12
21,-12,11:18.12
23,-12,11:18.12
24,-12,11:18.12
25,-12,11:18.12
26,-12,11:17.12
27,-12,11:17.12
28,-12,11:18.12
29,-12,11:18.12
30,-12,11:18.12
31,-12,11:18.12
32,-12,11:18.12
20,-11,11:18.12
21,-11,11:18.12
22,-11,11:18.12
23,-11,11:18.12
24,-11,11:18.12
29,-11,11:18.12
30,-11,11:18.12
31,-11,11:18.12
32,-11,11:18.12
20,-10,11:18.12
21,-10,11:18.12
22,-10,11:18.12
23,-10,11:18.12
24,-10,11:18.12
26,-10,11:17.12
27,-10,11:17.12
29,-10,11:18.12
30,-10,11:18.12
31,-10,11:18.12
32,-10,11:18.12
33,-10,11:18.12
21,-9,11:18.12
22,-9,11:18.12
23,-9,11:18.12
24,-9,11:18.12
26,-9,11:18.12
27,-9,11:17.12
28,-9,11:18.12
29,-9,11:18.12
30,-9,11:18.12
31,-9,11:18.12
32,-9,11:18.4
33,-9,11:18.4
34,-9,11:18.4
21,-8,11:18.12
22,-8,11:18.12
23,-8,11:18.12
24,-8,11:18.12
25,-8,11:18.12
26,-8,11:18.12
27,-8,11:18.12
28,-8,11:18.12
29,-8,11:18.12
30,-8,11:18.12
31,-8,11:18.12
32,-8,11:18.4
33,-8,11:18.4
34,-8,11:18.4
35,-8,11:18.4
21,-7,11:18.4
22,-7,11:18.12
23,-7,11:18.12
24,-7,11:18.12
25,-7,11:18.12
26,-7,11:18.12
27,-7,11:18.12
28,-7,11:18.12
29,-7,11:18.12
30,-7,11:18.12
31,-7,11:18.12
32,-7,11:18.4
22,-6,11:18.12
23,-6,11:18.12
24,-6,11:18.12
25,-6,11:18.12
26,-6,11:18.12
27,-6,11:18.12
28,-6,11:18.12
29,-6,11:18.12
30,-6,11:18.12
31,-6,11:18.12
21,-5,11:18.4
22,-5,11:18.4
23,-5,11:18.12
24,-5,11:18.12
25,-5,11:18.12
26,-5,11:18.12
27,-5,11:18.12
28,-5,11:18.12
29,-5,11:18.12
30,-5,11:18.12
21,-4,11:18.4
26,-4,11:18.4
27,-4,11:18.4
28,-4,11:18.4
29,-4,11:18.4
29,-3,11:18.4
29,-2,11:18.4
31,-29,12:18.12
32,-29,12:18.12
33,-29,12:18.12
34,-29,12:18.12
35,-29,12:18.12
30,-28,12:18.12
31,-28,12:18.12
32,-28,12:18.12
34,-28,12:18.12
35,-28,12:18.12
36,-28,12:18.4
18,-27,12:18.12
25,-27,12:18.12
26,-27,12:18.12
27,-27,12:18.12
28,-27,12:18.12
29,-27,12:18.12
30,-27,12:18.12
31,-27,12:18.12
32,-27,12:18.12
33,-27,12:18.12
34,-27,12:18.12
35,-27,12:18.12
36,-27,12:18.4
37,-27,12:18.4
18,-26,12:18.12
26,-26,12:18.12
27,-26,12:18.12
28,-26,12:18.12
29,-26,12:18.12
30,-26,12:17.12
31,-26,12:17.12
32,-26,12:18.12
33,-26,12:18.12
34,-26,12:18.12
35,-26,12:18.12
36,-26,12:18.12
37,-26,12:18.12
13,-25,12:18.4
14,-25,12:18.12
15,-25,12:18.12
16,-25,12:18.12
18,-25,12:18.12
19,-25,12:18.12
21,-25,12:18.12
26,-25,12:18.12
27,-25,12:18.12
28,-25,12:18.12
29,-25,12:18.12
30,-25,12:18.12
31,-25,12:18.12
35,-25,12:18.12
36,-25,12:18.12
37,-25,12:18.12
38,-25,12:18.12
13,-24,12:18.12
14,-24,12:18.12
16,-24,12:18.12
17,-24,12:18.12
18,-24,12:18.12
19,-24,12:18.12
25,-24,12:18.12
26,-24,12:18.12
27,-24,12:18.12
28,-24,12:18.12
31,-24,12:18.12
35,-24,12:18.12
36,-24,12:18.12
37,-24,12:18.12
38,-24,12:18.12
39,-24,12:18.12
12,-23,12:18.12
13,-23,12:18.12
14,-23,12:18.12
15,-23,12:18.12
17,-23,12:18.12
18,-23,12:18.12
19,-23,12:18.12
20,-23,12:18.12
25,-23,12:18.12
26,-23,12:18.12
27,-23,12:18.12
28,-23,12:18.12
31,-23,12:18.12
36,-23,12:18.12
37,-23,12:18.12
38,-23,12:18.12
39,-23,12:18.12
40,-23,12:18.12
11,-22,12:18.12
12,-22,12:18.12
13,-22,12:18.12
17,-22,12:18.12
18,-22,12:18.12
19,-22,12:18.12
20,-22,12:18.12
21,-22,12:18.12
22,-22,12:18.12
23,-22,12:18.12
24,-22,12:18.12
25,-22,12:18.12
26,-22,12:18.12
27,-22,12:18.12
36,-22,12:17.12
37,-22,12:18.12
38,-22,12:18.12
39,-22,12:18.12
40,-22,12:18.12
11,-21,12:18.12
16,-21,12:18.12
17,-21,12:18.12
19,-21,12:18.12
20,-21,12:18.12
24,-21,12:18.12
25,-21,12:18.12
26,-21,12:18.12
27,-21,12:18.12
30,-21,12:17.12
35,-21,12:17.12
36,-21,12:17.12
37,-21,12:18.12
38,-21,12:18.12
39,-21,12:18.12
11,-20,12:18.12
12,-20,12:18.12
15,-20,12:17.12
16,-20,12:17.12
17,-20,12:18.12
19,-20,12:18.12
20,-20,12:18.12
24,-20,12:18.12
25,-20,12:18.12
26,-20,12:18.12
27,-20,12:18.12
28,-20,12:18.12
36,-20,12:18.12
37,-20,12:18.12
38,-20,12:18.12
39,-20,12:18.12
11,-19,12:18.12
12,-19,12:18.12
16,-19,12:18.12
17,-19,12:18.12
20,-19,12:18.12
25,-19,12:18.12
26,-19,12:18.12
27,-19,12:18.12
28,-19,12:18.12
34,-19,12:17.12
35,-19,12:17.12
36,-19,12:18.12
37,-19,12:18.12
38,-19,12:18.12
11,-18,12:18.12
12,-18,12:18.12
13,-18,12:18.12
16,-18,12:18.12
18,-18,12:18.12
19,-18,12:18.12
20,-18,12:18.12
26,-18,12:18.12
27,-18,12:18.12
28,-18,12:18.12
29,-18,12:18.12
35,-18,12:18.12
36,-18,12:18.12
37,-18,12:18.12
38,-18,12:18.12
12,-17,12:18.12
13,-17,12:18.12
14,-17,12:18.12
15,-17,12:18.12
17,-17,12:18.12
18,-17,12:18.12
19,-17,12:18.12
26,-17,12:18.12
27,-17,12:18.12
28,-17,12:18.12
29,-17,12:18.12
30,-17,12:18.12
31,-17,12:18.12
32,-17,12:18.12
33,-17,12:18.12
34,-17,12:18.12
35,-17,12:18.12
36,-17,12:18.12
37,-17,12:18.12
38,-17,12:18.12
13,-16,12:18.12
14,-16,12:18.12
15,-16,12:18.12
16,-16,12:18.12
17,-16,12:18.12
21,-16,12:17.12
27,-16,12:18.12
28,-16,12:18.12
29,-16,12:18.12
30,-16,12:18.12
31,-16,12:18.12
32,-16,12:18.12
33,-16,12:18.12
34,-16,12:18.12
35,-16,12:18.12
36,-16,12:18.12
37,-16,12:18.12
21,-15,12:17.12
22,-15,12:18.12
25,-15,12:18.12
26,-15,12:18.12
27,-15,12:18.12
28,-15,12:18.12
29,-15,12:18.12
30,-15,12:18.12
31,-15,12:18.12
32,-15,12:18.12
33,-15,12:18.12
34,-15,12:18.12
35,-15,12:18.12
36,-15,12:18.12
37,-15,12:18.12
23,-14,12:18.12
24,-14,12:18.12
25,-14,12:18.12
26,-14,12:18.12
27,-14,12:18.12
28,-14,12:18.12
29,-14,12:18.12
30,-14,12:18.12
31,-14,12:18.12
23,-13,12:18.12
24,-13,12:18.12
25,-13,12:18.12
28,-13,12:18.12
29,-13,12:18.12
30,-13,12:18.12
19,-12,12:18.12
20,-12,12:18.12
21,-12,12:18.12
23,-12,12:18.12
24,-12,12:18.12
25,-12,12:18.12
26,-12,12:18.12
27,-12,12:18.12
28,-12,12:18.12
29,-12,12:18.12
30,-12,12:18.12
31,-12,12:18.12
21,-11,12:18.12
22,-11,12:18.12
23,-11,12:18.12
25,-11,12:18.12
26,-11,12:18.12
27,-11,12:18.12
28,-11,12:18.12
30,-11,12:18.12
31,-11,12:18.12
22,-10,12:18.12
23,-10,12:18.12
25,-10,12:18.12
26,-10,12:18.12
27,-10,12:18.12
28,-10,12:18.12
30,-10,12:18.12
31,-10,12:18.12
22,-9,12:18.12
23,-9,12:18.12
25,-9,12:18.12
26,-9,12:18.12
27,-9,12:18.12
28,-9,12:18.12
30,-9,12:18.12
31,-9,12:18.12
32,-9,12:18.4
33,-9,12:18.4
23,-8,12:18.12
24,-8,12:18.12
26,-8,12:18.12
27,-8,12:18.12
29,-8,12:18.12
30,-8,12:18.12
31,-8,12:18.12
23,-7,12:18.12
24,-7,12:18.12
25,-7,12:18.12
26,-7,12:18.12
27,-7,12:18.12
28,-7,12:18.12
29,-7,12:18.12
30,-7,12:18.12
22,-6,12:18.12
23,-6,12:18.12
24,-6,12:18.12
25,-6,12:18.12
26,-6,12:18.12
27,-6,12:18.12
28,-6,12:18.12
29,-6,12:18.12
22,-5,12:18.4
28,-5,12:18.12
28,-4,12:18.4
29,-4,12:18.4
29,-3,12:18.4
33,-29,13:18.12
34,-29,13:18.12
35,-29,13:18.12
30,-28,13:18.12
31,-28,13:18.12
32,-28,13:18.12
34,-28,13:18.12
35,-28,13:18.12
22,-27,13:18.12
25,-27,13:18.12
26,-27,13:18.12
27,-27,13:18.12
28,-27,13:18.12
29,-27,13:18.12
30,-27,13:18.12
31,-27,13:18.12
32,-27,13:18.12
33,-27,13:18.12
34,-27,13:18.12
35,-27,13:18.12
17,-26,13:18.12
27,-26,13:18.12
28,-26,13:18.12
29,-26,13:18.12
30,-26,13:18.12
31,-26,13:18.12
32,-26,13:18.12
33,-26,13:18.12
34,-26,13:18.12
35,-26,13:18.12
36,-26,13:18.12
14,-25,13:18.12
19,-25,13:18.12
23,-25,13:18.12
27,-25,13:18.12
28,-25,13:18.12
29,-25,13:18.12
30,-25,13:18.12
31,-25,13:18.12
32,-25,13:18.12
33,-25,13:18.12
34,-25,13:18.12
35,-25,13:18.12
36,-25,13:18.12
14,-24,13:18.12
15,-24,13:18.12
16,-24,13:18.12
17,-24,13:18.12
18,-24,13:18.12
19,-24,13:18.12
27,-24,13:18.12
28,-24,13:18.12
29,-24,13:18.12
30,-24,13:18.12
31,-24,13:18.12
32,-24,13:18.12
33,-24,13:18.12
34,-24,13:18.12
35,-24,13:18.12
36,-24,13:18.12
37,-24,13:18.12
13,-23,13:18.12
14,-23,13:18.12
15,-23,13:18.12
16,-23,13:18.12
17,-23,13:18.12
18,-23,13:18.12
19,-23,13:18.12
20,-23,13:18.12
26,-23,13:18.12
27,-23,13:18.12
28,-23,13:18.12
29,-23,13:18.12
30,-23,13:18.12
31,-23,13:18.12
32,-23,13:18.12
33,-23,13:18.12
34,-23,13:18.12
35,-23,13:18.12
36,-23,13:18.12
37,-23,13:18.12
38,-23,13:18.12
39,-23,13:18.12
40,-23,13:18.12
11,-22,13:18.12
12,-22,13:18.12
13,-22,13:18.12
14,-22,13:18.12
15,-22,13:18.12
16,-22,13:18.12
17,-22,13:18.12
18,-22,13:18.12
19,-22,13:18.12
26,-22,13:18.12
27,-22,13:18.12
28,-22,13:18.12
29,-22,13:18.12
30,-22,13:18.12
34,-22,13:18.12
35,-22,13:18.12
36,-22,13:17.12
37,-22,13:18.12
38,-22,13:18.12
12,-21,13:18.12
13,-21,13:18.12
14,-21,13:18.12
15,-21,13:18.12
16,-21,13:18.12
17,-21,13:18.12
18,-21,13:18.12
19,-21,13:18.12
21,-21,13:18.12
25,-21,13:18.12
26,-21,13:18.12
27,-21,13:18.12
28,-21,13:18.12
29,-21,13:18.12
30,-21,13:18.12
34,-21,13:18.12
35,-21,13:18.12
36,-21,13:18.12
37,-21,13:18.12
38,-21,13:18.12
12,-20,13:18.12
13,-20,13:18.12
14,-20,13:18.12
15,-20,13:17.12
16,-20,13:18.12
17,-20,13:18.12
18,-20,13:18.12
19,-20,13:18.12
23,-20,13:18.12
24,-20,13:18.12
25,-20,13:18.12
26,-20,13:18.12
27,-20,13:18.12
28,-20,13:18.12
29,-20,13:18.12
30,-20,13:18.12
31,-20,13:18.12
32,-20,13:18.12
33,-20,13:18.12
36,-20,13:18.12
37,-20,13:18.12
12,-19,13:18.12
13,-19,13:18.12
14,-19,13:18.12
15,-19,13:18.12
16,-19,13:18.12
17,-19,13:18.12
18,-19,13:18.12
19,-19,13:18.12
27,-19,13:18.12
28,-19,13:18.12
29,-19,13:18.12
30,-19,13:18.12
31,-19,13:18.12
32,-19,13:18.12
33,-19,13:18.12
34,-19,13:18.12
35,-19,13:17.12
36,-19,13:18.12
37,-19,13:18.12
12,-18,13:18.12
13,-18,13:18.12
14,-18,13:18.12
15,-18,13:18.12
16,-18,13:18.12
17,-18,13:18.12
18,-18,13:18.12
19,-18,13:18.12
27,-18,13:18.12
28,-18,13:18.12
29,-18,13:18.12
30,-18,13:18.12
31,-18,13:18.12
32,-18,13:18.12
33,-18,13:18.12
34,-18,13:18.12
35,-18,13:18.12
36,-18,13:18.12
37,-18,13:18.12
12,-17,13:18.12
14,-17,13:18.12
15,-17,13:18.12
16,-17,13:18.12
17,-17,13:18.12
28,-17,13:18.12
29,-17,13:18.12
30,-17,13:18.12
31,-17,13:18.12
32,-17,13:18.12
33,-17,13:18.12
34,-17,13:18.12
35,-17,13:18.12
36,-17,13:18.12
16,-16,13:18.12
20,-16,13:17.12
21,-16,13:18.12
29,-16,13:18.12
30,-16,13:18.12
31,-16,13:18.12
32,-16,13:18.12
33,-16,13:18.12
34,-16,13:18.12
35,-16,13:18.12
36,-16,13:18.12
37,-16,13:18.12
15,-15,13:18.12
16,-15,13:18.12
20,-15,13:17.12
21,-15,13:17.12
22,-15,13:18.12
29,-15,13:18.12
37,-15,13:18.12
15,-14,13:18.12
23,-14,13:18.12
29,-14,13:18.12
14,-13,13:18.12
25,-13,13:18.12
26,-13,13:18.12
27,-13,13:18.12
28,-13,13:18.12
29,-13,13:18.12
14,-12,13:18.12
24,-12,13:18.12
25,-12,13:18.12
26,-12,13:18.12
27,-12,13:18.12
28,-12,13:18.12
29,-12,13:18.12
14,-11,13:18.12
15,-11,13:18.12
21,-11,13:18.12
22,-11,13:18.12
23,-11,13:18.12
24,-11,13:18.12
25,-11,13:18.12
28,-11,13:18.12
29,-11,13:18.12
15,-10,13:18.12
21,-10,13:18.12
22,-10,13:18.12
23,-10,13:18.12
24,-10,13:18.12
28,-10,13:18.12
29,-10,13:18.12
30,-10,13:18.12
15,-9,13:18.12
20,-9,13:18.12
24,-9,13:18.12
25,-9,13:18.12
28,-9,13:18.12
29,-9,13:18.12
30,-9,13:18.12
31,-9,13:18.12
32,-9,13:18.4
15,-8,13:18.12
24,-8,13:18.12
25,-8,13:18.12
26,-8,13:18.12
27,-8,13:18.12
28,-8,13:18.12
29,-8,13:18.12
23,-7,13:18.12
24,-7,13:18.12
25,-7,13:18.12
26,-7,13:18.12
27,-7,13:18.12
28,-7,13:18.12
22,-6,13:18.12
23,-6,13:18.12
28,-6,13:18.12
28,-5,13:18.12
28,-4,13:18.4
35,-29,14:18.12
30,-28,14:18.12
31,-28,14:18.12
34,-28,14:18.12
35,-28,14:18.12
18,-27,14:18.12
19,-27,14:18.12
20,-27,14:18.12
21,-27,14:18.12
22,-27,14:18.12
28,-27,14:18.12
34,-27,14:18.12
17,-26,14:18.12
18,-26,14:18.12
19,-26,14:18.12
20,-26,14:18.12
21,-26,14:18.12
22,-26,14:18.12
23,-26,14:18.12
28,-26,14:18.12
29,-26,14:18.12
32,-26,14:18.12
33,-26,14:18.12
34,-26,14:18.12
14,-25,14:18.12
16,-25,14:18.12
17,-25,14:18.12
18,-25,14:18.12
19,-25,14:18.12
21,-25,14:18.12
22,-25,14:18.12
23,-25,14:18.12
29,-25,14:18.12
30,-25,14:18.12
31,-25,14:18.12
32,-25,14:18.12
33,-25,14:18.12
34,-25,14:18.12
35,-25,14:18.12
14,-24,14:18.12
16,-24,14:18.12
17,-24,14:18.12
18,-24,14:18.12
19,-24,14:18.12
21,-24,14:18.12
22,-24,14:18.12
23,-24,14:18.12
28,-24,14:18.12
29,-24,14:18.12
30,-24,14:18.12
31,-24,14:18.12
34,-24,14:18.12
35,-24,14:18.12
14,-23,14:18.12
15,-23,14:18.12
16,-23,14:18.12
17,-23,14:18.12
18,-23,14:18.12
19,-23,14:18.12
20,-23,14:18.12
22,-23,14:18.12
23,-23,14:18.12
28,-23,14:18.12
29,-23,14:18.12
31,-23,14:18.12
32,-23,14:18.12
35,-23,14:18.12
36,-23,14:18.12
13,-22,14:18.12
14,-22,14:18.12
15,-22,14:18.12
16,-22,14:18.12
17,-22,14:18.12
18,-22,14:18.12
19,-22,14:18.12
20,-22,14:18.12
21,-22,14:18.12
22,-22,14:18.12
28,-22,14:18.12
29,-22,14:18.12
31,-22,14:18.12
32,-22,14:18.12
33,-22,14:18.12
35,-22,14:18.12
36,-22,14:18.12
37,-22,14:18.12
38,-22,14:18.12
12,-21,14:18.12
13,-21,14:18.12
14,-21,14:18.12
16,-21,14:18.12
17,-21,14:18.12
18,-21,14:18.12
19,-21,14:18.12
20,-21,14:18.12
21,-21,14:18.12
25,-21,14:18.12
26,-21,14:18.12
27,-21,14:18.12
28,-21,14:18.12
29,-21,14:18.12
30,-21,14:18.12
31,-21,14:18.12
32,-21,14:18.12
33,-21,14:18.12
35,-21,14:18.12
36,-21,14:18.12
13,-20,14:18.12
17,-20,14:18.12
18,-20,14:18.12
20,-20,14:18.12
25,-20,14:18.12
28,-20,14:18.12
29,-20,14:18.12
31,-20,14:18.12
32,-20,14:18.12
33,-20,14:18.12
36,-20,14:18.12
13,-19,14:18.12
14,-19,14:18.12
15,-19,14:18.12
16,-19,14:18.12
17,-19,14:18.12
18,-19,14:18.12
19,-19,14:18.12
28,-19,14:18.12
29,-19,14:18.12
30,-19,14:18.12
34,-19,14:18.12
35,-19,14:18.12
12,-18,14:18.12
13,-18,14:18.12
14,-18,14:18.12
15,-18,14:18.12
16,-18,14:18.12
19,-18,14:18.12
20,-18,14:18.12
29,-18,14:18.12
30,-18,14:18.12
31,-18,14:18.12
32,-18,14:18.12
33,-18,14:18.12
34,-18,14:18.12
35,-18,14:18.12
36,-18,14:18.12
37,-18,14:18.12
15,-17,14:18.12
16,-17,14:18.12
18,-17,14:18.12
19,-17,14:18.12
20,-17,14:18.12
21,-17,14:18.12
22,-17,14:18.12
23,-17,14:18.12
24,-17,14:18.12
30,-17,14:18.12
31,-17,14:18.12
32,-17,14:18.12
33,-17,14:18.12
35,-17,14:18.12
36,-17,14:18.12
16,-16,14:18.12
17,-16,14:18.12
18,-16,14:18.12
19,-16,14:18.12
20,-16,14:18.12
21,-16,14:18.12
22,-16,14:18.12
23,-16,14:18.12
24,-16,14:18.12
25,-16,14:18.12
30,-16,14:18.12
32,-16,14:18.12
36,-16,14:18.12
16,-15,14:18.12
17,-15,14:18.12
18,-15,14:18.12
19,-15,14:17.12
20,-15,14:17.12
22,-15,14:18.12
25,-15,14:18.12
26,-15,14:18.12
29,-15,14:18.12
33,-15,14:18.12
15,-14,14:18.12
16,-14,14:18.12
17,-14,14:18.12
18,-14,14:17.12
19,-14,14:17.12
23,-14,14:18.12
25,-14,14:18.12
26,-14,14:18.12
14,-13,14:18.12
15,-13,14:18.12
16,-13,14:18.12
26,-13,14:18.12
15,-12,14:18.12
16,-12,14:18.12
26,-12,14:18.12
27,-12,14:18.12
15,-11,14:18.12
22,-11,14:18.12
23,-11,14:18.12
24,-11,14:18.12
25,-11,14:18.12
26,-11,14:18.12
27,-11,14:18.12
28,-11,14:18.12
15,-10,14:18.12
16,-10,14:18.12
21,-10,14:18.12
22,-10,14:18.12
25,-10,14:18.12
26,-10,14:18.12
27,-10,14:18.12
28,-10,14:18.12
29,-10,14:18.12
15,-9,14:18.12
16,-9,14:18.12
17,-9,14:18.12
19,-9,14:18.12
20,-9,14:18.12
25,-9,14:18.12
26,-9,14:18.12
27,-9,14:18.12
30,-9,14:18.12
16,-8,14:18.4
17,-8,14:18.4
18,-8,14:18.4
24,-8,14:18.12
25,-8,14:18.12
27,-8,14:18.12
16,-7,14:18.4
17,-7,14:18.4
18,-7,14:18.4
19,-7,14:18.4
23,-7,14:18.12
24,-7,14:18.12
27,-7,14:18.12
18,-6,14:18.4
19,-6,14:18.4
20,-6,14:18.4
21,-6,14:18.4
22,-6,14:18.12
23,-6,14:18.12
24,-6,14:18.12
28,-6,14:18.12
21,-5,14:18.4
22,-5,14:18.4
28,-5,14:18.12
19,-27,15:18.12
34,-27,15:18.12
19,-26,15:18.12
20,-26,15:18.12
21,-26,15:18.12
22,-26,15:18.12
28,-26,15:18.12
29,-26,15:18.12
34,-26,15:18.12
17,-25,15:18.12
18,-25,15:18.12
19,-25,15:18.12
21,-25,15:18.12
29,-25,15:18.12
33,-25,15:18.12
18,-24,15:18.12
21,-24,15:18.12
22,-24,15:18.12
30,-24,15:18.12
31,-24,15:18.12
32,-24,15:18.12
33,-24,15:18.12
34,-24,15:18.12
14,-23,15:18.12
18,-23,15:18.12
19,-23,15:18.12
20,-23,15:18.12
30,-23,15:18.12
31,-23,15:18.12
32,-23,15:18.12
33,-23,15:18.12
34,-23,15:18.12
15,-22,15:18.12
18,-22,15:18.12
19,-22,15:18.12
20,-22,15:18.12
29,-22,15:18.12
30,-22,15:18.12
34,-22,15:18.12
35,-22,15:18.12
36,-22,15:18.12
37,-22,15:18.12
13,-21,15:18.12
14,-21,15:18.12
15,-21,15:18.12
16,-21,15:18.12
20,-21,15:18.12
26,-21,15:18.12
27,-21,15:18.12
28,-21,15:18.12
29,-21,15:18.12
30,-21,15:18.12
34,-21,15:18.12
35,-21,15:18.12
40,-21,15:18.12
14,-20,15:18.12
15,-20,15:18.12
16,-20,15:18.12
29,-20,15:18.12
30,-20,15:18.12
31,-20,15:18.12
32,-20,15:18.12
33,-20,15:18.12
13,-19,15:18.12
14,-19,15:18.12
15,-19,15:18.12
16,-19,15:18.12
17,-19,15:18.12
18,-19,15:18.12
30,-19,15:18.12
31,-19,15:18.12
32,-19,15:18.12
33,-19,15:18.12
34,-19,15:18.12
35,-19,15:17.12
41,-19,15:18.4
15,-18,15:18.12
31,-18,15:18.12
35,-18,15:18.12
36,-18,15:18.12
37,-18,15:18.12
38,-18,15:18.12
39,-18,15:18.12
42,-18,15:18.4
18,-17,15:18.12
19,-17,15:18.12
30,-17,15:18.12
32,-17,15:18.12
35,-17,15:18.12
42,-17,15:18.4
18,-16,15:18.12
19,-16,15:18.12
20,-16,15:18.12
21,-16,15:18.12
22,-16,15:18.12
23,-16,15:18.12
24,-16,15:18.12
30,-16,15:18.12
32,-16,15:18.12
42,-16,15:18.4
17,-15,15:18.12
18,-15,15:18.12
19,-15,15:18.12
20,-15,15:18.12
21,-15,15:18.12
22,-15,15:18.12
23,-15,15:18.12
24,-15,15:18.12
33,-15,15:18.12
41,-15,15:18.4
16,-14,15:18.12
17,-14,15:18.12
18,-14,15:18.12
19,-14,15:18.12
20,-14,15:18.12
21,-14,15:18.12
22,-14,15:18.12
23,-14,15:18.12
24,-14,15:18.12
25,-14,15:18.12
30,-14,15:18.12
33,-14,15:18.4
41,-14,15:18.4
15,-13,15:18.12
16,-13,15:18.12
17,-13,15:18.12
18,-13,15:17.12
19,-13,15:18.12
20,-13,15:18.12
21,-13,15:18.12
22,-13,15:18.12
23,-13,15:18.12
24,-13,15:18.12
25,-13,15:18.12
31,-13,15:18.12
33,-13,15:18.4
40,-13,15:18.4
41,-13,15:18.4
16,-12,15:18.12
17,-12,15:18.12
18,-12,15:18.12
19,-12,15:18.12
20,-12,15:18.12
21,-12,15:18.12
23,-12,15:18.12
24,-12,15:18.12
25,-12,15:18.12
26,-12,15:18.12
32,-12,15:18.4
39,-12,15:18.4
40,-12,15:18.4
17,-11,15:18.12
18,-11,15:18.12
19,-11,15:18.12
20,-11,15:18.12
21,-11,15:18.12
22,-11,15:18.12
23,-11,15:18.12
24,-11,15:18.12
25,-11,15:18.12
26,-11,15:18.12
33,-11,15:18.4
34,-11,15:18.4
35,-11,15:18.4
36,-11,15:18.4
37,-11,15:18.4
38,-11,15:18.4
39,-11,15:18.4
40,-11,15:18.4
16,-10,15:18.12
17,-10,15:18.12
18,-10,15:18.12
19,-10,15:18.12
20,-10,15:18.12
21,-10,15:18.12
22,-10,15:18.12
23,-10,15:18.12
24,-10,15:18.12
25,-10,15:18.12
26,-10,15:18.12
27,-10,15:18.12
16,-9,15:18.12
17,-9,15:18.12
18,-9,15:18.12
19,-9,15:18.12
20,-9,15:18.12
21,-9,15:18.12
22,-9,15:18.12
23,-9,15:18.12
24,-9,15:18.12
25,-9,15:18.12
16,-8,15:18.4
17,-8,15:18.4
18,-8,15:18.4
19,-8,15:18.4
20,-8,15:18.4
21,-8,15:18.4
22,-8,15:18.12
23,-8,15:18.12
24,-8,15:18.12
16,-7,15:18.4
19,-7,15:18.4
20,-7,15:18.4
21,-7,15:18.4
22,-7,15:18.12
23,-7,15:18.12
22,-6,15:18.12
19,-25,16:18.4
21,-25,16:18.4
33,-25,16:18.12
19,-24,16:18.12
30,-24,16:18.12
33,-24,16:18.12
20,-23,16:18.12
31,-23,16:18.12
32,-23,16:18.12
33,-23,16:18.12
36,-23,16:18.12
37,-23,16:18.12
38,-23,16:18.12
20,-22,16:18.12
31,-22,16:18.12
32,-22,16:18.12
33,-22,16:18.12
34,-22,16:18.12
35,-22,16:18.12
36,-22,16:18.12
37,-22,16:18.12
38,-22,16:18.12
39,-22,16:18.12
28,-21,16:18.12
29,-21,16:18.12
30,-21,16:18.12
31,-21,16:18.12
32,-21,16:18.12
33,-21,16:18.12
34,-21,16:18.12
38,-21,16:18.12
39,-21,16:18.12
40,-21,16:18.12
15,-20,16:18.12
31,-20,16:18.12
32,-20,16:18.12
33,-20,16:18.12
39,-20,16:18.12
40,-20,16:18.12
31,-19,16:18.12
34,-19,16:18.12
35,-19,16:17.12
39,-19,16:18.12
40,-19,16:18.12
41,-19,16:18.4
30,-18,16:18.12
31,-18,16:18.12
35,-18,16:18.12
36,-18,16:18.12
37,-18,16:18.12
38,-18,16:18.12
39,-18,16:18.12
40,-18,16:18.12
41,-18,16:18.4
18,-17,16:18.12
30,-17,16:18.12
31,-17,16:18.12
39,-17,16:18.12
40,-17,16:18.12
41,-17,16:18.4
42,-17,16:18.4
19,-16,16:18.12
24,-16,16:18.12
29,-16,16:18.4
30,-16,16:18.12
32,-16,16:18.12
39,-16,16:18.12
40,-16,16:18.4
41,-16,16:18.4
19,-15,16:18.12
20,-15,16:18.12
21,-15,16:18.12
22,-15,16:18.12
23,-15,16:18.12
30,-15,16:18.12
31,-15,16:18.12
33,-15,16:18.12
38,-15,16:18.12
39,-15,16:18.12
40,-15,16:18.4
41,-15,16:18.4
18,-14,16:18.12
19,-14,16:18.12
20,-14,16:18.12
21,-14,16:18.12
22,-14,16:18.12
23,-14,16:18.12
30,-14,16:18.4
31,-14,16:18.4
32,-14,16:18.4
33,-14,16:18.4
36,-14,16:18.4
37,-14,16:18.4
38,-14,16:18.4
39,-14,16:18.4
40,-14,16:18.4
15,-13,16:18.12
16,-13,16:18.12
17,-13,16:18.12
18,-13,16:18.12
22,-13,16:18.12
23,-13,16:18.12
24,-13,16:18.12
31,-13,16:18.4
32,-13,16:18.4
33,-13,16:18.4
34,-13,16:18.4
35,-13,16:18.4
36,-13,16:18.4
37,-13,16:18.4
38,-13,16:18.4
39,-13,16:18.4
40,-13,16:18.4
17,-12,16:18.12
23,-12,16:18.12
24,-12,16:18.12
32,-12,16:18.4
33,-12,16:18.4
34,-12,16:18.4
35,-12,16:18.4
36,-12,16:18.4
37,-12,16:18.4
38,-12,16:18.4
39,-12,16:18.4
40,-12,16:18.4
17,-11,16:18.12
18,-11,16:18.12
23,-11,16:18.12
24,-11,16:18.12
25,-11,16:18.12
33,-11,16:18.4
34,-11,16:18.4
35,-11,16:18.4
36,-11,16:18.4
17,-10,16:18.12
18,-10,16:18.12
22,-10,16:18.12
23,-10,16:18.12
24,-10,16:18.4
25,-10,16:18.4
26,-10,16:18.4
17,-9,16:18.12
18,-9,16:18.12
19,-9,16:18.12
20,-9,16:18.12
21,-9,16:18.12
22,-9,16:18.12
23,-9,16:18.4
17,-8,16:18.4
19,-8,16:18.4
20,-8,16:18.4
21,-8,16:18.4
22,-8,16:18.4
21,-7,16:18.4
22,-7,16:18.4
22,-6,16:18.4
29,-27,17:18.12
27,-25,17:18.4
35,-24,17:18.12
33,-23,17:18.12
30,-22,17:18.4
33,-22,17:18.12
36,-22,17:18.12
38,-22,17:18.12
31,-21,17:18.12
32,-21,17:18.12
33,-21,17:18.12
34,-21,17:18.12
35,-21,17:18.12
36,-21,17:18.12
37,-21,17:18.12
38,-21,17:18.12
32,-20,17:18.12
33,-20,17:18.12
36,-20,17:18.12
37,-20,17:18.12
38,-20,17:18.12
39,-20,17:18.12
32,-19,17:18.12
33,-19,17:18.12
34,-19,17:18.12
35,-19,17:17.0
36,-19,17:18.12
37,-19,17:18.12
38,-19,17:18.12
39,-19,17:18.12
40,-19,17:18.12
29,-18,17:18.4
31,-18,17:18.12
32,-18,17:18.12
33,-18,17:18.12
34,-18,17:18.12
35,-18,17:18.12
36,-18,17:18.12
37,-18,17:18.12
38,-18,17:18.12
39,-18,17:18.12
40,-18,17:18.12
31,-17,17:18.12
32,-17,17:18.12
33,-17,17:18.12
34,-17,17:18.12
35,-17,17:18.12
36,-17,17:18.12
37,-17,17:18.12
38,-17,17:18.12
39,-17,17:18.12
40,-17,17:18.4
41,-17,17:18.4
42,-17,17:18.4
19,-16,17:18.12
31,-16,17:18.12
32,-16,17:18.12
33,-16,17:18.12
34,-16,17:18.12
35,-16,17:18.12
36,-16,17:18.12
37,-16,17:18.12
38,-16,17:18.12
39,-16,17:18.12
40,-16,17:18.4
19,-15,17:18.12
23,-15,17:18.12
31,-15,17:18.12
32,-15,17:18.12
33,-15,17:18.12
34,-15,17:18.12
35,-15,17:18.12
36,-15,17:18.12
37,-15,17:18.12
38,-15,17:18.12
39,-15,17:18.12
40,-15,17:18.4
19,-14,17:18.12
20,-14,17:18.12
21,-14,17:18.12
22,-14,17:18.12
32,-14,17:18.4
33,-14,17:18.4
34,-14,17:18.4
35,-14,17:18.4
36,-14,17:18.4
37,-14,17:18.4
39,-14,17:18.4
16,-13,17:18.12
18,-13,17:18.12
19,-13,17:18.12
20,-13,17:18.12
21,-13,17:18.12
22,-13,17:18.12
33,-13,17:18.4
34,-13,17:18.4
35,-13,17:18.4
36,-13,17:18.4
37,-13,17:18.4
38,-13,17:18.4
39,-13,17:18.4
17,-12,17:18.12
18,-12,17:18.12
21,-12,17:18.12
34,-12,17:18.4
35,-12,17:18.4
36,-12,17:18.4
39,-12,17:18.4
40,-12,17:18.4
18,-11,17:18.12
19,-11,17:18.12
21,-11,17:18.12
22,-11,17:18.12
23,-11,17:18.12
24,-11,17:18.12
25,-11,17:18.12
34,-11,17:18.4
18,-10,17:18.12
19,-10,17:18.12
20,-10,17:18.12
21,-10,17:18.12
22,-10,17:18.12
17,-9,17:18.12
18,-9,17:18.12
20,-9,17:18.12
21,-9,17:18.12
21,-8,17:18.4
21,-7,17:18.4
31,-27,18:18.4
32,-27,18:18.4
28,-26,18:18.4
29,-26,18:18.4
30,-26,18:18.4
31,-26,18:18.4
32,-26,18:18.4
33,-26,18:18.4
27,-25,18:18.4
28,-25,18:18.4
29,-25,18:18.4
30,-25,18:18.4
31,-25,18:18.4
32,-25,18:18.4
33,-25,18:18.4
34,-25,18:18.4
27,-24,18:18.4
28,-24,18:18.4
29,-24,18:18.4
30,-24,18:18.4
31,-24,18:18.4
32,-24,18:18.4
33,-24,18:18.4
34,-24,18:18.4
35,-24,18:18.4
27,-23,18:18.4
28,-23,18:18.4
29,-23,18:18.4
30,-23,18:18.4
32,-23,18:18.12
33,-23,18:18.12
34,-23,18:18.12
35,-23,18:18.12
36,-23,18:18.12
27,-22,18:18.4
28,-22,18:18.4
29,-22,18:18.4
30,-22,18:18.4
32,-22,18:18.12
33,-22,18:18.12
34,-22,18:18.12
35,-22,18:18.12
36,-22,18:18.12
38,-22,18:18.12
27,-21,18:18.4
28,-21,18:18.4
29,-21,18:18.4
30,-21,18:18.4
31,-21,18:18.12
32,-21,18:18.12
33,-21,18:18.12
34,-21,18:18.12
35,-21,18:18.12
36,-21,18:18.12
38,-21,18:18.12
28,-20,18:18.4
29,-20,18:18.4
30,-20,18:18.4
31,-20,18:18.12
32,-20,18:18.12
33,-20,18:18.12
36,-20,18:18.12
37,-20,18:18.12
38,-20,18:18.12
29,-19,18:18.4
30,-19,18:18.4
31,-19,18:18.12
32,-19,18:18.12
33,-19,18:18.12
34,-19,18:18.12
35,-19,18:18.12
36,-19,18:18.12
37,-19,18:18.12
38,-19,18:18.12
29,-18,18:18.4
30,-18,18:18.4
31,-18,18:18.12
32,-18,18:18.12
33,-18,18:18.12
34,-18,18:18.12
35,-18,18:18.12
38,-18,18:18.12
39,-18,18:18.12
33,-17,18:18.12
34,-17,18:18.12
38,-17,18:18.12
39,-17,18:18.12
40,-17,18:18.4
41,-17,18:18.4
32,-16,18:18.12
33,-16,18:18.12
38,-16,18:18.12
39,-16,18:18.12
33,-15,18:18.12
34,-15,18:18.12
38,-15,18:18.12
39,-15,18:18.12
19,-14,18:18.12
22,-14,18:18.12
34,-14,18:18.4
35,-14,18:18.4
36,-14,18:18.4
37,-14,18:18.4
38,-14,18:18.4
19,-13,18:18.12
20,-13,18:18.12
21,-13,18:18.12
35,-13,18:18.4
36,-13,18:18.4
38,-13,18:18.4
39,-13,18:18.4
18,-12,18:18.12
19,-12,18:18.12
20,-12,18:18.12
21,-12,18:18.12
34,-12,18:18.4
35,-12,18:18.4
19,-11,18:18.12
20,-11,18:18.12
21,-11,18:18.12
22,-11,18:18.12
23,-11,18:18.12
18,-10,18:18.12
20,-10,18:18.12
21,-9,18:18.12
21,-8,18:18.4
28,-26,19:18.4
32,-26,19:18.4
29,-25,19:18.4
30,-25,19:18.4
31,-25,19:18.4
32,-25,19:18.4
33,-25,19:18.4
28,-24,19:18.4
29,-24,19:18.4
30,-24,19:18.4
32,-24,19:18.4
33,-24,19:18.4
28,-23,19:18.4
29,-23,19:18.4
31,-23,19:18.12
32,-23,19:18.12
33,-23,19:18.12
34,-23,19:18.12
35,-23,19:18.12
36,-23,19:18.12
27,-22,19:18.4
28,-22,19:18.4
29,-22,19:18.4
30,-22,19:18.4
31,-22,19:18.12
32,-22,19:18.12
33,-22,19:18.12
34,-22,19:18.12
29,-21,19:18.4
30,-21,19:18.4
33,-21,19:18.12
34,-21,19:18.12
38,-21,19:18.12
29,-20,19:18.4
30,-20,19:18.4
31,-20,19:18.12
32,-20,19:18.12
33,-20,19:18.12
38,-20,19:18.12
30,-19,19:18.4
31,-19,19:18.12
32,-19,19:18.12
33,-19,19:18.12
34,-19,19:18.12
37,-19,19:18.12
30,-18,19:18.4
34,-18,19:18.12
35,-18,19:18.12
36,-18,19:18.12
37,-18,19:18.12
34,-17,19:18.12
35,-17,19:18.12
36,-17,19:18.12
37,-17,19:18.12
38,-17,19:18.12
39,-17,19:18.12
40,-17,19:18.4
34,-16,19:18.12
35,-16,19:18.12
37,-16,19:18.12
38,-16,19:18.12
34,-15,19:18.12
35,-15,19:18.12
36,-15,19:18.12
37,-15,19:18.12
38,-15,19:18.12
35,-14,19:18.4
36,-14,19:18.4
37,-14,19:18.4
38,-14,19:18.4
35,-13,19:18.4
38,-13,19:18.4
20,-12,19:18.12
29,-25,20:18.4
32,-25,20:18.4
30,-24,20:18.4
31,-24,20:18.4
32,-24,20:18.4
29,-23,20:18.4
30,-23,20:18.4
31,-23,20:18.12
32,-23,20:18.12
33,-23,20:18.12
34,-23,20:18.12
35,-23,20:18.12
28,-22,20:18.4
29,-22,20:18.4
30,-22,20:18.4
31,-22,20:18.12
32,-22,20:18.12
33,-22,20:18.12
30,-21,20:18.4
31,-21,20:18.12
32,-21,20:18.12
33,-21,20:18.12
30,-20,20:18.4
30,-19,20:18.4
37,-19,20:18.12
35,-18,20:18.12
37,-18,20:18.12
35,-17,20:18.12
36,-17,20:18.12
37,-17,20:18.12
35,-16,20:18.12
36,-16,20:18.12
37,-16,20:18.12
38,-16,20:18.12
36,-15,20:18.12
37,-15,20:18.12
31,-23,21:18.4
32,-23,21:18.4
30,-22,21:18.4
31,-22,21:18.4
32,-22,21:18.4
31,-21,21:18.4
