[META]
version=2.0
spawnOnBlockType=2
spawnSunlight=True
spawnDarkness=True
spawnWater=False
spawnLava=False
underFill=False
randomRotation=True
dig=True
tree=False
branch=False
needsFoundation=True
rarity=100
collisionPercentage=20
spawnElevationMin=0
spawnElevationMax=200
spawnInBiome=Custom
[DATA]
11,-7,-8:17.12
10,-6,-8:17.12
12,-6,-8:17.12
10,-5,-8:17.12
7,-3,-8:17.12
8,-3,-8:17.12
13,-3,-8:17.12
6,-2,-8:17.12
7,-2,-8:17.12
13,-2,-8:17.12
7,-1,-8:17.12
12,-1,-8:17.12
10,-8,-7:17.12
11,-8,-7:17.12
10,-7,-7:17.12
11,-6,-7:17.12
12,-6,-7:17.12
13,-6,-7:17.12
8,-4,-7:17.12
11,-4,-7:17.12
12,-4,-7:17.12
7,-3,-7:17.12
10,-3,-7:17.12
12,-3,-7:17.12
11,-2,-7:17.12
12,-2,-7:17.12
13,-2,-7:17.12
14,-2,-7:17.12
8,-1,-7:17.12
10,-1,-7:17.12
7,0,-7:17.12
12,0,-7:17.12
13,0,-7:17.12
10,-10,-6:17.12
12,-10,-6:17.12
11,-9,-6:17.12
12,-9,-6:17.12
13,-9,-6:17.12
10,-8,-6:17.12
11,-8,-6:17.12
13,-8,-6:17.12
9,-7,-6:17.12
10,-7,-6:17.12
11,-7,-6:17.12
12,-7,-6:17.12
7,-6,-6:17.12
9,-6,-6:17.12
10,-6,-6:17.12
11,-6,-6:17.12
12,-6,-6:17.12
14,-6,-6:17.12
15,-6,-6:17.12
7,-5,-6:17.12
8,-5,-6:17.12
9,-5,-6:17.12
10,-5,-6:17.12
11,-5,-6:17.12
12,-5,-6:17.12
14,-5,-6:17.12
6,-4,-6:17.12
7,-4,-6:17.12
8,-4,-6:17.12
9,-4,-6:17.12
10,-4,-6:17.12
11,-4,-6:17.12
12,-4,-6:17.12
6,-3,-6:17.12
7,-3,-6:17.12
8,-3,-6:17.12
9,-3,-6:17.12
10,-3,-6:17.12
12,-3,-6:17.12
13,-3,-6:17.12
14,-3,-6:17.12
5,-2,-6:17.12
6,-2,-6:17.12
7,-2,-6:17.12
8,-2,-6:17.12
9,-2,-6:17.12
10,-2,-6:17.12
11,-2,-6:17.12
12,-2,-6:17.12
13,-2,-6:17.12
14,-2,-6:17.12
7,-1,-6:17.12
9,-1,-6:17.12
10,-1,-6:17.12
11,-1,-6:17.12
12,-1,-6:17.12
7,0,-6:17.12
11,0,-6:17.12
12,-11,-5:17.12
13,-11,-5:17.12
14,-11,-5:17.12
11,-10,-5:17.12
12,-10,-5:17.12
13,-10,-5:17.12
8,-9,-5:17.12
10,-9,-5:17.12
11,-9,-5:17.12
12,-9,-5:17.12
13,-9,-5:17.12
10,-8,-5:17.12
12,-8,-5:17.12
13,-8,-5:17.12
14,-8,-5:17.12
6,-7,-5:17.12
7,-7,-5:17.12
9,-7,-5:17.12
10,-7,-5:17.12
11,-7,-5:17.12
12,-7,-5:17.12
13,-7,-5:17.12
14,-7,-5:17.12
15,-7,-5:17.12
9,-6,-5:17.12
10,-6,-5:17.12
11,-6,-5:17.12
12,-6,-5:17.12
13,-6,-5:17.12
14,-6,-5:17.12
16,-6,-5:17.12
5,-5,-5:17.12
6,-5,-5:17.12
8,-5,-5:17.12
9,-5,-5:17.12
10,-5,-5:17.12
11,-5,-5:17.12
12,-5,-5:17.12
13,-5,-5:17.12
6,-4,-5:17.12
7,-4,-5:17.12
8,-4,-5:17.12
10,-4,-5:17.12
11,-4,-5:17.12
12,-4,-5:17.12
14,-4,-5:17.12
6,-3,-5:17.12
7,-3,-5:17.12
8,-3,-5:17.12
9,-3,-5:17.12
10,-3,-5:17.12
11,-3,-5:17.12
12,-3,-5:17.12
13,-3,-5:17.12
14,-3,-5:17.12
5,-2,-5:17.12
6,-2,-5:17.12
7,-2,-5:17.12
8,-2,-5:17.12
9,-2,-5:17.12
10,-2,-5:17.12
11,-2,-5:17.12
12,-2,-5:17.12
13,-2,-5:17.12
14,-2,-5:17.12
7,-1,-5:17.12
8,-1,-5:17.12
9,-1,-5:17.12
10,-1,-5:17.12
12,-1,-5:17.12
13,-1,-5:17.12
14,-1,-5:17.12
7,0,-5:17.12
11,0,-5:17.12
12,0,-5:17.12
8,1,-5:17.12
9,1,-5:17.12
14,-11,-4:17.12
10,-10,-4:17.12
12,-10,-4:17.12
13,-10,-4:17.12
14,-10,-4:17.12
8,-9,-4:17.12
9,-9,-4:17.12
10,-9,-4:17.12
11,-9,-4:17.12
12,-9,-4:17.12
13,-9,-4:17.12
15,-9,-4:17.12
9,-8,-4:17.12
10,-8,-4:17.12
11,-8,-4:17.12
13,-8,-4:17.12
14,-8,-4:17.12
7,-7,-4:17.12
8,-7,-4:17.12
9,-7,-4:17.12
10,-7,-4:17.12
11,-7,-4:17.12
12,-7,-4:17.12
13,-7,-4:17.12
14,-7,-4:17.12
16,-7,-4:17.12
7,-6,-4:17.12
8,-6,-4:17.12
9,-6,-4:17.12
10,-6,-4:17.12
11,-6,-4:17.12
12,-6,-4:17.12
13,-6,-4:17.12
14,-6,-4:17.12
15,-6,-4:17.12
16,-6,-4:17.12
5,-5,-4:17.12
6,-5,-4:17.12
7,-5,-4:17.12
8,-5,-4:17.12
9,-5,-4:17.12
10,-5,-4:17.12
11,-5,-4:17.12
12,-5,-4:17.12
13,-5,-4:17.12
14,-5,-4:17.12
15,-5,-4:17.12
16,-5,-4:17.12
6,-4,-4:17.12
7,-4,-4:17.12
8,-4,-4:17.12
9,-4,-4:17.12
10,-4,-4:17.12
11,-4,-4:17.12
12,-4,-4:17.12
13,-4,-4:17.12
14,-4,-4:17.12
15,-4,-4:17.12
6,-3,-4:17.12
7,-3,-4:17.12
8,-3,-4:17.12
9,-3,-4:17.12
10,-3,-4:17.12
11,-3,-4:17.12
12,-3,-4:17.12
13,-3,-4:17.12
14,-3,-4:17.12
15,-3,-4:17.12
6,-2,-4:17.12
7,-2,-4:17.12
8,-2,-4:17.12
9,-2,-4:17.12
10,-2,-4:17.12
11,-2,-4:17.12
12,-2,-4:17.12
13,-2,-4:17.12
6,-1,-4:17.12
7,-1,-4:17.12
8,-1,-4:17.12
9,-1,-4:17.12
10,-1,-4:17.12
11,-1,-4:17.12
12,-1,-4:17.12
7,0,-4:17.12
8,0,-4:17.12
9,0,-4:17.12
10,0,-4:17.12
11,0,-4:17.12
8,1,-4:17.12
9,1,-4:17.12
14,-11,-3:17.12
8,-10,-3:17.12
11,-10,-3:17.12
12,-10,-3:17.12
8,-9,-3:17.12
9,-9,-3:17.12
10,-9,-3:17.12
11,-9,-3:17.12
12,-9,-3:17.12
13,-9,-3:17.12
14,-9,-3:17.12
6,-8,-3:17.12
8,-8,-3:17.12
9,-8,-3:17.12
10,-8,-3:17.12
11,-8,-3:17.12
12,-8,-3:17.12
13,-8,-3:17.12
14,-8,-3:17.12
8,-7,-3:17.12
9,-7,-3:17.12
10,-7,-3:17.12
11,-7,-3:17.12
12,-7,-3:17.12
13,-7,-3:17.12
14,-7,-3:17.12
6,-6,-3:17.12
7,-6,-3:17.12
9,-6,-3:17.12
10,-6,-3:17.12
11,-6,-3:17.12
12,-6,-3:17.12
13,-6,-3:17.12
14,-6,-3:17.12
16,-6,-3:17.12
6,-5,-3:17.12
8,-5,-3:17.12
9,-5,-3:17.12
10,-5,-3:17.12
11,-5,-3:17.12
12,-5,-3:17.12
13,-5,-3:17.12
14,-5,-3:17.12
6,-4,-3:17.12
7,-4,-3:17.12
8,-4,-3:17.12
10,-4,-3:17.12
11,-4,-3:17.12
12,-4,-3:17.12
14,-4,-3:17.12
15,-4,-3:17.12
6,-3,-3:17.12
7,-3,-3:17.12
8,-3,-3:17.12
9,-3,-3:17.12
10,-3,-3:17.12
11,-3,-3:17.12
12,-3,-3:17.12
13,-3,-3:17.12
14,-3,-3:17.12
15,-3,-3:17.12
7,-2,-3:17.12
8,-2,-3:17.12
9,-2,-3:17.12
10,-2,-3:17.12
11,-2,-3:17.12
13,-2,-3:17.12
8,-1,-3:17.12
11,-1,-3:17.12
14,-1,-3:17.12
7,0,-3:17.12
8,0,-3:17.12
9,1,-3:17.12
10,1,-3:17.12
11,-11,-2:17.12
12,-11,-2:17.12
8,-10,-2:17.12
9,-10,-2:17.12
10,-10,-2:17.12
11,-10,-2:17.12
12,-10,-2:17.12
13,-10,-2:17.12
7,-9,-2:17.12
8,-9,-2:17.12
9,-9,-2:17.12
11,-9,-2:17.12
12,-9,-2:17.12
13,-9,-2:17.12
14,-9,-2:17.12
6,-8,-2:17.12
7,-8,-2:17.12
9,-8,-2:17.12
10,-8,-2:17.12
11,-8,-2:17.12
12,-8,-2:17.12
13,-8,-2:17.12
15,-8,-2:17.12
6,-7,-2:17.12
8,-7,-2:17.12
9,-7,-2:17.12
11,-7,-2:17.12
12,-7,-2:17.12
13,-7,-2:17.12
15,-7,-2:17.12
16,-7,-2:17.12
6,-6,-2:17.12
8,-6,-2:17.12
9,-6,-2:17.12
10,-6,-2:17.12
11,-6,-2:17.12
12,-6,-2:17.12
13,-6,-2:17.12
14,-6,-2:17.12
16,-6,-2:17.12
6,-5,-2:17.12
7,-5,-2:17.12
8,-5,-2:17.12
9,-5,-2:17.12
10,-5,-2:17.12
11,-5,-2:17.12
15,-5,-2:17.12
16,-5,-2:17.12
6,-4,-2:17.12
8,-4,-2:17.12
9,-4,-2:17.12
10,-4,-2:17.12
11,-4,-2:17.12
12,-4,-2:17.12
13,-4,-2:17.12
14,-4,-2:17.12
15,-4,-2:17.12
6,-3,-2:17.12
7,-3,-2:17.12
8,-3,-2:17.12
9,-3,-2:17.12
11,-3,-2:17.12
12,-3,-2:17.12
13,-3,-2:17.12
14,-3,-2:17.12
15,-3,-2:17.12
6,-2,-2:17.12
8,-2,-2:17.12
9,-2,-2:17.12
11,-2,-2:17.12
12,-2,-2:17.12
13,-2,-2:17.12
14,-2,-2:17.12
6,-1,-2:17.12
9,-1,-2:17.12
11,-1,-2:17.12
14,-1,-2:17.12
6,0,-2:17.12
7,0,-2:17.12
9,0,-2:17.12
11,0,-2:17.12
12,0,-2:17.12
13,0,-2:17.12
14,0,-2:17.12
7,1,-2:17.12
8,1,-2:17.12
9,1,-2:17.12
10,1,-2:17.12
11,1,-2:17.12
12,1,-2:17.12
9,-10,-1:17.12
10,-10,-1:17.12
11,-10,-1:17.12
12,-10,-1:17.12
13,-10,-1:17.12
7,-9,-1:17.12
8,-9,-1:17.12
9,-9,-1:17.12
13,-9,-1:17.12
14,-9,-1:17.12
7,-8,-1:17.12
8,-8,-1:17.12
10,-8,-1:17.12
11,-8,-1:17.12
15,-8,-1:17.12
7,-7,-1:17.12
10,-7,-1:17.12
12,-7,-1:17.12
15,-7,-1:17.12
16,-7,-1:17.12
6,-6,-1:17.12
10,-6,-1:17.12
11,-6,-1:17.12
12,-6,-1:17.12
15,-6,-1:17.12
16,-6,-1:17.12
6,-5,-1:17.12
11,-5,-1:17.12
12,-5,-1:17.12
15,-5,-1:17.12
6,-4,-1:17.12
7,-4,-1:17.12
14,-4,-1:17.12
15,-4,-1:17.12
6,-3,-1:17.12
7,-3,-1:17.12
14,-3,-1:17.12
6,-2,-1:17.12
7,-2,-1:17.12
14,-2,-1:17.12
6,-1,-1:17.12
7,-1,-1:17.12
13,-1,-1:17.12
14,-1,-1:17.12
7,0,-1:17.12
8,0,-1:17.12
9,0,-1:17.12
10,0,-1:17.12
11,0,-1:17.12
12,0,-1:17.12
13,0,-1:17.12
9,1,-1:17.12
10,1,-1:17.12
10,-10,0:17.12
11,-10,0:17.12
12,-10,0:17.12
13,-10,0:17.12
8,-9,0:17.12
9,-9,0:17.12
10,-9,0:17.12
13,-9,0:17.12
14,-9,0:17.12
8,-8,0:17.12
14,-8,0:17.12
15,-8,0:17.12
7,-7,0:17.12
8,-7,0:17.12
15,-7,0:17.12
7,-6,0:17.12
15,-6,0:17.12
7,-5,0:17.12
14,-5,0:17.12
15,-5,0:17.12
7,-4,0:17.12
8,-4,0:17.12
14,-4,0:17.12
7,-3,0:17.12
8,-3,0:17.12
14,-3,0:17.12
7,-2,0:17.12
13,-2,0:17.12
14,-2,0:17.12
7,-1,0:17.12
8,-1,0:17.12
9,-1,0:17.12
11,-1,0:17.12
12,-1,0:17.12
13,-1,0:17.12
9,0,0:17.12
10,0,0:17.12
11,0,0:17.12
11,-10,1:17.12
12,-10,1:17.12
13,-10,1:17.12
9,-9,1:17.12
10,-9,1:17.12
11,-9,1:17.12
12,-9,1:17.12
13,-9,1:17.12
14,-9,1:17.12
15,-9,1:17.12
8,-8,1:17.12
9,-8,1:17.12
15,-8,1:17.12
16,-8,1:17.12
7,-7,1:17.12
8,-7,1:17.12
15,-7,1:17.12
16,-7,1:17.12
7,-6,1:17.12
8,-6,1:17.12
15,-6,1:17.12
8,-5,1:17.12
14,-5,1:17.12
15,-5,1:17.12
8,-4,1:17.12
14,-4,1:17.12
8,-3,1:17.12
13,-3,1:17.12
14,-3,1:17.12
8,-2,1:17.12
9,-2,1:17.12
11,-2,1:17.12
12,-2,1:17.12
13,-2,1:17.12
9,-1,1:17.12
10,-1,1:17.12
11,-1,1:17.12
12,-1,1:17.12
10,-9,2:17.12
11,-9,2:17.12
12,-9,2:17.12
13,-9,2:17.12
14,-9,2:17.12
15,-9,2:17.12
9,-8,2:17.12
10,-8,2:17.12
11,-8,2:17.12
16,-8,2:17.12
17,-8,2:17.12
8,-7,2:17.12
9,-7,2:17.12
16,-7,2:17.12
17,-7,2:17.12
8,-6,2:17.12
9,-6,2:17.12
16,-6,2:17.12
17,-6,2:17.12
9,-5,2:17.12
15,-5,2:17.12
16,-5,2:17.12
9,-4,2:17.12
14,-4,2:17.12
15,-4,2:17.12
8,-3,2:17.12
9,-3,2:17.12
12,-3,2:17.12
13,-3,2:17.12
14,-3,2:17.12
9,-2,2:17.12
10,-2,2:17.12
11,-2,2:17.12
12,-2,2:17.12
13,-9,3:17.12
14,-9,3:17.12
15,-9,3:17.12
16,-9,3:17.12
17,-9,3:17.12
10,-8,3:17.12
11,-8,3:17.12
12,-8,3:17.12
13,-8,3:17.12
14,-8,3:17.12
16,-8,3:17.12
17,-8,3:17.12
18,-8,3:17.12
9,-7,3:17.12
10,-7,3:17.12
11,-7,3:17.12
17,-7,3:17.12
18,-7,3:17.12
9,-6,3:17.12
10,-6,3:17.12
11,-6,3:17.12
17,-6,3:17.12
9,-5,3:17.12
10,-5,3:17.12
11,-5,3:17.12
15,-5,3:17.12
16,-5,3:17.12
17,-5,3:17.12
9,-4,3:17.12
10,-4,3:17.12
11,-4,3:17.12
12,-4,3:17.12
13,-4,3:17.12
14,-4,3:17.12
15,-4,3:17.12
10,-3,3:17.12
11,-3,3:17.12
12,-3,3:17.12
13,-3,3:17.12
15,-9,4:17.12
16,-9,4:17.12
17,-9,4:17.12
18,-9,4:17.12
12,-8,4:17.12
13,-8,4:17.12
14,-8,4:17.12
18,-8,4:17.12
11,-7,4:17.12
12,-7,4:17.12
13,-7,4:17.12
17,-7,4:17.12
18,-7,4:17.12
12,-6,4:17.12
13,-6,4:17.12
17,-6,4:17.12
12,-5,4:17.12
13,-5,4:17.12
14,-5,4:17.12
15,-5,4:17.12
16,-5,4:17.12
17,-5,4:17.12
11,-4,4:17.12
12,-4,4:17.12
13,-4,4:17.12
14,-4,4:17.12
15,-9,5:17.12
16,-9,5:17.12
17,-9,5:17.12
18,-9,5:17.12
19,-9,5:17.12
13,-8,5:17.12
14,-8,5:17.12
18,-8,5:17.12
19,-8,5:17.12
14,-7,5:17.12
17,-7,5:17.12
18,-7,5:17.12
14,-6,5:17.12
15,-6,5:17.12
16,-6,5:17.12
17,-6,5:17.12
14,-5,5:17.12
15,-5,5:17.12
16,-5,5:17.12
18,-10,6:17.12
15,-9,6:17.12
16,-9,6:17.12
17,-9,6:17.12
18,-9,6:17.12
19,-9,6:17.12
14,-8,6:17.12
15,-8,6:17.12
19,-8,6:17.12
15,-7,6:17.12
17,-7,6:17.12
18,-7,6:17.12
15,-6,6:17.12
16,-6,6:17.12
17,-6,6:17.12
22,-17,7:17.12
21,-16,7:17.12
22,-16,7:17.12
21,-12,7:17.12
22,-12,7:17.12
20,-11,7:17.12
21,-11,7:17.12
22,-11,7:17.12
16,-10,7:17.12
17,-10,7:17.12
18,-10,7:17.12
19,-10,7:17.12
20,-10,7:17.12
21,-10,7:17.12
15,-9,7:17.12
16,-9,7:17.12
17,-9,7:17.12
19,-9,7:17.12
15,-8,7:17.12
19,-8,7:17.12
15,-7,7:17.12
18,-7,7:17.12
19,-7,7:17.12
16,-6,7:17.12
17,-6,7:17.12
18,-6,7:17.12
22,-16,8:17.12
23,-16,8:17.12
10,-15,8:18.6
11,-15,8:18.6
22,-15,8:17.12
12,-14,8:18.14
21,-14,8:17.12
22,-14,8:17.12
21,-13,8:17.12
22,-13,8:17.12
23,-13,8:17.12
20,-12,8:17.12
21,-12,8:17.12
22,-12,8:17.12
23,-12,8:17.12
16,-11,8:17.12
17,-11,8:17.12
19,-11,8:17.12
20,-11,8:17.12
21,-11,8:17.12
22,-11,8:17.12
15,-10,8:17.12
16,-10,8:17.12
17,-10,8:17.12
18,-10,8:17.12
19,-10,8:17.12
20,-10,8:17.12
21,-10,8:17.12
14,-9,8:17.12
15,-9,8:17.12
19,-9,8:17.12
20,-9,8:17.12
14,-8,8:17.12
15,-8,8:17.12
19,-8,8:17.12
20,-8,8:17.12
26,-8,8:17.12
27,-8,8:17.12
14,-7,8:17.12
15,-7,8:17.12
18,-7,8:17.12
19,-7,8:17.12
15,-6,8:17.12
16,-6,8:17.12
17,-6,8:17.12
18,-6,8:17.12
17,-5,8:17.12
23,-18,9:18.12
24,-18,9:18.12
21,-17,9:18.12
24,-17,9:17.12
10,-16,9:18.6
20,-16,9:18.12
21,-16,9:18.12
22,-16,9:18.12
23,-16,9:17.12
25,-16,9:18.12
11,-15,9:18.6
20,-15,9:18.12
21,-15,9:18.12
23,-15,9:18.12
24,-15,9:18.12
12,-14,9:18.14
13,-14,9:18.14
20,-14,9:18.12
21,-14,9:18.12
22,-14,9:18.12
23,-14,9:18.12
24,-14,9:18.12
25,-14,9:18.12
26,-14,9:18.12
20,-13,9:18.12
22,-13,9:17.12
23,-13,9:17.12
24,-13,9:18.12
16,-12,9:17.12
17,-12,9:17.12
20,-12,9:18.12
22,-12,9:18.12
23,-12,9:18.12
24,-12,9:18.12
16,-11,9:17.12
17,-11,9:17.12
18,-11,9:17.12
19,-11,9:17.12
15,-10,9:17.12
16,-10,9:17.12
18,-10,9:17.12
19,-10,9:17.12
20,-10,9:17.12
14,-9,9:17.12
15,-9,9:17.12
18,-9,9:17.12
19,-9,9:17.12
20,-9,9:17.12
21,-9,9:17.12
14,-8,9:17.12
19,-8,9:17.12
20,-8,9:17.12
26,-8,9:17.12
27,-8,9:17.12
14,-7,9:17.12
19,-7,9:17.12
14,-6,9:17.12
15,-6,9:17.12
16,-6,9:17.12
18,-6,9:17.12
19,-6,9:17.12
16,-5,9:17.12
17,-5,9:17.12
18,-5,9:17.12
23,-4,9:18.14
24,-3,9:18.14
21,-18,10:18.12
22,-18,10:18.12
23,-18,10:18.12
24,-18,10:18.12
25,-18,10:18.12
26,-18,10:18.12
21,-17,10:18.12
22,-17,10:18.12
23,-17,10:18.12
24,-17,10:18.12
25,-17,10:18.12
26,-17,10:18.12
27,-17,10:18.12
10,-16,10:18.6
11,-16,10:18.6
20,-16,10:18.12
21,-16,10:18.12
22,-16,10:18.12
23,-16,10:18.12
24,-16,10:18.12
25,-16,10:18.12
26,-16,10:18.12
27,-16,10:18.12
28,-16,10:18.12
11,-15,10:18.6
12,-15,10:18.14
20,-15,10:18.12
21,-15,10:18.12
22,-15,10:18.12
23,-15,10:18.12
24,-15,10:18.12
25,-15,10:18.12
26,-15,10:18.12
27,-15,10:18.12
28,-15,10:18.12
13,-14,10:18.14
14,-14,10:18.14
19,-14,10:18.12
20,-14,10:18.12
21,-14,10:18.12
22,-14,10:18.12
23,-14,10:18.12
24,-14,10:18.12
25,-14,10:18.12
26,-14,10:18.12
27,-14,10:18.12
28,-14,10:18.12
14,-13,10:18.14
16,-13,10:17.12
19,-13,10:18.12
20,-13,10:18.12
21,-13,10:18.12
22,-13,10:18.12
23,-13,10:18.12
24,-13,10:18.12
25,-13,10:18.12
26,-13,10:18.12
27,-13,10:18.12
28,-13,10:18.12
16,-12,10:17.12
17,-12,10:17.12
20,-12,10:18.12
22,-12,10:18.12
23,-12,10:18.12
24,-12,10:18.12
26,-12,10:18.12
27,-12,10:18.12
28,-12,10:18.12
16,-11,10:17.12
17,-11,10:17.12
20,-11,10:18.12
21,-11,10:18.12
22,-11,10:18.12
23,-11,10:18.12
24,-11,10:18.12
25,-11,10:18.12
26,-11,10:18.12
27,-11,10:18.12
15,-10,10:17.12
16,-10,10:17.12
17,-10,10:17.12
21,-10,10:18.12
22,-10,10:18.12
23,-10,10:18.12
24,-10,10:18.12
25,-10,10:18.12
26,-10,10:18.12
14,-9,10:17.12
15,-9,10:17.12
16,-9,10:17.12
17,-9,10:17.12
18,-9,10:17.12
19,-9,10:17.12
20,-9,10:17.12
21,-9,10:17.12
23,-9,10:18.12
24,-9,10:18.12
13,-8,10:17.12
14,-8,10:17.12
15,-8,10:17.12
16,-8,10:17.12
17,-8,10:17.12
18,-8,10:17.12
19,-8,10:17.12
20,-8,10:17.12
21,-8,10:17.12
22,-8,10:17.12
23,-8,10:17.12
24,-8,10:17.12
25,-8,10:17.12
26,-8,10:17.12
12,-7,10:17.12
13,-7,10:17.12
14,-7,10:17.12
15,-7,10:17.12
16,-7,10:17.12
18,-7,10:17.12
19,-7,10:17.12
20,-7,10:17.12
21,-7,10:17.12
22,-7,10:17.12
13,-6,10:17.12
15,-6,10:17.12
18,-6,10:17.12
7,-5,10:18.14
8,-5,10:18.14
9,-5,10:18.14
10,-5,10:18.14
16,-5,10:17.12
17,-5,10:17.12
18,-5,10:17.12
23,-5,10:18.14
17,-4,10:17.12
23,-4,10:18.14
24,-3,10:18.14
14,1,10:18.14
26,-18,11:18.12
16,-17,11:18.12
22,-17,11:18.12
23,-17,11:18.12
24,-17,11:18.12
25,-17,11:18.12
26,-17,11:18.12
11,-16,11:18.6
16,-16,11:18.12
22,-16,11:18.12
23,-16,11:18.12
24,-16,11:18.12
25,-16,11:18.12
26,-16,11:18.12
12,-15,11:18.14
13,-15,11:18.14
16,-15,11:18.12
21,-15,11:18.12
22,-15,11:18.12
25,-15,11:18.12
26,-15,11:18.12
27,-15,11:18.12
13,-14,11:18.14
14,-14,11:18.14
16,-14,11:18.12
19,-14,11:18.12
20,-14,11:18.12
21,-14,11:18.12
22,-14,11:18.12
23,-14,11:18.12
26,-14,11:18.12
27,-14,11:18.12
28,-14,11:18.12
14,-13,11:18.12
15,-13,11:18.14
16,-13,11:17.12
17,-13,11:18.12
20,-13,11:18.12
21,-13,11:18.12
22,-13,11:18.12
23,-13,11:18.12
24,-13,11:18.12
25,-13,11:18.12
26,-13,11:18.12
27,-13,11:18.12
14,-12,11:18.12
15,-12,11:18.12
16,-12,11:17.12
17,-12,11:17.12
20,-12,11:18.12
22,-12,11:18.12
23,-12,11:18.12
24,-12,11:18.12
26,-12,11:18.12
27,-12,11:18.12
15,-11,11:18.12
22,-11,11:18.12
23,-11,11:18.12
24,-11,11:18.12
25,-11,11:18.12
26,-11,11:18.12
18,-10,11:18.12
21,-10,11:18.12
22,-10,11:18.12
24,-10,11:18.12
25,-10,11:18.12
26,-10,11:18.12
26,-9,11:17.12
27,-9,11:17.12
28,-9,11:17.12
13,-8,11:17.12
14,-8,11:17.12
17,-8,11:17.12
19,-8,11:17.12
20,-8,11:17.12
21,-8,11:17.12
22,-8,11:17.12
23,-8,11:17.12
24,-8,11:17.12
25,-8,11:17.12
12,-7,11:17.12
13,-7,11:17.12
14,-7,11:17.12
16,-7,11:17.12
17,-7,11:17.12
18,-7,11:17.12
21,-7,11:17.12
22,-7,11:17.12
23,-7,11:17.12
12,-6,11:17.12
13,-6,11:17.12
16,-6,11:17.12
17,-6,11:17.12
18,-6,11:17.12
23,-6,11:18.14
7,-5,11:18.14
8,-5,11:18.14
9,-5,11:18.14
10,-5,11:18.14
11,-5,11:18.14
12,-5,11:17.12
16,-5,11:17.12
17,-5,11:17.12
18,-5,11:17.12
23,-5,11:18.14
16,-4,11:17.12
17,-4,11:17.12
18,-4,11:17.12
23,-4,11:18.14
16,-3,11:17.12
17,-3,11:17.12
24,-3,11:18.14
24,-2,11:18.14
15,-1,11:18.14
14,0,11:18.14
15,0,11:18.14
14,1,11:18.14
14,2,11:18.14
15,-21,12:18.4
16,-21,12:18.4
12,-20,12:18.4
13,-20,12:18.4
14,-20,12:18.4
15,-20,12:18.4
16,-20,12:18.4
17,-20,12:18.4
18,-20,12:18.12
19,-20,12:18.12
10,-19,12:18.4
11,-19,12:18.4
12,-19,12:18.4
13,-19,12:18.4
14,-19,12:18.4
15,-19,12:18.4
16,-19,12:18.4
17,-19,12:18.4
18,-19,12:18.12
19,-19,12:18.12
20,-19,12:18.12
9,-18,12:18.4
10,-18,12:18.4
11,-18,12:18.4
12,-18,12:18.4
13,-18,12:18.4
14,-18,12:18.4
15,-18,12:18.4
16,-18,12:18.4
17,-18,12:18.12
18,-18,12:18.12
19,-18,12:18.12
20,-18,12:18.12
21,-18,12:18.12
9,-17,12:18.4
10,-17,12:18.4
11,-17,12:18.4
12,-17,12:18.12
13,-17,12:18.12
15,-17,12:18.12
16,-17,12:18.12
20,-17,12:18.12
21,-17,12:18.12
22,-17,12:18.12
26,-17,12:18.12
8,-16,12:18.4
9,-16,12:18.4
10,-16,12:18.4
11,-16,12:18.6
12,-16,12:18.14
15,-16,12:18.12
16,-16,12:18.12
22,-16,12:18.12
23,-16,12:18.12
25,-16,12:18.12
8,-15,12:18.4
9,-15,12:18.4
10,-15,12:18.4
11,-15,12:18.4
12,-15,12:18.12
13,-15,12:18.14
14,-15,12:18.14
15,-15,12:18.12
20,-15,12:18.12
21,-15,12:18.12
22,-15,12:18.12
23,-15,12:18.12
24,-15,12:18.12
25,-15,12:18.12
8,-14,12:18.4
9,-14,12:18.4
13,-14,12:18.12
14,-14,12:18.14
15,-14,12:18.12
18,-14,12:18.12
19,-14,12:18.12
20,-14,12:18.12
21,-14,12:18.12
22,-14,12:18.12
23,-14,12:18.12
24,-14,12:18.12
25,-14,12:18.12
26,-14,12:18.12
27,-14,12:18.12
8,-13,12:18.4
9,-13,12:18.4
14,-13,12:18.12
15,-13,12:18.12
16,-13,12:17.12
17,-13,12:18.12
21,-13,12:18.12
22,-13,12:18.12
23,-13,12:18.12
24,-13,12:18.12
25,-13,12:18.12
26,-13,12:18.12
8,-12,12:18.4
14,-12,12:18.12
15,-12,12:18.12
16,-12,12:18.12
17,-12,12:18.12
19,-12,12:18.12
20,-12,12:18.12
22,-12,12:18.12
23,-12,12:18.12
24,-12,12:18.12
26,-12,12:18.12
27,-12,12:18.12
8,-11,12:18.12
12,-11,12:18.12
13,-11,12:18.12
15,-11,12:18.12
17,-11,12:18.12
18,-11,12:18.12
19,-11,12:18.12
20,-11,12:18.12
21,-11,12:18.12
22,-11,12:18.12
23,-11,12:18.12
24,-11,12:18.12
25,-11,12:18.12
26,-11,12:18.12
27,-11,12:18.12
28,-11,12:18.12
8,-10,12:18.12
10,-10,12:18.12
11,-10,12:18.12
15,-10,12:18.12
18,-10,12:18.12
19,-10,12:18.12
20,-10,12:18.12
21,-10,12:18.12
22,-10,12:18.12
23,-10,12:18.12
24,-10,12:18.12
25,-10,12:18.12
26,-10,12:18.12
27,-10,12:18.12
28,-10,12:18.12
29,-10,12:18.12
9,-9,12:18.12
18,-9,12:18.12
19,-9,12:18.12
20,-9,12:18.12
21,-9,12:18.12
22,-9,12:18.12
23,-9,12:17.12
24,-9,12:17.12
25,-9,12:18.12
26,-9,12:18.12
27,-9,12:18.12
28,-9,12:18.12
29,-9,12:18.12
9,-8,12:18.12
10,-8,12:18.12
15,-8,12:18.12
18,-8,12:18.12
19,-8,12:18.12
20,-8,12:18.12
21,-8,12:18.12
23,-8,12:17.12
26,-8,12:18.12
27,-8,12:18.12
28,-8,12:18.12
29,-8,12:18.12
11,-7,12:18.12
12,-7,12:17.12
13,-7,12:18.12
15,-7,12:18.12
18,-7,12:18.12
19,-7,12:18.12
20,-7,12:18.12
21,-7,12:18.12
23,-7,12:17.12
26,-7,12:18.12
27,-7,12:18.12
28,-7,12:18.12
29,-7,12:18.12
11,-6,12:18.12
12,-6,12:17.12
13,-6,12:18.12
18,-6,12:18.12
19,-6,12:18.12
20,-6,12:18.12
21,-6,12:18.12
23,-6,12:17.12
26,-6,12:18.12
27,-6,12:18.12
28,-6,12:18.12
7,-5,12:18.14
8,-5,12:18.14
9,-5,12:18.14
10,-5,12:18.14
11,-5,12:18.14
12,-5,12:17.12
16,-5,12:18.12
17,-5,12:17.12
18,-5,12:18.12
19,-5,12:18.12
20,-5,12:18.12
21,-5,12:18.12
22,-5,12:18.12
23,-5,12:18.14
24,-5,12:18.12
25,-5,12:18.12
26,-5,12:18.12
27,-5,12:18.12
28,-5,12:18.12
16,-4,12:17.12
17,-4,12:17.12
19,-4,12:18.12
20,-4,12:18.12
21,-4,12:18.12
22,-4,12:18.12
23,-4,12:18.14
24,-4,12:18.12
25,-4,12:18.12
26,-4,12:18.12
27,-4,12:18.12
14,-3,12:18.12
15,-3,12:18.12
16,-3,12:17.12
17,-3,12:17.12
20,-3,12:18.12
21,-3,12:18.12
22,-3,12:18.12
23,-3,12:18.12
24,-3,12:18.12
25,-3,12:18.12
26,-3,12:18.12
15,-2,12:18.12
16,-2,12:17.12
17,-2,12:17.12
23,-2,12:18.12
24,-2,12:18.12
14,-1,12:18.12
15,-1,12:18.14
16,-1,12:18.12
14,0,12:18.14
14,1,12:18.14
13,2,12:18.14
16,-21,13:18.4
15,-20,13:18.4
16,-20,13:18.4
13,-19,13:18.4
14,-19,13:18.4
15,-19,13:18.4
16,-19,13:18.4
17,-19,13:18.4
18,-19,13:18.4
11,-18,13:18.4
12,-18,13:18.4
13,-18,13:18.4
14,-18,13:18.4
15,-18,13:18.4
16,-18,13:18.4
17,-18,13:18.4
18,-18,13:18.4
19,-18,13:18.12
20,-18,13:18.12
8,-17,13:18.4
9,-17,13:18.4
10,-17,13:18.4
11,-17,13:18.4
12,-17,13:18.12
13,-17,13:18.12
14,-17,13:18.12
15,-17,13:18.12
16,-17,13:18.12
17,-17,13:18.12
18,-17,13:18.12
19,-17,13:18.12
20,-17,13:18.12
21,-17,13:18.12
22,-17,13:18.12
23,-17,13:18.12
9,-16,13:18.4
10,-16,13:18.4
11,-16,13:18.4
12,-16,13:18.12
13,-16,13:18.12
14,-16,13:18.12
15,-16,13:18.12
16,-16,13:18.12
17,-16,13:18.12
18,-16,13:18.12
19,-16,13:18.12
20,-16,13:18.12
21,-16,13:18.12
22,-16,13:18.12
25,-16,13:18.12
9,-15,13:18.4
10,-15,13:18.4
11,-15,13:18.4
12,-15,13:18.12
13,-15,13:18.12
14,-15,13:18.12
15,-15,13:18.12
16,-15,13:18.12
17,-15,13:18.12
18,-15,13:18.12
19,-15,13:18.12
20,-15,13:18.12
21,-15,13:18.12
22,-15,13:18.12
23,-15,13:18.12
24,-15,13:18.12
25,-15,13:18.12
9,-14,13:18.4
10,-14,13:18.4
11,-14,13:18.12
12,-14,13:18.12
13,-14,13:18.12
14,-14,13:18.12
15,-14,13:18.12
16,-14,13:18.12
18,-14,13:18.12
19,-14,13:18.12
20,-14,13:18.12
21,-14,13:18.12
22,-14,13:18.12
23,-14,13:18.12
24,-14,13:18.12
25,-14,13:18.12
26,-14,13:18.12
9,-13,13:18.4
10,-13,13:18.12
11,-13,13:18.12
12,-13,13:18.12
13,-13,13:18.12
14,-13,13:18.12
15,-13,13:18.12
16,-13,13:18.12
17,-13,13:18.12
18,-13,13:18.12
19,-13,13:18.12
20,-13,13:18.12
21,-13,13:18.12
22,-13,13:18.12
23,-13,13:18.12
24,-13,13:18.12
9,-12,13:18.12
10,-12,13:18.12
11,-12,13:18.12
12,-12,13:18.12
13,-12,13:18.12
14,-12,13:18.12
15,-12,13:18.12
16,-12,13:18.12
17,-12,13:18.12
18,-12,13:18.12
19,-12,13:18.12
20,-12,13:18.12
22,-12,13:18.12
23,-12,13:18.12
24,-12,13:18.12
9,-11,13:18.12
10,-11,13:18.12
11,-11,13:18.12
12,-11,13:18.12
13,-11,13:18.12
14,-11,13:18.12
15,-11,13:18.12
17,-11,13:18.12
18,-11,13:18.12
19,-11,13:18.12
20,-11,13:18.12
21,-11,13:18.12
22,-11,13:18.12
23,-11,13:18.12
24,-11,13:18.12
25,-11,13:18.12
26,-11,13:18.12
28,-11,13:18.12
9,-10,13:18.12
10,-10,13:18.12
11,-10,13:18.12
12,-10,13:18.12
13,-10,13:18.12
14,-10,13:18.12
15,-10,13:18.12
17,-10,13:18.12
18,-10,13:18.12
19,-10,13:18.12
20,-10,13:18.12
21,-10,13:18.12
22,-10,13:18.12
24,-10,13:18.12
25,-10,13:18.12
26,-10,13:18.12
27,-10,13:18.12
28,-10,13:18.12
8,-9,13:18.12
9,-9,13:18.12
10,-9,13:18.12
11,-9,13:18.12
12,-9,13:18.12
13,-9,13:18.12
14,-9,13:18.12
16,-9,13:18.12
17,-9,13:18.12
18,-9,13:18.12
19,-9,13:18.12
20,-9,13:18.12
21,-9,13:18.12
22,-9,13:18.12
23,-9,13:18.12
24,-9,13:18.12
25,-9,13:18.12
26,-9,13:18.12
27,-9,13:18.12
10,-8,13:18.12
11,-8,13:18.12
12,-8,13:18.12
13,-8,13:18.12
14,-8,13:18.12
15,-8,13:18.12
16,-8,13:18.12
17,-8,13:18.12
18,-8,13:18.12
19,-8,13:18.12
20,-8,13:18.12
21,-8,13:18.12
22,-8,13:18.12
23,-8,13:18.12
24,-8,13:18.12
25,-8,13:18.12
26,-8,13:18.12
27,-8,13:18.12
11,-7,13:18.12
12,-7,13:18.12
13,-7,13:18.12
14,-7,13:18.12
15,-7,13:18.12
16,-7,13:18.12
17,-7,13:18.12
18,-7,13:18.12
19,-7,13:18.12
20,-7,13:18.12
21,-7,13:18.12
23,-7,13:18.12
24,-7,13:18.12
25,-7,13:18.12
26,-7,13:18.12
27,-7,13:18.12
11,-6,13:17.12
12,-6,13:17.12
13,-6,13:18.12
14,-6,13:18.12
15,-6,13:18.12
16,-6,13:18.12
17,-6,13:18.12
18,-6,13:18.12
19,-6,13:18.12
20,-6,13:18.12
21,-6,13:18.12
22,-6,13:18.12
23,-6,13:17.12
24,-6,13:18.12
25,-6,13:18.12
26,-6,13:18.12
27,-6,13:18.12
8,-5,13:18.14
10,-5,13:18.14
11,-5,13:18.12
12,-5,13:18.12
13,-5,13:18.12
14,-5,13:18.12
15,-5,13:18.12
16,-5,13:18.12
17,-5,13:18.12
18,-5,13:18.12
19,-5,13:18.12
20,-5,13:18.12
21,-5,13:18.12
22,-5,13:18.12
23,-5,13:18.12
24,-5,13:18.12
25,-5,13:18.12
26,-5,13:18.12
27,-5,13:18.12
28,-5,13:18.12
11,-4,13:18.12
12,-4,13:18.12
13,-4,13:18.12
14,-4,13:18.12
15,-4,13:18.12
16,-4,13:18.12
17,-4,13:18.12
18,-4,13:18.12
19,-4,13:18.12
20,-4,13:18.12
21,-4,13:18.12
22,-4,13:18.12
23,-4,13:18.12
24,-4,13:18.12
25,-4,13:18.12
10,-3,13:18.12
11,-3,13:18.12
12,-3,13:18.12
13,-3,13:18.12
14,-3,13:18.12
15,-3,13:18.12
16,-3,13:18.12
17,-3,13:18.12
18,-3,13:18.12
19,-3,13:18.12
21,-3,13:18.12
23,-3,13:18.12
10,-2,13:18.12
11,-2,13:18.12
12,-2,13:18.12
13,-2,13:18.12
15,-2,13:18.12
16,-2,13:18.12
17,-2,13:18.12
21,-2,13:18.12
22,-2,13:18.12
23,-2,13:18.12
10,-1,13:18.12
11,-1,13:18.12
12,-1,13:18.12
13,-1,13:18.12
14,-1,13:18.12
15,-1,13:18.14
16,-1,13:18.12
17,-1,13:18.12
18,-1,13:18.12
21,-1,13:18.12
22,-1,13:18.12
11,0,13:18.12
12,0,13:18.12
13,0,13:18.12
14,0,13:18.14
16,0,13:18.12
18,0,13:18.12
19,0,13:18.12
21,0,13:18.12
11,1,13:18.4
12,1,13:18.12
13,1,13:18.12
14,1,13:18.14
16,1,13:18.12
21,1,13:18.12
12,2,13:18.12
13,2,13:18.12
14,2,13:18.12
16,2,13:18.12
19,2,13:18.12
20,2,13:18.12
13,3,13:18.4
14,3,13:18.4
17,3,13:18.4
18,3,13:18.4
19,3,13:18.4
17,4,13:18.4
16,-20,14:18.4
16,-19,14:18.4
14,-18,14:18.4
15,-18,14:18.4
16,-18,14:18.4
9,-17,14:18.4
13,-17,14:18.12
14,-17,14:18.12
15,-17,14:18.12
16,-17,14:18.12
17,-17,14:18.12
18,-17,14:18.12
22,-17,14:18.4
10,-16,14:18.4
11,-16,14:18.4
12,-16,14:18.12
13,-16,14:18.12
14,-16,14:18.12
16,-16,14:18.12
17,-16,14:18.12
18,-16,14:18.12
19,-16,14:18.12
20,-16,14:18.12
21,-16,14:18.12
11,-15,14:18.4
12,-15,14:18.12
18,-15,14:18.12
19,-15,14:18.12
20,-15,14:18.12
11,-14,14:18.12
12,-14,14:18.12
15,-14,14:18.12
19,-14,14:18.12
20,-14,14:18.12
11,-13,14:18.12
12,-13,14:18.12
14,-13,14:18.12
15,-13,14:18.12
16,-13,14:18.12
17,-13,14:18.12
19,-13,14:18.12
20,-13,14:18.12
10,-12,14:18.12
11,-12,14:18.12
12,-12,14:18.12
13,-12,14:18.12
14,-12,14:18.12
15,-12,14:18.12
16,-12,14:18.12
17,-12,14:18.12
19,-12,14:18.12
20,-12,14:18.12
7,-11,14:18.4
10,-11,14:18.12
11,-11,14:18.12
12,-11,14:18.12
14,-11,14:18.12
15,-11,14:18.12
16,-11,14:18.12
17,-11,14:18.12
18,-11,14:18.12
19,-11,14:18.12
20,-11,14:18.12
23,-11,14:18.12
6,-10,14:18.4
9,-10,14:18.12
10,-10,14:18.12
11,-10,14:18.12
12,-10,14:18.12
13,-10,14:18.12
14,-10,14:18.12
15,-10,14:18.12
16,-10,14:18.12
17,-10,14:18.12
18,-10,14:18.12
19,-10,14:18.12
20,-10,14:18.12
21,-10,14:18.12
22,-10,14:18.12
23,-10,14:18.12
24,-10,14:18.12
25,-10,14:18.12
26,-10,14:18.12
6,-9,14:18.4
10,-9,14:18.12
12,-9,14:18.12
13,-9,14:18.12
14,-9,14:18.12
16,-9,14:18.12
17,-9,14:18.12
18,-9,14:18.12
19,-9,14:18.12
21,-9,14:18.12
22,-9,14:18.12
23,-9,14:18.12
24,-9,14:18.12
25,-9,14:18.12
10,-8,14:18.12
13,-8,14:18.12
14,-8,14:18.12
15,-8,14:18.12
16,-8,14:18.12
17,-8,14:18.12
18,-8,14:18.12
21,-8,14:18.12
22,-8,14:18.12
23,-8,14:18.12
24,-8,14:18.12
25,-8,14:18.12
10,-7,14:18.12
12,-7,14:18.12
13,-7,14:18.12
15,-7,14:18.12
16,-7,14:18.12
20,-7,14:18.12
21,-7,14:18.12
23,-7,14:18.12
24,-7,14:18.12
25,-7,14:18.12
7,-6,14:18.12
8,-6,14:18.12
9,-6,14:18.12
11,-6,14:18.12
12,-6,14:17.12
14,-6,14:18.12
15,-6,14:18.12
16,-6,14:18.12
17,-6,14:18.12
18,-6,14:18.12
22,-6,14:18.12
23,-6,14:18.12
24,-6,14:18.12
26,-6,14:18.12
9,-5,14:18.12
10,-5,14:18.12
11,-5,14:18.12
12,-5,14:18.12
13,-5,14:18.12
14,-5,14:18.12
15,-5,14:18.12
16,-5,14:18.12
17,-5,14:18.12
18,-5,14:18.12
19,-5,14:18.12
22,-5,14:18.12
23,-5,14:18.12
10,-4,14:18.12
12,-4,14:18.12
13,-4,14:18.12
14,-4,14:18.12
15,-4,14:18.12
16,-4,14:18.12
17,-4,14:18.12
18,-4,14:18.12
19,-4,14:18.12
20,-4,14:18.12
21,-4,14:18.12
23,-4,14:18.12
10,-3,14:18.12
12,-3,14:18.12
13,-3,14:18.12
14,-3,14:18.12
15,-3,14:18.12
16,-3,14:18.12
17,-3,14:18.12
18,-3,14:18.12
19,-3,14:18.12
20,-3,14:18.12
21,-3,14:18.12
12,-2,14:18.12
13,-2,14:18.12
14,-2,14:18.12
15,-2,14:18.12
16,-2,14:18.12
17,-2,14:18.12
18,-2,14:18.12
19,-2,14:18.12
20,-2,14:18.12
21,-2,14:18.12
12,-1,14:18.12
13,-1,14:18.12
14,-1,14:18.12
15,-1,14:18.12
16,-1,14:18.12
17,-1,14:18.12
18,-1,14:18.12
19,-1,14:18.12
20,-1,14:18.12
21,-1,14:18.12
11,0,14:18.12
12,0,14:18.12
13,0,14:18.12
14,0,14:18.12
15,0,14:18.12
16,0,14:18.12
17,0,14:18.12
18,0,14:18.12
19,0,14:18.12
20,0,14:18.12
21,0,14:18.12
11,1,14:18.4
12,1,14:18.12
13,1,14:18.12
14,1,14:18.12
15,1,14:18.12
16,1,14:18.12
17,1,14:18.12
18,1,14:18.12
19,1,14:18.12
20,1,14:18.12
21,1,14:18.12
13,2,14:18.12
14,2,14:18.12
15,2,14:18.12
16,2,14:18.12
17,2,14:18.12
18,2,14:18.12
19,2,14:18.12
20,2,14:18.12
21,2,14:18.12
14,3,14:18.4
15,3,14:18.4
16,3,14:18.4
17,3,14:18.4
18,3,14:18.4
15,4,14:18.4
16,-18,15:18.4
15,-17,15:18.12
11,-16,15:18.4
14,-16,15:18.12
15,-16,15:18.12
16,-16,15:18.12
20,-16,15:18.12
12,-15,15:18.12
13,-15,15:18.12
14,-15,15:18.12
15,-15,15:18.12
16,-15,15:18.12
17,-15,15:18.12
18,-15,15:18.12
19,-15,15:18.12
12,-14,15:18.12
13,-14,15:18.12
14,-14,15:18.12
18,-14,15:18.12
12,-13,15:18.12
13,-13,15:18.12
17,-13,15:18.12
18,-13,15:18.12
8,-12,15:18.4
9,-12,15:18.12
10,-12,15:18.12
11,-12,15:18.12
12,-12,15:18.12
13,-12,15:18.12
14,-12,15:18.12
16,-12,15:18.12
17,-12,15:18.12
18,-12,15:18.12
8,-11,15:18.12
9,-11,15:18.12
10,-11,15:18.12
11,-11,15:18.12
12,-11,15:18.12
13,-11,15:18.12
14,-11,15:18.12
15,-11,15:18.12
16,-11,15:18.12
17,-11,15:18.12
18,-11,15:18.12
19,-11,15:18.12
7,-10,15:18.12
8,-10,15:18.12
9,-10,15:18.12
10,-10,15:18.12
11,-10,15:18.12
12,-10,15:18.12
13,-10,15:18.12
14,-10,15:18.12
15,-10,15:18.12
16,-10,15:18.12
17,-10,15:18.12
19,-10,15:18.12
20,-10,15:18.12
6,-9,15:18.4
7,-9,15:18.12
8,-9,15:18.12
9,-9,15:18.12
10,-9,15:18.12
11,-9,15:18.12
12,-9,15:18.12
13,-9,15:18.12
14,-9,15:18.12
16,-9,15:18.12
17,-9,15:18.12
23,-9,15:18.12
24,-9,15:18.12
5,-8,15:18.4
6,-8,15:18.4
7,-8,15:18.12
8,-8,15:18.12
9,-8,15:18.12
10,-8,15:18.12
11,-8,15:18.12
12,-8,15:18.12
13,-8,15:18.12
14,-8,15:18.12
15,-8,15:18.12
16,-8,15:18.12
17,-8,15:18.12
22,-8,15:18.12
23,-8,15:18.12
5,-7,15:18.4
7,-7,15:18.12
9,-7,15:18.12
10,-7,15:18.12
12,-7,15:18.12
13,-7,15:18.12
14,-7,15:18.12
15,-7,15:18.12
16,-7,15:18.12
17,-7,15:18.12
18,-7,15:18.12
23,-7,15:18.12
5,-6,15:18.4
6,-6,15:18.4
7,-6,15:18.12
8,-6,15:18.12
9,-6,15:18.12
10,-6,15:18.12
11,-6,15:18.12
12,-6,15:18.12
15,-6,15:18.12
16,-6,15:18.12
17,-6,15:18.12
18,-6,15:18.12
23,-6,15:18.12
5,-5,15:18.4
6,-5,15:18.4
7,-5,15:18.12
8,-5,15:18.12
10,-5,15:18.12
11,-5,15:18.12
12,-5,15:18.12
13,-5,15:18.12
14,-5,15:18.12
15,-5,15:18.12
16,-5,15:18.12
17,-5,15:18.12
18,-5,15:18.12
5,-4,15:18.4
6,-4,15:18.4
7,-4,15:18.12
8,-4,15:18.12
10,-4,15:18.12
11,-4,15:17.12
12,-4,15:18.12
13,-4,15:18.12
14,-4,15:18.12
15,-4,15:18.12
16,-4,15:18.12
17,-4,15:18.12
18,-4,15:18.12
19,-4,15:18.12
20,-4,15:18.12
5,-3,15:18.4
6,-3,15:18.4
7,-3,15:18.12
8,-3,15:18.12
9,-3,15:18.12
10,-3,15:18.12
12,-3,15:18.12
13,-3,15:18.12
14,-3,15:18.12
15,-3,15:18.12
16,-3,15:18.12
17,-3,15:18.12
18,-3,15:18.12
19,-3,15:18.12
6,-2,15:18.4
7,-2,15:18.12
8,-2,15:18.12
9,-2,15:18.12
13,-2,15:18.12
14,-2,15:18.12
15,-2,15:18.12
16,-2,15:18.12
17,-2,15:18.12
18,-2,15:18.12
19,-2,15:18.12
7,-1,15:18.12
8,-1,15:18.12
9,-1,15:18.12
10,-1,15:18.12
11,-1,15:18.12
12,-1,15:18.12
13,-1,15:18.12
14,-1,15:18.12
15,-1,15:18.12
16,-1,15:18.12
17,-1,15:18.12
18,-1,15:18.12
19,-1,15:18.12
8,0,15:18.12
9,0,15:18.12
10,0,15:18.12
11,0,15:18.12
12,0,15:18.12
13,0,15:18.12
14,0,15:18.12
15,0,15:18.12
16,0,15:18.12
17,0,15:18.12
18,0,15:18.12
19,0,15:18.12
10,1,15:18.4
11,1,15:18.4
12,1,15:18.12
14,1,15:18.12
15,1,15:18.12
16,1,15:18.12
17,1,15:18.12
20,1,15:18.12
15,2,15:18.12
15,3,15:18.4
15,-17,16:18.12
15,-16,16:18.12
12,-15,16:18.12
13,-15,16:18.12
15,-15,16:18.12
17,-15,16:18.12
18,-15,16:18.12
13,-14,16:18.12
14,-14,16:18.12
15,-14,16:18.12
16,-14,16:18.12
14,-13,16:18.12
15,-13,16:18.12
16,-13,16:18.12
8,-12,16:18.4
12,-12,16:18.12
13,-12,16:18.12
14,-12,16:18.12
15,-12,16:18.12
16,-12,16:18.12
17,-12,16:18.12
9,-11,16:18.12
14,-11,16:18.12
15,-11,16:18.12
18,-11,16:18.12
19,-11,16:18.12
9,-10,16:18.12
10,-10,16:18.12
11,-10,16:18.12
12,-10,16:18.12
13,-10,16:18.12
14,-10,16:18.12
15,-10,16:18.12
8,-9,16:18.12
9,-9,16:18.12
10,-9,16:18.12
11,-9,16:18.12
12,-9,16:18.12
13,-9,16:18.12
14,-9,16:18.12
7,-8,16:18.12
8,-8,16:18.12
9,-8,16:18.12
10,-8,16:18.12
11,-8,16:18.12
12,-8,16:18.12
13,-8,16:18.12
14,-8,16:18.12
15,-8,16:18.12
7,-7,16:18.12
9,-7,16:18.12
10,-7,16:18.12
11,-7,16:18.12
12,-7,16:18.12
13,-7,16:18.12
14,-7,16:18.12
15,-7,16:18.12
16,-7,16:18.12
5,-6,16:18.4
6,-6,16:18.4
7,-6,16:18.12
8,-6,16:18.12
9,-6,16:18.12
10,-6,16:18.12
11,-6,16:18.12
12,-6,16:18.12
13,-6,16:18.12
14,-6,16:18.12
15,-6,16:18.12
16,-6,16:18.12
6,-5,16:18.4
7,-5,16:18.12
8,-5,16:18.12
9,-5,16:18.12
10,-5,16:18.12
11,-5,16:18.12
12,-5,16:18.12
13,-5,16:18.12
14,-5,16:18.12
15,-5,16:18.12
16,-5,16:18.12
17,-5,16:18.12
18,-5,16:18.12
7,-4,16:18.12
8,-4,16:18.12
9,-4,16:18.12
10,-4,16:18.12
11,-4,16:18.12
12,-4,16:18.12
13,-4,16:18.12
14,-4,16:18.12
15,-4,16:18.12
16,-4,16:18.12
7,-3,16:18.12
8,-3,16:18.12
9,-3,16:18.12
10,-3,16:18.12
11,-3,16:18.12
12,-3,16:18.12
13,-3,16:18.12
14,-3,16:18.12
15,-3,16:18.12
16,-3,16:18.12
17,-3,16:18.12
18,-3,16:18.12
8,-2,16:18.12
9,-2,16:18.12
10,-2,16:18.12
11,-2,16:18.12
12,-2,16:18.12
13,-2,16:18.12
14,-2,16:18.12
15,-2,16:18.12
16,-2,16:18.12
17,-2,16:18.12
8,-1,16:18.12
9,-1,16:18.12
10,-1,16:18.12
11,-1,16:18.12
12,-1,16:18.12
13,-1,16:18.12
14,-1,16:18.12
15,-1,16:18.12
16,-1,16:18.12
17,-1,16:18.12
7,0,16:18.12
12,0,16:18.12
13,0,16:18.12
14,0,16:18.12
16,0,16:18.12
18,0,16:18.12
15,1,16:18.12
9,-11,17:18.4
14,-11,17:18.4
9,-10,17:18.12
14,-10,17:18.12
9,-9,17:18.12
10,-9,17:18.12
13,-9,17:18.12
9,-8,17:18.12
10,-8,17:18.12
11,-8,17:18.12
12,-8,17:18.12
13,-8,17:18.12
9,-7,17:18.12
10,-7,17:18.12
11,-7,17:18.12
12,-7,17:18.12
13,-7,17:18.12
14,-7,17:18.12
6,-6,17:18.4
7,-6,17:18.12
8,-6,17:18.12
9,-6,17:18.12
10,-6,17:18.12
12,-6,17:18.12
13,-6,17:18.12
14,-6,17:18.12
15,-6,17:18.12
8,-5,17:18.12
9,-5,17:18.12
10,-5,17:18.12
12,-5,17:18.12
13,-5,17:18.12
14,-5,17:18.12
16,-5,17:18.12
17,-5,17:18.4
18,-5,17:18.4
9,-4,17:18.12
10,-4,17:18.12
11,-4,17:18.12
12,-4,17:18.12
13,-4,17:18.12
14,-4,17:18.12
9,-3,17:18.12
10,-3,17:18.12
11,-3,17:18.12
12,-3,17:18.12
13,-3,17:18.12
8,-2,17:18.12
9,-2,17:18.12
13,-2,17:18.12
8,-1,17:18.12
13,-1,17:18.12
7,0,17:18.12
14,0,17:18.12
10,-9,18:18.12
13,-9,18:18.12
10,-8,18:18.12
12,-8,18:18.12
10,-7,18:18.12
11,-7,18:18.12
12,-7,18:18.12
7,-6,18:18.12
8,-6,18:18.12
9,-6,18:18.12
10,-6,18:18.12
11,-6,18:18.12
12,-6,18:18.12
13,-6,18:18.12
14,-6,18:18.12
15,-6,18:18.12
10,-5,18:18.12
11,-5,18:18.12
12,-5,18:18.12
10,-4,18:18.12
12,-4,18:18.12
9,-3,18:18.12
12,-3,18:18.12
13,-2,18:18.12
12,-3,19:18.12
