[META]
version=2.0
spawnOnBlockType=2
spawnSunlight=True
spawnDarkness=True
spawnWater=False
spawnLava=False
underFill=False
randomRotation=True
dig=True
tree=False
branch=False
needsFoundation=True
rarity=100
collisionPercentage=20
spawnElevationMin=0
spawnElevationMax=200
spawnInBiome=Custom
[DATA]
7,-13,-8:17.12
4,-12,-8:17.12
11,-12,-8:17.12
10,-11,-8:17.12
13,-11,-8:17.12
1,-10,-8:17.12
1,-9,-8:17.12
-2,-7,-8:17.12
-1,-7,-8:17.12
-1,-6,-8:17.12
5,-6,-8:17.12
11,-6,-8:17.12
5,-5,-8:17.12
10,-5,-8:17.12
8,-3,-8:17.12
-1,-2,-8:17.12
1,0,-8:17.12
8,1,-8:17.12
8,3,-8:17.12
5,-12,-7:17.12
6,-12,-7:17.12
10,-12,-7:17.12
11,-12,-7:17.12
10,-11,-7:17.12
11,-11,-7:17.12
12,-11,-7:17.12
10,-10,-7:17.12
11,-10,-7:17.12
1,-9,-7:17.12
11,-9,-7:17.12
-1,-7,-7:17.12
11,-7,-7:17.12
-2,-6,-7:17.12
-1,-6,-7:17.12
0,-6,-7:17.12
5,-6,-7:17.12
10,-6,-7:17.12
-2,-5,-7:17.12
-1,-5,-7:17.12
10,-5,-7:17.12
11,-5,-7:17.12
12,-5,-7:17.12
9,-4,-7:17.12
10,-4,-7:17.12
11,-4,-7:17.12
12,-4,-7:17.12
8,-3,-7:17.12
9,-3,-7:17.12
-1,-2,-7:17.12
0,-1,-7:17.12
1,-1,-7:17.12
1,0,-7:17.12
8,0,-7:17.12
7,1,-7:17.12
8,1,-7:17.12
9,1,-7:17.12
7,2,-7:17.12
8,2,-7:17.12
9,2,-7:17.12
7,3,-7:17.12
8,3,-7:17.12
9,3,-7:17.12
6,-12,-6:17.12
6,-11,-6:17.12
10,-11,-6:17.12
11,-11,-6:17.12
10,-10,-6:17.12
11,-10,-6:17.12
12,-10,-6:17.12
1,-9,-6:17.12
10,-9,-6:17.12
11,-9,-6:17.12
11,-8,-6:17.12
-2,-7,-6:17.12
-1,-7,-6:17.12
0,-7,-6:17.12
10,-7,-6:17.12
11,-7,-6:17.12
-1,-6,-6:17.12
0,-6,-6:17.12
5,-6,-6:17.12
10,-6,-6:17.12
11,-6,-6:17.12
12,-6,-6:17.12
-2,-5,-6:17.12
-1,-5,-6:17.12
0,-5,-6:17.12
10,-5,-6:17.12
11,-5,-6:17.12
11,-4,-6:17.12
0,-3,-6:17.12
0,-2,-6:17.12
6,0,-6:17.12
7,0,-6:17.12
8,0,-6:17.12
7,1,-6:17.12
8,1,-6:17.12
7,2,-6:17.12
8,2,-6:17.12
6,-11,-5:17.12
7,-11,-5:17.12
11,-11,-5:17.12
10,-10,-5:17.12
11,-10,-5:17.12
1,-9,-5:17.12
10,-9,-5:17.12
11,-9,-5:17.12
12,-9,-5:17.12
0,-8,-5:17.12
1,-8,-5:17.12
2,-8,-5:17.12
10,-8,-5:17.12
11,-8,-5:17.12
-1,-7,-5:17.12
0,-7,-5:17.12
1,-7,-5:17.12
5,-7,-5:17.12
10,-7,-5:17.12
11,-7,-5:17.12
12,-7,-5:17.12
-1,-6,-5:17.12
0,-6,-5:17.12
1,-6,-5:17.12
2,-6,-5:17.12
4,-6,-5:17.12
5,-6,-5:17.12
6,-6,-5:17.12
10,-6,-5:17.12
11,-6,-5:17.12
12,-6,-5:17.12
-1,-5,-5:17.12
0,-5,-5:17.12
1,-5,-5:17.12
1,-4,-5:17.12
6,-1,-5:17.12
7,-1,-5:17.12
8,-1,-5:17.12
6,0,-5:17.12
7,0,-5:17.12
8,0,-5:17.12
6,1,-5:17.12
7,1,-5:17.12
8,1,-5:17.12
9,1,-5:17.12
6,2,-5:17.12
7,2,-5:17.12
8,2,-5:17.12
7,-11,-4:17.12
7,-10,-4:17.12
8,-10,-4:17.12
11,-10,-4:17.12
0,-9,-4:17.12
1,-9,-4:17.12
2,-9,-4:17.12
8,-9,-4:17.12
9,-9,-4:17.12
10,-9,-4:17.12
11,-9,-4:17.12
12,-9,-4:17.12
0,-8,-4:17.12
1,-8,-4:17.12
2,-8,-4:17.12
3,-8,-4:17.12
9,-8,-4:17.12
10,-8,-4:17.12
11,-8,-4:17.12
12,-8,-4:17.12
0,-7,-4:17.12
1,-7,-4:17.12
2,-7,-4:17.12
10,-7,-4:17.12
11,-7,-4:17.12
0,-6,-4:17.12
1,-6,-4:17.12
2,-6,-4:17.12
3,-6,-4:17.12
4,-6,-4:17.12
0,-5,-4:17.12
1,-5,-4:17.12
5,-2,-4:17.12
4,-1,-4:17.12
5,-1,-4:17.12
6,-1,-4:17.12
7,-1,-4:17.12
5,0,-4:17.12
6,0,-4:17.12
7,0,-4:17.12
8,0,-4:17.12
6,1,-4:17.12
7,1,-4:17.12
8,1,-4:17.12
7,2,-4:17.12
2,-9,-3:17.12
3,-9,-3:17.12
9,-9,-3:17.12
10,-9,-3:17.12
11,-9,-3:17.12
0,-8,-3:17.12
1,-8,-3:17.12
2,-8,-3:17.12
3,-8,-3:17.12
4,-8,-3:17.12
9,-8,-3:17.12
10,-8,-3:17.12
11,-8,-3:17.12
12,-8,-3:17.12
2,-7,-3:17.12
3,-7,-3:17.12
4,-7,-3:17.12
9,-7,-3:17.12
10,-7,-3:17.12
11,-7,-3:17.12
0,-6,-3:17.12
1,-6,-3:17.12
2,-6,-3:17.12
3,-6,-3:17.12
4,-6,-3:17.12
10,-6,-3:17.12
1,-5,-3:17.12
2,-5,-3:17.12
3,-5,-3:17.12
4,-2,-3:17.12
5,-2,-3:17.12
6,-2,-3:17.12
4,-1,-3:17.12
5,-1,-3:17.12
6,-1,-3:17.12
7,-1,-3:17.12
5,0,-3:17.12
6,0,-3:17.12
7,0,-3:17.12
8,0,-3:17.12
5,1,-3:17.12
6,1,-3:17.12
2,-9,-2:17.12
4,-9,-2:17.12
10,-9,-2:17.12
1,-8,-2:17.12
2,-8,-2:17.12
3,-8,-2:17.12
4,-8,-2:17.12
9,-8,-2:17.12
10,-8,-2:17.12
11,-8,-2:17.12
2,-7,-2:17.12
3,-7,-2:17.12
4,-7,-2:17.12
9,-7,-2:17.12
10,-7,-2:17.12
11,-7,-2:17.12
1,-6,-2:17.12
2,-6,-2:17.12
3,-6,-2:17.12
4,-6,-2:17.12
9,-6,-2:17.12
10,-6,-2:17.12
11,-6,-2:17.12
2,-5,-2:17.12
3,-5,-2:17.12
4,-5,-2:17.12
10,-5,-2:17.12
2,-4,-2:17.12
3,-4,-2:17.12
3,-3,-2:17.12
4,-3,-2:17.12
5,-3,-2:17.12
6,-3,-2:17.12
4,-2,-2:17.12
5,-2,-2:17.12
6,-2,-2:17.12
4,-1,-2:17.12
5,-1,-2:17.12
6,-1,-2:17.12
5,0,-2:17.12
6,1,-2:17.12
4,-9,-1:17.12
5,-9,-1:17.12
6,-9,-1:17.12
7,-9,-1:17.12
8,-9,-1:17.12
2,-8,-1:17.12
3,-8,-1:17.12
4,-8,-1:17.12
5,-8,-1:17.12
6,-8,-1:17.12
7,-8,-1:17.12
8,-8,-1:17.12
9,-8,-1:17.12
10,-8,-1:17.12
1,-7,-1:17.12
2,-7,-1:17.12
3,-7,-1:17.12
4,-7,-1:17.12
5,-7,-1:17.12
6,-7,-1:17.12
7,-7,-1:17.12
8,-7,-1:17.12
9,-7,-1:17.12
10,-7,-1:17.12
11,-7,-1:17.12
1,-6,-1:17.12
2,-6,-1:17.12
3,-6,-1:17.12
4,-6,-1:17.12
5,-6,-1:17.12
6,-6,-1:17.12
7,-6,-1:17.12
8,-6,-1:17.12
9,-6,-1:17.12
10,-6,-1:17.12
11,-6,-1:17.12
2,-5,-1:17.12
3,-5,-1:17.12
4,-5,-1:17.12
5,-5,-1:17.12
6,-5,-1:17.12
7,-5,-1:17.12
8,-5,-1:17.12
9,-5,-1:17.12
10,-5,-1:17.12
2,-4,-1:17.12
3,-4,-1:17.12
4,-4,-1:17.12
5,-4,-1:17.12
6,-4,-1:17.12
7,-4,-1:17.12
8,-4,-1:17.12
9,-4,-1:17.12
2,-3,-1:17.12
3,-3,-1:17.12
4,-3,-1:17.12
5,-3,-1:17.12
6,-3,-1:17.12
7,-3,-1:17.12
8,-3,-1:17.12
9,-3,-1:17.12
4,-2,-1:17.12
5,-2,-1:17.12
6,-2,-1:17.12
7,-2,-1:17.12
8,-2,-1:17.12
5,-1,-1:17.12
6,-1,-1:17.12
5,-9,0:17.12
6,-9,0:17.12
7,-9,0:17.12
4,-8,0:17.12
5,-8,0:17.12
6,-8,0:17.12
7,-8,0:17.12
8,-8,0:17.12
3,-7,0:17.12
4,-7,0:17.12
9,-7,0:17.12
10,-7,0:17.12
2,-6,0:17.12
3,-6,0:17.12
9,-6,0:17.12
10,-6,0:17.12
11,-6,0:17.12
2,-5,0:17.12
3,-5,0:17.12
9,-5,0:17.12
10,-5,0:17.12
2,-4,0:17.12
3,-4,0:17.12
9,-4,0:17.12
3,-3,0:17.12
4,-3,0:17.12
5,-3,0:17.12
8,-3,0:17.12
9,-3,0:17.12
4,-2,0:17.12
5,-2,0:17.12
6,-2,0:17.12
7,-2,0:17.12
8,-2,0:17.12
5,-1,0:17.12
4,-8,1:17.12
5,-8,1:17.12
6,-8,1:17.12
7,-8,1:17.12
8,-8,1:17.12
3,-7,1:17.12
4,-7,1:17.12
8,-7,1:17.12
9,-7,1:17.12
3,-6,1:17.12
9,-6,1:17.12
3,-5,1:17.12
9,-5,1:17.12
3,-4,1:17.12
4,-4,1:17.12
9,-4,1:17.12
4,-3,1:17.12
8,-3,1:17.12
4,-2,1:17.12
5,-2,1:17.12
6,-2,1:17.12
7,-2,1:17.12
8,-2,1:17.12
4,-8,2:17.12
5,-8,2:17.12
6,-8,2:17.12
7,-8,2:17.12
8,-8,2:17.12
4,-7,2:17.12
8,-7,2:17.12
3,-6,2:17.12
9,-6,2:17.12
3,-5,2:17.12
9,-5,2:17.12
3,-4,2:17.12
4,-4,2:17.12
8,-4,2:17.12
9,-4,2:17.12
4,-3,2:17.12
5,-3,2:17.12
6,-3,2:17.12
7,-3,2:17.12
8,-3,2:17.12
5,-2,2:17.12
6,-2,2:17.12
7,-2,2:17.12
4,-8,3:17.12
5,-8,3:17.12
6,-8,3:17.12
7,-8,3:17.12
8,-8,3:17.12
4,-7,3:17.12
8,-7,3:17.12
3,-6,3:17.12
4,-6,3:17.12
9,-6,3:17.12
3,-5,3:17.12
9,-5,3:17.12
4,-4,3:17.12
8,-4,3:17.12
4,-3,3:17.12
5,-3,3:17.12
6,-3,3:17.12
7,-3,3:17.12
8,-3,3:17.12
4,-8,4:17.12
5,-8,4:17.12
6,-8,4:17.12
7,-8,4:17.12
8,-8,4:17.12
4,-7,4:17.12
8,-7,4:17.12
3,-6,4:17.12
4,-6,4:17.12
8,-6,4:17.12
9,-6,4:17.12
3,-5,4:17.12
9,-5,4:17.12
4,-4,4:17.12
8,-4,4:17.12
4,-3,4:17.12
5,-3,4:17.12
6,-3,4:17.12
7,-3,4:17.12
8,-3,4:17.12
4,-8,5:17.12
5,-8,5:17.12
6,-8,5:17.12
7,-8,5:17.12
8,-8,5:17.12
4,-7,5:17.12
8,-7,5:17.12
3,-6,5:17.12
4,-6,5:17.12
8,-6,5:17.12
9,-6,5:17.12
3,-5,5:17.12
9,-5,5:17.12
4,-4,5:17.12
8,-4,5:17.12
4,-3,5:17.12
5,-3,5:17.12
6,-3,5:17.12
7,-3,5:17.12
8,-3,5:17.12
4,-8,6:17.12
5,-8,6:17.12
6,-8,6:17.12
7,-8,6:17.12
8,-8,6:17.12
4,-7,6:17.12
8,-7,6:17.12
3,-6,6:17.12
4,-6,6:17.12
8,-6,6:17.12
9,-6,6:17.12
3,-5,6:17.12
9,-5,6:17.12
4,-4,6:17.12
8,-4,6:17.12
4,-3,6:17.12
5,-3,6:17.12
6,-3,6:17.12
7,-3,6:17.12
8,-3,6:17.12
4,-8,7:17.12
5,-8,7:17.12
6,-8,7:17.12
7,-8,7:17.12
8,-8,7:17.12
4,-7,7:17.12
8,-7,7:17.12
3,-6,7:17.12
4,-6,7:17.12
8,-6,7:17.12
9,-6,7:17.12
3,-5,7:17.12
8,-5,7:17.12
9,-5,7:17.12
4,-4,7:17.12
8,-4,7:17.12
4,-3,7:17.12
5,-3,7:17.12
6,-3,7:17.12
7,-3,7:17.12
8,-3,7:17.12
-2,5,7:18.14
15,-22,8:18.14
15,-21,8:18.14
16,-21,8:18.14
16,-20,8:18.14
-2,-19,8:18.6
-1,-19,8:18.6
0,-19,8:18.6
1,-19,8:18.6
3,-19,8:18.6
4,-19,8:18.6
9,-19,8:18.6
10,-19,8:18.6
-2,-18,8:18.6
-3,-17,8:18.6
-4,-16,8:18.6
-4,-15,8:18.6
17,-15,8:18.6
-5,-14,8:18.6
-7,-10,8:18.6
4,-8,8:17.12
5,-8,8:17.12
6,-8,8:17.12
7,-8,8:17.12
8,-8,8:17.12
4,-7,8:17.12
8,-7,8:17.12
21,-7,8:18.6
3,-6,8:17.12
4,-6,8:17.12
8,-6,8:17.12
9,-6,8:17.12
22,-6,8:18.6
3,-5,8:17.12
8,-5,8:17.12
9,-5,8:17.12
22,-5,8:18.6
4,-4,8:17.12
8,-4,8:17.12
21,-4,8:18.6
4,-3,8:17.12
5,-3,8:17.12
6,-3,8:17.12
7,-3,8:17.12
8,-3,8:17.12
-7,-1,8:18.6
-3,6,8:18.14
0,8,8:18.14
0,9,8:18.14
15,-23,9:18.14
-2,-20,9:18.6
14,-20,9:18.6
-2,-19,9:18.6
-1,-19,9:18.6
0,-19,9:18.6
1,-19,9:18.6
2,-19,9:18.6
3,-19,9:18.6
4,-19,9:18.6
5,-19,9:18.6
6,-19,9:18.6
8,-19,9:18.6
9,-19,9:18.6
10,-19,9:18.6
11,-19,9:18.6
12,-19,9:18.6
14,-19,9:18.6
16,-19,9:18.14
-2,-18,9:18.6
-3,-17,9:18.6
15,-17,9:18.6
-4,-16,9:18.6
-3,-16,9:18.6
16,-16,9:18.6
-4,-15,9:18.6
16,-15,9:18.6
17,-15,9:18.6
-5,-14,9:18.6
-4,-14,9:18.6
17,-14,9:18.6
-5,-13,9:18.6
-6,-11,9:18.6
19,-11,9:18.6
-7,-10,9:18.6
19,-10,9:18.6
20,-10,9:18.6
-8,-9,9:18.6
-7,-9,9:18.6
20,-9,9:18.6
-8,-8,9:18.6
4,-8,9:17.12
5,-8,9:17.12
6,-8,9:17.12
7,-8,9:17.12
8,-8,9:17.12
20,-8,9:18.6
21,-8,9:18.6
4,-7,9:17.12
8,-7,9:17.12
21,-7,9:18.6
-10,-6,9:18.6
-9,-6,9:18.6
3,-6,9:17.12
9,-6,9:17.12
22,-6,9:18.6
-9,-5,9:18.6
3,-5,9:17.12
9,-5,9:17.12
21,-5,9:18.6
22,-5,9:18.6
4,-4,9:17.12
8,-4,9:17.12
21,-4,9:18.6
-8,-3,9:18.6
4,-3,9:17.12
5,-3,9:17.12
6,-3,9:17.12
7,-3,9:17.12
8,-3,9:17.12
20,-3,9:18.6
21,-3,9:18.6
-7,-2,9:18.6
20,-2,9:18.6
-7,-1,9:18.6
19,-1,9:18.6
-6,0,9:18.6
19,0,9:18.6
-5,2,9:18.6
-5,3,9:18.6
-4,3,9:18.6
17,3,9:18.6
-4,4,9:18.6
16,4,9:18.6
17,4,9:18.6
-3,5,9:18.6
16,5,9:18.6
-3,6,9:18.14
-2,7,9:18.14
-1,8,9:18.14
0,8,9:18.14
1,8,9:18.14
2,8,9:18.14
3,8,9:18.14
4,8,9:18.14
5,8,9:18.6
8,8,9:18.6
9,8,9:18.6
10,8,9:18.6
11,8,9:18.6
14,8,9:18.6
-1,9,9:18.14
-3,-21,10:18.6
15,-21,10:18.6
-2,-20,10:18.6
14,-20,10:18.6
15,-20,10:18.6
-2,-19,10:18.6
-1,-19,10:18.6
0,-19,10:18.6
1,-19,10:18.6
2,-19,10:18.14
3,-19,10:18.14
4,-19,10:18.14
5,-19,10:18.14
6,-19,10:18.14
7,-19,10:18.14
8,-19,10:18.14
9,-19,10:18.14
10,-19,10:18.14
11,-19,10:18.6
12,-19,10:18.6
13,-19,10:18.6
14,-19,10:18.6
-2,-18,10:18.6
-1,-18,10:18.6
0,-18,10:18.6
1,-18,10:18.6
2,-18,10:18.14
3,-18,10:18.14
4,-18,10:18.14
5,-18,10:18.14
6,-18,10:18.14
7,-18,10:18.14
8,-18,10:18.14
9,-18,10:18.14
14,-18,10:18.6
15,-18,10:18.6
-3,-17,10:18.6
-2,-17,10:18.6
-1,-17,10:18.6
15,-17,10:18.6
-3,-16,10:18.6
-2,-16,10:18.6
15,-16,10:18.6
16,-16,10:18.6
-4,-15,10:18.6
-3,-15,10:18.6
16,-15,10:18.6
-5,-14,10:18.6
-4,-14,10:18.6
17,-14,10:18.6
-5,-13,10:18.6
-4,-13,10:18.6
17,-13,10:18.6
18,-13,10:18.6
-6,-12,10:18.6
-5,-12,10:18.6
18,-12,10:18.6
-6,-11,10:18.6
-5,-11,10:18.6
18,-11,10:18.6
19,-11,10:18.6
-7,-10,10:18.6
-6,-10,10:18.6
19,-10,10:18.6
-7,-9,10:18.6
5,-9,10:17.12
6,-9,10:17.12
7,-9,10:17.12
20,-9,10:18.6
-8,-8,10:18.6
-7,-8,10:18.6
4,-8,10:17.12
5,-8,10:17.12
6,-8,10:17.12
7,-8,10:17.12
8,-8,10:17.12
20,-8,10:18.14
21,-8,10:18.14
-8,-7,10:18.6
3,-7,10:17.12
4,-7,10:17.12
8,-7,10:17.12
9,-7,10:17.12
21,-7,10:18.14
-12,-6,10:18.6
-11,-6,10:18.6
-10,-6,10:18.6
-9,-6,10:18.6
3,-6,10:17.12
9,-6,10:17.12
21,-6,10:18.14
22,-6,10:18.14
23,-6,10:18.14
-9,-5,10:18.6
3,-5,10:17.12
9,-5,10:17.12
21,-5,10:18.14
22,-5,10:18.14
-8,-4,10:18.6
3,-4,10:17.12
4,-4,10:17.12
8,-4,10:17.12
9,-4,10:17.12
21,-4,10:18.6
-8,-3,10:18.6
-7,-3,10:18.6
4,-3,10:17.12
5,-3,10:17.12
6,-3,10:17.12
7,-3,10:17.12
8,-3,10:17.12
20,-3,10:18.6
-7,-2,10:18.6
5,-2,10:17.12
6,-2,10:17.12
7,-2,10:17.12
19,-2,10:18.6
20,-2,10:18.6
-7,-1,10:18.6
-6,-1,10:18.6
19,-1,10:18.6
-6,0,10:18.14
18,0,10:18.6
19,0,10:18.6
-5,1,10:18.6
18,1,10:18.6
-5,2,10:18.6
17,2,10:18.6
-4,3,10:18.6
17,3,10:18.6
-4,4,10:18.6
-3,4,10:18.6
16,4,10:18.6
-3,5,10:18.6
15,5,10:18.6
16,5,10:18.6
-3,6,10:18.14
-2,6,10:18.14
15,6,10:18.6
-2,7,10:18.14
14,7,10:18.6
-2,8,10:18.14
-1,8,10:18.14
0,8,10:18.14
1,8,10:18.14
2,8,10:18.14
3,8,10:18.14
4,8,10:18.14
5,8,10:18.6
6,8,10:18.6
7,8,10:18.6
8,8,10:18.6
9,8,10:18.6
10,8,10:18.6
11,8,10:18.6
12,8,10:18.6
13,8,10:18.6
14,8,10:18.6
-2,9,10:18.14
15,9,10:18.6
15,10,10:18.6
17,-25,11:18.6
-4,-24,11:18.6
17,-24,11:18.6
16,-23,11:18.14
-3,-22,11:18.6
15,-22,11:18.14
-3,-21,11:18.6
-2,-21,11:18.6
15,-21,11:18.6
-2,-20,11:18.6
14,-20,11:18.6
15,-20,11:18.6
-2,-19,11:18.6
-1,-19,11:18.6
0,-19,11:18.6
1,-19,11:18.6
2,-19,11:18.14
3,-19,11:18.14
4,-19,11:18.14
5,-19,11:18.14
6,-19,11:18.14
7,-19,11:18.14
8,-19,11:18.14
9,-19,11:18.14
10,-19,11:18.14
11,-19,11:18.6
12,-19,11:18.6
13,-19,11:18.6
14,-19,11:18.6
-2,-18,11:18.6
2,-18,11:18.14
3,-18,11:18.14
4,-18,11:18.14
5,-18,11:18.14
6,-18,11:18.14
7,-18,11:18.14
8,-18,11:18.14
9,-18,11:18.14
10,-18,11:18.14
11,-18,11:18.6
12,-18,11:18.6
13,-18,11:18.6
14,-18,11:18.6
15,-18,11:18.6
-3,-17,11:18.6
-2,-17,11:18.6
-1,-17,11:18.6
0,-17,11:18.6
1,-17,11:18.6
2,-17,11:18.14
3,-17,11:18.14
4,-17,11:18.14
5,-17,11:18.14
6,-17,11:18.14
7,-17,11:18.14
8,-17,11:18.14
9,-17,11:18.14
10,-17,11:18.14
11,-17,11:18.6
12,-17,11:18.6
13,-17,11:18.6
14,-17,11:18.6
15,-17,11:18.6
-3,-16,11:18.6
-2,-16,11:18.6
-1,-16,11:18.6
0,-16,11:18.6
1,-16,11:18.6
2,-16,11:18.14
3,-16,11:18.14
4,-16,11:18.14
5,-16,11:18.14
6,-16,11:18.14
7,-16,11:18.14
8,-16,11:18.14
9,-16,11:18.14
10,-16,11:18.14
11,-16,11:18.6
12,-16,11:18.6
13,-16,11:18.6
14,-16,11:18.6
15,-16,11:18.6
16,-16,11:18.6
-4,-15,11:18.6
-3,-15,11:18.6
-2,-15,11:18.6
-1,-15,11:18.6
0,-15,11:18.6
1,-15,11:18.6
2,-15,11:18.14
3,-15,11:18.14
4,-15,11:18.14
5,-15,11:18.14
6,-15,11:18.14
7,-15,11:18.14
8,-15,11:18.14
9,-15,11:18.14
10,-15,11:18.14
11,-15,11:18.14
12,-15,11:18.14
13,-15,11:18.14
14,-15,11:18.14
15,-15,11:18.14
16,-15,11:18.6
-4,-14,11:18.6
-3,-14,11:18.6
-2,-14,11:18.6
-1,-14,11:18.6
0,-14,11:18.6
1,-14,11:18.14
2,-14,11:18.14
3,-14,11:18.14
4,-14,11:18.14
5,-14,11:18.14
6,-14,11:18.14
7,-14,11:18.14
12,-14,11:18.14
13,-14,11:18.14
14,-14,11:18.14
15,-14,11:18.14
16,-14,11:18.6
17,-14,11:18.6
-5,-13,11:18.6
-4,-13,11:18.6
-3,-13,11:18.6
-2,-13,11:18.6
-1,-13,11:18.6
0,-13,11:18.14
12,-13,11:18.14
13,-13,11:18.14
14,-13,11:18.14
15,-13,11:18.14
17,-13,11:18.6
-6,-12,11:18.6
-5,-12,11:18.6
-4,-12,11:18.6
-3,-12,11:18.6
-2,-12,11:18.6
-1,-12,11:18.14
0,-12,11:18.14
13,-12,11:18.14
14,-12,11:18.14
15,-12,11:18.14
16,-12,11:18.6
17,-12,11:18.6
18,-12,11:18.6
-6,-11,11:18.6
-5,-11,11:18.6
-4,-11,11:18.6
-3,-11,11:18.6
-2,-11,11:18.6
-1,-11,11:18.14
14,-11,11:18.14
15,-11,11:18.14
16,-11,11:18.6
17,-11,11:18.6
18,-11,11:18.6
19,-11,11:18.6
-7,-10,11:18.6
-6,-10,11:18.6
-5,-10,11:18.6
-4,-10,11:18.14
-3,-10,11:18.14
-2,-10,11:18.14
14,-10,11:18.14
15,-10,11:18.14
16,-10,11:18.14
17,-10,11:18.14
18,-10,11:18.14
19,-10,11:18.6
-7,-9,11:18.6
-6,-9,11:18.14
-5,-9,11:18.14
-4,-9,11:18.14
-3,-9,11:18.14
-2,-9,11:18.14
4,-9,11:17.12
5,-9,11:17.12
6,-9,11:17.12
7,-9,11:17.12
8,-9,11:17.12
15,-9,11:18.14
16,-9,11:18.14
17,-9,11:18.14
18,-9,11:18.14
19,-9,11:18.6
20,-9,11:18.6
-8,-8,11:18.6
-7,-8,11:18.6
-6,-8,11:18.14
-5,-8,11:18.14
-4,-8,11:18.14
-3,-8,11:18.14
3,-8,11:17.12
4,-8,11:17.12
8,-8,11:17.12
16,-8,11:18.14
17,-8,11:18.14
18,-8,11:18.14
19,-8,11:18.6
20,-8,11:18.14
-8,-7,11:18.6
-7,-7,11:18.6
-6,-7,11:18.14
-5,-7,11:18.14
-4,-7,11:18.14
3,-7,11:17.12
9,-7,11:17.12
17,-7,11:18.14
18,-7,11:18.14
19,-7,11:18.6
20,-7,11:18.14
-16,-6,11:18.6
-15,-6,11:18.6
-14,-6,11:18.6
-12,-6,11:18.6
-11,-6,11:18.6
-10,-6,11:18.6
-9,-6,11:18.6
-8,-6,11:18.6
-7,-6,11:18.6
-6,-6,11:18.14
-5,-6,11:18.14
-4,-6,11:18.14
2,-6,11:17.12
3,-6,11:17.12
9,-6,11:17.12
10,-6,11:17.12
17,-6,11:18.14
18,-6,11:18.14
19,-6,11:18.6
20,-6,11:18.14
21,-6,11:18.14
-9,-5,11:18.6
-8,-5,11:18.6
-7,-5,11:18.6
-6,-5,11:18.14
-5,-5,11:18.14
-4,-5,11:18.14
2,-5,11:17.12
3,-5,11:17.12
9,-5,11:17.12
10,-5,11:17.12
17,-5,11:18.14
18,-5,11:18.14
19,-5,11:18.6
20,-5,11:18.6
21,-5,11:18.14
-8,-4,11:18.6
-7,-4,11:18.6
-6,-4,11:18.14
-5,-4,11:18.14
-4,-4,11:18.14
3,-4,11:17.12
9,-4,11:17.12
17,-4,11:18.14
18,-4,11:18.14
19,-4,11:18.6
20,-4,11:18.6
21,-4,11:18.6
-8,-3,11:18.6
-7,-3,11:18.6
-6,-3,11:18.14
-5,-3,11:18.14
-4,-3,11:18.14
-3,-3,11:18.14
3,-3,11:17.12
4,-3,11:17.12
8,-3,11:17.12
16,-3,11:18.14
17,-3,11:18.14
19,-3,11:18.6
20,-3,11:18.6
-7,-2,11:18.6
-6,-2,11:18.14
-5,-2,11:18.14
-4,-2,11:18.14
-3,-2,11:18.14
4,-2,11:17.12
5,-2,11:17.12
6,-2,11:17.12
7,-2,11:17.12
8,-2,11:17.12
16,-2,11:18.14
17,-2,11:18.14
18,-2,11:18.14
19,-2,11:18.6
20,-2,11:18.6
-7,-1,11:18.6
-6,-1,11:18.14
-5,-1,11:18.14
-4,-1,11:18.14
-3,-1,11:18.14
-2,-1,11:18.14
15,-1,11:18.14
16,-1,11:18.14
17,-1,11:18.14
18,-1,11:18.14
19,-1,11:18.6
-6,0,11:18.14
-5,0,11:18.6
-4,0,11:18.6
-3,0,11:18.6
-2,0,11:18.6
15,0,11:18.6
16,0,11:18.6
17,0,11:18.6
18,0,11:18.6
-5,1,11:18.6
-4,1,11:18.6
-3,1,11:18.6
-2,1,11:18.6
-1,1,11:18.14
14,1,11:18.6
15,1,11:18.6
17,1,11:18.6
18,1,11:18.6
-5,2,11:18.6
-4,2,11:18.6
-3,2,11:18.6
-2,2,11:18.6
-1,2,11:18.6
14,2,11:18.6
15,2,11:18.6
16,2,11:18.6
17,2,11:18.6
-4,3,11:18.6
-3,3,11:18.6
-2,3,11:18.6
-1,3,11:18.6
0,3,11:18.6
13,3,11:18.6
14,3,11:18.6
15,3,11:18.6
16,3,11:18.6
17,3,11:18.6
-4,4,11:18.6
-3,4,11:18.6
-2,4,11:18.6
-1,4,11:18.6
0,4,11:18.6
1,4,11:18.6
2,4,11:18.6
3,4,11:18.6
13,4,11:18.6
14,4,11:18.6
15,4,11:18.6
16,4,11:18.6
-3,5,11:18.6
-2,5,11:18.6
-1,5,11:18.6
0,5,11:18.6
1,5,11:18.6
2,5,11:18.6
3,5,11:18.6
4,5,11:18.6
5,5,11:18.6
6,5,11:18.6
7,5,11:18.6
8,5,11:18.6
9,5,11:18.6
10,5,11:18.6
11,5,11:18.6
12,5,11:18.6
13,5,11:18.6
14,5,11:18.6
15,5,11:18.6
16,5,11:18.6
-2,6,11:18.14
-1,6,11:18.14
0,6,11:18.6
1,6,11:18.6
2,6,11:18.6
3,6,11:18.6
4,6,11:18.6
5,6,11:18.6
6,6,11:18.6
7,6,11:18.6
8,6,11:18.6
9,6,11:18.6
10,6,11:18.6
11,6,11:18.6
12,6,11:18.6
13,6,11:18.6
14,6,11:18.6
15,6,11:18.6
-2,7,11:18.14
-1,7,11:18.14
0,7,11:18.14
1,7,11:18.14
2,7,11:18.14
3,7,11:18.14
4,7,11:18.6
5,7,11:18.6
6,7,11:18.6
7,7,11:18.6
8,7,11:18.6
9,7,11:18.6
10,7,11:18.6
11,7,11:18.6
12,7,11:18.6
13,7,11:18.6
14,7,11:18.6
-2,8,11:18.14
-1,8,11:18.14
0,8,11:18.14
1,8,11:18.14
2,8,11:18.14
3,8,11:18.14
4,8,11:18.6
5,8,11:18.6
6,8,11:18.6
7,8,11:18.6
8,8,11:18.6
9,8,11:18.6
10,8,11:18.6
11,8,11:18.6
12,8,11:18.6
13,8,11:18.6
14,8,11:18.6
-2,9,11:18.14
15,9,11:18.6
-3,10,11:18.14
15,10,11:18.6
-5,-26,12:18.6
18,-26,12:18.6
-5,-25,12:18.6
17,-25,12:18.6
-4,-24,12:18.6
17,-24,12:18.6
-4,-23,12:18.6
16,-23,12:18.14
-3,-22,12:18.6
15,-22,12:18.14
16,-22,12:18.14
-3,-21,12:18.6
-2,-21,12:18.6
15,-21,12:18.6
-2,-20,12:18.6
14,-20,12:18.6
15,-20,12:18.6
-2,-19,12:18.6
-1,-19,12:18.6
0,-19,12:18.6
1,-19,12:18.6
2,-19,12:18.14
3,-19,12:18.14
4,-19,12:18.14
5,-19,12:18.14
6,-19,12:18.14
7,-19,12:18.14
8,-19,12:18.14
9,-19,12:18.14
10,-19,12:18.14
11,-19,12:18.6
12,-19,12:18.6
13,-19,12:18.6
14,-19,12:18.6
-2,-18,12:18.6
14,-18,12:18.6
-2,-17,12:18.6
15,-17,12:18.6
-3,-16,12:18.6
15,-16,12:18.6
-4,-15,12:18.6
-3,-15,12:18.6
16,-15,12:18.6
-4,-14,12:18.6
2,-14,12:18.14
3,-14,12:18.14
4,-14,12:18.14
5,-14,12:18.14
6,-14,12:18.14
7,-14,12:18.14
8,-14,12:18.14
9,-14,12:18.14
10,-14,12:18.14
11,-14,12:18.14
16,-14,12:18.6
17,-14,12:18.6
-5,-13,12:18.6
-4,-13,12:18.6
1,-13,12:18.14
2,-13,12:18.14
3,-13,12:18.14
4,-13,12:18.14
5,-13,12:18.14
6,-13,12:18.14
7,-13,12:18.14
8,-13,12:18.14
9,-13,12:18.14
10,-13,12:18.14
11,-13,12:18.14
12,-13,12:18.14
17,-13,12:18.6
-5,-12,12:18.6
0,-12,12:18.14
1,-12,12:18.14
2,-12,12:18.14
3,-12,12:18.14
4,-12,12:18.14
5,-12,12:18.14
6,-12,12:18.14
8,-12,12:18.14
9,-12,12:18.14
10,-12,12:18.14
11,-12,12:18.14
12,-12,12:18.14
13,-12,12:18.14
18,-12,12:18.6
-6,-11,12:18.6
-1,-11,12:18.14
0,-11,12:18.14
1,-11,12:18.14
2,-11,12:18.14
3,-11,12:18.14
4,-11,12:18.14
5,-11,12:18.14
6,-11,12:18.14
7,-11,12:18.14
8,-11,12:18.14
9,-11,12:18.14
10,-11,12:18.14
11,-11,12:18.14
12,-11,12:18.14
13,-11,12:18.14
18,-11,12:18.6
-6,-10,12:18.14
-1,-10,12:18.14
0,-10,12:18.14
1,-10,12:18.14
2,-10,12:18.14
3,-10,12:18.14
9,-10,12:18.14
10,-10,12:18.14
11,-10,12:18.14
12,-10,12:18.14
13,-10,12:18.14
14,-10,12:18.14
19,-10,12:18.14
-7,-9,12:18.14
-2,-9,12:18.14
-1,-9,12:18.14
0,-9,12:18.14
1,-9,12:18.14
2,-9,12:18.14
4,-9,12:17.12
5,-9,12:17.12
6,-9,12:17.12
7,-9,12:17.12
8,-9,12:17.12
10,-9,12:18.14
11,-9,12:18.14
12,-9,12:18.14
13,-9,12:18.14
14,-9,12:18.14
15,-9,12:18.14
19,-9,12:18.14
20,-9,12:18.6
-8,-8,12:18.14
-7,-8,12:18.14
-2,-8,12:18.14
-1,-8,12:18.14
0,-8,12:18.14
1,-8,12:18.14
2,-8,12:18.14
3,-8,12:17.12
8,-8,12:17.12
9,-8,12:17.12
11,-8,12:18.14
12,-8,12:18.14
13,-8,12:18.14
14,-8,12:18.14
15,-8,12:18.14
20,-8,12:18.14
-8,-7,12:18.14
-3,-7,12:18.14
-2,-7,12:18.14
-1,-7,12:18.14
0,-7,12:18.14
1,-7,12:18.14
3,-7,12:17.12
9,-7,12:17.12
11,-7,12:18.14
12,-7,12:18.14
13,-7,12:18.14
14,-7,12:18.14
15,-7,12:18.14
16,-7,12:18.14
20,-7,12:18.14
-17,-6,12:18.6
-16,-6,12:18.6
-15,-6,12:18.6
-14,-6,12:18.6
-13,-6,12:18.6
-12,-6,12:18.6
-11,-6,12:18.6
-10,-6,12:18.6
-9,-6,12:18.6
-8,-6,12:18.14
-4,-6,12:18.14
-3,-6,12:18.14
-2,-6,12:18.14
-1,-6,12:18.14
0,-6,12:18.14
2,-6,12:17.12
10,-6,12:17.12
12,-6,12:18.14
13,-6,12:18.14
14,-6,12:18.14
15,-6,12:18.14
16,-6,12:18.14
17,-6,12:18.14
21,-6,12:18.14
25,-6,12:18.14
27,-6,12:18.6
28,-6,12:18.6
29,-6,12:18.6
-9,-5,12:18.6
-8,-5,12:18.14
-4,-5,12:18.14
-3,-5,12:18.14
-2,-5,12:18.14
-1,-5,12:18.14
2,-5,12:17.12
9,-5,12:17.12
10,-5,12:17.12
12,-5,12:18.14
13,-5,12:18.14
14,-5,12:18.14
15,-5,12:18.14
16,-5,12:18.14
17,-5,12:18.14
21,-5,12:18.14
-8,-4,12:18.14
-3,-4,12:18.14
-2,-4,12:18.14
-1,-4,12:18.14
0,-4,12:18.14
3,-4,12:17.12
9,-4,12:17.12
12,-4,12:18.14
13,-4,12:18.14
14,-4,12:18.14
15,-4,12:18.14
16,-4,12:18.14
20,-4,12:18.6
21,-4,12:18.6
-7,-3,12:18.14
-3,-3,12:18.14
-2,-3,12:18.14
-1,-3,12:18.14
0,-3,12:18.14
1,-3,12:18.14
3,-3,12:17.12
4,-3,12:17.12
8,-3,12:17.12
9,-3,12:17.12
11,-3,12:18.14
12,-3,12:18.14
13,-3,12:18.14
14,-3,12:18.14
15,-3,12:18.14
16,-3,12:18.14
20,-3,12:18.6
-7,-2,12:18.14
-2,-2,12:18.14
-1,-2,12:18.14
0,-2,12:18.14
1,-2,12:18.14
2,-2,12:18.14
4,-2,12:17.12
5,-2,12:17.12
6,-2,12:17.12
7,-2,12:17.12
8,-2,12:17.12
11,-2,12:18.14
12,-2,12:18.14
13,-2,12:18.14
14,-2,12:18.14
15,-2,12:18.14
19,-2,12:18.14
-6,-1,12:18.14
-2,-1,12:18.14
-1,-1,12:18.14
0,-1,12:18.14
1,-1,12:18.14
2,-1,12:18.14
10,-1,12:18.14
11,-1,12:18.14
12,-1,12:18.14
13,-1,12:18.14
14,-1,12:18.14
15,-1,12:18.14
18,-1,12:18.14
19,-1,12:18.14
-6,0,12:18.14
-5,0,12:18.6
-1,0,12:18.14
0,0,12:18.14
1,0,12:18.14
2,0,12:18.14
3,0,12:18.14
4,0,12:18.14
5,0,12:18.14
6,0,12:18.14
7,0,12:18.14
8,0,12:18.14
9,0,12:18.14
10,0,12:18.14
11,0,12:18.14
12,0,12:18.14
13,0,12:18.14
14,0,12:18.6
18,0,12:18.6
-7,1,12:18.14
-6,1,12:18.14
-5,1,12:18.6
-1,1,12:18.14
0,1,12:18.14
1,1,12:18.14
2,1,12:18.14
3,1,12:18.14
4,1,12:18.14
5,1,12:18.14
6,1,12:18.14
7,1,12:18.14
8,1,12:18.14
9,1,12:18.14
10,1,12:18.14
11,1,12:18.14
12,1,12:18.14
13,1,12:18.14
14,1,12:18.6
17,1,12:18.6
18,1,12:18.6
-5,2,12:18.6
-4,2,12:18.6
0,2,12:18.14
1,2,12:18.14
2,2,12:18.14
3,2,12:18.14
4,2,12:18.14
5,2,12:18.14
6,2,12:18.14
7,2,12:18.14
8,2,12:18.14
9,2,12:18.14
10,2,12:18.14
11,2,12:18.14
12,2,12:18.14
13,2,12:18.6
17,2,12:18.6
-4,3,12:18.6
0,3,12:18.6
1,3,12:18.6
2,3,12:18.14
3,3,12:18.14
4,3,12:18.14
5,3,12:18.14
6,3,12:18.14
7,3,12:18.14
8,3,12:18.14
9,3,12:18.14
10,3,12:18.14
11,3,12:18.14
12,3,12:18.6
13,3,12:18.6
16,3,12:18.6
17,3,12:18.6
-3,4,12:18.6
1,4,12:18.6
2,4,12:18.14
3,4,12:18.14
4,4,12:18.14
5,4,12:18.14
6,4,12:18.14
7,4,12:18.14
8,4,12:18.14
9,4,12:18.14
10,4,12:18.14
11,4,12:18.14
12,4,12:18.6
16,4,12:18.6
-3,5,12:18.6
15,5,12:18.6
-2,6,12:18.6
14,6,12:18.6
15,6,12:18.6
-2,7,12:18.14
-1,7,12:18.14
0,7,12:18.14
1,7,12:18.14
2,7,12:18.14
3,7,12:18.6
4,7,12:18.6
5,7,12:18.6
6,7,12:18.6
7,7,12:18.6
8,7,12:18.6
9,7,12:18.6
10,7,12:18.6
11,7,12:18.6
12,7,12:18.6
13,7,12:18.6
14,7,12:18.6
-2,8,12:18.14
14,8,12:18.6
-2,9,12:18.14
15,9,12:18.6
-3,10,12:18.6
15,10,12:18.6
16,11,12:18.6
-4,12,12:18.6
16,12,12:18.6
17,12,12:18.6
-5,13,12:18.6
17,13,12:18.6
-5,14,12:18.6
18,14,12:18.6
-5,-26,13:18.6
18,-26,13:18.14
-5,-25,13:18.6
17,-25,13:18.6
-4,-24,13:18.6
17,-24,13:18.6
-4,-23,13:18.6
16,-23,13:18.14
-3,-22,13:18.6
15,-22,13:18.14
16,-22,13:18.14
-3,-21,13:18.6
15,-21,13:18.6
-2,-20,13:18.6
14,-20,13:18.6
15,-20,13:18.6
-2,-19,13:18.6
-1,-19,13:18.6
0,-19,13:18.6
1,-19,13:18.6
2,-19,13:18.14
3,-19,13:18.14
4,-19,13:18.14
5,-19,13:18.14
6,-19,13:18.14
7,-19,13:18.14
8,-19,13:18.14
9,-19,13:18.14
10,-19,13:18.14
11,-19,13:18.6
12,-19,13:18.6
13,-19,13:18.6
14,-19,13:18.6
-2,-18,13:18.6
-1,-18,13:18.6
14,-18,13:18.6
-2,-17,13:18.6
14,-17,13:18.6
15,-17,13:18.6
-3,-16,13:18.6
15,-16,13:18.14
-3,-15,13:18.6
16,-15,13:18.14
-4,-14,13:18.6
16,-14,13:18.14
-5,-13,13:18.6
-4,-13,13:18.6
17,-13,13:18.6
-5,-12,13:18.6
17,-12,13:18.6
18,-12,13:18.6
-6,-11,13:18.6
-5,-11,13:18.6
18,-11,13:18.6
-6,-10,13:18.14
3,-10,13:18.14
4,-10,13:18.14
5,-10,13:18.14
6,-10,13:18.14
7,-10,13:18.14
8,-10,13:18.14
9,-10,13:18.14
18,-10,13:18.14
19,-10,13:18.14
-7,-9,13:18.14
3,-9,13:18.14
4,-9,13:17.12
5,-9,13:17.12
6,-9,13:17.12
7,-9,13:17.12
8,-9,13:17.12
9,-9,13:18.14
10,-9,13:18.14
19,-9,13:18.14
-7,-8,13:18.14
2,-8,13:18.14
3,-8,13:17.12
8,-8,13:17.12
9,-8,13:17.12
10,-8,13:18.14
20,-8,13:18.14
-8,-7,13:18.14
1,-7,13:18.14
2,-7,13:18.14
3,-7,13:17.12
7,-7,13:17.12
9,-7,13:17.12
10,-7,13:18.14
11,-7,13:18.14
20,-7,13:18.14
-17,-6,13:18.6
-16,-6,13:18.6
-15,-6,13:18.6
-14,-6,13:18.6
-13,-6,13:18.6
-12,-6,13:18.6
-11,-6,13:18.14
-10,-6,13:18.14
-9,-6,13:18.14
-8,-6,13:18.14
1,-6,13:18.14
2,-6,13:17.12
10,-6,13:17.12
11,-6,13:18.14
12,-6,13:18.14
21,-6,13:18.14
25,-6,13:18.14
26,-6,13:18.6
27,-6,13:18.6
28,-6,13:18.6
29,-6,13:18.6
-8,-5,13:18.14
1,-5,13:18.14
2,-5,13:17.12
10,-5,13:17.12
11,-5,13:18.14
12,-5,13:18.14
21,-5,13:18.14
-8,-4,13:18.14
2,-4,13:18.14
3,-4,13:17.12
9,-4,13:17.12
11,-4,13:18.14
20,-4,13:18.14
-7,-3,13:18.14
2,-3,13:18.14
3,-3,13:17.12
8,-3,13:17.12
9,-3,13:17.12
10,-3,13:18.14
11,-3,13:18.14
19,-3,13:18.14
20,-3,13:18.14
-7,-2,13:18.14
-6,-2,13:18.14
2,-2,13:18.14
3,-2,13:18.14
4,-2,13:17.12
5,-2,13:17.12
6,-2,13:17.12
7,-2,13:17.12
8,-2,13:17.12
9,-2,13:18.14
10,-2,13:18.14
19,-2,13:18.14
-6,-1,13:18.14
3,-1,13:18.14
4,-1,13:18.14
5,-1,13:18.14
6,-1,13:18.14
7,-1,13:18.14
8,-1,13:18.14
9,-1,13:18.14
10,-1,13:18.14
18,-1,13:18.14
19,-1,13:18.14
-6,0,13:18.14
-5,0,13:18.6
4,0,13:18.14
5,0,13:18.14
6,0,13:18.14
7,0,13:18.14
8,0,13:18.14
9,0,13:18.14
18,0,13:18.6
-6,1,13:18.14
-5,1,13:18.6
17,1,13:18.6
-4,2,13:18.6
17,2,13:18.6
-4,3,13:18.6
16,3,13:18.6
-3,4,13:18.6
15,4,13:18.6
16,4,13:18.6
-3,5,13:18.6
-2,5,13:18.6
15,5,13:18.6
-2,6,13:18.6
14,6,13:18.6
15,6,13:18.6
-2,7,13:18.6
-1,7,13:18.6
0,7,13:18.6
1,7,13:18.6
2,7,13:18.14
3,7,13:18.14
4,7,13:18.14
5,7,13:18.14
6,7,13:18.14
7,7,13:18.14
8,7,13:18.14
9,7,13:18.14
10,7,13:18.14
11,7,13:18.14
12,7,13:18.6
13,7,13:18.6
14,7,13:18.6
-2,8,13:18.6
14,8,13:18.6
-2,9,13:18.6
15,9,13:18.6
-3,10,13:18.6
15,10,13:18.6
-4,11,13:18.6
-3,11,13:18.6
16,11,13:18.6
-4,12,13:18.6
16,12,13:18.6
17,12,13:18.6
-5,13,13:18.6
-4,13,13:18.6
17,13,13:18.6
-5,14,13:18.6
18,14,13:18.6
-6,-27,14:18.14
-5,-26,14:18.14
18,-26,14:18.14
-5,-25,14:18.6
17,-25,14:18.6
-4,-24,14:18.6
17,-24,14:18.6
-4,-23,14:18.6
15,-23,14:18.14
16,-23,14:18.14
-3,-22,14:18.6
15,-22,14:18.14
16,-22,14:18.14
-3,-21,14:18.6
-2,-21,14:18.6
15,-21,14:18.6
-2,-20,14:18.6
14,-20,14:18.6
15,-20,14:18.6
-2,-19,14:18.6
-1,-19,14:18.6
14,-19,14:18.6
-2,-18,14:18.6
-1,-18,14:18.6
0,-18,14:18.6
1,-18,14:18.14
2,-18,14:18.14
3,-18,14:18.14
4,-18,14:18.14
5,-18,14:18.14
6,-18,14:18.14
7,-18,14:18.14
8,-18,14:18.14
9,-18,14:18.14
10,-18,14:18.14
11,-18,14:18.14
12,-18,14:18.14
13,-18,14:18.14
14,-18,14:18.14
-2,-17,14:18.6
6,-17,14:17.12
14,-17,14:18.14
15,-17,14:18.14
-3,-16,14:18.6
-2,-16,14:18.6
15,-16,14:18.14
-3,-15,14:18.6
15,-15,14:18.14
16,-15,14:18.14
-4,-14,14:18.6
16,-14,14:18.14
-4,-13,14:18.6
17,-13,14:18.14
-5,-12,14:18.6
17,-12,14:18.14
-6,-11,14:18.6
-5,-11,14:18.6
18,-11,14:18.6
-6,-10,14:18.14
6,-10,14:17.12
18,-10,14:18.14
19,-10,14:18.14
-7,-9,14:18.14
-6,-9,14:18.14
4,-9,14:17.12
5,-9,14:17.12
6,-9,14:17.12
7,-9,14:17.12
8,-9,14:17.12
9,-9,14:17.12
19,-9,14:18.14
-7,-8,14:18.14
3,-8,14:17.12
4,-8,14:17.12
7,-8,14:17.12
8,-8,14:17.12
9,-8,14:17.12
19,-8,14:18.14
20,-8,14:18.14
-8,-7,14:18.14
3,-7,14:17.12
6,-7,14:17.12
7,-7,14:17.12
8,-7,14:17.12
9,-7,14:17.12
20,-7,14:18.14
-19,-6,14:18.6
-18,-6,14:18.6
-17,-6,14:18.6
-16,-6,14:18.6
-15,-6,14:18.6
-14,-6,14:18.6
-13,-6,14:18.14
-12,-6,14:18.14
-11,-6,14:18.14
-10,-6,14:18.14
-9,-6,14:18.14
-8,-6,14:18.14
2,-6,14:17.12
3,-6,14:17.12
9,-6,14:17.12
10,-6,14:17.12
21,-6,14:18.14
22,-6,14:18.14
23,-6,14:18.14
24,-6,14:18.14
25,-6,14:18.14
26,-6,14:18.6
27,-6,14:18.6
28,-6,14:18.6
29,-6,14:18.6
-8,-5,14:18.14
2,-5,14:17.12
3,-5,14:17.12
9,-5,14:17.12
10,-5,14:17.12
20,-5,14:18.14
21,-5,14:18.14
-8,-4,14:18.14
-7,-4,14:18.14
3,-4,14:17.12
9,-4,14:17.12
20,-4,14:18.14
-7,-3,14:18.14
4,-3,14:17.12
8,-3,14:17.12
19,-3,14:18.14
20,-3,14:18.14
-7,-2,14:18.14
-6,-2,14:18.14
4,-2,14:17.12
5,-2,14:17.12
6,-2,14:17.12
7,-2,14:17.12
8,-2,14:17.12
19,-2,14:18.14
-6,-1,14:18.14
18,-1,14:18.14
-5,0,14:18.6
17,0,14:18.6
18,0,14:18.6
-6,1,14:18.14
-5,1,14:18.6
-4,1,14:18.6
17,1,14:18.6
-4,2,14:18.6
16,2,14:18.6
17,2,14:18.6
-4,3,14:18.6
-3,3,14:18.6
16,3,14:18.6
-3,4,14:18.6
15,4,14:18.6
16,4,14:18.6
-2,5,14:18.6
15,5,14:18.6
-2,6,14:18.6
14,6,14:18.6
-1,7,14:18.6
0,7,14:18.6
1,7,14:18.6
2,7,14:18.14
3,7,14:18.14
4,7,14:18.14
5,7,14:18.14
6,7,14:18.14
7,7,14:18.14
8,7,14:18.14
9,7,14:18.14
10,7,14:18.14
11,7,14:18.14
12,7,14:18.6
13,7,14:18.6
14,7,14:18.6
-2,8,14:18.6
14,8,14:18.6
-2,9,14:18.6
15,9,14:18.6
-3,10,14:18.6
15,10,14:18.6
-4,11,14:18.6
-3,11,14:18.6
16,11,14:18.6
-4,12,14:18.6
16,12,14:18.6
17,12,14:18.6
-5,13,14:18.6
17,13,14:18.6
-5,14,14:18.6
18,14,14:18.6
18,15,14:18.6
19,16,14:18.6
18,-27,15:18.14
-6,-26,15:18.14
-5,-26,15:18.14
18,-26,15:18.14
-5,-25,15:18.6
17,-25,15:18.14
-4,-24,15:18.6
16,-24,15:18.14
17,-24,15:18.14
-4,-23,15:18.6
16,-23,15:18.14
-3,-22,15:18.6
15,-22,15:18.14
16,-22,15:18.14
-3,-21,15:18.6
-2,-21,15:18.6
15,-21,15:18.6
-2,-20,15:18.6
14,-20,15:18.6
15,-20,15:18.6
-2,-19,15:18.6
-1,-19,15:18.6
14,-19,15:18.6
-1,-18,15:18.6
0,-18,15:18.6
1,-18,15:18.14
2,-18,15:18.14
3,-18,15:18.14
4,-18,15:18.14
5,-18,15:18.14
6,-18,15:18.14
7,-18,15:18.14
8,-18,15:18.14
9,-18,15:18.14
10,-18,15:18.14
11,-18,15:18.14
12,-18,15:18.14
13,-18,15:18.14
14,-18,15:18.14
-2,-17,15:18.6
6,-17,15:17.12
14,-17,15:18.14
-3,-16,15:18.6
-2,-16,15:18.6
6,-16,15:17.12
15,-16,15:18.14
-3,-15,15:18.14
6,-15,15:17.12
15,-15,15:18.14
16,-15,15:18.14
-4,-14,15:18.6
-3,-14,15:18.14
6,-14,15:17.12
16,-14,15:18.14
-4,-13,15:18.6
6,-13,15:17.12
17,-13,15:18.14
-5,-12,15:18.6
6,-12,15:17.12
17,-12,15:18.14
-5,-11,15:18.6
6,-11,15:17.12
7,-11,15:17.12
10,-11,15:17.12
11,-11,15:17.12
18,-11,15:18.6
-6,-10,15:18.14
5,-10,15:17.12
6,-10,15:17.12
7,-10,15:17.12
8,-10,15:17.12
9,-10,15:17.12
10,-10,15:17.12
11,-10,15:17.12
18,-10,15:18.14
-7,-9,15:18.14
-6,-9,15:18.14
5,-9,15:17.12
6,-9,15:17.12
7,-9,15:17.12
8,-9,15:17.12
9,-9,15:17.12
10,-9,15:17.12
19,-9,15:18.14
-7,-8,15:18.14
4,-8,15:17.12
5,-8,15:17.12
7,-8,15:17.12
8,-8,15:17.12
9,-8,15:17.12
19,-8,15:18.14
20,-8,15:18.14
-8,-7,15:18.14
-7,-7,15:18.14
3,-7,15:17.12
4,-7,15:17.12
8,-7,15:17.12
9,-7,15:17.12
20,-7,15:18.14
22,-7,15:18.14
-19,-6,15:18.14
-18,-6,15:18.14
-17,-6,15:18.14
-16,-6,15:18.14
-15,-6,15:18.14
-14,-6,15:18.14
-13,-6,15:18.14
-12,-6,15:18.14
-11,-6,15:18.14
-10,-6,15:18.14
-9,-6,15:18.14
-8,-6,15:18.14
0,-6,15:17.12
1,-6,15:17.12
2,-6,15:17.12
3,-6,15:17.12
9,-6,15:17.12
10,-6,15:17.12
11,-6,15:17.12
12,-6,15:17.12
13,-6,15:17.12
14,-6,15:17.12
20,-6,15:18.14
21,-6,15:18.14
22,-6,15:18.14
23,-6,15:18.14
24,-6,15:18.6
25,-6,15:18.6
26,-6,15:18.6
27,-6,15:18.6
28,-6,15:18.6
29,-6,15:18.6
30,-6,15:18.6
31,-6,15:18.6
-8,-5,15:18.14
-2,-5,15:17.12
-1,-5,15:17.12
0,-5,15:17.12
1,-5,15:17.12
2,-5,15:17.12
3,-5,15:17.12
4,-5,15:17.12
8,-5,15:17.12
9,-5,15:17.12
10,-5,15:17.12
11,-5,15:17.12
12,-5,15:17.12
13,-5,15:17.12
14,-5,15:17.12
20,-5,15:18.14
-7,-4,15:18.14
4,-4,15:17.12
7,-4,15:17.12
8,-4,15:17.12
9,-4,15:17.12
20,-4,15:18.14
-7,-3,15:18.14
4,-3,15:17.12
5,-3,15:17.12
6,-3,15:17.12
7,-3,15:17.12
8,-3,15:17.12
19,-3,15:18.14
-6,-2,15:18.14
6,-2,15:17.12
7,-2,15:17.12
18,-2,15:18.14
19,-2,15:18.14
-6,-1,15:18.14
-5,-1,15:18.14
6,-1,15:17.12
18,-1,15:18.14
-5,0,15:18.6
17,0,15:18.6
18,0,15:18.6
-6,1,15:18.14
-5,1,15:18.6
-4,1,15:18.6
17,1,15:18.6
-4,2,15:18.6
16,2,15:18.6
-3,3,15:18.6
16,3,15:18.6
-3,4,15:18.6
15,4,15:18.6
-2,5,15:18.6
14,5,15:18.6
15,5,15:18.6
-2,6,15:18.6
-1,6,15:18.6
14,6,15:18.6
-1,7,15:18.6
0,7,15:18.6
1,7,15:18.6
2,7,15:18.14
3,7,15:18.14
4,7,15:18.14
5,7,15:18.14
6,7,15:18.14
7,7,15:18.14
8,7,15:18.14
9,7,15:18.14
10,7,15:18.14
11,7,15:18.14
12,7,15:18.6
13,7,15:18.6
14,7,15:18.6
-2,8,15:18.6
14,8,15:18.6
-3,9,15:18.6
-2,9,15:18.6
15,9,15:18.6
-3,10,15:18.6
15,10,15:18.6
16,10,15:18.6
-4,11,15:18.6
-3,11,15:18.6
16,11,15:18.6
-4,12,15:18.6
16,12,15:18.6
17,12,15:18.6
-5,13,15:18.6
17,13,15:18.6
-5,14,15:18.6
18,14,15:18.6
-6,15,15:18.6
18,15,15:18.6
-6,16,15:18.6
19,16,15:18.6
18,-27,16:18.14
-6,-26,16:18.14
-5,-26,16:18.14
18,-26,16:18.6
-5,-25,16:18.6
17,-25,16:18.14
-4,-24,16:18.6
17,-24,16:18.14
-4,-23,16:18.6
16,-23,16:18.14
-3,-22,16:18.6
15,-22,16:18.14
16,-22,16:18.14
-3,-21,16:18.6
-2,-21,16:18.6
15,-21,16:18.6
-2,-20,16:18.6
14,-20,16:18.6
15,-20,16:18.6
-2,-19,16:18.6
-1,-19,16:18.6
14,-19,16:18.6
-1,-18,16:18.6
0,-18,16:18.6
1,-18,16:18.14
2,-18,16:18.14
3,-18,16:18.14
4,-18,16:18.14
5,-18,16:18.14
6,-18,16:18.14
7,-18,16:18.14
8,-18,16:18.14
9,-18,16:18.14
10,-18,16:18.14
11,-18,16:18.14
12,-18,16:18.14
13,-18,16:18.14
14,-18,16:18.14
-2,-17,16:18.6
-1,-17,16:18.6
14,-17,16:18.14
-2,-16,16:18.6
14,-16,16:18.14
15,-16,16:18.14
-3,-15,16:18.14
6,-15,16:17.12
15,-15,16:18.14
-4,-14,16:18.6
-3,-14,16:18.14
5,-14,16:17.12
6,-14,16:17.12
7,-14,16:17.12
16,-14,16:18.14
-4,-13,16:18.6
5,-13,16:17.12
6,-13,16:17.12
7,-13,16:17.12
17,-13,16:18.14
-5,-12,16:18.6
-4,-12,16:18.6
5,-12,16:17.12
6,-12,16:17.12
7,-12,16:17.12
17,-12,16:18.14
-5,-11,16:18.6
5,-11,16:17.12
6,-11,16:17.12
7,-11,16:17.12
10,-11,16:17.12
11,-11,16:17.12
17,-11,16:18.14
18,-11,16:18.6
-6,-10,16:18.14
5,-10,16:17.12
6,-10,16:17.12
7,-10,16:17.12
9,-10,16:17.12
10,-10,16:17.12
11,-10,16:17.12
18,-10,16:18.14
-6,-9,16:18.14
4,-9,16:17.12
5,-9,16:17.12
6,-9,16:17.12
7,-9,16:17.12
10,-9,16:17.12
18,-9,16:18.14
19,-9,16:18.14
-7,-8,16:18.14
3,-8,16:17.12
4,-8,16:17.12
5,-8,16:17.12
6,-8,16:17.12
7,-8,16:17.12
8,-8,16:17.12
19,-8,16:18.14
-8,-7,16:18.14
-7,-7,16:18.14
3,-7,16:17.12
4,-7,16:17.12
5,-7,16:17.12
7,-7,16:17.12
8,-7,16:17.12
12,-7,16:17.12
20,-7,16:18.14
22,-7,16:18.14
-19,-6,16:18.14
-18,-6,16:18.14
-17,-6,16:18.14
-16,-6,16:18.14
-15,-6,16:18.14
-14,-6,16:18.14
-13,-6,16:18.14
-12,-6,16:18.14
-11,-6,16:18.14
-10,-6,16:18.14
-9,-6,16:18.14
-8,-6,16:18.14
-4,-6,16:17.12
-3,-6,16:17.12
-2,-6,16:17.12
-1,-6,16:17.12
0,-6,16:17.12
1,-6,16:17.12
2,-6,16:17.12
3,-6,16:17.12
4,-6,16:17.12
8,-6,16:17.12
10,-6,16:17.12
11,-6,16:17.12
12,-6,16:17.12
13,-6,16:17.12
14,-6,16:17.12
15,-6,16:17.12
20,-6,16:18.14
21,-6,16:18.14
22,-6,16:18.14
23,-6,16:18.14
24,-6,16:18.6
25,-6,16:18.6
26,-6,16:18.6
27,-6,16:18.6
28,-6,16:18.6
29,-6,16:18.6
30,-6,16:18.6
-8,-5,16:18.14
-4,-5,16:17.12
-3,-5,16:17.12
-2,-5,16:17.12
-1,-5,16:17.12
0,-5,16:17.12
1,-5,16:17.12
2,-5,16:17.12
3,-5,16:17.12
4,-5,16:17.12
5,-5,16:17.12
7,-5,16:17.12
8,-5,16:17.12
9,-5,16:17.12
10,-5,16:17.12
11,-5,16:17.12
12,-5,16:17.12
13,-5,16:17.12
14,-5,16:17.12
15,-5,16:17.12
20,-5,16:18.14
-7,-4,16:18.14
4,-4,16:17.12
5,-4,16:17.12
6,-4,16:17.12
7,-4,16:17.12
8,-4,16:17.12
9,-4,16:17.12
19,-4,16:18.14
20,-4,16:18.14
-7,-3,16:18.14
-6,-3,16:18.14
5,-3,16:17.12
6,-3,16:17.12
7,-3,16:17.12
8,-3,16:17.12
19,-3,16:18.14
-6,-2,16:18.14
5,-2,16:17.12
6,-2,16:17.12
7,-2,16:17.12
18,-2,16:18.14
19,-2,16:18.14
-6,-1,16:18.14
-5,-1,16:18.14
6,-1,16:17.12
7,-1,16:17.12
18,-1,16:18.14
-5,0,16:18.6
6,0,16:17.12
7,0,16:17.12
17,0,16:18.6
-4,1,16:18.6
6,1,16:17.12
7,1,16:17.12
17,1,16:18.6
-4,2,16:18.6
16,2,16:18.6
-3,3,16:18.6
15,3,16:18.6
16,3,16:18.6
-3,4,16:18.6
-2,4,16:18.6
15,4,16:18.6
-2,5,16:18.6
14,5,16:18.6
15,5,16:18.6
-2,6,16:18.6
-1,6,16:18.6
14,6,16:18.6
-1,7,16:18.6
0,7,16:18.6
1,7,16:18.6
2,7,16:18.14
3,7,16:18.14
4,7,16:18.14
5,7,16:18.14
6,7,16:18.14
7,7,16:18.14
8,7,16:18.14
9,7,16:18.14
10,7,16:18.14
11,7,16:18.14
12,7,16:18.6
13,7,16:18.6
14,7,16:18.6
-2,8,16:18.6
14,8,16:18.6
-3,9,16:18.6
-2,9,16:18.6
15,9,16:18.6
-3,10,16:18.6
15,10,16:18.6
16,10,16:18.6
-4,11,16:18.6
-3,11,16:18.6
16,11,16:18.6
-4,12,16:18.6
16,12,16:18.6
17,12,16:18.6
-5,13,16:18.6
17,13,16:18.6
-5,14,16:18.6
18,14,16:18.6
-6,15,16:18.6
18,15,16:18.6
19,16,16:18.6
-5,-26,17:18.14
-5,-25,17:18.6
-4,-24,17:18.6
17,-24,17:18.14
-4,-23,17:18.6
16,-23,17:18.14
-3,-22,17:18.6
15,-22,17:18.14
16,-22,17:18.14
-3,-21,17:18.6
-2,-21,17:18.6
15,-21,17:18.6
-2,-20,17:18.6
14,-20,17:18.6
15,-20,17:18.6
-2,-19,17:18.6
-1,-19,17:18.6
14,-19,17:18.6
-1,-18,17:18.6
0,-18,17:18.6
1,-18,17:18.14
2,-18,17:18.14
3,-18,17:18.14
4,-18,17:18.14
5,-18,17:18.14
6,-18,17:18.14
7,-18,17:18.14
8,-18,17:18.14
9,-18,17:18.14
10,-18,17:18.14
11,-18,17:18.14
12,-18,17:18.14
13,-18,17:18.14
-2,-17,17:18.6
-1,-17,17:18.6
14,-17,17:18.14
-2,-16,17:18.6
14,-16,17:18.14
15,-16,17:18.14
-3,-15,17:18.14
-2,-15,17:18.14
6,-15,17:17.12
15,-15,17:18.14
-3,-14,17:18.14
6,-14,17:17.12
7,-14,17:17.12
15,-14,17:18.14
16,-14,17:18.14
-4,-13,17:18.6
-4,-12,17:18.6
10,-12,17:17.12
11,-12,17:17.12
12,-12,17:17.12
17,-12,17:18.14
-5,-11,17:18.6
10,-11,17:17.12
11,-11,17:17.12
12,-11,17:17.12
17,-11,17:18.14
-6,-10,17:18.14
-5,-10,17:18.14
3,-10,17:17.12
11,-10,17:17.12
18,-10,17:18.14
-6,-9,17:18.14
2,-9,17:17.12
3,-9,17:17.12
4,-9,17:17.12
18,-9,17:18.14
19,-9,17:18.14
-7,-8,17:18.14
-6,-8,17:18.14
2,-8,17:17.12
3,-8,17:17.12
4,-8,17:17.12
5,-8,17:17.12
19,-8,17:18.14
-7,-7,17:18.14
4,-7,17:17.12
5,-7,17:17.12
6,-7,17:17.12
7,-7,17:17.12
19,-7,17:18.14
20,-7,17:18.14
22,-7,17:18.14
-15,-6,17:18.14
-14,-6,17:18.14
-13,-6,17:18.14
-12,-6,17:18.14
-11,-6,17:18.14
-10,-6,17:18.14
-9,-6,17:18.14
-8,-6,17:18.14
-7,-6,17:17.12
-6,-6,17:17.12
-5,-6,17:17.12
-4,-6,17:17.12
-1,-6,17:17.12
5,-6,17:17.12
6,-6,17:17.12
7,-6,17:17.12
14,-6,17:17.12
15,-6,17:17.12
16,-6,17:17.12
17,-6,17:17.12
18,-6,17:17.12
20,-6,17:18.14
21,-6,17:18.14
22,-6,17:18.14
23,-6,17:18.14
24,-6,17:18.6
25,-6,17:18.6
26,-6,17:18.6
27,-6,17:18.6
28,-6,17:18.6
29,-6,17:18.6
30,-6,17:18.6
-8,-5,17:18.14
-7,-5,17:17.12
-6,-5,17:17.12
-5,-5,17:17.12
-4,-5,17:17.12
-2,-5,17:17.12
-1,-5,17:17.12
5,-5,17:17.12
6,-5,17:17.12
7,-5,17:17.12
14,-5,17:17.12
15,-5,17:17.12
16,-5,17:17.12
17,-5,17:17.12
20,-5,17:18.14
-7,-4,17:18.14
6,-4,17:17.12
7,-4,17:17.12
8,-4,17:17.12
9,-4,17:17.12
10,-4,17:17.12
19,-4,17:18.14
20,-4,17:18.14
-7,-3,17:18.14
-6,-3,17:18.14
8,-3,17:17.12
9,-3,17:17.12
10,-3,17:17.12
19,-3,17:18.14
-6,-2,17:18.14
9,-2,17:17.12
18,-2,17:18.14
-5,-1,17:18.14
17,-1,17:18.14
18,-1,17:18.14
-5,0,17:18.6
-4,0,17:18.6
6,0,17:17.12
7,0,17:17.12
17,0,17:18.6
-4,1,17:18.6
6,1,17:17.12
7,1,17:17.12
17,1,17:18.6
-4,2,17:18.6
-3,2,17:18.6
6,2,17:17.12
7,2,17:17.12
16,2,17:18.14
-3,3,17:18.6
6,3,17:17.12
7,3,17:17.12
15,3,17:18.14
-3,4,17:18.6
-2,4,17:18.6
15,4,17:18.14
-2,5,17:18.6
14,5,17:18.6
-1,6,17:18.6
0,6,17:18.6
1,6,17:18.6
2,6,17:18.14
3,6,17:18.14
4,6,17:18.14
5,6,17:18.14
6,6,17:18.14
7,6,17:18.14
8,6,17:18.14
9,6,17:18.14
10,6,17:18.14
11,6,17:18.14
12,6,17:18.6
13,6,17:18.6
14,6,17:18.6
-1,7,17:18.6
0,7,17:18.6
1,7,17:18.6
2,7,17:18.14
3,7,17:18.14
4,7,17:18.14
5,7,17:18.14
6,7,17:18.14
7,7,17:18.14
8,7,17:18.14
9,7,17:18.14
10,7,17:18.14
11,7,17:18.14
12,7,17:18.6
13,7,17:18.6
14,7,17:18.6
-2,8,17:18.6
14,8,17:18.6
-3,9,17:18.6
-2,9,17:18.6
15,9,17:18.6
-3,10,17:18.6
15,10,17:18.6
16,10,17:18.6
-4,11,17:18.6
-3,11,17:18.6
16,11,17:18.6
-4,12,17:18.6
16,12,17:18.6
17,12,17:18.6
-5,13,17:18.6
17,13,17:18.6
-6,14,17:18.6
-5,14,17:18.6
18,14,17:18.6
-6,15,17:18.6
18,15,17:18.6
19,16,17:18.6
17,-25,18:18.14
-4,-24,18:18.6
17,-24,18:18.6
-4,-23,18:18.6
16,-23,18:18.6
-3,-22,18:18.6
15,-22,18:18.14
16,-22,18:18.6
-3,-21,18:18.6
-2,-21,18:18.6
15,-21,18:18.6
-2,-20,18:18.6
14,-20,18:18.6
-2,-19,18:18.6
-1,-19,18:18.6
14,-19,18:18.14
-1,-18,18:18.6
0,-18,18:18.6
1,-18,18:18.14
2,-18,18:18.14
3,-18,18:18.14
4,-18,18:18.14
5,-18,18:18.14
6,-18,18:18.14
7,-18,18:18.14
8,-18,18:18.14
9,-18,18:18.14
10,-18,18:18.14
11,-18,18:18.14
12,-18,18:18.14
13,-18,18:18.14
-1,-17,18:18.14
13,-17,18:18.14
14,-17,18:18.14
-2,-16,18:18.14
6,-16,18:17.12
14,-16,18:18.14
-3,-15,18:18.14
-2,-15,18:18.14
6,-15,18:17.12
7,-15,18:17.12
15,-15,18:18.14
-3,-14,18:18.14
13,-14,18:17.12
15,-14,18:18.14
16,-14,18:18.14
-4,-13,18:18.14
-3,-13,18:18.14
11,-13,18:17.12
12,-13,18:17.12
13,-13,18:17.12
-4,-12,18:18.14
11,-12,18:17.12
12,-12,18:17.12
16,-12,18:18.14
17,-12,18:18.14
-5,-11,18:18.14
2,-11,18:17.12
11,-11,18:17.12
12,-11,18:17.12
17,-11,18:18.14
-5,-10,18:18.14
1,-10,18:17.12
2,-10,18:17.12
3,-10,18:17.12
18,-10,18:18.14
-6,-9,18:18.14
1,-9,18:17.12
2,-9,18:17.12
3,-9,18:17.12
4,-9,18:17.12
18,-9,18:18.14
-7,-8,18:18.14
-6,-8,18:18.14
3,-8,18:17.12
4,-8,18:17.12
19,-8,18:18.14
-7,-7,18:18.14
5,-7,18:17.12
6,-7,18:17.12
19,-7,18:18.14
20,-7,18:18.14
22,-7,18:18.14
-17,-6,18:18.14
-16,-6,18:18.14
-15,-6,18:18.14
-14,-6,18:18.14
-13,-6,18:18.14
-12,-6,18:18.14
-11,-6,18:18.14
-10,-6,18:18.14
-9,-6,18:18.14
-8,-6,18:18.14
-7,-6,18:18.14
-2,-6,18:17.12
-1,-6,18:17.12
5,-6,18:17.12
6,-6,18:17.12
7,-6,18:17.12
15,-6,18:17.12
16,-6,18:17.12
17,-6,18:17.12
18,-6,18:17.12
19,-6,18:17.12
20,-6,18:18.14
21,-6,18:18.14
22,-6,18:18.14
23,-6,18:18.14
24,-6,18:18.6
25,-6,18:18.6
26,-6,18:18.6
27,-6,18:18.6
28,-6,18:18.6
-9,-5,18:17.12
-8,-5,18:17.12
-7,-5,18:18.14
-2,-5,18:17.12
-1,-5,18:17.12
5,-5,18:17.12
6,-5,18:17.12
7,-5,18:17.12
15,-5,18:17.12
16,-5,18:17.12
17,-5,18:17.12
18,-5,18:17.12
20,-5,18:18.14
-7,-4,18:18.14
8,-4,18:17.12
9,-4,18:17.12
19,-4,18:18.14
-6,-3,18:18.14
9,-3,18:17.12
10,-3,18:17.12
11,-3,18:17.12
19,-3,18:18.14
-6,-2,18:18.14
-5,-2,18:18.14
9,-2,18:17.12
10,-2,18:17.12
18,-2,18:18.14
-5,-1,18:18.14
17,-1,18:18.14
18,-1,18:18.14
-5,0,18:18.6
-4,0,18:18.6
17,0,18:18.14
-4,1,18:18.6
6,1,18:17.12
7,1,18:17.12
-3,2,18:18.14
16,2,18:18.14
-3,3,18:18.14
6,3,18:17.12
7,3,18:17.12
15,3,18:18.14
-2,4,18:18.14
6,4,18:17.12
7,4,18:17.12
14,4,18:18.14
15,4,18:18.14
-2,5,18:18.6
-1,5,18:18.6
14,5,18:18.6
-1,6,18:18.6
0,6,18:18.6
1,6,18:18.6
2,6,18:18.14
3,6,18:18.14
4,6,18:18.14
5,6,18:18.14
6,6,18:18.14
7,6,18:18.14
8,6,18:18.14
9,6,18:18.14
10,6,18:18.14
11,6,18:18.14
12,6,18:18.6
13,6,18:18.6
14,6,18:18.6
-1,7,18:18.6
13,7,18:18.6
14,7,18:18.6
-2,8,18:18.6
14,8,18:18.6
-3,9,18:18.6
-2,9,18:18.6
15,9,18:18.6
-3,10,18:18.6
15,10,18:18.6
16,10,18:18.6
-4,11,18:18.6
-3,11,18:18.6
16,11,18:18.6
-4,12,18:18.6
16,12,18:18.6
17,12,18:18.6
-5,13,18:18.6
17,13,18:18.6
-5,14,18:18.6
18,14,18:18.6
-5,-25,19:18.6
17,-25,19:18.14
-4,-24,19:18.6
16,-24,19:18.6
17,-24,19:18.6
-4,-23,19:18.6
16,-23,19:18.6
-3,-22,19:18.6
15,-22,19:18.14
16,-22,19:18.6
-3,-21,19:18.6
-2,-21,19:18.6
15,-21,19:18.6
-2,-20,19:18.6
14,-20,19:18.14
-2,-19,19:18.6
-1,-19,19:18.6
14,-19,19:18.14
-1,-18,19:18.6
0,-18,19:18.6
1,-18,19:18.14
2,-18,19:18.14
3,-18,19:18.14
4,-18,19:18.14
5,-18,19:18.14
6,-18,19:18.14
7,-18,19:18.14
8,-18,19:18.14
9,-18,19:18.14
10,-18,19:18.14
11,-18,19:18.14
12,-18,19:18.14
13,-18,19:18.14
-1,-17,19:18.14
6,-17,19:17.12
13,-17,19:18.14
14,-17,19:18.14
-2,-16,19:18.14
6,-16,19:17.12
14,-16,19:18.14
-2,-15,19:18.14
14,-15,19:18.14
15,-15,19:18.14
-3,-14,19:18.14
12,-14,19:17.12
13,-14,19:17.12
15,-14,19:18.14
-4,-13,19:18.14
-3,-13,19:18.14
13,-13,19:17.12
-4,-12,19:18.14
16,-12,19:18.14
17,-12,19:18.14
-5,-11,19:18.14
-4,-11,19:18.14
1,-11,19:17.12
2,-11,19:17.12
17,-11,19:18.14
-5,-10,19:18.14
1,-10,19:17.12
2,-10,19:17.12
17,-10,19:18.14
18,-10,19:18.14
-6,-9,19:18.14
2,-9,19:17.12
3,-9,19:17.12
18,-9,19:18.14
-6,-8,19:18.14
19,-8,19:18.14
-7,-7,19:18.14
6,-7,19:17.12
19,-7,19:18.14
22,-7,19:18.14
-16,-6,19:18.14
-15,-6,19:18.14
-14,-6,19:18.14
-13,-6,19:18.14
-12,-6,19:18.14
-11,-6,19:18.14
-10,-6,19:18.14
-9,-6,19:18.14
-8,-6,19:18.14
-7,-6,19:18.14
-1,-6,19:17.12
5,-6,19:17.12
6,-6,19:17.12
7,-6,19:17.12
18,-6,19:17.12
19,-6,19:17.12
20,-6,19:18.14
21,-6,19:18.14
22,-6,19:18.14
23,-6,19:18.14
24,-6,19:18.14
25,-6,19:18.6
26,-6,19:18.6
27,-6,19:18.6
28,-6,19:18.6
29,-6,19:18.6
-19,-5,19:17.12
-10,-5,19:17.12
-9,-5,19:17.12
-7,-5,19:18.14
-2,-5,19:17.12
-1,-5,19:17.12
4,-5,19:17.12
5,-5,19:17.12
6,-5,19:17.12
18,-5,19:17.12
19,-5,19:18.14
20,-5,19:18.14
-7,-4,19:18.14
-6,-4,19:18.14
3,-4,19:17.12
4,-4,19:17.12
5,-4,19:17.12
19,-4,19:18.14
-6,-3,19:18.14
3,-3,19:17.12
4,-3,19:17.12
10,-3,19:17.12
11,-3,19:17.12
19,-3,19:18.14
-6,-2,19:18.14
-5,-2,19:18.14
10,-2,19:17.12
11,-2,19:17.12
18,-2,19:18.14
-5,-1,19:18.14
17,-1,19:18.14
-4,0,19:18.14
16,0,19:18.14
17,0,19:18.14
-4,1,19:18.14
6,1,19:17.12
7,1,19:17.12
-3,2,19:18.14
15,2,19:18.14
16,2,19:18.14
-3,3,19:18.14
-2,3,19:18.14
15,3,19:18.14
-2,4,19:18.14
6,4,19:17.12
7,4,19:17.12
14,4,19:18.14
-2,5,19:18.6
-1,5,19:18.6
6,5,19:17.12
7,5,19:17.12
14,5,19:18.6
-1,6,19:18.6
0,6,19:18.6
1,6,19:18.6
2,6,19:18.14
3,6,19:18.14
4,6,19:18.14
5,6,19:18.14
6,6,19:17.12
7,6,19:18.14
8,6,19:18.14
9,6,19:18.14
10,6,19:18.14
11,6,19:18.14
12,6,19:18.6
13,6,19:18.6
-1,7,19:18.6
6,7,19:17.12
13,7,19:18.6
14,7,19:18.6
-2,8,19:18.6
14,8,19:18.6
-3,9,19:18.6
-2,9,19:18.6
15,9,19:18.6
-3,10,19:18.6
15,10,19:18.6
16,10,19:18.6
-4,11,19:18.6
-3,11,19:18.6
16,11,19:18.6
-4,12,19:18.6
16,12,19:18.6
17,12,19:18.6
-5,13,19:18.6
17,13,19:18.6
-5,14,19:18.6
18,14,19:18.6
-5,-26,20:18.6
-5,-25,20:18.6
17,-25,20:18.14
-4,-24,20:18.6
16,-24,20:18.6
17,-24,20:18.6
-4,-23,20:18.6
16,-23,20:18.6
-3,-22,20:18.6
15,-22,20:18.6
16,-22,20:18.6
-3,-21,20:18.6
-2,-21,20:18.6
15,-21,20:18.6
-2,-20,20:18.6
14,-20,20:18.14
-2,-19,20:18.6
-1,-19,20:18.6
6,-19,20:17.12
14,-19,20:18.14
-1,-18,20:18.6
0,-18,20:18.6
1,-18,20:18.14
2,-18,20:18.14
3,-18,20:18.14
4,-18,20:18.14
5,-18,20:18.14
6,-18,20:17.12
7,-18,20:18.14
8,-18,20:18.14
9,-18,20:18.14
10,-18,20:18.14
11,-18,20:18.14
12,-18,20:18.14
13,-18,20:18.14
-1,-17,20:18.14
6,-17,20:17.12
13,-17,20:18.14
-2,-16,20:18.14
-1,-16,20:18.14
6,-16,20:17.12
14,-16,20:18.14
-2,-15,20:18.14
14,-15,20:18.14
15,-15,20:18.14
-3,-14,20:18.14
13,-14,20:17.12
15,-14,20:18.14
-3,-13,20:18.14
15,-13,20:18.14
-4,-12,20:18.14
16,-12,20:18.14
-5,-11,20:18.14
-4,-11,20:18.14
1,-11,20:17.12
2,-11,20:17.12
17,-11,20:18.14
-5,-10,20:18.14
1,-10,20:17.12
2,-10,20:17.12
17,-10,20:18.14
18,-10,20:18.14
-6,-9,20:18.14
-5,-9,20:18.14
18,-9,20:18.14
-6,-8,20:18.14
18,-8,20:18.14
19,-8,20:18.14
-7,-7,20:18.14
19,-7,20:18.14
22,-7,20:18.14
-18,-6,20:17.12
-17,-6,20:18.14
-16,-6,20:18.14
-15,-6,20:18.14
-14,-6,20:18.14
-13,-6,20:18.14
-12,-6,20:18.14
-11,-6,20:18.14
-10,-6,20:18.14
-9,-6,20:18.14
-8,-6,20:18.14
-7,-6,20:18.14
-2,-6,20:17.12
-1,-6,20:17.12
5,-6,20:17.12
6,-6,20:17.12
7,-6,20:17.12
19,-6,20:17.12
20,-6,20:18.14
21,-6,20:18.14
22,-6,20:18.14
23,-6,20:18.14
24,-6,20:18.14
25,-6,20:18.6
26,-6,20:18.6
27,-6,20:18.6
28,-6,20:18.6
-7,-5,20:18.14
-3,-5,20:17.12
-2,-5,20:17.12
-1,-5,20:17.12
4,-5,20:17.12
5,-5,20:17.12
6,-5,20:17.12
7,-5,20:17.12
19,-5,20:18.14
-7,-4,20:18.14
-6,-4,20:18.14
3,-4,20:17.12
4,-4,20:17.12
5,-4,20:17.12
19,-4,20:18.14
-6,-3,20:18.14
2,-3,20:17.12
3,-3,20:17.12
4,-3,20:17.12
10,-3,20:17.12
11,-3,20:17.12
-5,-2,20:18.14
3,-2,20:17.12
10,-2,20:17.12
11,-2,20:17.12
17,-2,20:18.14
18,-2,20:18.14
-5,-1,20:18.14
-4,-1,20:18.14
17,-1,20:18.14
-4,0,20:18.14
6,0,20:17.12
7,0,20:17.12
16,0,20:18.14
17,0,20:18.14
-4,1,20:18.14
-3,1,20:18.14
6,1,20:17.12
7,1,20:17.12
-3,2,20:18.14
15,2,20:18.14
-3,3,20:18.14
-2,3,20:18.14
15,3,20:18.14
-2,4,20:18.14
14,4,20:18.14
-1,5,20:18.6
13,5,20:18.14
14,5,20:18.14
-1,6,20:18.6
0,6,20:18.6
1,6,20:18.6
2,6,20:18.14
3,6,20:18.14
4,6,20:18.14
5,6,20:18.14
6,6,20:18.14
7,6,20:18.14
8,6,20:18.14
9,6,20:18.14
10,6,20:18.14
11,6,20:18.14
12,6,20:18.6
13,6,20:18.6
-1,7,20:18.6
6,7,20:17.12
7,7,20:17.12
13,7,20:18.6
14,7,20:18.6
-2,8,20:18.6
14,8,20:18.6
-3,9,20:18.6
-2,9,20:18.6
15,9,20:18.6
-3,10,20:18.6
15,10,20:18.6
16,10,20:18.6
-4,11,20:18.6
-3,11,20:18.6
16,11,20:18.6
-4,12,20:18.6
16,12,20:18.6
17,12,20:18.6
-5,13,20:18.6
17,13,20:18.6
-5,-26,21:18.6
-5,-25,21:18.6
17,-25,21:18.14
-4,-24,21:18.6
-4,-23,21:18.6
16,-23,21:18.6
-3,-22,21:18.6
15,-22,21:18.6
16,-22,21:18.6
-3,-21,21:18.6
-2,-21,21:18.6
6,-21,21:17.12
15,-21,21:18.6
-2,-20,21:18.6
6,-20,21:17.12
14,-20,21:18.14
-2,-19,21:18.6
-1,-19,21:18.6
6,-19,21:17.12
14,-19,21:18.14
-1,-18,21:18.14
13,-18,21:18.14
-1,-17,21:18.14
0,-17,21:18.14
1,-17,21:18.14
2,-17,21:18.14
3,-17,21:18.14
4,-17,21:18.14
5,-17,21:18.14
6,-17,21:18.14
7,-17,21:18.14
8,-17,21:18.14
9,-17,21:18.14
10,-17,21:18.14
11,-17,21:18.14
12,-17,21:18.14
13,-17,21:18.14
-1,-16,21:18.14
6,-16,21:17.12
14,-16,21:18.14
-2,-15,21:18.14
14,-15,21:18.14
-3,-14,21:18.14
-2,-14,21:18.14
13,-14,21:17.12
14,-14,21:17.12
15,-14,21:18.14
-3,-13,21:18.14
15,-13,21:18.14
-4,-12,21:18.14
-3,-12,21:18.14
16,-12,21:18.14
-4,-11,21:18.14
1,-11,21:17.12
16,-11,21:18.14
17,-11,21:18.14
-5,-10,21:18.14
1,-10,21:17.12
2,-10,21:17.12
17,-10,21:18.14
-6,-9,21:18.14
-5,-9,21:18.14
18,-9,21:18.14
-6,-8,21:18.14
18,-8,21:18.14
-7,-7,21:18.14
-6,-7,21:18.14
19,-7,21:18.14
22,-7,21:18.14
-17,-6,21:18.14
-16,-6,21:18.14
-14,-6,21:18.14
-13,-6,21:18.14
-12,-6,21:18.14
-11,-6,21:18.14
-10,-6,21:18.14
-9,-6,21:18.14
-8,-6,21:18.14
-7,-6,21:18.14
-3,-6,21:17.12
6,-6,21:17.12
7,-6,21:17.12
19,-6,21:18.14
20,-6,21:18.14
21,-6,21:18.14
22,-6,21:18.14
23,-6,21:18.14
24,-6,21:18.14
25,-6,21:18.6
26,-6,21:18.6
27,-6,21:18.6
28,-6,21:18.6
29,-6,21:18.6
-7,-5,21:18.14
-4,-5,21:17.12
-3,-5,21:17.12
5,-5,21:17.12
6,-5,21:17.12
7,-5,21:17.12
19,-5,21:18.14
-6,-4,21:18.14
18,-4,21:18.14
19,-4,21:18.14
-6,-3,21:18.14
-5,-3,21:18.14
2,-3,21:17.12
3,-3,21:17.12
10,-3,21:17.12
-5,-2,21:18.14
2,-2,21:17.12
3,-2,21:17.12
10,-2,21:17.12
11,-2,21:17.12
12,-2,21:17.12
17,-2,21:18.14
18,-2,21:18.14
-5,-1,21:18.14
-4,-1,21:18.14
11,-1,21:17.12
12,-1,21:17.12
17,-1,21:18.14
-4,0,21:18.14
6,0,21:17.12
12,0,21:17.12
16,0,21:18.14
-3,1,21:18.14
6,1,21:17.12
7,1,21:17.12
15,1,21:18.14
-3,2,21:18.14
15,2,21:18.14
-2,3,21:18.14
14,3,21:18.14
15,3,21:18.14
-2,4,21:18.14
-1,4,21:18.14
14,4,21:18.14
-1,5,21:18.6
13,5,21:18.14
14,5,21:18.14
-1,6,21:18.6
0,6,21:18.6
1,6,21:18.6
2,6,21:18.14
3,6,21:18.14
4,6,21:18.14
5,6,21:18.14
6,6,21:18.14
7,6,21:18.14
8,6,21:18.14
9,6,21:18.14
10,6,21:18.14
11,6,21:18.14
12,6,21:18.14
13,6,21:18.14
-1,7,21:18.6
13,7,21:18.6
14,7,21:18.6
-2,8,21:18.6
6,8,21:17.12
7,8,21:17.12
14,8,21:18.6
-3,9,21:18.6
-2,9,21:18.6
15,9,21:18.6
-3,10,21:18.6
15,10,21:18.6
16,10,21:18.6
-4,11,21:18.6
-3,11,21:18.6
16,11,21:18.6
-4,12,21:18.6
17,12,21:18.6
-5,13,21:18.6
17,13,21:18.6
-5,14,21:18.6
18,14,21:18.6
18,15,21:18.6
16,-24,22:18.6
-4,-23,22:18.6
6,-23,22:17.12
16,-23,22:18.6
-3,-22,22:18.6
6,-22,22:17.12
15,-22,22:18.6
-3,-21,22:18.6
-2,-21,22:18.6
6,-21,22:17.12
15,-21,22:18.6
-2,-20,22:18.14
14,-20,22:18.14
-2,-19,22:18.14
-1,-19,22:18.14
6,-19,22:17.12
14,-19,22:18.14
-1,-18,22:18.14
13,-18,22:18.14
-1,-17,22:18.14
0,-17,22:18.14
1,-17,22:18.14
2,-17,22:18.14
3,-17,22:18.14
4,-17,22:18.14
5,-17,22:18.14
6,-17,22:18.14
7,-17,22:18.14
8,-17,22:18.14
9,-17,22:18.14
10,-17,22:18.14
11,-17,22:18.14
12,-17,22:18.14
13,-17,22:18.14
-1,-16,22:18.14
13,-16,22:18.14
14,-16,22:18.14
-2,-15,22:18.14
13,-15,22:17.12
14,-15,22:18.14
-2,-14,22:18.14
13,-14,22:17.12
14,-14,22:18.14
15,-14,22:18.14
-3,-13,22:18.14
-1,-13,22:17.12
15,-13,22:18.14
-4,-12,22:18.14
-3,-12,22:18.14
-1,-12,22:17.12
0,-12,22:17.12
1,-12,22:17.12
16,-12,22:18.14
-4,-11,22:18.14
0,-11,22:17.12
1,-11,22:17.12
16,-11,22:18.14
17,-11,22:18.14
-5,-10,22:18.14
1,-10,22:17.12
2,-10,22:17.12
17,-10,22:18.14
-5,-9,22:18.14
17,-9,22:18.14
18,-9,22:18.14
-6,-8,22:18.14
18,-8,22:18.14
-7,-7,22:18.14
-6,-7,22:18.14
6,-7,22:17.12
19,-7,22:18.14
22,-7,22:18.14
-15,-6,22:18.14
-14,-6,22:18.14
-13,-6,22:18.14
-12,-6,22:18.14
-11,-6,22:18.14
-10,-6,22:18.14
-9,-6,22:18.14
-8,-6,22:18.14
-7,-6,22:18.14
-4,-6,22:17.12
6,-6,22:17.12
7,-6,22:17.12
19,-6,22:18.14
20,-6,22:18.14
21,-6,22:18.14
22,-6,22:18.14
23,-6,22:18.14
24,-6,22:18.14
25,-6,22:18.6
26,-6,22:18.6
27,-6,22:18.6
28,-6,22:18.6
-7,-5,22:18.14
-6,-5,22:18.14
-5,-5,22:17.12
-4,-5,22:17.12
5,-5,22:17.12
6,-5,22:17.12
7,-5,22:17.12
19,-5,22:18.14
-6,-4,22:18.14
18,-4,22:18.14
-6,-3,22:18.14
-5,-3,22:18.14
2,-3,22:17.12
-5,-2,22:18.14
1,-2,22:17.12
2,-2,22:17.12
3,-2,22:17.12
17,-2,22:18.14
-4,-1,22:18.14
1,-1,22:17.12
2,-1,22:17.12
12,-1,22:17.12
13,-1,22:17.12
16,-1,22:18.14
17,-1,22:18.14
-4,0,22:18.14
1,0,22:17.12
12,0,22:17.12
13,0,22:17.12
16,0,22:18.14
-3,1,22:18.14
6,1,22:17.12
15,1,22:18.14
-3,2,22:18.14
-2,2,22:18.14
6,2,22:17.12
15,2,22:18.14
-2,3,22:18.14
14,3,22:18.14
-2,4,22:18.14
-1,4,22:18.14
14,4,22:18.14
-1,5,22:18.14
13,5,22:18.14
-1,6,22:18.14
0,6,22:18.14
1,6,22:18.14
2,6,22:18.14
3,6,22:18.14
4,6,22:18.14
5,6,22:18.14
6,6,22:18.14
7,6,22:18.14
8,6,22:18.14
9,6,22:18.14
10,6,22:18.14
11,6,22:18.14
12,6,22:18.14
13,6,22:18.14
-1,7,22:18.6
13,7,22:18.6
14,7,22:18.6
-2,8,22:18.6
6,8,22:17.12
14,8,22:18.6
-3,9,22:18.6
-2,9,22:18.6
6,9,22:17.12
15,9,22:18.6
-3,10,22:18.6
15,10,22:18.6
16,10,22:18.6
-4,11,22:18.6
-3,11,22:18.6
16,11,22:18.6
-4,12,22:18.6
16,12,22:18.6
-5,13,22:18.6
-5,14,22:18.6
18,14,22:18.6
-4,-24,23:18.6
6,-24,23:17.12
16,-24,23:18.6
-4,-23,23:18.6
6,-23,23:17.12
-3,-22,23:18.6
15,-22,23:18.6
-3,-21,23:18.6
-2,-21,23:18.6
15,-21,23:18.6
-2,-20,23:18.14
14,-20,23:18.14
-2,-19,23:18.14
-1,-19,23:18.14
6,-19,23:17.12
14,-19,23:18.14
-1,-18,23:18.14
13,-18,23:18.14
-1,-17,23:18.14
0,-17,23:18.14
1,-17,23:18.14
2,-17,23:18.14
3,-17,23:18.14
4,-17,23:18.14
5,-17,23:18.14
6,-17,23:18.14
7,-17,23:18.14
8,-17,23:18.14
9,-17,23:18.14
10,-17,23:18.14
11,-17,23:18.14
12,-17,23:18.14
13,-17,23:18.14
-1,-16,23:18.14
13,-16,23:18.14
15,-16,23:17.12
-2,-15,23:18.14
-1,-15,23:18.14
14,-15,23:18.14
-2,-14,23:18.14
14,-14,23:18.14
15,-14,23:18.14
-3,-13,23:18.14
-2,-13,23:17.12
-1,-13,23:17.12
15,-13,23:18.14
-3,-12,23:18.14
-1,-12,23:17.12
0,-12,23:17.12
15,-12,23:18.14
16,-12,23:18.14
-4,-11,23:18.14
16,-11,23:18.14
-5,-10,23:18.14
-4,-10,23:18.14
17,-10,23:18.14
-5,-9,23:18.14
17,-9,23:18.14
18,-9,23:18.14
-6,-8,23:18.14
18,-8,23:18.14
-6,-7,23:18.14
6,-7,23:17.12
18,-7,23:18.14
19,-7,23:18.14
22,-7,23:18.14
-15,-6,23:18.14
-14,-6,23:18.14
-12,-6,23:18.14
-11,-6,23:18.14
-10,-6,23:18.14
-9,-6,23:18.14
-8,-6,23:18.14
-7,-6,23:18.14
6,-6,23:17.12
7,-6,23:17.12
19,-6,23:18.14
20,-6,23:18.14
21,-6,23:18.14
22,-6,23:18.14
23,-6,23:18.14
24,-6,23:18.14
25,-6,23:18.6
26,-6,23:18.6
27,-6,23:18.6
-7,-5,23:18.14
-6,-5,23:18.14
19,-5,23:18.14
-6,-4,23:18.14
18,-4,23:18.14
-5,-3,23:18.14
17,-3,23:18.14
-5,-2,23:18.14
-4,-2,23:18.14
17,-2,23:18.14
-4,-1,23:18.14
1,-1,23:17.12
16,-1,23:18.14
17,-1,23:18.14
-4,0,23:18.14
-3,0,23:18.14
0,0,23:17.12
1,0,23:17.12
13,0,23:17.12
14,0,23:17.12
16,0,23:18.14
-3,1,23:18.14
15,1,23:18.14
-3,2,23:18.14
-2,2,23:18.14
6,2,23:17.12
14,2,23:18.14
15,2,23:18.14
-2,3,23:18.14
14,3,23:18.14
-1,4,23:18.14
13,4,23:18.14
14,4,23:18.14
-1,5,23:18.14
0,5,23:18.14
1,5,23:18.14
2,5,23:18.14
3,5,23:18.14
4,5,23:18.14
5,5,23:18.14
6,5,23:18.14
7,5,23:18.14
8,5,23:18.14
9,5,23:18.14
10,5,23:18.14
11,5,23:18.14
12,5,23:18.14
13,5,23:18.14
-1,6,23:18.14
0,6,23:18.14
13,6,23:18.14
-1,7,23:18.6
13,7,23:18.6
14,7,23:18.6
-2,8,23:18.6
14,8,23:18.6
-3,9,23:18.6
-2,9,23:18.6
6,9,23:17.12
15,9,23:18.6
-3,10,23:18.6
6,10,23:17.12
15,10,23:18.6
-4,11,23:18.6
16,11,23:18.6
-4,12,23:18.6
16,12,23:18.6
6,-25,24:17.12
-4,-24,24:18.6
-4,-23,24:18.6
-3,-22,24:18.6
15,-22,24:18.6
-3,-21,24:18.6
-2,-21,24:18.6
15,-21,24:18.6
-2,-20,24:18.14
6,-20,24:17.12
14,-20,24:18.14
-2,-19,24:18.14
-1,-19,24:18.14
6,-19,24:17.12
13,-19,24:18.14
14,-19,24:18.14
-1,-18,24:18.14
13,-18,24:18.14
-1,-17,24:18.14
0,-17,24:18.14
1,-17,24:18.14
2,-17,24:18.14
3,-17,24:18.14
4,-17,24:18.14
5,-17,24:18.14
6,-17,24:18.14
7,-17,24:18.14
8,-17,24:18.14
9,-17,24:18.14
10,-17,24:18.14
11,-17,24:18.14
12,-17,24:18.14
13,-17,24:18.14
-1,-16,24:18.14
13,-16,24:18.14
-2,-15,24:18.14
-1,-15,24:18.14
14,-15,24:18.14
-2,-14,24:18.14
14,-14,24:18.14
-3,-13,24:18.14
-2,-13,24:17.12
15,-13,24:18.14
-3,-12,24:18.14
15,-12,24:18.14
16,-12,24:18.14
-4,-11,24:18.14
16,-11,24:18.14
-4,-10,24:18.14
6,-10,24:17.12
16,-10,24:18.14
17,-10,24:18.14
-5,-9,24:18.14
6,-9,24:17.12
17,-9,24:18.14
-6,-8,24:18.14
-5,-8,24:18.14
6,-8,24:17.12
18,-8,24:18.14
-6,-7,24:18.14
6,-7,24:17.12
7,-7,24:17.12
18,-7,24:18.14
19,-7,24:18.14
-12,-6,24:18.6
-11,-6,24:18.6
-10,-6,24:18.6
-9,-6,24:18.14
-8,-6,24:18.14
-7,-6,24:18.14
-6,-6,24:18.14
6,-6,24:17.12
7,-6,24:17.12
19,-6,24:18.14
20,-6,24:18.14
21,-6,24:18.14
22,-6,24:18.14
23,-6,24:18.14
24,-6,24:18.14
25,-6,24:18.6
26,-6,24:18.6
27,-6,24:18.6
-6,-5,24:18.14
18,-5,24:18.14
19,-5,24:18.14
-6,-4,24:18.14
-5,-4,24:18.14
18,-4,24:18.14
-5,-3,24:18.14
17,-3,24:18.14
-5,-2,24:18.14
-4,-2,24:18.14
17,-2,24:18.14
-4,-1,24:18.14
16,-1,24:18.14
-3,0,24:18.14
0,0,24:17.12
1,0,24:17.12
14,0,24:17.12
15,0,24:18.14
16,0,24:18.14
-3,1,24:18.14
14,1,24:17.12
15,1,24:18.14
-2,2,24:18.14
6,2,24:17.12
14,2,24:18.14
15,2,24:18.14
-2,3,24:18.14
-1,3,24:18.14
6,3,24:17.12
14,3,24:18.14
-1,4,24:18.14
13,4,24:18.14
-1,5,24:18.14
0,5,24:18.14
1,5,24:18.14
2,5,24:18.14
3,5,24:18.14
4,5,24:18.14
5,5,24:18.14
6,5,24:18.14
7,5,24:18.14
8,5,24:18.14
9,5,24:18.14
10,5,24:18.14
11,5,24:18.14
12,5,24:18.14
13,5,24:18.14
-1,6,24:18.14
13,6,24:18.14
-2,7,24:18.6
-1,7,24:18.6
13,7,24:18.6
14,7,24:18.6
-2,8,24:18.6
14,8,24:18.6
-3,9,24:18.6
-2,9,24:18.6
15,9,24:18.6
-3,10,24:18.6
15,10,24:18.6
-4,11,24:18.6
-4,12,24:18.6
17,12,24:18.6
-3,-22,25:18.6
-3,-21,25:18.6
-2,-21,25:18.6
6,-21,25:17.12
15,-21,25:18.6
-2,-20,25:18.14
14,-20,25:18.14
-2,-19,25:18.14
-1,-19,25:18.14
13,-19,25:18.14
14,-19,25:18.14
-1,-18,25:18.14
13,-18,25:18.14
0,-17,25:18.14
1,-17,25:18.14
2,-17,25:18.14
3,-17,25:18.14
4,-17,25:18.14
5,-17,25:18.14
6,-17,25:18.14
7,-17,25:18.14
8,-17,25:18.14
9,-17,25:18.14
10,-17,25:18.14
11,-17,25:18.14
12,-17,25:18.14
13,-17,25:18.14
-1,-16,25:18.14
13,-16,25:18.14
-1,-15,25:18.14
13,-15,25:18.14
14,-15,25:18.14
-3,-14,25:17.12
-2,-14,25:18.14
14,-14,25:18.14
-3,-13,25:18.14
-2,-13,25:18.14
15,-13,25:18.14
-3,-12,25:18.14
15,-12,25:18.14
-4,-11,25:18.14
-3,-11,25:18.14
16,-11,25:18.14
-4,-10,25:18.14
6,-10,25:17.12
16,-10,25:18.14
17,-10,25:18.14
-5,-9,25:18.14
6,-9,25:17.12
17,-9,25:18.6
-5,-8,25:18.14
17,-8,25:18.6
18,-8,25:18.6
-6,-7,25:18.14
6,-7,25:17.12
18,-7,25:18.6
-11,-6,25:18.6
-10,-6,25:18.6
-9,-6,25:18.14
-8,-6,25:18.14
-7,-6,25:18.14
-6,-6,25:18.14
6,-6,25:17.12
7,-6,25:17.12
19,-6,25:18.6
20,-6,25:18.6
21,-6,25:18.6
22,-6,25:18.14
23,-6,25:18.14
24,-6,25:18.14
25,-6,25:18.6
-6,-5,25:18.14
6,-5,25:17.12
18,-5,25:18.6
-6,-4,25:18.14
-5,-4,25:18.14
18,-4,25:18.14
-5,-3,25:18.14
17,-3,25:18.14
-4,-2,25:18.14
16,-2,25:18.14
17,-2,25:18.14
-4,-1,25:18.14
16,-1,25:18.14
-3,0,25:18.14
0,0,25:17.12
1,0,25:17.12
15,0,25:18.14
16,0,25:18.14
-3,1,25:18.14
-2,1,25:18.14
14,1,25:17.12
15,1,25:18.14
-2,2,25:18.14
14,2,25:18.14
15,2,25:17.12
-2,3,25:18.14
-1,3,25:18.14
13,3,25:18.14
14,3,25:18.14
-1,4,25:18.14
13,4,25:18.14
0,5,25:18.14
1,5,25:18.14
2,5,25:18.14
3,5,25:18.14
4,5,25:18.14
5,5,25:18.14
6,5,25:18.14
7,5,25:18.14
8,5,25:18.14
9,5,25:18.14
10,5,25:18.14
11,5,25:18.14
12,5,25:18.14
13,5,25:18.14
-1,6,25:18.14
13,6,25:18.14
-2,7,25:18.6
-1,7,25:18.6
13,7,25:18.6
14,7,25:18.6
-2,8,25:18.6
14,8,25:18.6
-3,9,25:18.6
-2,9,25:18.6
15,9,25:18.6
-3,10,25:18.6
15,10,25:18.6
-3,-22,26:18.6
-3,-21,26:18.6
-2,-21,26:18.6
-2,-20,26:18.14
14,-20,26:18.14
-2,-19,26:18.14
-1,-19,26:18.14
13,-19,26:18.14
14,-19,26:18.14
-1,-18,26:18.14
13,-18,26:18.14
0,-17,26:18.14
1,-17,26:18.14
2,-17,26:18.14
3,-17,26:18.14
4,-17,26:18.14
5,-17,26:18.14
6,-17,26:18.14
7,-17,26:18.14
8,-17,26:18.14
9,-17,26:18.14
10,-17,26:18.14
11,-17,26:18.14
12,-17,26:18.14
13,-17,26:18.14
-4,-16,26:17.12
-1,-16,26:18.14
0,-16,26:18.14
13,-16,26:18.14
-4,-15,26:17.12
-3,-15,26:17.12
-1,-15,26:18.14
13,-15,26:18.14
-3,-14,26:17.12
-2,-14,26:18.14
6,-14,26:17.12
14,-14,26:18.14
-2,-13,26:18.14
6,-13,26:17.12
14,-13,26:18.14
15,-13,26:18.14
-3,-12,26:18.14
6,-12,26:17.12
15,-12,26:18.14
-4,-11,26:18.14
-3,-11,26:18.14
6,-11,26:17.12
15,-11,26:18.14
16,-11,26:18.14
-4,-10,26:18.14
6,-10,26:17.12
16,-10,26:18.14
-5,-9,26:18.14
-4,-9,26:18.14
17,-9,26:18.6
-5,-8,26:18.14
17,-8,26:18.6
18,-8,26:18.6
-6,-7,26:18.14
18,-7,26:18.6
-10,-6,26:18.6
-9,-6,26:18.14
-8,-6,26:18.14
-7,-6,26:18.14
-6,-6,26:18.14
6,-6,26:17.12
18,-6,26:18.6
19,-6,26:18.6
20,-6,26:18.6
21,-6,26:18.6
22,-6,26:18.14
23,-6,26:18.14
24,-6,26:18.14
25,-6,26:18.6
-6,-5,26:18.14
6,-5,26:17.12
7,-5,26:17.12
18,-5,26:18.6
-5,-4,26:18.14
17,-4,26:18.14
18,-4,26:18.14
-5,-3,26:18.14
17,-3,26:18.14
-4,-2,26:18.14
16,-2,26:18.14
17,-2,26:18.14
-4,-1,26:18.14
-3,-1,26:18.14
16,-1,26:18.14
-3,0,26:18.14
0,0,26:17.12
15,0,26:18.14
-3,1,26:18.14
-2,1,26:18.14
0,1,26:17.12
14,1,26:18.14
15,1,26:18.14
-2,2,26:18.14
-1,2,26:17.12
14,2,26:18.14
-1,3,26:18.14
13,3,26:18.14
14,3,26:18.14
-1,4,26:18.14
0,4,26:18.14
13,4,26:18.14
0,5,26:18.14
1,5,26:18.14
2,5,26:18.14
3,5,26:18.14
4,5,26:18.14
5,5,26:18.14
6,5,26:18.14
7,5,26:18.14
8,5,26:18.14
9,5,26:18.14
10,5,26:18.14
11,5,26:18.14
12,5,26:18.14
13,5,26:18.14
-1,6,26:18.14
13,6,26:18.14
-2,7,26:18.6
-1,7,26:18.6
13,7,26:18.6
14,7,26:18.6
-2,8,26:18.6
14,8,26:18.6
-3,9,26:18.6
-2,9,26:18.6
15,9,26:18.6
-3,10,26:18.6
-2,-21,27:18.6
-2,-20,27:18.14
14,-20,27:18.14
-2,-19,27:18.14
-1,-19,27:18.14
13,-19,27:18.14
14,-19,27:18.14
-1,-18,27:18.14
13,-18,27:18.14
0,-17,27:18.14
1,-17,27:18.14
2,-17,27:18.14
3,-17,27:18.14
4,-17,27:18.14
5,-17,27:18.14
6,-17,27:18.14
7,-17,27:18.14
8,-17,27:18.14
9,-17,27:18.14
10,-17,27:18.14
11,-17,27:18.14
12,-17,27:18.14
13,-17,27:18.14
0,-16,27:18.14
12,-16,27:18.14
13,-16,27:18.14
-1,-15,27:18.14
6,-15,27:17.12
13,-15,27:18.14
-2,-14,27:18.14
-1,-14,27:18.14
14,-14,27:18.14
-2,-13,27:18.14
14,-13,27:18.14
-3,-12,27:18.14
-2,-12,27:18.14
15,-12,27:18.14
-3,-11,27:18.14
15,-11,27:18.6
16,-11,27:18.6
-4,-10,27:18.14
16,-10,27:18.6
-5,-9,27:18.14
-4,-9,27:18.14
16,-9,27:18.6
17,-9,27:18.6
-5,-8,27:18.14
17,-8,27:18.6
-6,-7,27:18.6
-5,-7,27:18.6
18,-7,27:18.6
-10,-6,27:18.6
-9,-6,27:18.6
-8,-6,27:18.6
-7,-6,27:18.6
-6,-6,27:18.6
18,-6,27:18.6
19,-6,27:18.6
20,-6,27:18.6
21,-6,27:18.6
22,-6,27:18.14
23,-6,27:18.14
24,-6,27:18.14
-6,-5,27:18.6
-5,-5,27:18.6
6,-5,27:17.12
18,-5,27:18.6
-5,-4,27:18.6
17,-4,27:18.14
-5,-3,27:18.6
-4,-3,27:18.14
17,-3,27:18.14
-4,-2,27:18.14
16,-2,27:18.14
-3,-1,27:18.14
15,-1,27:18.14
16,-1,27:18.14
-3,0,27:18.14
15,0,27:18.14
-2,1,27:18.14
14,1,27:18.14
15,1,27:18.14
-2,2,27:18.14
-1,2,27:18.14
14,2,27:18.14
-1,3,27:18.14
13,3,27:18.14
-1,4,27:18.14
0,4,27:18.14
12,4,27:18.14
13,4,27:18.14
0,5,27:18.14
1,5,27:18.14
2,5,27:18.14
3,5,27:18.14
4,5,27:18.14
5,5,27:18.14
6,5,27:18.14
7,5,27:18.14
8,5,27:18.14
9,5,27:18.14
10,5,27:18.14
11,5,27:18.14
12,5,27:18.14
13,5,27:18.14
-1,6,27:18.14
13,6,27:18.14
-2,7,27:18.6
-1,7,27:18.6
13,7,27:18.6
14,7,27:18.6
-2,8,27:18.6
14,8,27:18.6
-3,9,27:18.6
-2,9,27:18.6
-2,-20,28:18.14
-2,-19,28:18.14
-1,-19,28:18.14
13,-19,28:18.6
14,-19,28:18.6
-1,-18,28:18.14
13,-18,28:18.6
0,-17,28:18.14
12,-17,28:18.6
13,-17,28:18.6
0,-16,28:18.14
1,-16,28:18.14
2,-16,28:18.14
3,-16,28:18.14
4,-16,28:18.14
5,-16,28:18.14
6,-16,28:18.14
7,-16,28:18.14
8,-16,28:18.14
9,-16,28:18.14
10,-16,28:18.14
11,-16,28:18.6
12,-16,28:18.6
13,-16,28:18.6
-1,-15,28:18.14
6,-15,28:17.12
13,-15,28:18.6
-1,-14,28:18.14
13,-14,28:18.6
14,-14,28:18.6
-2,-13,28:18.14
14,-13,28:18.6
-3,-12,28:18.14
-2,-12,28:18.14
15,-12,28:18.6
-3,-11,28:18.14
15,-11,28:18.6
-4,-10,28:18.14
-3,-10,28:18.14
16,-10,28:18.6
-4,-9,28:18.14
16,-9,28:18.6
17,-9,28:18.6
-5,-8,28:18.6
17,-8,28:18.6
-6,-7,28:18.6
-5,-7,28:18.6
17,-7,28:18.6
18,-7,28:18.6
-9,-6,28:18.6
-8,-6,28:18.6
-7,-6,28:18.6
-6,-6,28:18.6
18,-6,28:18.6
19,-6,28:18.6
20,-6,28:18.6
21,-6,28:18.6
22,-6,28:18.6
23,-6,28:18.6
-6,-5,28:18.6
-5,-5,28:18.6
6,-5,28:17.12
17,-5,28:18.6
18,-5,28:18.6
-5,-4,28:18.6
17,-4,28:18.14
-4,-3,28:18.14
16,-3,28:18.14
17,-3,28:18.14
-4,-2,28:18.14
16,-2,28:18.14
-3,-1,28:18.14
15,-1,28:18.14
16,-1,28:18.14
-3,0,28:18.14
-2,0,28:18.14
15,0,28:18.14
-2,1,28:18.14
14,1,28:18.14
-2,2,28:18.14
-1,2,28:18.14
13,2,28:18.14
14,2,28:18.14
-1,3,28:18.14
13,3,28:18.14
0,4,28:18.14
1,4,28:18.14
2,4,28:18.14
3,4,28:18.14
4,4,28:18.14
5,4,28:18.14
7,4,28:18.14
8,4,28:18.14
9,4,28:18.14
10,4,28:18.14
11,4,28:18.14
12,4,28:18.14
13,4,28:18.14
0,5,28:18.14
1,5,28:18.14
2,5,28:18.14
3,5,28:18.14
4,5,28:18.14
5,5,28:18.14
6,5,28:18.14
7,5,28:18.14
8,5,28:18.14
9,5,28:18.14
10,5,28:18.14
11,5,28:18.14
12,5,28:18.14
13,5,28:18.14
-1,6,28:18.14
13,6,28:18.14
-2,7,28:18.6
-1,7,28:18.6
13,7,28:18.6
14,7,28:18.6
-2,8,28:18.6
-2,-20,29:18.14
-1,-19,29:18.14
13,-19,29:18.6
-1,-18,29:18.14
13,-18,29:18.6
0,-17,29:18.14
12,-17,29:18.6
0,-16,29:18.14
1,-16,29:18.14
2,-16,29:18.14
3,-16,29:18.14
4,-16,29:18.14
5,-16,29:18.14
6,-16,29:18.14
7,-16,29:18.14
8,-16,29:18.14
9,-16,29:18.14
10,-16,29:18.14
11,-16,29:18.6
12,-16,29:18.6
-1,-15,29:18.14
0,-15,29:18.14
1,-15,29:18.14
2,-15,29:18.14
3,-15,29:18.14
4,-15,29:18.14
5,-15,29:18.14
6,-15,29:18.14
7,-15,29:18.14
8,-15,29:18.14
10,-15,29:18.14
11,-15,29:18.6
-1,-14,29:18.14
0,-14,29:18.14
1,-14,29:18.14
2,-14,29:18.14
3,-14,29:18.14
4,-14,29:18.14
5,-14,29:18.14
6,-14,29:18.14
7,-14,29:18.14
8,-14,29:18.14
9,-14,29:18.14
10,-14,29:18.14
11,-14,29:18.6
12,-14,29:18.6
13,-14,29:18.6
14,-14,29:18.6
-2,-13,29:18.14
-1,-13,29:18.14
0,-13,29:18.14
1,-13,29:18.14
11,-13,29:18.6
12,-13,29:18.6
14,-13,29:18.6
-2,-12,29:18.14
-1,-12,29:18.14
0,-12,29:18.14
12,-12,29:18.6
13,-12,29:18.6
14,-12,29:18.6
15,-12,29:18.6
-3,-11,29:18.14
-2,-11,29:18.14
-1,-11,29:18.14
0,-11,29:18.14
12,-11,29:18.6
13,-11,29:18.6
15,-11,29:18.6
-4,-10,29:18.14
-3,-10,29:18.14
-2,-10,29:18.14
-1,-10,29:18.14
13,-10,29:18.6
14,-10,29:18.6
16,-10,29:18.6
-4,-9,29:18.6
-3,-9,29:18.6
-2,-9,29:18.6
14,-9,29:18.6
16,-9,29:18.6
-5,-8,29:18.6
-4,-8,29:18.6
-3,-8,29:18.6
-2,-8,29:18.6
14,-8,29:18.6
15,-8,29:18.6
17,-8,29:18.6
-5,-7,29:18.6
-4,-7,29:18.6
-3,-7,29:18.6
15,-7,29:18.6
16,-7,29:18.6
17,-7,29:18.6
18,-7,29:18.6
-9,-6,29:18.6
-8,-6,29:18.6
-7,-6,29:18.6
-6,-6,29:18.6
-5,-6,29:18.6
-4,-6,29:18.6
-3,-6,29:18.6
6,-6,29:17.12
16,-6,29:18.6
18,-6,29:18.6
19,-6,29:18.6
20,-6,29:18.6
21,-6,29:18.6
22,-6,29:18.6
-5,-5,29:18.6
-4,-5,29:18.6
-3,-5,29:18.6
6,-5,29:17.12
15,-5,29:18.6
16,-5,29:18.6
17,-5,29:18.6
18,-5,29:18.6
-5,-4,29:18.6
-4,-4,29:18.14
-3,-4,29:18.14
15,-4,29:18.6
17,-4,29:18.6
-4,-3,29:18.14
-3,-3,29:18.14
-2,-3,29:18.14
15,-3,29:18.14
16,-3,29:18.14
-4,-2,29:18.14
-3,-2,29:18.14
-2,-2,29:18.14
14,-2,29:18.14
16,-2,29:18.14
-3,-1,29:18.14
-2,-1,29:18.14
-1,-1,29:18.14
13,-1,29:18.14
15,-1,29:18.14
-3,0,29:18.14
-2,0,29:18.14
-1,0,29:18.14
13,0,29:18.14
14,0,29:18.14
15,0,29:18.14
-2,1,29:18.14
-1,1,29:18.14
0,1,29:18.14
12,1,29:18.14
14,1,29:18.14
-1,2,29:18.14
0,2,29:18.14
12,2,29:18.14
13,2,29:18.14
14,2,29:18.14
-1,3,29:18.14
0,3,29:18.14
1,3,29:18.14
2,3,29:18.14
3,3,29:18.14
4,3,29:18.14
5,3,29:18.14
6,3,29:18.6
7,3,29:18.6
8,3,29:18.6
10,3,29:18.14
11,3,29:18.14
12,3,29:18.14
13,3,29:18.14
0,4,29:18.14
1,4,29:18.14
2,4,29:18.14
3,4,29:18.14
4,4,29:18.14
5,4,29:18.14
6,4,29:18.6
7,4,29:18.6
8,4,29:18.6
9,4,29:18.6
10,4,29:18.14
11,4,29:18.14
12,4,29:18.14
0,5,29:18.14
12,5,29:18.14
13,5,29:18.14
-1,6,29:18.14
13,6,29:18.14
-2,7,29:18.6
-1,7,29:18.6
14,7,29:18.6
-2,8,29:18.6
-1,-19,30:18.14
-1,-18,30:18.14
0,-17,30:18.14
0,-16,30:18.14
1,-16,30:18.14
2,-16,30:18.14
3,-16,30:18.14
4,-16,30:18.14
5,-16,30:18.14
6,-16,30:18.14
7,-16,30:18.14
8,-16,30:18.14
9,-16,30:18.14
10,-16,30:18.14
12,-16,30:18.6
-1,-15,30:18.14
0,-15,30:18.14
-1,-14,30:18.14
13,-14,30:18.6
-2,-13,30:18.14
-1,-13,30:18.14
1,-13,30:18.14
2,-13,30:18.14
3,-13,30:18.14
4,-13,30:18.14
5,-13,30:18.14
6,-13,30:18.14
7,-13,30:18.14
8,-13,30:18.14
9,-13,30:18.14
10,-13,30:18.14
14,-13,30:18.6
-2,-12,30:18.14
1,-12,30:18.14
2,-12,30:18.14
3,-12,30:18.14
4,-12,30:18.14
5,-12,30:18.14
6,-12,30:18.14
8,-12,30:18.14
9,-12,30:18.14
10,-12,30:18.14
11,-12,30:18.6
14,-12,30:18.6
-3,-11,30:18.14
0,-11,30:18.14
1,-11,30:18.14
2,-11,30:18.14
3,-11,30:18.14
4,-11,30:18.14
5,-11,30:18.14
6,-11,30:18.14
7,-11,30:18.14
8,-11,30:18.14
9,-11,30:18.14
10,-11,30:18.14
11,-11,30:18.6
12,-11,30:18.6
15,-11,30:18.6
-3,-10,30:18.14
-1,-10,30:18.14
0,-10,30:18.14
1,-10,30:18.14
2,-10,30:18.14
9,-10,30:18.14
10,-10,30:18.14
11,-10,30:18.6
12,-10,30:18.6
13,-10,30:18.6
15,-10,30:18.6
16,-10,30:18.6
-4,-9,30:18.6
-1,-9,30:18.6
0,-9,30:18.6
1,-9,30:18.6
2,-9,30:18.14
10,-9,30:18.14
11,-9,30:18.14
12,-9,30:18.6
13,-9,30:18.6
16,-9,30:18.6
-4,-8,30:18.6
-2,-8,30:18.6
-1,-8,30:18.6
0,-8,30:18.6
1,-8,30:18.6
11,-8,30:18.14
12,-8,30:18.6
13,-8,30:18.6
14,-8,30:18.6
17,-8,30:18.6
-2,-7,30:18.6
-1,-7,30:18.6
0,-7,30:18.6
1,-7,30:18.6
11,-7,30:18.14
12,-7,30:18.6
13,-7,30:18.6
14,-7,30:18.6
17,-7,30:18.6
-6,-6,30:18.6
-3,-6,30:18.6
-2,-6,30:18.6
-1,-6,30:18.6
0,-6,30:18.6
6,-6,30:17.12
12,-6,30:18.6
13,-6,30:18.6
14,-6,30:18.6
15,-6,30:18.6
18,-6,30:18.6
19,-6,30:18.6
20,-6,30:18.6
21,-6,30:18.6
-3,-5,30:18.6
-2,-5,30:18.6
-1,-5,30:18.6
6,-5,30:17.12
12,-5,30:18.6
13,-5,30:18.6
14,-5,30:18.6
15,-5,30:18.6
17,-5,30:18.6
-5,-4,30:18.6
-4,-4,30:18.14
-2,-4,30:18.14
-1,-4,30:18.14
0,-4,30:18.14
11,-4,30:18.14
12,-4,30:18.6
13,-4,30:18.6
14,-4,30:18.6
17,-4,30:18.6
-4,-3,30:18.14
-2,-3,30:18.14
-1,-3,30:18.14
0,-3,30:18.14
1,-3,30:18.14
10,-3,30:18.14
11,-3,30:18.14
12,-3,30:18.6
13,-3,30:18.6
14,-3,30:18.6
16,-3,30:18.6
-4,-2,30:18.14
-3,-2,30:18.14
-1,-2,30:18.14
0,-2,30:18.14
1,-2,30:18.14
2,-2,30:18.14
10,-2,30:18.14
11,-2,30:18.14
12,-2,30:18.6
13,-2,30:18.6
15,-2,30:18.6
16,-2,30:18.6
-3,-1,30:18.14
-1,-1,30:18.14
0,-1,30:18.14
1,-1,30:18.14
2,-1,30:18.14
9,-1,30:18.14
10,-1,30:18.14
11,-1,30:18.14
12,-1,30:18.6
13,-1,30:18.6
15,-1,30:18.6
-2,0,30:18.14
0,0,30:18.14
1,0,30:18.14
2,0,30:18.14
3,0,30:18.14
4,0,30:18.14
5,0,30:18.6
6,0,30:18.6
7,0,30:18.6
8,0,30:18.6
9,0,30:18.6
10,0,30:18.6
11,0,30:18.6
12,0,30:18.6
14,0,30:18.6
15,0,30:18.6
-2,1,30:18.14
-1,1,30:18.14
0,1,30:18.14
1,1,30:18.14
2,1,30:18.14
3,1,30:18.14
4,1,30:18.14
5,1,30:18.6
6,1,30:18.6
7,1,30:18.6
8,1,30:18.6
9,1,30:18.6
10,1,30:18.6
11,1,30:18.6
12,1,30:18.6
14,1,30:18.6
-1,2,30:18.14
1,2,30:18.14
2,2,30:18.14
3,2,30:18.14
4,2,30:18.14
5,2,30:18.6
6,2,30:18.6
7,2,30:18.6
8,2,30:18.6
9,2,30:18.6
10,2,30:18.6
11,2,30:18.6
13,2,30:18.6
-1,3,30:18.14
0,3,30:18.14
3,3,30:18.14
6,3,30:18.6
7,3,30:18.6
8,3,30:18.6
9,3,30:18.6
10,3,30:18.6
13,3,30:18.6
0,4,30:18.14
1,4,30:18.14
2,4,30:18.14
3,4,30:18.14
4,4,30:18.14
5,4,30:18.6
6,4,30:18.6
7,4,30:18.6
8,4,30:18.6
9,4,30:18.6
12,4,30:18.6
0,5,30:18.14
12,5,30:18.6
-1,6,30:18.14
13,6,30:18.6
-1,7,30:18.6
0,-16,31:18.6
1,-16,31:18.6
2,-16,31:18.14
3,-16,31:18.14
4,-16,31:18.14
5,-16,31:18.14
6,-16,31:18.14
7,-16,31:18.14
8,-16,31:18.14
9,-16,31:18.14
0,-15,31:18.6
-1,-14,31:18.6
-2,-13,31:18.6
-1,-13,31:18.6
13,-13,31:18.6
14,-13,31:18.6
-2,-12,31:18.6
14,-12,31:18.6
-3,-11,31:18.6
15,-11,31:18.6
-3,-10,31:18.6
3,-10,31:18.14
4,-10,31:18.14
5,-10,31:18.14
6,-10,31:18.14
7,-10,31:18.14
8,-10,31:18.14
9,-10,31:18.14
15,-10,31:18.6
-4,-9,31:18.6
2,-9,31:18.14
3,-9,31:18.14
4,-9,31:18.14
5,-9,31:18.14
6,-9,31:18.14
7,-9,31:18.14
8,-9,31:18.14
9,-9,31:18.14
16,-9,31:18.6
2,-8,31:18.14
3,-8,31:18.14
4,-8,31:18.14
5,-8,31:18.14
6,-8,31:18.14
7,-8,31:18.14
8,-8,31:18.14
9,-8,31:18.14
10,-8,31:18.14
16,-8,31:18.6
17,-8,31:18.6
1,-7,31:18.6
2,-7,31:18.14
3,-7,31:18.14
4,-7,31:18.14
8,-7,31:18.14
9,-7,31:18.14
10,-7,31:18.14
11,-7,31:18.6
17,-7,31:18.6
0,-6,31:18.6
1,-6,31:18.6
2,-6,31:18.14
3,-6,31:18.14
4,-6,31:18.14
8,-6,31:18.14
9,-6,31:18.14
10,-6,31:18.14
11,-6,31:18.6
17,-6,31:18.6
18,-6,31:18.6
1,-5,31:18.6
2,-5,31:18.14
3,-5,31:18.14
4,-5,31:18.14
8,-5,31:18.14
9,-5,31:18.14
10,-5,31:18.14
11,-5,31:18.6
17,-5,31:18.6
-4,-4,31:18.6
2,-4,31:18.14
3,-4,31:18.14
4,-4,31:18.14
5,-4,31:18.14
6,-4,31:18.14
7,-4,31:18.14
8,-4,31:18.14
9,-4,31:18.14
11,-4,31:18.6
16,-4,31:18.6
17,-4,31:18.6
-4,-3,31:18.6
2,-3,31:18.14
3,-3,31:18.14
4,-3,31:18.14
5,-3,31:18.14
6,-3,31:18.14
7,-3,31:18.14
8,-3,31:18.14
9,-3,31:18.14
10,-3,31:18.14
16,-3,31:18.6
-3,-2,31:18.6
2,-2,31:18.14
3,-2,31:18.14
4,-2,31:18.14
5,-2,31:18.14
6,-2,31:18.14
7,-2,31:18.14
8,-2,31:18.14
9,-2,31:18.14
10,-2,31:18.14
15,-2,31:18.6
-3,-1,31:18.6
3,-1,31:18.14
4,-1,31:18.14
5,-1,31:18.14
6,-1,31:18.14
7,-1,31:18.14
8,-1,31:18.14
9,-1,31:18.14
15,-1,31:18.6
-2,0,31:18.6
14,0,31:18.6
-2,1,31:18.6
-1,1,31:18.6
13,1,31:18.6
14,1,31:18.6
-1,2,31:18.6
13,2,31:18.6
0,3,31:18.6
0,4,31:18.6
1,4,31:18.6
2,4,31:18.6
3,4,31:18.6
4,4,31:18.6
5,4,31:18.6
6,4,31:18.6
7,4,31:18.6
8,4,31:18.6
9,4,31:18.6
-1,6,31:18.6
0,-16,32:18.6
1,-16,32:18.6
2,-16,32:18.14
3,-16,32:18.14
4,-16,32:18.14
5,-16,32:18.14
8,-16,32:18.14
9,-16,32:18.14
0,-15,32:18.6
-1,-14,32:18.6
-1,-13,32:18.6
13,-13,32:18.6
14,-13,32:18.6
14,-12,32:18.6
-3,-10,32:18.6
-4,-9,32:18.6
-3,-9,32:18.6
16,-9,32:18.6
16,-8,32:18.6
5,-7,32:18.14
6,-7,32:18.14
7,-7,32:18.14
17,-7,32:18.6
4,-6,32:18.14
5,-6,32:18.14
6,-6,32:18.14
7,-6,32:18.14
8,-6,32:18.14
17,-6,32:18.6
4,-5,32:18.14
5,-5,32:18.14
6,-5,32:18.14
7,-5,32:18.14
17,-5,32:18.6
-4,-4,32:18.6
5,-4,32:18.14
6,-4,32:18.14
7,-4,32:18.14
16,-4,32:18.6
-4,-3,32:18.6
-3,-3,32:18.6
15,-3,32:18.6
16,-3,32:18.6
-3,-2,32:18.6
15,-2,32:18.6
-2,0,32:18.6
14,0,32:18.6
-1,1,32:18.6
13,1,32:18.6
14,1,32:18.6
-1,2,32:18.6
0,3,32:18.6
0,4,32:18.6
1,4,32:18.6
2,4,32:18.6
3,4,32:18.6
4,4,32:18.6
7,4,32:18.6
8,4,32:18.6
9,4,32:18.6
3,-16,33:18.6
4,-16,33:18.6
8,-16,33:18.6
-1,-14,33:18.6
-1,-13,33:18.6
13,-13,33:18.6
-3,-9,33:18.6
16,-9,33:18.6
16,-8,33:18.6
16,-4,33:18.6
-3,-3,33:18.6
15,-3,33:18.6
16,-3,33:18.6
-1,1,33:18.6
13,1,33:18.6
-1,2,33:18.6
3,4,33:18.6
4,4,33:18.6
8,4,33:18.6
