[META]
version=2.0
spawnOnBlockType=2
spawnSunlight=True
spawnDarkness=True
spawnWater=False
spawnLava=False
underFill=False
randomRotation=True
dig=True
tree=False
branch=False
needsFoundation=True
rarity=100
collisionPercentage=20
spawnElevationMin=0
spawnElevationMax=200
spawnInBiome=Custom
[DATA]
-1,-5,-8:17.12
-1,-4,-8:17.12
0,-4,-8:17.12
-5,1,-8:17.12
-5,2,-8:17.12
-4,4,-8:17.12
2,5,-8:17.12
-2,-5,-7:17.12
-1,-5,-7:17.12
-2,-4,-7:17.12
-1,-4,-7:17.12
-1,-3,-7:17.12
4,-3,-7:17.12
4,-2,-7:17.12
5,-2,-7:17.12
6,-2,-7:17.12
4,-1,-7:17.12
-5,2,-7:17.12
-4,3,-7:17.12
1,3,-7:17.12
2,3,-7:17.12
3,3,-7:17.12
1,4,-7:17.12
2,4,-7:17.12
1,5,-7:17.12
2,5,-7:17.12
-3,-5,-6:17.12
-2,-5,-6:17.12
-1,-5,-6:17.12
-2,-4,-6:17.12
-1,-4,-6:17.12
0,-4,-6:17.12
-3,-3,-6:17.12
-2,-3,-6:17.12
4,-3,-6:17.12
5,-3,-6:17.12
6,-3,-6:17.12
3,-2,-6:17.12
4,-2,-6:17.12
5,-2,-6:17.12
6,-2,-6:17.12
6,-1,-6:17.12
2,1,-6:17.12
-6,2,-6:17.12
-5,2,-6:17.12
-4,2,-6:17.12
-3,2,-6:17.12
1,2,-6:17.12
2,2,-6:17.12
2,3,-6:17.12
3,3,-6:17.12
1,4,-6:17.12
2,4,-6:17.12
2,5,-6:17.12
-2,-5,-5:17.12
-3,-4,-5:17.12
-2,-4,-5:17.12
-1,-4,-5:17.12
4,-4,-5:17.12
5,-4,-5:17.12
-2,-3,-5:17.12
-1,-3,-5:17.12
2,-3,-5:17.12
3,-3,-5:17.12
4,-3,-5:17.12
5,-3,-5:17.12
-2,-2,-5:17.12
3,-2,-5:17.12
4,-2,-5:17.12
5,-2,-5:17.12
6,-2,-5:17.12
1,1,-5:17.12
2,1,-5:17.12
3,1,-5:17.12
-4,2,-5:17.12
1,2,-5:17.12
2,2,-5:17.12
3,2,-5:17.12
-4,3,-5:17.12
-3,3,-5:17.12
1,3,-5:17.12
2,3,-5:17.12
3,3,-5:17.12
2,4,-5:17.12
2,5,-5:17.12
-2,-4,-4:17.12
-3,-3,-4:17.12
-2,-3,-4:17.12
-1,-3,-4:17.12
3,-3,-4:17.12
4,-3,-4:17.12
-3,-2,-4:17.12
-2,-2,-4:17.12
3,-2,-4:17.12
4,-2,-4:17.12
3,-1,-4:17.12
-3,1,-4:17.12
-5,2,-4:17.12
-4,2,-4:17.12
-3,2,-4:17.12
-2,2,-4:17.12
1,2,-4:17.12
2,2,-4:17.12
3,2,-4:17.12
-5,3,-4:17.12
-4,3,-4:17.12
-3,3,-4:17.12
-2,3,-4:17.12
1,3,-4:17.12
2,3,-4:17.12
3,3,-4:17.12
-3,4,-4:17.12
1,4,-4:17.12
2,4,-4:17.12
3,4,-4:17.12
-1,-5,-3:17.12
0,-5,-3:17.12
-2,-4,-3:17.12
-1,-4,-3:17.12
0,-4,-3:17.12
1,-4,-3:17.12
4,-4,-3:17.12
-3,-3,-3:17.12
-2,-3,-3:17.12
-1,-3,-3:17.12
0,-3,-3:17.12
4,-3,-3:17.12
5,-3,-3:17.12
-3,-2,-3:17.12
-2,-2,-3:17.12
-1,-2,-3:17.12
2,-2,-3:17.12
3,-2,-3:17.12
4,-2,-3:17.12
-3,-1,-3:17.12
-2,-1,-3:17.12
-1,-1,-3:17.12
3,-1,-3:17.12
-2,0,-3:17.12
4,0,-3:17.12
-4,1,-3:17.12
-3,1,-3:17.12
0,1,-3:17.12
1,1,-3:17.12
5,1,-3:17.12
-3,2,-3:17.12
-2,2,-3:17.12
0,2,-3:17.12
1,2,-3:17.12
2,2,-3:17.12
3,2,-3:17.12
4,2,-3:17.12
5,2,-3:17.12
-3,3,-3:17.12
1,3,-3:17.12
2,3,-3:17.12
3,3,-3:17.12
1,4,-3:17.12
2,4,-3:17.12
3,4,-3:17.12
2,5,-3:17.12
-1,-5,-2:17.12
0,-5,-2:17.12
1,-5,-2:17.12
-2,-4,-2:17.12
-1,-4,-2:17.12
0,-4,-2:17.12
1,-4,-2:17.12
2,-4,-2:17.12
3,-4,-2:17.12
4,-4,-2:17.12
-3,-3,-2:17.12
-2,-3,-2:17.12
-1,-3,-2:17.12
0,-3,-2:17.12
1,-3,-2:17.12
2,-3,-2:17.12
3,-3,-2:17.12
4,-3,-2:17.12
5,-3,-2:17.12
-4,-2,-2:17.12
-3,-2,-2:17.12
-2,-2,-2:17.12
-1,-2,-2:17.12
0,-2,-2:17.12
1,-2,-2:17.12
2,-2,-2:17.12
3,-2,-2:17.12
4,-2,-2:17.12
5,-2,-2:17.12
-4,-1,-2:17.12
-3,-1,-2:17.12
-2,-1,-2:17.12
-1,-1,-2:17.12
0,-1,-2:17.12
1,-1,-2:17.12
2,-1,-2:17.12
3,-1,-2:17.12
4,-1,-2:17.12
5,-1,-2:17.12
-4,0,-2:17.12
-3,0,-2:17.12
-2,0,-2:17.12
-1,0,-2:17.12
0,0,-2:17.12
1,0,-2:17.12
2,0,-2:17.12
3,0,-2:17.12
4,0,-2:17.12
5,0,-2:17.12
-4,1,-2:17.12
-3,1,-2:17.12
-2,1,-2:17.12
-1,1,-2:17.12
0,1,-2:17.12
1,1,-2:17.12
2,1,-2:17.12
3,1,-2:17.12
4,1,-2:17.12
5,1,-2:17.12
6,1,-2:17.12
-4,2,-2:17.12
-3,2,-2:17.12
-2,2,-2:17.12
-1,2,-2:17.12
0,2,-2:17.12
1,2,-2:17.12
2,2,-2:17.12
3,2,-2:17.12
4,2,-2:17.12
5,2,-2:17.12
-4,3,-2:17.12
-3,3,-2:17.12
-2,3,-2:17.12
-1,3,-2:17.12
0,3,-2:17.12
1,3,-2:17.12
2,3,-2:17.12
3,3,-2:17.12
4,3,-2:17.12
-3,4,-2:17.12
-2,4,-2:17.12
-1,4,-2:17.12
0,4,-2:17.12
1,4,-2:17.12
2,4,-2:17.12
3,4,-2:17.12
0,5,-2:17.12
1,5,-2:17.12
2,5,-2:17.12
0,-5,-1:17.12
-2,-4,-1:17.12
-1,-4,-1:17.12
0,-4,-1:17.12
1,-4,-1:17.12
2,-4,-1:17.12
3,-4,-1:17.12
-3,-3,-1:17.12
-2,-3,-1:17.12
3,-3,-1:17.12
4,-3,-1:17.12
-4,-2,-1:17.12
-3,-2,-1:17.12
-2,-2,-1:17.12
2,-2,-1:17.12
3,-2,-1:17.12
4,-2,-1:17.12
5,-2,-1:17.12
-4,-1,-1:17.12
-1,-1,-1:17.12
3,-1,-1:17.12
4,-1,-1:17.12
5,-1,-1:17.12
-4,0,-1:17.12
5,0,-1:17.12
-4,1,-1:17.12
2,1,-1:17.12
5,1,-1:17.12
-4,2,-1:17.12
-3,2,-1:17.12
0,2,-1:17.12
1,2,-1:17.12
2,2,-1:17.12
3,2,-1:17.12
4,2,-1:17.12
5,2,-1:17.12
-3,3,-1:17.12
2,3,-1:17.12
3,3,-1:17.12
4,3,-1:17.12
-2,4,-1:17.12
-1,4,-1:17.12
0,4,-1:17.12
2,4,-1:17.12
3,4,-1:17.12
0,5,-1:17.12
1,5,-1:17.12
2,5,-1:17.12
-1,-4,0:17.12
0,-4,0:17.12
1,-4,0:17.12
2,-4,0:17.12
-2,-3,0:17.12
2,-3,0:17.12
3,-3,0:17.12
4,-3,0:17.12
-3,-2,0:17.12
4,-2,0:17.12
-3,-1,0:17.12
4,-1,0:17.12
-4,0,0:17.12
4,0,0:17.12
5,0,0:17.12
-4,1,0:17.12
-3,1,0:17.12
4,1,0:17.12
5,1,0:17.12
-3,2,0:17.12
4,2,0:17.12
-3,3,0:17.12
-2,3,0:17.12
3,3,0:17.12
4,3,0:17.12
-2,4,0:17.12
-1,4,0:17.12
0,4,0:17.12
1,4,0:17.12
2,4,0:17.12
3,4,0:17.12
0,-4,1:17.12
1,-4,1:17.12
-2,-3,1:17.12
-1,-3,1:17.12
0,-3,1:17.12
1,-3,1:17.12
2,-3,1:17.12
3,-3,1:17.12
-3,-2,1:17.12
-2,-2,1:17.12
3,-2,1:17.12
4,-2,1:17.12
-3,-1,1:17.12
4,-1,1:17.12
-3,0,1:17.12
4,0,1:17.12
-3,1,1:17.12
4,1,1:17.12
-3,2,1:17.12
3,2,1:17.12
4,2,1:17.12
-2,3,1:17.12
2,3,1:17.12
3,3,1:17.12
-1,4,1:17.12
0,4,1:17.12
1,4,1:17.12
2,4,1:17.12
-1,-3,2:17.12
0,-3,2:17.12
1,-3,2:17.12
2,-3,2:17.12
-2,-2,2:17.12
2,-2,2:17.12
3,-2,2:17.12
-3,-1,2:17.12
3,-1,2:17.12
-3,0,2:17.12
4,0,2:17.12
-3,1,2:17.12
3,1,2:17.12
4,1,2:17.12
-3,2,2:17.12
-2,2,2:17.12
3,2,2:17.12
-2,3,2:17.12
-1,3,2:17.12
0,3,2:17.12
1,3,2:17.12
2,3,2:17.12
3,3,2:17.12
-1,4,2:17.12
0,4,2:17.12
1,4,2:17.12
0,-3,3:17.12
1,-3,3:17.12
-2,-2,3:17.12
-1,-2,3:17.12
0,-2,3:17.12
1,-2,3:17.12
2,-2,3:17.12
-2,-1,3:17.12
2,-1,3:17.12
3,-1,3:17.12
-3,0,3:17.12
-2,0,3:17.12
3,0,3:17.12
-3,1,3:17.12
3,1,3:17.12
-2,2,3:17.12
2,2,3:17.12
3,2,3:17.12
-2,3,3:17.12
-1,3,3:17.12
0,3,3:17.12
1,3,3:17.12
2,3,3:17.12
-2,-2,4:17.12
-1,-2,4:17.12
0,-2,4:17.12
1,-2,4:17.12
2,-2,4:17.12
-2,-1,4:17.12
2,-1,4:17.12
3,-1,4:17.12
-2,0,4:17.12
3,0,4:17.12
-3,1,4:17.12
-2,1,4:17.12
3,1,4:17.12
-2,2,4:17.12
-1,2,4:17.12
3,2,4:17.12
-1,3,4:17.12
0,3,4:17.12
1,3,4:17.12
2,3,4:17.12
3,3,4:17.12
0,4,4:17.12
-1,-2,5:17.12
0,-2,5:17.12
1,-2,5:17.12
2,-2,5:17.12
-2,-1,5:17.12
-1,-1,5:17.12
2,-1,5:17.12
-2,0,5:17.12
-1,0,5:17.12
3,0,5:17.12
4,0,5:17.12
-2,1,5:17.12
3,1,5:17.12
-2,2,5:17.12
-1,2,5:17.12
3,2,5:17.12
-1,3,5:17.12
0,3,5:17.12
1,3,5:17.12
2,3,5:17.12
3,3,5:17.12
0,4,5:17.12
1,-12,6:18.5
2,-11,6:18.5
2,-10,6:18.5
-12,-3,6:18.5
-11,-3,6:18.5
-11,-2,6:18.5
-10,-2,6:18.5
1,-2,6:17.12
2,-2,6:17.12
-10,-1,6:18.5
-9,-1,6:18.5
-2,-1,6:17.12
-1,-1,6:17.12
0,-1,6:17.12
1,-1,6:17.12
2,-1,6:17.12
-11,0,6:18.5
-10,0,6:18.5
-9,0,6:18.5
-1,0,6:17.12
3,0,6:17.12
4,0,6:17.12
-13,1,6:18.5
-12,1,6:18.5
-11,1,6:18.5
-2,1,6:17.12
-1,1,6:17.12
3,1,6:17.12
4,1,6:17.12
-2,2,6:17.12
-1,2,6:17.12
3,2,6:17.12
12,2,6:18.5
-1,3,6:17.12
0,3,6:17.12
1,3,6:17.12
2,3,6:17.12
3,3,6:17.12
4,3,6:17.12
12,3,6:18.5
0,4,6:17.12
1,4,6:17.12
-1,11,6:18.13
0,11,6:18.13
-2,12,6:18.13
0,12,6:18.13
1,12,6:18.13
-3,13,6:18.5
-2,13,6:18.5
1,13,6:18.5
-3,14,6:18.5
1,14,6:18.5
-1,-16,7:18.5
0,-16,7:18.5
-1,-15,7:18.5
0,-15,7:18.5
-1,-14,7:18.5
0,-14,7:18.5
6,-14,7:18.5
0,-13,7:18.5
5,-13,7:18.5
6,-13,7:18.5
0,-12,7:18.5
1,-12,7:18.5
5,-12,7:18.5
0,-11,7:18.5
1,-11,7:18.5
4,-11,7:18.5
5,-11,7:18.5
1,-10,7:18.13
2,-10,7:18.13
4,-10,7:18.13
1,-9,7:18.13
2,-9,7:18.13
3,-9,7:18.13
4,-9,7:18.13
3,-8,7:18.13
10,-8,7:18.14
2,-7,7:18.13
3,-7,7:18.13
10,-7,7:18.14
-14,-6,7:18.5
2,-6,7:18.13
10,-6,7:18.14
-14,-5,7:18.5
-13,-5,7:18.5
-13,-4,7:18.5
-12,-4,7:18.5
-11,-4,7:18.5
-11,-3,7:18.5
-10,-3,7:18.13
-9,-3,7:18.13
-10,-2,7:18.13
-9,-2,7:18.13
-8,-2,7:18.13
1,-2,7:17.12
2,-2,7:17.12
-6,-1,7:18.13
-2,-1,7:17.12
-1,-1,7:17.12
0,-1,7:17.12
1,-1,7:17.12
2,-1,7:17.12
4,-1,7:17.12
-9,0,7:18.13
-8,0,7:18.13
-7,0,7:18.13
-6,0,7:18.13
-5,0,7:18.13
-1,0,7:17.12
2,0,7:17.12
3,0,7:17.12
4,0,7:17.12
13,0,7:18.5
14,0,7:18.5
15,0,7:18.5
16,0,7:18.5
-12,1,7:18.5
-11,1,7:18.5
-10,1,7:18.13
-9,1,7:18.13
-8,1,7:18.13
-7,1,7:18.13
-1,1,7:17.12
4,1,7:17.12
10,1,7:18.13
11,1,7:18.13
12,1,7:18.13
13,1,7:18.5
14,1,7:18.5
15,1,7:18.5
-14,2,7:18.5
-13,2,7:18.5
-12,2,7:18.5
-11,2,7:18.5
-10,2,7:18.13
-2,2,7:17.12
-1,2,7:17.12
3,2,7:17.12
4,2,7:17.12
8,2,7:18.13
9,2,7:18.13
10,2,7:18.13
11,2,7:18.13
12,2,7:18.13
-15,3,7:18.5
-14,3,7:18.5
-2,3,7:17.12
-1,3,7:17.12
0,3,7:17.12
2,3,7:17.12
3,3,7:17.12
4,3,7:17.12
11,3,7:18.13
0,4,7:17.12
1,4,7:17.12
2,4,7:17.12
4,4,7:17.12
11,4,7:18.13
12,4,7:18.13
13,4,7:18.5
1,5,7:17.12
2,5,7:17.12
12,5,7:18.13
13,5,7:18.5
14,5,7:18.5
15,6,7:18.5
16,6,7:18.5
0,7,7:18.13
16,7,7:18.5
17,7,7:18.5
0,8,7:18.13
1,8,7:18.13
-1,9,7:18.13
0,9,7:18.13
-2,10,7:18.13
-1,10,7:18.13
-2,11,7:18.13
-1,11,7:18.13
1,11,7:18.13
-3,12,7:18.13
-2,12,7:18.13
1,12,7:18.13
2,12,7:18.13
-4,13,7:18.5
-3,13,7:18.13
1,13,7:18.13
2,13,7:18.13
-4,14,7:18.5
-3,14,7:18.5
2,14,7:18.5
-5,15,7:18.5
-4,15,7:18.5
2,15,7:18.5
3,15,7:18.5
-5,16,7:18.5
2,16,7:18.5
2,17,7:18.5
3,17,7:18.5
-3,-16,8:18.5
-2,-16,8:18.5
-2,-15,8:18.5
-1,-15,8:18.5
7,-15,8:18.5
-2,-14,8:18.5
-1,-14,8:18.5
7,-14,8:18.5
-2,-13,8:18.5
-1,-13,8:18.5
6,-13,8:18.5
7,-13,8:18.5
-1,-12,8:18.5
0,-12,8:18.5
6,-12,8:18.5
-1,-11,8:18.13
0,-11,8:18.13
5,-11,8:18.13
6,-11,8:18.13
-1,-10,8:18.13
0,-10,8:18.13
5,-10,8:18.13
0,-9,8:18.13
1,-9,8:18.13
4,-9,8:18.13
5,-9,8:18.13
0,-8,8:18.13
1,-8,8:18.13
4,-8,8:18.13
10,-8,8:18.14
11,-8,8:18.14
-15,-7,8:18.5
-14,-7,8:18.5
0,-7,8:18.13
1,-7,8:18.13
3,-7,8:18.13
4,-7,8:18.13
10,-7,8:18.14
11,-7,8:18.14
-14,-6,8:18.5
-13,-6,8:18.5
-12,-6,8:18.5
1,-6,8:18.13
2,-6,8:18.13
3,-6,8:18.13
10,-6,8:18.14
-13,-5,8:18.5
-12,-5,8:18.5
-11,-5,8:18.5
1,-5,8:18.13
2,-5,8:18.13
3,-5,8:18.13
9,-5,8:18.14
10,-5,8:18.14
-11,-4,8:18.13
-10,-4,8:18.13
-9,-4,8:18.13
1,-4,8:18.13
2,-4,8:18.13
10,-4,8:18.14
11,-4,8:18.14
12,-4,8:18.14
13,-4,8:18.14
-9,-3,8:18.13
-8,-3,8:18.13
2,-3,8:17.12
12,-3,8:18.14
-8,-2,8:18.13
-7,-2,8:18.13
-6,-2,8:18.13
1,-2,8:17.12
2,-2,8:17.12
17,-2,8:18.5
-6,-1,8:18.13
-5,-1,8:18.13
-4,-1,8:18.13
-1,-1,8:17.12
0,-1,8:17.12
1,-1,8:17.12
2,-1,8:17.12
4,-1,8:17.12
5,-1,8:17.12
13,-1,8:18.13
14,-1,8:18.5
15,-1,8:18.5
16,-1,8:18.5
17,-1,8:18.5
-5,0,8:18.13
-4,0,8:18.13
-3,0,8:18.13
-2,0,8:17.12
-1,0,8:17.12
2,0,8:17.12
3,0,8:17.12
4,0,8:17.12
9,0,8:18.13
10,0,8:18.13
11,0,8:18.13
12,0,8:18.13
13,0,8:18.13
14,0,8:18.5
-8,1,8:18.13
-7,1,8:18.13
-6,1,8:18.13
-5,1,8:18.13
-4,1,8:18.13
-3,1,8:18.13
-1,1,8:17.12
0,1,8:17.12
4,1,8:17.12
6,1,8:18.13
7,1,8:18.13
8,1,8:18.13
9,1,8:18.13
10,1,8:18.13
11,1,8:18.13
-11,2,8:18.13
-10,2,8:18.13
-9,2,8:18.13
-8,2,8:18.13
-7,2,8:18.13
-6,2,8:18.13
-1,2,8:17.12
0,2,8:17.12
3,2,8:17.12
4,2,8:17.12
5,2,8:18.13
6,2,8:18.13
7,2,8:18.13
8,2,8:18.13
-15,3,8:18.5
-14,3,8:18.5
-13,3,8:18.5
-12,3,8:18.5
-11,3,8:18.13
-10,3,8:18.13
-2,3,8:17.12
-1,3,8:17.12
0,3,8:17.12
2,3,8:17.12
3,3,8:17.12
4,3,8:17.12
5,3,8:17.12
7,3,8:18.13
8,3,8:18.13
-14,4,8:18.5
-13,4,8:18.5
-2,4,8:17.12
1,4,8:17.12
2,4,8:17.12
5,4,8:17.12
8,4,8:18.13
9,4,8:18.13
10,4,8:18.13
11,4,8:18.13
0,5,8:18.13
1,5,8:17.12
2,5,8:17.12
10,5,8:18.13
11,5,8:18.13
12,5,8:18.13
0,6,8:18.13
1,6,8:18.13
2,6,8:17.12
12,6,8:18.13
13,6,8:18.13
14,6,8:18.5
-1,7,8:18.13
0,7,8:18.13
1,7,8:18.13
14,7,8:18.5
15,7,8:18.5
16,7,8:18.5
-2,8,8:18.13
-1,8,8:18.13
1,8,8:18.13
2,8,8:18.13
16,8,8:18.5
-2,9,8:18.13
-1,9,8:18.13
1,9,8:18.13
2,9,8:18.13
17,9,8:18.5
-3,10,8:18.13
-2,10,8:18.13
2,10,8:18.13
-4,11,8:18.13
-3,11,8:18.13
2,11,8:18.13
3,11,8:18.13
-4,12,8:18.13
-3,12,8:18.13
2,12,8:18.13
3,12,8:18.13
-5,13,8:18.5
-4,13,8:18.5
2,13,8:18.13
3,13,8:18.13
-5,14,8:18.5
3,14,8:18.13
4,14,8:18.13
-6,15,8:18.5
-5,15,8:18.5
3,15,8:18.5
4,15,8:18.5
-6,16,8:18.5
4,16,8:18.5
4,17,8:18.5
4,18,8:18.5
-4,-16,9:18.5
-3,-16,9:18.5
-4,-15,9:18.5
-3,-15,9:18.5
-3,-14,9:18.5
-2,-14,9:18.5
8,-14,9:18.5
-3,-13,9:18.5
-2,-13,9:18.5
7,-13,9:18.5
8,-13,9:18.5
-3,-12,9:18.13
-2,-12,9:18.13
7,-12,9:18.5
-2,-11,9:18.13
-1,-11,9:18.13
6,-11,9:18.13
7,-11,9:18.5
-2,-10,9:18.13
-1,-10,9:18.13
6,-10,9:18.13
-15,-9,9:18.5
-2,-9,9:18.13
-1,-9,9:18.13
5,-9,9:18.13
6,-9,9:18.13
-15,-8,9:18.5
-14,-8,9:18.5
-1,-8,9:18.13
0,-8,9:18.13
5,-8,9:18.13
10,-8,9:18.14
-14,-7,9:18.5
-13,-7,9:18.5
-12,-7,9:18.5
-1,-7,9:18.13
0,-7,9:18.13
4,-7,9:18.13
5,-7,9:18.13
12,-7,9:18.14
-12,-6,9:18.5
-11,-6,9:18.5
-10,-6,9:18.5
-1,-6,9:18.13
0,-6,9:18.13
4,-6,9:18.13
10,-6,9:18.14
12,-6,9:18.14
-11,-5,9:18.5
-10,-5,9:18.5
-9,-5,9:18.5
0,-5,9:18.13
1,-5,9:18.13
3,-5,9:18.13
4,-5,9:18.13
9,-5,9:18.14
10,-5,9:18.14
13,-5,9:18.14
-9,-4,9:18.13
-8,-4,9:18.13
-7,-4,9:18.13
0,-4,9:18.13
1,-4,9:18.13
2,-4,9:17.12
3,-4,9:18.13
9,-4,9:18.14
10,-4,9:18.14
11,-4,9:18.14
12,-4,9:18.14
-8,-3,9:18.13
-7,-3,9:18.13
-6,-3,9:18.13
0,-3,9:18.13
1,-3,9:18.13
2,-3,9:17.12
3,-3,9:18.13
12,-3,9:18.14
15,-3,9:18.5
16,-3,9:18.5
-6,-2,9:18.13
-5,-2,9:18.13
-4,-2,9:18.13
1,-2,9:17.12
2,-2,9:18.13
5,-2,9:17.12
12,-2,9:18.13
13,-2,9:18.13
14,-2,9:18.13
15,-2,9:18.5
16,-2,9:18.5
-4,-1,9:18.13
-3,-1,9:18.13
1,-1,9:17.12
2,-1,9:17.12
3,-1,9:17.12
4,-1,9:17.12
5,-1,9:17.12
8,-1,9:18.13
9,-1,9:18.13
10,-1,9:18.13
11,-1,9:18.13
12,-1,9:18.13
13,-1,9:18.13
14,-1,9:18.13
-3,0,9:17.12
-2,0,9:17.12
-1,0,9:17.12
0,0,9:17.12
1,0,9:17.12
2,0,9:17.12
3,0,9:17.12
4,0,9:17.12
5,0,9:17.12
6,0,9:18.13
7,0,9:18.13
8,0,9:18.13
9,0,9:18.13
10,0,9:18.13
-4,1,9:18.13
-3,1,9:18.13
-2,1,9:18.13
-1,1,9:17.12
0,1,9:17.12
1,1,9:17.12
2,1,9:17.12
3,1,9:17.12
4,1,9:18.13
5,1,9:18.13
6,1,9:18.13
7,1,9:18.13
-7,2,9:18.13
-6,2,9:18.13
-5,2,9:18.13
-4,2,9:18.13
-3,2,9:18.13
-2,2,9:18.13
-1,2,9:17.12
0,2,9:17.12
1,2,9:17.12
2,2,9:17.12
3,2,9:17.12
4,2,9:17.12
5,2,9:17.12
6,2,9:17.12
-11,3,9:18.13
-10,3,9:18.13
-9,3,9:18.13
-8,3,9:18.13
-7,3,9:18.13
-6,3,9:18.13
-2,3,9:17.12
-1,3,9:17.12
0,3,9:17.12
1,3,9:17.12
2,3,9:17.12
3,3,9:17.12
4,3,9:17.12
5,3,9:17.12
6,3,9:17.12
7,3,9:18.13
-14,4,9:18.5
-13,4,9:18.5
-12,4,9:18.13
-11,4,9:18.13
-10,4,9:18.13
-9,4,9:18.13
-3,4,9:17.12
-2,4,9:17.12
-1,4,9:17.12
0,4,9:18.13
1,4,9:17.12
2,4,9:17.12
6,4,9:18.13
8,4,9:18.13
9,4,9:18.13
-14,5,9:18.5
-13,5,9:18.13
-12,5,9:18.13
-4,5,9:17.12
-3,5,9:17.12
-2,5,9:17.12
-1,5,9:18.13
0,5,9:18.13
1,5,9:17.12
2,5,9:17.12
8,5,9:18.13
9,5,9:18.13
10,5,9:18.13
-2,6,9:18.13
-1,6,9:18.13
1,6,9:17.12
2,6,9:17.12
10,6,9:18.13
11,6,9:18.13
12,6,9:18.13
-2,7,9:18.13
-1,7,9:18.13
2,7,9:18.13
3,7,9:18.13
11,7,9:18.13
12,7,9:18.13
13,7,9:18.13
14,7,9:18.13
-3,8,9:18.13
-2,8,9:18.13
2,8,9:18.13
3,8,9:18.13
13,8,9:18.5
14,8,9:18.5
15,8,9:18.5
-3,9,9:18.13
2,9,9:18.13
3,9,9:18.13
15,9,9:18.5
16,9,9:18.5
17,9,9:18.5
-4,10,9:18.13
-3,10,9:18.13
3,10,9:18.13
-5,11,9:18.13
-4,11,9:18.13
3,11,9:18.13
4,11,9:18.13
-5,12,9:18.13
-4,12,9:18.13
3,12,9:18.13
-6,13,9:18.13
-5,13,9:18.13
4,13,9:18.13
-7,14,9:18.5
-6,14,9:18.5
4,14,9:18.13
5,14,9:18.13
-7,15,9:18.5
-6,15,9:18.5
4,15,9:18.13
5,15,9:18.13
4,16,9:18.5
5,16,9:18.5
5,17,9:18.5
6,17,9:18.5
-5,-17,10:18.5
-5,-16,10:18.5
-5,-15,10:18.5
-4,-15,10:18.5
-5,-14,10:18.5
-4,-14,10:18.5
-4,-13,10:18.5
8,-13,10:18.5
-4,-12,10:18.5
-3,-12,10:18.13
8,-12,10:18.5
-4,-11,10:18.5
-3,-11,10:18.13
7,-11,10:18.5
8,-11,10:18.5
-3,-10,10:18.13
7,-10,10:18.13
-15,-9,10:18.5
-14,-9,10:18.5
-13,-9,10:18.5
-3,-9,10:18.13
-2,-9,10:18.13
6,-9,10:18.13
7,-9,10:18.13
-14,-8,10:18.5
-13,-8,10:18.5
-12,-8,10:18.5
-3,-8,10:18.13
-2,-8,10:18.13
6,-8,10:18.13
11,-8,10:18.14
-12,-7,10:18.5
-11,-7,10:18.5
-10,-7,10:18.5
-3,-7,10:18.13
-2,-7,10:18.13
5,-7,10:18.13
6,-7,10:18.13
11,-7,10:18.14
-11,-6,10:18.5
-10,-6,10:18.5
-9,-6,10:18.5
-8,-6,10:18.5
-2,-6,10:18.13
-1,-6,10:18.13
5,-6,10:18.13
11,-6,10:18.14
-9,-5,10:18.5
-8,-5,10:18.5
-7,-5,10:18.5
-2,-5,10:18.13
-1,-5,10:18.13
2,-5,10:17.12
4,-5,10:18.13
5,-5,10:18.13
11,-5,10:18.14
13,-5,10:18.14
-7,-4,10:18.13
-6,-4,10:18.13
-5,-4,10:18.13
-2,-4,10:18.13
-1,-4,10:18.13
1,-4,10:17.12
2,-4,10:17.12
4,-4,10:18.13
11,-4,10:18.14
12,-4,10:18.14
15,-4,10:18.5
17,-4,10:18.5
-6,-3,10:18.13
-5,-3,10:18.13
-4,-3,10:18.13
-1,-3,10:18.13
0,-3,10:18.13
1,-3,10:17.12
2,-3,10:17.12
3,-3,10:18.13
4,-3,10:18.13
6,-3,10:17.12
11,-3,10:18.13
12,-3,10:18.13
13,-3,10:18.13
14,-3,10:18.5
15,-3,10:18.5
16,-3,10:18.5
-4,-2,10:18.13
-3,-2,10:18.13
-2,-2,10:18.13
-1,-2,10:18.13
1,-2,10:17.12
2,-2,10:17.12
3,-2,10:18.13
4,-2,10:17.12
5,-2,10:17.12
6,-2,10:17.12
8,-2,10:18.13
9,-2,10:18.13
10,-2,10:18.13
11,-2,10:18.13
12,-2,10:18.13
13,-2,10:18.13
-3,-1,10:18.13
-2,-1,10:18.13
-1,-1,10:18.13
0,-1,10:18.13
1,-1,10:17.12
2,-1,10:18.13
3,-1,10:18.13
4,-1,10:17.12
5,-1,10:17.12
6,-1,10:18.13
7,-1,10:18.13
8,-1,10:18.13
9,-1,10:18.13
10,-1,10:18.13
-4,0,10:17.12
-3,0,10:17.12
-2,0,10:17.12
-1,0,10:17.12
0,0,10:18.13
2,0,10:18.13
3,0,10:18.13
4,0,10:18.13
5,0,10:18.13
6,0,10:18.13
-3,1,10:17.12
-2,1,10:17.12
-1,1,10:17.12
3,1,10:18.13
-3,2,10:18.13
-2,2,10:18.13
-1,2,10:18.13
0,2,10:18.13
2,2,10:18.13
5,2,10:17.12
6,2,10:17.12
7,2,10:17.12
-7,3,10:18.13
-6,3,10:18.13
-5,3,10:18.13
-4,3,10:18.13
-3,3,10:18.13
-2,3,10:18.13
-1,3,10:18.13
0,3,10:18.13
2,3,10:18.13
3,3,10:18.13
4,3,10:18.13
5,3,10:17.12
6,3,10:17.12
7,3,10:17.12
-10,4,10:18.13
-9,4,10:18.13
-8,4,10:18.13
-7,4,10:18.13
-6,4,10:18.13
-5,4,10:18.13
-4,4,10:18.13
-3,4,10:17.12
-2,4,10:17.12
-1,4,10:18.13
2,4,10:18.13
3,4,10:18.13
4,4,10:18.13
5,4,10:18.13
6,4,10:18.13
-13,5,10:18.13
-12,5,10:18.13
-11,5,10:18.13
-10,5,10:18.13
-9,5,10:18.13
-8,5,10:18.13
-5,5,10:17.12
-4,5,10:17.12
-3,5,10:17.12
-2,5,10:18.13
-1,5,10:18.13
1,5,10:17.12
2,5,10:17.12
3,5,10:18.13
6,5,10:18.13
7,5,10:18.13
8,5,10:18.13
-16,6,10:18.5
-15,6,10:18.5
-14,6,10:18.5
-13,6,10:18.13
-12,6,10:18.13
-5,6,10:17.12
-4,6,10:17.12
-3,6,10:18.13
-2,6,10:18.13
1,6,10:17.12
2,6,10:17.12
3,6,10:18.13
8,6,10:18.13
9,6,10:18.13
10,6,10:18.13
-15,7,10:18.5
-3,7,10:18.13
1,7,10:17.12
2,7,10:17.12
3,7,10:18.13
4,7,10:18.13
9,7,10:18.13
10,7,10:18.13
11,7,10:18.13
12,7,10:18.13
-4,8,10:18.13
-3,8,10:18.13
2,8,10:17.12
3,8,10:18.13
4,8,10:18.13
11,8,10:18.5
12,8,10:18.5
13,8,10:18.5
-5,9,10:18.13
-4,9,10:18.13
4,9,10:18.13
13,9,10:18.5
14,9,10:18.5
15,9,10:18.5
-5,10,10:18.13
-4,10,10:18.13
5,10,10:18.13
14,10,10:18.5
15,10,10:18.5
16,10,10:18.5
-6,11,10:18.13
-5,11,10:18.13
4,11,10:18.13
5,11,10:18.13
16,11,10:18.5
17,11,10:18.5
-6,12,10:18.13
5,12,10:18.13
-7,13,10:18.13
-6,13,10:18.13
5,13,10:18.13
6,13,10:18.13
-8,14,10:18.5
-7,14,10:18.5
5,14,10:18.13
6,14,10:18.5
-8,15,10:18.5
5,15,10:18.13
6,15,10:18.5
-9,16,10:18.5
-8,16,10:18.5
6,16,10:18.5
6,17,10:18.5
7,17,10:18.13
6,18,10:18.5
7,18,10:18.13
-7,-16,11:18.5
-7,-15,11:18.5
-6,-15,11:18.5
-5,-14,11:18.5
10,-14,11:18.5
-6,-13,11:18.5
-5,-13,11:18.5
9,-13,11:18.5
10,-13,11:18.5
-6,-12,11:18.5
-5,-12,11:18.5
9,-12,11:18.5
-5,-11,11:18.5
-4,-11,11:18.5
8,-11,11:18.5
9,-11,11:18.5
-14,-10,11:18.5
-5,-10,11:18.5
-4,-10,11:18.5
8,-10,11:18.13
-13,-9,11:18.5
-12,-9,11:18.5
-11,-9,11:18.5
-5,-9,11:18.5
-4,-9,11:18.5
7,-9,11:18.13
8,-9,11:18.13
-12,-8,11:18.5
-11,-8,11:18.5
-10,-8,11:18.5
-4,-8,11:18.5
-3,-8,11:18.13
7,-8,11:18.13
-10,-7,11:18.5
-9,-7,11:18.5
-8,-7,11:18.5
-4,-7,11:18.5
-3,-7,11:18.13
6,-7,11:18.13
7,-7,11:18.13
-9,-6,11:18.5
-8,-6,11:18.5
-7,-6,11:18.5
-4,-6,11:18.5
-3,-6,11:18.13
1,-6,11:17.12
2,-6,11:17.12
6,-6,11:18.13
11,-6,11:18.14
13,-6,11:18.14
14,-6,11:18.6
-7,-5,11:18.5
-6,-5,11:18.13
-5,-5,11:18.13
-3,-5,11:18.13
-2,-5,11:18.13
1,-5,11:17.12
2,-5,11:17.12
5,-5,11:18.13
6,-5,11:18.13
11,-5,11:18.14
13,-5,11:18.14
14,-5,11:18.5
15,-5,11:18.5
16,-5,11:18.5
17,-5,11:18.5
-5,-4,11:18.13
-3,-4,11:18.13
-2,-4,11:18.13
1,-4,11:17.12
2,-4,11:17.12
5,-4,11:18.13
6,-4,11:17.12
7,-4,11:17.12
10,-4,11:18.13
11,-4,11:18.13
12,-4,11:18.13
13,-4,11:18.13
14,-4,11:18.5
15,-4,11:18.5
-4,-3,11:18.13
-3,-3,11:18.13
-2,-3,11:18.13
-1,-3,11:18.13
1,-3,11:17.12
2,-3,11:17.12
4,-3,11:18.13
5,-3,11:18.13
6,-3,11:17.12
7,-3,11:17.12
8,-3,11:18.13
9,-3,11:18.13
10,-3,11:18.13
11,-3,11:18.13
12,-3,11:18.13
-3,-2,11:18.13
-2,-2,11:18.13
-1,-2,11:18.13
0,-2,11:18.13
1,-2,11:18.13
2,-2,11:18.13
3,-2,11:18.13
4,-2,11:18.13
5,-2,11:18.13
6,-2,11:18.13
7,-2,11:18.13
8,-2,11:18.13
9,-2,11:18.13
-2,-1,11:18.13
-1,-1,11:18.13
0,-1,11:18.13
1,-1,11:18.13
2,-1,11:18.13
3,-1,11:18.13
4,-1,11:18.13
5,-1,11:18.13
-6,0,11:17.12
-5,0,11:17.12
-4,0,11:17.12
-3,0,11:17.12
-2,0,11:18.13
-1,0,11:18.13
3,0,11:18.13
4,0,11:18.13
-5,1,11:17.12
-4,1,11:17.12
-3,1,11:17.12
-2,1,11:18.13
-1,1,11:18.13
3,1,11:18.13
4,1,11:18.13
-2,2,11:18.13
-1,2,11:18.13
3,2,11:18.13
4,2,11:18.13
6,2,11:17.12
7,2,11:17.12
8,2,11:17.12
-3,3,11:18.13
-2,3,11:18.13
-1,3,11:18.13
0,3,11:18.13
1,3,11:18.13
2,3,11:18.13
3,3,11:18.13
4,3,11:18.13
6,3,11:17.12
7,3,11:17.12
8,3,11:17.12
-6,4,11:18.13
-5,4,11:18.13
-4,4,11:18.13
-3,4,11:18.13
-2,4,11:18.13
-1,4,11:18.13
0,4,11:18.13
1,4,11:18.13
2,4,11:18.13
3,4,11:18.13
4,4,11:18.13
-9,5,11:18.13
-8,5,11:18.13
-7,5,11:18.13
-6,5,11:18.13
-5,5,11:18.13
-4,5,11:17.12
-3,5,11:18.13
-2,5,11:18.13
3,5,11:18.13
4,5,11:18.13
5,5,11:18.13
6,5,11:18.13
-12,6,11:18.13
-11,6,11:18.13
-10,6,11:18.13
-9,6,11:18.13
-8,6,11:18.13
-6,6,11:17.12
-5,6,11:17.12
-4,6,11:17.12
-3,6,11:18.13
1,6,11:17.12
2,6,11:17.12
4,6,11:18.13
5,6,11:18.13
6,6,11:18.13
7,6,11:18.13
8,6,11:18.13
-15,7,11:18.5
-13,7,11:18.13
-12,7,11:18.13
-11,7,11:18.13
-6,7,11:17.12
-5,7,11:17.12
-4,7,11:18.13
1,7,11:17.12
2,7,11:17.12
4,7,11:18.13
5,7,11:18.13
7,7,11:18.13
8,7,11:18.13
9,7,11:18.13
10,7,11:18.13
-5,8,11:18.13
-4,8,11:18.13
1,8,11:17.12
2,8,11:17.12
4,8,11:18.13
5,8,11:18.13
9,8,11:18.13
10,8,11:18.5
11,8,11:18.5
-6,9,11:18.13
-5,9,11:18.13
1,9,11:17.12
5,9,11:18.13
6,9,11:18.13
11,9,11:18.5
12,9,11:18.5
13,9,11:18.5
-6,10,11:18.13
5,10,11:18.13
6,10,11:18.13
12,10,11:18.5
13,10,11:18.5
14,10,11:18.5
15,10,11:18.5
-7,11,11:18.13
-6,11,11:18.13
5,11,11:18.13
6,11,11:18.13
14,11,11:18.5
15,11,11:18.5
16,11,11:18.5
-8,12,11:18.13
-7,12,11:18.13
6,12,11:18.13
-8,13,11:18.13
-7,13,11:18.13
6,13,11:18.13
7,13,11:18.5
-9,14,11:18.5
-8,14,11:18.5
6,14,11:18.5
7,14,11:18.5
-9,15,11:18.5
7,15,11:18.5
7,16,11:18.5
7,17,11:18.13
8,17,11:18.13
-7,-16,12:18.5
12,-16,12:18.5
-7,-15,12:18.5
12,-15,12:18.5
-7,-14,12:18.5
-7,-13,12:18.5
-6,-13,12:18.5
10,-13,12:18.5
11,-13,12:18.5
-7,-12,12:18.5
-6,-12,12:18.5
10,-12,12:18.5
-7,-11,12:18.5
-6,-11,12:18.5
9,-11,12:18.5
10,-11,12:18.5
-13,-10,12:18.5
-12,-10,12:18.5
-11,-10,12:18.5
-6,-10,12:18.5
-5,-10,12:18.5
9,-10,12:18.13
-11,-9,12:18.5
-10,-9,12:18.5
-9,-9,12:18.5
-6,-9,12:18.5
-5,-9,12:18.5
8,-9,12:18.13
9,-9,12:18.13
-10,-8,12:18.5
-9,-8,12:18.5
-8,-8,12:18.5
-6,-8,12:18.5
-5,-8,12:18.5
8,-8,12:18.13
-8,-7,12:18.5
-7,-7,12:18.5
-6,-7,12:18.5
-5,-7,12:18.5
-4,-7,12:18.5
1,-7,12:17.12
2,-7,12:17.12
7,-7,12:18.13
8,-7,12:18.13
18,-7,12:18.5
-7,-6,12:18.5
-6,-6,12:18.5
-4,-6,12:18.5
1,-6,12:17.12
2,-6,12:17.12
7,-6,12:18.13
13,-6,12:18.13
14,-6,12:18.5
15,-6,12:18.5
16,-6,12:18.5
-5,-5,12:18.13
-4,-5,12:18.13
-3,-5,12:18.13
-2,-5,12:18.13
1,-5,12:17.12
2,-5,12:17.12
6,-5,12:18.13
7,-5,12:18.13
8,-5,12:17.12
10,-5,12:18.13
11,-5,12:18.13
12,-5,12:18.13
13,-5,12:18.13
14,-5,12:18.5
15,-5,12:18.5
-5,-4,12:18.13
-3,-4,12:18.13
-2,-4,12:18.13
-1,-4,12:18.13
0,-4,12:18.13
1,-4,12:17.12
2,-4,12:17.12
3,-4,12:18.13
4,-4,12:18.13
5,-4,12:18.13
6,-4,12:18.13
7,-4,12:17.12
8,-4,12:18.13
9,-4,12:18.13
10,-4,12:18.13
11,-4,12:18.13
12,-4,12:18.13
-5,-3,12:18.13
-4,-3,12:18.13
-3,-3,12:18.13
-2,-3,12:18.13
-1,-3,12:18.13
0,-3,12:18.13
1,-3,12:18.13
2,-3,12:18.13
3,-3,12:18.13
4,-3,12:18.13
5,-3,12:18.13
6,-3,12:18.13
7,-3,12:18.13
8,-3,12:18.13
-4,-2,12:18.13
-3,-2,12:18.13
-1,-2,12:18.13
0,-2,12:18.13
1,-2,12:18.13
2,-2,12:18.13
3,-2,12:18.13
4,-2,12:18.13
5,-2,12:18.13
6,-2,12:18.13
-4,-1,12:18.13
-3,-1,12:18.13
-2,-1,12:18.13
-1,-1,12:18.13
0,-1,12:18.13
2,-1,12:18.13
3,-1,12:18.13
4,-1,12:18.13
5,-1,12:18.13
6,-1,12:18.13
-7,0,12:17.12
-6,0,12:17.12
-5,0,12:17.12
-4,0,12:18.13
-3,0,12:18.13
-2,0,12:18.13
3,0,12:18.13
4,0,12:18.13
5,0,12:18.13
6,0,12:18.13
-6,1,12:17.12
-5,1,12:17.12
-4,1,12:18.13
-3,1,12:18.13
-2,1,12:18.13
4,1,12:18.13
5,1,12:18.13
6,1,12:18.13
-4,2,12:18.13
-3,2,12:18.13
-2,2,12:18.13
4,2,12:18.13
5,2,12:18.13
6,2,12:18.13
7,2,12:17.12
8,2,12:17.12
9,2,12:17.12
-5,3,12:18.13
-4,3,12:18.13
-3,3,12:18.13
-2,3,12:18.13
-1,3,12:18.13
3,3,12:18.13
4,3,12:18.13
5,3,12:18.13
6,3,12:18.13
7,3,12:17.12
8,3,12:17.12
9,3,12:17.12
-5,4,12:18.13
-4,4,12:18.13
-3,4,12:18.13
-2,4,12:18.13
-1,4,12:18.13
0,4,12:18.13
1,4,12:18.13
2,4,12:18.13
3,4,12:18.13
4,4,12:18.13
5,4,12:18.13
6,4,12:18.13
-5,5,12:18.13
-4,5,12:18.13
-3,5,12:18.13
-2,5,12:18.13
-1,5,12:18.13
0,5,12:18.13
1,5,12:18.13
2,5,12:18.13
3,5,12:18.13
4,5,12:18.13
5,5,12:18.13
6,5,12:18.13
-9,6,12:18.13
-8,6,12:18.13
-7,6,12:18.13
-6,6,12:18.13
-5,6,12:18.13
-4,6,12:18.13
-3,6,12:18.13
-2,6,12:18.13
-1,6,12:18.13
0,6,12:18.13
1,6,12:18.13
2,6,12:18.13
3,6,12:18.13
4,6,12:18.13
5,6,12:18.13
6,6,12:18.13
-12,7,12:18.13
-11,7,12:18.13
-10,7,12:18.13
-9,7,12:18.13
-8,7,12:18.13
-7,7,12:17.12
-6,7,12:17.12
-5,7,12:18.13
1,7,12:17.12
2,7,12:17.12
4,7,12:18.13
5,7,12:18.13
6,7,12:18.13
7,7,12:18.13
-14,8,12:18.5
-13,8,12:18.13
-12,8,12:18.13
-11,8,12:18.13
-10,8,12:18.13
-8,8,12:17.12
-7,8,12:17.12
-6,8,12:18.13
-5,8,12:18.13
0,8,12:17.12
1,8,12:17.12
2,8,12:17.12
6,8,12:18.13
7,8,12:18.13
8,8,12:18.13
9,8,12:18.13
-17,9,12:18.5
-16,9,12:18.5
-15,9,12:18.5
-7,9,12:18.13
-6,9,12:18.13
1,9,12:17.12
2,9,12:17.12
6,9,12:18.13
7,9,12:18.5
9,9,12:18.5
11,9,12:18.5
-8,10,12:18.13
-7,10,12:18.13
1,10,12:17.12
6,10,12:18.13
7,10,12:18.5
10,10,12:18.5
11,10,12:18.5
12,10,12:18.5
13,10,12:18.5
-8,11,12:18.13
-7,11,12:18.13
6,11,12:18.13
7,11,12:18.5
12,11,12:18.5
13,11,12:18.5
-9,12,12:18.13
-8,12,12:18.13
7,12,12:18.5
8,12,12:18.5
14,12,12:18.5
15,12,12:18.5
16,12,12:18.5
-9,13,12:18.13
7,13,12:18.5
8,13,12:18.5
16,13,12:18.5
-10,14,12:18.5
-9,14,12:18.5
7,14,12:18.5
8,14,12:18.5
-11,15,12:18.5
8,15,12:18.5
9,15,12:18.5
-11,16,12:18.5
9,16,12:18.5
-11,17,12:18.5
8,17,12:18.13
9,17,12:18.13
12,-15,13:18.5
13,-15,13:18.5
-9,-14,13:18.5
-8,-14,13:18.5
12,-14,13:18.5
-9,-13,13:18.5
-8,-13,13:18.5
12,-13,13:18.5
-12,-12,13:18.5
-8,-12,13:18.5
-7,-12,13:18.5
11,-12,13:18.5
-12,-11,13:18.5
-11,-11,13:18.5
-8,-11,13:18.5
-7,-11,13:18.5
10,-11,13:18.5
11,-11,13:18.5
-11,-10,13:18.5
-10,-10,13:18.5
-9,-10,13:18.5
-8,-10,13:18.5
-7,-10,13:18.5
10,-10,13:18.13
-10,-9,13:18.5
-9,-9,13:18.5
-8,-9,13:18.5
-7,-9,13:18.5
-6,-9,13:18.5
9,-9,13:18.13
10,-9,13:18.13
-8,-8,13:18.5
-7,-8,13:18.5
-6,-8,13:18.5
-5,-8,13:18.5
1,-8,13:17.12
2,-8,13:17.12
9,-8,13:18.13
16,-8,13:18.5
17,-8,13:18.5
18,-8,13:18.5
-7,-7,13:18.5
-6,-7,13:18.5
-5,-7,13:18.5
-4,-7,13:18.5
-3,-7,13:18.13
-2,-7,13:18.13
1,-7,13:17.12
2,-7,13:17.12
8,-7,13:18.13
9,-7,13:18.13
12,-7,13:18.13
13,-7,13:18.13
14,-7,13:18.5
15,-7,13:18.5
17,-7,13:18.5
-7,-6,13:18.5
-6,-6,13:18.5
-4,-6,13:18.5
-3,-6,13:18.13
-2,-6,13:18.13
-1,-6,13:18.13
0,-6,13:18.13
1,-6,13:17.12
2,-6,13:17.12
7,-6,13:18.13
8,-6,13:18.13
9,-6,13:17.12
10,-6,13:18.13
11,-6,13:18.13
12,-6,13:18.13
13,-6,13:18.13
14,-6,13:18.5
-7,-5,13:18.5
-6,-5,13:18.5
-5,-5,13:18.5
-2,-5,13:18.13
-1,-5,13:18.13
0,-5,13:18.13
1,-5,13:18.13
2,-5,13:18.13
3,-5,13:18.13
4,-5,13:18.13
5,-5,13:18.13
6,-5,13:18.13
7,-5,13:18.13
8,-5,13:18.13
9,-5,13:18.13
10,-5,13:18.13
11,-5,13:18.13
-7,-4,13:18.13
-6,-4,13:18.13
-5,-4,13:18.13
-1,-4,13:18.13
0,-4,13:18.13
1,-4,13:18.13
2,-4,13:18.13
3,-4,13:18.13
4,-4,13:18.13
5,-4,13:18.13
6,-4,13:18.13
7,-4,13:18.13
8,-4,13:18.13
-6,-3,13:18.13
-5,-3,13:18.13
-2,-3,13:18.13
-1,-3,13:18.13
0,-3,13:18.13
2,-3,13:18.13
3,-3,13:18.13
4,-3,13:18.13
6,-3,13:18.13
7,-3,13:18.13
8,-3,13:18.13
-6,-2,13:18.13
-5,-2,13:18.13
-3,-2,13:18.13
-2,-2,13:18.13
3,-2,13:18.13
4,-2,13:18.13
5,-2,13:18.13
6,-2,13:18.13
7,-2,13:18.13
-6,-1,13:18.13
-5,-1,13:18.13
-4,-1,13:18.13
-3,-1,13:18.13
4,-1,13:18.13
5,-1,13:18.13
6,-1,13:18.13
7,-1,13:18.13
-8,0,13:17.12
-7,0,13:17.12
-6,0,13:17.12
-5,0,13:18.13
-4,0,13:18.13
5,0,13:18.13
6,0,13:18.13
7,0,13:18.13
-7,1,13:17.12
-6,1,13:18.13
-5,1,13:18.13
-4,1,13:18.13
6,1,13:18.13
7,1,13:18.13
-6,2,13:18.13
-5,2,13:18.13
-4,2,13:18.13
5,2,13:18.13
6,2,13:18.13
7,2,13:18.13
9,2,13:17.12
10,2,13:17.12
-7,3,13:18.13
-6,3,13:18.13
-5,3,13:18.13
-4,3,13:18.13
-3,3,13:18.13
5,3,13:18.13
6,3,13:18.13
7,3,13:18.13
8,3,13:17.12
9,3,13:17.12
10,3,13:17.12
11,3,13:17.12
-7,4,13:18.13
-6,4,13:18.13
-5,4,13:18.13
-4,4,13:18.13
-3,4,13:18.13
-2,4,13:18.13
4,4,13:18.13
5,4,13:18.13
6,4,13:18.13
-7,5,13:18.13
-6,5,13:18.13
-5,5,13:18.13
-3,5,13:18.13
-2,5,13:18.13
-1,5,13:18.13
3,5,13:18.13
4,5,13:18.13
5,5,13:18.13
6,5,13:18.13
7,5,13:18.13
-7,6,13:18.13
-6,6,13:18.13
-5,6,13:18.13
-4,6,13:18.13
-3,6,13:18.13
-2,6,13:18.13
-1,6,13:18.13
0,6,13:18.13
1,6,13:18.13
2,6,13:18.13
3,6,13:18.13
6,6,13:18.13
7,6,13:18.13
8,6,13:18.13
-8,7,13:18.13
-7,7,13:18.13
-6,7,13:18.13
-5,7,13:18.13
-4,7,13:18.13
-3,7,13:18.13
-2,7,13:18.13
-1,7,13:18.13
0,7,13:18.13
1,7,13:18.13
2,7,13:18.13
3,7,13:18.13
4,7,13:18.13
5,7,13:18.13
7,7,13:18.13
8,7,13:18.13
-12,8,13:18.13
-11,8,13:18.13
-10,8,13:18.13
-9,8,13:18.13
-8,8,13:18.13
-7,8,13:18.13
-6,8,13:18.13
-5,8,13:18.13
-4,8,13:18.13
-3,8,13:18.13
-2,8,13:18.13
1,8,13:18.13
2,8,13:18.13
3,8,13:18.13
4,8,13:18.13
5,8,13:18.13
6,8,13:18.13
7,8,13:18.5
8,8,13:18.5
-15,9,13:18.5
-14,9,13:18.5
-13,9,13:18.13
-12,9,13:18.13
-11,9,13:18.13
-10,9,13:18.13
-9,9,13:17.12
-8,9,13:18.13
-7,9,13:18.13
0,9,13:17.12
1,9,13:17.12
2,9,13:17.12
5,9,13:18.13
6,9,13:18.13
7,9,13:18.5
8,9,13:18.5
9,9,13:18.5
-17,10,13:18.5
-16,10,13:18.5
-15,10,13:18.5
-14,10,13:18.5
-13,10,13:18.13
-9,10,13:18.13
-8,10,13:18.13
0,10,13:17.12
1,10,13:17.12
7,10,13:18.5
8,10,13:18.5
9,10,13:18.5
10,10,13:18.5
-17,11,13:18.5
-9,11,13:18.13
-8,11,13:18.13
1,11,13:17.12
8,11,13:18.5
9,11,13:18.5
10,11,13:18.5
11,11,13:18.5
12,11,13:18.5
-10,12,13:18.13
-9,12,13:18.13
8,12,13:18.5
9,12,13:18.5
12,12,13:18.5
13,12,13:18.5
14,12,13:18.5
-11,13,13:18.13
-10,13,13:18.13
8,13,13:18.5
9,13,13:18.5
14,13,13:18.5
-11,14,13:18.5
9,14,13:18.5
-12,15,13:18.5
-11,15,13:18.5
9,15,13:18.5
-12,16,13:18.5
9,16,13:18.5
10,16,13:18.5
-13,17,13:18.5
-12,-18,14:18.5
-11,-17,14:18.5
13,-16,14:18.5
-16,-15,14:18.5
-15,-15,14:18.5
-10,-15,14:18.5
13,-15,14:18.5
-14,-14,14:18.5
-10,-14,14:18.5
-9,-14,14:18.5
13,-14,14:18.5
-13,-13,14:18.5
-12,-13,14:18.5
-10,-13,14:18.5
-9,-13,14:18.5
12,-13,14:18.5
13,-13,14:18.5
-12,-12,14:18.5
-11,-12,14:18.5
-10,-12,14:18.5
-9,-12,14:18.5
12,-12,14:18.5
-11,-11,14:18.5
-10,-11,14:18.5
-8,-11,14:18.5
11,-11,14:18.5
12,-11,14:18.5
-10,-10,14:18.5
-9,-10,14:18.5
-8,-10,14:18.5
-7,-10,14:18.5
-6,-10,14:18.5
1,-10,14:17.12
11,-10,14:18.13
-9,-9,14:18.5
-8,-9,14:18.5
-7,-9,14:18.5
-6,-9,14:18.5
-5,-9,14:18.5
-4,-9,14:18.5
-3,-9,14:18.13
1,-9,14:17.12
10,-9,14:18.13
11,-9,14:18.13
15,-9,14:18.5
16,-9,14:18.5
17,-9,14:18.5
18,-9,14:18.5
19,-9,14:18.5
-9,-8,14:18.5
-8,-8,14:18.5
-5,-8,14:18.5
-4,-8,14:18.5
-3,-8,14:18.13
-2,-8,14:18.13
-1,-8,14:18.13
1,-8,14:17.12
2,-8,14:17.12
10,-8,14:18.13
12,-8,14:18.13
13,-8,14:18.13
14,-8,14:18.5
15,-8,14:18.5
16,-8,14:18.5
17,-8,14:18.5
-9,-7,14:18.5
-8,-7,14:18.5
-7,-7,14:18.5
-3,-7,14:18.13
-2,-7,14:18.13
-1,-7,14:18.13
0,-7,14:18.13
1,-7,14:18.13
2,-7,14:18.13
3,-7,14:18.13
4,-7,14:18.13
5,-7,14:18.13
6,-7,14:18.13
7,-7,14:18.13
8,-7,14:18.13
9,-7,14:18.13
10,-7,14:18.13
11,-7,14:18.13
12,-7,14:18.13
13,-7,14:18.13
-9,-6,14:18.5
-8,-6,14:18.5
-7,-6,14:18.5
-1,-6,14:18.13
0,-6,14:18.13
1,-6,14:18.13
2,-6,14:18.13
3,-6,14:18.13
4,-6,14:18.13
5,-6,14:18.13
6,-6,14:18.13
7,-6,14:18.13
8,-6,14:18.13
9,-6,14:18.13
10,-6,14:18.13
-9,-5,14:18.5
-8,-5,14:18.5
-7,-5,14:18.5
-2,-5,14:18.13
-1,-5,14:18.13
0,-5,14:18.13
2,-5,14:18.13
3,-5,14:18.13
4,-5,14:18.13
8,-5,14:18.13
9,-5,14:18.13
-9,-4,14:18.13
-8,-4,14:18.13
-7,-4,14:18.13
-3,-4,14:18.13
-2,-4,14:18.13
-1,-4,14:18.13
3,-4,14:18.13
4,-4,14:18.13
5,-4,14:18.13
8,-4,14:18.13
9,-4,14:18.13
-8,-3,14:18.13
-7,-3,14:18.13
-5,-3,14:18.13
-4,-3,14:18.13
-3,-3,14:18.13
-2,-3,14:18.13
4,-3,14:18.13
5,-3,14:18.13
6,-3,14:18.13
8,-3,14:18.13
9,-3,14:18.13
-8,-2,14:18.13
-7,-2,14:18.13
-6,-2,14:18.13
-5,-2,14:18.13
-4,-2,14:18.13
5,-2,14:18.13
6,-2,14:18.13
7,-2,14:18.13
8,-2,14:18.13
9,-2,14:18.13
-8,-1,14:18.13
-7,-1,14:18.13
-6,-1,14:18.13
-5,-1,14:18.13
6,-1,14:18.13
7,-1,14:18.13
8,-1,14:18.13
9,-1,14:18.13
-10,0,14:17.12
-9,0,14:17.12
-8,0,14:17.12
-7,0,14:18.13
-6,0,14:18.13
6,0,14:18.13
7,0,14:18.13
8,0,14:18.13
9,0,14:18.13
-8,1,14:18.13
-7,1,14:18.13
-6,1,14:18.13
7,1,14:18.13
8,1,14:18.13
9,1,14:18.13
-8,2,14:18.13
-7,2,14:18.13
-6,2,14:18.13
7,2,14:18.13
8,2,14:18.13
9,2,14:18.13
10,2,14:17.12
11,2,14:17.12
-9,3,14:18.13
-8,3,14:18.13
-7,3,14:18.13
-6,3,14:18.13
-5,3,14:18.13
6,3,14:18.13
7,3,14:18.13
8,3,14:18.13
9,3,14:18.13
10,3,14:17.12
11,3,14:17.12
12,3,14:17.12
-9,4,14:18.13
-8,4,14:18.13
-7,4,14:18.13
-6,4,14:18.13
-5,4,14:18.13
-4,4,14:18.13
6,4,14:18.13
8,4,14:18.13
9,4,14:18.13
-9,5,14:18.13
-8,5,14:18.13
-7,5,14:18.13
-5,5,14:18.13
-4,5,14:18.13
-3,5,14:18.13
5,5,14:18.13
6,5,14:18.13
8,5,14:18.13
9,5,14:18.13
-9,6,14:18.13
-8,6,14:18.13
-5,6,14:18.13
-4,6,14:18.13
-3,6,14:18.13
-2,6,14:18.13
3,6,14:18.13
4,6,14:18.13
5,6,14:18.13
8,6,14:18.13
9,6,14:18.13
-9,7,14:18.13
-8,7,14:18.13
-3,7,14:18.13
-2,7,14:18.13
-1,7,14:18.13
0,7,14:18.13
1,7,14:18.13
2,7,14:18.13
3,7,14:18.13
4,7,14:18.13
8,7,14:18.13
9,7,14:18.13
-9,8,14:18.13
-8,8,14:18.13
-7,8,14:18.13
-6,8,14:18.13
-5,8,14:18.13
-4,8,14:18.13
-3,8,14:18.13
-2,8,14:18.13
-1,8,14:18.13
0,8,14:18.13
1,8,14:18.13
2,8,14:18.13
3,8,14:18.13
8,8,14:18.5
9,8,14:18.5
-11,9,14:18.13
-10,9,14:18.13
-9,9,14:18.13
-8,9,14:18.13
-7,9,14:18.13
-6,9,14:18.13
-5,9,14:18.13
-4,9,14:18.13
-3,9,14:18.13
-2,9,14:18.13
-1,9,14:18.13
0,9,14:18.13
1,9,14:18.13
2,9,14:18.13
3,9,14:18.13
4,9,14:18.13
5,9,14:18.13
8,9,14:18.5
9,9,14:18.5
-14,10,14:18.5
-13,10,14:18.13
-12,10,14:18.13
-11,10,14:18.13
-10,10,14:18.13
-9,10,14:18.13
-8,10,14:18.13
-7,10,14:18.13
-6,10,14:18.13
0,10,14:17.12
1,10,14:17.12
3,10,14:18.13
5,10,14:18.13
6,10,14:18.13
7,10,14:18.5
8,10,14:18.5
9,10,14:18.5
10,10,14:18.5
-16,11,14:18.5
-15,11,14:18.5
-14,11,14:18.5
-13,11,14:18.13
-11,11,14:18.13
-10,11,14:18.13
0,11,14:17.12
1,11,14:17.12
6,11,14:18.13
7,11,14:18.5
8,11,14:18.5
9,11,14:18.5
10,11,14:18.5
-18,12,14:18.5
-11,12,14:18.13
-10,12,14:18.13
1,12,14:17.12
9,12,14:18.5
10,12,14:18.5
11,12,14:18.5
12,12,14:18.5
-12,13,14:18.13
-11,13,14:18.13
9,13,14:18.5
10,13,14:18.5
11,13,14:18.5
12,13,14:18.5
13,13,14:18.5
-12,14,14:18.5
-11,14,14:18.5
10,14,14:18.5
11,14,14:18.5
13,14,14:18.5
14,14,14:18.5
-13,15,14:18.5
-12,15,14:18.5
10,15,14:18.5
11,15,14:18.5
-14,16,14:18.5
-13,16,14:18.5
10,16,14:18.5
11,16,14:18.5
-14,17,14:18.5
11,17,14:18.13
-13,-18,15:18.5
-12,-18,15:18.5
-13,-17,15:18.5
-12,-17,15:18.5
-15,-16,15:18.5
-12,-16,15:18.5
-11,-16,15:18.5
15,-16,15:18.5
-15,-15,15:18.5
-14,-15,15:18.5
-13,-15,15:18.5
-12,-15,15:18.5
-11,-15,15:18.5
14,-15,15:18.5
15,-15,15:18.5
-14,-14,15:18.5
-13,-14,15:18.5
-12,-14,15:18.5
-11,-14,15:18.5
13,-14,15:18.5
14,-14,15:18.5
-12,-13,15:18.5
-11,-13,15:18.5
-10,-13,15:18.5
-9,-13,15:18.5
13,-13,15:18.5
-11,-12,15:18.5
-10,-12,15:18.5
-9,-12,15:18.5
-8,-12,15:18.5
-7,-12,15:18.5
-6,-12,15:18.5
12,-12,15:18.5
13,-12,15:18.5
-11,-11,15:18.5
-10,-11,15:18.5
-8,-11,15:18.5
-7,-11,15:18.5
-6,-11,15:18.5
-5,-11,15:18.5
-4,-11,15:18.5
1,-11,15:17.12
12,-11,15:18.5
13,-11,15:18.5
18,-11,15:18.5
19,-11,15:18.5
-11,-10,15:18.5
-10,-10,15:18.5
-6,-10,15:18.5
-5,-10,15:18.5
-4,-10,15:18.5
-3,-10,15:18.13
-2,-10,15:18.13
-1,-10,15:18.13
1,-10,15:17.12
12,-10,15:18.13
14,-10,15:18.5
15,-10,15:18.5
16,-10,15:18.5
17,-10,15:18.5
-11,-9,15:18.5
-10,-9,15:18.5
-4,-9,15:18.5
-3,-9,15:18.13
-2,-9,15:18.13
-1,-9,15:18.13
0,-9,15:18.13
1,-9,15:17.12
2,-9,15:18.13
3,-9,15:18.13
4,-9,15:18.13
5,-9,15:18.13
6,-9,15:18.13
7,-9,15:18.13
8,-9,15:18.13
9,-9,15:18.13
10,-9,15:18.13
11,-9,15:18.13
12,-9,15:18.13
13,-9,15:18.13
14,-9,15:18.5
15,-9,15:18.5
16,-9,15:18.5
-11,-8,15:18.5
-10,-8,15:18.5
-1,-8,15:18.13
0,-8,15:18.13
1,-8,15:18.13
2,-8,15:18.13
3,-8,15:18.13
4,-8,15:18.13
5,-8,15:18.13
6,-8,15:18.13
7,-8,15:18.13
8,-8,15:18.13
9,-8,15:18.13
10,-8,15:18.13
11,-8,15:18.13
12,-8,15:18.13
13,-8,15:18.13
-11,-7,15:18.5
-10,-7,15:18.5
-9,-7,15:18.5
-2,-7,15:18.13
-1,-7,15:18.13
0,-7,15:18.13
1,-7,15:18.13
2,-7,15:18.13
3,-7,15:18.13
4,-7,15:18.13
10,-7,15:18.13
11,-7,15:18.13
-11,-6,15:18.5
-10,-6,15:18.5
-9,-6,15:18.5
-3,-6,15:18.13
-2,-6,15:18.13
-1,-6,15:18.13
3,-6,15:18.13
4,-6,15:18.13
5,-6,15:18.13
10,-6,15:18.13
11,-6,15:18.13
-11,-5,15:18.5
-10,-5,15:18.5
-9,-5,15:18.5
-4,-5,15:18.5
-3,-5,15:18.13
-2,-5,15:18.13
4,-5,15:18.13
5,-5,15:18.13
6,-5,15:18.13
10,-5,15:18.13
11,-5,15:18.13
-10,-4,15:18.13
-9,-4,15:18.13
-6,-4,15:18.13
-5,-4,15:18.13
5,-4,15:18.13
6,-4,15:18.13
7,-4,15:18.13
10,-4,15:18.13
11,-4,15:18.13
-10,-3,15:18.13
-9,-3,15:18.13
-7,-3,15:18.13
-6,-3,15:18.13
-5,-3,15:18.13
6,-3,15:18.13
7,-3,15:18.13
8,-3,15:18.13
10,-3,15:18.13
11,-3,15:18.13
-10,-2,15:18.13
-9,-2,15:18.13
-8,-2,15:18.13
-7,-2,15:18.13
-6,-2,15:18.13
7,-2,15:18.13
8,-2,15:18.13
10,-2,15:18.13
11,-2,15:18.13
-10,-1,15:18.13
-9,-1,15:18.13
-8,-1,15:18.13
-7,-1,15:18.13
7,-1,15:18.13
8,-1,15:18.13
9,-1,15:18.13
10,-1,15:18.13
11,-1,15:18.13
-11,0,15:17.12
-10,0,15:17.12
-9,0,15:18.13
-8,0,15:18.13
8,0,15:18.13
9,0,15:18.13
10,0,15:18.13
-10,1,15:18.13
-9,1,15:18.13
-8,1,15:18.13
9,1,15:18.13
10,1,15:18.13
-10,2,15:18.13
-9,2,15:18.13
-8,2,15:18.13
-7,2,15:18.13
9,2,15:18.13
10,2,15:18.13
11,2,15:17.12
12,2,15:17.12
-10,3,15:18.13
-9,3,15:18.13
-8,3,15:18.13
-7,3,15:18.13
8,3,15:18.13
9,3,15:18.13
10,3,15:18.13
11,3,15:17.12
12,3,15:17.12
13,3,15:17.12
-11,4,15:18.13
-10,4,15:18.13
-9,4,15:18.13
-8,4,15:18.13
-7,4,15:18.13
-6,4,15:18.13
8,4,15:18.13
9,4,15:18.13
10,4,15:18.13
11,4,15:18.13
-11,5,15:18.13
-10,5,15:18.13
-9,5,15:18.13
-7,5,15:18.13
-6,5,15:18.13
7,5,15:18.13
8,5,15:18.13
10,5,15:18.13
11,5,15:18.13
-11,6,15:18.13
-10,6,15:18.13
-6,6,15:18.13
-5,6,15:18.13
6,6,15:18.13
7,6,15:18.13
10,6,15:18.13
11,6,15:18.13
-11,7,15:18.13
-10,7,15:18.13
-6,7,15:18.13
-5,7,15:18.13
-4,7,15:18.13
-3,7,15:18.13
4,7,15:18.13
5,7,15:18.13
6,7,15:18.13
10,7,15:18.13
11,7,15:18.13
-11,8,15:18.13
-10,8,15:18.13
-4,8,15:18.13
-3,8,15:18.13
-2,8,15:18.13
-1,8,15:18.13
3,8,15:18.13
4,8,15:18.13
5,8,15:18.13
6,8,15:18.13
10,8,15:18.5
11,8,15:18.5
-12,9,15:18.13
-11,9,15:18.13
-10,9,15:18.13
-3,9,15:18.13
-2,9,15:18.13
-1,9,15:18.13
0,9,15:18.13
1,9,15:18.13
2,9,15:18.13
3,9,15:18.13
4,9,15:18.13
11,9,15:18.5
-12,10,15:18.13
-11,10,15:18.13
-10,10,15:18.13
-9,10,15:18.13
-8,10,15:18.13
-7,10,15:18.13
-6,10,15:18.13
-5,10,15:18.13
-4,10,15:18.13
-3,10,15:18.13
-2,10,15:18.13
-1,10,15:18.13
0,10,15:18.13
1,10,15:18.13
2,10,15:18.13
3,10,15:18.13
10,10,15:18.5
11,10,15:18.5
-14,11,15:18.5
-13,11,15:18.13
-12,11,15:18.13
-11,11,15:18.13
-10,11,15:18.13
-9,11,15:18.13
-8,11,15:18.13
-7,11,15:18.13
-6,11,15:18.13
-5,11,15:18.13
-4,11,15:18.13
-3,11,15:18.13
-2,11,15:18.13
-1,11,15:18.13
0,11,15:18.13
1,11,15:18.13
2,11,15:18.13
3,11,15:18.13
4,11,15:18.13
5,11,15:18.13
6,11,15:18.13
10,11,15:18.5
11,11,15:18.5
-17,12,15:18.5
-16,12,15:18.5
-15,12,15:18.5
-14,12,15:18.5
-13,12,15:18.13
-12,12,15:18.13
-11,12,15:18.13
-10,12,15:18.13
0,12,15:17.12
1,12,15:17.12
5,12,15:18.13
6,12,15:18.13
7,12,15:18.5
8,12,15:18.5
9,12,15:18.5
10,12,15:18.5
11,12,15:18.5
12,12,15:18.5
-19,13,15:18.5
-18,13,15:18.5
-17,13,15:18.5
-16,13,15:18.5
-15,13,15:18.5
-12,13,15:18.13
0,13,15:17.12
1,13,15:17.12
6,13,15:18.13
7,13,15:18.5
8,13,15:18.5
9,13,15:18.5
10,13,15:18.5
11,13,15:18.5
12,13,15:18.5
-14,14,15:18.5
-13,14,15:18.5
9,14,15:18.5
10,14,15:18.5
11,14,15:18.5
12,14,15:18.5
13,14,15:18.5
-14,15,15:18.5
11,15,15:18.5
12,15,15:18.5
13,15,15:18.5
14,15,15:18.13
-15,16,15:18.5
-14,16,15:18.5
12,16,15:18.5
14,16,15:18.13
15,16,15:18.13
-15,17,15:18.5
-14,17,15:18.5
12,17,15:18.13
13,17,15:18.13
16,17,15:18.13
17,17,15:18.13
-15,18,15:18.5
13,19,15:18.13
13,20,15:18.5
14,20,15:18.13
13,21,15:18.5
-15,-19,16:18.5
-16,-18,16:18.5
-14,-18,16:18.5
-16,-17,16:18.5
-15,-17,16:18.5
-14,-17,16:18.5
-13,-17,16:18.5
-15,-16,16:18.5
-14,-16,16:18.5
-13,-16,16:18.5
-12,-16,16:18.5
15,-16,16:18.5
16,-16,16:18.5
-14,-15,16:18.5
-13,-15,16:18.5
-12,-15,16:18.5
-11,-15,16:18.5
-10,-15,16:18.5
15,-15,16:18.5
16,-15,16:18.5
-14,-14,16:18.5
-13,-14,16:18.5
-12,-14,16:18.5
-11,-14,16:18.5
-10,-14,16:18.5
-9,-14,16:18.5
-8,-14,16:18.5
-7,-14,16:18.5
15,-14,16:18.5
-14,-13,16:18.5
-13,-13,16:18.5
-12,-13,16:18.5
-9,-13,16:18.5
-8,-13,16:18.5
-7,-13,16:18.5
-6,-13,16:18.5
-5,-13,16:18.5
-4,-13,16:18.5
14,-13,16:18.5
15,-13,16:18.5
-13,-12,16:18.5
-12,-12,16:18.5
-7,-12,16:18.5
-6,-12,16:18.5
-5,-12,16:18.5
-4,-12,16:18.5
-3,-12,16:18.13
-2,-12,16:18.13
1,-12,16:17.12
13,-12,16:18.5
14,-12,16:18.5
17,-12,16:18.5
18,-12,16:18.5
19,-12,16:18.5
-13,-11,16:18.5
-12,-11,16:18.5
-4,-11,16:18.5
-3,-11,16:18.13
-2,-11,16:18.13
-1,-11,16:18.13
0,-11,16:18.13
1,-11,16:17.12
2,-11,16:18.13
3,-11,16:18.13
4,-11,16:18.13
5,-11,16:18.13
6,-11,16:18.13
7,-11,16:18.5
8,-11,16:18.5
9,-11,16:18.5
10,-11,16:18.5
11,-11,16:18.5
12,-11,16:18.5
13,-11,16:18.5
14,-11,16:18.5
15,-11,16:18.5
16,-11,16:18.5
17,-11,16:18.5
18,-11,16:18.5
19,-11,16:18.5
-13,-10,16:18.5
-12,-10,16:18.5
-2,-10,16:18.13
-1,-10,16:18.13
0,-10,16:18.13
1,-10,16:18.13
2,-10,16:18.13
3,-10,16:18.13
4,-10,16:18.13
5,-10,16:18.13
6,-10,16:18.13
7,-10,16:18.13
8,-10,16:18.13
9,-10,16:18.13
10,-10,16:18.13
11,-10,16:18.13
12,-10,16:18.13
13,-10,16:18.13
14,-10,16:18.5
15,-10,16:18.5
-13,-9,16:18.5
-12,-9,16:18.5
-1,-9,16:18.13
0,-9,16:18.13
1,-9,16:18.13
2,-9,16:18.13
3,-9,16:18.13
4,-9,16:18.13
5,-9,16:18.13
6,-9,16:18.13
7,-9,16:18.13
8,-9,16:18.13
9,-9,16:18.13
10,-9,16:18.13
11,-9,16:18.13
12,-9,16:18.13
13,-9,16:18.13
-13,-8,16:18.5
-12,-8,16:18.5
-3,-8,16:18.13
-2,-8,16:18.13
-1,-8,16:18.13
2,-8,16:18.13
3,-8,16:18.13
4,-8,16:18.13
12,-8,16:18.13
13,-8,16:18.13
-13,-7,16:18.5
-12,-7,16:18.5
-11,-7,16:18.5
-4,-7,16:18.5
-3,-7,16:18.13
-2,-7,16:18.13
4,-7,16:18.13
5,-7,16:18.13
6,-7,16:18.13
12,-7,16:18.13
13,-7,16:18.13
-13,-6,16:18.5
-12,-6,16:18.5
-11,-6,16:18.5
-4,-6,16:18.5
-3,-6,16:18.13
5,-6,16:18.13
6,-6,16:18.13
7,-6,16:18.13
12,-6,16:18.13
13,-6,16:18.13
-13,-5,16:18.5
-12,-5,16:18.5
-11,-5,16:18.5
-7,-5,16:18.5
-6,-5,16:18.5
-5,-5,16:18.5
6,-5,16:18.13
7,-5,16:18.13
8,-5,16:18.13
12,-5,16:18.13
13,-5,16:18.13
-12,-4,16:18.13
-11,-4,16:18.13
-8,-4,16:18.13
-7,-4,16:18.13
-6,-4,16:18.13
7,-4,16:18.13
8,-4,16:18.13
11,-4,16:18.13
12,-4,16:18.13
13,-4,16:18.13
-12,-3,16:18.13
-11,-3,16:18.13
-9,-3,16:18.13
-8,-3,16:18.13
-7,-3,16:18.13
8,-3,16:18.13
9,-3,16:18.13
11,-3,16:18.13
12,-3,16:18.13
-12,-2,16:18.13
-11,-2,16:18.13
-10,-2,16:18.13
-9,-2,16:18.13
-8,-2,16:18.13
8,-2,16:18.13
9,-2,16:18.13
10,-2,16:18.13
11,-2,16:18.13
12,-2,16:18.13
-12,-1,16:18.13
-11,-1,16:18.13
-10,-1,16:18.13
-9,-1,16:18.13
9,-1,16:18.13
10,-1,16:18.13
11,-1,16:18.13
12,-1,16:18.13
-13,0,16:17.12
-12,0,16:17.12
-11,0,16:18.13
-10,0,16:18.13
10,0,16:18.13
11,0,16:18.13
12,0,16:18.13
-12,1,16:18.13
-11,1,16:18.13
-10,1,16:18.13
10,1,16:18.13
11,1,16:18.13
12,1,16:18.13
-12,2,16:18.13
-11,2,16:18.13
-10,2,16:18.13
-9,2,16:18.13
10,2,16:18.13
11,2,16:18.13
12,2,16:18.13
13,2,16:17.12
-12,3,16:18.13
-11,3,16:18.13
-10,3,16:18.13
-9,3,16:18.13
10,3,16:18.13
11,3,16:18.13
12,3,16:18.13
13,3,16:17.12
14,3,16:17.12
-13,4,16:18.13
-12,4,16:18.13
-11,4,16:18.13
-10,4,16:18.13
-9,4,16:18.13
-8,4,16:18.13
9,4,16:18.13
10,4,16:18.13
11,4,16:18.13
12,4,16:18.13
-13,5,16:18.13
-12,5,16:18.13
-11,5,16:18.13
-9,5,16:18.13
-8,5,16:18.13
-7,5,16:18.13
8,5,16:18.13
9,5,16:18.13
10,5,16:18.13
11,5,16:18.13
12,5,16:18.13
-13,6,16:18.13
-12,6,16:18.13
-8,6,16:18.13
-7,6,16:18.13
8,6,16:18.13
9,6,16:18.13
11,6,16:18.13
12,6,16:18.13
-13,7,16:18.13
-12,7,16:18.13
-8,7,16:18.13
-7,7,16:18.13
-6,7,16:18.13
7,7,16:18.13
8,7,16:18.13
11,7,16:18.13
12,7,16:18.13
13,7,16:18.13
-13,8,16:18.13
-12,8,16:18.13
-7,8,16:18.13
-6,8,16:18.13
-5,8,16:18.13
-4,8,16:18.13
5,8,16:18.13
6,8,16:18.13
7,8,16:18.5
11,8,16:18.5
12,8,16:18.5
13,8,16:18.5
-14,9,16:18.5
-13,9,16:18.13
-12,9,16:18.13
-5,9,16:18.13
-4,9,16:18.13
-3,9,16:18.13
4,9,16:18.13
5,9,16:18.13
6,9,16:18.13
7,9,16:18.5
12,9,16:18.5
13,9,16:18.5
-14,10,16:18.5
-13,10,16:18.13
-12,10,16:18.13
-4,10,16:18.13
-3,10,16:18.13
-2,10,16:18.13
-1,10,16:18.13
2,10,16:18.13
3,10,16:18.13
5,10,16:18.13
12,10,16:18.5
13,10,16:18.5
-14,11,16:18.5
-13,11,16:18.13
-12,11,16:18.13
-4,11,16:18.13
-3,11,16:18.13
-2,11,16:18.13
-1,11,16:18.13
0,11,16:18.13
1,11,16:18.13
2,11,16:18.13
3,11,16:18.13
12,11,16:18.5
13,11,16:18.5
-14,12,16:18.5
-13,12,16:18.13
-12,12,16:18.13
-11,12,16:18.13
-10,12,16:18.13
-9,12,16:18.13
-8,12,16:18.13
-7,12,16:18.13
-6,12,16:18.13
-5,12,16:18.13
-4,12,16:18.13
-3,12,16:18.13
-2,12,16:18.13
-1,12,16:18.13
0,12,16:18.13
1,12,16:18.13
2,12,16:18.13
3,12,16:18.13
12,12,16:18.5
13,12,16:18.5
-17,13,16:18.5
-16,13,16:18.5
-15,13,16:18.5
-14,13,16:18.5
-13,13,16:18.13
-12,13,16:18.13
-11,13,16:18.13
-10,13,16:18.13
-9,13,16:18.13
-8,13,16:18.13
-7,13,16:18.13
-6,13,16:18.13
-5,13,16:18.13
-4,13,16:18.13
-3,13,16:18.13
-2,13,16:18.13
0,13,16:17.12
1,13,16:17.12
2,13,16:18.13
3,13,16:18.13
4,13,16:18.13
5,13,16:18.13
6,13,16:18.13
7,13,16:18.5
12,13,16:18.5
13,13,16:18.5
-19,14,16:18.5
-18,14,16:18.5
-17,14,16:18.5
-15,14,16:18.5
-14,14,16:18.5
0,14,16:17.12
1,14,16:17.12
4,14,16:18.13
5,14,16:18.13
6,14,16:18.5
7,14,16:18.5
8,14,16:18.5
9,14,16:18.5
10,14,16:18.5
12,14,16:18.5
13,14,16:18.5
-15,15,16:18.5
-14,15,16:18.5
7,15,16:18.5
8,15,16:18.5
9,15,16:18.5
10,15,16:18.5
11,15,16:18.5
12,15,16:18.5
13,15,16:18.5
14,15,16:18.13
-16,16,16:18.5
-15,16,16:18.5
10,16,16:18.5
11,16,16:18.5
12,16,16:18.5
13,16,16:18.5
14,16,16:18.13
-16,17,16:18.5
13,17,16:18.13
14,17,16:18.13
15,17,16:18.13
16,17,16:18.13
11,18,16:18.6
12,18,16:18.14
13,18,16:18.14
14,18,16:18.13
16,18,16:18.13
17,18,16:18.13
14,19,16:18.13
14,20,16:18.13
-16,-19,17:18.5
-15,-19,17:18.5
-16,-18,17:18.5
-15,-18,17:18.5
-14,-18,17:18.5
-13,-18,17:18.5
-15,-17,17:18.5
-14,-17,17:18.5
-13,-17,17:18.5
-12,-17,17:18.5
-11,-17,17:18.5
-10,-17,17:18.5
-15,-16,17:18.5
-14,-16,17:18.5
-12,-16,17:18.5
-11,-16,17:18.5
-10,-16,17:18.5
-9,-16,17:18.5
-8,-16,17:18.5
16,-16,17:18.5
-15,-15,17:18.5
-14,-15,17:18.5
-10,-15,17:18.5
-9,-15,17:18.5
-8,-15,17:18.5
-7,-15,17:18.5
-6,-15,17:18.5
-5,-15,17:18.5
16,-15,17:18.5
-16,-14,17:18.5
-15,-14,17:18.5
-14,-14,17:18.5
-7,-14,17:18.5
-6,-14,17:18.5
-5,-14,17:18.5
-4,-14,17:18.5
-3,-14,17:18.13
15,-14,17:18.5
16,-14,17:18.5
-15,-13,17:18.5
-14,-13,17:18.5
-5,-13,17:18.5
-4,-13,17:18.5
-3,-13,17:18.13
-2,-13,17:18.13
-1,-13,17:18.13
0,-13,17:18.13
1,-13,17:17.12
15,-13,17:18.5
16,-13,17:18.5
17,-13,17:18.5
18,-13,17:18.5
19,-13,17:18.5
-15,-12,17:18.5
-14,-12,17:18.5
-2,-12,17:18.13
-1,-12,17:18.13
0,-12,17:18.13
1,-12,17:18.13
2,-12,17:18.13
3,-12,17:18.13
4,-12,17:18.13
5,-12,17:18.13
6,-12,17:18.13
7,-12,17:18.5
8,-12,17:18.5
9,-12,17:18.5
10,-12,17:18.5
11,-12,17:18.5
12,-12,17:18.5
13,-12,17:18.5
14,-12,17:18.5
15,-12,17:18.5
16,-12,17:18.5
17,-12,17:18.5
18,-12,17:18.5
-15,-11,17:18.5
-14,-11,17:18.5
-1,-11,17:18.13
0,-11,17:18.13
1,-11,17:18.13
2,-11,17:18.13
3,-11,17:18.13
4,-11,17:18.13
5,-11,17:18.13
6,-11,17:18.13
7,-11,17:18.5
8,-11,17:18.5
9,-11,17:18.5
10,-11,17:18.5
11,-11,17:18.5
12,-11,17:18.5
13,-11,17:18.5
14,-11,17:18.5
15,-11,17:18.5
-15,-10,17:18.5
-14,-10,17:18.5
-2,-10,17:18.13
-1,-10,17:18.13
0,-10,17:18.13
2,-10,17:18.13
3,-10,17:18.13
4,-10,17:18.13
14,-10,17:18.5
15,-10,17:18.5
-15,-9,17:18.5
-14,-9,17:18.5
-4,-9,17:18.5
-3,-9,17:18.13
-2,-9,17:18.13
3,-9,17:18.13
4,-9,17:18.13
5,-9,17:18.13
14,-9,17:18.5
15,-9,17:18.5
-15,-8,17:18.5
-14,-8,17:18.5
-13,-8,17:18.5
-5,-8,17:18.5
-4,-8,17:18.5
-3,-8,17:18.13
5,-8,17:18.13
6,-8,17:18.13
7,-8,17:18.13
14,-8,17:18.5
15,-8,17:18.5
-15,-7,17:18.5
-14,-7,17:18.5
-13,-7,17:18.5
-6,-7,17:18.5
-5,-7,17:18.5
-4,-7,17:18.5
6,-7,17:18.13
7,-7,17:18.13
8,-7,17:18.13
13,-7,17:18.13
14,-7,17:18.5
15,-7,17:18.5
-15,-6,17:18.5
-14,-6,17:18.5
-13,-6,17:18.5
-8,-6,17:18.5
-7,-6,17:18.5
-6,-6,17:18.5
7,-6,17:18.13
8,-6,17:18.13
9,-6,17:18.13
13,-6,17:18.13
14,-6,17:18.5
-14,-5,17:18.5
-13,-5,17:18.5
-9,-5,17:18.5
-8,-5,17:18.5
-7,-5,17:18.5
8,-5,17:18.13
9,-5,17:18.13
13,-5,17:18.13
14,-5,17:18.5
-14,-4,17:18.13
-13,-4,17:18.13
-10,-4,17:18.13
-9,-4,17:18.13
-8,-4,17:18.13
9,-4,17:18.13
10,-4,17:18.13
13,-4,17:18.13
14,-4,17:18.5
-14,-3,17:18.13
-13,-3,17:18.13
-11,-3,17:18.13
-10,-3,17:18.13
-9,-3,17:18.13
9,-3,17:18.13
10,-3,17:18.13
11,-3,17:18.13
13,-3,17:18.13
14,-3,17:18.5
-14,-2,17:18.13
-13,-2,17:18.13
-12,-2,17:18.13
-11,-2,17:18.13
-10,-2,17:18.13
10,-2,17:18.13
11,-2,17:18.13
13,-2,17:18.13
14,-2,17:18.13
-14,-1,17:18.13
-13,-1,17:18.13
-12,-1,17:18.13
-11,-1,17:18.13
11,-1,17:18.13
12,-1,17:18.13
13,-1,17:18.13
14,-1,17:18.13
-14,0,17:18.13
-13,0,17:18.13
-12,0,17:18.13
11,0,17:18.13
12,0,17:18.13
13,0,17:18.13
14,0,17:18.13
-14,1,17:18.13
-13,1,17:18.13
-12,1,17:18.13
12,1,17:18.13
13,1,17:18.13
14,1,17:18.13
-14,2,17:18.13
-13,2,17:18.13
-12,2,17:18.13
-11,2,17:18.13
12,2,17:18.13
13,2,17:18.13
14,2,17:17.12
-14,3,17:18.13
-13,3,17:18.13
-12,3,17:18.13
-11,3,17:18.13
12,3,17:18.13
13,3,17:18.13
14,3,17:17.12
15,3,17:17.12
-15,4,17:18.13
-14,4,17:18.13
-13,4,17:18.13
-11,4,17:18.13
-10,4,17:18.13
11,4,17:18.13
12,4,17:18.13
13,4,17:18.13
14,4,17:18.13
-15,5,17:18.5
-14,5,17:18.5
-13,5,17:18.13
-11,5,17:18.13
-10,5,17:18.13
-9,5,17:18.13
10,5,17:18.13
11,5,17:18.13
12,5,17:18.13
13,5,17:18.13
14,5,17:18.13
-15,6,17:18.5
-14,6,17:18.5
-10,6,17:18.13
-9,6,17:18.13
9,6,17:18.13
10,6,17:18.13
11,6,17:18.13
13,6,17:18.13
14,6,17:18.13
-15,7,17:18.5
-10,7,17:18.13
-9,7,17:18.13
-8,7,17:18.13
8,7,17:18.13
9,7,17:18.13
10,7,17:18.13
13,7,17:18.13
14,7,17:18.13
-15,8,17:18.5
-14,8,17:18.5
-9,8,17:18.13
-8,8,17:18.13
-7,8,17:18.13
8,8,17:18.5
9,8,17:18.5
13,8,17:18.5
14,8,17:18.5
-16,9,17:18.5
-15,9,17:18.5
-14,9,17:18.5
-8,9,17:18.13
-7,9,17:18.13
-6,9,17:18.13
-5,9,17:18.13
6,9,17:18.13
7,9,17:18.5
8,9,17:18.5
13,9,17:18.5
14,9,17:18.5
-16,10,17:18.5
-15,10,17:18.5
-14,10,17:18.5
-7,10,17:18.13
-6,10,17:18.13
-5,10,17:18.13
-4,10,17:18.13
5,10,17:18.13
6,10,17:18.13
7,10,17:18.5
8,10,17:18.5
13,10,17:18.5
14,10,17:18.5
-16,11,17:18.5
-15,11,17:18.5
-14,11,17:18.5
-5,11,17:18.13
-4,11,17:18.13
-3,11,17:18.13
-2,11,17:18.13
3,11,17:18.13
4,11,17:18.13
5,11,17:18.13
6,11,17:18.13
13,11,17:18.5
14,11,17:18.5
15,11,17:18.5
-16,12,17:18.5
-15,12,17:18.5
-3,12,17:18.13
-2,12,17:18.13
-1,12,17:18.13
1,12,17:18.13
2,12,17:18.13
3,12,17:18.13
14,12,17:18.5
-16,13,17:18.5
-15,13,17:18.5
-8,13,17:18.13
-7,13,17:18.13
-6,13,17:18.13
-5,13,17:18.13
-4,13,17:18.13
-3,13,17:18.13
-2,13,17:18.13
-1,13,17:18.13
0,13,17:18.13
1,13,17:18.13
2,13,17:18.13
3,13,17:18.13
14,13,17:18.5
15,13,17:18.5
-17,14,17:18.5
-15,14,17:18.5
-14,14,17:18.5
-13,14,17:18.5
-12,14,17:18.5
-11,14,17:18.5
-10,14,17:18.5
-9,14,17:18.5
-8,14,17:18.5
-7,14,17:18.5
-6,14,17:18.5
-5,14,17:18.5
-4,14,17:18.13
-3,14,17:18.13
-2,14,17:18.13
-1,14,17:18.13
0,14,17:18.13
1,14,17:18.13
2,14,17:18.13
3,14,17:18.13
4,14,17:18.13
5,14,17:18.13
14,14,17:18.5
15,14,17:18.5
-19,15,17:18.5
-18,15,17:18.5
-17,15,17:18.5
-16,15,17:18.5
-15,15,17:18.5
-14,15,17:18.5
-13,15,17:18.5
-12,15,17:18.5
-11,15,17:18.5
-10,15,17:18.5
-9,15,17:18.5
-8,15,17:18.5
-7,15,17:18.5
-6,15,17:18.5
0,15,17:17.12
2,15,17:18.13
3,15,17:18.13
4,15,17:18.13
5,15,17:18.13
6,15,17:18.5
7,15,17:18.5
8,15,17:18.5
14,15,17:18.13
15,15,17:18.13
-20,16,17:18.5
-19,16,17:18.5
-18,16,17:18.5
-17,16,17:18.5
-16,16,17:18.5
5,16,17:18.13
6,16,17:18.5
7,16,17:18.5
8,16,17:18.5
9,16,17:18.5
10,16,17:18.5
11,16,17:18.5
14,16,17:18.13
15,16,17:18.13
-18,17,17:18.5
-17,17,17:18.5
9,17,17:18.5
10,17,17:18.5
11,17,17:18.13
12,17,17:18.13
13,17,17:18.13
14,17,17:18.13
15,17,17:18.13
-18,18,17:18.5
11,18,17:18.14
12,18,17:18.13
13,18,17:18.13
14,18,17:18.13
15,18,17:18.13
16,18,17:18.14
15,19,17:18.13
16,19,17:18.13
17,19,17:18.13
15,20,17:18.13
16,20,17:18.13
17,20,17:18.13
18,20,17:18.13
16,21,17:18.13
-13,-19,18:18.5
-12,-19,18:18.5
-11,-19,18:18.5
-13,-18,18:18.5
-12,-18,18:18.5
-11,-18,18:18.5
-10,-18,18:18.5
-9,-18,18:18.5
-11,-17,18:18.5
-10,-17,18:18.5
-9,-17,18:18.5
-8,-17,18:18.5
-7,-17,18:18.5
-6,-17,18:18.5
18,-17,18:18.5
-17,-16,18:18.5
-8,-16,18:18.5
-7,-16,18:18.5
-6,-16,18:18.5
-5,-16,18:18.5
-4,-16,18:18.5
-3,-16,18:18.13
17,-16,18:18.5
18,-16,18:18.5
-17,-15,18:18.5
-16,-15,18:18.5
-6,-15,18:18.5
-5,-15,18:18.5
-4,-15,18:18.5
-3,-15,18:18.13
-2,-15,18:18.13
-1,-15,18:18.13
17,-15,18:18.5
18,-15,18:18.5
19,-15,18:18.5
-17,-14,18:18.5
-16,-14,18:18.5
-3,-14,18:18.13
-2,-14,18:18.13
-1,-14,18:18.13
0,-14,18:18.13
1,-14,18:18.13
2,-14,18:18.13
3,-14,18:18.13
5,-14,18:18.13
6,-14,18:18.5
7,-14,18:18.5
8,-14,18:18.5
9,-14,18:18.5
10,-14,18:18.5
11,-14,18:18.5
12,-14,18:18.5
13,-14,18:18.5
14,-14,18:18.5
15,-14,18:18.5
16,-14,18:18.5
17,-14,18:18.5
18,-14,18:18.5
19,-14,18:18.5
20,-14,18:18.5
-17,-13,18:18.5
-16,-13,18:18.5
-1,-13,18:18.13
0,-13,18:18.13
1,-13,18:18.13
2,-13,18:18.13
3,-13,18:18.13
4,-13,18:18.13
5,-13,18:18.13
6,-13,18:18.5
7,-13,18:18.5
8,-13,18:18.5
9,-13,18:18.5
10,-13,18:18.5
11,-13,18:18.5
12,-13,18:18.5
13,-13,18:18.5
14,-13,18:18.5
15,-13,18:18.5
16,-13,18:18.5
17,-13,18:18.5
-17,-12,18:18.5
-16,-12,18:18.5
-2,-12,18:18.13
-1,-12,18:18.13
0,-12,18:18.13
2,-12,18:18.13
3,-12,18:18.13
4,-12,18:18.13
16,-12,18:18.5
17,-12,18:18.5
-16,-11,18:18.5
-3,-11,18:18.13
-2,-11,18:18.13
-1,-11,18:18.13
3,-11,18:18.13
4,-11,18:18.13
5,-11,18:18.13
16,-11,18:18.5
17,-11,18:18.5
-16,-10,18:18.5
-5,-10,18:18.5
-4,-10,18:18.5
-3,-10,18:18.13
4,-10,18:18.13
5,-10,18:18.13
6,-10,18:18.13
15,-10,18:18.5
16,-10,18:18.5
17,-10,18:18.5
-16,-9,18:18.5
-15,-9,18:18.5
-6,-9,18:18.5
-5,-9,18:18.5
-4,-9,18:18.5
5,-9,18:18.13
6,-9,18:18.13
7,-9,18:18.5
15,-9,18:18.5
16,-9,18:18.5
-16,-8,18:18.5
-15,-8,18:18.5
-8,-8,18:18.5
-7,-8,18:18.5
-6,-8,18:18.5
-5,-8,18:18.5
7,-8,18:18.5
8,-8,18:18.5
9,-8,18:18.5
15,-8,18:18.5
16,-8,18:18.5
-16,-7,18:18.5
-15,-7,18:18.5
-9,-7,18:18.5
-8,-7,18:18.5
-7,-7,18:18.5
8,-7,18:18.5
9,-7,18:18.5
10,-7,18:18.5
15,-7,18:18.5
16,-7,18:18.5
-16,-6,18:18.5
-15,-6,18:18.5
-10,-6,18:18.5
-9,-6,18:18.5
-8,-6,18:18.5
9,-6,18:18.5
10,-6,18:18.5
15,-6,18:18.5
16,-6,18:18.5
-16,-5,18:18.5
-15,-5,18:18.5
-11,-5,18:18.5
-10,-5,18:18.5
-9,-5,18:18.5
10,-5,18:18.5
11,-5,18:18.5
15,-5,18:18.5
16,-5,18:18.5
-16,-4,18:18.13
-15,-4,18:18.13
-12,-4,18:18.13
-11,-4,18:18.13
-10,-4,18:18.13
10,-4,18:18.5
11,-4,18:18.5
12,-4,18:18.5
15,-4,18:18.5
16,-4,18:18.5
-16,-3,18:18.13
-15,-3,18:18.13
-13,-3,18:18.13
-12,-3,18:18.13
-11,-3,18:18.13
11,-3,18:18.5
12,-3,18:18.5
15,-3,18:18.5
16,-3,18:18.5
-15,-2,18:18.13
-14,-2,18:18.13
-13,-2,18:18.13
-12,-2,18:18.13
11,-2,18:18.13
12,-2,18:18.13
13,-2,18:18.13
14,-2,18:18.13
15,-2,18:18.13
16,-2,18:18.13
-15,-1,18:18.13
-14,-1,18:18.13
-13,-1,18:18.13
12,-1,18:18.13
13,-1,18:18.13
14,-1,18:18.13
15,-1,18:18.13
-15,0,18:18.13
-14,0,18:18.13
13,0,18:18.13
14,0,18:18.13
15,0,18:18.13
-16,1,18:18.13
-15,1,18:18.13
-14,1,18:18.13
13,1,18:18.13
14,1,18:18.13
15,1,18:18.13
-16,2,18:18.13
-15,2,18:18.13
-14,2,18:18.13
-13,2,18:18.13
14,2,18:18.13
15,2,18:18.13
-16,3,18:18.13
-15,3,18:18.13
-14,3,18:18.13
-13,3,18:18.13
-12,3,18:18.13
13,3,18:18.13
14,3,18:18.13
15,3,18:18.13
16,3,18:17.12
-16,4,18:18.13
-15,4,18:18.13
-13,4,18:18.13
-12,4,18:18.13
13,4,18:18.13
14,4,18:18.13
15,4,18:18.13
-17,5,18:18.5
-16,5,18:18.5
-15,5,18:18.5
-13,5,18:18.5
-12,5,18:18.5
-11,5,18:18.5
12,5,18:18.13
13,5,18:18.13
14,5,18:18.13
15,5,18:18.13
-17,6,18:18.5
-16,6,18:18.5
-12,6,18:18.5
-11,6,18:18.5
-10,6,18:18.5
11,6,18:18.13
12,6,18:18.13
14,6,18:18.13
15,6,18:18.13
16,6,18:18.13
-17,7,18:18.5
-16,7,18:18.5
-11,7,18:18.5
-10,7,18:18.5
10,7,18:18.13
11,7,18:18.13
12,7,18:18.13
15,7,18:18.13
16,7,18:18.13
-17,8,18:18.5
-16,8,18:18.5
-11,8,18:18.5
-10,8,18:18.5
-9,8,18:18.5
9,8,18:18.5
10,8,18:18.5
11,8,18:18.5
15,8,18:18.5
16,8,18:18.5
-18,9,18:18.5
-17,9,18:18.5
-16,9,18:18.5
-10,9,18:18.5
-9,9,18:18.5
-8,9,18:18.5
9,9,18:18.5
15,9,18:18.5
16,9,18:18.5
-18,10,18:18.5
-17,10,18:18.5
-16,10,18:18.5
-9,10,18:18.5
-8,10,18:18.5
-7,10,18:18.5
8,10,18:18.5
9,10,18:18.5
15,10,18:18.5
16,10,18:18.5
-18,11,18:18.5
-17,11,18:18.5
-16,11,18:18.5
-8,11,18:18.5
-7,11,18:18.5
-6,11,18:18.5
-5,11,18:18.5
6,11,18:18.5
7,11,18:18.5
8,11,18:18.5
15,11,18:18.5
16,11,18:18.5
-18,12,18:18.5
-17,12,18:18.5
-6,12,18:18.5
-5,12,18:18.5
-4,12,18:18.13
-3,12,18:18.13
5,12,18:18.13
6,12,18:18.5
7,12,18:18.5
15,12,18:18.5
16,12,18:18.5
-18,13,18:18.5
-17,13,18:18.5
-5,13,18:18.5
-4,13,18:18.13
-3,13,18:18.13
-2,13,18:18.13
2,13,18:18.13
3,13,18:18.13
4,13,18:18.13
5,13,18:18.13
15,13,18:18.5
16,13,18:18.5
-18,14,18:18.5
-17,14,18:18.5
-3,14,18:18.13
-2,14,18:18.13
-1,14,18:18.13
0,14,18:18.13
1,14,18:18.13
2,14,18:18.13
3,14,18:18.13
15,14,18:18.5
16,14,18:18.5
17,14,18:18.5
-19,15,18:18.5
-18,15,18:18.5
-17,15,18:18.5
-12,15,18:18.5
-11,15,18:18.5
-10,15,18:18.5
-9,15,18:18.5
-8,15,18:18.5
-7,15,18:18.5
-6,15,18:18.5
-5,15,18:18.5
-4,15,18:18.13
-3,15,18:18.13
-2,15,18:18.13
-1,15,18:18.13
0,15,18:18.13
1,15,18:18.13
2,15,18:18.13
3,15,18:18.13
16,15,18:18.13
17,15,18:18.13
-19,16,18:18.5
-18,16,18:18.5
-17,16,18:18.5
-16,16,18:18.5
-15,16,18:18.5
-14,16,18:18.5
-13,16,18:18.5
-12,16,18:18.5
-11,16,18:18.5
-10,16,18:18.5
-9,16,18:18.5
-8,16,18:18.5
-7,16,18:18.5
-6,16,18:18.5
-5,16,18:18.5
-4,16,18:18.13
-3,16,18:18.13
-2,16,18:18.13
-1,16,18:18.13
0,16,18:17.12
1,16,18:18.13
2,16,18:18.13
4,16,18:18.13
5,16,18:18.13
6,16,18:18.5
16,16,18:18.13
17,16,18:18.13
-20,17,18:18.5
-19,17,18:18.5
-18,17,18:18.5
-17,17,18:18.5
-16,17,18:18.5
-15,17,18:18.5
-14,17,18:18.5
-13,17,18:18.5
-11,17,18:18.5
-10,17,18:18.5
3,17,18:18.13
4,17,18:18.13
5,17,18:18.13
6,17,18:18.5
7,17,18:18.5
8,17,18:18.5
9,17,18:18.13
16,17,18:18.13
17,17,18:18.13
-19,18,18:18.5
6,18,18:18.5
7,18,18:18.5
8,18,18:18.5
9,18,18:18.13
10,18,18:18.13
11,18,18:18.13
16,18,18:18.13
17,18,18:18.13
9,19,18:18.13
10,19,18:18.13
11,19,18:18.13
12,19,18:18.13
13,19,18:18.13
14,19,18:18.13
15,19,18:18.13
16,19,18:18.13
17,19,18:18.13
12,20,18:18.5
13,20,18:18.5
14,20,18:18.13
15,20,18:18.13
16,20,18:18.13
17,20,18:18.13
15,21,18:18.13
16,21,18:18.13
17,21,18:18.13
18,21,18:18.13
17,22,18:18.13
-13,-19,19:18.5
-12,-19,19:18.5
-11,-19,19:18.5
-10,-19,19:18.5
-9,-19,19:18.5
-8,-19,19:18.5
-7,-19,19:18.5
-6,-19,19:18.5
-5,-19,19:18.5
-4,-19,19:18.5
-3,-19,19:18.5
-2,-19,19:18.5
-1,-19,19:18.5
-10,-18,19:18.5
-9,-18,19:18.5
-8,-18,19:18.5
-7,-18,19:18.5
-7,-17,19:18.5
-6,-17,19:18.5
-5,-17,19:18.5
-4,-17,19:18.5
19,-17,19:18.5
-17,-16,19:18.5
-4,-16,19:18.5
-3,-16,19:18.13
-2,-16,19:18.13
-1,-16,19:18.13
7,-16,19:18.5
8,-16,19:18.5
9,-16,19:18.5
10,-16,19:18.5
11,-16,19:18.5
12,-16,19:18.5
13,-16,19:18.5
14,-16,19:18.5
15,-16,19:18.5
16,-16,19:18.5
17,-16,19:18.5
18,-16,19:18.5
19,-16,19:18.5
-17,-15,19:18.5
-1,-15,19:18.13
0,-15,19:18.13
1,-15,19:18.13
2,-15,19:18.13
3,-15,19:18.13
4,-15,19:18.13
5,-15,19:18.13
6,-15,19:18.5
7,-15,19:18.5
9,-15,19:18.5
10,-15,19:18.5
11,-15,19:18.5
12,-15,19:18.5
13,-15,19:18.5
14,-15,19:18.5
15,-15,19:18.5
16,-15,19:18.5
17,-15,19:18.5
18,-15,19:18.5
19,-15,19:18.5
-18,-14,19:18.5
-17,-14,19:18.5
-2,-14,19:18.13
-1,-14,19:18.13
0,-14,19:18.13
1,-14,19:18.13
2,-14,19:18.13
3,-14,19:18.13
7,-14,19:18.5
9,-14,19:18.5
18,-14,19:18.5
19,-14,19:18.5
-18,-13,19:18.5
-17,-13,19:18.5
-3,-13,19:18.13
-2,-13,19:18.13
-1,-13,19:18.13
3,-13,19:18.13
4,-13,19:18.13
5,-13,19:18.13
17,-13,19:18.5
18,-13,19:18.5
19,-13,19:18.5
-17,-12,19:18.5
-5,-12,19:18.5
-4,-12,19:18.5
-3,-12,19:18.13
-2,-12,19:18.13
4,-12,19:18.13
5,-12,19:18.13
6,-12,19:18.5
17,-12,19:18.5
18,-12,19:18.5
-17,-11,19:18.5
-6,-11,19:18.5
-5,-11,19:18.5
-4,-11,19:18.5
5,-11,19:18.13
6,-11,19:18.5
7,-11,19:18.5
17,-11,19:18.5
18,-11,19:18.5
-18,-10,19:18.5
-17,-10,19:18.5
-7,-10,19:18.5
-6,-10,19:18.5
-5,-10,19:18.5
6,-10,19:18.5
7,-10,19:18.5
8,-10,19:18.5
17,-10,19:18.5
18,-10,19:18.5
-18,-9,19:18.5
-17,-9,19:18.5
-16,-9,19:18.5
-9,-9,19:18.5
-8,-9,19:18.5
-7,-9,19:18.5
-6,-9,19:18.5
8,-9,19:18.5
9,-9,19:18.5
10,-9,19:18.5
17,-9,19:18.5
18,-9,19:18.5
-18,-8,19:18.5
-16,-8,19:18.5
-10,-8,19:18.5
-9,-8,19:18.5
-8,-8,19:18.5
9,-8,19:18.5
10,-8,19:18.5
11,-8,19:18.5
17,-8,19:18.5
18,-8,19:18.5
-18,-7,19:18.5
-16,-7,19:18.5
-11,-7,19:18.5
-10,-7,19:18.5
-9,-7,19:18.5
10,-7,19:18.5
11,-7,19:18.5
17,-7,19:18.5
18,-7,19:18.5
-18,-6,19:18.5
-16,-6,19:18.5
-12,-6,19:18.5
-11,-6,19:18.5
-10,-6,19:18.5
11,-6,19:18.5
12,-6,19:18.5
17,-6,19:18.5
18,-6,19:18.5
-18,-5,19:18.5
-16,-5,19:18.5
-13,-5,19:18.5
-12,-5,19:18.5
-11,-5,19:18.5
11,-5,19:18.5
12,-5,19:18.5
17,-5,19:18.5
18,-5,19:18.5
-16,-4,19:18.13
-14,-4,19:18.13
-13,-4,19:18.13
-12,-4,19:18.13
12,-4,19:18.5
13,-4,19:18.5
16,-4,19:18.5
17,-4,19:18.5
-16,-3,19:18.13
-14,-3,19:18.13
-13,-3,19:18.13
12,-3,19:18.5
13,-3,19:18.5
14,-3,19:18.5
16,-3,19:18.5
17,-3,19:18.5
-15,-2,19:18.13
-14,-2,19:18.13
13,-2,19:18.13
14,-2,19:18.13
16,-2,19:18.13
17,-2,19:18.13
-16,-1,19:18.13
-15,-1,19:18.13
14,-1,19:18.13
15,-1,19:18.13
16,-1,19:18.13
17,-1,19:18.13
-16,0,19:18.13
-15,0,19:18.13
14,0,19:18.13
15,0,19:18.13
16,0,19:18.13
17,0,19:18.13
-19,1,19:18.5
-16,1,19:18.13
-15,1,19:18.13
15,1,19:18.13
16,1,19:18.13
17,1,19:18.13
-19,2,19:18.5
-16,2,19:18.13
-15,2,19:18.13
15,2,19:18.13
16,2,19:18.13
17,2,19:18.13
-19,3,19:18.5
-16,3,19:18.13
-15,3,19:18.13
-14,3,19:18.13
15,3,19:18.13
16,3,19:18.13
17,3,19:17.12
-19,4,19:18.5
-17,4,19:18.13
-15,4,19:18.13
-14,4,19:18.13
14,4,19:18.13
15,4,19:18.13
16,4,19:18.13
17,4,19:18.13
-19,5,19:18.5
-17,5,19:18.5
-14,5,19:18.5
-13,5,19:18.5
13,5,19:18.13
14,5,19:18.13
15,5,19:18.13
16,5,19:18.13
17,5,19:18.13
-19,6,19:18.5
-17,6,19:18.5
-14,6,19:18.5
-13,6,19:18.5
-12,6,19:18.5
13,6,19:18.13
14,6,19:18.13
16,6,19:18.13
17,6,19:18.13
-19,7,19:18.5
-18,7,19:18.5
-17,7,19:18.5
-13,7,19:18.5
-12,7,19:18.5
12,7,19:18.13
13,7,19:18.13
16,7,19:18.13
17,7,19:18.13
-20,8,19:18.5
-19,8,19:18.5
-18,8,19:18.5
-13,8,19:18.5
-12,8,19:18.5
-11,8,19:18.5
11,8,19:18.5
12,8,19:18.5
13,8,19:18.5
16,8,19:18.5
17,8,19:18.5
-18,9,19:18.5
-12,9,19:18.5
-11,9,19:18.5
-10,9,19:18.5
11,9,19:18.5
12,9,19:18.5
16,9,19:18.5
17,9,19:18.5
18,9,19:18.5
-20,10,19:18.5
-18,10,19:18.5
-11,10,19:18.5
-10,10,19:18.5
-9,10,19:18.5
10,10,19:18.5
11,10,19:18.5
17,10,19:18.5
18,10,19:18.5
-20,11,19:18.5
-19,11,19:18.5
-18,11,19:18.5
-11,11,19:18.5
-10,11,19:18.5
-9,11,19:18.5
-8,11,19:18.5
9,11,19:18.5
10,11,19:18.5
17,11,19:18.5
18,11,19:18.5
-19,12,19:18.5
-9,12,19:18.5
-8,12,19:18.5
-7,12,19:18.5
-6,12,19:18.5
7,12,19:18.5
8,12,19:18.5
9,12,19:18.5
17,12,19:18.5
18,12,19:18.5
-19,13,19:18.5
-8,13,19:18.5
-7,13,19:18.5
-6,13,19:18.5
-5,13,19:18.5
5,13,19:18.13
6,13,19:18.5
7,13,19:18.5
8,13,19:18.5
17,13,19:18.5
18,13,19:18.5
-19,14,19:18.5
-6,14,19:18.5
-5,14,19:18.5
-4,14,19:18.13
-3,14,19:18.13
3,14,19:18.13
4,14,19:18.13
5,14,19:18.13
6,14,19:18.5
17,14,19:18.5
18,14,19:18.5
-20,15,19:18.5
-19,15,19:18.5
-4,15,19:18.13
-3,15,19:18.13
-2,15,19:18.13
2,15,19:18.13
3,15,19:18.13
4,15,19:18.13
17,15,19:18.13
18,15,19:18.13
-20,16,19:18.5
-19,16,19:18.5
-4,16,19:18.13
-3,16,19:18.13
-2,16,19:18.13
-1,16,19:18.13
0,16,19:18.13
1,16,19:18.13
2,16,19:18.13
17,16,19:18.13
18,16,19:18.13
-20,17,19:18.5
-19,17,19:18.5
-16,17,19:18.5
-15,17,19:18.5
-14,17,19:18.5
-13,17,19:18.5
-11,17,19:18.5
-10,17,19:18.5
-9,17,19:18.5
-8,17,19:18.5
-7,17,19:18.5
-6,17,19:18.5
-5,17,19:18.5
-4,17,19:18.13
-3,17,19:18.13
-2,17,19:18.13
-1,17,19:18.13
0,17,19:18.13
1,17,19:18.13
2,17,19:18.13
3,17,19:18.13
4,17,19:18.13
17,17,19:18.13
18,17,19:18.13
-19,18,19:18.5
-18,18,19:18.5
-17,18,19:18.5
-16,18,19:18.5
-15,18,19:18.5
-14,18,19:18.5
-13,18,19:18.5
-12,18,19:18.5
-11,18,19:18.5
-10,18,19:18.5
-9,18,19:18.5
-8,18,19:18.5
-7,18,19:18.5
-6,18,19:18.5
-5,18,19:18.5
-4,18,19:18.13
-3,18,19:18.13
-2,18,19:18.13
0,18,19:17.12
1,18,19:18.13
2,18,19:18.13
3,18,19:18.13
4,18,19:18.13
5,18,19:18.13
6,18,19:18.5
7,18,19:18.5
-18,19,19:18.5
-16,19,19:18.5
4,19,19:18.13
5,19,19:18.5
6,19,19:18.5
7,19,19:18.5
8,19,19:18.5
9,19,19:18.13
10,19,19:18.13
-10,20,19:18.5
-9,20,19:18.5
-8,20,19:18.5
-7,20,19:18.5
7,20,19:18.5
8,20,19:18.5
9,20,19:18.5
11,20,19:18.5
12,20,19:18.5
13,20,19:18.5
1,21,19:18.13
2,21,19:18.13
3,21,19:18.13
4,21,19:18.13
5,21,19:18.5
6,21,19:18.5
7,21,19:18.5
10,21,19:18.5
11,21,19:18.5
12,21,19:18.5
13,21,19:18.5
14,21,19:18.13
8,22,19:18.5
13,22,19:18.5
-13,-20,20:18.5
-13,-19,20:18.5
-12,-19,20:18.5
-11,-19,20:18.5
-10,-19,20:18.5
-9,-19,20:18.5
-8,-19,20:18.5
-7,-19,20:18.5
-6,-19,20:18.5
-14,-18,20:18.5
-13,-18,20:18.5
-12,-18,20:18.5
-11,-18,20:18.5
-10,-18,20:18.5
-9,-18,20:18.5
-8,-18,20:18.5
-7,-18,20:18.5
-6,-18,20:18.5
-5,-18,20:18.5
-4,-18,20:18.5
-3,-18,20:18.5
-2,-18,20:18.5
-1,-18,20:18.5
0,-18,20:18.5
3,-18,20:18.5
6,-18,20:18.5
7,-18,20:18.5
8,-18,20:18.5
9,-18,20:18.5
10,-18,20:18.5
-6,-17,20:18.5
-5,-17,20:18.5
-4,-17,20:18.5
13,-17,20:18.5
14,-17,20:18.5
15,-17,20:18.5
16,-17,20:18.5
17,-17,20:18.5
18,-17,20:18.5
-16,-16,20:18.5
-3,-16,20:18.13
-2,-16,20:18.13
-1,-16,20:18.13
0,-16,20:18.13
4,-16,20:18.13
5,-16,20:18.13
6,-16,20:18.5
7,-16,20:18.5
8,-16,20:18.5
9,-16,20:18.5
10,-16,20:18.5
11,-16,20:18.5
12,-16,20:18.5
13,-16,20:18.5
14,-16,20:18.5
15,-16,20:18.5
16,-16,20:18.5
17,-16,20:18.5
18,-16,20:18.5
19,-16,20:18.5
-17,-15,20:18.5
-16,-15,20:18.5
-1,-15,20:18.13
0,-15,20:18.13
1,-15,20:18.13
2,-15,20:18.13
3,-15,20:18.13
4,-15,20:18.13
19,-15,20:18.5
-17,-14,20:18.5
-16,-14,20:18.5
-3,-14,20:18.13
-2,-14,20:18.13
-1,-14,20:18.13
2,-14,20:18.13
3,-14,20:18.13
19,-14,20:18.5
20,-14,20:18.5
-17,-13,20:18.5
-16,-13,20:18.5
-5,-13,20:18.5
-4,-13,20:18.5
-3,-13,20:18.13
5,-13,20:18.13
6,-13,20:18.5
7,-13,20:18.5
19,-13,20:18.5
20,-13,20:18.5
-17,-12,20:18.5
-16,-12,20:18.5
-7,-12,20:18.5
-6,-12,20:18.5
-5,-12,20:18.5
6,-12,20:18.5
7,-12,20:18.5
8,-12,20:18.5
19,-12,20:18.5
20,-12,20:18.5
-17,-11,20:18.5
-8,-11,20:18.5
-7,-11,20:18.5
-6,-11,20:18.5
7,-11,20:18.5
8,-11,20:18.5
9,-11,20:18.5
19,-11,20:18.5
20,-11,20:18.5
-17,-10,20:18.5
-10,-10,20:18.5
-9,-10,20:18.5
-8,-10,20:18.5
-7,-10,20:18.5
9,-10,20:18.5
10,-10,20:18.5
19,-10,20:18.5
20,-10,20:18.5
-17,-9,20:18.5
-11,-9,20:18.5
-10,-9,20:18.5
-9,-9,20:18.5
10,-9,20:18.5
11,-9,20:18.5
12,-9,20:18.5
19,-9,20:18.5
20,-9,20:18.5
-17,-8,20:18.5
-12,-8,20:18.5
-11,-8,20:18.5
-10,-8,20:18.5
11,-8,20:18.5
12,-8,20:18.5
18,-8,20:18.5
19,-8,20:18.5
-18,-7,20:18.5
-17,-7,20:18.5
-16,-7,20:18.5
-13,-7,20:18.5
-12,-7,20:18.5
-11,-7,20:18.5
12,-7,20:18.5
13,-7,20:18.5
18,-7,20:18.5
19,-7,20:18.5
20,-7,20:18.5
-18,-6,20:18.5
-17,-6,20:18.5
-16,-6,20:18.5
-13,-6,20:18.5
-12,-6,20:18.5
12,-6,20:18.5
13,-6,20:18.5
18,-6,20:18.5
19,-6,20:18.5
20,-6,20:18.5
-18,-5,20:18.5
-17,-5,20:18.5
-16,-5,20:18.5
-14,-5,20:18.5
-13,-5,20:18.5
13,-5,20:18.5
14,-5,20:18.5
18,-5,20:18.5
19,-5,20:18.5
-17,-4,20:18.13
-16,-4,20:18.13
-14,-4,20:18.13
13,-4,20:18.5
14,-4,20:18.5
15,-4,20:18.5
18,-4,20:18.5
19,-4,20:18.5
20,-4,20:18.5
-18,-3,20:18.5
-17,-3,20:18.13
-16,-3,20:18.13
-14,-3,20:18.13
14,-3,20:18.5
15,-3,20:18.5
18,-3,20:18.5
19,-3,20:18.5
20,-3,20:18.5
-18,-2,20:18.5
-15,-2,20:18.13
15,-2,20:18.13
16,-2,20:18.13
18,-2,20:18.13
19,-2,20:18.5
20,-2,20:18.5
-18,-1,20:18.5
-16,-1,20:18.13
-15,-1,20:18.13
15,-1,20:18.13
16,-1,20:18.13
18,-1,20:18.13
19,-1,20:18.13
20,-1,20:18.13
-18,0,20:18.5
-16,0,20:18.13
16,0,20:18.13
17,0,20:18.13
18,0,20:18.13
19,0,20:18.13
-18,1,20:18.5
-16,1,20:18.13
-15,1,20:18.13
16,1,20:18.13
17,1,20:18.13
18,1,20:18.13
19,1,20:18.13
-18,2,20:18.5
-16,2,20:18.13
-15,2,20:18.13
17,2,20:18.13
18,2,20:18.13
-19,3,20:18.5
-18,3,20:18.5
-17,3,20:18.13
-15,3,20:18.13
17,3,20:18.13
18,3,20:18.13
-19,4,20:18.5
-18,4,20:18.5
-17,4,20:18.13
-15,4,20:18.13
16,4,20:18.13
17,4,20:18.13
18,4,20:18.13
-19,5,20:18.5
-17,5,20:18.5
-15,5,20:18.5
15,5,20:18.13
16,5,20:18.13
17,5,20:18.13
18,5,20:18.13
-19,6,20:18.5
-18,6,20:18.5
-17,6,20:18.5
-15,6,20:18.5
-14,6,20:18.5
14,6,20:18.13
15,6,20:18.13
16,6,20:18.13
18,6,20:18.13
-19,7,20:18.5
-18,7,20:18.5
14,7,20:18.13
15,7,20:18.13
18,7,20:18.13
-19,8,20:18.5
-18,8,20:18.5
-14,8,20:18.5
-13,8,20:18.5
13,8,20:18.5
14,8,20:18.5
18,8,20:18.5
19,8,20:18.5
-19,9,20:18.5
-18,9,20:18.5
-14,9,20:18.5
-13,9,20:18.5
-12,9,20:18.5
12,9,20:18.5
13,9,20:18.5
18,9,20:18.5
19,9,20:18.5
-19,10,20:18.5
-18,10,20:18.5
-13,10,20:18.5
-12,10,20:18.5
11,10,20:18.5
12,10,20:18.5
13,10,20:18.5
18,10,20:18.5
19,10,20:18.5
-19,11,20:18.5
-13,11,20:18.5
-12,11,20:18.5
-11,11,20:18.5
11,11,20:18.5
12,11,20:18.5
18,11,20:18.5
19,11,20:18.5
-19,12,20:18.5
-12,12,20:18.5
-11,12,20:18.5
-10,12,20:18.5
-9,12,20:18.5
10,12,20:18.5
11,12,20:18.5
18,12,20:18.5
19,12,20:18.5
-19,13,20:18.5
-10,13,20:18.5
-9,13,20:18.5
-8,13,20:18.5
8,13,20:18.5
9,13,20:18.5
10,13,20:18.5
18,13,20:18.5
19,13,20:18.5
-20,14,20:18.5
-19,14,20:18.5
-9,14,20:18.5
-8,14,20:18.5
-7,14,20:18.5
-6,14,20:18.5
6,14,20:18.5
7,14,20:18.5
8,14,20:18.5
9,14,20:18.5
18,14,20:18.5
19,14,20:18.5
-20,15,20:18.5
-7,15,20:18.5
-6,15,20:18.5
-5,15,20:18.5
-4,15,20:18.13
4,15,20:18.13
5,15,20:18.13
6,15,20:18.5
7,15,20:18.5
18,15,20:18.13
19,15,20:18.13
-20,16,20:18.5
-6,16,20:18.5
-5,16,20:18.5
-4,16,20:18.13
-3,16,20:18.13
4,16,20:18.13
5,16,20:18.13
6,16,20:18.5
18,16,20:18.13
19,16,20:18.13
-4,17,20:18.13
-3,17,20:18.13
-2,17,20:18.13
-1,17,20:18.13
1,17,20:18.13
2,17,20:18.13
3,17,20:18.13
4,17,20:18.13
18,17,20:18.13
19,17,20:18.13
-15,18,20:18.5
-14,18,20:18.5
-13,18,20:18.5
-8,18,20:18.5
-7,18,20:18.5
-6,18,20:18.5
-5,18,20:18.5
-4,18,20:18.13
-3,18,20:18.13
-2,18,20:18.13
-1,18,20:18.13
0,18,20:18.13
1,18,20:18.13
2,18,20:18.13
-18,19,20:18.5
-17,19,20:18.5
-16,19,20:18.5
-15,19,20:18.5
-14,19,20:18.5
-13,19,20:18.5
-12,19,20:18.5
-11,19,20:18.5
-10,19,20:18.5
-9,19,20:18.5
-8,19,20:18.5
-7,19,20:18.5
-6,19,20:18.5
-5,19,20:18.5
-3,19,20:18.13
-2,19,20:18.13
-1,19,20:18.13
0,19,20:18.13
1,19,20:18.13
2,19,20:18.13
3,19,20:18.13
4,19,20:18.13
-7,20,20:18.5
-6,20,20:18.5
-3,20,20:18.13
-2,20,20:18.13
0,20,20:18.13
1,20,20:18.13
2,20,20:18.13
3,20,20:18.13
4,20,20:18.13
5,20,20:18.5
6,20,20:18.5
7,20,20:18.5
8,20,20:18.5
2,21,20:18.13
3,21,20:18.13
4,21,20:18.13
5,21,20:18.5
6,21,20:18.5
7,21,20:18.5
8,21,20:18.5
9,21,20:18.5
10,21,20:18.5
11,21,20:18.5
12,21,20:18.5
13,21,20:18.5
11,22,20:18.5
12,22,20:18.5
13,22,20:18.5
14,22,20:18.13
-11,-19,21:18.5
-10,-19,21:18.5
-9,-19,21:18.5
-15,-18,21:18.5
-14,-18,21:18.5
-13,-18,21:18.5
-12,-18,21:18.5
-11,-18,21:18.5
-10,-18,21:18.5
-9,-18,21:18.5
-8,-18,21:18.5
-7,-18,21:18.5
-6,-18,21:18.5
-5,-18,21:18.5
-15,-17,21:18.5
-14,-17,21:18.5
-13,-17,21:18.5
-12,-17,21:18.5
-11,-17,21:18.5
-10,-17,21:18.5
-9,-17,21:18.5
-8,-17,21:18.5
-7,-17,21:18.5
-6,-17,21:18.5
-5,-17,21:18.5
-4,-17,21:18.5
-3,-17,21:18.13
-2,-17,21:18.13
-1,-17,21:18.13
0,-17,21:18.13
1,-17,21:18.13
2,-17,21:18.13
3,-17,21:18.13
4,-17,21:18.13
5,-17,21:18.13
6,-17,21:18.5
7,-17,21:18.5
8,-17,21:18.5
9,-17,21:18.5
10,-17,21:18.5
11,-17,21:18.5
12,-17,21:18.5
13,-17,21:18.5
14,-17,21:18.5
15,-17,21:18.5
16,-17,21:18.5
17,-17,21:18.5
-15,-16,21:18.5
-2,-16,21:18.13
-1,-16,21:18.13
0,-16,21:18.13
1,-16,21:18.13
2,-16,21:18.13
3,-16,21:18.13
4,-16,21:18.13
5,-16,21:18.13
6,-16,21:18.5
7,-16,21:18.5
8,-16,21:18.5
9,-16,21:18.5
10,-16,21:18.5
11,-16,21:18.5
12,-16,21:18.5
13,-16,21:18.5
14,-16,21:18.5
15,-16,21:18.5
-16,-15,21:18.5
-15,-15,21:18.5
-1,-15,21:18.13
0,-15,21:18.13
1,-15,21:18.13
2,-15,21:18.13
3,-15,21:18.13
-18,-14,21:18.5
-16,-14,21:18.5
-15,-14,21:18.5
-4,-14,21:18.5
-3,-14,21:18.13
-2,-14,21:18.13
3,-14,21:18.13
5,-14,21:18.13
20,-14,21:18.5
-18,-13,21:18.5
-17,-13,21:18.5
-16,-13,21:18.5
-15,-13,21:18.5
-6,-13,21:18.5
-5,-13,21:18.5
-4,-13,21:18.5
5,-13,21:18.13
6,-13,21:18.5
7,-13,21:18.5
20,-13,21:18.5
-17,-12,21:18.5
-16,-12,21:18.5
-15,-12,21:18.5
-9,-12,21:18.5
-8,-12,21:18.5
-7,-12,21:18.5
8,-12,21:18.5
9,-12,21:18.5
19,-12,21:18.5
20,-12,21:18.5
-17,-11,21:18.5
-16,-11,21:18.5
-11,-11,21:18.5
-10,-11,21:18.5
-8,-11,21:18.5
9,-11,21:18.5
10,-11,21:18.5
11,-11,21:18.5
19,-11,21:18.5
20,-11,21:18.5
-17,-10,21:18.5
-16,-10,21:18.5
-11,-10,21:18.5
-10,-10,21:18.5
11,-10,21:18.5
12,-10,21:18.5
13,-10,21:18.5
19,-10,21:18.5
20,-10,21:18.5
-17,-9,21:18.5
-16,-9,21:18.5
-12,-9,21:18.5
-11,-9,21:18.5
12,-9,21:18.5
13,-9,21:18.5
19,-9,21:18.5
20,-9,21:18.5
-17,-8,21:18.5
-16,-8,21:18.5
-12,-8,21:18.5
13,-8,21:18.5
14,-8,21:18.5
19,-8,21:18.5
20,-8,21:18.5
-17,-7,21:18.5
-16,-7,21:18.5
-13,-7,21:18.5
13,-7,21:18.5
14,-7,21:18.5
19,-7,21:18.5
-17,-6,21:18.5
-16,-6,21:18.5
-13,-6,21:18.5
14,-6,21:18.5
15,-6,21:18.5
19,-6,21:18.5
-17,-5,21:18.5
-16,-5,21:18.5
-14,-5,21:18.5
14,-5,21:18.5
15,-5,21:18.5
18,-5,21:18.5
19,-5,21:18.5
-17,-4,21:18.5
-16,-4,21:18.5
-14,-4,21:18.5
15,-4,21:18.5
16,-4,21:18.5
18,-4,21:18.5
19,-4,21:18.5
-17,-3,21:18.5
-16,-3,21:18.5
-15,-3,21:18.5
16,-3,21:18.5
18,-3,21:18.5
19,-3,21:18.5
-17,-2,21:18.5
-15,-2,21:18.5
16,-2,21:18.13
17,-2,21:18.13
18,-2,21:18.13
19,-2,21:18.5
-17,-1,21:18.5
-16,-1,21:18.5
-15,-1,21:18.5
17,-1,21:18.13
18,-1,21:18.13
19,-1,21:18.13
-17,0,21:18.5
-16,0,21:18.5
17,0,21:18.13
18,0,21:18.13
19,0,21:18.13
-17,1,21:18.5
-16,1,21:18.5
18,1,21:18.13
19,1,21:18.13
-18,2,21:18.5
-17,2,21:18.5
-16,2,21:18.5
-15,2,21:18.5
18,2,21:18.13
19,2,21:18.13
-18,3,21:18.5
-17,3,21:18.5
-15,3,21:18.5
18,3,21:18.13
-18,4,21:18.5
-17,4,21:18.5
-15,4,21:18.5
17,4,21:18.13
18,4,21:18.13
-17,5,21:18.5
-15,5,21:18.5
17,5,21:18.13
18,5,21:18.13
-18,6,21:18.5
-17,6,21:18.5
-15,6,21:18.5
16,6,21:18.13
17,6,21:18.13
18,6,21:18.13
-18,7,21:18.5
-15,7,21:18.5
15,7,21:18.13
16,7,21:18.13
18,7,21:18.13
-18,8,21:18.5
-14,8,21:18.5
15,8,21:18.5
17,8,21:18.5
18,8,21:18.5
-19,9,21:18.5
-18,9,21:18.5
-14,9,21:18.5
14,9,21:18.5
15,9,21:18.5
17,9,21:18.5
18,9,21:18.5
19,9,21:18.5
-19,10,21:18.5
-18,10,21:18.5
-14,10,21:18.5
13,10,21:18.5
14,10,21:18.5
17,10,21:18.5
18,10,21:18.5
19,10,21:18.5
-19,11,21:18.5
-18,11,21:18.5
-14,11,21:18.5
-13,11,21:18.5
12,11,21:18.5
13,11,21:18.5
14,11,21:18.5
17,11,21:18.5
18,11,21:18.5
19,11,21:18.5
-19,12,21:18.5
-18,12,21:18.5
-14,12,21:18.5
-13,12,21:18.5
-12,12,21:18.5
11,12,21:18.5
12,12,21:18.5
13,12,21:18.5
17,12,21:18.5
18,12,21:18.5
19,12,21:18.5
-20,13,21:18.5
-19,13,21:18.5
-18,13,21:18.5
-13,13,21:18.5
-12,13,21:18.5
-11,13,21:18.5
-10,13,21:18.5
11,13,21:18.5
12,13,21:18.5
17,13,21:18.5
18,13,21:18.5
19,13,21:18.5
-19,14,21:18.5
-18,14,21:18.5
-11,14,21:18.5
-10,14,21:18.5
-9,14,21:18.5
9,14,21:18.5
10,14,21:18.5
11,14,21:18.5
17,14,21:18.5
18,14,21:18.5
19,14,21:18.5
-19,15,21:18.5
-18,15,21:18.5
-10,15,21:18.5
-9,15,21:18.5
-8,15,21:18.5
-7,15,21:18.5
7,15,21:18.5
8,15,21:18.5
9,15,21:18.5
10,15,21:18.5
17,15,21:18.13
18,15,21:18.13
19,15,21:18.13
-7,16,21:18.5
-6,16,21:18.5
-5,16,21:18.5
6,16,21:18.5
7,16,21:18.5
8,16,21:18.5
17,16,21:18.13
19,16,21:18.13
-16,17,21:18.5
-15,17,21:18.5
-14,17,21:18.5
-5,17,21:18.5
-4,17,21:18.13
-3,17,21:18.13
3,17,21:18.13
4,17,21:18.13
5,17,21:18.5
6,17,21:18.5
17,17,21:18.13
19,17,21:18.13
-16,18,21:18.5
-15,18,21:18.5
-14,18,21:18.5
-13,18,21:18.5
-12,18,21:18.5
-11,18,21:18.5
-10,18,21:18.5
-9,18,21:18.5
-8,18,21:18.5
-7,18,21:18.5
-6,18,21:18.5
-5,18,21:18.5
-4,18,21:18.13
-3,18,21:18.13
-2,18,21:18.13
-1,18,21:18.13
1,18,21:18.13
2,18,21:18.13
3,18,21:18.13
-15,19,21:18.5
-14,19,21:18.5
-13,19,21:18.5
-12,19,21:18.5
-11,19,21:18.5
-10,19,21:18.5
-9,19,21:18.5
-8,19,21:18.5
-7,19,21:18.5
-6,19,21:18.5
-5,19,21:18.5
-3,19,21:18.13
-2,19,21:18.13
-1,19,21:18.13
0,19,21:18.13
1,19,21:18.13
2,19,21:18.13
3,19,21:18.13
4,19,21:18.13
5,19,21:18.5
6,19,21:18.5
-14,20,21:18.5
-12,20,21:18.5
1,20,21:18.13
2,20,21:18.13
3,20,21:18.13
4,20,21:18.13
5,20,21:18.5
6,20,21:18.5
7,20,21:18.5
8,20,21:18.5
9,20,21:18.5
11,20,21:18.5
12,20,21:18.5
13,20,21:18.5
14,20,21:18.13
15,20,21:18.13
5,21,21:18.5
6,21,21:18.5
7,21,21:18.5
8,21,21:18.5
9,21,21:18.5
10,21,21:18.5
11,21,21:18.5
12,21,21:18.5
13,21,21:18.5
14,21,21:18.13
15,21,21:18.13
9,22,21:18.5
10,22,21:18.5
11,22,21:18.5
12,22,21:18.5
13,22,21:18.5
13,23,21:18.5
-10,-19,22:18.5
-9,-19,22:18.5
-8,-19,22:18.5
-15,-18,22:18.5
-8,-18,22:18.5
-7,-18,22:18.5
-6,-18,22:18.5
-5,-18,22:18.5
-15,-17,22:18.5
-14,-17,22:18.5
-13,-17,22:18.5
-10,-17,22:18.5
-5,-17,22:18.5
-4,-17,22:18.5
-3,-17,22:18.5
-2,-17,22:18.5
8,-17,22:18.5
9,-17,22:18.5
10,-17,22:18.5
11,-17,22:18.5
12,-17,22:18.5
13,-17,22:18.5
14,-17,22:18.5
15,-17,22:18.5
-15,-16,22:18.5
-14,-16,22:18.5
-13,-16,22:18.5
-12,-16,22:18.5
-11,-16,22:18.5
-10,-16,22:18.5
-9,-16,22:18.5
-8,-16,22:18.5
-7,-16,22:18.5
-6,-16,22:18.5
-5,-16,22:18.5
-4,-16,22:18.5
-3,-16,22:18.5
-2,-16,22:18.5
-1,-16,22:18.5
0,-16,22:18.5
1,-16,22:18.5
2,-16,22:18.5
3,-16,22:18.5
4,-16,22:18.5
5,-16,22:18.5
6,-16,22:18.5
7,-16,22:18.5
8,-16,22:18.5
9,-16,22:18.5
10,-16,22:18.5
11,-16,22:18.5
12,-16,22:18.5
13,-16,22:18.5
14,-16,22:18.5
15,-16,22:18.5
16,-16,22:18.5
-15,-15,22:18.5
-14,-15,22:18.5
-2,-15,22:18.5
-1,-15,22:18.5
0,-15,22:18.5
1,-15,22:18.5
2,-15,22:18.5
3,-15,22:18.5
4,-15,22:18.5
7,-15,22:18.5
9,-15,22:18.5
10,-15,22:18.5
11,-15,22:18.5
12,-15,22:18.5
13,-15,22:18.5
14,-15,22:18.5
15,-15,22:18.5
-15,-14,22:18.5
-14,-14,22:18.5
-5,-14,22:18.5
-4,-14,22:18.5
-3,-14,22:18.5
5,-14,22:18.5
6,-14,22:18.5
18,-14,22:18.5
-18,-13,22:18.5
-15,-13,22:18.5
-14,-13,22:18.5
-7,-13,22:18.5
-6,-13,22:18.5
-5,-13,22:18.5
6,-13,22:18.5
7,-13,22:18.5
8,-13,22:18.5
18,-13,22:18.5
19,-13,22:18.5
-18,-12,22:18.5
-15,-12,22:18.5
-10,-12,22:18.5
-9,-12,22:18.5
-8,-12,22:18.5
-7,-12,22:18.5
8,-12,22:18.5
9,-12,22:18.5
10,-12,22:18.5
18,-12,22:18.5
19,-12,22:18.5
20,-12,22:18.5
-18,-11,22:18.5
-17,-11,22:18.5
-15,-11,22:18.5
-11,-11,22:18.5
-10,-11,22:18.5
10,-11,22:18.5
11,-11,22:18.5
12,-11,22:18.5
18,-11,22:18.5
19,-11,22:18.5
20,-11,22:18.5
-17,-10,22:18.5
-15,-10,22:18.5
-12,-10,22:18.5
-11,-10,22:18.5
13,-10,22:18.5
14,-10,22:18.5
18,-10,22:18.5
20,-10,22:18.5
-17,-9,22:18.5
-15,-9,22:18.5
-12,-9,22:18.5
14,-9,22:18.5
18,-9,22:18.5
20,-9,22:18.5
-17,-8,22:18.5
-16,-8,22:18.5
-15,-8,22:18.5
-13,-8,22:18.5
-12,-8,22:18.5
14,-8,22:18.5
15,-8,22:18.5
18,-8,22:18.5
20,-8,22:18.5
-17,-7,22:18.5
-16,-7,22:18.5
-15,-7,22:18.5
-13,-7,22:18.5
15,-7,22:18.5
18,-7,22:18.5
19,-7,22:18.5
20,-7,22:18.5
-17,-6,22:18.5
-16,-6,22:18.5
-15,-6,22:18.5
-14,-6,22:18.5
-13,-6,22:18.5
15,-6,22:18.5
17,-6,22:18.5
18,-6,22:18.5
19,-6,22:18.5
-17,-5,22:18.5
-16,-5,22:18.5
-15,-5,22:18.5
-14,-5,22:18.5
16,-5,22:18.5
17,-5,22:18.5
18,-5,22:18.5
19,-5,22:18.5
-17,-4,22:18.5
-16,-4,22:18.5
-15,-4,22:18.5
-14,-4,22:18.5
16,-4,22:18.5
17,-4,22:18.5
18,-4,22:18.5
19,-4,22:18.5
-17,-3,22:18.5
-16,-3,22:18.5
-15,-3,22:18.5
16,-3,22:18.5
17,-3,22:18.5
18,-3,22:18.5
19,-3,22:18.5
-15,-2,22:18.5
17,-2,22:18.5
18,-2,22:18.5
19,-2,22:18.5
-16,-1,22:18.5
17,-1,22:18.13
18,-1,22:18.13
19,-1,22:18.13
-16,0,22:18.5
17,0,22:18.13
18,0,22:18.13
19,0,22:18.13
-17,1,22:18.5
-16,1,22:18.5
17,1,22:18.13
18,1,22:18.13
19,1,22:18.13
-17,2,22:18.5
-16,2,22:18.5
17,2,22:18.13
18,2,22:18.13
19,2,22:18.13
-17,3,22:18.5
-16,3,22:18.5
17,3,22:18.13
18,3,22:18.13
-18,4,22:18.5
-17,4,22:18.5
-16,4,22:18.5
-15,4,22:18.5
17,4,22:18.13
18,4,22:18.13
-17,5,22:18.5
-16,5,22:18.5
-15,5,22:18.5
17,5,22:18.13
18,5,22:18.13
19,5,22:18.13
-18,6,22:18.5
-17,6,22:18.5
-15,6,22:18.5
16,6,22:18.13
17,6,22:18.13
18,6,22:18.13
19,6,22:18.13
-18,7,22:18.5
-17,7,22:18.5
-15,7,22:18.5
16,7,22:18.13
17,7,22:18.13
19,7,22:18.13
-19,8,22:18.5
-18,8,22:18.5
-17,8,22:18.5
-15,8,22:18.5
15,8,22:18.5
16,8,22:18.5
17,8,22:18.5
19,8,22:18.5
-19,9,22:18.5
-17,9,22:18.5
-14,9,22:18.5
15,9,22:18.5
16,9,22:18.5
17,9,22:18.5
19,9,22:18.5
-19,10,22:18.5
-17,10,22:18.5
-14,10,22:18.5
14,10,22:18.5
16,10,22:18.5
17,10,22:18.5
19,10,22:18.5
-19,11,22:18.5
-18,11,22:18.5
-17,11,22:18.5
-14,11,22:18.5
13,11,22:18.5
14,11,22:18.5
16,11,22:18.5
17,11,22:18.5
19,11,22:18.5
-20,12,22:18.5
-18,12,22:18.5
-17,12,22:18.5
-14,12,22:18.5
13,12,22:18.5
16,12,22:18.5
17,12,22:18.5
19,12,22:18.5
-20,13,22:18.5
-18,13,22:18.5
-13,13,22:18.5
12,13,22:18.5
13,13,22:18.5
16,13,22:18.5
17,13,22:18.5
19,13,22:18.5
-20,14,22:18.5
-18,14,22:18.5
-17,14,22:18.5
-13,14,22:18.5
-12,14,22:18.5
-11,14,22:18.5
12,14,22:18.5
16,14,22:18.5
17,14,22:18.5
19,14,22:18.5
-18,15,22:18.5
-17,15,22:18.5
-11,15,22:18.5
-10,15,22:18.5
-9,15,22:18.5
10,15,22:18.5
11,15,22:18.5
16,15,22:18.13
19,15,22:18.13
-19,16,22:18.5
-18,16,22:18.5
-17,16,22:18.5
-16,16,22:18.5
-15,16,22:18.5
-14,16,22:18.5
-9,16,22:18.5
-8,16,22:18.5
-7,16,22:18.5
7,16,22:18.5
8,16,22:18.5
9,16,22:18.5
10,16,22:18.5
16,16,22:18.13
19,16,22:18.13
-18,17,22:18.5
-17,17,22:18.5
-16,17,22:18.5
-15,17,22:18.5
-14,17,22:18.5
-13,17,22:18.5
-11,17,22:18.5
-10,17,22:18.5
-9,17,22:18.5
-8,17,22:18.5
-7,17,22:18.5
-6,17,22:18.5
-5,17,22:18.5
-4,17,22:18.13
5,17,22:18.5
6,17,22:18.5
7,17,22:18.5
16,17,22:18.13
19,17,22:18.13
-9,18,22:18.5
-8,18,22:18.5
-7,18,22:18.5
-6,18,22:18.5
-5,18,22:18.5
-4,18,22:18.13
-3,18,22:18.13
-2,18,22:18.13
-1,18,22:18.13
0,18,22:18.13
1,18,22:18.13
2,18,22:18.13
3,18,22:18.13
4,18,22:18.13
5,18,22:18.5
13,18,22:18.14
16,18,22:18.13
-3,19,22:18.13
-2,19,22:18.13
-1,19,22:18.13
0,19,22:18.13
1,19,22:18.13
2,19,22:18.13
3,19,22:18.13
4,19,22:18.13
5,19,22:18.5
6,19,22:18.5
7,19,22:18.5
8,19,22:18.5
9,19,22:18.5
10,19,22:18.5
11,19,22:18.5
12,19,22:18.13
13,19,22:18.13
14,19,22:18.13
15,19,22:18.13
16,19,22:18.13
-15,20,22:18.5
-14,20,22:18.5
-13,20,22:18.5
-12,20,22:18.5
-11,20,22:18.5
-10,20,22:18.5
-9,20,22:18.5
-8,20,22:18.5
-7,20,22:18.5
-6,20,22:18.5
-5,20,22:18.5
-4,20,22:18.13
-3,20,22:18.13
-2,20,22:18.13
-1,20,22:18.13
0,20,22:18.13
1,20,22:18.13
2,20,22:18.13
3,20,22:18.13
4,20,22:18.13
11,20,22:18.5
12,20,22:18.5
13,20,22:18.5
14,20,22:18.13
15,20,22:18.13
16,20,22:18.13
3,21,22:18.13
4,21,22:18.13
5,21,22:18.5
6,21,22:18.5
7,21,22:18.5
16,21,22:18.13
7,22,22:18.5
8,22,22:18.5
9,22,22:18.5
10,22,22:18.5
11,22,22:18.5
11,23,22:18.5
12,23,22:18.5
-9,-19,23:18.5
-8,-19,23:18.5
-7,-19,23:18.5
-7,-18,23:18.5
-6,-18,23:18.5
-5,-18,23:18.5
-4,-18,23:18.5
14,-18,23:18.5
15,-18,23:18.5
-14,-17,23:18.5
-13,-17,23:18.5
-4,-17,23:18.5
-3,-17,23:18.5
-2,-17,23:18.5
-1,-17,23:18.5
5,-17,23:18.5
6,-17,23:18.5
7,-17,23:18.5
8,-17,23:18.5
9,-17,23:18.5
10,-17,23:18.5
11,-17,23:18.5
12,-17,23:18.5
13,-17,23:18.5
14,-17,23:18.5
15,-17,23:18.5
-14,-16,23:18.5
-13,-16,23:18.5
-12,-16,23:18.5
-11,-16,23:18.5
-1,-16,23:18.5
0,-16,23:18.5
1,-16,23:18.5
2,-16,23:18.5
3,-16,23:18.5
4,-16,23:18.5
5,-16,23:18.5
-14,-15,23:18.5
-13,-15,23:18.5
-12,-15,23:18.5
-11,-15,23:18.5
-10,-15,23:18.5
-9,-15,23:18.5
-8,-15,23:18.5
-7,-15,23:18.5
-6,-15,23:18.5
-5,-15,23:18.5
-4,-15,23:18.5
-3,-15,23:18.5
-2,-15,23:18.5
-1,-15,23:18.5
0,-15,23:18.5
1,-15,23:18.5
2,-15,23:18.5
3,-15,23:18.5
4,-15,23:18.5
5,-15,23:18.5
6,-15,23:18.5
7,-15,23:18.5
9,-15,23:18.5
10,-15,23:18.5
11,-15,23:18.5
12,-15,23:18.5
13,-15,23:18.5
14,-15,23:18.5
15,-15,23:18.5
16,-15,23:18.5
17,-15,23:18.5
18,-15,23:18.5
-14,-14,23:18.5
-13,-14,23:18.5
-5,-14,23:18.5
-4,-14,23:18.5
-3,-14,23:18.5
5,-14,23:18.5
6,-14,23:18.5
7,-14,23:18.5
8,-14,23:18.5
9,-14,23:18.5
10,-14,23:18.5
11,-14,23:18.5
12,-14,23:18.5
13,-14,23:18.5
14,-14,23:18.5
15,-14,23:18.5
16,-14,23:18.5
17,-14,23:18.5
18,-14,23:18.5
-14,-13,23:18.5
-8,-13,23:18.5
-7,-13,23:18.5
-6,-13,23:18.5
7,-13,23:18.5
8,-13,23:18.5
9,-13,23:18.5
17,-13,23:18.5
18,-13,23:18.5
-18,-12,23:18.5
-14,-12,23:18.5
-10,-12,23:18.5
-9,-12,23:18.5
-8,-12,23:18.5
9,-12,23:18.5
10,-12,23:18.5
11,-12,23:18.5
17,-12,23:18.5
18,-12,23:18.5
20,-12,23:18.5
-18,-11,23:18.5
-14,-11,23:18.5
-11,-11,23:18.5
-10,-11,23:18.5
11,-11,23:18.5
12,-11,23:18.5
17,-11,23:18.5
20,-11,23:18.5
-18,-10,23:18.5
-14,-10,23:18.5
-12,-10,23:18.5
-11,-10,23:18.5
13,-10,23:18.5
14,-10,23:18.5
17,-10,23:18.5
20,-10,23:18.5
-18,-9,23:18.5
-17,-9,23:18.5
-15,-9,23:18.5
-14,-9,23:18.5
-12,-9,23:18.5
14,-9,23:18.5
17,-9,23:18.5
20,-9,23:18.5
-17,-8,23:18.5
-15,-8,23:18.5
-14,-8,23:18.5
-13,-8,23:18.5
15,-8,23:18.5
17,-8,23:18.5
20,-8,23:18.5
-17,-7,23:18.5
-15,-7,23:18.5
-14,-7,23:18.5
-13,-7,23:18.5
15,-7,23:18.5
17,-7,23:18.5
20,-7,23:18.5
-17,-6,23:18.5
-15,-6,23:18.5
-14,-6,23:18.5
15,-6,23:18.5
16,-6,23:18.5
17,-6,23:18.5
19,-6,23:18.5
20,-6,23:18.5
-17,-5,23:18.5
-15,-5,23:18.5
-14,-5,23:18.5
16,-5,23:18.5
17,-5,23:18.5
19,-5,23:18.5
-17,-4,23:18.5
-15,-4,23:18.5
-14,-4,23:18.5
16,-4,23:18.5
17,-4,23:18.5
19,-4,23:18.5
-17,-3,23:18.5
-15,-3,23:18.5
16,-3,23:18.5
17,-3,23:18.5
19,-3,23:18.5
-17,-2,23:18.5
-15,-2,23:18.5
16,-2,23:18.5
17,-2,23:18.5
19,-2,23:18.5
-17,-1,23:18.5
-16,-1,23:18.5
-15,-1,23:18.5
16,-1,23:18.13
17,-1,23:18.13
19,-1,23:18.13
-17,0,23:18.5
-16,0,23:18.5
-15,0,23:18.5
16,0,23:18.13
17,0,23:18.13
18,0,23:18.13
19,0,23:18.13
-17,1,23:18.5
-16,1,23:18.5
-15,1,23:18.5
16,1,23:18.13
17,1,23:18.13
18,1,23:18.13
19,1,23:18.13
-17,2,23:18.5
-16,2,23:18.5
-15,2,23:18.5
16,2,23:18.13
18,2,23:18.13
19,2,23:18.13
-17,3,23:18.5
-16,3,23:18.5
-15,3,23:18.5
16,3,23:18.13
18,3,23:18.13
19,3,23:18.13
-18,4,23:18.5
-16,4,23:18.5
-15,4,23:18.5
16,4,23:18.13
18,4,23:18.13
19,4,23:18.13
-16,5,23:18.5
-15,5,23:18.5
16,5,23:18.13
17,5,23:18.13
19,5,23:18.13
-18,6,23:18.5
-16,6,23:18.5
-15,6,23:18.5
16,6,23:18.13
17,6,23:18.13
19,6,23:18.13
-19,7,23:18.5
-18,7,23:18.5
-16,7,23:18.5
-15,7,23:18.5
15,7,23:18.13
16,7,23:18.13
19,7,23:18.13
-19,8,23:18.5
-16,8,23:18.5
-15,8,23:18.5
15,8,23:18.5
16,8,23:18.5
19,8,23:18.5
-19,9,23:18.5
-16,9,23:18.5
-15,9,23:18.5
15,9,23:18.5
16,9,23:18.5
19,9,23:18.5
-19,10,23:18.5
-17,10,23:18.5
-16,10,23:18.5
-15,10,23:18.5
-14,10,23:18.5
14,10,23:18.5
15,10,23:18.5
16,10,23:18.5
19,10,23:18.5
-20,11,23:18.5
-17,11,23:18.5
-16,11,23:18.5
-14,11,23:18.5
14,11,23:18.5
15,11,23:18.5
16,11,23:18.5
19,11,23:18.5
-20,12,23:18.5
-17,12,23:18.5
-16,12,23:18.5
-14,12,23:18.5
-13,12,23:18.5
13,12,23:18.5
15,12,23:18.5
16,12,23:18.5
19,12,23:18.5
-20,13,23:18.5
-17,13,23:18.5
-16,13,23:18.5
-13,13,23:18.5
-12,13,23:18.5
12,13,23:18.5
13,13,23:18.5
15,13,23:18.5
16,13,23:18.5
19,13,23:18.5
-17,14,23:18.5
-12,14,23:18.5
11,14,23:18.5
12,14,23:18.5
15,14,23:18.5
16,14,23:18.5
19,14,23:18.5
-17,15,23:18.5
-16,15,23:18.5
-15,15,23:18.5
-11,15,23:18.5
-10,15,23:18.5
10,15,23:18.5
11,15,23:18.5
15,15,23:18.5
19,15,23:18.5
-18,16,23:18.5
-17,16,23:18.5
-16,16,23:18.5
-15,16,23:18.5
-14,16,23:18.5
-13,16,23:18.5
-12,16,23:18.5
-11,16,23:18.5
-10,16,23:18.5
-9,16,23:18.5
-8,16,23:18.5
-7,16,23:18.5
-6,16,23:18.5
-5,16,23:18.5
9,16,23:18.5
10,16,23:18.5
15,16,23:18.5
19,16,23:18.5
-17,17,23:18.5
-9,17,23:18.5
-8,17,23:18.5
-7,17,23:18.5
-6,17,23:18.5
-5,17,23:18.5
-4,17,23:18.13
-3,17,23:18.13
-2,17,23:18.13
-1,17,23:18.13
0,17,23:18.13
1,17,23:18.13
2,17,23:18.13
3,17,23:18.13
4,17,23:18.13
5,17,23:18.5
6,17,23:18.5
7,17,23:18.5
8,17,23:18.5
15,17,23:18.13
-5,18,23:18.5
-4,18,23:18.13
0,18,23:18.13
1,18,23:18.13
2,18,23:18.13
3,18,23:18.13
4,18,23:18.13
5,18,23:18.5
6,18,23:18.5
7,18,23:18.5
8,18,23:18.5
9,18,23:18.5
10,18,23:18.5
11,18,23:18.5
12,18,23:18.5
13,18,23:18.5
14,18,23:18.5
15,18,23:18.13
-3,19,23:18.13
-2,19,23:18.13
-1,19,23:18.13
1,19,23:18.13
2,19,23:18.13
3,19,23:18.13
10,19,23:18.5
11,19,23:18.5
12,19,23:18.5
13,19,23:18.5
14,19,23:18.5
15,19,23:18.13
16,19,23:18.13
-13,20,23:18.5
-12,20,23:18.5
-11,20,23:18.5
-10,20,23:18.5
-9,20,23:18.5
-8,20,23:18.5
-7,20,23:18.5
-6,20,23:18.5
-5,20,23:18.5
-4,20,23:18.13
-3,20,23:18.13
-2,20,23:18.13
-1,20,23:18.13
0,20,23:18.13
1,20,23:18.13
2,20,23:18.13
15,20,23:18.5
-12,21,23:18.5
-11,21,23:18.5
2,21,23:18.13
3,21,23:18.13
4,21,23:18.13
5,21,23:18.5
5,22,23:18.5
6,22,23:18.5
7,22,23:18.5
8,22,23:18.5
9,22,23:18.5
9,23,23:18.5
10,23,23:18.5
-9,-19,24:18.5
-8,-19,24:18.5
-7,-19,24:18.5
-6,-19,24:18.5
-6,-18,24:18.5
-5,-18,24:18.5
-4,-18,24:18.5
-3,-18,24:18.5
12,-18,24:18.5
13,-18,24:18.5
-3,-17,24:18.5
-2,-17,24:18.5
-1,-17,24:18.5
0,-17,24:18.5
2,-17,24:18.5
3,-17,24:18.5
4,-17,24:18.5
5,-17,24:18.5
6,-17,24:18.5
7,-17,24:18.5
8,-17,24:18.5
9,-17,24:18.5
10,-17,24:18.5
11,-17,24:18.5
-13,-16,24:18.5
-12,-16,24:18.5
-1,-16,24:18.5
0,-16,24:18.5
1,-16,24:18.5
2,-16,24:18.5
3,-16,24:18.5
-13,-15,24:18.5
-12,-15,24:18.5
-4,-15,24:18.5
-3,-15,24:18.5
-2,-15,24:18.5
3,-15,24:18.5
4,-15,24:18.5
5,-15,24:18.5
17,-15,24:18.5
-13,-14,24:18.5
-12,-14,24:18.5
-11,-14,24:18.5
-10,-14,24:18.5
-9,-14,24:18.5
-8,-14,24:18.5
-7,-14,24:18.5
-6,-14,24:18.5
-5,-14,24:18.5
-4,-14,24:18.5
-3,-14,24:18.5
-2,-14,24:18.5
-1,-14,24:18.5
0,-14,24:18.5
1,-14,24:18.5
2,-14,24:18.5
3,-14,24:18.5
5,-14,24:18.5
6,-14,24:18.5
7,-14,24:18.5
8,-14,24:18.5
9,-14,24:18.5
10,-14,24:18.5
11,-14,24:18.5
12,-14,24:18.5
13,-14,24:18.5
14,-14,24:18.5
15,-14,24:18.5
16,-14,24:18.5
17,-14,24:18.5
18,-14,24:18.5
-13,-13,24:18.5
-8,-13,24:18.5
-7,-13,24:18.5
3,-13,24:18.5
4,-13,24:18.5
5,-13,24:18.5
6,-13,24:18.5
7,-13,24:18.5
8,-13,24:18.5
9,-13,24:18.5
10,-13,24:18.5
11,-13,24:18.5
12,-13,24:18.5
13,-13,24:18.5
14,-13,24:18.5
15,-13,24:18.5
16,-13,24:18.5
17,-13,24:18.5
-18,-12,24:18.5
-13,-12,24:18.5
-9,-12,24:18.5
-8,-12,24:18.5
10,-12,24:18.5
11,-12,24:18.5
16,-12,24:18.5
-18,-11,24:18.5
-13,-11,24:18.5
-10,-11,24:18.5
11,-11,24:18.5
12,-11,24:18.5
16,-11,24:18.5
20,-11,24:18.5
-18,-10,24:18.5
-13,-10,24:18.5
-12,-10,24:18.5
-11,-10,24:18.5
12,-10,24:18.5
13,-10,24:18.5
16,-10,24:18.5
20,-10,24:18.5
-18,-9,24:18.5
-14,-9,24:18.5
-13,-9,24:18.5
-12,-9,24:18.5
13,-9,24:18.5
14,-9,24:18.5
16,-9,24:18.5
20,-9,24:18.5
-18,-8,24:18.5
-14,-8,24:18.5
-13,-8,24:18.5
14,-8,24:18.5
15,-8,24:18.5
16,-8,24:18.5
20,-8,24:18.5
-18,-7,24:18.5
-17,-7,24:18.5
-14,-7,24:18.5
-13,-7,24:18.5
15,-7,24:18.5
16,-7,24:18.5
20,-7,24:18.5
-17,-6,24:18.5
-14,-6,24:18.5
-13,-6,24:18.5
15,-6,24:18.5
16,-6,24:18.5
20,-6,24:18.5
-17,-5,24:18.5
-15,-5,24:18.5
-14,-5,24:18.5
15,-5,24:18.5
16,-5,24:18.5
19,-5,24:18.5
20,-5,24:18.5
-17,-4,24:18.5
-15,-4,24:18.5
-14,-4,24:18.5
15,-4,24:18.5
16,-4,24:18.5
19,-4,24:18.5
-17,-3,24:18.5
-16,-3,24:18.5
-15,-3,24:18.5
-14,-3,24:18.5
15,-3,24:18.5
16,-3,24:18.5
17,-3,24:18.5
19,-3,24:18.5
-17,-2,24:18.5
-14,-2,24:18.5
15,-2,24:18.5
16,-2,24:18.5
17,-2,24:18.5
19,-2,24:18.5
-17,-1,24:18.5
-16,-1,24:18.5
-14,-1,24:18.5
15,-1,24:18.5
16,-1,24:18.5
17,-1,24:18.5
19,-1,24:18.5
-17,0,24:18.5
-15,0,24:18.5
-14,0,24:18.5
15,0,24:18.5
16,0,24:18.5
18,0,24:18.5
19,0,24:18.5
-17,1,24:18.5
-16,1,24:18.5
-15,1,24:18.5
-14,1,24:18.5
15,1,24:18.5
16,1,24:18.5
18,1,24:18.5
19,1,24:18.5
-17,2,24:18.5
-16,2,24:18.5
-15,2,24:18.5
-14,2,24:18.5
15,2,24:18.5
18,2,24:18.5
19,2,24:18.5
-18,3,24:18.5
-16,3,24:18.5
-15,3,24:18.5
-14,3,24:18.5
15,3,24:18.5
18,3,24:18.5
19,3,24:18.5
-18,4,24:18.5
-16,4,24:18.5
-15,4,24:18.5
-14,4,24:18.5
15,4,24:18.5
18,4,24:18.5
19,4,24:18.5
-16,5,24:18.5
-15,5,24:18.5
15,5,24:18.5
17,5,24:18.5
19,5,24:18.5
-19,6,24:18.5
-18,6,24:18.5
-16,6,24:18.5
-15,6,24:18.5
14,6,24:18.5
15,6,24:18.5
17,6,24:18.5
19,6,24:18.5
-19,7,24:18.5
-15,7,24:18.5
14,7,24:18.5
15,7,24:18.5
16,7,24:18.5
19,7,24:18.5
-19,8,24:18.5
-15,8,24:18.5
14,8,24:18.5
15,8,24:18.5
16,8,24:18.5
19,8,24:18.5
-19,9,24:18.5
-16,9,24:18.5
-15,9,24:18.5
14,9,24:18.5
15,9,24:18.5
19,9,24:18.5
-20,10,24:18.5
-16,10,24:18.5
-15,10,24:18.5
-14,10,24:18.5
14,10,24:18.5
15,10,24:18.5
19,10,24:18.5
-20,11,24:18.5
-16,11,24:18.5
-15,11,24:18.5
-14,11,24:18.5
-13,11,24:18.5
14,11,24:18.5
15,11,24:18.5
19,11,24:18.5
-20,12,24:18.5
-16,12,24:18.5
-15,12,24:18.5
-13,12,24:18.5
13,12,24:18.5
14,12,24:18.5
15,12,24:18.5
19,12,24:18.5
-16,13,24:18.5
-15,13,24:18.5
-12,13,24:18.5
12,13,24:18.5
13,13,24:18.5
14,13,24:18.5
15,13,24:18.5
19,13,24:18.5
-18,14,24:18.5
-17,14,24:18.5
-15,14,24:18.5
-12,14,24:18.5
-11,14,24:18.5
11,14,24:18.5
12,14,24:18.5
14,14,24:18.5
15,14,24:18.5
19,14,24:18.5
-18,15,24:18.5
-17,15,24:18.5
-16,15,24:18.5
-15,15,24:18.5
-14,15,24:18.5
-13,15,24:18.5
-12,15,24:18.5
-11,15,24:18.5
-10,15,24:18.5
-9,15,24:18.5
-8,15,24:18.5
-7,15,24:18.5
-6,15,24:18.5
10,15,24:18.5
11,15,24:18.5
14,15,24:18.5
-16,16,24:18.5
-10,16,24:18.5
-9,16,24:18.5
-8,16,24:18.5
-7,16,24:18.5
-6,16,24:18.5
-5,16,24:18.5
-4,16,24:18.5
-3,16,24:18.5
-2,16,24:18.5
-1,16,24:18.5
0,16,24:18.5
1,16,24:18.5
2,16,24:18.5
4,16,24:18.5
9,16,24:18.5
10,16,24:18.5
14,16,24:18.5
-9,17,24:18.5
-8,17,24:18.5
-7,17,24:18.5
-1,17,24:18.5
0,17,24:18.5
1,17,24:18.5
2,17,24:18.5
3,17,24:18.5
4,17,24:18.5
5,17,24:18.5
6,17,24:18.5
7,17,24:18.5
8,17,24:18.5
9,17,24:18.5
10,17,24:18.5
11,17,24:18.5
12,17,24:18.5
13,17,24:18.5
14,17,24:18.5
-7,18,24:18.5
-6,18,24:18.5
-5,18,24:18.5
5,18,24:18.5
6,18,24:18.5
7,18,24:18.5
9,18,24:18.5
10,18,24:18.5
11,18,24:18.5
12,18,24:18.5
13,18,24:18.5
14,18,24:18.5
15,18,24:18.13
-3,19,24:18.5
2,19,24:18.5
3,19,24:18.5
4,19,24:18.5
5,19,24:18.5
13,19,24:18.5
14,19,24:18.5
-3,20,24:18.5
-2,20,24:18.5
-1,20,24:18.5
0,20,24:18.5
1,20,24:18.5
2,20,24:18.5
14,20,24:18.5
-10,21,24:18.5
-9,21,24:18.5
-8,21,24:18.5
-7,21,24:18.5
-6,21,24:18.5
-5,21,24:18.5
-4,21,24:18.5
-3,21,24:18.5
-2,21,24:18.5
-1,21,24:18.5
0,21,24:18.5
1,21,24:18.5
2,21,24:18.5
3,21,24:18.5
3,22,24:18.5
4,22,24:18.5
5,22,24:18.5
6,22,24:18.5
7,22,24:18.5
7,23,24:18.5
8,23,24:18.5
9,23,24:18.5
10,23,24:18.5
-6,-19,25:18.5
-5,-19,25:18.5
-5,-18,25:18.5
-4,-18,25:18.5
-3,-18,25:18.5
-2,-18,25:18.5
9,-18,25:18.5
10,-18,25:18.5
-2,-17,25:18.5
-1,-17,25:18.5
0,-17,25:18.5
1,-17,25:18.5
2,-17,25:18.5
3,-17,25:18.5
4,-17,25:18.5
5,-17,25:18.5
6,-17,25:18.5
7,-17,25:18.5
8,-17,25:18.5
-12,-16,25:18.5
-2,-16,25:18.5
-1,-16,25:18.5
0,-16,25:18.5
1,-16,25:18.5
2,-16,25:18.5
3,-16,25:18.5
-12,-15,25:18.5
-4,-15,25:18.5
-3,-15,25:18.5
-2,-15,25:18.5
3,-15,25:18.5
4,-15,25:18.5
5,-15,25:18.5
-14,-14,25:18.5
-13,-14,25:18.5
-12,-14,25:18.5
-7,-14,25:18.5
-6,-14,25:18.5
-5,-14,25:18.5
6,-14,25:18.5
7,-14,25:18.5
8,-14,25:18.5
-14,-13,25:18.5
-13,-13,25:18.5
-12,-13,25:18.5
-11,-13,25:18.5
-10,-13,25:18.5
-9,-13,25:18.5
-8,-13,25:18.5
-7,-13,25:18.5
-6,-13,25:18.5
-5,-13,25:18.5
-4,-13,25:18.5
-3,-13,25:18.5
-2,-13,25:18.5
-1,-13,25:18.5
0,-13,25:18.5
1,-13,25:18.5
2,-13,25:18.5
3,-13,25:18.5
4,-13,25:18.5
5,-13,25:18.5
6,-13,25:18.5
7,-13,25:18.5
8,-13,25:18.5
9,-13,25:18.5
10,-13,25:18.5
11,-13,25:18.5
12,-13,25:18.5
13,-13,25:18.5
14,-13,25:18.5
15,-13,25:18.5
16,-13,25:18.5
17,-13,25:18.5
-12,-12,25:18.5
-9,-12,25:18.5
-8,-12,25:18.5
1,-12,25:18.5
2,-12,25:18.5
3,-12,25:18.5
4,-12,25:18.5
5,-12,25:18.5
6,-12,25:18.5
7,-12,25:18.5
8,-12,25:18.5
9,-12,25:18.5
10,-12,25:18.5
11,-12,25:18.5
12,-12,25:18.5
13,-12,25:18.5
14,-12,25:18.5
15,-12,25:18.5
16,-12,25:18.5
17,-12,25:18.5
-12,-11,25:18.5
-10,-11,25:18.5
11,-11,25:18.5
15,-11,25:18.5
-18,-10,25:18.5
-13,-10,25:18.5
-12,-10,25:18.5
-11,-10,25:18.5
-10,-10,25:18.5
12,-10,25:18.5
15,-10,25:18.5
20,-10,25:18.5
-18,-9,25:18.5
-13,-9,25:18.5
-12,-9,25:18.5
13,-9,25:18.5
15,-9,25:18.5
20,-9,25:18.5
-18,-8,25:18.5
-13,-8,25:18.5
-12,-8,25:18.5
14,-8,25:18.5
15,-8,25:18.5
20,-8,25:18.5
-18,-7,25:18.5
-14,-7,25:18.5
-13,-7,25:18.5
-12,-7,25:18.5
14,-7,25:18.5
15,-7,25:18.5
20,-7,25:18.5
-18,-6,25:18.5
-14,-6,25:18.5
-13,-6,25:18.5
-12,-6,25:18.5
14,-6,25:18.5
15,-6,25:18.5
16,-6,25:18.5
20,-6,25:18.5
-18,-5,25:18.5
-15,-5,25:18.5
-13,-5,25:18.5
14,-5,25:18.5
15,-5,25:18.5
16,-5,25:18.5
20,-5,25:18.5
-18,-4,25:18.5
-17,-4,25:18.5
-15,-4,25:18.5
-13,-4,25:18.5
14,-4,25:18.5
15,-4,25:18.5
16,-4,25:18.5
19,-4,25:18.5
20,-4,25:18.5
-17,-3,25:18.5
-16,-3,25:18.5
-13,-3,25:18.5
14,-3,25:18.5
15,-3,25:18.5
17,-3,25:18.5
19,-3,25:18.5
-17,-2,25:18.5
-13,-2,25:18.5
14,-2,25:18.5
15,-2,25:18.5
17,-2,25:18.5
19,-2,25:18.5
-17,-1,25:18.5
-14,-1,25:18.5
-13,-1,25:18.5
14,-1,25:18.5
15,-1,25:18.5
17,-1,25:18.5
18,-1,25:18.5
19,-1,25:18.5
-17,0,25:18.5
-14,0,25:18.5
-13,0,25:18.5
14,0,25:18.5
15,0,25:18.5
18,0,25:18.5
19,0,25:18.5
-17,1,25:18.5
-14,1,25:18.5
-13,1,25:18.5
14,1,25:18.5
18,1,25:18.5
19,1,25:18.5
-18,2,25:18.5
-17,2,25:18.5
-16,2,25:18.5
-14,2,25:18.5
-13,2,25:18.5
14,2,25:18.5
18,2,25:18.5
19,2,25:18.5
-18,3,25:18.5
-16,3,25:18.5
-14,3,25:18.5
-13,3,25:18.5
14,3,25:18.5
18,3,25:18.5
19,3,25:18.5
-18,4,25:18.5
-16,4,25:18.5
-14,4,25:18.5
14,4,25:18.5
18,4,25:18.5
19,4,25:18.5
-19,5,25:18.5
-16,5,25:18.5
-14,5,25:18.5
14,5,25:18.5
17,5,25:18.5
18,5,25:18.5
19,5,25:18.5
-19,6,25:18.5
-16,6,25:18.5
-14,6,25:18.5
13,6,25:18.5
14,6,25:18.5
17,6,25:18.5
19,6,25:18.5
-19,7,25:18.5
-16,7,25:18.5
-15,7,25:18.5
13,7,25:18.5
14,7,25:18.5
16,7,25:18.5
19,7,25:18.5
-19,8,25:18.5
-15,8,25:18.5
-14,8,25:18.5
13,8,25:18.5
14,8,25:18.5
16,8,25:18.5
19,8,25:18.5
-20,9,25:18.5
-15,9,25:18.5
-14,9,25:18.5
13,9,25:18.5
14,9,25:18.5
15,9,25:18.5
19,9,25:18.5
-20,10,25:18.5
-15,10,25:18.5
-14,10,25:18.5
13,10,25:18.5
14,10,25:18.5
15,10,25:18.5
19,10,25:18.5
-15,11,25:18.5
-14,11,25:18.5
-13,11,25:18.5
13,11,25:18.5
14,11,25:18.5
19,11,25:18.5
-15,12,25:18.5
-14,12,25:18.5
-13,12,25:18.5
-12,12,25:18.5
13,12,25:18.5
14,12,25:18.5
19,12,25:18.5
-17,13,25:18.5
-16,13,25:18.5
-15,13,25:18.5
-14,13,25:18.5
-12,13,25:18.5
-11,13,25:18.5
12,13,25:18.5
13,13,25:18.5
14,13,25:18.5
19,13,25:18.5
-17,14,25:18.5
-15,14,25:18.5
-14,14,25:18.5
-13,14,25:18.5
-12,14,25:18.5
-11,14,25:18.5
-10,14,25:18.5
-9,14,25:18.5
-8,14,25:18.5
-7,14,25:18.5
-6,14,25:18.5
11,14,25:18.5
13,14,25:18.5
19,14,25:18.5
-15,15,25:18.5
-11,15,25:18.5
-10,15,25:18.5
-9,15,25:18.5
-8,15,25:18.5
-7,15,25:18.5
-6,15,25:18.5
-5,15,25:18.5
-4,15,25:18.5
-3,15,25:18.5
-2,15,25:18.5
-1,15,25:18.5
0,15,25:18.5
1,15,25:18.5
2,15,25:18.5
3,15,25:18.5
4,15,25:18.5
10,15,25:18.5
13,15,25:18.5
-9,16,25:18.5
-1,16,25:18.5
0,16,25:18.5
1,16,25:18.5
2,16,25:18.5
4,16,25:18.5
5,16,25:18.5
6,16,25:18.5
7,16,25:18.5
8,16,25:18.5
9,16,25:18.5
10,16,25:18.5
11,16,25:18.5
12,16,25:18.5
13,16,25:18.5
14,16,25:18.5
-8,17,25:18.5
7,17,25:18.5
8,17,25:18.5
9,17,25:18.5
10,17,25:18.5
11,17,25:18.5
12,17,25:18.5
13,17,25:18.5
14,17,25:18.5
-7,18,25:18.5
-6,18,25:18.5
6,18,25:18.5
7,18,25:18.5
12,18,25:18.5
13,18,25:18.5
-6,19,25:18.5
-5,19,25:18.5
4,19,25:18.5
5,19,25:18.5
6,19,25:18.5
12,19,25:18.5
13,19,25:18.5
-3,20,25:18.5
-2,20,25:18.5
1,20,25:18.5
2,20,25:18.5
3,20,25:18.5
4,20,25:18.5
-9,21,25:18.5
-8,21,25:18.5
-7,21,25:18.5
-6,21,25:18.5
-5,21,25:18.5
-4,21,25:18.5
-3,21,25:18.5
-2,21,25:18.5
-1,21,25:18.5
0,21,25:18.5
1,21,25:18.5
2,21,25:18.5
1,22,25:18.5
2,22,25:18.5
3,22,25:18.5
4,22,25:18.5
5,22,25:18.5
5,23,25:18.5
6,23,25:18.5
7,23,25:18.5
-4,-19,26:18.5
-4,-18,26:18.5
-3,-18,26:18.5
-2,-18,26:18.5
-1,-18,26:18.5
6,-18,26:18.5
7,-18,26:18.5
8,-18,26:18.5
9,-18,26:18.5
-1,-17,26:18.5
0,-17,26:18.5
1,-17,26:18.5
2,-17,26:18.5
3,-17,26:18.5
4,-17,26:18.5
5,-17,26:18.5
6,-17,26:18.5
-11,-16,26:18.5
-3,-16,26:18.5
-2,-16,26:18.5
-1,-16,26:18.5
2,-16,26:18.5
3,-16,26:18.5
4,-16,26:18.5
-11,-15,26:18.5
-5,-15,26:18.5
-4,-15,26:18.5
-3,-15,26:18.5
4,-15,26:18.5
5,-15,26:18.5
6,-15,26:18.5
-11,-14,26:18.5
-6,-14,26:18.5
-5,-14,26:18.5
6,-14,26:18.5
7,-14,26:18.5
8,-14,26:18.5
14,-14,26:18.5
-13,-13,26:18.5
-12,-13,26:18.5
-11,-13,26:18.5
-7,-13,26:18.5
-6,-13,26:18.5
8,-13,26:18.5
9,-13,26:18.5
14,-13,26:18.5
-13,-12,26:18.5
-12,-12,26:18.5
-11,-12,26:18.5
-10,-12,26:18.5
-9,-12,26:18.5
-8,-12,26:18.5
-7,-12,26:18.5
-6,-12,26:18.5
-5,-12,26:18.5
-4,-12,26:18.5
-3,-12,26:18.5
-2,-12,26:18.5
-1,-12,26:18.5
0,-12,26:18.5
1,-12,26:18.5
2,-12,26:18.5
3,-12,26:18.5
4,-12,26:18.5
5,-12,26:18.5
6,-12,26:18.5
7,-12,26:18.5
8,-12,26:18.5
9,-12,26:18.5
10,-12,26:18.5
11,-12,26:18.5
12,-12,26:18.5
13,-12,26:18.5
14,-12,26:18.5
15,-12,26:18.5
16,-12,26:18.5
-12,-11,26:18.5
-11,-11,26:18.5
-10,-11,26:18.5
0,-11,26:18.5
1,-11,26:18.5
2,-11,26:18.5
3,-11,26:18.5
4,-11,26:18.5
5,-11,26:18.5
6,-11,26:18.5
7,-11,26:18.5
8,-11,26:18.5
9,-11,26:18.5
10,-11,26:18.5
11,-11,26:18.5
12,-11,26:18.5
13,-11,26:18.5
14,-11,26:18.5
15,-11,26:18.5
16,-11,26:18.5
17,-11,26:18.5
-12,-10,26:18.5
-11,-10,26:18.5
-10,-10,26:18.5
11,-10,26:18.5
12,-10,26:18.5
14,-10,26:18.5
-12,-9,26:18.5
-11,-9,26:18.5
12,-9,26:18.5
13,-9,26:18.5
14,-9,26:18.5
-18,-8,26:18.5
-13,-8,26:18.5
-12,-8,26:18.5
-11,-8,26:18.5
13,-8,26:18.5
