[META]
version=2.0
spawnOnBlockType=2
spawnSunlight=True
spawnDarkness=True
spawnWater=False
spawnLava=False
underFill=False
randomRotation=True
dig=True
tree=False
branch=False
needsFoundation=True
rarity=100
collisionPercentage=20
spawnElevationMin=0
spawnElevationMax=200
spawnInBiome=Custom
[DATA]
-4,-8,-8:17.12
-4,-7,-8:17.12
-3,-7,-8:17.12
-3,-6,-8:17.12
-6,-3,-8:17.12
-6,-2,-8:17.12
-6,-1,-8:17.12
-5,-9,-7:17.12
-4,-8,-7:17.12
-3,-8,-7:17.12
2,-8,-7:17.12
-3,-7,-7:17.12
2,-7,-7:17.12
3,-7,-7:17.12
-4,-6,-7:17.12
-3,-6,-7:17.12
-2,-6,-7:17.12
4,-4,-7:17.12
-7,-3,-7:17.12
-6,-2,-7:17.12
-5,-2,-7:17.12
-4,-2,-7:17.12
-6,-1,-7:17.12
-5,-1,-7:17.12
-4,-1,-7:17.12
0,1,-7:17.12
-4,-8,-6:17.12
-3,-8,-6:17.12
2,-8,-6:17.12
-4,-7,-6:17.12
1,-7,-6:17.12
2,-7,-6:17.12
3,-7,-6:17.12
-4,-6,-6:17.12
-3,-6,-6:17.12
3,-6,-6:17.12
-3,-5,-6:17.12
4,-4,-6:17.12
5,-4,-6:17.12
-6,-3,-6:17.12
3,-3,-6:17.12
4,-3,-6:17.12
-6,-2,-6:17.12
-5,-2,-6:17.12
3,-2,-6:17.12
4,-2,-6:17.12
-6,-1,-6:17.12
-5,-1,-6:17.12
-4,-1,-6:17.12
0,1,-6:17.12
1,-8,-5:17.12
2,-8,-5:17.12
3,-8,-5:17.12
-3,-7,-5:17.12
0,-7,-5:17.12
1,-7,-5:17.12
2,-7,-5:17.12
3,-7,-5:17.12
-4,-6,-5:17.12
-3,-6,-5:17.12
-2,-6,-5:17.12
1,-6,-5:17.12
2,-6,-5:17.12
-3,-5,-5:17.12
3,-4,-5:17.12
-4,-3,-5:17.12
2,-3,-5:17.12
3,-3,-5:17.12
4,-3,-5:17.12
5,-3,-5:17.12
-5,-2,-5:17.12
-4,-2,-5:17.12
-3,-2,-5:17.12
-2,-2,-5:17.12
3,-2,-5:17.12
4,-2,-5:17.12
-5,-1,-5:17.12
-4,-1,-5:17.12
-2,-1,-5:17.12
1,1,-5:17.12
2,-8,-4:17.12
-3,-7,-4:17.12
-2,-7,-4:17.12
1,-7,-4:17.12
2,-7,-4:17.12
3,-7,-4:17.12
-4,-6,-4:17.12
-3,-6,-4:17.12
-2,-6,-4:17.12
1,-6,-4:17.12
-3,-5,-4:17.12
2,-4,-4:17.12
3,-4,-4:17.12
4,-4,-4:17.12
-4,-3,-4:17.12
-3,-3,-4:17.12
2,-3,-4:17.12
3,-3,-4:17.12
4,-3,-4:17.12
-5,-2,-4:17.12
-3,-2,-4:17.12
-2,-2,-4:17.12
-1,-2,-4:17.12
3,-2,-4:17.12
-4,-1,-4:17.12
-3,-1,-4:17.12
-2,-1,-4:17.12
-3,0,-4:17.12
-2,0,-4:17.12
1,0,-4:17.12
1,-8,-3:17.12
-3,-7,-3:17.12
0,-7,-3:17.12
2,-7,-3:17.12
-4,-6,-3:17.12
-3,-6,-3:17.12
-2,-6,-3:17.12
0,-6,-3:17.12
1,-6,-3:17.12
-3,-5,-3:17.12
-2,-5,-3:17.12
1,-5,-3:17.12
2,-4,-3:17.12
-4,-3,-3:17.12
-2,-3,-3:17.12
2,-3,-3:17.12
-3,-2,-3:17.12
-2,-2,-3:17.12
-1,-2,-3:17.12
2,-2,-3:17.12
3,-2,-3:17.12
-3,-1,-3:17.12
-2,-1,-3:17.12
-1,-1,-3:17.12
0,0,-3:17.12
0,-8,-2:17.12
-3,-7,-2:17.12
-2,-7,-2:17.12
-1,-7,-2:17.12
0,-7,-2:17.12
1,-7,-2:17.12
2,-7,-2:17.12
-4,-6,-2:17.12
-3,-6,-2:17.12
-2,-6,-2:17.12
-1,-6,-2:17.12
0,-6,-2:17.12
1,-6,-2:17.12
2,-6,-2:17.12
-4,-5,-2:17.12
-3,-5,-2:17.12
-2,-5,-2:17.12
-1,-5,-2:17.12
0,-5,-2:17.12
1,-5,-2:17.12
2,-5,-2:17.12
-5,-4,-2:17.12
-4,-4,-2:17.12
-3,-4,-2:17.12
-2,-4,-2:17.12
-1,-4,-2:17.12
0,-4,-2:17.12
1,-4,-2:17.12
2,-4,-2:17.12
-5,-3,-2:17.12
-4,-3,-2:17.12
-3,-3,-2:17.12
-2,-3,-2:17.12
-1,-3,-2:17.12
0,-3,-2:17.12
1,-3,-2:17.12
2,-3,-2:17.12
3,-3,-2:17.12
-5,-2,-2:17.12
-4,-2,-2:17.12
-3,-2,-2:17.12
-2,-2,-2:17.12
-1,-2,-2:17.12
0,-2,-2:17.12
1,-2,-2:17.12
2,-2,-2:17.12
-4,-1,-2:17.12
-3,-1,-2:17.12
-2,-1,-2:17.12
-1,-1,-2:17.12
0,-1,-2:17.12
1,-1,-2:17.12
2,-1,-2:17.12
-2,0,-2:17.12
-1,0,-2:17.12
0,0,-2:17.12
1,0,-2:17.12
0,-8,-1:17.12
-3,-7,-1:17.12
-2,-7,-1:17.12
-1,-7,-1:17.12
0,-7,-1:17.12
-4,-6,-1:17.12
-3,-6,-1:17.12
-2,-6,-1:17.12
-1,-6,-1:17.12
1,-6,-1:17.12
2,-6,-1:17.12
-4,-5,-1:17.12
-3,-5,-1:17.12
2,-5,-1:17.12
-5,-4,-1:17.12
-4,-4,-1:17.12
-2,-4,-1:17.12
1,-4,-1:17.12
2,-4,-1:17.12
-5,-3,-1:17.12
-4,-3,-1:17.12
-2,-3,-1:17.12
1,-3,-1:17.12
-4,-2,-1:17.12
-3,-2,-1:17.12
1,-2,-1:17.12
-4,-1,-1:17.12
-3,-1,-1:17.12
-2,-1,-1:17.12
-1,-1,-1:17.12
0,-1,-1:17.12
1,-1,-1:17.12
0,0,-1:17.12
-3,-7,0:17.12
-2,-7,0:17.12
-1,-7,0:17.12
0,-7,0:17.12
-4,-6,0:17.12
-3,-6,0:17.12
1,-6,0:17.12
-4,-5,0:17.12
1,-5,0:17.12
2,-5,0:17.12
-4,-4,0:17.12
1,-4,0:17.12
-4,-3,0:17.12
1,-3,0:17.12
-4,-2,0:17.12
-3,-2,0:17.12
1,-2,0:17.12
-3,-1,0:17.12
-2,-1,0:17.12
-1,-1,0:17.12
0,-1,0:17.12
-3,-7,1:17.12
-2,-7,1:17.12
-4,-6,1:17.12
-3,-6,1:17.12
-1,-6,1:17.12
0,-6,1:17.12
1,-6,1:17.12
-4,-5,1:17.12
1,-5,1:17.12
-4,-4,1:17.12
1,-4,1:17.12
-4,-3,1:17.12
1,-3,1:17.12
-4,-2,1:17.12
-3,-2,1:17.12
-2,-2,1:17.12
0,-2,1:17.12
1,-2,1:17.12
-1,-1,1:17.12
0,-1,1:17.12
-2,-7,2:17.12
-3,-6,2:17.12
-2,-6,2:17.12
-1,-6,2:17.12
0,-6,2:17.12
1,-6,2:17.12
-4,-5,2:17.12
1,-5,2:17.12
-4,-4,2:17.12
1,-4,2:17.12
-4,-3,2:17.12
1,-3,2:17.12
-4,-2,2:17.12
-3,-2,2:17.12
-2,-2,2:17.12
-1,-2,2:17.12
0,-2,2:17.12
-1,-1,2:17.12
-3,-6,3:17.12
-2,-6,3:17.12
-1,-6,3:17.12
0,-6,3:17.12
1,-6,3:17.12
-4,-5,3:17.12
1,-5,3:17.12
-4,-4,3:17.12
1,-4,3:17.12
-4,-3,3:17.12
1,-3,3:17.12
-3,-2,3:17.12
-2,-2,3:17.12
-1,-2,3:17.12
0,-2,3:17.12
-1,-1,3:17.12
-3,-6,4:17.12
-2,-6,4:17.12
-1,-6,4:17.12
0,-6,4:17.12
-4,-5,4:17.12
1,-5,4:17.12
-4,-4,4:17.12
0,-4,4:17.12
1,-4,4:17.12
-4,-3,4:17.12
0,-3,4:17.12
1,-3,4:17.12
-3,-2,4:17.12
-2,-2,4:17.12
-1,-2,4:17.12
0,-2,4:17.12
-3,-6,5:17.12
-2,-6,5:17.12
-1,-6,5:17.12
0,-6,5:17.12
-3,-5,5:17.12
0,-5,5:17.12
1,-5,5:17.12
-3,-4,5:17.12
0,-4,5:17.12
1,-4,5:17.12
-4,-3,5:17.12
-3,-3,5:17.12
0,-3,5:17.12
-3,-2,5:17.12
-2,-2,5:17.12
-1,-2,5:17.12
0,-2,5:17.12
-3,-6,6:17.12
-2,-6,6:17.12
-1,-6,6:17.12
0,-6,6:17.12
-3,-5,6:17.12
0,-5,6:17.12
-3,-4,6:17.12
0,-4,6:17.12
-4,-3,6:17.12
-3,-3,6:17.12
0,-3,6:17.12
-3,-2,6:17.12
-2,-2,6:17.12
-1,-2,6:17.12
0,-2,6:17.12
-3,-6,7:17.12
-2,-6,7:17.12
-1,-6,7:17.12
0,-6,7:17.12
-3,-5,7:17.12
0,-5,7:17.12
-3,-4,7:17.12
0,-4,7:17.12
-3,-3,7:17.12
0,-3,7:17.12
-3,-2,7:17.12
-2,-2,7:17.12
-1,-2,7:17.12
0,-2,7:17.12
-3,-6,8:17.12
-2,-6,8:17.12
-1,-6,8:17.12
0,-6,8:17.12
-3,-5,8:17.12
0,-5,8:17.12
-3,-4,8:17.12
0,-4,8:17.12
-3,-3,8:17.12
0,-3,8:17.12
-3,-2,8:17.12
-2,-2,8:17.12
-1,-2,8:17.12
0,-2,8:17.12
-2,-6,9:17.12
-1,-6,9:17.12
0,-6,9:17.12
0,-5,9:17.12
-4,-4,9:17.12
-3,-4,9:17.12
0,-4,9:17.12
-3,-3,9:17.12
0,-3,9:17.12
1,-3,9:17.12
-3,-2,9:17.12
-2,-2,9:17.12
-1,-2,9:17.12
0,-2,9:17.12
-2,-6,10:17.12
-1,-6,10:17.12
0,-6,10:17.12
-4,-5,10:17.12
-3,-5,10:17.12
0,-5,10:17.12
-4,-4,10:17.12
0,-4,10:17.12
-4,-3,10:17.12
-3,-3,10:17.12
0,-3,10:17.12
1,-3,10:17.12
-4,-2,10:17.12
-3,-2,10:17.12
-2,-2,10:17.12
-1,-2,10:17.12
0,-2,10:17.12
-3,-6,11:17.12
-2,-6,11:17.12
-1,-6,11:17.12
0,-6,11:17.12
1,-6,11:17.12
-4,-5,11:17.12
-3,-5,11:17.12
-2,-5,11:17.12
-1,-5,11:17.12
0,-5,11:17.12
1,-5,11:17.12
-4,-4,11:17.12
-3,-4,11:17.12
-2,-4,11:17.12
-1,-4,11:17.12
0,-4,11:17.12
1,-4,11:17.12
-4,-3,11:17.12
-3,-3,11:17.12
-2,-3,11:17.12
-1,-3,11:17.12
0,-3,11:17.12
1,-3,11:17.12
-4,-2,11:17.12
-3,-2,11:17.12
-2,-2,11:17.12
-1,-2,11:17.12
0,-2,11:17.12
1,-2,11:17.12
-3,-1,11:17.12
-4,-6,12:17.12
-3,-6,12:17.12
-2,-6,12:17.12
-1,-6,12:17.12
0,-6,12:17.12
1,-6,12:17.12
-4,-5,12:17.12
-3,-5,12:17.12
-2,-5,12:17.12
-1,-5,12:17.12
0,-5,12:17.12
1,-5,12:17.12
-4,-4,12:17.12
-3,-4,12:17.12
-2,-4,12:17.12
-1,-4,12:17.12
0,-4,12:17.12
1,-4,12:17.12
-4,-3,12:17.12
-3,-3,12:17.12
-2,-3,12:17.12
-1,-3,12:17.12
0,-3,12:17.12
1,-3,12:17.12
-4,-2,12:17.12
-3,-2,12:17.12
-2,-2,12:17.12
-1,-2,12:17.12
0,-2,12:17.12
1,-2,12:17.12
2,-2,12:17.12
-4,-1,12:17.12
-3,-1,12:17.12
-2,-1,12:17.12
0,-1,12:17.12
1,-1,12:17.12
0,-7,13:17.12
1,-7,13:17.12
-4,-6,13:17.12
-3,-6,13:17.12
-2,-6,13:17.12
-1,-6,13:17.12
0,-6,13:17.12
1,-6,13:17.12
2,-6,13:17.12
-4,-5,13:17.12
-3,-5,13:17.12
-2,-5,13:17.12
-1,-5,13:17.12
0,-5,13:17.12
1,-5,13:17.12
2,-5,13:17.12
-4,-4,13:17.12
-3,-4,13:17.12
-2,-4,13:17.12
-1,-4,13:17.12
0,-4,13:17.12
1,-4,13:17.12
-4,-3,13:17.12
-3,-3,13:17.12
-2,-3,13:17.12
-1,-3,13:17.12
0,-3,13:17.12
1,-3,13:17.12
-5,-2,13:17.12
-4,-2,13:17.12
-3,-2,13:17.12
-2,-2,13:17.12
-1,-2,13:17.12
0,-2,13:17.12
1,-2,13:17.12
2,-2,13:17.12
-5,-1,13:17.12
-4,-1,13:17.12
-3,-1,13:17.12
0,-1,13:17.12
1,-1,13:17.12
2,-1,13:17.12
0,-7,14:17.12
1,-7,14:17.12
2,-7,14:17.12
-5,-6,14:17.12
-4,-6,14:17.12
-3,-6,14:17.12
-1,-6,14:17.12
0,-6,14:17.12
2,-6,14:17.12
-5,-5,14:17.12
-4,-5,14:17.12
-3,-5,14:17.12
-2,-5,14:17.12
-1,-5,14:17.12
0,-5,14:17.12
1,-5,14:17.12
2,-5,14:17.12
-4,-4,14:17.12
-3,-4,14:17.12
0,-4,14:17.12
1,-4,14:17.12
-3,-3,14:17.12
0,-3,14:17.12
1,-3,14:17.12
-5,-2,14:17.12
-4,-2,14:17.12
-3,-2,14:17.12
-2,-2,14:17.12
-1,-2,14:17.12
0,-2,14:17.12
1,-2,14:17.12
2,-2,14:17.12
-5,-1,14:17.12
-4,-1,14:17.12
-3,-1,14:17.12
-1,-1,14:17.12
1,-1,14:17.12
2,-1,14:17.12
3,-1,14:17.12
-5,0,14:17.12
-4,0,14:17.12
1,0,14:17.12
2,0,14:17.12
3,0,14:17.12
-5,-7,15:17.12
-4,-7,15:17.12
1,-7,15:17.12
2,-7,15:17.12
3,-7,15:17.12
-5,-6,15:17.12
-4,-6,15:17.12
-3,-6,15:17.12
-1,-6,15:17.12
0,-6,15:17.12
1,-6,15:17.12
2,-6,15:17.12
3,-6,15:17.12
-5,-5,15:17.12
-4,-5,15:17.12
-3,-5,15:17.12
-2,-5,15:17.12
-1,-5,15:17.12
0,-5,15:17.12
1,-5,15:17.12
2,-5,15:17.12
-3,-4,15:17.12
-2,-4,15:17.12
0,-4,15:17.12
1,-4,15:17.12
-3,-3,15:17.12
-2,-3,15:17.12
1,-3,15:17.12
-5,-2,15:17.12
-4,-2,15:17.12
-3,-2,15:17.12
-2,-2,15:17.12
-1,-2,15:17.12
0,-2,15:17.12
1,-2,15:17.12
-6,-1,15:17.12
-5,-1,15:17.12
-4,-1,15:17.12
-1,-1,15:17.12
2,-1,15:17.12
3,-1,15:17.12
-6,0,15:17.12
-5,0,15:17.12
-4,0,15:17.12
2,0,15:17.12
3,0,15:17.12
-2,-13,16:18.6
0,-13,16:18.6
-2,-12,16:18.14
-1,-12,16:18.14
0,-12,16:18.14
-1,-11,16:18.14
0,-11,16:18.14
-5,-7,16:17.12
-4,-7,16:17.12
1,-7,16:17.12
2,-7,16:17.12
3,-7,16:17.12
-5,-6,16:17.12
-4,-6,16:17.12
-1,-6,16:17.12
1,-6,16:17.12
2,-6,16:17.12
3,-6,16:17.12
-9,-5,16:18.14
-8,-5,16:18.14
-5,-5,16:17.12
-4,-5,16:17.12
-2,-5,16:17.12
-1,-5,16:17.12
0,-5,16:17.12
1,-5,16:17.12
7,-5,16:18.14
8,-5,16:18.14
-8,-4,16:18.14
-3,-4,16:17.12
-2,-4,16:17.12
0,-4,16:17.12
1,-4,16:17.12
6,-4,16:18.14
-10,-3,16:18.14
-9,-3,16:18.14
-3,-3,16:17.12
-2,-3,16:17.12
1,-3,16:17.12
6,-3,16:18.14
7,-3,16:18.14
8,-3,16:18.14
-3,-2,16:17.12
-2,-2,16:17.12
-1,-2,16:17.12
0,-2,16:17.12
1,-2,16:17.12
-6,-1,16:17.12
-5,-1,16:17.12
-1,-1,16:17.12
0,-1,16:17.12
2,-1,16:17.12
3,-1,16:17.12
-6,0,16:17.12
-5,0,16:17.12
2,0,16:17.12
3,0,16:17.12
-2,3,16:18.14
-1,3,16:18.14
-2,4,16:18.14
0,4,16:18.14
-2,5,16:18.14
0,5,16:18.14
-4,-15,17:18.6
2,-15,17:18.6
-4,-14,17:18.6
-3,-14,17:18.6
1,-14,17:18.6
-3,-13,17:18.14
1,-13,17:18.14
-3,-12,17:18.14
-2,-12,17:18.14
0,-12,17:18.14
1,-12,17:18.14
-2,-11,17:18.14
0,-11,17:18.14
0,-10,17:18.14
-1,-9,17:18.14
0,-9,17:18.14
-12,-7,17:18.6
-11,-7,17:18.6
-5,-7,17:17.12
-4,-7,17:17.12
2,-7,17:17.12
3,-7,17:17.12
-11,-6,17:18.6
-10,-6,17:18.14
-9,-6,17:18.14
-6,-6,17:17.12
-5,-6,17:17.12
-4,-6,17:17.12
-1,-6,17:17.12
2,-6,17:17.12
3,-6,17:17.12
8,-6,17:18.14
9,-6,17:18.14
-9,-5,17:18.14
-8,-5,17:18.14
-7,-5,17:18.14
-2,-5,17:17.12
-1,-5,17:17.12
0,-5,17:17.12
1,-5,17:17.12
5,-5,17:18.14
6,-5,17:18.14
7,-5,17:18.14
8,-5,17:18.14
-7,-4,17:18.14
-6,-4,17:18.14
-5,-4,17:18.14
-3,-4,17:17.12
-2,-4,17:17.12
0,-4,17:17.12
1,-4,17:17.12
4,-4,17:18.14
5,-4,17:18.14
6,-4,17:18.14
-10,-3,17:18.14
-9,-3,17:18.14
-8,-3,17:18.14
-7,-3,17:18.14
-2,-3,17:17.12
1,-3,17:17.12
6,-3,17:18.14
7,-3,17:18.14
-11,-2,17:18.6
-10,-2,17:18.14
-9,-2,17:18.14
-3,-2,17:17.12
-2,-2,17:17.12
-1,-2,17:17.12
0,-2,17:17.12
1,-2,17:17.12
2,-2,17:17.12
7,-2,17:18.14
8,-2,17:18.14
9,-2,17:18.14
-6,-1,17:17.12
-5,-1,17:17.12
-1,-1,17:17.12
0,-1,17:17.12
9,-1,17:18.14
10,-1,17:18.6
-6,0,17:17.12
-5,0,17:17.12
3,0,17:17.12
4,0,17:17.12
-1,1,17:18.14
3,1,17:17.12
-2,2,17:18.14
-2,3,17:18.14
0,3,17:18.14
-3,4,17:18.14
-2,4,17:18.14
0,4,17:18.14
1,4,17:18.14
-3,5,17:18.14
0,5,17:18.14
1,5,17:18.14
-4,6,17:18.14
-3,6,17:18.14
1,6,17:18.14
-4,7,17:18.6
1,7,17:18.6
2,7,17:18.6
-5,-15,18:18.6
2,-15,18:18.6
-5,-14,18:18.14
-4,-14,18:18.14
2,-14,18:18.14
-4,-13,18:18.14
-3,-13,18:18.14
1,-13,18:18.14
2,-13,18:18.14
-4,-12,18:18.14
-3,-12,18:18.14
1,-12,18:18.14
-3,-11,18:18.14
0,-11,18:18.14
1,-11,18:18.14
-3,-10,18:18.14
0,-10,18:18.14
1,-10,18:18.14
-2,-9,18:18.14
-1,-9,18:18.14
0,-9,18:18.14
-12,-8,18:18.6
-11,-8,18:18.14
-2,-8,18:18.14
-1,-8,18:18.14
0,-8,18:18.14
-11,-7,18:18.14
-10,-7,18:18.14
-9,-7,18:18.14
-6,-7,18:17.12
-5,-7,18:17.12
-4,-7,18:17.12
-1,-7,18:18.14
2,-7,18:17.12
3,-7,18:17.12
8,-7,18:18.14
9,-7,18:18.14
10,-7,18:18.6
-9,-6,18:18.14
-8,-6,18:18.14
-7,-6,18:18.14
-6,-6,18:17.12
-5,-6,18:17.12
-1,-6,18:17.12
1,-6,18:17.12
2,-6,18:17.12
3,-6,18:17.12
6,-6,18:18.14
7,-6,18:18.14
8,-6,18:18.14
-7,-5,18:18.14
-6,-5,18:18.14
-5,-5,18:18.14
-1,-5,18:17.12
0,-5,18:17.12
1,-5,18:17.12
2,-5,18:17.12
4,-5,18:18.14
5,-5,18:18.14
6,-5,18:18.14
-5,-4,18:18.14
-4,-4,18:18.14
-3,-4,18:17.12
-2,-4,18:17.12
-1,-4,18:17.12
0,-4,18:17.12
1,-4,18:17.12
2,-4,18:18.14
3,-4,18:18.14
4,-4,18:18.14
-8,-3,18:18.14
-7,-3,18:18.14
-6,-3,18:18.14
-5,-3,18:18.14
-3,-3,18:17.12
-2,-3,18:17.12
-1,-3,18:17.12
0,-3,18:17.12
1,-3,18:17.12
2,-3,18:17.12
3,-3,18:18.14
4,-3,18:18.14
5,-3,18:18.14
-10,-2,18:18.14
-9,-2,18:18.14
-8,-2,18:18.14
-7,-2,18:18.14
-3,-2,18:17.12
-2,-2,18:17.12
-1,-2,18:17.12
0,-2,18:17.12
1,-2,18:17.12
2,-2,18:17.12
5,-2,18:18.14
6,-2,18:18.14
7,-2,18:18.14
-12,-1,18:18.6
-11,-1,18:18.14
-10,-1,18:18.14
-6,-1,18:17.12
-4,-1,18:17.12
-3,-1,18:17.12
-2,-1,18:17.12
-1,-1,18:17.12
0,-1,18:17.12
7,-1,18:18.14
8,-1,18:18.14
9,-1,18:18.14
-6,0,18:17.12
-5,0,18:17.12
-2,0,18:18.14
-1,0,18:18.14
0,0,18:17.12
3,0,18:17.12
4,0,18:17.12
10,0,18:18.14
-6,1,18:17.12
-5,1,18:17.12
-2,1,18:18.14
-1,1,18:18.14
0,1,18:18.14
3,1,18:17.12
4,1,18:17.12
-3,2,18:18.14
-2,2,18:18.14
0,2,18:18.14
1,2,18:18.14
-3,3,18:18.14
-2,3,18:18.14
0,3,18:18.14
1,3,18:18.14
-3,4,18:18.14
1,4,18:18.14
-4,5,18:18.14
-3,5,18:18.14
1,5,18:18.14
2,5,18:18.14
-4,6,18:18.14
2,6,18:18.14
-4,7,18:18.6
2,7,18:18.6
3,7,18:18.6
-6,-15,19:18.6
-5,-14,19:18.14
2,-14,19:18.14
3,-14,19:18.14
-5,-13,19:18.14
-4,-13,19:18.14
2,-13,19:18.14
-4,-12,19:18.14
2,-12,19:18.14
-4,-11,19:18.14
-3,-11,19:18.14
1,-11,19:18.14
-4,-10,19:18.14
-3,-10,19:18.14
1,-10,19:18.14
-12,-9,19:18.6
-3,-9,19:18.14
-2,-9,19:18.14
0,-9,19:18.14
1,-9,19:18.14
-12,-8,19:18.14
-11,-8,19:18.14
-10,-8,19:18.14
-3,-8,19:18.14
-2,-8,19:18.14
-1,-8,19:17.12
0,-8,19:18.14
8,-8,19:18.14
9,-8,19:18.14
-10,-7,19:18.14
-9,-7,19:18.14
-8,-7,19:18.14
-6,-7,19:17.12
-5,-7,19:17.12
-2,-7,19:18.14
-1,-7,19:17.12
0,-7,19:18.14
2,-7,19:17.12
3,-7,19:17.12
4,-7,19:17.12
6,-7,19:18.14
7,-7,19:18.14
8,-7,19:18.14
-8,-6,19:18.14
-7,-6,19:18.14
-6,-6,19:18.14
-5,-6,19:17.12
-2,-6,19:18.14
-1,-6,19:17.12
0,-6,19:18.14
1,-6,19:17.12
2,-6,19:17.12
3,-6,19:17.12
4,-6,19:18.14
5,-6,19:18.14
6,-6,19:18.14
-6,-5,19:18.14
-5,-5,19:18.14
-4,-5,19:18.14
-2,-5,19:17.12
-1,-5,19:17.12
0,-5,19:17.12
1,-5,19:17.12
2,-5,19:18.14
3,-5,19:18.14
4,-5,19:18.14
-5,-4,19:17.12
-4,-4,19:17.12
-3,-4,19:17.12
-2,-4,19:17.12
1,-4,19:18.14
2,-4,19:18.14
-6,-3,19:18.14
-5,-3,19:18.14
-4,-3,19:18.14
-3,-3,19:17.12
-2,-3,19:17.12
1,-3,19:17.12
2,-3,19:17.12
3,-3,19:17.12
-8,-2,19:18.14
-7,-2,19:18.14
-6,-2,19:18.14
-5,-2,19:18.14
-3,-2,19:17.12
-2,-2,19:17.12
-1,-2,19:18.14
3,-2,19:17.12
4,-2,19:18.14
5,-2,19:18.14
6,-2,19:18.14
-11,-1,19:18.14
-10,-1,19:18.14
-9,-1,19:18.14
-8,-1,19:18.14
-4,-1,19:17.12
-3,-1,19:17.12
-2,-1,19:18.14
-1,-1,19:17.12
0,-1,19:17.12
6,-1,19:18.14
7,-1,19:18.14
8,-1,19:18.14
-11,0,19:18.14
-10,0,19:18.14
-6,0,19:17.12
-5,0,19:17.12
-4,0,19:17.12
-2,0,19:18.14
-1,0,19:17.12
0,0,19:17.12
3,0,19:17.12
4,0,19:17.12
8,0,19:18.14
9,0,19:18.14
10,0,19:18.14
-6,1,19:17.12
-5,1,19:17.12
-3,1,19:18.14
-2,1,19:18.14
0,1,19:18.14
1,1,19:18.14
3,1,19:17.12
4,1,19:17.12
-3,2,19:18.14
1,2,19:18.14
-4,3,19:18.14
-3,3,19:18.14
1,3,19:18.14
2,3,19:18.14
-4,4,19:18.14
2,4,19:18.14
-5,5,19:18.14
-4,5,19:18.14
2,5,19:18.14
3,5,19:18.14
-5,6,19:18.14
3,6,19:18.14
3,7,19:18.14
-7,-15,20:18.6
-6,-15,20:18.14
-6,-14,20:18.14
3,-14,20:18.14
-6,-13,20:18.14
-5,-13,20:18.14
2,-13,20:18.14
3,-13,20:18.14
-5,-12,20:18.14
2,-12,20:18.14
-5,-11,20:18.14
-4,-11,20:18.14
2,-11,20:18.14
-4,-10,20:18.14
1,-10,20:18.14
2,-10,20:18.14
-12,-9,20:18.6
-11,-9,20:18.6
-10,-9,20:18.14
-4,-9,20:18.14
-3,-9,20:18.14
1,-9,20:18.14
-11,-8,20:18.14
-10,-8,20:18.14
-9,-8,20:18.14
-8,-8,20:18.14
-3,-8,20:18.14
-1,-8,20:17.12
1,-8,20:18.14
3,-8,20:17.12
7,-8,20:18.14
8,-8,20:18.14
-8,-7,20:18.14
-7,-7,20:18.14
-6,-7,20:17.12
-5,-7,20:17.12
-3,-7,20:18.14
-2,-7,20:18.14
-1,-7,20:17.12
0,-7,20:18.14
1,-7,20:18.14
2,-7,20:17.12
3,-7,20:17.12
4,-7,20:17.12
5,-7,20:18.14
6,-7,20:18.14
7,-7,20:18.14
-6,-6,20:18.14
-5,-6,20:18.14
-4,-6,20:18.14
-3,-6,20:18.14
-2,-6,20:18.14
-1,-6,20:17.12
0,-6,20:18.14
1,-6,20:17.12
2,-6,20:17.12
3,-6,20:18.14
4,-6,20:18.14
5,-6,20:18.14
-4,-5,20:18.14
-3,-5,20:18.14
-2,-5,20:18.14
0,-5,20:18.14
1,-5,20:18.14
2,-5,20:18.14
-5,-4,20:17.12
-4,-4,20:17.12
-3,-4,20:17.12
0,-4,20:18.14
3,-4,20:17.12
-4,-3,20:17.12
-3,-3,20:18.14
-2,-3,20:18.14
-1,-3,20:18.14
0,-3,20:18.14
1,-3,20:18.14
2,-3,20:17.12
3,-3,20:17.12
4,-3,20:17.12
-6,-2,20:18.14
-5,-2,20:18.14
-4,-2,20:18.14
-3,-2,20:18.14
-2,-2,20:18.14
0,-2,20:18.14
2,-2,20:18.14
3,-2,20:18.14
4,-2,20:18.14
-9,-1,20:18.14
-8,-1,20:18.14
-7,-1,20:18.14
-6,-1,20:18.14
-4,-1,20:17.12
-3,-1,20:17.12
-2,-1,20:18.14
0,-1,20:18.14
1,-1,20:18.14
4,-1,20:18.14
5,-1,20:18.14
6,-1,20:18.14
-10,0,20:18.14
-9,0,20:18.14
-8,0,20:18.14
-6,0,20:17.12
-5,0,20:17.12
-4,0,20:17.12
-3,0,20:18.14
-1,0,20:17.12
0,0,20:17.12
1,0,20:18.14
4,0,20:17.12
6,0,20:18.14
7,0,20:18.14
8,0,20:18.14
9,0,20:18.14
-6,1,20:17.12
-3,1,20:18.14
0,1,20:17.12
1,1,20:18.14
2,1,20:18.14
3,1,20:17.12
4,1,20:17.12
-4,2,20:18.14
-3,2,20:18.14
2,2,20:18.14
-4,3,20:18.14
2,3,20:18.14
3,3,20:18.14
-5,4,20:18.14
-4,4,20:18.14
2,4,20:18.14
3,4,20:18.14
-5,5,20:18.14
3,5,20:18.14
-5,6,20:18.14
3,6,20:18.14
4,6,20:18.14
4,7,20:18.14
-8,-15,21:18.6
4,-15,21:18.14
-7,-14,21:18.6
3,-14,21:18.14
4,-14,21:18.14
-7,-13,21:18.6
-6,-13,21:18.14
3,-13,21:18.14
-6,-12,21:18.14
3,-12,21:18.14
-6,-11,21:18.14
-5,-11,21:18.14
2,-11,21:18.14
3,-11,21:18.14
-12,-10,21:18.6
-5,-10,21:18.14
2,-10,21:18.14
-11,-9,21:18.14
-10,-9,21:18.14
-9,-9,21:18.14
-5,-9,21:18.14
-4,-9,21:18.14
-1,-9,21:17.12
2,-9,21:18.14
4,-9,21:17.12
7,-9,21:18.14
8,-9,21:18.14
9,-9,21:18.14
-9,-8,21:18.14
-8,-8,21:18.14
-7,-8,21:18.14
-4,-8,21:18.14
-2,-8,21:17.12
-1,-8,21:17.12
1,-8,21:18.14
2,-8,21:18.14
3,-8,21:17.12
4,-8,21:17.12
5,-8,21:18.14
6,-8,21:18.14
7,-8,21:18.14
-7,-7,21:18.14
-6,-7,21:17.12
-5,-7,21:18.14
-4,-7,21:18.14
-3,-7,21:18.14
-2,-7,21:17.12
-1,-7,21:17.12
1,-7,21:18.14
2,-7,21:17.12
3,-7,21:17.12
4,-7,21:18.14
5,-7,21:18.14
-6,-6,21:17.12
-5,-6,21:18.14
-4,-6,21:18.14
-3,-6,21:18.14
-2,-6,21:18.14
-1,-6,21:18.14
0,-6,21:18.14
1,-6,21:18.14
2,-6,21:18.14
3,-6,21:18.14
4,-6,21:17.12
-3,-5,21:18.14
-2,-5,21:18.14
-1,-5,21:18.14
0,-5,21:18.14
1,-5,21:18.14
-6,-4,21:17.12
-5,-4,21:17.12
-4,-4,21:17.12
-3,-4,21:18.14
-2,-4,21:18.14
0,-4,21:18.14
1,-4,21:18.14
4,-4,21:17.12
-5,-3,21:17.12
-3,-3,21:18.14
-2,-3,21:18.14
-1,-3,21:18.14
0,-3,21:18.14
1,-3,21:18.14
3,-3,21:17.12
4,-3,21:17.12
5,-3,21:17.12
-4,-2,21:18.14
-3,-2,21:18.14
-2,-2,21:18.14
-1,-2,21:18.14
0,-2,21:18.14
1,-2,21:18.14
2,-2,21:18.14
-7,-1,21:18.14
-6,-1,21:18.14
-5,-1,21:18.14
-4,-1,21:18.14
-3,-1,21:18.14
1,-1,21:18.14
2,-1,21:18.14
3,-1,21:18.14
4,-1,21:18.14
5,-1,21:18.14
-9,0,21:18.14
-8,0,21:18.14
-7,0,21:18.14
-6,0,21:17.12
-5,0,21:17.12
-4,0,21:17.12
-3,0,21:18.14
0,0,21:17.12
2,0,21:18.14
5,0,21:18.14
6,0,21:18.14
7,0,21:18.14
-11,1,21:18.14
-10,1,21:18.14
-9,1,21:18.14
-6,1,21:17.12
-5,1,21:17.12
-4,1,21:18.14
-1,1,21:17.12
0,1,21:17.12
2,1,21:18.14
3,1,21:18.14
4,1,21:17.12
7,1,21:18.14
8,1,21:18.14
9,1,21:18.14
-11,2,21:18.14
-5,2,21:18.14
-4,2,21:18.14
0,2,21:17.12
2,2,21:18.14
3,2,21:18.14
-5,3,21:18.14
3,3,21:18.14
-5,4,21:18.14
3,4,21:18.14
4,4,21:18.14
-6,5,21:18.14
4,5,21:18.14
-6,6,21:18.14
4,6,21:18.14
5,6,21:18.14
-6,7,21:18.14
5,7,21:18.14
5,-16,22:18.6
-8,-14,22:18.6
4,-14,22:18.14
-8,-13,22:18.6
-7,-13,22:18.6
4,-13,22:18.14
-7,-12,22:18.6
3,-12,22:18.14
4,-12,22:18.14
-7,-11,22:18.14
-6,-11,22:18.14
3,-11,22:18.14
10,-11,22:18.6
-12,-10,22:18.6
-11,-10,22:18.14
-10,-10,22:18.14
-9,-10,22:18.14
-6,-10,22:18.14
-1,-10,22:17.12
3,-10,22:18.14
4,-10,22:17.12
7,-10,22:18.14
8,-10,22:18.14
-10,-9,22:18.14
-9,-9,22:18.14
-8,-9,22:18.14
-7,-9,22:18.14
-6,-9,22:18.14
-5,-9,22:18.14
-2,-9,22:17.12
-1,-9,22:17.12
2,-9,22:18.14
3,-9,22:17.12
4,-9,22:17.12
5,-9,22:18.14
6,-9,22:18.14
7,-9,22:18.14
-7,-8,22:18.14
-6,-8,22:18.14
-5,-8,22:18.14
-4,-8,22:18.14
-2,-8,22:17.12
-1,-8,22:17.12
2,-8,22:18.14
3,-8,22:18.14
4,-8,22:18.14
5,-8,22:18.14
-6,-7,22:17.12
-5,-7,22:18.14
-4,-7,22:18.14
-3,-7,22:18.14
-2,-7,22:18.14
-1,-7,22:18.14
0,-7,22:18.14
1,-7,22:18.14
2,-7,22:18.14
3,-7,22:18.14
4,-7,22:17.12
-6,-6,22:17.12
-5,-6,22:18.14
-4,-6,22:18.14
-3,-6,22:18.14
-2,-6,22:18.14
-1,-6,22:18.14
0,-6,22:18.14
1,-6,22:18.14
2,-6,22:18.14
4,-6,22:17.12
-4,-5,22:18.14
-3,-5,22:18.14
-2,-5,22:18.14
0,-5,22:18.14
1,-5,22:18.14
2,-5,22:18.14
-7,-4,22:17.12
-6,-4,22:17.12
-5,-4,22:17.12
-4,-4,22:18.14
-3,-4,22:18.14
1,-4,22:18.14
2,-4,22:18.14
4,-4,22:17.12
5,-4,22:17.12
-6,-3,22:17.12
-4,-3,22:18.14
-3,-3,22:18.14
1,-3,22:18.14
2,-3,22:18.14
4,-3,22:17.12
5,-3,22:17.12
-4,-2,22:18.14
-3,-2,22:18.14
-2,-2,22:18.14
-1,-2,22:18.14
0,-2,22:18.14
1,-2,22:18.14
2,-2,22:18.14
-5,-1,22:18.14
-4,-1,22:18.14
-3,-1,22:18.14
-2,-1,22:18.14
-1,-1,22:18.14
0,-1,22:18.14
1,-1,22:18.14
2,-1,22:18.14
3,-1,22:18.14
-7,0,22:18.14
-6,0,22:18.14
-5,0,22:18.14
-4,0,22:18.14
2,0,22:18.14
3,0,22:18.14
4,0,22:18.14
5,0,22:18.14
-10,1,22:18.14
-9,1,22:18.14
-8,1,22:18.14
-7,1,22:18.14
-6,1,22:17.12
-5,1,22:17.12
-4,1,22:18.14
-1,1,22:17.12
0,1,22:17.12
3,1,22:18.14
4,1,22:17.12
5,1,22:18.14
6,1,22:18.14
7,1,22:18.14
8,1,22:18.14
-11,2,22:18.14
-10,2,22:18.14
-6,2,22:17.12
-5,2,22:18.14
-1,2,22:17.12
0,2,22:17.12
3,2,22:18.14
4,2,22:18.14
7,2,22:18.14
8,2,22:18.14
9,2,22:18.14
-12,3,22:18.6
-6,3,22:18.14
-5,3,22:18.14
4,3,22:18.14
10,3,22:18.14
-6,4,22:18.14
4,4,22:18.14
5,4,22:18.14
-7,5,22:18.14
-6,5,22:18.14
5,5,22:18.14
-7,6,22:18.14
5,6,22:18.14
6,6,22:18.14
-8,8,22:18.6
5,-16,23:18.6
6,-16,23:18.6
5,-15,23:18.14
5,-14,23:18.14
-9,-13,23:18.6
-8,-13,23:18.6
4,-13,23:18.14
5,-13,23:18.14
-8,-12,23:18.6
4,-12,23:18.14
10,-12,23:18.6
-11,-11,23:18.14
-10,-11,23:18.14
-8,-11,23:18.14
-7,-11,23:18.14
4,-11,23:18.14
8,-11,23:18.14
9,-11,23:18.14
10,-11,23:18.6
-10,-10,23:18.14
-9,-10,23:18.14
-8,-10,23:18.14
-7,-10,23:18.14
-2,-10,23:17.12
-1,-10,23:17.12
3,-10,23:18.14
4,-10,23:17.12
5,-10,23:17.12
6,-10,23:18.14
7,-10,23:18.14
-8,-9,23:18.14
-7,-9,23:18.14
-6,-9,23:18.14
-5,-9,23:18.14
-4,-9,23:18.14
-2,-9,23:17.12
-1,-9,23:17.12
2,-9,23:18.14
3,-9,23:18.14
4,-9,23:18.14
5,-9,23:18.14
6,-9,23:18.14
-7,-8,23:18.14
-6,-8,23:18.14
-5,-8,23:18.14
-4,-8,23:18.14
-3,-8,23:18.14
-2,-8,23:18.14
-1,-8,23:18.14
0,-8,23:18.14
1,-8,23:18.14
2,-8,23:18.14
3,-8,23:18.14
-6,-7,23:18.14
-5,-7,23:18.14
-3,-7,23:18.14
-2,-7,23:18.14
-1,-7,23:18.14
0,-7,23:18.14
1,-7,23:18.14
2,-7,23:18.14
3,-7,23:18.14
4,-7,23:17.12
-6,-6,23:18.14
-5,-6,23:18.14
-4,-6,23:18.14
-3,-6,23:18.14
-2,-6,23:18.14
0,-6,23:18.14
1,-6,23:18.14
2,-6,23:18.14
3,-6,23:18.14
4,-6,23:17.12
-6,-5,23:18.14
-5,-5,23:18.14
-4,-5,23:18.14
-3,-5,23:18.14
2,-5,23:18.14
3,-5,23:18.14
-8,-4,23:17.12
-7,-4,23:17.12
-6,-4,23:17.12
-5,-4,23:18.14
-4,-4,23:18.14
2,-4,23:18.14
3,-4,23:18.14
5,-4,23:17.12
-7,-3,23:17.12
-6,-3,23:17.12
-5,-3,23:18.14
-4,-3,23:18.14
2,-3,23:18.14
3,-3,23:18.14
5,-3,23:17.12
6,-3,23:17.12
-5,-2,23:18.14
-4,-2,23:18.14
-3,-2,23:18.14
1,-2,23:18.14
2,-2,23:18.14
3,-2,23:18.14
-5,-1,23:18.14
-3,-1,23:18.14
-2,-1,23:18.14
-1,-1,23:18.14
0,-1,23:18.14
1,-1,23:18.14
3,-1,23:18.14
4,-1,23:18.14
-6,0,23:18.14
-5,0,23:18.14
-4,0,23:18.14
-3,0,23:18.14
-2,0,23:18.14
-1,0,23:18.14
0,0,23:18.14
1,0,23:18.14
2,0,23:18.14
3,0,23:18.14
4,0,23:18.14
-8,1,23:18.14
-7,1,23:18.14
-6,1,23:18.14
-5,1,23:18.14
-4,1,23:18.14
2,1,23:18.14
3,1,23:18.14
5,1,23:18.14
6,1,23:18.14
-10,2,23:18.14
-9,2,23:18.14
-8,2,23:18.14
-7,2,23:17.12
-6,2,23:18.14
-5,2,23:18.14
-1,2,23:17.12
0,2,23:17.12
4,2,23:18.14
5,2,23:18.14
6,2,23:18.14
7,2,23:18.14
8,2,23:18.14
-12,3,23:18.6
-11,3,23:18.14
-10,3,23:18.14
-7,3,23:17.12
-6,3,23:18.14
0,3,23:17.12
5,3,23:18.14
8,3,23:18.14
9,3,23:18.14
-7,4,23:18.14
-6,4,23:18.14
5,4,23:18.14
-7,5,23:18.14
5,5,23:18.14
6,5,23:18.14
9,5,23:18.14
-8,6,23:18.14
6,6,23:18.14
9,6,23:18.14
-8,7,23:18.14
-8,8,23:18.6
-11,-16,24:18.6
6,-16,24:18.6
6,-15,24:18.14
-10,-14,24:18.6
5,-14,24:18.14
6,-14,24:18.14
-10,-13,24:18.6
-9,-13,24:18.6
5,-13,24:18.14
-11,-12,24:18.6
-9,-12,24:18.6
-8,-12,24:18.6
4,-12,24:18.14
5,-12,24:18.14
8,-12,24:18.14
9,-12,24:18.14
10,-12,24:18.6
-11,-11,24:18.14
-10,-11,24:18.14
-9,-11,24:18.14
-8,-11,24:18.14
-2,-11,24:17.12
4,-11,24:18.14
5,-11,24:17.12
6,-11,24:18.14
7,-11,24:18.14
8,-11,24:18.14
-9,-10,24:18.14
-8,-10,24:18.14
-7,-10,24:18.14
-6,-10,24:18.14
-5,-10,24:18.14
-4,-10,24:18.14
-2,-10,24:17.12
-1,-10,24:17.12
1,-10,24:18.14
2,-10,24:18.14
3,-10,24:18.14
4,-10,24:18.14
5,-10,24:18.14
6,-10,24:18.14
-8,-9,24:18.14
-7,-9,24:18.14
-6,-9,24:18.14
-5,-9,24:18.14
-4,-9,24:18.14
-3,-9,24:18.14
-2,-9,24:18.14
-1,-9,24:18.14
0,-9,24:18.14
1,-9,24:18.14
2,-9,24:18.14
3,-9,24:18.14
4,-9,24:18.14
-8,-8,24:18.14
-7,-8,24:18.14
-3,-8,24:18.14
-2,-8,24:18.14
-1,-8,24:18.14
0,-8,24:18.14
1,-8,24:18.14
3,-8,24:18.14
4,-8,24:18.14
-7,-7,24:18.14
-6,-7,24:17.12
-4,-7,24:18.14
-3,-7,24:18.14
0,-7,24:18.14
1,-7,24:18.14
2,-7,24:18.14
3,-7,24:18.14
4,-7,24:18.14
-7,-6,24:18.14
-6,-6,24:18.14
-5,-6,24:18.14
-4,-6,24:18.14
2,-6,24:18.14
3,-6,24:18.14
4,-6,24:18.14
-7,-5,24:18.14
-6,-5,24:18.14
-5,-5,24:18.14
3,-5,24:18.14
4,-5,24:18.14
-8,-4,24:17.12
-7,-4,24:17.12
-6,-4,24:18.14
-5,-4,24:18.14
3,-4,24:18.14
4,-4,24:18.14
6,-4,24:17.12
-8,-3,24:17.12
-7,-3,24:18.14
-6,-3,24:18.14
-5,-3,24:18.14
3,-3,24:18.14
4,-3,24:18.14
6,-3,24:17.12
-7,-2,24:18.14
-6,-2,24:18.14
-5,-2,24:18.14
-4,-2,24:18.14
2,-2,24:18.14
3,-2,24:18.14
4,-2,24:18.14
5,-2,24:18.14
-7,-1,24:18.14
-6,-1,24:18.14
-4,-1,24:18.14
-3,-1,24:18.14
1,-1,24:18.14
2,-1,24:18.14
4,-1,24:18.14
5,-1,24:18.14
-7,0,24:18.14
-6,0,24:18.14
-3,0,24:18.14
-2,0,24:18.14
-1,0,24:18.14
0,0,24:18.14
1,0,24:18.14
4,0,24:18.14
5,0,24:18.14
-7,1,24:18.14
-6,1,24:18.14
-5,1,24:18.14
-4,1,24:18.14
-3,1,24:18.14
-2,1,24:18.14
-1,1,24:18.14
0,1,24:18.14
1,1,24:18.14
2,1,24:18.14
3,1,24:18.14
5,1,24:18.14
-8,2,24:18.14
-7,2,24:18.14
-6,2,24:18.14
-5,2,24:18.14
-4,2,24:18.14
2,2,24:18.14
3,2,24:18.14
4,2,24:18.14
5,2,24:18.14
6,2,24:18.14
-11,3,24:18.14
-10,3,24:18.14
-9,3,24:18.14
-8,3,24:18.14
-7,3,24:18.14
-1,3,24:17.12
0,3,24:17.12
5,3,24:18.14
6,3,24:18.14
7,3,24:18.14
8,3,24:18.14
9,3,24:18.6
-12,4,24:18.6
-11,4,24:18.14
-8,4,24:18.14
-7,4,24:18.14
0,4,24:17.12
6,4,24:18.14
9,4,24:18.6
-8,5,24:18.14
-7,5,24:18.14
6,5,24:18.14
7,5,24:18.14
-8,6,24:18.14
7,6,24:18.6
-9,7,24:18.14
-8,7,24:18.14
-9,8,24:18.6
9,8,24:18.14
7,-17,25:18.6
-11,-16,25:18.6
7,-16,25:18.6
-11,-15,25:18.6
6,-15,25:18.14
-13,-14,25:18.6
-11,-14,25:18.6
6,-14,25:18.14
-13,-13,25:18.6
-12,-13,25:18.6
-11,-13,25:18.6
-10,-13,25:18.6
5,-13,25:18.14
6,-13,25:18.14
9,-13,25:18.14
10,-13,25:18.6
-11,-12,25:18.6
-10,-12,25:18.6
-9,-12,25:18.6
-8,-12,25:18.6
-7,-12,25:18.6
-2,-12,25:17.12
5,-12,25:18.14
6,-12,25:18.14
7,-12,25:18.14
8,-12,25:18.14
9,-12,25:18.14
-10,-11,25:18.14
-9,-11,25:18.14
-8,-11,25:18.14
-7,-11,25:18.14
-6,-11,25:18.14
-5,-11,25:18.14
-4,-11,25:18.14
-3,-11,25:18.14
-2,-11,25:17.12
0,-11,25:18.14
1,-11,25:18.14
2,-11,25:18.14
3,-11,25:18.14
4,-11,25:18.14
5,-11,25:18.14
6,-11,25:18.14
-10,-10,25:18.14
-9,-10,25:18.14
-5,-10,25:18.14
-4,-10,25:18.14
-3,-10,25:18.14
-1,-10,25:18.14
0,-10,25:18.14
1,-10,25:18.14
2,-10,25:18.14
3,-10,25:18.14
4,-10,25:18.14
5,-10,25:18.14
-9,-9,25:18.14
-8,-9,25:18.14
-3,-9,25:18.14
-2,-9,25:18.14
-1,-9,25:18.14
0,-9,25:18.14
1,-9,25:18.14
5,-9,25:18.14
-9,-8,25:18.14
-8,-8,25:18.14
-4,-8,25:18.14
-3,-8,25:18.14
1,-8,25:18.14
2,-8,25:18.14
4,-8,25:18.14
5,-8,25:18.14
-9,-7,25:18.14
-8,-7,25:18.14
-7,-7,25:17.12
-5,-7,25:18.14
-4,-7,25:18.14
2,-7,25:18.14
3,-7,25:18.14
4,-7,25:18.14
5,-7,25:18.14
-8,-6,25:18.14
-6,-6,25:18.14
-5,-6,25:18.14
3,-6,25:18.14
4,-6,25:18.14
5,-6,25:18.14
-8,-5,25:18.14
-7,-5,25:18.14
-6,-5,25:18.14
4,-5,25:18.14
5,-5,25:18.14
-9,-4,25:17.12
-8,-4,25:18.14
-7,-4,25:18.14
4,-4,25:18.14
5,-4,25:18.14
6,-4,25:17.12
7,-4,25:17.12
-9,-3,25:17.12
-8,-3,25:18.14
-7,-3,25:18.14
-6,-3,25:18.14
4,-3,25:18.14
5,-3,25:18.14
7,-3,25:17.12
-8,-2,25:18.14
-7,-2,25:18.14
-6,-2,25:18.14
-5,-2,25:18.14
3,-2,25:18.14
4,-2,25:18.14
5,-2,25:18.14
6,-2,25:18.14
-8,-1,25:18.14
-7,-1,25:18.14
-6,-1,25:18.14
-5,-1,25:18.14
2,-1,25:18.14
3,-1,25:18.14
5,-1,25:18.14
6,-1,25:18.14
-8,0,25:18.14
-7,0,25:18.14
-5,0,25:18.14
-4,0,25:18.14
-3,0,25:18.14
1,0,25:18.14
2,0,25:18.14
3,0,25:18.14
5,0,25:18.14
6,0,25:18.14
-8,1,25:18.14
-7,1,25:18.14
-3,1,25:18.14
-2,1,25:18.14
-1,1,25:18.14
0,1,25:18.14
1,1,25:18.14
6,1,25:18.14
-8,2,25:18.14
-7,2,25:18.14
-6,2,25:18.14
-5,2,25:18.14
-4,2,25:18.14
-3,2,25:18.14
-2,2,25:18.14
-1,2,25:18.14
0,2,25:18.14
1,2,25:18.14
2,2,25:18.14
3,2,25:18.14
4,2,25:18.14
6,2,25:18.14
7,2,25:18.14
-9,3,25:18.14
-8,3,25:18.14
-7,3,25:18.14
-6,3,25:18.14
-5,3,25:18.14
-4,3,25:18.14
-3,3,25:18.14
0,3,25:17.12
2,3,25:18.14
3,3,25:18.14
4,3,25:18.14
5,3,25:18.14
6,3,25:18.14
7,3,25:18.14
-11,4,25:18.14
-10,4,25:18.14
-9,4,25:18.14
-8,4,25:18.14
-1,4,25:17.12
0,4,25:17.12
6,4,25:18.14
7,4,25:18.14
8,4,25:18.14
9,4,25:18.6
-13,5,25:18.6
-12,5,25:18.6
-9,5,25:18.14
-8,5,25:18.14
7,5,25:18.14
10,5,25:18.14
-13,6,25:18.6
-9,6,25:18.14
7,6,25:18.6
8,6,25:18.6
-10,7,25:18.14
-9,7,25:18.14
8,7,25:18.6
-10,8,25:18.6
9,8,25:18.14
7,-16,26:18.6
8,-16,26:18.6
-12,-15,26:18.6
7,-15,26:18.14
-13,-14,26:18.6
-12,-14,26:18.6
-11,-14,26:18.6
7,-14,26:18.14
9,-14,26:18.14
10,-14,26:18.6
-12,-13,26:18.6
-11,-13,26:18.6
-10,-13,26:18.6
-9,-13,26:18.6
-8,-13,26:18.6
-7,-13,26:18.6
-2,-13,26:17.12
5,-13,26:18.14
6,-13,26:18.14
7,-13,26:18.14
8,-13,26:18.14
9,-13,26:18.14
-11,-12,26:18.6
-10,-12,26:18.6
-9,-12,26:18.6
-8,-12,26:18.6
-7,-12,26:18.6
-6,-12,26:18.14
-5,-12,26:18.14
-4,-12,26:18.14
-3,-12,26:18.14
-2,-12,26:17.12
-1,-12,26:18.14
0,-12,26:18.14
1,-12,26:18.14
2,-12,26:18.14
3,-12,26:18.14
4,-12,26:18.14
5,-12,26:18.14
6,-12,26:18.14
7,-12,26:18.14
-11,-11,26:18.14
-10,-11,26:18.14
-5,-11,26:18.14
-4,-11,26:18.14
-3,-11,26:18.14
-2,-11,26:18.14
-1,-11,26:18.14
0,-11,26:18.14
1,-11,26:18.14
2,-11,26:18.14
3,-11,26:18.14
6,-11,26:18.14
-11,-10,26:18.14
-10,-10,26:18.14
-4,-10,26:18.14
-3,-10,26:18.14
-1,-10,26:18.14
0,-10,26:18.14
1,-10,26:18.14
6,-10,26:18.14
-10,-9,26:18.14
-5,-9,26:18.14
-4,-9,26:18.14
-3,-9,26:18.14
1,-9,26:18.14
2,-9,26:18.14
6,-9,26:18.14
-10,-8,26:18.14
-9,-8,26:18.14
-5,-8,26:18.14
-4,-8,26:18.14
2,-8,26:18.14
3,-8,26:18.14
6,-8,26:18.14
-10,-7,26:18.14
-9,-7,26:18.14
-6,-7,26:18.14
-5,-7,26:18.14
3,-7,26:18.14
4,-7,26:18.14
6,-7,26:18.14
-10,-6,26:18.14
-9,-6,26:18.14
-7,-6,26:18.14
-6,-6,26:18.14
4,-6,26:18.14
5,-6,26:18.14
6,-6,26:18.14
-9,-5,26:18.14
-8,-5,26:18.14
-7,-5,26:18.14
5,-5,26:18.14
6,-5,26:18.14
-10,-4,26:17.12
-9,-4,26:18.14
-8,-4,26:18.14
5,-4,26:18.14
6,-4,26:18.14
7,-4,26:17.12
8,-4,26:17.12
-10,-3,26:17.12
-9,-3,26:18.14
-8,-3,26:18.14
5,-3,26:18.14
6,-3,26:18.14
-9,-2,26:18.14
-8,-2,26:18.14
-7,-2,26:18.14
4,-2,26:18.14
5,-2,26:18.14
6,-2,26:18.14
7,-2,26:18.14
-9,-1,26:18.14
-8,-1,26:18.14
-7,-1,26:18.14
-6,-1,26:18.14
3,-1,26:18.14
4,-1,26:18.14
6,-1,26:18.14
7,-1,26:18.14
-9,0,26:18.14
-8,0,26:18.14
-6,0,26:18.14
-5,0,26:18.14
3,0,26:18.14
4,0,26:18.14
6,0,26:18.14
7,0,26:18.14
-9,1,26:18.14
-8,1,26:18.14
-5,1,26:18.14
-4,1,26:18.14
-3,1,26:18.14
1,1,26:18.14
2,1,26:18.14
3,1,26:18.14
7,1,26:18.14
-9,2,26:18.14
-8,2,26:18.14
-3,2,26:18.14
-2,2,26:18.14
-1,2,26:18.14
0,2,26:18.14
1,2,26:18.14
7,2,26:18.14
8,2,26:18.14
-9,3,26:18.14
-8,3,26:18.14
-6,3,26:18.14
-5,3,26:18.14
-4,3,26:18.14
-3,3,26:18.14
-2,3,26:18.14
-1,3,26:18.14
0,3,26:18.14
1,3,26:18.14
2,3,26:18.14
3,3,26:18.14
4,3,26:18.14
7,3,26:18.14
8,3,26:18.14
-9,4,26:18.14
-8,4,26:18.14
-7,4,26:18.14
-6,4,26:18.14
-5,4,26:18.14
-4,4,26:18.14
-3,4,26:18.14
0,4,26:17.12
2,4,26:18.14
3,4,26:18.14
4,4,26:18.14
5,4,26:18.14
6,4,26:18.14
7,4,26:18.14
8,4,26:18.14
-12,5,26:18.6
-11,5,26:18.14
-10,5,26:18.14
-9,5,26:18.14
-8,5,26:18.14
0,5,26:17.12
6,5,26:18.14
7,5,26:18.14
8,5,26:18.14
9,5,26:18.6
10,5,26:18.14
-13,6,26:18.6
-12,6,26:18.6
-10,6,26:18.14
-9,6,26:18.14
8,6,26:18.6
9,6,26:18.6
10,6,26:18.14
-10,7,26:18.14
9,7,26:18.6
-11,8,26:18.6
-10,8,26:18.6
9,8,26:18.14
-14,-16,27:18.6
-13,-16,27:18.6
8,-16,27:18.6
-14,-15,27:18.6
-13,-15,27:18.6
-12,-15,27:18.6
-11,-15,27:18.6
7,-15,27:18.14
8,-15,27:18.14
9,-15,27:18.14
10,-15,27:18.6
-13,-14,27:18.6
-12,-14,27:18.6
-11,-14,27:18.6
-10,-14,27:18.6
-9,-14,27:18.6
-8,-14,27:18.6
-7,-14,27:18.6
-6,-14,27:18.14
4,-14,27:18.14
5,-14,27:18.14
6,-14,27:18.14
7,-14,27:18.14
8,-14,27:18.14
9,-14,27:18.14
-13,-13,27:18.6
-12,-13,27:18.6
-9,-13,27:18.6
-8,-13,27:18.6
-7,-13,27:18.6
-6,-13,27:18.14
-5,-13,27:18.14
-4,-13,27:18.14
-3,-13,27:18.14
-2,-13,27:17.12
-1,-13,27:18.14
0,-13,27:18.14
1,-13,27:18.14
2,-13,27:18.14
3,-13,27:18.14
4,-13,27:18.14
5,-13,27:18.14
6,-13,27:18.14
7,-13,27:18.14
-13,-12,27:18.6
-12,-12,27:18.6
-4,-12,27:18.14
-3,-12,27:18.14
-2,-12,27:18.14
-1,-12,27:18.14
0,-12,27:18.14
1,-12,27:18.14
2,-12,27:18.14
7,-12,27:18.14
-12,-11,27:18.6
-11,-11,27:18.14
-4,-11,27:18.14
-3,-11,27:18.14
-1,-11,27:18.14
0,-11,27:18.14
1,-11,27:18.14
7,-11,27:18.14
-12,-10,27:18.6
-11,-10,27:18.14
-5,-10,27:18.14
-4,-10,27:18.14
1,-10,27:18.14
2,-10,27:18.14
3,-10,27:18.14
7,-10,27:18.14
-12,-9,27:18.6
-11,-9,27:18.14
-6,-9,27:18.14
-5,-9,27:18.14
2,-9,27:18.14
3,-9,27:18.14
4,-9,27:18.14
7,-9,27:18.14
-11,-8,27:18.14
-7,-8,27:18.14
-6,-8,27:18.14
4,-8,27:18.14
5,-8,27:18.14
7,-8,27:18.14
-11,-7,27:18.14
-10,-7,27:18.14
-8,-7,27:18.14
-7,-7,27:18.14
4,-7,27:18.14
5,-7,27:18.14
6,-7,27:18.14
7,-7,27:18.14
-11,-6,27:18.14
-10,-6,27:18.14
-8,-6,27:18.14
-7,-6,27:18.14
5,-6,27:18.14
6,-6,27:18.14
7,-6,27:18.14
-11,-5,27:18.14
-9,-5,27:18.14
-8,-5,27:18.14
6,-5,27:18.14
7,-5,27:18.14
-11,-4,27:17.12
-10,-4,27:18.14
-9,-4,27:18.14
6,-4,27:18.14
7,-4,27:18.14
8,-4,27:17.12
9,-4,27:17.12
-11,-3,27:17.12
-10,-3,27:18.14
-9,-3,27:18.14
6,-3,27:18.14
7,-3,27:18.14
8,-3,27:18.14
-10,-2,27:18.14
-9,-2,27:18.14
-8,-2,27:18.14
5,-2,27:18.14
6,-2,27:18.14
7,-2,27:18.14
8,-2,27:18.14
-10,-1,27:18.14
-9,-1,27:18.14
-8,-1,27:18.14
-7,-1,27:18.14
5,-1,27:18.14
7,-1,27:18.14
8,-1,27:18.14
-10,0,27:18.14
-7,0,27:18.14
-6,0,27:18.14
4,0,27:18.14
5,0,27:18.14
8,0,27:18.14
-10,1,27:18.14
-7,1,27:18.14
-6,1,27:18.14
-5,1,27:18.14
3,1,27:18.14
8,1,27:18.14
-10,2,27:18.14
-6,2,27:18.14
-5,2,27:18.14
-4,2,27:18.14
-3,2,27:18.14
1,2,27:18.14
2,2,27:18.14
3,2,27:18.14
8,2,27:18.6
9,2,27:18.6
-10,3,27:18.14
-4,3,27:18.14
-3,3,27:18.14
-2,3,27:18.14
-1,3,27:18.14
0,3,27:18.14
1,3,27:18.14
2,3,27:18.14
8,3,27:18.6
9,3,27:18.6
-10,4,27:18.14
-5,4,27:18.14
-4,4,27:18.14
-3,4,27:18.14
-2,4,27:18.14
-1,4,27:18.14
0,4,27:18.14
1,4,27:18.14
2,4,27:18.14
3,4,27:18.14
4,4,27:18.14
8,4,27:18.6
9,4,27:18.6
-10,5,27:18.14
-9,5,27:18.14
-8,5,27:18.14
-7,5,27:18.14
-6,5,27:18.14
-5,5,27:18.14
-4,5,27:18.14
-3,5,27:18.14
0,5,27:17.12
1,5,27:18.14
2,5,27:18.14
3,5,27:18.14
4,5,27:18.14
5,5,27:18.6
6,5,27:18.6
7,5,27:18.6
8,5,27:18.6
9,5,27:18.6
-12,6,27:18.6
-11,6,27:18.14
-10,6,27:18.14
-9,6,27:18.14
-8,6,27:18.14
0,6,27:17.12
6,6,27:18.6
7,6,27:18.6
8,6,27:18.6
9,6,27:18.6
10,6,27:18.14
11,6,27:18.14
-13,7,27:18.6
-12,7,27:18.6
-11,7,27:18.14
-10,7,27:18.14
10,7,27:18.14
11,7,27:18.14
-11,8,27:18.6
10,8,27:18.14
9,-17,28:18.6
-14,-16,28:18.6
-12,-16,28:18.6
-11,-16,28:18.6
-10,-16,28:18.6
9,-16,28:18.6
10,-16,28:18.6
-12,-15,28:18.6
-11,-15,28:18.6
-10,-15,28:18.6
-9,-15,28:18.6
-8,-15,28:18.6
-7,-15,28:18.6
-6,-15,28:18.14
3,-15,28:18.14
4,-15,28:18.14
5,-15,28:18.14
6,-15,28:18.14
7,-15,28:18.14
8,-15,28:18.14
9,-15,28:18.14
10,-15,28:18.6
-14,-14,28:18.6
-8,-14,28:18.6
-7,-14,28:18.6
-6,-14,28:18.14
-5,-14,28:18.14
-4,-14,28:18.14
-3,-14,28:18.14
-2,-14,28:18.14
-1,-14,28:18.14
0,-14,28:18.14
1,-14,28:18.14
2,-14,28:18.14
3,-14,28:18.14
4,-14,28:18.14
5,-14,28:18.14
6,-14,28:18.14
7,-14,28:18.14
8,-14,28:18.14
-14,-13,28:18.6
-13,-13,28:18.6
-4,-13,28:18.14
-3,-13,28:18.14
-2,-13,28:18.14
-1,-13,28:18.14
0,-13,28:18.14
1,-13,28:18.14
8,-13,28:18.14
-14,-12,28:18.6
-13,-12,28:18.6
-4,-12,28:18.14
-3,-12,28:18.14
-1,-12,28:18.14
0,-12,28:18.14
1,-12,28:18.14
8,-12,28:18.14
-14,-11,28:18.6
-13,-11,28:18.6
-5,-11,28:18.14
-4,-11,28:18.14
1,-11,28:18.14
2,-11,28:18.14
3,-11,28:18.14
8,-11,28:18.14
-13,-10,28:18.6
-12,-10,28:18.6
-6,-10,28:18.14
-5,-10,28:18.14
2,-10,28:18.14
3,-10,28:18.14
4,-10,28:18.14
8,-10,28:18.14
-13,-9,28:18.6
-12,-9,28:18.6
-7,-9,28:18.14
-6,-9,28:18.14
4,-9,28:18.14
5,-9,28:18.14
8,-9,28:18.14
-13,-8,28:18.14
-12,-8,28:18.14
-8,-8,28:18.14
-7,-8,28:18.14
5,-8,28:18.14
6,-8,28:18.14
8,-8,28:18.14
-12,-7,28:18.14
-9,-7,28:18.14
-8,-7,28:18.14
5,-7,28:18.14
6,-7,28:18.14
8,-7,28:18.14
-12,-6,28:18.14
-11,-6,28:18.14
-10,-6,28:18.14
-9,-6,28:18.14
6,-6,28:18.14
7,-6,28:18.14
8,-6,28:18.14
-12,-5,28:18.14
-11,-5,28:18.14
-9,-5,28:18.14
7,-5,28:18.14
8,-5,28:18.14
-12,-4,28:18.14
-11,-4,28:18.14
-10,-4,28:18.14
7,-4,28:18.14
8,-4,28:18.14
9,-4,28:17.12
-11,-3,28:18.14
-10,-3,28:18.14
7,-3,28:18.14
8,-3,28:18.14
9,-3,28:18.14
-11,-2,28:18.14
-10,-2,28:18.14
-9,-2,28:18.14
6,-2,28:18.14
7,-2,28:18.14
8,-2,28:18.14
9,-2,28:18.14
-12,-1,28:18.14
-11,-1,28:18.14
-10,-1,28:18.14
-9,-1,28:18.14
-8,-1,28:18.14
6,-1,28:18.14
8,-1,28:18.14
9,-1,28:18.14
-12,0,28:18.14
-11,0,28:18.14
-9,0,28:18.14
-8,0,28:18.14
5,0,28:18.14
6,0,28:18.14
9,0,28:18.14
-12,1,28:18.14
-11,1,28:18.14
-8,1,28:18.14
-7,1,28:18.14
5,1,28:18.14
9,1,28:18.14
10,1,28:18.14
-12,2,28:18.6
-11,2,28:18.6
-7,2,28:18.6
-6,2,28:18.6
-5,2,28:18.14
3,2,28:18.14
4,2,28:18.14
9,2,28:18.6
10,2,28:18.6
-12,3,28:18.6
-11,3,28:18.6
-6,3,28:18.6
-5,3,28:18.14
-4,3,28:18.14
-3,3,28:18.14
1,3,28:18.14
2,3,28:18.14
3,3,28:18.14
9,3,28:18.6
10,3,28:18.6
-12,4,28:18.6
-11,4,28:18.6
-4,4,28:18.14
-3,4,28:18.14
-2,4,28:18.14
-1,4,28:18.14
0,4,28:18.14
1,4,28:18.14
2,4,28:18.14
10,4,28:18.6
-12,5,28:18.6
-11,5,28:18.6
-5,5,28:18.14
-4,5,28:18.14
-3,5,28:18.14
-2,5,28:18.14
0,5,28:18.14
1,5,28:18.14
2,5,28:18.14
3,5,28:18.14
4,5,28:18.14
10,5,28:18.6
11,5,28:18.6
-12,6,28:18.6
-11,6,28:18.6
-10,6,28:18.6
-9,6,28:18.6
-8,6,28:18.6
-7,6,28:18.6
-6,6,28:18.6
-5,6,28:18.14
-4,6,28:18.14
-3,6,28:18.14
-2,6,28:18.14
0,6,28:17.12
1,6,28:18.14
2,6,28:18.14
3,6,28:18.14
4,6,28:18.14
5,6,28:18.6
6,6,28:18.6
7,6,28:18.6
8,6,28:18.6
10,6,28:18.6
11,6,28:18.6
-13,7,28:18.6
-12,7,28:18.6
-11,7,28:18.6
-10,7,28:18.6
-9,7,28:18.6
-8,7,28:18.6
6,7,28:18.6
7,7,28:18.6
8,7,28:18.6
9,7,28:18.6
10,7,28:18.6
11,7,28:18.6
-14,8,28:18.6
-13,8,28:18.6
-12,8,28:18.6
11,8,28:18.6
12,8,28:18.6
-12,9,28:18.6
-10,-17,29:18.6
-8,-17,29:18.6
-7,-17,29:18.6
-6,-17,29:18.14
-5,-17,29:18.14
9,-17,29:18.6
10,-17,29:18.6
-12,-16,29:18.6
-11,-16,29:18.6
-10,-16,29:18.6
-9,-16,29:18.6
-8,-16,29:18.6
2,-16,29:18.14
3,-16,29:18.6
4,-16,29:18.6
5,-16,29:18.6
6,-16,29:18.6
7,-16,29:18.6
8,-16,29:18.6
9,-16,29:18.6
10,-16,29:18.6
-8,-15,29:18.6
-7,-15,29:18.6
-6,-15,29:18.14
-5,-15,29:18.14
-4,-15,29:18.14
-3,-15,29:18.14
-2,-15,29:18.14
-1,-15,29:18.14
0,-15,29:18.14
1,-15,29:18.14
2,-15,29:18.14
3,-15,29:18.6
4,-15,29:18.6
5,-15,29:18.6
6,-15,29:18.6
9,-15,29:18.6
10,-15,29:18.6
-4,-14,29:18.14
-3,-14,29:18.14
-2,-14,29:18.14
-1,-14,29:18.14
0,-14,29:18.14
9,-14,29:18.6
10,-14,29:18.6
-14,-13,29:18.6
-5,-13,29:18.14
-4,-13,29:18.14
-3,-13,29:18.14
-1,-13,29:18.14
0,-13,29:18.14
1,-13,29:18.14
9,-13,29:18.6
10,-13,29:18.6
-15,-12,29:18.6
-14,-12,29:18.6
-5,-12,29:18.14
-4,-12,29:18.14
1,-12,29:18.14
2,-12,29:18.14
3,-12,29:18.6
9,-12,29:18.6
10,-12,29:18.6
-14,-11,29:18.6
-6,-11,29:18.14
-5,-11,29:18.14
3,-11,29:18.6
4,-11,29:18.6
9,-11,29:18.6
10,-11,29:18.6
-14,-10,29:18.6
-13,-10,29:18.6
-7,-10,29:18.14
-6,-10,29:18.14
4,-10,29:18.6
5,-10,29:18.6
9,-10,29:18.6
-15,-9,29:18.6
-13,-9,29:18.6
-8,-9,29:18.14
-7,-9,29:18.14
5,-9,29:18.6
6,-9,29:18.6
9,-9,29:18.6
-15,-8,29:18.14
-13,-8,29:18.14
-9,-8,29:18.14
-8,-8,29:18.14
6,-8,29:18.14
7,-8,29:18.14
9,-8,29:18.14
-13,-7,29:18.14
-10,-7,29:18.14
-9,-7,29:18.14
7,-7,29:18.14
8,-7,29:18.14
9,-7,29:18.14
-13,-6,29:18.14
-12,-6,29:18.14
-11,-6,29:18.14
-10,-6,29:18.14
7,-6,29:18.14
8,-6,29:18.14
9,-6,29:18.14
-12,-5,29:18.14
-11,-5,29:18.14
8,-5,29:18.14
9,-5,29:18.14
-12,-4,29:18.14
-11,-4,29:18.14
9,-4,29:18.14
10,-4,29:17.12
-12,-3,29:18.14
-11,-3,29:18.14
8,-3,29:18.14
9,-3,29:18.14
10,-3,29:18.14
-12,-2,29:18.14
-11,-2,29:18.14
7,-2,29:18.14
8,-2,29:18.14
9,-2,29:18.14
10,-2,29:18.14
-12,-1,29:18.14
-11,-1,29:18.14
-10,-1,29:18.14
7,-1,29:18.14
9,-1,29:18.14
10,-1,29:18.14
-12,0,29:18.14
-10,0,29:18.14
-9,0,29:18.14
6,0,29:18.14
7,0,29:18.14
10,0,29:18.14
-13,1,29:18.14
-12,1,29:18.14
-9,1,29:18.14
-8,1,29:18.14
5,1,29:18.14
6,1,29:18.14
10,1,29:18.14
11,1,29:18.14
-13,2,29:18.6
-12,2,29:18.6
-8,2,29:18.6
-7,2,29:18.6
4,2,29:18.14
5,2,29:18.6
6,2,29:18.6
10,2,29:18.6
11,2,29:18.6
-13,3,29:18.6
-12,3,29:18.6
-8,3,29:18.6
-7,3,29:18.6
-6,3,29:18.6
-5,3,29:18.14
3,3,29:18.14
4,3,29:18.14
5,3,29:18.6
10,3,29:18.6
11,3,29:18.6
-13,4,29:18.6
-12,4,29:18.6
-6,4,29:18.6
-5,4,29:18.14
-4,4,29:18.14
-3,4,29:18.14
2,4,29:18.14
3,4,29:18.14
11,4,29:18.6
-13,5,29:18.6
-12,5,29:18.6
-4,5,29:18.14
-3,5,29:18.14
-2,5,29:18.14
0,5,29:18.14
1,5,29:18.14
2,5,29:18.14
11,5,29:18.6
12,5,29:18.6
-13,6,29:18.6
-12,6,29:18.6
-5,6,29:18.14
-4,6,29:18.14
-3,6,29:18.14
-2,6,29:18.14
-1,6,29:18.14
0,6,29:18.14
1,6,29:18.14
2,6,29:18.14
3,6,29:18.14
11,6,29:18.6
12,6,29:18.6
-13,7,29:18.6
-12,7,29:18.6
-10,7,29:18.6
-9,7,29:18.6
-8,7,29:18.6
-7,7,29:18.6
-6,7,29:18.6
-5,7,29:18.14
-4,7,29:18.14
-3,7,29:18.14
-2,7,29:18.14
0,7,29:17.12
1,7,29:18.14
2,7,29:18.14
3,7,29:18.14
4,7,29:18.14
5,7,29:18.6
6,7,29:18.6
7,7,29:18.6
8,7,29:18.6
11,7,29:18.6
-13,8,29:18.6
-12,8,29:18.6
-11,8,29:18.6
-10,8,29:18.6
-9,8,29:18.6
-8,8,29:18.6
6,8,29:18.6
8,8,29:18.6
9,8,29:18.6
10,8,29:18.6
12,8,29:18.6
-13,9,29:18.6
-12,9,29:18.6
-12,-17,30:18.6
-9,-17,30:18.6
-8,-17,30:18.6
-7,-17,30:18.6
-6,-17,30:18.14
-5,-17,30:18.14
-4,-17,30:18.14
-3,-17,30:18.14
1,-17,30:18.14
2,-17,30:18.14
3,-17,30:18.6
5,-17,30:18.6
6,-17,30:18.6
7,-17,30:18.6
8,-17,30:18.6
9,-17,30:18.6
-12,-16,30:18.6
-11,-16,30:18.6
-10,-16,30:18.6
-9,-16,30:18.6
-8,-16,30:18.6
-7,-16,30:18.6
-6,-16,30:18.14
1,-16,30:18.14
2,-16,30:18.14
3,-16,30:18.6
4,-16,30:18.6
5,-16,30:18.6
10,-16,30:18.6
11,-16,30:18.6
-6,-15,30:18.14
-5,-15,30:18.14
-4,-15,30:18.14
-3,-15,30:18.14
-2,-15,30:18.14
-1,-15,30:18.14
0,-15,30:18.14
1,-15,30:18.14
10,-15,30:18.6
11,-15,30:18.6
-4,-14,30:18.14
-3,-14,30:18.14
-1,-14,30:18.14
0,-14,30:18.14
1,-14,30:18.14
10,-14,30:18.6
11,-14,30:18.6
-15,-13,30:18.6
-14,-13,30:18.6
-6,-13,30:18.14
-5,-13,30:18.14
1,-13,30:18.14
2,-13,30:18.14
3,-13,30:18.6
10,-13,30:18.6
11,-13,30:18.6
-14,-12,30:18.6
-7,-12,30:18.6
-6,-12,30:18.14
3,-12,30:18.6
4,-12,30:18.6
10,-12,30:18.6
11,-12,30:18.6
-14,-11,30:18.6
-8,-11,30:18.6
-7,-11,30:18.6
4,-11,30:18.6
5,-11,30:18.6
6,-11,30:18.6
10,-11,30:18.6
11,-11,30:18.6
-14,-10,30:18.6
-9,-10,30:18.6
-8,-10,30:18.6
6,-10,30:18.6
10,-10,30:18.6
11,-10,30:18.6
-14,-9,30:18.6
-13,-9,30:18.6
-10,-9,30:18.6
-9,-9,30:18.6
-8,-9,30:18.6
6,-9,30:18.6
7,-9,30:18.6
10,-9,30:18.6
-14,-8,30:18.14
-13,-8,30:18.14
-10,-8,30:18.14
-9,-8,30:18.14
7,-8,30:18.14
8,-8,30:18.14
10,-8,30:18.14
11,-8,30:18.14
-14,-7,30:18.14
-13,-7,30:18.14
-11,-7,30:18.14
-10,-7,30:18.14
8,-7,30:18.14
9,-7,30:18.14
10,-7,30:18.14
11,-7,30:18.14
-13,-6,30:18.14
-11,-6,30:18.14
8,-6,30:18.14
9,-6,30:18.14
10,-6,30:18.14
11,-6,30:18.14
-13,-5,30:18.14
-12,-5,30:18.14
-11,-5,30:18.14
9,-5,30:18.14
10,-5,30:18.14
11,-5,30:18.14
-12,-4,30:18.14
10,-4,30:18.14
11,-4,30:18.14
-14,-3,30:18.14
-12,-3,30:18.14
9,-3,30:18.14
10,-3,30:18.14
11,-3,30:18.14
-14,-2,30:18.14
-12,-2,30:18.14
-11,-2,30:18.14
8,-2,30:18.14
9,-2,30:18.14
10,-2,30:18.14
11,-2,30:18.14
-14,-1,30:18.14
-12,-1,30:18.14
-11,-1,30:18.14
8,-1,30:18.14
11,-1,30:18.14
-14,0,30:18.14
-13,0,30:18.14
-11,0,30:18.14
-10,0,30:18.14
7,0,30:18.14
8,0,30:18.14
11,0,30:18.14
12,0,30:18.14
-14,1,30:18.14
-13,1,30:18.14
-10,1,30:18.14
-9,1,30:18.14
6,1,30:18.6
7,1,30:18.6
11,1,30:18.6
12,1,30:18.6
-14,2,30:18.6
-13,2,30:18.6
-10,2,30:18.6
-9,2,30:18.6
6,2,30:18.6
7,2,30:18.6
11,2,30:18.6
12,2,30:18.6
-14,3,30:18.6
-13,3,30:18.6
-9,3,30:18.6
-8,3,30:18.6
5,3,30:18.6
6,3,30:18.6
12,3,30:18.6
-14,4,30:18.6
-13,4,30:18.6
-8,4,30:18.6
-7,4,30:18.6
-6,4,30:18.6
-5,4,30:18.6
3,4,30:18.14
4,4,30:18.14
5,4,30:18.6
12,4,30:18.6
-13,5,30:18.6
-6,5,30:18.6
-5,5,30:18.6
-4,5,30:18.14
-3,5,30:18.14
2,5,30:18.14
3,5,30:18.14
12,5,30:18.6
-13,6,30:18.6
-4,6,30:18.14
-3,6,30:18.14
-2,6,30:18.14
-1,6,30:18.14
0,6,30:18.14
1,6,30:18.14
2,6,30:18.14
12,6,30:18.6
-14,7,30:18.6
-13,7,30:18.6
-4,7,30:18.14
-3,7,30:18.14
-2,7,30:18.14
-1,7,30:18.14
0,7,30:18.14
1,7,30:18.14
2,7,30:18.14
3,7,30:18.14
-14,8,30:18.6
-13,8,30:18.6
-9,8,30:18.6
-8,8,30:18.6
-6,8,30:18.6
-5,8,30:18.6
-4,8,30:18.14
-3,8,30:18.14
-2,8,30:18.14
0,8,30:17.12
1,8,30:18.14
2,8,30:18.14
3,8,30:18.14
4,8,30:18.14
5,8,30:18.6
6,8,30:18.6
8,8,30:18.6
-12,9,30:18.6
-11,9,30:18.6
-10,9,30:18.6
-9,9,30:18.6
-8,9,30:18.6
-7,9,30:18.6
-6,9,30:18.6
-5,9,30:18.6
1,9,30:18.14
2,9,30:18.14
3,9,30:18.14
4,9,30:18.14
6,9,30:18.6
7,9,30:18.6
8,9,30:18.6
9,9,30:18.6
10,9,30:18.6
-11,-17,31:18.6
-1,-17,31:18.14
1,-17,31:18.14
2,-17,31:18.14
3,-17,31:18.6
4,-17,31:18.6
5,-17,31:18.6
6,-17,31:18.6
7,-17,31:18.6
8,-17,31:18.6
-13,-16,31:18.6
-12,-16,31:18.6
-11,-16,31:18.6
-10,-16,31:18.6
-9,-16,31:18.6
-8,-16,31:18.6
-7,-16,31:18.6
-6,-16,31:18.14
-5,-16,31:18.14
-4,-16,31:18.14
-3,-16,31:18.14
-2,-16,31:18.14
-1,-16,31:18.14
0,-16,31:18.14
1,-16,31:18.14
2,-16,31:18.14
3,-16,31:18.6
4,-16,31:18.6
11,-16,31:18.6
-12,-15,31:18.6
-5,-15,31:18.14
-4,-15,31:18.14
-3,-15,31:18.14
-2,-15,31:18.14
-1,-15,31:18.14
0,-15,31:18.14
11,-15,31:18.6
-14,-14,31:18.6
-5,-14,31:18.14
-4,-14,31:18.14
-3,-14,31:18.14
-1,-14,31:18.14
0,-14,31:18.14
1,-14,31:18.14
2,-14,31:18.14
11,-14,31:18.6
-15,-13,31:18.6
-14,-13,31:18.6
-7,-13,31:18.6
-6,-13,31:18.14
-5,-13,31:18.14
3,-13,31:18.6
4,-13,31:18.6
5,-13,31:18.6
10,-13,31:18.6
11,-13,31:18.6
-14,-12,31:18.6
-8,-12,31:18.6
-7,-12,31:18.6
4,-12,31:18.6
5,-12,31:18.6
6,-12,31:18.6
10,-12,31:18.6
11,-12,31:18.6
-14,-11,31:18.6
-9,-11,31:18.6
-8,-11,31:18.6
6,-11,31:18.6
7,-11,31:18.6
10,-11,31:18.6
11,-11,31:18.6
-14,-10,31:18.6
-10,-10,31:18.6
-9,-10,31:18.6
7,-10,31:18.6
8,-10,31:18.6
11,-10,31:18.6
-14,-9,31:18.6
-10,-9,31:18.6
7,-9,31:18.6
8,-9,31:18.6
-14,-8,31:18.14
-13,-8,31:18.14
-11,-8,31:18.14
8,-8,31:18.14
9,-8,31:18.14
11,-8,31:18.14
-14,-7,31:18.14
-13,-7,31:18.14
-11,-7,31:18.14
9,-7,31:18.14
11,-7,31:18.14
-14,-6,31:18.14
-13,-6,31:18.14
-11,-6,31:18.14
10,-6,31:18.14
11,-6,31:18.14
-14,-5,31:18.14
-13,-5,31:18.14
-12,-5,31:18.14
10,-5,31:18.14
11,-5,31:18.14
-14,-4,31:18.14
-13,-4,31:18.14
-12,-4,31:18.14
10,-4,31:18.14
11,-4,31:18.14
-14,-3,31:18.14
-12,-3,31:18.14
10,-3,31:18.14
11,-3,31:18.14
-14,-2,31:18.14
-13,-2,31:18.14
-12,-2,31:18.14
9,-2,31:18.14
10,-2,31:18.14
11,-2,31:18.14
-14,-1,31:18.14
-13,-1,31:18.14
-12,-1,31:18.14
-11,-1,31:18.14
9,-1,31:18.14
11,-1,31:18.14
-14,0,31:18.14
-13,0,31:18.14
-11,0,31:18.14
8,0,31:18.14
9,0,31:18.14
11,0,31:18.14
-14,1,31:18.14
-13,1,31:18.14
-11,1,31:18.14
8,1,31:18.6
11,1,31:18.6
12,1,31:18.6
-14,2,31:18.6
-13,2,31:18.6
-11,2,31:18.6
-10,2,31:18.6
7,2,31:18.6
8,2,31:18.6
11,2,31:18.6
12,2,31:18.6
-14,3,31:18.6
-13,3,31:18.6
-10,3,31:18.6
-9,3,31:18.6
6,3,31:18.6
7,3,31:18.6
11,3,31:18.6
12,3,31:18.6
-14,4,31:18.6
-13,4,31:18.6
-9,4,31:18.6
-8,4,31:18.6
5,4,31:18.6
6,4,31:18.6
11,4,31:18.6
12,4,31:18.6
-14,5,31:18.6
-13,5,31:18.6
-8,5,31:18.6
-7,5,31:18.6
-6,5,31:18.6
3,5,31:18.14
4,5,31:18.14
5,5,31:18.6
11,5,31:18.6
12,5,31:18.6
-14,6,31:18.6
-13,6,31:18.6
-6,6,31:18.6
-5,6,31:18.6
-4,6,31:18.14
-3,6,31:18.14
2,6,31:18.14
3,6,31:18.14
4,6,31:18.14
12,6,31:18.6
-14,7,31:18.6
-4,7,31:18.14
-3,7,31:18.14
-2,7,31:18.14
-1,7,31:18.14
0,7,31:18.14
1,7,31:18.14
2,7,31:18.14
-5,8,31:18.6
-4,8,31:18.14
-3,8,31:18.14
-2,8,31:18.14
-1,8,31:18.14
0,8,31:18.14
1,8,31:18.14
2,8,31:18.14
3,8,31:18.14
4,8,31:18.14
5,8,31:18.6
6,8,31:18.6
8,8,31:18.6
9,8,31:18.6
-11,9,31:18.6
-10,9,31:18.6
-9,9,31:18.6
-8,9,31:18.6
-7,9,31:18.6
-6,9,31:18.6
-5,9,31:18.6
-4,9,31:18.14
-3,9,31:18.14
-2,9,31:18.14
0,9,31:18.14
1,9,31:18.14
2,9,31:18.14
3,9,31:18.14
4,9,31:18.14
6,9,31:18.6
7,9,31:18.6
8,9,31:18.6
9,9,31:18.6
-11,10,31:18.6
-11,-17,32:18.6
-10,-17,32:18.6
3,-17,32:18.6
4,-17,32:18.6
5,-17,32:18.6
6,-17,32:18.6
7,-17,32:18.6
8,-17,32:18.6
-10,-16,32:18.6
-9,-16,32:18.6
-8,-16,32:18.6
-7,-16,32:18.6
-6,-16,32:18.6
-5,-16,32:18.6
-4,-16,32:18.6
-3,-16,32:18.6
-2,-16,32:18.6
-1,-16,32:18.6
0,-16,32:18.6
1,-16,32:18.6
2,-16,32:18.6
3,-16,32:18.6
4,-16,32:18.6
5,-16,32:18.6
6,-16,32:18.6
7,-16,32:18.6
-13,-15,32:18.6
-12,-15,32:18.6
-11,-15,32:18.6
-10,-15,32:18.6
-9,-15,32:18.6
-8,-15,32:18.6
-7,-15,32:18.6
-6,-15,32:18.6
-5,-15,32:18.6
-4,-15,32:18.6
-3,-15,32:18.6
-2,-15,32:18.6
-1,-15,32:18.6
10,-15,32:18.6
11,-15,32:18.6
-13,-14,32:18.6
-5,-14,32:18.6
-4,-14,32:18.6
0,-14,32:18.6
1,-14,32:18.6
2,-14,32:18.6
3,-14,32:18.6
10,-14,32:18.6
11,-14,32:18.6
-13,-13,32:18.6
-7,-13,32:18.6
-6,-13,32:18.6
3,-13,32:18.6
4,-13,32:18.6
5,-13,32:18.6
6,-13,32:18.6
10,-13,32:18.6
11,-13,32:18.6
-15,-12,32:18.6
-14,-12,32:18.6
-13,-12,32:18.6
-9,-12,32:18.6
-8,-12,32:18.6
-7,-12,32:18.6
6,-12,32:18.6
7,-12,32:18.6
10,-12,32:18.6
11,-12,32:18.6
-14,-11,32:18.6
-13,-11,32:18.6
-10,-11,32:18.6
-9,-11,32:18.6
7,-11,32:18.6
8,-11,32:18.6
10,-11,32:18.6
11,-11,32:18.6
-14,-10,32:18.6
-13,-10,32:18.6
-10,-10,32:18.6
8,-10,32:18.6
10,-10,32:18.6
11,-10,32:18.6
-14,-9,32:18.6
-13,-9,32:18.6
-11,-9,32:18.6
-10,-9,32:18.6
8,-9,32:18.6
9,-9,32:18.6
10,-9,32:18.6
-14,-8,32:18.6
-13,-8,32:18.6
-11,-8,32:18.6
9,-8,32:18.14
10,-8,32:18.14
11,-8,32:18.14
-13,-7,32:18.6
-11,-7,32:18.6
9,-7,32:18.14
10,-7,32:18.14
11,-7,32:18.14
-13,-6,32:18.6
-12,-6,32:18.6
10,-6,32:18.14
11,-6,32:18.14
-13,-5,32:18.6
-12,-5,32:18.6
10,-5,32:18.14
11,-5,32:18.14
-13,-4,32:18.6
-12,-4,32:18.6
10,-4,32:18.14
11,-4,32:18.14
-13,-3,32:18.6
-12,-3,32:18.6
10,-3,32:18.14
11,-3,32:18.14
-13,-2,32:18.6
-12,-2,32:18.6
10,-2,32:18.14
11,-2,32:18.14
-13,-1,32:18.6
-12,-1,32:18.6
9,-1,32:18.14
10,-1,32:18.14
11,-1,32:18.14
-13,0,32:18.6
-11,0,32:18.6
9,0,32:18.14
11,0,32:18.14
12,0,32:18.14
-13,1,32:18.6
-11,1,32:18.6
8,1,32:18.6
9,1,32:18.6
11,1,32:18.6
12,1,32:18.6
-13,2,32:18.6
-11,2,32:18.6
8,2,32:18.6
11,2,32:18.6
12,2,32:18.6
-13,3,32:18.6
-10,3,32:18.6
7,3,32:18.6
8,3,32:18.6
11,3,32:18.6
12,3,32:18.6
-14,4,32:18.6
-13,4,32:18.6
-10,4,32:18.6
6,4,32:18.6
7,4,32:18.6
11,4,32:18.6
12,4,32:18.6
-14,5,32:18.6
-13,5,32:18.6
-10,5,32:18.6
-9,5,32:18.6
-8,5,32:18.6
5,5,32:18.6
6,5,32:18.6
11,5,32:18.6
12,5,32:18.6
-14,6,32:18.6
-13,6,32:18.6
-8,6,32:18.6
-7,6,32:18.6
-6,6,32:18.6
-5,6,32:18.6
3,6,32:18.14
4,6,32:18.14
5,6,32:18.6
11,6,32:18.6
12,6,32:18.6
-13,7,32:18.6
-5,7,32:18.6
-4,7,32:18.14
-3,7,32:18.14
-2,7,32:18.14
1,7,32:18.14
2,7,32:18.14
3,7,32:18.14
-10,8,32:18.6
-9,8,32:18.6
-8,8,32:18.6
-6,8,32:18.6
-5,8,32:18.6
-4,8,32:18.14
-3,8,32:18.14
-2,8,32:18.14
-1,8,32:18.14
0,8,32:18.14
1,8,32:18.14
2,8,32:18.14
3,8,32:18.14
4,8,32:18.14
5,8,32:18.6
6,8,32:18.6
8,8,32:18.6
9,8,32:18.6
10,8,32:18.6
-11,9,32:18.6
-10,9,32:18.6
-9,9,32:18.6
-8,9,32:18.6
-7,9,32:18.6
-6,9,32:18.6
-5,9,32:18.6
-4,9,32:18.14
-3,9,32:18.14
-2,9,32:18.14
2,9,32:18.14
3,9,32:18.14
4,9,32:18.14
6,9,32:18.6
7,9,32:18.6
8,9,32:18.6
9,9,32:18.6
-10,10,32:18.6
-9,10,32:18.6
7,-18,33:18.6
-10,-17,33:18.6
-9,-17,33:18.6
3,-17,33:18.6
4,-17,33:18.6
5,-17,33:18.6
6,-17,33:18.6
7,-17,33:18.6
-9,-16,33:18.6
-8,-16,33:18.6
-7,-16,33:18.6
-6,-16,33:18.6
-5,-16,33:18.6
-4,-16,33:18.6
-2,-16,33:18.6
-1,-16,33:18.6
0,-16,33:18.6
1,-16,33:18.6
2,-16,33:18.6
3,-16,33:18.6
4,-16,33:18.6
5,-16,33:18.6
6,-16,33:18.6
7,-16,33:18.6
8,-16,33:18.6
-13,-15,33:18.6
-12,-15,33:18.6
-11,-15,33:18.6
-10,-15,33:18.6
-9,-15,33:18.6
-8,-15,33:18.6
-7,-15,33:18.6
-6,-15,33:18.6
-5,-15,33:18.6
-4,-15,33:18.6
-3,-15,33:18.6
-2,-15,33:18.6
-1,-15,33:18.6
0,-15,33:18.6
1,-15,33:18.6
9,-15,33:18.6
-13,-14,33:18.6
-12,-14,33:18.6
-11,-14,33:18.6
-5,-14,33:18.6
-4,-14,33:18.6
0,-14,33:18.6
1,-14,33:18.6
2,-14,33:18.6
3,-14,33:18.6
9,-14,33:18.6
11,-14,33:18.6
-13,-13,33:18.6
-7,-13,33:18.6
-6,-13,33:18.6
4,-13,33:18.6
5,-13,33:18.6
6,-13,33:18.6
9,-13,33:18.6
10,-13,33:18.6
11,-13,33:18.6
-13,-12,33:18.6
-9,-12,33:18.6
-8,-12,33:18.6
6,-12,33:18.6
7,-12,33:18.6
9,-12,33:18.6
10,-12,33:18.6
11,-12,33:18.6
-15,-11,33:18.6
-14,-11,33:18.6
-13,-11,33:18.6
-10,-11,33:18.6
-9,-11,33:18.6
7,-11,33:18.6
8,-11,33:18.6
9,-11,33:18.6
10,-11,33:18.6
11,-11,33:18.6
-14,-10,33:18.6
-13,-10,33:18.6
-11,-10,33:18.6
-10,-10,33:18.6
8,-10,33:18.6
9,-10,33:18.6
10,-10,33:18.6
11,-10,33:18.6
-14,-9,33:18.6
-13,-9,33:18.6
-11,-9,33:18.6
8,-9,33:18.6
9,-9,33:18.6
10,-9,33:18.6
-14,-8,33:18.6
-13,-8,33:18.6
-11,-8,33:18.6
9,-8,33:18.14
10,-8,33:18.14
11,-8,33:18.14
-14,-7,33:18.6
-13,-7,33:18.6
-12,-7,33:18.6
-11,-7,33:18.6
9,-7,33:18.14
10,-7,33:18.14
11,-7,33:18.14
-13,-6,33:18.6
-12,-6,33:18.6
10,-6,33:18.14
11,-6,33:18.14
-13,-5,33:18.6
-12,-5,33:18.6
10,-5,33:18.14
11,-5,33:18.14
-13,-4,33:18.6
-12,-4,33:18.6
10,-4,33:18.14
11,-4,33:18.14
-13,-3,33:18.6
-12,-3,33:18.6
10,-3,33:18.14
11,-3,33:18.14
-13,-2,33:18.6
-12,-2,33:18.6
10,-2,33:18.14
11,-2,33:18.14
-13,-1,33:18.6
-12,-1,33:18.6
9,-1,33:18.14
10,-1,33:18.14
11,-1,33:18.14
-13,0,33:18.6
-12,0,33:18.6
-11,0,33:18.6
9,0,33:18.14
10,0,33:18.14
11,0,33:18.14
12,0,33:18.14
-13,1,33:18.6
-12,1,33:18.6
-11,1,33:18.6
9,1,33:18.6
10,1,33:18.6
12,1,33:18.6
-13,2,33:18.6
-12,2,33:18.6
-11,2,33:18.6
8,2,33:18.6
10,2,33:18.6
11,2,33:18.6
12,2,33:18.6
-14,3,33:18.6
-13,3,33:18.6
-12,3,33:18.6
-11,3,33:18.6
-10,3,33:18.6
8,3,33:18.6
10,3,33:18.6
11,3,33:18.6
12,3,33:18.6
-14,4,33:18.6
-13,4,33:18.6
-12,4,33:18.6
-10,4,33:18.6
7,4,33:18.6
10,4,33:18.6
11,4,33:18.6
12,4,33:18.6
-14,5,33:18.6
-13,5,33:18.6
-12,5,33:18.6
-10,5,33:18.6
-9,5,33:18.6
6,5,33:18.6
7,5,33:18.6
10,5,33:18.6
11,5,33:18.6
12,5,33:18.6
-14,6,33:18.6
-13,6,33:18.6
-12,6,33:18.6
-9,6,33:18.6
-8,6,33:18.6
-7,6,33:18.6
-6,6,33:18.6
4,6,33:18.14
5,6,33:18.6
10,6,33:18.6
11,6,33:18.6
-13,7,33:18.6
-12,7,33:18.6
-6,7,33:18.6
-5,7,33:18.6
-4,7,33:18.14
-3,7,33:18.14
2,7,33:18.14
3,7,33:18.14
4,7,33:18.14
5,7,33:18.6
6,7,33:18.6
7,7,33:18.6
8,7,33:18.6
9,7,33:18.6
10,7,33:18.6
11,7,33:18.6
-12,8,33:18.6
-11,8,33:18.6
-10,8,33:18.6
-9,8,33:18.6
-8,8,33:18.6
-6,8,33:18.6
-5,8,33:18.6
-4,8,33:18.14
-3,8,33:18.14
-2,8,33:18.14
-1,8,33:18.14
0,8,33:18.14
1,8,33:18.14
2,8,33:18.14
3,8,33:18.14
4,8,33:18.14
5,8,33:18.6
6,8,33:18.6
8,8,33:18.6
9,8,33:18.6
10,8,33:18.6
11,8,33:18.6
-7,9,33:18.6
-6,9,33:18.6
-5,9,33:18.6
-4,9,33:18.14
-3,9,33:18.14
-2,9,33:18.14
-1,9,33:18.14
0,9,33:18.14
1,9,33:18.14
2,9,33:18.14
3,9,33:18.14
4,9,33:18.14
6,9,33:18.6
7,9,33:18.6
-10,10,33:18.6
-9,10,33:18.6
-8,10,33:18.6
-7,10,33:18.6
7,10,33:18.6
8,10,33:18.6
-9,-17,34:18.6
-8,-17,34:18.6
2,-17,34:18.6
3,-17,34:18.6
4,-17,34:18.6
5,-17,34:18.6
6,-17,34:18.6
-8,-16,34:18.6
-7,-16,34:18.6
-6,-16,34:18.6
-5,-16,34:18.6
-4,-16,34:18.6
-3,-16,34:18.6
-2,-16,34:18.6
-1,-16,34:18.6
0,-16,34:18.6
1,-16,34:18.6
2,-16,34:18.6
6,-16,34:18.6
7,-16,34:18.6
8,-16,34:18.6
9,-16,34:18.6
-12,-15,34:18.6
-7,-15,34:18.6
-6,-15,34:18.6
-5,-15,34:18.6
-4,-15,34:18.6
-3,-15,34:18.6
-2,-15,34:18.6
-1,-15,34:18.6
0,-15,34:18.6
1,-15,34:18.6
2,-15,34:18.6
3,-15,34:18.6
4,-15,34:18.6
5,-15,34:18.6
6,-15,34:18.6
7,-15,34:18.6
8,-15,34:18.6
9,-15,34:18.6
-13,-14,34:18.6
-12,-14,34:18.6
-11,-14,34:18.6
-10,-14,34:18.6
-9,-14,34:18.6
-8,-14,34:18.6
-7,-14,34:18.6
-6,-14,34:18.6
-5,-14,34:18.6
-4,-14,34:18.6
1,-14,34:18.6
2,-14,34:18.6
3,-14,34:18.6
4,-14,34:18.6
9,-14,34:18.6
11,-14,34:18.6
-12,-13,34:18.6
-8,-13,34:18.6
-7,-13,34:18.6
-6,-13,34:18.6
4,-13,34:18.6
5,-13,34:18.6
6,-13,34:18.6
9,-13,34:18.6
11,-13,34:18.6
-12,-12,34:18.6
-9,-12,34:18.6
-8,-12,34:18.6
6,-12,34:18.6
7,-12,34:18.6
9,-12,34:18.6
11,-12,34:18.6
-15,-11,34:18.6
-12,-11,34:18.6
-10,-11,34:18.6
-9,-11,34:18.6
7,-11,34:18.6
8,-11,34:18.6
9,-11,34:18.6
11,-11,34:18.6
-15,-10,34:18.6
-14,-10,34:18.6
-12,-10,34:18.6
-11,-10,34:18.6
-10,-10,34:18.6
8,-10,34:18.6
9,-10,34:18.6
11,-10,34:18.6
-14,-9,34:18.6
-12,-9,34:18.6
-11,-9,34:18.6
8,-9,34:18.6
9,-9,34:18.6
-14,-8,34:18.6
-12,-8,34:18.6
-11,-8,34:18.6
9,-8,34:18.6
11,-8,34:18.6
-14,-7,34:18.6
-12,-7,34:18.6
9,-7,34:18.6
10,-7,34:18.6
11,-7,34:18.6
-14,-6,34:18.6
-13,-6,34:18.6
-12,-6,34:18.6
9,-6,34:18.6
10,-6,34:18.6
11,-6,34:18.6
-13,-5,34:18.6
-12,-5,34:18.6
9,-5,34:18.6
10,-5,34:18.6
11,-5,34:18.6
-13,-4,34:18.6
-12,-4,34:18.6
9,-4,34:18.6
10,-4,34:18.6
11,-4,34:18.6
-13,-3,34:18.6
-12,-3,34:18.6
9,-3,34:18.6
10,-3,34:18.6
11,-3,34:18.6
-13,-2,34:18.6
-12,-2,34:18.6
9,-2,34:18.6
10,-2,34:18.6
11,-2,34:18.6
-13,-1,34:18.6
-12,-1,34:18.6
9,-1,34:18.6
10,-1,34:18.6
11,-1,34:18.6
-13,0,34:18.6
-12,0,34:18.6
9,0,34:18.6
10,0,34:18.6
12,0,34:18.6
-13,1,34:18.6
-12,1,34:18.6
-11,1,34:18.6
9,1,34:18.6
10,1,34:18.6
12,1,34:18.6
-14,2,34:18.6
-12,2,34:18.6
-11,2,34:18.6
8,2,34:18.6
10,2,34:18.6
12,2,34:18.6
-14,3,34:18.6
-12,3,34:18.6
-11,3,34:18.6
8,3,34:18.6
10,3,34:18.6
12,3,34:18.6
-14,4,34:18.6
-12,4,34:18.6
-10,4,34:18.6
7,4,34:18.6
10,4,34:18.6
12,4,34:18.6
-14,5,34:18.6
-12,5,34:18.6
-10,5,34:18.6
-9,5,34:18.6
6,5,34:18.6
7,5,34:18.6
10,5,34:18.6
-14,6,34:18.6
-12,6,34:18.6
-8,6,34:18.6
-7,6,34:18.6
4,6,34:18.14
5,6,34:18.6
6,6,34:18.6
10,6,34:18.6
-12,7,34:18.6
-10,7,34:18.6
-9,7,34:18.6
-8,7,34:18.6
-7,7,34:18.6
-6,7,34:18.6
-5,7,34:18.6
-4,7,34:18.14
-3,7,34:18.14
-2,7,34:18.14
-1,7,34:18.14
0,7,34:18.14
1,7,34:18.14
2,7,34:18.14
3,7,34:18.14
4,7,34:18.14
5,7,34:18.6
6,7,34:18.6
7,7,34:18.6
8,7,34:18.6
9,7,34:18.6
10,7,34:18.6
11,7,34:18.6
-13,8,34:18.6
-12,8,34:18.6
-11,8,34:18.6
-10,8,34:18.6
-9,8,34:18.6
-8,8,34:18.6
-6,8,34:18.6
-5,8,34:18.6
-4,8,34:18.14
-3,8,34:18.14
-2,8,34:18.14
-1,8,34:18.14
1,8,34:18.14
2,8,34:18.14
10,8,34:18.6
-5,9,34:18.6
-4,9,34:18.14
-3,9,34:18.14
-2,9,34:18.14
-1,9,34:18.14
0,9,34:18.14
1,9,34:18.14
2,9,34:18.14
3,9,34:18.14
4,9,34:18.14
-9,10,34:18.6
-8,10,34:18.6
-7,10,34:18.6
-6,10,34:18.6
-5,10,34:18.6
-4,10,34:18.14
5,10,34:18.6
6,10,34:18.6
7,10,34:18.6
-9,-17,35:18.6
-8,-17,35:18.6
-7,-17,35:18.6
1,-17,35:18.6
2,-17,35:18.6
3,-17,35:18.6
4,-17,35:18.6
-7,-16,35:18.6
-6,-16,35:18.6
-5,-16,35:18.6
-4,-16,35:18.6
-3,-16,35:18.6
-2,-16,35:18.6
-1,-16,35:18.6
0,-16,35:18.6
1,-16,35:18.6
8,-16,35:18.6
-12,-15,35:18.6
-4,-15,35:18.6
-3,-15,35:18.6
-2,-15,35:18.6
-1,-15,35:18.6
0,-15,35:18.6
1,-15,35:18.6
2,-15,35:18.6
3,-15,35:18.6
4,-15,35:18.6
5,-15,35:18.6
6,-15,35:18.6
7,-15,35:18.6
8,-15,35:18.6
9,-15,35:18.6
-12,-14,35:18.6
-11,-14,35:18.6
-10,-14,35:18.6
-9,-14,35:18.6
-8,-14,35:18.6
-7,-14,35:18.6
-6,-14,35:18.6
-5,-14,35:18.6
-4,-14,35:18.6
-3,-14,35:18.6
-2,-14,35:18.6
-1,-14,35:18.6
0,-14,35:18.6
1,-14,35:18.6
2,-14,35:18.6
3,-14,35:18.6
4,-14,35:18.6
8,-14,35:18.6
-12,-13,35:18.6
-11,-13,35:18.6
-10,-13,35:18.6
-8,-13,35:18.6
-7,-13,35:18.6
4,-13,35:18.6
5,-13,35:18.6
8,-13,35:18.6
11,-13,35:18.6
-12,-12,35:18.6
-9,-12,35:18.6
-8,-12,35:18.6
6,-12,35:18.6
8,-12,35:18.6
9,-12,35:18.6
11,-12,35:18.6
-12,-11,35:18.6
-10,-11,35:18.6
-9,-11,35:18.6
7,-11,35:18.6
8,-11,35:18.6
9,-11,35:18.6
11,-11,35:18.6
-15,-10,35:18.6
-12,-10,35:18.6
-10,-10,35:18.6
8,-10,35:18.6
9,-10,35:18.6
11,-10,35:18.6
-15,-9,35:18.6
-14,-9,35:18.6
-12,-9,35:18.6
-11,-9,35:18.6
8,-9,35:18.6
9,-9,35:18.6
-14,-8,35:18.6
-12,-8,35:18.6
-11,-8,35:18.6
9,-8,35:18.6
11,-8,35:18.6
-14,-7,35:18.6
-12,-7,35:18.6
9,-7,35:18.6
10,-7,35:18.6
11,-7,35:18.6
-14,-6,35:18.6
-12,-6,35:18.6
9,-6,35:18.6
10,-6,35:18.6
11,-6,35:18.6
-14,-5,35:18.6
-13,-5,35:18.6
-12,-5,35:18.6
9,-5,35:18.6
11,-5,35:18.6
-13,-4,35:18.6
-12,-4,35:18.6
9,-4,35:18.6
11,-4,35:18.6
-13,-3,35:18.6
-12,-3,35:18.6
9,-3,35:18.6
10,-3,35:18.6
11,-3,35:18.6
-13,-2,35:18.6
-12,-2,35:18.6
9,-2,35:18.6
10,-2,35:18.6
11,-2,35:18.6
-13,-1,35:18.6
-12,-1,35:18.6
9,-1,35:18.6
10,-1,35:18.6
11,-1,35:18.6
12,-1,35:18.6
-14,0,35:18.6
-13,0,35:18.6
-12,0,35:18.6
-11,0,35:18.6
9,0,35:18.6
12,0,35:18.6
-14,1,35:18.6
-12,1,35:18.6
-11,1,35:18.6
9,1,35:18.6
12,1,35:18.6
-14,2,35:18.6
-12,2,35:18.6
-11,2,35:18.6
8,2,35:18.6
9,2,35:18.6
12,2,35:18.6
-14,3,35:18.6
-12,3,35:18.6
-11,3,35:18.6
7,3,35:18.6
8,3,35:18.6
9,3,35:18.6
12,3,35:18.6
-14,4,35:18.6
-12,4,35:18.6
-11,4,35:18.6
-10,4,35:18.6
-9,4,35:18.6
7,4,35:18.6
9,4,35:18.6
10,4,35:18.6
-14,5,35:18.6
-12,5,35:18.6
-11,5,35:18.6
-9,5,35:18.6
-8,5,35:18.6
6,5,35:18.6
9,5,35:18.6
10,5,35:18.6
-12,6,35:18.6
-11,6,35:18.6
-8,6,35:18.6
-7,6,35:18.6
4,6,35:18.6
5,6,35:18.6
6,6,35:18.6
7,6,35:18.6
8,6,35:18.6
9,6,35:18.6
10,6,35:18.6
-12,7,35:18.6
-11,7,35:18.6
-10,7,35:18.6
-9,7,35:18.6
-8,7,35:18.6
-7,7,35:18.6
-6,7,35:18.6
-5,7,35:18.6
-4,7,35:18.6
-3,7,35:18.6
-2,7,35:18.6
-1,7,35:18.6
0,7,35:18.6
1,7,35:18.6
2,7,35:18.6
3,7,35:18.6
4,7,35:18.6
5,7,35:18.6
6,7,35:18.6
7,7,35:18.6
8,7,35:18.6
9,7,35:18.6
10,7,35:18.6
-12,8,35:18.6
-5,8,35:18.6
-4,8,35:18.6
-3,8,35:18.6
-2,8,35:18.6
1,8,35:18.6
2,8,35:18.6
3,8,35:18.6
9,8,35:18.6
-2,9,35:18.6
-1,9,35:18.6
0,9,35:18.6
1,9,35:18.6
2,9,35:18.6
-7,10,35:18.6
-6,10,35:18.6
-5,10,35:18.6
-4,10,35:18.6
-3,10,35:18.6
-2,10,35:18.6
2,10,35:18.6
3,10,35:18.6
4,10,35:18.6
5,10,35:18.6
6,10,35:18.6
-7,-17,36:18.6
-6,-17,36:18.6
0,-17,36:18.6
1,-17,36:18.6
2,-17,36:18.6
3,-17,36:18.6
-6,-16,36:18.6
-5,-16,36:18.6
-4,-16,36:18.6
-3,-16,36:18.6
-2,-16,36:18.6
-1,-16,36:18.6
0,-16,36:18.6
-5,-15,36:18.6
-4,-15,36:18.6
-3,-15,36:18.6
-1,-15,36:18.6
0,-15,36:18.6
1,-15,36:18.6
2,-15,36:18.6
7,-15,36:18.6
8,-15,36:18.6
-11,-14,36:18.6
-7,-14,36:18.6
-6,-14,36:18.6
-5,-14,36:18.6
-4,-14,36:18.6
-3,-14,36:18.6
-2,-14,36:18.6
-1,-14,36:18.6
0,-14,36:18.6
1,-14,36:18.6
2,-14,36:18.6
3,-14,36:18.6
4,-14,36:18.6
5,-14,36:18.6
6,-14,36:18.6
7,-14,36:18.6
8,-14,36:18.6
9,-14,36:18.6
-12,-13,36:18.6
-11,-13,36:18.6
-10,-13,36:18.6
-9,-13,36:18.6
-8,-13,36:18.6
-7,-13,36:18.6
-6,-13,36:18.6
-5,-13,36:18.6
-4,-13,36:18.6
-3,-13,36:18.6
4,-13,36:18.6
5,-13,36:18.6
8,-13,36:18.6
-11,-12,36:18.6
-8,-12,36:18.6
5,-12,36:18.6
6,-12,36:18.6
8,-12,36:18.6
11,-12,36:18.6
-11,-11,36:18.6
-9,-11,36:18.6
6,-11,36:18.6
7,-11,36:18.6
8,-11,36:18.6
11,-11,36:18.6
-11,-10,36:18.6
-10,-10,36:18.6
8,-10,36:18.6
11,-10,36:18.6
-11,-9,36:18.6
8,-9,36:18.6
9,-9,36:18.6
-14,-8,36:18.6
-12,-8,36:18.6
-11,-8,36:18.6
8,-8,36:18.6
9,-8,36:18.6
11,-8,36:18.6
-14,-7,36:18.6
-12,-7,36:18.6
-11,-7,36:18.6
8,-7,36:18.6
10,-7,36:18.6
11,-7,36:18.6
-14,-6,36:18.6
-12,-6,36:18.6
-11,-6,36:18.6
8,-6,36:18.6
10,-6,36:18.6
11,-6,36:18.6
-14,-5,36:18.6
-13,-5,36:18.6
-11,-5,36:18.6
8,-5,36:18.6
11,-5,36:18.6
-13,-4,36:18.6
-11,-4,36:18.6
8,-4,36:18.6
9,-4,36:18.6
11,-4,36:18.6
-13,-3,36:18.6
-11,-3,36:18.6
8,-3,36:18.6
9,-3,36:18.6
10,-3,36:18.6
11,-3,36:18.6
-13,-2,36:18.6
-11,-2,36:18.6
8,-2,36:18.6
9,-2,36:18.6
10,-2,36:18.6
11,-2,36:18.6
-14,-1,36:18.6
-13,-1,36:18.6
-12,-1,36:18.6
-11,-1,36:18.6
8,-1,36:18.6
9,-1,36:18.6
10,-1,36:18.6
12,-1,36:18.6
-14,0,36:18.6
-12,0,36:18.6
-11,0,36:18.6
9,0,36:18.6
12,0,36:18.6
-14,1,36:18.6
-12,1,36:18.6
-11,1,36:18.6
9,1,36:18.6
12,1,36:18.6
-14,2,36:18.6
-11,2,36:18.6
8,2,36:18.6
9,2,36:18.6
12,2,36:18.6
-14,3,36:18.6
-11,3,36:18.6
-10,3,36:18.6
7,3,36:18.6
8,3,36:18.6
9,3,36:18.6
12,3,36:18.6
-11,4,36:18.6
-10,4,36:18.6
-9,4,36:18.6
6,4,36:18.6
7,4,36:18.6
9,4,36:18.6
-11,5,36:18.6
-9,5,36:18.6
-8,5,36:18.6
6,5,36:18.6
9,5,36:18.6
-12,6,36:18.6
-11,6,36:18.6
-10,6,36:18.6
-9,6,36:18.6
-8,6,36:18.6
-7,6,36:18.6
-6,6,36:18.6
-5,6,36:18.6
-4,6,36:18.6
-3,6,36:18.6
-2,6,36:18.6
-1,6,36:18.6
0,6,36:18.6
1,6,36:18.6
2,6,36:18.6
3,6,36:18.6
4,6,36:18.6
5,6,36:18.6
6,6,36:18.6
7,6,36:18.6
8,6,36:18.6
9,6,36:18.6
10,6,36:18.6
-12,7,36:18.6
-11,7,36:18.6
-10,7,36:18.6
-9,7,36:18.6
-8,7,36:18.6
-7,7,36:18.6
-6,7,36:18.6
-5,7,36:18.6
4,7,36:18.6
9,7,36:18.6
-5,8,36:18.6
-4,8,36:18.6
-3,8,36:18.6
2,8,36:18.6
3,8,36:18.6
-3,9,36:18.6
-2,9,36:18.6
-1,9,36:18.6
0,9,36:18.6
1,9,36:18.6
2,9,36:18.6
-6,10,36:18.6
-5,10,36:18.6
-4,10,36:18.6
-3,10,36:18.6
-2,10,36:18.6
-1,10,36:18.6
0,10,36:18.6
1,10,36:18.6
2,10,36:18.6
3,10,36:18.6
4,10,36:18.6
-6,-17,37:18.6
-1,-17,37:18.6
0,-17,37:18.6
1,-17,37:18.6
-5,-16,37:18.6
-4,-16,37:18.6
-3,-16,37:18.6
-2,-16,37:18.6
-1,-16,37:18.6
-5,-15,37:18.6
-4,-15,37:18.6
-1,-15,37:18.6
0,-15,37:18.6
1,-15,37:18.6
2,-15,37:18.6
-11,-14,37:18.6
-6,-14,37:18.6
1,-14,37:18.6
2,-14,37:18.6
3,-14,37:18.6
4,-14,37:18.6
5,-14,37:18.6
6,-14,37:18.6
7,-14,37:18.6
8,-14,37:18.6
-11,-13,37:18.6
-10,-13,37:18.6
-9,-13,37:18.6
-8,-13,37:18.6
-7,-13,37:18.6
-6,-13,37:18.6
-5,-13,37:18.6
-4,-13,37:18.6
-3,-13,37:18.6
-2,-13,37:18.6
-1,-13,37:18.6
0,-13,37:18.6
1,-13,37:18.6
2,-13,37:18.6
3,-13,37:18.6
4,-13,37:18.6
7,-13,37:18.6
-12,-12,37:18.6
-11,-12,37:18.6
-10,-12,37:18.6
-9,-12,37:18.6
-8,-12,37:18.6
5,-12,37:18.6
7,-12,37:18.6
-11,-11,37:18.6
-9,-11,37:18.6
6,-11,37:18.6
7,-11,37:18.6
8,-11,37:18.6
11,-11,37:18.6
-11,-10,37:18.6
-10,-10,37:18.6
-9,-10,37:18.6
7,-10,37:18.6
8,-10,37:18.6
11,-10,37:18.6
-11,-9,37:18.6
-10,-9,37:18.6
7,-9,37:18.6
8,-9,37:18.6
9,-9,37:18.6
-12,-8,37:18.6
-11,-8,37:18.6
8,-8,37:18.6
9,-8,37:18.6
11,-8,37:18.6
-14,-7,37:18.6
-12,-7,37:18.6
-11,-7,37:18.6
8,-7,37:18.6
10,-7,37:18.6
11,-7,37:18.6
-14,-6,37:18.6
-13,-6,37:18.6
-12,-6,37:18.6
-11,-6,37:18.6
8,-6,37:18.6
10,-6,37:18.6
11,-6,37:18.6
-14,-5,37:18.6
-13,-5,37:18.6
-11,-5,37:18.6
8,-5,37:18.6
11,-5,37:18.6
-14,-4,37:18.6
-13,-4,37:18.6
-11,-4,37:18.6
8,-4,37:18.6
11,-4,37:18.6
-14,-3,37:18.6
-13,-3,37:18.6
-11,-3,37:18.6
8,-3,37:18.6
10,-3,37:18.6
11,-3,37:18.6
-14,-2,37:18.6
-13,-2,37:18.6
-11,-2,37:18.6
8,-2,37:18.6
10,-2,37:18.6
11,-2,37:18.6
-14,-1,37:18.6
-13,-1,37:18.6
-11,-1,37:18.6
8,-1,37:18.6
10,-1,37:18.6
12,-1,37:18.6
-14,0,37:18.6
-12,0,37:18.6
-11,0,37:18.6
8,0,37:18.6
9,0,37:18.6
12,0,37:18.6
-14,1,37:18.6
-12,1,37:18.6
-11,1,37:18.6
-10,1,37:18.6
8,1,37:18.6
9,1,37:18.6
12,1,37:18.6
-14,2,37:18.6
-12,2,37:18.6
-11,2,37:18.6
-10,2,37:18.6
8,2,37:18.6
12,2,37:18.6
-14,3,37:18.6
-11,3,37:18.6
-10,3,37:18.6
7,3,37:18.6
8,3,37:18.6
-11,4,37:18.6
-10,4,37:18.6
-9,4,37:18.6
6,4,37:18.6
7,4,37:18.6
8,4,37:18.6
9,4,37:18.6
-11,5,37:18.6
-10,5,37:18.6
-8,5,37:18.6
-7,5,37:18.6
4,5,37:18.6
5,5,37:18.6
6,5,37:18.6
7,5,37:18.6
8,5,37:18.6
9,5,37:18.6
-12,6,37:18.6
-11,6,37:18.6
-10,6,37:18.6
-9,6,37:18.6
-8,6,37:18.6
-7,6,37:18.6
-6,6,37:18.6
-5,6,37:18.6
-4,6,37:18.6
-3,6,37:18.6
-2,6,37:18.6
-1,6,37:18.6
0,6,37:18.6
1,6,37:18.6
2,6,37:18.6
3,6,37:18.6
4,6,37:18.6
5,6,37:18.6
6,6,37:18.6
7,6,37:18.6
8,6,37:18.6
9,6,37:18.6
-6,7,37:18.6
-5,7,37:18.6
4,7,37:18.6
8,7,37:18.6
-5,8,37:18.6
-4,8,37:18.6
3,8,37:18.6
-4,9,37:18.6
-3,9,37:18.6
-2,9,37:18.6
-1,9,37:18.6
1,9,37:18.6
2,9,37:18.6
-4,10,37:18.6
-3,10,37:18.6
-2,10,37:18.6
-1,10,37:18.6
0,10,37:18.6
1,10,37:18.6
2,10,37:18.6
3,10,37:18.6
-5,-17,38:18.6
-1,-17,38:18.6
0,-17,38:18.6
-4,-16,38:18.6
-3,-16,38:18.6
-2,-16,38:18.6
-1,-16,38:18.6
-5,-15,38:18.6
0,-15,38:18.6
1,-15,38:18.6
-6,-14,38:18.6
1,-14,38:18.6
2,-14,38:18.6
6,-14,38:18.6
7,-14,38:18.6
-10,-13,38:18.6
-7,-13,38:18.6
-6,-13,38:18.6
-5,-13,38:18.6
-4,-13,38:18.6
-3,-13,38:18.6
-2,-13,38:18.6
-1,-13,38:18.6
0,-13,38:18.6
1,-13,38:18.6
2,-13,38:18.6
3,-13,38:18.6
4,-13,38:18.6
5,-13,38:18.6
6,-13,38:18.6
7,-13,38:18.6
8,-13,38:18.6
9,-13,38:18.6
-12,-12,38:18.6
-11,-12,38:18.6
-10,-12,38:18.6
-9,-12,38:18.6
-8,-12,38:18.6
-7,-12,38:18.6
-6,-12,38:18.6
-5,-12,38:18.6
-4,-12,38:18.6
-3,-12,38:18.6
-2,-12,38:18.6
4,-12,38:18.6
5,-12,38:18.6
7,-12,38:18.6
-10,-11,38:18.6
-9,-11,38:18.6
-8,-11,38:18.6
5,-11,38:18.6
6,-11,38:18.6
7,-11,38:18.6
-10,-10,38:18.6
-9,-10,38:18.6
7,-10,38:18.6
8,-10,38:18.6
11,-10,38:18.6
-11,-9,38:18.6
-10,-9,38:18.6
7,-9,38:18.6
8,-9,38:18.6
9,-9,38:18.6
-12,-8,38:18.6
-11,-8,38:18.6
-10,-8,38:18.6
7,-8,38:18.6
9,-8,38:18.6
11,-8,38:18.6
-15,-7,38:18.6
-14,-7,38:18.6
-12,-7,38:18.6
-10,-7,38:18.6
7,-7,38:18.6
10,-7,38:18.6
11,-7,38:18.6
-14,-6,38:18.6
-13,-6,38:18.6
-10,-6,38:18.6
7,-6,38:18.6
10,-6,38:18.6
11,-6,38:18.6
-14,-5,38:18.6
-13,-5,38:18.6
7,-5,38:18.6
11,-5,38:18.6
-14,-4,38:18.6
-13,-4,38:18.6
-10,-4,38:18.6
7,-4,38:18.6
11,-4,38:18.6
-14,-3,38:18.6
-13,-3,38:18.6
-10,-3,38:18.6
7,-3,38:18.6
8,-3,38:18.6
10,-3,38:18.6
11,-3,38:18.6
-14,-2,38:18.6
-13,-2,38:18.6
-10,-2,38:18.6
7,-2,38:18.6
8,-2,38:18.6
10,-2,38:18.6
11,-2,38:18.6
12,-2,38:18.6
-14,-1,38:18.6
-13,-1,38:18.6
-10,-1,38:18.6
7,-1,38:18.6
8,-1,38:18.6
10,-1,38:18.6
12,-1,38:18.6
-14,0,38:18.6
-10,0,38:18.6
7,0,38:18.6
8,0,38:18.6
9,0,38:18.6
12,0,38:18.6
-14,1,38:18.6
-12,1,38:18.6
-10,1,38:18.6
8,1,38:18.6
9,1,38:18.6
-11,2,38:18.6
-10,2,38:18.6
7,2,38:18.6
8,2,38:18.6
-10,3,38:18.6
-9,3,38:18.6
7,3,38:18.6
8,3,38:18.6
-10,4,38:18.6
-9,4,38:18.6
-8,4,38:18.6
6,4,38:18.6
8,4,38:18.6
-12,5,38:18.6
-11,5,38:18.6
-10,5,38:18.6
-9,5,38:18.6
-8,5,38:18.6
-7,5,38:18.6
-6,5,38:18.6
-5,5,38:18.6
-4,5,38:18.6
-3,5,38:18.6
-2,5,38:18.6
0,5,38:18.6
1,5,38:18.6
2,5,38:18.6
3,5,38:18.6
4,5,38:18.6
5,5,38:18.6
6,5,38:18.6
7,5,38:18.6
8,5,38:18.6
9,5,38:18.6
-11,6,38:18.6
-10,6,38:18.6
-9,6,38:18.6
-8,6,38:18.6
-7,6,38:18.6
-6,6,38:18.6
4,6,38:18.6
5,6,38:18.6
8,6,38:18.6
-10,7,38:18.6
-6,7,38:18.6
-5,7,38:18.6
4,7,38:18.6
8,7,38:18.6
-4,8,38:18.6
3,8,38:18.6
-3,9,38:18.6
-2,9,38:18.6
2,9,38:18.6
-2,10,38:18.6
-1,10,38:18.6
0,10,38:18.6
1,10,38:18.6
2,10,38:18.6
3,10,38:18.6
-2,11,38:18.6
2,11,38:18.6
-5,-17,39:18.6
-4,-17,39:18.6
-3,-17,39:18.6
-2,-17,39:18.6
-1,-17,39:18.6
-4,-16,39:18.6
-3,-16,39:18.6
-5,-15,39:18.6
1,-15,39:18.6
-10,-14,39:18.6
-6,-14,39:18.6
-5,-14,39:18.6
1,-14,39:18.6
2,-14,39:18.6
6,-14,39:18.6
-10,-13,39:18.6
-7,-13,39:18.6
-6,-13,39:18.6
2,-13,39:18.6
3,-13,39:18.6
4,-13,39:18.6
5,-13,39:18.6
6,-13,39:18.6
7,-13,39:18.6
8,-13,39:18.6
-10,-12,39:18.6
-9,-12,39:18.6
-8,-12,39:18.6
-7,-12,39:18.6
-6,-12,39:18.6
-5,-12,39:18.6
-4,-12,39:18.6
-3,-12,39:18.6
-2,-12,39:18.6
-1,-12,39:18.6
0,-12,39:18.6
1,-12,39:18.6
2,-12,39:18.6
3,-12,39:18.6
4,-12,39:18.6
5,-12,39:18.6
6,-12,39:18.6
-12,-11,39:18.6
-11,-11,39:18.6
-10,-11,39:18.6
-9,-11,39:18.6
-8,-11,39:18.6
5,-11,39:18.6
6,-11,39:18.6
-10,-10,39:18.6
-9,-10,39:18.6
6,-10,39:18.6
7,-10,39:18.6
-10,-9,39:18.6
6,-9,39:18.6
7,-9,39:18.6
8,-9,39:18.6
-11,-8,39:18.6
-10,-8,39:18.6
6,-8,39:18.6
7,-8,39:18.6
9,-8,39:18.6
11,-8,39:18.6
-12,-7,39:18.6
-10,-7,39:18.6
6,-7,39:18.6
7,-7,39:18.6
10,-7,39:18.6
11,-7,39:18.6
-15,-6,39:18.6
-14,-6,39:18.6
-13,-6,39:18.6
-10,-6,39:18.6
7,-6,39:18.6
10,-6,39:18.6
11,-6,39:18.6
-14,-5,39:18.6
-13,-5,39:18.6
7,-5,39:18.6
11,-5,39:18.6
-14,-4,39:18.6
-10,-4,39:18.6
7,-4,39:18.6
11,-4,39:18.6
-14,-3,39:18.6
-10,-3,39:18.6
7,-3,39:18.6
11,-3,39:18.6
-14,-2,39:18.6
-10,-2,39:18.6
7,-2,39:18.6
10,-2,39:18.6
12,-2,39:18.6
-14,-1,39:18.6
-13,-1,39:18.6
-10,-1,39:18.6
7,-1,39:18.6
10,-1,39:18.6
12,-1,39:18.6
-13,0,39:18.6
-12,0,39:18.6
-10,0,39:18.6
7,0,39:18.6
9,0,39:18.6
12,0,39:18.6
-12,1,39:18.6
-11,1,39:18.6
-10,1,39:18.6
7,1,39:18.6
8,1,39:18.6
9,1,39:18.6
-11,2,39:18.6
-10,2,39:18.6
7,2,39:18.6
8,2,39:18.6
-10,3,39:18.6
-9,3,39:18.6
7,3,39:18.6
-10,4,39:18.6
-9,4,39:18.6
-8,4,39:18.6
4,4,39:18.6
6,4,39:18.6
7,4,39:18.6
8,4,39:18.6
-11,5,39:18.6
-10,5,39:18.6
-9,5,39:18.6
-8,5,39:18.6
-7,5,39:18.6
-6,5,39:18.6
-5,5,39:18.6
-4,5,39:18.6
-3,5,39:18.6
-2,5,39:18.6
0,5,39:18.6
1,5,39:18.6
2,5,39:18.6
3,5,39:18.6
4,5,39:18.6
5,5,39:18.6
6,5,39:18.6
7,5,39:18.6
8,5,39:18.6
-10,6,39:18.6
-9,6,39:18.6
-6,6,39:18.6
4,6,39:18.6
5,6,39:18.6
7,6,39:18.6
-5,7,39:18.6
-4,7,39:18.6
3,7,39:18.6
4,7,39:18.6
-4,8,39:18.6
3,8,39:18.6
2,9,39:18.6
0,10,39:18.6
1,10,39:18.6
-2,11,39:18.6
-1,11,39:18.6
0,11,39:18.6
1,11,39:18.6
2,11,39:18.6
-4,-17,40:18.6
-3,-17,40:18.6
-5,-15,40:18.6
-6,-14,40:18.6
1,-14,40:18.6
5,-14,40:18.6
-7,-13,40:18.6
-6,-13,40:18.6
2,-13,40:18.6
3,-13,40:18.6
6,-13,40:18.6
-9,-12,40:18.6
-7,-12,40:18.6
-4,-12,40:18.6
-3,-12,40:18.6
-2,-12,40:18.6
-1,-12,40:18.6
0,-12,40:18.6
1,-12,40:18.6
2,-12,40:18.6
3,-12,40:18.6
4,-12,40:18.6
5,-12,40:18.6
6,-12,40:18.6
7,-12,40:18.6
8,-12,40:18.6
-12,-11,40:18.6
-11,-11,40:18.6
-10,-11,40:18.6
-9,-11,40:18.6
-8,-11,40:18.6
-7,-11,40:18.6
-6,-11,40:18.6
-5,-11,40:18.6
-4,-11,40:18.6
-3,-11,40:18.6
-2,-11,40:18.6
-1,-11,40:18.6
4,-11,40:18.6
5,-11,40:18.6
6,-11,40:18.6
-12,-10,40:18.6
-9,-10,40:18.6
6,-10,40:18.6
7,-10,40:18.6
-10,-9,40:18.6
-9,-9,40:18.6
6,-9,40:18.6
7,-9,40:18.6
8,-9,40:18.6
-11,-8,40:18.6
-9,-8,40:18.6
6,-8,40:18.6
8,-8,40:18.6
9,-8,40:18.6
-12,-7,40:18.6
-9,-7,40:18.6
6,-7,40:18.6
10,-7,40:18.6
11,-7,40:18.6
-15,-6,40:18.6
-13,-6,40:18.6
-9,-6,40:18.6
6,-6,40:18.6
10,-6,40:18.6
11,-6,40:18.6
-14,-5,40:18.6
-9,-5,40:18.6
6,-5,40:18.6
11,-5,40:18.6
-14,-4,40:18.6
-9,-4,40:18.6
6,-4,40:18.6
11,-4,40:18.6
-14,-3,40:18.6
-9,-3,40:18.6
6,-3,40:18.6
11,-3,40:18.6
-14,-2,40:18.6
-9,-2,40:18.6
6,-2,40:18.6
7,-2,40:18.6
10,-2,40:18.6
12,-2,40:18.6
-14,-1,40:18.6
-13,-1,40:18.6
-9,-1,40:18.6
6,-1,40:18.6
7,-1,40:18.6
9,-1,40:18.6
10,-1,40:18.6
12,-1,40:18.6
-13,0,40:18.6
-12,0,40:18.6
-9,0,40:18.6
6,0,40:18.6
7,0,40:18.6
9,0,40:18.6
-11,1,40:18.6
-9,1,40:18.6
6,1,40:18.6
7,1,40:18.6
8,1,40:18.6
-10,2,40:18.6
-9,2,40:18.6
7,2,40:18.6
8,2,40:18.6
-9,3,40:18.6
-8,3,40:18.6
6,3,40:18.6
7,3,40:18.6
-11,4,40:18.6
-10,4,40:18.6
-9,4,40:18.6
-8,4,40:18.6
-7,4,40:18.6
-6,4,40:18.6
-5,4,40:18.6
-4,4,40:18.6
-3,4,40:18.6
-2,4,40:18.6
-1,4,40:18.6
0,4,40:18.6
1,4,40:18.6
2,4,40:18.6
3,4,40:18.6
4,4,40:18.6
5,4,40:18.6
6,4,40:18.6
7,4,40:18.6
8,4,40:18.6
9,4,40:18.6
-10,5,40:18.6
-9,5,40:18.6
-8,5,40:18.6
-7,5,40:18.6
-6,5,40:18.6
5,5,40:18.6
7,5,40:18.6
-9,6,40:18.6
-6,6,40:18.6
-5,6,40:18.6
4,6,40:18.6
7,6,40:18.6
-9,7,40:18.6
3,7,40:18.6
4,7,40:18.6
3,8,40:18.6
2,9,40:18.6
0,11,40:18.6
1,11,40:18.6
5,-14,41:18.6
5,-13,41:18.6
-9,-12,41:18.6
3,-12,41:18.6
4,-12,41:18.6
5,-12,41:18.6
6,-12,41:18.6
-9,-11,41:18.6
-8,-11,41:18.6
-7,-11,41:18.6
-6,-11,41:18.6
-5,-11,41:18.6
-4,-11,41:18.6
-3,-11,41:18.6
-2,-11,41:18.6
-1,-11,41:18.6
0,-11,41:18.6
1,-11,41:18.6
2,-11,41:18.6
3,-11,41:18.6
4,-11,41:18.6
5,-11,41:18.6
6,-11,41:18.6
7,-11,41:18.6
-12,-10,41:18.6
-11,-10,41:18.6
-10,-10,41:18.6
-9,-10,41:18.6
-8,-10,41:18.6
-7,-10,41:18.6
5,-10,41:18.6
6,-10,41:18.6
-10,-9,41:18.6
-9,-9,41:18.6
5,-9,41:18.6
6,-9,41:18.6
7,-9,41:18.6
-10,-8,41:18.6
-9,-8,41:18.6
5,-8,41:18.6
6,-8,41:18.6
8,-8,41:18.6
9,-8,41:18.6
-12,-7,41:18.6
-9,-7,41:18.6
5,-7,41:18.6
6,-7,41:18.6
9,-7,41:18.6
10,-7,41:18.6
-9,-6,41:18.6
5,-6,41:18.6
6,-6,41:18.6
10,-6,41:18.6
11,-6,41:18.6
-15,-5,41:18.6
-9,-5,41:18.6
6,-5,41:18.6
11,-5,41:18.6
-14,-4,41:18.6
-9,-4,41:18.6
6,-4,41:18.6
11,-4,41:18.6
-14,-3,41:18.6
-9,-3,41:18.6
6,-3,41:18.6
11,-3,41:18.6
12,-3,41:18.6
-14,-2,41:18.6
-9,-2,41:18.6
6,-2,41:18.6
12,-2,41:18.6
-13,-1,41:18.6
-12,-1,41:18.6
-9,-1,41:18.6
6,-1,41:18.6
9,-1,41:18.6
10,-1,41:18.6
-12,0,41:18.6
-9,0,41:18.6
6,0,41:18.6
9,0,41:18.6
-11,1,41:18.6
-9,1,41:18.6
6,1,41:18.6
8,1,41:18.6
-9,2,41:18.6
-8,2,41:18.6
6,2,41:18.6
7,2,41:18.6
-9,3,41:18.6
-8,3,41:18.6
3,3,41:18.6
4,3,41:18.6
5,3,41:18.6
6,3,41:18.6
7,3,41:18.6
8,3,41:18.6
9,3,41:18.6
-10,4,41:18.6
-9,4,41:18.6
-8,4,41:18.6
-7,4,41:18.6
-6,4,41:18.6
-5,4,41:18.6
-4,4,41:18.6
-3,4,41:18.6
-2,4,41:18.6
-1,4,41:18.6
0,4,41:18.6
1,4,41:18.6
2,4,41:18.6
3,4,41:18.6
4,4,41:18.6
5,4,41:18.6
6,4,41:18.6
7,4,41:18.6
-9,5,41:18.6
-8,5,41:18.6
-6,5,41:18.6
5,5,41:18.6
6,5,41:18.6
-8,6,41:18.6
-8,7,41:18.6
4,-14,42:18.6
4,-13,42:18.6
5,-13,42:18.6
-8,-12,42:18.6
4,-12,42:18.6
5,-12,42:18.6
-8,-11,42:18.6
-3,-11,42:18.6
-2,-11,42:18.6
-1,-11,42:18.6
0,-11,42:18.6
1,-11,42:18.6
2,-11,42:18.6
3,-11,42:18.6
4,-11,42:18.6
5,-11,42:18.6
6,-11,42:18.6
-11,-10,42:18.6
-10,-10,42:18.6
-9,-10,42:18.6
-8,-10,42:18.6
-7,-10,42:18.6
-6,-10,42:18.6
-5,-10,42:18.6
-4,-10,42:18.6
-3,-10,42:18.6
-1,-10,42:18.6
0,-10,42:18.6
5,-10,42:18.6
6,-10,42:18.6
-8,-9,42:18.6
5,-9,42:18.6
6,-9,42:18.6
-8,-8,42:18.6
5,-8,42:18.6
8,-8,42:18.6
-8,-7,42:18.6
5,-7,42:18.6
9,-7,42:18.6
10,-7,42:18.6
-8,-6,42:18.6
5,-6,42:18.6
10,-6,42:18.6
11,-6,42:18.6
-8,-5,42:18.6
5,-5,42:18.6
11,-5,42:18.6
-8,-4,42:18.6
5,-4,42:18.6
11,-4,42:18.6
-8,-3,42:18.6
5,-3,42:18.6
12,-3,42:18.6
-8,-2,42:18.6
5,-2,42:18.6
-8,-1,42:18.6
5,-1,42:18.6
6,-1,42:18.6
9,-1,42:18.6
-8,0,42:18.6
5,0,42:18.6
6,0,42:18.6
9,0,42:18.6
-8,1,42:18.6
5,1,42:18.6
6,1,42:18.6
-8,2,42:18.6
5,2,42:18.6
6,2,42:18.6
7,2,42:18.6
-10,3,42:18.6
-9,3,42:18.6
-8,3,42:18.6
-7,3,42:18.6
-6,3,42:18.6
-5,3,42:18.6
-4,3,42:18.6
-3,3,42:18.6
-2,3,42:18.6
-1,3,42:18.6
0,3,42:18.6
1,3,42:18.6
2,3,42:18.6
3,3,42:18.6
4,3,42:18.6
5,3,42:18.6
6,3,42:18.6
7,3,42:18.6
8,3,42:18.6
9,3,42:18.6
-8,4,42:18.6
-7,4,42:18.6
-6,4,42:18.6
5,4,42:18.6
6,4,42:18.6
-8,5,42:18.6
5,5,42:18.6
6,5,42:18.6
-8,6,42:18.6
-8,7,42:18.6
4,-13,43:18.6
-8,-12,43:18.6
4,-12,43:18.6
-8,-11,43:18.6
4,-11,43:18.6
5,-11,43:18.6
-8,-10,43:18.6
-7,-10,43:18.6
-6,-10,43:18.6
-5,-10,43:18.6
-4,-10,43:18.6
-3,-10,43:18.6
-1,-10,43:18.6
0,-10,43:18.6
1,-10,43:18.6
2,-10,43:18.6
3,-10,43:18.6
4,-10,43:18.6
5,-10,43:18.6
6,-10,43:18.6
-12,-9,43:18.6
-11,-9,43:18.6
-10,-9,43:18.6
-9,-9,43:18.6
-8,-9,43:18.6
-7,-9,43:18.6
-6,-9,43:18.6
4,-9,43:18.6
5,-9,43:18.6
-8,-8,43:18.6
4,-8,43:18.6
5,-8,43:18.6
-8,-7,43:18.6
4,-7,43:18.6
5,-7,43:18.6
-8,-6,43:18.6
4,-6,43:18.6
5,-6,43:18.6
-8,-5,43:18.6
4,-5,43:18.6
5,-5,43:18.6
11,-5,43:18.6
-8,-4,43:18.6
5,-4,43:18.6
11,-4,43:18.6
-8,-3,43:18.6
5,-3,43:18.6
12,-3,43:18.6
-8,-2,43:18.6
5,-2,43:18.6
-8,-1,43:18.6
5,-1,43:18.6
-8,0,43:18.6
5,0,43:18.6
-8,1,43:18.6
5,1,43:18.6
-8,2,43:18.6
2,2,43:18.6
3,2,43:18.6
4,2,43:18.6
5,2,43:18.6
6,2,43:18.6
7,2,43:18.6
8,2,43:18.6
-10,3,43:18.6
-9,3,43:18.6
-8,3,43:18.6
-7,3,43:18.6
-6,3,43:18.6
-5,3,43:18.6
-4,3,43:18.6
-3,3,43:18.6
-2,3,43:18.6
-1,3,43:18.6
0,3,43:18.6
1,3,43:18.6
2,3,43:18.6
3,3,43:18.6
4,3,43:18.6
5,3,43:18.6
6,3,43:18.6
-8,4,43:18.6
-7,4,43:18.6
5,4,43:18.6
-7,5,43:18.6
5,5,43:18.6
-7,6,43:18.6
3,-14,44:18.6
-7,-13,44:18.6
3,-13,44:18.6
-7,-12,44:18.6
3,-12,44:18.6
4,-12,44:18.6
-7,-11,44:18.6
3,-11,44:18.6
4,-11,44:18.6
-7,-10,44:18.6
-1,-10,44:18.6
0,-10,44:18.6
1,-10,44:18.6
2,-10,44:18.6
3,-10,44:18.6
4,-10,44:18.6
5,-10,44:18.6
6,-10,44:18.6
-11,-9,44:18.6
-10,-9,44:18.6
-9,-9,44:18.6
-8,-9,44:18.6
-7,-9,44:18.6
-6,-9,44:18.6
-5,-9,44:18.6
-4,-9,44:18.6
-3,-9,44:18.6
-2,-9,44:18.6
-1,-9,44:18.6
0,-9,44:18.6
1,-9,44:18.6
4,-9,44:18.6
6,-9,44:18.6
7,-9,44:18.6
-11,-8,44:18.6
-10,-8,44:18.6
-7,-8,44:18.6
4,-8,44:18.6
-7,-7,44:18.6
4,-7,44:18.6
-7,-6,44:18.6
4,-6,44:18.6
-7,-5,44:18.6
4,-5,44:18.6
-7,-4,44:18.6
4,-4,44:18.6
-7,-3,44:18.6
4,-3,44:18.6
-7,-2,44:18.6
4,-2,44:18.6
-7,-1,44:18.6
4,-1,44:18.6
-7,0,44:18.6
4,0,44:18.6
-7,1,44:18.6
5,1,44:18.6
-11,2,44:18.6
-10,2,44:18.6
-9,2,44:18.6
-8,2,44:18.6
-7,2,44:18.6
-6,2,44:18.6
-5,2,44:18.6
-4,2,44:18.6
-3,2,44:18.6
-2,2,44:18.6
-1,2,44:18.6
0,2,44:18.6
1,2,44:18.6
2,2,44:18.6
3,2,44:18.6
4,2,44:18.6
5,2,44:18.6
6,2,44:18.6
7,2,44:18.6
8,2,44:18.6
9,2,44:18.6
-7,3,44:18.6
4,3,44:18.6
5,3,44:18.6
-7,4,44:18.6
4,4,44:18.6
-7,5,44:18.6
4,5,44:18.6
-7,6,44:18.6
4,6,44:18.6
-7,-13,45:18.6
2,-13,45:18.6
3,-13,45:18.6
-7,-12,45:18.6
3,-12,45:18.6
-7,-11,45:18.6
3,-11,45:18.6
-7,-10,45:18.6
3,-10,45:18.6
-7,-9,45:18.6
-6,-9,45:18.6
-5,-9,45:18.6
-4,-9,45:18.6
-3,-9,45:18.6
-2,-9,45:18.6
-1,-9,45:18.6
0,-9,45:18.6
1,-9,45:18.6
2,-9,45:18.6
3,-9,45:18.6
4,-9,45:18.6
5,-9,45:18.6
6,-9,45:18.6
7,-9,45:18.6
-11,-8,45:18.6
-10,-8,45:18.6
-9,-8,45:18.6
-8,-8,45:18.6
-7,-8,45:18.6
-6,-8,45:18.6
-5,-8,45:18.6
3,-8,45:18.6
-7,-7,45:18.6
3,-7,45:18.6
4,-7,45:18.6
-7,-6,45:18.6
3,-6,45:18.6
4,-6,45:18.6
-7,-5,45:18.6
3,-5,45:18.6
4,-5,45:18.6
-7,-4,45:18.6
3,-4,45:18.6
4,-4,45:18.6
-7,-3,45:18.6
4,-3,45:18.6
-7,-2,45:18.6
4,-2,45:18.6
-7,-1,45:18.6
4,-1,45:18.6
-7,0,45:18.6
4,0,45:18.6
-11,1,45:18.6
-10,1,45:18.6
-7,1,45:18.6
2,1,45:18.6
3,1,45:18.6
5,1,45:18.6
6,1,45:18.6
7,1,45:18.6
8,1,45:18.6
-11,2,45:18.6
-10,2,45:18.6
-9,2,45:18.6
-8,2,45:18.6
-7,2,45:18.6
-6,2,45:18.6
-5,2,45:18.6
-4,2,45:18.6
-3,2,45:18.6
-2,2,45:18.6
-1,2,45:18.6
0,2,45:18.6
1,2,45:18.6
2,2,45:18.6
3,2,45:18.6
4,2,45:18.6
5,2,45:18.6
6,2,45:18.6
-7,3,45:18.6
-6,3,45:18.6
4,3,45:18.6
-7,4,45:18.6
-6,4,45:18.6
4,4,45:18.6
-6,5,45:18.6
3,5,45:18.6
4,5,45:18.6
-6,6,45:18.6
2,-13,46:18.6
-6,-12,46:18.6
2,-12,46:18.6
-6,-11,46:18.6
2,-11,46:18.6
3,-11,46:18.6
-6,-10,46:18.6
2,-10,46:18.6
3,-10,46:18.6
-6,-9,46:18.6
-1,-9,46:18.6
0,-9,46:18.6
1,-9,46:18.6
2,-9,46:18.6
3,-9,46:18.6
4,-9,46:18.6
5,-9,46:18.6
-9,-8,46:18.6
-8,-8,46:18.6
-7,-8,46:18.6
-6,-8,46:18.6
-5,-8,46:18.6
-4,-8,46:18.6
-3,-8,46:18.6
-2,-8,46:18.6
-1,-8,46:18.6
0,-8,46:18.6
1,-8,46:18.6
3,-8,46:18.6
4,-8,46:18.6
5,-8,46:18.6
6,-8,46:18.6
7,-8,46:18.6
-11,-7,46:18.6
-10,-7,46:18.6
-9,-7,46:18.6
-6,-7,46:18.6
3,-7,46:18.6
-6,-6,46:18.6
3,-6,46:18.6
-6,-5,46:18.6
3,-5,46:18.6
-6,-4,46:18.6
3,-4,46:18.6
-6,-3,46:18.6
3,-3,46:18.6
-6,-2,46:18.6
3,-2,46:18.6
-6,-1,46:18.6
3,-1,46:18.6
-6,0,46:18.6
3,0,46:18.6
-10,1,46:18.6
-9,1,46:18.6
-8,1,46:18.6
-7,1,46:18.6
-6,1,46:18.6
-5,1,46:18.6
-4,1,46:18.6
-3,1,46:18.6
-2,1,46:18.6
-1,1,46:18.6
0,1,46:18.6
1,1,46:18.6
2,1,46:18.6
3,1,46:18.6
5,1,46:18.6
6,1,46:18.6
7,1,46:18.6
-6,2,46:18.6
3,2,46:18.6
-6,3,46:18.6
3,3,46:18.6
-6,4,46:18.6
3,4,46:18.6
-6,5,46:18.6
3,5,46:18.6
1,-13,47:18.6
-6,-12,47:18.6
1,-12,47:18.6
2,-12,47:18.6
-6,-11,47:18.6
2,-11,47:18.6
-6,-10,47:18.6
2,-10,47:18.6
-6,-9,47:18.6
2,-9,47:18.6
-6,-8,47:18.6
-5,-8,47:18.6
-4,-8,47:18.6
-3,-8,47:18.6
-2,-8,47:18.6
-1,-8,47:18.6
0,-8,47:18.6
1,-8,47:18.6
2,-8,47:18.6
3,-8,47:18.6
4,-8,47:18.6
5,-8,47:18.6
6,-8,47:18.6
7,-8,47:18.6
-11,-7,47:18.6
-10,-7,47:18.6
-9,-7,47:18.6
-8,-7,47:18.6
-7,-7,47:18.6
-6,-7,47:18.6
-5,-7,47:18.6
-4,-7,47:18.6
2,-7,47:18.6
3,-7,47:18.6
6,-7,47:18.6
7,-7,47:18.6
-11,-6,47:18.6
-6,-6,47:18.6
2,-6,47:18.6
3,-6,47:18.6
-6,-5,47:18.6
2,-5,47:18.6
3,-5,47:18.6
-6,-4,47:18.6
2,-4,47:18.6
3,-4,47:18.6
-6,-3,47:18.6
3,-3,47:18.6
-6,-2,47:18.6
3,-2,47:18.6
-6,-1,47:18.6
3,-1,47:18.6
-11,0,47:18.6
-10,0,47:18.6
-9,0,47:18.6
-6,0,47:18.6
2,0,47:18.6
3,0,47:18.6
4,0,47:18.6
5,0,47:18.6
6,0,47:18.6
7,0,47:18.6
8,0,47:18.6
-10,1,47:18.6
-9,1,47:18.6
-8,1,47:18.6
-7,1,47:18.6
-6,1,47:18.6
-5,1,47:18.6
-4,1,47:18.6
-3,1,47:18.6
-2,1,47:18.6
-1,1,47:18.6
0,1,47:18.6
1,1,47:18.6
2,1,47:18.6
3,1,47:18.6
5,1,47:18.6
-6,2,47:18.6
-5,2,47:18.6
3,2,47:18.6
-6,3,47:18.6
-5,3,47:18.6
2,3,47:18.6
3,3,47:18.6
-5,4,47:18.6
2,4,47:18.6
3,4,47:18.6
-5,5,47:18.6
2,5,47:18.6
-5,6,47:18.6
2,6,47:18.6
1,-13,48:18.6
-5,-12,48:18.6
1,-12,48:18.6
-5,-11,48:18.6
1,-11,48:18.6
-5,-10,48:18.6
1,-10,48:18.6
2,-10,48:18.6
-5,-9,48:18.6
1,-9,48:18.6
2,-9,48:18.6
-5,-8,48:18.6
0,-8,48:18.6
1,-8,48:18.6
2,-8,48:18.6
3,-8,48:18.6
-8,-7,48:18.6
-7,-7,48:18.6
-6,-7,48:18.6
-5,-7,48:18.6
-4,-7,48:18.6
-3,-7,48:18.6
-2,-7,48:18.6
-1,-7,48:18.6
0,-7,48:18.6
1,-7,48:18.6
2,-7,48:18.6
3,-7,48:18.6
4,-7,48:18.6
5,-7,48:18.6
6,-7,48:18.6
7,-7,48:18.6
-9,-6,48:18.6
-8,-6,48:18.6
-5,-6,48:18.6
2,-6,48:18.6
-5,-5,48:18.6
2,-5,48:18.6
-5,-4,48:18.6
2,-4,48:18.6
-5,-3,48:18.6
2,-3,48:18.6
-5,-2,48:18.6
2,-2,48:18.6
-5,-1,48:18.6
2,-1,48:18.6
-11,0,48:18.6
-10,0,48:18.6
-9,0,48:18.6
-8,0,48:18.6
-7,0,48:18.6
-6,0,48:18.6
-5,0,48:18.6
-4,0,48:18.6
-3,0,48:18.6
-2,0,48:18.6
-1,0,48:18.6
0,0,48:18.6
1,0,48:18.6
2,0,48:18.6
3,0,48:18.6
4,0,48:18.6
5,0,48:18.6
6,0,48:18.6
7,0,48:18.6
-5,1,48:18.6
2,1,48:18.6
-5,2,48:18.6
2,2,48:18.6
-5,3,48:18.6
2,3,48:18.6
-5,4,48:18.6
2,4,48:18.6
-5,5,48:18.6
2,5,48:18.6
-5,-12,49:18.6
-5,-11,49:18.6
0,-11,49:18.6
1,-11,49:18.6
-5,-10,49:18.6
1,-10,49:18.6
-5,-9,49:18.6
1,-9,49:18.6
-5,-8,49:18.6
1,-8,49:18.6
-5,-7,49:18.6
-4,-7,49:18.6
-3,-7,49:18.6
-2,-7,49:18.6
-1,-7,49:18.6
0,-7,49:18.6
1,-7,49:18.6
2,-7,49:18.6
3,-7,49:18.6
4,-7,49:18.6
5,-7,49:18.6
6,-7,49:18.6
-9,-6,49:18.6
-8,-6,49:18.6
-7,-6,49:18.6
-6,-6,49:18.6
-5,-6,49:18.6
-4,-6,49:18.6
-3,-6,49:18.6
1,-6,49:18.6
2,-6,49:18.6
4,-6,49:18.6
5,-6,49:18.6
6,-6,49:18.6
-5,-5,49:18.6
1,-5,49:18.6
2,-5,49:18.6
-5,-4,49:18.6
1,-4,49:18.6
2,-4,49:18.6
-5,-3,49:18.6
1,-3,49:18.6
2,-3,49:18.6
-5,-2,49:18.6
1,-2,49:18.6
2,-2,49:18.6
-10,-1,49:18.6
-9,-1,49:18.6
-8,-1,49:18.6
-7,-1,49:18.6
-5,-1,49:18.6
1,-1,49:18.6
2,-1,49:18.6
3,-1,49:18.6
4,-1,49:18.6
5,-1,49:18.6
6,-1,49:18.6
-9,0,49:18.6
-8,0,49:18.6
-7,0,49:18.6
-6,0,49:18.6
-5,0,49:18.6
-4,0,49:18.6
-3,0,49:18.6
-2,0,49:18.6
-1,0,49:18.6
0,0,49:18.6
1,0,49:18.6
2,0,49:18.6
3,0,49:18.6
4,0,49:18.6
-5,1,49:18.6
-4,1,49:18.6
1,1,49:18.6
2,1,49:18.6
-5,2,49:18.6
-4,2,49:18.6
1,2,49:18.6
2,2,49:18.6
-4,3,49:18.6
1,3,49:18.6
-4,4,49:18.6
1,4,49:18.6
1,5,49:18.6
-4,-11,50:18.6
0,-11,50:18.6
-4,-10,50:18.6
0,-10,50:18.6
-4,-9,50:18.6
0,-9,50:18.6
-4,-8,50:18.6
0,-8,50:18.6
1,-8,50:18.6
-4,-7,50:18.6
0,-7,50:18.6
1,-7,50:18.6
-7,-6,50:18.6
-6,-6,50:18.6
-5,-6,50:18.6
-4,-6,50:18.6
-3,-6,50:18.6
-2,-6,50:18.6
-1,-6,50:18.6
0,-6,50:18.6
1,-6,50:18.6
2,-6,50:18.6
3,-6,50:18.6
4,-6,50:18.6
5,-6,50:18.6
6,-6,50:18.6
-8,-5,50:18.6
-7,-5,50:18.6
-4,-5,50:18.6
1,-5,50:18.6
-4,-4,50:18.6
1,-4,50:18.6
-4,-3,50:18.6
1,-3,50:18.6
-4,-2,50:18.6
1,-2,50:18.6
-9,-1,50:18.6
-8,-1,50:18.6
-7,-1,50:18.6
-6,-1,50:18.6
-5,-1,50:18.6
-4,-1,50:18.6
-3,-1,50:18.6
-2,-1,50:18.6
-1,-1,50:18.6
0,-1,50:18.6
1,-1,50:18.6
2,-1,50:18.6
3,-1,50:18.6
4,-1,50:18.6
5,-1,50:18.6
-4,0,50:18.6
1,0,50:18.6
-4,1,50:18.6
1,1,50:18.6
-4,2,50:18.6
1,2,50:18.6
-4,3,50:18.6
1,3,50:18.6
1,4,50:18.6
-4,-10,51:18.6
0,-10,51:18.6
-4,-9,51:18.6
0,-9,51:18.6
-4,-8,51:18.6
0,-8,51:18.6
-4,-7,51:18.6
0,-7,51:18.6
-4,-6,51:18.6
-3,-6,51:18.6
-2,-6,51:18.6
-1,-6,51:18.6
0,-6,51:18.6
1,-6,51:18.6
2,-6,51:18.6
3,-6,51:18.6
-8,-5,51:18.6
-7,-5,51:18.6
-6,-5,51:18.6
-5,-5,51:18.6
-4,-5,51:18.6
-3,-5,51:18.6
-2,-5,51:18.6
0,-5,51:18.6
1,-5,51:18.6
2,-5,51:18.6
3,-5,51:18.6
4,-5,51:18.6
5,-5,51:18.6
-4,-4,51:18.6
0,-4,51:18.6
1,-4,51:18.6
-4,-3,51:18.6
0,-3,51:18.6
1,-3,51:18.6
-9,-2,51:18.6
-8,-2,51:18.6
-7,-2,51:18.6
-6,-2,51:18.6
-4,-2,51:18.6
0,-2,51:18.6
1,-2,51:18.6
2,-2,51:18.6
3,-2,51:18.6
4,-2,51:18.6
-8,-1,51:18.6
-7,-1,51:18.6
-6,-1,51:18.6
-5,-1,51:18.6
-4,-1,51:18.6
-3,-1,51:18.6
-2,-1,51:18.6
-1,-1,51:18.6
0,-1,51:18.6
1,-1,51:18.6
2,-1,51:18.6
3,-1,51:18.6
-4,0,51:18.6
-3,0,51:18.6
0,0,51:18.6
1,0,51:18.6
-4,1,51:18.6
-3,1,51:18.6
0,1,51:18.6
-3,2,51:18.6
0,2,51:18.6
-3,3,51:18.6
0,3,51:18.6
-3,-10,52:18.6
-3,-9,52:18.6
-3,-8,52:18.6
-1,-8,52:18.6
-3,-7,52:18.6
-1,-7,52:18.6
0,-7,52:18.6
-3,-6,52:18.6
0,-6,52:18.6
-6,-5,52:18.6
-5,-5,52:18.6
-4,-5,52:18.6
-3,-5,52:18.6
-2,-5,52:18.6
-1,-5,52:18.6
0,-5,52:18.6
1,-5,52:18.6
2,-5,52:18.6
3,-5,52:18.6
4,-5,52:18.6
5,-5,52:18.6
-7,-4,52:18.6
-6,-4,52:18.6
-3,-4,52:18.6
0,-4,52:18.6
5,-4,52:18.6
-3,-3,52:18.6
0,-3,52:18.6
-8,-2,52:18.6
-7,-2,52:18.6
-6,-2,52:18.6
-5,-2,52:18.6
-4,-2,52:18.6
-3,-2,52:18.6
-2,-2,52:18.6
-1,-2,52:18.6
0,-2,52:18.6
1,-2,52:18.6
2,-2,52:18.6
3,-2,52:18.6
-3,-1,52:18.6
0,-1,52:18.6
-3,0,52:18.6
0,0,52:18.6
-3,1,52:18.6
0,1,52:18.6
-1,2,52:18.6
0,2,52:18.6
-1,3,52:18.6
0,3,52:18.6
-3,-9,53:18.6
-3,-8,53:18.6
-1,-8,53:18.6
-3,-7,53:18.6
-3,-6,53:18.6
-1,-6,53:18.6
-3,-5,53:18.6
-2,-5,53:18.6
-1,-5,53:18.6
0,-5,53:18.6
1,-5,53:18.6
-4,-4,53:18.6
-3,-4,53:18.6
-2,-4,53:18.6
-1,-4,53:18.6
0,-4,53:18.6
2,-4,53:18.6
3,-4,53:18.6
4,-4,53:18.6
-3,-3,53:18.6
-1,-3,53:18.6
0,-3,53:18.6
-6,-2,53:18.6
-5,-2,53:18.6
-4,-2,53:18.6
-3,-2,53:18.6
-2,-2,53:18.6
-1,-2,53:18.6
0,-2,53:18.6
1,-2,53:18.6
-3,-1,53:18.6
-1,1,53:18.6
-2,-5,54:18.6
-1,-5,54:18.6
-4,-4,54:18.6
-3,-4,54:18.6
-2,-4,54:18.6
-1,-4,54:18.6
0,-4,54:18.6
-3,-3,54:18.6
-2,-3,54:18.6
-1,-3,54:18.6
0,-3,54:18.6
-2,-2,54:18.6
-1,-2,54:18.6
-2,-1,54:18.6
-2,-5,55:18.6
-2,-4,55:18.6
-1,-4,55:18.6
-3,-3,55:18.6
-2,-3,55:18.6
-1,-3,55:18.6
-2,-2,55:18.6
