[META]
version=2.0
spawnOnBlockType=2
spawnSunlight=True
spawnDarkness=True
spawnWater=False
spawnLava=False
underFill=False
randomRotation=True
dig=True
tree=False
branch=False
needsFoundation=True
rarity=100
collisionPercentage=20
spawnElevationMin=0
spawnElevationMax=200
spawnInBiome=Custom
[DATA]
0,-3,-8:17.12
-3,-2,-8:17.12
2,1,-8:17.12
2,2,-8:17.12
-3,-2,-7:17.12
0,-2,-7:17.12
-2,-1,-7:17.12
1,0,-7:17.12
-4,1,-7:17.12
-3,1,-7:17.12
0,1,-7:17.12
2,1,-7:17.12
3,1,-7:17.12
-4,2,-7:17.12
-3,2,-7:17.12
-2,2,-7:17.12
1,2,-7:17.12
-3,3,-7:17.12
-2,-3,-6:17.12
-1,-3,-6:17.12
-2,-2,-6:17.12
-1,-2,-6:17.12
-1,-1,-6:17.12
0,0,-6:17.12
1,0,-6:17.12
2,0,-6:17.12
-3,1,-6:17.12
-2,1,-6:17.12
1,1,-6:17.12
-4,2,-6:17.12
-3,2,-6:17.12
-2,2,-6:17.12
-2,-3,-5:17.12
-1,-3,-5:17.12
-3,-2,-5:17.12
-2,-2,-5:17.12
-1,-2,-5:17.12
-2,-1,-5:17.12
-1,-1,-5:17.12
0,-1,-5:17.12
-2,0,-5:17.12
-1,0,-5:17.12
1,0,-5:17.12
2,0,-5:17.12
-4,1,-5:17.12
1,1,-5:17.12
2,1,-5:17.12
-3,2,-5:17.12
-2,2,-5:17.12
1,2,-5:17.12
-3,3,-5:17.12
-2,3,-5:17.12
-2,-3,-4:17.12
-3,-2,-4:17.12
-2,-2,-4:17.12
-1,-2,-4:17.12
-3,-1,-4:17.12
-2,-1,-4:17.12
-1,-1,-4:17.12
0,-1,-4:17.12
1,-1,-4:17.12
-2,0,-4:17.12
-1,0,-4:17.12
1,0,-4:17.12
-3,1,-4:17.12
-2,1,-4:17.12
1,1,-4:17.12
2,1,-4:17.12
-3,2,-4:17.12
-2,2,-4:17.12
-1,2,-4:17.12
0,2,-4:17.12
1,2,-4:17.12
-3,-2,-3:17.12
-1,-2,-3:17.12
-3,-1,-3:17.12
-2,-1,-3:17.12
-1,-1,-3:17.12
1,-1,-3:17.12
-2,0,-3:17.12
-1,0,-3:17.12
0,0,-3:17.12
1,0,-3:17.12
-2,1,-3:17.12
-1,1,-3:17.12
0,1,-3:17.12
1,1,-3:17.12
-2,2,-3:17.12
0,2,-3:17.12
-2,-2,-2:17.12
-1,-2,-2:17.12
0,-2,-2:17.12
-3,-1,-2:17.12
-2,-1,-2:17.12
-1,-1,-2:17.12
0,-1,-2:17.12
1,-1,-2:17.12
-3,0,-2:17.12
-2,0,-2:17.12
-1,0,-2:17.12
0,0,-2:17.12
1,0,-2:17.12
-3,1,-2:17.12
-2,1,-2:17.12
-1,1,-2:17.12
0,1,-2:17.12
1,1,-2:17.12
-2,2,-2:17.12
-1,2,-2:17.12
0,2,-2:17.12
-2,-2,-1:17.12
-1,-2,-1:17.12
0,-2,-1:17.12
-3,-1,-1:17.12
-1,-1,-1:17.12
1,-1,-1:17.12
-3,0,-1:17.12
-2,0,-1:17.12
-1,0,-1:17.12
1,0,-1:17.12
-3,1,-1:17.12
-2,1,-1:17.12
-1,1,-1:17.12
0,1,-1:17.12
1,1,-1:17.12
-2,2,-1:17.12
-1,2,-1:17.12
0,2,-1:17.12
-2,-2,0:17.12
-1,-2,0:17.12
0,-2,0:17.12
-3,-1,0:17.12
-2,-1,0:17.12
0,-1,0:17.12
1,-1,0:17.12
-3,0,0:17.12
1,0,0:17.12
-3,1,0:17.12
-2,1,0:17.12
0,1,0:17.12
-2,2,0:17.12
-1,2,0:17.12
-1,-2,1:17.12
-2,-1,1:17.12
-1,-1,1:17.12
0,-1,1:17.12
3,-1,1:18.12
-3,0,1:17.12
-2,0,1:17.12
0,0,1:17.12
1,0,1:17.12
4,0,1:18.12
5,0,1:18.12
-2,1,1:17.12
-1,1,1:17.12
0,1,1:17.12
3,1,1:18.12
4,1,1:18.12
1,-7,2:18.12
0,-6,2:18.12
1,-5,2:18.12
2,-5,2:18.12
3,-5,2:18.12
1,-4,2:18.12
3,-4,2:18.12
1,-3,2:18.12
2,-3,2:18.12
3,-3,2:18.12
1,-2,2:18.12
2,-2,2:18.12
-7,-1,2:18.12
-2,-1,2:17.12
-1,-1,2:17.12
0,-1,2:17.12
4,-1,2:18.12
5,-1,2:18.12
6,-1,2:18.12
-2,0,2:17.12
0,0,2:17.12
1,0,2:17.12
4,0,2:18.12
5,0,2:18.12
-2,1,2:17.12
-1,1,2:17.12
0,1,2:17.12
4,1,2:18.12
5,1,2:18.12
6,1,2:18.12
-1,2,2:17.12
2,2,2:18.12
3,2,2:18.12
4,2,2:18.12
-1,-7,3:18.12
0,-7,3:18.12
1,-7,3:18.12
2,-7,3:18.12
-1,-6,3:18.12
0,-6,3:18.12
1,-6,3:18.12
2,-6,3:18.12
0,-5,3:18.12
1,-5,3:18.12
2,-5,3:18.12
3,-5,3:18.12
0,-4,3:18.12
1,-4,3:18.12
2,-4,3:18.12
3,-4,3:18.12
4,-4,3:18.12
0,-3,3:18.12
1,-3,3:18.12
2,-3,3:18.12
3,-3,3:18.12
4,-3,3:18.12
-7,-2,3:18.12
-6,-2,3:18.12
0,-2,3:18.12
1,-2,3:18.12
2,-2,3:18.12
4,-2,3:18.12
5,-2,3:18.12
6,-2,3:18.12
-7,-1,3:18.12
-6,-1,3:18.12
-5,-1,3:18.12
-4,-1,3:18.12
-2,-1,3:17.12
-1,-1,3:17.12
0,-1,3:17.12
1,-1,3:17.12
5,-1,3:18.12
6,-1,3:18.12
7,-1,3:18.12
-8,0,3:18.12
-7,0,3:18.12
-6,0,3:18.12
-5,0,3:18.12
-4,0,3:18.12
-3,0,3:18.12
-2,0,3:17.12
0,0,3:17.12
1,0,3:17.12
3,0,3:18.12
4,0,3:18.12
5,0,3:18.12
6,0,3:18.12
-2,1,3:17.12
-1,1,3:17.12
0,1,3:17.12
1,1,3:17.12
2,1,3:18.12
3,1,3:18.12
4,1,3:18.12
5,1,3:18.12
6,1,3:18.12
-1,2,3:17.12
0,2,3:17.12
2,2,3:18.12
3,2,3:18.12
4,2,3:18.12
5,2,3:18.12
6,2,3:18.12
-1,3,3:18.12
2,3,3:18.12
3,3,3:18.12
4,3,3:18.12
5,3,3:18.12
-2,4,3:18.12
-1,4,3:18.12
-2,5,3:18.12
-1,5,3:18.12
-3,6,3:18.12
-2,6,3:18.12
-1,6,3:18.12
0,6,3:18.12
-3,7,3:18.12
-2,7,3:18.12
-1,7,3:18.12
0,7,3:18.12
-2,-8,4:18.12
-2,-7,4:18.12
-1,-7,4:18.12
2,-7,4:18.12
3,-7,4:18.12
-2,-6,4:18.12
-1,-6,4:18.12
0,-6,4:18.12
1,-6,4:18.12
2,-6,4:18.12
3,-6,4:18.12
-2,-5,4:18.12
-1,-5,4:18.12
0,-5,4:18.12
1,-5,4:18.12
2,-5,4:18.12
3,-5,4:18.12
4,-5,4:18.12
5,-5,4:18.12
-8,-4,4:18.12
-7,-4,4:18.12
-2,-4,4:18.12
-1,-4,4:18.12
1,-4,4:18.12
2,-4,4:18.12
3,-4,4:18.12
4,-4,4:18.12
-8,-3,4:18.12
-7,-3,4:18.12
-6,-3,4:18.12
-5,-3,4:18.12
-1,-3,4:18.12
0,-3,4:18.12
1,-3,4:18.12
2,-3,4:18.12
3,-3,4:18.12
4,-3,4:18.12
-6,-2,4:18.12
-5,-2,4:18.12
-4,-2,4:18.12
-3,-2,4:18.12
-1,-2,4:18.12
0,-2,4:18.12
1,-2,4:18.12
2,-2,4:18.12
5,-2,4:18.12
6,-2,4:18.12
-4,-1,4:18.12
-3,-1,4:18.12
-2,-1,4:18.12
-1,-1,4:18.12
0,-1,4:18.12
1,-1,4:17.12
2,-1,4:17.12
3,-1,4:18.12
4,-1,4:18.12
5,-1,4:18.12
6,-1,4:18.12
-7,0,4:18.12
-6,0,4:18.12
-5,0,4:18.12
-4,0,4:18.12
-3,0,4:18.12
-2,0,4:17.12
-1,0,4:18.12
0,0,4:18.12
1,0,4:17.12
2,0,4:18.12
3,0,4:18.12
4,0,4:18.12
5,0,4:18.12
6,0,4:18.12
7,0,4:18.12
-8,1,4:18.12
-7,1,4:18.12
-6,1,4:18.12
-5,1,4:18.12
-4,1,4:18.12
-3,1,4:18.12
-2,1,4:17.12
-1,1,4:17.12
0,1,4:18.12
1,1,4:17.12
2,1,4:18.12
3,1,4:18.12
4,1,4:18.12
5,1,4:18.12
6,1,4:18.12
-2,2,4:18.12
-1,2,4:18.12
0,2,4:17.12
1,2,4:18.12
2,2,4:18.12
3,2,4:18.12
4,2,4:18.12
5,2,4:18.12
6,2,4:18.12
-1,3,4:18.12
0,3,4:18.12
1,3,4:18.12
2,3,4:18.12
3,3,4:18.12
4,3,4:18.12
5,3,4:18.12
6,3,4:18.12
7,3,4:18.12
-3,4,4:18.12
-2,4,4:18.12
0,4,4:18.12
1,4,4:18.12
5,4,4:18.12
6,4,4:18.12
7,4,4:18.12
-3,5,4:18.12
-2,5,4:18.12
0,5,4:18.12
1,5,4:18.12
-4,6,4:18.12
-3,6,4:18.12
0,6,4:18.12
1,6,4:18.12
-4,7,4:18.12
-3,7,4:18.12
0,7,4:18.12
1,7,4:18.12
-4,-8,5:18.12
-3,-8,5:18.12
-4,-7,5:18.12
-3,-7,5:18.12
3,-7,5:18.12
4,-7,5:18.12
-3,-6,5:18.12
-2,-6,5:18.12
0,-6,5:18.12
1,-6,5:18.12
2,-6,5:18.12
3,-6,5:18.12
4,-6,5:18.12
-8,-5,5:18.12
-7,-5,5:18.12
-3,-5,5:18.12
-2,-5,5:18.12
0,-5,5:18.12
1,-5,5:18.12
2,-5,5:18.12
3,-5,5:18.12
5,-5,5:18.12
6,-5,5:18.12
-7,-4,5:18.12
-6,-4,5:18.12
-5,-4,5:18.12
-3,-4,5:18.12
-2,-4,5:18.12
1,-4,5:18.12
2,-4,5:18.12
3,-4,5:18.12
4,-4,5:18.12
5,-4,5:18.12
-5,-3,5:18.12
-4,-3,5:18.12
-3,-3,5:18.12
-2,-3,5:18.12
-1,-3,5:18.12
0,-3,5:17.12
1,-3,5:18.12
2,-3,5:18.12
3,-3,5:18.12
4,-3,5:18.12
6,-3,5:18.12
7,-3,5:18.12
-3,-2,5:18.12
-2,-2,5:18.12
-1,-2,5:18.12
0,-2,5:18.12
1,-2,5:18.12
2,-2,5:18.12
3,-2,5:18.12
4,-2,5:18.12
5,-2,5:18.12
6,-2,5:18.12
7,-2,5:18.12
-4,-1,5:17.12
-3,-1,5:18.12
-2,-1,5:18.12
-1,-1,5:18.12
0,-1,5:18.12
1,-1,5:18.12
2,-1,5:18.12
3,-1,5:18.12
4,-1,5:18.12
5,-1,5:18.12
6,-1,5:18.12
-4,0,5:17.12
-3,0,5:17.12
-2,0,5:17.12
-1,0,5:17.12
0,0,5:17.12
1,0,5:18.12
2,0,5:18.12
4,0,5:18.12
5,0,5:18.12
6,0,5:18.12
7,0,5:18.12
8,0,5:18.12
-3,1,5:18.12
-2,1,5:18.12
-1,1,5:17.12
0,1,5:17.12
1,1,5:18.12
2,1,5:17.12
3,1,5:18.12
4,1,5:18.12
5,1,5:18.12
6,1,5:18.12
7,1,5:18.12
8,1,5:18.12
-8,2,5:18.12
-7,2,5:18.12
-6,2,5:18.12
-5,2,5:18.12
-4,2,5:18.12
-3,2,5:18.12
-2,2,5:18.12
-1,2,5:18.12
0,2,5:18.12
1,2,5:18.12
2,2,5:18.12
3,2,5:18.12
4,2,5:18.12
5,2,5:18.12
6,2,5:18.12
7,2,5:18.12
8,2,5:18.12
-8,3,5:18.12
-4,3,5:17.12
-3,3,5:18.12
-1,3,5:17.12
0,3,5:17.12
1,3,5:18.12
2,3,5:18.12
3,3,5:18.12
4,3,5:18.12
5,3,5:18.12
6,3,5:18.12
7,3,5:18.12
8,3,5:18.12
-4,4,5:18.12
-3,4,5:18.12
0,4,5:17.12
1,4,5:18.12
2,4,5:18.12
4,4,5:18.12
5,4,5:18.12
6,4,5:18.12
7,4,5:18.12
1,5,5:18.12
2,5,5:18.12
6,5,5:18.12
7,5,5:18.12
-5,6,5:18.12
-4,6,5:18.12
1,6,5:18.12
2,6,5:18.12
-5,7,5:18.12
1,7,5:18.12
2,7,5:18.12
2,8,5:18.12
-5,-9,6:18.4
-5,-8,6:18.4
-4,-8,6:18.12
-5,-7,6:18.4
-4,-7,6:18.12
4,-7,6:18.12
5,-7,6:18.12
-8,-6,6:18.4
-7,-6,6:18.4
-6,-6,6:18.4
-5,-6,6:18.4
-4,-6,6:18.12
0,-6,6:18.12
2,-6,6:18.12
3,-6,6:18.12
4,-6,6:18.12
-7,-5,6:18.12
-6,-5,6:18.12
-5,-5,6:18.12
-4,-5,6:18.12
-3,-5,6:18.12
-2,-5,6:18.12
-1,-5,6:18.12
0,-5,6:17.12
1,-5,6:18.12
2,-5,6:18.12
3,-5,6:18.12
4,-5,6:18.12
-5,-4,6:18.12
-4,-4,6:18.12
-3,-4,6:18.12
-2,-4,6:18.12
-1,-4,6:18.12
0,-4,6:18.12
1,-4,6:18.12
2,-4,6:18.12
3,-4,6:18.12
4,-4,6:17.12
5,-4,6:18.12
6,-4,6:18.12
7,-4,6:18.12
-5,-3,6:18.12
-4,-3,6:18.12
-3,-3,6:18.12
-2,-3,6:18.12
-1,-3,6:18.12
0,-3,6:18.12
1,-3,6:18.12
2,-3,6:18.12
3,-3,6:18.12
4,-3,6:18.12
5,-3,6:18.12
6,-3,6:18.12
7,-3,6:18.12
-5,-2,6:18.12
-4,-2,6:18.12
-3,-2,6:18.12
-2,-2,6:18.12
-1,-2,6:18.12
0,-2,6:17.12
1,-2,6:18.12
2,-2,6:18.12
3,-2,6:18.12
4,-2,6:18.12
5,-2,6:18.12
-5,-1,6:18.12
-4,-1,6:18.12
-3,-1,6:18.12
-2,-1,6:18.12
1,-1,6:18.12
2,-1,6:18.12
3,-1,6:18.12
4,-1,6:18.12
5,-1,6:18.12
6,-1,6:18.12
-5,0,6:18.12
-4,0,6:18.12
-3,0,6:17.12
2,0,6:18.12
3,0,6:18.12
4,0,6:18.12
5,0,6:18.12
6,0,6:18.12
7,0,6:18.12
8,0,6:18.12
-5,1,6:18.12
-4,1,6:18.12
-3,1,6:18.12
2,1,6:18.12
3,1,6:18.12
4,1,6:18.12
5,1,6:18.12
7,1,6:18.4
8,1,6:18.12
9,1,6:18.12
-5,2,6:18.12
-4,2,6:18.12
-3,2,6:18.12
-2,2,6:18.12
-1,2,6:18.12
0,2,6:18.12
1,2,6:18.12
2,2,6:18.12
3,2,6:18.12
4,2,6:18.12
5,2,6:18.12
6,2,6:18.12
7,2,6:18.4
8,2,6:18.12
-9,3,6:18.4
-8,3,6:18.12
-7,3,6:18.12
-6,3,6:18.12
-5,3,6:18.12
-4,3,6:18.12
-3,3,6:18.12
-1,3,6:18.12
0,3,6:18.12
1,3,6:18.12
2,3,6:18.12
3,3,6:18.12
4,3,6:18.12
5,3,6:18.12
6,3,6:18.12
7,3,6:18.4
8,3,6:18.12
-9,4,6:18.4
-8,4,6:18.12
-7,4,6:18.12
-6,4,6:18.12
-5,4,6:18.12
-4,4,6:18.12
-3,4,6:18.12
-2,4,6:18.12
-1,4,6:17.12
0,4,6:18.12
1,4,6:18.12
2,4,6:18.12
3,4,6:18.12
4,4,6:18.12
5,4,6:18.12
6,4,6:18.12
7,4,6:18.4
8,4,6:18.12
-5,5,6:18.12
-1,5,6:17.12
0,5,6:17.12
2,5,6:18.12
3,5,6:18.12
4,5,6:18.12
5,5,6:18.12
6,5,6:18.12
-6,6,6:18.12
-5,6,6:18.12
3,6,6:18.12
6,6,6:18.4
7,6,6:18.4
-6,7,6:18.12
3,7,6:18.12
4,7,6:18.12
3,8,6:18.12
4,8,6:18.12
-7,-9,7:18.4
-6,-9,7:18.4
-8,-8,7:18.4
-7,-8,7:18.4
-6,-8,7:18.4
-8,-7,7:18.4
-7,-7,7:18.4
-6,-7,7:18.4
-5,-7,7:18.4
-4,-7,7:18.12
-3,-7,7:18.12
-2,-7,7:18.12
5,-7,7:18.12
6,-7,7:18.12
-7,-6,7:18.4
-6,-6,7:18.4
-5,-6,7:18.4
-4,-6,7:18.12
-3,-6,7:18.12
-2,-6,7:18.12
-1,-6,7:18.12
0,-6,7:18.12
1,-6,7:18.12
2,-6,7:18.12
3,-6,7:18.12
4,-6,7:18.12
5,-6,7:18.12
-7,-5,7:18.12
-6,-5,7:18.12
-5,-5,7:18.12
-4,-5,7:18.12
-3,-5,7:18.12
-2,-5,7:18.12
-1,-5,7:18.12
0,-5,7:18.12
1,-5,7:18.12
2,-5,7:18.12
3,-5,7:18.12
4,-5,7:18.12
5,-5,7:18.12
6,-5,7:18.12
7,-5,7:18.12
-7,-4,7:18.12
-6,-4,7:18.12
-5,-4,7:18.12
-2,-4,7:18.12
-1,-4,7:18.12
0,-4,7:17.12
1,-4,7:18.12
2,-4,7:18.12
3,-4,7:18.12
4,-4,7:18.12
5,-4,7:18.12
6,-4,7:18.12
-7,-3,7:18.12
-6,-3,7:18.12
-5,-3,7:18.12
-3,-3,7:18.12
-2,-3,7:18.12
1,-3,7:18.12
2,-3,7:18.12
4,-3,7:18.12
5,-3,7:18.12
-7,-2,7:18.12
-6,-2,7:18.12
-5,-2,7:18.12
-4,-2,7:18.12
-3,-2,7:18.12
2,-2,7:18.12
3,-2,7:18.12
4,-2,7:18.12
5,-2,7:18.12
-7,-1,7:18.12
-6,-1,7:18.12
-5,-1,7:18.12
-4,-1,7:18.12
3,-1,7:18.12
4,-1,7:18.12
5,-1,7:18.12
6,-1,7:18.12
7,-1,7:18.12
-7,0,7:18.12
-6,0,7:18.12
-5,0,7:18.12
4,0,7:18.12
5,0,7:18.12
6,0,7:18.12
7,0,7:18.12
8,0,7:18.12
-7,1,7:18.12
-6,1,7:18.12
-5,1,7:18.12
-4,1,7:18.12
3,1,7:18.12
4,1,7:18.12
5,1,7:18.12
6,1,7:18.12
7,1,7:18.4
8,1,7:18.4
9,1,7:18.4
-7,2,7:18.12
-6,2,7:18.12
-5,2,7:18.12
-4,2,7:18.12
-3,2,7:18.12
2,2,7:18.12
3,2,7:18.12
4,2,7:18.12
5,2,7:18.12
6,2,7:18.12
7,2,7:18.4
8,2,7:18.12
-7,3,7:18.12
-6,3,7:18.12
-5,3,7:18.12
-4,3,7:18.12
-3,3,7:18.12
1,3,7:18.12
2,3,7:18.12
3,3,7:18.12
4,3,7:18.12
5,3,7:18.12
6,3,7:18.12
7,3,7:18.4
-9,4,7:18.4
-8,4,7:18.12
-7,4,7:18.12
-6,4,7:18.12
-5,4,7:18.12
-4,4,7:18.12
-3,4,7:18.12
-2,4,7:18.12
-1,4,7:17.12
0,4,7:18.12
1,4,7:18.12
2,4,7:18.12
4,4,7:18.12
5,4,7:18.12
6,4,7:18.12
7,4,7:18.4
-9,5,7:18.4
-8,5,7:18.12
-7,5,7:18.12
-6,5,7:18.12
-5,5,7:18.12
-3,5,7:18.12
-2,5,7:18.12
-1,5,7:18.12
0,5,7:18.12
1,5,7:18.12
2,5,7:18.12
3,5,7:18.12
4,5,7:18.12
5,5,7:18.12
-7,6,7:18.12
-6,6,7:18.12
-3,6,7:18.12
-2,6,7:18.12
-1,6,7:17.12
0,6,7:18.12
1,6,7:18.12
2,6,7:18.12
3,6,7:18.12
4,6,7:18.12
6,6,7:18.4
-7,7,7:18.12
4,7,7:18.12
5,7,7:18.4
6,7,7:18.4
7,7,7:18.4
4,8,7:18.12
5,8,7:18.4
-8,-9,8:18.4
-7,-9,8:18.4
-6,-9,8:18.4
-5,-9,8:18.4
-4,-9,8:18.12
-3,-9,8:18.12
-2,-9,8:18.12
-8,-8,8:18.4
-7,-8,8:18.4
-6,-8,8:18.4
-5,-8,8:18.4
-4,-8,8:18.12
-3,-8,8:18.12
-2,-8,8:18.12
-1,-8,8:18.12
0,-8,8:18.12
1,-8,8:18.12
2,-8,8:18.12
7,-8,8:18.12
-8,-7,8:18.4
-7,-7,8:18.4
-5,-7,8:18.4
-4,-7,8:18.12
-3,-7,8:18.12
-2,-7,8:18.12
-1,-7,8:18.12
0,-7,8:18.12
1,-7,8:18.12
2,-7,8:18.12
3,-7,8:18.12
4,-7,8:18.12
5,-7,8:18.12
6,-7,8:18.12
7,-7,8:18.12
-8,-6,8:18.4
-7,-6,8:18.4
-2,-6,8:18.12
-1,-6,8:18.12
0,-6,8:18.12
1,-6,8:18.12
2,-6,8:18.12
3,-6,8:18.12
4,-6,8:18.12
5,-6,8:18.12
6,-6,8:18.12
7,-6,8:18.12
-9,-5,8:18.4
-8,-5,8:18.12
-7,-5,8:18.12
-3,-5,8:18.12
-2,-5,8:18.12
1,-5,8:18.12
2,-5,8:18.12
5,-5,8:18.12
6,-5,8:18.12
7,-5,8:18.12
-9,-4,8:18.4
-8,-4,8:18.12
-7,-4,8:18.12
-4,-4,8:18.12
-3,-4,8:18.12
2,-4,8:18.12
3,-4,8:18.12
6,-4,8:18.12
7,-4,8:18.12
-9,-3,8:18.4
-8,-3,8:18.12
-7,-3,8:18.12
-6,-3,8:18.12
-5,-3,8:18.12
-4,-3,8:18.12
3,-3,8:18.12
4,-3,8:18.12
6,-3,8:18.12
7,-3,8:18.12
-9,-2,8:18.4
-8,-2,8:18.12
-7,-2,8:18.12
-6,-2,8:18.12
-5,-2,8:18.12
4,-2,8:18.12
5,-2,8:18.12
6,-2,8:18.12
7,-2,8:18.12
-9,-1,8:18.4
-8,-1,8:18.12
-7,-1,8:18.12
4,-1,8:18.12
5,-1,8:18.12
6,-1,8:18.12
7,-1,8:18.12
-9,0,8:18.4
-8,0,8:18.12
-7,0,8:18.12
5,0,8:18.12
6,0,8:18.12
7,0,8:18.12
-9,1,8:18.4
-8,1,8:18.12
-7,1,8:18.12
-6,1,8:18.12
5,1,8:18.12
6,1,8:18.12
7,1,8:18.4
8,1,8:18.4
9,1,8:18.4
-9,2,8:18.4
-8,2,8:18.12
-7,2,8:18.12
-6,2,8:18.12
-5,2,8:18.12
3,2,8:18.12
4,2,8:18.12
5,2,8:18.12
6,2,8:18.12
7,2,8:18.4
8,2,8:18.4
-9,3,8:18.4
-8,3,8:18.12
-7,3,8:18.12
-6,3,8:18.12
-5,3,8:18.12
-4,3,8:18.12
3,3,8:18.12
4,3,8:18.12
5,3,8:18.12
6,3,8:18.12
7,3,8:18.4
-9,4,8:18.4
-8,4,8:18.12
-7,4,8:18.12
-5,4,8:18.12
-4,4,8:18.12
-3,4,8:18.12
2,4,8:18.12
3,4,8:18.12
6,4,8:18.12
7,4,8:18.4
-9,5,8:18.4
-8,5,8:18.12
-7,5,8:18.12
-3,5,8:18.12
-2,5,8:18.12
1,5,8:18.12
2,5,8:18.12
5,5,8:18.12
6,5,8:18.12
7,5,8:18.4
-9,6,8:18.4
-8,6,8:18.12
-7,6,8:18.12
-6,6,8:18.12
-5,6,8:18.12
-4,6,8:18.12
-3,6,8:18.12
-2,6,8:18.12
-1,6,8:18.12
0,6,8:18.12
1,6,8:18.12
6,6,8:18.4
-9,7,8:18.4
-8,7,8:18.12
-7,7,8:18.12
-6,7,8:18.12
-5,7,8:18.12
-4,7,8:18.12
-3,7,8:18.12
-2,7,8:18.12
-1,7,8:18.12
0,7,8:18.12
1,7,8:18.12
2,7,8:18.12
3,7,8:18.12
4,7,8:18.12
5,7,8:18.4
6,7,8:18.4
-1,8,8:18.12
0,8,8:18.12
1,8,8:18.12
2,8,8:18.12
3,8,8:18.12
4,8,8:18.12
5,8,8:18.4
6,8,8:18.4
7,8,8:18.4
6,9,8:18.4
-8,-9,9:18.4
-7,-9,9:18.4
-6,-9,9:18.4
-5,-9,9:18.4
-4,-9,9:18.12
-3,-9,9:18.12
-2,-9,9:18.12
-1,-9,9:18.12
0,-9,9:18.12
1,-9,9:18.12
2,-9,9:18.12
-8,-8,9:18.4
-7,-8,9:18.4
-6,-8,9:18.4
-5,-8,9:18.4
-4,-8,9:18.12
-3,-8,9:18.12
-2,-8,9:18.12
-1,-8,9:18.12
0,-8,9:18.12
1,-8,9:18.12
2,-8,9:18.12
3,-8,9:18.12
4,-8,9:18.12
5,-8,9:18.12
6,-8,9:18.12
7,-8,9:18.12
8,-8,9:18.12
-9,-7,9:18.4
-8,-7,9:18.4
-3,-7,9:18.12
-2,-7,9:18.12
1,-7,9:18.12
2,-7,9:18.12
5,-7,9:18.12
6,-7,9:18.12
7,-7,9:18.12
8,-7,9:18.12
-9,-6,9:18.4
-8,-6,9:18.4
-4,-6,9:18.12
-3,-6,9:18.12
2,-6,9:18.12
3,-6,9:18.12
7,-6,9:18.12
8,-6,9:18.12
-9,-5,9:18.4
-8,-5,9:18.12
-5,-5,9:18.12
-4,-5,9:18.12
3,-5,9:18.12
4,-5,9:18.12
7,-5,9:18.12
8,-5,9:18.12
-9,-4,9:18.4
-8,-4,9:18.12
-7,-4,9:18.12
-6,-4,9:18.12
-5,-4,9:18.12
-4,-4,9:18.12
3,-4,9:18.12
4,-4,9:18.12
5,-4,9:18.12
7,-4,9:18.12
8,-4,9:18.12
-9,-3,9:18.4
-8,-3,9:18.12
-7,-3,9:18.12
-6,-3,9:18.12
4,-3,9:18.12
5,-3,9:18.12
6,-3,9:18.12
7,-3,9:18.12
8,-3,9:18.12
-9,-2,9:18.4
-8,-2,9:18.12
5,-2,9:18.12
6,-2,9:18.12
7,-2,9:18.12
8,-2,9:18.12
-9,-1,9:18.4
5,-1,9:18.12
6,-1,9:18.12
7,-1,9:18.12
8,-1,9:18.12
9,-1,9:18.4
-9,0,9:18.4
5,0,9:18.12
6,0,9:18.12
7,0,9:18.12
8,0,9:18.12
9,0,9:18.4
-9,1,9:18.4
-8,1,9:18.12
5,1,9:18.12
6,1,9:18.12
7,1,9:18.4
8,1,9:18.4
9,1,9:18.4
-9,2,9:18.4
-8,2,9:18.12
-7,2,9:18.12
5,2,9:18.12
6,2,9:18.12
7,2,9:18.4
8,2,9:18.4
9,2,9:18.4
-10,3,9:18.4
-9,3,9:18.4
-7,3,9:18.12
-6,3,9:18.12
4,3,9:18.12
5,3,9:18.12
6,3,9:18.12
7,3,9:18.4
8,3,9:18.4
-10,4,9:18.4
-9,4,9:18.4
-6,4,9:18.12
-5,4,9:18.12
3,4,9:18.12
4,4,9:18.12
5,4,9:18.12
7,4,9:18.4
8,4,9:18.4
-10,5,9:18.4
-9,5,9:18.4
-5,5,9:18.12
2,5,9:18.12
3,5,9:18.12
4,5,9:18.12
7,5,9:18.4
8,5,9:18.4
-10,6,9:18.4
-9,6,9:18.4
-4,6,9:18.12
-3,6,9:18.12
1,6,9:18.12
2,6,9:18.12
3,6,9:18.12
7,6,9:18.4
8,6,9:18.4
-10,7,9:18.4
-9,7,9:18.4
-8,7,9:18.12
-7,7,9:18.12
-6,7,9:18.12
-5,7,9:18.12
-4,7,9:18.12
-3,7,9:18.12
-2,7,9:18.12
0,7,9:18.12
1,7,9:18.12
7,7,9:18.4
-8,8,9:18.4
-7,8,9:18.4
-6,8,9:18.4
-5,8,9:18.12
-4,8,9:18.12
-3,8,9:18.12
-2,8,9:18.12
-1,8,9:18.12
0,8,9:18.12
1,8,9:18.12
2,8,9:18.12
3,8,9:18.12
4,8,9:18.12
5,8,9:18.4
7,8,9:18.4
-4,9,9:18.12
-3,9,9:18.12
-2,9,9:18.12
-1,9,9:18.12
0,9,9:18.12
1,9,9:18.12
2,9,9:18.12
3,9,9:18.12
4,9,9:18.12
5,9,9:18.4
6,9,9:18.4
7,9,9:18.4
-7,-9,10:18.4
-6,-9,10:18.4
-5,-9,10:18.4
-4,-9,10:18.12
-3,-9,10:18.12
-2,-9,10:18.12
-1,-9,10:18.12
0,-9,10:18.12
1,-9,10:18.12
-8,-8,10:18.4
-7,-8,10:18.4
-6,-8,10:18.4
-5,-8,10:18.4
-4,-8,10:18.12
-3,-8,10:18.12
-2,-8,10:18.12
-1,-8,10:18.12
0,-8,10:18.12
1,-8,10:18.12
2,-8,10:18.12
3,-8,10:18.12
4,-8,10:18.12
5,-8,10:18.12
6,-8,10:18.12
7,-8,10:18.12
-8,-7,10:18.4
-7,-7,10:18.4
-6,-7,10:18.4
-5,-7,10:18.4
-4,-7,10:18.12
-3,-7,10:18.12
-2,-7,10:18.12
-1,-7,10:18.12
0,-7,10:18.12
1,-7,10:18.12
2,-7,10:18.12
3,-7,10:18.12
4,-7,10:18.12
5,-7,10:18.12
6,-7,10:18.12
7,-7,10:18.12
8,-7,10:18.12
-9,-6,10:18.4
-8,-6,10:18.4
-7,-6,10:18.4
-5,-6,10:18.4
-4,-6,10:18.12
3,-6,10:18.12
4,-6,10:18.12
7,-6,10:18.12
8,-6,10:18.12
-9,-5,10:18.4
-8,-5,10:18.4
-7,-5,10:18.4
-6,-5,10:18.4
-5,-5,10:18.4
4,-5,10:18.12
5,-5,10:18.12
7,-5,10:18.12
8,-5,10:18.12
-9,-4,10:18.4
-8,-4,10:18.4
-7,-4,10:18.12
-6,-4,10:18.12
5,-4,10:18.12
6,-4,10:18.12
7,-4,10:18.12
8,-4,10:18.12
-9,-3,10:18.4
-8,-3,10:18.4
-7,-3,10:18.12
6,-3,10:18.12
7,-3,10:18.12
8,-3,10:18.12
-9,-2,10:18.4
-8,-2,10:18.4
-7,-2,10:18.12
6,-2,10:18.12
7,-2,10:18.12
8,-2,10:18.12
9,-2,10:18.4
-9,-1,10:18.4
-8,-1,10:18.4
6,-1,10:18.12
7,-1,10:18.12
8,-1,10:18.12
9,-1,10:18.4
-9,0,10:18.4
-8,0,10:18.4
6,0,10:18.12
7,0,10:18.12
8,0,10:18.12
9,0,10:18.4
-9,1,10:18.4
-8,1,10:18.4
6,1,10:18.4
7,1,10:18.4
8,1,10:18.4
9,1,10:18.4
-9,2,10:18.4
-8,2,10:18.4
6,2,10:18.4
7,2,10:18.4
8,2,10:18.4
9,2,10:18.4
-9,3,10:18.4
-8,3,10:18.4
-7,3,10:18.12
6,3,10:18.4
7,3,10:18.4
8,3,10:18.4
-10,4,10:18.4
-9,4,10:18.4
-8,4,10:18.4
-7,4,10:18.12
5,4,10:18.4
6,4,10:18.4
7,4,10:18.4
8,4,10:18.4
-10,5,10:18.4
-9,5,10:18.4
-8,5,10:18.4
-7,5,10:18.4
-6,5,10:18.4
4,5,10:18.12
5,5,10:18.4
6,5,10:18.4
8,5,10:18.4
-10,6,10:18.4
-9,6,10:18.4
-8,6,10:18.4
-7,6,10:18.4
-6,6,10:18.4
-5,6,10:18.12
3,6,10:18.12
4,6,10:18.12
6,6,10:18.4
7,6,10:18.4
8,6,10:18.4
-9,7,10:18.4
-8,7,10:18.4
-7,7,10:18.4
-6,7,10:18.4
-5,7,10:18.12
-4,7,10:18.12
-3,7,10:18.12
-2,7,10:18.12
-1,7,10:18.12
0,7,10:18.12
1,7,10:18.12
2,7,10:18.12
3,7,10:18.12
6,7,10:18.4
7,7,10:18.4
-8,8,10:18.4
-7,8,10:18.4
-6,8,10:18.4
-5,8,10:18.12
-3,8,10:18.12
-2,8,10:18.12
-1,8,10:18.12
0,8,10:18.12
1,8,10:18.12
2,8,10:18.12
3,8,10:18.12
4,8,10:18.12
5,8,10:18.4
6,8,10:18.4
7,8,10:18.4
-4,9,10:18.12
-3,9,10:18.12
-2,9,10:18.12
-1,9,10:18.12
0,9,10:18.12
1,9,10:18.12
2,9,10:18.12
3,9,10:18.12
4,9,10:18.12
5,9,10:18.4
6,9,10:18.4
-4,-9,11:18.4
-3,-9,11:18.4
-2,-9,11:18.4
-1,-9,11:18.4
0,-9,11:18.4
-6,-8,11:18.4
-2,-8,11:18.12
-1,-8,11:18.12
0,-8,11:18.12
1,-8,11:18.12
2,-8,11:18.12
3,-8,11:18.12
4,-8,11:18.12
-7,-7,11:18.4
-6,-7,11:18.4
-5,-7,11:18.4
-4,-7,11:18.12
-3,-7,11:18.12
-2,-7,11:18.12
-1,-7,11:18.12
0,-7,11:18.12
1,-7,11:18.12
2,-7,11:18.12
3,-7,11:18.12
6,-7,11:18.4
-9,-6,11:18.4
-7,-6,11:18.4
-6,-6,11:18.4
-5,-6,11:18.4
-4,-6,11:18.12
-3,-6,11:18.12
-2,-6,11:18.12
-1,-6,11:18.12
0,-6,11:18.12
1,-6,11:18.12
2,-6,11:18.12
3,-6,11:18.12
4,-6,11:18.12
5,-6,11:18.4
6,-6,11:18.4
7,-6,11:18.4
-9,-5,11:18.4
-7,-5,11:18.4
-6,-5,11:18.4
-5,-5,11:18.4
4,-5,11:18.12
5,-5,11:18.4
6,-5,11:18.4
8,-5,11:18.4
-9,-4,11:18.4
-7,-4,11:18.4
-6,-4,11:18.4
5,-4,11:18.4
6,-4,11:18.4
8,-4,11:18.4
-9,-3,11:18.4
-8,-3,11:18.4
-7,-3,11:18.4
-6,-3,11:18.4
5,-3,11:18.4
6,-3,11:18.4
8,-3,11:18.4
-9,-2,11:18.4
-8,-2,11:18.4
-7,-2,11:18.4
5,-2,11:18.4
6,-2,11:18.4
7,-2,11:18.4
8,-2,11:18.4
-9,-1,11:18.4
-7,-1,11:18.4
5,-1,11:18.4
6,-1,11:18.4
7,-1,11:18.4
8,-1,11:18.4
-9,0,11:18.4
-7,0,11:18.4
5,0,11:18.4
6,0,11:18.4
8,0,11:18.4
9,0,11:18.4
-9,1,11:18.4
-8,1,11:18.4
-7,1,11:18.4
5,1,11:18.4
6,1,11:18.4
8,1,11:18.4
9,1,11:18.4
-9,2,11:18.4
-8,2,11:18.4
-7,2,11:18.4
5,2,11:18.4
6,2,11:18.4
7,2,11:18.4
8,2,11:18.4
-9,3,11:18.4
-8,3,11:18.4
-7,3,11:18.4
5,3,11:18.4
6,3,11:18.4
7,3,11:18.4
8,3,11:18.4
-9,4,11:18.4
-8,4,11:18.4
-7,4,11:18.4
5,4,11:18.4
6,4,11:18.4
8,4,11:18.4
-9,5,11:18.4
-8,5,11:18.4
-7,5,11:18.4
-6,5,11:18.4
4,5,11:18.4
5,5,11:18.4
7,5,11:18.4
8,5,11:18.4
-9,6,11:18.4
-8,6,11:18.4
-7,6,11:18.4
-6,6,11:18.4
-5,6,11:18.12
-4,6,11:18.12
-3,6,11:18.12
-2,6,11:18.12
-1,6,11:18.12
0,6,11:18.12
1,6,11:18.12
2,6,11:18.12
3,6,11:18.12
4,6,11:18.4
7,6,11:18.4
-8,7,11:18.4
-4,7,11:18.12
-3,7,11:18.12
-2,7,11:18.12
-1,7,11:18.12
0,7,11:18.12
1,7,11:18.12
2,7,11:18.12
3,7,11:18.12
4,7,11:18.4
5,7,11:18.4
6,7,11:18.4
-6,8,11:18.4
-5,8,11:18.12
-3,8,11:18.12
-2,8,11:18.12
0,8,11:18.12
1,8,11:18.12
5,8,11:18.4
-4,9,11:18.12
-3,9,11:18.12
-2,9,11:18.12
-1,9,11:18.12
0,9,11:18.12
1,9,11:18.12
2,9,11:18.12
3,9,11:18.12
-3,-9,12:18.4
-2,-9,12:18.4
-1,-9,12:18.4
-5,-8,12:18.4
-2,-8,12:18.4
-1,-8,12:18.4
0,-8,12:18.4
1,-8,12:18.4
2,-8,12:18.4
3,-8,12:18.4
-6,-7,12:18.4
-5,-7,12:18.4
-3,-7,12:18.4
-2,-7,12:18.4
1,-7,12:18.4
2,-7,12:18.4
5,-7,12:18.4
-7,-6,12:18.4
-6,-6,12:18.4
-5,-6,12:18.4
-4,-6,12:18.4
-3,-6,12:18.4
-2,-6,12:18.4
-1,-6,12:18.4
0,-6,12:18.4
1,-6,12:18.4
2,-6,12:18.4
3,-6,12:18.4
4,-6,12:18.4
5,-6,12:18.4
-7,-5,12:18.4
-6,-5,12:18.4
-5,-5,12:18.4
-4,-5,12:18.4
-3,-5,12:18.4
-2,-5,12:18.4
-1,-5,12:18.4
0,-5,12:18.4
1,-5,12:18.4
2,-5,12:18.4
3,-5,12:18.4
4,-5,12:18.4
5,-5,12:18.4
6,-5,12:18.4
7,-5,12:18.4
-9,-4,12:18.4
-7,-4,12:18.4
-6,-4,12:18.4
-5,-4,12:18.4
4,-4,12:18.4
5,-4,12:18.4
8,-4,12:18.4
-9,-3,12:18.4
-7,-3,12:18.4
-6,-3,12:18.4
-5,-3,12:18.4
4,-3,12:18.4
5,-3,12:18.4
6,-3,12:18.4
8,-3,12:18.4
-9,-2,12:18.4
-8,-2,12:18.4
-6,-2,12:18.4
4,-2,12:18.4
5,-2,12:18.4
6,-2,12:18.4
7,-2,12:18.4
8,-2,12:18.4
-9,-1,12:18.4
-6,-1,12:18.4
4,-1,12:18.4
5,-1,12:18.4
7,-1,12:18.4
8,-1,12:18.4
-9,0,12:18.4
-6,0,12:18.4
4,0,12:18.4
5,0,12:18.4
8,0,12:18.4
-9,1,12:18.4
-8,1,12:18.4
-7,1,12:18.4
-6,1,12:18.4
4,1,12:18.4
5,1,12:18.4
8,1,12:18.4
-9,2,12:18.4
-8,2,12:18.4
-7,2,12:18.4
-6,2,12:18.4
4,2,12:18.4
5,2,12:18.4
7,2,12:18.4
8,2,12:18.4
-9,3,12:18.4
-7,3,12:18.4
-6,3,12:18.4
4,3,12:18.4
5,3,12:18.4
6,3,12:18.4
8,3,12:18.4
-8,4,12:18.4
-7,4,12:18.4
-6,4,12:18.4
4,4,12:18.4
5,4,12:18.4
7,4,12:18.4
-8,5,12:18.4
-7,5,12:18.4
-6,5,12:18.4
-5,5,12:18.4
-3,5,12:18.4
-2,5,12:18.4
-1,5,12:18.4
0,5,12:18.4
1,5,12:18.4
2,5,12:18.4
3,5,12:18.4
4,5,12:18.4
7,5,12:18.4
-7,6,12:18.4
-5,6,12:18.4
-4,6,12:18.4
-3,6,12:18.4
-2,6,12:18.4
-1,6,12:18.4
0,6,12:18.4
1,6,12:18.4
2,6,12:18.4
3,6,12:18.4
4,6,12:18.4
6,6,12:18.4
-7,7,12:18.4
-4,7,12:18.4
-3,7,12:18.4
1,7,12:18.4
2,7,12:18.4
4,7,12:18.4
-3,8,12:18.4
-2,8,12:18.4
0,8,12:18.4
1,8,12:18.4
4,8,12:18.4
-4,9,12:18.4
-3,9,12:18.4
-2,9,12:18.4
-1,9,12:18.4
0,9,12:18.4
1,9,12:18.4
-2,-8,13:18.4
-1,-8,13:18.4
0,-8,13:18.4
1,-8,13:18.4
-5,-7,13:18.4
-4,-7,13:18.4
-3,-7,13:18.4
-2,-7,13:18.4
1,-7,13:18.4
-5,-6,13:18.4
-4,-6,13:18.4
-3,-6,13:18.4
2,-6,13:18.4
4,-6,13:18.4
-7,-5,13:18.4
-6,-5,13:18.4
-5,-5,13:18.4
-4,-5,13:18.4
-3,-5,13:18.4
-2,-5,13:18.4
-1,-5,13:18.4
0,-5,13:18.4
1,-5,13:18.4
2,-5,13:18.4
3,-5,13:18.4
4,-5,13:18.4
-6,-4,13:18.4
-5,-4,13:18.4
-4,-4,13:18.4
-3,-4,13:18.4
-2,-4,13:18.4
-1,-4,13:18.4
0,-4,13:18.4
1,-4,13:18.4
2,-4,13:18.4
3,-4,13:18.4
4,-4,13:18.4
5,-4,13:18.4
6,-4,13:18.4
-9,-3,13:18.4
-7,-3,13:18.4
-5,-3,13:18.4
3,-3,13:18.4
4,-3,13:18.4
5,-3,13:18.4
-9,-2,13:18.4
-8,-2,13:18.4
-5,-2,13:18.4
3,-2,13:18.4
4,-2,13:18.4
6,-2,13:18.4
8,-2,13:18.4
-9,-1,13:18.4
-5,-1,13:18.4
3,-1,13:18.4
4,-1,13:18.4
7,-1,13:18.4
8,-1,13:18.4
-9,0,13:18.4
-8,0,13:18.4
-5,0,13:18.4
3,0,13:18.4
4,0,13:18.4
7,0,13:18.4
8,0,13:18.4
-9,1,13:18.4
-8,1,13:18.4
-6,1,13:18.4
-5,1,13:18.4
3,1,13:18.4
4,1,13:18.4
7,1,13:18.4
8,1,13:18.4
-8,2,13:18.4
-7,2,13:18.4
-6,2,13:18.4
-5,2,13:18.4
3,2,13:18.4
4,2,13:18.4
6,2,13:18.4
7,2,13:18.4
8,2,13:18.4
-7,3,13:18.4
-6,3,13:18.4
-5,3,13:18.4
3,3,13:18.4
4,3,13:18.4
5,3,13:18.4
6,3,13:18.4
7,3,13:18.4
-8,4,13:18.4
-7,4,13:18.4
-6,4,13:18.4
-5,4,13:18.4
-4,4,13:18.4
-3,4,13:18.4
-2,4,13:18.4
-1,4,13:18.4
0,4,13:18.4
1,4,13:18.4
3,4,13:18.4
4,4,13:18.4
5,4,13:18.4
-6,5,13:18.4
-5,5,13:18.4
-3,5,13:18.4
-2,5,13:18.4
-1,5,13:18.4
0,5,13:18.4
1,5,13:18.4
2,5,13:18.4
3,5,13:18.4
4,5,13:18.4
5,5,13:18.4
6,5,13:18.4
-6,6,13:18.4
-4,6,13:18.4
2,6,13:18.4
3,6,13:18.4
-3,7,13:18.4
1,7,13:18.4
2,7,13:18.4
3,7,13:18.4
-3,8,13:18.4
-2,8,13:18.4
0,8,13:18.4
1,8,13:18.4
-2,9,13:18.4
-1,9,13:18.4
0,9,13:18.4
-4,-7,14:18.4
-2,-7,14:18.4
-4,-6,14:18.4
-3,-6,14:18.4
2,-6,14:18.4
3,-6,14:18.4
-5,-5,14:18.4
-4,-5,14:18.4
-3,-5,14:18.4
2,-5,14:18.4
3,-5,14:18.4
-7,-4,14:18.4
-6,-4,14:18.4
-5,-4,14:18.4
-4,-4,14:18.4
-3,-4,14:18.4
-2,-4,14:18.4
-1,-4,14:18.4
0,-4,14:18.4
1,-4,14:18.4
2,-4,14:18.4
3,-4,14:18.4
4,-4,14:18.4
-7,-3,14:18.4
-6,-3,14:18.4
-5,-3,14:18.4
-4,-3,14:18.4
-3,-3,14:18.4
-2,-3,14:18.4
-1,-3,14:18.4
0,-3,14:18.4
1,-3,14:18.4
2,-3,14:18.4
3,-3,14:18.4
4,-3,14:18.4
5,-3,14:18.4
6,-3,14:18.4
-9,-2,14:18.4
-8,-2,14:18.4
-7,-2,14:18.4
-4,-2,14:18.4
2,-2,14:18.4
3,-2,14:18.4
5,-2,14:18.4
6,-2,14:18.4
-9,-1,14:18.4
-8,-1,14:18.4
-4,-1,14:18.4
2,-1,14:18.4
3,-1,14:18.4
6,-1,14:18.4
7,-1,14:18.4
-9,0,14:18.4
-8,0,14:18.4
-5,0,14:18.4
-4,0,14:18.4
2,0,14:18.4
3,0,14:18.4
7,0,14:18.4
8,0,14:18.4
-8,1,14:18.4
-7,1,14:18.4
-5,1,14:18.4
-4,1,14:18.4
2,1,14:18.4
3,1,14:18.4
7,1,14:18.4
8,1,14:18.4
-7,2,14:18.4
-5,2,14:18.4
-4,2,14:18.4
2,2,14:18.4
3,2,14:18.4
6,2,14:18.4
7,2,14:18.4
-8,3,14:18.4
-7,3,14:18.4
-6,3,14:18.4
-5,3,14:18.4
-4,3,14:18.4
-3,3,14:18.4
-1,3,14:18.4
0,3,14:18.4
1,3,14:18.4
2,3,14:18.4
3,3,14:18.4
5,3,14:18.4
6,3,14:18.4
-5,4,14:18.4
-4,4,14:18.4
-3,4,14:18.4
-2,4,14:18.4
-1,4,14:18.4
0,4,14:18.4
1,4,14:18.4
2,4,14:18.4
3,4,14:18.4
4,4,14:18.4
5,4,14:18.4
-5,5,14:18.4
2,5,14:18.4
3,5,14:18.4
-5,6,14:18.4
-4,6,14:18.4
2,6,14:18.4
-3,7,14:18.4
1,7,14:18.4
2,7,14:18.4
-3,-6,15:18.4
-2,-6,15:18.4
2,-6,15:18.4
-3,-5,15:18.4
2,-5,15:18.4
-3,-4,15:18.4
2,-4,15:18.4
-7,-3,15:18.4
-6,-3,15:18.4
-5,-3,15:18.4
-4,-3,15:18.4
-3,-3,15:18.4
-2,-3,15:18.4
-1,-3,15:18.4
0,-3,15:18.4
1,-3,15:18.4
2,-3,15:18.4
-6,-2,15:18.4
-5,-2,15:18.4
-4,-2,15:18.4
-3,-2,15:18.4
-2,-2,15:18.4
-1,-2,15:18.4
0,-2,15:18.4
1,-2,15:18.4
2,-2,15:18.4
3,-2,15:18.4
4,-2,15:18.4
5,-2,15:18.4
-3,-1,15:18.4
1,-1,15:18.4
2,-1,15:18.4
5,-1,15:18.4
-4,0,15:18.4
-3,0,15:18.4
1,0,15:18.4
2,0,15:18.4
7,0,15:18.4
-4,1,15:18.4
-3,1,15:18.4
1,1,15:18.4
2,1,15:18.4
7,1,15:18.4
-7,2,15:18.4
-6,2,15:18.4
-5,2,15:18.4
-4,2,15:18.4
-3,2,15:18.4
-2,2,15:18.4
-1,2,15:18.4
0,2,15:18.4
1,2,15:18.4
2,2,15:18.4
-4,3,15:18.4
-3,3,15:18.4
-1,3,15:18.4
0,3,15:18.4
1,3,15:18.4
2,3,15:18.4
3,3,15:18.4
4,3,15:18.4
5,3,15:18.4
-4,4,15:18.4
-3,4,15:18.4
1,4,15:18.4
1,5,15:18.4
-4,6,15:18.4
1,6,15:18.4
-2,-6,16:18.4
-2,-5,16:18.4
1,-5,16:18.4
-2,-4,16:18.4
1,-4,16:18.4
-2,-3,16:18.4
0,-3,16:18.4
1,-3,16:18.4
-6,-2,16:18.4
-5,-2,16:18.4
-4,-2,16:18.4
-3,-2,16:18.4
-2,-2,16:18.4
-1,-2,16:18.4
0,-2,16:18.4
1,-2,16:18.4
-5,-1,16:18.4
-4,-1,16:18.4
-3,-1,16:18.4
-2,-1,16:18.4
-1,-1,16:18.4
0,-1,16:18.4
1,-1,16:18.4
2,-1,16:18.4
3,-1,16:18.4
4,-1,16:18.4
5,-1,16:18.4
-3,0,16:18.4
-2,0,16:18.4
0,0,16:18.4
1,0,16:18.4
4,0,16:18.4
-7,1,16:18.4
-6,1,16:18.4
-5,1,16:18.4
-4,1,16:18.4
-3,1,16:18.4
-2,1,16:18.4
-1,1,16:18.4
0,1,16:18.4
1,1,16:18.4
-4,2,16:18.4
-3,2,16:18.4
-2,2,16:18.4
-1,2,16:18.4
0,2,16:18.4
1,2,16:18.4
2,2,16:18.4
3,2,16:18.4
4,2,16:18.4
5,2,16:18.4
-3,3,16:18.4
0,3,16:18.4
-3,4,16:18.4
-2,4,16:18.4
0,4,16:18.4
-3,5,16:18.4
0,5,16:18.4
-3,6,16:18.4
0,6,16:18.4
-1,-5,17:18.4
0,-5,17:18.4
-1,-4,17:18.4
0,-4,17:18.4
-1,-3,17:18.4
0,-3,17:18.4
-1,-2,17:18.4
0,-2,17:18.4
-6,-1,17:18.4
-5,-1,17:18.4
-4,-1,17:18.4
-3,-1,17:18.4
-2,-1,17:18.4
-1,-1,17:18.4
0,-1,17:18.4
-6,0,17:18.4
-5,0,17:18.4
-4,0,17:18.4
-3,0,17:18.4
-2,0,17:18.4
-1,0,17:18.4
0,0,17:18.4
1,0,17:18.4
2,0,17:18.4
3,0,17:18.4
4,0,17:18.4
-4,1,17:18.4
-3,1,17:18.4
-2,1,17:18.4
-1,1,17:18.4
0,1,17:18.4
1,1,17:18.4
2,1,17:18.4
3,1,17:18.4
4,1,17:18.4
-2,2,17:18.4
-1,2,17:18.4
0,2,17:18.4
-1,3,17:18.4
-2,4,17:18.4
-1,4,17:18.4
-2,5,17:18.4
-1,5,17:18.4
