[META]
version=2.0
spawnOnBlockType=2
spawnSunlight=True
spawnDarkness=True
spawnWater=False
spawnLava=False
underFill=False
randomRotation=True
dig=True
tree=False
branch=False
needsFoundation=True
rarity=100
collisionPercentage=20
spawnElevationMin=0
spawnElevationMax=200
spawnInBiome=Custom
[DATA]
-1,-1,-8:17.12
3,1,-8:17.12
4,1,-8:17.12
-1,3,-8:17.12
-2,-3,-7:17.12
-1,-3,-7:17.12
-2,-2,-7:17.12
-1,-2,-7:17.12
-2,-1,-7:17.12
3,0,-7:17.12
2,1,-7:17.12
3,1,-7:17.12
4,1,-7:17.12
3,2,-7:17.12
4,2,-7:17.12
-3,3,-7:17.12
-2,3,-7:17.12
-1,3,-7:17.12
-2,4,-7:17.12
-1,4,-7:17.12
-2,-3,-6:17.12
-1,-3,-6:17.12
-2,-2,-6:17.12
-1,-2,-6:17.12
0,-2,-6:17.12
-2,-1,-6:17.12
-1,-1,-6:17.12
0,-1,-6:17.12
2,0,-6:17.12
1,1,-6:17.12
2,1,-6:17.12
3,1,-6:17.12
-2,2,-6:17.12
-1,2,-6:17.12
3,2,-6:17.12
-2,3,-6:17.12
-3,4,-6:17.12
-2,4,-6:17.12
-1,-3,-5:17.12
-2,-2,-5:17.12
-1,-2,-5:17.12
-2,-1,-5:17.12
-1,-1,-5:17.12
1,0,-5:17.12
2,0,-5:17.12
3,0,-5:17.12
-1,1,-5:17.12
0,1,-5:17.12
1,1,-5:17.12
2,1,-5:17.12
3,1,-5:17.12
-3,2,-5:17.12
-2,2,-5:17.12
-1,2,-5:17.12
1,2,-5:17.12
2,2,-5:17.12
3,2,-5:17.12
-2,3,-5:17.12
-1,3,-5:17.12
-1,-3,-4:17.12
0,-3,-4:17.12
-2,-2,-4:17.12
-1,-2,-4:17.12
0,-2,-4:17.12
0,-1,-4:17.12
1,0,-4:17.12
2,0,-4:17.12
3,0,-4:17.12
-3,1,-4:17.12
-2,1,-4:17.12
-1,1,-4:17.12
1,1,-4:17.12
2,1,-4:17.12
3,1,-4:17.12
-3,2,-4:17.12
-2,2,-4:17.12
-1,2,-4:17.12
1,2,-4:17.12
2,2,-4:17.12
3,2,-4:17.12
-2,3,-4:17.12
-1,3,-4:17.12
-1,-3,-3:17.12
-2,-2,-3:17.12
-1,-2,-3:17.12
0,-2,-3:17.12
-1,-1,-3:17.12
2,0,-3:17.12
-3,1,-3:17.12
-2,1,-3:17.12
-1,1,-3:17.12
1,1,-3:17.12
2,1,-3:17.12
3,1,-3:17.12
-2,2,-3:17.12
-1,2,-3:17.12
1,2,-3:17.12
2,2,-3:17.12
-3,3,-3:17.12
-2,3,-3:17.12
-1,3,-3:17.12
1,3,-3:17.12
-1,-3,-2:17.12
-2,-2,-2:17.12
-1,-2,-2:17.12
0,-2,-2:17.12
1,-2,-2:17.12
-3,-1,-2:17.12
-2,-1,-2:17.12
-1,-1,-2:17.12
0,-1,-2:17.12
1,-1,-2:17.12
2,-1,-2:17.12
-4,0,-2:1.0
-3,0,-2:17.12
-2,0,-2:17.12
-1,0,-2:17.12
0,0,-2:17.12
1,0,-2:17.12
2,0,-2:17.12
-4,1,-2:17.12
-3,1,-2:17.12
-2,1,-2:17.12
-1,1,-2:17.12
0,1,-2:17.12
1,1,-2:17.12
2,1,-2:17.12
3,1,-2:17.12
-3,2,-2:17.12
-2,2,-2:17.12
-1,2,-2:17.12
0,2,-2:17.12
1,2,-2:17.12
2,2,-2:17.12
3,2,-2:17.12
-2,3,-2:17.12
-1,3,-2:17.12
0,3,-2:17.12
1,3,-2:17.12
2,3,-2:17.12
-1,4,-2:17.12
-2,-2,-1:17.12
-1,-2,-1:17.12
0,-2,-1:17.12
1,-2,-1:17.12
-3,-1,-1:17.12
-2,-1,-1:17.12
0,-1,-1:17.12
1,-1,-1:17.12
-3,0,-1:17.12
-1,0,-1:17.12
2,0,-1:17.12
-3,1,-1:17.12
-2,1,-1:17.12
-1,1,-1:17.12
2,1,-1:17.12
-3,2,-1:17.12
1,2,-1:17.12
2,2,-1:17.12
-2,3,-1:17.12
-1,3,-1:17.12
0,3,-1:17.12
1,3,-1:17.12
-1,-2,0:17.12
0,-2,0:17.12
-3,-1,0:17.12
-2,-1,0:17.12
0,-1,0:17.12
1,-1,0:17.12
-3,0,0:17.12
2,0,0:17.12
-3,1,0:17.12
2,1,0:17.12
-3,2,0:17.12
-2,2,0:17.12
1,2,0:17.12
-2,3,0:17.12
-1,3,0:17.12
0,3,0:17.12
1,3,0:17.12
-2,-1,1:17.12
-1,-1,1:17.12
0,-1,1:17.12
1,-1,1:17.12
-3,0,1:17.12
1,0,1:17.12
-3,1,1:17.12
1,1,1:17.12
2,1,1:17.12
-3,2,1:17.12
-2,2,1:17.12
1,2,1:17.12
-2,3,1:17.12
-1,3,1:17.12
0,3,1:17.12
-2,-1,2:17.12
-1,-1,2:17.12
0,-1,2:17.12
1,-1,2:17.12
-3,0,2:17.12
1,0,2:17.12
-3,1,2:17.12
1,1,2:17.12
-3,2,2:17.12
-2,2,2:17.12
0,2,2:17.12
1,2,2:17.12
-1,3,2:17.12
0,3,2:17.12
-2,-1,3:17.12
-1,-1,3:17.12
0,-1,3:17.12
-3,0,3:17.12
-2,0,3:17.12
1,0,3:17.12
-3,1,3:17.12
-2,1,3:17.12
1,1,3:17.12
-2,2,3:17.12
-1,2,3:17.12
0,2,3:17.12
1,2,3:17.12
-1,3,3:17.12
-1,-1,4:17.12
0,-1,4:17.12
-2,0,4:17.12
0,0,4:17.12
1,0,4:17.12
-2,1,4:17.12
1,1,4:17.12
-2,2,4:17.12
-1,2,4:17.12
0,2,4:17.12
1,2,4:17.12
-1,3,4:17.12
0,3,4:17.12
4,-6,5:18.12
5,-6,5:18.12
-6,-5,5:18.12
4,-5,5:18.12
5,-5,5:18.12
6,-5,5:18.12
-7,-4,5:18.12
-6,-4,5:18.12
-5,-4,5:18.12
3,-4,5:18.12
4,-4,5:18.12
5,-4,5:18.12
-7,-3,5:18.12
-6,-3,5:18.12
-5,-3,5:18.12
3,-3,5:18.12
4,-3,5:18.12
-5,-2,5:18.12
-4,-2,5:18.12
-1,-1,5:17.12
-2,0,5:17.12
-1,0,5:17.12
0,0,5:17.12
1,0,5:17.12
-2,1,5:17.12
1,1,5:17.12
-2,2,5:17.12
-1,2,5:17.12
0,2,5:17.12
1,2,5:17.12
-2,3,5:17.12
-1,3,5:17.12
0,3,5:17.12
-4,5,5:18.12
4,5,5:18.12
5,5,5:18.12
6,5,5:18.12
-5,6,5:18.12
-4,6,5:18.12
5,6,5:18.12
6,6,5:18.12
7,6,5:18.12
-6,7,5:18.12
-5,7,5:18.12
-4,7,5:18.12
6,7,5:18.12
-5,8,5:18.12
3,-7,6:18.12
4,-7,6:18.12
-6,-6,6:18.12
-5,-6,6:18.12
3,-6,6:18.12
4,-6,6:18.12
-6,-5,6:18.12
-5,-5,6:18.12
2,-5,6:18.12
3,-5,6:18.12
6,-5,6:18.12
-5,-4,6:18.12
-4,-4,6:18.12
2,-4,6:18.12
3,-4,6:18.12
5,-4,6:18.12
6,-4,6:18.12
-8,-3,6:18.12
-7,-3,6:18.12
-5,-3,6:18.12
-4,-3,6:18.12
-3,-3,6:18.12
2,-3,6:18.12
3,-3,6:18.12
4,-3,6:18.12
5,-3,6:18.12
-8,-2,6:18.12
-7,-2,6:18.12
-6,-2,6:18.12
-5,-2,6:18.12
-4,-2,6:18.12
-3,-2,6:18.12
1,-2,6:18.12
2,-2,6:18.12
3,-2,6:18.12
4,-2,6:18.12
-6,-1,6:18.12
-5,-1,6:18.12
-4,-1,6:18.12
-3,-1,6:18.12
-2,-1,6:18.12
1,-1,6:18.12
2,-1,6:18.12
3,-1,6:18.12
-4,0,6:18.12
-3,0,6:18.12
-2,0,6:18.12
-1,0,6:17.12
0,0,6:17.12
1,0,6:18.12
2,0,6:18.12
-3,1,6:17.12
-2,1,6:17.12
-1,1,6:18.12
0,1,6:18.12
1,1,6:17.12
2,1,6:17.12
-2,2,6:17.12
-1,2,6:18.12
0,2,6:18.12
1,2,6:17.12
2,2,6:17.12
-2,3,6:18.12
-1,3,6:17.12
0,3,6:17.12
1,3,6:18.12
2,3,6:18.12
3,3,6:18.12
4,3,6:18.12
-4,4,6:18.12
-3,4,6:18.12
-2,4,6:18.12
-1,4,6:17.12
0,4,6:17.12
1,4,6:17.12
2,4,6:18.12
3,4,6:18.12
4,4,6:18.12
5,4,6:18.12
6,4,6:18.12
7,4,6:18.12
-5,5,6:18.12
-4,5,6:18.12
-3,5,6:18.12
-2,5,6:18.12
2,5,6:18.12
3,5,6:18.12
4,5,6:18.12
5,5,6:18.12
6,5,6:18.12
7,5,6:18.12
-7,6,6:18.12
-6,6,6:18.12
-5,6,6:18.12
-3,6,6:18.12
-2,6,6:18.12
3,6,6:18.12
4,6,6:18.12
-7,7,6:18.12
-4,7,6:18.12
-3,7,6:18.12
4,7,6:18.12
5,7,6:18.12
-4,8,6:18.12
-3,8,6:18.12
5,8,6:18.12
-4,9,6:18.12
2,-8,7:18.12
3,-8,7:18.12
-5,-7,7:18.12
2,-7,7:18.12
3,-7,7:18.12
-5,-6,7:18.12
-4,-6,7:18.12
1,-6,7:18.12
2,-6,7:18.12
-5,-5,7:18.12
-4,-5,7:18.12
-3,-5,7:18.12
1,-5,7:18.12
2,-5,7:18.12
-4,-4,7:18.12
0,-4,7:18.12
1,-4,7:18.12
2,-4,7:18.12
6,-4,7:18.12
7,-4,7:18.12
-3,-3,7:18.12
-2,-3,7:18.12
0,-3,7:18.12
1,-3,7:18.12
5,-3,7:18.12
6,-3,7:18.12
7,-3,7:18.12
-9,-2,7:18.12
-8,-2,7:18.12
-7,-2,7:18.12
-3,-2,7:18.12
-2,-2,7:18.12
-1,-2,7:18.12
0,-2,7:18.12
1,-2,7:18.12
4,-2,7:18.12
5,-2,7:18.12
-8,-1,7:18.12
-7,-1,7:18.12
-6,-1,7:18.12
-2,-1,7:18.12
-1,-1,7:18.12
0,-1,7:18.12
1,-1,7:17.12
2,-1,7:17.12
3,-1,7:18.12
4,-1,7:18.12
-7,0,7:18.12
-6,0,7:18.12
-5,0,7:18.12
-4,0,7:18.12
-3,0,7:18.12
-2,0,7:17.12
-1,0,7:18.12
0,0,7:18.12
1,0,7:17.12
2,0,7:18.12
3,0,7:18.12
-5,1,7:18.12
-4,1,7:18.12
-3,1,7:18.12
-2,1,7:18.12
-1,1,7:18.12
0,1,7:18.12
1,1,7:18.12
2,1,7:17.12
3,1,7:17.12
4,1,7:17.12
-4,2,7:17.12
-3,2,7:17.12
-2,2,7:17.12
-1,2,7:18.12
0,2,7:17.12
1,2,7:18.12
2,2,7:18.12
3,2,7:18.12
4,2,7:18.12
5,2,7:18.12
-4,3,7:18.12
-3,3,7:18.12
-2,3,7:17.12
-1,3,7:17.12
0,3,7:18.12
1,3,7:17.12
2,3,7:17.12
3,3,7:18.12
4,3,7:18.12
5,3,7:18.12
6,3,7:18.12
7,3,7:18.12
8,3,7:18.12
-6,4,7:18.12
-5,4,7:18.12
-4,4,7:18.12
-2,4,7:17.12
-1,4,7:18.12
0,4,7:18.12
1,4,7:18.12
2,4,7:17.12
6,4,7:18.12
7,4,7:18.12
8,4,7:18.12
-7,5,7:18.12
-6,5,7:18.12
-5,5,7:18.12
-2,5,7:18.12
-1,5,7:18.12
1,5,7:18.12
2,5,7:18.12
-8,6,7:18.12
-7,6,7:18.12
-2,6,7:18.12
-1,6,7:18.12
2,6,7:18.12
3,6,7:18.12
-2,7,7:18.12
-1,7,7:18.12
3,7,7:18.12
4,7,7:18.12
-3,8,7:18.12
-2,8,7:18.12
3,8,7:18.12
4,8,7:18.12
5,8,7:18.12
-3,9,7:18.12
-2,9,7:18.12
4,9,7:18.12
5,9,7:18.12
-3,10,7:18.12
1,-9,8:18.12
-5,-8,8:18.12
-4,-8,8:18.12
1,-8,8:18.12
2,-8,8:18.12
-4,-7,8:18.12
-3,-7,8:18.12
0,-7,8:18.12
1,-7,8:18.12
-4,-6,8:18.12
-3,-6,8:18.12
0,-6,8:18.12
1,-6,8:18.12
-3,-5,8:18.12
-2,-5,8:18.12
-1,-5,8:18.12
0,-5,8:18.12
-2,-4,8:18.12
-1,-4,8:18.12
0,-4,8:18.12
8,-4,8:18.12
-2,-3,8:18.12
-1,-3,8:18.12
0,-3,8:18.12
7,-3,8:18.12
8,-3,8:18.12
-2,-2,8:18.12
-1,-2,8:18.12
0,-2,8:18.12
1,-2,8:18.12
2,-2,8:17.12
5,-2,8:18.12
6,-2,8:18.12
7,-2,8:18.12
-10,-1,8:18.12
-9,-1,8:18.12
-8,-1,8:18.12
-4,-1,8:17.12
-3,-1,8:17.12
-2,-1,8:18.12
-1,-1,8:18.12
0,-1,8:18.12
1,-1,8:17.12
2,-1,8:18.12
4,-1,8:18.12
5,-1,8:18.12
6,-1,8:18.12
-9,0,8:18.12
-8,0,8:18.12
-7,0,8:18.12
-6,0,8:18.12
-4,0,8:18.12
-3,0,8:18.12
-2,0,8:17.12
-1,0,8:18.12
0,0,8:18.12
1,0,8:17.12
2,0,8:18.12
3,0,8:18.12
4,0,8:18.12
5,0,8:17.12
-7,1,8:18.12
-6,1,8:18.12
-5,1,8:18.12
-4,1,8:18.12
-3,1,8:18.12
-2,1,8:18.12
-1,1,8:17.12
0,1,8:17.12
1,1,8:18.12
2,1,8:18.12
3,1,8:17.12
4,1,8:17.12
5,1,8:18.12
6,1,8:18.12
-6,2,8:17.12
-5,2,8:17.12
-4,2,8:17.12
-3,2,8:18.12
-2,2,8:18.12
-1,2,8:17.12
0,2,8:17.12
1,2,8:18.12
2,2,8:18.12
3,2,8:18.12
4,2,8:18.12
5,2,8:18.12
6,2,8:18.12
7,2,8:18.12
8,2,8:18.12
9,2,8:18.12
-6,3,8:18.12
-5,3,8:18.12
-4,3,8:18.12
-3,3,8:18.12
-2,3,8:18.12
-1,3,8:17.12
0,3,8:18.12
1,3,8:18.12
2,3,8:18.12
3,3,8:18.12
7,3,8:18.12
8,3,8:18.12
9,3,8:18.12
-8,4,8:18.12
-7,4,8:18.12
-6,4,8:18.12
-3,4,8:18.12
-2,4,8:17.12
-1,4,8:18.12
0,4,8:18.12
1,4,8:18.12
2,4,8:17.12
3,4,8:17.12
-9,5,8:18.12
-8,5,8:18.12
-7,5,8:18.12
-3,5,8:17.12
-2,5,8:17.12
-1,5,8:18.12
0,5,8:18.12
1,5,8:18.12
2,5,8:17.12
3,5,8:17.12
-9,6,8:18.12
-1,6,8:18.12
0,6,8:18.12
1,6,8:18.12
2,6,8:18.12
-1,7,8:18.12
0,7,8:18.12
1,7,8:18.12
2,7,8:18.12
-2,8,8:18.12
-1,8,8:18.12
0,8,8:18.12
2,8,8:18.12
3,8,8:18.12
-2,9,8:18.12
-1,9,8:18.12
3,9,8:18.12
4,9,8:18.12
-2,10,8:18.12
-1,10,8:18.12
4,10,8:18.12
-2,11,8:18.12
-4,-10,9:18.4
0,-10,9:18.4
-4,-9,9:18.4
-3,-9,9:18.4
-1,-9,9:18.12
0,-9,9:18.12
1,-9,9:18.12
-4,-8,9:18.12
-3,-8,9:18.4
-1,-8,9:18.12
0,-8,9:18.12
-3,-7,9:18.12
-2,-7,9:18.12
-1,-7,9:18.12
0,-7,9:18.12
-3,-6,9:18.12
-2,-6,9:18.12
-1,-6,9:18.12
-3,-5,9:18.12
-2,-5,9:18.12
-1,-5,9:18.12
0,-5,9:18.12
-2,-4,9:18.12
-1,-4,9:18.12
0,-4,9:18.12
1,-4,9:18.12
2,-4,9:18.12
3,-4,9:17.12
-4,-3,9:18.12
-3,-3,9:18.12
-2,-3,9:18.12
0,-3,9:18.12
1,-3,9:18.12
2,-3,9:17.12
3,-3,9:17.12
8,-3,9:18.12
9,-3,9:18.12
-5,-2,9:17.12
-4,-2,9:18.12
-3,-2,9:18.12
-2,-2,9:18.12
-1,-2,9:18.12
0,-2,9:18.12
1,-2,9:18.12
2,-2,9:17.12
3,-2,9:18.12
4,-2,9:18.12
7,-2,9:18.12
8,-2,9:18.12
-5,-1,9:18.12
-4,-1,9:17.12
-3,-1,9:17.12
-2,-1,9:18.12
-1,-1,9:18.12
0,-1,9:18.12
1,-1,9:17.12
2,-1,9:18.12
3,-1,9:18.12
4,-1,9:18.12
5,-1,9:18.12
6,-1,9:18.12
7,-1,9:18.12
-11,0,9:18.12
-10,0,9:18.12
-9,0,9:18.12
-6,0,9:18.12
-5,0,9:18.12
-4,0,9:18.12
-3,0,9:17.12
2,0,9:18.12
3,0,9:18.12
4,0,9:18.12
5,0,9:18.12
6,0,9:17.12
7,0,9:17.12
-10,1,9:18.12
-9,1,9:18.12
-8,1,9:18.12
-7,1,9:18.12
-6,1,9:18.12
-5,1,9:18.12
-4,1,9:18.12
-3,1,9:18.12
2,1,9:18.12
3,1,9:18.12
4,1,9:18.12
5,1,9:18.12
6,1,9:18.12
7,1,9:18.12
8,1,9:18.12
9,1,9:18.12
-8,2,9:18.12
-7,2,9:18.12
-6,2,9:18.12
-5,2,9:18.12
-4,2,9:18.12
-3,2,9:18.12
2,2,9:18.12
3,2,9:18.12
4,2,9:18.12
5,2,9:18.12
8,2,9:18.12
9,2,9:18.12
10,2,9:18.12
-8,3,9:18.12
-6,3,9:18.12
-5,3,9:18.12
-4,3,9:18.12
-3,3,9:18.12
2,3,9:17.12
3,3,9:18.12
4,3,9:18.12
-10,4,9:18.12
-9,4,9:18.12
-8,4,9:18.12
-5,4,9:18.12
-4,4,9:18.12
-3,4,9:18.12
-2,4,9:17.12
-1,4,9:18.12
0,4,9:18.12
1,4,9:18.12
2,4,9:18.12
3,4,9:17.12
4,4,9:18.12
-10,5,9:18.12
-9,5,9:18.12
-4,5,9:18.12
-3,5,9:17.12
-2,5,9:18.12
-1,5,9:18.12
0,5,9:18.12
1,5,9:18.12
2,5,9:18.12
3,5,9:18.12
4,5,9:17.12
-3,6,9:17.12
-2,6,9:18.12
-1,6,9:18.12
0,6,9:18.12
1,6,9:18.12
2,6,9:18.12
3,6,9:18.12
-1,7,9:18.12
0,7,9:18.12
1,7,9:18.12
2,7,9:18.12
0,8,9:18.12
1,8,9:18.12
2,8,9:18.12
-1,9,9:18.12
0,9,9:18.12
1,9,9:18.12
2,9,9:18.12
3,9,9:18.12
-1,10,9:18.12
0,10,9:18.12
2,10,9:18.12
3,10,9:18.12
-1,11,9:18.12
0,11,9:18.12
3,11,9:18.4
4,11,9:18.4
-1,12,9:18.12
-4,-11,10:18.4
-3,-11,10:18.4
-1,-11,10:18.4
-4,-10,10:18.4
-3,-10,10:18.4
-2,-10,10:18.4
-1,-10,10:18.4
-3,-9,10:18.4
-2,-9,10:18.4
-1,-9,10:18.12
-3,-8,10:18.4
-2,-8,10:18.4
-1,-8,10:18.12
0,-8,10:18.12
-4,-7,10:18.12
-3,-7,10:18.12
-2,-7,10:18.12
-1,-7,10:18.12
0,-7,10:18.12
1,-7,10:18.12
-5,-6,10:18.12
-4,-6,10:18.12
-3,-6,10:18.12
-2,-6,10:18.12
-1,-6,10:18.12
0,-6,10:18.12
1,-6,10:18.12
2,-6,10:18.12
-5,-5,10:18.12
-4,-5,10:18.12
-3,-5,10:18.12
1,-5,10:18.12
2,-5,10:18.12
3,-5,10:18.12
4,-5,10:18.12
-6,-4,10:18.12
-5,-4,10:18.12
-4,-4,10:18.12
0,-4,10:18.12
1,-4,10:18.12
2,-4,10:18.12
3,-4,10:18.12
4,-4,10:18.12
5,-4,10:18.12
-7,-3,10:18.12
-6,-3,10:18.12
-5,-3,10:18.12
-4,-3,10:18.12
-3,-3,10:18.12
-2,-3,10:18.12
-1,-3,10:18.12
0,-3,10:18.12
1,-3,10:18.12
2,-3,10:17.12
3,-3,10:18.12
4,-3,10:18.12
5,-3,10:18.12
6,-3,10:18.12
9,-3,10:18.12
10,-3,10:18.12
-7,-2,10:18.12
-6,-2,10:18.12
-5,-2,10:17.12
-4,-2,10:18.12
-3,-2,10:18.12
-2,-2,10:18.12
-1,-2,10:18.12
3,-2,10:18.12
4,-2,10:18.12
5,-2,10:18.12
6,-2,10:18.12
7,-2,10:18.12
8,-2,10:18.12
9,-2,10:18.12
10,-2,10:18.12
-8,-1,10:18.12
-7,-1,10:18.12
-6,-1,10:18.12
-5,-1,10:18.12
3,-1,10:18.12
4,-1,10:18.12
5,-1,10:18.12
6,-1,10:18.12
7,-1,10:18.12
8,-1,10:18.12
-8,0,10:18.12
-7,0,10:18.12
-6,0,10:18.12
-5,0,10:18.12
3,0,10:18.12
4,0,10:18.12
6,0,10:18.12
7,0,10:18.12
8,0,10:18.12
9,0,10:18.12
10,0,10:18.12
-12,1,10:18.4
-11,1,10:18.4
-10,1,10:18.12
-9,1,10:18.12
-8,1,10:18.12
-7,1,10:18.12
-6,1,10:18.12
-5,1,10:18.12
3,1,10:18.12
4,1,10:18.12
6,1,10:18.12
7,1,10:18.12
8,1,10:18.12
9,1,10:18.12
10,1,10:18.12
11,1,10:18.12
-11,2,10:18.4
-10,2,10:18.12
-9,2,10:18.12
-8,2,10:18.12
-7,2,10:18.12
-5,2,10:18.12
-4,2,10:18.12
4,2,10:18.12
5,2,10:18.12
6,2,10:18.12
7,2,10:18.12
-10,3,10:18.12
-9,3,10:18.12
-8,3,10:18.12
-6,3,10:18.12
-5,3,10:18.12
-4,3,10:18.12
4,3,10:18.12
5,3,10:18.12
6,3,10:18.12
-11,4,10:18.4
-10,4,10:18.12
-9,4,10:18.12
-8,4,10:18.12
-7,4,10:18.12
-6,4,10:18.12
-5,4,10:18.12
-4,4,10:18.12
3,4,10:17.12
4,4,10:18.12
5,4,10:18.12
6,4,10:18.12
-11,5,10:18.4
-6,5,10:18.12
-5,5,10:18.12
-4,5,10:18.12
-3,5,10:17.12
-1,5,10:18.12
0,5,10:18.12
1,5,10:18.12
2,5,10:18.12
3,5,10:18.12
4,5,10:18.12
5,5,10:18.12
-5,6,10:18.12
-4,6,10:18.12
-3,6,10:18.12
-2,6,10:18.12
-1,6,10:18.12
0,6,10:18.12
1,6,10:18.12
2,6,10:18.12
3,6,10:18.12
4,6,10:18.12
5,6,10:17.12
-4,7,10:17.12
-3,7,10:18.12
-2,7,10:18.12
-1,7,10:18.12
2,7,10:18.12
3,7,10:18.12
4,7,10:18.12
-3,8,10:18.12
-2,8,10:18.12
-1,8,10:18.12
0,8,10:18.12
1,8,10:18.12
2,8,10:18.12
3,8,10:18.12
-1,9,10:18.12
0,9,10:18.12
1,9,10:18.12
2,9,10:18.12
0,10,10:18.12
1,10,10:18.12
2,10,10:18.12
0,11,10:18.12
1,11,10:18.4
2,11,10:18.4
3,11,10:18.4
-1,12,10:18.12
0,12,10:18.4
2,12,10:18.4
3,12,10:18.4
0,13,10:18.4
-3,-12,11:18.4
-2,-12,11:18.4
-3,-11,11:18.4
-2,-11,11:18.4
-1,-11,11:18.4
-4,-10,11:18.4
-3,-10,11:18.4
-2,-10,11:18.4
-1,-10,11:18.4
0,-10,11:18.4
-5,-9,11:18.4
-4,-9,11:18.4
-3,-9,11:18.4
-2,-9,11:18.4
-1,-9,11:18.12
0,-9,11:18.12
1,-9,11:18.12
2,-9,11:18.12
-6,-8,11:18.12
-5,-8,11:18.12
-4,-8,11:18.12
-3,-8,11:18.4
0,-8,11:18.12
1,-8,11:18.12
2,-8,11:18.12
3,-8,11:18.12
-6,-7,11:18.12
-5,-7,11:18.12
-4,-7,11:18.12
1,-7,11:18.12
2,-7,11:18.12
3,-7,11:18.12
4,-7,11:18.12
-7,-6,11:18.12
-6,-6,11:18.12
-5,-6,11:18.12
2,-6,11:18.12
3,-6,11:18.12
4,-6,11:18.12
5,-6,11:18.12
-8,-5,11:18.12
-7,-5,11:18.12
-6,-5,11:18.12
-5,-5,11:18.12
-1,-5,11:18.12
0,-5,11:18.12
1,-5,11:18.12
2,-5,11:18.12
3,-5,11:17.12
4,-5,11:18.12
5,-5,11:18.12
6,-5,11:18.12
-8,-4,11:18.12
-7,-4,11:18.12
-6,-4,11:18.12
-5,-4,11:18.12
-4,-4,11:18.12
-2,-4,11:18.12
-1,-4,11:18.12
0,-4,11:18.12
1,-4,11:18.12
4,-4,11:18.12
5,-4,11:18.12
6,-4,11:18.12
7,-4,11:18.12
-9,-3,11:18.12
-8,-3,11:18.12
-7,-3,11:18.12
-6,-3,11:17.12
-2,-3,11:18.12
4,-3,11:18.12
5,-3,11:18.12
6,-3,11:18.12
7,-3,11:18.12
8,-3,11:18.12
11,-3,11:18.12
-9,-2,11:18.12
-8,-2,11:18.12
-7,-2,11:18.12
4,-2,11:18.12
5,-2,11:18.12
7,-2,11:18.12
8,-2,11:18.12
9,-2,11:18.12
10,-2,11:18.12
11,-2,11:18.12
-10,-1,11:18.12
-9,-1,11:18.12
-8,-1,11:18.12
-7,-1,11:18.12
-6,-1,11:18.12
4,-1,11:18.12
5,-1,11:18.12
8,-1,11:18.12
10,-1,11:18.12
11,-1,11:18.12
-10,0,11:18.12
-9,0,11:18.12
-8,0,11:18.12
-7,0,11:18.12
-6,0,11:18.12
5,0,11:18.12
8,0,11:18.12
9,0,11:18.12
10,0,11:18.12
11,0,11:18.12
-10,1,11:18.12
-9,1,11:18.12
-7,1,11:18.12
-6,1,11:18.12
5,1,11:18.12
8,1,11:18.12
9,1,11:18.12
-13,2,11:18.4
-12,2,11:18.4
-11,2,11:18.4
-10,2,11:18.12
-9,2,11:18.12
-6,2,11:18.12
5,2,11:18.12
6,2,11:18.12
7,2,11:18.12
8,2,11:18.12
9,2,11:18.12
-12,3,11:18.4
-11,3,11:18.4
-10,3,11:18.12
-9,3,11:18.12
-6,3,11:18.12
-5,3,11:18.12
5,3,11:18.12
6,3,11:18.12
7,3,11:18.12
8,3,11:18.12
-12,4,11:18.4
-11,4,11:18.4
-10,4,11:18.12
-9,4,11:18.12
-8,4,11:18.12
-6,4,11:18.12
-5,4,11:18.12
5,4,11:18.12
6,4,11:18.12
7,4,11:18.12
8,4,11:18.12
-9,5,11:18.12
-8,5,11:18.12
-7,5,11:18.12
-6,5,11:18.12
-5,5,11:18.12
5,5,11:17.12
6,5,11:18.12
7,5,11:18.12
-8,6,11:18.12
-7,6,11:18.12
-6,6,11:18.12
-5,6,11:18.12
-4,6,11:18.12
-1,6,11:18.12
0,6,11:18.12
1,6,11:18.12
2,6,11:18.12
3,6,11:18.12
4,6,11:18.12
5,6,11:18.12
6,6,11:17.12
7,6,11:18.12
-7,7,11:18.12
-6,7,11:18.12
-5,7,11:18.12
-4,7,11:17.12
-3,7,11:18.12
-2,7,11:18.12
-1,7,11:18.12
0,7,11:18.12
1,7,11:18.12
2,7,11:18.12
3,7,11:18.12
4,7,11:18.12
5,7,11:18.12
6,7,11:18.12
-5,8,11:18.12
-4,8,11:18.12
-3,8,11:18.12
-2,8,11:18.12
3,8,11:18.12
4,8,11:18.12
5,8,11:18.12
-4,9,11:18.12
-3,9,11:18.12
-2,9,11:18.12
-1,9,11:18.12
3,9,11:18.12
4,9,11:18.12
-3,10,11:18.12
-2,10,11:18.12
-1,10,11:18.12
0,10,11:18.12
2,10,11:18.12
3,10,11:18.12
4,10,11:18.12
-1,11,11:18.12
0,11,11:18.12
1,11,11:18.4
2,11,11:18.4
3,11,11:18.4
0,12,11:18.4
1,12,11:18.4
2,12,11:18.4
0,13,11:18.4
1,13,11:18.4
2,13,11:18.4
3,13,11:18.4
1,14,11:18.4
2,14,11:18.4
-3,-13,12:18.4
-4,-12,12:18.4
-3,-12,12:18.4
-2,-12,12:18.4
-1,-12,12:18.4
-4,-11,12:18.4
-3,-11,12:18.4
-1,-11,12:18.4
0,-11,12:18.4
-5,-10,12:18.4
-4,-10,12:18.4
0,-10,12:18.4
1,-10,12:18.4
2,-10,12:18.4
-6,-9,12:18.4
-5,-9,12:18.4
2,-9,12:18.12
3,-9,12:18.12
-7,-8,12:18.12
-6,-8,12:18.12
3,-8,12:18.12
4,-8,12:18.12
5,-8,12:18.12
-7,-7,12:18.12
-6,-7,12:18.12
1,-7,12:18.12
2,-7,12:18.12
3,-7,12:18.12
4,-7,12:18.12
5,-7,12:18.12
6,-7,12:18.12
-8,-6,12:18.12
-7,-6,12:18.12
-6,-6,12:18.12
-5,-6,12:18.12
-4,-6,12:18.12
-3,-6,12:18.12
-2,-6,12:18.12
-1,-6,12:18.12
0,-6,12:18.12
1,-6,12:18.12
2,-6,12:18.12
5,-6,12:18.12
6,-6,12:18.12
7,-6,12:18.12
-9,-5,12:18.12
-8,-5,12:18.12
-7,-5,12:18.12
-6,-5,12:18.12
-5,-5,12:18.12
-4,-5,12:18.12
-3,-5,12:18.12
-2,-5,12:18.12
-1,-5,12:18.12
0,-5,12:18.12
5,-5,12:18.12
6,-5,12:18.12
7,-5,12:18.12
8,-5,12:18.4
9,-5,12:18.4
-9,-4,12:18.12
-8,-4,12:17.12
5,-4,12:18.12
6,-4,12:18.12
8,-4,12:18.12
9,-4,12:18.12
10,-4,12:18.12
-10,-3,12:18.12
-9,-3,12:18.12
-8,-3,12:18.12
5,-3,12:18.12
6,-3,12:18.12
9,-3,12:18.12
10,-3,12:18.12
11,-3,12:18.12
-11,-2,12:18.12
-10,-2,12:18.12
-9,-2,12:18.12
-8,-2,12:18.12
5,-2,12:18.12
6,-2,12:18.12
10,-2,12:18.12
11,-2,12:18.12
12,-2,12:18.4
-11,-1,12:18.12
-10,-1,12:18.12
-8,-1,12:18.12
6,-1,12:18.12
10,-1,12:18.12
11,-1,12:18.12
12,-1,12:18.4
-12,0,12:18.12
-11,0,12:18.12
-10,0,12:18.12
-8,0,12:18.12
-7,0,12:18.12
6,0,12:18.12
7,0,12:18.12
10,0,12:18.12
11,0,12:18.12
-13,1,12:18.4
-12,1,12:18.4
-11,1,12:18.4
-8,1,12:18.12
-7,1,12:18.12
6,1,12:18.12
7,1,12:18.12
9,1,12:18.12
10,1,12:18.12
11,1,12:18.12
-13,2,12:18.4
-12,2,12:18.4
-11,2,12:18.4
-8,2,12:18.12
-7,2,12:18.12
6,2,12:18.12
7,2,12:18.12
9,2,12:18.12
10,2,12:18.12
-14,3,12:18.4
-13,3,12:18.4
-12,3,12:18.4
-11,3,12:18.4
-8,3,12:18.12
6,3,12:18.12
7,3,12:18.12
8,3,12:18.12
9,3,12:18.12
10,3,12:18.12
-13,4,12:18.4
-12,4,12:18.4
-11,4,12:18.4
-10,4,12:18.12
-7,4,12:18.12
-6,4,12:18.12
6,4,12:18.12
7,4,12:18.12
8,4,12:18.12
9,4,12:18.12
-11,5,12:18.4
-10,5,12:18.12
-9,5,12:18.12
-7,5,12:18.12
-6,5,12:18.12
7,5,12:18.12
8,5,12:18.12
9,5,12:18.12
-10,6,12:18.12
-9,6,12:18.12
-8,6,12:18.12
-7,6,12:18.12
-6,6,12:18.12
6,6,12:18.12
7,6,12:18.12
8,6,12:18.12
-9,7,12:18.12
-8,7,12:18.12
-7,7,12:18.12
-6,7,12:18.12
0,7,12:18.12
1,7,12:18.12
2,7,12:18.12
3,7,12:18.12
4,7,12:18.12
5,7,12:18.12
6,7,12:18.12
7,7,12:18.12
8,7,12:18.12
-8,8,12:18.12
-7,8,12:18.12
-6,8,12:18.12
-5,8,12:17.12
-4,8,12:18.12
-3,8,12:18.12
-2,8,12:18.12
-1,8,12:18.12
0,8,12:18.12
1,8,12:18.12
2,8,12:18.12
3,8,12:18.12
4,8,12:18.12
5,8,12:18.12
6,8,12:18.12
7,8,12:18.12
-7,9,12:18.12
-6,9,12:18.12
-5,9,12:18.12
-4,9,12:18.12
-3,9,12:18.12
-2,9,12:18.12
5,9,12:18.12
6,9,12:18.12
7,9,12:18.12
-5,10,12:18.12
-4,10,12:18.12
-3,10,12:18.12
4,10,12:18.12
5,10,12:18.12
6,10,12:18.12
-4,11,12:18.12
-3,11,12:18.12
-2,11,12:18.12
-1,11,12:18.12
3,11,12:18.4
4,11,12:18.4
5,11,12:18.4
-3,12,12:18.12
-2,12,12:18.12
-1,12,12:18.12
0,12,12:18.4
3,12,12:18.4
4,12,12:18.4
-1,13,12:18.4
0,13,12:18.4
1,13,12:18.4
2,13,12:18.4
3,13,12:18.4
4,13,12:18.4
0,14,12:18.4
1,14,12:18.4
2,14,12:18.4
3,14,12:18.4
-3,-12,13:18.4
-2,-12,13:18.4
-1,-12,13:18.4
-4,-11,13:18.4
-3,-11,13:18.4
-2,-11,13:18.4
-1,-11,13:18.4
0,-11,13:18.4
-5,-10,13:18.4
-4,-10,13:18.4
-3,-10,13:18.4
-2,-10,13:18.4
-1,-10,13:18.4
0,-10,13:18.4
1,-10,13:18.4
2,-10,13:18.4
-6,-9,13:18.4
-5,-9,13:18.4
-4,-9,13:18.4
0,-9,13:18.12
1,-9,13:18.12
2,-9,13:18.12
3,-9,13:18.12
-6,-8,13:18.12
-5,-8,13:18.12
1,-8,13:18.12
2,-8,13:18.12
3,-8,13:18.12
4,-8,13:18.12
5,-8,13:18.12
-7,-7,13:18.12
-6,-7,13:18.12
-5,-7,13:18.12
-3,-7,13:18.12
-2,-7,13:18.12
-1,-7,13:18.12
0,-7,13:18.12
1,-7,13:18.12
2,-7,13:18.12
3,-7,13:18.12
4,-7,13:18.12
5,-7,13:18.12
6,-7,13:18.12
-8,-6,13:18.12
-7,-6,13:18.12
-6,-6,13:18.12
-5,-6,13:18.12
-4,-6,13:18.12
-3,-6,13:18.12
-2,-6,13:18.12
-1,-6,13:18.12
5,-6,13:18.12
6,-6,13:18.12
7,-6,13:18.12
8,-6,13:18.4
-9,-5,13:18.12
-8,-5,13:18.12
-7,-5,13:18.12
6,-5,13:18.12
7,-5,13:18.12
8,-5,13:18.4
9,-5,13:18.4
-9,-4,13:18.12
-8,-4,13:18.12
6,-4,13:18.12
7,-4,13:18.12
8,-4,13:18.12
9,-4,13:18.12
10,-4,13:18.12
-10,-3,13:18.12
-9,-3,13:18.12
-8,-3,13:18.12
6,-3,13:18.12
7,-3,13:18.12
9,-3,13:18.12
10,-3,13:18.12
11,-3,13:18.12
12,-3,13:18.4
-11,-2,13:18.12
-10,-2,13:18.12
-9,-2,13:18.12
7,-2,13:18.12
11,-2,13:18.12
12,-2,13:18.4
13,-2,13:18.4
-11,-1,13:18.12
-10,-1,13:18.12
-9,-1,13:18.12
7,-1,13:18.12
8,-1,13:18.12
11,-1,13:18.12
12,-1,13:18.4
-12,0,13:18.12
-11,0,13:18.12
-9,0,13:18.12
7,0,13:18.12
8,0,13:18.12
11,0,13:18.12
12,0,13:18.4
-13,1,13:18.4
-12,1,13:18.4
-11,1,13:18.4
-9,1,13:18.12
-8,1,13:18.12
7,1,13:18.12
8,1,13:18.12
10,1,13:18.12
11,1,13:18.12
12,1,13:18.4
-13,2,13:18.4
-12,2,13:18.4
-9,2,13:18.12
-8,2,13:18.12
7,2,13:18.12
8,2,13:18.12
9,2,13:18.12
10,2,13:18.12
11,2,13:18.12
-14,3,13:18.4
-13,3,13:18.4
-9,3,13:18.4
-8,3,13:18.12
8,3,13:18.12
9,3,13:18.12
10,3,13:18.12
11,3,13:18.12
-13,4,13:18.4
-12,4,13:18.4
-11,4,13:18.4
-9,4,13:18.12
-8,4,13:18.12
8,4,13:18.12
9,4,13:18.12
10,4,13:18.12
-12,5,13:18.4
-11,5,13:18.4
-10,5,13:18.4
-8,5,13:18.12
-7,5,13:18.12
7,5,13:18.12
8,5,13:18.12
9,5,13:18.12
10,5,13:18.12
-11,6,13:18.4
-10,6,13:18.4
-9,6,13:18.12
-8,6,13:18.12
-7,6,13:18.12
7,6,13:18.12
8,6,13:18.12
9,6,13:18.12
-10,7,13:18.4
-9,7,13:18.12
-8,7,13:18.12
-7,7,13:18.12
6,7,13:18.12
7,7,13:18.12
8,7,13:18.12
9,7,13:18.12
-9,8,13:18.12
-8,8,13:18.12
-7,8,13:18.12
-6,8,13:18.12
1,8,13:18.12
2,8,13:18.12
3,8,13:18.12
4,8,13:18.12
5,8,13:18.12
6,8,13:18.12
7,8,13:18.12
8,8,13:18.12
-8,9,13:18.12
-7,9,13:18.12
-6,9,13:18.12
-5,9,13:18.12
-4,9,13:18.12
-3,9,13:18.12
-2,9,13:18.12
-1,9,13:18.12
0,9,13:18.12
1,9,13:18.12
2,9,13:18.12
3,9,13:18.12
4,9,13:18.12
5,9,13:18.12
6,9,13:18.12
7,9,13:18.12
8,9,13:18.12
-7,10,13:18.12
-6,10,13:18.12
-5,10,13:18.12
-4,10,13:18.12
-3,10,13:18.12
-2,10,13:18.12
4,10,13:18.12
5,10,13:18.12
6,10,13:18.12
7,10,13:18.12
-6,11,13:18.12
-5,11,13:18.12
-4,11,13:18.12
-3,11,13:18.12
-2,11,13:18.12
3,11,13:18.4
4,11,13:18.4
5,11,13:18.4
6,11,13:18.4
-4,12,13:18.12
-3,12,13:18.12
-2,12,13:18.12
-1,12,13:18.12
0,12,13:18.4
2,12,13:18.4
3,12,13:18.4
4,12,13:18.4
5,12,13:18.4
-2,13,13:18.4
-1,13,13:18.4
0,13,13:18.4
1,13,13:18.4
2,13,13:18.4
3,13,13:18.4
4,13,13:18.4
0,14,13:18.4
1,14,13:18.4
2,14,13:18.4
3,14,13:18.4
-3,-11,14:18.4
-2,-11,14:18.4
0,-11,14:18.4
-5,-10,14:18.4
-3,-10,14:18.4
-2,-10,14:18.4
-1,-10,14:18.4
1,-10,14:18.4
2,-10,14:18.4
-6,-9,14:18.4
-5,-9,14:18.4
-4,-9,14:18.4
-3,-9,14:18.4
-2,-9,14:18.4
-1,-9,14:18.12
0,-9,14:18.12
2,-9,14:18.12
3,-9,14:18.12
-6,-8,14:18.12
-4,-8,14:18.12
-3,-8,14:18.4
0,-8,14:18.12
1,-8,14:18.12
2,-8,14:18.12
4,-8,14:18.12
5,-8,14:18.12
-7,-7,14:18.12
-5,-7,14:18.12
-4,-7,14:18.12
-3,-7,14:18.12
-2,-7,14:18.12
-1,-7,14:18.12
0,-7,14:18.12
1,-7,14:18.12
2,-7,14:18.12
3,-7,14:18.12
4,-7,14:18.12
5,-7,14:18.12
6,-7,14:18.12
-8,-6,14:18.12
-7,-6,14:18.12
-6,-6,14:18.12
-5,-6,14:18.12
-4,-6,14:18.12
3,-6,14:18.12
4,-6,14:18.12
5,-6,14:18.12
6,-6,14:18.12
7,-6,14:18.12
-9,-5,14:18.12
-8,-5,14:18.12
-7,-5,14:18.12
-6,-5,14:18.12
4,-5,14:18.12
5,-5,14:18.12
6,-5,14:18.12
8,-5,14:18.4
9,-5,14:18.4
-9,-4,14:18.12
-7,-4,14:18.12
-6,-4,14:18.12
6,-4,14:18.12
7,-4,14:18.12
8,-4,14:18.4
9,-4,14:18.4
10,-4,14:18.4
-10,-3,14:18.12
-9,-3,14:18.12
-8,-3,14:18.12
-7,-3,14:18.12
7,-3,14:18.12
8,-3,14:18.4
9,-3,14:18.4
10,-3,14:18.4
11,-3,14:18.4
-11,-2,14:18.12
-10,-2,14:18.12
-9,-2,14:18.12
-8,-2,14:18.12
7,-2,14:18.12
9,-2,14:18.4
10,-2,14:18.4
11,-2,14:18.4
-11,-1,14:18.12
-10,-1,14:18.12
-9,-1,14:18.12
8,-1,14:18.4
10,-1,14:18.4
11,-1,14:18.4
12,-1,14:18.4
-12,0,14:18.12
-11,0,14:18.12
-10,0,14:18.12
-9,0,14:18.12
8,0,14:18.4
9,0,14:18.4
10,0,14:18.4
11,0,14:18.4
12,0,14:18.4
-13,1,14:18.4
-12,1,14:18.4
-11,1,14:18.4
-10,1,14:18.12
-9,1,14:18.12
8,1,14:18.12
9,1,14:18.12
10,1,14:18.4
11,1,14:18.4
-13,2,14:18.4
-12,2,14:18.4
-11,2,14:18.4
-9,2,14:18.12
8,2,14:18.12
9,2,14:18.12
11,2,14:18.4
-13,3,14:18.4
-12,3,14:18.4
-11,3,14:18.4
-9,3,14:18.4
7,3,14:18.12
8,3,14:18.12
10,3,14:18.12
11,3,14:18.4
-12,4,14:18.4
-11,4,14:18.4
-10,4,14:18.4
-9,4,14:18.12
7,4,14:18.12
8,4,14:18.12
10,4,14:18.12
-12,5,14:18.4
-10,5,14:18.4
-9,5,14:18.12
-8,5,14:18.12
6,5,14:18.12
7,5,14:18.12
8,5,14:18.12
9,5,14:18.12
10,5,14:18.12
-11,6,14:18.4
-9,6,14:18.12
-8,6,14:18.12
-7,6,14:18.12
5,6,14:18.12
6,6,14:18.12
8,6,14:18.12
9,6,14:18.12
-10,7,14:18.4
-8,7,14:18.12
-7,7,14:18.12
-6,7,14:18.12
5,7,14:18.12
6,7,14:18.12
8,7,14:18.12
9,7,14:18.12
-9,8,14:18.12
-7,8,14:18.12
-6,8,14:18.12
-5,8,14:18.12
-4,8,14:18.12
4,8,14:18.12
5,8,14:18.12
6,8,14:18.12
7,8,14:18.12
8,8,14:18.12
-8,9,14:18.12
-7,9,14:18.12
-4,9,14:18.12
-3,9,14:18.12
1,9,14:18.12
2,9,14:18.12
3,9,14:18.12
4,9,14:18.12
7,9,14:18.12
-7,10,14:18.12
-6,10,14:18.12
-5,10,14:18.12
-4,10,14:18.12
-3,10,14:18.12
-2,10,14:18.12
-1,10,14:18.12
0,10,14:18.12
1,10,14:18.12
3,10,14:18.12
4,10,14:18.12
6,10,14:18.12
-6,11,14:18.12
-5,11,14:18.12
-4,11,14:18.12
-2,11,14:18.12
-1,11,14:18.12
0,11,14:18.12
2,11,14:18.4
3,11,14:18.4
5,11,14:18.4
-4,12,14:18.12
-3,12,14:18.12
0,12,14:18.4
1,12,14:18.4
2,12,14:18.4
4,12,14:18.4
-2,13,14:18.4
-1,13,14:18.4
1,13,14:18.4
2,13,14:18.4
3,13,14:18.4
-3,-10,15:18.4
-2,-10,15:18.4
-1,-10,15:18.4
1,-10,15:18.4
-6,-9,15:18.4
-5,-9,15:18.4
-3,-9,15:18.4
-2,-9,15:18.4
-1,-9,15:18.12
2,-9,15:18.12
3,-9,15:18.12
-6,-8,15:18.12
-3,-8,15:18.4
-2,-8,15:18.4
-1,-8,15:18.12
0,-8,15:18.12
3,-8,15:18.12
4,-8,15:18.12
-7,-7,15:18.12
-4,-7,15:18.12
-3,-7,15:18.12
-2,-7,15:18.12
-1,-7,15:18.12
0,-7,15:18.12
1,-7,15:18.12
2,-7,15:18.12
3,-7,15:18.12
4,-7,15:18.12
5,-7,15:18.12
6,-7,15:18.12
-8,-6,15:18.12
-7,-6,15:18.12
-6,-6,15:18.12
-5,-6,15:18.12
-4,-6,15:18.12
-3,-6,15:18.12
1,-6,15:18.12
2,-6,15:18.12
3,-6,15:18.12
5,-6,15:18.12
6,-6,15:18.12
7,-6,15:18.12
-9,-5,15:18.12
-8,-5,15:18.12
-7,-5,15:18.12
-6,-5,15:18.12
-5,-5,15:18.12
-4,-5,15:18.12
2,-5,15:18.12
3,-5,15:18.12
4,-5,15:18.12
6,-5,15:18.12
8,-5,15:18.4
-9,-4,15:18.12
-6,-4,15:18.12
-5,-4,15:18.12
4,-4,15:18.12
5,-4,15:18.12
6,-4,15:18.12
9,-4,15:18.4
-10,-3,15:18.12
-9,-3,15:18.12
-7,-3,15:18.12
-6,-3,15:18.12
5,-3,15:18.12
6,-3,15:18.12
7,-3,15:18.12
8,-3,15:18.4
-11,-2,15:18.12
-10,-2,15:18.12
-9,-2,15:18.12
-8,-2,15:18.12
-7,-2,15:18.12
7,-2,15:18.12
8,-2,15:18.4
9,-2,15:18.4
10,-2,15:18.4
-11,-1,15:18.12
-9,-1,15:18.12
-8,-1,15:18.12
7,-1,15:18.12
8,-1,15:18.4
10,-1,15:18.4
-12,0,15:18.12
-11,0,15:18.12
-9,0,15:18.12
-8,0,15:18.12
7,0,15:18.4
8,0,15:18.4
9,0,15:18.4
10,0,15:18.4
-10,1,15:18.12
-9,1,15:18.12
7,1,15:18.12
8,1,15:18.12
11,1,15:18.4
-12,2,15:18.4
-11,2,15:18.4
-10,2,15:18.4
-9,2,15:18.4
7,2,15:18.12
8,2,15:18.12
10,2,15:18.12
11,2,15:18.4
-12,3,15:18.4
-11,3,15:18.4
-10,3,15:18.4
-9,3,15:18.4
6,3,15:18.12
7,3,15:18.12
8,3,15:18.12
10,3,15:18.12
-12,4,15:18.4
-11,4,15:18.4
-10,4,15:18.4
-9,4,15:18.12
-8,4,15:18.12
5,4,15:18.12
6,4,15:18.12
8,4,15:18.12
10,4,15:18.12
-9,5,15:18.12
-8,5,15:18.12
-7,5,15:18.12
5,5,15:18.12
6,5,15:18.12
8,5,15:18.12
9,5,15:18.12
-11,6,15:18.4
-8,6,15:18.12
-7,6,15:18.12
-6,6,15:18.12
-5,6,15:18.12
4,6,15:18.12
5,6,15:18.12
8,6,15:18.12
9,6,15:18.12
-10,7,15:18.4
-8,7,15:18.12
-6,7,15:18.12
-5,7,15:18.12
-4,7,15:18.12
3,7,15:18.12
4,7,15:18.12
7,7,15:18.12
8,7,15:18.12
9,7,15:18.12
-9,8,15:18.12
-8,8,15:18.12
-7,8,15:18.12
-4,8,15:18.12
-3,8,15:18.12
-2,8,15:18.12
3,8,15:18.12
4,8,15:18.12
5,8,15:18.12
6,8,15:18.12
7,8,15:18.12
8,8,15:18.12
-8,9,15:18.12
-7,9,15:18.12
-3,9,15:18.12
-2,9,15:18.12
-1,9,15:18.12
0,9,15:18.12
1,9,15:18.12
2,9,15:18.12
3,9,15:18.12
6,9,15:18.12
7,9,15:18.12
-7,10,15:18.12
-6,10,15:18.12
-5,10,15:18.12
-4,10,15:18.12
-3,10,15:18.12
-2,10,15:18.12
-1,10,15:18.12
0,10,15:18.12
1,10,15:18.4
2,10,15:18.12
5,10,15:18.12
6,10,15:18.12
-6,11,15:18.12
-5,11,15:18.12
-4,11,15:18.12
0,11,15:18.12
1,11,15:18.4
2,11,15:18.4
4,11,15:18.4
5,11,15:18.4
-4,12,15:18.12
-3,12,15:18.12
0,12,15:18.4
1,12,15:18.4
2,12,15:18.4
4,12,15:18.4
-2,13,15:18.4
-4,-9,16:18.4
-3,-9,16:18.4
-1,-9,16:18.4
2,-9,16:18.4
3,-9,16:18.4
-6,-8,16:18.12
-4,-8,16:18.12
-3,-8,16:18.4
-2,-8,16:18.4
-1,-8,16:18.4
3,-8,16:18.4
4,-8,16:18.4
-7,-7,16:18.12
-3,-7,16:18.4
-2,-7,16:18.4
-1,-7,16:18.4
0,-7,16:18.4
1,-7,16:18.4
2,-7,16:18.4
3,-7,16:18.4
4,-7,16:18.4
5,-7,16:18.4
6,-7,16:18.4
-8,-6,16:18.12
-7,-6,16:18.12
-6,-6,16:18.12
-5,-6,16:18.12
-4,-6,16:18.12
-3,-6,16:18.4
-2,-6,16:18.4
-1,-6,16:18.4
0,-6,16:18.4
1,-6,16:18.4
5,-6,16:18.4
6,-6,16:18.4
7,-6,16:18.4
-8,-5,16:18.12
-7,-5,16:18.12
-6,-5,16:18.12
-4,-5,16:18.12
-3,-5,16:18.4
0,-5,16:18.4
1,-5,16:18.4
2,-5,16:18.4
3,-5,16:18.4
6,-5,16:18.4
-9,-4,16:18.12
-8,-4,16:18.12
-5,-4,16:18.12
-4,-4,16:18.12
2,-4,16:18.4
3,-4,16:18.4
4,-4,16:18.4
6,-4,16:18.4
-10,-3,16:18.12
-9,-3,16:18.12
-6,-3,16:18.12
-5,-3,16:18.12
4,-3,16:18.4
5,-3,16:18.4
6,-3,16:18.4
-10,-2,16:18.12
-9,-2,16:18.12
-7,-2,16:18.12
-6,-2,16:18.12
5,-2,16:18.4
6,-2,16:18.4
7,-2,16:18.4
8,-2,16:18.4
9,-2,16:18.4
-11,-1,16:18.12
-9,-1,16:18.12
-7,-1,16:18.12
-6,-1,16:18.12
7,-1,16:18.4
8,-1,16:18.4
-9,0,16:18.12
-8,0,16:18.12
-7,0,16:18.12
7,0,16:18.4
8,0,16:18.4
9,0,16:18.4
10,0,16:18.4
-11,1,16:18.4
-9,1,16:18.4
-8,1,16:18.4
6,1,16:18.4
7,1,16:18.4
8,1,16:18.4
-11,2,16:18.4
-10,2,16:18.4
-9,2,16:18.4
-8,2,16:18.4
6,2,16:18.4
7,2,16:18.4
8,2,16:18.4
10,2,16:18.4
-10,3,16:18.4
-9,3,16:18.4
-8,3,16:18.4
5,3,16:18.4
6,3,16:18.4
8,3,16:18.4
10,3,16:18.4
-11,4,16:18.4
-10,4,16:18.4
-8,4,16:18.12
-7,4,16:18.12
-6,4,16:18.12
4,4,16:18.4
5,4,16:18.4
8,4,16:18.4
9,4,16:18.4
-8,5,16:18.12
-7,5,16:18.12
-6,5,16:18.12
-5,5,16:18.12
4,5,16:18.4
5,5,16:18.4
8,5,16:18.4
9,5,16:18.4
-8,6,16:18.12
-5,6,16:18.12
-4,6,16:18.12
3,6,16:18.4
4,6,16:18.4
8,6,16:18.4
9,6,16:18.4
-8,7,16:18.12
-7,7,16:18.12
-4,7,16:18.12
-3,7,16:18.12
-2,7,16:18.12
2,7,16:18.4
3,7,16:18.4
7,7,16:18.4
8,7,16:18.4
-9,8,16:18.12
-8,8,16:18.12
-7,8,16:18.12
-3,8,16:18.12
-2,8,16:18.12
-1,8,16:18.12
2,8,16:18.4
3,8,16:18.4
4,8,16:18.4
5,8,16:18.4
6,8,16:18.4
7,8,16:18.4
-8,9,16:18.12
-7,9,16:18.12
-1,9,16:18.12
0,9,16:18.4
1,9,16:18.4
2,9,16:18.4
6,9,16:18.4
-7,10,16:18.12
-6,10,16:18.12
-5,10,16:18.12
-4,10,16:18.12
-3,10,16:18.12
-2,10,16:18.12
0,10,16:18.4
1,10,16:18.4
2,10,16:18.4
5,10,16:18.4
-6,11,16:18.12
-5,11,16:18.12
-4,11,16:18.12
-1,11,16:18.12
0,11,16:18.4
1,11,16:18.4
2,11,16:18.4
3,11,16:18.4
-4,12,16:18.12
0,12,16:18.4
0,-9,17:18.4
-4,-8,17:18.4
-1,-8,17:18.4
0,-8,17:18.4
4,-8,17:18.4
-7,-7,17:18.4
-4,-7,17:18.4
-3,-7,17:18.4
-2,-7,17:18.4
-1,-7,17:18.4
0,-7,17:18.4
1,-7,17:18.4
2,-7,17:18.4
3,-7,17:18.4
4,-7,17:18.4
5,-7,17:18.4
-8,-6,17:18.4
-7,-6,17:18.4
-6,-6,17:18.4
-5,-6,17:18.4
-4,-6,17:18.4
-3,-6,17:18.4
-2,-6,17:18.4
-1,-6,17:18.4
0,-6,17:18.4
5,-6,17:18.4
6,-6,17:18.4
-8,-5,17:18.4
-7,-5,17:18.4
-6,-5,17:18.4
-3,-5,17:18.4
-2,-5,17:18.4
-1,-5,17:18.4
0,-5,17:18.4
1,-5,17:18.4
5,-5,17:18.4
6,-5,17:18.4
-9,-4,17:18.4
-8,-4,17:18.4
-4,-4,17:18.4
0,-4,17:18.4
1,-4,17:18.4
2,-4,17:18.4
6,-4,17:18.4
-10,-3,17:18.4
-9,-3,17:18.4
-5,-3,17:18.4
-4,-3,17:18.4
2,-3,17:18.4
3,-3,17:18.4
4,-3,17:18.4
6,-3,17:18.4
8,-3,17:18.4
-10,-2,17:18.4
-9,-2,17:18.4
-5,-2,17:18.4
-4,-2,17:18.4
3,-2,17:18.4
4,-2,17:18.4
5,-2,17:18.4
6,-2,17:18.4
7,-2,17:18.4
8,-2,17:18.4
-9,-1,17:18.4
-8,-1,17:18.4
-6,-1,17:18.4
-5,-1,17:18.4
5,-1,17:18.4
6,-1,17:18.4
7,-1,17:18.4
-8,0,17:18.4
-7,0,17:18.4
-6,0,17:18.4
6,0,17:18.4
7,0,17:18.4
8,0,17:18.4
-10,1,17:18.4
-9,1,17:18.4
-8,1,17:18.4
-7,1,17:18.4
5,1,17:18.4
6,1,17:18.4
7,1,17:18.4
8,1,17:18.4
9,1,17:18.4
-9,2,17:18.4
-8,2,17:18.4
-7,2,17:18.4
4,2,17:18.4
5,2,17:18.4
7,2,17:18.4
-9,3,17:18.4
-8,3,17:18.4
-6,3,17:18.4
4,3,17:18.4
5,3,17:18.4
7,3,17:18.4
8,3,17:18.4
-10,4,17:18.4
-9,4,17:18.4
-8,4,17:18.4
-7,4,17:18.4
-6,4,17:18.4
-5,4,17:18.4
3,4,17:18.4
4,4,17:18.4
8,4,17:18.4
9,4,17:18.4
-8,5,17:18.4
-7,5,17:18.4
-5,5,17:18.4
-4,5,17:18.4
-3,5,17:18.4
2,5,17:18.4
3,5,17:18.4
8,5,17:18.4
9,5,17:18.4
-7,6,17:18.4
-4,6,17:18.4
-3,6,17:18.4
-2,6,17:18.4
2,6,17:18.4
3,6,17:18.4
8,6,17:18.4
-7,7,17:18.4
-2,7,17:18.4
-1,7,17:18.4
1,7,17:18.4
2,7,17:18.4
6,7,17:18.4
7,7,17:18.4
8,7,17:18.4
-7,8,17:18.4
-1,8,17:18.4
0,8,17:18.4
1,8,17:18.4
2,8,17:18.4
3,8,17:18.4
4,8,17:18.4
5,8,17:18.4
6,8,17:18.4
7,8,17:18.4
-7,9,17:18.4
-2,9,17:18.4
-1,9,17:18.4
0,9,17:18.4
1,9,17:18.4
2,9,17:18.4
6,9,17:18.4
-7,10,17:18.4
-6,10,17:18.4
-5,10,17:18.4
-4,10,17:18.4
-3,10,17:18.4
-1,10,17:18.4
0,10,17:18.4
2,10,17:18.4
3,10,17:18.4
-6,11,17:18.4
-5,11,17:18.4
-1,11,17:18.4
0,-8,18:18.4
-4,-7,18:18.4
0,-7,18:18.4
1,-7,18:18.4
2,-7,18:18.4
3,-7,18:18.4
4,-7,18:18.4
-7,-6,18:18.4
-5,-6,18:18.4
-4,-6,18:18.4
-3,-6,18:18.4
-2,-6,18:18.4
-1,-6,18:18.4
0,-6,18:18.4
5,-6,18:18.4
-8,-5,18:18.4
-7,-5,18:18.4
-6,-5,18:18.4
-5,-5,18:18.4
-3,-5,18:18.4
-2,-5,18:18.4
-1,-5,18:18.4
5,-5,18:18.4
-9,-4,18:18.4
-8,-4,18:18.4
-2,-4,18:18.4
-1,-4,18:18.4
0,-4,18:18.4
5,-4,18:18.4
-9,-3,18:18.4
-8,-3,18:18.4
-3,-3,18:18.4
-2,-3,18:18.4
0,-3,18:18.4
1,-3,18:18.4
2,-3,18:18.4
5,-3,18:18.4
6,-3,18:18.4
7,-3,18:18.4
-8,-2,18:18.4
-4,-2,18:18.4
-3,-2,18:18.4
1,-2,18:18.4
2,-2,18:18.4
3,-2,18:18.4
6,-2,18:18.4
7,-2,18:18.4
-8,-1,18:18.4
-5,-1,18:18.4
-4,-1,18:18.4
3,-1,18:18.4
4,-1,18:18.4
5,-1,18:18.4
6,-1,18:18.4
-9,0,18:18.4
-8,0,18:18.4
-6,0,18:18.4
-5,0,18:18.4
4,0,18:18.4
5,0,18:18.4
6,0,18:18.4
-9,1,18:18.4
-8,1,18:18.4
-7,1,18:18.4
-6,1,18:18.4
4,1,18:18.4
5,1,18:18.4
6,1,18:18.4
7,1,18:18.4
8,1,18:18.4
-8,2,18:18.4
-7,2,18:18.4
-6,2,18:18.4
3,2,18:18.4
4,2,18:18.4
7,2,18:18.4
8,2,18:18.4
-8,3,18:18.4
-6,3,18:18.4
-5,3,18:18.4
3,3,18:18.4
7,3,18:18.4
-9,4,18:18.4
-8,4,18:18.4
-7,4,18:18.4
-5,4,18:18.4
-4,4,18:18.4
-3,4,18:18.4
2,4,18:18.4
3,4,18:18.4
7,4,18:18.4
-9,5,18:18.4
-7,5,18:18.4
-4,5,18:18.4
-3,5,18:18.4
-2,5,18:18.4
1,5,18:18.4
2,5,18:18.4
7,5,18:18.4
8,5,18:18.4
-7,6,18:18.4
-2,6,18:18.4
-1,6,18:18.4
0,6,18:18.4
1,6,18:18.4
8,6,18:18.4
-7,7,18:18.4
-1,7,18:18.4
0,7,18:18.4
1,7,18:18.4
5,7,18:18.4
6,7,18:18.4
7,7,18:18.4
8,7,18:18.4
-7,8,18:18.4
-1,8,18:18.4
0,8,18:18.4
1,8,18:18.4
2,8,18:18.4
3,8,18:18.4
4,8,18:18.4
6,8,18:18.4
7,8,18:18.4
-3,9,18:18.4
-2,9,18:18.4
-1,9,18:18.4
0,9,18:18.4
2,9,18:18.4
3,9,18:18.4
-6,10,18:18.4
-5,10,18:18.4
-4,10,18:18.4
-2,10,18:18.4
-1,10,18:18.4
1,-7,19:18.4
-5,-6,19:18.4
-4,-6,19:18.4
0,-6,19:18.4
1,-6,19:18.4
-8,-5,19:18.4
-7,-5,19:18.4
-6,-5,19:18.4
-5,-5,19:18.4
-4,-5,19:18.4
-3,-5,19:18.4
-1,-5,19:18.4
0,-5,19:18.4
-8,-4,19:18.4
-2,-4,19:18.4
-1,-4,19:18.4
-8,-3,19:18.4
-2,-3,19:18.4
-1,-3,19:18.4
0,-3,19:18.4
6,-3,19:18.4
-8,-2,19:18.4
-3,-2,19:18.4
-2,-2,19:18.4
0,-2,19:18.4
1,-2,19:18.4
2,-2,19:18.4
5,-2,19:18.4
6,-2,19:18.4
-8,-1,19:18.4
-4,-1,19:18.4
-3,-1,19:18.4
1,-1,19:18.4
2,-1,19:18.4
3,-1,19:18.4
4,-1,19:18.4
5,-1,19:18.4
-9,0,19:18.4
-8,0,19:18.4
-7,0,19:18.4
-5,0,19:18.4
-4,0,19:18.4
3,0,19:18.4
4,0,19:18.4
5,0,19:18.4
-7,1,19:18.4
-6,1,19:18.4
-5,1,19:18.4
-4,1,19:18.4
3,1,19:18.4
4,1,19:18.4
5,1,19:18.4
6,1,19:18.4
-6,2,19:18.4
-5,2,19:18.4
-4,2,19:18.4
2,2,19:18.4
3,2,19:18.4
5,2,19:18.4
6,2,19:18.4
7,2,19:18.4
-6,3,19:18.4
-5,3,19:18.4
-4,3,19:18.4
-3,3,19:18.4
1,3,19:18.4
2,3,19:18.4
7,3,19:18.4
-8,4,19:18.4
-7,4,19:18.4
-3,4,19:18.4
-2,4,19:18.4
1,4,19:18.4
2,4,19:18.4
7,4,19:18.4
-8,5,19:18.4
-7,5,19:18.4
-2,5,19:18.4
-1,5,19:18.4
0,5,19:18.4
1,5,19:18.4
7,5,19:18.4
-1,6,19:18.4
0,6,19:18.4
1,6,19:18.4
7,6,19:18.4
8,6,19:18.4
-2,7,19:18.4
-1,7,19:18.4
1,7,19:18.4
2,7,19:18.4
3,7,19:18.4
5,7,19:18.4
6,7,19:18.4
7,7,19:18.4
-2,8,19:18.4
-1,8,19:18.4
2,8,19:18.4
3,8,19:18.4
-2,9,19:18.4
1,-6,20:18.4
-5,-5,20:18.4
-4,-5,20:18.4
0,-5,20:18.4
1,-5,20:18.4
-5,-4,20:18.4
-4,-4,20:18.4
0,-4,20:18.4
-3,-3,20:18.4
-2,-3,20:18.4
-1,-3,20:18.4
0,-3,20:18.4
4,-3,20:18.4
5,-3,20:18.4
-2,-2,20:18.4
-1,-2,20:18.4
0,-2,20:18.4
4,-2,20:18.4
5,-2,20:18.4
-8,-1,20:18.4
-7,-1,20:18.4
-3,-1,20:18.4
-2,-1,20:18.4
-1,-1,20:18.4
0,-1,20:18.4
1,-1,20:18.4
3,-1,20:18.4
4,-1,20:18.4
-7,0,20:18.4
-6,0,20:18.4
-5,0,20:18.4
-3,0,20:18.4
-2,0,20:18.4
1,0,20:18.4
2,0,20:18.4
3,0,20:18.4
-6,1,20:18.4
-5,1,20:18.4
-4,1,20:18.4
-3,1,20:18.4
1,1,20:18.4
2,1,20:18.4
3,1,20:18.4
4,1,20:18.4
-5,2,20:18.4
-4,2,20:18.4
-3,2,20:18.4
1,2,20:18.4
2,2,20:18.4
4,2,20:18.4
5,2,20:18.4
-6,3,20:18.4
-5,3,20:18.4
-3,3,20:18.4
-2,3,20:18.4
-1,3,20:18.4
0,3,20:18.4
1,3,20:18.4
5,3,20:18.4
6,3,20:18.4
-6,4,20:18.4
-5,4,20:18.4
-2,4,20:18.4
-1,4,20:18.4
0,4,20:18.4
-7,5,20:18.4
-6,5,20:18.4
-1,5,20:18.4
0,5,20:18.4
1,5,20:18.4
2,5,20:18.4
-2,6,20:18.4
-1,6,20:18.4
1,6,20:18.4
2,6,20:18.4
3,6,20:18.4
-3,7,20:18.4
-2,7,20:18.4
3,7,20:18.4
4,7,20:18.4
-3,8,20:18.4
1,-5,21:18.4
2,-5,21:18.4
-5,-4,21:18.4
1,-4,21:18.4
2,-4,21:18.4
4,-4,21:18.4
-5,-3,21:18.4
-4,-3,21:18.4
-3,-3,21:18.4
0,-3,21:18.4
1,-3,21:18.4
3,-3,21:18.4
4,-3,21:18.4
-7,-2,21:18.4
-4,-2,21:18.4
-3,-2,21:18.4
-2,-2,21:18.4
-1,-2,21:18.4
0,-2,21:18.4
2,-2,21:18.4
3,-2,21:18.4
-7,-1,21:18.4
-6,-1,21:18.4
-5,-1,21:18.4
-2,-1,21:18.4
-1,-1,21:18.4
0,-1,21:18.4
2,-1,21:18.4
3,-1,21:18.4
-5,0,21:18.4
-4,0,21:18.4
-2,0,21:18.4
-1,0,21:18.4
0,0,21:18.4
1,0,21:18.4
2,0,21:18.4
-4,1,21:18.4
-3,1,21:18.4
-2,1,21:18.4
0,1,21:18.4
1,1,21:18.4
2,1,21:18.4
-4,2,21:18.4
-3,2,21:18.4
-2,2,21:18.4
-1,2,21:18.4
0,2,21:18.4
1,2,21:18.4
2,2,21:18.4
3,2,21:18.4
4,2,21:18.4
-4,3,21:18.4
-3,3,21:18.4
-1,3,21:18.4
0,3,21:18.4
3,3,21:18.4
4,3,21:18.4
5,3,21:18.4
-5,4,21:18.4
-4,4,21:18.4
-2,4,21:18.4
-1,4,21:18.4
0,4,21:18.4
1,4,21:18.4
2,4,21:18.4
4,4,21:18.4
5,4,21:18.4
-6,5,21:18.4
-5,5,21:18.4
-3,5,21:18.4
-2,5,21:18.4
2,5,21:18.4
3,5,21:18.4
-6,6,21:18.4
-4,6,21:18.4
-3,6,21:18.4
-2,6,21:18.4
3,6,21:18.4
4,6,21:18.4
-4,7,21:18.4
-3,7,21:18.4
2,-4,22:18.4
3,-4,22:18.4
-6,-3,22:18.4
-5,-3,22:18.4
1,-3,22:18.4
2,-3,22:18.4
3,-3,22:18.4
-6,-2,22:18.4
-5,-2,22:18.4
-4,-2,22:18.4
0,-2,22:18.4
1,-2,22:18.4
2,-2,22:18.4
-5,-1,22:18.4
-4,-1,22:18.4
-3,-1,22:18.4
-2,-1,22:18.4
0,-1,22:18.4
1,-1,22:18.4
-4,0,22:18.4
-3,0,22:18.4
-2,0,22:18.4
-1,0,22:18.4
0,0,22:18.4
1,0,22:18.4
-2,1,22:18.4
-1,1,22:18.4
0,1,22:18.4
-2,2,22:18.4
-1,2,22:18.4
0,2,22:18.4
1,2,22:18.4
2,2,22:18.4
-3,3,22:18.4
-2,3,22:18.4
-1,3,22:18.4
0,3,22:18.4
1,3,22:18.4
2,3,22:18.4
3,3,22:18.4
-4,4,22:18.4
-3,4,22:18.4
-2,4,22:18.4
2,4,22:18.4
3,4,22:18.4
4,4,22:18.4
-5,5,22:18.4
-4,5,22:18.4
-3,5,22:18.4
3,5,22:18.4
4,5,22:18.4
-5,6,22:18.4
-4,6,22:18.4
