[META]
version=2.0
spawnOnBlockType=2
spawnSunlight=True
spawnDarkness=True
spawnWater=False
spawnLava=False
underFill=False
randomRotation=True
dig=True
tree=False
branch=False
needsFoundation=True
rarity=100
collisionPercentage=20
spawnElevationMin=0
spawnElevationMax=200
spawnInBiome=Custom
[DATA]
3,-5,-8:17.12
2,-4,-8:17.12
3,-4,-8:17.12
-1,0,-8:17.12
0,1,-8:17.12
4,1,-8:17.12
3,2,-8:17.12
5,2,-8:17.12
4,-5,-7:17.12
3,-4,-7:17.12
3,-3,-7:17.12
4,-3,-7:17.12
0,-2,-7:17.12
2,-2,-7:17.12
3,-2,-7:17.12
-1,-1,-7:17.12
0,-1,-7:17.12
1,-1,-7:17.12
0,0,-7:17.12
3,1,-7:17.12
4,1,-7:17.12
5,1,-7:17.12
3,2,-7:17.12
4,2,-7:17.12
3,3,-7:17.12
2,-4,-6:17.12
3,-4,-6:17.12
4,-4,-6:17.12
7,-4,-6:17.12
2,-3,-6:17.12
3,-3,-6:17.12
4,-3,-6:17.12
0,-2,-6:17.12
1,-2,-6:17.12
2,-2,-6:17.12
3,-2,-6:17.12
4,-2,-6:17.12
7,-2,-6:17.12
-1,-1,-6:17.12
0,-1,-6:17.12
1,-1,-6:17.12
2,-1,-6:17.12
-1,0,-6:17.12
0,0,-6:17.12
1,0,-6:17.12
3,1,-6:17.12
4,1,-6:17.12
3,2,-6:17.12
4,2,-6:17.12
5,2,-6:17.12
2,-4,-5:17.12
2,-3,-5:17.12
3,-3,-5:17.12
4,-3,-5:17.12
7,-3,-5:17.12
0,-2,-5:17.12
1,-2,-5:17.12
3,-2,-5:17.12
0,-1,-5:17.12
1,-1,-5:17.12
2,-1,-5:17.12
1,0,-5:17.12
4,0,-5:17.12
2,1,-5:17.12
3,1,-5:17.12
4,1,-5:17.12
5,1,-5:17.12
3,2,-5:17.12
4,2,-5:17.12
5,2,-5:17.12
3,-4,-4:17.12
2,-3,-4:17.12
3,-3,-4:17.12
4,-3,-4:17.12
6,-3,-4:17.12
0,-2,-4:17.12
1,-2,-4:17.12
2,-2,-4:17.12
3,-2,-4:17.12
4,-2,-4:17.12
0,-1,-4:17.12
1,-1,-4:17.12
-1,0,-4:17.12
0,0,-4:17.12
1,0,-4:17.12
3,0,-4:17.12
4,0,-4:17.12
5,0,-4:17.12
2,1,-4:17.12
3,1,-4:17.12
4,1,-4:17.12
5,1,-4:17.12
3,2,-4:17.12
4,2,-4:17.12
5,2,-4:17.12
2,-4,-3:17.12
2,-3,-3:17.12
3,-3,-3:17.12
4,-3,-3:17.12
6,-3,-3:17.12
3,-2,-3:17.12
4,-2,-3:17.12
0,-1,-3:17.12
1,-1,-3:17.12
3,-1,-3:17.12
1,0,-3:17.12
2,0,-3:17.12
3,0,-3:17.12
4,0,-3:17.12
2,1,-3:17.12
4,1,-3:17.12
5,1,-3:17.12
3,2,-3:17.12
4,2,-3:17.12
2,-4,-2:17.12
3,-4,-2:17.12
4,-4,-2:17.12
1,-3,-2:17.12
2,-3,-2:17.12
3,-3,-2:17.12
4,-3,-2:17.12
5,-3,-2:17.12
6,-3,-2:17.12
0,-2,-2:17.12
1,-2,-2:17.12
2,-2,-2:17.12
3,-2,-2:17.12
4,-2,-2:17.12
5,-2,-2:17.12
6,-2,-2:17.12
0,-1,-2:17.12
1,-1,-2:17.12
2,-1,-2:17.12
3,-1,-2:17.12
4,-1,-2:17.12
5,-1,-2:17.12
6,-1,-2:17.12
0,0,-2:17.12
1,0,-2:17.12
2,0,-2:17.12
3,0,-2:17.12
4,0,-2:17.12
5,0,-2:17.12
6,0,-2:17.12
0,1,-2:17.12
1,1,-2:17.12
2,1,-2:17.12
3,1,-2:17.12
4,1,-2:17.12
5,1,-2:17.12
6,1,-2:17.12
2,2,-2:17.12
3,2,-2:17.12
4,2,-2:17.12
5,2,-2:17.12
2,-4,-1:17.12
3,-4,-1:17.12
4,-4,-1:17.12
1,-3,-1:17.12
2,-3,-1:17.12
5,-3,-1:17.12
6,-3,-1:17.12
1,-2,-1:17.12
3,-2,-1:17.12
6,-2,-1:17.12
1,-1,-1:17.12
6,-1,-1:17.12
0,0,-1:17.12
1,0,-1:17.12
6,0,-1:17.12
1,1,-1:17.12
2,1,-1:17.12
3,1,-1:17.12
4,1,-1:17.12
5,1,-1:17.12
6,1,-1:17.12
3,2,-1:17.12
4,2,-1:17.12
3,-4,0:17.12
4,-4,0:17.12
1,-3,0:17.12
2,-3,0:17.12
5,-3,0:17.12
6,-3,0:17.12
1,-2,0:17.12
6,-2,0:17.12
1,-1,0:17.12
6,-1,0:17.12
1,0,0:17.12
2,0,0:17.12
6,0,0:17.12
2,1,0:17.12
3,1,0:17.12
4,1,0:17.12
5,1,0:17.12
6,1,0:17.12
3,-4,1:17.12
4,-4,1:17.12
1,-3,1:17.12
2,-3,1:17.12
5,-3,1:17.12
6,-3,1:17.12
1,-2,1:17.12
6,-2,1:17.12
1,-1,1:17.12
6,-1,1:17.12
1,0,1:17.12
2,0,1:17.12
6,0,1:17.12
2,1,1:17.12
3,1,1:17.12
4,1,1:17.12
5,1,1:17.12
3,-4,2:17.12
4,-4,2:17.12
1,-3,2:17.12
2,-3,2:17.12
5,-3,2:17.12
1,-2,2:17.12
6,-2,2:17.12
1,-1,2:17.12
6,-1,2:17.12
1,0,2:17.12
2,0,2:17.12
6,0,2:17.12
2,1,2:17.12
3,1,2:17.12
4,1,2:17.12
5,1,2:17.12
3,-4,3:17.12
4,-4,3:17.12
1,-3,3:17.12
2,-3,3:17.12
5,-3,3:17.12
1,-2,3:17.12
6,-2,3:17.12
1,-1,3:17.12
6,-1,3:17.12
1,0,3:17.12
2,0,3:17.12
5,0,3:17.12
6,0,3:17.12
2,1,3:17.12
3,1,3:17.12
4,1,3:17.12
5,1,3:17.12
3,-4,4:17.12
4,-4,4:17.12
1,-3,4:17.12
2,-3,4:17.12
5,-3,4:17.12
1,-2,4:17.12
6,-2,4:17.12
1,-1,4:17.12
6,-1,4:17.12
1,0,4:17.12
2,0,4:17.12
5,0,4:17.12
2,1,4:17.12
3,1,4:17.12
4,1,4:17.12
5,1,4:17.12
3,-4,5:17.12
4,-4,5:17.12
2,-3,5:17.12
3,-3,5:17.12
4,-3,5:17.12
5,-3,5:17.12
1,-2,5:17.12
5,-2,5:17.12
6,-2,5:17.12
1,-1,5:17.12
5,-1,5:17.12
6,-1,5:17.12
1,0,5:17.12
2,0,5:17.12
5,0,5:17.12
2,1,5:17.12
3,1,5:17.12
4,1,5:17.12
3,-4,6:17.12
4,-4,6:17.12
2,-3,6:17.12
3,-3,6:17.12
4,-3,6:17.12
5,-3,6:17.12
1,-2,6:17.12
5,-2,6:17.12
1,-1,6:17.12
5,-1,6:17.12
1,0,6:17.12
2,0,6:17.12
5,0,6:17.12
3,1,6:17.12
4,1,6:17.12
3,-4,7:17.12
2,-3,7:17.12
3,-3,7:17.12
4,-3,7:17.12
5,-3,7:17.12
1,-2,7:17.12
5,-2,7:17.12
1,-1,7:17.12
5,-1,7:17.12
2,0,7:17.12
3,0,7:17.12
4,0,7:17.12
5,0,7:17.12
3,1,7:17.12
4,1,7:17.12
2,-3,8:17.12
3,-3,8:17.12
4,-3,8:17.12
5,-3,8:17.12
1,-2,8:17.12
5,-2,8:17.12
1,-1,8:17.12
5,-1,8:17.12
2,0,8:17.12
3,0,8:17.12
4,0,8:17.12
5,0,8:17.12
3,1,8:17.12
4,1,8:17.12
2,-3,9:17.12
3,-3,9:17.12
4,-3,9:17.12
5,-3,9:17.12
1,-2,9:17.12
2,-2,9:17.12
5,-2,9:17.12
1,-1,9:17.12
2,-1,9:17.12
5,-1,9:17.12
2,0,9:17.12
3,0,9:17.12
4,0,9:17.12
5,0,9:17.12
2,-3,10:17.12
3,-3,10:17.12
4,-3,10:17.12
5,-3,10:17.12
1,-2,10:17.12
2,-2,10:17.12
3,-2,10:17.12
4,-2,10:17.12
5,-2,10:17.12
1,-1,10:17.12
2,-1,10:17.12
3,-1,10:17.12
4,-1,10:17.12
5,-1,10:17.12
2,0,10:17.12
3,0,10:17.12
4,0,10:17.12
4,1,10:17.12
2,-3,11:17.12
3,-3,11:17.12
4,-3,11:17.12
1,-2,11:17.12
2,-2,11:17.12
5,-2,11:17.12
1,-1,11:17.12
2,-1,11:17.12
5,-1,11:17.12
2,0,11:17.12
3,0,11:17.12
4,0,11:17.12
3,1,11:17.12
4,1,11:17.12
2,-3,12:17.12
3,-3,12:17.12
4,-3,12:17.12
1,-2,12:17.12
2,-2,12:17.12
4,-2,12:17.12
5,-2,12:17.12
1,-1,12:17.12
2,-1,12:17.12
5,-1,12:17.12
2,0,12:17.12
4,0,12:17.12
2,1,12:17.12
3,1,12:17.12
4,1,12:17.12
4,4,12:18.14
2,-3,13:17.12
4,-3,13:17.12
2,-2,13:17.12
3,-2,13:17.12
4,-2,13:17.12
1,-1,13:17.12
2,-1,13:17.12
4,-1,13:17.12
5,-1,13:17.12
2,0,13:17.12
4,0,13:17.12
2,1,13:17.12
3,1,13:17.12
4,1,13:17.12
3,3,13:18.14
2,4,13:18.14
3,4,13:18.14
2,5,13:18.14
8,-9,14:18.14
4,-8,14:18.6
2,-3,14:17.12
4,-3,14:17.12
2,-2,14:17.12
3,-2,14:17.12
4,-2,14:17.12
-3,-1,14:18.14
-2,-1,14:18.14
1,-1,14:17.12
4,-1,14:17.12
5,-1,14:17.12
11,-1,14:18.14
-2,0,14:18.14
1,0,14:17.12
2,0,14:17.12
4,0,14:17.12
5,0,14:17.12
-3,1,14:18.14
2,1,14:17.12
3,1,14:17.12
4,1,14:17.12
-3,2,14:18.14
-2,2,14:18.14
2,2,14:18.14
3,2,14:18.14
4,2,14:18.14
-3,3,14:18.14
-2,3,14:18.14
1,3,14:18.14
2,3,14:18.14
-2,4,14:18.14
0,4,14:18.14
1,4,14:18.14
2,4,14:18.14
-3,5,14:18.14
-2,5,14:18.14
-1,5,14:18.14
0,5,14:18.14
1,5,14:18.14
6,-11,15:18.14
2,-10,15:18.14
6,-10,15:18.14
2,-9,15:18.14
5,-9,15:18.14
2,-8,15:18.14
3,-8,15:18.14
4,-8,15:18.14
5,-8,15:18.14
3,-7,15:18.14
4,-7,15:18.14
3,-6,15:18.14
-6,-3,15:18.14
-5,-3,15:18.14
2,-3,15:17.12
4,-3,15:17.12
-5,-2,15:18.14
-4,-2,15:18.14
-3,-2,15:18.14
2,-2,15:17.12
3,-2,15:17.12
4,-2,15:17.12
10,-2,15:18.14
11,-2,15:18.14
12,-2,15:18.14
14,-2,15:18.14
-3,-1,15:18.14
-2,-1,15:18.14
-1,-1,15:18.14
1,-1,15:17.12
2,-1,15:17.12
4,-1,15:17.12
5,-1,15:17.12
8,-1,15:18.14
10,-1,15:18.14
11,-1,15:18.14
14,-1,15:18.14
-5,0,15:18.14
-4,0,15:18.14
-3,0,15:18.14
-2,0,15:18.14
-1,0,15:18.14
0,0,15:17.12
1,0,15:17.12
2,0,15:17.12
4,0,15:17.12
5,0,15:17.12
9,0,15:18.14
10,0,15:18.14
11,0,15:18.14
-7,1,15:18.14
-6,1,15:18.14
-5,1,15:18.14
-2,1,15:18.14
-1,1,15:18.14
2,1,15:17.12
3,1,15:17.12
4,1,15:17.12
11,1,15:18.14
12,1,15:18.14
-7,2,15:18.14
-2,2,15:18.14
-1,2,15:18.14
1,2,15:18.14
2,2,15:18.14
-2,3,15:18.14
-1,3,15:18.14
0,3,15:18.14
1,3,15:18.14
-2,4,15:18.14
-1,4,15:18.14
0,4,15:18.14
3,4,15:18.14
-3,5,15:18.14
-2,5,15:18.14
-1,5,15:18.14
4,5,15:18.14
-1,6,15:18.14
0,6,15:18.14
2,6,15:18.14
3,6,15:18.14
4,6,15:18.14
2,7,15:18.14
4,7,15:18.14
5,7,15:18.14
5,8,15:18.14
5,9,15:18.14
1,-11,16:18.14
6,-11,16:18.14
1,-10,16:18.14
6,-10,16:18.14
1,-9,16:18.14
2,-9,16:18.14
6,-9,16:18.14
2,-8,16:18.14
5,-8,16:18.14
6,-8,16:18.14
9,-8,16:18.14
10,-8,16:18.14
2,-7,16:18.14
5,-7,16:18.14
10,-7,16:18.14
2,-6,16:18.14
3,-6,16:18.14
4,-6,16:18.14
5,-6,16:18.14
10,-6,16:18.14
3,-5,16:18.14
4,-5,16:18.14
-6,-4,16:18.14
3,-4,16:18.14
4,-4,16:18.14
-6,-3,16:18.14
-5,-3,16:18.14
-4,-3,16:18.14
-1,-3,16:18.14
0,-3,16:18.14
1,-3,16:17.12
3,-3,16:17.12
4,-3,16:17.12
11,-3,16:18.14
15,-3,16:18.14
-4,-2,16:18.14
-3,-2,16:18.14
-2,-2,16:18.14
-1,-2,16:18.14
0,-2,16:18.14
1,-2,16:17.12
2,-2,16:17.12
3,-2,16:17.12
4,-2,16:17.12
8,-2,16:18.14
9,-2,16:18.14
10,-2,16:18.14
11,-2,16:18.14
13,-2,16:18.14
-2,-1,16:18.14
-1,-1,16:18.14
0,-1,16:18.14
1,-1,16:17.12
2,-1,16:17.12
3,-1,16:18.14
4,-1,16:17.12
5,-1,16:17.12
6,-1,16:17.12
7,-1,16:18.14
8,-1,16:18.14
13,-1,16:18.14
-3,0,16:18.14
-2,0,16:18.14
-1,0,16:18.14
0,0,16:17.12
1,0,16:17.12
2,0,16:17.12
3,0,16:17.12
4,0,16:17.12
5,0,16:17.12
6,0,16:17.12
7,0,16:18.14
8,0,16:18.14
9,0,16:18.14
10,0,16:18.14
13,0,16:18.14
-5,1,16:18.14
-4,1,16:18.14
-3,1,16:18.14
-1,1,16:18.14
0,1,16:18.14
1,1,16:18.14
2,1,16:17.12
3,1,16:17.12
4,1,16:17.12
5,1,16:17.12
10,1,16:18.14
11,1,16:18.14
12,1,16:18.14
-7,2,16:18.14
-6,2,16:18.14
-5,2,16:18.14
-2,2,16:18.14
-1,2,16:18.14
0,2,16:18.14
1,2,16:18.14
2,2,16:17.12
3,2,16:18.14
4,2,16:17.12
5,2,16:17.12
-3,3,16:18.14
-2,3,16:18.14
-1,3,16:18.14
0,3,16:18.14
1,3,16:18.14
3,3,16:18.14
4,3,16:18.14
-4,4,16:18.14
-2,4,16:18.14
-1,4,16:18.14
0,4,16:18.14
1,4,16:18.14
2,4,16:18.14
3,4,16:18.14
4,4,16:18.14
-5,5,16:18.14
-4,5,16:18.14
-3,5,16:18.14
0,5,16:18.14
1,5,16:18.14
2,5,16:18.14
4,5,16:18.14
5,5,16:18.14
-4,6,16:18.14
-3,6,16:18.14
0,6,16:18.14
1,6,16:18.14
2,6,16:18.14
4,6,16:18.14
5,6,16:18.14
0,7,16:18.14
1,7,16:18.14
2,7,16:18.14
5,7,16:18.14
0,8,16:18.14
5,8,16:18.14
6,8,16:18.14
6,9,16:18.14
0,-10,17:18.14
0,-9,17:18.6
1,-9,17:18.14
6,-9,17:18.14
7,-9,17:18.14
1,-8,17:18.14
6,-8,17:18.14
8,-8,17:18.14
9,-8,17:18.14
1,-7,17:18.14
2,-7,17:18.14
5,-7,17:18.14
6,-7,17:18.14
9,-7,17:18.14
2,-6,17:18.14
5,-6,17:18.14
9,-6,17:18.14
10,-6,17:18.14
2,-5,17:18.14
4,-5,17:18.14
5,-5,17:18.14
10,-5,17:18.14
-6,-4,17:18.6
-5,-4,17:18.14
-4,-4,17:18.14
0,-4,17:17.0
1,-4,17:18.14
2,-4,17:18.14
3,-4,17:18.14
4,-4,17:18.14
-4,-3,17:18.14
-3,-3,17:18.14
-2,-3,17:18.14
0,-3,17:17.0
1,-3,17:17.0
2,-3,17:18.14
3,-3,17:18.14
4,-3,17:18.14
9,-3,17:18.14
10,-3,17:18.14
11,-3,17:18.14
-2,-2,17:18.14
-1,-2,17:18.14
0,-2,17:18.14
1,-2,17:17.0
2,-2,17:17.12
3,-2,17:17.12
4,-2,17:17.12
7,-2,17:18.14
8,-2,17:18.14
9,-2,17:18.14
11,-2,17:18.14
12,-2,17:18.14
13,-2,17:18.14
0,-1,17:18.14
1,-1,17:18.14
2,-1,17:18.14
3,-1,17:17.12
4,-1,17:17.12
5,-1,17:17.12
6,-1,17:18.14
7,-1,17:18.14
12,-1,17:18.14
-2,0,17:18.14
-1,0,17:18.14
0,0,17:18.14
1,0,17:17.12
2,0,17:18.14
4,0,17:17.12
5,0,17:17.12
6,0,17:18.14
7,0,17:18.14
8,0,17:18.14
12,0,17:18.14
-4,1,17:18.14
-3,1,17:18.14
-2,1,17:18.14
-1,1,17:18.14
0,1,17:18.14
1,1,17:18.14
2,1,17:17.12
3,1,17:17.12
4,1,17:17.12
5,1,17:17.12
8,1,17:18.14
9,1,17:18.14
10,1,17:18.14
11,1,17:18.14
-6,2,17:18.14
-5,2,17:18.14
-4,2,17:18.14
-3,2,17:18.14
-2,2,17:18.14
1,2,17:18.14
2,2,17:17.12
3,2,17:17.12
4,2,17:18.14
5,2,17:17.12
6,2,17:17.12
11,2,17:18.14
12,2,17:18.14
-6,3,17:18.14
-5,3,17:18.14
-4,3,17:18.14
-3,3,17:18.14
1,3,17:18.14
2,3,17:18.14
3,3,17:18.14
4,3,17:18.14
-5,4,17:18.14
1,4,17:18.14
2,4,17:18.14
3,4,17:18.14
4,4,17:18.14
5,4,17:18.14
-5,5,17:18.14
-4,5,17:18.14
-3,5,17:18.14
-2,5,17:18.14
-1,5,17:18.14
1,5,17:18.14
2,5,17:18.14
3,5,17:18.14
4,5,17:18.14
5,5,17:18.14
-4,6,17:18.14
-3,6,17:18.14
-2,6,17:18.14
-1,6,17:18.14
0,6,17:18.14
1,6,17:18.14
2,6,17:18.14
3,6,17:18.14
4,6,17:18.14
5,6,17:18.14
6,6,17:18.14
-1,7,17:18.14
0,7,17:18.14
1,7,17:18.14
2,7,17:18.14
3,7,17:18.14
4,7,17:18.14
6,7,17:18.14
0,8,17:18.14
1,8,17:18.14
2,8,17:18.14
3,8,17:18.14
4,8,17:18.14
5,8,17:17.0
6,8,17:18.14
7,8,17:18.14
-1,9,17:18.14
0,9,17:18.14
4,9,17:18.14
5,9,17:18.14
6,9,17:18.14
7,9,17:18.14
-1,10,17:18.14
6,10,17:18.14
-1,-10,18:18.14
0,-10,18:18.6
7,-10,18:18.14
0,-9,18:18.6
7,-9,18:18.14
8,-9,18:18.14
10,-9,18:18.14
11,-9,18:18.14
0,-8,18:18.14
6,-8,18:18.6
7,-8,18:18.14
8,-8,18:18.14
9,-8,18:18.14
11,-8,18:18.14
0,-7,18:18.14
1,-7,18:18.14
6,-7,18:18.14
7,-7,18:18.14
8,-7,18:18.14
9,-7,18:18.14
11,-7,18:18.14
1,-6,18:18.14
6,-6,18:18.14
9,-6,18:18.14
10,-6,18:18.14
11,-6,18:18.14
-6,-5,18:18.6
-5,-5,18:18.6
1,-5,18:18.14
2,-5,18:18.14
3,-5,18:17.0
5,-5,18:18.14
6,-5,18:18.14
10,-5,18:18.14
11,-5,18:18.14
-5,-4,18:18.6
-4,-4,18:18.14
-3,-4,18:18.14
0,-4,18:17.0
1,-4,18:18.14
2,-4,18:18.14
3,-4,18:17.0
4,-4,18:17.0
5,-4,18:18.14
9,-4,18:18.14
10,-4,18:18.14
11,-4,18:18.14
-3,-3,18:18.14
-2,-3,18:18.14
-1,-3,18:18.14
0,-3,18:17.0
1,-3,18:18.14
2,-3,18:18.14
3,-3,18:17.0
4,-3,18:17.0
5,-3,18:18.14
7,-3,18:18.14
8,-3,18:18.14
9,-3,18:18.14
11,-3,18:18.14
12,-3,18:18.14
-1,-2,18:18.14
0,-2,18:18.14
1,-2,18:18.14
2,-2,18:18.14
3,-2,18:18.14
4,-2,18:18.14
5,-2,18:18.14
6,-2,18:18.14
7,-2,18:18.14
11,-2,18:18.14
12,-2,18:18.14
13,-2,18:18.14
-3,-1,18:18.14
-2,-1,18:18.14
-1,-1,18:18.14
0,-1,18:17.0
1,-1,18:18.14
2,-1,18:18.14
3,-1,18:18.14
5,-1,18:17.0
6,-1,18:17.0
7,-1,18:17.0
12,-1,18:18.14
-4,0,18:18.14
-3,0,18:18.14
-2,0,18:18.14
-1,0,18:17.0
0,0,18:17.0
1,0,18:18.14
2,0,18:18.14
3,0,18:18.14
4,0,18:18.14
5,0,18:18.14
6,0,18:18.14
12,0,18:18.14
-6,1,18:18.14
-5,1,18:18.14
-4,1,18:18.14
-3,1,18:18.14
-2,1,18:18.14
-1,1,18:18.14
0,1,18:18.14
1,1,18:18.14
2,1,18:18.14
3,1,18:18.14
4,1,18:18.14
5,1,18:17.0
6,1,18:18.14
7,1,18:18.14
8,1,18:18.14
9,1,18:18.14
-7,2,18:18.14
-6,2,18:18.14
-5,2,18:18.14
-4,2,18:18.14
-3,2,18:18.14
-2,2,18:18.14
-1,2,18:18.14
2,2,18:18.14
3,2,18:18.14
4,2,18:18.14
5,2,18:17.0
6,2,18:17.0
9,2,18:18.14
10,2,18:18.14
11,2,18:18.14
12,2,18:18.14
13,2,18:18.14
-6,3,18:18.14
-5,3,18:18.14
-4,3,18:18.14
-3,3,18:18.14
1,3,18:18.14
2,3,18:17.0
3,3,18:17.0
4,3,18:18.14
5,3,18:18.14
6,3,18:17.0
7,3,18:17.0
12,3,18:18.14
13,3,18:18.14
-6,4,18:18.14
-5,4,18:18.14
-4,4,18:18.14
-2,4,18:18.14
-1,4,18:18.14
0,4,18:18.14
1,4,18:18.14
2,4,18:17.0
4,4,18:18.14
5,4,18:18.14
6,4,18:18.14
-6,5,18:18.14
-5,5,18:18.14
-4,5,18:18.14
-3,5,18:18.14
-2,5,18:18.14
-1,5,18:18.14
0,5,18:18.14
1,5,18:18.14
2,5,18:18.14
4,5,18:18.14
5,5,18:18.14
6,5,18:18.14
0,6,18:18.14
1,6,18:18.14
2,6,18:18.14
3,6,18:18.14
4,6,18:18.14
5,6,18:18.14
6,6,18:18.14
7,6,18:18.14
0,7,18:18.14
3,7,18:18.14
4,7,18:18.14
5,7,18:18.14
6,7,18:18.14
7,7,18:18.14
-1,8,18:18.14
0,8,18:18.14
5,8,18:18.14
6,8,18:18.14
7,8,18:18.14
-1,9,18:18.14
5,9,18:18.14
6,9,18:18.14
-2,10,18:18.14
-1,10,18:18.14
5,10,18:18.14
9,-12,19:18.14
9,-11,19:18.14
-2,-10,19:18.14
-1,-10,19:18.14
8,-10,19:18.14
9,-10,19:18.14
-1,-9,19:18.6
8,-9,19:18.14
9,-9,19:18.14
10,-9,19:18.14
11,-9,19:18.14
-1,-8,19:18.14
0,-8,19:18.14
7,-8,19:18.6
8,-8,19:18.6
9,-8,19:18.14
10,-8,19:18.14
0,-7,19:18.14
7,-7,19:18.14
8,-7,19:18.14
9,-7,19:18.14
10,-7,19:18.14
11,-7,19:18.14
14,-7,19:18.14
-7,-6,19:18.6
-6,-6,19:18.6
0,-6,19:18.14
1,-6,19:18.14
6,-6,19:18.14
7,-6,19:18.14
9,-6,19:18.14
10,-6,19:18.14
11,-6,19:18.14
12,-6,19:18.14
13,-6,19:18.14
-6,-5,19:18.6
-5,-5,19:18.6
-4,-5,19:18.14
-1,-5,19:17.0
0,-5,19:18.14
1,-5,19:18.14
3,-5,19:17.0
6,-5,19:18.14
9,-5,19:18.14
10,-5,19:18.14
11,-5,19:18.14
-4,-4,19:18.14
-3,-4,19:18.14
-2,-4,19:18.14
-1,-4,19:17.0
0,-4,19:17.0
1,-4,19:18.14
2,-4,19:18.14
3,-4,19:17.0
4,-4,19:17.0
5,-4,19:18.14
6,-4,19:18.14
7,-4,19:18.14
8,-4,19:18.14
9,-4,19:18.14
10,-4,19:18.14
11,-4,19:18.14
12,-4,19:18.14
-2,-3,19:18.14
-1,-3,19:18.14
0,-3,19:18.14
1,-3,19:18.14
2,-3,19:18.14
3,-3,19:18.14
4,-3,19:18.14
5,-3,19:18.14
6,-3,19:18.14
7,-3,19:18.14
11,-3,19:18.14
12,-3,19:18.14
-5,-2,19:18.6
-4,-2,19:18.14
-3,-2,19:18.14
-2,-2,19:18.14
1,-2,19:18.14
2,-2,19:18.14
3,-2,19:18.14
4,-2,19:18.14
5,-2,19:18.14
11,-2,19:18.14
12,-2,19:18.14
13,-2,19:18.14
-7,-1,19:18.14
-6,-1,19:18.14
-5,-1,19:18.14
-4,-1,19:18.14
-3,-1,19:18.14
-1,-1,19:17.0
2,-1,19:18.14
3,-1,19:18.14
4,-1,19:18.14
5,-1,19:18.14
6,-1,19:17.0
7,-1,19:17.0
8,-1,19:17.0
12,-1,19:18.14
-7,0,19:18.14
-6,0,19:18.14
-5,0,19:18.14
-4,0,19:18.14
-2,0,19:17.0
-1,0,19:17.0
0,0,19:17.0
2,0,19:18.14
3,0,19:18.14
4,0,19:18.14
5,0,19:18.14
12,0,19:18.14
-8,1,19:18.14
-7,1,19:18.14
-6,1,19:18.14
0,1,19:18.14
1,1,19:18.14
2,1,19:18.14
3,1,19:18.14
4,1,19:18.14
5,1,19:18.14
6,1,19:18.14
7,1,19:18.14
12,1,19:18.14
-10,2,19:18.14
-9,2,19:18.14
-8,2,19:18.14
-7,2,19:18.14
-6,2,19:18.14
-5,2,19:18.14
-4,2,19:18.14
-3,2,19:18.14
-2,2,19:18.14
-1,2,19:18.14
0,2,19:18.14
1,2,19:18.14
2,2,19:18.14
4,2,19:18.14
5,2,19:18.14
6,2,19:17.0
7,2,19:17.0
8,2,19:18.14
9,2,19:18.14
10,2,19:18.14
13,2,19:18.14
-10,3,19:18.14
-9,3,19:18.14
-8,3,19:18.14
-7,3,19:18.14
-6,3,19:18.14
-5,3,19:18.14
-4,3,19:18.14
-3,3,19:18.14
-2,3,19:18.14
-1,3,19:18.14
0,3,19:18.14
1,3,19:18.14
2,3,19:17.0
3,3,19:17.0
5,3,19:18.14
6,3,19:18.14
7,3,19:17.0
10,3,19:18.14
11,3,19:18.14
12,3,19:18.6
-7,4,19:18.14
-6,4,19:18.14
-5,4,19:18.14
-4,4,19:18.14
0,4,19:18.14
1,4,19:18.14
2,4,19:18.14
3,4,19:18.14
5,4,19:18.14
6,4,19:18.14
7,4,19:18.14
8,4,19:17.0
13,4,19:18.14
14,4,19:18.14
17,4,19:18.14
-7,5,19:18.14
0,5,19:18.14
2,5,19:18.14
3,5,19:18.14
4,5,19:18.14
5,5,19:18.14
6,5,19:18.14
7,5,19:18.14
-1,6,19:18.14
0,6,19:18.14
4,6,19:18.14
5,6,19:18.14
6,6,19:18.14
7,6,19:18.14
8,6,19:18.14
-1,7,19:18.14
5,7,19:18.14
6,7,19:18.14
7,7,19:18.14
8,7,19:18.14
-2,8,19:18.14
-1,8,19:18.14
6,8,19:18.14
7,8,19:18.14
8,8,19:18.14
-2,9,19:18.14
6,9,19:18.14
-2,10,19:18.14
10,-12,20:18.14
9,-11,20:18.14
10,-11,20:18.14
-2,-10,20:18.14
8,-10,20:18.6
9,-10,20:18.14
10,-10,20:18.14
-2,-9,20:18.6
-1,-9,20:18.6
8,-9,20:18.6
9,-9,20:18.6
10,-9,20:18.14
11,-9,20:18.14
-2,-8,20:18.14
-1,-8,20:18.14
8,-8,20:18.6
9,-8,20:18.6
10,-8,20:18.6
11,-8,20:18.6
-8,-7,20:18.6
-1,-7,20:18.14
7,-7,20:18.14
8,-7,20:18.14
10,-7,20:18.6
11,-7,20:18.6
12,-7,20:18.6
13,-7,20:18.6
-6,-6,20:18.6
-5,-6,20:18.6
-4,-6,20:18.14
-2,-6,20:17.0
-1,-6,20:18.14
0,-6,20:18.14
3,-6,20:17.0
7,-6,20:18.14
8,-6,20:18.14
9,-6,20:18.6
10,-6,20:18.6
11,-6,20:18.6
-4,-5,20:18.14
-2,-5,20:18.14
-1,-5,20:17.0
0,-5,20:18.14
3,-5,20:17.0
4,-5,20:17.0
6,-5,20:18.14
7,-5,20:18.14
8,-5,20:18.14
9,-5,20:18.14
10,-5,20:18.14
11,-5,20:18.14
12,-5,20:18.6
-2,-4,20:18.14
-1,-4,20:18.14
0,-4,20:18.14
1,-4,20:18.14
2,-4,20:18.14
3,-4,20:18.14
4,-4,20:18.14
5,-4,20:18.14
6,-4,20:18.14
7,-4,20:18.14
10,-4,20:18.14
11,-4,20:18.14
12,-4,20:18.6
-12,-3,20:18.6
-3,-3,20:18.14
-2,-3,20:18.14
-1,-3,20:18.14
0,-3,20:18.14
1,-3,20:18.14
2,-3,20:18.14
3,-3,20:18.14
4,-3,20:18.14
5,-3,20:18.14
6,-3,20:18.14
10,-3,20:18.14
11,-3,20:18.14
12,-3,20:18.6
13,-3,20:18.6
-12,-2,20:18.6
-5,-2,20:18.6
-4,-2,20:18.14
-3,-2,20:18.14
-2,-2,20:18.14
-1,-2,20:18.14
0,-2,20:18.14
1,-2,20:18.14
2,-2,20:18.14
3,-2,20:18.14
4,-2,20:18.14
5,-2,20:18.14
6,-2,20:18.14
7,-2,20:17.0
11,-2,20:18.14
12,-2,20:18.14
13,-2,20:18.14
-6,-1,20:18.14
-5,-1,20:18.14
-4,-1,20:18.14
1,-1,20:18.14
2,-1,20:18.14
3,-1,20:18.14
4,-1,20:18.14
5,-1,20:18.14
6,-1,20:18.14
7,-1,20:17.0
8,-1,20:17.0
9,-1,20:17.0
11,-1,20:18.14
12,-1,20:18.14
13,-1,20:18.14
-8,0,20:18.14
-7,0,20:18.14
-6,0,20:18.14
-3,0,20:17.0
-2,0,20:17.0
-1,0,20:17.0
1,0,20:18.14
2,0,20:18.14
4,0,20:18.14
5,0,20:18.14
6,0,20:18.14
12,0,20:18.14
-10,1,20:18.14
-9,1,20:18.14
-8,1,20:18.14
-7,1,20:18.14
-6,1,20:18.14
-5,1,20:18.14
-4,1,20:18.14
-3,1,20:18.14
-2,1,20:18.14
-1,1,20:18.14
0,1,20:18.14
1,1,20:18.14
2,1,20:18.14
3,1,20:18.14
4,1,20:18.14
5,1,20:18.14
6,1,20:18.14
12,1,20:18.14
-11,2,20:18.14
-10,2,20:18.14
-9,2,20:18.14
-8,2,20:18.14
-7,2,20:18.14
-6,2,20:18.14
-5,2,20:18.14
-4,2,20:18.14
-3,2,20:18.14
-2,2,20:18.14
-1,2,20:18.14
0,2,20:18.14
1,2,20:18.14
2,2,20:18.14
3,2,20:18.14
4,2,20:18.14
5,2,20:18.14
6,2,20:18.14
7,2,20:18.14
8,2,20:18.14
-2,3,20:18.14
-1,3,20:18.14
0,3,20:18.14
1,3,20:18.14
2,3,20:18.14
3,3,20:18.14
5,3,20:18.14
6,3,20:18.14
7,3,20:17.0
8,3,20:17.0
9,3,20:18.14
10,3,20:18.14
11,3,20:18.14
-5,4,20:18.14
-4,4,20:18.14
-2,4,20:18.14
-1,4,20:18.14
0,4,20:18.14
2,4,20:17.0
3,4,20:17.0
5,4,20:18.14
6,4,20:18.14
7,4,20:18.14
8,4,20:17.0
11,4,20:18.14
12,4,20:18.6
13,4,20:18.6
17,4,20:18.14
-7,5,20:18.14
-6,5,20:18.14
-5,5,20:18.14
-1,5,20:18.14
0,5,20:18.14
2,5,20:17.0
3,5,20:17.0
4,5,20:18.14
5,5,20:18.14
6,5,20:18.14
7,5,20:18.14
8,5,20:18.14
15,5,20:18.14
-7,6,20:18.14
-1,6,20:18.14
5,6,20:18.14
6,6,20:18.14
7,6,20:18.14
8,6,20:18.14
-2,7,20:18.14
-1,7,20:18.14
6,7,20:18.14
7,7,20:18.14
8,7,20:18.14
9,7,20:18.14
-2,8,20:18.14
6,8,20:18.14
7,8,20:18.14
8,8,20:18.14
9,8,20:18.14
-3,9,20:18.6
6,9,20:18.14
-3,10,20:18.6
11,-13,21:18.14
-4,-12,21:18.14
-4,-11,21:18.14
-3,-11,21:18.14
11,-11,21:18.14
-3,-10,21:18.6
9,-10,21:18.6
10,-10,21:18.14
11,-10,21:18.14
12,-10,21:18.14
-3,-9,21:18.6
-2,-9,21:18.6
9,-9,21:18.6
10,-9,21:18.14
11,-9,21:18.14
-8,-8,21:18.6
-7,-8,21:18.6
-2,-8,21:18.14
9,-8,21:18.6
10,-8,21:18.6
11,-8,21:18.6
12,-8,21:18.6
-7,-7,21:18.6
-6,-7,21:18.6
-5,-7,21:18.6
-2,-7,21:18.14
3,-7,21:17.0
8,-7,21:18.14
9,-7,21:18.6
10,-7,21:18.6
11,-7,21:18.6
12,-7,21:18.6
-5,-6,21:18.6
-4,-6,21:18.14
-3,-6,21:18.14
-2,-6,21:17.0
-1,-6,21:18.14
3,-6,21:17.0
6,-6,21:18.14
7,-6,21:18.14
8,-6,21:18.14
9,-6,21:18.6
10,-6,21:18.6
11,-6,21:18.6
12,-6,21:18.6
-2,-5,21:18.14
-1,-5,21:18.14
0,-5,21:18.14
1,-5,21:18.14
2,-5,21:18.14
3,-5,21:18.14
4,-5,21:18.14
5,-5,21:18.14
6,-5,21:18.14
7,-5,21:18.14
8,-5,21:18.14
9,-5,21:18.14
10,-5,21:18.14
12,-5,21:18.6
-3,-4,21:18.14
-2,-4,21:18.14
-1,-4,21:18.14
0,-4,21:18.14
1,-4,21:18.14
2,-4,21:18.14
3,-4,21:18.14
4,-4,21:18.14
5,-4,21:18.14
7,-4,21:18.14
8,-4,21:18.14
9,-4,21:18.14
10,-4,21:18.14
12,-4,21:18.6
13,-4,21:18.6
-4,-3,21:18.14
-3,-3,21:18.14
-1,-3,21:18.14
0,-3,21:18.14
1,-3,21:18.14
2,-3,21:18.14
4,-3,21:18.14
5,-3,21:18.14
6,-3,21:18.14
7,-3,21:18.14
8,-3,21:18.14
10,-3,21:18.14
11,-3,21:18.14
13,-3,21:18.6
-12,-2,21:18.6
-11,-2,21:18.6
-10,-2,21:18.6
-6,-2,21:18.6
-5,-2,21:18.6
-4,-2,21:18.14
-2,-2,21:18.14
-1,-2,21:18.14
0,-2,21:18.14
1,-2,21:18.14
2,-2,21:18.14
4,-2,21:18.14
6,-2,21:18.14
7,-2,21:18.14
8,-2,21:17.0
11,-2,21:18.14
12,-2,21:18.6
13,-2,21:18.14
14,-2,21:18.14
-12,-1,21:18.14
-7,-1,21:18.14
-6,-1,21:18.14
-4,-1,21:18.14
-3,-1,21:18.14
-2,-1,21:18.14
-1,-1,21:18.14
0,-1,21:18.14
1,-1,21:18.14
2,-1,21:18.14
3,-1,21:18.14
4,-1,21:18.14
6,-1,21:18.14
7,-1,21:18.14
8,-1,21:17.0
9,-1,21:17.0
11,-1,21:18.14
12,-1,21:18.6
13,-1,21:18.14
14,-1,21:18.14
-9,0,21:18.14
-8,0,21:18.14
-7,0,21:18.14
-6,0,21:18.14
-5,0,21:18.14
-4,0,21:18.14
-3,0,21:17.0
-2,0,21:17.0
-1,0,21:18.14
0,0,21:18.14
1,0,21:18.14
3,0,21:18.14
4,0,21:18.14
5,0,21:18.14
6,0,21:18.14
7,0,21:18.14
11,0,21:18.14
14,0,21:18.14
-11,1,21:18.14
-10,1,21:18.14
-9,1,21:18.14
-8,1,21:18.14
-7,1,21:18.14
-6,1,21:18.14
-5,1,21:18.14
-4,1,21:18.14
-3,1,21:18.14
-2,1,21:18.14
-1,1,21:18.14
0,1,21:18.14
1,1,21:18.14
2,1,21:18.14
3,1,21:18.14
4,1,21:18.14
5,1,21:18.14
6,1,21:18.14
7,1,21:18.14
-11,2,21:18.14
-10,2,21:18.14
-9,2,21:18.14
-8,2,21:18.14
-1,2,21:18.14
0,2,21:18.14
1,2,21:18.14
2,2,21:18.14
3,2,21:18.14
4,2,21:18.14
5,2,21:18.14
6,2,21:18.14
7,2,21:18.14
8,2,21:18.14
-12,3,21:18.14
-11,3,21:18.14
-10,3,21:18.14
-1,3,21:18.14
0,3,21:18.14
1,3,21:18.14
2,3,21:18.14
3,3,21:18.14
4,3,21:18.14
5,3,21:18.14
6,3,21:18.14
8,3,21:18.14
9,3,21:18.14
-12,4,21:18.14
-2,4,21:18.14
-1,4,21:18.14
0,4,21:18.14
1,4,21:18.14
3,4,21:18.14
4,4,21:18.14
5,4,21:18.14
6,4,21:18.14
8,4,21:18.14
9,4,21:17.0
10,4,21:18.14
11,4,21:18.14
12,4,21:18.6
-5,5,21:18.14
-4,5,21:18.6
-3,5,21:18.6
-2,5,21:18.14
-1,5,21:18.14
3,5,21:17.0
4,5,21:18.14
5,5,21:18.14
6,5,21:18.14
8,5,21:18.14
9,5,21:18.14
12,5,21:18.6
13,5,21:18.6
14,5,21:18.14
15,5,21:18.14
-6,6,21:18.14
-5,6,21:18.14
-2,6,21:18.14
3,6,21:17.0
5,6,21:18.14
6,6,21:18.14
9,6,21:18.14
-3,7,21:18.6
-2,7,21:18.14
6,7,21:18.14
7,7,21:18.14
9,7,21:18.14
10,7,21:18.14
-3,8,21:18.6
6,8,21:18.14
7,8,21:18.14
10,8,21:18.6
-3,9,21:18.6
7,9,21:18.14
8,9,21:18.14
10,9,21:18.14
11,9,21:18.14
12,-13,22:18.14
-4,-12,22:18.6
12,-12,22:18.14
-4,-11,22:18.6
10,-11,22:18.6
11,-11,22:18.14
12,-11,22:18.14
13,-11,22:18.14
-4,-10,22:18.6
-3,-10,22:18.6
10,-10,22:18.6
11,-10,22:18.14
12,-10,22:18.14
-4,-9,22:18.6
-3,-9,22:18.6
9,-9,22:18.6
10,-9,22:18.6
11,-9,22:18.6
12,-9,22:18.6
13,-9,22:18.6
-8,-8,22:18.6
-7,-8,22:18.6
-6,-8,22:18.6
-3,-8,22:18.6
3,-8,22:17.0
9,-8,22:18.6
10,-8,22:18.6
11,-8,22:18.6
12,-8,22:18.6
-6,-7,22:18.6
-5,-7,22:18.6
-4,-7,22:18.6
-3,-7,22:18.6
-2,-7,22:18.6
3,-7,22:17.0
5,-7,22:18.14
6,-7,22:18.14
7,-7,22:18.14
8,-7,22:18.14
9,-7,22:18.6
10,-7,22:18.6
11,-7,22:18.6
12,-7,22:18.6
-4,-6,22:18.6
-3,-6,22:18.6
-2,-6,22:18.6
-1,-6,22:18.14
0,-6,22:18.14
1,-6,22:18.14
2,-6,22:18.14
3,-6,22:18.14
4,-6,22:18.14
5,-6,22:18.14
6,-6,22:18.14
7,-6,22:18.14
9,-6,22:18.6
10,-6,22:18.6
11,-6,22:18.6
12,-6,22:18.6
-2,-5,22:18.14
-1,-5,22:18.14
0,-5,22:18.14
1,-5,22:18.14
2,-5,22:18.14
3,-5,22:18.14
4,-5,22:18.14
5,-5,22:18.14
8,-5,22:18.14
9,-5,22:18.14
10,-5,22:18.14
12,-5,22:18.6
13,-5,22:18.6
-2,-4,22:18.14
-1,-4,22:18.14
0,-4,22:18.14
1,-4,22:18.14
2,-4,22:18.14
4,-4,22:18.14
5,-4,22:18.14
6,-4,22:18.14
8,-4,22:18.14
9,-4,22:18.14
10,-4,22:18.14
13,-4,22:18.6
-5,-3,22:18.6
-4,-3,22:18.14
-2,-3,22:18.14
-1,-3,22:18.14
0,-3,22:18.14
1,-3,22:18.14
6,-3,22:18.14
7,-3,22:18.14
8,-3,22:18.14
9,-3,22:18.14
10,-3,22:18.14
13,-3,22:18.6
14,-3,22:18.6
-7,-2,22:18.6
-6,-2,22:18.6
-5,-2,22:18.6
-2,-2,22:18.14
-1,-2,22:18.14
0,-2,22:18.14
1,-2,22:18.14
2,-2,22:18.14
7,-2,22:18.14
8,-2,22:18.14
9,-2,22:17.0
10,-2,22:18.14
11,-2,22:18.14
14,-2,22:18.6
-12,-1,22:18.14
-11,-1,22:18.14
-10,-1,22:18.14
-9,-1,22:18.14
-8,-1,22:18.14
-7,-1,22:18.14
-2,-1,22:18.14
-1,-1,22:18.14
0,-1,22:18.14
1,-1,22:18.14
2,-1,22:18.14
5,-1,22:18.14
7,-1,22:18.14
8,-1,22:18.14
9,-1,22:17.0
10,-1,22:17.0
11,-1,22:18.14
12,-1,22:18.6
13,-1,22:18.6
14,-1,22:18.14
15,-1,22:18.14
-12,0,22:18.14
-10,0,22:18.14
-9,0,22:18.14
-8,0,22:18.14
-6,0,22:18.14
-5,0,22:18.14
-4,0,22:18.14
-3,0,22:17.0
-2,0,22:18.14
-1,0,22:18.14
0,0,22:18.14
2,0,22:18.14
5,0,22:18.14
7,0,22:18.14
8,0,22:18.14
15,0,22:18.14
16,0,22:18.14
17,0,22:18.14
-12,1,22:18.14
-11,1,22:18.14
-10,1,22:18.14
-9,1,22:18.14
-8,1,22:18.14
-7,1,22:18.14
-6,1,22:18.14
-5,1,22:18.14
-4,1,22:18.14
-3,1,22:18.14
-2,1,22:18.14
-1,1,22:18.14
0,1,22:18.14
1,1,22:18.14
2,1,22:18.14
3,1,22:18.14
5,1,22:18.14
6,1,22:18.14
7,1,22:18.14
8,1,22:18.14
9,1,22:18.14
14,1,22:18.14
15,1,22:18.14
16,1,22:18.14
-12,2,22:18.14
-11,2,22:18.14
-10,2,22:18.14
-8,2,22:18.14
-7,2,22:18.14
-6,2,22:18.14
-2,2,22:18.14
-1,2,22:18.14
0,2,22:18.14
1,2,22:18.14
2,2,22:18.14
3,2,22:18.14
5,2,22:18.14
6,2,22:18.14
8,2,22:18.14
9,2,22:18.14
-12,3,22:18.14
-11,3,22:18.14
-10,3,22:18.14
-9,3,22:18.14
-8,3,22:18.14
-2,3,22:18.14
-1,3,22:18.14
1,3,22:18.14
2,3,22:18.14
3,3,22:18.14
4,3,22:18.14
5,3,22:18.14
6,3,22:18.14
8,3,22:18.14
9,3,22:18.14
-12,4,22:18.14
-11,4,22:18.14
-10,4,22:18.14
-2,4,22:18.14
-1,4,22:18.14
0,4,22:18.14
1,4,22:18.14
2,4,22:18.14
3,4,22:18.14
4,4,22:18.14
5,4,22:18.14
6,4,22:18.14
7,4,22:18.14
8,4,22:18.14
9,4,22:18.14
10,4,22:18.14
11,4,22:18.14
-12,5,22:18.14
-3,5,22:18.6
-2,5,22:18.14
-1,5,22:18.14
0,5,22:18.14
1,5,22:18.14
3,5,22:17.0
4,5,22:18.14
5,5,22:18.14
6,5,22:18.14
9,5,22:18.14
10,5,22:17.0
11,5,22:18.14
12,5,22:18.6
13,5,22:18.6
15,5,22:18.14
-6,6,22:18.14
-5,6,22:18.14
-4,6,22:18.6
-3,6,22:18.6
-2,6,22:18.14
3,6,22:17.0
4,6,22:18.14
5,6,22:18.14
6,6,22:18.14
7,6,22:18.14
9,6,22:18.14
10,6,22:18.14
13,6,22:18.6
14,6,22:18.14
-6,7,22:18.14
-5,7,22:18.14
-3,7,22:18.6
5,7,22:18.14
6,7,22:18.14
7,7,22:18.14
10,7,22:18.14
-4,8,22:18.6
-3,8,22:18.6
5,8,22:18.14
6,8,22:18.14
7,8,22:18.6
8,8,22:18.6
10,8,22:18.6
11,8,22:18.6
-4,9,22:18.6
6,9,22:18.14
7,9,22:18.14
8,9,22:18.14
11,9,22:18.14
6,10,22:18.14
7,10,22:18.14
7,11,22:18.14
7,12,22:18.14
13,-14,23:18.14
13,-13,23:18.14
-6,-12,23:18.6
-5,-12,23:18.6
12,-12,23:18.14
13,-12,23:18.14
-5,-11,23:18.6
12,-11,23:18.6
13,-11,23:18.14
-9,-10,23:18.6
-5,-10,23:18.6
-4,-10,23:18.6
11,-10,23:18.6
12,-10,23:18.6
13,-10,23:18.14
14,-10,23:18.14
-8,-9,23:18.6
-7,-9,23:18.6
-4,-9,23:18.6
3,-9,23:17.0
8,-9,23:18.6
9,-9,23:18.6
10,-9,23:18.6
11,-9,23:18.6
12,-9,23:18.6
-6,-8,23:18.6
-5,-8,23:18.6
-4,-8,23:18.6
-3,-8,23:18.6
3,-8,23:17.0
4,-8,23:18.6
5,-8,23:18.6
6,-8,23:18.6
7,-8,23:18.6
8,-8,23:18.6
9,-8,23:18.6
10,-8,23:18.6
11,-8,23:18.6
12,-8,23:18.6
-4,-7,23:18.6
-3,-7,23:18.6
-2,-7,23:18.6
-1,-7,23:18.6
0,-7,23:18.6
1,-7,23:18.6
2,-7,23:18.6
3,-7,23:18.6
4,-7,23:18.6
5,-7,23:18.6
6,-7,23:18.6
10,-7,23:18.6
11,-7,23:18.6
12,-7,23:18.6
-3,-6,23:18.6
1,-6,23:18.6
2,-6,23:18.6
3,-6,23:18.6
4,-6,23:18.6
5,-6,23:18.6
10,-6,23:18.6
11,-6,23:18.6
12,-6,23:18.6
13,-6,23:18.6
0,-5,23:18.6
1,-5,23:18.6
5,-5,23:18.6
6,-5,23:18.6
10,-5,23:18.6
11,-5,23:18.6
13,-5,23:18.6
-3,-4,23:18.6
-2,-4,23:18.6
-1,-4,23:18.6
0,-4,23:18.6
6,-4,23:18.6
7,-4,23:18.6
9,-4,23:18.6
10,-4,23:18.6
13,-4,23:18.6
14,-4,23:18.6
-5,-3,23:18.6
-3,-3,23:18.6
-2,-3,23:18.6
-1,-3,23:18.6
7,-3,23:18.6
8,-3,23:18.6
9,-3,23:18.6
10,-3,23:18.6
14,-3,23:18.6
-8,-2,23:18.6
-7,-2,23:18.6
-6,-2,23:18.6
-3,-2,23:18.6
-2,-2,23:18.6
-1,-2,23:18.6
8,-2,23:18.6
9,-2,23:18.6
10,-2,23:18.6
11,-2,23:17.0
14,-2,23:18.6
15,-2,23:18.6
-9,-1,23:18.6
-8,-1,23:18.6
-3,-1,23:18.6
-2,-1,23:18.6
-1,-1,23:18.6
0,-1,23:18.6
1,-1,23:18.6
2,-1,23:18.6
8,-1,23:18.6
9,-1,23:18.6
10,-1,23:17.0
11,-1,23:17.0
12,-1,23:18.6
13,-1,23:18.6
14,-1,23:18.6
15,-1,23:18.6
16,-1,23:18.6
17,-1,23:18.6
-12,0,23:18.6
-11,0,23:18.6
-10,0,23:18.6
-9,0,23:18.6
-8,0,23:18.6
-7,0,23:18.6
-6,0,23:18.6
-5,0,23:18.6
-4,0,23:17.0
-3,0,23:18.6
-2,0,23:18.6
-1,0,23:18.6
0,0,23:18.6
1,0,23:18.6
8,0,23:18.6
9,0,23:18.6
10,0,23:18.6
15,0,23:18.6
16,0,23:18.6
17,0,23:18.6
-12,1,23:18.6
-11,1,23:18.6
-10,1,23:18.6
-9,1,23:18.6
-4,1,23:18.6
-3,1,23:18.6
-2,1,23:18.6
-1,1,23:18.6
1,1,23:18.6
2,1,23:18.6
5,1,23:18.6
6,1,23:18.6
7,1,23:18.6
8,1,23:18.6
9,1,23:18.6
10,1,23:18.6
16,1,23:18.6
17,1,23:18.6
-12,2,23:18.6
-11,2,23:18.6
-10,2,23:18.6
-9,2,23:18.6
-8,2,23:18.6
-6,2,23:18.6
-5,2,23:18.6
-4,2,23:18.6
-3,2,23:18.6
-2,2,23:18.6
-1,2,23:18.6
0,2,23:18.6
1,2,23:18.6
2,2,23:18.6
6,2,23:18.6
7,2,23:18.6
9,2,23:18.6
10,2,23:18.6
-12,3,23:18.6
-8,3,23:18.6
-7,3,23:18.6
-6,3,23:18.6
-3,3,23:18.6
-2,3,23:18.6
0,3,23:18.6
1,3,23:18.6
2,3,23:18.6
3,3,23:18.6
4,3,23:18.6
5,3,23:18.6
6,3,23:18.6
9,3,23:18.6
10,3,23:18.6
-10,4,23:18.6
-9,4,23:18.6
-8,4,23:18.6
1,4,23:18.6
2,4,23:18.6
3,4,23:18.6
4,4,23:18.6
5,4,23:18.6
6,4,23:18.6
9,4,23:18.6
10,4,23:18.6
-12,5,23:18.6
-11,5,23:18.6
-10,5,23:18.6
-4,5,23:18.6
-3,5,23:18.6
-1,5,23:18.6
0,5,23:18.6
1,5,23:18.6
2,5,23:18.6
3,5,23:18.6
4,5,23:18.6
5,5,23:18.6
6,5,23:18.6
7,5,23:18.6
8,5,23:18.6
9,5,23:18.6
10,5,23:18.6
11,5,23:18.6
12,5,23:18.6
17,5,23:18.14
-12,6,23:18.6
-4,6,23:18.6
-3,6,23:18.6
-2,6,23:18.6
-1,6,23:18.6
0,6,23:18.6
1,6,23:18.6
3,6,23:17.0
4,6,23:18.6
6,6,23:18.6
7,6,23:18.6
10,6,23:18.14
11,6,23:18.14
12,6,23:18.14
13,6,23:18.14
14,6,23:18.14
-6,7,23:18.6
-5,7,23:18.6
-4,7,23:18.6
-3,7,23:18.6
3,7,23:17.0
4,7,23:18.6
5,7,23:18.6
7,7,23:18.6
11,7,23:18.14
-7,8,23:18.6
-4,8,23:18.6
4,8,23:18.6
5,8,23:18.6
7,8,23:18.6
8,8,23:18.6
11,8,23:18.14
12,8,23:18.14
14,8,23:18.14
-8,9,23:18.6
-5,9,23:18.6
-4,9,23:18.6
5,9,23:18.6
7,9,23:18.6
8,9,23:18.14
9,9,23:18.14
12,9,23:18.14
-5,10,23:18.6
5,10,23:18.6
6,10,23:18.6
7,10,23:18.6
9,10,23:18.14
10,10,23:18.14
12,10,23:18.14
13,10,23:18.14
-6,11,23:18.6
6,11,23:18.6
7,11,23:18.14
8,11,23:18.14
6,12,23:18.6
7,12,23:18.14
8,12,23:18.14
13,-14,24:18.14
14,-14,24:18.14
13,-13,24:18.14
14,-13,24:18.14
-6,-12,24:18.6
13,-12,24:18.14
14,-12,24:18.14
-6,-11,24:18.6
-5,-11,24:18.6
11,-11,24:18.6
12,-11,24:18.6
13,-11,24:18.14
14,-11,24:18.14
15,-11,24:18.14
16,-11,24:18.14
-8,-10,24:18.6
-7,-10,24:18.6
-6,-10,24:18.6
-5,-10,24:18.6
7,-10,24:18.6
8,-10,24:18.6
9,-10,24:18.6
10,-10,24:18.6
11,-10,24:18.6
12,-10,24:18.6
13,-10,24:18.14
14,-10,24:18.14
-7,-9,24:18.6
-6,-9,24:18.6
-5,-9,24:18.6
-4,-9,24:18.6
-3,-9,24:18.6
-2,-9,24:18.6
-1,-9,24:18.6
0,-9,24:18.6
1,-9,24:18.6
2,-9,24:18.6
3,-9,24:17.0
4,-9,24:18.6
5,-9,24:18.6
6,-9,24:18.6
7,-9,24:18.6
8,-9,24:18.6
9,-9,24:18.6
11,-9,24:18.6
12,-9,24:18.6
-5,-8,24:18.6
-4,-8,24:18.6
-3,-8,24:18.6
-2,-8,24:18.6
-1,-8,24:18.6
0,-8,24:18.6
1,-8,24:18.6
2,-8,24:18.6
3,-8,24:18.6
4,-8,24:18.6
5,-8,24:18.6
10,-8,24:18.6
11,-8,24:18.6
12,-8,24:18.6
-5,-7,24:18.6
-4,-7,24:18.6
1,-7,24:18.6
2,-7,24:18.6
4,-7,24:18.6
5,-7,24:18.6
11,-7,24:18.6
12,-7,24:18.6
13,-7,24:18.6
-5,-6,24:18.6
-4,-6,24:18.6
0,-6,24:18.6
1,-6,24:18.6
5,-6,24:18.6
6,-6,24:18.6
11,-6,24:18.6
12,-6,24:18.6
13,-6,24:18.6
-4,-5,24:18.6
-1,-5,24:18.6
0,-5,24:18.6
6,-5,24:18.6
7,-5,24:18.6
8,-5,24:18.6
11,-5,24:18.6
13,-5,24:18.6
14,-5,24:18.6
-4,-4,24:18.6
-3,-4,24:18.6
-2,-4,24:18.6
-1,-4,24:18.6
7,-4,24:18.6
8,-4,24:18.6
10,-4,24:18.6
11,-4,24:18.6
14,-4,24:18.6
-4,-3,24:18.6
-3,-3,24:18.6
-2,-3,24:18.6
8,-3,24:18.6
9,-3,24:18.6
10,-3,24:18.6
11,-3,24:18.6
15,-3,24:18.6
-12,-2,24:18.6
-11,-2,24:18.6
-4,-2,24:18.6
-3,-2,24:18.6
-2,-2,24:18.6
9,-2,24:18.6
10,-2,24:18.6
11,-2,24:17.0
12,-2,24:17.0
15,-2,24:18.6
17,-2,24:18.6
-12,-1,24:18.6
-11,-1,24:18.6
-10,-1,24:18.6
-9,-1,24:18.6
-4,-1,24:18.6
-3,-1,24:18.6
0,-1,24:18.6
10,-1,24:18.6
11,-1,24:18.6
15,-1,24:18.6
16,-1,24:18.6
17,-1,24:18.6
-12,0,24:18.6
-11,0,24:18.6
-10,0,24:18.6
-9,0,24:18.6
-8,0,24:18.6
-7,0,24:18.6
-6,0,24:18.6
-5,0,24:17.0
-4,0,24:17.0
-3,0,24:18.6
0,0,24:18.6
1,0,24:18.6
2,0,24:18.6
9,0,24:18.6
10,0,24:18.6
11,0,24:18.6
15,0,24:18.6
16,0,24:18.6
17,0,24:18.6
-12,1,24:18.6
-11,1,24:18.6
-10,1,24:18.6
-9,1,24:18.6
-8,1,24:18.6
-5,1,24:18.6
-4,1,24:18.6
-3,1,24:18.6
-2,1,24:18.6
-1,1,24:18.6
0,1,24:18.6
1,1,24:18.6
8,1,24:18.6
9,1,24:18.6
10,1,24:18.6
11,1,24:18.6
17,1,24:18.6
-12,2,24:18.6
-11,2,24:18.6
-10,2,24:18.6
-8,2,24:18.6
-4,2,24:18.6
-3,2,24:18.6
-2,2,24:18.6
-1,2,24:18.6
0,2,24:18.6
1,2,24:18.6
6,2,24:18.6
8,2,24:18.6
10,2,24:18.6
11,2,24:18.6
-12,3,24:18.6
-11,3,24:18.6
-6,3,24:18.6
-5,3,24:18.6
-4,3,24:18.6
-3,3,24:18.6
-1,3,24:18.6
0,3,24:18.6
1,3,24:18.6
2,3,24:18.6
3,3,24:18.6
4,3,24:18.6
6,3,24:18.6
8,3,24:18.6
11,3,24:18.6
-12,4,24:18.6
-8,4,24:18.6
-7,4,24:18.6
-6,4,24:18.6
-5,4,24:18.6
-4,4,24:18.6
0,4,24:18.6
1,4,24:18.6
2,4,24:18.6
4,4,24:18.6
5,4,24:18.6
6,4,24:18.6
7,4,24:18.6
11,4,24:18.6
17,4,24:18.6
-10,5,24:18.6
-9,5,24:18.6
-8,5,24:18.6
-5,5,24:18.6
-4,5,24:18.6
1,5,24:18.6
2,5,24:18.6
3,5,24:18.6
4,5,24:18.6
5,5,24:18.6
6,5,24:18.6
7,5,24:18.6
11,5,24:18.14
12,5,24:18.14
16,5,24:18.14
17,5,24:18.14
-12,6,24:18.6
-11,6,24:18.6
-10,6,24:18.6
-5,6,24:18.6
-4,6,24:18.6
0,6,24:18.6
1,6,24:18.6
2,6,24:18.6
3,6,24:18.6
4,6,24:18.6
5,6,24:18.6
6,6,24:18.6
7,6,24:18.6
8,6,24:18.6
9,6,24:18.14
10,6,24:18.14
11,6,24:18.14
12,6,24:18.14
15,6,24:18.14
16,6,24:18.14
-12,7,24:18.6
-5,7,24:18.6
-4,7,24:18.6
-3,7,24:18.6
-2,7,24:18.6
-1,7,24:18.6
0,7,24:18.6
1,7,24:18.6
2,7,24:18.6
3,7,24:18.6
4,7,24:18.6
7,7,24:18.6
8,7,24:18.6
14,7,24:18.14
15,7,24:18.14
-6,8,24:18.6
-5,8,24:18.6
-4,8,24:18.6
-3,8,24:18.6
3,8,24:17.0
4,8,24:18.6
7,8,24:18.6
8,8,24:18.6
14,8,24:18.14
15,8,24:18.14
-8,9,24:18.6
-7,9,24:18.6
-6,9,24:18.6
-5,9,24:18.6
4,9,24:18.6
8,9,24:18.6
9,9,24:18.14
-6,10,24:18.6
4,10,24:18.6
5,10,24:18.6
8,10,24:18.6
9,10,24:18.14
10,10,24:18.14
13,10,24:18.14
-6,11,24:18.6
5,11,24:18.6
8,11,24:18.6
5,12,24:18.6
6,12,24:18.6
7,12,24:18.6
14,-13,25:18.14
-7,-12,25:18.6
10,-12,25:18.6
11,-12,25:18.6
12,-12,25:18.6
13,-12,25:18.6
14,-12,25:18.14
-9,-11,25:18.6
-7,-11,25:18.6
-6,-11,25:18.6
6,-11,25:18.6
7,-11,25:18.6
8,-11,25:18.6
9,-11,25:18.6
10,-11,25:18.6
11,-11,25:18.6
12,-11,25:18.6
13,-11,25:18.6
14,-11,25:18.14
-8,-10,25:18.6
-7,-10,25:18.6
-6,-10,25:18.6
-5,-10,25:18.6
-4,-10,25:18.6
-3,-10,25:18.6
-2,-10,25:18.6
-1,-10,25:18.6
0,-10,25:18.6
1,-10,25:18.6
2,-10,25:18.6
3,-10,25:17.0
4,-10,25:18.6
5,-10,25:18.6
6,-10,25:18.6
7,-10,25:18.6
8,-10,25:18.6
12,-10,25:18.6
13,-10,25:18.6
14,-10,25:18.14
15,-10,25:18.14
-6,-9,25:18.6
-5,-9,25:18.6
-4,-9,25:18.6
-3,-9,25:18.6
-2,-9,25:18.6
-1,-9,25:18.6
0,-9,25:18.6
1,-9,25:18.6
2,-9,25:18.6
3,-9,25:18.6
4,-9,25:18.6
5,-9,25:18.6
12,-9,25:18.6
13,-9,25:18.6
14,-9,25:18.6
-6,-8,25:18.6
-5,-8,25:18.6
0,-8,25:18.6
1,-8,25:18.6
2,-8,25:18.6
4,-8,25:18.6
5,-8,25:18.6
11,-8,25:18.6
12,-8,25:18.6
13,-8,25:18.6
-6,-7,25:18.6
-5,-7,25:18.6
-1,-7,25:18.6
0,-7,25:18.6
1,-7,25:18.6
5,-7,25:18.6
6,-7,25:18.6
7,-7,25:18.6
12,-7,25:18.6
13,-7,25:18.6
-12,-6,25:18.6
-6,-6,25:18.6
-5,-6,25:18.6
-2,-6,25:18.6
-1,-6,25:18.6
0,-6,25:18.6
6,-6,25:18.6
7,-6,25:18.6
8,-6,25:18.6
12,-6,25:18.6
13,-6,25:18.6
14,-6,25:18.6
-12,-5,25:18.6
-5,-5,25:18.6
-2,-5,25:18.6
7,-5,25:18.6
8,-5,25:18.6
9,-5,25:18.6
12,-5,25:18.6
13,-5,25:18.6
14,-5,25:18.6
-12,-4,25:18.6
-11,-4,25:18.6
-5,-4,25:18.6
-3,-4,25:18.6
-2,-4,25:18.6
9,-4,25:18.6
10,-4,25:18.6
12,-4,25:18.6
15,-4,25:18.6
-12,-3,25:18.6
-11,-3,25:18.6
-10,-3,25:18.6
-5,-3,25:18.6
-4,-3,25:18.6
-3,-3,25:18.6
10,-3,25:18.6
11,-3,25:18.6
12,-3,25:18.6
15,-3,25:18.6
-11,-2,25:18.6
-10,-2,25:18.6
-9,-2,25:18.6
-5,-2,25:18.6
-4,-2,25:18.6
-3,-2,25:18.6
11,-2,25:18.6
12,-2,25:17.0
16,-2,25:18.6
17,-2,25:18.6
-11,-1,25:18.6
-10,-1,25:18.6
-9,-1,25:18.6
-8,-1,25:18.6
-5,-1,25:18.6
-4,-1,25:18.6
11,-1,25:18.6
12,-1,25:18.6
15,-1,25:18.6
16,-1,25:18.6
17,-1,25:18.6
-12,0,25:18.6
-11,0,25:18.6
-9,0,25:18.6
-8,0,25:18.6
-7,0,25:18.6
-6,0,25:17.0
-5,0,25:17.0
-4,0,25:18.6
-2,0,25:18.6
-1,0,25:18.6
10,0,25:18.6
11,0,25:18.6
12,0,25:18.6
17,0,25:18.6
-12,1,25:18.6
-8,1,25:18.6
-7,1,25:18.6
-6,1,25:18.6
-5,1,25:18.6
-4,1,25:18.6
-3,1,25:18.6
-1,1,25:18.6
0,1,25:18.6
1,1,25:18.6
2,1,25:18.6
9,1,25:18.6
10,1,25:18.6
11,1,25:18.6
12,1,25:18.6
-12,2,25:18.6
-9,2,25:18.6
-8,2,25:18.6
-5,2,25:18.6
-4,2,25:18.6
-3,2,25:18.6
-2,2,25:18.6
-1,2,25:18.6
0,2,25:18.6
1,2,25:18.6
9,2,25:18.6
12,2,25:18.6
17,2,25:18.6
-11,3,25:18.6
-10,3,25:18.6
-9,3,25:18.6
-5,3,25:18.6
-4,3,25:18.6
-3,3,25:18.6
-2,3,25:18.6
-1,3,25:18.6
0,3,25:18.6
1,3,25:18.6
2,3,25:18.6
8,3,25:18.6
9,3,25:18.6
12,3,25:18.6
16,3,25:18.6
17,3,25:18.6
-12,4,25:18.6
-11,4,25:18.6
-10,4,25:18.6
-6,4,25:18.6
-5,4,25:18.6
-4,4,25:18.6
-2,4,25:18.6
-1,4,25:18.6
0,4,25:18.6
1,4,25:18.6
3,4,25:18.6
4,4,25:18.6
5,4,25:18.6
7,4,25:18.6
8,4,25:18.6
12,4,25:18.6
13,4,25:18.6
16,4,25:18.6
17,4,25:18.6
-12,5,25:18.6
-11,5,25:18.6
-8,5,25:18.6
-7,5,25:18.6
-6,5,25:18.6
-5,5,25:18.6
0,5,25:18.6
1,5,25:18.6
2,5,25:18.6
5,5,25:18.6
6,5,25:18.6
7,5,25:18.6
12,5,25:18.14
13,5,25:18.14
15,5,25:18.6
16,5,25:18.6
-12,6,25:18.6
-10,6,25:18.6
-9,6,25:18.6
-8,6,25:18.6
-6,6,25:18.6
-5,6,25:18.6
1,6,25:18.6
2,6,25:18.6
3,6,25:18.6
4,6,25:18.6
5,6,25:18.6
6,6,25:18.6
7,6,25:18.6
8,6,25:18.6
14,6,25:18.14
15,6,25:18.14
-12,7,25:18.6
-11,7,25:18.6
-10,7,25:18.6
-6,7,25:18.6
-5,7,25:18.6
0,7,25:18.6
1,7,25:18.6
2,7,25:18.6
3,7,25:18.6
4,7,25:18.6
5,7,25:18.6
6,7,25:18.6
7,7,25:18.6
8,7,25:18.6
9,7,25:18.14
-12,8,25:18.6
-6,8,25:18.6
-4,8,25:18.6
-3,8,25:18.6
-2,8,25:18.6
-1,8,25:18.6
0,8,25:18.6
1,8,25:18.6
2,8,25:18.6
3,8,25:18.6
8,8,25:18.6
9,8,25:18.14
15,8,25:18.14
16,8,25:18.14
-7,9,25:18.6
-6,9,25:18.6
-5,9,25:18.6
-4,9,25:18.6
-3,9,25:18.6
-2,9,25:18.6
3,9,25:18.6
4,9,25:18.6
8,9,25:18.6
9,9,25:18.14
15,9,25:18.14
16,9,25:18.14
17,9,25:18.14
-8,10,25:18.6
-7,10,25:18.6
-6,10,25:18.6
3,10,25:18.6
4,10,25:18.6
8,10,25:18.6
14,10,25:18.14
17,10,25:18.14
-7,11,25:18.6
4,11,25:18.6
7,11,25:18.6
8,11,25:18.6
-12,12,25:18.6
4,12,25:18.6
5,12,25:18.6
7,12,25:18.6
13,-14,26:18.6
-8,-13,26:18.6
9,-13,26:18.6
10,-13,26:18.6
11,-13,26:18.6
12,-13,26:18.6
13,-13,26:18.6
-9,-12,26:18.6
-8,-12,26:18.6
-7,-12,26:18.6
5,-12,26:18.6
6,-12,26:18.6
7,-12,26:18.6
8,-12,26:18.6
9,-12,26:18.6
10,-12,26:18.6
11,-12,26:18.6
-9,-11,26:18.6
-8,-11,26:18.6
-7,-11,26:18.6
-6,-11,26:18.6
-5,-11,26:18.6
-4,-11,26:18.6
-3,-11,26:18.6
-2,-11,26:18.6
-1,-11,26:18.6
0,-11,26:18.6
1,-11,26:18.6
2,-11,26:18.6
3,-11,26:18.6
4,-11,26:18.6
5,-11,26:18.6
6,-11,26:18.6
7,-11,26:18.6
12,-11,26:18.6
14,-11,26:18.14
-7,-10,26:18.6
-6,-10,26:18.6
-5,-10,26:18.6
-4,-10,26:18.6
-3,-10,26:18.6
-2,-10,26:18.6
-1,-10,26:18.6
0,-10,26:18.6
1,-10,26:18.6
2,-10,26:18.6
3,-10,26:18.6
4,-10,26:18.6
5,-10,26:18.6
12,-10,26:18.6
13,-10,26:18.6
14,-10,26:18.14
15,-10,26:18.14
-7,-9,26:18.6
0,-9,26:18.6
1,-9,26:18.6
2,-9,26:18.6
4,-9,26:18.6
5,-9,26:18.6
6,-9,26:18.6
13,-9,26:18.6
14,-9,26:18.6
15,-9,26:18.14
-7,-8,26:18.6
-6,-8,26:18.6
-1,-8,26:18.6
0,-8,26:18.6
1,-8,26:18.6
6,-8,26:18.6
7,-8,26:18.6
11,-8,26:18.6
12,-8,26:18.6
13,-8,26:18.6
14,-8,26:18.6
-7,-7,26:18.6
-6,-7,26:18.6
-2,-7,26:18.6
-1,-7,26:18.6
7,-7,26:18.6
8,-7,26:18.6
11,-7,26:18.6
13,-7,26:18.6
14,-7,26:18.6
-12,-6,26:18.6
-7,-6,26:18.6
-6,-6,26:18.6
-3,-6,26:18.6
-2,-6,26:18.6
8,-6,26:18.6
9,-6,26:18.6
13,-6,26:18.6
14,-6,26:18.6
-12,-5,26:18.6
-6,-5,26:18.6
9,-5,26:18.6
10,-5,26:18.6
13,-5,26:18.6
14,-5,26:18.6
15,-5,26:18.6
-12,-4,26:18.6
-11,-4,26:18.6
-10,-4,26:18.6
-6,-4,26:18.6
-4,-4,26:18.6
-3,-4,26:18.6
10,-4,26:18.6
11,-4,26:18.6
13,-4,26:18.6
15,-4,26:18.6
16,-4,26:18.6
-11,-3,26:18.6
-10,-3,26:18.6
-9,-3,26:18.6
-6,-3,26:18.6
-5,-3,26:18.6
-4,-3,26:18.6
11,-3,26:18.6
12,-3,26:18.6
13,-3,26:18.6
17,-3,26:18.6
-10,-2,26:18.6
-9,-2,26:18.6
-8,-2,26:18.6
-6,-2,26:18.6
-5,-2,26:18.6
-4,-2,26:18.6
12,-2,26:18.6
13,-2,26:18.6
14,-2,26:18.6
15,-2,26:18.6
16,-2,26:18.6
17,-2,26:18.6
-8,-1,26:18.6
-6,-1,26:18.6
-5,-1,26:18.6
12,-1,26:18.6
13,-1,26:18.6
14,-1,26:18.6
17,-1,26:18.6
-6,0,26:17.0
-5,0,26:18.6
-2,0,26:18.6
11,0,26:18.6
12,0,26:18.6
13,0,26:18.6
17,0,26:18.6
-6,1,26:18.6
-5,1,26:18.6
-4,1,26:18.6
-2,1,26:18.6
-1,1,26:18.6
10,1,26:18.6
11,1,26:18.6
13,1,26:18.6
17,1,26:18.6
-8,2,26:18.6
-6,2,26:18.6
-5,2,26:18.6
-4,2,26:18.6
-3,2,26:18.6
-2,2,26:18.6
-1,2,26:18.6
0,2,26:18.6
1,2,26:18.6
10,2,26:18.6
11,2,26:18.6
13,2,26:18.6
17,2,26:18.6
-10,3,26:18.6
-9,3,26:18.6
-8,3,26:18.6
-6,3,26:18.6
-3,3,26:18.6
-2,3,26:18.6
-1,3,26:18.6
0,3,26:18.6
1,3,26:18.6
9,3,26:18.6
10,3,26:18.6
13,3,26:18.6
14,3,26:18.6
16,3,26:18.6
17,3,26:18.6
-11,4,26:18.6
-10,4,26:18.6
-7,4,26:18.6
-6,4,26:18.6
-4,4,26:18.6
-2,4,26:18.6
-1,4,26:18.6
0,4,26:18.6
2,4,26:18.6
3,4,26:18.6
4,4,26:18.6
8,4,26:18.6
9,4,26:18.6
13,4,26:18.6
14,4,26:18.6
15,4,26:18.6
16,4,26:18.6
-12,5,26:18.6
-11,5,26:18.6
-7,5,26:18.6
-6,5,26:18.6
-5,5,26:18.6
-4,5,26:18.6
-2,5,26:18.6
-1,5,26:18.6
0,5,26:18.6
1,5,26:18.6
5,5,26:18.6
6,5,26:18.6
7,5,26:18.6
8,5,26:18.6
9,5,26:18.6
13,5,26:18.14
14,5,26:18.14
15,5,26:18.6
-12,6,26:18.6
-8,6,26:18.6
-7,6,26:18.6
-6,6,26:18.6
0,6,26:18.6
1,6,26:18.6
6,6,26:18.6
7,6,26:18.6
8,6,26:18.6
14,6,26:18.14
-10,7,26:18.6
-9,7,26:18.6
-8,7,26:18.6
-7,7,26:18.6
-6,7,26:18.6
1,7,26:18.6
2,7,26:18.6
3,7,26:18.6
4,7,26:18.6
5,7,26:18.6
6,7,26:18.6
8,7,26:18.6
-12,8,26:18.6
-11,8,26:18.6
-10,8,26:18.6
-7,8,26:18.6
0,8,26:18.6
1,8,26:18.6
2,8,26:18.6
3,8,26:18.6
4,8,26:18.6
5,8,26:18.6
6,8,26:18.6
7,8,26:18.6
8,8,26:18.6
9,8,26:18.14
15,8,26:18.14
-12,9,26:18.6
-8,9,26:18.6
-7,9,26:18.6
-4,9,26:18.6
-3,9,26:18.6
-2,9,26:18.6
-1,9,26:18.6
0,9,26:18.6
1,9,26:18.6
2,9,26:18.6
3,9,26:18.6
4,9,26:17.0
9,9,26:18.14
15,9,26:18.14
16,9,26:18.6
-12,10,26:18.6
-8,10,26:18.6
-7,10,26:18.6
-6,10,26:18.6
-5,10,26:18.6
-4,10,26:18.6
-3,10,26:18.6
-2,10,26:18.6
2,10,26:18.6
3,10,26:18.6
15,10,26:18.14
17,10,26:18.6
-12,11,26:18.6
-9,11,26:18.6
-8,11,26:18.6
-7,11,26:18.6
-6,11,26:18.6
3,11,26:18.6
7,11,26:18.6
-12,12,26:18.6
-11,12,26:18.6
-8,12,26:18.6
3,12,26:18.6
4,12,26:18.6
7,12,26:18.6
7,-14,27:18.6
8,-14,27:18.6
9,-14,27:18.6
11,-14,27:18.6
12,-14,27:18.6
13,-14,27:18.6
-8,-13,27:18.6
-7,-13,27:18.6
8,-13,27:18.6
9,-13,27:18.6
10,-13,27:18.6
11,-13,27:18.6
12,-13,27:18.6
-9,-12,27:18.6
-8,-12,27:18.6
-7,-12,27:18.6
-6,-12,27:18.6
-5,-12,27:18.6
-4,-12,27:18.6
-3,-12,27:18.6
-2,-12,27:18.6
-1,-12,27:18.6
0,-12,27:18.6
1,-12,27:18.6
2,-12,27:18.6
5,-12,27:18.6
6,-12,27:18.6
7,-12,27:18.6
-9,-11,27:18.6
-8,-11,27:18.6
1,-11,27:18.6
2,-11,27:18.6
3,-11,27:18.6
4,-11,27:18.6
13,-11,27:18.6
-8,-10,27:18.6
0,-10,27:18.6
1,-10,27:18.6
4,-10,27:18.6
5,-10,27:18.6
6,-10,27:18.6
13,-10,27:18.6
15,-10,27:18.14
-8,-9,27:18.6
-1,-9,27:18.6
0,-9,27:18.6
6,-9,27:18.6
7,-9,27:18.6
13,-9,27:18.6
14,-9,27:18.6
15,-9,27:18.14
16,-9,27:18.14
-8,-8,27:18.6
-7,-8,27:18.6
-3,-8,27:18.6
-2,-8,27:18.6
-1,-8,27:18.6
7,-8,27:18.6
8,-8,27:18.6
12,-8,27:18.6
13,-8,27:18.6
14,-8,27:18.6
15,-8,27:18.6
16,-8,27:18.6
-8,-7,27:18.6
-7,-7,27:18.6
-3,-7,27:18.6
-2,-7,27:18.6
8,-7,27:18.6
9,-7,27:18.6
11,-7,27:18.6
12,-7,27:18.6
14,-7,27:18.6
15,-7,27:18.6
16,-7,27:18.6
-12,-6,27:18.6
-8,-6,27:18.6
-7,-6,27:18.6
-4,-6,27:18.6
-3,-6,27:18.6
9,-6,27:18.6
10,-6,27:18.6
14,-6,27:18.6
15,-6,27:18.6
16,-6,27:18.6
-12,-5,27:18.6
-11,-5,27:18.6
-8,-5,27:18.6
-7,-5,27:18.6
-4,-5,27:18.6
10,-5,27:18.6
11,-5,27:18.6
14,-5,27:18.6
15,-5,27:18.6
16,-5,27:18.6
-12,-4,27:18.6
-11,-4,27:18.6
-10,-4,27:18.6
-5,-4,27:18.6
-4,-4,27:18.6
11,-4,27:18.6
12,-4,27:18.6
14,-4,27:18.6
16,-4,27:18.6
-12,-3,27:18.6
-11,-3,27:18.6
-9,-3,27:18.6
-7,-3,27:18.6
-6,-3,27:18.6
-5,-3,27:18.6
12,-3,27:18.6
13,-3,27:18.6
14,-3,27:18.6
15,-3,27:18.6
17,-3,27:18.6
-11,-2,27:18.6
-10,-2,27:18.6
-7,-2,27:18.6
-6,-2,27:18.6
-5,-2,27:18.6
13,-2,27:18.6
14,-2,27:18.6
15,-2,27:18.6
17,-2,27:18.6
-10,-1,27:18.6
-9,-1,27:18.6
-7,-1,27:18.6
-6,-1,27:18.6
13,-1,27:18.6
14,-1,27:18.6
17,-1,27:18.6
-7,0,27:17.0
-6,0,27:18.6
12,0,27:18.6
13,0,27:18.6
14,0,27:18.6
-9,1,27:18.6
-7,1,27:18.6
-6,1,27:18.6
-5,1,27:18.6
-3,1,27:18.6
11,1,27:18.6
12,1,27:18.6
14,1,27:18.6
17,1,27:18.6
-10,2,27:18.6
-9,2,27:18.6
-7,2,27:18.6
-6,2,27:18.6
-5,2,27:18.6
-4,2,27:18.6
-3,2,27:18.6
-2,2,27:18.6
11,2,27:18.6
12,2,27:18.6
14,2,27:18.6
17,2,27:18.6
-11,3,27:18.6
-10,3,27:18.6
-7,3,27:18.6
-5,3,27:18.6
-4,3,27:18.6
-2,3,27:18.6
-1,3,27:18.6
0,3,27:18.6
1,3,27:18.6
2,3,27:18.6
3,3,27:18.6
10,3,27:18.6
11,3,27:18.6
14,3,27:18.6
15,3,27:18.6
16,3,27:18.6
17,3,27:18.6
-12,4,27:18.6
-11,4,27:18.6
-10,4,27:18.6
-8,4,27:18.6
-7,4,27:18.6
-4,4,27:18.6
-2,4,27:18.6
-1,4,27:18.6
0,4,27:18.6
1,4,27:18.6
10,4,27:18.6
14,4,27:18.6
15,4,27:18.6
16,4,27:18.6
-12,5,27:18.6
-11,5,27:18.6
-8,5,27:18.6
-7,5,27:18.6
-4,5,27:18.6
-3,5,27:18.6
-2,5,27:18.6
-1,5,27:18.6
0,5,27:18.6
8,5,27:18.6
9,5,27:18.6
10,5,27:18.6
14,5,27:18.14
15,5,27:18.6
16,5,27:18.6
-8,6,27:18.6
-7,6,27:18.6
-6,6,27:18.6
-5,6,27:18.6
-4,6,27:18.6
-2,6,27:18.6
-1,6,27:18.6
0,6,27:18.6
7,6,27:18.6
8,6,27:18.6
9,6,27:18.6
14,6,27:18.14
15,6,27:18.14
-12,7,27:18.6
-9,7,27:18.6
-8,7,27:18.6
-7,7,27:18.6
-6,7,27:18.6
-1,7,27:18.6
0,7,27:18.6
1,7,27:18.6
6,7,27:18.6
7,7,27:18.6
8,7,27:18.6
15,7,27:18.14
-12,8,27:18.6
-10,8,27:18.6
-9,8,27:18.6
-8,8,27:18.6
1,8,27:18.6
2,8,27:18.6
3,8,27:18.6
4,8,27:18.6
5,8,27:18.6
6,8,27:18.6
15,8,27:18.14
16,8,27:18.6
-12,9,27:18.6
-11,9,27:18.6
-10,9,27:18.6
-8,9,27:18.6
1,9,27:18.6
2,9,27:18.6
3,9,27:18.6
4,9,27:18.6
5,9,27:18.6
6,9,27:18.6
7,9,27:18.6
8,9,27:18.6
9,9,27:18.14
15,9,27:18.14
16,9,27:18.6
17,9,27:18.6
-12,10,27:18.6
-11,10,27:18.6
-8,10,27:18.6
-4,10,27:18.6
-3,10,27:18.6
-2,10,27:18.6
-1,10,27:18.6
0,10,27:18.6
1,10,27:18.6
2,10,27:18.6
3,10,27:18.6
4,10,27:17.0
9,10,27:18.14
10,10,27:18.14
14,10,27:18.14
15,10,27:18.14
17,10,27:18.6
-12,11,27:18.6
-11,11,27:18.6
-6,11,27:18.6
-5,11,27:18.6
-4,11,27:18.6
-3,11,27:18.6
-2,11,27:18.6
-1,11,27:18.6
2,11,27:18.6
3,11,27:18.6
-11,12,27:18.6
-10,12,27:18.6
2,12,27:18.6
3,12,27:18.6
7,12,27:18.6
7,-14,28:18.6
8,-14,28:18.6
11,-14,28:18.6
12,-14,28:18.6
-8,-13,28:18.6
-7,-13,28:18.6
-6,-13,28:18.6
-5,-13,28:18.6
-4,-13,28:18.6
-3,-13,28:18.6
-2,-13,28:18.6
-1,-13,28:18.6
0,-13,28:18.6
1,-13,28:18.6
2,-13,28:18.6
4,-13,28:18.6
6,-13,28:18.6
7,-13,28:18.6
8,-13,28:18.6
9,-13,28:18.6
10,-13,28:18.6
11,-13,28:18.6
12,-13,28:18.6
13,-13,28:18.6
-9,-12,28:18.6
-4,-12,28:18.6
-3,-12,28:18.6
-2,-12,28:18.6
-1,-12,28:18.6
0,-12,28:18.6
1,-12,28:18.6
2,-12,28:18.6
3,-12,28:18.6
5,-12,28:18.6
6,-12,28:18.6
7,-12,28:18.6
-9,-11,28:18.6
0,-11,28:18.6
1,-11,28:18.6
2,-11,28:18.6
3,-11,28:18.6
4,-11,28:18.6
5,-11,28:18.6
6,-11,28:18.6
13,-11,28:18.6
-9,-10,28:18.6
-2,-10,28:18.6
-1,-10,28:18.6
0,-10,28:18.6
6,-10,28:18.6
7,-10,28:18.6
8,-10,28:18.6
13,-10,28:18.6
14,-10,28:18.14
15,-10,28:18.14
-9,-9,28:18.6
-3,-9,28:18.6
-2,-9,28:18.6
-1,-9,28:18.6
7,-9,28:18.6
8,-9,28:18.6
9,-9,28:18.6
14,-9,28:18.6
15,-9,28:18.14
16,-9,28:18.14
17,-9,28:18.14
-9,-8,28:18.6
-8,-8,28:18.6
-4,-8,28:18.6
-3,-8,28:18.6
8,-8,28:18.6
9,-8,28:18.6
10,-8,28:18.6
13,-8,28:18.6
14,-8,28:18.6
15,-8,28:18.6
16,-8,28:18.6
-12,-7,28:18.6
-9,-7,28:18.6
-8,-7,28:18.6
-5,-7,28:18.6
-4,-7,28:18.6
9,-7,28:18.6
10,-7,28:18.6
11,-7,28:18.6
12,-7,28:18.6
13,-7,28:18.6
15,-7,28:18.6
16,-7,28:18.6
-12,-6,28:18.6
-11,-6,28:18.6
-9,-6,28:18.6
-8,-6,28:18.6
-5,-6,28:18.6
-4,-6,28:18.6
10,-6,28:18.6
11,-6,28:18.6
12,-6,28:18.6
14,-6,28:18.6
15,-6,28:18.6
16,-6,28:18.6
-11,-5,28:18.6
-10,-5,28:18.6
-9,-5,28:18.6
-8,-5,28:18.6
-5,-5,28:18.6
11,-5,28:18.6
12,-5,28:18.6
14,-5,28:18.6
15,-5,28:18.6
16,-5,28:18.6
-10,-4,28:18.6
-9,-4,28:18.6
-8,-4,28:18.6
-6,-4,28:18.6
-5,-4,28:18.6
12,-4,28:18.6
13,-4,28:18.6
14,-4,28:18.6
16,-4,28:18.6
17,-4,28:18.6
-12,-3,28:18.6
-8,-3,28:18.6
-7,-3,28:18.6
-6,-3,28:18.6
13,-3,28:18.6
14,-3,28:18.6
15,-3,28:18.6
17,-3,28:18.6
-12,-2,28:18.6
-11,-2,28:18.6
-8,-2,28:18.6
-7,-2,28:18.6
-6,-2,28:18.6
14,-2,28:18.6
17,-2,28:18.6
-11,-1,28:18.6
-10,-1,28:18.6
-8,-1,28:18.6
-7,-1,28:18.6
13,-1,28:18.6
14,-1,28:18.6
-10,0,28:18.6
-9,0,28:18.6
-8,0,28:18.6
-7,0,28:18.6
13,0,28:18.6
14,0,28:18.6
-10,1,28:18.6
-9,1,28:18.6
-8,1,28:18.6
-7,1,28:18.6
-6,1,28:18.6
13,1,28:18.6
14,1,28:18.6
15,1,28:18.6
16,1,28:18.6
17,1,28:18.6
-12,2,28:18.6
-11,2,28:18.6
-10,2,28:18.6
-9,2,28:18.6
-8,2,28:18.6
-7,2,28:18.6
-6,2,28:18.6
-4,2,28:18.6
-3,2,28:18.6
12,2,28:18.6
13,2,28:18.6
16,2,28:18.6
17,2,28:18.6
-12,3,28:18.6
-9,3,28:18.6
-8,3,28:18.6
-6,3,28:18.6
-5,3,28:18.6
-3,3,28:18.6
-2,3,28:18.6
11,3,28:18.6
12,3,28:18.6
15,3,28:18.6
16,3,28:18.6
17,3,28:18.6
-10,4,28:18.6
-9,4,28:18.6
-8,4,28:18.6
-5,4,28:18.6
-4,4,28:18.6
-2,4,28:18.6
0,4,28:18.6
1,4,28:18.6
2,4,28:18.6
3,4,28:18.6
11,4,28:18.6
15,4,28:18.6
16,4,28:18.6
17,4,28:18.6
-12,5,28:18.6
-11,5,28:18.6
-10,5,28:18.6
-9,5,28:18.6
-8,5,28:18.6
-4,5,28:18.6
-3,5,28:18.6
-2,5,28:18.6
-1,5,28:18.6
0,5,28:18.6
1,5,28:18.6
10,5,28:18.6
11,5,28:18.6
15,5,28:18.6
16,5,28:18.6
-12,6,28:18.6
-9,6,28:18.6
-8,6,28:18.6
-4,6,28:18.6
-3,6,28:18.6
-2,6,28:18.6
-1,6,28:18.6
9,6,28:18.6
10,6,28:18.6
15,6,28:18.6
16,6,28:18.6
-12,7,28:18.6
-11,7,28:18.6
-9,7,28:18.6
-6,7,28:18.6
-5,7,28:18.6
-4,7,28:18.6
-2,7,28:18.6
-1,7,28:18.6
0,7,28:18.6
7,7,28:18.6
8,7,28:18.6
9,7,28:18.6
16,7,28:18.6
-12,8,28:18.6
-11,8,28:18.6
-9,8,28:18.6
-8,8,28:18.6
-7,8,28:18.6
-6,8,28:18.6
-1,8,28:18.6
0,8,28:18.6
1,8,28:18.6
6,8,28:18.6
7,8,28:18.6
16,8,28:18.6
17,8,28:18.6
-12,9,28:18.6
-11,9,28:18.6
-10,9,28:18.6
-9,9,28:18.6
-8,9,28:18.6
0,9,28:18.6
1,9,28:18.6
2,9,28:18.6
3,9,28:18.6
4,9,28:18.6
5,9,28:18.6
6,9,28:18.6
16,9,28:18.6
17,9,28:18.6
-12,10,28:18.6
-11,10,28:18.6
-10,10,28:18.6
-9,10,28:18.6
0,10,28:18.6
1,10,28:18.6
2,10,28:18.6
3,10,28:18.6
4,10,28:18.6
5,10,28:18.6
6,10,28:18.6
7,10,28:18.6
8,10,28:18.6
9,10,28:18.14
10,10,28:18.14
11,10,28:18.14
12,10,28:18.14
13,10,28:18.14
14,10,28:18.14
15,10,28:18.14
17,10,28:18.6
-12,11,28:18.6
-11,11,28:18.6
-10,11,28:18.6
-3,11,28:18.6
-2,11,28:18.6
-1,11,28:18.6
0,11,28:18.6
1,11,28:18.6
2,11,28:18.6
3,11,28:18.6
5,11,28:18.6
6,11,28:18.6
7,11,28:18.6
8,11,28:18.6
9,11,28:18.6
10,11,28:18.14
-10,12,28:18.6
-9,12,28:18.6
-6,12,28:18.6
-5,12,28:18.6
-4,12,28:18.6
-3,12,28:18.6
-2,12,28:18.6
-1,12,28:18.6
1,12,28:18.6
2,12,28:18.6
6,12,28:18.6
7,12,28:18.6
11,-14,29:18.6
12,-14,29:18.6
-7,-13,29:18.6
-6,-13,29:18.6
-5,-13,29:18.6
-4,-13,29:18.6
-3,-13,29:18.6
-2,-13,29:18.6
-1,-13,29:18.6
0,-13,29:18.6
1,-13,29:18.6
2,-13,29:18.6
3,-13,29:18.6
4,-13,29:18.6
5,-13,29:18.6
6,-13,29:18.6
7,-13,29:18.6
8,-13,29:18.6
9,-13,29:18.6
10,-13,29:18.6
11,-13,29:18.6
12,-13,29:18.6
13,-13,29:18.6
-2,-12,29:18.6
-1,-12,29:18.6
0,-12,29:18.6
1,-12,29:18.6
2,-12,29:18.6
3,-12,29:18.6
5,-12,29:18.6
6,-12,29:18.6
14,-12,29:18.14
-10,-11,29:18.6
0,-11,29:18.6
1,-11,29:18.6
2,-11,29:18.6
4,-11,29:18.6
5,-11,29:18.6
6,-11,29:18.6
14,-11,29:18.14
-10,-10,29:18.6
-9,-10,29:18.6
-3,-10,29:18.6
-2,-10,29:18.6
-1,-10,29:18.6
7,-10,29:18.6
8,-10,29:18.6
9,-10,29:18.6
14,-10,29:18.14
15,-10,29:18.14
16,-10,29:18.14
-10,-9,29:18.6
-9,-9,29:18.6
-4,-9,29:18.6
-3,-9,29:18.6
9,-9,29:18.6
10,-9,29:18.6
14,-9,29:18.6
15,-9,29:18.6
16,-9,29:18.14
17,-9,29:18.14
-9,-8,29:18.6
-5,-8,29:18.6
-4,-8,29:18.6
10,-8,29:18.6
11,-8,29:18.6
14,-8,29:18.6
15,-8,29:18.6
16,-8,29:18.6
-12,-7,29:18.6
-9,-7,29:18.6
-6,-7,29:18.6
-5,-7,29:18.6
11,-7,29:18.6
13,-7,29:18.6
14,-7,29:18.6
15,-7,29:18.6
16,-7,29:18.6
-11,-6,29:18.6
-9,-6,29:18.6
-6,-6,29:18.6
-5,-6,29:18.6
12,-6,29:18.6
15,-6,29:18.6
16,-6,29:18.6
-10,-5,29:18.6
-9,-5,29:18.6
-6,-5,29:18.6
12,-5,29:18.6
13,-5,29:18.6
14,-5,29:18.6
15,-5,29:18.6
16,-5,29:18.6
17,-5,29:18.6
-9,-4,29:18.6
-6,-4,29:18.6
13,-4,29:18.6
14,-4,29:18.6
15,-4,29:18.6
16,-4,29:18.6
17,-4,29:18.6
-9,-3,29:18.6
-8,-3,29:18.6
-7,-3,29:18.6
13,-3,29:18.6
14,-3,29:18.6
15,-3,29:18.6
17,-3,29:18.6
-12,-2,29:18.6
-9,-2,29:18.6
-8,-2,29:18.6
-7,-2,29:18.6
14,-2,29:18.6
15,-2,29:18.6
-12,-1,29:18.6
-11,-1,29:18.6
-9,-1,29:18.6
-8,-1,29:18.6
14,-1,29:18.6
15,-1,29:18.6
16,-1,29:18.6
-12,0,29:18.6
-11,0,29:18.6
-10,0,29:18.6
-9,0,29:18.6
-8,0,29:18.6
13,0,29:18.6
14,0,29:18.6
15,0,29:18.6
-12,1,29:18.6
-11,1,29:18.6
-10,1,29:18.6
-9,1,29:18.6
-8,1,29:18.6
-7,1,29:18.6
13,1,29:18.6
15,1,29:18.6
16,1,29:18.6
17,1,29:18.6
-12,2,29:18.6
-10,2,29:18.6
-9,2,29:18.6
-8,2,29:18.6
-7,2,29:18.6
-5,2,29:18.6
-4,2,29:18.6
13,2,29:18.6
16,2,29:18.6
17,2,29:18.6
-9,3,29:18.6
-8,3,29:18.6
-7,3,29:18.6
-6,3,29:18.6
-4,3,29:18.6
-3,3,29:18.6
12,3,29:18.6
13,3,29:18.6
15,3,29:18.6
16,3,29:18.6
-9,4,29:18.6
-8,4,29:18.6
-6,4,29:18.6
-5,4,29:18.6
-4,4,29:18.6
12,4,29:18.6
15,4,29:18.6
16,4,29:18.6
17,4,29:18.6
-11,5,29:18.6
-10,5,29:18.6
-9,5,29:18.6
-8,5,29:18.6
-5,5,29:18.6
-4,5,29:18.6
-3,5,29:18.6
-2,5,29:18.6
0,5,29:18.6
1,5,29:18.6
2,5,29:18.6
3,5,29:18.6
11,5,29:18.6
12,5,29:18.6
15,5,29:18.6
16,5,29:18.6
17,5,29:18.6
-12,6,29:18.6
-11,6,29:18.6
-10,6,29:18.6
-9,6,29:18.6
-8,6,29:18.6
-5,6,29:18.6
-4,6,29:18.6
-3,6,29:18.6
-2,6,29:18.6
-1,6,29:18.6
0,6,29:18.6
1,6,29:18.6
2,6,29:18.6
10,6,29:18.6
11,6,29:18.6
16,6,29:18.6
-11,7,29:18.6
-10,7,29:18.6
-9,7,29:18.6
-8,7,29:18.6
-4,7,29:18.6
-3,7,29:18.6
-2,7,29:18.6
-1,7,29:18.6
9,7,29:18.6
10,7,29:18.6
15,7,29:18.6
16,7,29:18.6
-11,8,29:18.6
-10,8,29:18.6
-9,8,29:18.6
-8,8,29:18.6
-6,8,29:18.6
-5,8,29:18.6
-4,8,29:18.6
-3,8,29:18.6
-2,8,29:18.6
-1,8,29:18.6
7,8,29:18.6
8,8,29:18.6
9,8,29:18.6
16,8,29:18.6
17,8,29:18.6
-10,9,29:18.6
-9,9,29:18.6
-8,9,29:18.6
-7,9,29:18.6
-6,9,29:18.6
-1,9,29:18.6
0,9,29:18.6
1,9,29:18.6
6,9,29:18.6
7,9,29:18.6
8,9,29:18.6
-10,10,29:18.6
-9,10,29:18.6
-8,10,29:18.6
0,10,29:18.6
2,10,29:18.6
3,10,29:18.6
4,10,29:18.6
5,10,29:18.6
6,10,29:18.6
7,10,29:18.6
8,10,29:18.6
9,10,29:18.6
10,10,29:18.6
11,10,29:18.6
12,10,29:18.6
13,10,29:18.6
14,10,29:18.6
15,10,29:18.6
17,10,29:18.6
-12,11,29:18.6
-11,11,29:18.6
-10,11,29:18.6
-9,11,29:18.6
-6,11,29:18.6
-5,11,29:18.6
-4,11,29:18.6
-3,11,29:18.6
-2,11,29:18.6
-1,11,29:18.6
0,11,29:18.6
1,11,29:18.6
2,11,29:18.6
3,11,29:18.6
4,11,29:18.6
5,11,29:18.6
6,11,29:18.6
7,11,29:18.6
8,11,29:18.6
9,11,29:18.6
10,11,29:18.6
11,11,29:18.6
12,11,29:18.6
13,11,29:18.6
14,11,29:18.6
-12,12,29:18.6
-9,12,29:18.6
-8,12,29:18.6
-6,12,29:18.6
-5,12,29:18.6
-4,12,29:18.6
-3,12,29:18.6
0,12,29:18.6
1,12,29:18.6
4,12,29:18.6
5,12,29:18.6
6,12,29:18.6
11,-14,30:18.6
-6,-13,30:18.6
-5,-13,30:18.6
-4,-13,30:18.6
-3,-13,30:18.6
-2,-13,30:18.6
-1,-13,30:18.6
2,-13,30:18.6
5,-13,30:18.6
6,-13,30:18.6
7,-13,30:18.6
8,-13,30:18.6
9,-13,30:18.6
10,-13,30:18.6
11,-13,30:18.6
12,-13,30:18.6
13,-13,30:18.6
14,-13,30:18.14
-7,-12,30:18.6
-6,-12,30:18.6
-5,-12,30:18.6
-4,-12,30:18.6
-3,-12,30:18.6
-2,-12,30:18.6
-1,-12,30:18.6
0,-12,30:18.6
1,-12,30:18.6
2,-12,30:18.6
3,-12,30:18.6
5,-12,30:18.6
6,-12,30:18.6
7,-12,30:18.6
8,-12,30:18.6
9,-12,30:18.6
10,-12,30:18.6
11,-12,30:18.6
12,-12,30:18.6
13,-12,30:18.6
14,-12,30:18.14
-1,-11,30:18.6
0,-11,30:18.6
1,-11,30:18.6
2,-11,30:18.6
4,-11,30:18.6
5,-11,30:18.6
6,-11,30:18.6
7,-11,30:18.6
14,-11,30:18.14
17,-11,30:18.14
-10,-10,30:18.6
-9,-10,30:18.6
-8,-10,30:18.6
-4,-10,30:18.6
-3,-10,30:18.6
-2,-10,30:18.6
7,-10,30:18.6
8,-10,30:18.6
9,-10,30:18.6
10,-10,30:18.6
14,-10,30:18.14
15,-10,30:18.14
16,-10,30:18.14
17,-10,30:18.14
-10,-9,30:18.6
-9,-9,30:18.6
-8,-9,30:18.6
-6,-9,30:18.6
-5,-9,30:18.6
-4,-9,30:18.6
10,-9,30:18.6
11,-9,30:18.6
14,-9,30:18.6
15,-9,30:18.6
16,-9,30:18.6
17,-9,30:18.6
-12,-8,30:18.6
-10,-8,30:18.6
-9,-8,30:18.6
-8,-8,30:18.6
-6,-8,30:18.6
-5,-8,30:18.6
11,-8,30:18.6
14,-8,30:18.6
15,-8,30:18.6
16,-8,30:18.6
17,-8,30:18.6
-12,-7,30:18.6
-10,-7,30:18.6
-9,-7,30:18.6
-8,-7,30:18.6
-6,-7,30:18.6
11,-7,30:18.6
12,-7,30:18.6
14,-7,30:18.6
15,-7,30:18.6
16,-7,30:18.6
-9,-6,30:18.6
-8,-6,30:18.6
-7,-6,30:18.6
-6,-6,30:18.6
12,-6,30:18.6
14,-6,30:18.6
15,-6,30:18.6
16,-6,30:18.6
17,-6,30:18.6
-9,-5,30:18.6
-8,-5,30:18.6
-7,-5,30:18.6
12,-5,30:18.6
13,-5,30:18.6
14,-5,30:18.6
15,-5,30:18.6
16,-5,30:18.6
17,-5,30:18.6
-9,-4,30:18.6
-8,-4,30:18.6
13,-4,30:18.6
14,-4,30:18.6
15,-4,30:18.6
16,-4,30:18.6
17,-4,30:18.6
-9,-3,30:18.6
-8,-3,30:18.6
-7,-3,30:18.6
14,-3,30:18.6
15,-3,30:18.6
-9,-2,30:18.6
-8,-2,30:18.6
14,-2,30:18.6
15,-2,30:18.6
-9,-1,30:18.6
-8,-1,30:18.6
14,-1,30:18.6
15,-1,30:18.6
-12,0,30:18.6
-11,0,30:18.6
-9,0,30:18.6
-8,0,30:18.6
13,0,30:18.6
14,0,30:18.6
15,0,30:18.6
-12,1,30:18.6
-11,1,30:18.6
-9,1,30:18.6
-8,1,30:18.6
13,1,30:18.6
15,1,30:18.6
17,1,30:18.6
-11,2,30:18.6
-9,2,30:18.6
-8,2,30:18.6
-7,2,30:18.6
13,2,30:18.6
16,2,30:18.6
17,2,30:18.6
-9,3,30:18.6
-8,3,30:18.6
-7,3,30:18.6
13,3,30:18.6
15,3,30:18.6
16,3,30:18.6
-9,4,30:18.6
-8,4,30:18.6
-6,4,30:18.6
-4,4,30:18.6
12,4,30:18.6
15,4,30:18.6
16,4,30:18.6
-10,5,30:18.6
-9,5,30:18.6
-8,5,30:18.6
-6,5,30:18.6
-5,5,30:18.6
-4,5,30:18.6
-3,5,30:18.6
3,5,30:18.6
12,5,30:18.6
15,5,30:18.6
16,5,30:18.6
17,5,30:18.6
-12,6,30:18.6
-10,6,30:18.6
-9,6,30:18.6
-8,6,30:18.6
-5,6,30:18.6
-4,6,30:18.6
-3,6,30:18.6
0,6,30:18.6
1,6,30:18.6
2,6,30:18.6
3,6,30:18.6
12,6,30:18.6
15,6,30:18.6
16,6,30:18.6
17,6,30:18.6
-10,7,30:18.6
-9,7,30:18.6
-8,7,30:18.6
-5,7,30:18.6
-4,7,30:18.6
-3,7,30:18.6
-2,7,30:18.6
-1,7,30:18.6
0,7,30:18.6
1,7,30:18.6
2,7,30:18.6
10,7,30:18.6
11,7,30:18.6
15,7,30:18.6
16,7,30:18.6
17,7,30:18.6
-10,8,30:18.6
-9,8,30:18.6
-8,8,30:18.6
-4,8,30:18.6
-3,8,30:18.6
-2,8,30:18.6
-1,8,30:18.6
8,8,30:18.6
9,8,30:18.6
10,8,30:18.6
16,8,30:18.6
17,8,30:18.6
-9,9,30:18.6
-8,9,30:18.6
-6,9,30:18.6
-5,9,30:18.6
-4,9,30:18.6
-2,9,30:18.6
-1,9,30:18.6
0,9,30:18.6
1,9,30:18.6
6,9,30:18.6
7,9,30:18.6
8,9,30:18.6
13,9,30:18.6
14,9,30:18.6
-9,10,30:18.6
-8,10,30:18.6
-7,10,30:18.6
-6,10,30:18.6
-3,10,30:18.6
-2,10,30:18.6
-1,10,30:18.6
0,10,30:18.6
1,10,30:18.6
2,10,30:18.6
3,10,30:18.6
4,10,30:18.6
5,10,30:18.6
6,10,30:18.6
7,10,30:18.6
8,10,30:18.6
9,10,30:18.6
10,10,30:18.6
11,10,30:18.6
12,10,30:18.6
13,10,30:18.6
14,10,30:18.6
-10,11,30:18.6
-9,11,30:18.6
-8,11,30:18.6
-6,11,30:18.6
-5,11,30:18.6
-4,11,30:18.6
-3,11,30:18.6
-2,11,30:18.6
-1,11,30:18.6
0,11,30:18.6
1,11,30:18.6
2,11,30:18.6
3,11,30:18.6
4,11,30:18.6
5,11,30:18.6
6,11,30:18.6
7,11,30:18.6
8,11,30:18.6
9,11,30:18.6
10,11,30:18.6
11,11,30:18.6
12,11,30:18.6
13,11,30:18.6
-12,12,30:18.6
-11,12,30:18.6
-10,12,30:18.6
-8,12,30:18.6
-7,12,30:18.6
-6,12,30:18.6
-5,12,30:18.6
-4,12,30:18.6
-3,12,30:18.6
-2,12,30:18.6
0,12,30:18.6
2,12,30:18.6
3,12,30:18.6
4,12,30:18.6
9,-14,31:18.6
-6,-13,31:18.6
-5,-13,31:18.6
-4,-13,31:18.6
-3,-13,31:18.6
-2,-13,31:18.6
-1,-13,31:18.6
0,-13,31:18.6
5,-13,31:18.6
6,-13,31:18.6
7,-13,31:18.6
8,-13,31:18.6
13,-13,31:18.6
-8,-12,31:18.6
-7,-12,31:18.6
-6,-12,31:18.6
-5,-12,31:18.6
-4,-12,31:18.6
-3,-12,31:18.6
-2,-12,31:18.6
-1,-12,31:18.6
0,-12,31:18.6
1,-12,31:18.6
2,-12,31:18.6
3,-12,31:18.6
5,-12,31:18.6
6,-12,31:18.6
7,-12,31:18.6
8,-12,31:18.6
9,-12,31:18.6
10,-12,31:18.6
11,-12,31:18.6
12,-12,31:18.6
13,-12,31:18.6
14,-12,31:18.6
-8,-11,31:18.6
-2,-11,31:18.6
-1,-11,31:18.6
0,-11,31:18.6
1,-11,31:18.6
5,-11,31:18.6
6,-11,31:18.6
7,-11,31:18.6
13,-11,31:18.6
14,-11,31:18.6
15,-11,31:18.6
-8,-10,31:18.6
-4,-10,31:18.6
-3,-10,31:18.6
-2,-10,31:18.6
8,-10,31:18.6
9,-10,31:18.6
10,-10,31:18.6
13,-10,31:18.6
14,-10,31:18.6
15,-10,31:18.6
17,-10,31:18.6
-10,-9,31:18.6
-8,-9,31:18.6
-5,-9,31:18.6
10,-9,31:18.6
11,-9,31:18.6
14,-9,31:18.6
16,-9,31:18.6
17,-9,31:18.6
-10,-8,31:18.6
-8,-8,31:18.6
-6,-8,31:18.6
11,-8,31:18.6
14,-8,31:18.6
15,-8,31:18.6
16,-8,31:18.6
17,-8,31:18.6
-10,-7,31:18.6
-8,-7,31:18.6
-6,-7,31:18.6
12,-7,31:18.6
14,-7,31:18.6
15,-7,31:18.6
16,-7,31:18.6
17,-7,31:18.6
-10,-6,31:18.6
-8,-6,31:18.6
-7,-6,31:18.6
12,-6,31:18.6
14,-6,31:18.6
15,-6,31:18.6
17,-6,31:18.6
-10,-5,31:18.6
-9,-5,31:18.6
-8,-5,31:18.6
-7,-5,31:18.6
13,-5,31:18.6
14,-5,31:18.6
15,-5,31:18.6
16,-5,31:18.6
17,-5,31:18.6
-9,-4,31:18.6
-8,-4,31:18.6
13,-4,31:18.6
14,-4,31:18.6
15,-4,31:18.6
-9,-3,31:18.6
-8,-3,31:18.6
14,-3,31:18.6
15,-3,31:18.6
-9,-2,31:18.6
-8,-2,31:18.6
14,-2,31:18.6
-12,-1,31:18.6
-9,-1,31:18.6
-8,-1,31:18.6
14,-1,31:18.6
15,-1,31:18.6
-12,0,31:18.6
-9,0,31:18.6
-8,0,31:18.6
14,0,31:18.6
15,0,31:18.6
-12,1,31:18.6
-9,1,31:18.6
-8,1,31:18.6
13,1,31:18.6
14,1,31:18.6
15,1,31:18.6
17,1,31:18.6
-12,2,31:18.6
-9,2,31:18.6
-8,2,31:18.6
-7,2,31:18.6
13,2,31:18.6
14,2,31:18.6
16,2,31:18.6
17,2,31:18.6
-9,3,31:18.6
-8,3,31:18.6
-7,3,31:18.6
13,3,31:18.6
14,3,31:18.6
15,3,31:18.6
16,3,31:18.6
-9,4,31:18.6
-8,4,31:18.6
-7,4,31:18.6
-6,4,31:18.6
12,4,31:18.6
13,4,31:18.6
15,4,31:18.6
16,4,31:18.6
-10,5,31:18.6
-9,5,31:18.6
-8,5,31:18.6
-7,5,31:18.6
-6,5,31:18.6
-5,5,31:18.6
12,5,31:18.6
15,5,31:18.6
16,5,31:18.6
-10,6,31:18.6
-9,6,31:18.6
-8,6,31:18.6
-7,6,31:18.6
-6,6,31:18.6
-5,6,31:18.6
-4,6,31:18.6
11,6,31:18.6
12,6,31:18.6
15,6,31:18.6
16,6,31:18.6
17,6,31:18.6
-10,7,31:18.6
-9,7,31:18.6
-8,7,31:18.6
-7,7,31:18.6
-5,7,31:18.6
-4,7,31:18.6
-3,7,31:18.6
0,7,31:18.6
1,7,31:18.6
2,7,31:18.6
10,7,31:18.6
11,7,31:18.6
15,7,31:18.6
16,7,31:18.6
17,7,31:18.6
-10,8,31:18.6
-8,8,31:18.6
-4,8,31:18.6
-3,8,31:18.6
-2,8,31:18.6
-1,8,31:18.6
0,8,31:18.6
1,8,31:18.6
2,8,31:18.6
8,8,31:18.6
9,8,31:18.6
10,8,31:18.6
15,8,31:18.6
-8,9,31:18.6
-7,9,31:18.6
-4,9,31:18.6
-3,9,31:18.6
-2,9,31:18.6
-1,9,31:18.6
0,9,31:18.6
1,9,31:18.6
4,9,31:18.6
5,9,31:18.6
6,9,31:18.6
7,9,31:18.6
8,9,31:18.6
9,9,31:18.6
10,9,31:18.6
11,9,31:18.6
12,9,31:18.6
13,9,31:18.6
14,9,31:18.6
15,9,31:18.6
-8,10,31:18.6
-7,10,31:18.6
-6,10,31:18.6
-5,10,31:18.6
-4,10,31:18.6
-3,10,31:18.6
-2,10,31:18.6
-1,10,31:18.6
0,10,31:18.6
1,10,31:18.6
2,10,31:18.6
3,10,31:18.6
4,10,31:18.6
5,10,31:18.6
6,10,31:18.6
7,10,31:18.6
8,10,31:18.6
-8,11,31:18.6
-7,11,31:18.6
-6,11,31:18.6
-2,11,31:18.6
-1,11,31:18.6
0,11,31:18.6
1,11,31:18.6
2,11,31:18.6
3,11,31:18.6
4,11,31:18.6
5,11,31:18.6
6,11,31:18.6
7,11,31:18.6
8,11,31:18.6
9,11,31:18.6
10,11,31:18.6
11,11,31:18.6
12,11,31:18.6
13,11,31:18.6
-10,12,31:18.6
-9,12,31:18.6
-8,12,31:18.6
-7,12,31:18.6
-6,12,31:18.6
-5,12,31:18.6
-4,12,31:18.6
-3,12,31:18.6
-2,12,31:18.6
-1,12,31:18.6
0,12,31:18.6
1,12,31:18.6
2,12,31:18.6
8,-14,32:18.6
9,-14,32:18.6
-5,-13,32:18.6
-4,-13,32:18.6
-3,-13,32:18.6
-2,-13,32:18.6
-1,-13,32:18.6
0,-13,32:18.6
1,-13,32:18.6
4,-13,32:18.6
5,-13,32:18.6
6,-13,32:18.6
7,-13,32:18.6
8,-13,32:18.6
-8,-12,32:18.6
-7,-12,32:18.6
1,-12,32:18.6
2,-12,32:18.6
3,-12,32:18.6
5,-12,32:18.6
6,-12,32:18.6
7,-12,32:18.6
8,-12,32:18.6
9,-12,32:18.6
10,-12,32:18.6
11,-12,32:18.6
12,-12,32:18.6
13,-12,32:18.6
14,-12,32:18.6
-8,-11,32:18.6
-7,-11,32:18.6
-6,-11,32:18.6
-5,-11,32:18.6
-4,-11,32:18.6
-3,-11,32:18.6
-2,-11,32:18.6
-1,-11,32:18.6
0,-11,32:18.6
1,-11,32:18.6
2,-11,32:18.6
3,-11,32:18.6
4,-11,32:18.6
5,-11,32:18.6
6,-11,32:18.6
7,-11,32:18.6
8,-11,32:18.6
9,-11,32:18.6
10,-11,32:18.6
11,-11,32:18.6
12,-11,32:18.6
13,-11,32:18.6
14,-11,32:18.6
-8,-10,32:18.6
-7,-10,32:18.6
-4,-10,32:18.6
-3,-10,32:18.6
8,-10,32:18.6
9,-10,32:18.6
13,-10,32:18.6
-8,-9,32:18.6
-7,-9,32:18.6
-5,-9,32:18.6
10,-9,32:18.6
13,-9,32:18.6
16,-9,32:18.6
17,-9,32:18.6
-10,-8,32:18.6
-8,-8,32:18.6
-7,-8,32:18.6
-6,-8,32:18.6
-5,-8,32:18.6
11,-8,32:18.6
13,-8,32:18.6
16,-8,32:18.6
17,-8,32:18.6
-10,-7,32:18.6
-8,-7,32:18.6
-7,-7,32:18.6
-6,-7,32:18.6
12,-7,32:18.6
13,-7,32:18.6
15,-7,32:18.6
16,-7,32:18.6
17,-7,32:18.6
-10,-6,32:18.6
-8,-6,32:18.6
-7,-6,32:18.6
12,-6,32:18.6
13,-6,32:18.6
14,-6,32:18.6
15,-6,32:18.6
17,-6,32:18.6
-10,-5,32:18.6
-8,-5,32:18.6
-7,-5,32:18.6
13,-5,32:18.6
14,-5,32:18.6
15,-5,32:18.6
-10,-4,32:18.6
-8,-4,32:18.6
13,-4,32:18.6
14,-4,32:18.6
15,-4,32:18.6
-10,-3,32:18.6
-9,-3,32:18.6
-8,-3,32:18.6
-7,-3,32:18.6
13,-3,32:18.6
14,-3,32:18.6
15,-3,32:18.6
-9,-2,32:18.6
-8,-2,32:18.6
-7,-2,32:18.6
14,-2,32:18.6
15,-2,32:18.6
-9,-1,32:18.6
-7,-1,32:18.6
14,-1,32:18.6
15,-1,32:18.6
-9,0,32:18.6
-7,0,32:18.6
14,0,32:18.6
15,0,32:18.6
-9,1,32:18.6
-8,1,32:18.6
-7,1,32:18.6
13,1,32:18.6
14,1,32:18.6
15,1,32:18.6
17,1,32:18.6
-9,2,32:18.6
-8,2,32:18.6
-7,2,32:18.6
13,2,32:18.6
14,2,32:18.6
16,2,32:18.6
17,2,32:18.6
-10,3,32:18.6
-9,3,32:18.6
-8,3,32:18.6
-7,3,32:18.6
13,3,32:18.6
14,3,32:18.6
16,3,32:18.6
-10,4,32:18.6
-7,4,32:18.6
13,4,32:18.6
14,4,32:18.6
16,4,32:18.6
-10,5,32:18.6
-7,5,32:18.6
-6,5,32:18.6
12,5,32:18.6
14,5,32:18.6
16,5,32:18.6
-10,6,32:18.6
-8,6,32:18.6
-7,6,32:18.6
-6,6,32:18.6
-5,6,32:18.6
11,6,32:18.6
12,6,32:18.6
14,6,32:18.6
17,6,32:18.6
-10,7,32:18.6
-8,7,32:18.6
-7,7,32:18.6
-5,7,32:18.6
-4,7,32:18.6
10,7,32:18.6
11,7,32:18.6
14,7,32:18.6
15,7,32:18.6
17,7,32:18.6
-7,8,32:18.6
-4,8,32:18.6
-3,8,32:18.6
-2,8,32:18.6
1,8,32:18.6
2,8,32:18.6
8,8,32:18.6
9,8,32:18.6
10,8,32:18.6
12,8,32:18.6
13,8,32:18.6
14,8,32:18.6
15,8,32:18.6
-7,9,32:18.6
-6,9,32:18.6
-4,9,32:18.6
-3,9,32:18.6
-2,9,32:18.6
-1,9,32:18.6
0,9,32:18.6
1,9,32:18.6
2,9,32:18.6
3,9,32:18.6
4,9,32:18.6
5,9,32:18.6
6,9,32:18.6
7,9,32:18.6
8,9,32:18.6
9,9,32:18.6
10,9,32:18.6
11,9,32:18.6
12,9,32:18.6
13,9,32:18.6
14,9,32:18.6
15,9,32:18.6
-8,10,32:18.6
-7,10,32:18.6
-6,10,32:18.6
-5,10,32:18.6
-4,10,32:18.6
-3,10,32:18.6
-2,10,32:18.6
-1,10,32:18.6
1,10,32:18.6
2,10,32:18.6
3,10,32:18.6
4,10,32:18.6
5,10,32:18.6
6,10,32:18.6
-7,11,32:18.6
-6,11,32:18.6
-5,11,32:18.6
-4,11,32:18.6
-3,11,32:18.6
-2,11,32:18.6
-1,11,32:18.6
0,11,32:18.6
1,11,32:18.6
2,11,32:18.6
3,11,32:18.6
4,11,32:18.6
5,11,32:18.6
6,11,32:18.6
7,11,32:18.6
8,11,32:18.6
9,11,32:18.6
10,11,32:18.6
11,11,32:18.6
12,11,32:18.6
13,11,32:18.6
-8,12,32:18.6
-7,12,32:18.6
-6,12,32:18.6
-5,12,32:18.6
-4,12,32:18.6
-3,12,32:18.6
-2,12,32:18.6
-1,12,32:18.6
0,12,32:18.6
7,-14,33:18.6
8,-14,33:18.6
9,-14,33:18.6
-4,-13,33:18.6
-3,-13,33:18.6
-2,-13,33:18.6
-1,-13,33:18.6
0,-13,33:18.6
1,-13,33:18.6
2,-13,33:18.6
3,-13,33:18.6
4,-13,33:18.6
5,-13,33:18.6
6,-13,33:18.6
7,-13,33:18.6
-7,-12,33:18.6
0,-12,33:18.6
1,-12,33:18.6
2,-12,33:18.6
3,-12,33:18.6
5,-12,33:18.6
-8,-11,33:18.6
-7,-11,33:18.6
-6,-11,33:18.6
-5,-11,33:18.6
-4,-11,33:18.6
-3,-11,33:18.6
-2,-11,33:18.6
-1,-11,33:18.6
0,-11,33:18.6
1,-11,33:18.6
2,-11,33:18.6
3,-11,33:18.6
4,-11,33:18.6
5,-11,33:18.6
6,-11,33:18.6
7,-11,33:18.6
8,-11,33:18.6
9,-11,33:18.6
10,-11,33:18.6
11,-11,33:18.6
12,-11,33:18.6
13,-11,33:18.6
14,-11,33:18.6
-7,-10,33:18.6
-4,-10,33:18.6
-3,-10,33:18.6
8,-10,33:18.6
9,-10,33:18.6
12,-10,33:18.6
13,-10,33:18.6
-7,-9,33:18.6
-5,-9,33:18.6
-4,-9,33:18.6
9,-9,33:18.6
10,-9,33:18.6
12,-9,33:18.6
13,-9,33:18.6
-7,-8,33:18.6
-6,-8,33:18.6
-5,-8,33:18.6
11,-8,33:18.6
12,-8,33:18.6
13,-8,33:18.6
17,-8,33:18.6
-7,-7,33:18.6
-6,-7,33:18.6
12,-7,33:18.6
13,-7,33:18.6
16,-7,33:18.6
17,-7,33:18.6
-10,-6,33:18.6
-7,-6,33:18.6
13,-6,33:18.6
15,-6,33:18.6
-10,-5,33:18.6
-8,-5,33:18.6
-7,-5,33:18.6
13,-5,33:18.6
15,-5,33:18.6
-10,-4,33:18.6
-8,-4,33:18.6
13,-4,33:18.6
14,-4,33:18.6
15,-4,33:18.6
-10,-3,33:18.6
-8,-3,33:18.6
-7,-3,33:18.6
13,-3,33:18.6
14,-3,33:18.6
15,-3,33:18.6
-10,-2,33:18.6
-9,-2,33:18.6
-7,-2,33:18.6
13,-2,33:18.6
15,-2,33:18.6
-10,-1,33:18.6
-9,-1,33:18.6
-7,-1,33:18.6
13,-1,33:18.6
14,-1,33:18.6
15,-1,33:18.6
-9,0,33:18.6
-7,0,33:18.6
13,0,33:18.6
14,0,33:18.6
15,0,33:18.6
-10,1,33:18.6
-9,1,33:18.6
-7,1,33:18.6
13,1,33:18.6
14,1,33:18.6
15,1,33:18.6
16,1,33:18.6
17,1,33:18.6
-10,2,33:18.6
-9,2,33:18.6
-8,2,33:18.6
-7,2,33:18.6
13,2,33:18.6
14,2,33:18.6
16,2,33:18.6
-10,3,33:18.6
-8,3,33:18.6
-7,3,33:18.6
13,3,33:18.6
14,3,33:18.6
16,3,33:18.6
-10,4,33:18.6
-7,4,33:18.6
12,4,33:18.6
13,4,33:18.6
14,4,33:18.6
16,4,33:18.6
-10,5,33:18.6
-7,5,33:18.6
-6,5,33:18.6
12,5,33:18.6
14,5,33:18.6
17,5,33:18.6
-10,6,33:18.6
-7,6,33:18.6
-6,6,33:18.6
-5,6,33:18.6
11,6,33:18.6
14,6,33:18.6
17,6,33:18.6
-7,7,33:18.6
-6,7,33:18.6
-4,7,33:18.6
10,7,33:18.6
14,7,33:18.6
-7,8,33:18.6
-6,8,33:18.6
-3,8,33:18.6
-2,8,33:18.6
3,8,33:18.6
4,8,33:18.6
5,8,33:18.6
6,8,33:18.6
7,8,33:18.6
8,8,33:18.6
9,8,33:18.6
10,8,33:18.6
11,8,33:18.6
12,8,33:18.6
13,8,33:18.6
14,8,33:18.6
15,8,33:18.6
-8,9,33:18.6
-7,9,33:18.6
-6,9,33:18.6
-5,9,33:18.6
-4,9,33:18.6
-3,9,33:18.6
-2,9,33:18.6
-1,9,33:18.6
0,9,33:18.6
1,9,33:18.6
2,9,33:18.6
3,9,33:18.6
4,9,33:18.6
5,9,33:18.6
6,9,33:18.6
7,9,33:18.6
8,9,33:18.6
14,9,33:18.6
-4,10,33:18.6
-3,10,33:18.6
1,10,33:18.6
2,10,33:18.6
3,10,33:18.6
5,10,33:18.6
6,10,33:18.6
-5,11,33:18.6
-4,11,33:18.6
-3,11,33:18.6
-2,11,33:18.6
-1,11,33:18.6
0,11,33:18.6
1,11,33:18.6
2,11,33:18.6
3,11,33:18.6
4,11,33:18.6
5,11,33:18.6
6,11,33:18.6
7,11,33:18.6
8,11,33:18.6
9,11,33:18.6
10,11,33:18.6
11,11,33:18.6
12,11,33:18.6
-6,12,33:18.6
-5,12,33:18.6
-4,12,33:18.6
-3,12,33:18.6
-2,12,33:18.6
-1,12,33:18.6
-3,-14,34:18.6
6,-14,34:18.6
7,-14,34:18.6
-3,-13,34:18.6
-2,-13,34:18.6
-1,-13,34:18.6
0,-13,34:18.6
1,-13,34:18.6
2,-13,34:18.6
3,-13,34:18.6
4,-13,34:18.6
5,-13,34:18.6
6,-13,34:18.6
0,-12,34:18.6
1,-12,34:18.6
2,-12,34:18.6
5,-12,34:18.6
6,-12,34:18.6
12,-12,34:18.6
-7,-11,34:18.6
-6,-11,34:18.6
-3,-11,34:18.6
-2,-11,34:18.6
-1,-11,34:18.6
0,-11,34:18.6
1,-11,34:18.6
2,-11,34:18.6
3,-11,34:18.6
4,-11,34:18.6
5,-11,34:18.6
6,-11,34:18.6
7,-11,34:18.6
8,-11,34:18.6
9,-11,34:18.6
10,-11,34:18.6
11,-11,34:18.6
12,-11,34:18.6
13,-11,34:18.6
-7,-10,34:18.6
-6,-10,34:18.6
-5,-10,34:18.6
-4,-10,34:18.6
-3,-10,34:18.6
-2,-10,34:18.6
-1,-10,34:18.6
0,-10,34:18.6
1,-10,34:18.6
2,-10,34:18.6
3,-10,34:18.6
4,-10,34:18.6
5,-10,34:18.6
6,-10,34:18.6
7,-10,34:18.6
8,-10,34:18.6
9,-10,34:18.6
10,-10,34:18.6
11,-10,34:18.6
12,-10,34:18.6
13,-10,34:18.6
-7,-9,34:18.6
-6,-9,34:18.6
-4,-9,34:18.6
9,-9,34:18.6
10,-9,34:18.6
12,-9,34:18.6
-7,-8,34:18.6
-6,-8,34:18.6
-5,-8,34:18.6
10,-8,34:18.6
11,-8,34:18.6
12,-8,34:18.6
-7,-7,34:18.6
-6,-7,34:18.6
11,-7,34:18.6
12,-7,34:18.6
-7,-6,34:18.6
-6,-6,34:18.6
12,-6,34:18.6
13,-6,34:18.6
16,-6,34:18.6
-10,-5,34:18.6
-8,-5,34:18.6
-7,-5,34:18.6
-6,-5,34:18.6
12,-5,34:18.6
13,-5,34:18.6
14,-5,34:18.6
15,-5,34:18.6
-10,-4,34:18.6
-8,-4,34:18.6
-6,-4,34:18.6
12,-4,34:18.6
13,-4,34:18.6
14,-4,34:18.6
15,-4,34:18.6
-10,-3,34:18.6
-9,-3,34:18.6
-6,-3,34:18.6
12,-3,34:18.6
13,-3,34:18.6
14,-3,34:18.6
15,-3,34:18.6
-10,-2,34:18.6
-9,-2,34:18.6
-6,-2,34:18.6
12,-2,34:18.6
13,-2,34:18.6
15,-2,34:18.6
-10,-1,34:18.6
-9,-1,34:18.6
-6,-1,34:18.6
13,-1,34:18.6
14,-1,34:18.6
15,-1,34:18.6
-10,0,34:18.6
-6,0,34:18.6
13,0,34:18.6
14,0,34:18.6
15,0,34:18.6
16,0,34:18.6
-10,1,34:18.6
-9,1,34:18.6
-6,1,34:18.6
13,1,34:18.6
14,1,34:18.6
16,1,34:18.6
-10,2,34:18.6
-9,2,34:18.6
-6,2,34:18.6
13,2,34:18.6
14,2,34:18.6
16,2,34:18.6
-10,3,34:18.6
-8,3,34:18.6
-6,3,34:18.6
13,3,34:18.6
16,3,34:18.6
-10,4,34:18.6
-8,4,34:18.6
-7,4,34:18.6
-6,4,34:18.6
12,4,34:18.6
13,4,34:18.6
-7,5,34:18.6
-6,5,34:18.6
11,5,34:18.6
12,5,34:18.6
13,5,34:18.6
-6,6,34:18.6
-5,6,34:18.6
-4,6,34:18.6
10,6,34:18.6
11,6,34:18.6
13,6,34:18.6
-6,7,34:18.6
-4,7,34:18.6
-3,7,34:18.6
9,7,34:18.6
10,7,34:18.6
11,7,34:18.6
12,7,34:18.6
13,7,34:18.6
14,7,34:18.6
-7,8,34:18.6
-6,8,34:18.6
-5,8,34:18.6
-4,8,34:18.6
-3,8,34:18.6
-2,8,34:18.6
-1,8,34:18.6
0,8,34:18.6
1,8,34:18.6
2,8,34:18.6
3,8,34:18.6
4,8,34:18.6
5,8,34:18.6
6,8,34:18.6
7,8,34:18.6
8,8,34:18.6
9,8,34:18.6
10,8,34:18.6
11,8,34:18.6
12,8,34:18.6
13,8,34:18.6
14,8,34:18.6
-7,9,34:18.6
-6,9,34:18.6
-5,9,34:18.6
-4,9,34:18.6
-3,9,34:18.6
-2,9,34:18.6
-1,9,34:18.6
0,9,34:18.6
7,9,34:18.6
8,9,34:18.6
13,9,34:18.6
1,10,34:18.6
2,10,34:18.6
3,10,34:18.6
5,10,34:18.6
6,10,34:18.6
0,11,34:18.6
1,11,34:18.6
2,11,34:18.6
3,11,34:18.6
4,11,34:18.6
5,11,34:18.6
6,11,34:18.6
7,11,34:18.6
8,11,34:18.6
9,11,34:18.6
10,11,34:18.6
11,11,34:18.6
-4,12,34:18.6
-3,12,34:18.6
-2,12,34:18.6
-1,12,34:18.6
-2,-14,35:18.6
6,-14,35:18.6
7,-14,35:18.6
-2,-13,35:18.6
-1,-13,35:18.6
0,-13,35:18.6
1,-13,35:18.6
2,-13,35:18.6
3,-13,35:18.6
4,-13,35:18.6
5,-13,35:18.6
-1,-12,35:18.6
0,-12,35:18.6
1,-12,35:18.6
2,-12,35:18.6
5,-12,35:18.6
6,-12,35:18.6
-6,-11,35:18.6
-2,-11,35:18.6
-1,-11,35:18.6
7,-11,35:18.6
11,-11,35:18.6
-7,-10,35:18.6
-6,-10,35:18.6
-5,-10,35:18.6
-4,-10,35:18.6
-3,-10,35:18.6
-2,-10,35:18.6
-1,-10,35:18.6
0,-10,35:18.6
1,-10,35:18.6
2,-10,35:18.6
3,-10,35:18.6
4,-10,35:18.6
5,-10,35:18.6
6,-10,35:18.6
7,-10,35:18.6
8,-10,35:18.6
9,-10,35:18.6
10,-10,35:18.6
11,-10,35:18.6
12,-10,35:18.6
13,-10,35:18.6
-6,-9,35:18.6
-4,-9,35:18.6
-3,-9,35:18.6
9,-9,35:18.6
10,-9,35:18.6
11,-9,35:18.6
12,-9,35:18.6
-6,-8,35:18.6
-5,-8,35:18.6
-4,-8,35:18.6
10,-8,35:18.6
11,-8,35:18.6
12,-8,35:18.6
-6,-7,35:18.6
-5,-7,35:18.6
11,-7,35:18.6
12,-7,35:18.6
-7,-6,35:18.6
-6,-6,35:18.6
12,-6,35:18.6
13,-6,35:18.6
-8,-5,35:18.6
-7,-5,35:18.6
-6,-5,35:18.6
12,-5,35:18.6
13,-5,35:18.6
14,-5,35:18.6
16,-5,35:18.6
-8,-4,35:18.6
-6,-4,35:18.6
12,-4,35:18.6
14,-4,35:18.6
15,-4,35:18.6
-9,-3,35:18.6
-6,-3,35:18.6
12,-3,35:18.6
15,-3,35:18.6
-10,-2,35:18.6
-9,-2,35:18.6
-6,-2,35:18.6
12,-2,35:18.6
15,-2,35:18.6
-10,-1,35:18.6
-6,-1,35:18.6
12,-1,35:18.6
15,-1,35:18.6
16,-1,35:18.6
-10,0,35:18.6
-6,0,35:18.6
12,0,35:18.6
14,0,35:18.6
16,0,35:18.6
-10,1,35:18.6
-9,1,35:18.6
-6,1,35:18.6
12,1,35:18.6
14,1,35:18.6
-10,2,35:18.6
-9,2,35:18.6
-6,2,35:18.6
12,2,35:18.6
13,2,35:18.6
14,2,35:18.6
-10,3,35:18.6
-9,3,35:18.6
-8,3,35:18.6
-6,3,35:18.6
12,3,35:18.6
13,3,35:18.6
-8,4,35:18.6
-7,4,35:18.6
-6,4,35:18.6
12,4,35:18.6
13,4,35:18.6
-6,5,35:18.6
-5,5,35:18.6
11,5,35:18.6
12,5,35:18.6
13,5,35:18.6
-6,6,35:18.6
-5,6,35:18.6
-4,6,35:18.6
10,6,35:18.6
13,6,35:18.6
-6,7,35:18.6
-5,7,35:18.6
-4,7,35:18.6
-3,7,35:18.6
2,7,35:18.6
3,7,35:18.6
4,7,35:18.6
5,7,35:18.6
6,7,35:18.6
7,7,35:18.6
8,7,35:18.6
9,7,35:18.6
10,7,35:18.6
11,7,35:18.6
12,7,35:18.6
13,7,35:18.6
-7,8,35:18.6
-6,8,35:18.6
-5,8,35:18.6
-4,8,35:18.6
-3,8,35:18.6
-2,8,35:18.6
-1,8,35:18.6
0,8,35:18.6
1,8,35:18.6
2,8,35:18.6
3,8,35:18.6
4,8,35:18.6
5,8,35:18.6
6,8,35:18.6
8,8,35:18.6
9,8,35:18.6
12,8,35:18.6
13,8,35:18.6
-5,9,35:18.6
-1,9,35:18.6
0,9,35:18.6
7,9,35:18.6
8,9,35:18.6
1,10,35:18.6
2,10,35:18.6
3,10,35:18.6
5,10,35:18.6
6,10,35:18.6
0,11,35:18.6
1,11,35:18.6
2,11,35:18.6
3,11,35:18.6
4,11,35:18.6
5,11,35:18.6
6,11,35:18.6
7,11,35:18.6
8,11,35:18.6
9,11,35:18.6
10,11,35:18.6
-2,12,35:18.6
-1,12,35:18.6
5,-14,36:18.6
6,-14,36:18.6
0,-13,36:18.6
1,-13,36:18.6
2,-13,36:18.6
3,-13,36:18.6
4,-13,36:18.6
5,-13,36:18.6
-1,-12,36:18.6
0,-12,36:18.6
1,-12,36:18.6
5,-12,36:18.6
6,-12,36:18.6
-5,-11,36:18.6
-2,-11,36:18.6
-1,-11,36:18.6
6,-11,36:18.6
7,-11,36:18.6
11,-11,36:18.6
-6,-10,36:18.6
-5,-10,36:18.6
-3,-10,36:18.6
-2,-10,36:18.6
-1,-10,36:18.6
0,-10,36:18.6
1,-10,36:18.6
2,-10,36:18.6
3,-10,36:18.6
4,-10,36:18.6
5,-10,36:18.6
6,-10,36:18.6
7,-10,36:18.6
8,-10,36:18.6
9,-10,36:18.6
10,-10,36:18.6
11,-10,36:18.6
-7,-9,36:18.6
-6,-9,36:18.6
-5,-9,36:18.6
-4,-9,36:18.6
-3,-9,36:18.6
-2,-9,36:18.6
-1,-9,36:18.6
0,-9,36:18.6
1,-9,36:18.6
2,-9,36:18.6
3,-9,36:18.6
4,-9,36:18.6
5,-9,36:18.6
6,-9,36:18.6
7,-9,36:18.6
8,-9,36:18.6
9,-9,36:18.6
10,-9,36:18.6
11,-9,36:18.6
12,-9,36:18.6
13,-9,36:18.6
-6,-8,36:18.6
-5,-8,36:18.6
-4,-8,36:18.6
10,-8,36:18.6
11,-8,36:18.6
-6,-7,36:18.6
-5,-7,36:18.6
11,-7,36:18.6
12,-7,36:18.6
-6,-6,36:18.6
-5,-6,36:18.6
11,-6,36:18.6
12,-6,36:18.6
13,-6,36:18.6
-7,-5,36:18.6
-6,-5,36:18.6
-5,-5,36:18.6
11,-5,36:18.6
13,-5,36:18.6
14,-5,36:18.6
16,-5,36:18.6
-8,-4,36:18.6
-5,-4,36:18.6
11,-4,36:18.6
14,-4,36:18.6
15,-4,36:18.6
16,-4,36:18.6
-9,-3,36:18.6
-8,-3,36:18.6
-5,-3,36:18.6
11,-3,36:18.6
12,-3,36:18.6
15,-3,36:18.6
-11,-2,36:18.6
-5,-2,36:18.6
11,-2,36:18.6
12,-2,36:18.6
15,-2,36:18.6
-11,-1,36:18.6
-10,-1,36:18.6
-5,-1,36:18.6
11,-1,36:18.6
12,-1,36:18.6
16,-1,36:18.6
-10,0,36:18.6
-5,0,36:18.6
12,0,36:18.6
14,0,36:18.6
16,0,36:18.6
-11,1,36:18.6
-10,1,36:18.6
-5,1,36:18.6
12,1,36:18.6
13,1,36:18.6
14,1,36:18.6
-11,2,36:18.6
-10,2,36:18.6
-9,2,36:18.6
-5,2,36:18.6
12,2,36:18.6
13,2,36:18.6
-9,3,36:18.6
-8,3,36:18.6
-5,3,36:18.6
12,3,36:18.6
-7,4,36:18.6
-6,4,36:18.6
-5,4,36:18.6
11,4,36:18.6
12,4,36:18.6
-6,5,36:18.6
-5,5,36:18.6
10,5,36:18.6
11,5,36:18.6
12,5,36:18.6
-5,6,36:18.6
-4,6,36:18.6
10,6,36:18.6
11,6,36:18.6
12,6,36:18.6
13,6,36:18.6
14,6,36:18.6
-5,7,36:18.6
-4,7,36:18.6
-3,7,36:18.6
-2,7,36:18.6
-1,7,36:18.6
0,7,36:18.6
1,7,36:18.6
2,7,36:18.6
3,7,36:18.6
4,7,36:18.6
5,7,36:18.6
6,7,36:18.6
7,7,36:18.6
8,7,36:18.6
9,7,36:18.6
10,7,36:18.6
11,7,36:18.6
12,7,36:18.6
-6,8,36:18.6
-5,8,36:18.6
-4,8,36:18.6
-3,8,36:18.6
-2,8,36:18.6
-1,8,36:18.6
8,8,36:18.6
9,8,36:18.6
12,8,36:18.6
-5,9,36:18.6
-1,9,36:18.6
0,9,36:18.6
7,9,36:18.6
8,9,36:18.6
1,10,36:18.6
2,10,36:18.6
5,10,36:18.6
6,10,36:18.6
0,11,36:18.6
1,11,36:18.6
2,11,36:18.6
3,11,36:18.6
4,11,36:18.6
5,11,36:18.6
6,11,36:18.6
7,11,36:18.6
8,11,36:18.6
9,11,36:18.6
0,12,36:18.6
1,-14,37:18.6
4,-14,37:18.6
5,-14,37:18.6
1,-13,37:18.6
2,-13,37:18.6
3,-13,37:18.6
4,-13,37:18.6
0,-12,37:18.6
5,-12,37:18.6
6,-12,37:18.6
10,-12,37:18.6
-5,-11,37:18.6
-1,-11,37:18.6
6,-11,37:18.6
7,-11,37:18.6
10,-11,37:18.6
-5,-10,37:18.6
-2,-10,37:18.6
7,-10,37:18.6
8,-10,37:18.6
10,-10,37:18.6
-6,-9,37:18.6
-5,-9,37:18.6
-4,-9,37:18.6
-3,-9,37:18.6
-2,-9,37:18.6
-1,-9,37:18.6
0,-9,37:18.6
1,-9,37:18.6
2,-9,37:18.6
3,-9,37:18.6
4,-9,37:18.6
5,-9,37:18.6
6,-9,37:18.6
7,-9,37:18.6
8,-9,37:18.6
9,-9,37:18.6
10,-9,37:18.6
11,-9,37:18.6
12,-9,37:18.6
-5,-8,37:18.6
-4,-8,37:18.6
-3,-8,37:18.6
10,-8,37:18.6
11,-8,37:18.6
-5,-7,37:18.6
-4,-7,37:18.6
10,-7,37:18.6
11,-7,37:18.6
-6,-6,37:18.6
-5,-6,37:18.6
11,-6,37:18.6
12,-6,37:18.6
13,-6,37:18.6
-7,-5,37:18.6
-6,-5,37:18.6
-5,-5,37:18.6
11,-5,37:18.6
13,-5,37:18.6
14,-5,37:18.6
-8,-4,37:18.6
-5,-4,37:18.6
11,-4,37:18.6
14,-4,37:18.6
16,-4,37:18.6
-8,-3,37:18.6
-5,-3,37:18.6
11,-3,37:18.6
15,-3,37:18.6
-5,-2,37:18.6
11,-2,37:18.6
16,-2,37:18.6
-11,-1,37:18.6
-5,-1,37:18.6
11,-1,37:18.6
16,-1,37:18.6
-11,0,37:18.6
-5,0,37:18.6
11,0,37:18.6
-11,1,37:18.6
-5,1,37:18.6
11,1,37:18.6
13,1,37:18.6
-9,2,37:18.6
-5,2,37:18.6
11,2,37:18.6
12,2,37:18.6
13,2,37:18.6
-8,3,37:18.6
-7,3,37:18.6
-5,3,37:18.6
11,3,37:18.6
12,3,37:18.6
-7,4,37:18.6
-6,4,37:18.6
-5,4,37:18.6
-4,4,37:18.6
11,4,37:18.6
12,4,37:18.6
-6,5,37:18.6
-5,5,37:18.6
-4,5,37:18.6
10,5,37:18.6
11,5,37:18.6
12,5,37:18.6
-5,6,37:18.6
-4,6,37:18.6
1,6,37:18.6
2,6,37:18.6
3,6,37:18.6
4,6,37:18.6
5,6,37:18.6
6,6,37:18.6
7,6,37:18.6
8,6,37:18.6
9,6,37:18.6
10,6,37:18.6
11,6,37:18.6
12,6,37:18.6
13,6,37:18.6
-7,7,37:18.6
-6,7,37:18.6
-5,7,37:18.6
-4,7,37:18.6
-3,7,37:18.6
-2,7,37:18.6
-1,7,37:18.6
0,7,37:18.6
1,7,37:18.6
2,7,37:18.6
3,7,37:18.6
4,7,37:18.6
5,7,37:18.6
8,7,37:18.6
9,7,37:18.6
11,7,37:18.6
-5,8,37:18.6
-2,8,37:18.6
-1,8,37:18.6
8,8,37:18.6
11,8,37:18.6
-4,9,37:18.6
-1,9,37:18.6
0,9,37:18.6
7,9,37:18.6
1,10,37:18.6
2,10,37:18.6
5,10,37:18.6
6,10,37:18.6
1,11,37:18.6
2,11,37:18.6
3,11,37:18.6
4,11,37:18.6
5,11,37:18.6
6,11,37:18.6
7,11,37:18.6
0,12,37:18.6
1,-14,38:18.6
2,-14,38:18.6
3,-14,38:18.6
4,-14,38:18.6
5,-14,38:18.6
1,-13,38:18.6
2,-13,38:18.6
3,-13,38:18.6
0,-12,38:18.6
1,-12,38:18.6
-1,-11,38:18.6
0,-11,38:18.6
6,-11,38:18.6
7,-11,38:18.6
9,-11,38:18.6
10,-11,38:18.6
-4,-10,38:18.6
-2,-10,38:18.6
-1,-10,38:18.6
7,-10,38:18.6
8,-10,38:18.6
10,-10,38:18.6
-5,-9,38:18.6
-4,-9,38:18.6
-3,-9,38:18.6
-2,-9,38:18.6
-1,-9,38:18.6
0,-9,38:18.6
1,-9,38:18.6
2,-9,38:18.6
3,-9,38:18.6
4,-9,38:18.6
5,-9,38:18.6
6,-9,38:18.6
7,-9,38:18.6
8,-9,38:18.6
9,-9,38:18.6
10,-9,38:18.6
11,-9,38:18.6
-7,-8,38:18.6
-6,-8,38:18.6
-5,-8,38:18.6
-4,-8,38:18.6
-3,-8,38:18.6
-2,-8,38:18.6
-1,-8,38:18.6
0,-8,38:18.6
1,-8,38:18.6
2,-8,38:18.6
3,-8,38:18.6
4,-8,38:18.6
5,-8,38:18.6
6,-8,38:18.6
7,-8,38:18.6
8,-8,38:18.6
9,-8,38:18.6
10,-8,38:18.6
11,-8,38:18.6
-5,-7,38:18.6
-4,-7,38:18.6
10,-7,38:18.6
-5,-6,38:18.6
-4,-6,38:18.6
10,-6,38:18.6
-6,-5,38:18.6
-5,-5,38:18.6
-4,-5,38:18.6
10,-5,38:18.6
-4,-4,38:18.6
10,-4,38:18.6
-4,-3,38:18.6
10,-3,38:18.6
-4,-2,38:18.6
10,-2,38:18.6
11,-2,38:18.6
-4,-1,38:18.6
10,-1,38:18.6
11,-1,38:18.6
-4,0,38:18.6
10,0,38:18.6
11,0,38:18.6
-4,1,38:18.6
11,1,38:18.6
13,1,38:18.6
-4,2,38:18.6
11,2,38:18.6
-4,3,38:18.6
11,3,38:18.6
12,3,38:18.6
-4,4,38:18.6
10,4,38:18.6
11,4,38:18.6
-5,5,38:18.6
-4,5,38:18.6
9,5,38:18.6
10,5,38:18.6
11,5,38:18.6
12,5,38:18.6
13,5,38:18.6
14,5,38:18.6
-5,6,38:18.6
-4,6,38:18.6
-3,6,38:18.6
-2,6,38:18.6
-1,6,38:18.6
0,6,38:18.6
1,6,38:18.6
2,6,38:18.6
3,6,38:18.6
4,6,38:18.6
5,6,38:18.6
6,6,38:18.6
7,6,38:18.6
8,6,38:18.6
9,6,38:18.6
10,6,38:18.6
11,6,38:18.6
-4,7,38:18.6
-3,7,38:18.6
-2,7,38:18.6
8,7,38:18.6
9,7,38:18.6
11,7,38:18.6
-4,8,38:18.6
-2,8,38:18.6
-1,8,38:18.6
7,8,38:18.6
8,8,38:18.6
-4,9,38:18.6
0,9,38:18.6
7,9,38:18.6
1,10,38:18.6
6,10,38:18.6
1,11,38:18.6
2,11,38:18.6
3,11,38:18.6
4,11,38:18.6
5,11,38:18.6
6,11,38:18.6
1,12,38:18.6
2,-14,39:18.6
3,-14,39:18.6
4,-14,39:18.6
9,-11,39:18.6
9,-10,39:18.6
-4,-9,39:18.6
8,-9,39:18.6
9,-9,39:18.6
-7,-8,39:18.6
-6,-8,39:18.6
-5,-8,39:18.6
-4,-8,39:18.6
-3,-8,39:18.6
-2,-8,39:18.6
-1,-8,39:18.6
0,-8,39:18.6
1,-8,39:18.6
2,-8,39:18.6
3,-8,39:18.6
4,-8,39:18.6
5,-8,39:18.6
6,-8,39:18.6
7,-8,39:18.6
8,-8,39:18.6
9,-8,39:18.6
10,-8,39:18.6
11,-8,39:18.6
-7,-7,39:18.6
-6,-7,39:18.6
-4,-7,39:18.6
9,-7,39:18.6
10,-7,39:18.6
-5,-6,39:18.6
-4,-6,39:18.6
9,-6,39:18.6
10,-6,39:18.6
-4,-5,39:18.6
10,-5,39:18.6
-4,-4,39:18.6
10,-4,39:18.6
-4,-3,39:18.6
10,-3,39:18.6
-4,-2,39:18.6
10,-2,39:18.6
-4,-1,39:18.6
10,-1,39:18.6
-4,0,39:18.6
10,0,39:18.6
-4,1,39:18.6
10,1,39:18.6
-4,2,39:18.6
10,2,39:18.6
-4,3,39:18.6
-3,3,39:18.6
10,3,39:18.6
11,3,39:18.6
-4,4,39:18.6
10,4,39:18.6
11,4,39:18.6
13,4,39:18.6
-5,5,39:18.6
-4,5,39:18.6
-3,5,39:18.6
0,5,39:18.6
1,5,39:18.6
2,5,39:18.6
3,5,39:18.6
4,5,39:18.6
5,5,39:18.6
6,5,39:18.6
7,5,39:18.6
8,5,39:18.6
9,5,39:18.6
10,5,39:18.6
11,5,39:18.6
12,5,39:18.6
13,5,39:18.6
-5,6,39:18.6
-4,6,39:18.6
-3,6,39:18.6
-2,6,39:18.6
-1,6,39:18.6
0,6,39:18.6
1,6,39:18.6
2,6,39:18.6
3,6,39:18.6
4,6,39:18.6
9,6,39:18.6
10,6,39:18.6
-4,7,39:18.6
-3,7,39:18.6
-2,7,39:18.6
8,7,39:18.6
10,7,39:18.6
-3,8,39:18.6
-1,8,39:18.6
7,8,39:18.6
-3,9,39:18.6
0,9,39:18.6
6,9,39:18.6
7,9,39:18.6
5,10,39:18.6
6,10,39:18.6
2,11,39:18.6
3,11,39:18.6
4,11,39:18.6
5,11,39:18.6
6,11,39:18.6
8,-11,40:18.6
8,-10,40:18.6
-3,-9,40:18.6
9,-9,40:18.6
-4,-8,40:18.6
-3,-8,40:18.6
-1,-8,40:18.6
0,-8,40:18.6
1,-8,40:18.6
2,-8,40:18.6
3,-8,40:18.6
4,-8,40:18.6
5,-8,40:18.6
6,-8,40:18.6
7,-8,40:18.6
8,-8,40:18.6
9,-8,40:18.6
10,-8,40:18.6
11,-8,40:18.6
-6,-7,40:18.6
-5,-7,40:18.6
-4,-7,40:18.6
-3,-7,40:18.6
-2,-7,40:18.6
-1,-7,40:18.6
0,-7,40:18.6
1,-7,40:18.6
2,-7,40:18.6
3,-7,40:18.6
4,-7,40:18.6
5,-7,40:18.6
6,-7,40:18.6
7,-7,40:18.6
8,-7,40:18.6
9,-7,40:18.6
10,-7,40:18.6
11,-7,40:18.6
-4,-6,40:18.6
-3,-6,40:18.6
9,-6,40:18.6
9,-5,40:18.6
-3,-4,40:18.6
9,-4,40:18.6
-3,-3,40:18.6
9,-3,40:18.6
-3,-2,40:18.6
9,-2,40:18.6
-3,-1,40:18.6
9,-1,40:18.6
10,-1,40:18.6
-3,0,40:18.6
9,0,40:18.6
10,0,40:18.6
-3,1,40:18.6
9,1,40:18.6
10,1,40:18.6
-3,2,40:18.6
10,2,40:18.6
-3,3,40:18.6
10,3,40:18.6
8,4,40:18.6
9,4,40:18.6
10,4,40:18.6
11,4,40:18.6
12,4,40:18.6
13,4,40:18.6
-5,5,40:18.6
-4,5,40:18.6
-3,5,40:18.6
-2,5,40:18.6
-1,5,40:18.6
0,5,40:18.6
1,5,40:18.6
2,5,40:18.6
3,5,40:18.6
4,5,40:18.6
5,5,40:18.6
6,5,40:18.6
7,5,40:18.6
8,5,40:18.6
9,5,40:18.6
10,5,40:18.6
-3,6,40:18.6
9,6,40:18.6
10,6,40:18.6
-3,7,40:18.6
-3,8,40:18.6
6,9,40:18.6
5,10,40:18.6
3,11,40:18.6
4,11,40:18.6
5,11,40:18.6
8,-11,41:18.6
8,-10,41:18.6
-3,-9,41:18.6
8,-9,41:18.6
-3,-8,41:18.6
8,-8,41:18.6
-6,-7,41:18.6
-5,-7,41:18.6
-4,-7,41:18.6
-3,-7,41:18.6
-2,-7,41:18.6
-1,-7,41:18.6
0,-7,41:18.6
1,-7,41:18.6
2,-7,41:18.6
3,-7,41:18.6
4,-7,41:18.6
5,-7,41:18.6
6,-7,41:18.6
7,-7,41:18.6
8,-7,41:18.6
9,-7,41:18.6
10,-7,41:18.6
11,-7,41:18.6
12,-7,41:18.6
-7,-6,41:18.6
-6,-6,41:18.6
-5,-6,41:18.6
-3,-6,41:18.6
8,-6,41:18.6
9,-6,41:18.6
8,-5,41:18.6
9,-5,41:18.6
-3,-4,41:18.6
9,-4,41:18.6
-3,-3,41:18.6
9,-3,41:18.6
-3,-2,41:18.6
9,-2,41:18.6
-3,-1,41:18.6
9,-1,41:18.6
-3,0,41:18.6
9,0,41:18.6
-3,1,41:18.6
9,1,41:18.6
-3,2,41:18.6
9,2,41:18.6
-3,3,41:18.6
-2,3,41:18.6
9,3,41:18.6
12,3,41:18.6
13,3,41:18.6
-6,4,41:18.6
-5,4,41:18.6
-4,4,41:18.6
-2,4,41:18.6
0,4,41:18.6
1,4,41:18.6
2,4,41:18.6
3,4,41:18.6
4,4,41:18.6
5,4,41:18.6
6,4,41:18.6
7,4,41:18.6
8,4,41:18.6
9,4,41:18.6
10,4,41:18.6
11,4,41:18.6
-5,5,41:18.6
-4,5,41:18.6
-3,5,41:18.6
-2,5,41:18.6
-1,5,41:18.6
0,5,41:18.6
1,5,41:18.6
2,5,41:18.6
3,5,41:18.6
9,5,41:18.6
-3,6,41:18.6
-2,6,41:18.6
9,6,41:18.6
-3,7,41:18.6
-2,7,41:18.6
-2,8,41:18.6
-2,9,41:18.6
7,-11,42:18.6
-2,-10,42:18.6
7,-10,42:18.6
-2,-9,42:18.6
7,-9,42:18.6
8,-9,42:18.6
-2,-8,42:18.6
8,-8,42:18.6
-3,-7,42:18.6
-2,-7,42:18.6
-1,-7,42:18.6
0,-7,42:18.6
1,-7,42:18.6
2,-7,42:18.6
3,-7,42:18.6
4,-7,42:18.6
5,-7,42:18.6
6,-7,42:18.6
7,-7,42:18.6
8,-7,42:18.6
9,-7,42:18.6
10,-7,42:18.6
11,-7,42:18.6
12,-7,42:18.6
-6,-6,42:18.6
-5,-6,42:18.6
-4,-6,42:18.6
-3,-6,42:18.6
-2,-6,42:18.6
-1,-6,42:18.6
0,-6,42:18.6
1,-6,42:18.6
2,-6,42:18.6
3,-6,42:18.6
4,-6,42:18.6
5,-6,42:18.6
6,-6,42:18.6
7,-6,42:18.6
8,-6,42:18.6
9,-6,42:18.6
10,-6,42:18.6
11,-6,42:18.6
-2,-5,42:18.6
8,-5,42:18.6
-2,-4,42:18.6
8,-4,42:18.6
-2,-3,42:18.6
8,-3,42:18.6
-2,-2,42:18.6
8,-2,42:18.6
-2,-1,42:18.6
8,-1,42:18.6
-2,0,42:18.6
8,0,42:18.6
9,0,42:18.6
-2,1,42:18.6
8,1,42:18.6
9,1,42:18.6
-2,2,42:18.6
8,2,42:18.6
9,2,42:18.6
-2,3,42:18.6
8,3,42:18.6
9,3,42:18.6
10,3,42:18.6
11,3,42:18.6
12,3,42:18.6
13,3,42:18.6
-6,4,42:18.6
-5,4,42:18.6
-4,4,42:18.6
-2,4,42:18.6
-1,4,42:18.6
0,4,42:18.6
1,4,42:18.6
2,4,42:18.6
3,4,42:18.6
4,4,42:18.6
5,4,42:18.6
6,4,42:18.6
7,4,42:18.6
8,4,42:18.6
9,4,42:18.6
-2,5,42:18.6
8,5,42:18.6
9,5,42:18.6
-2,6,42:18.6
8,6,42:18.6
9,6,42:18.6
-2,7,42:18.6
8,7,42:18.6
-2,8,42:18.6
-2,-10,43:18.6
7,-10,43:18.6
-2,-9,43:18.6
-1,-9,43:18.6
7,-9,43:18.6
-2,-8,43:18.6
7,-8,43:18.6
-2,-7,43:18.6
7,-7,43:18.6
-5,-6,43:18.6
-4,-6,43:18.6
-3,-6,43:18.6
-2,-6,43:18.6
-1,-6,43:18.6
0,-6,43:18.6
1,-6,43:18.6
2,-6,43:18.6
3,-6,43:18.6
4,-6,43:18.6
5,-6,43:18.6
6,-6,43:18.6
7,-6,43:18.6
8,-6,43:18.6
9,-6,43:18.6
10,-6,43:18.6
11,-6,43:18.6
-5,-5,43:18.6
-4,-5,43:18.6
-2,-5,43:18.6
7,-5,43:18.6
8,-5,43:18.6
-2,-4,43:18.6
7,-4,43:18.6
8,-4,43:18.6
-2,-3,43:18.6
7,-3,43:18.6
8,-3,43:18.6
-2,-2,43:18.6
8,-2,43:18.6
-2,-1,43:18.6
8,-1,43:18.6
-2,0,43:18.6
8,0,43:18.6
-2,1,43:18.6
8,1,43:18.6
-2,2,43:18.6
8,2,43:18.6
11,2,43:18.6
12,2,43:18.6
-6,3,43:18.6
-5,3,43:18.6
-4,3,43:18.6
-3,3,43:18.6
-2,3,43:18.6
-1,3,43:18.6
0,3,43:18.6
1,3,43:18.6
2,3,43:18.6
3,3,43:18.6
4,3,43:18.6
5,3,43:18.6
6,3,43:18.6
8,3,43:18.6
9,3,43:18.6
10,3,43:18.6
11,3,43:18.6
-2,4,43:18.6
-1,4,43:18.6
0,4,43:18.6
1,4,43:18.6
2,4,43:18.6
8,4,43:18.6
-2,5,43:18.6
-1,5,43:18.6
8,5,43:18.6
-2,6,43:18.6
-1,6,43:18.6
8,6,43:18.6
-1,7,43:18.6
8,7,43:18.6
6,-11,44:18.6
-1,-10,44:18.6
6,-10,44:18.6
-1,-9,44:18.6
6,-9,44:18.6
-1,-8,44:18.6
6,-8,44:18.6
7,-8,44:18.6
-1,-7,44:18.6
7,-7,44:18.6
-2,-6,44:18.6
-1,-6,44:18.6
0,-6,44:18.6
1,-6,44:18.6
2,-6,44:18.6
3,-6,44:18.6
4,-6,44:18.6
5,-6,44:18.6
6,-6,44:18.6
7,-6,44:18.6
8,-6,44:18.6
9,-6,44:18.6
10,-6,44:18.6
11,-6,44:18.6
-6,-5,44:18.6
-5,-5,44:18.6
-4,-5,44:18.6
-2,-5,44:18.6
-1,-5,44:18.6
0,-5,44:18.6
1,-5,44:18.6
2,-5,44:18.6
3,-5,44:18.6
4,-5,44:18.6
5,-5,44:18.6
6,-5,44:18.6
7,-5,44:18.6
8,-5,44:18.6
9,-5,44:18.6
10,-5,44:18.6
11,-5,44:18.6
-1,-4,44:18.6
7,-4,44:18.6
-1,-3,44:18.6
7,-3,44:18.6
-1,-2,44:18.6
7,-2,44:18.6
-1,-1,44:18.6
7,-1,44:18.6
-1,0,44:18.6
7,0,44:18.6
-1,1,44:18.6
7,1,44:18.6
8,1,44:18.6
-5,2,44:18.6
-1,2,44:18.6
6,2,44:18.6
7,2,44:18.6
8,2,44:18.6
9,2,44:18.6
10,2,44:18.6
11,2,44:18.6
12,2,44:18.6
-5,3,44:18.6
-4,3,44:18.6
-3,3,44:18.6
-2,3,44:18.6
-1,3,44:18.6
0,3,44:18.6
1,3,44:18.6
2,3,44:18.6
3,3,44:18.6
4,3,44:18.6
5,3,44:18.6
6,3,44:18.6
8,3,44:18.6
-1,4,44:18.6
7,4,44:18.6
8,4,44:18.6
-1,5,44:18.6
7,5,44:18.6
-1,6,44:18.6
7,6,44:18.6
-1,7,44:18.6
7,7,44:18.6
-1,8,44:18.6
0,-10,45:18.6
6,-10,45:18.6
-1,-9,45:18.6
0,-9,45:18.6
6,-9,45:18.6
-1,-8,45:18.6
0,-8,45:18.6
6,-8,45:18.6
-1,-7,45:18.6
0,-7,45:18.6
6,-7,45:18.6
-1,-6,45:18.6
6,-6,45:18.6
-4,-5,45:18.6
-2,-5,45:18.6
-1,-5,45:18.6
0,-5,45:18.6
1,-5,45:18.6
2,-5,45:18.6
3,-5,45:18.6
4,-5,45:18.6
5,-5,45:18.6
6,-5,45:18.6
7,-5,45:18.6
8,-5,45:18.6
9,-5,45:18.6
10,-5,45:18.6
11,-5,45:18.6
12,-5,45:18.6
-6,-4,45:18.6
-5,-4,45:18.6
-4,-4,45:18.6
-3,-4,45:18.6
-1,-4,45:18.6
6,-4,45:18.6
7,-4,45:18.6
-1,-3,45:18.6
6,-3,45:18.6
7,-3,45:18.6
-1,-2,45:18.6
7,-2,45:18.6
-1,-1,45:18.6
7,-1,45:18.6
-1,0,45:18.6
7,0,45:18.6
-1,1,45:18.6
7,1,45:18.6
9,1,45:18.6
10,1,45:18.6
11,1,45:18.6
12,1,45:18.6
-6,2,45:18.6
-5,2,45:18.6
-4,2,45:18.6
-3,2,45:18.6
-2,2,45:18.6
-1,2,45:18.6
0,2,45:18.6
1,2,45:18.6
2,2,45:18.6
3,2,45:18.6
4,2,45:18.6
5,2,45:18.6
6,2,45:18.6
7,2,45:18.6
8,2,45:18.6
9,2,45:18.6
10,2,45:18.6
-1,3,45:18.6
0,3,45:18.6
1,3,45:18.6
-1,4,45:18.6
0,4,45:18.6
7,4,45:18.6
-1,5,45:18.6
0,5,45:18.6
6,5,45:18.6
7,5,45:18.6
0,6,45:18.6
6,6,45:18.6
7,6,45:18.6
0,7,45:18.6
6,7,45:18.6
0,-10,46:18.6
0,-9,46:18.6
5,-9,46:18.6
0,-8,46:18.6
5,-8,46:18.6
0,-7,46:18.6
5,-7,46:18.6
6,-7,46:18.6
0,-6,46:18.6
6,-6,46:18.6
-1,-5,46:18.6
0,-5,46:18.6
1,-5,46:18.6
2,-5,46:18.6
3,-5,46:18.6
4,-5,46:18.6
5,-5,46:18.6
6,-5,46:18.6
7,-5,46:18.6
8,-5,46:18.6
9,-5,46:18.6
10,-5,46:18.6
11,-5,46:18.6
-4,-4,46:18.6
-3,-4,46:18.6
-2,-4,46:18.6
-1,-4,46:18.6
0,-4,46:18.6
1,-4,46:18.6
2,-4,46:18.6
3,-4,46:18.6
4,-4,46:18.6
5,-4,46:18.6
6,-4,46:18.6
7,-4,46:18.6
8,-4,46:18.6
9,-4,46:18.6
10,-4,46:18.6
0,-3,46:18.6
6,-3,46:18.6
0,-2,46:18.6
6,-2,46:18.6
0,-1,46:18.6
6,-1,46:18.6
0,0,46:18.6
6,0,46:18.6
-5,1,46:18.6
-4,1,46:18.6
-3,1,46:18.6
0,1,46:18.6
5,1,46:18.6
6,1,46:18.6
7,1,46:18.6
8,1,46:18.6
9,1,46:18.6
10,1,46:18.6
-4,2,46:18.6
-3,2,46:18.6
-2,2,46:18.6
-1,2,46:18.6
0,2,46:18.6
1,2,46:18.6
2,2,46:18.6
3,2,46:18.6
4,2,46:18.6
5,2,46:18.6
6,2,46:18.6
7,2,46:18.6
0,3,46:18.6
6,3,46:18.6
0,4,46:18.6
6,4,46:18.6
0,5,46:18.6
6,5,46:18.6
0,6,46:18.6
6,6,46:18.6
6,7,46:18.6
1,-9,47:18.6
0,-8,47:18.6
5,-8,47:18.6
0,-7,47:18.6
1,-7,47:18.6
5,-7,47:18.6
0,-6,47:18.6
1,-6,47:18.6
5,-6,47:18.6
0,-5,47:18.6
5,-5,47:18.6
-3,-4,47:18.6
-2,-4,47:18.6
-1,-4,47:18.6
0,-4,47:18.6
1,-4,47:18.6
2,-4,47:18.6
3,-4,47:18.6
4,-4,47:18.6
5,-4,47:18.6
6,-4,47:18.6
7,-4,47:18.6
8,-4,47:18.6
9,-4,47:18.6
10,-4,47:18.6
-4,-3,47:18.6
-3,-3,47:18.6
0,-3,47:18.6
5,-3,47:18.6
6,-3,47:18.6
0,-2,47:18.6
5,-2,47:18.6
6,-2,47:18.6
0,-1,47:18.6
5,-1,47:18.6
6,-1,47:18.6
0,0,47:18.6
6,0,47:18.6
8,0,47:18.6
9,0,47:18.6
10,0,47:18.6
-4,1,47:18.6
-3,1,47:18.6
-2,1,47:18.6
-1,1,47:18.6
0,1,47:18.6
1,1,47:18.6
2,1,47:18.6
3,1,47:18.6
4,1,47:18.6
5,1,47:18.6
6,1,47:18.6
7,1,47:18.6
8,1,47:18.6
9,1,47:18.6
0,2,47:18.6
1,2,47:18.6
6,2,47:18.6
0,3,47:18.6
1,3,47:18.6
5,3,47:18.6
6,3,47:18.6
0,4,47:18.6
1,4,47:18.6
5,4,47:18.6
6,4,47:18.6
1,5,47:18.6
5,5,47:18.6
5,6,47:18.6
1,-8,48:18.6
1,-7,48:18.6
4,-7,48:18.6
1,-6,48:18.6
4,-6,48:18.6
5,-6,48:18.6
1,-5,48:18.6
4,-5,48:18.6
5,-5,48:18.6
0,-4,48:18.6
1,-4,48:18.6
2,-4,48:18.6
3,-4,48:18.6
4,-4,48:18.6
5,-4,48:18.6
6,-4,48:18.6
7,-4,48:18.6
8,-4,48:18.6
9,-4,48:18.6
-3,-3,48:18.6
-2,-3,48:18.6
-1,-3,48:18.6
0,-3,48:18.6
1,-3,48:18.6
2,-3,48:18.6
3,-3,48:18.6
4,-3,48:18.6
5,-3,48:18.6
6,-3,48:18.6
7,-3,48:18.6
8,-3,48:18.6
9,-3,48:18.6
1,-2,48:18.6
5,-2,48:18.6
1,-1,48:18.6
5,-1,48:18.6
-4,0,48:18.6
-3,0,48:18.6
-2,0,48:18.6
-1,0,48:18.6
1,0,48:18.6
4,0,48:18.6
5,0,48:18.6
6,0,48:18.6
7,0,48:18.6
8,0,48:18.6
9,0,48:18.6
-3,1,48:18.6
-2,1,48:18.6
-1,1,48:18.6
0,1,48:18.6
1,1,48:18.6
2,1,48:18.6
3,1,48:18.6
4,1,48:18.6
5,1,48:18.6
6,1,48:18.6
1,2,48:18.6
5,2,48:18.6
1,3,48:18.6
5,3,48:18.6
1,4,48:18.6
5,4,48:18.6
5,5,48:18.6
2,-8,49:18.6
1,-7,49:18.6
2,-7,49:18.6
1,-6,49:18.6
2,-6,49:18.6
4,-6,49:18.6
1,-5,49:18.6
2,-5,49:18.6
4,-5,49:18.6
1,-4,49:18.6
4,-4,49:18.6
-2,-3,49:18.6
-1,-3,49:18.6
0,-3,49:18.6
1,-3,49:18.6
2,-3,49:18.6
3,-3,49:18.6
4,-3,49:18.6
5,-3,49:18.6
6,-3,49:18.6
7,-3,49:18.6
8,-3,49:18.6
9,-3,49:18.6
-2,-2,49:18.6
1,-2,49:18.6
4,-2,49:18.6
5,-2,49:18.6
1,-1,49:18.6
4,-1,49:18.6
5,-1,49:18.6
7,-1,49:18.6
-4,0,49:18.6
-3,0,49:18.6
-2,0,49:18.6
-1,0,49:18.6
0,0,49:18.6
1,0,49:18.6
2,0,49:18.6
3,0,49:18.6
4,0,49:18.6
5,0,49:18.6
6,0,49:18.6
7,0,49:18.6
8,0,49:18.6
1,1,49:18.6
2,1,49:18.6
4,1,49:18.6
5,1,49:18.6
1,2,49:18.6
2,2,49:18.6
4,2,49:18.6
5,2,49:18.6
1,3,49:18.6
2,3,49:18.6
4,3,49:18.6
4,4,49:18.6
4,5,49:18.6
2,-5,50:18.6
2,-4,50:18.6
4,-4,50:18.6
1,-3,50:18.6
2,-3,50:18.6
3,-3,50:18.6
4,-3,50:18.6
5,-3,50:18.6
6,-3,50:18.6
7,-3,50:18.6
0,-2,50:18.6
1,-2,50:18.6
2,-2,50:18.6
3,-2,50:18.6
4,-2,50:18.6
2,-1,50:18.6
3,-1,50:18.6
4,-1,50:18.6
5,-1,50:18.6
6,-1,50:18.6
7,-1,50:18.6
8,-1,50:18.6
-1,0,50:18.6
0,0,50:18.6
1,0,50:18.6
2,0,50:18.6
3,0,50:18.6
4,0,50:18.6
5,0,50:18.6
2,1,50:18.6
4,1,50:18.6
4,2,50:18.6
2,3,50:18.6
4,3,50:18.6
4,4,50:18.6
2,-3,51:18.6
3,-3,51:18.6
1,-2,51:18.6
2,-2,51:18.6
3,-2,51:18.6
4,-2,51:18.6
1,-1,51:18.6
2,-1,51:18.6
3,-1,51:18.6
4,-1,51:18.6
5,-1,51:18.6
2,0,51:18.6
3,0,51:18.6
4,0,51:18.6
3,-3,52:18.6
3,-2,52:18.6
4,-2,52:18.6
3,-1,52:18.6
3,0,52:18.6
