[META]
version=2.0
spawnOnBlockType=2
spawnSunlight=True
spawnDarkness=True
spawnWater=False
spawnLava=False
underFill=False
randomRotation=True
dig=True
tree=False
branch=False
needsFoundation=True
rarity=100
collisionPercentage=20
spawnElevationMin=0
spawnElevationMax=200
spawnInBiome=Custom
[DATA]
1,5,-8:17.12
0,-3,-7:17.12
2,2,-7:17.12
-4,3,-7:17.12
-3,3,-7:17.12
-2,3,-7:17.12
-3,4,-7:17.12
1,4,-7:17.12
-1,-4,-6:17.12
0,-4,-6:17.12
-4,-3,-6:17.12
-3,-3,-6:17.12
-2,-3,-6:17.12
-1,-3,-6:17.12
0,-3,-6:17.12
-4,-2,-6:17.12
-2,-2,-6:17.12
-4,2,-6:17.12
-3,2,-6:17.12
1,2,-6:17.12
-4,3,-6:17.12
-3,3,-6:17.12
1,3,-6:17.12
2,3,-6:17.12
3,3,-6:17.12
-3,4,-6:17.12
-2,4,-6:17.12
1,4,-6:17.12
2,4,-6:17.12
-2,-3,-5:17.12
-1,-3,-5:17.12
-2,-2,-5:17.12
-2,-1,-5:17.12
-4,0,-5:17.12
-4,1,-5:17.12
-3,1,-5:17.12
-2,1,-5:17.12
1,1,-5:17.12
-3,2,-5:17.12
0,2,-5:17.12
1,2,-5:17.12
-4,3,-5:17.12
-3,3,-5:17.12
1,3,-5:17.12
2,3,-5:17.12
-3,4,-5:17.12
2,4,-5:17.12
-2,-3,-4:17.12
-1,-3,-4:17.12
-3,-2,-4:17.12
-2,-2,-4:17.12
-1,-2,-4:17.12
0,-2,-4:17.12
-3,-1,-4:17.12
-2,-1,-4:17.12
-1,-1,-4:17.12
-4,0,-4:17.12
-4,1,-4:17.12
-3,1,-4:17.12
-2,1,-4:17.12
-4,2,-4:17.12
-3,2,-4:17.12
-2,2,-4:17.12
0,2,-4:17.12
1,2,-4:17.12
-3,3,-4:17.12
-2,3,-4:17.12
0,3,-4:17.12
1,3,-4:17.12
2,3,-4:17.12
0,4,-4:17.12
-1,-3,-3:17.12
-3,-2,-3:17.12
-2,-2,-3:17.12
-1,-2,-3:17.12
0,-2,-3:17.12
2,-2,-3:17.12
-3,-1,-3:17.12
-2,-1,-3:17.12
-1,-1,-3:17.12
0,-1,-3:17.12
-4,1,-3:17.12
-3,1,-3:17.12
0,1,-3:17.12
1,1,-3:17.12
-4,2,-3:17.12
-3,2,-3:17.12
-2,2,-3:17.12
0,2,-3:17.12
1,2,-3:17.12
2,2,-3:17.12
-4,3,-3:17.12
-3,3,-3:17.12
-2,3,-3:17.12
-1,3,-3:17.12
0,3,-3:17.12
1,3,-3:17.12
2,3,-3:17.12
-1,4,-3:17.12
0,4,-3:17.12
1,4,-3:17.12
-3,-3,-2:17.12
-2,-3,-2:17.12
-1,-3,-2:17.12
0,-3,-2:17.12
1,-3,-2:17.12
-3,-2,-2:17.12
-2,-2,-2:17.12
-1,-2,-2:17.12
0,-2,-2:17.12
1,-2,-2:17.12
2,-2,-2:17.12
-4,-1,-2:17.12
-3,-1,-2:17.12
-2,-1,-2:17.12
-1,-1,-2:17.12
0,-1,-2:17.12
1,-1,-2:17.12
2,-1,-2:17.12
3,-1,-2:17.12
-4,0,-2:17.12
-3,0,-2:17.12
-2,0,-2:17.12
-1,0,-2:17.12
0,0,-2:17.12
1,0,-2:17.12
2,0,-2:17.12
-4,1,-2:17.12
-3,1,-2:17.12
-2,1,-2:17.12
-1,1,-2:17.12
0,1,-2:17.12
1,1,-2:17.12
2,1,-2:17.12
-4,2,-2:17.12
-3,2,-2:17.12
-2,2,-2:17.12
-1,2,-2:17.12
0,2,-2:17.12
1,2,-2:17.12
-4,3,-2:17.12
-3,3,-2:17.12
-2,3,-2:17.12
-1,3,-2:17.12
0,3,-2:17.12
1,3,-2:17.12
2,3,-2:17.12
-4,4,-2:17.12
-3,4,-2:17.12
-2,4,-2:17.12
-1,4,-2:17.12
0,4,-2:17.12
1,4,-2:17.12
-3,5,-2:17.12
-2,5,-2:17.12
-1,5,-2:17.12
0,5,-2:17.12
-2,-3,-1:17.12
-1,-3,-1:17.12
-2,-2,-1:17.12
-1,-2,-1:17.12
0,-2,-1:17.12
1,-2,-1:17.12
-3,-1,-1:17.12
-2,-1,-1:17.12
-1,-1,-1:17.12
0,-1,-1:17.12
1,-1,-1:17.12
-3,0,-1:17.12
1,0,-1:17.12
2,0,-1:17.12
-4,1,-1:17.12
-3,1,-1:17.12
1,1,-1:17.12
2,1,-1:17.12
-3,2,-1:17.12
-2,2,-1:17.12
0,2,-1:17.12
1,2,-1:17.12
-3,3,-1:17.12
-2,3,-1:17.12
-1,3,-1:17.12
0,3,-1:17.12
1,3,-1:17.12
-3,4,-1:17.12
-2,4,-1:17.12
-1,4,-1:17.12
1,4,-1:17.12
0,5,-1:17.12
-2,-1,0:17.12
-1,-1,0:17.12
0,-1,0:17.12
1,-1,0:17.12
-3,0,0:17.12
-2,0,0:17.12
1,0,0:17.12
-3,1,0:17.12
1,1,0:17.12
-3,2,0:17.12
0,2,0:17.12
1,2,0:17.12
-3,3,0:17.12
-2,3,0:17.12
-1,3,0:17.12
-2,4,0:17.12
-1,4,0:17.12
-2,-1,1:17.12
-1,-1,1:17.12
0,-1,1:17.12
-2,0,1:17.12
0,0,1:17.12
1,0,1:17.12
-3,1,1:17.12
-2,1,1:17.12
1,1,1:17.12
-3,2,1:17.12
0,2,1:17.12
1,2,1:17.12
-2,3,1:17.12
-1,3,1:17.12
-1,-1,2:17.12
0,-1,2:17.12
-2,0,2:17.12
-1,0,2:17.12
0,0,2:17.12
1,0,2:17.12
-3,1,2:17.12
-2,1,2:17.12
1,1,2:17.12
-3,2,2:17.12
0,2,2:17.12
-2,3,2:17.12
-1,3,2:17.12
-2,-1,3:17.12
-1,-1,3:17.12
-2,0,3:17.12
0,0,3:17.12
-3,1,3:17.12
0,1,3:17.12
1,1,3:17.12
-3,2,3:17.12
-2,2,3:17.12
0,2,3:17.12
-2,3,3:17.12
-1,3,3:17.12
-2,-1,4:17.12
-1,-1,4:17.12
-3,0,4:17.12
-2,0,4:17.12
-1,0,4:17.12
0,0,4:17.12
-3,1,4:17.12
0,1,4:17.12
-3,2,4:17.12
-2,2,4:17.12
-1,2,4:17.12
0,2,4:17.12
-2,3,4:17.12
-1,3,4:17.12
-3,0,5:17.12
-2,0,5:17.12
-1,0,5:17.12
0,0,5:17.12
-3,1,5:17.12
0,1,5:17.12
-3,2,5:17.12
-2,2,5:17.12
-1,2,5:17.12
0,2,5:17.12
-2,3,5:17.12
-2,0,6:17.12
-1,0,6:17.12
0,0,6:17.12
-3,1,6:17.12
0,1,6:17.12
-3,2,6:17.12
-1,2,6:17.12
0,2,6:17.12
-3,3,6:17.12
-2,3,6:17.12
-1,3,6:17.12
-1,-1,7:17.12
-2,0,7:17.12
-1,0,7:17.12
0,0,7:17.12
-3,1,7:17.12
0,1,7:17.12
-3,2,7:17.12
0,2,7:17.12
-3,3,7:17.12
-2,3,7:17.12
-1,3,7:17.12
-2,4,7:17.12
-12,-12,8:18.6
-12,-11,8:18.6
-11,-11,8:18.6
11,-11,8:18.6
10,-10,8:18.6
-2,-1,8:17.12
-1,-1,8:17.12
-3,0,8:17.12
-2,0,8:17.12
-1,0,8:17.12
0,0,8:17.12
-3,1,8:17.12
-2,1,8:17.12
-1,1,8:17.12
0,1,8:17.12
-4,2,8:18.14
-3,2,8:17.12
-2,2,8:17.12
-1,2,8:17.12
0,2,8:18.14
-3,3,8:18.14
-2,3,8:17.12
-1,3,8:18.14
0,3,8:18.14
-3,4,8:18.14
-2,4,8:18.14
-14,10,8:18.6
-13,-13,9:18.6
-11,-11,9:18.6
11,-11,9:18.6
-10,-10,9:18.6
-9,-9,9:18.6
9,-9,9:18.6
10,-9,9:18.6
-8,-8,9:18.6
-7,-8,9:18.6
-7,-7,9:18.6
-6,-6,9:18.6
-5,-6,9:18.6
7,-6,9:18.6
-5,-5,9:18.14
-4,-5,9:18.14
6,-5,9:18.6
-4,-4,9:18.14
5,-4,9:18.6
4,-3,9:18.14
5,-3,9:18.6
-1,-2,9:18.14
3,-2,9:18.14
4,-2,9:18.14
-2,-1,9:18.14
-1,-1,9:18.14
0,-1,9:18.14
3,-1,9:18.14
-3,0,9:18.14
-2,0,9:18.14
0,0,9:18.14
-4,1,9:18.14
-3,1,9:18.14
0,1,9:18.14
1,1,9:18.14
-4,2,9:18.14
0,2,9:18.14
1,2,9:18.14
-4,3,9:18.14
-3,3,9:18.14
-1,3,9:18.14
-8,4,9:18.6
-7,4,9:18.14
-3,4,9:18.14
-2,4,9:18.14
-9,5,9:18.6
-8,5,9:18.6
-2,5,9:18.14
-10,6,9:18.6
-11,7,9:18.6
0,7,9:18.14
-12,8,9:18.6
1,8,9:18.14
-14,9,9:18.6
-13,9,9:18.6
2,9,9:18.6
-14,10,9:18.6
3,10,9:18.6
-15,11,9:18.6
6,13,9:18.6
7,13,9:18.6
7,14,9:18.6
-12,-13,10:18.6
-12,-12,10:18.6
-11,-12,10:18.6
11,-11,10:18.6
-10,-10,10:18.6
-9,-10,10:18.6
10,-10,10:18.6
-9,-9,10:18.6
-8,-9,10:18.6
9,-9,10:18.6
-8,-8,10:18.6
-7,-8,10:18.6
8,-8,10:18.6
-7,-7,10:18.6
-6,-7,10:18.6
7,-7,10:18.6
8,-7,10:18.6
-5,-6,10:18.6
7,-6,10:18.6
-5,-5,10:18.14
-4,-5,10:18.14
6,-5,10:18.6
-4,-4,10:18.14
-3,-4,10:18.14
5,-4,10:18.6
-3,-3,10:18.14
-2,-3,10:18.14
4,-3,10:18.14
-2,-2,10:18.14
-1,-2,10:18.14
3,-2,10:18.14
4,-2,10:18.14
-3,-1,10:18.14
-2,-1,10:18.14
-1,-1,10:18.14
0,-1,10:18.14
3,-1,10:18.14
-4,0,10:18.14
-3,0,10:18.14
0,0,10:18.14
2,0,10:18.14
-5,1,10:18.14
-4,1,10:18.14
0,1,10:18.14
1,1,10:18.14
-6,2,10:18.14
-5,2,10:18.14
-4,2,10:18.14
0,2,10:18.14
-7,3,10:18.14
-6,3,10:18.14
-4,3,10:18.14
-1,3,10:18.14
-8,4,10:18.6
-7,4,10:18.14
-4,4,10:18.14
-3,4,10:18.14
-2,4,10:18.14
-9,5,10:18.6
-3,5,10:18.14
-2,5,10:18.14
-11,6,10:18.6
-10,6,10:18.6
-2,6,10:18.14
-1,6,10:18.14
-12,7,10:18.6
-11,7,10:18.6
-1,7,10:18.14
0,7,10:18.14
-13,8,10:18.6
-12,8,10:18.6
0,8,10:18.14
1,8,10:18.14
-14,9,10:18.6
1,9,10:18.6
2,9,10:18.6
-15,10,10:18.6
2,10,10:18.6
3,10,10:18.6
-16,11,10:18.6
3,11,10:18.6
4,11,10:18.6
4,12,10:18.6
5,12,10:18.6
5,13,10:18.6
6,13,10:18.6
7,14,10:18.6
-13,-14,11:18.6
-12,-13,11:18.6
-11,-12,11:18.6
12,-12,11:18.6
-10,-11,11:18.6
11,-11,11:18.6
-9,-10,11:18.6
10,-10,11:18.6
-8,-9,11:18.6
9,-9,11:18.6
-7,-8,11:18.6
8,-8,11:18.6
9,-8,11:18.6
-6,-7,11:18.6
7,-7,11:18.6
8,-7,11:18.6
-5,-6,11:18.6
7,-6,11:18.6
-4,-5,11:18.14
6,-5,11:18.6
-3,-4,11:18.14
5,-4,11:18.6
-2,-3,11:18.14
-1,-3,11:18.14
4,-3,11:18.14
5,-3,11:18.6
-1,-2,11:18.14
0,-2,11:18.14
4,-2,11:18.14
-3,-1,11:18.14
-2,-1,11:18.14
-1,-1,11:18.14
0,-1,11:18.14
3,-1,11:18.14
-4,0,11:18.14
0,0,11:18.14
2,0,11:18.14
-5,1,11:18.14
-4,1,11:18.14
0,1,11:18.14
1,1,11:18.14
-6,2,11:18.14
-5,2,11:18.14
-4,2,11:18.14
0,2,11:18.14
-7,3,11:18.14
-4,3,11:18.14
-1,3,11:18.14
1,3,11:18.14
-9,4,11:18.6
-8,4,11:18.6
-4,4,11:18.14
-2,4,11:18.14
-10,5,11:18.6
-9,5,11:18.6
-4,5,11:18.14
-3,5,11:18.14
-2,5,11:18.14
-11,6,11:18.6
-10,6,11:18.6
-3,6,11:18.14
-2,6,11:18.14
-12,7,11:18.6
-2,7,11:18.14
-1,7,11:18.14
-13,8,11:18.6
-1,8,11:18.14
0,8,11:18.14
-14,9,11:18.6
0,9,11:18.6
1,9,11:18.6
-16,10,11:18.6
-15,10,11:18.6
1,10,11:18.6
2,10,11:18.6
-17,11,11:18.6
-16,11,11:18.6
3,11,11:18.6
3,12,11:18.6
4,12,11:18.6
4,13,11:18.6
5,13,11:18.6
6,14,11:18.6
-13,-14,12:18.6
-12,-14,12:18.6
-11,-13,12:18.6
-10,-12,12:18.6
-10,-11,12:18.6
-9,-11,12:18.6
11,-11,12:18.6
-9,-10,12:18.6
10,-10,12:18.6
-8,-9,12:18.6
-7,-9,12:18.6
-7,-8,12:18.6
-6,-8,12:18.6
8,-8,12:18.6
-6,-7,12:18.6
-5,-7,12:18.6
7,-7,12:18.6
8,-7,12:18.6
-5,-6,12:18.6
-4,-6,12:18.6
7,-6,12:18.6
-4,-5,12:18.14
-3,-5,12:18.14
6,-5,12:18.6
-3,-4,12:18.14
-2,-4,12:18.14
5,-4,12:18.6
-2,-3,12:18.14
-1,-3,12:18.14
4,-3,12:18.14
5,-3,12:18.6
-1,-2,12:18.14
0,-2,12:18.14
3,-2,12:18.14
4,-2,12:18.14
-3,-1,12:18.14
-2,-1,12:18.14
2,-1,12:18.14
3,-1,12:18.14
-5,0,12:18.14
2,0,12:18.14
-6,1,12:18.14
-5,1,12:18.14
0,1,12:18.14
1,1,12:18.14
-7,2,12:18.14
-6,2,12:18.14
-5,2,12:18.14
0,2,12:18.14
-8,3,12:18.6
-7,3,12:18.14
-1,3,12:18.14
1,3,12:18.14
-9,4,12:18.6
-8,4,12:18.6
-2,4,12:18.14
1,4,12:18.14
-11,5,12:18.6
-10,5,12:18.6
-4,5,12:18.14
-3,5,12:18.14
-2,5,12:18.14
1,5,12:18.14
-12,6,12:18.6
-11,6,12:18.6
-3,6,12:18.14
-12,7,12:18.6
-4,7,12:18.14
-3,7,12:18.14
-2,7,12:18.14
-14,8,12:18.6
-13,8,12:18.6
-1,8,12:18.6
-15,9,12:18.6
0,9,12:18.6
-16,10,12:18.6
1,10,12:18.6
2,10,12:18.6
-17,11,12:18.6
2,11,12:18.6
3,11,12:18.6
3,12,12:18.6
4,12,12:18.6
4,13,12:18.6
5,14,12:18.6
6,14,12:18.6
6,15,12:18.6
7,15,12:18.6
-11,-13,13:18.6
-10,-12,13:18.6
-9,-11,13:18.6
11,-11,13:18.6
-8,-10,13:18.6
-7,-9,13:18.6
9,-9,13:18.6
-6,-8,13:18.6
8,-8,13:18.6
9,-8,13:18.6
7,-7,13:18.6
8,-7,13:18.6
-4,-6,13:18.6
7,-6,13:18.6
-3,-5,13:18.6
6,-5,13:18.6
-2,-4,13:18.6
5,-4,13:18.6
-1,-3,13:18.6
4,-3,13:18.6
5,-3,13:18.6
-6,-2,13:18.6
-2,-2,13:18.6
-1,-2,13:18.6
0,-2,13:18.6
1,-2,13:18.6
3,-2,13:18.6
-6,-1,13:18.6
-3,-1,13:18.6
-2,-1,13:18.6
2,-1,13:18.6
3,-1,13:18.6
-6,0,13:18.6
-5,0,13:18.6
0,0,13:18.6
2,0,13:18.6
-6,1,13:18.6
-5,1,13:18.6
0,1,13:18.6
1,1,13:18.6
-8,2,13:18.6
-7,2,13:18.6
-5,2,13:18.6
0,2,13:18.6
-9,3,13:18.6
-8,3,13:18.6
-5,3,13:18.6
-1,3,13:18.6
-2,4,13:18.6
1,4,13:18.6
-11,5,13:18.6
-10,5,13:18.6
-4,5,13:18.6
-3,5,13:18.6
-2,5,13:18.6
1,5,13:18.6
-12,6,13:18.6
-4,6,13:18.6
1,6,13:18.6
-14,7,13:18.6
-13,7,13:18.6
-4,7,13:18.6
-3,7,13:18.6
-2,7,13:18.6
-15,8,13:18.6
-14,8,13:18.6
-4,8,13:18.6
-2,8,13:18.6
-1,8,13:18.6
-16,9,13:18.6
-15,9,13:18.6
0,10,13:18.6
1,10,13:18.6
1,11,13:18.6
2,11,13:18.6
2,12,13:18.6
3,12,13:18.6
3,13,13:18.6
4,13,13:18.6
4,14,13:18.6
5,14,13:18.6
6,15,13:18.6
-12,-14,14:18.6
-11,-13,14:18.6
-10,-13,14:18.6
-10,-12,14:18.6
-9,-12,14:18.6
-9,-11,14:18.6
-8,-11,14:18.6
-8,-10,14:18.6
-7,-10,14:18.6
10,-10,14:18.6
-7,-9,14:18.6
-6,-9,14:18.6
9,-9,14:18.6
-6,-8,14:18.6
-5,-8,14:18.6
8,-8,14:18.6
9,-8,14:18.6
-4,-7,14:18.6
7,-7,14:18.6
8,-7,14:18.6
-4,-6,14:18.6
-3,-6,14:18.6
7,-6,14:18.6
-3,-5,14:18.6
-2,-5,14:18.6
6,-5,14:18.6
5,-4,14:18.6
-1,-3,14:18.6
1,-3,14:18.6
2,-3,14:18.6
4,-3,14:18.6
5,-3,14:18.6
-6,-2,14:18.6
-2,-2,14:18.6
-1,-2,14:18.6
1,-2,14:18.6
-6,-1,14:18.6
-4,-1,14:18.6
-3,-1,14:18.6
-2,-1,14:18.6
0,-1,14:18.6
2,-1,14:18.6
3,-1,14:18.6
-6,0,14:18.6
0,0,14:18.6
2,0,14:18.6
0,1,14:18.6
1,1,14:18.6
-8,2,14:18.6
-5,2,14:18.6
0,2,14:18.6
-9,3,14:18.6
-8,3,14:18.6
-5,3,14:18.6
-1,3,14:18.6
-11,4,14:18.6
-10,4,14:18.6
-2,4,14:18.6
1,4,14:18.6
-12,5,14:18.6
-11,5,14:18.6
-5,5,14:18.6
-4,5,14:18.6
-2,5,14:18.6
1,5,14:18.6
-13,6,14:18.6
-12,6,14:18.6
-4,6,14:18.6
1,6,14:18.6
-14,7,14:18.6
-13,7,14:18.6
-3,7,14:18.6
1,7,14:18.6
-15,8,14:18.6
-4,8,14:18.6
-3,8,14:18.6
-2,8,14:18.6
-5,9,14:18.6
-2,9,14:18.6
-1,9,14:18.6
-17,10,14:18.6
-5,10,14:18.6
-1,10,14:18.6
0,10,14:18.6
0,11,14:18.6
1,11,14:18.6
1,12,14:18.6
2,12,14:18.6
2,13,14:18.6
3,13,14:18.6
4,14,14:18.6
5,15,14:18.6
-12,-15,15:18.6
-11,-14,15:18.6
-10,-13,15:18.6
-10,-12,15:18.6
-9,-12,15:18.6
-9,-11,15:18.6
-7,-10,15:18.6
10,-10,15:18.6
-6,-9,15:18.6
-6,-8,15:18.6
-5,-8,15:18.6
9,-8,15:18.6
-5,-7,15:18.6
-4,-7,15:18.6
7,-7,15:18.6
8,-7,15:18.6
-4,-6,15:18.6
-3,-6,15:18.6
7,-6,15:18.6
-3,-5,15:18.6
-2,-5,15:18.6
6,-5,15:18.6
-7,-4,15:18.6
5,-4,15:18.6
-7,-3,15:18.6
-1,-3,15:18.6
1,-3,15:18.6
2,-3,15:18.6
3,-3,15:18.6
4,-3,15:18.6
-2,-2,15:18.6
-1,-2,15:18.6
3,-2,15:18.6
4,-2,15:18.6
-6,-1,15:18.6
-5,-1,15:18.6
-4,-1,15:18.6
-3,-1,15:18.6
0,-1,15:18.6
2,-1,15:18.6
3,-1,15:18.6
-6,0,15:18.6
0,0,15:18.6
2,0,15:18.6
0,1,15:18.6
1,1,15:18.6
-9,2,15:18.6
-8,2,15:18.6
-6,2,15:18.6
-5,2,15:18.6
0,2,15:18.6
-9,3,15:18.6
-5,3,15:18.6
-1,3,15:18.6
1,3,15:18.6
-11,4,15:18.6
-10,4,15:18.6
-5,4,15:18.6
-2,4,15:18.6
1,4,15:18.6
-5,5,15:18.6
-2,5,15:18.6
-13,6,15:18.6
-5,6,15:18.6
1,6,15:18.6
-14,7,15:18.6
-4,7,15:18.6
-16,8,15:18.6
-15,8,15:18.6
-4,8,15:18.6
-3,8,15:18.6
2,8,15:18.6
-17,9,15:18.6
-16,9,15:18.6
-5,9,15:18.6
-2,9,15:18.6
-5,10,15:18.6
-1,10,15:18.6
0,11,15:18.6
1,12,15:18.6
2,13,15:18.6
3,14,15:18.6
5,16,15:18.6
-11,-14,16:18.6
-10,-13,16:18.6
-9,-12,16:18.6
-8,-12,16:18.6
-8,-11,16:18.6
-7,-11,16:18.6
-7,-10,16:18.6
10,-10,16:18.6
-6,-9,16:18.6
-5,-9,16:18.6
9,-9,16:18.6
-5,-8,16:18.6
8,-8,16:18.6
9,-8,16:18.6
-4,-7,16:18.6
8,-7,16:18.6
-3,-6,16:18.6
-2,-6,16:18.6
7,-6,16:18.6
-2,-5,16:18.6
6,-5,16:18.6
-7,-4,16:18.6
4,-4,16:18.6
-7,-3,16:18.6
-1,-3,16:18.6
1,-3,16:18.6
2,-3,16:18.6
4,-3,16:18.6
-3,-2,16:18.6
-2,-2,16:18.6
-1,-2,16:18.6
0,-2,16:18.6
3,-2,16:18.6
4,-2,16:18.6
-7,-1,16:18.6
-6,-1,16:18.6
-5,-1,16:18.6
-4,-1,16:18.6
-3,-1,16:18.6
0,-1,16:18.6
2,-1,16:18.6
3,-1,16:18.6
-6,0,16:18.6
0,0,16:18.6
2,0,16:18.6
-8,1,16:18.6
-6,1,16:18.6
0,1,16:18.6
1,1,16:18.6
-9,2,16:18.6
-6,2,16:18.6
0,2,16:18.6
-6,3,16:18.6
-5,3,16:18.6
-1,3,16:18.6
0,3,16:18.6
1,3,16:18.6
-12,4,16:18.6
-11,4,16:18.6
-5,4,16:18.6
-2,4,16:18.6
1,4,16:18.6
-13,5,16:18.6
-5,5,16:18.6
-2,5,16:18.6
1,5,16:18.6
-14,6,16:18.6
-13,6,16:18.6
-3,6,16:18.6
1,6,16:18.6
-15,7,16:18.6
-4,7,16:18.6
-3,7,16:18.6
1,7,16:18.6
-17,8,16:18.6
-16,8,16:18.6
-4,8,16:18.6
-3,8,16:18.6
2,8,16:18.6
-5,9,16:18.6
-3,9,16:18.6
-5,10,16:18.6
-1,10,16:18.6
-6,11,16:18.6
-1,11,16:18.6
0,12,16:18.6
1,12,16:18.6
1,13,16:18.6
2,13,16:18.6
2,14,16:18.6
3,14,16:18.6
3,15,16:18.6
4,15,16:18.6
-11,-14,17:18.6
-10,-14,17:18.6
-10,-13,17:18.6
-9,-13,17:18.6
-9,-12,17:18.6
-8,-12,17:18.6
-8,-11,17:18.6
-7,-11,17:18.6
-7,-10,17:18.6
-6,-10,17:18.6
-6,-9,17:18.6
-5,-9,17:18.6
9,-9,17:18.6
8,-8,17:18.6
9,-8,17:18.6
7,-7,17:18.6
8,-7,17:18.6
-3,-6,17:18.6
-2,-6,17:18.6
6,-6,17:18.6
7,-6,17:18.6
-8,-5,17:18.6
6,-5,17:18.6
-8,-4,17:18.6
-1,-4,17:18.6
4,-4,17:18.6
5,-4,17:18.6
-7,-3,17:18.6
-1,-3,17:18.6
1,-3,17:18.6
2,-3,17:18.6
3,-3,17:18.6
4,-3,17:18.6
-7,-2,17:18.6
-3,-2,17:18.6
-2,-2,17:18.6
-1,-2,17:18.6
0,-2,17:18.6
4,-2,17:18.6
-7,-1,17:18.6
-6,-1,17:18.6
-4,-1,17:18.6
-3,-1,17:18.6
0,-1,17:18.6
-8,0,17:18.6
-7,0,17:18.6
-6,0,17:18.6
0,0,17:18.6
-9,1,17:18.6
-8,1,17:18.6
-6,1,17:18.6
0,1,17:18.6
1,1,17:18.6
-10,2,17:18.6
-9,2,17:18.6
-6,2,17:18.6
0,2,17:18.6
-6,3,17:18.6
-1,3,17:18.6
0,3,17:18.6
1,3,17:18.6
-12,4,17:18.6
-2,4,17:18.6
1,4,17:18.6
-13,5,17:18.6
-5,5,17:18.6
-2,5,17:18.6
1,5,17:18.6
-15,6,17:18.6
-14,6,17:18.6
-5,6,17:18.6
-3,6,17:18.6
1,6,17:18.6
-16,7,17:18.6
-15,7,17:18.6
-4,7,17:18.6
-3,7,17:18.6
1,7,17:18.6
-17,8,17:18.6
-5,8,17:18.6
-4,8,17:18.6
2,8,17:18.6
-5,9,17:18.6
-4,9,17:18.6
2,9,17:18.6
-5,10,17:18.6
-6,11,17:18.6
-2,11,17:18.6
-1,11,17:18.6
-1,12,17:18.6
0,12,17:18.6
0,13,17:18.6
1,13,17:18.6
2,14,17:18.6
3,15,17:18.6
-11,-15,18:18.6
-10,-14,18:18.6
-9,-13,18:18.6
-8,-12,18:18.6
-6,-10,18:18.6
-5,-9,18:18.6
9,-9,18:18.6
8,-8,18:18.6
-3,-7,18:18.6
-2,-7,18:18.6
7,-7,18:18.6
8,-7,18:18.6
-2,-6,18:18.6
6,-6,18:18.6
7,-6,18:18.6
-8,-5,18:18.6
-1,-5,18:18.6
6,-5,18:18.6
-8,-4,18:18.6
4,-4,18:18.6
5,-4,18:18.6
-8,-3,18:18.6
-1,-3,18:18.6
0,-3,18:18.6
1,-3,18:18.6
2,-3,18:18.6
3,-3,18:18.6
4,-3,18:18.6
-7,-2,18:18.6
-3,-2,18:18.6
-2,-2,18:18.6
-1,-2,18:18.6
0,-2,18:18.6
4,-2,18:18.6
-7,-1,18:18.6
-6,-1,18:18.6
-5,-1,18:18.6
-4,-1,18:18.6
0,-1,18:18.6
-9,0,18:18.6
-8,0,18:18.6
-7,0,18:18.6
0,0,18:18.6
-10,1,18:18.6
-9,1,18:18.6
-7,1,18:18.6
0,1,18:18.6
1,1,18:18.6
-11,2,18:18.6
-10,2,18:18.6
-6,2,18:18.6
-1,2,18:18.6
0,2,18:18.6
-12,3,18:18.6
-11,3,18:18.6
-6,3,18:18.6
-1,3,18:18.6
0,3,18:18.6
-13,4,18:18.6
-12,4,18:18.6
-6,4,18:18.6
-2,4,18:18.6
1,4,18:18.6
-14,5,18:18.6
-13,5,18:18.6
-6,5,18:18.6
-2,5,18:18.6
1,5,18:18.6
-3,6,18:18.6
1,6,18:18.6
-17,7,18:18.6
-16,7,18:18.6
-5,7,18:18.6
-4,7,18:18.6
-5,8,18:18.6
-4,8,18:18.6
2,8,18:18.6
-5,9,18:18.6
-4,9,18:18.6
2,9,18:18.6
-5,10,18:18.6
-4,10,18:18.6
-3,10,18:18.6
-6,11,18:18.6
-2,11,18:18.6
-6,12,18:18.6
-1,12,18:18.6
1,14,18:18.6
2,15,18:18.6
3,16,18:18.6
-10,-15,19:18.6
-10,-14,19:18.6
-9,-14,19:18.6
-7,-11,19:18.6
-6,-11,19:18.6
-6,-10,19:18.6
-5,-10,19:18.6
-5,-9,19:18.6
-4,-9,19:18.6
9,-9,19:18.6
-4,-8,19:18.6
-3,-8,19:18.6
-3,-7,19:18.6
-2,-7,19:18.6
7,-7,19:18.6
8,-7,19:18.6
-9,-6,19:18.6
-2,-6,19:18.6
7,-6,19:18.6
-9,-5,19:18.6
-8,-5,19:18.6
-1,-5,19:18.6
4,-4,19:18.6
5,-4,19:18.6
6,-4,19:18.6
-8,-3,19:18.6
-1,-3,19:18.6
0,-3,19:18.6
1,-3,19:18.6
2,-3,19:18.6
4,-3,19:18.6
-8,-2,19:18.6
-3,-2,19:18.6
-2,-2,19:18.6
-1,-2,19:18.6
3,-2,19:18.6
4,-2,19:18.6
-8,-1,19:18.6
-7,-1,19:18.6
-6,-1,19:18.6
-4,-1,19:18.6
0,-1,19:18.6
2,-1,19:18.6
3,-1,19:18.6
-9,0,19:18.6
-8,0,19:18.6
-7,0,19:18.6
0,0,19:18.6
1,0,19:18.6
2,0,19:18.6
-10,1,19:18.6
-7,1,19:18.6
0,1,19:18.6
1,1,19:18.6
-11,2,19:18.6
-10,2,19:18.6
-7,2,19:18.6
0,2,19:18.6
-12,3,19:18.6
-7,3,19:18.6
-6,3,19:18.6
0,3,19:18.6
-13,4,19:18.6
-1,4,19:18.6
1,4,19:18.6
-15,5,19:18.6
-14,5,19:18.6
-6,5,19:18.6
-2,5,19:18.6
1,5,19:18.6
-16,6,19:18.6
-15,6,19:18.6
-3,6,19:18.6
1,6,19:18.6
-17,7,19:18.6
-16,7,19:18.6
-6,7,19:18.6
-5,7,19:18.6
-3,7,19:18.6
1,7,19:18.6
-5,8,19:18.6
-4,8,19:18.6
2,8,19:18.6
-5,9,19:18.6
-4,9,19:18.6
2,9,19:18.6
-5,10,19:18.6
-4,10,19:18.6
-3,10,19:18.6
2,10,19:18.6
-6,11,19:18.6
-3,11,19:18.6
-2,11,19:18.6
2,11,19:18.6
-6,12,19:18.6
-2,12,19:18.6
-1,12,19:18.6
-7,13,19:18.6
-1,13,19:18.6
1,15,19:18.6
2,15,19:18.6
2,16,19:18.6
-10,-15,20:18.6
-9,-14,20:18.6
-8,-13,20:18.6
-7,-12,20:18.6
-6,-11,20:18.6
-5,-10,20:18.6
-4,-9,20:18.6
-3,-8,20:18.6
8,-8,20:18.6
-9,-7,20:18.6
-2,-7,20:18.6
7,-7,20:18.6
8,-7,20:18.6
-9,-6,20:18.6
-2,-6,20:18.6
7,-6,20:18.6
-9,-5,20:18.6
-1,-5,20:18.6
6,-5,20:18.6
-9,-4,20:18.6
-8,-4,20:18.6
-1,-4,20:18.6
3,-4,20:18.6
4,-4,20:18.6
5,-4,20:18.6
-8,-3,20:18.6
-1,-3,20:18.6
0,-3,20:18.6
1,-3,20:18.6
2,-3,20:18.6
4,-3,20:18.6
-8,-2,20:18.6
-4,-2,20:18.6
-3,-2,20:18.6
-2,-2,20:18.6
-1,-2,20:18.6
3,-2,20:18.6
-8,-1,20:18.6
-7,-1,20:18.6
-6,-1,20:18.6
-5,-1,20:18.6
-4,-1,20:18.6
-1,-1,20:18.6
0,-1,20:18.6
2,-1,20:18.6
3,-1,20:18.6
-10,0,20:18.6
-9,0,20:18.6
-8,0,20:18.6
-7,0,20:18.6
0,0,20:18.6
1,0,20:18.6
2,0,20:18.6
-11,1,20:18.6
-10,1,20:18.6
-7,1,20:18.6
0,1,20:18.6
1,1,20:18.6
-11,2,20:18.6
-7,2,20:18.6
-1,2,20:18.6
0,2,20:18.6
-13,3,20:18.6
-7,3,20:18.6
-1,3,20:18.6
0,3,20:18.6
-14,4,20:18.6
-13,4,20:18.6
-7,4,20:18.6
-2,4,20:18.6
-15,5,20:18.6
-6,5,20:18.6
-2,5,20:18.6
1,5,20:18.6
-16,6,20:18.6
-6,6,20:18.6
-3,6,20:18.6
1,6,20:18.6
-6,7,20:18.6
-3,7,20:18.6
1,7,20:18.6
-6,8,20:18.6
-5,8,20:18.6
-4,8,20:18.6
2,8,20:18.6
-5,9,20:18.6
-4,9,20:18.6
2,9,20:18.6
-5,10,20:18.6
2,10,20:18.6
-6,11,20:18.6
-3,11,20:18.6
2,11,20:18.6
-6,12,20:18.6
-3,12,20:18.6
-2,12,20:18.6
-7,13,20:18.6
-2,13,20:18.6
-1,13,20:18.6
-7,14,20:18.6
-1,14,20:18.6
0,14,20:18.6
1,15,20:18.6
2,16,20:18.6
-8,-13,21:18.6
-7,-13,21:18.6
-7,-12,21:18.6
-6,-12,21:18.6
-6,-11,21:18.6
-5,-11,21:18.6
-5,-10,21:18.6
-4,-10,21:18.6
-10,-9,21:18.6
-10,-8,21:18.6
-3,-8,21:18.6
-2,-8,21:18.6
-10,-7,21:18.6
-2,-7,21:18.6
7,-7,21:18.6
-9,-6,21:18.6
-2,-6,21:18.6
-9,-5,21:18.6
6,-5,21:18.6
7,-5,21:18.6
-9,-4,21:18.6
-1,-4,21:18.6
3,-4,21:18.6
4,-4,21:18.6
5,-4,21:18.6
-9,-3,21:18.6
-8,-3,21:18.6
-1,-3,21:18.6
0,-3,21:18.6
2,-3,21:18.6
-4,-2,21:18.6
-3,-2,21:18.6
-2,-2,21:18.6
-1,-2,21:18.6
3,-2,21:18.6
-8,-1,21:18.6
-7,-1,21:18.6
-5,-1,21:18.6
-1,-1,21:18.6
0,-1,21:18.6
3,-1,21:18.6
-10,0,21:18.6
-8,0,21:18.6
0,0,21:18.6
-11,1,21:18.6
-7,1,21:18.6
0,1,21:18.6
1,1,21:18.6
-12,2,21:18.6
-7,2,21:18.6
0,2,21:18.6
-13,3,21:18.6
-7,3,21:18.6
-1,3,21:18.6
0,3,21:18.6
-14,4,21:18.6
-7,4,21:18.6
-1,4,21:18.6
1,4,21:18.6
-16,5,21:18.6
-15,5,21:18.6
-2,5,21:18.6
1,5,21:18.6
-17,6,21:18.6
-16,6,21:18.6
-6,6,21:18.6
-3,6,21:18.6
1,6,21:18.6
-3,7,21:18.6
1,7,21:18.6
-6,8,21:18.6
-4,8,21:18.6
-6,9,21:18.6
-5,9,21:18.6
-4,9,21:18.6
2,9,21:18.6
-5,10,21:18.6
-6,11,21:18.6
-5,11,21:18.6
-4,11,21:18.6
-6,12,21:18.6
-3,12,21:18.6
-7,13,21:18.6
-2,13,21:18.6
-1,14,21:18.6
-8,-14,22:18.6
-7,-13,22:18.6
-7,-12,22:18.6
-6,-12,22:18.6
-5,-11,22:18.6
-4,-10,22:18.6
-3,-9,22:18.6
-10,-8,22:18.6
-2,-8,22:18.6
-2,-7,22:18.6
-10,-6,22:18.6
-9,-5,22:18.6
6,-5,22:18.6
7,-5,22:18.6
8,-5,22:18.6
-9,-4,22:18.6
-1,-4,22:18.6
2,-4,22:18.6
3,-4,22:18.6
4,-4,22:18.6
5,-4,22:18.6
-9,-3,22:18.6
-1,-3,22:18.6
0,-3,22:18.6
2,-3,22:18.6
4,-3,22:18.6
-9,-2,22:18.6
-4,-2,22:18.6
-3,-2,22:18.6
-2,-2,22:18.6
-1,-2,22:18.6
3,-2,22:18.6
-8,-1,22:18.6
-7,-1,22:18.6
-5,-1,22:18.6
-1,-1,22:18.6
2,-1,22:18.6
-11,0,22:18.6
-10,0,22:18.6
-8,0,22:18.6
0,0,22:18.6
1,0,22:18.6
-12,1,22:18.6
-11,1,22:18.6
-8,1,22:18.6
0,1,22:18.6
1,1,22:18.6
-13,2,22:18.6
-12,2,22:18.6
-8,2,22:18.6
0,2,22:18.6
-14,3,22:18.6
-13,3,22:18.6
-7,3,22:18.6
0,3,22:18.6
-15,4,22:18.6
-7,4,22:18.6
-2,4,22:18.6
-1,4,22:18.6
1,4,22:18.6
-16,5,22:18.6
-7,5,22:18.6
-2,5,22:18.6
1,5,22:18.6
-17,6,22:18.6
-7,6,22:18.6
-3,6,22:18.6
1,6,22:18.6
-3,7,22:18.6
-6,8,22:18.6
-4,8,22:18.6
-6,9,22:18.6
-6,10,22:18.6
-5,10,22:18.6
-6,11,22:18.6
-5,11,22:18.6
-4,11,22:18.6
-4,12,22:18.6
-7,13,22:18.6
-3,13,22:18.6
-2,14,22:18.6
-1,15,22:18.6
0,16,22:18.6
-9,-15,23:18.6
-8,-14,23:18.6
-7,-13,23:18.6
-6,-13,23:18.6
-5,-12,23:18.6
-5,-11,23:18.6
-4,-10,23:18.6
-3,-9,23:18.6
-2,-9,23:18.6
-2,-8,23:18.6
-2,-7,23:18.6
-2,-6,23:18.6
5,-5,23:18.6
6,-5,23:18.6
8,-5,23:18.6
-9,-4,23:18.6
-1,-4,23:18.6
2,-4,23:18.6
3,-4,23:18.6
4,-4,23:18.6
5,-4,23:18.6
-9,-3,23:18.6
-1,-3,23:18.6
1,-3,23:18.6
4,-3,23:18.6
-9,-2,23:18.6
-5,-2,23:18.6
-4,-2,23:18.6
-3,-2,23:18.6
-2,-2,23:18.6
-1,-2,23:18.6
3,-2,23:18.6
-8,-1,23:18.6
-7,-1,23:18.6
-6,-1,23:18.6
-5,-1,23:18.6
-1,-1,23:18.6
2,-1,23:18.6
3,-1,23:18.6
-11,0,23:18.6
-10,0,23:18.6
-9,0,23:18.6
0,0,23:18.6
1,0,23:18.6
2,0,23:18.6
-13,1,23:18.6
-12,1,23:18.6
-8,1,23:18.6
0,1,23:18.6
1,1,23:18.6
-13,2,23:18.6
-8,2,23:18.6
0,2,23:18.6
-15,3,23:18.6
-14,3,23:18.6
-8,3,23:18.6
0,3,23:18.6
-16,4,23:18.6
-15,4,23:18.6
-7,4,23:18.6
-2,4,23:18.6
-1,4,23:18.6
0,4,23:18.6
-17,5,23:18.6
-16,5,23:18.6
-7,5,23:18.6
-2,5,23:18.6
-7,6,23:18.6
-3,6,23:18.6
1,6,23:18.6
-7,7,23:18.6
-3,7,23:18.6
-6,8,23:18.6
-6,9,23:18.6
-6,10,23:18.6
-5,10,23:18.6
-6,11,23:18.6
-5,11,23:18.6
-4,12,23:18.6
-4,13,23:18.6
-3,13,23:18.6
-3,14,23:18.6
-2,14,23:18.6
-7,-14,24:18.6
-7,-13,24:18.6
-6,-13,24:18.6
-6,-12,24:18.6
-5,-12,24:18.6
-4,-11,24:18.6
-3,-10,24:18.6
-2,-9,24:18.6
-2,-7,24:18.6
-2,-6,24:18.6
-1,-5,24:18.6
6,-5,24:18.6
-10,-4,24:18.6
-1,-4,24:18.6
3,-4,24:18.6
5,-4,24:18.6
-1,-3,24:18.6
0,-3,24:18.6
1,-3,24:18.6
4,-3,24:18.6
-5,-2,24:18.6
-4,-2,24:18.6
3,-2,24:18.6
-9,-1,24:18.6
-8,-1,24:18.6
-7,-1,24:18.6
-6,-1,24:18.6
-1,-1,24:18.6
2,-1,24:18.6
-11,0,24:18.6
-10,0,24:18.6
-9,0,24:18.6
1,0,24:18.6
-13,1,24:18.6
-12,1,24:18.6
0,1,24:18.6
1,1,24:18.6
-13,2,24:18.6
-8,2,24:18.6
0,2,24:18.6
-15,3,24:18.6
-8,3,24:18.6
-1,3,24:18.6
0,3,24:18.6
-17,4,24:18.6
-16,4,24:18.6
-8,4,24:18.6
-2,4,24:18.6
-1,4,24:18.6
-17,5,24:18.6
-7,5,24:18.6
-2,5,24:18.6
-7,6,24:18.6
-3,6,24:18.6
-7,7,24:18.6
-3,7,24:18.6
-7,8,24:18.6
-7,9,24:18.6
-6,9,24:18.6
-5,9,24:18.6
-4,9,24:18.6
-5,10,24:18.6
-6,11,24:18.6
-6,12,24:18.6
-5,12,24:18.6
-5,13,24:18.6
-4,13,24:18.6
-3,14,24:18.6
-2,15,24:18.6
-8,-15,25:18.6
-7,-14,25:18.6
-6,-13,25:18.6
-5,-12,25:18.6
-4,-11,25:18.6
-3,-10,25:18.6
-2,-9,25:18.6
-2,-7,25:18.6
-2,-6,25:18.6
-2,-5,25:18.6
-1,-5,25:18.6
-1,-4,25:18.6
3,-4,25:18.6
5,-4,25:18.6
-2,-3,25:18.6
-1,-3,25:18.6
0,-3,25:18.6
4,-3,25:18.6
-4,-2,25:18.6
3,-2,25:18.6
-9,-1,25:18.6
-8,-1,25:18.6
-7,-1,25:18.6
-1,-1,25:18.6
2,-1,25:18.6
3,-1,25:18.6
-11,0,25:18.6
-10,0,25:18.6
-9,0,25:18.6
1,0,25:18.6
2,0,25:18.6
-14,1,25:18.6
-9,1,25:18.6
0,1,25:18.6
1,1,25:18.6
0,2,25:18.6
-16,3,25:18.6
-15,3,25:18.6
-8,3,25:18.6
-1,3,25:18.6
0,3,25:18.6
-17,4,25:18.6
-2,4,25:18.6
-1,4,25:18.6
-2,5,25:18.6
-8,6,25:18.6
-7,6,25:18.6
-7,7,25:18.6
-3,7,25:18.6
-4,8,25:18.6
-7,9,25:18.6
-5,10,25:18.6
-6,12,25:18.6
-4,14,25:18.6
-3,15,25:18.6
-7,-14,26:18.6
-5,-13,26:18.6
-5,-12,26:18.6
-3,-11,26:18.6
-3,-10,26:18.6
-2,-8,26:18.6
-2,-7,26:18.6
6,-6,26:18.6
-2,-5,26:18.6
5,-5,26:18.6
6,-5,26:18.6
-1,-4,26:18.6
5,-4,26:18.6
0,-3,26:18.6
4,-3,26:18.6
-4,-2,26:18.6
3,-2,26:18.6
-9,-1,26:18.6
-8,-1,26:18.6
2,-1,26:18.6
3,-1,26:18.6
-12,0,26:18.6
-11,0,26:18.6
1,0,26:18.6
2,0,26:18.6
-14,1,26:18.6
-13,1,26:18.6
1,1,26:18.6
-15,2,26:18.6
0,2,26:18.6
-17,3,26:18.6
-16,3,26:18.6
-1,3,26:18.6
-1,4,26:18.6
-2,5,26:18.6
-8,6,26:18.6
-8,7,26:18.6
-7,7,26:18.6
-3,7,26:18.6
-7,9,26:18.6
-7,10,26:18.6
-5,10,26:18.6
-7,11,26:18.6
-6,12,26:18.6
-6,13,26:18.6
-5,13,26:18.6
-5,14,26:18.6
-5,-13,27:18.6
-4,-12,27:18.6
-3,-11,27:18.6
-3,-10,27:18.6
-3,-9,27:18.6
-2,-9,27:18.6
-2,-8,27:18.6
-2,-6,27:18.6
-2,-5,27:18.6
5,-4,27:18.6
-1,-3,27:18.6
3,-2,27:18.6
-9,-1,27:18.6
-8,-1,27:18.6
-13,0,27:18.6
-12,0,27:18.6
-11,0,27:18.6
-10,0,27:18.6
1,0,27:18.6
2,0,27:18.6
-14,1,27:18.6
-13,1,27:18.6
-16,2,27:18.6
-15,2,27:18.6
0,2,27:18.6
-17,3,27:18.6
-1,4,27:18.6
-2,5,27:18.6
-8,6,27:18.6
-8,7,27:18.6
-7,9,27:18.6
-7,10,27:18.6
-7,11,27:18.6
-7,12,27:18.6
-6,13,27:18.6
-6,14,27:18.6
-5,14,27:18.6
-5,15,27:18.6
-5,-14,28:18.6
-5,-13,28:18.6
-4,-13,28:18.6
-4,-12,28:18.6
-3,-10,28:18.6
-3,-9,28:18.6
-2,-8,28:18.6
-2,-7,28:18.6
-2,-6,28:18.6
-2,-5,28:18.6
3,-2,28:18.6
-9,-1,28:18.6
2,-1,28:18.6
-12,0,28:18.6
-11,0,28:18.6
-10,0,28:18.6
1,0,28:18.6
2,0,28:18.6
-16,1,28:18.6
-14,1,28:18.6
0,1,28:18.6
1,1,28:18.6
-16,2,28:18.6
0,2,28:18.6
-17,3,28:18.6
-1,4,28:18.6
-2,5,28:18.6
-8,7,28:18.6
-8,8,28:18.6
-8,9,28:18.6
-7,10,28:18.6
-7,12,28:18.6
-6,14,28:18.6
-5,15,28:18.6
-5,-14,29:18.6
-4,-13,29:18.6
-3,-11,29:18.6
-3,-10,29:18.6
-2,-8,29:18.6
-2,-7,29:18.6
-2,-6,29:18.6
-2,-5,29:18.6
3,-2,29:18.6
-9,-1,29:18.6
2,-1,29:18.6
-11,0,29:18.6
2,0,29:18.6
-16,1,29:18.6
-15,1,29:18.6
-14,1,29:18.6
0,1,29:18.6
1,1,29:18.6
0,2,29:18.6
-1,3,29:18.6
-1,4,29:18.6
-8,7,29:18.6
-8,8,29:18.6
-8,9,29:18.6
-7,12,29:18.6
-7,13,29:18.6
-7,14,29:18.6
-5,16,29:18.6
-6,-15,30:18.6
-5,-14,30:18.6
-3,-13,30:18.6
-3,-12,30:18.6
-3,-11,30:18.6
-3,-10,30:18.6
-2,-8,30:18.6
-2,-7,30:18.6
3,-2,30:18.6
2,-1,30:18.6
-14,0,30:18.6
-11,0,30:18.6
2,0,30:18.6
1,1,30:18.6
-17,2,30:18.6
-1,3,30:18.6
-1,4,30:18.6
-2,5,30:18.6
-8,9,30:18.6
-8,11,30:18.6
-7,13,30:18.6
-7,14,30:18.6
-3,-13,31:18.6
-3,-12,31:18.6
-3,-10,31:18.6
3,-2,31:18.6
1,0,31:18.6
1,1,31:18.6
-1,3,31:18.6
-1,4,31:18.6
-8,12,31:18.6
-7,15,31:18.6
-4,-14,32:18.6
1,0,32:18.6
0,2,32:18.6
2,-1,33:18.6
