[META]
version=2.0
spawnOnBlockType=2
spawnSunlight=True
spawnDarkness=True
spawnWater=False
spawnLava=False
underFill=False
randomRotation=True
dig=True
tree=False
branch=False
needsFoundation=True
rarity=100
collisionPercentage=20
spawnElevationMin=0
spawnElevationMax=200
spawnInBiome=Custom
[DATA]
-3,-3,-8:17.12
-2,-1,-8:17.12
-4,1,-8:17.12
-1,2,-8:17.12
-4,-3,-7:17.12
-2,-1,-7:17.12
-4,1,-7:17.12
-1,1,-7:17.12
-1,2,-7:17.12
-4,-2,-6:17.12
-2,-1,-6:17.12
-4,1,-6:17.12
-3,1,-6:17.12
-1,1,-6:17.12
-4,-1,-5:17.12
-2,-1,-5:17.12
-3,1,-5:17.12
-2,1,-5:17.12
-1,1,-5:17.12
-1,2,-5:17.12
-4,-1,-4:17.12
-2,-1,-4:17.12
-1,0,-4:17.12
-2,1,-4:17.12
-1,1,-4:17.12
-3,-1,-3:17.12
-2,-1,-3:17.12
-2,0,-3:17.12
-1,0,-3:17.12
-2,1,-3:17.12
-2,-2,-2:17.12
-3,-1,-2:17.12
-2,-1,-2:17.12
-1,-1,-2:17.12
-3,0,-2:17.12
-2,0,-2:17.12
-1,0,-2:17.12
-3,1,-2:17.12
-2,1,-2:17.12
-1,1,-2:17.12
-3,-1,-1:17.12
-2,-1,-1:17.12
-1,-1,-1:17.12
-3,0,-1:17.12
-1,0,-1:17.12
-3,1,-1:17.12
-2,1,-1:17.12
-3,-1,0:17.12
-2,-1,0:17.12
-1,-1,0:17.12
-2,0,0:17.12
-1,0,0:17.12
-5,1,0:18.14
-4,1,0:18.14
-3,1,0:18.14
-2,1,0:17.12
-4,2,0:18.14
-3,2,0:18.14
-3,-1,1:17.12
-2,-1,1:17.12
-1,-1,1:17.12
-2,0,1:17.12
-1,0,1:17.12
-4,1,1:18.14
-3,1,1:18.14
-2,1,1:18.14
-4,2,1:18.14
-3,2,1:18.14
-2,2,1:18.14
-2,-1,2:17.12
-3,0,2:18.14
-2,0,2:17.12
-1,0,2:17.12
-4,1,2:18.14
-3,1,2:18.14
-2,1,2:18.14
-4,2,2:18.14
-3,2,2:18.14
-2,2,2:18.14
-3,3,2:18.14
-2,-1,3:17.12
-1,-1,3:17.12
-3,0,3:18.14
-2,0,3:17.12
-1,0,3:17.12
-4,1,3:18.14
-3,1,3:18.14
-2,1,3:17.12
-3,2,3:18.14
-2,-3,4:18.14
-1,-3,4:18.14
-2,-2,4:18.14
-2,-1,4:17.12
-1,-1,4:17.12
1,-1,4:18.14
-3,0,4:18.14
-2,0,4:17.12
-1,0,4:17.12
0,0,4:18.14
1,0,4:18.14
2,0,4:18.14
-4,1,4:18.14
-3,1,4:18.14
-2,1,4:17.12
-1,1,4:17.12
-2,2,4:18.14
-1,2,4:18.14
-2,3,4:18.14
-1,3,4:18.14
-3,-4,5:18.14
-1,-4,5:18.14
-3,-3,5:18.14
-1,-3,5:18.14
-3,-2,5:18.14
-2,-2,5:18.14
-1,-2,5:18.14
1,-2,5:18.14
2,-2,5:18.14
-5,-1,5:18.14
-4,-1,5:18.14
-3,-1,5:18.14
-2,-1,5:18.14
-1,-1,5:17.12
0,-1,5:18.14
1,-1,5:18.14
-3,0,5:18.14
-2,0,5:17.12
-1,0,5:17.12
0,0,5:18.14
1,0,5:18.14
-5,1,5:18.14
-4,1,5:18.14
-3,1,5:18.14
-2,1,5:18.14
-1,1,5:18.14
1,1,5:18.14
2,1,5:18.14
-2,2,5:18.14
-1,2,5:18.14
0,2,5:18.14
-2,3,5:18.14
0,3,5:18.14
-4,-4,6:18.14
0,-4,6:18.14
-4,-3,6:18.14
-3,-3,6:18.14
0,-3,6:18.14
1,-3,6:18.14
2,-3,6:18.14
-5,-2,6:18.14
-4,-2,6:18.14
-3,-2,6:18.14
-2,-2,6:17.12
-1,-2,6:18.14
0,-2,6:18.14
1,-2,6:18.14
-4,-1,6:18.14
-3,-1,6:18.14
-2,-1,6:18.14
-1,-1,6:18.14
0,-1,6:18.14
-3,0,6:17.12
-2,0,6:18.14
-1,0,6:18.14
0,0,6:17.12
1,0,6:17.12
-4,1,6:18.14
-3,1,6:18.14
-2,1,6:18.14
-1,1,6:18.14
0,1,6:18.14
1,1,6:18.14
2,1,6:18.14
-5,2,6:18.14
-4,2,6:18.14
-3,2,6:18.14
-2,2,6:18.14
-1,2,6:17.12
0,2,6:18.14
1,2,6:18.14
2,2,6:18.14
-3,3,6:18.14
1,3,6:18.14
1,-5,7:18.14
0,-4,7:18.14
1,-4,7:18.14
2,-4,7:18.14
-6,-3,7:18.14
-5,-3,7:18.14
-4,-3,7:18.14
-2,-3,7:17.12
-1,-3,7:18.14
0,-3,7:18.14
1,-3,7:18.14
-5,-2,7:18.14
-4,-2,7:18.14
-3,-2,7:18.14
-2,-2,7:18.14
-1,-2,7:18.14
0,-2,7:18.14
1,-2,7:18.14
-4,-1,7:18.14
-3,-1,7:18.14
-2,-1,7:18.14
-1,-1,7:18.14
0,-1,7:18.14
1,-1,7:18.14
-4,0,7:17.12
-3,0,7:18.14
0,0,7:18.14
1,0,7:18.14
-4,1,7:18.14
-3,1,7:18.14
-2,1,7:18.14
-1,1,7:18.14
0,1,7:18.14
1,1,7:18.14
-4,2,7:18.14
-3,2,7:18.14
-2,2,7:18.14
-1,2,7:18.14
0,2,7:18.14
1,2,7:18.14
2,2,7:18.14
-5,3,7:18.14
-4,3,7:18.14
-3,3,7:18.14
2,3,7:18.14
3,3,7:18.14
-4,4,7:18.14
1,-5,8:18.14
2,-5,8:18.14
-6,-4,8:18.14
-5,-4,8:18.14
-4,-4,8:18.14
-3,-4,8:18.14
-2,-4,8:18.14
-1,-4,8:18.14
0,-4,8:18.14
1,-4,8:18.14
2,-4,8:18.14
-6,-3,8:18.14
-5,-3,8:18.14
-4,-3,8:18.14
-3,-3,8:18.14
-2,-3,8:18.14
-1,-3,8:18.14
0,-3,8:18.14
1,-3,8:18.14
2,-3,8:18.14
-6,-2,8:18.14
-5,-2,8:18.14
-3,-2,8:18.14
-2,-2,8:18.14
-1,-2,8:18.14
0,-2,8:18.14
1,-2,8:18.14
2,-2,8:18.14
-5,-1,8:18.14
-4,-1,8:18.14
-3,-1,8:18.14
1,-1,8:18.14
2,-1,8:18.14
-5,0,8:18.14
1,0,8:18.14
2,0,8:18.14
-5,1,8:18.14
-4,1,8:18.14
-3,1,8:18.14
0,1,8:18.14
1,1,8:18.14
2,1,8:18.14
3,1,8:18.14
-5,2,8:18.14
-4,2,8:18.14
-3,2,8:18.14
-2,2,8:18.14
-1,2,8:18.14
0,2,8:18.14
1,2,8:18.14
2,2,8:18.14
3,2,8:18.14
-5,3,8:18.14
-4,3,8:18.14
-3,3,8:18.14
-2,3,8:18.14
-1,3,8:18.14
0,3,8:18.14
1,3,8:18.14
2,3,8:18.14
3,3,8:18.14
-5,4,8:18.14
-4,4,8:18.14
-3,4,8:18.14
2,4,8:18.14
-1,-5,9:18.14
0,-5,9:18.14
1,-5,9:18.14
2,-5,9:18.14
-5,-4,9:18.14
-4,-4,9:18.14
-3,-4,9:18.14
-2,-4,9:18.14
-1,-4,9:18.14
0,-4,9:18.14
2,-4,9:18.14
-6,-3,9:18.14
-4,-3,9:18.14
-3,-3,9:18.14
-1,-3,9:18.14
0,-3,9:18.14
1,-3,9:18.14
2,-3,9:18.14
-6,-2,9:18.14
-4,-2,9:18.14
1,-2,9:18.14
2,-2,9:18.14
3,-2,9:18.14
-6,-1,9:18.14
-5,-1,9:18.14
-4,-1,9:18.14
2,-1,9:18.14
3,-1,9:18.14
-6,0,9:18.14
-5,0,9:18.14
2,0,9:18.14
3,0,9:18.14
-6,1,9:18.14
-5,1,9:18.14
-4,1,9:18.14
2,1,9:18.14
3,1,9:18.14
-6,2,9:18.14
-5,2,9:18.14
-4,2,9:18.14
-3,2,9:18.14
1,2,9:18.14
2,2,9:18.14
3,2,9:18.14
-5,3,9:18.14
-4,3,9:18.14
-3,3,9:18.14
-2,3,9:18.14
-1,3,9:18.14
0,3,9:18.14
1,3,9:18.14
3,3,9:18.14
-5,4,9:18.14
-4,4,9:18.14
-3,4,9:18.14
-2,4,9:18.14
-1,4,9:18.14
0,4,9:18.14
1,4,9:18.14
2,4,9:18.14
-4,5,9:18.6
0,-5,10:18.14
1,-5,10:18.14
-5,-4,10:18.14
-4,-4,10:18.14
-3,-4,10:18.14
-2,-4,10:18.14
-1,-4,10:18.14
0,-4,10:18.14
1,-4,10:18.14
2,-4,10:18.14
-6,-3,10:18.14
-5,-3,10:18.14
-4,-3,10:18.14
-3,-3,10:18.14
0,-3,10:18.14
1,-3,10:18.14
2,-3,10:18.14
-6,-2,10:18.14
-5,-2,10:18.14
-4,-2,10:18.14
2,-2,10:18.14
3,-2,10:18.6
-6,-1,10:18.14
-5,-1,10:18.14
2,-1,10:18.14
3,-1,10:18.6
-5,0,10:18.14
2,0,10:18.14
3,0,10:18.6
-6,1,10:18.14
-5,1,10:18.14
2,1,10:18.14
3,1,10:18.6
-5,2,10:18.14
-4,2,10:18.14
2,2,10:18.14
3,2,10:18.6
-5,3,10:18.6
-4,3,10:18.6
-3,3,10:18.6
-1,3,10:18.6
0,3,10:18.6
1,3,10:18.6
2,3,10:18.6
3,3,10:18.6
-5,4,10:18.6
-4,4,10:18.6
-3,4,10:18.6
-2,4,10:18.6
-1,4,10:18.6
0,4,10:18.6
1,4,10:18.6
2,4,10:18.6
-4,5,10:18.6
-3,5,10:18.6
-1,-5,11:18.14
-3,-4,11:18.14
-2,-4,11:18.14
-1,-4,11:18.14
0,-4,11:18.14
1,-4,11:18.14
2,-4,11:18.14
-5,-3,11:18.14
-4,-3,11:18.14
-3,-3,11:18.14
-2,-3,11:18.14
-1,-3,11:18.14
0,-3,11:18.14
1,-3,11:18.14
2,-3,11:18.14
3,-3,11:18.6
-6,-2,11:18.14
-5,-2,11:18.14
-4,-2,11:18.14
1,-2,11:18.14
2,-2,11:18.14
3,-2,11:18.6
-6,-1,11:18.14
-5,-1,11:18.14
2,-1,11:18.14
3,-1,11:18.6
-6,0,11:18.14
-5,0,11:18.14
2,0,11:18.14
3,0,11:18.6
-6,1,11:18.14
-5,1,11:18.14
-4,1,11:18.14
2,1,11:18.14
3,1,11:18.6
-5,2,11:18.6
-4,2,11:18.6
1,2,11:18.6
2,2,11:18.6
-5,3,11:18.6
-4,3,11:18.6
-3,3,11:18.6
-2,3,11:18.6
-1,3,11:18.6
0,3,11:18.6
1,3,11:18.6
2,3,11:18.6
-5,4,11:18.6
-4,4,11:18.6
-3,4,11:18.6
-2,4,11:18.6
-1,4,11:18.6
0,4,11:18.6
1,4,11:18.6
-2,5,11:18.6
-1,5,11:18.6
-3,-4,12:18.6
-2,-4,12:18.6
-1,-4,12:18.6
1,-4,12:18.6
-5,-3,12:18.6
-4,-3,12:18.6
-3,-3,12:18.6
-2,-3,12:18.6
-1,-3,12:18.6
0,-3,12:18.6
1,-3,12:18.6
-6,-2,12:18.6
-5,-2,12:18.6
-4,-2,12:18.6
-3,-2,12:18.6
1,-2,12:18.6
2,-2,12:18.6
-6,-1,12:18.6
-5,-1,12:18.6
-4,-1,12:18.6
1,-1,12:18.6
3,-1,12:18.6
-6,0,12:18.6
-5,0,12:18.6
1,0,12:18.6
3,0,12:18.6
-6,1,12:18.6
-5,1,12:18.6
-4,1,12:18.6
1,1,12:18.6
2,1,12:18.6
-6,2,12:18.6
-5,2,12:18.6
-4,2,12:18.6
-1,2,12:18.6
0,2,12:18.6
1,2,12:18.6
2,2,12:18.6
-4,3,12:18.6
-3,3,12:18.6
-2,3,12:18.6
-1,3,12:18.6
0,3,12:18.6
1,3,12:18.6
2,3,12:18.6
-2,4,12:18.6
0,4,12:18.6
-1,5,12:18.6
0,5,12:18.6
-6,-3,13:18.6
-4,-3,13:18.6
0,-3,13:18.6
1,-3,13:18.6
-5,-2,13:18.6
-4,-2,13:18.6
-3,-2,13:18.6
-2,-2,13:18.6
-1,-2,13:18.6
0,-2,13:18.6
1,-2,13:18.6
-5,-1,13:18.6
-4,-1,13:18.6
-3,-1,13:18.6
1,-1,13:18.6
3,-1,13:18.6
-6,0,13:18.6
-3,0,13:18.6
1,0,13:18.6
-6,1,13:18.6
-5,1,13:18.6
-4,1,13:18.6
-3,1,13:18.6
1,1,13:18.6
2,1,13:18.6
-4,2,13:18.6
-3,2,13:18.6
-2,2,13:18.6
-1,2,13:18.6
0,2,13:18.6
1,2,13:18.6
2,2,13:18.6
-4,3,13:18.6
-3,3,13:18.6
1,3,13:18.6
-3,-3,14:18.6
0,-3,14:18.6
-3,-2,14:18.6
-2,-2,14:18.6
-1,-2,14:18.6
0,-2,14:18.6
1,-2,14:18.6
-5,-1,14:18.6
-4,-1,14:18.6
-3,-1,14:18.6
-2,-1,14:18.6
0,-1,14:18.6
-3,0,14:18.6
0,0,14:18.6
-3,1,14:18.6
0,1,14:18.6
1,1,14:18.6
2,1,14:18.6
-4,2,14:18.6
-3,2,14:18.6
-2,2,14:18.6
-1,2,14:18.6
0,2,14:18.6
1,2,14:18.6
-3,3,14:18.6
-2,3,14:18.6
0,3,14:18.6
1,3,14:18.6
-3,-3,15:18.6
-1,-3,15:18.6
-3,-2,15:18.6
-2,-2,15:18.6
-1,-2,15:18.6
0,-2,15:18.6
-4,-1,15:18.6
-3,-1,15:18.6
-2,-1,15:18.6
-1,-1,15:18.6
0,-1,15:18.6
1,-1,15:18.6
-3,0,15:18.6
-2,0,15:18.6
0,0,15:18.6
-4,1,15:18.6
-3,1,15:18.6
-2,1,15:18.6
-1,1,15:18.6
0,1,15:18.6
1,1,15:18.6
-2,2,15:18.6
0,2,15:18.6
-2,3,15:18.6
0,3,15:18.6
-2,-2,16:18.6
-1,-2,16:18.6
-2,-1,16:18.6
-1,-1,16:18.6
0,-1,16:18.6
1,-1,16:18.6
-3,0,16:18.6
-2,0,16:18.6
-1,0,16:18.6
0,0,16:18.6
1,0,16:18.6
-3,1,16:18.6
-2,1,16:18.6
-1,1,16:18.6
0,1,16:18.6
-2,2,16:18.6
-1,2,16:18.6
0,2,16:18.6
-2,0,17:18.6
-1,0,17:18.6
-1,1,17:18.6
