[META]
version=2.0
spawnOnBlockType=2
spawnSunlight=True
spawnDarkness=True
spawnWater=False
spawnLava=False
underFill=False
randomRotation=True
dig=True
tree=False
branch=False
needsFoundation=True
rarity=100
collisionPercentage=20
spawnElevationMin=0
spawnElevationMax=200
spawnInBiome=Custom
[DATA]
-3,-7,-8:17.12
4,-7,-8:17.12
5,-7,-8:17.12
4,-6,-8:17.12
4,-5,-8:17.12
5,-5,-8:17.12
-7,-3,-8:17.12
-7,-2,-8:17.12
5,-2,-8:17.12
-5,5,-8:17.12
3,5,-8:17.12
-4,6,-8:17.12
1,6,-8:17.12
2,6,-8:17.12
3,6,-8:17.12
3,7,-8:17.12
-2,-7,-7:17.12
4,-7,-7:17.12
-3,-6,-7:17.12
-1,-6,-7:17.12
-3,-5,-7:17.12
-2,-5,-7:17.12
3,-5,-7:17.12
4,-5,-7:17.12
5,-5,-7:17.12
-2,-4,-7:17.12
4,-4,-7:17.12
5,-4,-7:17.12
-6,-3,-7:17.12
-8,-2,-7:17.12
-7,-2,-7:17.12
-7,-1,-7:17.12
4,-1,-7:17.12
5,-1,-7:17.12
3,0,-7:17.12
4,0,-7:17.12
5,0,-7:17.12
4,1,-7:17.12
-4,4,-7:17.12
-5,5,-7:17.12
-4,5,-7:17.12
-3,5,-7:17.12
4,5,-7:17.12
1,6,-7:17.12
2,6,-7:17.12
3,6,-7:17.12
4,6,-7:17.12
3,7,-7:17.12
-2,-8,-6:17.12
-4,-7,-6:17.12
-3,-7,-6:17.12
-2,-7,-6:17.12
-4,-6,-6:17.12
-3,-6,-6:17.12
-2,-6,-6:17.12
3,-6,-6:17.12
-3,-5,-6:17.12
-2,-5,-6:17.12
-1,-5,-6:17.12
2,-5,-6:17.12
3,-5,-6:17.12
4,-5,-6:17.12
5,-5,-6:17.12
-3,-4,-6:17.12
4,-4,-6:17.12
-7,-3,-6:17.12
-5,-3,-6:17.12
-7,-2,-6:17.12
-6,-2,-6:17.12
-5,-2,-6:17.12
5,-2,-6:17.12
-7,-1,-6:17.12
-5,-1,-6:17.12
3,-1,-6:17.12
4,-1,-6:17.12
5,-1,-6:17.12
-6,0,-6:17.12
3,0,-6:17.12
4,0,-6:17.12
5,0,-6:17.12
6,0,-6:17.12
4,1,-6:17.12
5,1,-6:17.12
6,1,-6:17.12
-6,2,-6:17.12
-5,2,-6:17.12
-4,2,-6:17.12
-5,3,-6:17.12
-4,4,-6:17.12
-3,4,-6:17.12
-5,5,-6:17.12
-4,5,-6:17.12
-3,5,-6:17.12
2,5,-6:17.12
-4,6,-6:17.12
-3,6,-6:17.12
2,6,-6:17.12
3,6,-6:17.12
4,6,-6:17.12
4,7,-6:17.12
-3,-7,-5:17.12
-2,-7,-5:17.12
-3,-6,-5:17.12
-2,-6,-5:17.12
-1,-6,-5:17.12
4,-6,-5:17.12
5,-6,-5:17.12
-3,-5,-5:17.12
-2,-5,-5:17.12
2,-5,-5:17.12
3,-5,-5:17.12
4,-5,-5:17.12
5,-5,-5:17.12
-3,-4,-5:17.12
4,-4,-5:17.12
-7,-2,-5:17.12
-6,-2,-5:17.12
-5,-2,-5:17.12
-4,-2,-5:17.12
-6,-1,-5:17.12
-5,-1,-5:17.12
-4,-1,-5:17.12
4,-1,-5:17.12
-7,0,-5:17.12
-6,0,-5:17.12
-5,0,-5:17.12
-4,0,-5:17.12
3,0,-5:17.12
4,0,-5:17.12
5,0,-5:17.12
6,0,-5:17.12
-5,1,-5:17.12
-4,1,-5:17.12
3,1,-5:17.12
4,1,-5:17.12
-5,2,-5:17.12
-4,2,-5:17.12
5,2,-5:17.12
-5,3,-5:17.12
-4,4,-5:17.12
2,4,-5:17.12
-5,5,-5:17.12
-4,5,-5:17.12
-3,5,-5:17.12
2,5,-5:17.12
3,5,-5:17.12
-5,6,-5:17.12
-4,6,-5:17.12
-3,6,-5:17.12
1,6,-5:17.12
2,6,-5:17.12
3,6,-5:17.12
4,6,-5:17.12
1,-8,-4:17.12
0,-7,-4:17.12
1,-7,-4:17.12
2,-7,-4:17.12
-3,-6,-4:17.12
-2,-6,-4:17.12
-1,-6,-4:17.12
1,-6,-4:17.12
2,-6,-4:17.12
-4,-5,-4:17.12
-3,-5,-4:17.12
-2,-5,-4:17.12
2,-5,-4:17.12
3,-5,-4:17.12
4,-5,-4:17.12
5,-5,-4:17.12
6,-5,-4:17.12
-3,-4,-4:17.12
3,-4,-4:17.12
4,-4,-4:17.12
7,-4,-4:17.12
-5,-3,-4:17.12
-6,-2,-4:17.12
-5,-2,-4:17.12
-6,-1,-4:17.12
-5,-1,-4:17.12
4,-1,-4:17.12
-6,0,-4:17.12
-5,0,-4:17.12
-4,0,-4:17.12
4,0,-4:17.12
-6,1,-4:17.12
-5,1,-4:17.12
-4,1,-4:17.12
-3,1,-4:17.12
3,1,-4:17.12
4,1,-4:17.12
5,1,-4:17.12
6,1,-4:17.12
-6,2,-4:17.12
-5,2,-4:17.12
-4,2,-4:17.12
-3,2,-4:17.12
4,2,-4:17.12
6,2,-4:17.12
-6,3,-4:17.12
-5,3,-4:17.12
-3,3,-4:17.12
-2,3,-4:17.12
-4,4,-4:17.12
-3,4,-4:17.12
1,4,-4:17.12
2,4,-4:17.12
3,4,-4:17.12
-4,5,-4:17.12
-3,5,-4:17.12
1,5,-4:17.12
2,5,-4:17.12
-4,6,-4:17.12
1,6,-4:17.12
2,6,-4:17.12
3,6,-4:17.12
1,-8,-3:17.12
-6,-7,-3:17.12
-4,-7,-3:17.12
-3,-7,-3:17.12
-2,-7,-3:17.12
1,-7,-3:17.12
2,-7,-3:17.12
-7,-6,-3:17.12
-4,-6,-3:17.12
-3,-6,-3:17.12
-2,-6,-3:17.12
-1,-6,-3:17.12
0,-6,-3:17.12
1,-6,-3:17.12
2,-6,-3:17.12
3,-6,-3:17.12
-4,-5,-3:17.12
-3,-5,-3:17.12
-2,-5,-3:17.12
-1,-5,-3:17.12
1,-5,-3:17.12
2,-5,-3:17.12
3,-5,-3:17.12
4,-5,-3:17.12
6,-5,-3:17.12
-3,-4,-3:17.12
2,-4,-3:17.12
3,-4,-3:17.12
4,-4,-3:17.12
6,-4,-3:17.12
6,-3,-3:17.12
7,-3,-3:17.12
-7,-2,-3:17.12
-5,-2,-3:17.12
-7,-1,-3:17.12
-6,-1,-3:17.12
-5,-1,-3:17.12
3,-1,-3:17.12
4,-1,-3:17.12
-7,0,-3:17.12
-6,0,-3:17.12
-5,0,-3:17.12
-4,0,-3:17.12
3,0,-3:17.12
4,0,-3:17.12
5,0,-3:17.12
-6,1,-3:17.12
-5,1,-3:17.12
-4,1,-3:17.12
-3,1,-3:17.12
4,1,-3:17.12
5,1,-3:17.12
6,1,-3:17.12
-7,2,-3:17.12
-6,2,-3:17.12
-5,2,-3:17.12
-4,2,-3:17.12
4,2,-3:17.12
-7,3,-3:17.12
-6,3,-3:17.12
-5,3,-3:17.12
-2,3,-3:17.12
-7,4,-3:17.12
-6,4,-3:17.12
-4,4,-3:17.12
-3,4,-3:17.12
-2,4,-3:17.12
2,4,-3:17.12
-4,5,-3:17.12
-3,5,-3:17.12
-2,5,-3:17.12
0,5,-3:17.12
1,5,-3:17.12
2,5,-3:17.12
3,5,-3:17.12
2,6,-3:17.12
-2,-8,-2:17.12
-1,-8,-2:17.12
0,-8,-2:17.12
1,-8,-2:17.12
-6,-7,-2:17.12
-5,-7,-2:17.12
-4,-7,-2:17.12
-3,-7,-2:17.12
-2,-7,-2:17.12
-1,-7,-2:17.12
0,-7,-2:17.12
1,-7,-2:17.12
2,-7,-2:17.12
-7,-6,-2:17.12
-6,-6,-2:17.12
-5,-6,-2:17.12
-4,-6,-2:17.12
-3,-6,-2:17.12
-2,-6,-2:17.12
-1,-6,-2:17.12
0,-6,-2:17.12
1,-6,-2:17.12
2,-6,-2:17.12
3,-6,-2:17.12
4,-6,-2:17.12
-8,-5,-2:17.12
-7,-5,-2:17.12
-6,-5,-2:17.12
-5,-5,-2:17.12
-4,-5,-2:17.12
-3,-5,-2:17.12
-2,-5,-2:17.12
-1,-5,-2:17.12
0,-5,-2:17.12
1,-5,-2:17.12
2,-5,-2:17.12
3,-5,-2:17.12
4,-5,-2:17.12
5,-5,-2:17.12
6,-5,-2:17.12
-8,-4,-2:17.12
-7,-4,-2:17.12
-6,-4,-2:17.12
-5,-4,-2:17.12
-4,-4,-2:17.12
-3,-4,-2:17.12
-2,-4,-2:17.12
-1,-4,-2:17.12
0,-4,-2:17.12
1,-4,-2:17.12
2,-4,-2:17.12
3,-4,-2:17.12
4,-4,-2:17.12
5,-4,-2:17.12
6,-4,-2:17.12
7,-4,-2:17.12
-7,-3,-2:17.12
-6,-3,-2:17.12
-5,-3,-2:17.12
-4,-3,-2:17.12
-3,-3,-2:17.12
-2,-3,-2:17.12
-1,-3,-2:17.12
0,-3,-2:17.12
1,-3,-2:17.12
2,-3,-2:17.12
3,-3,-2:17.12
4,-3,-2:17.12
5,-3,-2:17.12
6,-3,-2:17.12
-7,-2,-2:17.12
-6,-2,-2:17.12
-5,-2,-2:17.12
-4,-2,-2:17.12
-3,-2,-2:17.12
-2,-2,-2:17.12
-1,-2,-2:17.12
0,-2,-2:17.12
1,-2,-2:17.12
2,-2,-2:17.12
3,-2,-2:17.12
4,-2,-2:17.12
5,-2,-2:17.12
6,-2,-2:17.12
-7,-1,-2:17.12
-6,-1,-2:17.12
-5,-1,-2:17.12
-4,-1,-2:17.12
-3,-1,-2:17.12
-2,-1,-2:17.12
-1,-1,-2:17.12
0,-1,-2:17.12
1,-1,-2:17.12
2,-1,-2:17.12
3,-1,-2:17.12
4,-1,-2:17.12
5,-1,-2:17.12
6,-1,-2:17.12
-7,0,-2:17.12
-6,0,-2:17.12
-5,0,-2:17.12
-4,0,-2:17.12
-3,0,-2:17.12
-2,0,-2:17.12
-1,0,-2:17.12
0,0,-2:17.12
1,0,-2:17.12
2,0,-2:17.12
3,0,-2:17.12
4,0,-2:17.12
5,0,-2:17.12
6,0,-2:17.12
-7,1,-2:17.12
-6,1,-2:17.12
-5,1,-2:17.12
-4,1,-2:17.12
-3,1,-2:17.12
-2,1,-2:17.12
-1,1,-2:17.12
0,1,-2:17.12
1,1,-2:17.12
2,1,-2:17.12
3,1,-2:17.12
4,1,-2:17.12
5,1,-2:17.12
6,1,-2:17.12
-7,2,-2:17.12
-6,2,-2:17.12
-5,2,-2:17.12
-4,2,-2:17.12
-3,2,-2:17.12
-2,2,-2:17.12
-1,2,-2:17.12
0,2,-2:17.12
1,2,-2:17.12
2,2,-2:17.12
3,2,-2:17.12
4,2,-2:17.12
5,2,-2:17.12
6,2,-2:17.12
-7,3,-2:17.12
-6,3,-2:17.12
-5,3,-2:17.12
-4,3,-2:17.12
-3,3,-2:17.12
-2,3,-2:17.12
-1,3,-2:17.12
0,3,-2:17.12
1,3,-2:17.12
2,3,-2:17.12
3,3,-2:17.12
4,3,-2:17.12
5,3,-2:17.12
6,3,-2:17.12
-6,4,-2:17.12
-5,4,-2:17.12
-4,4,-2:17.12
-3,4,-2:17.12
-2,4,-2:17.12
-1,4,-2:17.12
0,4,-2:17.12
1,4,-2:17.12
2,4,-2:17.12
3,4,-2:17.12
4,4,-2:17.12
5,4,-2:17.12
-5,5,-2:17.12
-4,5,-2:17.12
-3,5,-2:17.12
-2,5,-2:17.12
-1,5,-2:17.12
0,5,-2:17.12
1,5,-2:17.12
2,5,-2:17.12
3,5,-2:17.12
4,5,-2:17.12
-3,6,-2:17.12
-2,6,-2:17.12
-1,6,-2:17.12
0,6,-2:17.12
1,6,-2:17.12
2,6,-2:17.12
3,6,-2:17.12
-1,7,-2:17.12
0,7,-2:17.12
-1,-8,-1:17.12
0,-8,-1:17.12
-3,-7,-1:17.12
-2,-7,-1:17.12
-1,-7,-1:17.12
0,-7,-1:17.12
1,-7,-1:17.12
2,-7,-1:17.12
-7,-6,-1:17.12
-6,-6,-1:17.12
-5,-6,-1:17.12
-4,-6,-1:17.12
2,-6,-1:17.12
3,-6,-1:17.12
-7,-5,-1:17.12
-6,-5,-1:17.12
-4,-5,-1:17.12
-3,-5,-1:17.12
-2,-5,-1:17.12
3,-5,-1:17.12
4,-5,-1:17.12
5,-5,-1:17.12
-7,-4,-1:17.12
-3,-4,-1:17.12
2,-4,-1:17.12
3,-4,-1:17.12
4,-4,-1:17.12
5,-4,-1:17.12
6,-4,-1:17.12
-7,-3,-1:17.12
3,-3,-1:17.12
5,-3,-1:17.12
6,-3,-1:17.12
-7,-2,-1:17.12
5,-2,-1:17.12
6,-2,-1:17.12
-7,-1,-1:17.12
-5,-1,-1:17.12
5,-1,-1:17.12
6,-1,-1:17.12
-7,0,-1:17.12
-5,0,-1:17.12
5,0,-1:17.12
6,0,-1:17.12
-7,1,-1:17.12
-6,1,-1:17.12
-5,1,-1:17.12
5,1,-1:17.12
6,1,-1:17.12
-7,2,-1:17.12
-6,2,-1:17.12
5,2,-1:17.12
6,2,-1:17.12
-7,3,-1:17.12
-6,3,-1:17.12
4,3,-1:17.12
5,3,-1:17.12
-6,4,-1:17.12
-5,4,-1:17.12
-4,4,-1:17.12
-2,4,-1:17.12
2,4,-1:17.12
3,4,-1:17.12
4,4,-1:17.12
-4,5,-1:17.12
-3,5,-1:17.12
-2,5,-1:17.12
1,5,-1:17.12
2,5,-1:17.12
-2,6,-1:17.12
-1,6,-1:17.12
0,6,-1:17.12
1,6,-1:17.12
2,6,-1:17.12
-1,7,-1:17.12
0,7,-1:17.12
-2,-7,0:17.12
-1,-7,0:17.12
0,-7,0:17.12
1,-7,0:17.12
-4,-6,0:17.12
-3,-6,0:17.12
-2,-6,0:17.12
0,-6,0:17.12
1,-6,0:17.12
2,-6,0:17.12
-6,-5,0:17.12
-5,-5,0:17.12
-4,-5,0:17.12
3,-5,0:17.12
4,-5,0:17.12
-7,-4,0:17.12
-6,-4,0:17.12
5,-4,0:17.12
-7,-3,0:17.12
5,-3,0:17.12
-7,-2,0:17.12
-6,-2,0:17.12
5,-2,0:17.12
-7,-1,0:17.12
-6,-1,0:17.12
5,-1,0:17.12
-7,0,0:17.12
-6,0,0:17.12
5,0,0:17.12
-6,1,0:17.12
5,1,0:17.12
-6,2,0:17.12
4,2,0:17.12
5,2,0:17.12
-6,3,0:17.12
-5,3,0:17.12
3,3,0:17.12
4,3,0:17.12
-4,4,0:17.12
-3,4,0:17.12
2,4,0:17.12
3,4,0:17.12
-3,5,0:17.12
-2,5,0:17.12
-1,5,0:17.12
0,5,0:17.12
1,5,0:17.12
-1,6,0:17.12
0,6,0:17.12
1,6,0:17.12
-1,-7,1:17.12
-3,-6,1:17.12
-2,-6,1:17.12
-1,-6,1:17.12
0,-6,1:17.12
1,-6,1:17.12
-5,-5,1:17.12
-4,-5,1:17.12
-3,-5,1:17.12
1,-5,1:17.12
2,-5,1:17.12
3,-5,1:17.12
-6,-4,1:17.12
-5,-4,1:17.12
4,-4,1:17.12
-6,-3,1:17.12
4,-3,1:17.12
-6,-2,1:17.12
4,-2,1:17.12
-6,-1,1:17.12
4,-1,1:17.12
-6,0,1:17.12
4,0,1:17.12
-6,1,1:17.12
-5,1,1:17.12
4,1,1:17.12
-6,2,1:17.12
-5,2,1:17.12
3,2,1:17.12
4,2,1:17.12
-5,3,1:17.12
-4,3,1:17.12
2,3,1:17.12
3,3,1:17.12
-3,4,1:17.12
-2,4,1:17.12
1,4,1:17.12
2,4,1:17.12
-2,5,1:17.12
-1,5,1:17.12
0,5,1:17.12
1,5,1:17.12
-2,-6,2:17.12
-1,-6,2:17.12
0,-6,2:17.12
-3,-5,2:17.12
-2,-5,2:17.12
0,-5,2:17.12
1,-5,2:17.12
2,-5,2:17.12
-5,-4,2:17.12
-4,-4,2:17.12
3,-4,2:17.12
4,-4,2:17.12
-6,-3,2:17.12
-5,-3,2:17.12
4,-3,2:17.12
-6,-2,2:17.12
4,-2,2:17.12
-6,-1,2:17.12
-5,-1,2:17.12
4,-1,2:17.12
-5,0,2:17.12
4,0,2:17.12
-5,1,2:17.12
4,1,2:17.12
-5,2,2:17.12
3,2,2:17.12
4,2,2:17.12
-4,3,2:17.12
-3,3,2:17.12
1,3,2:17.12
2,3,2:17.12
-2,4,2:17.12
-1,4,2:17.12
0,4,2:17.12
1,4,2:17.12
-1,5,2:17.12
0,5,2:17.12
-2,-6,3:17.12
-1,-6,3:17.12
-3,-5,3:17.12
-2,-5,3:17.12
0,-5,3:17.12
1,-5,3:17.12
2,-5,3:17.12
-5,-4,3:17.12
-4,-4,3:17.12
-3,-4,3:17.12
2,-4,3:17.12
3,-4,3:17.12
-5,-3,3:17.12
4,-3,3:17.12
-6,-2,3:17.12
-5,-2,3:17.12
4,-2,3:17.12
-5,-1,3:17.12
4,-1,3:17.12
-5,0,3:17.12
4,0,3:17.12
-5,1,3:17.12
4,1,3:17.12
-5,2,3:17.12
3,2,3:17.12
4,2,3:17.12
-4,3,3:17.12
-3,3,3:17.12
1,3,3:17.12
2,3,3:17.12
-2,4,3:17.12
-1,4,3:17.12
0,4,3:17.12
1,4,3:17.12
-3,-5,4:17.12
-2,-5,4:17.12
-1,-5,4:17.12
0,-5,4:17.12
1,-5,4:17.12
-4,-4,4:17.12
-3,-4,4:17.12
2,-4,4:17.12
3,-4,4:17.12
-5,-3,4:17.12
3,-3,4:17.12
4,-3,4:17.12
-5,-2,4:17.12
4,-2,4:17.12
-5,-1,4:17.12
4,-1,4:17.12
-5,0,4:17.12
4,0,4:17.12
-5,1,4:17.12
4,1,4:17.12
-5,2,4:17.12
-4,2,4:17.12
3,2,4:17.12
-4,3,4:17.12
-3,3,4:17.12
-2,3,4:17.12
1,3,4:17.12
2,3,4:17.12
-2,4,4:17.12
-1,4,4:17.12
0,4,4:17.12
1,4,4:17.12
-2,-5,5:17.12
-1,-5,5:17.12
0,-5,5:17.12
1,-5,5:17.12
-4,-4,5:17.12
-3,-4,5:17.12
2,-4,5:17.12
3,-4,5:17.12
-5,-3,5:17.12
-4,-3,5:17.12
3,-3,5:17.12
-5,-2,5:17.12
4,-2,5:17.12
-5,-1,5:17.12
4,-1,5:17.12
-5,0,5:17.12
4,0,5:17.12
-5,1,5:17.12
-4,1,5:17.12
3,1,5:17.12
4,1,5:17.12
-4,2,5:17.12
3,2,5:17.12
-4,3,5:17.12
-3,3,5:17.12
-2,3,5:17.12
1,3,5:17.12
2,3,5:17.12
-1,4,5:17.12
0,4,5:17.12
1,4,5:17.12
-2,-5,6:17.12
-1,-5,6:17.12
0,-5,6:17.12
1,-5,6:17.12
-4,-4,6:17.12
-3,-4,6:17.12
2,-4,6:17.12
3,-4,6:17.12
-4,-3,6:17.12
3,-3,6:17.12
-5,-2,6:17.12
-4,-2,6:17.12
3,-2,6:17.12
4,-2,6:17.12
-5,-1,6:17.12
4,-1,6:17.12
-5,0,6:17.12
4,0,6:17.12
-4,1,6:17.12
3,1,6:17.12
4,1,6:17.12
-4,2,6:17.12
2,2,6:17.12
3,2,6:17.12
-3,3,6:17.12
-2,3,6:17.12
-1,3,6:17.12
0,3,6:17.12
1,3,6:17.12
2,3,6:17.12
-1,4,6:17.12
0,4,6:17.12
1,4,6:17.12
-2,-5,7:17.12
-1,-5,7:17.12
0,-5,7:17.12
1,-5,7:17.12
-3,-4,7:17.12
-2,-4,7:17.12
-1,-4,7:17.12
0,-4,7:17.12
1,-4,7:17.12
2,-4,7:17.12
-4,-3,7:17.12
-3,-3,7:17.12
3,-3,7:17.12
-4,-2,7:17.12
3,-2,7:17.12
4,-2,7:17.12
-5,-1,7:17.12
-4,-1,7:17.12
4,-1,7:17.12
-4,0,7:17.12
4,0,7:17.12
-4,1,7:17.12
3,1,7:17.12
-4,2,7:17.12
-3,2,7:17.12
2,2,7:17.12
3,2,7:17.12
-3,3,7:17.12
-2,3,7:17.12
-1,3,7:17.12
0,3,7:17.12
1,3,7:17.12
2,3,7:17.12
-3,-4,8:17.12
-2,-4,8:17.12
-1,-4,8:17.12
0,-4,8:17.12
1,-4,8:17.12
2,-4,8:17.12
-3,-3,8:17.12
2,-3,8:17.12
3,-3,8:17.12
-4,-2,8:17.12
3,-2,8:17.12
-4,-1,8:17.12
4,-1,8:17.12
-4,0,8:17.12
3,0,8:17.12
4,0,8:17.12
-4,1,8:17.12
-3,1,8:17.12
3,1,8:17.12
-3,2,8:17.12
2,2,8:17.12
3,2,8:17.12
-2,3,8:17.12
-1,3,8:17.12
0,3,8:17.12
1,3,8:17.12
2,3,8:17.12
-2,-4,9:17.12
-1,-4,9:17.12
0,-4,9:17.12
1,-4,9:17.12
2,-4,9:17.12
-3,-3,9:17.12
-2,-3,9:17.12
-1,-3,9:17.12
0,-3,9:17.12
1,-3,9:17.12
2,-3,9:17.12
3,-3,9:17.12
-4,-2,9:17.12
-3,-2,9:17.12
-2,-2,9:17.12
-1,-2,9:17.12
0,-2,9:17.12
1,-2,9:17.12
2,-2,9:17.12
3,-2,9:17.12
-4,-1,9:17.12
-3,-1,9:17.12
-2,-1,9:17.12
-1,-1,9:17.12
0,-1,9:17.12
1,-1,9:17.12
2,-1,9:17.12
3,-1,9:17.12
4,-1,9:17.12
-4,0,9:17.12
-3,0,9:17.12
-2,0,9:17.12
-1,0,9:17.12
0,0,9:17.12
1,0,9:17.12
2,0,9:17.12
3,0,9:17.12
4,0,9:17.12
-3,1,9:17.12
-2,1,9:17.12
-1,1,9:17.12
0,1,9:17.12
1,1,9:17.12
2,1,9:17.12
3,1,9:17.12
-3,2,9:17.12
-2,2,9:17.12
-1,2,9:17.12
0,2,9:17.12
1,2,9:17.12
2,2,9:17.12
-2,3,9:17.12
-1,3,9:17.12
0,3,9:17.12
1,3,9:17.12
2,3,9:17.12
1,-5,10:17.12
2,-5,10:17.12
-2,-4,10:17.12
-1,-4,10:17.12
0,-4,10:17.12
1,-4,10:17.12
2,-4,10:17.12
-3,-3,10:17.12
-2,-3,10:17.12
2,-3,10:17.12
-3,-2,10:17.12
3,-2,10:17.12
4,-2,10:17.12
-4,-1,10:17.12
3,-1,10:17.12
4,-1,10:17.12
-4,0,10:17.12
-3,0,10:17.12
3,0,10:17.12
-3,1,10:17.12
-2,1,10:17.12
2,1,10:17.12
3,1,10:17.12
-2,2,10:17.12
-1,2,10:17.12
0,2,10:17.12
1,2,10:17.12
2,2,10:17.12
-2,3,10:17.12
-1,3,10:17.12
-3,-5,11:17.12
-2,-5,11:17.12
-1,-5,11:17.12
0,-5,11:17.12
1,-5,11:17.12
2,-5,11:17.12
-3,-4,11:17.12
-2,-4,11:17.12
-1,-4,11:17.12
2,-4,11:17.12
-3,-3,11:17.12
-2,-3,11:17.12
2,-3,11:17.12
3,-3,11:17.12
4,-3,11:17.12
-3,-2,11:17.12
3,-2,11:17.12
4,-2,11:17.12
-4,-1,11:17.12
-3,-1,11:17.12
3,-1,11:17.12
-3,0,11:17.12
3,0,11:17.12
-3,1,11:17.12
-2,1,11:17.12
0,1,11:17.12
1,1,11:17.12
2,1,11:17.12
-2,2,11:17.12
-1,2,11:17.12
0,2,11:17.12
1,2,11:17.12
2,2,11:17.12
1,-6,12:17.12
-3,-5,12:17.12
-2,-5,12:17.12
-1,-5,12:17.12
0,-5,12:17.12
1,-5,12:17.12
-3,-4,12:17.12
-2,-4,12:17.12
2,-4,12:17.12
4,-4,12:17.12
-2,-3,12:17.12
2,-3,12:17.12
3,-3,12:17.12
4,-3,12:17.12
-4,-2,12:17.12
-3,-2,12:17.12
3,-2,12:17.12
4,-2,12:17.12
-4,-1,12:17.12
-3,-1,12:17.12
3,-1,12:17.12
-3,0,12:17.12
-2,0,12:17.12
2,0,12:17.12
3,0,12:17.12
-2,1,12:17.12
-1,1,12:17.12
0,1,12:17.12
1,1,12:17.12
2,1,12:17.12
3,1,12:17.12
-1,2,12:17.12
-3,-19,13:18.6
-8,-18,13:18.6
-3,-18,13:18.6
-7,-17,13:18.6
-6,-17,13:18.14
-3,-17,13:18.14
-7,-16,13:18.6
-6,-16,13:18.14
-4,-16,13:18.14
-3,-16,13:18.14
-6,-15,13:18.14
-5,-15,13:18.14
-3,-15,13:18.14
-5,-14,13:18.14
-4,-14,13:18.14
17,-11,13:18.6
15,-9,13:18.6
13,-8,13:18.14
14,-8,13:18.6
15,-8,13:18.6
1,-7,13:17.12
12,-7,13:18.14
13,-7,13:18.14
0,-6,13:17.12
1,-6,13:17.12
11,-6,13:18.14
12,-6,13:18.14
13,-6,13:18.14
-4,-5,13:17.12
-3,-5,13:17.12
-2,-5,13:17.12
-1,-5,13:17.12
0,-5,13:17.12
1,-5,13:17.12
4,-5,13:17.12
-3,-4,13:17.12
-2,-4,13:17.12
1,-4,13:17.12
2,-4,13:17.12
3,-4,13:17.12
4,-4,13:17.12
11,-4,13:18.14
12,-4,13:18.14
13,-4,13:18.14
14,-4,13:18.6
15,-4,13:18.6
16,-4,13:18.6
17,-4,13:18.6
-2,-3,13:17.12
3,-3,13:17.12
4,-3,13:17.12
-4,-2,13:17.12
-3,-2,13:17.12
3,-2,13:17.12
-4,-1,13:17.12
-3,-1,13:17.12
-2,-1,13:17.12
3,-1,13:17.12
-19,0,13:18.6
-18,0,13:18.6
-17,0,13:18.6
-16,0,13:18.6
-2,0,13:17.12
0,0,13:17.12
1,0,13:17.12
2,0,13:17.12
3,0,13:17.12
-17,1,13:18.6
-16,1,13:18.6
-15,1,13:18.6
-14,1,13:18.14
-13,1,13:18.14
-2,1,13:17.12
-1,1,13:17.12
0,1,13:17.12
2,1,13:17.12
3,1,13:17.12
-15,2,13:18.6
-14,2,13:18.14
-13,2,13:18.14
-1,2,13:17.12
0,2,13:17.12
-15,3,13:18.6
-14,3,13:18.14
-16,4,13:18.6
-15,4,13:18.6
-17,5,13:18.6
-16,5,13:18.6
-19,7,13:18.6
-18,7,13:18.6
-20,8,13:18.6
3,10,13:18.14
1,11,13:18.14
2,11,13:18.14
3,11,13:18.14
4,11,13:18.14
1,12,13:18.14
2,12,13:18.14
4,12,13:18.14
5,12,13:18.14
1,13,13:18.6
5,13,13:18.6
1,14,13:18.6
6,14,13:18.6
1,15,13:18.6
7,15,13:18.6
0,18,13:18.6
0,19,13:18.6
0,20,13:18.6
-1,-24,14:18.6
-2,-23,14:18.6
-1,-23,14:18.6
-2,-22,14:18.6
-1,-22,14:18.6
-2,-21,14:18.6
-1,-21,14:18.6
-11,-20,14:18.6
-1,-20,14:18.6
-11,-19,14:18.6
-10,-19,14:18.6
-2,-19,14:18.6
-1,-19,14:18.6
-11,-18,14:18.6
-10,-18,14:18.6
-9,-18,14:18.6
-2,-18,14:18.14
-1,-18,14:18.14
-10,-17,14:18.6
-9,-17,14:18.6
-8,-17,14:18.6
-2,-17,14:18.14
-1,-17,14:18.14
-9,-16,14:18.6
-8,-16,14:18.6
-7,-16,14:18.14
-3,-16,14:18.14
-2,-16,14:18.14
-1,-16,14:18.14
-8,-15,14:18.6
-7,-15,14:18.14
-6,-15,14:18.14
-3,-15,14:18.14
-2,-15,14:18.14
-7,-14,14:18.14
-6,-14,14:18.14
-5,-14,14:18.14
-2,-14,14:18.14
18,-14,14:18.6
-6,-13,14:18.14
-5,-13,14:18.14
-6,-12,14:18.14
-5,-12,14:18.14
-4,-12,14:18.14
-2,-12,14:18.14
15,-12,14:18.6
16,-12,14:18.6
17,-12,14:18.6
18,-12,14:18.6
-5,-11,14:18.14
-4,-11,14:18.14
-3,-11,14:18.14
-2,-11,14:18.14
14,-11,14:18.14
15,-11,14:18.14
16,-11,14:18.6
17,-11,14:18.6
-3,-10,14:18.14
-2,-10,14:18.14
13,-10,14:18.14
14,-10,14:18.14
15,-10,14:18.14
16,-10,14:18.6
-3,-9,14:18.14
12,-9,14:18.14
13,-9,14:18.14
14,-9,14:18.14
0,-8,14:17.12
1,-8,14:17.12
11,-8,14:18.14
12,-8,14:18.14
13,-8,14:18.14
0,-7,14:17.12
1,-7,14:17.12
9,-7,14:18.14
10,-7,14:18.14
12,-7,14:18.14
-6,-6,14:17.12
-5,-6,14:17.12
-4,-6,14:17.12
-3,-6,14:17.12
-1,-6,14:17.12
0,-6,14:17.12
1,-6,14:17.12
8,-6,14:18.14
11,-6,14:18.14
-5,-5,14:17.12
-4,-5,14:17.12
-3,-5,14:17.12
-2,-5,14:17.12
-1,-5,14:17.12
0,-5,14:17.12
1,-5,14:17.12
2,-5,14:17.12
3,-5,14:17.12
4,-5,14:17.12
5,-5,14:17.12
7,-5,14:18.14
8,-5,14:18.14
-4,-4,14:17.12
-3,-4,14:17.12
0,-4,14:17.12
1,-4,14:17.12
2,-4,14:17.12
4,-4,14:17.12
6,-4,14:18.14
7,-4,14:18.14
8,-4,14:18.14
9,-4,14:18.14
10,-4,14:18.14
11,-4,14:18.14
12,-4,14:18.14
13,-4,14:18.14
-2,-3,14:17.12
2,-3,14:17.12
3,-3,14:17.12
7,-3,14:18.14
8,-3,14:18.14
9,-3,14:18.14
10,-3,14:18.14
11,-3,14:18.14
12,-3,14:18.14
14,-3,14:18.14
15,-3,14:18.14
16,-3,14:18.6
17,-3,14:18.6
18,-3,14:18.6
19,-3,14:18.6
-5,-2,14:17.12
-4,-2,14:17.12
-3,-2,14:17.12
3,-2,14:17.12
14,-2,14:18.14
15,-2,14:18.6
16,-2,14:18.6
17,-2,14:18.6
18,-2,14:18.6
19,-2,14:18.6
20,-2,14:18.6
-22,-1,14:18.6
-21,-1,14:18.6
-20,-1,14:18.6
-19,-1,14:18.6
-18,-1,14:18.6
-17,-1,14:18.6
-16,-1,14:18.14
-15,-1,14:18.14
-14,-1,14:18.14
-13,-1,14:18.14
-12,-1,14:18.14
-11,-1,14:18.14
-10,-1,14:18.14
-6,-1,14:17.12
-5,-1,14:17.12
-4,-1,14:17.12
-3,-1,14:17.12
-2,-1,14:17.12
1,-1,14:17.12
3,-1,14:17.12
4,-1,14:17.12
-20,0,14:18.6
-19,0,14:18.6
-18,0,14:18.6
-17,0,14:18.6
-16,0,14:18.14
-15,0,14:18.14
-14,0,14:18.14
-13,0,14:18.14
-12,0,14:18.14
-11,0,14:18.14
-10,0,14:18.14
-9,0,14:18.14
-8,0,14:18.14
-2,0,14:17.12
-1,0,14:17.12
1,0,14:17.12
2,0,14:17.12
3,0,14:17.12
4,0,14:17.12
-10,1,14:18.14
-9,1,14:18.14
-1,1,14:17.12
0,1,14:17.12
1,1,14:17.12
4,1,14:17.12
5,1,14:17.12
-10,2,14:18.14
0,2,14:17.12
-14,3,14:18.14
-13,3,14:18.14
-12,3,14:18.14
-11,3,14:18.14
-15,4,14:18.14
-14,4,14:18.14
-13,4,14:18.14
-12,4,14:18.14
-16,5,14:18.14
-15,5,14:18.14
-14,5,14:18.14
-13,5,14:18.14
1,5,14:18.14
-16,6,14:18.14
-15,6,14:18.14
-14,6,14:18.14
1,6,14:18.14
2,6,14:18.14
-18,7,14:18.6
-17,7,14:18.6
-16,7,14:18.6
-15,7,14:18.6
0,7,14:18.14
1,7,14:18.14
2,7,14:18.14
3,7,14:18.14
-19,8,14:18.6
-18,8,14:18.6
-17,8,14:18.6
0,8,14:18.14
1,8,14:18.14
2,8,14:18.14
3,8,14:18.14
4,8,14:18.14
-20,9,14:18.6
-19,9,14:18.6
-18,9,14:18.6
0,9,14:18.14
3,9,14:18.14
4,9,14:18.14
5,9,14:18.14
0,10,14:18.14
3,10,14:18.14
4,10,14:18.14
5,10,14:18.14
-20,11,14:18.6
0,11,14:18.14
1,11,14:18.14
4,11,14:18.14
5,11,14:18.14
6,11,14:18.14
0,12,14:18.14
1,12,14:18.14
5,12,14:18.14
6,12,14:18.14
7,12,14:18.14
-1,13,14:18.14
0,13,14:18.14
1,13,14:18.14
6,13,14:18.14
7,13,14:18.14
8,13,14:18.6
-1,14,14:18.6
0,14,14:18.6
7,14,14:18.6
8,14,14:18.6
-1,15,14:18.6
0,15,14:18.6
7,15,14:18.6
8,15,14:18.6
9,15,14:18.6
-1,16,14:18.6
0,16,14:18.6
8,16,14:18.6
9,16,14:18.6
10,16,14:18.6
-1,17,14:18.6
0,17,14:18.6
-1,18,14:18.6
0,18,14:18.6
-1,19,14:18.6
0,19,14:18.6
-1,20,14:18.6
-2,21,14:18.6
0,-25,15:18.6
0,-24,15:18.6
1,-24,15:18.6
0,-23,15:18.6
1,-23,15:18.6
0,-22,15:18.6
1,-22,15:18.6
0,-21,15:18.6
1,-21,15:18.6
0,-20,15:18.6
1,-20,15:18.6
0,-19,15:18.14
1,-19,15:18.14
-13,-18,15:18.6
-12,-18,15:18.6
-11,-18,15:18.6
-1,-18,15:18.14
0,-18,15:18.14
1,-18,15:18.14
-12,-17,15:18.6
-11,-17,15:18.6
-10,-17,15:18.6
-1,-17,15:18.14
0,-17,15:18.14
-11,-16,15:18.6
-10,-16,15:18.6
-1,-16,15:18.14
0,-16,15:18.14
-11,-15,15:18.6
-10,-15,15:18.6
-9,-15,15:18.6
-8,-15,15:18.14
-1,-15,15:18.14
0,-15,15:18.14
16,-15,15:18.6
17,-15,15:18.6
-10,-14,15:18.6
-9,-14,15:18.6
-8,-14,15:18.14
-1,-14,15:18.14
0,-14,15:18.14
15,-14,15:18.6
16,-14,15:18.6
17,-14,15:18.6
18,-14,15:18.6
-9,-13,15:18.6
-8,-13,15:18.14
-7,-13,15:18.14
-1,-13,15:18.14
0,-13,15:18.14
14,-13,15:18.6
15,-13,15:18.6
16,-13,15:18.6
-8,-12,15:18.14
-7,-12,15:18.14
-6,-12,15:18.14
-1,-12,15:18.14
0,-12,15:18.14
13,-12,15:18.6
14,-12,15:18.6
15,-12,15:18.6
-7,-11,15:18.14
-6,-11,15:18.14
-5,-11,15:18.14
-2,-11,15:18.14
-1,-11,15:18.14
0,-11,15:18.14
11,-11,15:18.14
12,-11,15:18.14
13,-11,15:18.14
14,-11,15:18.14
-6,-10,15:18.14
-5,-10,15:18.14
-2,-10,15:18.14
-1,-10,15:18.14
0,-10,15:17.12
10,-10,15:18.14
11,-10,15:18.14
12,-10,15:18.14
13,-10,15:18.14
-5,-9,15:18.14
-4,-9,15:18.14
-3,-9,15:18.14
-1,-9,15:18.14
0,-9,15:17.12
9,-9,15:18.14
10,-9,15:18.14
11,-9,15:18.14
12,-9,15:18.14
-5,-8,15:18.14
-4,-8,15:18.14
-3,-8,15:18.14
-2,-8,15:18.14
-1,-8,15:17.12
0,-8,15:17.12
1,-8,15:17.12
8,-8,15:18.14
9,-8,15:18.14
10,-8,15:18.14
-8,-7,15:17.12
-4,-7,15:18.14
-3,-7,15:18.14
-2,-7,15:18.14
-1,-7,15:17.12
0,-7,15:17.12
1,-7,15:17.12
6,-7,15:18.14
7,-7,15:18.14
8,-7,15:18.14
9,-7,15:18.14
-8,-6,15:17.12
-7,-6,15:17.12
-6,-6,15:17.12
-5,-6,15:17.12
-4,-6,15:17.12
-3,-6,15:17.12
-2,-6,15:18.14
-1,-6,15:17.12
0,-6,15:17.12
1,-6,15:17.12
5,-6,15:18.14
6,-6,15:18.14
7,-6,15:18.14
8,-6,15:18.14
-6,-5,15:17.12
-5,-5,15:17.12
-4,-5,15:17.12
-3,-5,15:17.12
-2,-5,15:17.12
0,-5,15:17.12
1,-5,15:17.12
2,-5,15:17.12
3,-5,15:17.12
4,-5,15:17.12
5,-5,15:17.12
6,-5,15:18.14
7,-5,15:18.14
-5,-4,15:17.12
-4,-4,15:17.12
-3,-4,15:17.12
-2,-4,15:17.12
-1,-4,15:17.12
0,-4,15:17.12
2,-4,15:17.12
3,-4,15:17.12
4,-4,15:17.12
5,-4,15:17.12
-22,-3,15:18.6
-21,-3,15:18.6
-20,-3,15:18.6
-19,-3,15:18.6
-3,-3,15:17.12
-2,-3,15:17.12
-1,-3,15:17.12
0,-3,15:17.12
1,-3,15:17.12
2,-3,15:17.12
3,-3,15:17.12
4,-3,15:17.12
5,-3,15:18.14
6,-3,15:18.14
7,-3,15:18.14
8,-3,15:18.14
9,-3,15:18.14
-22,-2,15:18.6
-21,-2,15:18.6
-20,-2,15:18.6
-19,-2,15:18.6
-18,-2,15:18.6
-17,-2,15:18.6
-16,-2,15:18.14
-15,-2,15:18.14
-14,-2,15:18.14
-13,-2,15:18.14
-12,-2,15:18.14
-11,-2,15:18.14
-10,-2,15:18.14
-9,-2,15:18.14
-8,-2,15:18.14
-7,-2,15:18.14
-6,-2,15:18.14
-5,-2,15:18.14
-4,-2,15:17.12
-3,-2,15:17.12
-2,-2,15:17.12
-1,-2,15:17.12
0,-2,15:17.12
1,-2,15:17.12
2,-2,15:17.12
3,-2,15:17.12
4,-2,15:17.12
5,-2,15:18.14
6,-2,15:18.14
7,-2,15:18.14
8,-2,15:18.14
9,-2,15:18.14
10,-2,15:18.14
11,-2,15:18.14
12,-2,15:18.14
13,-2,15:18.14
14,-2,15:18.14
15,-2,15:18.14
16,-2,15:18.14
17,-2,15:18.6
-17,-1,15:18.14
-16,-1,15:18.14
-15,-1,15:18.14
-14,-1,15:18.14
-13,-1,15:18.14
-12,-1,15:18.14
-11,-1,15:18.14
-10,-1,15:18.14
-9,-1,15:18.14
-8,-1,15:18.14
-7,-1,15:18.14
-6,-1,15:17.12
-5,-1,15:17.12
-4,-1,15:17.12
-3,-1,15:17.12
-2,-1,15:17.12
-1,-1,15:17.12
0,-1,15:17.12
1,-1,15:17.12
2,-1,15:17.12
3,-1,15:17.12
4,-1,15:17.12
5,-1,15:17.12
10,-1,15:18.14
11,-1,15:18.14
12,-1,15:18.14
13,-1,15:18.14
14,-1,15:18.14
15,-1,15:18.6
16,-1,15:18.6
17,-1,15:18.6
18,-1,15:18.6
19,-1,15:18.6
20,-1,15:18.6
-7,0,15:17.12
-6,0,15:17.12
-5,0,15:17.12
-4,0,15:17.12
-3,0,15:17.12
-2,0,15:17.12
-1,0,15:17.12
0,0,15:17.12
1,0,15:17.12
2,0,15:17.12
3,0,15:17.12
4,0,15:17.12
5,0,15:17.12
6,0,15:17.12
17,0,15:18.6
18,0,15:18.6
19,0,15:18.6
20,0,15:18.6
-8,1,15:18.14
-7,1,15:18.14
-6,1,15:18.14
-1,1,15:17.12
0,1,15:17.12
1,1,15:17.12
4,1,15:17.12
5,1,15:17.12
6,1,15:17.12
-9,2,15:18.14
-8,2,15:18.14
-7,2,15:18.14
0,2,15:17.12
1,2,15:17.12
6,2,15:17.12
7,2,15:17.12
-11,3,15:18.14
-10,3,15:18.14
-9,3,15:18.14
-8,3,15:18.14
-1,3,15:18.14
0,3,15:17.12
1,3,15:17.12
2,3,15:18.14
-11,4,15:18.14
-10,4,15:18.14
-9,4,15:18.14
-1,4,15:18.14
0,4,15:18.14
1,4,15:17.12
2,4,15:18.14
3,4,15:18.14
-13,5,15:18.14
-12,5,15:18.14
-11,5,15:18.14
-10,5,15:18.14
-1,5,15:18.14
0,5,15:18.14
2,5,15:18.14
3,5,15:18.14
4,5,15:18.14
-14,6,15:18.14
-13,6,15:18.14
-12,6,15:18.14
-11,6,15:18.14
-1,6,15:18.14
0,6,15:18.14
3,6,15:18.14
4,6,15:18.14
-15,7,15:18.14
-14,7,15:18.14
-13,7,15:18.14
-12,7,15:18.14
-1,7,15:18.14
0,7,15:18.14
3,7,15:18.14
4,7,15:18.14
5,7,15:18.14
-16,8,15:18.6
-15,8,15:18.6
-14,8,15:18.6
-13,8,15:18.6
-1,8,15:18.14
0,8,15:18.14
4,8,15:18.14
5,8,15:18.14
6,8,15:18.14
-17,9,15:18.6
-16,9,15:18.6
-15,9,15:18.6
-2,9,15:18.14
-1,9,15:18.14
0,9,15:18.14
5,9,15:18.14
6,9,15:18.14
7,9,15:18.14
-18,10,15:18.6
-17,10,15:18.6
-16,10,15:18.6
-2,10,15:18.14
-1,10,15:18.14
6,10,15:18.14
7,10,15:18.14
8,10,15:18.14
-19,11,15:18.6
-18,11,15:18.6
-17,11,15:18.6
-2,11,15:18.14
-1,11,15:18.14
6,11,15:18.14
7,11,15:18.14
8,11,15:18.14
-18,12,15:18.6
-2,12,15:18.14
-1,12,15:18.14
7,12,15:18.14
8,12,15:18.14
9,12,15:18.6
-2,13,15:18.14
-1,13,15:18.14
8,13,15:18.14
9,13,15:18.6
10,13,15:18.6
-2,14,15:18.6
-1,14,15:18.14
9,14,15:18.6
10,14,15:18.6
11,14,15:18.6
-3,15,15:18.6
-2,15,15:18.6
-1,15,15:18.14
10,15,15:18.6
11,15,15:18.6
-3,16,15:18.6
-2,16,15:18.6
-1,16,15:18.6
10,16,15:18.6
-3,17,15:18.6
-2,17,15:18.6
-3,18,15:18.6
-2,18,15:18.6
-3,19,15:18.6
-2,19,15:18.6
-3,20,15:18.6
-2,20,15:18.6
-2,21,15:18.6
3,-26,16:18.6
2,-25,16:18.6
3,-25,16:18.6
2,-24,16:18.6
3,-24,16:18.6
2,-23,16:18.6
3,-23,16:18.6
2,-22,16:18.6
3,-22,16:18.6
1,-21,16:18.6
2,-21,16:18.6
3,-21,16:18.6
1,-20,16:18.6
2,-20,16:18.6
1,-19,16:18.14
2,-19,16:18.6
-15,-18,16:18.6
1,-18,16:18.14
2,-18,16:18.14
-13,-17,16:18.6
1,-17,16:18.14
2,-17,16:18.14
16,-17,16:18.6
17,-17,16:18.6
-14,-16,16:18.6
-13,-16,16:18.6
-12,-16,16:18.6
1,-16,16:18.14
2,-16,16:18.14
15,-16,16:18.6
16,-16,16:18.6
17,-16,16:18.6
-13,-15,16:18.6
-12,-15,16:18.6
-11,-15,16:18.6
1,-15,16:18.14
2,-15,16:18.14
13,-15,16:18.6
14,-15,16:18.6
15,-15,16:18.6
16,-15,16:18.6
-12,-14,16:18.6
-11,-14,16:18.6
-10,-14,16:18.6
0,-14,16:18.14
1,-14,16:18.14
2,-14,16:18.14
12,-14,16:18.6
13,-14,16:18.6
14,-14,16:18.6
15,-14,16:18.6
-11,-13,16:18.14
-10,-13,16:18.14
-9,-13,16:18.14
0,-13,16:18.14
1,-13,16:18.14
11,-13,16:18.6
12,-13,16:18.6
13,-13,16:18.6
14,-13,16:18.6
-10,-12,16:18.14
-9,-12,16:18.14
-8,-12,16:18.14
0,-12,16:18.14
1,-12,16:18.14
10,-12,16:18.6
11,-12,16:18.6
12,-12,16:18.6
-10,-11,16:18.14
-9,-11,16:18.14
-8,-11,16:18.14
-1,-11,16:17.12
0,-11,16:18.14
1,-11,16:18.14
9,-11,16:18.14
10,-11,16:18.14
11,-11,16:18.14
-9,-10,16:18.14
-8,-10,16:18.14
-7,-10,16:18.14
-2,-10,16:17.12
-1,-10,16:17.12
0,-10,16:18.14
1,-10,16:18.14
7,-10,16:18.14
8,-10,16:18.14
9,-10,16:18.14
10,-10,16:18.14
-8,-9,16:18.14
-7,-9,16:18.14
-6,-9,16:18.14
-2,-9,16:17.12
-1,-9,16:17.12
0,-9,16:18.14
1,-9,16:18.14
6,-9,16:18.14
7,-9,16:18.14
8,-9,16:18.14
9,-9,16:18.14
-7,-8,16:18.14
-6,-8,16:18.14
-5,-8,16:18.14
-2,-8,16:17.12
-1,-8,16:17.12
0,-8,16:18.14
1,-8,16:18.14
5,-8,16:18.14
6,-8,16:18.14
7,-8,16:18.14
8,-8,16:18.14
-10,-7,16:17.12
-9,-7,16:17.12
-8,-7,16:17.12
-7,-7,16:17.12
-6,-7,16:18.14
-5,-7,16:18.14
-4,-7,16:18.14
-1,-7,16:17.12
0,-7,16:18.14
1,-7,16:18.14
4,-7,16:18.14
5,-7,16:18.14
6,-7,16:18.14
-24,-6,16:18.14
-9,-6,16:17.12
-8,-6,16:17.12
-7,-6,16:17.12
-6,-6,16:17.12
-5,-6,16:18.14
-4,-6,16:18.14
-3,-6,16:18.14
3,-6,16:18.14
4,-6,16:18.14
5,-6,16:18.14
6,-6,16:17.12
7,-6,16:17.12
8,-6,16:17.12
-7,-5,16:17.12
-6,-5,16:17.12
-5,-5,16:17.12
-4,-5,16:18.14
-3,-5,16:18.14
-2,-5,16:18.14
0,-5,16:18.14
1,-5,16:18.14
3,-5,16:18.14
4,-5,16:17.12
5,-5,16:17.12
6,-5,16:17.12
7,-5,16:17.12
-24,-4,16:18.6
-21,-4,16:18.6
-20,-4,16:18.6
-19,-4,16:18.6
-18,-4,16:18.14
-17,-4,16:18.14
-16,-4,16:18.14
-15,-4,16:18.14
-14,-4,16:18.14
-13,-4,16:18.14
-5,-4,16:17.12
-4,-4,16:18.14
-3,-4,16:18.14
-2,-4,16:18.14
0,-4,16:18.14
1,-4,16:18.14
4,-4,16:17.12
5,-4,16:17.12
6,-4,16:17.12
-21,-3,16:18.6
-20,-3,16:18.6
-19,-3,16:18.6
-18,-3,16:18.6
-17,-3,16:18.14
-16,-3,16:18.14
-15,-3,16:18.14
-14,-3,16:18.14
-13,-3,16:18.14
-12,-3,16:18.14
-11,-3,16:18.14
-10,-3,16:18.14
-9,-3,16:18.14
-8,-3,16:18.14
-7,-3,16:18.14
-6,-3,16:18.14
-5,-3,16:18.14
-4,-3,16:18.14
-3,-3,16:18.14
-2,-3,16:18.14
-12,-2,16:18.14
-11,-2,16:18.14
-10,-2,16:18.14
-9,-2,16:18.14
-8,-2,16:18.14
-7,-2,16:18.14
-6,-2,16:18.14
-5,-2,16:18.14
-4,-2,16:18.14
-3,-2,16:18.14
1,-2,16:18.14
2,-2,16:18.14
3,-2,16:18.14
4,-2,16:18.14
5,-2,16:18.14
6,-2,16:18.14
-6,-1,16:17.12
-5,-1,16:17.12
-4,-1,16:17.12
-3,-1,16:17.12
1,-1,16:18.14
2,-1,16:18.14
3,-1,16:18.14
4,-1,16:18.14
5,-1,16:18.14
6,-1,16:18.14
7,-1,16:18.14
8,-1,16:18.14
9,-1,16:18.14
10,-1,16:18.14
11,-1,16:18.14
12,-1,16:18.14
13,-1,16:18.14
-8,0,16:17.12
-7,0,16:17.12
-6,0,16:17.12
-5,0,16:17.12
-4,0,16:17.12
-3,0,16:17.12
-2,0,16:18.14
0,0,16:18.14
1,0,16:18.14
2,0,16:18.14
4,0,16:17.12
5,0,16:17.12
6,0,16:17.12
7,0,16:17.12
8,0,16:18.14
9,0,16:18.14
10,0,16:18.14
11,0,16:18.14
12,0,16:18.14
13,0,16:18.14
14,0,16:18.14
15,0,16:18.14
16,0,16:18.14
17,0,16:18.6
18,0,16:18.6
19,0,16:18.6
-9,1,16:17.12
-8,1,16:17.12
-7,1,16:17.12
-6,1,16:17.12
-5,1,16:18.14
-4,1,16:18.14
-2,1,16:18.14
-1,1,16:17.12
0,1,16:17.12
1,1,16:18.14
2,1,16:18.14
3,1,16:18.14
4,1,16:17.12
5,1,16:17.12
6,1,16:17.12
7,1,16:17.12
8,1,16:17.12
13,1,16:18.14
14,1,16:18.14
15,1,16:18.14
16,1,16:18.14
17,1,16:18.14
18,1,16:18.6
19,1,16:18.6
-6,2,16:18.14
-5,2,16:18.14
-4,2,16:18.14
0,2,16:17.12
1,2,16:17.12
2,2,16:18.14
3,2,16:18.14
4,2,16:18.14
6,2,16:17.12
7,2,16:17.12
8,2,16:17.12
-8,3,16:18.14
-7,3,16:18.14
-6,3,16:18.14
-5,3,16:18.14
-2,3,16:18.14
-1,3,16:18.14
0,3,16:17.12
1,3,16:17.12
2,3,16:17.12
3,3,16:18.14
4,3,16:18.14
8,3,16:17.12
9,3,16:17.12
-9,4,16:18.14
-8,4,16:18.14
-7,4,16:18.14
-6,4,16:18.14
-2,4,16:18.14
-1,4,16:18.14
0,4,16:17.12
1,4,16:17.12
2,4,16:17.12
3,4,16:18.14
4,4,16:18.14
5,4,16:18.14
-10,5,16:18.14
-9,5,16:18.14
-8,5,16:18.14
-7,5,16:18.14
-3,5,16:18.14
-2,5,16:18.14
-1,5,16:18.14
1,5,16:17.12
2,5,16:17.12
4,5,16:18.14
5,5,16:18.14
6,5,16:18.14
-11,6,16:18.14
-10,6,16:18.14
-9,6,16:18.14
-8,6,16:18.14
-3,6,16:18.14
-2,6,16:18.14
1,6,16:17.12
2,6,16:17.12
5,6,16:18.14
6,6,16:18.14
7,6,16:18.14
-12,7,16:18.14
-11,7,16:18.14
-10,7,16:18.14
-9,7,16:18.14
-3,7,16:18.14
-2,7,16:18.14
6,7,16:18.14
7,7,16:18.14
-13,8,16:18.14
-12,8,16:18.14
-11,8,16:18.14
-10,8,16:18.14
-3,8,16:18.14
-2,8,16:18.14
6,8,16:18.14
7,8,16:18.14
8,8,16:18.14
-14,9,16:18.6
-13,9,16:18.6
-12,9,16:18.6
-3,9,16:18.14
-2,9,16:18.14
7,9,16:18.14
8,9,16:18.14
9,9,16:18.14
-15,10,16:18.6
-14,10,16:18.6
-13,10,16:18.6
-3,10,16:18.14
-2,10,16:18.14
8,10,16:18.14
9,10,16:18.6
10,10,16:18.14
-16,11,16:18.6
-15,11,16:18.6
-14,11,16:18.6
-4,11,16:18.6
-3,11,16:18.14
-2,11,16:18.14
9,11,16:18.6
10,11,16:18.6
11,11,16:18.6
-18,12,16:18.6
-17,12,16:18.6
-16,12,16:18.6
-15,12,16:18.6
-4,12,16:18.6
-3,12,16:18.6
-2,12,16:18.14
9,12,16:18.6
10,12,16:18.6
11,12,16:18.6
-19,13,16:18.6
-18,13,16:18.6
-17,13,16:18.6
-16,13,16:18.6
-4,13,16:18.6
-3,13,16:18.6
10,13,16:18.6
11,13,16:18.6
12,13,16:18.6
-19,14,16:18.6
-18,14,16:18.6
-17,14,16:18.6
-4,14,16:18.6
-3,14,16:18.6
11,14,16:18.6
-4,15,16:18.6
-3,15,16:18.6
14,15,16:18.6
-4,16,16:18.6
-3,16,16:18.6
-4,17,16:18.6
-3,17,16:18.6
-5,18,16:18.6
-4,18,16:18.6
-3,18,16:18.6
-5,19,16:18.6
-4,19,16:18.6
-5,20,16:18.6
-4,20,16:18.6
-5,21,16:18.6
-4,21,16:18.6
-5,22,16:18.6
-4,22,16:18.6
4,-25,17:18.6
3,-24,17:18.6
4,-24,17:18.6
3,-23,17:18.6
4,-23,17:18.6
3,-22,17:18.6
4,-22,17:18.6
3,-21,17:18.6
4,-21,17:18.6
4,-20,17:18.6
3,-19,17:18.6
4,-19,17:18.6
-16,-18,17:18.6
3,-18,17:18.6
4,-18,17:18.6
15,-18,17:18.6
16,-18,17:18.6
-16,-17,17:18.6
-15,-17,17:18.6
2,-17,17:18.14
3,-17,17:18.6
4,-17,17:18.6
13,-17,17:18.6
14,-17,17:18.6
15,-17,17:18.6
16,-17,17:18.6
-16,-16,17:18.6
-15,-16,17:18.6
2,-16,17:18.14
3,-16,17:18.14
4,-16,17:18.6
12,-16,17:18.6
13,-16,17:18.6
14,-16,17:18.6
-15,-15,17:18.6
-14,-15,17:18.6
2,-15,17:18.14
3,-15,17:18.14
11,-15,17:18.6
12,-15,17:18.6
13,-15,17:18.6
-15,-14,17:18.14
-14,-14,17:18.6
-13,-14,17:18.6
-12,-14,17:18.6
2,-14,17:18.14
3,-14,17:18.14
9,-14,17:18.6
11,-14,17:18.6
12,-14,17:18.6
-14,-13,17:18.14
-13,-13,17:18.14
-12,-13,17:18.14
-2,-13,17:17.12
2,-13,17:18.14
3,-13,17:18.14
8,-13,17:18.6
9,-13,17:18.6
10,-13,17:18.6
11,-13,17:18.6
-13,-12,17:18.14
-12,-12,17:18.14
-11,-12,17:18.14
-2,-12,17:17.12
-1,-12,17:17.12
2,-12,17:18.14
3,-12,17:18.14
7,-12,17:18.6
8,-12,17:18.6
9,-12,17:18.14
10,-12,17:18.14
-12,-11,17:18.14
-11,-11,17:18.14
-10,-11,17:18.14
-3,-11,17:17.12
-2,-11,17:17.12
-1,-11,17:17.12
2,-11,17:18.14
3,-11,17:18.14
6,-11,17:18.14
7,-11,17:18.14
8,-11,17:18.14
-11,-10,17:18.14
-10,-10,17:18.14
-9,-10,17:18.14
-3,-10,17:17.12
-2,-10,17:17.12
-1,-10,17:17.12
2,-10,17:18.14
3,-10,17:18.14
5,-10,17:18.14
6,-10,17:18.14
7,-10,17:18.14
-10,-9,17:18.14
-9,-9,17:18.14
-8,-9,17:18.14
-2,-9,17:17.12
-1,-9,17:17.12
1,-9,17:18.14
2,-9,17:18.14
3,-9,17:18.14
4,-9,17:18.14
5,-9,17:18.14
6,-9,17:18.14
-24,-8,17:18.14
-23,-8,17:18.14
-12,-8,17:17.12
-11,-8,17:17.12
-10,-8,17:17.12
-9,-8,17:18.14
-8,-8,17:18.14
-7,-8,17:18.14
1,-8,17:18.14
2,-8,17:18.14
3,-8,17:18.14
4,-8,17:18.14
5,-8,17:18.14
-24,-7,17:18.14
-23,-7,17:18.14
-11,-7,17:17.12
-10,-7,17:17.12
-9,-7,17:17.12
-8,-7,17:18.14
-7,-7,17:18.14
0,-7,17:18.14
1,-7,17:18.14
2,-7,17:18.14
3,-7,17:18.14
4,-7,17:18.14
-22,-6,17:18.14
-10,-6,17:17.12
-9,-6,17:17.12
-8,-6,17:17.12
-7,-6,17:18.14
-6,-6,17:18.14
-2,-6,17:18.14
-1,-6,17:18.14
0,-6,17:18.14
1,-6,17:18.14
2,-6,17:18.14
3,-6,17:18.14
6,-6,17:17.12
7,-6,17:17.12
8,-6,17:17.12
9,-6,17:17.12
-24,-5,17:18.6
-23,-5,17:18.6
-22,-5,17:18.6
-21,-5,17:18.6
-20,-5,17:18.14
-19,-5,17:18.14
-18,-5,17:18.14
-17,-5,17:18.14
-16,-5,17:18.14
-15,-5,17:18.14
-14,-5,17:18.14
-13,-5,17:18.14
-12,-5,17:18.14
-11,-5,17:18.14
-10,-5,17:18.14
-9,-5,17:18.14
-8,-5,17:18.14
-7,-5,17:18.14
-6,-5,17:18.14
-5,-5,17:18.14
-4,-5,17:18.14
-3,-5,17:18.14
-2,-5,17:18.14
-1,-5,17:18.14
0,-5,17:18.14
1,-5,17:18.14
2,-5,17:18.14
3,-5,17:18.14
6,-5,17:17.12
7,-5,17:17.12
8,-5,17:17.12
-20,-4,17:18.6
-19,-4,17:18.6
-18,-4,17:18.14
-17,-4,17:18.14
-16,-4,17:18.14
-15,-4,17:18.14
-14,-4,17:18.14
-13,-4,17:18.14
-12,-4,17:18.14
-11,-4,17:18.14
-10,-4,17:18.14
-9,-4,17:18.14
-8,-4,17:18.14
-7,-4,17:18.14
-6,-4,17:18.14
-5,-4,17:18.14
-4,-4,17:18.14
-3,-4,17:18.14
-2,-4,17:18.14
-1,-4,17:18.14
0,-4,17:18.14
1,-4,17:18.14
2,-4,17:18.14
3,-4,17:18.14
7,-4,17:17.12
-6,-3,17:18.14
-5,-3,17:18.14
-4,-3,17:18.14
-3,-3,17:18.14
1,-3,17:18.14
2,-3,17:18.14
3,-3,17:18.14
-4,-2,17:18.14
-3,-2,17:18.14
2,-2,17:18.14
3,-2,17:18.14
-6,-1,17:17.12
-4,-1,17:18.14
-3,-1,17:18.14
2,-1,17:18.14
3,-1,17:18.14
4,-1,17:18.14
-8,0,17:17.12
-7,0,17:17.12
-6,0,17:17.12
-5,0,17:17.12
-4,0,17:18.14
-3,0,17:18.14
-2,0,17:18.14
0,0,17:18.14
1,0,17:18.14
2,0,17:18.14
3,0,17:18.14
4,0,17:18.14
5,0,17:18.14
6,0,17:18.14
7,0,17:18.14
8,0,17:18.14
9,0,17:18.14
-10,1,17:17.12
-9,1,17:17.12
-8,1,17:17.12
-7,1,17:17.12
-6,1,17:17.12
-5,1,17:18.14
-4,1,17:18.14
-3,1,17:18.14
-2,1,17:18.14
-1,1,17:18.14
0,1,17:18.14
1,1,17:18.14
2,1,17:18.14
3,1,17:18.14
4,1,17:18.14
5,1,17:18.14
6,1,17:18.14
7,1,17:18.14
8,1,17:18.14
9,1,17:18.14
10,1,17:18.14
11,1,17:18.14
12,1,17:18.14
13,1,17:18.14
14,1,17:18.14
15,1,17:18.14
16,1,17:18.14
-4,2,17:18.14
-3,2,17:18.14
-2,2,17:18.14
-1,2,17:18.14
0,2,17:18.14
1,2,17:18.14
4,2,17:18.14
5,2,17:18.14
6,2,17:18.14
7,2,17:17.12
8,2,17:17.12
9,2,17:17.12
10,2,17:18.14
11,2,17:18.14
12,2,17:18.14
13,2,17:18.14
14,2,17:18.14
15,2,17:18.14
16,2,17:18.14
17,2,17:18.14
18,2,17:18.14
19,2,17:18.14
20,2,17:18.6
21,2,17:18.6
-5,3,17:18.14
-4,3,17:18.14
-3,3,17:18.14
-2,3,17:18.14
-1,3,17:18.14
0,3,17:17.12
1,3,17:17.12
2,3,17:17.12
5,3,17:18.14
6,3,17:18.14
7,3,17:18.14
8,3,17:17.12
9,3,17:17.12
10,3,17:17.12
17,3,17:18.14
18,3,17:18.14
19,3,17:18.14
20,3,17:18.6
21,3,17:18.6
-5,4,17:18.14
-4,4,17:18.14
-3,4,17:18.14
-2,4,17:18.14
0,4,17:17.12
1,4,17:17.12
2,4,17:17.12
6,4,17:18.14
7,4,17:18.14
10,4,17:17.12
11,4,17:17.12
-7,5,17:18.14
-6,5,17:18.14
-5,5,17:18.14
-4,5,17:18.14
-3,5,17:18.14
1,5,17:17.12
2,5,17:17.12
6,5,17:18.14
7,5,17:18.14
8,5,17:18.14
-8,6,17:18.14
-7,6,17:18.14
-6,6,17:18.14
-5,6,17:18.14
-4,6,17:18.14
-3,6,17:18.14
1,6,17:17.12
2,6,17:17.12
7,6,17:18.14
8,6,17:18.14
9,6,17:18.14
-9,7,17:18.14
-8,7,17:18.14
-7,7,17:18.14
-6,7,17:18.6
-4,7,17:18.14
-3,7,17:18.14
2,7,17:17.12
8,7,17:18.14
9,7,17:18.14
10,7,17:18.14
-10,8,17:18.14
-9,8,17:18.14
-8,8,17:18.6
-7,8,17:18.6
-5,8,17:18.6
-4,8,17:18.14
2,8,17:17.12
9,8,17:18.14
10,8,17:18.14
-11,9,17:18.6
-10,9,17:18.6
-9,9,17:18.6
-5,9,17:18.6
-4,9,17:18.6
9,9,17:18.14
10,9,17:18.14
11,9,17:18.14
-12,10,17:18.6
-11,10,17:18.6
-10,10,17:18.6
-5,10,17:18.6
-4,10,17:18.6
10,10,17:18.14
11,10,17:18.14
12,10,17:18.14
-13,11,17:18.6
-12,11,17:18.6
-11,11,17:18.6
-5,11,17:18.6
-4,11,17:18.6
11,11,17:18.6
12,11,17:18.6
13,11,17:18.6
-15,12,17:18.6
-14,12,17:18.6
-13,12,17:18.6
-12,12,17:18.6
-5,12,17:18.6
-4,12,17:18.6
13,12,17:18.6
14,12,17:18.6
-16,13,17:18.6
-15,13,17:18.6
-14,13,17:18.6
-13,13,17:18.6
-4,13,17:18.6
13,13,17:18.6
14,13,17:18.6
-17,14,17:18.6
-16,14,17:18.6
-6,14,17:18.6
-5,14,17:18.6
-4,14,17:18.6
13,14,17:18.6
14,14,17:18.6
15,14,17:18.6
-16,15,17:18.6
-6,15,17:18.6
-5,15,17:18.6
14,15,17:18.6
-18,16,17:18.6
-17,16,17:18.6
-16,16,17:18.6
-6,16,17:18.6
-5,16,17:18.6
-6,17,17:18.6
-5,17,17:18.6
-6,18,17:18.6
-5,18,17:18.6
-5,19,17:18.6
-6,20,17:18.6
-5,20,17:18.6
-7,21,17:18.6
-6,21,17:18.6
-7,22,17:18.6
5,-26,18:18.6
5,-25,18:18.6
6,-25,18:18.6
5,-24,18:18.6
6,-24,18:18.6
6,-23,18:18.6
5,-22,18:18.6
6,-22,18:18.6
5,-21,18:18.6
6,-21,18:18.6
5,-20,18:18.6
6,-20,18:18.6
4,-19,18:18.6
5,-19,18:18.6
6,-19,18:18.6
13,-19,18:18.6
14,-19,18:18.6
15,-19,18:18.6
-20,-18,18:18.6
-19,-18,18:18.6
4,-18,18:18.6
5,-18,18:18.6
11,-18,18:18.6
12,-18,18:18.6
13,-18,18:18.6
-20,-17,18:18.6
-19,-17,18:18.6
4,-17,18:18.6
5,-17,18:18.6
10,-17,18:18.6
11,-17,18:18.6
12,-17,18:18.6
-19,-16,18:18.6
-17,-16,18:18.6
4,-16,18:18.6
9,-16,18:18.6
10,-16,18:18.6
11,-16,18:18.6
12,-16,18:18.6
-17,-15,18:18.6
-16,-15,18:18.6
4,-15,18:18.6
5,-15,18:18.6
8,-15,18:18.6
9,-15,18:18.6
10,-15,18:18.6
-17,-14,18:18.14
-16,-14,18:18.14
-15,-14,18:18.14
-3,-14,18:17.12
-2,-14,18:17.12
4,-14,18:18.14
5,-14,18:18.6
7,-14,18:18.6
8,-14,18:18.6
9,-14,18:18.6
-24,-13,18:18.6
-16,-13,18:18.14
-15,-13,18:18.14
-14,-13,18:18.14
-3,-13,18:17.12
-2,-13,18:17.12
4,-13,18:18.14
5,-13,18:18.6
6,-13,18:18.6
7,-13,18:18.6
8,-13,18:18.6
-15,-12,18:18.14
-14,-12,18:18.14
-13,-12,18:18.14
-3,-12,18:17.12
-2,-12,18:17.12
3,-12,18:18.14
4,-12,18:18.14
5,-12,18:18.14
6,-12,18:18.6
7,-12,18:18.6
-14,-11,18:18.14
-13,-11,18:18.14
-12,-11,18:18.14
-3,-11,18:17.12
-2,-11,18:17.12
2,-11,18:18.14
3,-11,18:18.14
4,-11,18:18.14
5,-11,18:18.14
6,-11,18:18.14
-13,-10,18:18.14
-12,-10,18:18.14
0,-10,18:18.14
1,-10,18:18.14
2,-10,18:18.14
3,-10,18:18.14
4,-10,18:18.14
5,-10,18:18.14
-14,-9,18:17.12
-13,-9,18:18.14
-12,-9,18:18.14
-11,-9,18:18.14
-1,-9,18:18.14
0,-9,18:18.14
1,-9,18:18.14
2,-9,18:18.14
3,-9,18:18.14
4,-9,18:18.14
5,-9,18:18.14
-24,-8,18:18.6
-23,-8,18:18.14
-22,-8,18:18.14
-14,-8,18:17.12
-13,-8,18:17.12
-12,-8,18:17.12
-11,-8,18:18.14
-10,-8,18:18.14
-5,-8,18:18.14
-4,-8,18:18.14
-3,-8,18:18.14
-2,-8,18:18.14
-1,-8,18:18.14
0,-8,18:18.14
1,-8,18:18.14
2,-8,18:18.14
3,-8,18:18.14
4,-8,18:18.14
5,-8,18:18.14
-24,-7,18:18.6
-21,-7,18:18.14
-20,-7,18:18.14
-19,-7,18:18.14
-18,-7,18:18.14
-17,-7,18:18.14
-13,-7,18:17.12
-12,-7,18:17.12
-11,-7,18:17.12
-10,-7,18:18.14
-9,-7,18:18.14
-8,-7,18:18.14
-7,-7,18:18.14
-6,-7,18:18.14
-5,-7,18:18.14
-4,-7,18:18.14
-3,-7,18:18.14
-2,-7,18:18.14
-1,-7,18:18.14
0,-7,18:18.14
1,-7,18:18.14
2,-7,18:18.14
3,-7,18:18.14
4,-7,18:18.14
5,-7,18:18.14
9,-7,18:17.12
10,-7,18:17.12
11,-7,18:17.12
-22,-6,18:18.14
-21,-6,18:18.14
-20,-6,18:18.14
-19,-6,18:18.14
-18,-6,18:18.14
-17,-6,18:18.14
-16,-6,18:18.14
-15,-6,18:18.14
-14,-6,18:18.14
-13,-6,18:18.14
-12,-6,18:18.14
-11,-6,18:18.14
-10,-6,18:18.14
-9,-6,18:18.14
-8,-6,18:18.14
-7,-6,18:18.14
-6,-6,18:18.14
-5,-6,18:18.14
-4,-6,18:18.14
-3,-6,18:18.14
-2,-6,18:18.14
-1,-6,18:18.14
0,-6,18:18.14
1,-6,18:18.14
2,-6,18:18.14
3,-6,18:18.14
4,-6,18:18.14
5,-6,18:18.14
7,-6,18:17.12
8,-6,18:17.12
9,-6,18:17.12
10,-6,18:17.12
-15,-5,18:18.14
-14,-5,18:18.14
-13,-5,18:18.14
-12,-5,18:18.14
-11,-5,18:18.14
-10,-5,18:18.14
-9,-5,18:18.14
-8,-5,18:18.14
-7,-5,18:18.14
-6,-5,18:18.14
-5,-5,18:18.14
-4,-5,18:18.14
-3,-5,18:18.14
1,-5,18:18.14
2,-5,18:18.14
3,-5,18:18.14
4,-5,18:18.14
5,-5,18:18.14
8,-5,18:17.12
9,-5,18:17.12
-9,-4,18:18.14
-8,-4,18:18.14
-7,-4,18:18.14
-6,-4,18:18.14
-5,-4,18:18.14
-4,-4,18:18.14
3,-4,18:18.14
4,-4,18:18.14
5,-4,18:18.14
-9,-3,18:18.14
-8,-3,18:18.14
-7,-3,18:18.14
-6,-3,18:18.14
-5,-3,18:18.14
-4,-3,18:18.14
3,-3,18:18.14
4,-3,18:18.14
5,-3,18:18.14
6,-3,18:18.14
-8,-2,18:18.14
-7,-2,18:18.14
-6,-2,18:18.14
-5,-2,18:18.14
3,-2,18:18.14
4,-2,18:18.14
5,-2,18:18.14
6,-2,18:18.14
-8,-1,18:18.14
-7,-1,18:18.14
-6,-1,18:18.14
3,-1,18:18.14
4,-1,18:18.14
5,-1,18:18.14
6,-1,18:18.14
7,-1,18:18.14
-8,0,18:17.12
-7,0,18:18.14
-6,0,18:18.14
-5,0,18:18.14
-4,0,18:18.14
3,0,18:18.14
4,0,18:18.14
5,0,18:18.14
6,0,18:18.14
7,0,18:18.14
-10,1,18:17.12
-9,1,18:17.12
-8,1,18:17.12
-7,1,18:18.14
-6,1,18:18.14
-5,1,18:18.14
-3,1,18:18.14
-2,1,18:18.14
2,1,18:18.14
3,1,18:18.14
4,1,18:18.14
5,1,18:18.14
6,1,18:18.14
7,1,18:18.14
8,1,18:18.14
-12,2,18:17.12
-11,2,18:17.12
-10,2,18:17.12
-9,2,18:17.12
-8,2,18:17.12
-7,2,18:18.14
-6,2,18:18.14
-5,2,18:18.14
-4,2,18:18.14
-3,2,18:18.14
-2,2,18:18.14
-1,2,18:18.14
0,2,18:18.14
1,2,18:18.14
2,2,18:18.14
3,2,18:18.14
4,2,18:18.14
5,2,18:18.14
6,2,18:18.14
7,2,18:18.14
8,2,18:18.14
9,2,18:18.14
10,2,18:18.14
11,2,18:18.14
12,2,18:18.14
-7,3,18:18.14
-6,3,18:18.14
-5,3,18:18.14
-3,3,18:18.14
-2,3,18:18.14
-1,3,18:18.14
0,3,18:18.14
1,3,18:18.14
2,3,18:18.14
3,3,18:18.14
4,3,18:18.14
5,3,18:18.14
6,3,18:18.14
7,3,18:18.14
8,3,18:18.14
9,3,18:18.14
10,3,18:18.14
11,3,18:18.14
12,3,18:18.14
13,3,18:18.14
14,3,18:18.14
15,3,18:18.14
16,3,18:18.14
17,3,18:18.14
18,3,18:18.14
19,3,18:18.14
20,3,18:18.6
-7,4,18:18.14
-6,4,18:18.14
-5,4,18:18.14
-2,4,18:18.14
-1,4,18:18.14
0,4,18:18.14
1,4,18:18.14
2,4,18:18.14
3,4,18:18.14
4,4,18:18.14
5,4,18:18.14
6,4,18:18.14
7,4,18:18.14
8,4,18:18.14
9,4,18:18.14
10,4,18:17.12
11,4,18:17.12
12,4,18:17.12
13,4,18:18.14
14,4,18:18.14
15,4,18:18.14
16,4,18:18.14
17,4,18:18.14
18,4,18:18.14
19,4,18:18.14
20,4,18:18.6
23,4,18:18.6
24,4,18:18.6
-7,5,18:18.14
-6,5,18:18.14
-5,5,18:18.14
-4,5,18:18.14
-3,5,18:18.14
-2,5,18:18.14
-1,5,18:18.14
0,5,18:18.14
1,5,18:18.14
2,5,18:18.14
3,5,18:18.14
8,5,18:18.14
9,5,18:18.14
10,5,18:18.14
11,5,18:17.12
12,5,18:17.12
13,5,18:17.12
22,5,18:18.6
23,5,18:18.6
24,5,18:18.6
-7,6,18:18.14
-6,6,18:18.14
-5,6,18:18.14
-4,6,18:18.14
-3,6,18:18.14
-2,6,18:18.14
-1,6,18:18.14
0,6,18:18.14
1,6,18:17.12
2,6,18:17.12
3,6,18:17.12
9,6,18:18.14
10,6,18:18.14
11,6,18:18.14
-7,7,18:18.14
-6,7,18:18.6
-4,7,18:18.14
-3,7,18:18.14
-2,7,18:18.14
-1,7,18:18.14
1,7,18:17.12
2,7,18:17.12
3,7,18:17.12
10,7,18:18.14
11,7,18:18.14
12,7,18:18.14
-7,8,18:18.6
-6,8,18:18.6
-5,8,18:18.6
-4,8,18:18.14
-3,8,18:18.14
2,8,18:17.12
3,8,18:17.12
11,8,18:18.14
12,8,18:18.14
13,8,18:18.14
-8,9,18:18.6
-7,9,18:18.6
-6,9,18:18.6
-5,9,18:18.6
2,9,18:17.12
3,9,18:17.12
12,9,18:18.14
13,9,18:18.14
-9,10,18:18.6
-8,10,18:18.6
-7,10,18:18.6
-5,10,18:18.6
12,10,18:18.14
13,10,18:18.14
14,10,18:18.14
-11,11,18:18.6
-10,11,18:18.6
-9,11,18:18.6
-8,11,18:18.6
-7,11,18:18.6
-6,11,18:18.6
13,11,18:18.6
14,11,18:18.6
15,11,18:18.6
-12,12,18:18.6
-11,12,18:18.6
-10,12,18:18.6
-9,12,18:18.6
-7,12,18:18.6
-6,12,18:18.6
14,12,18:18.6
15,12,18:18.6
-13,13,18:18.6
-12,13,18:18.6
-11,13,18:18.6
-10,13,18:18.6
-7,13,18:18.6
-6,13,18:18.6
15,13,18:18.6
17,13,18:18.6
-14,14,18:18.6
-13,14,18:18.6
-12,14,18:18.6
-11,14,18:18.6
-7,14,18:18.6
-6,14,18:18.6
17,14,18:18.6
-15,15,18:18.6
-14,15,18:18.6
-13,15,18:18.6
-7,15,18:18.6
-6,15,18:18.6
17,15,18:18.6
18,15,18:18.6
-15,16,18:18.6
-14,16,18:18.6
-8,16,18:18.6
-7,16,18:18.6
-6,16,18:18.6
17,16,18:18.6
-8,17,18:18.6
-7,17,18:18.6
-8,18,18:18.6
-7,18,18:18.6
-8,19,18:18.6
-7,19,18:18.6
-8,20,18:18.6
-7,20,18:18.6
-7,21,18:18.6
7,-24,19:18.6
7,-23,19:18.6
8,-23,19:18.6
7,-22,19:18.6
8,-22,19:18.6
6,-21,19:18.6
7,-21,19:18.6
12,-21,19:18.6
13,-21,19:18.6
6,-20,19:18.6
7,-20,19:18.6
11,-20,19:18.6
12,-20,19:18.6
13,-20,19:18.6
6,-19,19:18.6
7,-19,19:18.6
10,-19,19:18.6
11,-19,19:18.6
-21,-18,19:18.6
6,-18,19:18.6
7,-18,19:18.6
9,-18,19:18.6
10,-18,19:18.6
11,-18,19:18.6
-21,-17,19:18.6
-20,-17,19:18.6
6,-17,19:18.6
7,-17,19:18.6
8,-17,19:18.6
9,-17,19:18.6
10,-17,19:18.6
-21,-16,19:18.6
-20,-16,19:18.6
-19,-16,19:18.6
6,-16,19:18.6
7,-16,19:18.6
8,-16,19:18.6
9,-16,19:18.6
-20,-15,19:18.6
-19,-15,19:18.6
-18,-15,19:18.6
-4,-15,19:17.12
-3,-15,19:17.12
4,-15,19:18.6
5,-15,19:18.6
6,-15,19:18.6
7,-15,19:18.6
8,-15,19:18.6
-19,-14,19:18.14
-18,-14,19:18.14
-4,-14,19:17.12
-3,-14,19:17.12
2,-14,19:18.14
3,-14,19:18.14
4,-14,19:18.14
5,-14,19:18.6
6,-14,19:18.6
7,-14,19:18.6
-24,-13,19:18.6
-23,-13,19:18.14
-19,-13,19:18.14
-18,-13,19:18.14
-17,-13,19:18.14
-16,-13,19:18.14
-4,-13,19:17.12
-3,-13,19:17.12
0,-13,19:18.14
1,-13,19:18.14
2,-13,19:18.14
3,-13,19:18.14
4,-13,19:18.14
5,-13,19:18.6
6,-13,19:18.6
7,-13,19:18.6
-24,-12,19:18.6
-18,-12,19:18.14
-17,-12,19:18.14
-16,-12,19:18.14
-2,-12,19:18.14
-1,-12,19:18.14
0,-12,19:18.14
1,-12,19:18.14
2,-12,19:18.14
3,-12,19:18.14
4,-12,19:18.14
5,-12,19:18.14
6,-12,19:18.6
7,-12,19:18.6
-17,-11,19:18.14
-16,-11,19:18.14
-15,-11,19:18.14
-4,-11,19:18.14
-3,-11,19:18.14
-2,-11,19:18.14
-1,-11,19:18.14
0,-11,19:18.14
1,-11,19:18.14
2,-11,19:18.14
5,-11,19:18.14
6,-11,19:18.14
7,-11,19:18.14
-16,-10,19:18.14
-15,-10,19:18.14
-14,-10,19:18.14
-7,-10,19:18.14
-6,-10,19:18.14
-5,-10,19:18.14
-3,-10,19:18.14
-2,-10,19:18.14
-1,-10,19:18.14
0,-10,19:18.14
5,-10,19:18.14
6,-10,19:18.14
7,-10,19:18.14
-23,-9,19:18.14
-22,-9,19:18.14
-21,-9,19:18.14
-16,-9,19:17.12
-15,-9,19:17.12
-13,-9,19:18.14
-11,-9,19:18.14
-10,-9,19:18.14
-9,-9,19:18.14
-8,-9,19:18.14
-7,-9,19:18.14
-6,-9,19:18.14
-5,-9,19:18.14
-4,-9,19:18.14
-3,-9,19:18.14
-1,-9,19:18.14
0,-9,19:18.14
1,-9,19:18.14
2,-9,19:18.14
3,-9,19:18.14
5,-9,19:18.14
6,-9,19:18.14
7,-9,19:18.14
-24,-8,19:18.6
-23,-8,19:18.14
-22,-8,19:18.14
-21,-8,19:18.14
-20,-8,19:18.14
-19,-8,19:18.14
-18,-8,19:18.14
-17,-8,19:18.14
-16,-8,19:18.14
-15,-8,19:18.14
-14,-8,19:18.14
-13,-8,19:18.14
-12,-8,19:18.14
-11,-8,19:18.14
-10,-8,19:18.14
-9,-8,19:18.14
-8,-8,19:18.14
-7,-8,19:18.14
-6,-8,19:18.14
-5,-8,19:18.14
-4,-8,19:18.14
-3,-8,19:18.14
-2,-8,19:18.14
-1,-8,19:18.14
0,-8,19:18.14
1,-8,19:18.14
2,-8,19:18.14
3,-8,19:18.14
4,-8,19:18.14
5,-8,19:18.14
6,-8,19:18.14
7,-8,19:18.14
8,-8,19:18.14
-23,-7,19:18.14
-21,-7,19:18.14
-20,-7,19:18.14
-19,-7,19:18.14
-18,-7,19:18.14
-17,-7,19:18.14
-16,-7,19:18.14
-15,-7,19:18.14
-14,-7,19:18.14
-13,-7,19:18.14
-12,-7,19:18.14
-11,-7,19:18.14
-10,-7,19:18.14
-9,-7,19:18.14
-8,-7,19:18.14
-7,-7,19:18.14
-6,-7,19:18.14
-5,-7,19:18.14
-4,-7,19:18.14
2,-7,19:18.14
3,-7,19:18.14
4,-7,19:18.14
5,-7,19:18.14
6,-7,19:18.14
7,-7,19:18.14
8,-7,19:18.14
10,-7,19:17.12
11,-7,19:17.12
12,-7,19:17.12
-13,-6,19:18.14
-12,-6,19:18.14
-11,-6,19:18.14
-7,-6,19:18.14
-6,-6,19:18.14
-5,-6,19:18.14
3,-6,19:18.14
4,-6,19:18.14
5,-6,19:18.14
6,-6,19:18.14
7,-6,19:18.14
8,-6,19:18.14
9,-6,19:17.12
10,-6,19:17.12
11,-6,19:17.12
12,-6,19:17.12
-13,-5,19:18.14
-12,-5,19:18.14
-11,-5,19:18.14
-10,-5,19:18.14
-8,-5,19:18.14
-7,-5,19:18.14
-6,-5,19:18.14
5,-5,19:18.14
6,-5,19:18.14
7,-5,19:18.14
8,-5,19:18.14
-12,-4,19:18.14
-11,-4,19:18.14
-10,-4,19:18.14
-8,-4,19:18.14
-7,-4,19:18.14
-6,-4,19:18.14
6,-4,19:18.14
7,-4,19:18.14
8,-4,19:18.14
-12,-3,19:18.14
-11,-3,19:18.14
-10,-3,19:18.14
-9,-3,19:18.14
-8,-3,19:18.14
-7,-3,19:18.14
6,-3,19:18.14
7,-3,19:18.14
8,-3,19:18.14
9,-3,19:18.14
-12,-2,19:18.14
-11,-2,19:18.14
-10,-2,19:18.14
-9,-2,19:18.14
-8,-2,19:18.14
-7,-2,19:18.14
5,-2,19:18.14
6,-2,19:18.14
7,-2,19:18.14
8,-2,19:18.14
9,-2,19:18.14
-11,-1,19:18.14
-10,-1,19:18.14
-9,-1,19:18.14
-8,-1,19:18.14
-7,-1,19:18.14
5,-1,19:18.14
6,-1,19:18.14
7,-1,19:18.14
8,-1,19:18.14
9,-1,19:18.14
10,-1,19:18.14
-11,0,19:18.14
-10,0,19:18.14
-9,0,19:18.14
-8,0,19:18.14
-7,0,19:18.14
5,0,19:18.14
6,0,19:18.14
7,0,19:18.14
8,0,19:18.14
9,0,19:18.14
10,0,19:18.14
-10,1,19:18.14
-9,1,19:18.14
-8,1,19:18.14
-7,1,19:18.14
5,1,19:18.14
6,1,19:18.14
7,1,19:18.14
8,1,19:18.14
9,1,19:18.14
10,1,19:18.14
11,1,19:18.14
-12,2,19:17.12
-11,2,19:17.12
-10,2,19:17.12
-9,2,19:18.14
-8,2,19:18.14
-7,2,19:18.14
-6,2,19:18.14
-5,2,19:18.14
4,2,19:18.14
5,2,19:18.14
6,2,19:18.14
9,2,19:18.14
10,2,19:18.14
11,2,19:18.14
-13,3,19:17.12
-12,3,19:17.12
-11,3,19:17.12
-10,3,19:18.14
-9,3,19:18.14
-8,3,19:18.14
-7,3,19:18.14
-6,3,19:18.14
-5,3,19:18.14
-4,3,19:18.14
-3,3,19:18.14
3,3,19:18.14
4,3,19:18.14
5,3,19:18.14
6,3,19:18.14
9,3,19:18.14
10,3,19:18.14
11,3,19:18.14
12,3,19:18.14
-10,4,19:18.14
-9,4,19:18.14
-8,4,19:18.14
-7,4,19:18.14
-6,4,19:18.14
-5,4,19:18.14
-4,4,19:18.14
-3,4,19:18.14
-2,4,19:18.14
-1,4,19:18.14
3,4,19:18.14
4,4,19:18.14
5,4,19:18.14
6,4,19:18.14
7,4,19:18.14
8,4,19:18.14
9,4,19:18.14
10,4,19:18.14
11,4,19:18.14
12,4,19:18.14
13,4,19:18.14
14,4,19:18.14
15,4,19:18.14
-10,5,19:18.14
-9,5,19:18.14
-8,5,19:18.14
-7,5,19:18.14
-4,5,19:18.14
-3,5,19:18.14
-2,5,19:18.14
-1,5,19:18.14
0,5,19:18.14
1,5,19:18.14
2,5,19:18.14
3,5,19:18.14
4,5,19:18.14
5,5,19:18.14
6,5,19:18.14
7,5,19:18.14
8,5,19:18.14
9,5,19:18.14
10,5,19:18.14
11,5,19:18.14
12,5,19:18.14
13,5,19:17.12
14,5,19:18.14
15,5,19:18.14
16,5,19:18.14
17,5,19:18.14
18,5,19:18.14
19,5,19:18.14
20,5,19:18.6
21,5,19:18.6
22,5,19:18.6
23,5,19:18.6
-10,6,19:18.14
-9,6,19:18.14
-8,6,19:18.14
-7,6,19:18.14
-2,6,19:18.14
-1,6,19:18.14
0,6,19:18.14
1,6,19:18.14
2,6,19:18.14
3,6,19:18.14
4,6,19:18.14
5,6,19:18.14
6,6,19:18.14
7,6,19:18.14
8,6,19:18.14
9,6,19:18.14
10,6,19:18.14
11,6,19:18.14
12,6,19:18.14
13,6,19:18.14
14,6,19:17.12
15,6,19:17.12
16,6,19:18.14
17,6,19:18.14
18,6,19:18.14
19,6,19:18.14
20,6,19:18.6
21,6,19:18.6
22,6,19:18.6
23,6,19:18.6
24,6,19:18.6
25,6,19:18.6
-9,7,19:18.14
-8,7,19:18.14
-7,7,19:18.14
-1,7,19:18.14
0,7,19:18.14
1,7,19:18.14
2,7,19:18.14
3,7,19:18.14
4,7,19:18.14
5,7,19:18.14
6,7,19:18.14
7,7,19:18.14
12,7,19:18.14
13,7,19:18.14
14,7,19:18.14
-9,8,19:18.14
-8,8,19:18.6
-7,8,19:18.6
-3,8,19:18.14
-2,8,19:18.14
-1,8,19:18.14
0,8,19:18.14
1,8,19:18.14
2,8,19:17.12
3,8,19:17.12
13,8,19:18.14
14,8,19:18.14
15,8,19:18.14
-9,9,19:18.6
-8,9,19:18.6
-7,9,19:18.6
-5,9,19:18.6
-4,9,19:18.6
-3,9,19:18.14
-2,9,19:18.14
-1,9,19:18.14
0,9,19:18.14
1,9,19:18.14
2,9,19:17.12
3,9,19:17.12
14,9,19:18.14
15,9,19:18.14
16,9,19:18.14
-9,10,19:18.6
-8,10,19:18.6
-7,10,19:18.6
-5,10,19:18.6
-4,10,19:18.6
-3,10,19:18.14
-2,10,19:18.14
-1,10,19:18.14
3,10,19:17.12
4,10,19:17.12
15,10,19:18.14
16,10,19:18.14
17,10,19:18.14
-9,11,19:18.6
-8,11,19:18.6
-7,11,19:18.6
-6,11,19:18.6
-5,11,19:18.6
-4,11,19:18.6
-3,11,19:18.14
3,11,19:17.12
16,11,19:18.6
17,11,19:18.6
-9,12,19:18.6
-8,12,19:18.6
-7,12,19:18.6
-6,12,19:18.6
-5,12,19:18.6
-4,12,19:18.6
16,12,19:18.6
17,12,19:18.6
18,12,19:18.6
-10,13,19:18.6
-9,13,19:18.6
-8,13,19:18.6
-7,13,19:18.6
-6,13,19:18.6
17,13,19:18.6
18,13,19:18.6
19,13,19:18.6
-11,14,19:18.6
-10,14,19:18.6
-9,14,19:18.6
-8,14,19:18.6
-7,14,19:18.6
18,14,19:18.6
19,14,19:18.6
-11,15,19:18.6
-10,15,19:18.6
-9,15,19:18.6
-8,15,19:18.6
19,15,19:18.6
20,15,19:18.6
-13,16,19:18.6
-12,16,19:18.6
-11,16,19:18.6
-10,16,19:18.6
-9,16,19:18.6
-8,16,19:18.6
20,16,19:18.6
-14,17,19:18.6
-13,17,19:18.6
-12,17,19:18.6
-9,17,19:18.6
-14,18,19:18.6
-13,18,19:18.6
-10,18,19:18.6
-9,18,19:18.6
-14,19,19:18.6
-10,19,19:18.6
-9,19,19:18.6
-10,20,19:18.6
-9,20,19:18.6
-10,21,19:18.6
10,-30,20:18.6
10,-29,20:18.6
10,-28,20:18.6
10,-27,20:18.6
15,-26,20:18.6
16,-26,20:18.6
9,-25,20:18.6
14,-25,20:18.6
15,-25,20:18.6
8,-24,20:18.6
9,-24,20:18.6
14,-24,20:18.6
8,-23,20:18.6
9,-23,20:18.6
12,-23,20:18.6
8,-22,20:18.6
9,-22,20:18.6
11,-22,20:18.6
12,-22,20:18.6
13,-22,20:18.6
8,-21,20:18.6
9,-21,20:18.6
10,-21,20:18.6
11,-21,20:18.6
12,-21,20:18.6
7,-20,20:18.6
8,-20,20:18.6
9,-20,20:18.6
10,-20,20:18.6
11,-20,20:18.6
6,-19,20:18.6
7,-19,20:18.6
8,-19,20:18.6
10,-19,20:18.6
4,-18,20:18.6
5,-18,20:18.6
6,-18,20:18.6
7,-18,20:18.6
8,-18,20:18.6
9,-18,20:18.6
-24,-17,20:18.6
-4,-17,20:17.12
2,-17,20:18.14
3,-17,20:18.6
4,-17,20:18.6
5,-17,20:18.6
6,-17,20:18.6
7,-17,20:18.6
8,-17,20:18.6
9,-17,20:18.6
-24,-16,20:18.6
-23,-16,20:18.6
-22,-16,20:18.6
-5,-16,20:17.12
-4,-16,20:17.12
0,-16,20:18.14
1,-16,20:18.14
2,-16,20:18.14
3,-16,20:18.14
4,-16,20:18.6
7,-16,20:18.6
8,-16,20:18.6
9,-16,20:18.6
-23,-15,20:18.6
-22,-15,20:18.6
-21,-15,20:18.6
-5,-15,20:17.12
-4,-15,20:17.12
-1,-15,20:18.14
0,-15,20:18.14
1,-15,20:18.14
2,-15,20:18.14
3,-15,20:18.14
4,-15,20:18.6
7,-15,20:18.6
8,-15,20:18.6
9,-15,20:18.6
-21,-14,20:18.14
-20,-14,20:18.14
-4,-14,20:17.12
-3,-14,20:18.14
-2,-14,20:18.14
-1,-14,20:18.14
0,-14,20:18.14
1,-14,20:18.14
2,-14,20:18.14
8,-14,20:18.6
9,-14,20:18.6
-22,-13,20:18.14
-21,-13,20:18.14
-20,-13,20:18.14
-19,-13,20:18.14
-6,-13,20:18.14
-5,-13,20:18.14
-4,-13,20:18.14
-3,-13,20:18.14
-2,-13,20:18.14
-1,-13,20:18.14
0,-13,20:18.14
8,-13,20:18.6
9,-13,20:18.6
10,-13,20:18.6
-24,-12,20:18.6
-23,-12,20:18.14
-20,-12,20:18.14
-19,-12,20:18.14
-18,-12,20:18.14
-10,-12,20:18.14
-9,-12,20:18.14
-8,-12,20:18.14
-7,-12,20:18.14
-6,-12,20:18.14
-5,-12,20:18.14
-4,-12,20:18.14
-3,-12,20:18.14
-2,-12,20:18.14
-1,-12,20:18.14
0,-12,20:18.14
1,-12,20:18.14
8,-12,20:18.6
9,-12,20:18.14
10,-12,20:18.14
-24,-11,20:18.6
-19,-11,20:18.14
-18,-11,20:18.14
-17,-11,20:18.14
-14,-11,20:18.14
-13,-11,20:18.14
-12,-11,20:18.14
-11,-11,20:18.14
-10,-11,20:18.14
-9,-11,20:18.14
-8,-11,20:18.14
-7,-11,20:18.14
-6,-11,20:18.14
-5,-11,20:18.14
-4,-11,20:18.14
-3,-11,20:18.14
-2,-11,20:18.14
-1,-11,20:18.14
0,-11,20:18.14
1,-11,20:18.14
2,-11,20:18.14
3,-11,20:18.14
4,-11,20:18.6
8,-11,20:18.14
9,-11,20:18.14
10,-11,20:18.14
-24,-10,20:18.6
-23,-10,20:18.14
-22,-10,20:18.14
-21,-10,20:18.14
-20,-10,20:18.14
-19,-10,20:17.12
-18,-10,20:18.14
-17,-10,20:18.14
-16,-10,20:18.14
-15,-10,20:18.14
-14,-10,20:18.14
-13,-10,20:18.14
-12,-10,20:18.14
-11,-10,20:18.14
-10,-10,20:18.14
-9,-10,20:18.14
-8,-10,20:18.14
-7,-10,20:18.14
-6,-10,20:18.14
-5,-10,20:18.14
-1,-10,20:18.14
0,-10,20:18.14
1,-10,20:18.14
2,-10,20:18.14
3,-10,20:18.14
4,-10,20:18.14
5,-10,20:18.14
8,-10,20:18.14
9,-10,20:18.14
10,-10,20:18.14
-23,-9,20:18.14
-22,-9,20:18.14
-21,-9,20:18.14
-20,-9,20:18.14
-19,-9,20:18.14
-18,-9,20:18.14
-17,-9,20:18.14
-16,-9,20:18.14
-15,-9,20:18.14
-13,-9,20:18.14
-12,-9,20:18.14
-11,-9,20:18.14
-10,-9,20:18.14
-8,-9,20:18.14
-7,-9,20:18.14
-6,-9,20:18.14
-5,-9,20:18.14
3,-9,20:18.14
4,-9,20:18.14
5,-9,20:18.14
6,-9,20:18.14
8,-9,20:18.14
9,-9,20:18.14
10,-9,20:18.14
-18,-8,20:18.14
-17,-8,20:18.14
-16,-8,20:18.14
-15,-8,20:18.14
-14,-8,20:18.14
-8,-8,20:18.14
-7,-8,20:18.14
-6,-8,20:18.14
4,-8,20:18.14
5,-8,20:18.14
6,-8,20:18.14
7,-8,20:18.14
8,-8,20:18.14
9,-8,20:18.14
10,-8,20:18.14
-17,-7,20:18.14
-16,-7,20:18.14
-15,-7,20:18.14
-14,-7,20:18.14
-9,-7,20:18.14
-8,-7,20:18.14
-7,-7,20:18.14
6,-7,20:18.14
7,-7,20:18.14
8,-7,20:18.14
9,-7,20:18.14
10,-7,20:18.14
11,-7,20:17.12
12,-7,20:17.12
13,-7,20:17.12
14,-7,20:17.12
-16,-6,20:18.14
-15,-6,20:18.14
-14,-6,20:18.14
-10,-6,20:18.14
-9,-6,20:18.14
-8,-6,20:18.14
7,-6,20:18.14
8,-6,20:18.14
9,-6,20:18.14
10,-6,20:18.14
12,-6,20:17.12
-16,-5,20:18.14
-15,-5,20:18.14
-14,-5,20:18.14
-13,-5,20:18.14
-10,-5,20:18.14
-9,-5,20:18.14
-8,-5,20:18.14
8,-5,20:18.14
9,-5,20:18.14
10,-5,20:18.14
11,-5,20:18.14
-16,-4,20:18.14
-15,-4,20:18.14
-14,-4,20:18.14
-13,-4,20:18.14
-10,-4,20:18.14
-9,-4,20:18.14
8,-4,20:18.14
9,-4,20:18.14
10,-4,20:18.14
11,-4,20:18.14
-15,-3,20:18.14
-14,-3,20:18.14
-13,-3,20:18.14
-12,-3,20:18.14
-11,-3,20:18.14
-10,-3,20:18.14
-9,-3,20:18.14
8,-3,20:18.14
9,-3,20:18.14
10,-3,20:18.14
11,-3,20:18.14
12,-3,20:18.14
-15,-2,20:18.14
-14,-2,20:18.14
-13,-2,20:18.14
-12,-2,20:18.14
-11,-2,20:18.14
-10,-2,20:18.14
-9,-2,20:18.14
8,-2,20:18.14
9,-2,20:18.14
10,-2,20:18.14
11,-2,20:18.14
12,-2,20:18.14
-14,-1,20:18.14
-13,-1,20:18.14
-12,-1,20:18.14
-11,-1,20:18.14
-10,-1,20:18.14
-9,-1,20:18.14
7,-1,20:18.14
8,-1,20:18.14
9,-1,20:18.14
10,-1,20:18.14
11,-1,20:18.14
12,-1,20:18.14
13,-1,20:18.14
-14,0,20:18.14
-13,0,20:18.14
-12,0,20:18.14
-11,0,20:18.14
-10,0,20:18.14
7,0,20:18.14
8,0,20:18.14
9,0,20:18.14
11,0,20:18.14
12,0,20:18.14
13,0,20:18.14
-13,1,20:18.14
-12,1,20:18.14
-11,1,20:18.14
-10,1,20:18.14
7,1,20:18.14
8,1,20:18.14
9,1,20:18.14
11,1,20:18.14
12,1,20:18.14
13,1,20:18.14
14,1,20:18.14
-13,2,20:18.14
-12,2,20:18.14
-11,2,20:18.14
-10,2,20:18.14
7,2,20:18.14
8,2,20:18.14
9,2,20:18.14
12,2,20:18.14
13,2,20:18.14
14,2,20:18.14
-14,3,20:17.12
-13,3,20:17.12
-12,3,20:17.12
-11,3,20:18.14
-10,3,20:18.14
-9,3,20:18.14
-8,3,20:18.14
6,3,20:18.14
7,3,20:18.14
8,3,20:18.14
9,3,20:18.14
12,3,20:18.14
13,3,20:18.14
14,3,20:18.14
15,3,20:18.14
-15,4,20:17.12
-14,4,20:17.12
-13,4,20:17.12
-12,4,20:18.14
-11,4,20:18.14
-10,4,20:18.14
-9,4,20:18.14
-8,4,20:18.14
-7,4,20:18.14
-6,4,20:18.14
6,4,20:18.14
7,4,20:18.14
8,4,20:18.14
13,4,20:18.14
14,4,20:18.14
15,4,20:18.14
-12,5,20:18.14
-11,5,20:18.14
-10,5,20:18.14
-9,5,20:18.14
-8,5,20:18.14
-7,5,20:18.14
-6,5,20:18.14
-5,5,20:18.14
-4,5,20:18.14
5,5,20:18.14
6,5,20:18.14
7,5,20:18.14
13,5,20:18.14
14,5,20:18.14
15,5,20:18.14
16,5,20:18.14
-12,6,20:18.14
-11,6,20:18.14
-10,6,20:18.14
-7,6,20:18.14
-6,6,20:18.14
-5,6,20:18.14
-4,6,20:18.14
-3,6,20:18.14
-2,6,20:18.14
4,6,20:18.14
5,6,20:18.14
6,6,20:18.14
7,6,20:18.14
10,6,20:18.14
11,6,20:18.14
12,6,20:18.14
13,6,20:18.14
14,6,20:18.14
15,6,20:18.14
16,6,20:18.14
17,6,20:18.14
18,6,20:18.14
19,6,20:18.14
-12,7,20:18.14
-11,7,20:18.14
-10,7,20:18.14
-4,7,20:18.14
-3,7,20:18.14
-2,7,20:18.14
-1,7,20:18.14
0,7,20:18.14
3,7,20:18.14
4,7,20:18.14
5,7,20:18.14
6,7,20:18.14
7,7,20:18.14
8,7,20:18.14
9,7,20:18.14
10,7,20:18.14
11,7,20:18.14
12,7,20:18.14
13,7,20:18.14
14,7,20:18.14
15,7,20:18.14
16,7,20:18.14
17,7,20:18.14
18,7,20:18.14
19,7,20:18.14
20,7,20:18.6
21,7,20:18.6
22,7,20:18.6
23,7,20:18.6
24,7,20:18.6
-12,8,20:18.14
-11,8,20:18.14
-10,8,20:18.14
-3,8,20:18.14
-2,8,20:18.14
-1,8,20:18.14
0,8,20:18.14
1,8,20:18.14
2,8,20:18.14
3,8,20:18.14
4,8,20:18.14
5,8,20:18.14
6,8,20:18.14
7,8,20:18.14
8,8,20:18.14
9,8,20:18.14
10,8,20:18.14
11,8,20:18.14
12,8,20:18.14
13,8,20:18.14
14,8,20:18.14
15,8,20:18.14
16,8,20:18.14
17,8,20:18.14
20,8,20:18.6
21,8,20:18.6
24,8,20:18.6
25,8,20:18.6
26,8,20:18.6
27,8,20:18.6
-12,9,20:18.14
-11,9,20:18.6
-10,9,20:18.6
-1,9,20:18.14
0,9,20:18.14
1,9,20:18.14
2,9,20:18.14
3,9,20:18.14
4,9,20:18.14
5,9,20:18.14
6,9,20:18.14
7,9,20:18.14
8,9,20:18.14
9,9,20:18.14
10,9,20:18.14
11,9,20:18.14
16,9,20:18.14
17,9,20:18.14
18,9,20:18.14
27,9,20:18.6
-12,10,20:18.6
-11,10,20:18.6
-10,10,20:18.6
-1,10,20:18.14
0,10,20:18.14
1,10,20:18.14
2,10,20:18.14
3,10,20:18.14
4,10,20:18.14
5,10,20:18.14
6,10,20:18.14
7,10,20:18.14
17,10,20:18.14
18,10,20:18.14
19,10,20:18.14
-12,11,20:18.6
-11,11,20:18.6
-10,11,20:18.6
-2,11,20:18.14
-1,11,20:18.14
0,11,20:18.14
1,11,20:18.14
2,11,20:18.14
3,11,20:17.12
4,11,20:17.12
19,11,20:18.6
-12,12,20:18.6
-11,12,20:18.6
-10,12,20:18.6
-4,12,20:18.6
-3,12,20:18.6
-2,12,20:18.14
-1,12,20:18.14
0,12,20:18.14
1,12,20:18.14
3,12,20:17.12
4,12,20:17.12
18,12,20:18.6
19,12,20:18.6
20,12,20:18.6
-12,13,20:18.6
-11,13,20:18.6
-10,13,20:18.6
-6,13,20:18.6
-4,13,20:18.6
-3,13,20:18.6
-2,13,20:18.14
-1,13,20:18.14
0,13,20:18.14
4,13,20:17.12
19,13,20:18.6
20,13,20:18.6
21,13,20:18.6
-12,14,20:18.6
-11,14,20:18.6
-10,14,20:18.6
-7,14,20:18.6
-6,14,20:18.6
-5,14,20:18.6
-4,14,20:18.6
-3,14,20:18.6
-2,14,20:18.6
20,14,20:18.6
21,14,20:18.6
22,14,20:18.6
-11,15,20:18.6
-10,15,20:18.6
-9,15,20:18.6
-8,15,20:18.6
-7,15,20:18.6
-6,15,20:18.6
-5,15,20:18.6
-4,15,20:18.6
22,15,20:18.6
23,15,20:18.6
-12,16,20:18.6
-11,16,20:18.6
-10,16,20:18.6
-9,16,20:18.6
-8,16,20:18.6
-7,16,20:18.6
-6,16,20:18.6
-5,16,20:18.6
22,16,20:18.6
23,16,20:18.6
-12,17,20:18.6
-11,17,20:18.6
-10,17,20:18.6
-9,17,20:18.6
-8,17,20:18.6
-7,17,20:18.6
-12,18,20:18.6
-11,18,20:18.6
-10,18,20:18.6
-9,18,20:18.6
-8,18,20:18.6
-13,19,20:18.6
-12,19,20:18.6
-11,19,20:18.6
-10,19,20:18.6
-13,20,20:18.6
-12,20,20:18.6
-11,20,20:18.6
-10,20,20:18.6
-15,21,20:18.6
-14,21,20:18.6
-12,21,20:18.6
-11,21,20:18.6
-10,21,20:18.6
-16,22,20:18.6
-15,22,20:18.6
-14,22,20:18.6
-12,22,20:18.6
-11,22,20:18.6
-18,23,20:18.6
-17,23,20:18.6
-16,23,20:18.6
-15,23,20:18.6
-12,23,20:18.6
-11,23,20:18.6
-16,24,20:18.6
-12,24,20:18.6
-11,24,20:18.6
-12,25,20:18.6
-11,25,20:18.6
-12,26,20:18.6
-11,26,20:18.6
11,-29,21:18.6
12,-29,21:18.6
10,-28,21:18.6
11,-28,21:18.6
12,-28,21:18.6
10,-27,21:18.6
11,-27,21:18.6
14,-27,21:18.6
15,-27,21:18.6
10,-26,21:18.6
11,-26,21:18.6
12,-26,21:18.6
13,-26,21:18.6
14,-26,21:18.6
15,-26,21:18.6
10,-25,21:18.6
11,-25,21:18.6
12,-25,21:18.6
13,-25,21:18.6
14,-25,21:18.6
9,-24,21:18.6
10,-24,21:18.6
11,-24,21:18.6
12,-24,21:18.6
13,-24,21:18.6
8,-23,21:18.6
9,-23,21:18.6
10,-23,21:18.6
11,-23,21:18.6
12,-23,21:18.6
6,-22,21:18.6
7,-22,21:18.6
8,-22,21:18.6
9,-22,21:18.6
10,-22,21:18.6
11,-22,21:18.6
4,-21,21:18.6
5,-21,21:18.6
6,-21,21:18.6
7,-21,21:18.6
8,-21,21:18.6
9,-21,21:18.6
10,-21,21:18.6
11,-21,21:18.6
12,-21,21:18.6
2,-20,21:18.6
4,-20,21:18.6
5,-20,21:18.6
6,-20,21:18.6
7,-20,21:18.6
10,-20,21:18.6
11,-20,21:18.6
12,-20,21:18.6
0,-19,21:18.14
1,-19,21:18.14
2,-19,21:18.6
3,-19,21:18.6
4,-19,21:18.6
5,-19,21:18.6
6,-19,21:18.6
10,-19,21:18.6
11,-19,21:18.6
12,-19,21:18.6
-5,-18,21:17.12
-1,-18,21:18.14
0,-18,21:18.14
1,-18,21:18.14
2,-18,21:18.14
3,-18,21:18.6
4,-18,21:18.6
10,-18,21:18.6
11,-18,21:18.6
12,-18,21:18.6
-5,-17,21:17.12
-4,-17,21:17.12
-3,-17,21:18.14
-2,-17,21:18.14
-1,-17,21:18.14
0,-17,21:18.14
1,-17,21:18.14
2,-17,21:18.14
10,-17,21:18.6
11,-17,21:18.6
12,-17,21:18.6
-24,-16,21:18.6
-5,-16,21:17.12
-4,-16,21:18.14
-3,-16,21:18.14
-2,-16,21:18.14
-1,-16,21:18.14
0,-16,21:18.14
10,-16,21:18.6
11,-16,21:18.6
12,-16,21:18.6
-24,-15,21:18.6
-23,-15,21:18.6
-9,-15,21:18.14
-8,-15,21:18.14
-7,-15,21:18.14
-6,-15,21:18.14
-5,-15,21:18.14
-4,-15,21:18.14
-3,-15,21:18.14
-2,-15,21:18.14
10,-15,21:18.6
11,-15,21:18.6
12,-15,21:18.6
-24,-14,21:18.6
-23,-14,21:18.14
-22,-14,21:18.14
-12,-14,21:18.6
-11,-14,21:18.6
-10,-14,21:18.6
-9,-14,21:18.14
-8,-14,21:18.14
-7,-14,21:18.14
-6,-14,21:18.14
-5,-14,21:18.14
-4,-14,21:18.14
-3,-14,21:18.14
-2,-14,21:18.14
-1,-14,21:18.14
0,-14,21:18.14
1,-14,21:18.14
11,-14,21:18.6
12,-14,21:18.6
-23,-13,21:18.14
-22,-13,21:18.14
-21,-13,21:18.14
-16,-13,21:18.14
-15,-13,21:18.14
-14,-13,21:18.14
-13,-13,21:18.14
-12,-13,21:18.14
-11,-13,21:18.14
-10,-13,21:18.14
-9,-13,21:18.14
-8,-13,21:18.14
-7,-13,21:18.14
-6,-13,21:18.14
-5,-13,21:18.14
-4,-13,21:18.14
-3,-13,21:18.14
-2,-13,21:18.14
-1,-13,21:18.14
0,-13,21:18.14
1,-13,21:18.14
2,-13,21:18.14
3,-13,21:18.14
4,-13,21:18.6
5,-13,21:18.6
10,-13,21:18.6
11,-13,21:18.6
12,-13,21:18.6
-23,-12,21:18.14
-22,-12,21:18.14
-21,-12,21:18.14
-20,-12,21:18.14
-19,-12,21:18.14
-18,-12,21:18.14
-17,-12,21:18.14
-16,-12,21:18.14
-15,-12,21:18.14
-14,-12,21:18.14
-13,-12,21:18.14
-12,-12,21:18.14
-11,-12,21:18.14
-10,-12,21:18.14
-9,-12,21:18.14
-8,-12,21:18.14
-7,-12,21:18.14
-6,-12,21:18.14
0,-12,21:18.14
1,-12,21:18.14
2,-12,21:18.14
3,-12,21:18.14
4,-12,21:18.6
5,-12,21:18.6
6,-12,21:18.6
10,-12,21:18.14
11,-12,21:18.14
12,-12,21:18.14
-24,-11,21:18.6
-23,-11,21:18.14
-22,-11,21:18.14
-21,-11,21:18.14
-20,-11,21:18.14
-19,-11,21:18.14
-18,-11,21:18.14
-17,-11,21:18.14
-16,-11,21:18.14
-15,-11,21:18.14
-14,-11,21:18.14
-13,-11,21:18.14
-9,-11,21:18.14
-8,-11,21:18.14
-7,-11,21:18.14
-6,-11,21:18.14
3,-11,21:18.14
4,-11,21:18.6
5,-11,21:18.14
6,-11,21:18.14
7,-11,21:18.14
10,-11,21:18.14
11,-11,21:18.14
12,-11,21:18.14
-24,-10,21:18.6
-23,-10,21:18.14
-22,-10,21:18.14
-21,-10,21:18.14
-20,-10,21:18.14
-19,-10,21:18.14
-18,-10,21:18.14
-17,-10,21:18.14
-10,-10,21:18.14
-9,-10,21:18.14
-8,-10,21:18.14
-7,-10,21:18.14
5,-10,21:18.14
6,-10,21:18.14
7,-10,21:18.14
8,-10,21:18.14
9,-10,21:18.14
10,-10,21:18.14
11,-10,21:18.14
12,-10,21:18.14
-21,-9,21:18.14
-20,-9,21:18.14
-19,-9,21:18.14
-18,-9,21:18.14
-10,-9,21:18.14
-9,-9,21:18.14
-8,-9,21:18.14
7,-9,21:18.14
8,-9,21:18.14
9,-9,21:18.14
10,-9,21:18.14
11,-9,21:18.14
12,-9,21:18.14
-24,-8,21:18.6
-20,-8,21:18.14
-19,-8,21:18.14
-18,-8,21:18.14
-11,-8,21:18.14
-10,-8,21:18.14
-9,-8,21:18.14
8,-8,21:18.14
9,-8,21:18.14
10,-8,21:18.14
11,-8,21:18.14
12,-8,21:18.14
13,-8,21:17.12
14,-8,21:17.12
15,-8,21:17.12
-20,-7,21:18.14
-19,-7,21:18.14
-18,-7,21:18.14
-17,-7,21:18.14
-12,-7,21:18.14
-11,-7,21:18.14
-10,-7,21:18.14
9,-7,21:18.14
10,-7,21:18.14
12,-7,21:18.14
13,-7,21:17.12
14,-7,21:17.12
15,-7,21:17.12
-20,-6,21:18.14
-19,-6,21:18.14
-18,-6,21:18.14
-17,-6,21:18.14
-12,-6,21:18.14
-11,-6,21:18.14
-10,-6,21:18.14
10,-6,21:18.14
11,-6,21:18.14
12,-6,21:18.14
13,-6,21:18.14
-19,-5,21:18.14
-18,-5,21:18.14
-17,-5,21:18.14
-16,-5,21:18.14
-12,-5,21:18.14
-11,-5,21:18.14
10,-5,21:18.14
11,-5,21:18.14
12,-5,21:18.14
13,-5,21:18.14
-19,-4,21:18.6
-18,-4,21:18.14
-17,-4,21:18.14
-16,-4,21:18.14
-13,-4,21:18.14
-12,-4,21:18.14
-11,-4,21:18.14
10,-4,21:18.14
11,-4,21:18.14
12,-4,21:18.14
13,-4,21:18.14
14,-4,21:18.14
-18,-3,21:18.6
-17,-3,21:18.14
-16,-3,21:18.14
-15,-3,21:18.14
-13,-3,21:18.14
-12,-3,21:18.14
-11,-3,21:18.14
10,-3,21:18.14
11,-3,21:18.14
12,-3,21:18.14
14,-3,21:18.14
-18,-2,21:18.6
-17,-2,21:18.6
-16,-2,21:18.14
-15,-2,21:18.14
-13,-2,21:18.14
-12,-2,21:18.14
-11,-2,21:18.14
10,-2,21:18.14
11,-2,21:18.14
12,-2,21:18.14
13,-2,21:18.14
14,-2,21:18.14
15,-2,21:18.14
-17,-1,21:18.14
-16,-1,21:18.14
-15,-1,21:18.14
-14,-1,21:18.14
-13,-1,21:18.14
-12,-1,21:18.14
10,-1,21:18.14
11,-1,21:18.14
12,-1,21:18.14
13,-1,21:18.14
14,-1,21:18.14
15,-1,21:18.6
-17,0,21:18.14
-16,0,21:18.14
-15,0,21:18.14
-14,0,21:18.14
-13,0,21:18.14
-12,0,21:18.14
10,0,21:18.14
11,0,21:18.14
13,0,21:18.14
14,0,21:18.14
15,0,21:18.14
16,0,21:18.14
-16,1,21:18.14
-15,1,21:18.14
-14,1,21:18.14
-13,1,21:18.14
-12,1,21:18.14
9,1,21:18.14
10,1,21:18.14
11,1,21:18.14
14,1,21:18.14
15,1,21:18.14
16,1,21:18.14
-16,2,21:18.14
-15,2,21:18.14
-14,2,21:18.14
-13,2,21:18.14
9,2,21:18.14
10,2,21:18.14
11,2,21:18.14
14,2,21:18.14
15,2,21:18.14
16,2,21:18.14
17,2,21:18.14
-15,3,21:18.14
-14,3,21:18.14
-13,3,21:18.14
-12,3,21:18.14
9,3,21:18.14
10,3,21:18.14
11,3,21:18.14
15,3,21:18.14
16,3,21:18.14
17,3,21:18.14
-16,4,21:17.12
-15,4,21:17.12
-14,4,21:18.14
-13,4,21:18.14
-12,4,21:18.14
-11,4,21:18.14
8,4,21:18.14
9,4,21:18.14
10,4,21:18.14
11,4,21:18.14
15,4,21:18.14
16,4,21:18.14
17,4,21:18.14
18,4,21:18.14
-16,5,21:17.12
-15,5,21:18.14
-14,5,21:18.14
-13,5,21:18.14
-12,5,21:18.14
-11,5,21:18.14
-10,5,21:18.14
-9,5,21:18.14
8,5,21:18.14
9,5,21:18.14
10,5,21:18.14
16,5,21:18.14
17,5,21:18.14
18,5,21:18.14
-15,6,21:18.14
-14,6,21:18.14
-13,6,21:18.14
-12,6,21:18.14
-11,6,21:18.14
-10,6,21:18.14
-9,6,21:18.14
-8,6,21:18.14
-7,6,21:18.14
7,6,21:18.14
8,6,21:18.14
9,6,21:18.14
16,6,21:18.14
17,6,21:18.14
18,6,21:18.14
19,6,21:18.14
-15,7,21:18.14
-14,7,21:18.14
-13,7,21:18.14
-10,7,21:18.14
-9,7,21:18.14
-8,7,21:18.14
-7,7,21:18.14
-6,7,21:18.6
6,7,21:18.14
7,7,21:18.14
8,7,21:18.14
9,7,21:18.14
17,7,21:18.14
18,7,21:18.14
19,7,21:18.14
-15,8,21:18.14
-14,8,21:18.14
-13,8,21:18.14
-8,8,21:18.6
-7,8,21:18.6
-6,8,21:18.6
-5,8,21:18.6
-4,8,21:18.14
-3,8,21:18.14
6,8,21:18.14
7,8,21:18.14
8,8,21:18.14
14,8,21:18.14
15,8,21:18.14
16,8,21:18.14
17,8,21:18.14
18,8,21:18.14
19,8,21:18.14
20,8,21:18.6
21,8,21:18.6
22,8,21:18.6
-15,9,21:18.14
-14,9,21:18.14
-13,9,21:18.14
-12,9,21:18.14
-6,9,21:18.6
-5,9,21:18.6
-4,9,21:18.6
-3,9,21:18.14
-2,9,21:18.14
-1,9,21:18.14
5,9,21:18.14
6,9,21:18.14
7,9,21:18.14
10,9,21:18.14
11,9,21:18.14
12,9,21:18.14
13,9,21:18.14
14,9,21:18.14
15,9,21:18.14
16,9,21:18.14
17,9,21:18.14
18,9,21:18.14
19,9,21:18.14
20,9,21:18.6
21,9,21:18.6
22,9,21:18.6
23,9,21:18.6
24,9,21:18.6
25,9,21:18.6
26,9,21:18.6
-15,10,21:18.6
-14,10,21:18.6
-13,10,21:18.6
-12,10,21:18.6
-4,10,21:18.6
-3,10,21:18.14
-2,10,21:18.14
-1,10,21:18.14
0,10,21:18.14
1,10,21:18.14
2,10,21:18.14
4,10,21:18.14
5,10,21:18.14
6,10,21:18.14
7,10,21:18.14
8,10,21:18.14
9,10,21:18.14
10,10,21:18.14
11,10,21:18.14
12,10,21:18.14
13,10,21:18.14
14,10,21:18.14
15,10,21:18.14
16,10,21:18.14
17,10,21:18.14
18,10,21:18.14
19,10,21:18.14
20,10,21:18.6
21,10,21:18.6
23,10,21:18.6
24,10,21:18.6
25,10,21:18.6
26,10,21:18.6
27,10,21:18.6
-15,11,21:18.6
-14,11,21:18.6
-13,11,21:18.6
-12,11,21:18.6
-2,11,21:18.14
-1,11,21:18.14
0,11,21:18.14
1,11,21:18.14
2,11,21:18.14
3,11,21:18.14
4,11,21:18.14
5,11,21:18.14
6,11,21:18.14
7,11,21:18.14
8,11,21:18.14
9,11,21:18.14
10,11,21:18.6
11,11,21:18.6
12,11,21:18.6
13,11,21:18.6
14,11,21:18.6
15,11,21:18.6
20,11,21:18.6
21,11,21:18.6
22,11,21:18.6
-14,12,21:18.6
-13,12,21:18.6
-12,12,21:18.6
0,12,21:18.14
1,12,21:18.14
2,12,21:18.14
3,12,21:18.14
4,12,21:18.14
5,12,21:18.14
6,12,21:18.14
7,12,21:18.14
8,12,21:18.14
9,12,21:18.14
10,12,21:18.6
11,12,21:18.6
21,12,21:18.6
22,12,21:18.6
23,12,21:18.6
-14,13,21:18.6
-13,13,21:18.6
-12,13,21:18.6
0,13,21:18.14
1,13,21:18.14
2,13,21:18.14
3,13,21:18.14
4,13,21:17.12
5,13,21:18.14
6,13,21:18.14
7,13,21:18.14
8,13,21:18.14
21,13,21:18.6
22,13,21:18.6
23,13,21:18.6
-14,14,21:18.6
-13,14,21:18.6
-12,14,21:18.6
-2,14,21:18.6
-1,14,21:18.14
0,14,21:18.14
1,14,21:18.14
2,14,21:18.14
3,14,21:18.14
4,14,21:17.12
5,14,21:17.12
22,14,21:18.6
23,14,21:18.6
24,14,21:18.6
-14,15,21:18.6
-13,15,21:18.6
-3,15,21:18.6
-2,15,21:18.6
-1,15,21:18.14
0,15,21:18.14
1,15,21:18.14
2,15,21:18.14
5,15,21:17.12
24,15,21:18.6
-14,16,21:18.6
-13,16,21:18.6
-12,16,21:18.6
-5,16,21:18.6
-4,16,21:18.6
-3,16,21:18.6
-2,16,21:18.6
-1,16,21:18.14
0,16,21:18.14
-14,17,21:18.6
-13,17,21:18.6
-12,17,21:18.6
-7,17,21:18.6
-6,17,21:18.6
-5,17,21:18.6
-4,17,21:18.6
-3,17,21:18.6
-2,17,21:18.6
-1,17,21:18.6
-14,18,21:18.6
-13,18,21:18.6
-12,18,21:18.6
-8,18,21:18.6
-7,18,21:18.6
-6,18,21:18.6
-5,18,21:18.6
-4,18,21:18.6
-3,18,21:18.6
-14,19,21:18.6
-13,19,21:18.6
-12,19,21:18.6
-10,19,21:18.6
-9,19,21:18.6
-8,19,21:18.6
-7,19,21:18.6
-5,19,21:18.6
-14,20,21:18.6
-13,20,21:18.6
-12,20,21:18.6
-11,20,21:18.6
-10,20,21:18.6
-9,20,21:18.6
-8,20,21:18.6
-7,20,21:18.6
-6,20,21:18.6
-14,21,21:18.6
-12,21,21:18.6
-11,21,21:18.6
-10,21,21:18.6
-9,21,21:18.6
-8,21,21:18.6
-14,22,21:18.6
-13,22,21:18.6
-12,22,21:18.6
-11,22,21:18.6
-10,22,21:18.6
-15,23,21:18.6
-14,23,21:18.6
-13,23,21:18.6
-12,23,21:18.6
-11,23,21:18.6
-16,24,21:18.6
-15,24,21:18.6
-14,24,21:18.6
-13,24,21:18.6
-12,24,21:18.6
-16,25,21:18.6
-15,25,21:18.6
-14,25,21:18.6
-13,25,21:18.6
-16,26,21:18.6
-14,26,21:18.6
-13,26,21:18.6
-17,27,21:18.6
-14,27,21:18.6
13,-31,22:18.6
14,-31,22:18.6
13,-30,22:18.6
14,-30,22:18.6
15,-30,22:18.6
16,-30,22:18.6
12,-29,22:18.6
13,-29,22:18.6
14,-29,22:18.6
15,-29,22:18.6
11,-28,22:18.6
12,-28,22:18.6
13,-28,22:18.6
14,-28,22:18.6
9,-27,22:18.6
10,-27,22:18.6
11,-27,22:18.6
12,-27,22:18.6
13,-27,22:18.6
14,-27,22:18.6
8,-26,22:18.6
9,-26,22:18.6
10,-26,22:18.6
11,-26,22:18.6
12,-26,22:18.6
13,-26,22:18.6
14,-26,22:18.6
6,-25,22:18.6
7,-25,22:18.6
8,-25,22:18.6
9,-25,22:18.6
10,-25,22:18.6
11,-25,22:18.6
12,-25,22:18.6
13,-25,22:18.6
14,-25,22:18.6
5,-24,22:18.6
6,-24,22:18.6
7,-24,22:18.6
8,-24,22:18.6
9,-24,22:18.6
12,-24,22:18.6
13,-24,22:18.6
14,-24,22:18.6
2,-23,22:18.6
3,-23,22:18.6
4,-23,22:18.6
5,-23,22:18.6
6,-23,22:18.6
7,-23,22:18.6
8,-23,22:18.6
12,-23,22:18.6
13,-23,22:18.6
14,-23,22:18.6
1,-22,22:18.6
2,-22,22:18.6
3,-22,22:18.6
4,-22,22:18.6
5,-22,22:18.6
6,-22,22:18.6
12,-22,22:18.6
13,-22,22:18.6
14,-22,22:18.6
-1,-21,22:18.14
0,-21,22:18.14
1,-21,22:18.6
2,-21,22:18.6
3,-21,22:18.6
4,-21,22:18.6
12,-21,22:18.6
13,-21,22:18.6
14,-21,22:18.6
-6,-20,22:17.12
-3,-20,22:18.14
-2,-20,22:18.14
-1,-20,22:18.14
0,-20,22:18.14
1,-20,22:18.6
2,-20,22:18.6
12,-20,22:18.6
13,-20,22:18.6
14,-20,22:18.6
-6,-19,22:17.12
-5,-19,22:17.12
-4,-19,22:18.14
-3,-19,22:18.14
-2,-19,22:18.14
-1,-19,22:18.14
0,-19,22:18.14
1,-19,22:18.14
12,-19,22:18.6
13,-19,22:18.6
14,-19,22:18.6
-7,-18,22:18.14
-6,-18,22:18.14
-5,-18,22:18.14
-4,-18,22:18.14
-3,-18,22:18.14
-2,-18,22:18.14
-1,-18,22:18.14
12,-18,22:18.6
13,-18,22:18.6
14,-18,22:18.6
-11,-17,22:18.14
-10,-17,22:18.14
-9,-17,22:18.14
-8,-17,22:18.14
-7,-17,22:18.14
-6,-17,22:18.14
-5,-17,22:18.14
-4,-17,22:18.14
-3,-17,22:18.14
-2,-17,22:18.14
-1,-17,22:18.14
12,-17,22:18.6
13,-17,22:18.6
14,-17,22:18.6
-15,-16,22:18.6
-14,-16,22:18.6
-13,-16,22:18.6
-12,-16,22:18.6
-11,-16,22:18.6
-10,-16,22:18.14
-9,-16,22:18.14
-8,-16,22:18.14
-7,-16,22:18.14
-6,-16,22:18.14
-5,-16,22:18.14
-4,-16,22:18.14
-3,-16,22:18.14
-2,-16,22:18.14
-1,-16,22:18.14
0,-16,22:18.14
1,-16,22:18.14
2,-16,22:18.14
12,-16,22:18.6
13,-16,22:18.6
14,-16,22:18.6
-19,-15,22:18.6
-18,-15,22:18.6
-17,-15,22:18.6
-16,-15,22:18.6
-15,-15,22:18.6
-14,-15,22:18.6
-13,-15,22:18.6
-12,-15,22:18.6
-11,-15,22:18.6
-10,-15,22:18.14
-9,-15,22:18.14
-8,-15,22:18.14
-7,-15,22:18.14
-6,-15,22:18.14
-3,-15,22:18.14
-2,-15,22:18.14
-1,-15,22:18.14
0,-15,22:18.14
1,-15,22:18.14
2,-15,22:18.14
3,-15,22:18.6
4,-15,22:18.6
5,-15,22:18.6
6,-15,22:18.6
12,-15,22:18.6
13,-15,22:18.6
14,-15,22:18.6
-22,-14,22:18.14
-21,-14,22:18.14
-20,-14,22:18.14
-19,-14,22:18.14
-18,-14,22:18.14
-17,-14,22:18.14
-16,-14,22:18.14
-15,-14,22:18.14
-14,-14,22:18.6
-13,-14,22:18.6
-12,-14,22:18.6
-9,-14,22:18.14
-8,-14,22:18.14
-7,-14,22:18.14
1,-14,22:18.14
2,-14,22:18.14
3,-14,22:18.6
4,-14,22:18.6
5,-14,22:18.6
6,-14,22:18.6
7,-14,22:18.6
12,-14,22:18.6
13,-14,22:18.6
14,-14,22:18.6
-24,-13,22:18.6
-23,-13,22:18.14
-22,-13,22:18.14
-21,-13,22:18.14
-20,-13,22:18.14
-19,-13,22:18.14
-18,-13,22:18.14
-17,-13,22:18.14
-16,-13,22:18.14
-15,-13,22:18.14
-10,-13,22:18.14
-9,-13,22:18.14
-8,-13,22:18.14
4,-13,22:18.6
5,-13,22:18.6
6,-13,22:18.6
7,-13,22:18.6
8,-13,22:18.6
13,-13,22:18.6
14,-13,22:18.6
15,-13,22:18.6
-24,-12,22:18.6
-23,-12,22:18.14
-22,-12,22:18.14
-21,-12,22:18.14
-20,-12,22:18.14
-19,-12,22:18.14
-11,-12,22:18.14
-10,-12,22:18.14
-9,-12,22:18.14
-8,-12,22:18.14
6,-12,22:18.6
7,-12,22:18.6
8,-12,22:18.6
9,-12,22:18.14
13,-12,22:18.14
14,-12,22:18.14
15,-12,22:18.14
-24,-11,22:18.6
-23,-11,22:18.14
-22,-11,22:18.14
-21,-11,22:18.14
-12,-11,22:18.14
-11,-11,22:18.14
-10,-11,22:18.14
-9,-11,22:18.14
7,-11,22:18.14
8,-11,22:18.14
9,-11,22:18.14
10,-11,22:18.14
11,-11,22:18.14
13,-11,22:18.14
14,-11,22:18.14
15,-11,22:18.14
-24,-10,22:18.6
-23,-10,22:18.14
-22,-10,22:18.14
-12,-10,22:18.14
-11,-10,22:18.14
-10,-10,22:18.14
9,-10,22:18.14
10,-10,22:18.14
11,-10,22:18.14
12,-10,22:18.14
13,-10,22:18.14
14,-10,22:18.14
15,-10,22:18.14
-23,-9,22:18.14
-22,-9,22:18.14
-21,-9,22:18.14
-13,-9,22:18.14
-12,-9,22:18.14
-11,-9,22:18.14
10,-9,22:18.14
11,-9,22:18.14
12,-9,22:18.14
13,-9,22:18.14
14,-9,22:18.14
15,-9,22:18.14
-24,-8,22:18.6
-23,-8,22:18.14
-22,-8,22:18.14
-21,-8,22:18.14
-14,-8,22:18.14
-13,-8,22:18.14
-12,-8,22:18.14
11,-8,22:18.14
12,-8,22:18.14
13,-8,22:18.14
14,-8,22:18.14
15,-8,22:17.12
16,-8,22:17.12
17,-8,22:17.12
-24,-7,22:18.6
-23,-7,22:18.14
-22,-7,22:18.14
-21,-7,22:18.14
-20,-7,22:18.14
-14,-7,22:18.14
-13,-7,22:18.14
-12,-7,22:18.14
12,-7,22:18.14
13,-7,22:18.14
14,-7,22:18.14
15,-7,22:18.14
-24,-6,22:18.6
-23,-6,22:18.14
-22,-6,22:18.14
-21,-6,22:18.14
-20,-6,22:18.14
-14,-6,22:18.14
-13,-6,22:18.14
13,-6,22:18.14
14,-6,22:18.14
15,-6,22:18.14
16,-6,22:18.14
-24,-5,22:18.6
-22,-5,22:18.6
-21,-5,22:18.6
-20,-5,22:18.14
-19,-5,22:18.14
-15,-5,22:18.14
-14,-5,22:18.14
-13,-5,22:18.14
13,-5,22:18.14
14,-5,22:18.14
15,-5,22:18.14
16,-5,22:18.14
-24,-4,22:18.6
-22,-4,22:18.6
-21,-4,22:18.6
-20,-4,22:18.6
-19,-4,22:18.6
-15,-4,22:18.14
-14,-4,22:18.14
-13,-4,22:18.14
13,-4,22:18.14
14,-4,22:18.14
15,-4,22:18.14
16,-4,22:18.14
17,-4,22:18.14
-21,-3,22:18.6
-20,-3,22:18.6
-19,-3,22:18.6
-15,-3,22:18.14
-14,-3,22:18.14
-13,-3,22:18.14
12,-3,22:18.14
14,-3,22:18.14
15,-3,22:18.14
16,-3,22:18.14
17,-3,22:18.14
-21,-2,22:18.6
-20,-2,22:18.6
-19,-2,22:18.6
-18,-2,22:18.6
-15,-2,22:18.14
-14,-2,22:18.14
12,-2,22:18.14
13,-2,22:18.14
14,-2,22:18.14
15,-2,22:18.14
16,-2,22:18.14
17,-2,22:18.6
18,-2,22:18.6
-20,-1,22:18.6
-19,-1,22:18.6
-18,-1,22:18.14
-16,-1,22:18.14
-15,-1,22:18.14
-14,-1,22:18.14
12,-1,22:18.14
13,-1,22:18.14
14,-1,22:18.6
16,-1,22:18.6
17,-1,22:18.6
18,-1,22:18.6
-20,0,22:18.14
-19,0,22:18.14
-18,0,22:18.14
-17,0,22:18.14
-16,0,22:18.14
-15,0,22:18.14
-14,0,22:18.14
12,0,22:18.14
13,0,22:18.14
14,0,22:18.14
16,0,22:18.14
17,0,22:18.6
18,0,22:18.6
19,0,22:18.6
-19,1,22:18.14
-18,1,22:18.14
-17,1,22:18.14
-16,1,22:18.14
-15,1,22:18.14
-14,1,22:18.14
12,1,22:18.14
13,1,22:18.14
14,1,22:18.14
17,1,22:18.14
18,1,22:18.6
19,1,22:18.6
-19,2,22:18.14
-18,2,22:18.14
-17,2,22:18.14
-16,2,22:18.14
-15,2,22:18.14
12,2,22:18.14
13,2,22:18.14
17,2,22:18.14
18,2,22:18.14
19,2,22:18.14
20,2,22:18.6
-18,3,22:18.14
-17,3,22:18.14
-16,3,22:18.14
-15,3,22:18.14
11,3,22:18.14
12,3,22:18.14
13,3,22:18.14
18,3,22:18.14
19,3,22:18.14
20,3,22:18.6
-18,4,22:18.14
-17,4,22:18.14
-16,4,22:18.14
-15,4,22:18.14
11,4,22:18.14
12,4,22:18.14
13,4,22:18.14
18,4,22:18.14
19,4,22:18.14
20,4,22:18.6
21,4,22:18.6
-18,5,22:17.12
-17,5,22:18.14
-16,5,22:18.14
-15,5,22:18.14
-14,5,22:18.14
11,5,22:18.14
12,5,22:18.14
13,5,22:18.14
19,5,22:18.14
20,5,22:18.6
21,5,22:18.6
-17,6,22:18.14
-16,6,22:18.14
-15,6,22:18.14
-14,6,22:18.14
-13,6,22:18.14
-12,6,22:18.14
10,6,22:18.14
11,6,22:18.14
12,6,22:18.14
19,6,22:18.14
20,6,22:18.6
21,6,22:18.6
22,6,22:18.6
-17,7,22:18.14
-16,7,22:18.14
-15,7,22:18.14
-14,7,22:18.14
-13,7,22:18.14
-12,7,22:18.14
-11,7,22:18.14
-10,7,22:18.14
9,7,22:18.14
10,7,22:18.14
11,7,22:18.14
12,7,22:18.14
20,7,22:18.6
21,7,22:18.6
22,7,22:18.6
-17,8,22:18.14
-16,8,22:18.14
-15,8,22:18.14
-13,8,22:18.14
-12,8,22:18.14
-11,8,22:18.14
-10,8,22:18.14
-9,8,22:18.14
-8,8,22:18.6
8,8,22:18.14
9,8,22:18.14
10,8,22:18.14
11,8,22:18.14
20,8,22:18.6
21,8,22:18.6
22,8,22:18.6
23,8,22:18.6
-17,9,22:18.14
-16,9,22:18.14
-15,9,22:18.14
-11,9,22:18.6
-10,9,22:18.6
-9,9,22:18.6
-8,9,22:18.6
-7,9,22:18.6
-6,9,22:18.6
8,9,22:18.14
9,9,22:18.14
10,9,22:18.14
21,9,22:18.6
22,9,22:18.6
23,9,22:18.6
-17,10,22:18.6
-16,10,22:18.6
-15,10,22:18.6
-9,10,22:18.6
-8,10,22:18.6
-7,10,22:18.6
-5,10,22:18.6
-4,10,22:18.6
7,10,22:18.14
8,10,22:18.14
9,10,22:18.14
10,10,22:18.14
18,10,22:18.14
19,10,22:18.14
20,10,22:18.6
21,10,22:18.6
22,10,22:18.6
23,10,22:18.6
24,10,22:18.6
25,10,22:18.6
-17,11,22:18.6
-16,11,22:18.6
-15,11,22:18.6
-7,11,22:18.6
-6,11,22:18.6
-5,11,22:18.6
-4,11,22:18.6
-3,11,22:18.14
-2,11,22:18.14
6,11,22:18.14
7,11,22:18.14
8,11,22:18.14
9,11,22:18.14
14,11,22:18.6
15,11,22:18.6
16,11,22:18.6
17,11,22:18.6
19,11,22:18.6
20,11,22:18.6
21,11,22:18.6
22,11,22:18.6
23,11,22:18.6
24,11,22:18.6
25,11,22:18.6
26,11,22:18.6
27,11,22:18.6
28,11,22:18.6
-17,12,22:18.6
-16,12,22:18.6
-15,12,22:18.6
-5,12,22:18.6
-4,12,22:18.6
-3,12,22:18.6
-2,12,22:18.14
-1,12,22:18.14
0,12,22:18.14
1,12,22:18.14
6,12,22:18.14
7,12,22:18.14
8,12,22:18.14
10,12,22:18.6
11,12,22:18.6
12,12,22:18.6
13,12,22:18.6
14,12,22:18.6
15,12,22:18.6
16,12,22:18.6
17,12,22:18.6
18,12,22:18.6
19,12,22:18.6
20,12,22:18.6
21,12,22:18.6
22,12,22:18.6
23,12,22:18.6
24,12,22:18.6
25,12,22:18.6
26,12,22:18.6
27,12,22:18.6
28,12,22:18.6
29,12,22:18.6
-17,13,22:18.6
-16,13,22:18.6
-15,13,22:18.6
-3,13,22:18.6
-2,13,22:18.14
-1,13,22:18.14
0,13,22:18.14
1,13,22:18.14
2,13,22:18.14
3,13,22:18.14
5,13,22:18.14
6,13,22:18.14
7,13,22:18.14
8,13,22:18.14
9,13,22:18.14
10,13,22:18.6
11,13,22:18.6
12,13,22:18.6
13,13,22:18.6
14,13,22:18.6
15,13,22:18.6
17,13,22:18.6
18,13,22:18.6
19,13,22:18.6
24,13,22:18.6
25,13,22:18.6
26,13,22:18.6
-17,14,22:18.6
-16,14,22:18.6
-15,14,22:18.6
-1,14,22:18.14
0,14,22:18.14
1,14,22:18.14
2,14,22:18.14
3,14,22:18.14
4,14,22:18.14
5,14,22:18.14
6,14,22:18.14
7,14,22:18.14
8,14,22:18.14
9,14,22:18.14
10,14,22:18.6
11,14,22:18.6
12,14,22:18.6
13,14,22:18.6
14,14,22:18.6
15,14,22:18.6
16,14,22:18.6
26,14,22:18.6
-17,15,22:18.6
-16,15,22:18.6
-15,15,22:18.6
1,15,22:18.14
2,15,22:18.14
3,15,22:18.14
4,15,22:18.14
5,15,22:18.14
6,15,22:18.14
7,15,22:18.14
8,15,22:18.14
9,15,22:18.14
10,15,22:18.6
11,15,22:18.6
26,15,22:18.6
27,15,22:18.6
-17,16,22:18.6
-16,16,22:18.6
-15,16,22:18.6
0,16,22:18.14
1,16,22:18.14
2,16,22:18.14
3,16,22:18.14
4,16,22:18.14
5,16,22:17.12
6,16,22:18.14
7,16,22:18.14
8,16,22:18.14
-17,17,22:18.6
-16,17,22:18.6
-15,17,22:18.6
-1,17,22:18.6
0,17,22:18.14
1,17,22:18.14
2,17,22:18.14
3,17,22:18.14
4,17,22:18.14
5,17,22:17.12
-17,18,22:18.6
-16,18,22:18.6
-15,18,22:18.6
-3,18,22:18.6
-2,18,22:18.6
-1,18,22:18.6
0,18,22:18.14
1,18,22:18.14
2,18,22:18.14
3,18,22:18.14
-17,19,22:18.6
-16,19,22:18.6
-15,19,22:18.6
-4,19,22:18.6
-3,19,22:18.6
-2,19,22:18.6
-1,19,22:18.6
0,19,22:18.6
1,19,22:18.14
-17,20,22:18.6
-16,20,22:18.6
-15,20,22:18.6
-6,20,22:18.6
-5,20,22:18.6
-4,20,22:18.6
-3,20,22:18.6
-2,20,22:18.14
-1,20,22:18.14
-17,21,22:18.6
-16,21,22:18.6
-15,21,22:18.6
-7,21,22:18.6
-6,21,22:18.6
-5,21,22:18.6
-4,21,22:18.6
-3,21,22:18.14
-2,21,22:18.14
-17,22,22:18.6
-16,22,22:18.6
-15,22,22:18.6
-9,22,22:18.6
-8,22,22:18.6
-7,22,22:18.6
-6,22,22:18.6
-5,22,22:18.6
-4,22,22:18.6
-17,23,22:18.6
-16,23,22:18.6
-15,23,22:18.6
-11,23,22:18.6
-10,23,22:18.6
-9,23,22:18.6
-8,23,22:18.6
-7,23,22:18.6
-6,23,22:18.6
-17,24,22:18.6
-16,24,22:18.6
-15,24,22:18.6
-14,24,22:18.6
-13,24,22:18.6
-12,24,22:18.6
-11,24,22:18.6
-10,24,22:18.6
-9,24,22:18.6
-8,24,22:18.6
-7,24,22:18.6
-16,25,22:18.6
-15,25,22:18.6
-14,25,22:18.6
-13,25,22:18.6
-12,25,22:18.6
-11,25,22:18.6
-10,25,22:18.6
-9,25,22:18.6
-16,26,22:18.6
-15,26,22:18.6
-14,26,22:18.6
-13,26,22:18.6
-12,26,22:18.6
-16,27,22:18.6
-15,27,22:18.6
-17,28,22:18.6
-16,28,22:18.6
-15,28,22:18.6
-16,29,22:18.6
14,-31,23:18.6
15,-31,23:18.6
10,-30,23:18.6
11,-30,23:18.6
12,-30,23:18.6
13,-30,23:18.6
14,-30,23:18.6
15,-30,23:18.6
8,-29,23:18.6
9,-29,23:18.6
10,-29,23:18.6
11,-29,23:18.6
12,-29,23:18.6
13,-29,23:18.6
14,-29,23:18.6
15,-29,23:18.6
6,-28,23:18.6
7,-28,23:18.6
8,-28,23:18.6
9,-28,23:18.6
10,-28,23:18.6
11,-28,23:18.6
14,-28,23:18.6
15,-28,23:18.6
4,-27,23:18.6
5,-27,23:18.6
6,-27,23:18.6
7,-27,23:18.6
8,-27,23:18.6
9,-27,23:18.6
14,-27,23:18.6
15,-27,23:18.6
16,-27,23:18.6
3,-26,23:18.6
4,-26,23:18.6
5,-26,23:18.6
6,-26,23:18.6
7,-26,23:18.6
8,-26,23:18.6
14,-26,23:18.6
15,-26,23:18.6
16,-26,23:18.6
1,-25,23:18.6
2,-25,23:18.6
3,-25,23:18.6
4,-25,23:18.6
5,-25,23:18.6
6,-25,23:18.6
14,-25,23:18.6
15,-25,23:18.6
16,-25,23:18.6
-1,-24,23:18.6
0,-24,23:18.6
1,-24,23:18.6
2,-24,23:18.6
3,-24,23:18.6
4,-24,23:18.6
14,-24,23:18.6
15,-24,23:18.6
16,-24,23:18.6
-3,-23,23:18.14
-2,-23,23:18.14
-1,-23,23:18.14
0,-23,23:18.6
1,-23,23:18.6
2,-23,23:18.6
14,-23,23:18.6
15,-23,23:18.6
16,-23,23:18.6
-5,-22,23:18.14
-4,-22,23:18.14
-3,-22,23:18.14
-2,-22,23:18.14
-1,-22,23:18.14
0,-22,23:18.6
1,-22,23:18.6
14,-22,23:18.6
15,-22,23:18.6
16,-22,23:18.6
-7,-21,23:17.12
-5,-21,23:18.14
-4,-21,23:18.14
-3,-21,23:18.14
-2,-21,23:18.14
-1,-21,23:18.14
15,-21,23:18.6
16,-21,23:18.6
-10,-20,23:18.14
-9,-20,23:18.14
-8,-20,23:18.14
-7,-20,23:18.14
-6,-20,23:18.14
-5,-20,23:18.14
-4,-20,23:18.14
-3,-20,23:18.14
15,-20,23:18.6
16,-20,23:18.6
17,-20,23:18.6
-13,-19,23:18.6
-11,-19,23:18.14
-10,-19,23:18.14
-9,-19,23:18.14
-8,-19,23:18.14
-7,-19,23:18.14
-6,-19,23:18.14
-5,-19,23:18.14
-4,-19,23:18.14
-3,-19,23:18.14
-2,-19,23:18.14
-1,-19,23:18.14
15,-19,23:18.6
16,-19,23:18.6
-17,-18,23:18.6
-16,-18,23:18.6
-15,-18,23:18.6
-14,-18,23:18.6
-13,-18,23:18.6
-12,-18,23:18.6
-11,-18,23:18.14
-10,-18,23:18.14
-9,-18,23:18.14
-8,-18,23:18.14
-7,-18,23:18.14
-6,-18,23:18.14
-5,-18,23:18.14
-4,-18,23:18.14
-3,-18,23:18.14
-2,-18,23:18.14
-1,-18,23:18.14
0,-18,23:18.14
1,-18,23:18.14
2,-18,23:18.6
3,-18,23:18.6
15,-18,23:18.6
16,-18,23:18.6
17,-18,23:18.6
-21,-17,23:18.6
-20,-17,23:18.6
-19,-17,23:18.6
-18,-17,23:18.6
-17,-17,23:18.6
-16,-17,23:18.6
-15,-17,23:18.6
-14,-17,23:18.6
-13,-17,23:18.6
-12,-17,23:18.6
-11,-17,23:18.14
-10,-17,23:18.14
-9,-17,23:18.14
-8,-17,23:18.14
-7,-17,23:18.14
-2,-17,23:18.14
-1,-17,23:18.14
0,-17,23:18.14
1,-17,23:18.14
2,-17,23:18.6
3,-17,23:18.6
4,-17,23:18.6
5,-17,23:18.6
6,-17,23:18.6
15,-17,23:18.6
16,-17,23:18.6
17,-17,23:18.6
-24,-16,23:18.6
-23,-16,23:18.6
-22,-16,23:18.6
-21,-16,23:18.6
-20,-16,23:18.6
-19,-16,23:18.6
-18,-16,23:18.6
-17,-16,23:18.6
-16,-16,23:18.6
-15,-16,23:18.6
-14,-16,23:18.6
-10,-16,23:18.14
-9,-16,23:18.14
-8,-16,23:18.14
2,-16,23:18.6
3,-16,23:18.6
4,-16,23:18.6
6,-16,23:18.6
7,-16,23:18.6
8,-16,23:18.6
15,-16,23:18.6
16,-16,23:18.6
17,-16,23:18.6
-24,-15,23:18.6
-23,-15,23:18.6
-22,-15,23:18.6
-21,-15,23:18.6
-20,-15,23:18.6
-19,-15,23:18.6
-18,-15,23:18.6
-11,-15,23:18.6
-10,-15,23:18.14
-9,-15,23:18.14
5,-15,23:18.6
6,-15,23:18.6
7,-15,23:18.6
8,-15,23:18.6
9,-15,23:18.6
15,-15,23:18.6
16,-15,23:18.6
17,-15,23:18.6
-24,-14,23:18.6
-23,-14,23:18.14
-22,-14,23:18.14
-12,-14,23:18.6
-11,-14,23:18.6
-10,-14,23:18.6
7,-14,23:18.6
8,-14,23:18.6
9,-14,23:18.6
15,-14,23:18.6
16,-14,23:18.6
17,-14,23:18.6
-24,-13,23:18.6
-23,-13,23:18.14
-22,-13,23:18.14
-21,-13,23:18.14
-20,-13,23:18.14
-13,-13,23:18.14
-12,-13,23:18.14
-11,-13,23:18.14
-10,-13,23:18.6
8,-13,23:18.6
9,-13,23:18.6
10,-13,23:18.6
11,-13,23:18.6
12,-13,23:18.6
15,-13,23:18.6
16,-13,23:18.6
17,-13,23:18.6
-24,-12,23:18.6
-23,-12,23:18.14
-22,-12,23:18.14
-21,-12,23:18.14
-20,-12,23:18.14
-14,-12,23:18.14
-13,-12,23:18.14
-12,-12,23:18.14
-11,-12,23:18.14
10,-12,23:18.14
11,-12,23:18.14
12,-12,23:18.14
13,-12,23:18.14
15,-12,23:18.14
16,-12,23:18.14
17,-12,23:18.14
-22,-11,23:18.14
-21,-11,23:18.14
-14,-11,23:18.14
-13,-11,23:18.14
-12,-11,23:18.14
11,-11,23:18.14
12,-11,23:18.14
13,-11,23:18.14
14,-11,23:18.14
15,-11,23:18.14
16,-11,23:18.14
17,-11,23:18.14
-22,-10,23:18.14
-21,-10,23:18.14
-15,-10,23:18.14
-14,-10,23:18.14
-13,-10,23:18.14
12,-10,23:18.14
13,-10,23:18.14
14,-10,23:18.14
15,-10,23:18.14
16,-10,23:18.14
17,-10,23:18.14
-22,-9,23:18.14
-21,-9,23:18.14
-16,-9,23:18.14
-15,-9,23:18.14
13,-9,23:18.14
14,-9,23:18.14
15,-9,23:18.14
16,-9,23:18.14
17,-9,23:18.14
18,-9,23:17.12
-24,-8,23:18.6
-23,-8,23:18.14
-22,-8,23:18.14
-16,-8,23:18.14
-15,-8,23:18.14
-14,-8,23:18.14
15,-8,23:18.14
16,-8,23:18.14
17,-8,23:18.14
18,-8,23:17.12
-24,-7,23:18.6
-23,-7,23:18.14
-22,-7,23:18.14
-16,-7,23:18.14
-15,-7,23:18.14
-14,-7,23:18.14
15,-7,23:18.14
16,-7,23:18.14
17,-7,23:18.14
18,-7,23:18.14
-24,-6,23:18.6
-23,-6,23:18.14
-22,-6,23:18.14
-16,-6,23:18.14
-15,-6,23:18.14
15,-6,23:18.14
16,-6,23:18.14
17,-6,23:18.14
18,-6,23:18.14
-24,-5,23:18.6
-23,-5,23:18.6
-17,-5,23:18.14
-16,-5,23:18.14
-15,-5,23:18.14
15,-5,23:18.14
16,-5,23:18.14
17,-5,23:18.14
18,-5,23:18.14
19,-5,23:18.14
-24,-4,23:18.6
-23,-4,23:18.6
-22,-4,23:18.6
-17,-4,23:18.6
-16,-4,23:18.6
-15,-4,23:18.6
15,-4,23:18.14
16,-4,23:18.14
17,-4,23:18.14
18,-4,23:18.14
19,-4,23:18.14
-24,-3,23:18.6
-23,-3,23:18.6
-22,-3,23:18.6
-17,-3,23:18.6
-16,-3,23:18.6
15,-3,23:18.14
16,-3,23:18.14
17,-3,23:18.14
18,-3,23:18.14
19,-3,23:18.14
20,-3,23:18.6
-24,-2,23:18.6
-23,-2,23:18.6
-22,-2,23:18.6
-18,-2,23:18.6
-17,-2,23:18.6
-16,-2,23:18.14
14,-2,23:18.14
15,-2,23:18.14
16,-2,23:18.14
18,-2,23:18.6
19,-2,23:18.6
20,-2,23:18.6
-24,-1,23:18.6
-23,-1,23:18.6
-22,-1,23:18.6
-21,-1,23:18.6
-18,-1,23:18.14
-17,-1,23:18.14
-16,-1,23:18.14
14,-1,23:18.6
15,-1,23:18.6
16,-1,23:18.6
19,-1,23:18.6
20,-1,23:18.6
-24,0,23:18.6
-23,0,23:18.6
-22,0,23:18.6
-21,0,23:18.6
-20,0,23:18.14
-18,0,23:18.14
-17,0,23:18.14
-16,0,23:18.14
14,0,23:18.6
15,0,23:18.6
16,0,23:18.6
19,0,23:18.6
20,0,23:18.6
21,0,23:18.6
-24,1,23:18.6
-22,1,23:18.14
-21,1,23:18.14
-19,1,23:18.14
-18,1,23:18.14
-17,1,23:18.14
14,1,23:18.14
15,1,23:18.14
16,1,23:18.14
20,1,23:18.6
21,1,23:18.6
22,1,23:18.6
-24,2,23:18.6
-23,2,23:18.6
-22,2,23:18.14
-21,2,23:18.14
-20,2,23:18.14
-19,2,23:18.14
-18,2,23:18.14
-17,2,23:18.14
14,2,23:18.14
15,2,23:18.14
16,2,23:18.14
20,2,23:18.6
21,2,23:18.6
22,2,23:18.6
23,2,23:18.6
-24,3,23:18.6
-21,3,23:18.14
-20,3,23:18.14
-19,3,23:18.14
-18,3,23:18.14
-17,3,23:18.14
14,3,23:18.14
15,3,23:18.14
21,3,23:18.6
22,3,23:18.6
23,3,23:18.6
-24,4,23:18.6
-21,4,23:18.14
-20,4,23:18.14
-19,4,23:18.14
-18,4,23:18.14
14,4,23:18.14
15,4,23:18.14
21,4,23:18.6
22,4,23:18.6
23,4,23:18.6
-24,5,23:18.6
-20,5,23:18.14
-19,5,23:18.14
-18,5,23:18.14
13,5,23:18.14
14,5,23:18.14
15,5,23:18.14
22,5,23:18.6
23,5,23:18.6
24,5,23:18.6
-20,6,23:18.14
-19,6,23:18.14
-18,6,23:18.14
-17,6,23:18.14
-16,6,23:18.14
13,6,23:18.14
14,6,23:18.14
15,6,23:18.14
22,6,23:18.6
23,6,23:18.6
24,6,23:18.6
-19,7,23:18.14
-18,7,23:18.14
-17,7,23:18.14
-16,7,23:18.14
-15,7,23:18.14
12,7,23:18.14
13,7,23:18.14
14,7,23:18.14
15,7,23:18.14
23,7,23:18.6
24,7,23:18.6
25,7,23:18.6
-19,8,23:18.14
-18,8,23:18.14
-17,8,23:18.14
-16,8,23:18.14
-15,8,23:18.14
-14,8,23:18.14
-13,8,23:18.14
11,8,23:18.14
12,8,23:18.14
13,8,23:18.14
14,8,23:18.14
23,8,23:18.6
24,8,23:18.6
25,8,23:18.6
26,8,23:18.6
-19,9,23:18.14
-18,9,23:18.14
-16,9,23:18.14
-15,9,23:18.14
-14,9,23:18.14
-13,9,23:18.14
-12,9,23:18.14
-11,9,23:18.6
11,9,23:18.14
12,9,23:18.14
13,9,23:18.14
24,9,23:18.6
25,9,23:18.6
26,9,23:18.6
-19,10,23:18.6
-18,10,23:18.6
-14,10,23:18.6
-13,10,23:18.6
-12,10,23:18.6
-11,10,23:18.6
-10,10,23:18.6
-9,10,23:18.6
10,10,23:18.14
11,10,23:18.14
12,10,23:18.14
24,10,23:18.6
25,10,23:18.6
26,10,23:18.6
-19,11,23:18.6
-18,11,23:18.6
-12,11,23:18.6
-11,11,23:18.6
-10,11,23:18.6
-9,11,23:18.6
-8,11,23:18.6
-7,11,23:18.6
9,11,23:18.14
10,11,23:18.6
11,11,23:18.6
12,11,23:18.6
25,11,23:18.6
26,11,23:18.6
27,11,23:18.6
-23,12,23:18.6
-19,12,23:18.6
-18,12,23:18.6
-10,12,23:18.6
-9,12,23:18.6
-8,12,23:18.6
-7,12,23:18.6
-6,12,23:18.6
-5,12,23:18.6
9,12,23:18.14
10,12,23:18.6
11,12,23:18.6
22,12,23:18.6
23,12,23:18.6
24,12,23:18.6
25,12,23:18.6
26,12,23:18.6
27,12,23:18.6
28,12,23:18.6
-23,13,23:18.6
-19,13,23:18.6
-18,13,23:18.6
-8,13,23:18.6
-7,13,23:18.6
-6,13,23:18.6
-4,13,23:18.6
-3,13,23:18.6
8,13,23:18.14
9,13,23:18.14
10,13,23:18.6
18,13,23:18.6
19,13,23:18.6
20,13,23:18.6
21,13,23:18.6
22,13,23:18.6
23,13,23:18.6
24,13,23:18.6
25,13,23:18.6
26,13,23:18.6
27,13,23:18.6
28,13,23:18.6
29,13,23:18.6
-19,14,23:18.6
-18,14,23:18.6
-17,14,23:18.6
-6,14,23:18.6
-5,14,23:18.6
-4,14,23:18.6
-3,14,23:18.6
-2,14,23:18.6
-1,14,23:18.14
7,14,23:18.14
8,14,23:18.14
9,14,23:18.14
10,14,23:18.6
15,14,23:18.6
16,14,23:18.6
17,14,23:18.6
18,14,23:18.6
19,14,23:18.6
20,14,23:18.6
21,14,23:18.6
22,14,23:18.6
23,14,23:18.6
24,14,23:18.6
25,14,23:18.6
26,14,23:18.6
27,14,23:18.6
28,14,23:18.6
-22,15,23:18.6
-19,15,23:18.6
-18,15,23:18.6
-17,15,23:18.6
-4,15,23:18.6
-3,15,23:18.6
-2,15,23:18.6
-1,15,23:18.14
0,15,23:18.14
1,15,23:18.14
2,15,23:18.14
6,15,23:18.14
7,15,23:18.14
8,15,23:18.14
9,15,23:18.14
11,15,23:18.6
12,15,23:18.6
13,15,23:18.6
14,15,23:18.6
15,15,23:18.6
16,15,23:18.6
17,15,23:18.6
18,15,23:18.6
19,15,23:18.6
20,15,23:18.6
21,15,23:18.6
22,15,23:18.6
23,15,23:18.6
24,15,23:18.6
28,15,23:18.6
-19,16,23:18.6
-18,16,23:18.6
-17,16,23:18.6
-2,16,23:18.6
-1,16,23:18.14
0,16,23:18.14
1,16,23:18.14
2,16,23:18.14
3,16,23:18.14
4,16,23:18.14
6,16,23:18.14
7,16,23:18.14
8,16,23:18.14
9,16,23:18.14
10,16,23:18.6
11,16,23:18.6
12,16,23:18.6
13,16,23:18.6
14,16,23:18.6
15,16,23:18.6
16,16,23:18.6
17,16,23:18.6
18,16,23:18.6
19,16,23:18.6
20,16,23:18.6
-19,17,23:18.6
-18,17,23:18.6
-17,17,23:18.6
1,17,23:18.14
2,17,23:18.14
3,17,23:18.14
4,17,23:18.14
5,17,23:18.14
6,17,23:18.14
7,17,23:18.14
8,17,23:18.14
9,17,23:18.14
10,17,23:18.6
11,17,23:18.6
12,17,23:18.6
13,17,23:18.6
14,17,23:18.6
15,17,23:18.6
-21,18,23:18.6
-18,18,23:18.6
-17,18,23:18.6
3,18,23:18.14
4,18,23:18.14
5,18,23:18.14
6,18,23:18.14
7,18,23:18.14
8,18,23:18.14
-18,19,23:18.6
-17,19,23:18.6
1,19,23:18.14
2,19,23:18.14
3,19,23:18.14
4,19,23:18.14
-18,20,23:18.6
-17,20,23:18.6
0,20,23:18.14
1,20,23:18.14
2,20,23:18.14
-20,21,23:18.6
-18,21,23:18.6
-17,21,23:18.6
-2,21,23:18.14
-18,22,23:18.6
-17,22,23:18.6
-4,22,23:18.6
-3,22,23:18.14
-18,23,23:18.6
-17,23,23:18.6
-5,23,23:18.6
-4,23,23:18.14
-3,23,23:18.14
-18,24,23:18.6
-17,24,23:18.6
-7,24,23:18.6
-6,24,23:18.6
-5,24,23:18.14
-4,24,23:18.14
-18,25,23:18.6
-9,25,23:18.6
-8,25,23:18.6
-7,25,23:18.6
-6,25,23:18.6
-10,26,23:18.6
-9,26,23:18.6
-8,26,23:18.6
-12,27,23:18.6
-11,27,23:18.6
-10,27,23:18.6
-12,28,23:18.6
-11,28,23:18.6
9,-31,24:18.6
10,-31,24:18.6
7,-30,24:18.6
8,-30,24:18.6
9,-30,24:18.6
3,-29,24:18.6
5,-29,24:18.6
6,-29,24:18.6
7,-29,24:18.6
8,-29,24:18.6
17,-29,24:18.6
0,-28,24:18.6
1,-28,24:18.6
2,-28,24:18.6
3,-28,24:18.6
4,-28,24:18.6
5,-28,24:18.6
6,-28,24:18.6
17,-28,24:18.6
-1,-27,24:18.6
0,-27,24:18.6
1,-27,24:18.6
2,-27,24:18.6
3,-27,24:18.6
4,-27,24:18.6
17,-27,24:18.6
-2,-26,24:18.6
-1,-26,24:18.6
0,-26,24:18.6
1,-26,24:18.6
2,-26,24:18.6
3,-26,24:18.6
17,-26,24:18.6
18,-26,24:18.6
-4,-25,24:18.14
-3,-25,24:18.14
-2,-25,24:18.6
-1,-25,24:18.6
0,-25,24:18.6
1,-25,24:18.6
17,-25,24:18.6
18,-25,24:18.6
-6,-24,24:18.14
-5,-24,24:18.14
-4,-24,24:18.14
-3,-24,24:18.14
-2,-24,24:18.14
-1,-24,24:18.6
17,-24,24:18.6
18,-24,24:18.6
-13,-23,24:18.6
-12,-23,24:18.6
-11,-23,24:18.14
-8,-23,24:18.14
-7,-23,24:18.14
-6,-23,24:18.14
-5,-23,24:18.14
-4,-23,24:18.14
-3,-23,24:18.14
17,-23,24:18.6
18,-23,24:18.6
19,-23,24:18.6
-16,-22,24:18.6
-15,-22,24:18.6
-14,-22,24:18.6
-13,-22,24:18.6
-12,-22,24:18.6
-11,-22,24:18.14
-10,-22,24:18.14
-9,-22,24:18.14
-8,-22,24:18.14
-7,-22,24:18.14
-6,-22,24:18.14
-5,-22,24:18.14
-4,-22,24:18.14
-3,-22,24:18.14
17,-22,24:18.6
18,-22,24:18.6
19,-22,24:18.6
-18,-21,24:18.6
-17,-21,24:18.6
-16,-21,24:18.6
-15,-21,24:18.6
-14,-21,24:18.6
-13,-21,24:18.6
-12,-21,24:18.6
-11,-21,24:18.14
-10,-21,24:18.14
-9,-21,24:18.14
-8,-21,24:18.14
-7,-21,24:18.14
-5,-21,24:18.14
-4,-21,24:18.14
-3,-21,24:18.14
-2,-21,24:18.14
-1,-21,24:18.14
0,-21,24:18.14
17,-21,24:18.6
18,-21,24:18.6
19,-21,24:18.6
-20,-20,24:18.6
-19,-20,24:18.6
-18,-20,24:18.6
-17,-20,24:18.6
-15,-20,24:18.6
-14,-20,24:18.6
-13,-20,24:18.6
-12,-20,24:18.6
-11,-20,24:18.14
-10,-20,24:18.14
-9,-20,24:18.14
-8,-20,24:18.14
-5,-20,24:18.14
-4,-20,24:18.14
-3,-20,24:18.14
-2,-20,24:18.14
-1,-20,24:18.14
0,-20,24:18.14
1,-20,24:18.6
2,-20,24:18.6
4,-20,24:18.6
17,-20,24:18.6
18,-20,24:18.6
19,-20,24:18.6
20,-20,24:18.6
-23,-19,24:18.6
-22,-19,24:18.6
-21,-19,24:18.6
-20,-19,24:18.6
-19,-19,24:18.6
-18,-19,24:18.6
-17,-19,24:18.6
-16,-19,24:18.6
-15,-19,24:18.6
-14,-19,24:18.6
-13,-19,24:18.6
-11,-19,24:18.14
-10,-19,24:18.14
-9,-19,24:18.14
-8,-19,24:18.14
-1,-19,24:18.14
0,-19,24:18.14
1,-19,24:18.6
2,-19,24:18.6
3,-19,24:18.6
4,-19,24:18.6
5,-19,24:18.6
6,-19,24:18.6
7,-19,24:18.6
18,-19,24:18.6
19,-19,24:18.6
20,-19,24:18.6
-24,-18,24:18.6
-23,-18,24:18.6
-22,-18,24:18.6
-21,-18,24:18.6
-20,-18,24:18.6
-19,-18,24:18.6
-18,-18,24:18.6
-17,-18,24:18.6
-12,-18,24:18.6
-11,-18,24:18.14
-10,-18,24:18.14
-9,-18,24:18.14
2,-18,24:18.6
3,-18,24:18.6
4,-18,24:18.6
5,-18,24:18.6
6,-18,24:18.6
7,-18,24:18.6
8,-18,24:18.6
9,-18,24:18.6
17,-18,24:18.6
18,-18,24:18.6
19,-18,24:18.6
20,-18,24:18.6
-24,-17,24:18.6
-23,-17,24:18.6
-22,-17,24:18.6
-21,-17,24:18.6
-12,-17,24:18.6
-11,-17,24:18.14
-10,-17,24:18.14
6,-17,24:18.6
7,-17,24:18.6
8,-17,24:18.6
9,-17,24:18.6
10,-17,24:18.6
17,-17,24:18.6
18,-17,24:18.6
19,-17,24:18.6
20,-17,24:18.6
21,-17,24:18.6
-24,-16,24:18.6
-13,-16,24:18.6
-12,-16,24:18.6
-11,-16,24:18.6
8,-16,24:18.6
9,-16,24:18.6
10,-16,24:18.6
11,-16,24:18.6
17,-16,24:18.6
18,-16,24:18.6
19,-16,24:18.6
21,-16,24:18.6
-14,-15,24:18.6
-13,-15,24:18.6
-12,-15,24:18.6
9,-15,24:18.6
10,-15,24:18.6
11,-15,24:18.6
12,-15,24:18.6
13,-15,24:18.6
17,-15,24:18.6
18,-15,24:18.6
19,-15,24:18.6
21,-15,24:18.6
-24,-14,24:18.6
-23,-14,24:18.14
-22,-14,24:18.14
-15,-14,24:18.14
-14,-14,24:18.6
-13,-14,24:18.6
-12,-14,24:18.6
11,-14,24:18.6
12,-14,24:18.6
13,-14,24:18.6
14,-14,24:18.6
17,-14,24:18.6
18,-14,24:18.6
19,-14,24:18.6
21,-14,24:18.6
22,-14,24:18.6
-24,-13,24:18.6
-23,-13,24:18.14
-22,-13,24:18.14
-21,-13,24:18.14
-20,-13,24:18.14
-16,-13,24:18.14
-15,-13,24:18.14
-14,-13,24:18.6
-13,-13,24:18.6
12,-13,24:18.6
13,-13,24:18.6
14,-13,24:18.6
15,-13,24:18.6
17,-13,24:18.6
18,-13,24:18.6
19,-13,24:18.6
22,-13,24:18.6
-20,-12,24:18.14
-19,-12,24:18.14
-16,-12,24:18.14
-15,-12,24:18.14
-14,-12,24:18.6
13,-12,24:18.14
14,-12,24:18.14
15,-12,24:18.14
16,-12,24:18.14
17,-12,24:18.14
18,-12,24:18.14
19,-12,24:18.14
22,-12,24:18.6
-20,-11,24:18.14
-17,-11,24:18.14
-16,-11,24:18.14
-15,-11,24:18.14
14,-11,24:18.14
15,-11,24:18.14
16,-11,24:18.14
17,-11,24:18.14
18,-11,24:18.14
19,-11,24:18.14
20,-11,24:18.14
22,-11,24:18.6
-21,-10,24:18.14
-20,-10,24:18.14
-18,-10,24:18.14
-17,-10,24:18.14
-16,-10,24:18.14
-15,-10,24:18.14
16,-10,24:18.14
17,-10,24:18.14
18,-10,24:18.14
19,-10,24:18.14
20,-10,24:18.14
-21,-9,24:18.14
-20,-9,24:18.14
-18,-9,24:18.14
-17,-9,24:18.14
-16,-9,24:18.14
17,-9,24:18.14
18,-9,24:18.14
19,-9,24:18.14
20,-9,24:18.14
-24,-8,24:18.6
-21,-8,24:18.14
-20,-8,24:18.14
-18,-8,24:18.14
-17,-8,24:18.14
-16,-8,24:18.14
18,-8,24:18.14
19,-8,24:18.14
20,-8,24:18.14
-24,-7,24:18.6
-22,-7,24:18.14
-21,-7,24:18.14
-18,-7,24:18.14
-17,-7,24:18.14
18,-7,24:18.14
19,-7,24:18.14
20,-7,24:18.14
21,-7,24:18.6
-24,-6,24:18.6
-23,-6,24:18.14
-22,-6,24:18.14
-21,-6,24:18.14
-19,-6,24:18.14
-18,-6,24:18.14
-17,-6,24:18.14
17,-6,24:18.14
18,-6,24:18.14
19,-6,24:18.14
20,-6,24:18.14
21,-6,24:18.6
-24,-5,24:18.6
-23,-5,24:18.6
-22,-5,24:18.6
-21,-5,24:18.6
-19,-5,24:18.6
-18,-5,24:18.6
-17,-5,24:18.6
17,-5,24:18.14
18,-5,24:18.14
19,-5,24:18.14
20,-5,24:18.14
21,-5,24:18.6
22,-5,24:18.6
-23,-4,24:18.6
-21,-4,24:18.6
-19,-4,24:18.6
-18,-4,24:18.6
17,-4,24:18.14
18,-4,24:18.14
19,-4,24:18.14
20,-4,24:18.14
21,-4,24:18.6
22,-4,24:18.6
-24,-3,24:18.6
-23,-3,24:18.6
-20,-3,24:18.6
-19,-3,24:18.6
-18,-3,24:18.6
17,-3,24:18.14
18,-3,24:18.14
19,-3,24:18.14
20,-3,24:18.6
21,-3,24:18.6
22,-3,24:18.6
23,-3,24:18.6
25,-3,24:18.6
-24,-2,24:18.6
-23,-2,24:18.6
-20,-2,24:18.6
-19,-2,24:18.6
-18,-2,24:18.6
17,-2,24:18.6
18,-2,24:18.6
19,-2,24:18.6
21,-2,24:18.6
22,-2,24:18.6
23,-2,24:18.6
25,-2,24:18.6
-24,-1,24:18.6
-23,-1,24:18.6
-20,-1,24:18.6
-19,-1,24:18.6
-18,-1,24:18.14
17,-1,24:18.6
18,-1,24:18.6
22,-1,24:18.6
23,-1,24:18.6
24,-1,24:18.6
25,-1,24:18.6
26,-1,24:18.6
-24,0,24:18.6
-23,0,24:18.6
-22,0,24:18.6
-20,0,24:18.14
-19,0,24:18.14
16,0,24:18.6
17,0,24:18.6
18,0,24:18.6
22,0,24:18.6
23,0,24:18.6
24,0,24:18.6
26,0,24:18.6
-24,1,24:18.6
-23,1,24:18.6
-22,1,24:18.14
-19,1,24:18.14
16,1,24:18.6
17,1,24:18.6
18,1,24:18.6
22,1,24:18.6
23,1,24:18.6
24,1,24:18.6
25,1,24:18.6
26,1,24:18.6
-24,2,24:18.6
-23,2,24:18.6
-22,2,24:18.14
-20,2,24:18.14
-19,2,24:18.14
16,2,24:18.6
17,2,24:18.6
18,2,24:18.6
23,2,24:18.6
24,2,24:18.6
25,2,24:18.6
-24,3,24:18.6
-22,3,24:18.14
-21,3,24:18.14
-20,3,24:18.14
16,3,24:18.6
17,3,24:18.6
18,3,24:18.6
23,3,24:18.6
24,3,24:18.6
25,3,24:18.6
-24,4,24:18.6
-23,4,24:18.6
-21,4,24:18.14
-20,4,24:18.14
16,4,24:18.6
17,4,24:18.6
18,4,24:18.6
24,4,24:18.6
25,4,24:18.6
26,4,24:18.6
-24,5,24:18.6
-21,5,24:18.14
-20,5,24:18.14
16,5,24:18.6
17,5,24:18.6
24,5,24:18.6
25,5,24:18.6
26,5,24:18.6
-20,6,24:18.14
15,6,24:18.6
16,6,24:18.6
17,6,24:18.6
25,6,24:18.6
26,6,24:18.6
27,6,24:18.6
-20,7,24:18.14
-19,7,24:18.14
15,7,24:18.6
16,7,24:18.6
17,7,24:18.6
25,7,24:18.6
26,7,24:18.6
27,7,24:18.6
28,7,24:18.6
-23,8,24:18.6
-20,8,24:18.14
-18,8,24:18.14
-17,8,24:18.14
14,8,24:18.6
15,8,24:18.6
16,8,24:18.6
17,8,24:18.6
26,8,24:18.6
27,8,24:18.6
28,8,24:18.6
-23,9,24:18.6
-20,9,24:18.14
-19,9,24:18.14
-17,9,24:18.14
-16,9,24:18.14
-15,9,24:18.14
14,9,24:18.6
15,9,24:18.6
16,9,24:18.6
26,9,24:18.6
27,9,24:18.6
28,9,24:18.6
-23,10,24:18.6
-20,10,24:18.6
-19,10,24:18.6
-16,10,24:18.6
-15,10,24:18.6
