[META]
version=2.0
spawnOnBlockType=2
spawnSunlight=True
spawnDarkness=True
spawnWater=False
spawnLava=False
underFill=False
randomRotation=True
dig=True
tree=False
branch=False
needsFoundation=True
rarity=100
collisionPercentage=20
spawnElevationMin=0
spawnElevationMax=200
spawnInBiome=Custom
[DATA]
19,-11,-8:17.13
11,-10,-8:17.13
18,-10,-8:17.13
19,-10,-8:17.13
20,-10,-8:17.13
7,-8,-8:17.13
6,-7,-8:17.13
7,-7,-8:17.13
8,-7,-8:17.13
8,-6,-8:17.13
17,-5,-8:17.13
18,-5,-8:17.13
8,-4,-8:17.13
21,-3,-8:17.13
22,-2,-8:17.13
21,-1,-8:17.13
13,2,-8:17.13
14,2,-8:17.13
13,3,-8:17.13
12,-11,-7:17.13
19,-11,-7:17.13
12,-10,-7:17.13
13,-10,-7:17.13
18,-10,-7:17.13
19,-10,-7:17.13
20,-10,-7:17.13
6,-9,-7:17.13
7,-9,-7:17.13
12,-9,-7:17.13
19,-9,-7:17.13
20,-9,-7:17.13
9,-8,-7:17.13
5,-7,-7:17.13
7,-7,-7:17.13
9,-7,-7:17.13
6,-6,-7:17.13
8,-6,-7:17.13
17,-6,-7:17.13
18,-6,-7:17.13
19,-6,-7:17.13
7,-5,-7:17.13
8,-5,-7:17.13
16,-5,-7:17.13
17,-5,-7:17.13
18,-5,-7:17.13
6,-4,-7:17.13
7,-4,-7:17.13
8,-4,-7:17.13
17,-4,-7:17.13
18,-4,-7:17.13
19,-4,-7:17.13
7,-3,-7:17.13
20,-3,-7:17.13
21,-3,-7:17.13
19,-2,-7:17.13
20,-2,-7:17.13
21,-2,-7:17.13
22,-2,-7:17.13
13,-1,-7:17.13
20,-1,-7:17.13
21,-1,-7:17.13
13,0,-7:17.13
14,0,-7:17.13
13,1,-7:17.13
14,1,-7:17.13
12,2,-7:17.13
13,2,-7:17.13
13,3,-7:17.13
14,3,-7:17.13
11,-11,-6:17.13
12,-11,-6:17.13
19,-11,-6:17.13
11,-10,-6:17.13
12,-10,-6:17.13
19,-10,-6:17.13
20,-10,-6:17.13
6,-9,-6:17.13
12,-9,-6:17.13
18,-9,-6:17.13
19,-9,-6:17.13
20,-9,-6:17.13
5,-8,-6:17.13
8,-8,-6:17.13
19,-8,-6:17.13
5,-7,-6:17.13
6,-7,-6:17.13
7,-7,-6:17.13
8,-7,-6:17.13
7,-6,-6:17.13
8,-6,-6:17.13
17,-6,-6:17.13
18,-6,-6:17.13
6,-5,-6:17.13
7,-5,-6:17.13
17,-5,-6:17.13
18,-5,-6:17.13
19,-5,-6:17.13
6,-4,-6:17.13
7,-4,-6:17.13
17,-4,-6:17.13
18,-4,-6:17.13
19,-4,-6:17.13
6,-3,-6:17.13
7,-3,-6:17.13
8,-3,-6:17.13
17,-3,-6:17.13
19,-3,-6:17.13
20,-3,-6:17.13
6,-2,-6:17.13
7,-2,-6:17.13
19,-2,-6:17.13
20,-2,-6:17.13
21,-2,-6:17.13
22,-2,-6:17.13
13,-1,-6:17.13
19,-1,-6:17.13
20,-1,-6:17.13
21,-1,-6:17.13
12,0,-6:17.13
13,0,-6:17.13
14,0,-6:17.13
12,1,-6:17.13
13,1,-6:17.13
14,1,-6:17.13
12,2,-6:17.13
13,2,-6:17.13
12,-12,-5:17.13
12,-11,-5:17.13
14,-11,-5:17.13
19,-11,-5:17.13
11,-10,-5:17.13
12,-10,-5:17.13
18,-10,-5:17.13
19,-10,-5:17.13
20,-10,-5:17.13
21,-10,-5:17.13
7,-9,-5:17.13
8,-9,-5:17.13
18,-9,-5:17.13
19,-9,-5:17.13
20,-9,-5:17.13
21,-9,-5:17.13
7,-8,-5:17.13
8,-8,-5:17.13
9,-8,-5:17.13
19,-8,-5:17.13
21,-8,-5:17.13
6,-7,-5:17.13
7,-7,-5:17.13
8,-7,-5:17.13
9,-7,-5:17.13
7,-6,-5:17.13
8,-6,-5:17.13
9,-6,-5:17.13
7,-5,-5:17.13
16,-5,-5:17.13
17,-5,-5:17.13
18,-5,-5:17.13
20,-5,-5:17.13
6,-4,-5:17.13
7,-4,-5:17.13
8,-4,-5:17.13
18,-4,-5:17.13
19,-4,-5:17.13
20,-4,-5:17.13
6,-3,-5:17.13
7,-3,-5:17.13
8,-3,-5:17.13
18,-3,-5:17.13
19,-3,-5:17.13
20,-3,-5:17.13
21,-3,-5:17.13
6,-2,-5:17.13
7,-2,-5:17.13
8,-2,-5:17.13
19,-2,-5:17.13
20,-2,-5:17.13
21,-2,-5:17.13
12,-1,-5:17.13
13,-1,-5:17.13
14,-1,-5:17.13
20,-1,-5:17.13
21,-1,-5:17.13
12,0,-5:17.13
13,0,-5:17.13
14,0,-5:17.13
12,1,-5:17.13
13,1,-5:17.13
14,1,-5:17.13
13,2,-5:17.13
12,-12,-4:17.13
13,-12,-4:17.13
11,-11,-4:17.13
13,-11,-4:17.13
14,-11,-4:17.13
20,-11,-4:17.13
12,-10,-4:17.13
13,-10,-4:17.13
19,-10,-4:17.13
20,-10,-4:17.13
21,-10,-4:17.13
18,-9,-4:17.13
19,-9,-4:17.13
20,-9,-4:17.13
21,-9,-4:17.13
7,-8,-4:17.13
8,-8,-4:17.13
9,-8,-4:17.13
20,-8,-4:17.13
21,-8,-4:17.13
6,-7,-4:17.13
7,-7,-4:17.13
8,-7,-4:17.13
9,-7,-4:17.13
10,-7,-4:17.13
7,-6,-4:17.13
8,-6,-4:17.13
9,-6,-4:17.13
19,-5,-4:17.13
8,-4,-4:17.13
19,-4,-4:17.13
6,-3,-4:17.13
7,-3,-4:17.13
8,-3,-4:17.13
9,-3,-4:17.13
18,-3,-4:17.13
19,-3,-4:17.13
20,-3,-4:17.13
21,-3,-4:17.13
7,-2,-4:17.13
8,-2,-4:17.13
9,-2,-4:17.13
19,-2,-4:17.13
20,-2,-4:17.13
21,-2,-4:17.13
11,-1,-4:17.13
13,-1,-4:17.13
14,-1,-4:17.13
20,-1,-4:17.13
12,0,-4:17.13
13,0,-4:17.13
14,0,-4:17.13
11,1,-4:17.13
12,1,-4:17.13
14,1,-4:17.13
17,1,-4:17.13
13,2,-4:17.13
12,-12,-3:17.13
13,-12,-3:17.13
14,-12,-3:17.13
12,-11,-3:17.13
13,-11,-3:17.13
14,-11,-3:17.13
15,-11,-3:17.13
19,-11,-3:17.13
20,-11,-3:17.13
21,-11,-3:17.13
12,-10,-3:17.13
13,-10,-3:17.13
19,-10,-3:17.13
20,-10,-3:17.13
21,-10,-3:17.13
20,-9,-3:17.13
7,-8,-3:17.13
8,-8,-3:17.13
9,-8,-3:17.13
20,-8,-3:17.13
7,-7,-3:17.13
8,-7,-3:17.13
9,-7,-3:17.13
10,-7,-3:17.13
11,-7,-3:17.13
7,-6,-3:17.13
8,-6,-3:17.13
10,-6,-3:17.13
8,-4,-3:17.13
9,-4,-3:17.13
8,-3,-3:17.13
9,-3,-3:17.13
19,-3,-3:17.13
20,-3,-3:17.13
8,-2,-3:17.13
9,-2,-3:17.13
12,-2,-3:17.13
19,-2,-3:17.13
20,-2,-3:17.13
21,-2,-3:17.13
9,-1,-3:17.13
10,-1,-3:17.13
13,-1,-3:17.13
19,-1,-3:17.13
20,-1,-3:17.13
21,-1,-3:17.13
9,0,-3:17.13
11,0,-3:17.13
12,0,-3:17.13
13,0,-3:17.13
14,0,-3:17.13
17,0,-3:17.13
12,1,-3:17.13
13,1,-3:17.13
14,1,-3:17.13
16,1,-3:17.13
17,1,-3:17.13
18,1,-3:17.13
10,2,-3:17.13
12,2,-3:17.13
13,2,-3:17.13
14,2,-3:17.13
16,2,-3:17.13
17,2,-3:17.13
13,-12,-2:17.13
14,-12,-2:17.13
13,-11,-2:17.13
14,-11,-2:17.13
15,-11,-2:17.13
18,-11,-2:17.13
20,-11,-2:17.13
11,-10,-2:17.13
12,-10,-2:17.13
15,-10,-2:17.13
16,-10,-2:17.13
17,-10,-2:17.13
18,-10,-2:17.13
19,-10,-2:17.13
20,-10,-2:17.13
10,-9,-2:17.13
19,-9,-2:17.13
20,-9,-2:17.13
8,-8,-2:17.13
9,-8,-2:17.13
10,-8,-2:17.13
11,-8,-2:17.13
20,-8,-2:17.13
9,-7,-2:17.13
10,-7,-2:17.13
11,-7,-2:17.13
20,-7,-2:17.13
8,-6,-2:17.13
9,-6,-2:17.13
10,-6,-2:17.13
11,-6,-2:17.13
20,-6,-2:17.13
8,-5,-2:17.13
10,-5,-2:17.13
8,-4,-2:17.13
9,-4,-2:17.13
7,-3,-2:17.13
8,-3,-2:17.13
9,-3,-2:17.13
20,-3,-2:17.13
8,-2,-2:17.13
9,-2,-2:17.13
19,-2,-2:17.13
20,-2,-2:17.13
21,-2,-2:17.13
9,-1,-2:17.13
10,-1,-2:17.13
11,-1,-2:17.13
12,-1,-2:17.13
19,-1,-2:17.13
20,-1,-2:17.13
21,-1,-2:17.13
9,0,-2:17.13
10,0,-2:17.13
11,0,-2:17.13
12,0,-2:17.13
13,0,-2:17.13
14,0,-2:17.13
10,1,-2:17.13
11,1,-2:17.13
12,1,-2:17.13
13,1,-2:17.13
14,1,-2:17.13
16,1,-2:17.13
17,1,-2:17.13
18,1,-2:17.13
12,2,-2:17.13
13,2,-2:17.13
14,2,-2:17.13
15,2,-2:17.13
17,2,-2:17.13
18,2,-2:17.13
15,3,-2:17.13
16,3,-2:17.13
14,-12,-1:17.13
14,-11,-1:17.13
15,-11,-1:17.13
19,-11,-1:17.13
11,-10,-1:17.13
12,-10,-1:17.13
13,-10,-1:17.13
14,-10,-1:17.13
15,-10,-1:17.13
16,-10,-1:17.13
17,-10,-1:17.13
18,-10,-1:17.13
19,-10,-1:17.13
20,-10,-1:17.13
10,-9,-1:17.13
11,-9,-1:17.13
20,-9,-1:17.13
10,-8,-1:17.13
11,-8,-1:17.13
20,-8,-1:17.13
9,-7,-1:17.13
10,-7,-1:17.13
11,-7,-1:17.13
20,-7,-1:17.13
10,-6,-1:17.13
20,-6,-1:17.13
10,-5,-1:17.13
20,-5,-1:17.13
8,-4,-1:17.13
9,-4,-1:17.13
10,-4,-1:17.13
11,-4,-1:17.13
20,-4,-1:17.13
7,-3,-1:17.13
8,-3,-1:17.13
9,-3,-1:17.13
11,-3,-1:17.13
19,-3,-1:17.13
20,-3,-1:17.13
21,-3,-1:17.13
9,-2,-1:17.13
10,-2,-1:17.13
11,-2,-1:17.13
12,-2,-1:17.13
19,-2,-1:17.13
20,-2,-1:17.13
21,-2,-1:17.13
10,-1,-1:17.13
11,-1,-1:17.13
13,-1,-1:17.13
19,-1,-1:17.13
20,-1,-1:17.13
21,-1,-1:17.13
9,0,-1:17.13
11,0,-1:17.13
12,0,-1:17.13
13,0,-1:17.13
14,0,-1:17.13
17,0,-1:17.13
18,0,-1:17.13
19,0,-1:17.13
20,0,-1:17.13
11,1,-1:17.13
12,1,-1:17.13
13,1,-1:17.13
16,1,-1:17.13
17,1,-1:17.13
18,1,-1:17.13
12,2,-1:17.13
13,2,-1:17.13
14,2,-1:17.13
15,2,-1:17.13
16,2,-1:17.13
17,2,-1:17.13
18,2,-1:17.13
14,3,-1:17.13
15,3,-1:17.13
16,3,-1:17.13
15,4,-1:17.13
12,-10,0:17.13
13,-10,0:17.13
14,-10,0:17.13
15,-10,0:17.13
16,-10,0:17.13
17,-10,0:17.13
18,-10,0:17.13
19,-10,0:17.13
11,-9,0:17.13
12,-9,0:17.13
18,-9,0:17.13
19,-9,0:17.13
20,-9,0:17.13
11,-8,0:17.13
12,-8,0:17.13
20,-8,0:17.13
11,-7,0:17.13
12,-7,0:17.13
20,-7,0:17.13
11,-6,0:17.13
20,-6,0:17.13
9,-5,0:17.13
10,-5,0:17.13
11,-5,0:17.13
20,-5,0:17.13
9,-4,0:17.13
10,-4,0:17.13
11,-4,0:17.13
20,-4,0:17.13
9,-3,0:17.13
10,-3,0:17.13
11,-3,0:17.13
20,-3,0:17.13
9,-2,0:17.13
10,-2,0:17.13
11,-2,0:17.13
12,-2,0:17.13
19,-2,0:17.13
20,-2,0:17.13
21,-2,0:17.13
22,-2,0:18.15
10,-1,0:17.13
11,-1,0:17.13
12,-1,0:17.13
13,-1,0:17.13
19,-1,0:17.13
20,-1,0:17.13
21,-1,0:18.15
22,-1,0:18.15
12,0,0:17.13
13,0,0:17.13
14,0,0:17.13
18,0,0:17.13
19,0,0:17.13
20,0,0:17.13
11,1,0:17.13
12,1,0:17.13
13,1,0:17.13
14,1,0:17.13
17,1,0:17.13
18,1,0:17.13
14,2,0:17.13
15,2,0:17.13
16,2,0:17.13
15,3,0:17.13
14,-10,1:17.13
15,-10,1:17.13
16,-10,1:17.13
20,-10,1:18.14
12,-9,1:17.13
13,-9,1:17.13
14,-9,1:17.13
15,-9,1:17.13
16,-9,1:17.13
17,-9,1:17.13
18,-9,1:17.13
19,-9,1:18.14
20,-9,1:18.14
21,-9,1:18.14
12,-8,1:17.13
13,-8,1:17.13
19,-8,1:18.14
20,-8,1:18.14
21,-8,1:18.14
12,-7,1:17.13
19,-7,1:18.14
20,-7,1:18.14
21,-7,1:18.14
22,-7,1:18.14
11,-6,1:17.13
12,-6,1:17.13
20,-6,1:18.14
21,-6,1:18.14
22,-6,1:18.14
10,-5,1:17.13
11,-5,1:17.13
20,-5,1:17.13
21,-5,1:18.14
9,-4,1:17.13
10,-4,1:17.13
11,-4,1:17.13
20,-4,1:17.13
9,-3,1:17.13
10,-3,1:17.13
11,-3,1:17.13
12,-3,1:17.13
20,-3,1:17.13
11,-2,1:18.14
12,-2,1:18.14
13,-2,1:17.13
20,-2,1:17.13
21,-2,1:18.15
11,-1,1:18.14
12,-1,1:18.14
13,-1,1:17.13
18,-1,1:17.13
19,-1,1:17.13
20,-1,1:17.13
21,-1,1:18.15
12,0,1:17.13
13,0,1:17.13
14,0,1:17.13
17,0,1:17.13
18,0,1:17.13
20,0,1:17.13
14,1,1:17.13
15,1,1:17.13
16,1,1:17.13
17,1,1:17.13
16,2,1:17.13
18,-10,2:18.14
20,-10,2:18.14
13,-9,2:17.13
14,-9,2:17.13
15,-9,2:17.13
16,-9,2:17.13
17,-9,2:17.13
18,-9,2:17.13
19,-9,2:18.14
20,-9,2:18.14
21,-9,2:18.14
22,-9,2:18.14
13,-8,2:17.13
19,-8,2:18.14
20,-8,2:18.14
21,-8,2:18.14
12,-7,2:17.13
13,-7,2:17.13
19,-7,2:17.13
20,-7,2:18.14
21,-7,2:18.14
22,-7,2:18.14
12,-6,2:17.13
20,-6,2:18.14
21,-6,2:18.14
22,-6,2:18.14
11,-5,2:17.13
12,-5,2:17.13
20,-5,2:17.13
21,-5,2:18.14
11,-4,2:17.13
12,-4,2:17.13
20,-4,2:17.13
12,-3,2:17.13
13,-3,2:17.13
20,-3,2:17.13
11,-2,2:18.14
12,-2,2:18.14
13,-2,2:17.13
14,-2,2:17.13
19,-2,2:17.13
20,-2,2:17.13
21,-2,2:18.15
11,-1,2:18.14
12,-1,2:18.14
14,-1,2:17.13
15,-1,2:17.13
18,-1,2:17.13
19,-1,2:17.13
21,-1,2:18.15
14,0,2:17.13
15,0,2:17.13
16,0,2:17.13
17,0,2:17.13
18,0,2:17.13
16,1,2:17.13
20,-10,3:18.14
14,-9,3:17.13
15,-9,3:17.13
16,-9,3:17.13
17,-9,3:17.13
18,-9,3:17.13
19,-9,3:18.14
20,-9,3:18.14
21,-9,3:18.14
22,-9,3:18.14
13,-8,3:17.13
14,-8,3:17.13
18,-8,3:17.13
19,-8,3:18.14
20,-8,3:18.14
21,-8,3:18.14
13,-7,3:17.13
19,-7,3:17.13
20,-7,3:18.14
21,-7,3:18.14
12,-6,3:17.13
13,-6,3:17.13
19,-6,3:17.13
20,-6,3:18.14
21,-6,3:18.14
12,-5,3:17.13
20,-5,3:17.13
12,-4,3:17.13
13,-4,3:17.13
14,-4,3:17.13
20,-4,3:17.13
13,-3,3:17.13
14,-3,3:17.13
19,-3,3:17.13
20,-3,3:17.13
14,-2,3:17.13
15,-2,3:17.13
18,-2,3:17.13
19,-2,3:17.13
15,-1,3:17.13
16,-1,3:17.13
17,-1,3:17.13
18,-1,3:17.13
16,0,3:17.13
17,0,3:17.13
14,-9,4:17.13
15,-9,4:17.13
16,-9,4:17.13
17,-9,4:17.13
18,-9,4:17.13
19,-9,4:18.14
20,-9,4:18.14
21,-9,4:18.14
14,-8,4:17.13
18,-8,4:17.13
19,-8,4:17.13
20,-8,4:18.14
21,-8,4:18.14
13,-7,4:17.13
14,-7,4:17.13
19,-7,4:17.13
20,-7,4:18.14
13,-6,4:17.13
19,-6,4:17.13
12,-5,4:17.13
13,-5,4:17.13
19,-5,4:17.13
13,-4,4:17.13
14,-4,4:17.13
19,-4,4:17.13
14,-3,4:17.13
15,-3,4:17.13
19,-3,4:17.13
15,-2,4:17.13
16,-2,4:17.13
18,-2,4:17.13
19,-2,4:17.13
16,-1,4:17.13
17,-1,4:17.13
18,-1,4:17.13
15,-9,5:17.13
16,-9,5:17.13
17,-9,5:17.13
18,-9,5:17.13
14,-8,5:17.13
19,-8,5:17.13
14,-7,5:17.13
19,-7,5:17.13
13,-6,5:17.13
19,-6,5:17.13
13,-5,5:17.13
14,-5,5:17.13
19,-5,5:17.13
14,-4,5:17.13
15,-4,5:17.13
19,-4,5:17.13
15,-3,5:17.13
18,-3,5:17.13
19,-3,5:17.13
15,-2,5:17.13
16,-2,5:17.13
17,-2,5:17.13
18,-2,5:17.13
16,-10,6:17.13
15,-9,6:17.13
16,-9,6:17.13
17,-9,6:17.13
18,-9,6:17.13
14,-8,6:17.13
15,-8,6:17.13
19,-8,6:17.13
14,-7,6:17.13
19,-7,6:17.13
13,-6,6:17.13
14,-6,6:17.13
19,-6,6:17.13
14,-5,6:17.13
15,-5,6:17.13
19,-5,6:17.13
15,-4,6:17.13
19,-4,6:17.13
15,-3,6:17.13
16,-3,6:17.13
17,-3,6:17.13
18,-3,6:17.13
16,-2,6:17.13
17,-2,6:17.13
16,-10,7:17.13
15,-9,7:17.13
16,-9,7:17.13
17,-9,7:17.13
18,-9,7:17.13
15,-8,7:17.13
19,-8,7:17.13
14,-7,7:17.13
15,-7,7:17.13
19,-7,7:17.13
14,-6,7:17.13
15,-6,7:17.13
19,-6,7:17.13
15,-5,7:17.13
19,-5,7:17.13
15,-4,7:17.13
16,-4,7:17.13
17,-4,7:17.13
18,-4,7:17.13
19,-4,7:17.13
16,-3,7:17.13
17,-3,7:17.13
18,-3,7:17.13
16,-10,8:17.13
17,-10,8:17.13
15,-9,8:17.13
17,-9,8:17.13
18,-9,8:17.13
19,-9,8:17.13
15,-8,8:17.13
19,-8,8:17.13
14,-7,8:17.13
15,-7,8:17.13
19,-7,8:17.13
15,-6,8:17.13
19,-6,8:17.13
15,-5,8:17.13
16,-5,8:17.13
19,-5,8:17.13
16,-4,8:17.13
17,-4,8:17.13
18,-4,8:17.13
16,-10,9:17.13
17,-10,9:17.13
18,-10,9:17.13
15,-9,9:17.13
18,-9,9:17.13
19,-9,9:17.13
15,-8,9:17.13
19,-8,9:17.13
14,-7,9:17.13
19,-7,9:17.13
14,-6,9:17.13
15,-6,9:17.13
19,-6,9:17.13
15,-5,9:17.13
16,-5,9:17.13
19,-5,9:17.13
16,-4,9:17.13
17,-4,9:17.13
18,-4,9:17.13
-1,-17,10:18.6
16,-10,10:17.13
17,-10,10:17.13
18,-10,10:17.13
15,-9,10:17.13
19,-9,10:17.13
14,-8,10:17.13
15,-8,10:17.13
19,-8,10:17.13
20,-8,10:17.13
14,-7,10:17.13
20,-7,10:17.13
14,-6,10:17.13
15,-6,10:17.13
19,-6,10:17.13
20,-6,10:17.13
15,-5,10:17.13
18,-5,10:17.13
19,-5,10:17.13
16,-4,10:17.13
17,-4,10:17.13
18,-4,10:17.13
23,-23,11:18.6
24,-22,11:18.6
1,-20,11:18.6
0,-19,11:18.6
0,-18,11:18.6
-1,-17,11:18.6
-1,-16,11:18.6
-1,-15,11:18.6
-1,-13,11:18.6
15,-10,11:17.13
16,-10,11:17.13
17,-10,11:17.13
18,-10,11:17.13
19,-10,11:17.13
15,-9,11:17.13
19,-9,11:17.13
20,-9,11:17.13
14,-8,11:17.13
20,-8,11:17.13
14,-7,11:17.13
20,-7,11:17.13
14,-6,11:17.13
15,-6,11:17.13
19,-6,11:17.13
15,-5,11:17.13
18,-5,11:17.13
19,-5,11:17.13
40,-5,11:18.6
16,-4,11:17.13
17,-4,11:17.13
18,-4,11:17.13
40,-4,11:18.6
38,-1,11:18.6
38,0,11:18.6
37,1,11:18.6
37,2,11:18.6
36,3,11:18.6
7,-27,12:18.6
8,-27,12:18.6
12,-27,12:18.6
14,-27,12:18.6
15,-27,12:18.6
16,-27,12:18.6
17,-27,12:18.6
17,-26,12:18.6
18,-26,12:18.6
3,-25,12:18.6
19,-25,12:18.6
20,-25,12:18.6
3,-24,12:18.6
20,-24,12:18.6
2,-23,12:18.6
3,-23,12:18.6
22,-23,12:18.6
23,-23,12:18.6
24,-22,12:18.6
25,-22,12:18.6
27,-22,12:18.6
1,-21,12:18.6
25,-21,12:18.6
26,-21,12:18.6
27,-21,12:18.6
1,-20,12:18.6
27,-20,12:18.6
28,-20,12:18.6
29,-20,12:18.6
0,-19,12:18.6
1,-19,12:18.6
30,-19,12:18.6
0,-18,12:18.6
24,-18,12:18.6
-1,-17,12:18.6
0,-17,12:18.6
-2,-16,12:18.6
-1,-16,12:18.6
0,-16,12:18.6
-2,-15,12:18.6
-1,-15,12:18.6
0,-15,12:18.6
0,-14,12:18.6
0,-13,12:18.6
0,-12,12:18.6
0,-11,12:18.6
39,-11,12:18.6
40,-11,12:18.6
15,-10,12:17.13
16,-10,12:17.13
17,-10,12:17.13
18,-10,12:17.13
19,-10,12:17.13
40,-10,12:18.6
15,-9,12:17.13
20,-9,12:17.13
40,-9,12:18.6
41,-9,12:18.6
14,-8,12:17.13
20,-8,12:17.13
41,-8,12:18.6
42,-8,12:18.6
14,-7,12:17.13
20,-7,12:17.13
41,-7,12:18.6
14,-6,12:17.13
15,-6,12:17.13
19,-6,12:17.13
20,-6,12:17.13
40,-6,12:18.6
41,-6,12:18.6
15,-5,12:17.13
19,-5,12:17.13
40,-5,12:18.6
15,-4,12:17.13
16,-4,12:17.13
17,-4,12:17.13
18,-4,12:17.13
19,-4,12:17.13
39,-4,12:18.6
40,-4,12:18.6
17,-3,12:17.13
18,-3,12:17.13
39,-3,12:18.6
39,-2,12:18.6
38,-1,12:18.6
37,0,12:18.6
38,0,12:18.6
37,1,12:18.6
36,2,12:18.6
37,2,12:18.6
35,3,12:18.6
36,3,12:18.6
35,4,12:18.6
34,5,12:18.6
16,-28,13:18.6
4,-27,13:18.6
6,-27,13:18.6
7,-27,13:18.6
8,-27,13:18.6
9,-27,13:18.6
10,-27,13:18.6
11,-27,13:18.6
12,-27,13:18.6
13,-27,13:18.6
14,-27,13:18.6
15,-27,13:18.6
16,-27,13:18.6
4,-26,13:18.6
5,-26,13:18.6
17,-26,13:18.6
18,-26,13:18.6
2,-25,13:18.6
3,-25,13:18.6
4,-25,13:18.6
18,-25,13:18.6
19,-25,13:18.6
20,-25,13:18.6
1,-24,13:18.6
2,-24,13:18.6
3,-24,13:18.6
20,-24,13:18.6
21,-24,13:18.6
23,-24,13:18.6
2,-23,13:18.6
3,-23,13:18.6
22,-23,13:18.6
23,-23,13:18.6
2,-22,13:18.6
3,-22,13:18.6
23,-22,13:18.6
24,-22,13:18.6
27,-22,13:18.6
2,-21,13:18.6
3,-21,13:18.6
25,-21,13:18.6
26,-21,13:18.6
27,-21,13:18.6
1,-20,13:18.6
3,-20,13:18.6
26,-20,13:18.6
27,-20,13:18.6
28,-20,13:18.6
0,-19,13:18.6
1,-19,13:18.6
2,-19,13:18.6
3,-19,13:18.6
18,-19,13:18.6
19,-19,13:18.6
20,-19,13:18.6
21,-19,13:18.6
22,-19,13:18.6
23,-19,13:18.6
29,-19,13:18.6
30,-19,13:18.6
31,-19,13:18.6
32,-19,13:18.6
0,-18,13:18.6
1,-18,13:18.6
2,-18,13:18.6
3,-18,13:18.6
10,-18,13:18.6
12,-18,13:18.6
13,-18,13:18.6
14,-18,13:18.6
15,-18,13:18.6
24,-18,13:18.6
32,-18,13:18.6
33,-18,13:18.6
34,-18,13:18.6
35,-18,13:18.6
0,-17,13:18.6
1,-17,13:18.6
2,-17,13:18.6
3,-17,13:18.6
25,-17,13:18.6
35,-17,13:18.6
36,-17,13:18.6
-3,-16,13:18.6
-2,-16,13:18.6
-1,-16,13:18.6
0,-16,13:18.6
1,-16,13:18.6
2,-16,13:18.6
3,-16,13:18.6
8,-16,13:18.6
36,-16,13:18.6
-1,-15,13:18.6
0,-15,13:18.6
1,-15,13:18.6
2,-15,13:18.6
3,-15,13:18.6
8,-15,13:18.6
26,-15,13:18.6
37,-15,13:18.6
-1,-14,13:18.6
0,-14,13:18.6
1,-14,13:18.6
2,-14,13:18.6
3,-14,13:18.6
7,-14,13:18.6
8,-14,13:18.6
37,-14,13:18.6
38,-14,13:18.6
-2,-13,13:18.6
-1,-13,13:18.6
0,-13,13:18.6
1,-13,13:18.6
2,-13,13:18.6
38,-13,13:18.6
0,-12,13:18.6
39,-12,13:18.6
40,-12,13:18.6
0,-11,13:18.6
6,-11,13:18.6
16,-11,13:17.13
38,-11,13:18.6
39,-11,13:18.6
40,-11,13:18.6
0,-10,13:18.6
5,-10,13:18.6
15,-10,13:17.13
16,-10,13:17.13
17,-10,13:17.13
18,-10,13:17.13
19,-10,13:17.13
20,-10,13:17.13
37,-10,13:18.6
38,-10,13:18.6
39,-10,13:18.6
40,-10,13:18.6
0,-9,13:18.6
5,-9,13:18.6
14,-9,13:17.13
15,-9,13:17.13
20,-9,13:17.13
37,-9,13:18.6
38,-9,13:18.6
40,-9,13:18.6
0,-8,13:18.6
4,-8,13:18.6
13,-8,13:17.13
14,-8,13:17.13
20,-8,13:17.13
37,-8,13:18.6
38,-8,13:18.6
39,-8,13:18.6
40,-8,13:18.6
41,-8,13:18.6
42,-8,13:18.6
43,-8,13:18.6
45,-8,13:18.6
0,-7,13:18.6
4,-7,13:18.6
13,-7,13:17.13
14,-7,13:17.13
20,-7,13:17.13
21,-7,13:17.13
36,-7,13:18.6
37,-7,13:18.6
38,-7,13:18.6
40,-7,13:18.6
41,-7,13:18.6
3,-6,13:18.6
14,-6,13:17.13
20,-6,13:17.13
21,-6,13:17.13
36,-6,13:18.6
37,-6,13:18.6
38,-6,13:18.6
39,-6,13:18.6
40,-6,13:18.6
14,-5,13:17.13
15,-5,13:17.13
20,-5,13:17.13
36,-5,13:18.6
37,-5,13:18.6
38,-5,13:18.6
39,-5,13:18.6
40,-5,13:18.6
4,-4,13:18.6
15,-4,13:17.13
16,-4,13:17.13
19,-4,13:17.13
20,-4,13:17.13
35,-4,13:18.6
36,-4,13:18.6
37,-4,13:18.6
38,-4,13:18.6
39,-4,13:18.6
40,-4,13:18.6
5,-3,13:18.6
16,-3,13:17.13
17,-3,13:17.13
18,-3,13:17.13
19,-3,13:17.13
35,-3,13:18.6
36,-3,13:18.6
38,-3,13:18.6
39,-3,13:18.6
6,-2,13:18.6
17,-2,13:17.13
18,-2,13:17.13
35,-2,13:18.6
36,-2,13:18.6
35,-1,13:18.6
36,-1,13:18.6
37,-1,13:18.6
38,-1,13:18.6
34,0,13:18.6
35,0,13:18.6
36,0,13:18.6
37,0,13:18.6
38,0,13:18.6
34,1,13:18.6
35,1,13:18.6
36,1,13:18.6
37,1,13:18.6
34,2,13:18.6
35,2,13:18.6
36,2,13:18.6
37,2,13:18.6
34,3,13:18.6
35,3,13:18.6
36,3,13:18.6
37,3,13:18.6
38,3,13:18.6
0,4,13:18.6
25,4,13:18.6
34,4,13:18.6
35,4,13:18.6
0,5,13:18.6
33,5,13:18.6
34,5,13:18.6
0,6,13:18.6
1,6,13:18.6
33,6,13:18.6
1,7,13:18.6
31,7,13:18.6
2,8,13:18.6
31,8,13:18.6
4,12,13:18.6
5,13,13:18.6
20,13,13:18.6
21,13,13:18.6
16,14,13:18.6
18,14,13:18.6
19,14,13:18.6
9,15,13:18.6
10,15,13:18.6
13,15,13:18.6
14,15,13:18.6
16,15,13:18.6
17,15,13:18.6
1,-31,14:18.6
2,-30,14:18.6
16,-30,14:18.6
2,-29,14:18.6
16,-29,14:18.6
3,-28,14:18.6
7,-28,14:18.6
8,-28,14:18.6
13,-28,14:18.6
15,-28,14:18.6
16,-28,14:18.6
4,-27,14:18.6
6,-27,14:18.6
7,-27,14:18.6
8,-27,14:18.6
9,-27,14:18.6
10,-27,14:18.6
11,-27,14:18.6
12,-27,14:18.6
13,-27,14:18.6
14,-27,14:18.6
15,-27,14:18.6
16,-27,14:18.6
17,-27,14:18.6
4,-26,14:18.6
5,-26,14:18.6
6,-26,14:18.6
7,-26,14:18.6
8,-26,14:18.6
9,-26,14:18.6
10,-26,14:18.6
12,-26,14:18.6
13,-26,14:18.6
14,-26,14:18.6
15,-26,14:18.6
16,-26,14:18.6
17,-26,14:18.6
18,-26,14:18.6
19,-26,14:18.6
4,-25,14:18.6
5,-25,14:18.6
6,-25,14:18.6
7,-25,14:18.6
8,-25,14:18.6
9,-25,14:18.6
10,-25,14:18.6
11,-25,14:18.6
12,-25,14:18.6
13,-25,14:18.6
14,-25,14:18.6
15,-25,14:18.6
16,-25,14:18.6
17,-25,14:18.6
18,-25,14:18.6
19,-25,14:18.6
28,-25,14:18.6
29,-25,14:18.6
3,-24,14:18.6
4,-24,14:18.6
5,-24,14:18.6
6,-24,14:18.6
7,-24,14:18.6
8,-24,14:18.6
9,-24,14:18.6
10,-24,14:18.6
11,-24,14:18.6
12,-24,14:18.6
13,-24,14:18.6
14,-24,14:18.6
15,-24,14:18.6
16,-24,14:18.6
17,-24,14:18.6
18,-24,14:18.6
19,-24,14:18.6
20,-24,14:18.6
21,-24,14:18.6
23,-24,14:18.6
28,-24,14:18.6
3,-23,14:18.6
4,-23,14:18.6
5,-23,14:18.6
6,-23,14:18.6
7,-23,14:18.6
8,-23,14:18.6
9,-23,14:18.6
10,-23,14:18.6
11,-23,14:18.6
12,-23,14:18.6
13,-23,14:18.6
14,-23,14:18.6
15,-23,14:18.6
16,-23,14:18.6
17,-23,14:18.6
18,-23,14:18.6
19,-23,14:18.6
20,-23,14:18.6
21,-23,14:18.6
22,-23,14:18.6
23,-23,14:18.6
24,-23,14:18.6
27,-23,14:18.6
28,-23,14:18.6
2,-22,14:18.6
3,-22,14:18.6
4,-22,14:18.6
5,-22,14:18.6
6,-22,14:18.6
7,-22,14:18.6
8,-22,14:18.6
9,-22,14:18.6
10,-22,14:18.6
11,-22,14:18.6
18,-22,14:18.6
19,-22,14:18.6
20,-22,14:18.6
21,-22,14:18.6
22,-22,14:18.6
23,-22,14:18.6
24,-22,14:18.6
27,-22,14:18.6
2,-21,14:18.6
4,-21,14:18.6
5,-21,14:18.6
6,-21,14:18.6
7,-21,14:18.6
19,-21,14:18.6
20,-21,14:18.6
21,-21,14:18.6
22,-21,14:18.6
23,-21,14:18.6
24,-21,14:18.6
25,-21,14:18.6
26,-21,14:18.6
27,-21,14:18.6
29,-21,14:18.6
30,-21,14:18.6
1,-20,14:18.6
2,-20,14:18.6
4,-20,14:18.6
5,-20,14:18.6
6,-20,14:18.6
7,-20,14:18.6
20,-20,14:18.6
21,-20,14:18.6
22,-20,14:18.6
23,-20,14:18.6
24,-20,14:18.6
25,-20,14:18.6
26,-20,14:18.6
27,-20,14:18.6
28,-20,14:18.6
29,-20,14:18.6
1,-19,14:18.6
4,-19,14:18.6
5,-19,14:18.6
6,-19,14:18.6
7,-19,14:18.6
18,-19,14:18.6
19,-19,14:18.6
20,-19,14:18.6
21,-19,14:18.6
22,-19,14:18.6
23,-19,14:18.6
24,-19,14:18.6
25,-19,14:18.6
26,-19,14:18.6
27,-19,14:18.6
28,-19,14:18.6
29,-19,14:18.6
30,-19,14:18.6
31,-19,14:18.6
32,-19,14:18.6
33,-19,14:18.6
34,-19,14:18.6
0,-18,14:18.6
1,-18,14:18.6
4,-18,14:18.6
5,-18,14:18.6
6,-18,14:18.6
7,-18,14:18.6
10,-18,14:18.6
11,-18,14:18.6
12,-18,14:18.6
13,-18,14:18.6
14,-18,14:18.6
15,-18,14:18.6
16,-18,14:18.6
17,-18,14:18.6
18,-18,14:18.6
19,-18,14:18.6
23,-18,14:18.6
24,-18,14:18.6
25,-18,14:18.6
26,-18,14:18.6
27,-18,14:18.6
28,-18,14:18.6
29,-18,14:18.6
30,-18,14:18.6
31,-18,14:18.6
32,-18,14:18.6
33,-18,14:18.6
34,-18,14:18.6
35,-18,14:18.6
36,-18,14:18.6
0,-17,14:18.6
4,-17,14:18.6
5,-17,14:18.6
6,-17,14:18.6
7,-17,14:18.6
9,-17,14:18.6
24,-17,14:18.6
25,-17,14:18.6
34,-17,14:18.6
35,-17,14:18.6
36,-17,14:18.6
-5,-16,14:18.6
-4,-16,14:18.6
-3,-16,14:18.6
-2,-16,14:18.6
-1,-16,14:18.6
0,-16,14:18.6
4,-16,14:18.6
5,-16,14:18.6
6,-16,14:18.6
7,-16,14:18.6
9,-16,14:18.6
25,-16,14:18.6
34,-16,14:18.6
35,-16,14:18.6
36,-16,14:18.6
37,-16,14:18.6
0,-15,14:18.6
4,-15,14:18.6
5,-15,14:18.6
6,-15,14:18.6
7,-15,14:18.6
8,-15,14:18.6
26,-15,14:18.6
34,-15,14:18.6
35,-15,14:18.6
36,-15,14:18.6
37,-15,14:18.6
0,-14,14:18.6
1,-14,14:18.6
4,-14,14:18.6
5,-14,14:18.6
6,-14,14:18.6
7,-14,14:18.6
8,-14,14:18.6
26,-14,14:18.6
27,-14,14:18.6
33,-14,14:18.6
34,-14,14:18.6
35,-14,14:18.6
36,-14,14:18.6
37,-14,14:18.6
0,-13,14:18.6
1,-13,14:18.6
2,-13,14:18.6
3,-13,14:18.6
4,-13,14:18.6
5,-13,14:18.6
6,-13,14:18.6
7,-13,14:18.6
27,-13,14:18.6
33,-13,14:18.6
34,-13,14:18.6
35,-13,14:18.6
37,-13,14:18.6
38,-13,14:18.6
0,-12,14:18.6
1,-12,14:18.6
2,-12,14:18.6
3,-12,14:18.6
4,-12,14:18.6
5,-12,14:18.6
6,-12,14:18.6
7,-12,14:18.6
28,-12,14:18.6
33,-12,14:18.6
34,-12,14:18.6
35,-12,14:18.6
36,-12,14:18.6
38,-12,14:18.6
0,-11,14:18.6
1,-11,14:18.6
2,-11,14:18.6
3,-11,14:18.6
4,-11,14:18.6
5,-11,14:18.6
6,-11,14:18.6
16,-11,14:17.13
17,-11,14:17.13
18,-11,14:17.13
28,-11,14:18.6
29,-11,14:18.6
32,-11,14:18.6
33,-11,14:18.6
34,-11,14:18.6
35,-11,14:18.6
36,-11,14:18.6
37,-11,14:18.6
39,-11,14:18.6
0,-10,14:18.6
1,-10,14:18.6
2,-10,14:18.6
3,-10,14:18.6
5,-10,14:18.6
6,-10,14:18.6
14,-10,14:17.13
15,-10,14:17.13
18,-10,14:17.13
19,-10,14:17.13
20,-10,14:17.13
29,-10,14:18.6
32,-10,14:18.6
33,-10,14:18.6
34,-10,14:18.6
35,-10,14:18.6
36,-10,14:18.6
37,-10,14:18.6
39,-10,14:18.6
40,-10,14:18.6
0,-9,14:18.6
1,-9,14:18.6
5,-9,14:18.6
13,-9,14:17.13
14,-9,14:17.13
21,-9,14:17.13
30,-9,14:18.6
32,-9,14:18.6
33,-9,14:18.6
34,-9,14:18.6
35,-9,14:18.6
36,-9,14:18.6
40,-9,14:18.6
0,-8,14:18.6
1,-8,14:18.6
4,-8,14:18.6
5,-8,14:18.6
13,-8,14:17.13
21,-8,14:17.13
31,-8,14:18.6
32,-8,14:18.6
33,-8,14:18.6
34,-8,14:18.6
35,-8,14:18.6
36,-8,14:18.6
40,-8,14:18.6
41,-8,14:18.6
42,-8,14:18.6
43,-8,14:18.6
44,-8,14:18.6
45,-8,14:18.6
46,-8,14:18.6
47,-8,14:18.6
0,-7,14:18.6
1,-7,14:18.6
4,-7,14:18.6
13,-7,14:17.13
21,-7,14:17.13
31,-7,14:18.6
32,-7,14:18.6
33,-7,14:18.6
34,-7,14:18.6
35,-7,14:18.6
36,-7,14:18.6
40,-7,14:18.6
1,-6,14:18.6
4,-6,14:18.6
13,-6,14:17.13
14,-6,14:17.13
21,-6,14:17.13
30,-6,14:18.6
31,-6,14:18.6
32,-6,14:18.6
33,-6,14:18.6
34,-6,14:18.6
35,-6,14:18.6
40,-6,14:18.6
1,-5,14:18.6
13,-5,14:17.13
14,-5,14:17.13
21,-5,14:17.13
29,-5,14:18.6
30,-5,14:18.6
31,-5,14:18.6
32,-5,14:18.6
33,-5,14:18.6
34,-5,14:18.6
35,-5,14:18.6
39,-5,14:18.6
0,-4,14:18.6
1,-4,14:18.6
5,-4,14:18.6
14,-4,14:17.13
15,-4,14:17.13
20,-4,14:17.13
21,-4,14:17.13
29,-4,14:18.6
30,-4,14:18.6
31,-4,14:18.6
32,-4,14:18.6
33,-4,14:18.6
34,-4,14:18.6
35,-4,14:18.6
39,-4,14:18.6
5,-3,14:18.6
6,-3,14:18.6
15,-3,14:17.13
16,-3,14:17.13
19,-3,14:17.13
20,-3,14:17.13
21,-3,14:17.13
28,-3,14:18.6
29,-3,14:18.6
30,-3,14:18.6
31,-3,14:18.6
32,-3,14:18.6
33,-3,14:18.6
34,-3,14:18.6
38,-3,14:18.6
0,-2,14:18.6
6,-2,14:18.6
16,-2,14:17.13
17,-2,14:17.13
18,-2,14:17.13
19,-2,14:17.13
29,-2,14:18.6
30,-2,14:18.6
31,-2,14:18.6
32,-2,14:18.6
33,-2,14:18.6
34,-2,14:18.6
0,-1,14:18.6
6,-1,14:18.6
7,-1,14:18.6
29,-1,14:18.6
30,-1,14:18.6
31,-1,14:18.6
32,-1,14:18.6
33,-1,14:18.6
37,-1,14:18.6
0,0,14:18.6
27,0,14:18.14
29,0,14:18.6
30,0,14:18.6
31,0,14:18.6
32,0,14:18.6
33,0,14:18.6
37,0,14:18.6
0,1,14:18.6
8,1,14:18.6
26,1,14:18.14
27,1,14:18.14
30,1,14:18.6
31,1,14:18.6
32,1,14:18.6
33,1,14:18.6
36,1,14:18.6
0,2,14:18.6
8,2,14:18.6
9,2,14:18.6
26,2,14:18.14
30,2,14:18.6
32,2,14:18.6
33,2,14:18.6
35,2,14:18.6
36,2,14:18.6
37,2,14:18.6
0,3,14:18.6
9,3,14:18.6
25,3,14:18.6
26,3,14:18.6
31,3,14:18.6
32,3,14:18.6
33,3,14:18.6
34,3,14:18.6
35,3,14:18.6
37,3,14:18.6
38,3,14:18.6
0,4,14:18.6
25,4,14:18.6
31,4,14:18.6
32,4,14:18.6
33,4,14:18.6
34,4,14:18.6
0,5,14:18.6
11,5,14:18.6
13,5,14:18.14
14,5,14:18.14
15,5,14:18.14
16,5,14:18.14
19,5,14:18.14
20,5,14:18.14
21,5,14:18.14
22,5,14:18.6
23,5,14:18.6
24,5,14:18.6
25,5,14:18.6
33,5,14:18.6
34,5,14:18.6
40,5,14:18.6
0,6,14:18.6
1,6,14:18.6
32,6,14:18.6
33,6,14:18.6
1,7,14:18.6
2,7,14:18.6
31,7,14:18.6
32,7,14:18.6
2,8,14:18.6
30,8,14:18.6
31,8,14:18.6
2,9,14:18.6
3,9,14:18.6
30,9,14:18.6
3,10,14:18.6
26,10,14:18.6
28,10,14:18.6
4,11,14:18.6
24,11,14:18.6
25,11,14:18.6
26,11,14:18.6
3,12,14:18.6
4,12,14:18.6
5,12,14:18.6
21,12,14:18.6
22,12,14:18.6
24,12,14:18.6
4,13,14:18.6
5,13,14:18.6
6,13,14:18.6
18,13,14:18.6
19,13,14:18.6
20,13,14:18.6
21,13,14:18.6
6,14,14:18.6
7,14,14:18.6
9,14,14:18.6
10,14,14:18.6
11,14,14:18.6
12,14,14:18.6
13,14,14:18.6
14,14,14:18.6
15,14,14:18.6
16,14,14:18.6
18,14,14:18.6
6,15,14:18.6
7,15,14:18.6
8,15,14:18.6
9,15,14:18.6
10,15,14:18.6
11,15,14:18.6
15,15,14:18.6
17,15,14:18.6
18,15,14:18.6
6,16,14:18.6
17,-34,15:18.6
16,-33,15:18.6
17,-33,15:18.6
16,-32,15:18.6
1,-31,15:18.6
16,-31,15:18.6
2,-30,15:18.6
16,-30,15:18.6
2,-29,15:18.6
3,-29,15:18.6
16,-29,15:18.6
3,-28,15:18.6
16,-28,15:18.6
4,-27,15:18.6
13,-27,15:18.6
14,-27,15:18.6
15,-27,15:18.6
4,-26,15:18.6
5,-26,15:18.6
6,-26,15:18.6
7,-26,15:18.6
8,-26,15:18.6
9,-26,15:18.6
10,-26,15:18.6
11,-26,15:18.6
12,-26,15:18.6
13,-26,15:18.6
14,-26,15:18.6
16,-26,15:18.6
17,-26,15:18.6
4,-25,15:18.6
17,-25,15:18.6
18,-25,15:18.6
19,-25,15:18.6
28,-25,15:18.6
29,-25,15:18.6
3,-24,15:18.6
4,-24,15:18.6
19,-24,15:18.6
20,-24,15:18.6
28,-24,15:18.6
3,-23,15:18.6
16,-23,15:18.6
21,-23,15:18.6
22,-23,15:18.6
27,-23,15:18.6
2,-22,15:18.6
3,-22,15:18.6
8,-22,15:18.6
9,-22,15:18.6
10,-22,15:18.6
11,-22,15:18.6
12,-22,15:18.6
13,-22,15:18.6
14,-22,15:18.6
15,-22,15:18.6
16,-22,15:18.6
17,-22,15:18.6
22,-22,15:18.6
23,-22,15:18.6
24,-22,15:18.6
27,-22,15:18.6
2,-21,15:18.6
7,-21,15:18.6
8,-21,15:18.6
9,-21,15:18.6
10,-21,15:18.6
11,-21,15:18.6
12,-21,15:18.6
13,-21,15:18.6
14,-21,15:18.6
15,-21,15:18.6
16,-21,15:18.6
17,-21,15:18.6
18,-21,15:18.6
19,-21,15:18.6
24,-21,15:18.6
25,-21,15:18.6
26,-21,15:18.6
37,-21,15:18.6
2,-20,15:18.6
8,-20,15:18.6
9,-20,15:18.6
10,-20,15:18.6
11,-20,15:18.6
13,-20,15:18.6
14,-20,15:18.6
15,-20,15:18.6
16,-20,15:18.6
17,-20,15:18.6
18,-20,15:18.6
19,-20,15:18.6
20,-20,15:18.6
25,-20,15:18.6
26,-20,15:18.6
1,-19,15:18.6
8,-19,15:18.6
9,-19,15:18.6
10,-19,15:18.6
11,-19,15:18.6
12,-19,15:18.6
13,-19,15:18.6
14,-19,15:18.6
15,-19,15:18.6
16,-19,15:18.6
17,-19,15:18.6
18,-19,15:18.6
19,-19,15:18.6
20,-19,15:18.6
21,-19,15:18.6
22,-19,15:18.6
23,-19,15:18.6
27,-19,15:18.6
28,-19,15:18.6
29,-19,15:18.6
36,-19,15:18.6
1,-18,15:18.6
8,-18,15:18.6
9,-18,15:18.6
10,-18,15:18.14
11,-18,15:18.14
12,-18,15:18.14
13,-18,15:18.14
14,-18,15:18.14
15,-18,15:18.14
16,-18,15:18.14
17,-18,15:18.14
18,-18,15:18.14
19,-18,15:18.6
20,-18,15:18.6
21,-18,15:18.6
22,-18,15:18.6
23,-18,15:18.6
24,-18,15:18.6
29,-18,15:18.6
30,-18,15:18.6
31,-18,15:18.6
32,-18,15:18.6
33,-18,15:18.6
34,-18,15:18.6
35,-18,15:18.6
36,-18,15:18.6
0,-17,15:18.6
8,-17,15:18.6
9,-17,15:18.6
10,-17,15:18.14
11,-17,15:18.14
12,-17,15:18.14
13,-17,15:18.14
14,-17,15:18.14
15,-17,15:18.14
16,-17,15:18.14
17,-17,15:18.14
18,-17,15:18.14
19,-17,15:18.14
20,-17,15:18.6
21,-17,15:18.6
22,-17,15:18.6
23,-17,15:18.6
24,-17,15:18.6
25,-17,15:18.6
26,-17,15:18.6
27,-17,15:18.6
28,-17,15:18.6
29,-17,15:18.6
30,-17,15:18.6
31,-17,15:18.6
32,-17,15:18.6
33,-17,15:18.6
34,-17,15:18.6
35,-17,15:18.6
-5,-16,15:18.6
-4,-16,15:18.6
-3,-16,15:18.6
-2,-16,15:18.6
-1,-16,15:18.6
0,-16,15:18.6
8,-16,15:18.6
9,-16,15:18.6
10,-16,15:18.14
11,-16,15:18.14
12,-16,15:18.14
13,-16,15:18.14
14,-16,15:18.14
17,-16,15:18.14
18,-16,15:18.14
19,-16,15:18.14
20,-16,15:18.14
21,-16,15:18.14
22,-16,15:18.14
23,-16,15:18.14
24,-16,15:18.14
25,-16,15:18.14
27,-16,15:18.14
28,-16,15:18.14
29,-16,15:18.6
30,-16,15:18.6
31,-16,15:18.6
32,-16,15:18.6
33,-16,15:18.6
34,-16,15:18.6
35,-16,15:18.6
36,-16,15:18.6
0,-15,15:18.6
1,-15,15:18.6
8,-15,15:18.6
9,-15,15:18.6
10,-15,15:18.14
19,-15,15:18.14
20,-15,15:18.14
21,-15,15:18.14
22,-15,15:18.14
23,-15,15:18.14
24,-15,15:18.14
25,-15,15:18.14
26,-15,15:18.14
28,-15,15:18.14
29,-15,15:18.6
30,-15,15:18.6
31,-15,15:18.6
32,-15,15:18.6
33,-15,15:18.6
36,-15,15:18.6
1,-14,15:18.6
8,-14,15:18.6
9,-14,15:18.14
10,-14,15:18.14
11,-14,15:18.14
20,-14,15:18.14
21,-14,15:18.14
22,-14,15:18.14
23,-14,15:18.14
24,-14,15:18.14
25,-14,15:18.14
26,-14,15:18.14
27,-14,15:18.14
28,-14,15:18.14
29,-14,15:18.6
30,-14,15:18.6
31,-14,15:18.6
32,-14,15:18.6
33,-14,15:18.6
37,-14,15:18.6
1,-13,15:18.6
7,-13,15:18.6
8,-13,15:18.6
9,-13,15:18.14
10,-13,15:18.14
11,-13,15:18.14
21,-13,15:18.14
22,-13,15:18.14
23,-13,15:18.14
24,-13,15:18.14
27,-13,15:18.14
28,-13,15:18.14
29,-13,15:18.6
30,-13,15:18.6
31,-13,15:18.6
32,-13,15:18.6
33,-13,15:18.6
37,-13,15:18.6
38,-13,15:18.6
1,-12,15:18.6
7,-12,15:18.6
8,-12,15:18.6
9,-12,15:18.14
10,-12,15:18.14
11,-12,15:18.14
27,-12,15:18.14
28,-12,15:18.14
29,-12,15:18.6
30,-12,15:18.6
31,-12,15:18.6
32,-12,15:18.6
38,-12,15:18.6
1,-11,15:18.6
6,-11,15:18.6
7,-11,15:18.6
8,-11,15:18.14
9,-11,15:18.14
10,-11,15:18.14
11,-11,15:18.14
15,-11,15:17.13
16,-11,15:17.13
17,-11,15:17.13
18,-11,15:17.13
19,-11,15:17.13
27,-11,15:18.14
28,-11,15:18.14
29,-11,15:18.14
30,-11,15:18.6
31,-11,15:18.6
32,-11,15:18.6
38,-11,15:18.6
39,-11,15:18.6
1,-10,15:18.6
3,-10,15:18.6
4,-10,15:18.6
5,-10,15:18.6
6,-10,15:18.6
7,-10,15:18.6
8,-10,15:18.14
9,-10,15:18.14
10,-10,15:18.14
11,-10,15:18.14
13,-10,15:17.13
14,-10,15:17.13
15,-10,15:17.13
19,-10,15:17.13
20,-10,15:17.13
21,-10,15:17.13
27,-10,15:18.14
29,-10,15:18.14
30,-10,15:18.6
31,-10,15:18.6
39,-10,15:18.6
1,-9,15:18.6
2,-9,15:18.6
3,-9,15:18.6
4,-9,15:18.6
5,-9,15:18.6
6,-9,15:18.6
7,-9,15:18.6
8,-9,15:18.14
9,-9,15:18.14
10,-9,15:18.14
13,-9,15:17.13
21,-9,15:17.13
26,-9,15:18.14
27,-9,15:18.14
28,-9,15:18.14
29,-9,15:18.14
30,-9,15:18.6
31,-9,15:18.6
40,-9,15:18.6
-1,-8,15:18.6
0,-8,15:18.6
1,-8,15:18.6
2,-8,15:18.6
3,-8,15:18.6
4,-8,15:18.6
5,-8,15:18.6
6,-8,15:18.6
7,-8,15:18.6
13,-8,15:17.13
21,-8,15:17.13
22,-8,15:17.13
26,-8,15:18.14
27,-8,15:18.14
28,-8,15:18.14
29,-8,15:18.14
30,-8,15:18.6
31,-8,15:18.6
40,-8,15:18.6
41,-8,15:18.6
42,-8,15:18.6
43,-8,15:18.6
44,-8,15:18.6
45,-8,15:18.6
46,-8,15:18.6
47,-8,15:18.6
-1,-7,15:18.6
0,-7,15:18.6
1,-7,15:18.6
2,-7,15:18.6
3,-7,15:18.6
4,-7,15:18.6
13,-7,15:17.13
21,-7,15:17.13
22,-7,15:17.13
25,-7,15:18.14
26,-7,15:18.14
27,-7,15:18.14
28,-7,15:18.14
29,-7,15:18.14
30,-7,15:18.6
40,-7,15:18.6
0,-6,15:18.6
1,-6,15:18.6
4,-6,15:18.6
13,-6,15:17.13
22,-6,15:17.13
25,-6,15:18.14
26,-6,15:18.14
27,-6,15:18.14
28,-6,15:18.14
29,-6,15:18.14
30,-6,15:18.6
39,-6,15:18.6
40,-6,15:18.6
1,-5,15:18.6
5,-5,15:18.6
13,-5,15:17.13
22,-5,15:17.13
25,-5,15:18.14
26,-5,15:18.14
27,-5,15:18.14
28,-5,15:18.14
29,-5,15:18.14
30,-5,15:18.6
39,-5,15:18.6
-1,-4,15:18.6
0,-4,15:18.6
1,-4,15:18.6
5,-4,15:18.6
13,-4,15:17.13
14,-4,15:17.13
21,-4,15:17.13
22,-4,15:17.13
24,-4,15:18.14
25,-4,15:18.14
26,-4,15:18.14
27,-4,15:18.14
28,-4,15:18.14
29,-4,15:18.14
38,-4,15:18.6
39,-4,15:18.6
1,-3,15:18.6
5,-3,15:18.6
6,-3,15:18.6
14,-3,15:17.13
15,-3,15:17.13
20,-3,15:17.13
21,-3,15:17.13
22,-3,15:17.13
24,-3,15:18.14
25,-3,15:18.14
26,-3,15:18.14
27,-3,15:18.14
28,-3,15:18.14
29,-3,15:18.14
38,-3,15:18.6
0,-2,15:18.6
1,-2,15:18.6
6,-2,15:18.6
7,-2,15:18.6
15,-2,15:17.13
16,-2,15:17.13
19,-2,15:17.13
20,-2,15:17.13
25,-2,15:18.14
26,-2,15:18.14
27,-2,15:18.14
28,-2,15:18.14
29,-2,15:18.14
37,-2,15:18.6
0,-1,15:18.6
1,-1,15:18.6
7,-1,15:18.6
16,-1,15:17.13
17,-1,15:17.13
18,-1,15:17.13
19,-1,15:17.13
25,-1,15:18.14
26,-1,15:18.14
27,-1,15:18.14
28,-1,15:18.6
37,-1,15:18.6
0,0,15:18.6
1,0,15:18.6
7,0,15:18.6
8,0,15:18.6
26,0,15:18.14
27,0,15:18.14
28,0,15:18.6
29,0,15:18.6
36,0,15:18.6
37,0,15:18.6
0,1,15:18.6
1,1,15:18.6
2,1,15:18.6
3,1,15:18.6
4,1,15:18.6
8,1,15:18.6
26,1,15:18.14
27,1,15:18.14
28,1,15:18.6
29,1,15:18.6
36,1,15:18.6
0,2,15:18.6
1,2,15:18.6
2,2,15:18.6
3,2,15:18.6
4,2,15:18.6
5,2,15:18.6
6,2,15:18.6
9,2,15:18.6
26,2,15:18.14
27,2,15:18.6
28,2,15:18.6
29,2,15:18.6
35,2,15:18.6
36,2,15:18.6
37,2,15:18.6
-1,3,15:18.6
0,3,15:18.6
1,3,15:18.6
2,3,15:18.6
3,3,15:18.6
4,3,15:18.6
5,3,15:18.6
6,3,15:18.6
9,3,15:18.6
10,3,15:18.6
25,3,15:18.6
28,3,15:18.6
29,3,15:18.6
30,3,15:18.6
34,3,15:18.6
35,3,15:18.6
37,3,15:18.6
38,3,15:18.6
-1,4,15:18.6
0,4,15:18.6
2,4,15:18.6
3,4,15:18.6
4,4,15:18.6
5,4,15:18.6
6,4,15:18.6
7,4,15:18.6
8,4,15:18.6
10,4,15:18.6
25,4,15:18.6
27,4,15:18.6
28,4,15:18.6
29,4,15:18.6
30,4,15:18.6
31,4,15:18.6
33,4,15:18.6
34,4,15:18.6
38,4,15:18.6
39,4,15:18.6
-1,5,15:18.6
0,5,15:18.6
1,5,15:18.6
2,5,15:18.6
3,5,15:18.6
4,5,15:18.6
5,5,15:18.6
6,5,15:18.6
7,5,15:18.6
8,5,15:18.6
9,5,15:18.6
10,5,15:18.6
11,5,15:18.6
12,5,15:18.6
13,5,15:18.14
14,5,15:18.14
15,5,15:18.14
16,5,15:18.14
17,5,15:18.14
18,5,15:18.14
19,5,15:18.14
20,5,15:18.14
21,5,15:18.14
22,5,15:18.6
23,5,15:18.6
24,5,15:18.6
28,5,15:18.6
29,5,15:18.6
30,5,15:18.6
32,5,15:18.6
33,5,15:18.6
39,5,15:18.6
40,5,15:18.6
-1,6,15:18.6
0,6,15:18.6
1,6,15:18.6
2,6,15:18.6
3,6,15:18.6
4,6,15:18.6
5,6,15:18.6
6,6,15:18.6
7,6,15:18.6
8,6,15:18.6
9,6,15:18.6
10,6,15:18.6
11,6,15:18.6
12,6,15:18.6
13,6,15:18.6
14,6,15:18.6
15,6,15:18.6
16,6,15:18.6
17,6,15:18.6
18,6,15:18.6
28,6,15:18.6
29,6,15:18.6
30,6,15:18.6
32,6,15:18.6
41,6,15:18.6
1,7,15:18.6
2,7,15:18.6
3,7,15:18.6
4,7,15:18.6
5,7,15:18.6
6,7,15:18.6
7,7,15:18.6
8,7,15:18.6
9,7,15:18.6
10,7,15:18.6
11,7,15:18.6
12,7,15:18.6
13,7,15:18.6
14,7,15:18.6
15,7,15:18.6
16,7,15:18.6
17,7,15:18.6
18,7,15:18.6
19,7,15:18.6
29,7,15:18.6
30,7,15:18.6
31,7,15:18.6
1,8,15:18.6
2,8,15:18.6
3,8,15:18.6
5,8,15:18.6
6,8,15:18.6
7,8,15:18.6
8,8,15:18.6
9,8,15:18.6
10,8,15:18.6
11,8,15:18.6
12,8,15:18.6
13,8,15:18.6
14,8,15:18.6
15,8,15:18.6
16,8,15:18.6
17,8,15:18.6
18,8,15:18.6
19,8,15:18.6
20,8,15:18.6
29,8,15:18.6
30,8,15:18.6
31,8,15:18.6
3,9,15:18.6
5,9,15:18.6
6,9,15:18.6
7,9,15:18.6
8,9,15:18.6
10,9,15:18.6
11,9,15:18.6
12,9,15:18.6
13,9,15:18.6
14,9,15:18.6
15,9,15:18.6
16,9,15:18.6
17,9,15:18.6
18,9,15:18.6
19,9,15:18.6
20,9,15:18.6
21,9,15:18.6
28,9,15:18.6
29,9,15:18.6
30,9,15:18.6
31,9,15:18.6
3,10,15:18.6
4,10,15:18.6
5,10,15:18.6
6,10,15:18.6
7,10,15:18.6
8,10,15:18.6
9,10,15:18.6
10,10,15:18.6
11,10,15:18.6
12,10,15:18.6
13,10,15:18.6
14,10,15:18.6
15,10,15:18.6
16,10,15:18.6
17,10,15:18.6
18,10,15:18.6
19,10,15:18.6
20,10,15:18.6
21,10,15:18.6
22,10,15:18.6
25,10,15:18.6
26,10,15:18.6
27,10,15:18.6
28,10,15:18.6
4,11,15:18.6
5,11,15:18.6
6,11,15:18.6
7,11,15:18.6
8,11,15:18.6
9,11,15:18.6
10,11,15:18.6
11,11,15:18.6
12,11,15:18.6
13,11,15:18.6
14,11,15:18.6
15,11,15:18.6
16,11,15:18.6
17,11,15:18.6
18,11,15:18.6
19,11,15:18.6
20,11,15:18.6
22,11,15:18.6
23,11,15:18.6
24,11,15:18.6
25,11,15:18.6
29,11,15:18.6
4,12,15:18.6
5,12,15:18.6
7,12,15:18.6
8,12,15:18.6
9,12,15:18.6
10,12,15:18.6
11,12,15:18.6
12,12,15:18.6
13,12,15:18.6
14,12,15:18.6
15,12,15:18.6
16,12,15:18.6
17,12,15:18.6
18,12,15:18.6
19,12,15:18.6
20,12,15:18.6
21,12,15:18.6
22,12,15:18.6
25,12,15:18.6
5,13,15:18.6
6,13,15:18.6
7,13,15:18.6
9,13,15:18.6
10,13,15:18.6
11,13,15:18.6
14,13,15:18.6
15,13,15:18.6
16,13,15:18.6
17,13,15:18.6
18,13,15:18.6
19,13,15:18.6
20,13,15:18.6
21,13,15:18.6
6,14,15:18.6
7,14,15:18.6
8,14,15:18.6
9,14,15:18.6
10,14,15:18.6
11,14,15:18.6
12,14,15:18.6
13,14,15:18.6
14,14,15:18.6
15,14,15:18.6
16,14,15:18.6
18,14,15:18.6
19,14,15:18.6
20,14,15:18.6
21,14,15:18.6
6,15,15:18.6
18,15,15:18.6
6,16,15:18.6
18,16,15:18.6
5,18,15:18.6
4,19,15:18.6
17,-34,16:18.6
16,-33,16:18.6
17,-33,16:18.6
0,-32,16:18.6
16,-32,16:18.6
1,-31,16:18.6
16,-31,16:18.6
2,-30,16:18.6
16,-30,16:18.6
2,-29,16:18.6
3,-29,16:18.6
16,-29,16:18.6
3,-28,16:18.6
15,-28,16:18.6
16,-28,16:18.6
4,-27,16:18.6
15,-27,16:18.6
29,-27,16:18.6
4,-26,16:18.6
5,-26,16:18.6
6,-26,16:18.6
7,-26,16:18.6
8,-26,16:18.6
9,-26,16:18.6
10,-26,16:18.6
11,-26,16:18.6
12,-26,16:18.6
13,-26,16:18.6
14,-26,16:18.6
15,-26,16:18.6
16,-26,16:18.6
17,-26,16:18.6
29,-26,16:18.6
4,-25,16:18.6
17,-25,16:18.6
18,-25,16:18.6
28,-25,16:18.6
4,-24,16:18.6
19,-24,16:18.6
20,-24,16:18.6
28,-24,16:18.6
3,-23,16:18.6
20,-23,16:18.6
21,-23,16:18.6
22,-23,16:18.6
27,-23,16:18.6
3,-22,16:18.6
22,-22,16:18.6
23,-22,16:18.6
27,-22,16:18.6
37,-22,16:18.6
38,-22,16:18.6
2,-21,16:18.6
3,-21,16:18.6
23,-21,16:18.6
24,-21,16:18.6
26,-21,16:18.6
37,-21,16:18.6
2,-20,16:18.6
24,-20,16:18.6
25,-20,16:18.6
26,-20,16:18.6
36,-20,16:18.6
37,-20,16:18.6
1,-19,16:18.6
2,-19,16:18.6
25,-19,16:18.6
26,-19,16:18.6
27,-19,16:18.6
28,-19,16:18.6
36,-19,16:18.6
1,-18,16:18.6
10,-18,16:18.14
11,-18,16:18.14
12,-18,16:18.14
13,-18,16:18.14
14,-18,16:18.14
15,-18,16:18.14
16,-18,16:18.14
17,-18,16:18.14
18,-18,16:18.14
19,-18,16:18.14
20,-18,16:18.6
21,-18,16:18.6
22,-18,16:18.6
23,-18,16:18.6
29,-18,16:18.6
30,-18,16:18.6
31,-18,16:18.6
32,-18,16:18.6
35,-18,16:18.6
36,-18,16:18.6
0,-17,16:18.6
1,-17,16:18.6
10,-17,16:18.14
24,-17,16:18.14
32,-17,16:18.6
33,-17,16:18.6
34,-17,16:18.6
35,-17,16:18.6
-7,-16,16:18.6
-5,-16,16:18.6
-4,-16,16:18.6
-3,-16,16:18.6
-2,-16,16:18.6
-1,-16,16:18.6
0,-16,16:18.6
1,-16,16:18.6
9,-16,16:18.14
12,-16,16:18.14
13,-16,16:18.14
14,-16,16:18.14
15,-16,16:18.14
16,-16,16:18.14
17,-16,16:18.14
24,-16,16:18.14
25,-16,16:18.14
35,-16,16:18.6
36,-16,16:18.6
1,-15,16:18.6
8,-15,16:18.14
9,-15,16:18.14
12,-15,16:18.14
13,-15,16:18.14
14,-15,16:18.14
15,-15,16:18.14
16,-15,16:18.14
17,-15,16:18.14
25,-15,16:18.14
36,-15,16:18.6
1,-14,16:18.6
8,-14,16:18.14
11,-14,16:18.14
12,-14,16:18.14
13,-14,16:18.14
14,-14,16:18.14
15,-14,16:18.14
16,-14,16:18.14
17,-14,16:18.14
18,-14,16:18.14
19,-14,16:18.14
20,-14,16:18.14
26,-14,16:18.14
36,-14,16:18.6
37,-14,16:18.6
1,-13,16:18.6
7,-13,16:18.6
8,-13,16:18.14
11,-13,16:18.14
12,-13,16:18.14
13,-13,16:18.14
14,-13,16:18.14
15,-13,16:18.14
16,-13,16:18.14
17,-13,16:18.14
18,-13,16:18.14
19,-13,16:18.14
20,-13,16:18.14
21,-13,16:18.14
22,-13,16:18.14
23,-13,16:18.14
24,-13,16:18.14
25,-13,16:18.14
26,-13,16:18.14
27,-13,16:18.14
37,-13,16:18.6
1,-12,16:18.6
7,-12,16:18.6
11,-12,16:18.14
12,-12,16:18.14
13,-12,16:18.14
14,-12,16:18.14
15,-12,16:18.14
16,-12,16:18.14
17,-12,16:18.14
18,-12,16:18.14
19,-12,16:18.14
20,-12,16:18.14
21,-12,16:18.14
22,-12,16:18.14
23,-12,16:18.14
24,-12,16:18.14
25,-12,16:18.14
26,-12,16:18.14
27,-12,16:18.14
37,-12,16:18.6
38,-12,16:18.6
1,-11,16:18.6
6,-11,16:18.6
7,-11,16:18.6
12,-11,16:18.14
13,-11,16:18.14
14,-11,16:18.14
15,-11,16:18.14
16,-11,16:17.13
17,-11,16:17.13
18,-11,16:17.13
19,-11,16:18.14
20,-11,16:18.14
21,-11,16:18.14
22,-11,16:18.14
23,-11,16:18.14
24,-11,16:18.14
25,-11,16:18.14
26,-11,16:18.14
27,-11,16:18.14
28,-11,16:18.14
38,-11,16:18.6
1,-10,16:18.6
6,-10,16:18.6
12,-10,16:18.14
13,-10,16:17.13
14,-10,16:18.14
15,-10,16:18.14
16,-10,16:18.14
17,-10,16:18.14
18,-10,16:18.14
19,-10,16:18.14
20,-10,16:17.13
21,-10,16:18.14
22,-10,16:18.14
23,-10,16:18.14
24,-10,16:18.14
25,-10,16:18.14
26,-10,16:18.14
29,-10,16:18.14
39,-10,16:18.6
1,-9,16:18.6
5,-9,16:18.6
6,-9,16:18.6
9,-9,16:18.14
10,-9,16:18.14
11,-9,16:18.14
12,-9,16:18.14
13,-9,16:18.14
14,-9,16:18.14
15,-9,16:18.14
18,-9,16:18.14
19,-9,16:18.14
20,-9,16:18.14
21,-9,16:18.14
22,-9,16:17.13
23,-9,16:18.14
24,-9,16:18.14
25,-9,16:18.14
26,-9,16:18.14
29,-9,16:18.14
39,-9,16:18.6
40,-9,16:18.6
1,-8,16:18.6
5,-8,16:18.6
6,-8,16:18.6
7,-8,16:18.6
8,-8,16:18.14
9,-8,16:18.14
10,-8,16:18.14
11,-8,16:18.14
12,-8,16:18.14
13,-8,16:18.14
14,-8,16:18.14
15,-8,16:18.14
20,-8,16:18.14
21,-8,16:18.14
22,-8,16:17.13
23,-8,16:18.14
24,-8,16:18.14
25,-8,16:18.14
30,-8,16:18.14
40,-8,16:18.6
41,-8,16:18.6
42,-8,16:18.6
43,-8,16:18.6
44,-8,16:18.6
45,-8,16:18.6
46,-8,16:18.6
47,-8,16:18.6
48,-8,16:18.6
1,-7,16:18.6
4,-7,16:18.6
5,-7,16:18.6
6,-7,16:18.6
7,-7,16:18.6
8,-7,16:18.14
9,-7,16:18.14
10,-7,16:18.14
11,-7,16:18.14
12,-7,16:18.14
13,-7,16:18.14
20,-7,16:18.14
21,-7,16:18.14
22,-7,16:17.13
23,-7,16:18.14
24,-7,16:18.14
25,-7,16:18.14
30,-7,16:18.14
40,-7,16:18.6
1,-6,16:18.6
2,-6,16:18.6
3,-6,16:18.6
4,-6,16:18.6
5,-6,16:18.6
6,-6,16:18.6
7,-6,16:18.6
8,-6,16:18.14
9,-6,16:18.14
10,-6,16:18.14
12,-6,16:17.13
20,-6,16:18.14
21,-6,16:18.14
22,-6,16:18.14
23,-6,16:18.14
24,-6,16:18.14
25,-6,16:18.14
29,-6,16:18.14
30,-6,16:18.14
39,-6,16:18.6
1,-5,16:18.6
2,-5,16:18.6
3,-5,16:18.6
5,-5,16:18.6
6,-5,16:18.6
7,-5,16:18.6
8,-5,16:18.14
9,-5,16:18.14
10,-5,16:18.14
12,-5,16:17.13
13,-5,16:17.13
20,-5,16:18.14
21,-5,16:18.14
22,-5,16:18.14
23,-5,16:18.14
24,-5,16:18.14
29,-5,16:18.14
39,-5,16:18.6
-3,-4,16:18.6
-2,-4,16:18.6
-1,-4,16:18.6
0,-4,16:18.6
1,-4,16:18.6
2,-4,16:18.6
3,-4,16:18.6
4,-4,16:18.6
5,-4,16:18.6
6,-4,16:18.6
7,-4,16:18.6
8,-4,16:18.14
9,-4,16:18.14
10,-4,16:18.14
11,-4,16:18.14
12,-4,16:18.14
13,-4,16:17.13
14,-4,16:17.13
20,-4,16:18.14
21,-4,16:18.14
22,-4,16:18.14
23,-4,16:18.14
24,-4,16:18.14
28,-4,16:18.14
29,-4,16:18.14
38,-4,16:18.6
1,-3,16:18.6
2,-3,16:18.6
3,-3,16:18.6
4,-3,16:18.6
5,-3,16:18.6
6,-3,16:18.6
7,-3,16:18.6
8,-3,16:18.14
9,-3,16:18.14
10,-3,16:18.14
11,-3,16:18.14
12,-3,16:18.14
13,-3,16:18.14
14,-3,16:17.13
15,-3,16:18.14
21,-3,16:18.14
22,-3,16:17.13
23,-3,16:18.14
24,-3,16:18.14
28,-3,16:18.14
38,-3,16:18.6
-1,-2,16:18.6
0,-2,16:18.6
1,-2,16:18.6
2,-2,16:18.6
3,-2,16:18.6
4,-2,16:18.6
5,-2,16:18.6
6,-2,16:18.6
7,-2,16:18.6
8,-2,16:18.14
9,-2,16:18.14
10,-2,16:18.14
11,-2,16:18.14
12,-2,16:18.14
13,-2,16:18.14
14,-2,16:18.14
15,-2,16:17.13
16,-2,16:18.14
17,-2,16:18.14
18,-2,16:18.14
20,-2,16:17.13
21,-2,16:17.13
22,-2,16:18.14
23,-2,16:18.14
24,-2,16:18.14
27,-2,16:18.14
28,-2,16:18.14
37,-2,16:18.6
-1,-1,16:18.6
0,-1,16:18.6
1,-1,16:18.6
2,-1,16:18.6
3,-1,16:18.6
4,-1,16:18.6
5,-1,16:18.6
6,-1,16:18.6
7,-1,16:18.6
8,-1,16:18.14
9,-1,16:18.14
10,-1,16:18.14
11,-1,16:18.14
12,-1,16:18.14
13,-1,16:18.14
14,-1,16:18.14
15,-1,16:18.14
16,-1,16:17.13
17,-1,16:18.14
18,-1,16:18.14
19,-1,16:17.13
20,-1,16:17.13
21,-1,16:18.14
22,-1,16:18.14
23,-1,16:18.14
24,-1,16:18.14
25,-1,16:18.14
27,-1,16:18.14
37,-1,16:18.6
1,0,16:18.6
2,0,16:18.6
3,0,16:18.6
4,0,16:18.6
5,0,16:18.6
6,0,16:18.6
7,0,16:18.6
8,0,16:18.6
9,0,16:18.14
10,0,16:18.14
11,0,16:18.14
12,0,16:18.14
13,0,16:18.14
14,0,16:18.14
15,0,16:18.14
16,0,16:18.14
17,0,16:17.13
18,0,16:17.13
19,0,16:18.14
20,0,16:18.14
22,0,16:18.14
23,0,16:18.14
24,0,16:18.14
25,0,16:18.14
26,0,16:18.14
27,0,16:18.14
36,0,16:18.6
1,1,16:18.6
3,1,16:18.6
4,1,16:18.6
5,1,16:18.6
6,1,16:18.6
7,1,16:18.6
8,1,16:18.6
9,1,16:18.6
10,1,16:18.14
11,1,16:18.14
12,1,16:18.14
13,1,16:18.14
14,1,16:18.14
15,1,16:18.14
16,1,16:18.14
17,1,16:18.14
18,1,16:18.14
19,1,16:18.14
20,1,16:18.14
21,1,16:18.14
22,1,16:18.14
23,1,16:18.14
24,1,16:18.14
25,1,16:18.14
26,1,16:18.14
36,1,16:18.6
1,2,16:18.6
6,2,16:18.6
7,2,16:18.6
8,2,16:18.6
9,2,16:18.6
10,2,16:18.14
11,2,16:18.14
13,2,16:18.14
14,2,16:18.14
15,2,16:18.14
16,2,16:18.14
17,2,16:18.14
18,2,16:18.14
19,2,16:18.14
20,2,16:18.14
21,2,16:18.14
22,2,16:18.14
23,2,16:18.14
24,2,16:18.14
25,2,16:18.14
26,2,16:18.14
35,2,16:18.6
36,2,16:18.6
37,2,16:18.6
1,3,16:18.6
8,3,16:18.6
9,3,16:18.6
10,3,16:18.6
11,3,16:18.14
12,3,16:18.14
13,3,16:18.14
14,3,16:18.14
15,3,16:18.14
16,3,16:18.14
17,3,16:18.14
18,3,16:18.14
19,3,16:18.14
20,3,16:18.14
21,3,16:18.14
22,3,16:18.14
23,3,16:18.14
24,3,16:18.14
25,3,16:18.14
26,3,16:18.14
34,3,16:18.6
37,3,16:18.6
38,3,16:18.6
9,4,16:18.6
10,4,16:18.6
11,4,16:18.6
12,4,16:18.14
13,4,16:18.14
14,4,16:18.14
15,4,16:18.14
16,4,16:18.14
17,4,16:18.14
18,4,16:18.14
19,4,16:18.14
20,4,16:18.14
21,4,16:18.14
22,4,16:18.14
23,4,16:18.14
24,4,16:18.14
25,4,16:18.14
26,4,16:18.14
27,4,16:18.14
33,4,16:18.6
38,4,16:18.6
39,4,16:18.6
0,5,16:18.6
1,5,16:18.6
10,5,16:18.6
11,5,16:18.6
12,5,16:18.6
13,5,16:18.14
14,5,16:18.14
15,5,16:18.14
16,5,16:18.14
17,5,16:18.14
18,5,16:18.14
19,5,16:18.14
20,5,16:18.14
21,5,16:18.14
22,5,16:18.14
23,5,16:18.14
24,5,16:18.14
25,5,16:18.14
26,5,16:18.14
27,5,16:18.14
32,5,16:18.6
33,5,16:18.6
40,5,16:18.6
-4,6,16:18.6
-3,6,16:18.6
-2,6,16:18.6
-1,6,16:18.6
1,6,16:18.6
2,6,16:18.6
15,6,16:18.6
16,6,16:18.6
17,6,16:18.6
18,6,16:18.6
19,6,16:18.6
20,6,16:18.6
21,6,16:18.6
22,6,16:18.6
23,6,16:18.6
24,6,16:18.6
25,6,16:18.6
26,6,16:18.6
27,6,16:18.6
28,6,16:18.6
31,6,16:18.6
32,6,16:18.6
41,6,16:18.6
2,7,16:18.6
19,7,16:18.6
20,7,16:18.6
21,7,16:18.6
22,7,16:18.6
23,7,16:18.6
24,7,16:18.6
25,7,16:18.6
26,7,16:18.6
27,7,16:18.6
28,7,16:18.6
30,7,16:18.6
31,7,16:18.6
2,8,16:18.6
3,8,16:18.6
20,8,16:18.6
21,8,16:18.6
22,8,16:18.6
23,8,16:18.6
24,8,16:18.6
25,8,16:18.6
26,8,16:18.6
27,8,16:18.6
28,8,16:18.6
29,8,16:18.6
30,8,16:18.6
3,9,16:18.6
4,9,16:18.6
22,9,16:18.6
23,9,16:18.6
24,9,16:18.6
25,9,16:18.6
26,9,16:18.6
27,9,16:18.6
28,9,16:18.6
29,9,16:18.6
4,10,16:18.6
23,10,16:18.6
24,10,16:18.6
25,10,16:18.6
26,10,16:18.6
28,10,16:18.6
4,11,16:18.6
5,11,16:18.6
20,11,16:18.6
22,11,16:18.6
23,11,16:18.6
24,11,16:18.6
25,11,16:18.6
26,11,16:18.6
29,11,16:18.6
5,12,16:18.6
6,12,16:18.6
18,12,16:18.6
19,12,16:18.6
20,12,16:18.6
25,12,16:18.6
26,12,16:18.6
29,12,16:18.6
6,13,16:18.6
17,13,16:18.6
18,13,16:18.6
6,14,16:18.6
7,14,16:18.6
8,14,16:18.6
9,14,16:18.6
10,14,16:18.6
11,14,16:18.6
12,14,16:18.6
13,14,16:18.6
14,14,16:18.6
15,14,16:18.6
16,14,16:18.6
18,14,16:18.6
6,15,16:18.6
18,15,16:18.6
6,16,16:18.6
18,16,16:18.6
5,17,16:18.6
19,17,16:18.6
5,18,16:18.6
19,18,16:18.6
4,19,16:18.6
19,19,16:18.6
20,19,16:18.6
4,20,16:18.6
17,-35,17:18.6
17,-34,17:18.6
16,-33,17:18.6
17,-33,17:18.6
16,-32,17:18.6
1,-31,17:18.6
16,-31,17:18.6
2,-30,17:18.6
16,-30,17:18.6
2,-29,17:18.6
3,-29,17:18.6
16,-29,17:18.6
3,-28,17:18.6
15,-28,17:18.6
16,-28,17:18.6
4,-27,17:18.6
15,-27,17:18.6
4,-26,17:18.6
5,-26,17:18.6
6,-26,17:18.6
7,-26,17:18.6
8,-26,17:18.6
9,-26,17:18.6
10,-26,17:18.6
11,-26,17:18.6
12,-26,17:18.6
13,-26,17:18.6
14,-26,17:18.6
15,-26,17:18.6
16,-26,17:18.6
29,-26,17:18.6
4,-25,17:18.6
5,-25,17:18.6
16,-25,17:18.6
17,-25,17:18.6
18,-25,17:18.6
28,-25,17:18.6
4,-24,17:18.6
18,-24,17:18.6
19,-24,17:18.6
27,-24,17:18.6
28,-24,17:18.6
3,-23,17:18.6
4,-23,17:18.6
20,-23,17:18.6
21,-23,17:18.6
27,-23,17:18.6
38,-23,17:18.6
3,-22,17:18.6
21,-22,17:18.6
22,-22,17:18.6
23,-22,17:18.6
26,-22,17:18.6
27,-22,17:18.6
37,-22,17:18.6
38,-22,17:18.6
2,-21,17:18.6
3,-21,17:18.6
23,-21,17:18.6
24,-21,17:18.6
26,-21,17:18.6
37,-21,17:18.6
2,-20,17:18.6
24,-20,17:18.6
25,-20,17:18.6
26,-20,17:18.6
36,-20,17:18.6
2,-19,17:18.6
25,-19,17:18.6
26,-19,17:18.6
27,-19,17:18.6
36,-19,17:18.6
1,-18,17:18.6
11,-18,17:18.14
12,-18,17:18.14
13,-18,17:18.14
14,-18,17:18.14
15,-18,17:18.14
16,-18,17:18.14
17,-18,17:18.14
18,-18,17:18.14
19,-18,17:18.14
20,-18,17:18.6
21,-18,17:18.6
22,-18,17:18.6
23,-18,17:18.6
28,-18,17:18.6
29,-18,17:18.6
30,-18,17:18.6
35,-18,17:18.6
1,-17,17:18.6
10,-17,17:18.14
11,-17,17:18.14
23,-17,17:18.14
24,-17,17:18.14
31,-17,17:18.6
32,-17,17:18.6
33,-17,17:18.6
34,-17,17:18.6
35,-17,17:18.6
-7,-16,17:18.6
-5,-16,17:18.6
-4,-16,17:18.6
-3,-16,17:18.6
-2,-16,17:18.6
-1,-16,17:18.6
0,-16,17:18.6
1,-16,17:18.6
9,-16,17:18.14
10,-16,17:18.14
24,-16,17:18.14
35,-16,17:18.6
1,-15,17:18.6
9,-15,17:18.14
25,-15,17:18.14
35,-15,17:18.6
36,-15,17:18.6
1,-14,17:18.6
2,-14,17:18.6
8,-14,17:18.14
25,-14,17:18.14
26,-14,17:18.14
36,-14,17:18.6
2,-13,17:18.6
8,-13,17:18.14
26,-13,17:18.14
37,-13,17:18.6
2,-12,17:18.6
7,-12,17:18.14
27,-12,17:18.14
37,-12,17:18.6
38,-12,17:18.6
2,-11,17:18.6
7,-11,17:18.6
15,-11,17:17.13
16,-11,17:17.13
17,-11,17:17.13
18,-11,17:17.13
19,-11,17:17.13
27,-11,17:18.14
28,-11,17:18.14
38,-11,17:18.6
2,-10,17:18.6
6,-10,17:18.6
13,-10,17:17.13
14,-10,17:17.13
15,-10,17:17.13
16,-10,17:18.14
17,-10,17:18.14
20,-10,17:17.13
21,-10,17:17.13
38,-10,17:18.6
39,-10,17:18.6
2,-9,17:18.6
6,-9,17:18.6
13,-9,17:17.13
15,-9,17:18.14
16,-9,17:18.14
17,-9,17:18.14
18,-9,17:18.14
19,-9,17:18.14
20,-9,17:18.14
22,-9,17:17.13
29,-9,17:18.14
39,-9,17:18.6
2,-8,17:18.6
5,-8,17:18.6
13,-8,17:17.13
14,-8,17:17.13
15,-8,17:18.14
16,-8,17:18.14
17,-8,17:18.14
19,-8,17:18.14
20,-8,17:18.14
22,-8,17:17.13
29,-8,17:18.14
30,-8,17:18.14
40,-8,17:18.6
41,-8,17:18.6
42,-8,17:18.6
43,-8,17:18.6
44,-8,17:18.6
45,-8,17:18.6
46,-8,17:18.6
47,-8,17:18.6
2,-7,17:18.6
5,-7,17:18.6
12,-7,17:17.13
13,-7,17:17.13
14,-7,17:18.14
15,-7,17:18.14
16,-7,17:18.14
17,-7,17:18.14
18,-7,17:18.14
19,-7,17:18.14
20,-7,17:18.14
22,-7,17:17.13
23,-7,17:17.13
30,-7,17:18.14
39,-7,17:18.6
40,-7,17:18.6
2,-6,17:18.6
4,-6,17:18.6
5,-6,17:18.6
10,-6,17:18.14
11,-6,17:18.14
12,-6,17:18.14
13,-6,17:17.13
14,-6,17:18.14
15,-6,17:18.14
16,-6,17:18.14
17,-6,17:18.14
18,-6,17:18.14
19,-6,17:18.14
23,-6,17:17.13
29,-6,17:18.14
39,-6,17:18.6
2,-5,17:18.6
5,-5,17:18.6
10,-5,17:18.14
11,-5,17:18.14
12,-5,17:18.14
13,-5,17:17.13
14,-5,17:18.14
15,-5,17:18.14
16,-5,17:18.14
17,-5,17:18.14
18,-5,17:18.14
19,-5,17:18.14
23,-5,17:17.13
29,-5,17:18.14
38,-5,17:18.6
39,-5,17:18.6
-4,-4,17:18.6
-3,-4,17:18.6
-2,-4,17:18.6
-1,-4,17:18.6
0,-4,17:18.6
1,-4,17:18.6
2,-4,17:18.6
5,-4,17:18.6
6,-4,17:18.14
13,-4,17:17.13
14,-4,17:17.13
15,-4,17:18.14
16,-4,17:18.14
17,-4,17:18.14
18,-4,17:18.14
19,-4,17:18.14
20,-4,17:18.14
23,-4,17:17.13
28,-4,17:18.14
38,-4,17:18.6
1,-3,17:18.6
6,-3,17:18.14
14,-3,17:17.13
15,-3,17:17.13
16,-3,17:18.14
17,-3,17:18.14
18,-3,17:18.14
19,-3,17:18.14
20,-3,17:18.14
22,-3,17:17.13
23,-3,17:17.13
28,-3,17:18.14
37,-3,17:18.6
38,-3,17:18.6
1,-2,17:18.6
7,-2,17:18.14
14,-2,17:17.13
15,-2,17:17.13
16,-2,17:17.13
18,-2,17:18.14
19,-2,17:18.14
20,-2,17:18.14
21,-2,17:17.13
22,-2,17:17.13
27,-2,17:18.14
37,-2,17:18.6
1,-1,17:18.6
7,-1,17:18.14
8,-1,17:18.14
15,-1,17:17.13
16,-1,17:17.13
17,-1,17:17.13
19,-1,17:17.13
20,-1,17:17.13
21,-1,17:18.14
27,-1,17:18.14
36,-1,17:18.6
37,-1,17:18.6
1,0,17:18.6
8,0,17:18.14
16,0,17:17.13
17,0,17:17.13
18,0,17:17.13
19,0,17:17.13
21,0,17:18.14
22,0,17:18.14
26,0,17:18.14
36,0,17:18.6
1,1,17:18.6
9,1,17:18.14
17,1,17:17.13
22,1,17:18.14
26,1,17:18.14
35,1,17:18.6
36,1,17:18.6
1,2,17:18.6
9,2,17:18.14
10,2,17:18.14
25,2,17:18.14
34,2,17:18.6
35,2,17:18.6
36,2,17:18.6
37,2,17:18.6
1,3,17:18.6
10,3,17:18.6
25,3,17:18.14
33,3,17:18.6
34,3,17:18.6
37,3,17:18.6
38,3,17:18.6
11,4,17:18.6
15,4,17:18.14
16,4,17:18.14
17,4,17:18.14
18,4,17:18.14
19,4,17:18.14
20,4,17:18.14
21,4,17:18.14
22,4,17:18.14
23,4,17:18.14
24,4,17:18.14
33,4,17:18.6
38,4,17:18.6
39,4,17:18.6
0,5,17:18.6
1,5,17:18.6
11,5,17:18.6
12,5,17:18.6
13,5,17:18.14
14,5,17:18.14
15,5,17:18.14
16,5,17:18.14
17,5,17:18.14
32,5,17:18.6
40,5,17:18.6
-4,6,17:18.6
-3,6,17:18.6
-2,6,17:18.6
-1,6,17:18.6
1,6,17:18.6
2,6,17:18.6
31,6,17:18.6
41,6,17:18.6
2,7,17:18.6
30,7,17:18.6
3,8,17:18.6
27,8,17:18.6
28,8,17:18.6
29,8,17:18.6
30,8,17:18.6
3,9,17:18.6
4,9,17:18.6
24,9,17:18.6
25,9,17:18.6
26,9,17:18.6
27,9,17:18.6
28,9,17:18.6
4,10,17:18.6
21,10,17:18.6
22,10,17:18.6
23,10,17:18.6
24,10,17:18.6
28,10,17:18.6
5,11,17:18.6
19,11,17:18.6
20,11,17:18.6
29,11,17:18.6
5,12,17:18.6
6,12,17:18.6
18,12,17:18.6
19,12,17:18.6
29,12,17:18.6
30,12,17:18.6
6,13,17:18.6
12,13,17:18.6
13,13,17:18.6
14,13,17:18.6
15,13,17:18.6
16,13,17:18.6
17,13,17:18.6
18,13,17:18.6
30,13,17:18.6
7,14,17:18.6
8,14,17:18.6
9,14,17:18.6
10,14,17:18.6
11,14,17:18.6
12,14,17:18.6
13,14,17:18.6
14,14,17:18.6
18,14,17:18.6
6,15,17:18.6
18,15,17:18.6
6,16,17:18.6
18,16,17:18.6
5,17,17:18.6
19,17,17:18.6
5,18,17:18.6
19,18,17:18.6
4,19,17:18.6
19,19,17:18.6
20,19,17:18.6
4,20,17:18.6
3,21,17:18.6
17,-35,18:18.6
17,-34,18:18.6
16,-33,18:18.6
16,-32,18:18.6
1,-31,18:18.6
16,-31,18:18.6
2,-30,18:18.6
16,-30,18:18.6
2,-29,18:18.6
3,-29,18:18.6
16,-29,18:18.6
3,-28,18:18.6
15,-28,18:18.6
4,-27,18:18.6
15,-27,18:18.6
4,-26,18:18.6
5,-26,18:18.6
7,-26,18:18.6
8,-26,18:18.6
9,-26,18:18.6
10,-26,18:18.6
11,-26,18:18.6
12,-26,18:18.6
13,-26,18:18.6
14,-26,18:18.6
15,-26,18:18.6
16,-26,18:18.6
29,-26,18:18.6
5,-25,18:18.6
6,-25,18:18.6
7,-25,18:18.6
8,-25,18:18.6
16,-25,18:18.6
17,-25,18:18.6
28,-25,18:18.6
4,-24,18:18.6
18,-24,18:18.6
19,-24,18:18.6
27,-24,18:18.6
28,-24,18:18.6
4,-23,18:18.6
19,-23,18:18.6
20,-23,18:18.6
21,-23,18:18.6
27,-23,18:18.6
38,-23,18:18.6
3,-22,18:18.6
21,-22,18:18.6
22,-22,18:18.6
26,-22,18:18.6
27,-22,18:18.6
37,-22,18:18.6
3,-21,18:18.6
22,-21,18:18.6
23,-21,18:18.6
26,-21,18:18.6
37,-21,18:18.6
2,-20,18:18.6
3,-20,18:18.6
23,-20,18:18.6
24,-20,18:18.6
25,-20,18:18.6
36,-20,18:18.6
2,-19,18:18.6
24,-19,18:18.6
25,-19,18:18.6
26,-19,18:18.6
36,-19,18:18.6
1,-18,18:18.6
2,-18,18:18.6
14,-18,18:18.14
15,-18,18:18.14
16,-18,18:18.14
17,-18,18:18.14
18,-18,18:18.14
19,-18,18:18.14
20,-18,18:18.14
21,-18,18:18.14
22,-18,18:18.14
23,-18,18:18.14
26,-18,18:18.6
27,-18,18:18.6
28,-18,18:18.6
29,-18,18:18.6
35,-18,18:18.6
1,-17,18:18.6
10,-17,18:18.14
11,-17,18:18.14
12,-17,18:18.14
13,-17,18:18.14
14,-17,18:18.14
15,-17,18:18.14
23,-17,18:18.14
24,-17,18:18.14
30,-17,18:18.14
31,-17,18:18.6
32,-17,18:18.6
33,-17,18:18.6
34,-17,18:18.6
35,-17,18:18.6
-7,-16,18:18.6
-5,-16,18:18.6
-4,-16,18:18.6
-3,-16,18:18.6
-2,-16,18:18.6
-1,-16,18:18.6
0,-16,18:18.6
1,-16,18:18.6
9,-16,18:18.14
10,-16,18:18.14
24,-16,18:18.14
35,-16,18:18.6
1,-15,18:18.6
9,-15,18:18.14
24,-15,18:18.14
25,-15,18:18.14
35,-15,18:18.6
36,-15,18:18.6
2,-14,18:18.6
8,-14,18:18.14
9,-14,18:18.14
25,-14,18:18.14
26,-14,18:18.14
36,-14,18:18.6
2,-13,18:18.6
8,-13,18:18.14
26,-13,18:18.14
36,-13,18:18.6
37,-13,18:18.6
2,-12,18:18.6
7,-12,18:18.14
8,-12,18:18.14
26,-12,18:18.14
27,-12,18:18.14
37,-12,18:18.6
2,-11,18:18.6
7,-11,18:18.6
16,-11,18:17.13
17,-11,18:17.13
18,-11,18:17.13
19,-11,18:17.13
20,-11,18:17.13
27,-11,18:18.14
28,-11,18:18.14
37,-11,18:18.6
38,-11,18:18.6
2,-10,18:18.6
6,-10,18:18.6
7,-10,18:18.6
14,-10,18:17.13
15,-10,18:17.13
16,-10,18:17.13
20,-10,18:17.13
21,-10,18:17.13
38,-10,18:18.6
2,-9,18:18.6
6,-9,18:18.6
13,-9,18:17.13
14,-9,18:17.13
22,-9,18:17.13
28,-9,18:18.14
29,-9,18:18.14
39,-9,18:18.6
2,-8,18:18.6
5,-8,18:18.6
6,-8,18:18.6
14,-8,18:17.13
20,-8,18:17.13
21,-8,18:17.13
22,-8,18:17.13
29,-8,18:18.14
39,-8,18:18.6
40,-8,18:18.6
41,-8,18:18.6
42,-8,18:18.6
43,-8,18:18.6
44,-8,18:18.6
47,-8,18:18.6
2,-7,18:18.6
5,-7,18:18.6
14,-7,18:17.13
20,-7,18:17.13
21,-7,18:17.13
22,-7,18:17.13
23,-7,18:17.13
29,-7,18:18.14
30,-7,18:18.14
39,-7,18:18.6
2,-6,18:18.6
5,-6,18:18.14
14,-6,18:17.13
15,-6,18:17.13
22,-6,18:17.13
23,-6,18:17.13
29,-6,18:18.14
38,-6,18:18.6
39,-6,18:18.6
2,-5,18:18.6
5,-5,18:18.14
6,-5,18:18.14
14,-5,18:17.13
15,-5,18:17.13
22,-5,18:17.13
23,-5,18:17.13
28,-5,18:18.14
29,-5,18:18.14
38,-5,18:18.6
-5,-4,18:18.6
-4,-4,18:18.6
-3,-4,18:18.6
-2,-4,18:18.6
-1,-4,18:18.6
0,-4,18:18.6
1,-4,18:18.6
2,-4,18:18.6
6,-4,18:18.14
15,-4,18:17.13
16,-4,18:17.13
20,-4,18:17.13
21,-4,18:17.13
22,-4,18:17.13
23,-4,18:17.13
28,-4,18:18.14
37,-4,18:18.6
38,-4,18:18.6
2,-3,18:18.6
6,-3,18:18.14
7,-3,18:18.14
15,-3,18:17.13
16,-3,18:17.13
19,-3,18:17.13
20,-3,18:17.13
21,-3,18:17.13
22,-3,18:17.13
27,-3,18:18.14
28,-3,18:18.14
37,-3,18:18.6
1,-2,18:18.6
2,-2,18:18.6
7,-2,18:18.14
16,-2,18:17.13
17,-2,18:17.13
18,-2,18:17.13
19,-2,18:17.13
20,-2,18:17.13
27,-2,18:18.14
36,-2,18:18.6
37,-2,18:18.6
1,-1,18:18.6
8,-1,18:18.14
17,-1,18:17.13
18,-1,18:17.13
26,-1,18:18.14
27,-1,18:18.14
36,-1,18:18.6
1,0,18:18.6
8,0,18:18.14
9,0,18:18.14
26,0,18:18.14
35,0,18:18.6
36,0,18:18.6
1,1,18:18.6
9,1,18:18.14
25,1,18:18.14
26,1,18:18.14
35,1,18:18.6
36,1,18:18.6
1,2,18:18.6
10,2,18:18.14
25,2,18:18.14
34,2,18:18.6
35,2,18:18.6
36,2,18:18.6
37,2,18:18.6
1,3,18:18.6
10,3,18:18.14
11,3,18:18.14
24,3,18:18.14
25,3,18:18.14
33,3,18:18.6
34,3,18:18.6
37,3,18:18.6
38,3,18:18.6
11,4,18:18.6
12,4,18:18.14
13,4,18:18.14
14,4,18:18.14
15,4,18:18.14
16,4,18:18.14
17,4,18:18.14
18,4,18:18.14
19,4,18:18.14
20,4,18:18.14
21,4,18:18.14
22,4,18:18.14
23,4,18:18.14
24,4,18:18.14
32,4,18:18.6
33,4,18:18.6
38,4,18:18.6
39,4,18:18.6
-1,5,18:18.6
0,5,18:18.6
1,5,18:18.6
2,5,18:18.6
31,5,18:18.6
32,5,18:18.6
40,5,18:18.6
41,5,18:18.6
-5,6,18:18.6
-4,6,18:18.6
-3,6,18:18.6
-2,6,18:18.6
-1,6,18:18.6
2,6,18:18.6
30,6,18:18.6
31,6,18:18.6
41,6,18:18.6
-6,7,18:18.6
-5,7,18:18.6
2,7,18:18.6
3,7,18:18.6
28,7,18:18.14
29,7,18:18.14
30,7,18:18.6
3,8,18:18.6
25,8,18:18.6
26,8,18:18.6
27,8,18:18.6
28,8,18:18.6
29,8,18:18.6
4,9,18:18.6
22,9,18:18.6
23,9,18:18.6
24,9,18:18.6
25,9,18:18.6
27,9,18:18.6
28,9,18:18.6
4,10,18:18.6
5,10,18:18.6
19,10,18:18.6
20,10,18:18.6
21,10,18:18.6
22,10,18:18.6
28,10,18:18.6
5,11,18:18.6
18,11,18:18.6
19,11,18:18.6
29,11,18:18.6
6,12,18:18.6
18,12,18:18.6
29,12,18:18.6
30,12,18:18.6
6,13,18:18.6
7,13,18:18.6
8,13,18:18.6
9,13,18:18.6
10,13,18:18.6
11,13,18:18.6
12,13,18:18.6
13,13,18:18.6
14,13,18:18.6
15,13,18:18.6
16,13,18:18.6
17,13,18:18.6
30,13,18:18.6
7,14,18:18.6
8,14,18:18.6
18,14,18:18.6
6,15,18:18.6
18,15,18:18.6
6,16,18:18.6
18,16,18:18.6
5,17,18:18.6
19,17,18:18.6
5,18,18:18.6
19,18,18:18.6
4,19,18:18.6
19,19,18:18.6
20,19,18:18.6
4,20,18:18.6
20,20,18:18.6
16,-33,19:18.6
16,-32,19:18.6
16,-31,19:18.6
16,-30,19:18.6
3,-29,19:18.6
16,-29,19:18.6
3,-28,19:18.6
15,-28,19:18.6
4,-27,19:18.6
15,-27,19:18.6
4,-26,19:18.6
5,-26,19:18.6
11,-26,19:18.6
12,-26,19:18.6
13,-26,19:18.6
14,-26,19:18.6
15,-26,19:18.6
5,-25,19:18.6
6,-25,19:18.6
7,-25,19:18.6
8,-25,19:18.6
9,-25,19:18.6
10,-25,19:18.6
11,-25,19:18.6
12,-25,19:18.6
16,-25,19:18.6
17,-25,19:18.6
4,-24,19:18.6
5,-24,19:18.6
17,-24,19:18.6
18,-24,19:18.6
27,-24,19:18.6
4,-23,19:18.6
19,-23,19:18.6
20,-23,19:18.6
27,-23,19:18.6
38,-23,19:18.6
3,-22,19:18.6
4,-22,19:18.6
21,-22,19:18.6
22,-22,19:18.6
26,-22,19:18.6
37,-22,19:18.6
3,-21,19:18.6
22,-21,19:18.6
23,-21,19:18.6
26,-21,19:18.6
37,-21,19:18.6
2,-20,19:18.6
3,-20,19:18.6
23,-20,19:18.6
24,-20,19:18.6
25,-20,19:18.6
36,-20,19:18.6
2,-19,19:18.6
24,-19,19:18.6
25,-19,19:18.6
35,-19,19:18.6
36,-19,19:18.6
2,-18,19:18.6
18,-18,19:18.14
19,-18,19:18.14
20,-18,19:18.14
21,-18,19:18.14
22,-18,19:18.14
23,-18,19:18.14
25,-18,19:18.6
26,-18,19:18.6
27,-18,19:18.6
28,-18,19:18.6
35,-18,19:18.6
1,-17,19:18.6
10,-17,19:18.14
11,-17,19:18.14
12,-17,19:18.14
13,-17,19:18.14
14,-17,19:18.14
15,-17,19:18.14
16,-17,19:18.14
17,-17,19:18.14
18,-17,19:18.14
23,-17,19:18.14
29,-17,19:18.14
30,-17,19:18.14
31,-17,19:18.6
32,-17,19:18.6
33,-17,19:18.6
34,-17,19:18.6
35,-17,19:18.6
-5,-16,19:18.6
-4,-16,19:18.6
-3,-16,19:18.6
-2,-16,19:18.6
-1,-16,19:18.6
0,-16,19:18.6
1,-16,19:18.6
10,-16,19:18.14
23,-16,19:18.14
24,-16,19:18.14
33,-16,19:18.6
34,-16,19:18.6
35,-16,19:18.6
1,-15,19:18.6
2,-15,19:18.6
9,-15,19:18.14
24,-15,19:18.14
25,-15,19:18.14
29,-15,19:17.1
30,-15,19:17.1
35,-15,19:18.6
2,-14,19:18.6
9,-14,19:18.14
14,-14,19:17.13
25,-14,19:18.14
28,-14,19:17.1
35,-14,19:18.6
36,-14,19:18.6
2,-13,19:18.6
8,-13,19:18.14
14,-13,19:17.13
15,-13,19:17.13
26,-13,19:18.14
36,-13,19:18.6
2,-12,19:18.6
3,-12,19:18.6
8,-12,19:18.14
15,-12,19:17.13
16,-12,19:17.13
24,-12,19:17.13
26,-12,19:18.14
27,-12,19:18.14
37,-12,19:18.6
2,-11,19:18.6
3,-11,19:18.6
7,-11,19:18.6
15,-11,19:17.13
16,-11,19:17.13
17,-11,19:17.13
18,-11,19:17.13
19,-11,19:17.13
20,-11,19:17.13
22,-11,19:17.13
23,-11,19:17.13
24,-11,19:17.13
27,-11,19:18.14
37,-11,19:18.6
38,-11,19:18.6
2,-10,19:18.6
3,-10,19:18.6
7,-10,19:18.6
15,-10,19:17.13
16,-10,19:17.13
20,-10,19:17.13
21,-10,19:17.13
22,-10,19:17.13
23,-10,19:17.13
38,-10,19:18.6
2,-9,19:18.6
3,-9,19:18.6
6,-9,19:18.6
14,-9,19:17.13
15,-9,19:17.13
20,-9,19:17.13
21,-9,19:17.13
22,-9,19:17.13
28,-9,19:18.14
29,-9,19:18.14
38,-9,19:18.6
39,-9,19:18.6
2,-8,19:18.6
3,-8,19:18.6
6,-8,19:18.6
14,-8,19:17.13
15,-8,19:17.13
20,-8,19:17.13
21,-8,19:17.13
22,-8,19:17.13
23,-8,19:17.13
29,-8,19:18.14
39,-8,19:18.6
40,-8,19:18.6
41,-8,19:18.6
42,-8,19:18.6
43,-8,19:18.6
44,-8,19:18.6
2,-7,19:18.6
3,-7,19:18.6
5,-7,19:18.6
14,-7,19:17.13
15,-7,19:17.13
20,-7,19:17.13
21,-7,19:17.13
22,-7,19:17.13
23,-7,19:17.13
24,-7,19:17.13
25,-7,19:17.13
29,-7,19:18.14
39,-7,19:18.6
2,-6,19:18.6
3,-6,19:18.6
5,-6,19:18.14
15,-6,19:17.13
21,-6,19:17.13
22,-6,19:17.13
23,-6,19:17.13
24,-6,19:17.13
25,-6,19:17.13
28,-6,19:18.14
29,-6,19:18.14
38,-6,19:18.6
2,-5,19:18.6
3,-5,19:18.6
5,-5,19:18.14
6,-5,19:18.14
14,-5,19:17.13
15,-5,19:17.13
16,-5,19:17.13
21,-5,19:17.13
22,-5,19:17.13
28,-5,19:18.14
38,-5,19:18.6
-4,-4,19:18.6
-3,-4,19:18.6
-2,-4,19:18.6
-1,-4,19:18.6
0,-4,19:18.6
1,-4,19:18.6
2,-4,19:18.6
3,-4,19:18.6
6,-4,19:18.14
16,-4,19:17.13
17,-4,19:17.13
19,-4,19:17.13
20,-4,19:17.13
21,-4,19:17.13
22,-4,19:17.13
27,-4,19:18.14
28,-4,19:18.14
37,-4,19:18.6
2,-3,19:18.6
7,-3,19:18.14
16,-3,19:17.13
17,-3,19:17.13
18,-3,19:17.13
19,-3,19:17.13
21,-3,19:17.13
22,-3,19:17.13
27,-3,19:18.14
37,-3,19:18.6
2,-2,19:18.6
7,-2,19:18.14
8,-2,19:18.14
17,-2,19:17.13
18,-2,19:17.13
22,-2,19:17.13
26,-2,19:18.14
27,-2,19:18.14
36,-2,19:18.6
1,-1,19:18.6
2,-1,19:18.6
8,-1,19:18.14
26,-1,19:18.14
36,-1,19:18.6
1,0,19:18.6
2,0,19:18.6
9,0,19:18.14
25,0,19:18.14
26,0,19:18.14
35,0,19:18.6
1,1,19:18.6
2,1,19:18.6
9,1,19:18.14
10,1,19:18.14
25,1,19:18.14
34,1,19:18.6
35,1,19:18.6
36,1,19:18.6
1,2,19:18.6
2,2,19:18.6
10,2,19:18.14
24,2,19:18.14
25,2,19:18.14
34,2,19:18.6
36,2,19:18.6
37,2,19:18.6
1,3,19:18.6
2,3,19:18.6
10,3,19:18.14
11,3,19:18.14
24,3,19:18.14
33,3,19:18.6
37,3,19:18.6
38,3,19:18.6
2,4,19:18.6
11,4,19:18.6
12,4,19:18.14
13,4,19:18.14
14,4,19:18.14
15,4,19:18.14
16,4,19:18.14
17,4,19:18.14
18,4,19:18.14
19,4,19:18.14
20,4,19:18.14
21,4,19:18.14
22,4,19:18.14
23,4,19:18.14
24,4,19:18.14
32,4,19:18.6
39,4,19:18.6
-1,5,19:18.6
0,5,19:18.6
1,5,19:18.6
2,5,19:18.6
31,5,19:18.6
40,5,19:18.6
-5,6,19:18.6
-4,6,19:18.6
-3,6,19:18.6
-2,6,19:18.6
-1,6,19:18.6
2,6,19:18.6
30,6,19:18.6
31,6,19:18.6
3,7,19:18.6
26,7,19:18.14
27,7,19:18.14
28,7,19:18.14
29,7,19:18.14
30,7,19:18.6
3,8,19:18.6
4,8,19:18.6
23,8,19:18.6
24,8,19:18.6
25,8,19:18.6
26,8,19:18.6
27,8,19:18.6
4,9,19:18.6
20,9,19:18.6
21,9,19:18.6
22,9,19:18.6
23,9,19:18.6
27,9,19:18.6
28,9,19:18.6
5,10,19:18.6
19,10,19:18.6
20,10,19:18.6
28,10,19:18.6
5,11,19:18.6
6,11,19:18.6
18,11,19:18.6
19,11,19:18.6
29,11,19:18.6
6,12,19:18.6
17,12,19:18.6
18,12,19:18.6
29,12,19:18.6
30,12,19:18.6
7,13,19:18.6
8,13,19:18.6
9,13,19:18.6
10,13,19:18.6
11,13,19:18.6
12,13,19:18.6
13,13,19:18.6
14,13,19:18.6
15,13,19:18.6
16,13,19:18.6
17,13,19:18.6
30,13,19:18.6
7,14,19:18.6
18,14,19:18.6
6,15,19:18.6
18,15,19:18.6
6,16,19:18.6
18,16,19:18.6
5,17,19:18.6
19,17,19:18.6
5,18,19:18.6
19,18,19:18.6
4,19,19:18.6
19,19,19:18.6
20,19,19:18.6
4,20,19:18.6
20,20,19:18.6
16,-32,20:18.6
16,-31,20:18.6
2,-30,20:18.6
16,-30,20:18.6
2,-29,20:18.6
3,-29,20:18.6
16,-29,20:18.6
3,-28,20:18.6
15,-28,20:18.6
4,-27,20:18.6
15,-27,20:18.6
4,-26,20:18.6
5,-26,20:18.6
15,-26,20:18.6
5,-25,20:18.6
6,-25,20:18.6
7,-25,20:18.6
8,-25,20:18.6
9,-25,20:18.6
10,-25,20:18.6
11,-25,20:18.6
12,-25,20:18.6
13,-25,20:18.6
14,-25,20:18.6
15,-25,20:18.6
16,-25,20:18.6
5,-24,20:18.6
17,-24,20:18.6
18,-24,20:18.6
27,-24,20:18.6
4,-23,20:18.6
18,-23,20:18.6
19,-23,20:18.6
20,-23,20:18.6
27,-23,20:18.6
4,-22,20:18.6
20,-22,20:18.6
21,-22,20:18.6
26,-22,20:18.6
3,-21,20:18.6
21,-21,20:18.6
22,-21,20:18.6
26,-21,20:18.6
36,-21,20:18.6
37,-21,20:18.6
3,-20,20:18.6
22,-20,20:18.6
23,-20,20:18.6
25,-20,20:18.6
36,-20,20:18.6
2,-19,20:18.6
3,-19,20:18.6
23,-19,20:18.6
24,-19,20:18.6
25,-19,20:18.6
35,-19,20:18.6
36,-19,20:18.6
2,-18,20:18.6
21,-18,20:18.14
22,-18,20:18.14
24,-18,20:18.14
25,-18,20:18.6
26,-18,20:18.6
27,-18,20:18.6
35,-18,20:18.6
1,-17,20:18.6
2,-17,20:18.6
10,-17,20:18.14
11,-17,20:18.14
12,-17,20:17.13
13,-17,20:18.14
14,-17,20:18.14
15,-17,20:18.14
16,-17,20:18.14
17,-17,20:18.14
18,-17,20:18.14
19,-17,20:18.14
20,-17,20:18.14
21,-17,20:18.14
22,-17,20:18.14
23,-17,20:18.14
27,-17,20:18.14
28,-17,20:18.14
29,-17,20:18.14
30,-17,20:18.14
31,-17,20:18.6
32,-17,20:18.6
34,-17,20:18.6
35,-17,20:18.6
-4,-16,20:18.6
-3,-16,20:18.6
-2,-16,20:18.6
-1,-16,20:18.6
0,-16,20:18.6
1,-16,20:18.6
10,-16,20:18.14
12,-16,20:17.13
13,-16,20:17.13
23,-16,20:18.14
24,-16,20:18.14
32,-16,20:18.6
33,-16,20:18.6
34,-16,20:18.6
2,-15,20:18.6
9,-15,20:18.14
10,-15,20:18.14
12,-15,20:17.13
13,-15,20:17.13
14,-15,20:17.13
24,-15,20:18.14
28,-15,20:17.1
29,-15,20:17.1
35,-15,20:18.6
2,-14,20:18.6
9,-14,20:18.14
13,-14,20:17.13
14,-14,20:17.13
15,-14,20:17.13
25,-14,20:18.14
26,-14,20:17.1
27,-14,20:17.1
28,-14,20:17.1
29,-14,20:17.1
35,-14,20:18.6
2,-13,20:18.6
3,-13,20:18.6
8,-13,20:18.14
9,-13,20:18.14
13,-13,20:17.13
14,-13,20:17.13
15,-13,20:17.13
16,-13,20:17.13
25,-13,20:17.13
26,-13,20:17.13
27,-13,20:17.1
28,-13,20:17.1
36,-13,20:18.6
3,-12,20:18.6
8,-12,20:18.14
14,-12,20:17.13
15,-12,20:17.13
16,-12,20:17.13
17,-12,20:17.13
18,-12,20:17.13
22,-12,20:17.13
23,-12,20:17.13
24,-12,20:17.13
25,-12,20:17.13
26,-12,20:18.14
36,-12,20:18.6
37,-12,20:18.6
3,-11,20:18.6
7,-11,20:18.6
8,-11,20:18.14
14,-11,20:17.13
15,-11,20:17.13
16,-11,20:17.13
17,-11,20:17.13
18,-11,20:17.13
19,-11,20:17.13
20,-11,20:17.13
21,-11,20:17.13
22,-11,20:17.13
23,-11,20:17.13
24,-11,20:17.13
25,-11,20:17.13
27,-11,20:18.14
37,-11,20:18.6
3,-10,20:18.6
7,-10,20:18.6
15,-10,20:17.13
16,-10,20:17.13
17,-10,20:17.13
18,-10,20:17.13
19,-10,20:17.13
20,-10,20:17.13
21,-10,20:17.13
22,-10,20:17.13
23,-10,20:17.13
24,-10,20:17.13
27,-10,20:18.14
37,-10,20:18.6
38,-10,20:18.6
3,-9,20:18.6
6,-9,20:18.6
7,-9,20:18.6
15,-9,20:17.13
16,-9,20:17.13
21,-9,20:17.13
22,-9,20:17.13
28,-9,20:18.14
38,-9,20:18.6
39,-9,20:18.6
3,-8,20:18.6
6,-8,20:18.6
15,-8,20:17.13
16,-8,20:17.13
21,-8,20:17.13
22,-8,20:17.13
23,-8,20:17.13
24,-8,20:17.13
25,-8,20:17.13
29,-8,20:18.14
39,-8,20:18.6
40,-8,20:18.6
41,-8,20:18.6
42,-8,20:18.6
43,-8,20:18.6
44,-8,20:18.6
45,-8,20:18.6
3,-7,20:18.6
5,-7,20:18.6
6,-7,20:18.14
15,-7,20:17.13
21,-7,20:17.13
22,-7,20:17.13
23,-7,20:17.13
24,-7,20:17.13
25,-7,20:17.13
26,-7,20:17.13
29,-7,20:18.14
38,-7,20:18.6
39,-7,20:18.6
3,-6,20:18.6
5,-6,20:18.14
14,-6,20:17.13
15,-6,20:17.13
16,-6,20:17.13
17,-6,20:17.13
20,-6,20:17.13
21,-6,20:17.13
22,-6,20:17.13
23,-6,20:17.13
24,-6,20:17.13
25,-6,20:17.13
26,-6,20:17.13
27,-6,20:17.13
28,-6,20:18.14
38,-6,20:18.6
1,-5,20:18.6
2,-5,20:18.6
3,-5,20:18.14
6,-5,20:18.14
13,-5,20:17.13
14,-5,20:17.13
15,-5,20:17.13
16,-5,20:17.13
17,-5,20:17.13
18,-5,20:17.13
19,-5,20:17.13
20,-5,20:17.13
21,-5,20:17.13
28,-5,20:18.14
37,-5,20:18.6
38,-5,20:18.6
-4,-4,20:18.6
-2,-4,20:18.6
-1,-4,20:18.6
0,-4,20:18.6
1,-4,20:18.6
3,-4,20:18.14
6,-4,20:18.14
7,-4,20:18.14
13,-4,20:17.13
14,-4,20:17.13
15,-4,20:17.13
16,-4,20:17.13
17,-4,20:17.13
18,-4,20:17.13
19,-4,20:17.13
20,-4,20:17.13
21,-4,20:17.13
22,-4,20:17.13
27,-4,20:18.14
37,-4,20:18.6
2,-3,20:18.14
3,-3,20:18.14
7,-3,20:18.14
20,-3,20:17.13
21,-3,20:17.13
22,-3,20:17.13
27,-3,20:18.14
36,-3,20:18.6
37,-3,20:18.6
2,-2,20:18.14
8,-2,20:18.14
21,-2,20:17.13
22,-2,20:17.13
23,-2,20:17.13
26,-2,20:18.14
36,-2,20:18.6
2,-1,20:18.14
8,-1,20:18.14
9,-1,20:18.14
21,-1,20:17.13
22,-1,20:17.13
23,-1,20:17.13
26,-1,20:18.14
35,-1,20:18.6
36,-1,20:18.6
2,0,20:18.14
9,0,20:18.14
22,0,20:17.13
23,0,20:17.13
25,0,20:18.14
35,0,20:18.6
2,1,20:18.14
9,1,20:18.14
10,1,20:18.14
23,1,20:17.13
24,1,20:17.13
25,1,20:18.14
34,1,20:18.6
35,1,20:18.6
36,1,20:18.6
2,2,20:18.14
10,2,20:18.14
11,2,20:18.14
24,2,20:18.14
33,2,20:18.6
34,2,20:18.6
36,2,20:18.6
37,2,20:18.6
2,3,20:18.14
11,3,20:18.14
18,3,20:18.14
19,3,20:18.14
20,3,20:18.14
21,3,20:18.14
22,3,20:18.14
23,3,20:18.14
24,3,20:18.14
32,3,20:18.6
33,3,20:18.6
37,3,20:18.6
38,3,20:18.6
2,4,20:18.14
11,4,20:18.14
12,4,20:18.14
13,4,20:18.14
14,4,20:18.14
15,4,20:18.14
16,4,20:18.14
17,4,20:18.14
18,4,20:18.14
19,4,20:18.14
20,4,20:18.14
31,4,20:18.6
32,4,20:18.6
39,4,20:18.6
-1,5,20:18.6
0,5,20:18.6
1,5,20:18.6
2,5,20:18.6
31,5,20:18.6
-4,6,20:18.6
-3,6,20:18.6
-2,6,20:18.6
2,6,20:18.6
3,6,20:18.6
27,6,20:18.14
28,6,20:18.14
29,6,20:18.14
30,6,20:18.6
3,7,20:18.6
24,7,20:18.14
25,7,20:18.14
26,7,20:18.14
27,7,20:18.14
28,7,20:18.14
4,8,20:18.6
21,8,20:18.6
22,8,20:18.6
23,8,20:18.6
24,8,20:18.6
27,8,20:18.6
4,9,20:18.6
5,9,20:18.6
19,9,20:18.6
20,9,20:18.6
21,9,20:18.6
27,9,20:18.6
28,9,20:18.6
5,10,20:18.6
19,10,20:18.6
28,10,20:18.6
6,11,20:18.6
18,11,20:18.6
29,11,20:18.6
6,12,20:18.6
7,12,20:18.6
14,12,20:18.6
15,12,20:18.6
16,12,20:18.6
17,12,20:18.6
18,12,20:18.6
29,12,20:18.6
30,12,20:18.6
7,13,20:18.6
8,13,20:18.6
9,13,20:18.6
10,13,20:18.6
11,13,20:18.6
12,13,20:18.6
13,13,20:18.6
14,13,20:18.6
15,13,20:18.6
16,13,20:18.6
17,13,20:18.6
30,13,20:18.6
6,14,20:18.6
7,14,20:18.6
18,14,20:18.6
6,15,20:18.6
18,15,20:18.6
5,16,20:18.6
6,16,20:18.6
18,16,20:18.6
5,17,20:18.6
19,17,20:18.6
19,18,20:18.6
16,-34,21:18.6
16,-33,21:18.6
16,-32,21:18.6
16,-31,21:18.6
2,-30,21:18.6
16,-30,21:18.6
2,-29,21:18.6
3,-29,21:18.6
15,-29,21:18.6
16,-29,21:18.6
3,-28,21:18.6
15,-28,21:18.6
4,-27,21:18.6
15,-27,21:18.6
4,-26,21:18.6
5,-26,21:18.6
15,-26,21:18.6
5,-25,21:18.6
6,-25,21:18.6
7,-25,21:18.6
8,-25,21:18.6
9,-25,21:18.6
10,-25,21:18.6
11,-25,21:18.6
12,-25,21:18.6
13,-25,21:18.6
14,-25,21:18.6
15,-25,21:18.6
16,-25,21:18.6
28,-25,21:18.6
5,-24,21:18.6
16,-24,21:18.6
17,-24,21:18.6
18,-24,21:18.6
27,-24,21:18.6
4,-23,21:18.6
5,-23,21:18.6
18,-23,21:18.6
19,-23,21:18.6
26,-23,21:18.6
27,-23,21:18.6
4,-22,21:18.6
20,-22,21:18.6
21,-22,21:18.6
26,-22,21:18.6
3,-21,21:18.6
4,-21,21:18.6
9,-21,21:17.1
21,-21,21:18.6
22,-21,21:18.6
25,-21,21:18.6
26,-21,21:18.6
36,-21,21:18.6
3,-20,21:18.6
9,-20,21:17.1
10,-20,21:17.1
22,-20,21:18.6
23,-20,21:18.6
25,-20,21:18.6
36,-20,21:18.6
2,-19,21:18.6
3,-19,21:18.6
10,-19,21:17.1
11,-19,21:17.1
23,-19,21:18.6
24,-19,21:18.6
25,-19,21:18.6
35,-19,21:18.6
36,-19,21:18.6
2,-18,21:18.6
11,-18,21:17.1
12,-18,21:17.1
24,-18,21:18.14
25,-18,21:18.6
26,-18,21:18.6
35,-18,21:18.6
2,-17,21:18.6
11,-17,21:17.1
12,-17,21:17.1
13,-17,21:18.14
14,-17,21:18.14
15,-17,21:18.14
16,-17,21:18.14
17,-17,21:18.14
18,-17,21:18.14
19,-17,21:18.14
20,-17,21:18.14
21,-17,21:18.14
22,-17,21:18.14
23,-17,21:18.14
26,-17,21:18.14
27,-17,21:18.14
28,-17,21:18.14
29,-17,21:18.14
30,-17,21:18.14
34,-17,21:18.6
-5,-16,21:18.6
-4,-16,21:18.6
-3,-16,21:18.6
-2,-16,21:18.6
-1,-16,21:18.6
0,-16,21:18.6
1,-16,21:18.6
2,-16,21:18.6
10,-16,21:18.14
11,-16,21:17.13
12,-16,21:17.13
13,-16,21:17.13
23,-16,21:18.14
30,-16,21:18.14
31,-16,21:18.6
32,-16,21:18.6
33,-16,21:18.6
34,-16,21:18.6
2,-15,21:18.6
10,-15,21:18.14
12,-15,21:17.13
13,-15,21:17.13
14,-15,21:17.13
24,-15,21:18.14
34,-15,21:18.6
35,-15,21:18.6
2,-14,21:18.6
9,-14,21:18.14
13,-14,21:17.13
14,-14,21:17.13
24,-14,21:18.14
25,-14,21:18.14
26,-14,21:17.1
27,-14,21:17.1
35,-14,21:18.6
3,-13,21:18.6
9,-13,21:18.14
13,-13,21:17.13
18,-13,21:17.13
19,-13,21:17.13
20,-13,21:17.13
24,-13,21:17.13
25,-13,21:18.14
26,-13,21:17.1
27,-13,21:17.1
35,-13,21:18.6
36,-13,21:18.6
3,-12,21:18.6
8,-12,21:18.14
18,-12,21:17.13
19,-12,21:17.13
20,-12,21:17.13
23,-12,21:17.13
24,-12,21:17.13
25,-12,21:17.13
26,-12,21:18.14
27,-12,21:17.1
36,-12,21:18.6
3,-11,21:18.6
4,-11,21:18.6
8,-11,21:18.14
18,-11,21:17.13
20,-11,21:17.13
23,-11,21:17.13
24,-11,21:17.13
25,-11,21:17.13
26,-11,21:18.14
27,-11,21:18.14
37,-11,21:18.6
3,-10,21:18.6
4,-10,21:18.6
7,-10,21:18.6
17,-10,21:17.13
18,-10,21:17.13
19,-10,21:17.13
20,-10,21:17.13
23,-10,21:17.13
24,-10,21:17.13
27,-10,21:18.14
37,-10,21:18.6
38,-10,21:18.6
3,-9,21:18.6
4,-9,21:18.6
7,-9,21:18.6
16,-9,21:17.13
17,-9,21:17.13
18,-9,21:17.13
19,-9,21:17.13
20,-9,21:17.13
21,-9,21:17.13
28,-9,21:18.14
38,-9,21:18.6
46,-9,21:18.6
3,-8,21:18.6
4,-8,21:18.6
6,-8,21:18.6
16,-8,21:17.13
17,-8,21:17.13
20,-8,21:17.13
21,-8,21:17.13
26,-8,21:17.13
28,-8,21:18.14
29,-8,21:18.14
38,-8,21:18.6
39,-8,21:18.6
40,-8,21:18.6
41,-8,21:18.6
42,-8,21:18.6
43,-8,21:18.6
44,-8,21:18.6
45,-8,21:18.6
3,-7,21:18.6
4,-7,21:18.6
5,-7,21:18.6
6,-7,21:18.14
16,-7,21:17.13
17,-7,21:17.13
18,-7,21:17.13
20,-7,21:17.13
21,-7,21:17.13
25,-7,21:17.13
26,-7,21:17.13
27,-7,21:17.13
28,-7,21:18.14
29,-7,21:18.14
38,-7,21:18.6
3,-6,21:18.6
4,-6,21:18.14
5,-6,21:18.14
6,-6,21:18.14
16,-6,21:17.13
17,-6,21:17.13
18,-6,21:17.13
19,-6,21:17.13
20,-6,21:17.13
25,-6,21:17.13
26,-6,21:17.13
27,-6,21:17.13
28,-6,21:18.14
38,-6,21:18.6
1,-5,21:18.6
2,-5,21:18.6
3,-5,21:18.14
6,-5,21:18.14
13,-5,21:17.13
14,-5,21:17.13
17,-5,21:17.13
18,-5,21:17.13
19,-5,21:17.13
26,-5,21:17.13
27,-5,21:18.14
28,-5,21:18.14
37,-5,21:18.6
-2,-4,21:18.6
-1,-4,21:18.6
0,-4,21:18.6
1,-4,21:18.6
3,-4,21:18.14
7,-4,21:18.14
12,-4,21:17.13
13,-4,21:17.13
14,-4,21:17.13
15,-4,21:17.13
17,-4,21:17.13
18,-4,21:17.13
19,-4,21:17.13
27,-4,21:18.14
37,-4,21:18.6
3,-3,21:18.14
7,-3,21:18.14
8,-3,21:18.14
11,-3,21:17.13
12,-3,21:17.13
13,-3,21:17.13
22,-3,21:17.13
26,-3,21:18.14
27,-3,21:18.14
36,-3,21:18.6
2,-2,21:18.14
3,-2,21:18.14
8,-2,21:18.14
10,-2,21:17.13
11,-2,21:17.13
21,-2,21:17.13
22,-2,21:17.13
23,-2,21:17.13
26,-2,21:18.14
36,-2,21:18.6
2,-1,21:18.14
9,-1,21:18.14
21,-1,21:17.13
22,-1,21:17.13
23,-1,21:17.13
24,-1,21:17.13
25,-1,21:18.14
26,-1,21:18.14
35,-1,21:18.6
2,0,21:18.14
9,0,21:18.14
10,0,21:18.14
22,0,21:17.13
23,0,21:17.13
24,0,21:17.13
25,0,21:18.14
35,0,21:18.6
2,1,21:18.14
10,1,21:18.14
22,1,21:17.13
23,1,21:17.13
24,1,21:17.13
25,1,21:18.14
34,1,21:18.6
35,1,21:18.6
36,1,21:18.6
2,2,21:18.14
10,2,21:18.14
11,2,21:18.14
24,2,21:18.14
33,2,21:18.6
36,2,21:18.6
37,2,21:18.6
2,3,21:18.14
11,3,21:18.14
12,3,21:18.14
13,3,21:18.14
14,3,21:18.14
15,3,21:18.14
16,3,21:18.14
17,3,21:18.14
18,3,21:18.14
19,3,21:18.14
20,3,21:18.14
21,3,21:18.14
22,3,21:18.14
23,3,21:18.14
24,3,21:18.14
32,3,21:18.6
37,3,21:18.6
38,3,21:18.6
2,4,21:18.14
12,4,21:18.14
13,4,21:18.14
14,4,21:18.14
31,4,21:18.6
32,4,21:18.6
39,4,21:18.6
40,4,21:18.6
-1,5,21:18.6
0,5,21:18.6
1,5,21:18.6
2,5,21:18.6
3,5,21:18.6
29,5,21:18.14
30,5,21:18.6
31,5,21:18.6
-3,6,21:18.6
-2,6,21:18.6
3,6,21:18.6
25,6,21:18.14
26,6,21:18.14
27,6,21:18.14
28,6,21:18.14
29,6,21:18.14
3,7,21:18.6
4,7,21:18.6
22,7,21:18.14
23,7,21:18.14
24,7,21:18.14
25,7,21:18.14
26,7,21:18.14
4,8,21:18.6
20,8,21:18.6
21,8,21:18.6
22,8,21:18.6
27,8,21:18.6
5,9,21:18.6
19,9,21:18.6
20,9,21:18.6
27,9,21:18.6
28,9,21:18.6
5,10,21:18.6
6,10,21:18.6
18,10,21:18.6
19,10,21:18.6
28,10,21:18.6
6,11,21:18.6
17,11,21:18.6
18,11,21:18.6
29,11,21:18.6
7,12,21:18.6
8,12,21:18.6
9,12,21:18.6
10,12,21:18.6
11,12,21:18.6
12,12,21:18.6
13,12,21:18.6
14,12,21:18.6
15,12,21:18.6
16,12,21:18.6
17,12,21:18.6
7,13,21:18.6
8,13,21:18.6
9,13,21:18.6
10,13,21:18.6
17,13,21:18.6
6,14,21:18.6
7,14,21:18.6
18,14,21:18.6
6,15,21:18.6
18,15,21:18.6
5,16,21:18.6
6,16,21:18.6
18,16,21:18.6
19,16,21:18.6
5,17,21:18.6
19,17,21:18.6
16,-33,22:18.6
16,-32,22:18.6
16,-31,22:18.6
16,-30,22:18.6
3,-29,22:18.6
15,-29,22:18.6
16,-29,22:18.6
3,-28,22:18.6
15,-28,22:18.6
4,-27,22:18.6
15,-27,22:18.6
4,-26,22:18.6
5,-26,22:18.6
15,-26,22:18.6
5,-25,22:18.6
6,-25,22:18.6
7,-25,22:18.6
8,-25,22:18.6
9,-25,22:18.6
10,-25,22:18.6
11,-25,22:18.6
12,-25,22:18.6
13,-25,22:18.6
14,-25,22:18.6
15,-25,22:18.6
27,-25,22:18.6
28,-25,22:18.6
5,-24,22:18.6
6,-24,22:18.6
16,-24,22:18.6
17,-24,22:18.6
27,-24,22:18.6
5,-23,22:18.6
17,-23,22:18.6
18,-23,22:18.6
19,-23,22:18.6
26,-23,22:18.6
4,-22,22:18.6
8,-22,22:17.1
9,-22,22:17.1
19,-22,22:18.6
20,-22,22:18.6
26,-22,22:18.6
37,-22,22:18.6
4,-21,22:18.6
9,-21,22:17.1
20,-21,22:18.6
21,-21,22:18.6
25,-21,22:18.6
26,-21,22:18.6
36,-21,22:18.6
3,-20,22:18.6
9,-20,22:17.1
10,-20,22:17.1
21,-20,22:18.6
22,-20,22:18.6
25,-20,22:18.6
36,-20,22:18.6
3,-19,22:18.6
10,-19,22:17.1
11,-19,22:17.1
22,-19,22:18.6
23,-19,22:18.6
24,-19,22:18.6
35,-19,22:18.6
2,-18,22:18.6
3,-18,22:18.6
10,-18,22:17.1
11,-18,22:17.1
23,-18,22:18.14
24,-18,22:18.14
25,-18,22:18.6
35,-18,22:18.6
2,-17,22:18.6
11,-17,22:18.14
12,-17,22:18.14
13,-17,22:18.14
14,-17,22:18.14
15,-17,22:18.14
16,-17,22:18.14
17,-17,22:18.14
18,-17,22:18.14
19,-17,22:18.14
20,-17,22:18.14
21,-17,22:18.14
22,-17,22:18.14
25,-17,22:18.14
26,-17,22:18.14
27,-17,22:18.14
28,-17,22:18.14
34,-17,22:18.6
-5,-16,22:18.6
-4,-16,22:18.6
-3,-16,22:18.6
-2,-16,22:18.6
-1,-16,22:18.6
0,-16,22:18.6
1,-16,22:18.6
2,-16,22:18.6
10,-16,22:18.14
11,-16,22:18.14
12,-16,22:17.1
13,-16,22:17.1
23,-16,22:18.14
29,-16,22:18.14
30,-16,22:18.14
31,-16,22:18.6
32,-16,22:18.6
33,-16,22:18.6
34,-16,22:18.6
2,-15,22:18.6
10,-15,22:18.14
12,-15,22:17.13
13,-15,22:17.13
23,-15,22:18.14
24,-15,22:18.14
34,-15,22:18.6
2,-14,22:18.6
3,-14,22:18.6
9,-14,22:18.14
10,-14,22:18.14
18,-14,22:17.13
19,-14,22:17.13
20,-14,22:17.13
24,-14,22:18.14
26,-14,22:17.1
27,-14,22:17.1
28,-14,22:17.1
35,-14,22:18.6
3,-13,22:18.6
9,-13,22:18.14
18,-13,22:17.13
19,-13,22:17.13
20,-13,22:17.13
25,-13,22:18.14
27,-13,22:17.1
35,-13,22:18.6
3,-12,22:18.6
4,-12,22:18.6
8,-12,22:18.14
9,-12,22:18.14
18,-12,22:17.13
19,-12,22:17.13
20,-12,22:17.13
25,-12,22:18.14
26,-12,22:18.14
36,-12,22:18.6
4,-11,22:18.6
8,-11,22:18.14
19,-11,22:17.13
20,-11,22:17.13
26,-11,22:18.14
36,-11,22:18.6
37,-11,22:18.6
4,-10,22:18.6
7,-10,22:18.6
8,-10,22:18.14
19,-10,22:17.13
27,-10,22:18.14
37,-10,22:18.6
4,-9,22:18.6
7,-9,22:18.6
17,-9,22:17.13
18,-9,22:17.13
19,-9,22:17.13
27,-9,22:18.14
28,-9,22:18.14
38,-9,22:18.6
4,-8,22:18.6
6,-8,22:18.6
7,-8,22:18.14
17,-8,22:17.13
18,-8,22:17.13
19,-8,22:17.13
28,-8,22:18.14
38,-8,22:18.6
39,-8,22:18.6
40,-8,22:18.6
41,-8,22:18.6
42,-8,22:18.6
43,-8,22:18.6
4,-7,22:18.6
6,-7,22:18.14
17,-7,22:17.13
18,-7,22:17.13
19,-7,22:17.13
26,-7,22:17.13
27,-7,22:17.13
28,-7,22:18.14
38,-7,22:18.6
4,-6,22:18.14
6,-6,22:18.14
17,-6,22:17.13
18,-6,22:17.13
26,-6,22:17.13
27,-6,22:17.13
28,-6,22:18.14
37,-6,22:18.6
38,-6,22:18.6
0,-5,22:18.6
1,-5,22:18.6
2,-5,22:18.6
3,-5,22:18.14
6,-5,22:18.14
7,-5,22:18.14
17,-5,22:17.13
18,-5,22:17.13
27,-5,22:18.14
37,-5,22:18.6
-2,-4,22:18.6
-1,-4,22:18.6
0,-4,22:18.6
3,-4,22:18.14
4,-4,22:18.14
7,-4,22:18.14
11,-4,22:17.13
12,-4,22:17.13
17,-4,22:17.13
18,-4,22:17.13
26,-4,22:18.14
27,-4,22:18.14
36,-4,22:18.6
37,-4,22:18.6
3,-3,22:18.14
8,-3,22:18.14
10,-3,22:17.13
11,-3,22:17.13
12,-3,22:17.13
13,-3,22:17.13
17,-3,22:17.13
18,-3,22:17.13
26,-3,22:18.14
36,-3,22:18.6
3,-2,22:18.14
8,-2,22:18.14
9,-2,22:17.13
10,-2,22:17.13
11,-2,22:17.13
12,-2,22:17.13
17,-2,22:17.13
18,-2,22:17.13
25,-2,22:18.14
26,-2,22:18.14
35,-2,22:18.6
36,-2,22:18.6
2,-1,22:18.14
3,-1,22:18.14
9,-1,22:18.14
10,-1,22:17.13
25,-1,22:18.14
35,-1,22:18.6
2,0,22:18.14
9,0,22:18.14
10,0,22:18.14
24,0,22:17.13
25,0,22:18.14
34,0,22:18.6
35,0,22:18.6
2,1,22:18.14
10,1,22:18.14
23,1,22:17.13
24,1,22:17.13
33,1,22:18.6
34,1,22:18.6
35,1,22:18.6
36,1,22:18.6
2,2,22:18.14
11,2,22:18.14
23,2,22:17.13
24,2,22:17.13
25,2,22:17.13
32,2,22:18.6
33,2,22:18.6
36,2,22:18.6
37,2,22:18.6
2,3,22:18.14
11,3,22:18.14
12,3,22:18.14
13,3,22:18.14
14,3,22:18.14
15,3,22:18.14
16,3,22:18.14
17,3,22:18.14
18,3,22:18.14
19,3,22:18.14
20,3,22:18.14
21,3,22:18.14
22,3,22:18.14
23,3,22:18.14
25,3,22:17.13
32,3,22:18.6
37,3,22:18.6
38,3,22:18.6
2,4,22:18.14
30,4,22:18.6
31,4,22:18.6
39,4,22:18.6
40,4,22:18.6
-2,5,22:18.6
-1,5,22:18.6
0,5,22:18.6
1,5,22:18.6
2,5,22:18.6
3,5,22:18.6
26,5,22:18.14
27,5,22:18.14
28,5,22:18.14
29,5,22:18.14
30,5,22:18.6
-3,6,22:18.6
-2,6,22:18.6
3,6,22:18.6
23,6,22:18.14
24,6,22:18.14
25,6,22:18.14
26,6,22:18.14
27,6,22:18.14
4,7,22:18.6
20,7,22:18.14
21,7,22:18.14
22,7,22:18.14
23,7,22:18.14
26,7,22:18.14
4,8,22:18.6
5,8,22:18.6
19,8,22:18.6
20,8,22:18.6
27,8,22:18.6
5,9,22:18.6
19,9,22:18.6
27,9,22:18.6
28,9,22:18.6
6,10,22:18.6
18,10,22:18.6
28,10,22:18.6
6,11,22:18.6
7,11,22:18.6
17,11,22:18.6
18,11,22:18.6
29,11,22:18.6
7,12,22:18.6
8,12,22:18.6
9,12,22:18.6
10,12,22:18.6
11,12,22:18.6
12,12,22:18.6
13,12,22:18.6
14,12,22:18.6
15,12,22:18.6
16,12,22:18.6
17,12,22:18.6
7,13,22:18.6
17,13,22:18.6
6,14,22:18.6
7,14,22:18.6
18,14,22:18.6
6,15,22:18.6
18,15,22:18.6
6,16,22:18.6
18,16,22:18.6
19,16,22:18.6
5,17,22:18.6
19,17,22:18.6
5,18,22:18.6
19,18,22:18.6
4,19,22:18.6
16,-32,23:18.6
16,-31,23:18.6
16,-30,23:18.6
15,-29,23:18.6
16,-29,23:18.6
15,-28,23:18.6
4,-27,23:18.6
15,-27,23:18.6
4,-26,23:18.6
5,-26,23:18.6
15,-26,23:18.6
5,-25,23:18.6
9,-25,23:18.6
10,-25,23:18.6
11,-25,23:18.6
12,-25,23:18.6
13,-25,23:18.6
14,-25,23:18.6
15,-25,23:18.6
5,-24,23:18.6
6,-24,23:18.6
7,-24,23:18.6
8,-24,23:18.6
9,-24,23:18.6
10,-24,23:18.6
15,-24,23:18.6
16,-24,23:18.6
17,-24,23:18.6
5,-23,23:18.6
8,-23,23:17.1
17,-23,23:18.6
18,-23,23:18.6
26,-23,23:18.6
4,-22,23:18.6
5,-22,23:18.6
8,-22,23:17.1
19,-22,23:18.6
26,-22,23:18.6
4,-21,23:18.6
20,-21,23:18.6
25,-21,23:18.6
36,-21,23:18.6
3,-20,23:18.6
4,-20,23:18.6
21,-20,23:18.6
25,-20,23:18.6
36,-20,23:18.6
3,-19,23:18.6
22,-19,23:18.6
24,-19,23:18.6
35,-19,23:18.6
2,-18,23:18.6
3,-18,23:18.6
23,-18,23:18.14
24,-18,23:18.14
35,-18,23:18.6
2,-17,23:18.6
14,-17,23:18.14
15,-17,23:18.14
16,-17,23:18.14
17,-17,23:18.14
18,-17,23:18.14
19,-17,23:18.14
20,-17,23:18.14
21,-17,23:18.14
22,-17,23:18.14
24,-17,23:18.14
25,-17,23:18.14
26,-17,23:18.14
27,-17,23:18.14
34,-17,23:18.6
-4,-16,23:18.6
-3,-16,23:18.6
-2,-16,23:18.6
-1,-16,23:18.6
0,-16,23:18.6
1,-16,23:18.6
2,-16,23:18.6
11,-16,23:18.14
12,-16,23:18.14
13,-16,23:18.14
14,-16,23:18.14
19,-16,23:17.1
22,-16,23:18.14
23,-16,23:18.14
27,-16,23:18.14
28,-16,23:18.14
29,-16,23:18.14
30,-16,23:18.14
31,-16,23:18.6
32,-16,23:18.6
33,-16,23:18.6
34,-16,23:18.6
2,-15,23:18.6
3,-15,23:18.6
10,-15,23:18.14
12,-15,23:17.1
13,-15,23:17.1
18,-15,23:17.1
19,-15,23:17.1
20,-15,23:17.1
23,-15,23:18.14
28,-15,23:17.1
34,-15,23:18.6
3,-14,23:18.6
10,-14,23:18.14
18,-14,23:17.13
19,-14,23:17.1
20,-14,23:17.1
24,-14,23:18.14
27,-14,23:17.1
28,-14,23:17.1
34,-14,23:18.6
35,-14,23:18.6
3,-13,23:18.6
9,-13,23:18.14
19,-13,23:17.13
20,-13,23:17.13
24,-13,23:18.14
25,-13,23:18.14
28,-13,23:17.1
35,-13,23:18.6
4,-12,23:18.6
9,-12,23:18.14
19,-12,23:17.13
20,-12,23:17.13
25,-12,23:18.14
35,-12,23:18.6
36,-12,23:18.6
4,-11,23:18.6
8,-11,23:18.14
19,-11,23:17.13
26,-11,23:18.14
36,-11,23:18.6
4,-10,23:18.6
7,-10,23:18.6
8,-10,23:18.14
26,-10,23:18.14
27,-10,23:18.14
37,-10,23:18.6
4,-9,23:18.6
7,-9,23:18.6
17,-9,23:17.13
18,-9,23:17.13
19,-9,23:17.13
27,-9,23:18.14
37,-9,23:18.6
38,-9,23:18.6
4,-8,23:18.6
6,-8,23:18.6
7,-8,23:18.14
17,-8,23:17.13
18,-8,23:17.13
19,-8,23:17.13
28,-8,23:18.14
38,-8,23:18.6
39,-8,23:18.6
40,-8,23:18.6
41,-8,23:18.6
42,-8,23:18.6
43,-8,23:18.6
4,-7,23:18.6
6,-7,23:18.14
18,-7,23:17.13
19,-7,23:17.13
27,-7,23:17.1
28,-7,23:17.1
29,-7,23:17.1
37,-7,23:18.6
38,-7,23:18.6
4,-6,23:18.14
6,-6,23:18.14
27,-6,23:17.1
28,-6,23:17.1
29,-6,23:17.1
30,-6,23:17.1
31,-6,23:17.1
37,-6,23:18.6
-1,-5,23:18.6
0,-5,23:18.6
1,-5,23:18.6
2,-5,23:18.6
3,-5,23:18.14
7,-5,23:18.14
27,-5,23:18.14
36,-5,23:18.6
37,-5,23:18.6
-3,-4,23:18.6
-2,-4,23:18.6
4,-4,23:18.14
7,-4,23:18.14
8,-4,23:18.14
17,-4,23:17.13
18,-4,23:17.13
26,-4,23:18.14
27,-4,23:18.14
36,-4,23:18.6
3,-3,23:18.14
4,-3,23:18.14
8,-3,23:18.14
11,-3,23:17.13
12,-3,23:17.13
17,-3,23:17.13
18,-3,23:17.13
26,-3,23:18.14
35,-3,23:18.6
36,-3,23:18.6
3,-2,23:18.14
8,-2,23:18.14
9,-2,23:17.13
10,-2,23:17.13
17,-2,23:17.13
18,-2,23:17.13
25,-2,23:18.14
26,-2,23:18.14
35,-2,23:18.6
3,-1,23:18.14
8,-1,23:17.13
9,-1,23:17.13
10,-1,23:17.13
17,-1,23:17.13
18,-1,23:17.13
25,-1,23:18.14
35,-1,23:18.6
3,0,23:18.14
10,0,23:18.14
24,0,23:18.14
34,0,23:18.6
35,0,23:18.6
2,1,23:18.14
3,1,23:18.14
10,1,23:18.14
11,1,23:18.14
24,1,23:18.14
25,1,23:17.13
33,1,23:18.6
35,1,23:18.6
36,1,23:18.6
2,2,23:18.14
3,2,23:18.14
11,2,23:18.14
21,2,23:18.14
22,2,23:18.14
23,2,23:18.14
24,2,23:17.13
25,2,23:17.13
32,2,23:18.6
33,2,23:18.6
36,2,23:18.6
37,2,23:18.6
2,3,23:18.14
3,3,23:18.14
12,3,23:18.14
13,3,23:18.14
14,3,23:18.14
15,3,23:18.14
16,3,23:18.14
17,3,23:18.14
18,3,23:18.14
19,3,23:18.14
20,3,23:18.14
21,3,23:18.14
22,3,23:18.14
24,3,23:17.13
25,3,23:17.1
26,3,23:17.1
31,3,23:18.6
32,3,23:18.6
38,3,23:18.6
2,4,23:18.14
3,4,23:18.14
25,4,23:17.1
26,4,23:17.1
28,4,23:18.14
29,4,23:18.14
30,4,23:18.6
31,4,23:18.6
-2,5,23:18.6
-1,5,23:18.6
0,5,23:18.6
1,5,23:18.6
2,5,23:18.6
3,5,23:18.6
24,5,23:18.14
25,5,23:18.14
26,5,23:18.14
27,5,23:18.14
28,5,23:18.14
-3,6,23:18.6
-2,6,23:18.6
3,6,23:18.6
4,6,23:18.6
21,6,23:18.14
22,6,23:18.14
23,6,23:18.14
24,6,23:18.14
25,6,23:18.14
26,6,23:18.14
4,7,23:18.6
20,7,23:18.14
21,7,23:18.14
22,7,23:18.14
26,7,23:18.14
5,8,23:18.6
19,8,23:18.6
20,8,23:18.6
27,8,23:18.6
5,9,23:18.6
6,9,23:18.6
18,9,23:18.6
19,9,23:18.6
27,9,23:18.6
28,9,23:18.6
6,10,23:18.6
18,10,23:18.6
28,10,23:18.6
7,11,23:18.6
16,11,23:18.6
17,11,23:18.6
29,11,23:18.6
7,12,23:18.6
8,12,23:18.6
9,12,23:18.6
10,12,23:18.6
11,12,23:18.6
12,12,23:18.6
13,12,23:18.6
14,12,23:18.6
15,12,23:18.6
16,12,23:18.6
17,12,23:18.6
29,12,23:18.6
7,13,23:18.6
17,13,23:18.6
6,14,23:18.6
7,14,23:18.6
18,14,23:18.6
6,15,23:18.6
18,15,23:18.6
5,16,23:18.6
6,16,23:18.6
18,16,23:18.6
19,17,23:18.6
5,18,23:18.6
19,18,23:18.6
15,-30,24:18.6
15,-29,24:18.6
15,-28,24:18.6
4,-27,24:18.6
15,-27,24:18.6
4,-26,24:18.6
5,-26,24:18.6
15,-26,24:18.6
5,-25,24:18.6
6,-25,24:17.1
7,-25,24:17.1
13,-25,24:18.6
14,-25,24:18.6
15,-25,24:18.6
6,-24,24:18.6
7,-24,24:17.1
8,-24,24:18.6
9,-24,24:18.6
10,-24,24:18.6
11,-24,24:18.6
12,-24,24:18.6
13,-24,24:18.6
15,-24,24:18.6
16,-24,24:18.6
5,-23,24:18.6
7,-23,24:17.1
8,-23,24:17.1
17,-23,24:18.6
18,-23,24:18.6
5,-22,24:18.6
18,-22,24:18.6
19,-22,24:18.6
26,-22,24:18.6
4,-21,24:18.6
19,-21,24:18.6
20,-21,24:18.6
25,-21,24:18.6
4,-20,24:18.6
20,-20,24:18.6
21,-20,24:18.6
24,-20,24:18.6
25,-20,24:18.6
35,-20,24:18.6
36,-20,24:18.6
3,-19,24:18.6
21,-19,24:18.6
22,-19,24:18.6
24,-19,24:18.6
35,-19,24:18.6
3,-18,24:18.6
22,-18,24:18.14
23,-18,24:18.14
24,-18,24:18.14
34,-18,24:18.6
35,-18,24:18.6
2,-17,24:18.6
3,-17,24:18.6
17,-17,24:18.14
18,-17,24:18.14
19,-17,24:18.14
20,-17,24:18.14
21,-17,24:18.14
22,-17,24:18.14
23,-17,24:18.14
24,-17,24:18.14
25,-17,24:18.14
26,-17,24:18.14
34,-17,24:18.6
-2,-16,24:18.6
-1,-16,24:18.6
0,-16,24:18.6
1,-16,24:18.6
2,-16,24:18.6
11,-16,24:18.14
12,-16,24:18.14
13,-16,24:18.14
14,-16,24:18.14
15,-16,24:18.14
16,-16,24:18.14
17,-16,24:18.14
18,-16,24:18.14
19,-16,24:17.1
20,-16,24:17.1
22,-16,24:18.14
23,-16,24:18.14
27,-16,24:18.14
28,-16,24:18.14
29,-16,24:18.14
30,-16,24:18.14
31,-16,24:18.6
32,-16,24:18.6
33,-16,24:18.6
34,-16,24:18.6
3,-15,24:18.6
10,-15,24:18.14
13,-15,24:17.1
19,-15,24:17.1
20,-15,24:17.1
23,-15,24:18.14
28,-15,24:17.1
29,-15,24:17.1
33,-15,24:18.6
34,-15,24:18.6
3,-14,24:18.6
10,-14,24:18.14
19,-14,24:17.1
20,-14,24:17.1
23,-14,24:18.14
24,-14,24:18.14
28,-14,24:17.1
29,-14,24:17.1
34,-14,24:18.6
3,-13,24:18.6
4,-13,24:18.6
9,-13,24:18.14
10,-13,24:18.14
19,-13,24:17.1
24,-13,24:18.14
25,-13,24:18.14
35,-13,24:18.6
4,-12,24:18.6
9,-12,24:18.14
25,-12,24:18.14
35,-12,24:18.6
4,-11,24:18.6
8,-11,24:18.14
9,-11,24:18.14
25,-11,24:18.14
26,-11,24:18.14
36,-11,24:18.6
5,-10,24:18.6
8,-10,24:18.14
26,-10,24:18.14
27,-10,24:18.14
36,-10,24:18.6
37,-10,24:18.6
5,-9,24:18.6
7,-9,24:18.6
8,-9,24:18.14
14,-9,24:17.13
15,-9,24:17.13
16,-9,24:17.13
17,-9,24:17.13
18,-9,24:17.13
19,-9,24:17.13
27,-9,24:18.14
37,-9,24:18.6
5,-8,24:18.6
7,-8,24:18.14
15,-8,24:17.13
16,-8,24:17.13
17,-8,24:17.13
18,-8,24:17.13
19,-8,24:17.13
27,-8,24:18.14
28,-8,24:18.14
38,-8,24:18.6
39,-8,24:18.6
40,-8,24:18.6
41,-8,24:18.6
5,-7,24:18.6
6,-7,24:18.14
17,-7,24:17.13
18,-7,24:17.13
19,-7,24:17.13
27,-7,24:18.14
28,-7,24:17.1
29,-7,24:17.1
30,-7,24:17.1
37,-7,24:18.6
5,-6,24:18.14
6,-6,24:18.14
7,-6,24:18.14
27,-6,24:18.14
28,-6,24:17.1
29,-6,24:17.1
30,-6,24:17.1
31,-6,24:17.1
37,-6,24:18.6
-1,-5,24:18.6
0,-5,24:18.6
1,-5,24:18.6
2,-5,24:18.6
3,-5,24:18.14
5,-5,24:18.14
7,-5,24:18.14
26,-5,24:18.14
27,-5,24:18.14
36,-5,24:18.6
4,-4,24:18.14
8,-4,24:18.14
26,-4,24:18.14
36,-4,24:18.6
4,-3,24:18.14
8,-3,24:18.14
9,-3,24:18.14
11,-3,24:17.13
12,-3,24:17.13
17,-3,24:17.13
25,-3,24:18.14
26,-3,24:18.14
35,-3,24:18.6
3,-2,24:18.14
4,-2,24:18.14
8,-2,24:17.13
9,-2,24:18.14
17,-2,24:17.13
18,-2,24:17.13
25,-2,24:18.14
35,-2,24:18.6
3,-1,24:18.14
7,-1,24:17.13
8,-1,24:17.13
9,-1,24:17.13
10,-1,24:18.14
17,-1,24:17.13
18,-1,24:17.13
24,-1,24:18.14
25,-1,24:18.14
3,0,24:18.14
6,0,24:17.13
7,0,24:17.13
8,0,24:17.13
10,0,24:18.14
24,0,24:18.14
33,0,24:18.6
34,0,24:18.6
35,0,24:18.6
3,1,24:18.14
6,1,24:17.1
11,1,24:18.14
23,1,24:18.14
24,1,24:18.14
32,1,24:18.6
33,1,24:18.6
35,1,24:18.6
36,1,24:18.6
3,2,24:18.14
11,2,24:18.14
15,2,24:18.14
16,2,24:18.14
17,2,24:18.14
18,2,24:18.14
19,2,24:18.14
20,2,24:18.14
21,2,24:18.14
22,2,24:18.14
23,2,24:18.14
32,2,24:18.6
36,2,24:18.6
37,2,24:18.6
3,3,24:18.14
12,3,24:18.14
13,3,24:18.14
14,3,24:18.14
15,3,24:18.14
16,3,24:18.14
17,3,24:18.14
30,3,24:18.6
31,3,24:18.6
38,3,24:18.6
39,3,24:18.6
2,4,24:18.14
3,4,24:18.14
25,4,24:18.14
26,4,24:17.1
27,4,24:18.14
28,4,24:18.14
29,4,24:18.14
30,4,24:18.6
-2,5,24:18.6
-1,5,24:18.6
0,5,24:18.6
1,5,24:18.6
3,5,24:18.6
4,5,24:18.6
22,5,24:18.14
23,5,24:18.14
24,5,24:18.14
25,5,24:18.14
26,5,24:17.1
4,6,24:18.6
20,6,24:18.14
21,6,24:18.14
22,6,24:18.14
23,6,24:18.14
25,6,24:18.14
26,6,24:18.14
4,7,24:18.6
5,7,24:18.6
19,7,24:18.6
20,7,24:18.14
26,7,24:18.14
5,8,24:18.6
19,8,24:18.6
27,8,24:18.6
6,9,24:18.6
18,9,24:18.6
27,9,24:18.6
28,9,24:18.6
6,10,24:18.6
7,10,24:18.6
17,10,24:18.6
18,10,24:18.6
28,10,24:18.6
7,11,24:18.6
10,11,24:18.6
11,11,24:18.6
12,11,24:18.6
13,11,24:18.6
14,11,24:18.6
15,11,24:18.6
16,11,24:18.6
17,11,24:18.6
29,11,24:18.6
7,12,24:18.6
8,12,24:18.6
9,12,24:18.6
10,12,24:18.6
11,12,24:18.6
12,12,24:18.6
17,12,24:18.6
7,13,24:18.6
17,13,24:18.6
6,14,24:18.6
7,14,24:18.6
18,14,24:18.6
6,15,24:18.6
18,15,24:18.6
6,16,24:18.6
18,16,24:18.6
15,-30,25:18.6
15,-29,25:18.6
15,-28,25:18.6
15,-27,25:18.6
5,-26,25:18.6
6,-26,25:17.1
15,-26,25:18.6
5,-25,25:18.6
6,-25,25:18.6
15,-25,25:18.6
6,-24,25:18.6
7,-24,25:18.6
8,-24,25:18.6
9,-24,25:18.6
10,-24,25:18.6
11,-24,25:18.6
12,-24,25:18.6
13,-24,25:18.6
14,-24,25:18.6
15,-24,25:18.6
16,-24,25:18.6
5,-23,25:18.6
6,-23,25:18.6
16,-23,25:18.6
17,-23,25:18.6
5,-22,25:18.6
18,-22,25:18.6
4,-21,25:18.6
5,-21,25:18.6
19,-21,25:18.6
25,-21,25:18.6
4,-20,25:18.6
20,-20,25:18.6
24,-20,25:18.6
25,-20,25:18.6
3,-19,25:18.6
4,-19,25:18.6
21,-19,25:18.6
24,-19,25:18.6
35,-19,25:18.6
3,-18,25:18.6
22,-18,25:18.14
23,-18,25:18.14
24,-18,25:18.14
34,-18,25:18.6
35,-18,25:18.6
2,-17,25:18.6
3,-17,25:18.6
21,-17,25:18.14
23,-17,25:18.14
24,-17,25:18.14
25,-17,25:18.14
34,-17,25:18.6
-2,-16,25:18.6
-1,-16,25:18.6
0,-16,25:18.6
1,-16,25:18.6
2,-16,25:18.6
3,-16,25:18.6
11,-16,25:18.14
12,-16,25:17.1
13,-16,25:18.14
14,-16,25:18.14
15,-16,25:18.14
16,-16,25:18.14
17,-16,25:18.14
18,-16,25:18.14
19,-16,25:17.1
20,-16,25:17.1
21,-16,25:18.14
22,-16,25:18.14
25,-16,25:18.14
27,-16,25:18.14
28,-16,25:18.14
29,-16,25:18.14
30,-16,25:18.6
31,-16,25:18.6
32,-16,25:18.6
33,-16,25:18.6
3,-15,25:18.6
13,-15,25:17.1
19,-15,25:17.1
20,-15,25:17.1
23,-15,25:18.14
28,-15,25:17.1
29,-15,25:17.1
30,-15,25:17.1
32,-15,25:18.6
33,-15,25:18.6
3,-14,25:18.6
10,-14,25:18.14
23,-14,25:18.14
24,-14,25:18.14
29,-14,25:17.1
34,-14,25:18.6
4,-13,25:18.6
10,-13,25:18.14
24,-13,25:18.14
34,-13,25:18.6
35,-13,25:18.6
4,-12,25:18.6
9,-12,25:18.14
25,-12,25:18.14
35,-12,25:18.6
4,-11,25:18.6
5,-11,25:18.6
8,-11,25:18.14
9,-11,25:18.14
25,-11,25:18.14
26,-11,25:18.14
35,-11,25:18.6
36,-11,25:18.6
5,-10,25:18.6
8,-10,25:18.14
13,-10,25:17.13
14,-10,25:17.13
15,-10,25:17.13
26,-10,25:18.14
36,-10,25:18.6
37,-10,25:18.6
5,-9,25:18.6
7,-9,25:18.6
8,-9,25:18.14
12,-9,25:17.13
13,-9,25:17.13
14,-9,25:17.13
15,-9,25:17.13
16,-9,25:17.13
17,-9,25:17.13
18,-9,25:17.13
19,-9,25:17.13
27,-9,25:18.14
37,-9,25:18.6
5,-8,25:18.6
7,-8,25:18.14
13,-8,25:17.13
14,-8,25:17.13
15,-8,25:17.13
16,-8,25:17.13
17,-8,25:17.13
18,-8,25:17.13
19,-8,25:17.13
27,-8,25:18.14
28,-8,25:18.14
37,-8,25:18.6
38,-8,25:18.6
39,-8,25:18.6
40,-8,25:18.6
5,-7,25:18.6
6,-7,25:18.14
7,-7,25:18.14
18,-7,25:17.13
19,-7,25:17.13
27,-7,25:18.14
30,-7,25:17.1
37,-7,25:18.6
4,-6,25:18.14
5,-6,25:18.14
7,-6,25:18.14
27,-6,25:18.14
30,-6,25:17.1
31,-6,25:17.1
36,-6,25:18.6
37,-6,25:18.6
1,-5,25:18.6
2,-5,25:18.6
3,-5,25:18.14
5,-5,25:18.14
7,-5,25:18.14
8,-5,25:18.14
26,-5,25:18.14
36,-5,25:18.6
4,-4,25:18.14
5,-4,25:18.14
8,-4,25:18.14
12,-4,25:17.13
26,-4,25:18.14
35,-4,25:18.6
36,-4,25:18.6
4,-3,25:18.14
8,-3,25:18.14
9,-3,25:18.14
11,-3,25:17.13
12,-3,25:17.13
25,-3,25:18.14
35,-3,25:18.6
4,-2,25:18.14
9,-2,25:18.14
17,-2,25:17.13
18,-2,25:17.13
25,-2,25:18.14
34,-2,25:18.6
35,-2,25:18.6
3,-1,25:18.14
4,-1,25:18.14
10,-1,25:18.14
17,-1,25:17.13
18,-1,25:17.13
24,-1,25:18.14
3,0,25:18.14
6,0,25:17.1
7,0,25:17.1
10,0,25:18.14
11,0,25:18.14
24,0,25:18.14
33,0,25:18.6
34,0,25:18.6
35,0,25:18.6
3,1,25:18.14
5,1,25:17.1
6,1,25:17.1
11,1,25:18.14
23,1,25:18.14
32,1,25:18.6
33,1,25:18.6
35,1,25:18.6
36,1,25:18.6
3,2,25:18.14
13,2,25:18.14
14,2,25:18.14
15,2,25:18.14
16,2,25:18.14
17,2,25:18.14
18,2,25:18.14
19,2,25:18.14
20,2,25:18.14
21,2,25:18.14
22,2,25:18.14
23,2,25:18.14
32,2,25:18.6
36,2,25:18.6
37,2,25:18.6
38,2,25:18.6
3,3,25:18.14
28,3,25:18.14
29,3,25:18.14
30,3,25:18.6
31,3,25:18.6
2,4,25:18.14
3,4,25:18.14
24,4,25:18.14
25,4,25:18.14
26,4,25:18.14
27,4,25:18.14
28,4,25:18.14
-1,5,25:18.6
0,5,25:18.6
1,5,25:18.6
3,5,25:18.6
4,5,25:18.6
21,5,25:18.14
22,5,25:18.14
23,5,25:18.14
24,5,25:18.14
25,5,25:18.14
26,5,25:17.1
27,5,25:17.1
4,6,25:18.6
20,6,25:18.14
21,6,25:18.14
25,6,25:18.14
26,6,25:18.14
5,7,25:18.6
19,7,25:18.6
20,7,25:18.14
26,7,25:18.14
5,8,25:18.6
6,8,25:18.6
18,8,25:18.6
19,8,25:18.6
27,8,25:18.6
6,9,25:18.6
18,9,25:18.6
27,9,25:18.6
28,9,25:18.6
7,10,25:18.6
17,10,25:18.6
7,11,25:18.6
8,11,25:18.6
9,11,25:18.6
10,11,25:18.6
11,11,25:18.6
12,11,25:18.6
13,11,25:18.6
14,11,25:18.6
15,11,25:18.6
16,11,25:18.6
17,11,25:18.6
7,12,25:18.6
8,12,25:18.6
17,12,25:18.6
7,13,25:18.6
17,13,25:18.6
6,14,25:18.6
7,14,25:18.6
18,14,25:18.6
18,15,25:18.6
18,16,25:18.6
15,-28,26:18.6
15,-27,26:18.6
15,-26,26:18.6
5,-25,26:18.6
6,-25,26:18.6
15,-25,26:18.6
6,-24,26:18.6
7,-24,26:18.6
8,-24,26:18.6
9,-24,26:18.6
10,-24,26:18.6
11,-24,26:18.6
12,-24,26:18.6
13,-24,26:18.6
14,-24,26:18.6
15,-24,26:18.6
6,-23,26:18.6
16,-23,26:18.6
17,-23,26:18.6
5,-22,26:18.6
6,-22,26:18.6
17,-22,26:18.6
18,-22,26:18.6
5,-21,26:18.6
18,-21,26:18.6
19,-21,26:18.6
4,-20,26:18.6
19,-20,26:18.6
20,-20,26:18.6
24,-20,26:18.6
4,-19,26:18.6
20,-19,26:18.6
21,-19,26:18.6
24,-19,26:18.6
35,-19,26:18.6
3,-18,26:18.6
21,-18,26:18.14
22,-18,26:18.14
23,-18,26:18.14
34,-18,26:18.6
3,-17,26:18.6
11,-17,26:17.1
12,-17,26:17.1
22,-17,26:18.14
23,-17,26:18.14
24,-17,26:18.14
31,-17,26:17.1
32,-17,26:17.1
34,-17,26:18.6
-1,-16,26:18.6
0,-16,26:18.6
1,-16,26:18.6
2,-16,26:18.6
3,-16,26:18.6
11,-16,26:18.14
12,-16,26:18.14
13,-16,26:18.14
14,-16,26:18.14
15,-16,26:18.14
16,-16,26:18.14
17,-16,26:18.14
18,-16,26:18.14
19,-16,26:17.1
20,-16,26:17.1
21,-16,26:18.14
22,-16,26:18.14
24,-16,26:18.14
25,-16,26:18.6
27,-16,26:18.6
28,-16,26:18.6
29,-16,26:18.6
30,-16,26:17.1
31,-16,26:17.1
33,-16,26:18.6
3,-15,26:18.6
19,-15,26:17.1
20,-15,26:17.1
22,-15,26:18.14
23,-15,26:18.14
28,-15,26:17.1
29,-15,26:17.1
30,-15,26:17.1
31,-15,26:18.6
32,-15,26:18.6
33,-15,26:18.6
3,-14,26:18.6
4,-14,26:18.6
10,-14,26:18.14
11,-14,26:18.14
23,-14,26:18.14
28,-14,26:17.1
33,-14,26:18.6
34,-14,26:18.6
4,-13,26:18.6
10,-13,26:18.14
24,-13,26:18.14
34,-13,26:18.6
4,-12,26:18.6
9,-12,26:18.14
10,-12,26:18.14
24,-12,26:18.14
25,-12,26:18.6
35,-12,26:18.6
5,-11,26:18.6
9,-11,26:18.14
25,-11,26:18.14
35,-11,26:18.6
36,-11,26:18.6
5,-10,26:18.6
8,-10,26:18.14
12,-10,26:17.1
13,-10,26:17.1
26,-10,26:18.14
36,-10,26:18.6
5,-9,26:18.6
6,-9,26:18.6
8,-9,26:18.14
12,-9,26:17.1
13,-9,26:17.1
18,-9,26:17.1
26,-9,26:18.14
27,-9,26:18.14
37,-9,26:18.6
5,-8,26:18.6
6,-8,26:18.6
7,-8,26:18.14
13,-8,26:17.1
17,-8,26:17.1
18,-8,26:17.1
19,-8,26:17.1
27,-8,26:18.14
37,-8,26:18.6
38,-8,26:18.6
39,-8,26:18.6
40,-8,26:18.6
5,-7,26:18.6
6,-7,26:18.14
7,-7,26:18.14
17,-7,26:17.13
18,-7,26:17.1
19,-7,26:17.1
27,-7,26:18.14
31,-7,26:17.1
37,-7,26:18.6
4,-6,26:18.14
5,-6,26:18.14
6,-6,26:18.14
7,-6,26:18.14
26,-6,26:18.14
27,-6,26:18.14
31,-6,26:17.1
36,-6,26:18.6
2,-5,26:18.6
3,-5,26:18.14
5,-5,26:18.14
7,-5,26:18.14
8,-5,26:18.14
26,-5,26:18.14
36,-5,26:18.6
5,-4,26:18.14
8,-4,26:18.14
12,-4,26:17.13
25,-4,26:18.14
26,-4,26:18.14
35,-4,26:18.6
4,-3,26:18.14
5,-3,26:18.14
9,-3,26:18.14
12,-3,26:17.13
25,-3,26:18.14
35,-3,26:18.6
4,-2,26:18.14
9,-2,26:18.14
10,-2,26:18.14
17,-2,26:17.13
18,-2,26:17.13
24,-2,26:18.14
25,-2,26:18.14
34,-2,26:18.6
4,-1,26:18.14
10,-1,26:18.14
17,-1,26:17.13
18,-1,26:17.13
24,-1,26:18.14
33,-1,26:18.6
4,0,26:18.14
11,0,26:18.14
23,0,26:18.14
24,0,26:18.14
33,0,26:18.6
34,0,26:18.6
35,0,26:18.6
3,1,26:18.14
4,1,26:17.1
5,1,26:17.1
11,1,26:18.14
12,1,26:18.14
23,1,26:18.14
32,1,26:18.6
35,1,26:18.6
36,1,26:18.6
3,2,26:18.14
13,2,26:18.14
14,2,26:18.14
15,2,26:18.14
16,2,26:18.14
17,2,26:18.14
18,2,26:18.14
19,2,26:18.14
20,2,26:18.14
21,2,26:18.14
22,2,26:18.14
23,2,26:18.14
29,2,26:18.14
30,2,26:18.6
37,2,26:18.6
3,3,26:18.14
24,3,26:18.14
25,3,26:18.14
26,3,26:18.14
28,3,26:18.14
29,3,26:18.14
2,4,26:18.14
3,4,26:18.14
4,4,26:18.14
22,4,26:18.14
23,4,26:18.14
24,4,26:18.14
25,4,26:18.14
-1,5,26:18.6
0,5,26:18.6
1,5,26:18.6
4,5,26:18.6
20,5,26:18.14
21,5,26:18.14
22,5,26:18.14
25,5,26:18.14
26,5,26:17.1
27,5,26:17.1
4,6,26:18.6
5,6,26:18.6
20,6,26:18.14
25,6,26:18.14
26,6,26:18.14
27,6,26:17.1
5,7,26:18.6
19,7,26:18.6
26,7,26:18.14
27,7,26:18.14
6,8,26:18.6
18,8,26:18.6
19,8,26:18.6
27,8,26:18.6
6,9,26:18.6
7,9,26:18.6
17,9,26:18.6
18,9,26:18.6
7,10,26:18.6
17,10,26:18.6
8,11,26:18.6
9,11,26:18.6
10,11,26:18.6
11,11,26:18.6
12,11,26:18.6
13,11,26:18.6
14,11,26:18.6
15,11,26:18.6
16,11,26:18.6
17,11,26:18.6
7,12,26:18.6
8,12,26:18.6
17,12,26:18.6
7,13,26:18.6
17,13,26:18.6
18,14,26:18.6
18,15,26:18.6
15,-28,27:18.6
15,-27,27:18.6
15,-26,27:18.6
5,-25,27:18.6
6,-25,27:18.6
14,-25,27:18.6
15,-25,27:18.6
5,-24,27:18.6
6,-24,27:18.6
7,-24,27:18.6
8,-24,27:18.6
9,-24,27:18.6
10,-24,27:18.6
11,-24,27:18.6
12,-24,27:18.6
13,-24,27:18.6
14,-24,27:18.6
15,-24,27:18.6
5,-23,27:18.6
6,-23,27:18.6
7,-23,27:18.6
8,-23,27:18.6
9,-23,27:18.6
10,-23,27:18.6
11,-23,27:18.6
12,-23,27:18.6
13,-23,27:18.6
14,-23,27:18.6
15,-23,27:18.6
16,-23,27:18.6
4,-22,27:18.6
5,-22,27:18.6
6,-22,27:18.6
7,-22,27:18.6
8,-22,27:18.6
9,-22,27:18.6
10,-22,27:18.6
11,-22,27:18.6
12,-22,27:18.6
13,-22,27:18.6
14,-22,27:18.6
15,-22,27:18.6
16,-22,27:18.6
17,-22,27:18.6
4,-21,27:18.6
5,-21,27:18.6
6,-21,27:18.6
7,-21,27:18.6
8,-21,27:18.6
15,-21,27:18.6
16,-21,27:18.6
17,-21,27:18.6
18,-21,27:18.6
4,-20,27:18.6
5,-20,27:18.6
6,-20,27:18.6
7,-20,27:18.6
17,-20,27:18.6
18,-20,27:18.6
19,-20,27:18.6
24,-20,27:18.6
4,-19,27:18.6
5,-19,27:18.6
6,-19,27:18.6
18,-19,27:18.6
19,-19,27:18.6
20,-19,27:18.6
24,-19,27:18.6
35,-19,27:17.1
3,-18,27:18.6
4,-18,27:18.6
5,-18,27:18.6
11,-18,27:17.1
19,-18,27:18.14
