[META]
version=2.0
spawnOnBlockType=2
spawnSunlight=True
spawnDarkness=True
spawnWater=False
spawnLava=False
underFill=False
randomRotation=True
dig=True
tree=False
branch=False
needsFoundation=True
rarity=100
collisionPercentage=20
spawnElevationMin=0
spawnElevationMax=200
spawnInBiome=Custom
[DATA]
2,2,-8:17.12
3,2,-8:17.12
1,3,-8:17.12
0,2,-7:17.12
1,2,-7:17.12
2,2,-7:17.12
3,2,-7:17.12
0,3,-7:17.12
3,4,-7:17.12
2,1,-6:17.12
0,2,-6:17.12
1,2,-6:17.12
2,2,-6:17.12
3,2,-6:17.12
4,2,-6:17.12
2,3,-6:17.12
3,3,-6:17.12
4,3,-6:17.12
1,4,-6:17.12
2,4,-6:17.12
3,4,-6:17.12
1,0,-5:17.12
2,0,-5:17.12
3,0,-5:17.12
0,1,-5:17.12
0,2,-5:17.12
1,2,-5:17.12
2,2,-5:17.12
3,2,-5:17.12
4,2,-5:17.12
0,3,-5:17.12
1,3,-5:17.12
2,3,-5:17.12
3,3,-5:17.12
2,0,-4:17.12
2,1,-4:17.12
3,1,-4:17.12
1,2,-4:17.12
2,2,-4:17.12
3,2,-4:17.12
0,3,-4:17.12
1,3,-4:17.12
3,3,-4:17.12
1,4,-4:17.12
3,4,-4:17.12
0,1,-3:17.12
2,1,-3:17.12
3,1,-3:17.12
1,2,-3:17.12
2,2,-3:17.12
3,2,-3:17.12
4,2,-3:17.12
1,3,-3:17.12
2,3,-3:17.12
3,3,-3:17.12
4,3,-3:17.12
2,4,-3:17.12
3,4,-3:17.12
1,0,-2:17.12
2,0,-2:17.12
3,0,-2:17.12
0,1,-2:17.12
1,1,-2:17.12
2,1,-2:17.12
4,1,-2:17.12
1,2,-2:17.12
2,2,-2:17.12
2,-1,-1:17.12
0,0,-1:17.12
1,0,-1:17.12
2,0,-1:17.12
3,0,-1:17.12
4,0,-1:17.12
0,1,-1:17.12
1,1,-1:17.12
4,1,-1:17.12
1,2,-1:17.12
2,2,-1:17.12
3,2,-1:17.12
4,2,-1:17.12
1,3,-1:17.12
2,3,-1:17.12
3,3,-1:17.12
4,3,-1:17.12
2,4,-1:17.12
3,4,-1:17.12
1,-1,0:17.12
2,-1,0:17.12
3,-1,0:17.12
0,0,0:17.12
1,0,0:17.12
3,0,0:17.12
4,0,0:17.12
0,1,0:17.12
1,1,0:17.12
4,1,0:17.12
1,2,0:17.12
3,2,0:17.12
4,2,0:17.12
1,3,0:17.12
2,3,0:17.12
3,3,0:17.12
1,-2,1:17.12
2,-2,1:17.12
0,-1,1:17.12
1,-1,1:17.12
2,-1,1:17.12
3,-1,1:17.12
0,0,1:17.12
3,0,1:17.12
4,0,1:17.12
0,1,1:17.12
1,1,1:17.12
3,1,1:17.12
4,1,1:17.12
1,2,1:17.12
2,2,1:17.12
3,2,1:17.12
2,3,1:17.12
0,-3,2:18.14
0,-2,2:17.12
1,-2,2:17.12
2,-2,2:17.12
0,-1,2:17.12
2,-1,2:17.12
3,-1,2:17.12
0,0,2:17.12
3,0,2:17.12
0,1,2:17.12
1,1,2:17.12
2,1,2:17.12
3,1,2:17.12
2,2,2:17.12
1,-5,3:18.14
2,-5,3:18.14
3,-5,3:18.14
1,-4,3:18.14
2,-4,3:18.14
3,-4,3:18.14
1,-3,3:17.12
2,-3,3:18.14
3,-3,3:18.14
0,-2,3:17.12
1,-2,3:17.12
2,-2,3:17.12
0,-1,3:17.12
3,-1,3:17.12
0,0,3:17.12
1,0,3:17.12
2,0,3:17.12
3,0,3:17.12
1,1,3:17.12
2,1,3:17.12
3,2,3:18.14
3,3,3:18.14
4,3,3:18.14
1,4,3:18.14
2,4,3:18.14
3,4,3:18.14
2,5,3:18.14
1,-5,4:18.14
2,-5,4:18.14
1,-4,4:18.14
2,-4,4:18.14
3,-4,4:18.14
0,-3,4:17.12
1,-3,4:17.12
2,-3,4:18.14
3,-3,4:18.14
0,-2,4:17.12
2,-2,4:17.12
0,-1,4:17.12
2,-1,4:17.12
3,-1,4:17.12
0,0,4:17.12
1,0,4:17.12
2,0,4:17.12
3,2,4:18.14
3,3,4:18.14
4,3,4:18.14
1,4,4:18.14
2,4,4:18.14
3,4,4:18.14
2,5,4:18.14
4,5,4:18.14
2,-5,5:18.14
2,-4,5:18.14
0,-3,5:17.12
1,-3,5:17.12
2,-3,5:17.12
0,-2,5:17.12
2,-2,5:17.12
0,-1,5:17.12
1,-1,5:17.12
2,-1,5:17.12
1,0,5:17.12
3,2,5:18.14
3,3,5:18.14
1,4,5:18.14
2,4,5:18.14
3,4,5:18.14
0,-3,6:17.12
1,-3,6:17.12
2,-3,6:17.12
0,-2,6:17.12
2,-2,6:17.12
0,-1,6:17.12
1,-1,6:17.12
2,-1,6:17.12
0,-3,7:17.12
1,-3,7:17.12
2,-3,7:17.12
0,-2,7:17.12
2,-2,7:17.12
1,-1,7:17.12
2,-1,7:17.12
1,-4,8:17.12
0,-3,8:17.12
1,-3,8:17.12
2,-3,8:17.12
0,-2,8:17.12
1,-2,8:17.12
2,-2,8:17.12
1,-1,8:17.12
1,-4,9:17.12
1,-3,9:17.12
2,-3,9:17.12
1,-2,9:17.12
2,-2,9:17.12
1,-3,10:17.12
2,-3,10:17.12
1,-2,10:17.12
2,-2,10:17.12
7,1,10:18.14
8,2,10:18.6
9,2,10:18.6
10,3,10:18.6
2,4,10:18.6
9,4,10:18.6
2,5,10:18.6
2,6,10:18.6
1,7,10:18.6
2,7,10:18.6
3,7,10:18.6
4,7,10:18.6
3,8,10:18.6
2,-10,11:18.6
4,-10,11:18.6
2,-9,11:18.6
2,-8,11:18.14
2,-7,11:18.14
2,-6,11:18.14
1,-3,11:17.12
2,-3,11:17.12
1,-2,11:17.12
2,-2,11:17.12
1,-1,11:17.12
2,-1,11:18.14
10,-1,11:18.6
5,0,11:18.14
10,0,11:18.6
-5,1,11:18.6
2,1,11:18.14
6,1,11:18.14
7,1,11:18.14
10,1,11:18.6
-5,2,11:18.6
2,2,11:18.14
8,2,11:18.6
9,2,11:18.6
10,2,11:18.6
-5,3,11:18.6
10,3,11:18.6
11,3,11:18.6
-4,4,11:18.6
-3,4,11:18.6
2,4,11:18.14
3,4,11:18.14
8,4,11:18.6
9,4,11:18.6
-2,5,11:18.6
-1,5,11:18.6
3,5,11:18.6
6,5,11:18.6
7,5,11:18.6
-1,6,11:18.6
0,6,11:18.6
1,6,11:18.6
3,6,11:18.6
4,6,11:18.6
5,6,11:18.6
6,6,11:18.6
1,7,11:18.6
2,7,11:18.6
3,7,11:18.6
4,7,11:18.6
3,8,11:18.6
3,9,11:18.6
3,-11,12:18.6
1,-10,12:18.6
2,-10,12:18.6
3,-10,12:18.6
4,-10,12:18.6
-1,-9,12:18.6
0,-9,12:18.6
3,-9,12:18.6
4,-9,12:18.6
5,-9,12:18.6
6,-9,12:18.6
3,-8,12:18.14
6,-8,12:18.6
7,-8,12:18.6
-4,-7,12:18.14
2,-7,12:18.14
3,-7,12:18.14
8,-7,12:18.6
9,-7,12:18.6
-5,-6,12:18.6
2,-6,12:18.14
10,-6,12:18.6
11,-6,12:18.6
-5,-5,12:18.6
-4,-5,12:18.14
-3,-5,12:18.14
2,-5,12:18.14
10,-5,12:18.6
-5,-4,12:18.6
-3,-4,12:18.14
-2,-4,12:18.14
-1,-4,12:18.14
2,-4,12:18.14
10,-4,12:18.6
-5,-3,12:18.6
-1,-3,12:18.14
0,-3,12:18.14
1,-3,12:17.12
2,-3,12:17.12
10,-3,12:18.6
-5,-2,12:18.6
1,-2,12:18.14
2,-2,12:18.14
10,-2,12:18.6
-5,-1,12:18.6
1,-1,12:17.12
2,-1,12:18.14
3,-1,12:18.14
4,-1,12:18.14
10,-1,12:18.6
-5,0,12:18.6
2,0,12:18.14
4,0,12:18.14
5,0,12:18.14
10,0,12:18.6
-5,1,12:18.6
2,1,12:18.14
6,1,12:18.14
7,1,12:18.14
10,1,12:18.6
-5,2,12:18.6
2,2,12:18.14
8,2,12:18.6
9,2,12:18.6
10,2,12:18.6
-5,3,12:18.6
-4,3,12:18.6
3,3,12:18.14
8,3,12:18.6
10,3,12:18.6
11,3,12:18.6
-6,4,12:18.6
-4,4,12:18.6
-3,4,12:18.6
3,4,12:18.14
6,4,12:18.14
7,4,12:18.14
8,4,12:18.6
9,4,12:18.6
11,4,12:18.6
-2,5,12:18.6
-1,5,12:18.6
3,5,12:18.6
4,5,12:18.6
5,5,12:18.6
6,5,12:18.6
7,5,12:18.6
0,6,12:18.6
1,6,12:18.6
2,6,12:18.6
3,6,12:18.6
4,6,12:18.6
5,6,12:18.6
2,7,12:18.6
3,7,12:18.6
3,8,12:18.6
3,9,12:18.6
3,10,12:18.6
3,-11,13:18.6
2,-10,13:18.6
3,-10,13:18.6
0,-9,13:18.6
1,-9,13:18.6
3,-9,13:18.6
4,-9,13:18.6
5,-9,13:18.6
-2,-8,13:18.14
-1,-8,13:18.14
3,-8,13:18.14
5,-8,13:18.14
6,-8,13:18.6
7,-8,13:18.6
-4,-7,13:18.6
-3,-7,13:18.14
-2,-7,13:18.14
3,-7,13:18.14
7,-7,13:18.6
8,-7,13:18.6
-6,-6,13:18.6
-5,-6,13:18.6
-4,-6,13:18.6
3,-6,13:18.14
9,-6,13:18.6
10,-6,13:18.6
11,-6,13:18.6
-5,-5,13:18.6
-4,-5,13:18.6
-3,-5,13:18.14
3,-5,13:18.14
10,-5,13:18.6
-5,-4,13:18.6
-3,-4,13:18.14
-2,-4,13:18.14
2,-4,13:18.14
3,-4,13:18.14
9,-4,13:18.6
10,-4,13:18.6
-5,-3,13:18.6
-1,-3,13:18.14
0,-3,13:18.14
2,-3,13:17.12
3,-3,13:18.14
8,-3,13:18.6
9,-3,13:18.6
10,-3,13:18.6
-5,-2,13:18.6
1,-2,13:18.14
2,-2,13:18.14
3,-2,13:17.12
7,-2,13:18.14
8,-2,13:18.6
9,-2,13:18.6
10,-2,13:18.6
-5,-1,13:18.6
1,-1,13:17.12
2,-1,13:17.12
3,-1,13:18.14
4,-1,13:18.14
6,-1,13:18.14
7,-1,13:18.14
8,-1,13:18.6
9,-1,13:18.6
10,-1,13:18.6
-5,0,13:18.6
2,0,13:18.14
3,0,13:18.14
4,0,13:18.14
5,0,13:18.14
6,0,13:18.14
7,0,13:18.14
8,0,13:18.6
9,0,13:18.6
10,0,13:18.6
-5,1,13:18.6
-4,1,13:18.6
2,1,13:18.14
3,1,13:18.14
4,1,13:18.14
5,1,13:18.14
6,1,13:18.14
7,1,13:18.14
8,1,13:18.6
9,1,13:18.6
10,1,13:18.6
-5,2,13:18.6
-4,2,13:18.6
-3,2,13:18.14
-2,2,13:18.14
-1,2,13:18.14
0,2,13:18.14
1,2,13:18.14
2,2,13:18.14
3,2,13:18.14
4,2,13:18.14
5,2,13:18.14
6,2,13:18.14
7,2,13:18.14
8,2,13:18.6
9,2,13:18.6
10,2,13:18.6
-5,3,13:18.6
-4,3,13:18.6
-3,3,13:18.14
-2,3,13:18.14
-1,3,13:18.14
0,3,13:18.14
1,3,13:18.14
3,3,13:18.14
4,3,13:18.14
5,3,13:18.14
6,3,13:18.14
7,3,13:18.14
8,3,13:18.6
10,3,13:18.6
-7,4,13:18.6
-6,4,13:18.6
-4,4,13:18.6
-3,4,13:18.6
-2,4,13:18.14
-1,4,13:18.14
0,4,13:18.14
1,4,13:18.14
2,4,13:18.14
3,4,13:18.14
4,4,13:18.14
5,4,13:18.14
6,4,13:18.14
7,4,13:18.14
8,4,13:18.6
11,4,13:18.6
12,4,13:18.6
-2,5,13:18.6
-1,5,13:18.6
0,5,13:18.6
1,5,13:18.6
2,5,13:18.6
3,5,13:18.6
4,5,13:18.6
5,5,13:18.6
6,5,13:18.6
0,6,13:18.6
1,6,13:18.6
2,6,13:18.6
3,6,13:18.6
4,6,13:18.6
2,7,13:18.6
3,7,13:18.6
3,8,13:18.6
3,9,13:18.6
3,10,13:18.6
3,-12,14:18.6
3,-11,14:18.6
2,-10,14:18.6
3,-10,14:18.6
1,-9,14:18.6
2,-9,14:18.6
3,-9,14:18.6
4,-9,14:18.6
-1,-8,14:18.6
0,-8,14:18.6
1,-8,14:18.6
2,-8,14:18.6
3,-8,14:18.6
4,-8,14:18.6
5,-8,14:18.6
6,-8,14:18.6
-3,-7,14:18.14
-2,-7,14:18.14
-1,-7,14:18.14
0,-7,14:18.14
1,-7,14:18.14
2,-7,14:18.14
3,-7,14:18.14
4,-7,14:18.14
5,-7,14:18.14
6,-7,14:18.14
7,-7,14:18.6
8,-7,14:18.6
12,-7,14:18.6
-7,-6,14:18.6
-6,-6,14:18.6
-5,-6,14:18.6
-4,-6,14:18.6
-3,-6,14:18.14
-2,-6,14:18.14
-1,-6,14:18.14
0,-6,14:18.14
1,-6,14:18.14
2,-6,14:18.14
3,-6,14:18.14
4,-6,14:18.14
5,-6,14:18.14
6,-6,14:18.14
7,-6,14:18.14
8,-6,14:18.6
9,-6,14:18.6
10,-6,14:18.6
11,-6,14:18.6
12,-6,14:18.6
-5,-5,14:18.6
-4,-5,14:18.6
-3,-5,14:18.14
-2,-5,14:18.14
-1,-5,14:18.14
0,-5,14:18.14
1,-5,14:18.14
2,-5,14:18.14
3,-5,14:18.14
4,-5,14:18.14
5,-5,14:18.14
6,-5,14:18.14
7,-5,14:18.14
8,-5,14:18.6
9,-5,14:18.6
10,-5,14:18.6
-5,-4,14:18.6
-4,-4,14:18.6
-3,-4,14:18.14
-2,-4,14:18.14
-1,-4,14:18.14
0,-4,14:18.14
1,-4,14:18.14
2,-4,14:18.14
3,-4,14:18.14
4,-4,14:18.14
5,-4,14:18.14
6,-4,14:18.14
7,-4,14:18.14
8,-4,14:18.6
9,-4,14:18.6
10,-4,14:18.6
-5,-3,14:18.6
-4,-3,14:18.6
-3,-3,14:18.14
-2,-3,14:18.14
-1,-3,14:18.14
0,-3,14:18.14
1,-3,14:18.14
2,-3,14:18.14
3,-3,14:18.14
4,-3,14:18.14
5,-3,14:18.14
6,-3,14:18.14
7,-3,14:18.14
8,-3,14:18.6
9,-3,14:18.6
-5,-2,14:18.6
-4,-2,14:18.6
-3,-2,14:18.14
-2,-2,14:18.14
-1,-2,14:18.14
0,-2,14:18.14
1,-2,14:18.14
2,-2,14:18.14
3,-2,14:18.14
4,-2,14:18.14
5,-2,14:18.14
6,-2,14:18.14
7,-2,14:18.14
9,-2,14:18.6
-5,-1,14:18.6
-4,-1,14:18.6
-3,-1,14:18.14
-2,-1,14:18.14
-1,-1,14:18.14
0,-1,14:18.14
1,-1,14:18.14
2,-1,14:17.12
3,-1,14:18.14
4,-1,14:18.14
5,-1,14:18.14
6,-1,14:18.14
9,-1,14:18.6
-5,0,14:18.6
-4,0,14:18.6
-3,0,14:18.14
-2,0,14:18.14
-1,0,14:18.14
0,0,14:18.14
1,0,14:18.14
2,0,14:18.14
3,0,14:18.14
4,0,14:18.14
5,0,14:18.14
9,0,14:18.6
-4,1,14:18.6
-3,1,14:18.14
-2,1,14:18.14
-1,1,14:18.14
0,1,14:18.14
1,1,14:18.14
2,1,14:18.14
3,1,14:18.14
9,1,14:18.6
-4,2,14:18.6
8,2,14:18.6
9,2,14:18.6
-5,3,14:18.6
-4,3,14:18.6
-3,3,14:18.14
-2,3,14:18.14
7,3,14:18.14
8,3,14:18.6
10,3,14:18.6
-7,4,14:18.6
-6,4,14:18.6
-3,4,14:18.6
-2,4,14:18.14
-1,4,14:18.14
0,4,14:18.14
5,4,14:18.14
6,4,14:18.14
7,4,14:18.14
11,4,14:18.6
12,4,14:18.6
0,5,14:18.6
1,5,14:18.6
2,5,14:18.6
3,5,14:18.6
4,5,14:18.6
5,5,14:18.6
12,5,14:18.6
2,6,14:18.6
3,6,14:18.6
3,7,14:18.6
3,8,14:18.6
3,9,14:18.6
3,10,14:18.6
3,-12,15:18.6
4,-12,15:18.6
3,-11,15:18.6
3,-10,15:18.6
2,-9,15:18.6
3,-9,15:18.6
0,-8,15:18.6
1,-8,15:18.6
2,-8,15:18.6
3,-8,15:18.6
4,-8,15:18.6
5,-8,15:18.6
-2,-7,15:18.14
-1,-7,15:18.14
0,-7,15:18.14
5,-7,15:18.14
6,-7,15:18.14
12,-7,15:18.6
-8,-6,15:18.6
-7,-6,15:18.6
-6,-6,15:18.6
-3,-6,15:18.14
-2,-6,15:18.14
6,-6,15:18.14
7,-6,15:18.14
8,-6,15:18.6
11,-6,15:18.6
12,-6,15:18.6
-6,-5,15:18.6
-5,-5,15:18.6
-4,-5,15:18.6
-3,-5,15:18.14
8,-5,15:18.6
9,-5,15:18.6
10,-5,15:18.6
-4,-4,15:18.6
8,-4,15:18.6
9,-4,15:18.6
-4,-3,15:18.6
8,-3,15:18.6
9,-3,15:18.6
-4,-2,15:18.6
1,-2,15:17.12
2,-2,15:17.12
3,-2,15:17.12
8,-2,15:18.6
9,-2,15:18.6
-4,-1,15:18.6
1,-1,15:17.12
2,-1,15:17.12
3,-1,15:17.12
8,-1,15:18.6
9,-1,15:18.6
-4,0,15:18.6
-3,0,15:18.14
2,0,15:17.12
8,0,15:18.6
-4,1,15:18.6
-3,1,15:18.14
8,1,15:18.6
-4,2,15:18.6
-3,2,15:18.14
7,2,15:18.14
8,2,15:18.6
-5,3,15:18.6
-4,3,15:18.6
-3,3,15:18.14
-2,3,15:18.14
-1,3,15:18.14
6,3,15:18.14
7,3,15:18.14
10,3,15:18.6
-6,4,15:18.6
-5,4,15:18.6
-1,4,15:18.14
0,4,15:18.14
1,4,15:18.14
4,4,15:18.14
5,4,15:18.14
6,4,15:18.14
10,4,15:18.6
11,4,15:18.6
1,5,15:18.6
2,5,15:18.6
3,5,15:18.6
4,5,15:18.6
12,5,15:18.6
3,6,15:18.6
3,7,15:18.6
3,8,15:18.6
4,-12,16:18.6
3,-11,16:18.6
4,-11,16:18.6
3,-10,16:18.6
3,-9,16:18.6
1,-8,16:18.6
2,-8,16:18.6
3,-8,16:18.6
0,-7,16:18.14
1,-7,16:18.14
3,-7,16:18.14
4,-7,16:18.14
5,-7,16:18.14
-8,-6,16:18.6
-2,-6,16:18.14
-1,-6,16:18.14
0,-6,16:18.14
5,-6,16:18.14
6,-6,16:18.14
11,-6,16:18.6
12,-6,16:18.6
-7,-5,16:18.6
-6,-5,16:18.6
-5,-5,16:18.6
-4,-5,16:18.6
-3,-5,16:18.14
-2,-5,16:18.14
6,-5,16:18.14
7,-5,16:18.14
8,-5,16:18.6
9,-5,16:18.6
10,-5,16:18.6
-4,-4,16:18.6
-3,-4,16:18.14
7,-4,16:18.14
8,-4,16:18.6
9,-4,16:18.6
-3,-3,16:18.14
7,-3,16:18.14
8,-3,16:18.6
-3,-2,16:18.14
2,-2,16:17.12
3,-2,16:17.12
8,-2,16:18.6
-3,-1,16:18.14
2,-1,16:17.12
3,-1,16:17.12
7,-1,16:18.14
8,-1,16:18.6
-3,0,16:18.14
2,0,16:17.12
3,0,16:17.12
7,0,16:18.14
8,0,16:18.6
-3,1,16:18.14
-2,1,16:18.14
7,1,16:18.14
8,1,16:18.6
-3,2,16:18.14
-2,2,16:18.14
-1,2,16:18.14
6,2,16:18.14
7,2,16:18.14
8,2,16:18.6
-5,3,16:18.6
-4,3,16:18.6
-3,3,16:18.14
-2,3,16:18.14
-1,3,16:18.14
0,3,16:18.14
1,3,16:18.14
4,3,16:18.14
5,3,16:18.14
6,3,16:18.14
10,3,16:18.6
-5,4,16:18.6
1,4,16:18.14
2,4,16:18.14
3,4,16:18.14
4,4,16:18.14
10,4,16:18.6
3,5,16:18.6
3,6,16:18.6
5,6,16:18.6
5,7,16:18.6
3,8,16:18.6
5,8,16:18.6
4,-12,17:18.6
3,-10,17:18.6
3,-9,17:18.6
3,-8,17:18.6
1,-7,17:18.14
2,-7,17:18.14
3,-7,17:18.14
-1,-6,17:18.14
0,-6,17:18.14
1,-6,17:18.14
3,-6,17:18.14
4,-6,17:18.14
5,-6,17:18.14
-6,-5,17:18.6
-5,-5,17:18.6
-4,-5,17:18.6
-3,-5,17:18.14
-2,-5,17:18.14
-1,-5,17:18.14
4,-5,17:18.14
5,-5,17:18.14
6,-5,17:18.14
10,-5,17:18.6
-3,-4,17:18.14
-2,-4,17:18.14
3,-4,17:18.14
6,-4,17:18.14
7,-4,17:18.14
8,-4,17:18.6
9,-4,17:18.6
-3,-3,17:18.14
-2,-3,17:18.14
7,-3,17:18.14
-3,-2,17:18.14
-2,-2,17:18.14
2,-2,17:17.12
3,-2,17:17.12
7,-2,17:18.14
-3,-1,17:18.14
-2,-1,17:18.14
2,-1,17:17.12
3,-1,17:17.12
7,-1,17:18.14
-2,0,17:18.14
2,0,17:17.12
3,0,17:17.12
7,0,17:18.14
-3,1,17:18.14
-2,1,17:18.14
-1,1,17:18.14
7,1,17:18.14
-4,2,17:18.6
-3,2,17:18.14
-2,2,17:18.14
-1,2,17:18.14
0,2,17:18.14
5,2,17:18.14
6,2,17:18.14
7,2,17:18.14
8,2,17:18.6
-3,3,17:18.14
0,3,17:18.14
1,3,17:18.14
3,3,17:18.14
4,3,17:18.14
5,3,17:18.14
2,4,17:18.14
3,4,17:18.14
4,4,17:18.14
3,5,17:18.6
4,5,17:18.6
5,6,17:18.6
5,7,17:18.6
5,8,17:18.6
6,8,17:18.6
3,-9,18:18.6
2,-7,18:18.6
3,-7,18:18.6
1,-6,18:18.14
2,-6,18:18.14
3,-6,18:18.14
4,-6,18:18.14
-6,-5,18:18.6
-5,-5,18:18.6
-1,-5,18:18.14
0,-5,18:18.14
1,-5,18:18.14
3,-5,18:18.14
4,-5,18:18.14
5,-5,18:18.14
-3,-4,18:18.14
-2,-4,18:18.14
-1,-4,18:18.14
3,-4,18:18.14
4,-4,18:18.14
5,-4,18:18.14
6,-4,18:18.14
7,-4,18:18.14
8,-4,18:18.6
-2,-3,18:18.14
3,-3,18:18.14
6,-3,18:18.14
-2,-2,18:18.14
-1,-2,18:18.14
3,-2,18:17.12
6,-2,18:18.14
-2,-1,18:18.14
-1,-1,18:18.14
2,-1,18:17.12
3,-1,18:17.12
4,-1,18:17.12
6,-1,18:18.14
-1,0,18:18.14
0,0,18:18.14
2,0,18:17.12
3,0,18:17.12
6,0,18:18.14
-3,1,18:18.14
-2,1,18:18.14
-1,1,18:18.14
6,1,18:18.14
-4,2,18:18.6
-3,2,18:18.14
-2,2,18:18.14
-1,2,18:18.14
0,2,18:18.14
1,2,18:18.14
2,2,18:18.14
3,2,18:18.14
4,2,18:18.14
5,2,18:18.14
6,2,18:18.14
7,2,18:18.14
8,2,18:18.6
-3,3,18:18.14
1,3,18:18.14
3,3,18:18.14
4,3,18:18.14
3,4,18:18.14
4,4,18:18.14
3,5,18:18.6
4,5,18:18.6
5,5,18:18.6
5,6,18:18.6
5,7,18:18.6
6,8,18:18.6
3,-7,19:18.6
2,-6,19:18.14
3,-6,19:18.14
4,-6,19:18.14
1,-5,19:18.14
3,-5,19:18.14
4,-5,19:18.14
-3,-4,19:18.14
-2,-4,19:18.14
-1,-4,19:18.14
0,-4,19:18.14
3,-4,19:18.14
4,-4,19:18.14
-1,-3,19:18.14
3,-3,19:18.14
6,-3,19:18.14
7,-3,19:18.14
8,-3,19:18.6
-1,-2,19:18.14
3,-2,19:18.14
5,-2,19:18.14
9,-2,19:18.6
-1,-1,19:18.14
2,-1,19:17.12
3,-1,19:17.12
4,-1,19:17.0
9,-1,19:18.6
10,-1,19:18.6
0,0,19:18.14
1,0,19:18.14
2,0,19:17.12
3,0,19:17.12
4,0,19:17.12
10,0,19:18.6
-3,1,19:18.14
-2,1,19:18.14
-1,1,19:18.14
0,1,19:18.14
3,1,19:18.14
10,1,19:18.6
-3,2,19:18.14
-2,2,19:18.14
-1,2,19:18.14
3,2,19:18.14
7,2,19:18.14
10,2,19:18.6
-3,3,19:18.14
4,3,19:18.14
10,3,19:18.6
-2,4,19:18.14
3,4,19:18.14
4,4,19:18.14
10,4,19:18.6
-2,5,19:18.6
-1,5,19:18.6
4,5,19:18.6
5,5,19:18.6
9,5,19:18.6
0,6,19:18.6
5,6,19:18.6
9,6,19:18.6
5,7,19:18.6
6,7,19:18.6
8,7,19:18.6
2,8,19:18.6
3,8,19:18.6
4,8,19:18.6
6,8,19:18.6
3,-6,20:18.6
4,-6,20:18.6
5,-6,20:18.6
-1,-5,20:18.14
0,-5,20:18.14
1,-5,20:18.14
2,-5,20:18.14
3,-5,20:18.14
4,-5,20:18.14
6,-5,20:18.14
-2,-4,20:18.14
-1,-4,20:18.14
4,-4,20:18.14
7,-4,20:18.14
-2,-3,20:18.14
3,-3,20:18.14
6,-3,20:18.14
7,-3,20:18.14
8,-3,20:18.6
-2,-2,20:18.14
3,-2,20:18.14
8,-2,20:18.6
9,-2,20:18.6
-2,-1,20:18.14
3,-1,20:17.0
4,-1,20:17.0
9,-1,20:18.6
10,-1,20:18.6
-2,0,20:18.14
1,0,20:18.14
2,0,20:18.14
3,0,20:18.14
4,0,20:17.0
10,0,20:18.6
-3,1,20:18.6
-2,1,20:18.14
-1,1,20:18.14
0,1,20:18.14
3,1,20:17.0
4,1,20:17.0
10,1,20:18.6
-2,2,20:18.14
3,2,20:18.14
4,2,20:18.14
10,2,20:18.6
-2,3,20:18.14
4,3,20:18.14
10,3,20:18.6
-2,4,20:18.14
4,4,20:18.14
9,4,20:18.6
-1,5,20:18.6
5,5,20:18.6
9,5,20:18.6
0,6,20:18.6
5,6,20:18.6
9,6,20:18.6
1,7,20:18.6
5,7,20:18.6
6,7,20:18.6
7,7,20:18.6
8,7,20:18.6
9,7,20:18.6
2,8,20:18.6
3,8,20:18.6
4,8,20:18.6
5,8,20:18.6
4,-6,21:18.6
5,-6,21:18.6
1,-5,21:18.6
2,-5,21:18.6
3,-5,21:18.6
4,-5,21:18.6
5,-5,21:18.6
6,-5,21:18.6
-2,-4,21:18.6
-1,-4,21:18.6
0,-4,21:18.6
4,-4,21:18.6
6,-4,21:18.6
7,-4,21:18.6
-2,-3,21:18.6
-1,-3,21:18.6
4,-3,21:18.6
7,-3,21:18.6
8,-3,21:18.6
-2,-2,21:18.6
3,-2,21:18.6
7,-2,21:18.6
8,-2,21:18.6
-2,-1,21:18.6
3,-1,21:18.6
7,-1,21:18.6
8,-1,21:18.6
9,-1,21:18.6
-2,0,21:18.6
1,0,21:18.6
2,0,21:18.6
3,0,21:17.0
4,0,21:17.0
7,0,21:18.6
8,0,21:18.6
9,0,21:18.6
10,0,21:18.6
-3,1,21:18.6
-2,1,21:18.6
-1,1,21:18.6
0,1,21:18.6
3,1,21:17.0
4,1,21:17.0
6,1,21:18.6
7,1,21:18.6
8,1,21:18.6
9,1,21:18.6
10,1,21:18.6
-2,2,21:18.6
-1,2,21:18.6
0,2,21:18.6
3,2,21:18.6
4,2,21:18.6
6,2,21:18.6
7,2,21:18.6
8,2,21:18.6
9,2,21:18.6
10,2,21:18.6
-2,3,21:18.6
-1,3,21:18.6
0,3,21:18.6
1,3,21:18.6
3,3,21:18.6
4,3,21:18.6
5,3,21:18.6
6,3,21:18.6
7,3,21:18.6
8,3,21:18.6
-2,4,21:18.6
-1,4,21:18.6
0,4,21:18.6
1,4,21:18.6
2,4,21:18.6
3,4,21:18.6
4,4,21:18.6
5,4,21:18.6
6,4,21:18.6
7,4,21:18.6
8,4,21:18.6
9,4,21:18.6
-1,5,21:18.6
0,5,21:18.6
1,5,21:18.6
2,5,21:18.6
3,5,21:18.6
4,5,21:18.6
5,5,21:18.6
6,5,21:18.6
7,5,21:18.6
8,5,21:18.6
9,5,21:18.6
0,6,21:18.6
1,6,21:18.6
2,6,21:18.6
3,6,21:18.6
4,6,21:18.6
5,6,21:18.6
6,6,21:18.6
7,6,21:18.6
8,6,21:18.6
9,6,21:18.6
1,7,21:18.6
2,7,21:18.6
3,7,21:18.6
4,7,21:18.6
5,7,21:18.6
6,7,21:18.6
7,7,21:18.6
9,7,21:18.6
2,8,21:18.6
3,8,21:18.6
4,8,21:18.6
2,-5,22:18.6
3,-5,22:18.6
4,-5,22:18.6
5,-5,22:18.6
-1,-4,22:18.6
0,-4,22:18.6
1,-4,22:18.6
2,-4,22:18.6
3,-4,22:18.6
4,-4,22:18.6
5,-4,22:18.6
6,-4,22:18.6
-1,-3,22:18.6
0,-3,22:18.6
1,-3,22:18.6
2,-3,22:18.6
3,-3,22:18.6
4,-3,22:18.6
5,-3,22:18.6
6,-3,22:18.6
7,-3,22:18.6
-1,-2,22:18.6
0,-2,22:18.6
1,-2,22:18.6
2,-2,22:18.6
3,-2,22:18.6
4,-2,22:18.6
5,-2,22:18.6
6,-2,22:18.6
7,-2,22:18.6
8,-2,22:18.6
-1,-1,22:18.6
0,-1,22:18.6
1,-1,22:18.6
2,-1,22:18.6
3,-1,22:18.6
4,-1,22:18.6
5,-1,22:18.6
6,-1,22:18.6
8,-1,22:18.6
9,-1,22:18.6
-1,0,22:18.6
0,0,22:18.6
1,0,22:18.6
2,0,22:18.6
3,0,22:18.6
4,0,22:17.0
5,0,22:18.6
6,0,22:18.6
8,0,22:18.6
9,0,22:18.6
10,0,22:18.6
11,0,22:18.6
-2,1,22:18.6
-1,1,22:18.6
0,1,22:18.6
1,1,22:18.6
2,1,22:18.6
3,1,22:18.6
4,1,22:17.0
5,1,22:18.6
6,1,22:18.6
9,1,22:18.6
-1,2,22:18.6
1,2,22:18.6
2,2,22:18.6
3,2,22:18.6
4,2,22:18.6
5,2,22:18.6
6,2,22:18.6
9,2,22:18.6
-1,3,22:18.6
3,3,22:18.6
4,3,22:18.6
5,3,22:18.6
8,3,22:18.6
-3,4,22:18.6
-2,4,22:18.6
-1,4,22:18.6
0,4,22:18.6
8,4,22:18.6
9,4,22:18.6
0,5,22:18.6
1,5,22:18.6
8,5,22:18.6
1,6,22:18.6
2,6,22:18.6
5,6,22:18.6
6,6,22:18.6
7,6,22:18.6
8,6,22:18.6
9,6,22:18.6
2,7,22:18.6
3,7,22:18.6
4,7,22:18.6
5,7,22:18.6
9,7,22:18.6
3,8,22:18.6
2,9,22:18.6
3,9,22:18.6
5,-6,23:18.6
5,-5,23:18.6
-2,-4,23:18.6
-1,-4,23:18.6
2,-4,23:18.6
3,-4,23:18.6
4,-4,23:18.6
5,-4,23:18.6
-1,-3,23:18.6
0,-3,23:18.6
1,-3,23:18.6
2,-3,23:18.6
3,-3,23:18.6
4,-3,23:18.6
5,-3,23:18.6
6,-3,23:18.6
-1,-2,23:18.6
0,-2,23:18.6
6,-2,23:18.6
7,-2,23:18.6
-1,-1,23:18.6
0,-1,23:18.6
7,-1,23:18.6
8,-1,23:18.6
-1,0,23:18.6
0,0,23:18.6
7,0,23:18.6
8,0,23:18.6
10,0,23:18.6
-1,1,23:18.6
0,1,23:18.6
3,1,23:17.0
4,1,23:17.0
8,1,23:18.6
9,1,23:18.6
-1,2,23:18.6
0,2,23:18.6
3,2,23:17.0
4,2,23:17.0
8,2,23:18.6
-1,3,23:18.6
0,3,23:18.6
8,3,23:18.6
-2,4,23:18.6
-1,4,23:18.6
0,4,23:18.6
1,4,23:18.6
7,4,23:18.6
8,4,23:18.6
1,5,23:18.6
2,5,23:18.6
6,5,23:18.6
7,5,23:18.6
8,5,23:18.6
2,6,23:18.6
3,6,23:18.6
4,6,23:18.6
5,6,23:18.6
6,6,23:18.6
8,6,23:18.6
3,7,23:18.6
9,7,23:18.6
3,8,23:18.6
5,-5,24:18.6
5,-4,24:18.6
-1,-3,24:18.6
0,-3,24:18.6
2,-3,24:18.6
3,-3,24:18.6
4,-3,24:18.6
5,-3,24:18.6
0,-2,24:18.6
1,-2,24:18.6
2,-2,24:18.6
3,-2,24:18.6
4,-2,24:18.6
5,-2,24:18.6
6,-2,24:18.6
0,-1,24:18.6
1,-1,24:18.6
6,-1,24:18.6
7,-1,24:18.6
0,0,24:18.6
1,0,24:18.6
6,0,24:18.6
7,0,24:18.6
10,0,24:18.6
11,0,24:18.6
0,1,24:18.6
1,1,24:18.6
4,1,24:17.0
7,1,24:18.6
8,1,24:18.6
9,1,24:18.6
0,2,24:18.6
1,2,24:18.6
4,2,24:17.0
5,2,24:17.0
7,2,24:18.6
8,2,24:18.6
0,3,24:18.6
1,3,24:18.6
7,3,24:18.6
-1,4,24:18.6
1,4,24:18.6
2,4,24:18.6
7,4,24:18.6
2,5,24:18.6
3,5,24:18.6
4,5,24:18.6
5,5,24:18.6
6,5,24:18.6
7,5,24:18.6
3,6,24:18.6
4,6,24:18.6
8,6,24:18.6
9,6,24:18.6
3,7,24:18.6
9,7,24:18.6
3,8,24:18.6
5,-5,25:18.6
-2,-4,25:18.6
-1,-4,25:18.6
5,-4,25:18.6
-1,-3,25:18.6
0,-3,25:18.6
5,-3,25:18.6
0,-2,25:18.6
1,-2,25:18.6
3,-2,25:18.6
4,-2,25:18.6
5,-2,25:18.6
1,-1,25:18.6
2,-1,25:18.6
3,-1,25:18.6
4,-1,25:18.6
5,-1,25:18.6
6,-1,25:18.6
1,0,25:18.6
2,0,25:18.6
5,0,25:18.6
6,0,25:18.6
10,0,25:18.6
11,0,25:18.6
1,1,25:18.6
2,1,25:18.6
6,1,25:18.6
7,1,25:18.6
8,1,25:18.6
9,1,25:18.6
10,1,25:18.6
1,2,25:18.6
2,2,25:18.6
4,2,25:17.0
5,2,25:17.0
7,2,25:18.6
0,3,25:18.6
1,3,25:18.6
4,3,25:17.0
6,3,25:18.6
7,3,25:18.6
-3,4,25:18.6
-2,4,25:18.6
-1,4,25:18.6
0,4,25:18.6
2,4,25:18.6
3,4,25:18.6
5,4,25:18.6
6,4,25:18.6
7,4,25:18.6
3,5,25:18.6
4,5,25:18.6
5,5,25:18.6
7,5,25:18.6
3,6,25:18.6
8,6,25:18.6
3,7,25:18.6
3,8,25:18.6
3,9,25:18.6
7,9,25:18.6
5,-6,26:18.6
5,-5,26:18.6
-2,-4,26:18.6
5,-4,26:18.6
-1,-3,26:18.6
5,-3,26:18.6
0,-2,26:18.6
5,-2,26:18.6
1,-1,26:18.6
3,-1,26:18.6
4,-1,26:18.6
5,-1,26:18.6
2,0,26:18.6
3,0,26:18.6
4,0,26:18.6
5,0,26:18.6
2,1,26:18.6
5,1,26:18.6
6,1,26:18.6
7,1,26:18.6
8,1,26:18.6
9,1,26:18.6
2,2,26:18.6
4,2,26:17.0
5,2,26:17.0
6,2,26:18.6
7,2,26:18.6
0,3,26:18.6
1,3,26:18.6
3,3,26:18.6
4,3,26:17.0
5,3,26:17.0
6,3,26:18.6
-3,4,26:18.6
-2,4,26:18.6
-1,4,26:18.6
0,4,26:18.6
2,4,26:18.6
3,4,26:18.6
4,4,26:18.6
5,4,26:18.6
6,4,26:18.6
1,5,26:18.6
4,5,26:18.6
7,5,26:18.6
3,6,26:18.6
6,6,26:18.6
3,7,26:18.6
6,7,26:18.6
3,8,26:18.6
7,8,26:18.6
3,9,26:18.6
7,9,26:18.6
5,-6,27:18.6
5,-5,27:18.6
5,-4,27:18.6
-1,-3,27:18.6
5,-3,27:18.6
0,-2,27:18.6
5,-2,27:18.6
1,-1,27:18.6
5,-1,27:18.6
2,0,27:18.6
4,0,27:18.6
5,0,27:18.6
6,0,27:18.6
3,1,27:18.6
4,1,27:18.6
5,1,27:18.6
6,1,27:18.6
3,2,27:18.6
5,2,27:18.6
6,2,27:18.6
7,2,27:18.6
10,2,27:18.6
1,3,27:18.6
3,3,27:18.6
4,3,27:18.6
5,3,27:18.6
10,3,27:18.6
-1,4,27:18.6
0,4,27:18.6
2,4,27:18.6
3,4,27:18.6
4,4,27:18.6
5,4,27:18.6
6,4,27:18.6
1,5,27:18.6
4,5,27:18.6
6,5,27:18.6
3,6,27:18.6
6,6,27:18.6
6,7,27:18.6
7,7,27:18.6
7,8,27:18.6
7,9,27:18.6
5,-1,28:18.6
6,-1,28:18.6
7,-1,28:18.6
2,0,28:18.6
3,0,28:18.6
4,0,28:18.6
5,0,28:18.6
6,0,28:18.6
8,0,28:18.6
2,1,28:18.6
3,1,28:18.6
4,1,28:18.6
6,1,28:18.6
9,1,28:18.6
1,2,28:18.6
2,2,28:18.6
4,2,28:18.6
5,2,28:18.6
6,2,28:18.6
10,2,28:18.6
1,3,28:18.6
3,3,28:18.6
4,3,28:18.6
5,3,28:18.6
10,3,28:18.6
1,4,28:18.6
2,4,28:18.6
3,4,28:18.6
4,4,28:18.6
5,4,28:18.6
6,4,28:18.6
10,4,28:18.6
1,5,28:18.6
2,5,28:18.6
6,5,28:18.6
10,5,28:18.6
1,6,28:18.6
2,6,28:18.6
6,6,28:18.6
9,6,28:18.6
10,6,28:18.6
2,7,28:18.6
3,7,28:18.6
7,7,28:18.6
9,7,28:18.6
3,8,28:18.6
4,8,28:18.6
6,8,28:18.6
7,8,28:18.6
8,8,28:18.6
9,8,28:18.6
4,9,28:18.6
5,9,28:18.6
6,-1,29:18.6
7,-1,29:18.6
2,0,29:18.6
3,0,29:18.6
4,0,29:18.6
5,0,29:18.6
6,0,29:18.6
7,0,29:18.6
8,0,29:18.6
2,1,29:18.6
3,1,29:18.6
4,1,29:18.6
5,1,29:18.6
6,1,29:18.6
7,1,29:18.6
8,1,29:18.6
9,1,29:18.6
2,2,29:18.6
3,2,29:18.6
4,2,29:18.6
5,2,29:18.6
6,2,29:18.6
7,2,29:18.6
8,2,29:18.6
9,2,29:18.6
10,2,29:18.6
1,3,29:18.6
3,3,29:18.6
4,3,29:18.6
5,3,29:18.6
6,3,29:18.6
7,3,29:18.6
8,3,29:18.6
10,3,29:18.6
1,4,29:18.6
2,4,29:18.6
3,4,29:18.6
4,4,29:18.6
5,4,29:18.6
6,4,29:18.6
7,4,29:18.6
8,4,29:18.6
9,4,29:18.6
10,4,29:18.6
1,5,29:18.6
2,5,29:18.6
3,5,29:18.6
4,5,29:18.6
5,5,29:18.6
6,5,29:18.6
7,5,29:18.6
8,5,29:18.6
9,5,29:18.6
10,5,29:18.6
1,6,29:18.6
2,6,29:18.6
3,6,29:18.6
4,6,29:18.6
5,6,29:18.6
6,6,29:18.6
7,6,29:18.6
8,6,29:18.6
9,6,29:18.6
3,7,29:18.6
4,7,29:18.6
5,7,29:18.6
6,7,29:18.6
7,7,29:18.6
8,7,29:18.6
9,7,29:18.6
4,8,29:18.6
5,8,29:18.6
6,8,29:18.6
7,8,29:18.6
8,8,29:18.6
4,9,29:18.6
7,-1,30:18.6
2,0,30:18.6
4,0,30:18.6
5,0,30:18.6
6,0,30:18.6
7,0,30:18.6
2,1,30:18.6
3,1,30:18.6
4,1,30:18.6
5,1,30:18.6
6,1,30:18.6
7,1,30:18.6
8,1,30:18.6
2,2,30:18.6
3,2,30:18.6
6,2,30:18.6
8,2,30:18.6
9,2,30:18.6
3,3,30:18.6
6,3,30:18.6
10,3,30:18.6
2,4,30:18.6
3,4,30:18.6
4,4,30:18.6
5,4,30:17.0
6,4,30:17.0
9,4,30:18.6
1,5,30:18.6
2,5,30:18.6
9,5,30:18.6
2,6,30:18.6
3,6,30:18.6
4,6,30:18.6
8,6,30:18.6
9,6,30:18.6
3,7,30:18.6
4,7,30:18.6
5,7,30:18.6
6,7,30:18.6
7,7,30:18.6
8,7,30:18.6
9,7,30:18.6
5,8,30:18.6
4,9,30:18.6
7,0,31:18.6
2,1,31:18.6
3,1,31:18.6
4,1,31:18.6
5,1,31:18.6
6,1,31:18.6
7,1,31:18.6
3,2,31:18.6
4,2,31:18.6
5,2,31:18.6
7,2,31:18.6
8,2,31:18.6
3,3,31:18.6
8,3,31:18.6
10,3,31:18.6
11,3,31:18.6
3,4,31:18.6
8,4,31:18.6
9,4,31:18.6
2,5,31:18.6
3,5,31:18.6
6,5,31:17.0
8,5,31:18.6
3,6,31:18.6
4,6,31:18.6
5,6,31:18.6
6,6,31:18.6
7,6,31:18.6
8,6,31:18.6
5,7,31:18.6
6,7,31:18.6
8,7,31:18.6
9,7,31:18.6
5,8,31:18.6
9,8,31:18.6
10,8,31:18.6
7,-1,32:18.6
2,0,32:18.6
7,0,32:18.6
2,1,32:18.6
3,1,32:18.6
6,1,32:18.6
3,2,32:18.6
4,2,32:18.6
5,2,32:18.6
6,2,32:18.6
7,2,32:18.6
4,3,32:18.6
5,3,32:18.6
7,3,32:18.6
8,3,32:18.6
10,3,32:18.6
11,3,32:18.6
4,4,32:18.6
7,4,32:18.6
8,4,32:18.6
1,5,32:18.6
2,5,32:18.6
3,5,32:18.6
4,5,32:18.6
5,5,32:18.6
7,5,32:18.6
8,5,32:18.6
0,6,32:18.6
1,6,32:18.6
5,6,32:18.6
6,6,32:18.6
7,6,32:18.6
8,6,32:18.6
5,7,32:18.6
8,7,32:18.6
9,7,32:18.6
5,8,32:18.6
4,9,32:18.6
5,9,32:18.6
7,-1,33:18.6
7,0,33:18.6
2,1,33:18.6
3,1,33:18.6
6,1,33:18.6
7,1,33:18.6
3,2,33:18.6
4,2,33:18.6
6,2,33:18.6
4,3,33:18.6
5,3,33:18.6
6,3,33:18.6
7,3,33:18.6
8,3,33:18.6
4,4,33:18.6
5,4,33:18.6
7,4,33:18.6
8,4,33:18.6
2,5,33:18.6
3,5,33:18.6
4,5,33:18.6
5,5,33:18.6
6,5,33:18.6
7,5,33:18.6
1,6,33:18.6
5,6,33:18.6
7,6,33:18.6
5,7,33:18.6
5,8,33:18.6
5,9,33:18.6
6,2,34:18.6
5,3,34:18.6
6,3,34:18.6
5,4,34:18.6
6,4,34:18.6
7,4,34:18.6
4,5,34:18.6
5,5,34:18.6
6,5,34:18.6
5,6,34:18.6
