[META]
version=2.0
spawnOnBlockType=2
spawnSunlight=True
spawnDarkness=True
spawnWater=False
spawnLava=False
underFill=False
randomRotation=True
dig=True
tree=False
branch=False
needsFoundation=True
rarity=100
collisionPercentage=20
spawnElevationMin=0
spawnElevationMax=200
spawnInBiome=Custom
[DATA]
1,2,-8:17.12
1,3,-8:17.12
2,0,-7:17.12
1,1,-7:17.12
-1,2,-7:17.12
0,2,-7:17.12
1,2,-7:17.12
3,3,-7:17.12
1,4,-7:17.12
1,-2,-6:17.12
3,-2,-6:17.12
0,-1,-6:17.12
2,-1,-6:17.12
3,-1,-6:17.12
4,-1,-6:17.12
-2,0,-6:17.12
0,0,-6:17.12
1,0,-6:17.12
2,0,-6:17.12
3,0,-6:17.12
4,0,-6:17.12
-2,1,-6:17.12
-1,1,-6:17.12
0,1,-6:17.12
3,1,-6:17.12
4,1,-6:17.12
0,2,-6:17.12
1,2,-6:17.12
2,2,-6:17.12
3,2,-6:17.12
4,2,-6:17.12
-1,3,-6:17.12
0,3,-6:17.12
1,3,-6:17.12
2,3,-6:17.12
3,3,-6:17.12
4,3,-6:17.12
-2,4,-6:17.12
0,4,-6:17.12
2,4,-6:17.12
-3,5,-6:17.12
-2,5,-6:17.12
0,5,-6:17.12
1,5,-6:17.12
-1,6,-6:17.12
1,6,-6:17.12
0,-3,-5:17.12
1,-3,-5:17.12
5,-3,-5:17.12
-2,-2,-5:17.12
0,-2,-5:17.12
6,-2,-5:17.12
-3,-1,-5:17.12
-2,-1,-5:17.12
0,-1,-5:17.12
1,-1,-5:17.12
2,-1,-5:17.12
3,-1,-5:17.12
4,-1,-5:17.12
5,-1,-5:17.12
-4,0,-5:17.12
-2,0,-5:17.12
-1,0,-5:17.12
0,0,-5:17.12
1,0,-5:17.12
3,0,-5:17.12
4,0,-5:17.12
5,0,-5:17.12
-3,1,-5:17.12
-2,1,-5:17.12
-1,1,-5:17.12
0,1,-5:17.12
1,1,-5:17.12
2,1,-5:17.12
3,1,-5:17.12
4,1,-5:17.12
6,1,-5:17.12
-1,2,-5:17.12
0,2,-5:17.12
1,2,-5:17.12
2,2,-5:17.12
3,2,-5:17.12
4,2,-5:17.12
5,2,-5:17.12
6,2,-5:17.12
-3,3,-5:17.12
-2,3,-5:17.12
0,3,-5:17.12
2,3,-5:17.12
3,3,-5:17.12
4,3,-5:17.12
5,3,-5:17.12
-1,4,-5:17.12
0,4,-5:17.12
1,4,-5:17.12
2,4,-5:17.12
4,4,-5:17.12
-1,5,-5:17.12
0,5,-5:17.12
1,5,-5:17.12
2,5,-5:17.12
4,5,-5:17.12
-1,6,-5:17.12
0,6,-5:17.12
0,7,-5:17.12
-1,-3,-4:17.12
0,-3,-4:17.12
2,-3,-4:17.12
3,-3,-4:17.12
5,-3,-4:17.12
-2,-2,-4:17.12
-1,-2,-4:17.12
0,-2,-4:17.12
1,-2,-4:17.12
2,-2,-4:17.12
3,-2,-4:17.12
4,-2,-4:17.12
5,-2,-4:17.12
-3,-1,-4:17.12
-2,-1,-4:17.12
-1,-1,-4:17.12
0,-1,-4:17.12
1,-1,-4:17.12
2,-1,-4:17.12
3,-1,-4:17.12
4,-1,-4:17.12
5,-1,-4:17.12
6,-1,-4:17.12
-2,0,-4:17.12
-1,0,-4:17.12
0,0,-4:17.12
1,0,-4:17.12
2,0,-4:17.12
3,0,-4:17.12
4,0,-4:17.12
6,0,-4:17.12
-4,1,-4:17.12
-3,1,-4:17.12
-2,1,-4:17.12
-1,1,-4:17.12
0,1,-4:17.12
1,1,-4:17.12
2,1,-4:17.12
3,1,-4:17.12
4,1,-4:17.12
5,1,-4:17.12
6,1,-4:17.12
-3,2,-4:17.12
-2,2,-4:17.12
-1,2,-4:17.12
0,2,-4:17.12
1,2,-4:17.12
2,2,-4:17.12
3,2,-4:17.12
5,2,-4:17.12
6,2,-4:17.12
-3,3,-4:17.12
-2,3,-4:17.12
-1,3,-4:17.12
0,3,-4:17.12
1,3,-4:17.12
2,3,-4:17.12
3,3,-4:17.12
4,3,-4:17.12
5,3,-4:17.12
-3,4,-4:17.12
-2,4,-4:17.12
-1,4,-4:17.12
0,4,-4:17.12
1,4,-4:17.12
2,4,-4:17.12
3,4,-4:17.12
4,4,-4:17.12
-2,5,-4:17.12
-1,5,-4:17.12
0,5,-4:17.12
1,5,-4:17.12
2,5,-4:17.12
3,5,-4:17.12
4,5,-4:17.12
-3,6,-4:17.12
-2,6,-4:17.12
-1,6,-4:17.12
0,6,-4:17.12
1,6,-4:17.12
2,6,-4:17.12
3,6,-4:17.12
-2,7,-4:17.12
-1,7,-4:17.12
0,7,-4:17.12
1,7,-4:17.12
2,-3,-3:17.12
4,-3,-3:17.12
-2,-2,-3:17.12
-1,-2,-3:17.12
1,-2,-3:17.12
2,-2,-3:17.12
4,-2,-3:17.12
5,-2,-3:17.12
-4,-1,-3:17.12
-2,-1,-3:17.12
-1,-1,-3:17.12
0,-1,-3:17.12
1,-1,-3:17.12
2,-1,-3:17.12
3,-1,-3:17.12
4,-1,-3:17.12
5,-1,-3:17.12
-4,0,-3:17.12
-3,0,-3:17.12
-2,0,-3:17.12
-1,0,-3:17.12
0,0,-3:17.12
2,0,-3:17.12
5,0,-3:17.12
6,0,-3:17.12
-4,1,-3:17.12
-3,1,-3:17.12
-2,1,-3:17.12
-1,1,-3:17.12
0,1,-3:17.12
1,1,-3:17.12
4,1,-3:17.12
5,1,-3:17.12
-4,2,-3:17.12
-2,2,-3:17.12
0,2,-3:17.12
1,2,-3:17.12
2,2,-3:17.12
3,2,-3:17.12
4,2,-3:17.12
5,2,-3:17.12
6,2,-3:17.12
-2,3,-3:17.12
5,3,-3:17.12
6,3,-3:17.12
-4,4,-3:17.12
-3,4,-3:17.12
-1,4,-3:17.12
0,4,-3:17.12
1,4,-3:17.12
2,4,-3:17.12
3,4,-3:17.12
4,4,-3:17.12
5,4,-3:17.12
-3,5,-3:17.12
-2,5,-3:17.12
-1,5,-3:17.12
0,5,-3:17.12
1,5,-3:17.12
2,5,-3:17.12
3,5,-3:17.12
4,5,-3:17.12
-3,6,-3:17.12
-2,6,-3:17.12
-1,6,-3:17.12
0,6,-3:17.12
1,6,-3:17.12
2,6,-3:17.12
3,6,-3:17.12
-2,7,-3:17.12
-1,7,-3:17.12
1,7,-3:17.12
-1,-3,-2:17.12
0,-3,-2:17.12
1,-3,-2:17.12
2,-3,-2:17.12
3,-3,-2:17.12
-4,-2,-2:17.12
-3,-2,-2:17.12
-2,-2,-2:17.12
0,-2,-2:17.12
3,-2,-2:17.12
4,-2,-2:17.12
-5,-1,-2:17.12
-4,-1,-2:17.12
-3,-1,-2:17.12
-2,-1,-2:17.12
-1,-1,-2:17.12
0,-1,-2:17.12
1,-1,-2:17.12
2,-1,-2:17.12
3,-1,-2:17.12
4,-1,-2:17.12
5,-1,-2:17.12
6,-1,-2:17.12
-5,0,-2:17.12
-3,0,-2:17.12
-1,0,-2:17.12
0,0,-2:17.12
2,0,-2:17.12
3,0,-2:17.12
4,0,-2:17.12
6,0,-2:17.12
-5,1,-2:17.12
-1,1,-2:17.12
0,1,-2:17.12
2,1,-2:17.12
6,1,-2:17.12
-5,2,-2:17.12
-4,2,-2:17.12
-3,2,-2:17.12
-2,2,-2:17.12
-1,2,-2:17.12
0,2,-2:17.12
1,2,-2:17.12
2,2,-2:17.12
3,2,-2:17.12
4,2,-2:17.12
5,2,-2:17.12
6,2,-2:17.12
-5,3,-2:17.12
-4,3,-2:17.12
-2,3,-2:17.12
-1,3,-2:17.12
1,3,-2:17.12
3,3,-2:17.12
6,3,-2:17.12
-4,4,-2:17.12
-2,4,-2:17.12
0,4,-2:17.12
1,4,-2:17.12
2,4,-2:17.12
5,4,-2:17.12
6,4,-2:17.12
-4,5,-2:17.12
-3,5,-2:17.12
-2,5,-2:17.12
-1,5,-2:17.12
0,5,-2:17.12
4,5,-2:17.12
5,5,-2:17.12
-3,6,-2:17.12
-2,6,-2:17.12
3,6,-2:17.12
4,6,-2:17.12
-2,7,-2:17.12
-1,7,-2:17.12
0,7,-2:17.12
1,7,-2:17.12
2,7,-2:17.12
-1,8,-2:17.12
0,8,-2:17.12
1,8,-2:17.12
-1,-3,-1:17.12
0,-3,-1:17.12
1,-3,-1:17.12
2,-3,-1:17.12
-3,-2,-1:17.12
-2,-2,-1:17.12
-1,-2,-1:17.12
3,-2,-1:17.12
4,-2,-1:17.12
-5,-1,-1:17.12
-4,-1,-1:17.12
-1,-1,-1:17.12
4,-1,-1:17.12
5,-1,-1:17.12
-4,0,-1:17.12
-3,0,-1:17.12
-2,0,-1:17.12
6,0,-1:17.12
-4,1,-1:17.12
6,1,-1:17.12
-4,2,-1:17.12
6,2,-1:17.12
-4,3,-1:17.12
5,3,-1:17.12
6,3,-1:17.12
-4,4,-1:17.12
5,4,-1:17.12
-3,5,-1:17.12
4,5,-1:17.12
5,5,-1:17.12
-3,6,-1:17.12
-2,6,-1:17.12
2,6,-1:17.12
3,6,-1:17.12
-1,7,-1:17.12
0,7,-1:17.12
1,7,-1:17.12
2,7,-1:17.12
-1,8,-1:17.12
0,8,-1:17.12
1,8,-1:17.12
1,-3,0:17.12
2,-3,0:17.12
-3,-2,0:17.12
-2,-2,0:17.12
-1,-2,0:17.12
0,-2,0:17.12
1,-2,0:17.12
2,-2,0:17.12
3,-2,0:17.12
-4,-1,0:17.12
-3,-1,0:17.12
4,-1,0:17.12
5,-1,0:17.12
-4,0,0:17.12
5,0,0:17.12
6,0,0:17.12
-4,1,0:17.12
6,1,0:17.12
-4,2,0:17.12
6,2,0:17.12
-4,3,0:17.12
5,3,0:17.12
-4,4,0:17.12
-3,4,0:17.12
4,4,0:17.12
5,4,0:17.12
-3,5,0:17.12
-2,5,0:17.12
3,5,0:17.12
4,5,0:17.12
-2,6,0:17.12
-1,6,0:17.12
2,6,0:17.12
3,6,0:17.12
-1,7,0:17.12
0,7,0:17.12
1,7,0:17.12
2,7,0:17.12
-1,8,0:17.12
0,8,0:17.12
-2,-2,1:17.12
-1,-2,1:17.12
0,-2,1:17.12
1,-2,1:17.12
2,-2,1:17.12
3,-2,1:17.12
-4,-1,1:17.12
-3,-1,1:17.12
-2,-1,1:17.12
3,-1,1:17.12
4,-1,1:17.12
5,-1,1:17.12
-4,0,1:17.12
5,0,1:17.12
6,0,1:17.12
-4,1,1:17.12
-3,1,1:17.12
6,1,1:17.12
-4,2,1:17.12
-3,2,1:17.12
5,2,1:17.12
6,2,1:17.12
-4,3,1:17.12
-3,3,1:17.12
5,3,1:17.12
-3,4,1:17.12
4,4,1:17.12
-3,5,1:17.12
-2,5,1:17.12
3,5,1:17.12
4,5,1:17.12
-2,6,1:17.12
-1,6,1:17.12
1,6,1:17.12
2,6,1:17.12
3,6,1:17.12
-1,7,1:17.12
0,7,1:17.12
1,7,1:17.12
0,-2,2:17.12
1,-2,2:17.12
2,-2,2:17.12
-3,-1,2:17.12
-2,-1,2:17.12
-1,-1,2:17.12
2,-1,2:17.12
3,-1,2:17.12
4,-1,2:17.12
-3,0,2:17.12
4,0,2:17.12
5,0,2:17.12
6,0,2:17.12
-3,1,2:17.12
5,1,2:17.12
6,1,2:17.12
-3,2,2:17.12
5,2,2:17.12
-3,3,2:17.12
4,3,2:17.12
-3,4,2:17.12
-2,4,2:17.12
4,4,2:17.12
-2,5,2:17.12
3,5,2:17.12
4,5,2:17.12
-1,6,2:17.12
0,6,2:17.12
1,6,2:17.12
2,6,2:17.12
1,-2,3:17.12
-3,-1,3:17.12
-2,-1,3:17.12
-1,-1,3:17.12
0,-1,3:17.12
2,-1,3:17.12
3,-1,3:17.12
-3,0,3:17.12
4,0,3:17.12
5,0,3:17.12
-3,1,3:17.12
5,1,3:17.12
-3,2,3:17.12
4,2,3:17.12
5,2,3:17.12
-3,3,3:17.12
4,3,3:17.12
-2,4,3:17.12
4,4,3:17.12
-2,5,3:17.12
-1,5,3:17.12
2,5,3:17.12
3,5,3:17.12
-1,6,3:17.12
0,6,3:17.12
1,6,3:17.12
2,6,3:17.12
1,-2,4:17.12
-2,-1,4:17.12
-1,-1,4:17.12
0,-1,4:17.12
2,-1,4:17.12
3,-1,4:17.12
-2,0,4:17.12
3,0,4:17.12
4,0,4:17.12
-3,1,4:17.12
4,1,4:17.12
5,1,4:17.12
-3,2,4:17.12
4,2,4:17.12
-3,3,4:17.12
-2,3,4:17.12
4,3,4:17.12
-2,4,4:17.12
-1,4,4:17.12
3,4,4:17.12
4,4,4:17.12
-1,5,4:17.12
1,5,4:17.12
2,5,4:17.12
3,5,4:17.12
0,6,4:17.12
1,6,4:17.12
1,-2,5:17.12
-2,-1,5:17.12
-1,-1,5:17.12
0,-1,5:17.12
2,-1,5:17.12
3,-1,5:17.12
-2,0,5:17.12
3,0,5:17.12
4,0,5:17.12
-3,1,5:17.12
-2,1,5:17.12
4,1,5:17.12
-3,2,5:17.12
4,2,5:17.12
-3,3,5:17.12
-2,3,5:17.12
4,3,5:17.12
-2,4,5:17.12
-1,4,5:17.12
3,4,5:17.12
4,4,5:17.12
-1,5,5:17.12
0,5,5:17.12
1,5,5:17.12
2,5,5:17.12
0,6,5:17.12
1,-2,6:17.12
2,-2,6:17.12
-2,-1,6:17.12
-1,-1,6:17.12
0,-1,6:17.12
2,-1,6:17.12
3,-1,6:17.12
-2,0,6:17.12
3,0,6:17.12
4,0,6:17.12
-2,1,6:17.12
4,1,6:17.12
-3,2,6:17.12
-2,2,6:17.12
4,2,6:17.12
-2,3,6:17.12
3,3,6:17.12
4,3,6:17.12
-1,4,6:17.12
2,4,6:17.12
3,4,6:17.12
0,5,6:17.12
1,5,6:17.12
2,5,6:17.12
0,-2,7:17.12
1,-2,7:17.12
2,-2,7:17.12
-2,-1,7:17.12
-1,-1,7:17.12
0,-1,7:17.12
2,-1,7:17.12
3,-1,7:17.12
-2,0,7:17.12
3,0,7:17.12
4,0,7:17.12
-2,1,7:17.12
4,1,7:17.12
-2,2,7:17.12
4,2,7:17.12
-2,3,7:17.12
-1,3,7:17.12
3,3,7:17.12
-1,4,7:17.12
2,4,7:17.12
3,4,7:17.12
0,5,7:17.12
1,5,7:17.12
0,-2,8:17.12
1,-2,8:17.12
2,-2,8:17.12
-2,-1,8:17.12
-1,-1,8:17.12
0,-1,8:17.12
2,-1,8:17.12
3,-1,8:17.12
-2,0,8:17.12
3,0,8:17.12
4,0,8:17.12
-2,1,8:17.12
4,1,8:17.12
-2,2,8:17.12
3,2,8:17.12
-2,3,8:17.12
-1,3,8:17.12
3,3,8:17.12
-1,4,8:17.12
0,4,8:17.12
1,4,8:17.12
2,4,8:17.12
3,4,8:17.12
0,5,8:17.12
1,5,8:17.12
0,-2,9:17.12
1,-2,9:17.12
2,-2,9:17.12
-2,-1,9:17.12
-1,-1,9:17.12
0,-1,9:17.12
2,-1,9:17.12
3,-1,9:17.12
-2,0,9:17.12
3,0,9:17.12
4,0,9:17.12
-2,1,9:17.12
3,1,9:17.12
4,1,9:17.12
-2,2,9:17.12
3,2,9:17.12
-2,3,9:17.12
-1,3,9:17.12
3,3,9:17.12
-1,4,9:17.12
0,4,9:17.12
1,4,9:17.12
2,4,9:17.12
0,5,9:17.12
0,-2,10:17.12
1,-2,10:17.12
2,-2,10:17.12
-1,-1,10:17.12
0,-1,10:17.12
2,-1,10:17.12
3,-1,10:17.12
-2,0,10:17.12
3,0,10:17.12
4,0,10:17.12
-2,1,10:17.12
3,1,10:17.12
-2,2,10:17.12
3,2,10:17.12
-1,3,10:17.12
2,3,10:17.12
3,3,10:17.12
0,4,10:17.12
1,4,10:17.12
2,4,10:17.12
0,-2,11:17.12
1,-2,11:17.12
2,-2,11:17.12
-1,-1,11:17.12
0,-1,11:17.12
2,-1,11:17.12
3,-1,11:17.12
-2,0,11:17.12
-1,0,11:17.12
3,0,11:17.12
-2,1,11:17.12
3,1,11:17.12
-2,2,11:17.12
-1,2,11:17.12
3,2,11:17.12
-1,3,11:17.12
2,3,11:17.12
3,3,11:17.12
0,4,11:17.12
1,4,11:17.12
0,-2,12:17.12
1,-2,12:17.12
2,-2,12:17.12
-1,-1,12:17.12
0,-1,12:17.12
2,-1,12:17.12
3,-1,12:17.12
-1,0,12:17.12
3,0,12:17.12
-2,1,12:17.12
3,1,12:17.12
-2,2,12:17.12
-1,2,12:17.12
3,2,12:17.12
-1,3,12:17.12
0,3,12:17.12
2,3,12:17.12
3,3,12:17.12
0,4,12:17.12
1,4,12:17.12
0,-2,13:17.12
1,-2,13:17.12
2,-2,13:17.12
-1,-1,13:17.12
2,-1,13:17.12
3,-1,13:17.12
-1,0,13:17.12
3,0,13:17.12
-2,1,13:17.12
3,1,13:17.12
-3,2,13:18.12
-2,2,13:17.12
-1,2,13:17.12
3,2,13:17.12
-8,3,13:18.4
-7,3,13:18.4
-1,3,13:17.12
0,3,13:17.12
1,3,13:17.12
2,3,13:17.12
3,3,13:17.12
0,4,13:17.12
1,4,13:17.12
2,-4,14:18.12
1,-3,14:18.12
-1,-2,14:17.12
0,-2,14:17.12
1,-2,14:17.12
2,-2,14:17.12
-1,-1,14:17.12
3,-1,14:17.12
-1,0,14:17.12
3,0,14:17.12
-2,1,14:17.12
-1,1,14:17.12
3,1,14:17.12
-4,2,14:18.12
-3,2,14:18.12
-2,2,14:18.12
-1,2,14:17.12
3,2,14:17.12
-9,3,14:18.4
-8,3,14:18.4
-7,3,14:18.4
-6,3,14:18.12
-1,3,14:17.12
0,3,14:17.12
1,3,14:17.12
2,3,14:17.12
4,3,14:18.12
-11,4,14:18.4
-10,4,14:18.4
-9,4,14:18.4
0,4,14:17.12
1,4,14:17.12
-13,-12,15:18.6
-12,-12,15:18.6
-13,-11,15:18.6
2,-9,15:18.4
2,-8,15:18.4
2,-7,15:18.4
2,-6,15:18.12
2,-5,15:18.12
1,-3,15:18.12
-1,-2,15:17.12
0,-2,15:17.12
1,-2,15:17.12
2,-2,15:17.12
-1,-1,15:17.12
3,-1,15:17.12
-1,0,15:17.12
3,0,15:17.12
-2,1,15:18.12
-1,1,15:17.12
3,1,15:17.12
-6,2,15:18.12
-5,2,15:18.12
-4,2,15:18.12
-1,2,15:17.12
2,2,15:17.12
3,2,15:17.12
4,2,15:18.12
-9,3,15:18.4
-8,3,15:18.4
-7,3,15:18.4
-6,3,15:18.12
0,3,15:17.12
1,3,15:17.12
2,3,15:17.12
4,3,15:18.12
5,3,15:18.12
-12,4,15:18.4
-11,4,15:18.4
-10,4,15:18.4
-12,5,15:18.4
-11,-13,16:18.6
-10,-13,16:18.6
-9,-13,16:18.6
3,-13,16:18.4
-13,-12,16:18.6
-12,-12,16:18.6
-11,-12,16:18.6
3,-12,16:18.4
-13,-11,16:18.6
2,-11,16:18.4
-13,-10,16:18.6
2,-10,16:18.4
-14,-9,16:18.6
2,-9,16:18.4
-14,-8,16:18.6
2,-8,16:18.4
2,-7,16:18.4
2,-6,16:18.12
2,-5,16:18.12
2,-4,16:18.12
1,-3,16:18.12
-1,-2,16:17.0
0,-2,16:17.0
1,-2,16:17.12
2,-2,16:17.12
3,-2,16:17.12
-1,-1,16:17.0
3,-1,16:17.12
-1,0,16:17.12
3,0,16:17.12
-3,1,16:18.12
-2,1,16:18.12
-1,1,16:17.12
3,1,16:17.12
-6,2,16:18.12
-5,2,16:18.12
-4,2,16:18.12
-1,2,16:17.12
0,2,16:17.12
2,2,16:17.12
3,2,16:17.12
4,2,16:18.12
-9,3,16:18.4
-8,3,16:18.4
-7,3,16:18.4
0,3,16:17.12
1,3,16:17.12
2,3,16:17.12
5,3,16:18.12
-12,4,16:18.4
-11,4,16:18.4
-10,4,16:18.4
-14,5,16:18.4
-13,5,16:18.4
11,7,16:18.4
15,7,16:18.6
11,8,16:18.4
15,8,16:18.6
13,9,16:18.4
15,9,16:18.6
13,10,16:18.4
14,10,16:18.4
12,11,16:18.6
13,11,16:18.6
14,11,16:18.6
11,12,16:18.6
12,12,16:18.6
5,14,16:18.6
-5,15,16:18.6
-4,15,16:18.6
-3,16,16:18.6
-1,16,16:18.6
0,16,16:18.6
1,16,16:18.6
-2,17,16:18.6
-1,17,16:18.6
0,-17,17:18.6
3,-16,17:18.4
3,-15,17:18.4
-8,-14,17:18.6
-7,-14,17:18.6
-6,-14,17:18.6
3,-14,17:18.4
-10,-13,17:18.6
-9,-13,17:18.6
-8,-13,17:18.6
3,-13,17:18.4
-13,-12,17:18.6
-12,-12,17:18.6
-11,-12,17:18.6
3,-12,17:18.4
-13,-11,17:18.6
2,-11,17:18.4
-13,-10,17:18.6
2,-10,17:18.4
-13,-9,17:18.6
2,-9,17:18.4
15,-9,17:18.6
-14,-8,17:18.6
-13,-8,17:18.6
2,-8,17:18.4
16,-8,17:18.6
-14,-7,17:18.6
2,-7,17:18.4
17,-7,17:18.6
-14,-6,17:18.6
2,-6,17:18.12
17,-6,17:18.6
-14,-5,17:18.6
2,-5,17:18.12
-14,-4,17:18.6
2,-4,17:18.12
17,-4,17:18.6
1,-3,17:17.0
2,-3,17:17.0
-1,-2,17:17.0
0,-2,17:17.0
1,-2,17:17.0
2,-2,17:17.0
3,-2,17:17.0
-1,-1,17:17.0
3,-1,17:17.0
-1,0,17:17.0
3,0,17:17.12
16,0,17:18.6
-4,1,17:18.12
-3,1,17:18.12
-2,1,17:18.12
-1,1,17:17.0
3,1,17:17.12
-15,2,17:18.6
-6,2,17:18.12
-5,2,17:18.12
-4,2,17:18.12
-1,2,17:17.0
0,2,17:17.0
2,2,17:17.12
3,2,17:17.12
4,2,17:18.12
-16,3,17:18.6
-10,3,17:18.4
-9,3,17:18.4
-8,3,17:18.4
0,3,17:17.0
1,3,17:17.12
5,3,17:18.12
6,3,17:18.12
-16,4,17:18.6
-13,4,17:18.4
-12,4,17:18.4
-11,4,17:18.4
-10,4,17:18.4
7,4,17:18.12
8,4,17:18.4
-16,5,17:18.6
-15,5,17:18.4
-14,5,17:18.4
-13,5,17:18.4
8,5,17:18.4
9,5,17:18.4
-16,6,17:18.6
9,6,17:18.4
10,6,17:18.4
15,6,17:18.6
-15,7,17:18.6
-14,7,17:18.6
10,7,17:18.4
11,7,17:18.4
15,7,17:18.6
-14,8,17:18.6
-13,8,17:18.6
11,8,17:18.4
12,8,17:18.4
14,8,17:18.6
15,8,17:18.6
12,9,17:18.4
13,9,17:18.4
14,9,17:18.6
13,10,17:18.4
14,10,17:18.6
12,11,17:18.6
13,11,17:18.6
14,11,17:18.6
15,11,17:18.6
-8,12,17:18.6
9,12,17:18.6
10,12,17:18.6
11,12,17:18.6
-7,13,17:18.6
-6,13,17:18.6
6,13,17:18.6
7,13,17:18.6
8,13,17:18.6
-6,14,17:18.6
-5,14,17:18.6
4,14,17:18.6
5,14,17:18.6
-5,15,17:18.6
-4,15,17:18.6
1,15,17:18.6
2,15,17:18.6
3,15,17:18.6
-4,16,17:18.6
-3,16,17:18.6
-2,16,17:18.6
-1,16,17:18.6
0,16,17:18.6
1,16,17:18.6
-2,17,17:18.6
-2,18,17:18.6
-3,19,17:18.6
-3,20,17:18.6
-3,21,17:18.6
-3,22,17:18.6
2,-18,18:18.6
3,-18,18:18.6
4,-18,18:18.6
0,-17,18:18.6
1,-17,18:18.6
2,-17,18:18.6
3,-17,18:18.4
4,-17,18:18.6
5,-17,18:18.6
-2,-16,18:18.6
-1,-16,18:18.6
3,-16,18:18.4
6,-16,18:18.6
-5,-15,18:18.6
-4,-15,18:18.6
-3,-15,18:18.6
3,-15,18:18.4
-15,-14,18:18.6
-7,-14,18:18.6
-6,-14,18:18.6
-5,-14,18:18.6
3,-14,18:18.4
-14,-13,18:18.6
-9,-13,18:18.6
-8,-13,18:18.6
-7,-13,18:18.6
3,-13,18:18.4
-14,-12,18:18.6
-13,-12,18:18.6
-12,-12,18:18.6
-11,-12,18:18.6
-10,-12,18:18.6
3,-12,18:18.4
11,-12,18:18.6
-13,-11,18:18.6
-12,-11,18:18.6
2,-11,18:18.4
12,-11,18:18.6
-13,-10,18:18.6
2,-10,18:18.4
13,-10,18:18.6
-13,-9,18:18.6
2,-9,18:18.4
14,-9,18:18.6
15,-9,18:18.6
-13,-8,18:18.6
2,-8,18:18.4
15,-8,18:18.6
16,-8,18:18.6
-14,-7,18:18.6
-13,-7,18:18.6
2,-7,18:18.4
16,-7,18:18.6
17,-7,18:18.6
-14,-6,18:18.6
2,-6,18:18.12
17,-6,18:18.6
-14,-5,18:18.6
2,-5,18:18.12
17,-5,18:18.6
-14,-4,18:18.6
2,-4,18:18.12
16,-4,18:18.6
17,-4,18:18.6
-14,-3,18:18.6
0,-3,18:17.0
1,-3,18:17.0
2,-3,18:17.0
16,-3,18:18.6
-15,-2,18:18.6
-14,-2,18:18.6
-1,-2,18:17.0
0,-2,18:17.0
2,-2,18:17.0
3,-2,18:17.0
16,-2,18:18.6
-15,-1,18:18.6
-1,-1,18:17.0
3,-1,18:17.0
16,-1,18:18.6
-1,0,18:17.0
3,0,18:17.0
16,0,18:18.6
-15,1,18:18.6
-4,1,18:18.12
-3,1,18:18.12
-2,1,18:18.12
-1,1,18:17.0
3,1,18:17.0
15,1,18:18.6
16,1,18:18.6
-15,2,18:18.6
-7,2,18:18.4
-6,2,18:18.12
-5,2,18:18.12
0,2,18:17.0
1,2,18:17.0
2,2,18:17.0
4,2,18:18.12
5,2,18:18.12
15,2,18:18.6
-15,3,18:18.6
-10,3,18:18.4
-9,3,18:18.4
-8,3,18:18.4
0,3,18:17.0
1,3,18:17.0
5,3,18:18.12
6,3,18:18.12
15,3,18:18.6
-16,4,18:18.6
-15,4,18:18.6
-13,4,18:18.4
-12,4,18:18.4
-11,4,18:18.4
7,4,18:18.12
15,4,18:18.6
-16,5,18:18.6
-15,5,18:18.4
-14,5,18:18.4
8,5,18:18.4
9,5,18:18.4
15,5,18:18.6
-16,6,18:18.6
-15,6,18:18.6
9,6,18:18.4
10,6,18:18.4
15,6,18:18.6
-15,7,18:18.6
-14,7,18:18.6
10,7,18:18.4
11,7,18:18.4
14,7,18:18.6
-13,8,18:18.6
11,8,18:18.4
12,8,18:18.4
14,8,18:18.6
-12,9,18:18.6
-11,9,18:18.6
12,9,18:18.4
13,9,18:18.4
14,9,18:18.6
-11,10,18:18.6
-10,10,18:18.6
13,10,18:18.4
14,10,18:18.6
-9,11,18:18.6
-8,11,18:18.6
11,11,18:18.6
12,11,18:18.6
13,11,18:18.6
14,11,18:18.6
15,11,18:18.6
-8,12,18:18.6
-7,12,18:18.6
8,12,18:18.6
9,12,18:18.6
10,12,18:18.6
15,12,18:18.6
-7,13,18:18.6
-6,13,18:18.6
6,13,18:18.6
7,13,18:18.6
8,13,18:18.6
16,13,18:18.6
-6,14,18:18.6
-5,14,18:18.6
3,14,18:18.6
4,14,18:18.6
5,14,18:18.6
-4,15,18:18.6
-3,15,18:18.6
0,15,18:18.6
1,15,18:18.6
2,15,18:18.6
3,15,18:18.6
-3,16,18:18.6
-2,16,18:18.6
-1,16,18:18.6
0,16,18:18.6
-2,17,18:18.6
-2,18,18:18.6
-3,19,18:18.6
-3,20,18:18.6
-3,21,18:18.6
-3,22,18:18.6
3,-19,19:18.6
3,-18,19:18.6
1,-17,19:18.6
2,-17,19:18.6
3,-17,19:18.4
4,-17,19:18.6
5,-17,19:18.6
-1,-16,19:18.6
0,-16,19:18.6
3,-16,19:18.4
5,-16,19:18.6
6,-16,19:18.6
-4,-15,19:18.6
-3,-15,19:18.6
-2,-15,19:18.6
3,-15,19:18.4
6,-15,19:18.6
7,-15,19:18.6
-15,-14,19:18.6
-6,-14,19:18.6
-5,-14,19:18.6
-4,-14,19:18.6
3,-14,19:18.4
7,-14,19:18.6
8,-14,19:18.6
-14,-13,19:18.6
-9,-13,19:18.6
-8,-13,19:18.6
-7,-13,19:18.6
3,-13,19:18.4
8,-13,19:18.6
9,-13,19:18.6
-13,-12,19:18.6
-11,-12,19:18.6
-10,-12,19:18.6
-9,-12,19:18.6
3,-12,19:18.4
10,-12,19:18.6
11,-12,19:18.6
-13,-11,19:18.6
-12,-11,19:18.6
2,-11,19:18.4
11,-11,19:18.6
12,-11,19:18.6
-13,-10,19:18.6
2,-10,19:18.4
12,-10,19:18.6
13,-10,19:18.6
-13,-9,19:18.6
2,-9,19:18.4
13,-9,19:18.6
14,-9,19:18.6
-13,-8,19:18.6
2,-8,19:18.4
14,-8,19:18.6
15,-8,19:18.6
-13,-7,19:18.6
2,-7,19:18.4
16,-7,19:18.6
17,-7,19:18.6
18,-7,19:18.6
-14,-6,19:18.6
-13,-6,19:18.6
2,-6,19:18.12
16,-6,19:18.6
-14,-5,19:18.6
2,-5,19:18.12
16,-5,19:18.6
-14,-4,19:18.6
1,-4,19:18.14
2,-4,19:18.12
16,-4,19:18.6
-14,-3,19:18.6
-2,-3,19:18.14
-1,-3,19:18.14
0,-3,19:18.14
1,-3,19:17.0
2,-3,19:17.0
3,-3,19:18.14
16,-3,19:18.6
-14,-2,19:18.6
-2,-2,19:18.14
-1,-2,19:17.0
0,-2,19:18.14
1,-2,19:18.14
2,-2,19:18.14
3,-2,19:17.0
4,-2,19:18.14
16,-2,19:18.6
-14,-1,19:18.6
-3,-1,19:18.14
-2,-1,19:18.14
-1,-1,19:17.0
0,-1,19:18.14
1,-1,19:18.14
2,-1,19:18.14
3,-1,19:17.0
4,-1,19:18.14
15,-1,19:18.6
16,-1,19:18.6
-15,0,19:18.6
-14,0,19:18.6
-3,0,19:18.14
-2,0,19:18.14
-1,0,19:18.14
2,0,19:18.14
3,0,19:17.0
4,0,19:18.14
15,0,19:18.6
16,0,19:18.6
-15,1,19:18.6
-5,1,19:18.12
-4,1,19:18.12
-3,1,19:18.12
-2,1,19:18.14
-1,1,19:17.0
0,1,19:18.14
1,1,19:18.14
2,1,19:18.14
3,1,19:17.0
4,1,19:18.14
15,1,19:18.6
-15,2,19:18.6
-8,2,19:18.4
-7,2,19:18.4
-6,2,19:18.4
-5,2,19:18.12
-2,2,19:18.14
-1,2,19:18.14
0,2,19:17.0
1,2,19:17.0
2,2,19:18.14
3,2,19:18.14
4,2,19:18.12
5,2,19:18.12
15,2,19:18.6
-15,3,19:18.6
-11,3,19:18.4
-10,3,19:18.4
-9,3,19:18.4
-8,3,19:18.4
-1,3,19:18.14
0,3,19:18.14
1,3,19:18.14
2,3,19:18.14
3,3,19:18.14
6,3,19:18.12
15,3,19:18.6
-15,4,19:18.6
-14,4,19:18.4
-13,4,19:18.4
-12,4,19:18.4
-11,4,19:18.4
0,4,19:18.14
7,4,19:18.12
15,4,19:18.6
-15,5,19:18.4
-14,5,19:18.4
8,5,19:18.4
15,5,19:18.6
-16,6,19:18.6
-15,6,19:18.6
-14,6,19:18.6
9,6,19:18.4
10,6,19:18.4
14,6,19:18.6
-14,7,19:18.6
-13,7,19:18.6
10,7,19:18.4
11,7,19:18.4
14,7,19:18.6
-13,8,19:18.6
-12,8,19:18.6
11,8,19:18.4
12,8,19:18.4
14,8,19:18.6
-12,9,19:18.6
-11,9,19:18.6
12,9,19:18.4
13,9,19:18.4
14,9,19:18.6
-10,10,19:18.6
-9,10,19:18.6
13,10,19:18.6
14,10,19:18.6
-9,11,19:18.6
-8,11,19:18.6
10,11,19:18.6
11,11,19:18.6
12,11,19:18.6
14,11,19:18.6
-8,12,19:18.6
-7,12,19:18.6
7,12,19:18.6
8,12,19:18.6
9,12,19:18.6
10,12,19:18.6
15,12,19:18.6
-6,13,19:18.6
5,13,19:18.6
6,13,19:18.6
7,13,19:18.6
15,13,19:18.6
16,13,19:18.6
-5,14,19:18.6
-4,14,19:18.6
2,14,19:18.6
3,14,19:18.6
4,14,19:18.6
16,14,19:18.6
-4,15,19:18.6
-3,15,19:18.6
0,15,19:18.6
1,15,19:18.6
2,15,19:18.6
-3,16,19:18.6
-2,16,19:18.6
-1,16,19:18.6
-2,17,19:18.6
-2,18,19:18.6
-3,19,19:18.6
-3,20,19:18.6
-3,21,19:18.6
-3,22,19:18.6
4,-21,20:18.6
4,-20,20:18.6
3,-19,20:18.6
4,-19,20:18.6
3,-18,20:18.6
2,-17,20:18.6
3,-17,20:18.6
4,-17,20:18.6
0,-16,20:18.6
1,-16,20:18.6
3,-16,20:18.4
4,-16,20:18.6
5,-16,20:18.6
-3,-15,20:18.6
-2,-15,20:18.6
-1,-15,20:18.6
3,-15,20:18.4
5,-15,20:18.6
6,-15,20:18.6
-15,-14,20:18.6
-5,-14,20:18.6
-4,-14,20:18.6
-3,-14,20:18.6
3,-14,20:18.4
7,-14,20:18.6
8,-14,20:18.6
-14,-13,20:18.6
-8,-13,20:18.6
-7,-13,20:18.6
-6,-13,20:18.6
3,-13,20:18.4
8,-13,20:18.6
9,-13,20:18.6
-13,-12,20:18.6
-11,-12,20:18.6
-10,-12,20:18.6
-9,-12,20:18.6
-8,-12,20:18.6
3,-12,20:18.4
9,-12,20:18.6
10,-12,20:18.6
-13,-11,20:18.6
-12,-11,20:18.6
-11,-11,20:18.6
2,-11,20:18.4
10,-11,20:18.6
11,-11,20:18.6
-12,-10,20:18.6
2,-10,20:18.4
11,-10,20:18.6
12,-10,20:18.6
-13,-9,20:18.6
1,-9,20:18.6
2,-9,20:18.4
13,-9,20:18.6
-13,-8,20:18.6
-3,-8,20:18.6
-2,-8,20:18.6
-1,-8,20:18.6
0,-8,20:18.6
1,-8,20:18.6
2,-8,20:18.6
3,-8,20:18.6
4,-8,20:18.6
14,-8,20:18.6
15,-8,20:18.6
19,-8,20:18.6
-13,-7,20:18.6
-7,-7,20:18.6
-6,-7,20:18.6
-5,-7,20:18.6
-4,-7,20:18.6
-3,-7,20:18.6
-2,-7,20:18.6
-1,-7,20:18.6
0,-7,20:18.6
1,-7,20:18.6
2,-7,20:18.6
3,-7,20:18.6
4,-7,20:18.6
5,-7,20:18.6
6,-7,20:18.6
15,-7,20:18.6
16,-7,20:18.6
17,-7,20:18.6
18,-7,20:18.6
19,-7,20:18.6
-13,-6,20:18.6
-7,-6,20:18.6
-6,-6,20:18.6
-5,-6,20:18.6
-4,-6,20:18.6
-3,-6,20:18.6
-2,-6,20:18.6
-1,-6,20:18.6
0,-6,20:18.6
1,-6,20:18.6
2,-6,20:18.6
3,-6,20:18.6
4,-6,20:18.6
5,-6,20:18.6
7,-6,20:18.6
8,-6,20:18.6
16,-6,20:18.6
-13,-5,20:18.6
-7,-5,20:18.6
-6,-5,20:18.6
-5,-5,20:18.6
-4,-5,20:18.6
-3,-5,20:18.6
-2,-5,20:18.6
-1,-5,20:18.6
0,-5,20:18.6
1,-5,20:18.6
2,-5,20:18.6
3,-5,20:18.6
4,-5,20:18.6
5,-5,20:18.6
6,-5,20:18.6
7,-5,20:18.6
8,-5,20:18.6
9,-5,20:18.6
10,-5,20:18.6
16,-5,20:18.6
-14,-4,20:18.6
-13,-4,20:18.6
-7,-4,20:18.6
-6,-4,20:18.6
-5,-4,20:18.6
-4,-4,20:18.6
-3,-4,20:18.6
-2,-4,20:18.6
-1,-4,20:18.6
0,-4,20:18.6
1,-4,20:18.6
2,-4,20:18.6
3,-4,20:18.6
4,-4,20:18.6
5,-4,20:18.6
6,-4,20:18.6
7,-4,20:18.6
8,-4,20:18.6
9,-4,20:18.6
10,-4,20:18.6
11,-4,20:18.6
16,-4,20:18.6
-14,-3,20:18.6
-7,-3,20:18.6
-6,-3,20:18.6
-5,-3,20:18.6
-4,-3,20:18.6
-3,-3,20:18.6
-2,-3,20:18.6
0,-3,20:17.0
1,-3,20:17.0
2,-3,20:17.0
3,-3,20:18.6
4,-3,20:18.6
5,-3,20:18.6
6,-3,20:18.6
7,-3,20:18.6
8,-3,20:18.6
9,-3,20:18.6
10,-3,20:18.6
15,-3,20:18.6
16,-3,20:18.6
-14,-2,20:18.6
-7,-2,20:18.6
-6,-2,20:18.6
-5,-2,20:18.6
-4,-2,20:18.6
-3,-2,20:18.6
-1,-2,20:17.0
3,-2,20:17.0
4,-2,20:17.0
5,-2,20:18.6
6,-2,20:18.6
7,-2,20:18.6
8,-2,20:18.6
9,-2,20:18.6
10,-2,20:18.6
15,-2,20:18.6
-14,-1,20:18.6
-8,-1,20:18.6
-7,-1,20:18.6
-6,-1,20:18.6
-5,-1,20:18.6
-4,-1,20:18.6
-3,-1,20:18.6
-1,-1,20:17.0
3,-1,20:17.0
5,-1,20:18.6
6,-1,20:18.6
7,-1,20:18.6
8,-1,20:18.6
9,-1,20:18.6
10,-1,20:18.6
15,-1,20:18.6
-14,0,20:18.6
-8,0,20:18.6
-7,0,20:18.6
-6,0,20:18.6
-5,0,20:18.6
-4,0,20:18.6
-3,0,20:18.6
-2,0,20:18.4
-1,0,20:17.0
3,0,20:17.0
5,0,20:18.6
6,0,20:18.6
7,0,20:18.6
8,0,20:18.6
9,0,20:18.6
10,0,20:18.6
15,0,20:18.6
-14,1,20:18.6
-8,1,20:18.6
-7,1,20:18.6
-6,1,20:18.6
-5,1,20:18.4
-4,1,20:18.4
-3,1,20:18.4
-1,1,20:17.0
0,1,20:17.0
2,1,20:17.0
3,1,20:17.0
4,1,20:18.4
5,1,20:18.6
6,1,20:18.6
7,1,20:18.6
8,1,20:18.6
9,1,20:18.6
10,1,20:18.6
15,1,20:18.6
-15,2,20:18.6
-14,2,20:18.6
-8,2,20:18.4
-7,2,20:18.4
-6,2,20:18.6
-5,2,20:18.6
-4,2,20:18.6
-3,2,20:18.6
-2,2,20:18.6
0,2,20:17.0
1,2,20:17.0
4,2,20:18.4
5,2,20:18.4
6,2,20:18.6
7,2,20:18.6
8,2,20:18.6
9,2,20:18.6
10,2,20:18.6
15,2,20:18.6
-15,3,20:18.6
-11,3,20:18.4
-10,3,20:18.4
-9,3,20:18.4
-8,3,20:18.6
-7,3,20:18.6
-6,3,20:18.6
-5,3,20:18.6
-4,3,20:18.6
-3,3,20:18.6
-2,3,20:18.6
-1,3,20:18.6
3,3,20:18.6
4,3,20:18.6
5,3,20:18.6
6,3,20:18.4
7,3,20:18.6
8,3,20:18.6
9,3,20:18.6
10,3,20:18.6
14,3,20:18.6
15,3,20:18.6
-15,4,20:18.6
-14,4,20:18.4
-13,4,20:18.4
-12,4,20:18.4
-7,4,20:18.6
-6,4,20:18.6
-4,4,20:18.6
-3,4,20:18.6
-2,4,20:18.6
-1,4,20:18.6
0,4,20:18.6
1,4,20:18.6
2,4,20:18.6
3,4,20:18.6
4,4,20:18.6
5,4,20:18.6
6,4,20:18.6
7,4,20:18.4
8,4,20:18.6
9,4,20:18.6
10,4,20:18.6
14,4,20:18.6
-15,5,20:18.6
-6,5,20:18.6
-5,5,20:18.6
-4,5,20:18.6
-3,5,20:18.6
-2,5,20:18.6
-1,5,20:18.6
0,5,20:18.6
1,5,20:18.6
2,5,20:18.6
3,5,20:18.6
4,5,20:18.6
5,5,20:18.6
6,5,20:18.6
7,5,20:18.6
8,5,20:18.4
9,5,20:18.6
14,5,20:18.6
-18,6,20:18.6
-17,6,20:18.6
-16,6,20:18.6
-15,6,20:18.6
-14,6,20:18.6
-5,6,20:18.6
-4,6,20:18.6
-3,6,20:18.6
-2,6,20:18.6
-1,6,20:18.6
0,6,20:18.6
1,6,20:18.6
2,6,20:18.6
3,6,20:18.6
4,6,20:18.6
5,6,20:18.6
6,6,20:18.6
7,6,20:18.6
8,6,20:18.6
9,6,20:18.4
10,6,20:18.6
14,6,20:18.6
-18,7,20:18.6
-14,7,20:18.6
-13,7,20:18.6
-4,7,20:18.6
-3,7,20:18.6
-2,7,20:18.6
-1,7,20:18.6
0,7,20:18.6
1,7,20:18.6
2,7,20:18.6
3,7,20:18.6
4,7,20:18.6
5,7,20:18.6
6,7,20:18.6
7,7,20:18.6
8,7,20:18.6
9,7,20:18.6
10,7,20:18.4
11,7,20:18.4
14,7,20:18.6
-12,8,20:18.6
-11,8,20:18.6
-3,8,20:18.6
-2,8,20:18.6
-1,8,20:18.6
0,8,20:18.6
1,8,20:18.6
2,8,20:18.6
3,8,20:18.6
4,8,20:18.6
5,8,20:18.6
6,8,20:18.6
7,8,20:18.6
11,8,20:18.4
12,8,20:18.4
14,8,20:18.6
-11,9,20:18.6
-10,9,20:18.6
-2,9,20:18.6
-1,9,20:18.6
0,9,20:18.6
1,9,20:18.6
2,9,20:18.6
3,9,20:18.6
4,9,20:18.6
12,9,20:18.4
13,9,20:18.6
14,9,20:18.6
-10,10,20:18.6
-9,10,20:18.6
-2,10,20:18.6
-1,10,20:18.6
0,10,20:18.6
1,10,20:18.6
12,10,20:18.6
13,10,20:18.6
14,10,20:18.6
-9,11,20:18.6
-8,11,20:18.6
9,11,20:18.6
10,11,20:18.6
11,11,20:18.6
12,11,20:18.6
14,11,20:18.6
-7,12,20:18.6
-6,12,20:18.6
7,12,20:18.6
8,12,20:18.6
9,12,20:18.6
15,12,20:18.6
-6,13,20:18.6
-5,13,20:18.6
4,13,20:18.6
5,13,20:18.6
6,13,20:18.6
15,13,20:18.6
16,13,20:18.6
-5,14,20:18.6
-4,14,20:18.6
2,14,20:18.6
3,14,20:18.6
4,14,20:18.6
16,14,20:18.6
-4,15,20:18.6
-3,15,20:18.6
-1,15,20:18.6
0,15,20:18.6
1,15,20:18.6
17,15,20:18.6
-2,16,20:18.6
-2,17,20:18.6
-2,18,20:18.6
-3,19,20:18.6
-3,20,20:18.6
-3,21,20:18.6
-3,22,20:18.6
4,-22,21:18.6
4,-21,21:18.6
4,-20,21:18.6
3,-19,21:18.6
4,-19,21:18.6
3,-18,21:18.6
3,-17,21:18.6
0,-16,21:18.6
1,-16,21:18.6
2,-16,21:18.6
3,-16,21:18.4
4,-16,21:18.6
-16,-15,21:18.6
-2,-15,21:18.6
-1,-15,21:18.6
0,-15,21:18.6
3,-15,21:18.4
5,-15,21:18.6
6,-15,21:18.6
-15,-14,21:18.6
-5,-14,21:18.6
-4,-14,21:18.6
-3,-14,21:18.6
1,-14,21:18.6
2,-14,21:18.6
3,-14,21:18.4
6,-14,21:18.6
7,-14,21:18.6
-14,-13,21:18.6
-7,-13,21:18.6
-6,-13,21:18.6
-5,-13,21:18.6
-3,-13,21:18.6
-2,-13,21:18.6
-1,-13,21:18.6
0,-13,21:18.6
1,-13,21:18.6
2,-13,21:18.6
3,-13,21:18.6
4,-13,21:18.6
5,-13,21:18.6
7,-13,21:18.6
8,-13,21:18.6
-13,-12,21:18.6
-10,-12,21:18.6
-9,-12,21:18.6
-8,-12,21:18.6
-7,-12,21:18.6
-6,-12,21:18.6
-5,-12,21:18.6
-4,-12,21:18.6
-3,-12,21:18.6
-2,-12,21:18.6
-1,-12,21:18.6
0,-12,21:18.6
1,-12,21:18.6
2,-12,21:18.6
3,-12,21:18.6
4,-12,21:18.6
5,-12,21:18.6
6,-12,21:18.6
7,-12,21:18.6
8,-12,21:18.6
9,-12,21:18.6
-13,-11,21:18.6
-12,-11,21:18.6
-11,-11,21:18.6
-10,-11,21:18.6
-9,-11,21:18.6
-8,-11,21:18.6
-7,-11,21:18.6
-6,-11,21:18.6
-5,-11,21:18.6
-4,-11,21:18.6
-3,-11,21:18.6
-2,-11,21:18.6
-1,-11,21:18.6
0,-11,21:18.6
1,-11,21:18.6
2,-11,21:18.6
3,-11,21:18.6
4,-11,21:18.6
5,-11,21:18.6
6,-11,21:18.6
7,-11,21:18.6
8,-11,21:18.6
9,-11,21:18.6
10,-11,21:18.6
-12,-10,21:18.6
-11,-10,21:18.6
-10,-10,21:18.6
-9,-10,21:18.6
-8,-10,21:18.6
-7,-10,21:18.6
-6,-10,21:18.6
-5,-10,21:18.6
-4,-10,21:18.6
-3,-10,21:18.6
-2,-10,21:18.6
-1,-10,21:18.6
0,-10,21:18.6
1,-10,21:18.6
2,-10,21:18.6
3,-10,21:18.6
4,-10,21:18.6
5,-10,21:18.6
6,-10,21:18.6
7,-10,21:18.6
8,-10,21:18.6
9,-10,21:18.6
10,-10,21:18.6
11,-10,21:18.6
12,-10,21:18.6
-12,-9,21:18.6
-11,-9,21:18.6
-10,-9,21:18.6
-9,-9,21:18.6
-8,-9,21:18.6
-7,-9,21:18.6
-6,-9,21:18.6
-5,-9,21:18.6
-4,-9,21:18.6
-3,-9,21:18.6
-2,-9,21:18.6
-1,-9,21:18.6
0,-9,21:18.6
1,-9,21:18.6
2,-9,21:18.4
3,-9,21:18.6
4,-9,21:18.6
5,-9,21:18.6
6,-9,21:18.6
7,-9,21:18.6
8,-9,21:18.6
9,-9,21:18.6
10,-9,21:18.6
11,-9,21:18.6
12,-9,21:18.6
13,-9,21:18.6
-13,-8,21:18.6
-12,-8,21:18.6
-11,-8,21:18.6
-10,-8,21:18.6
-9,-8,21:18.6
-8,-8,21:18.6
-7,-8,21:18.6
-6,-8,21:18.6
-5,-8,21:18.6
-4,-8,21:18.6
-3,-8,21:18.6
-2,-8,21:18.6
2,-8,21:18.4
4,-8,21:18.6
5,-8,21:18.6
6,-8,21:18.6
7,-8,21:18.6
8,-8,21:18.6
9,-8,21:18.6
10,-8,21:18.6
11,-8,21:18.6
12,-8,21:18.6
13,-8,21:18.6
14,-8,21:18.6
19,-8,21:18.6
20,-8,21:18.6
-13,-7,21:18.6
-12,-7,21:18.6
-11,-7,21:18.6
-10,-7,21:18.6
-9,-7,21:18.6
-8,-7,21:18.6
-7,-7,21:18.6
-6,-7,21:18.6
2,-7,21:18.4
6,-7,21:18.6
7,-7,21:18.6
8,-7,21:18.6
9,-7,21:18.6
10,-7,21:18.6
11,-7,21:18.6
12,-7,21:18.6
13,-7,21:18.6
14,-7,21:18.6
15,-7,21:18.6
17,-7,21:18.6
18,-7,21:18.6
19,-7,21:18.6
-13,-6,21:18.6
-12,-6,21:18.6
-11,-6,21:18.6
-10,-6,21:18.6
-9,-6,21:18.6
-8,-6,21:18.6
2,-6,21:18.4
8,-6,21:18.6
9,-6,21:18.6
10,-6,21:18.6
11,-6,21:18.6
12,-6,21:18.6
13,-6,21:18.6
14,-6,21:18.6
15,-6,21:18.6
16,-6,21:18.6
-13,-5,21:18.6
-12,-5,21:18.6
-11,-5,21:18.6
-10,-5,21:18.6
-8,-5,21:18.6
2,-5,21:18.4
10,-5,21:18.6
11,-5,21:18.6
12,-5,21:18.6
13,-5,21:18.6
14,-5,21:18.6
15,-5,21:18.6
16,-5,21:18.6
-13,-4,21:18.6
-12,-4,21:18.6
-10,-4,21:18.6
-9,-4,21:18.6
-8,-4,21:18.6
2,-4,21:18.4
11,-4,21:18.6
12,-4,21:18.6
13,-4,21:18.6
14,-4,21:18.6
15,-4,21:18.6
-14,-3,21:18.6
-13,-3,21:18.6
-12,-3,21:18.6
-11,-3,21:18.6
-10,-3,21:18.6
-9,-3,21:18.6
-8,-3,21:18.6
-1,-3,21:17.0
0,-3,21:17.0
1,-3,21:17.0
2,-3,21:17.0
11,-3,21:18.6
12,-3,21:18.6
13,-3,21:18.6
14,-3,21:18.6
15,-3,21:18.6
-14,-2,21:18.6
-13,-2,21:18.6
-12,-2,21:18.6
-11,-2,21:18.6
-10,-2,21:18.6
-9,-2,21:18.6
-8,-2,21:18.6
-1,-2,21:17.0
3,-2,21:17.0
11,-2,21:18.6
12,-2,21:18.6
13,-2,21:18.6
14,-2,21:18.6
15,-2,21:18.6
-14,-1,21:18.6
-12,-1,21:18.6
-11,-1,21:18.6
-10,-1,21:18.6
-9,-1,21:18.6
-8,-1,21:18.6
-1,-1,21:17.0
3,-1,21:17.0
11,-1,21:18.6
12,-1,21:18.6
13,-1,21:18.6
14,-1,21:18.6
15,-1,21:18.6
-14,0,21:18.6
-13,0,21:18.6
-12,0,21:18.6
-11,0,21:18.6
-10,0,21:18.6
-9,0,21:18.6
-8,0,21:18.6
-3,0,21:18.4
-2,0,21:18.4
-1,0,21:17.0
3,0,21:17.0
11,0,21:18.6
12,0,21:18.6
13,0,21:18.6
14,0,21:18.6
15,0,21:18.6
-14,1,21:18.6
-13,1,21:18.6
-12,1,21:18.6
-11,1,21:18.6
-10,1,21:18.6
-9,1,21:18.6
-8,1,21:18.6
-6,1,21:18.4
-5,1,21:18.4
-4,1,21:18.4
-3,1,21:18.4
0,1,21:17.0
1,1,21:17.0
2,1,21:17.0
3,1,21:17.0
4,1,21:18.4
10,1,21:18.6
11,1,21:18.6
12,1,21:18.6
13,1,21:18.6
14,1,21:18.6
15,1,21:18.6
-14,2,21:18.6
-13,2,21:18.6
-12,2,21:18.6
-11,2,21:18.6
-10,2,21:18.6
-9,2,21:18.6
-8,2,21:18.4
-7,2,21:18.4
-6,2,21:18.4
1,2,21:17.0
4,2,21:18.4
5,2,21:18.4
10,2,21:18.6
11,2,21:18.6
12,2,21:18.6
13,2,21:18.6
14,2,21:18.6
-14,3,21:18.6
-13,3,21:18.6
-12,3,21:18.6
-11,3,21:18.4
-10,3,21:18.4
-9,3,21:18.6
-8,3,21:18.6
6,3,21:18.4
10,3,21:18.6
11,3,21:18.6
12,3,21:18.6
13,3,21:18.6
14,3,21:18.6
-15,4,21:18.6
-14,4,21:18.4
-13,4,21:18.4
-12,4,21:18.6
-11,4,21:18.6
-10,4,21:18.6
-9,4,21:18.6
-8,4,21:18.6
-7,4,21:18.6
7,4,21:18.4
10,4,21:18.6
11,4,21:18.6
12,4,21:18.6
14,4,21:18.6
-15,5,21:18.6
-13,5,21:18.6
-12,5,21:18.6
-11,5,21:18.6
-10,5,21:18.6
-9,5,21:18.6
-8,5,21:18.6
-7,5,21:18.6
-6,5,21:18.6
8,5,21:18.4
11,5,21:18.6
12,5,21:18.6
13,5,21:18.6
14,5,21:18.6
-18,6,21:18.6
-17,6,21:18.6
-16,6,21:18.6
-15,6,21:18.6
-14,6,21:18.6
-12,6,21:18.6
-11,6,21:18.6
-9,6,21:18.6
-8,6,21:18.6
-7,6,21:18.6
-6,6,21:18.6
9,6,21:18.4
10,6,21:18.6
11,6,21:18.6
12,6,21:18.6
13,6,21:18.6
14,6,21:18.6
-19,7,21:18.6
-18,7,21:18.6
-13,7,21:18.6
-12,7,21:18.6
-10,7,21:18.6
-9,7,21:18.6
-8,7,21:18.6
-7,7,21:18.6
-6,7,21:18.6
-5,7,21:18.6
9,7,21:18.6
10,7,21:18.4
11,7,21:18.6
12,7,21:18.6
13,7,21:18.6
14,7,21:18.6
-12,8,21:18.6
-11,8,21:18.6
-10,8,21:18.6
-9,8,21:18.6
-8,8,21:18.6
-7,8,21:18.6
-6,8,21:18.6
-5,8,21:18.6
-4,8,21:18.6
6,8,21:18.6
7,8,21:18.6
8,8,21:18.6
9,8,21:18.6
10,8,21:18.6
11,8,21:18.6
12,8,21:18.6
13,8,21:18.6
-11,9,21:18.6
-10,9,21:18.6
-9,9,21:18.6
-8,9,21:18.6
-7,9,21:18.6
-6,9,21:18.6
-5,9,21:18.6
-4,9,21:18.6
-3,9,21:18.6
3,9,21:18.6
4,9,21:18.6
5,9,21:18.6
6,9,21:18.6
7,9,21:18.6
8,9,21:18.6
9,9,21:18.6
10,9,21:18.6
11,9,21:18.6
12,9,21:18.6
13,9,21:18.6
-9,10,21:18.6
-8,10,21:18.6
-7,10,21:18.6
-5,10,21:18.6
-4,10,21:18.6
-3,10,21:18.6
-2,10,21:18.6
0,10,21:18.6
1,10,21:18.6
2,10,21:18.6
3,10,21:18.6
4,10,21:18.6
6,10,21:18.6
7,10,21:18.6
8,10,21:18.6
9,10,21:18.6
10,10,21:18.6
11,10,21:18.6
12,10,21:18.6
13,10,21:18.6
-8,11,21:18.6
-7,11,21:18.6
-6,11,21:18.6
-5,11,21:18.6
-4,11,21:18.6
-3,11,21:18.6
-2,11,21:18.6
-1,11,21:18.6
0,11,21:18.6
1,11,21:18.6
3,11,21:18.6
4,11,21:18.6
5,11,21:18.6
6,11,21:18.6
7,11,21:18.6
8,11,21:18.6
9,11,21:18.6
10,11,21:18.6
11,11,21:18.6
14,11,21:18.6
-7,12,21:18.6
-6,12,21:18.6
-5,12,21:18.6
-4,12,21:18.6
-3,12,21:18.6
-2,12,21:18.6
-1,12,21:18.6
0,12,21:18.6
1,12,21:18.6
2,12,21:18.6
3,12,21:18.6
4,12,21:18.6
5,12,21:18.6
6,12,21:18.6
7,12,21:18.6
8,12,21:18.6
14,12,21:18.6
15,12,21:18.6
-6,13,21:18.6
-5,13,21:18.6
-4,13,21:18.6
-3,13,21:18.6
-2,13,21:18.6
-1,13,21:18.6
0,13,21:18.6
1,13,21:18.6
2,13,21:18.6
3,13,21:18.6
4,13,21:18.6
5,13,21:18.6
6,13,21:18.6
15,13,21:18.6
16,13,21:18.6
-4,14,21:18.6
-3,14,21:18.6
-2,14,21:18.6
-1,14,21:18.6
0,14,21:18.6
1,14,21:18.6
2,14,21:18.6
3,14,21:18.6
16,14,21:18.6
-3,15,21:18.6
-2,15,21:18.6
-1,15,21:18.6
0,15,21:18.6
17,15,21:18.6
-2,16,21:18.6
-2,17,21:18.6
-2,18,21:18.6
-3,19,21:18.6
-3,20,21:18.6
-3,21,21:18.6
4,-22,22:18.6
4,-21,22:18.6
4,-20,22:18.6
3,-19,22:18.6
4,-19,22:18.6
3,-18,22:18.6
3,-17,22:18.6
1,-16,22:18.6
2,-16,22:18.6
3,-16,22:18.6
-16,-15,22:18.6
-1,-15,22:18.6
0,-15,22:18.6
1,-15,22:18.6
2,-15,22:18.6
3,-15,22:18.6
4,-15,22:18.6
5,-15,22:18.6
-15,-14,22:18.6
-4,-14,22:18.6
-3,-14,22:18.6
-2,-14,22:18.6
-1,-14,22:18.6
0,-14,22:18.6
1,-14,22:18.6
2,-14,22:18.6
3,-14,22:18.6
4,-14,22:18.6
5,-14,22:18.6
6,-14,22:18.6
-14,-13,22:18.6
-7,-13,22:18.6
-6,-13,22:18.6
-5,-13,22:18.6
-4,-13,22:18.6
-3,-13,22:18.6
-2,-13,22:18.6
5,-13,22:18.6
6,-13,22:18.6
7,-13,22:18.6
-13,-12,22:18.6
-9,-12,22:18.6
-8,-12,22:18.6
-7,-12,22:18.6
-6,-12,22:18.6
7,-12,22:18.6
8,-12,22:18.6
9,-12,22:18.6
-13,-11,22:18.6
-12,-11,22:18.6
-11,-11,22:18.6
-10,-11,22:18.6
-9,-11,22:18.6
9,-11,22:18.6
10,-11,22:18.6
-12,-10,22:18.6
10,-10,22:18.6
11,-10,22:18.6
-12,-9,22:18.6
11,-9,22:18.6
12,-9,22:18.6
-12,-8,22:18.6
12,-8,22:18.6
13,-8,22:18.6
19,-8,22:18.6
20,-8,22:18.6
-13,-7,22:18.6
-12,-7,22:18.6
13,-7,22:18.6
14,-7,22:18.6
15,-7,22:18.6
17,-7,22:18.6
18,-7,22:18.6
19,-7,22:18.6
-13,-6,22:18.6
15,-6,22:18.6
16,-6,22:18.6
-13,-5,22:18.6
15,-5,22:18.6
-13,-4,22:18.6
15,-4,22:18.6
-13,-3,22:18.6
-1,-3,22:17.0
0,-3,22:17.0
1,-3,22:17.0
2,-3,22:17.0
3,-3,22:17.0
15,-3,22:18.6
-13,-2,22:18.6
-1,-2,22:17.0
3,-2,22:17.0
14,-2,22:18.6
15,-2,22:18.6
-14,-1,22:18.6
-13,-1,22:18.6
-1,-1,22:17.0
3,-1,22:17.0
14,-1,22:18.6
-14,0,22:18.6
-13,0,22:18.6
-1,0,22:17.0
3,0,22:17.0
14,0,22:18.6
-14,1,22:18.6
-13,1,22:18.6
0,1,22:17.0
1,1,22:17.0
2,1,22:17.0
3,1,22:17.0
14,1,22:18.6
-14,2,22:18.6
-13,2,22:18.6
1,2,22:17.0
14,2,22:18.6
-14,3,22:18.6
-13,3,22:18.6
14,3,22:18.6
-14,4,22:18.6
-13,4,22:18.6
14,4,22:18.6
-15,5,22:18.6
-14,5,22:18.6
-13,5,22:18.6
13,5,22:18.6
-17,6,22:18.6
-16,6,22:18.6
-15,6,22:18.6
-14,6,22:18.6
-13,6,22:18.6
-12,6,22:18.6
13,6,22:18.6
-19,7,22:18.6
-18,7,22:18.6
-13,7,22:18.6
-12,7,22:18.6
13,7,22:18.6
-12,8,22:18.6
-11,8,22:18.6
-10,8,22:18.6
13,8,22:18.6
-10,9,22:18.6
-9,9,22:18.6
12,9,22:18.6
13,9,22:18.6
-9,10,22:18.6
-8,10,22:18.6
10,10,22:18.6
11,10,22:18.6
12,10,22:18.6
13,10,22:18.6
-8,11,22:18.6
-7,11,22:18.6
8,11,22:18.6
9,11,22:18.6
10,11,22:18.6
14,11,22:18.6
-6,12,22:18.6
5,12,22:18.6
6,12,22:18.6
7,12,22:18.6
15,12,22:18.6
-5,13,22:18.6
-4,13,22:18.6
2,13,22:18.6
3,13,22:18.6
4,13,22:18.6
5,13,22:18.6
15,13,22:18.6
-4,14,22:18.6
-3,14,22:18.6
0,14,22:18.6
1,14,22:18.6
2,14,22:18.6
-3,15,22:18.6
-2,15,22:18.6
-1,15,22:18.6
0,15,22:18.6
-2,16,22:18.6
-2,17,22:18.6
-2,18,22:18.6
-3,19,22:18.6
-2,19,22:18.6
4,-20,23:18.6
4,-19,23:18.6
3,-18,23:18.6
3,-17,23:18.6
2,-16,23:18.6
3,-16,23:18.6
-1,-15,23:18.6
0,-15,23:18.6
1,-15,23:18.6
2,-15,23:18.6
3,-15,23:18.6
4,-15,23:18.6
-15,-14,23:18.6
-3,-14,23:18.6
-2,-14,23:18.6
-1,-14,23:18.6
4,-14,23:18.6
5,-14,23:18.6
-14,-13,23:18.6
-6,-13,23:18.6
-5,-13,23:18.6
-4,-13,23:18.6
-3,-13,23:18.6
5,-13,23:18.6
6,-13,23:18.6
7,-13,23:18.6
-13,-12,23:18.6
-8,-12,23:18.6
-7,-12,23:18.6
-6,-12,23:18.6
7,-12,23:18.6
8,-12,23:18.6
-13,-11,23:18.6
-12,-11,23:18.6
-11,-11,23:18.6
-10,-11,23:18.6
-9,-11,23:18.6
8,-11,23:18.6
9,-11,23:18.6
-12,-10,23:18.6
-11,-10,23:18.6
9,-10,23:18.6
10,-10,23:18.6
-12,-9,23:18.6
10,-9,23:18.6
11,-9,23:18.6
-12,-8,23:18.6
11,-8,23:18.6
12,-8,23:18.6
13,-8,23:18.6
20,-8,23:18.6
-12,-7,23:18.6
13,-7,23:18.6
14,-7,23:18.6
17,-7,23:18.6
18,-7,23:18.6
19,-7,23:18.6
-12,-6,23:18.6
14,-6,23:18.6
15,-6,23:18.6
16,-6,23:18.6
-13,-5,23:18.6
14,-5,23:18.6
15,-5,23:18.6
-13,-4,23:18.6
14,-4,23:18.6
-13,-3,23:18.6
-1,-3,23:17.0
0,-3,23:17.0
1,-3,23:17.0
2,-3,23:17.0
14,-3,23:18.6
-13,-2,23:18.6
-1,-2,23:17.0
3,-2,23:17.0
14,-2,23:18.6
-13,-1,23:18.6
-1,-1,23:17.0
3,-1,23:17.0
14,-1,23:18.6
-13,0,23:18.6
-1,0,23:17.0
0,0,23:17.0
3,0,23:17.0
14,0,23:18.6
-14,1,23:18.6
-13,1,23:18.6
0,1,23:17.0
1,1,23:17.0
2,1,23:17.0
13,1,23:18.6
14,1,23:18.6
-14,2,23:18.6
13,2,23:18.6
-14,3,23:18.6
13,3,23:18.6
-14,4,23:18.6
-15,5,23:18.6
-14,5,23:18.6
13,5,23:18.6
-18,6,23:18.6
-17,6,23:18.6
-16,6,23:18.6
-13,6,23:18.6
13,6,23:18.6
-19,7,23:18.6
-18,7,23:18.6
-12,7,23:18.6
12,7,23:18.6
13,7,23:18.6
-11,8,23:18.6
-10,8,23:18.6
12,8,23:18.6
-10,9,23:18.6
-9,9,23:18.6
11,9,23:18.6
12,9,23:18.6
-8,10,23:18.6
9,10,23:18.6
10,10,23:18.6
11,10,23:18.6
13,10,23:18.6
-7,11,23:18.6
-6,11,23:18.6
7,11,23:18.6
8,11,23:18.6
9,11,23:18.6
14,11,23:18.6
-6,12,23:18.6
-5,12,23:18.6
4,12,23:18.6
5,12,23:18.6
6,12,23:18.6
15,12,23:18.6
-5,13,23:18.6
-4,13,23:18.6
1,13,23:18.6
2,13,23:18.6
3,13,23:18.6
4,13,23:18.6
15,13,23:18.6
-3,14,23:18.6
-2,14,23:18.6
-1,14,23:18.6
0,14,23:18.6
1,14,23:18.6
-2,15,23:18.6
-2,16,23:18.6
-2,17,23:18.6
-2,18,23:18.6
-3,19,23:18.6
-2,19,23:18.6
4,-20,24:18.6
4,-19,24:18.6
3,-18,24:18.6
3,-17,24:18.6
3,-16,24:18.6
0,-15,24:18.6
1,-15,24:18.6
2,-15,24:18.6
3,-15,24:18.6
-2,-14,24:18.6
-1,-14,24:18.6
0,-14,24:18.6
3,-14,24:18.6
4,-14,24:18.6
5,-14,24:18.6
-14,-13,24:18.6
-5,-13,24:18.6
-4,-13,24:18.6
-3,-13,24:18.6
5,-13,24:18.6
6,-13,24:18.6
-13,-12,24:18.6
-7,-12,24:18.6
-6,-12,24:18.6
-5,-12,24:18.6
6,-12,24:18.6
7,-12,24:18.6
-13,-11,24:18.6
-12,-11,24:18.6
-10,-11,24:18.6
-9,-11,24:18.6
-8,-11,24:18.6
7,-11,24:18.6
8,-11,24:18.6
-12,-10,24:18.6
-11,-10,24:18.6
-10,-10,24:18.6
8,-10,24:18.6
9,-10,24:18.6
-12,-9,24:18.6
9,-9,24:18.6
10,-9,24:18.6
-12,-8,24:18.6
11,-8,24:18.6
12,-8,24:18.6
-12,-7,24:18.6
12,-7,24:18.6
13,-7,24:18.6
17,-7,24:18.6
18,-7,24:18.6
19,-7,24:18.6
-12,-6,24:18.6
13,-6,24:18.6
14,-6,24:18.6
15,-6,24:18.6
16,-6,24:18.6
17,-6,24:18.6
-12,-5,24:18.6
14,-5,24:18.6
-13,-4,24:18.6
-12,-4,24:18.6
14,-4,24:18.6
-13,-3,24:18.6
-1,-3,24:17.0
0,-3,24:17.0
1,-3,24:17.0
2,-3,24:17.0
13,-3,24:18.6
14,-3,24:18.6
-13,-2,24:18.6
-1,-2,24:17.0
3,-2,24:17.0
13,-2,24:18.6
14,-2,24:18.6
-13,-1,24:18.6
-1,-1,24:17.0
3,-1,24:17.0
13,-1,24:18.6
-13,0,24:18.6
-1,0,24:17.0
0,0,24:17.0
2,0,24:17.0
3,0,24:17.0
13,0,24:18.6
-13,1,24:18.6
0,1,24:17.0
1,1,24:17.0
2,1,24:17.0
13,1,24:18.6
-14,2,24:18.6
-13,2,24:18.6
13,2,24:18.6
-14,3,24:18.6
12,3,24:18.6
13,3,24:18.6
-14,4,24:18.6
12,4,24:18.6
-15,5,24:18.6
-14,5,24:18.6
-13,5,24:18.6
12,5,24:18.6
-18,6,24:18.6
-17,6,24:18.6
-16,6,24:18.6
-13,6,24:18.6
-12,6,24:18.6
12,6,24:18.6
-19,7,24:18.6
-12,7,24:18.6
12,7,24:18.6
-10,8,24:18.6
-9,8,24:18.6
12,8,24:18.6
-9,9,24:18.6
-8,9,24:18.6
10,9,24:18.6
11,9,24:18.6
12,9,24:18.6
-8,10,24:18.6
-7,10,24:18.6
8,10,24:18.6
9,10,24:18.6
10,10,24:18.6
13,10,24:18.6
-7,11,24:18.6
-6,11,24:18.6
5,11,24:18.6
6,11,24:18.6
7,11,24:18.6
8,11,24:18.6
14,11,24:18.6
-5,12,24:18.6
-4,12,24:18.6
3,12,24:18.6
4,12,24:18.6
5,12,24:18.6
15,12,24:18.6
-4,13,24:18.6
-3,13,24:18.6
0,13,24:18.6
1,13,24:18.6
2,13,24:18.6
3,13,24:18.6
15,13,24:18.6
16,13,24:18.6
-3,14,24:18.6
-2,14,24:18.6
-1,14,24:18.6
0,14,24:18.6
-2,15,24:18.6
-2,16,24:18.6
-2,17,24:18.6
-2,18,24:18.6
-3,19,24:18.6
-2,19,24:18.6
-3,20,24:18.6
3,-16,25:18.6
1,-15,25:18.6
2,-15,25:18.6
3,-15,25:18.6
-1,-14,25:18.6
0,-14,25:18.6
1,-14,25:18.6
2,-14,25:18.6
3,-14,25:18.6
4,-14,25:18.6
-14,-13,25:18.6
-4,-13,25:18.6
-3,-13,25:18.6
-2,-13,25:18.6
4,-13,25:18.6
5,-13,25:18.6
-13,-12,25:18.6
-6,-12,25:18.6
-5,-12,25:18.6
-4,-12,25:18.6
5,-12,25:18.6
6,-12,25:18.6
-13,-11,25:18.6
-12,-11,25:18.6
-9,-11,25:18.6
-8,-11,25:18.6
-7,-11,25:18.6
6,-11,25:18.6
7,-11,25:18.6
-12,-10,25:18.6
-11,-10,25:18.6
-10,-10,25:18.6
-9,-10,25:18.6
7,-10,25:18.6
8,-10,25:18.6
-11,-9,25:18.6
8,-9,25:18.6
9,-9,25:18.6
-12,-8,25:18.6
10,-8,25:18.6
11,-8,25:18.6
-12,-7,25:18.6
11,-7,25:18.6
12,-7,25:18.6
18,-7,25:18.6
19,-7,25:18.6
-12,-6,25:18.6
12,-6,25:18.6
13,-6,25:18.6
14,-6,25:18.6
15,-6,25:18.6
16,-6,25:18.6
-12,-5,25:18.6
13,-5,25:18.6
14,-5,25:18.6
-12,-4,25:18.6
13,-4,25:18.6
-12,-3,25:18.6
-1,-3,25:17.0
0,-3,25:17.0
1,-3,25:17.0
2,-3,25:17.0
13,-3,25:18.6
-13,-2,25:18.6
-1,-2,25:17.0
3,-2,25:17.0
13,-2,25:18.6
-13,-1,25:18.6
-1,-1,25:17.0
3,-1,25:17.0
13,-1,25:18.6
-13,0,25:18.6
-1,0,25:17.0
0,0,25:17.0
2,0,25:17.0
3,0,25:17.0
12,0,25:18.6
13,0,25:18.6
-13,1,25:18.6
0,1,25:17.0
1,1,25:17.0
2,1,25:17.0
12,1,25:18.6
13,1,25:18.6
-13,2,25:18.6
12,2,25:18.6
-13,3,25:18.6
12,3,25:18.6
-13,4,25:18.6
12,4,25:18.6
-16,5,25:18.6
-15,5,25:18.6
-14,5,25:18.6
-13,5,25:18.6
12,5,25:18.6
-18,6,25:18.6
-17,6,25:18.6
-16,6,25:18.6
-12,6,25:18.6
-11,6,25:18.6
12,6,25:18.6
-10,7,25:18.6
11,7,25:18.6
12,7,25:18.6
-10,8,25:18.6
-9,8,25:18.6
11,8,25:18.6
-9,9,25:18.6
-8,9,25:18.6
9,9,25:18.6
10,9,25:18.6
11,9,25:18.6
12,9,25:18.6
-7,10,25:18.6
7,10,25:18.6
8,10,25:18.6
9,10,25:18.6
13,10,25:18.6
-6,11,25:18.6
-5,11,25:18.6
4,11,25:18.6
5,11,25:18.6
6,11,25:18.6
7,11,25:18.6
14,11,25:18.6
-5,12,25:18.6
-4,12,25:18.6
2,12,25:18.6
3,12,25:18.6
4,12,25:18.6
-3,13,25:18.6
-2,13,25:18.6
-1,13,25:18.6
0,13,25:18.6
1,13,25:18.6
2,13,25:18.6
-2,14,25:18.6
-1,14,25:18.6
-2,15,25:18.6
-2,16,25:18.6
-2,17,25:18.6
-2,18,25:18.6
-2,19,25:18.6
-3,20,25:18.6
3,-17,26:18.6
3,-16,26:18.6
2,-15,26:18.6
0,-14,26:18.6
1,-14,26:18.6
2,-14,26:18.6
3,-14,26:18.6
-14,-13,26:18.6
-3,-13,26:18.6
-2,-13,26:18.6
-1,-13,26:18.6
3,-13,26:18.6
4,-13,26:18.6
-6,-12,26:18.6
-5,-12,26:18.6
-4,-12,26:18.6
-3,-12,26:18.6
4,-12,26:18.6
5,-12,26:18.6
-12,-11,26:18.6
-8,-11,26:18.6
-7,-11,26:18.6
-6,-11,26:18.6
5,-11,26:18.6
6,-11,26:18.6
-12,-10,26:18.6
-10,-10,26:18.6
-9,-10,26:18.6
-8,-10,26:18.6
6,-10,26:18.6
7,-10,26:18.6
8,-10,26:18.6
-11,-9,26:18.6
-10,-9,26:18.6
8,-9,26:18.6
9,-9,26:18.6
-11,-8,26:18.6
9,-8,26:18.6
10,-8,26:18.6
-12,-7,26:18.6
-11,-7,26:18.6
10,-7,26:18.6
11,-7,26:18.6
-12,-6,26:18.6
11,-6,26:18.6
12,-6,26:18.6
15,-6,26:18.6
16,-6,26:18.6
-12,-5,26:18.6
12,-5,26:18.6
13,-5,26:18.6
14,-5,26:18.6
-12,-4,26:18.6
13,-4,26:18.6
-12,-3,26:18.6
-1,-3,26:17.0
0,-3,26:17.0
1,-3,26:17.0
2,-3,26:17.0
12,-3,26:18.6
13,-3,26:18.6
-12,-2,26:18.6
-1,-2,26:17.0
2,-2,26:17.0
3,-2,26:17.0
12,-2,26:18.6
13,-2,26:18.6
-13,-1,26:18.6
-12,-1,26:18.6
-1,-1,26:17.0
3,-1,26:17.0
12,-1,26:18.6
-13,0,26:18.6
-1,0,26:17.0
0,0,26:17.0
2,0,26:17.0
3,0,26:17.0
12,0,26:18.6
-13,1,26:18.6
0,1,26:17.0
1,1,26:17.0
12,1,26:18.6
-13,2,26:18.6
12,2,26:18.6
-13,3,26:18.6
11,3,26:18.6
12,3,26:18.6
-13,4,26:18.6
11,4,26:18.6
12,4,26:18.6
-16,5,26:18.6
-15,5,26:18.6
-14,5,26:18.6
-13,5,26:18.6
-12,5,26:18.6
11,5,26:18.6
-18,6,26:18.6
-17,6,26:18.6
-16,6,26:18.6
-12,6,26:18.6
-11,6,26:18.6
11,6,26:18.6
-19,7,26:18.6
-10,7,26:18.6
11,7,26:18.6
-9,8,26:18.6
-8,8,26:18.6
10,8,26:18.6
11,8,26:18.6
-8,9,26:18.6
-7,9,26:18.6
8,9,26:18.6
9,9,26:18.6
10,9,26:18.6
12,9,26:18.6
-7,10,26:18.6
6,10,26:18.6
7,10,26:18.6
8,10,26:18.6
13,10,26:18.6
-5,11,26:18.6
-4,11,26:18.6
3,11,26:18.6
4,11,26:18.6
5,11,26:18.6
6,11,26:18.6
-4,12,26:18.6
-3,12,26:18.6
1,12,26:18.6
2,12,26:18.6
3,12,26:18.6
-3,13,26:18.6
-2,13,26:18.6
-1,13,26:18.6
0,13,26:18.6
1,13,26:18.6
-2,14,26:18.6
-2,15,26:18.6
-2,16,26:18.6
-2,17,26:18.6
3,-17,27:18.6
3,-16,27:18.6
2,-15,27:18.6
1,-14,27:18.6
2,-14,27:18.6
-2,-13,27:18.6
-1,-13,27:18.6
0,-13,27:18.6
2,-13,27:18.6
3,-13,27:18.6
-5,-12,27:18.6
-4,-12,27:18.6
-3,-12,27:18.6
-2,-12,27:18.6
3,-12,27:18.6
4,-12,27:18.6
-7,-11,27:18.6
-6,-11,27:18.6
-5,-11,27:18.6
4,-11,27:18.6
5,-11,27:18.6
-12,-10,27:18.6
-9,-10,27:18.6
-8,-10,27:18.6
-7,-10,27:18.6
5,-10,27:18.6
6,-10,27:18.6
7,-10,27:18.6
-11,-9,27:18.6
-10,-9,27:18.6
-9,-9,27:18.6
7,-9,27:18.6
8,-9,27:18.6
-11,-8,27:18.6
8,-8,27:18.6
9,-8,27:18.6
-11,-7,27:18.6
9,-7,27:18.6
10,-7,27:18.6
-11,-6,27:18.6
10,-6,27:18.6
11,-6,27:18.6
15,-6,27:18.6
16,-6,27:18.6
-12,-5,27:18.6
12,-5,27:18.6
13,-5,27:18.6
14,-5,27:18.6
-12,-4,27:18.6
12,-4,27:18.6
-12,-3,27:18.6
-1,-3,27:17.0
0,-3,27:17.0
1,-3,27:17.0
2,-3,27:17.0
12,-3,27:18.6
-12,-2,27:18.6
-1,-2,27:17.0
2,-2,27:17.0
3,-2,27:17.0
12,-2,27:18.6
-12,-1,27:18.6
-1,-1,27:17.0
2,-1,27:17.0
3,-1,27:17.0
12,-1,27:18.6
-12,0,27:18.6
-1,0,27:17.0
0,0,27:17.0
2,0,27:17.0
11,0,27:18.6
12,0,27:18.6
-13,1,27:18.6
-12,1,27:18.6
0,1,27:17.0
1,1,27:17.0
11,1,27:18.6
12,1,27:18.6
-13,2,27:18.6
-12,2,27:18.6
11,2,27:18.6
-13,3,27:18.6
11,3,27:18.6
-13,4,27:18.6
11,4,27:18.6
-16,5,27:18.6
-15,5,27:18.6
-14,5,27:18.6
-13,5,27:18.6
-12,5,27:18.6
11,5,27:18.6
-11,6,27:18.6
10,6,27:18.6
11,6,27:18.6
-10,7,27:18.6
-9,7,27:18.6
10,7,27:18.6
11,7,27:18.6
-9,8,27:18.6
-8,8,27:18.6
9,8,27:18.6
10,8,27:18.6
11,8,27:18.6
-7,9,27:18.6
-6,9,27:18.6
7,9,27:18.6
8,9,27:18.6
9,9,27:18.6
12,9,27:18.6
-5,10,27:18.6
6,10,27:18.6
7,10,27:18.6
13,10,27:18.6
-5,11,27:18.6
-4,11,27:18.6
3,11,27:18.6
4,11,27:18.6
5,11,27:18.6
14,11,27:18.6
-3,12,27:18.6
-2,12,27:18.6
0,12,27:18.6
1,12,27:18.6
2,12,27:18.6
-2,13,27:18.6
-1,13,27:18.6
0,13,27:18.6
-2,14,27:18.6
-2,15,27:18.6
-2,16,27:18.6
3,-16,28:18.6
2,-15,28:18.6
3,-15,28:18.6
1,-14,28:18.6
2,-14,28:18.6
-1,-13,28:18.6
0,-13,28:18.6
1,-13,28:18.6
2,-13,28:18.6
-4,-12,28:18.6
-3,-12,28:18.6
-2,-12,28:18.6
2,-12,28:18.6
3,-12,28:18.6
-12,-11,28:18.6
-6,-11,28:18.6
-5,-11,28:18.6
-4,-11,28:18.6
3,-11,28:18.6
4,-11,28:18.6
-12,-10,28:18.6
-8,-10,28:18.6
-7,-10,28:18.6
5,-10,28:18.6
6,-10,28:18.6
-11,-9,28:18.6
-10,-9,28:18.6
-9,-9,28:18.6
-8,-9,28:18.6
6,-9,28:18.6
7,-9,28:18.6
-11,-8,28:18.6
-10,-8,28:18.6
7,-8,28:18.6
8,-8,28:18.6
-11,-7,28:18.6
8,-7,28:18.6
9,-7,28:18.6
-11,-6,28:18.6
9,-6,28:18.6
10,-6,28:18.6
11,-6,28:18.6
15,-6,28:18.6
16,-6,28:18.6
17,-6,28:18.6
-11,-5,28:18.6
11,-5,28:18.6
12,-5,28:18.6
13,-5,28:18.6
14,-5,28:18.6
15,-5,28:18.6
-12,-4,28:18.6
12,-4,28:18.6
-12,-3,28:18.6
-1,-3,28:17.0
0,-3,28:17.0
1,-3,28:17.0
2,-3,28:17.0
11,-3,28:18.6
12,-3,28:18.6
-12,-2,28:18.6
-1,-2,28:17.0
2,-2,28:17.0
3,-2,28:17.0
11,-2,28:18.6
12,-2,28:18.6
-12,-1,28:18.6
-1,-1,28:17.0
2,-1,28:17.0
11,-1,28:18.6
-12,0,28:18.6
-1,0,28:17.0
0,0,28:17.0
1,0,28:17.0
2,0,28:17.0
11,0,28:18.6
-12,1,28:18.6
0,1,28:17.0
1,1,28:17.0
11,1,28:18.6
-12,2,28:18.6
11,2,28:18.6
-12,3,28:18.6
10,3,28:18.6
11,3,28:18.6
-13,4,28:18.6
-12,4,28:18.6
10,4,28:18.6
11,4,28:18.6
-16,5,28:18.6
-15,5,28:18.6
-14,5,28:18.6
-12,5,28:18.6
-11,5,28:18.6
-17,6,28:18.6
-11,6,28:18.6
10,6,28:18.6
-9,7,28:18.6
-8,7,28:18.6
10,7,28:18.6
-8,8,28:18.6
-7,8,28:18.6
8,8,28:18.6
9,8,28:18.6
10,8,28:18.6
11,8,28:18.6
-7,9,28:18.6
-6,9,28:18.6
6,9,28:18.6
7,9,28:18.6
8,9,28:18.6
12,9,28:18.6
-5,10,28:18.6
-4,10,28:18.6
4,10,28:18.6
6,10,28:18.6
13,10,28:18.6
14,10,28:18.6
-4,11,28:18.6
-3,11,28:18.6
1,11,28:18.6
3,11,28:18.6
4,11,28:18.6
14,11,28:18.6
-3,12,28:18.6
-2,12,28:18.6
-1,12,28:18.6
0,12,28:18.6
1,12,28:18.6
-1,13,28:18.6
-2,14,28:18.6
-2,15,28:18.6
2,-15,29:18.6
3,-15,29:18.6
1,-14,29:18.6
2,-14,29:18.6
0,-13,29:18.6
1,-13,29:18.6
-3,-12,29:18.6
-2,-12,29:18.6
-1,-12,29:18.6
1,-12,29:18.6
2,-12,29:18.6
-12,-11,29:18.6
-5,-11,29:18.6
-4,-11,29:18.6
-3,-11,29:18.6
2,-11,29:18.6
3,-11,29:18.6
4,-11,29:18.6
-12,-10,29:18.6
-7,-10,29:18.6
-6,-10,29:18.6
4,-10,29:18.6
5,-10,29:18.6
-11,-9,29:18.6
-9,-9,29:18.6
-8,-9,29:18.6
5,-9,29:18.6
6,-9,29:18.6
-11,-8,29:18.6
-10,-8,29:18.6
-9,-8,29:18.6
6,-8,29:18.6
7,-8,29:18.6
-11,-7,29:18.6
7,-7,29:18.6
8,-7,29:18.6
-11,-6,29:18.6
9,-6,29:18.6
10,-6,29:18.6
15,-6,29:18.6
-11,-5,29:18.6
10,-5,29:18.6
11,-5,29:18.6
13,-5,29:18.6
14,-5,29:18.6
11,-4,29:18.6
12,-4,29:18.6
-12,-3,29:18.6
-11,-3,29:18.6
-1,-3,29:17.0
0,-3,29:17.0
1,-3,29:17.0
2,-3,29:18.4
11,-3,29:18.6
-12,-2,29:18.6
-11,-2,29:18.6
-1,-2,29:17.0
2,-2,29:17.0
11,-2,29:18.6
-12,-1,29:18.6
-1,-1,29:17.0
2,-1,29:17.0
11,-1,29:18.6
-12,0,29:18.6
-1,0,29:17.0
0,0,29:17.0
1,0,29:17.0
2,0,29:17.0
10,0,29:18.6
11,0,29:18.6
-12,1,29:18.6
0,1,29:17.0
10,1,29:18.6
11,1,29:18.6
-12,2,29:18.6
10,2,29:18.6
-12,3,29:18.6
10,3,29:18.6
-13,4,29:18.6
-12,4,29:18.6
10,4,29:18.6
-16,5,29:18.6
-15,5,29:18.6
-14,5,29:18.6
-11,5,29:18.6
-10,5,29:18.6
-17,6,29:18.6
-9,6,29:18.6
9,6,29:18.6
10,6,29:18.6
-9,7,29:18.6
-8,7,29:18.6
9,7,29:18.6
10,7,29:18.6
-8,8,29:18.6
-7,8,29:18.6
-6,8,29:18.6
7,8,29:18.6
8,8,29:18.6
11,8,29:18.6
-6,9,29:18.6
-5,9,29:18.6
5,9,29:18.6
6,9,29:18.6
7,9,29:18.6
12,9,29:18.6
-5,10,29:18.6
-4,10,29:18.6
3,10,29:18.6
4,10,29:18.6
13,10,29:18.6
-3,11,29:18.6
-2,11,29:18.6
0,11,29:18.6
1,11,29:18.6
3,11,29:18.6
-2,12,29:18.6
-1,12,29:18.6
0,12,29:18.6
-1,13,29:18.6
-2,14,29:18.6
-2,15,29:18.6
2,-15,30:18.6
1,-14,30:18.6
2,-14,30:18.6
1,-13,30:18.6
-2,-12,30:18.6
-1,-12,30:18.6
0,-12,30:18.6
1,-12,30:18.6
-12,-11,30:18.6
-4,-11,30:18.6
-3,-11,30:18.6
-2,-11,30:18.6
1,-11,30:18.6
2,-11,30:18.6
3,-11,30:18.6
-12,-10,30:18.6
-6,-10,30:18.6
-5,-10,30:18.6
3,-10,30:18.6
4,-10,30:18.6
-11,-9,30:18.6
-8,-9,30:18.6
-7,-9,30:18.6
4,-9,30:18.6
5,-9,30:18.6
-11,-8,30:18.6
-9,-8,30:18.6
-8,-8,30:18.6
1,-8,30:18.4
5,-8,30:18.6
6,-8,30:18.6
6,-7,30:18.6
7,-7,30:18.6
8,-7,30:18.6
8,-6,30:18.6
9,-6,30:18.6
-11,-5,30:18.6
1,-5,30:18.4
9,-5,30:18.6
13,-5,30:18.6
14,-5,30:18.6
15,-5,30:18.6
1,-4,30:18.4
11,-4,30:18.6
12,-4,30:18.6
-11,-3,30:18.6
-1,-3,30:17.0
0,-3,30:17.0
1,-3,30:18.4
2,-3,30:18.4
3,-3,30:18.4
-11,-2,30:18.6
-1,-2,30:17.0
1,-2,30:18.4
2,-2,30:17.0
5,-2,30:18.4
6,-2,30:18.4
7,-2,30:18.4
10,-2,30:18.6
-11,-1,30:18.6
-1,-1,30:17.0
1,-1,30:18.4
2,-1,30:17.0
7,-1,30:18.4
8,-1,30:18.4
9,-1,30:18.4
10,-1,30:18.6
-11,0,30:18.6
-1,0,30:17.0
0,0,30:17.0
1,0,30:17.0
2,0,30:17.0
10,0,30:18.6
-12,1,30:18.6
-11,1,30:18.6
0,1,30:17.0
1,1,30:18.4
10,1,30:18.6
-12,2,30:18.6
-11,2,30:18.6
10,2,30:18.6
-12,3,30:18.6
9,3,30:18.6
10,3,30:18.6
-14,4,30:18.6
-13,4,30:18.6
-12,4,30:18.6
-11,4,30:18.6
9,4,30:18.6
-17,5,30:18.6
-16,5,30:18.6
-15,5,30:18.6
-14,5,30:18.6
-11,5,30:18.6
-10,5,30:18.6
9,5,30:18.6
-17,6,30:18.6
-9,6,30:18.6
-8,6,30:18.6
9,6,30:18.6
-8,7,30:18.6
-7,7,30:18.6
7,7,30:18.6
8,7,30:18.6
9,7,30:18.6
10,7,30:18.6
-7,8,30:18.6
-6,8,30:18.6
6,8,30:18.6
7,8,30:18.6
10,8,30:18.6
11,8,30:18.6
-5,9,30:18.6
-4,9,30:18.6
4,9,30:18.6
5,9,30:18.6
6,9,30:18.6
12,9,30:18.6
-4,10,30:18.6
-3,10,30:18.6
2,10,30:18.6
3,10,30:18.6
4,10,30:18.6
13,10,30:18.6
-3,11,30:18.6
-2,11,30:18.6
-1,11,30:18.6
0,11,30:18.6
1,11,30:18.6
-1,12,30:18.6
-1,13,30:18.6
-2,14,30:18.6
-2,15,30:18.6
-2,16,30:18.6
1,-14,31:18.6
2,-14,31:18.6
1,-13,31:18.6
-1,-12,31:18.6
0,-12,31:18.6
-4,-11,31:18.6
-3,-11,31:18.6
-2,-11,31:18.6
-1,-11,31:18.6
0,-11,31:18.6
1,-11,31:18.6
2,-11,31:18.6
-12,-10,31:18.6
-6,-10,31:18.6
-5,-10,31:18.6
-4,-10,31:18.6
1,-10,31:18.4
2,-10,31:18.6
3,-10,31:18.6
-11,-9,31:18.6
-7,-9,31:18.6
-6,-9,31:18.6
1,-9,31:18.4
3,-9,31:18.6
4,-9,31:18.6
-11,-8,31:18.6
-9,-8,31:18.6
-8,-8,31:18.6
1,-8,31:18.4
4,-8,31:18.6
5,-8,31:18.6
1,-7,31:18.4
5,-7,31:18.6
6,-7,31:18.6
7,-7,31:18.6
1,-6,31:18.4
7,-6,31:18.6
8,-6,31:18.6
1,-5,31:18.4
8,-5,31:18.6
13,-5,31:18.6
1,-4,31:18.4
12,-4,31:18.6
-11,-3,31:18.6
-9,-3,31:18.6
-1,-3,31:17.0
0,-3,31:17.0
1,-3,31:18.4
2,-3,31:18.4
3,-3,31:18.4
-11,-2,31:18.6
-1,-2,31:17.0
1,-2,31:18.4
2,-2,31:17.0
4,-2,31:18.4
5,-2,31:18.4
6,-2,31:18.4
7,-2,31:18.4
-11,-1,31:18.6
-1,-1,31:17.0
1,-1,31:18.4
2,-1,31:17.0
7,-1,31:18.4
8,-1,31:18.4
9,-1,31:18.4
10,-1,31:18.6
-11,0,31:18.6
-1,0,31:17.0
0,0,31:17.0
1,0,31:17.0
2,0,31:17.0
9,0,31:18.6
10,0,31:18.6
11,0,31:18.4
12,0,31:18.4
13,0,31:18.4
-11,1,31:18.6
1,1,31:18.4
9,1,31:18.6
15,1,31:18.4
-11,2,31:18.6
1,2,31:18.4
9,2,31:18.6
-11,3,31:18.6
1,3,31:18.4
9,3,31:18.6
-14,4,31:18.6
-13,4,31:18.6
-12,4,31:18.6
-11,4,31:18.6
1,4,31:18.4
9,4,31:18.6
-17,5,31:18.6
-16,5,31:18.6
-15,5,31:18.6
-14,5,31:18.6
-10,5,31:18.6
-9,5,31:18.6
-9,6,31:18.6
-8,6,31:18.6
9,6,31:18.6
-7,7,31:18.6
-6,7,31:18.6
6,7,31:18.6
7,7,31:18.6
8,7,31:18.6
-6,8,31:18.6
-5,8,31:18.6
5,8,31:18.6
6,8,31:18.6
10,8,31:18.6
11,8,31:18.6
-5,9,31:18.6
-4,9,31:18.6
3,9,31:18.6
4,9,31:18.6
5,9,31:18.6
12,9,31:18.6
-3,10,31:18.6
-2,10,31:18.6
1,10,31:18.6
2,10,31:18.6
3,10,31:18.6
-2,11,31:18.6
-1,11,31:18.6
0,11,31:18.6
-1,12,31:18.6
-1,13,31:18.6
-2,14,31:18.6
-1,14,31:18.6
-2,15,31:18.6
-2,16,31:18.6
1,-13,32:18.6
0,-12,32:18.6
1,-12,32:18.4
-3,-11,32:18.6
-2,-11,32:18.6
-1,-11,32:18.6
0,-11,32:18.6
1,-11,32:18.4
-12,-10,32:18.6
-5,-10,32:18.6
-4,-10,32:18.6
-3,-10,32:18.6
1,-10,32:18.6
2,-10,32:18.6
-11,-9,32:18.6
-6,-9,32:18.6
-5,-9,32:18.6
1,-9,32:18.4
2,-9,32:18.6
3,-9,32:18.6
15,-9,32:18.6
-11,-8,32:18.6
-7,-8,32:18.6
1,-8,32:18.4
3,-8,32:18.6
4,-8,32:18.6
15,-8,32:18.6
1,-7,32:18.4
5,-7,32:18.6
6,-7,32:18.6
-7,-6,32:18.6
1,-6,32:18.4
-8,-5,32:18.6
-7,-5,32:18.6
1,-5,32:18.4
-9,-4,32:18.6
-8,-4,32:18.6
1,-4,32:18.4
-10,-3,32:18.6
-9,-3,32:18.6
-1,-3,32:17.0
0,-3,32:17.0
1,-3,32:18.4
2,-3,32:18.4
3,-3,32:18.4
4,-3,32:18.4
-11,-2,32:18.6
-9,-2,32:18.6
-8,-2,32:18.6
-1,-2,32:17.0
1,-2,32:18.4
2,-2,32:17.0
4,-2,32:18.4
5,-2,32:18.4
6,-2,32:18.4
7,-2,32:18.4
-11,-1,32:18.6
-8,-1,32:18.6
-7,-1,32:18.6
-1,-1,32:17.0
1,-1,32:18.4
2,-1,32:17.0
8,-1,32:18.4
9,-1,32:18.4
10,-1,32:18.4
17,-1,32:18.6
-11,0,32:18.6
-7,0,32:18.6
-1,0,32:17.0
0,0,32:17.0
1,0,32:17.0
2,0,32:17.0
11,0,32:18.4
12,0,32:18.4
13,0,32:18.4
14,0,32:18.4
17,0,32:18.6
-11,1,32:18.6
-6,1,32:18.6
1,1,32:18.4
14,1,32:18.4
15,1,32:18.4
16,1,32:18.4
17,1,32:18.6
-11,2,32:18.6
-5,2,32:18.6
1,2,32:18.4
9,2,32:18.6
16,2,32:18.6
17,2,32:18.6
-11,3,32:18.6
1,3,32:18.4
9,3,32:18.6
15,3,32:18.6
-14,4,32:18.6
-13,4,32:18.6
-12,4,32:18.6
-11,4,32:18.6
-10,4,32:18.6
1,4,32:18.4
-17,5,32:18.6
-16,5,32:18.6
-15,5,32:18.6
-9,5,32:18.6
-8,5,32:18.6
1,5,32:18.4
-8,6,32:18.6
-7,6,32:18.6
1,6,32:18.4
-7,7,32:18.6
-6,7,32:18.6
5,7,32:18.6
6,7,32:18.6
7,7,32:18.6
-5,8,32:18.6
-4,8,32:18.6
4,8,32:18.6
5,8,32:18.6
-4,9,32:18.6
-3,9,32:18.6
2,9,32:18.6
3,9,32:18.6
4,9,32:18.6
-3,10,32:18.6
-2,10,32:18.6
1,10,32:18.6
2,10,32:18.6
-1,11,32:18.6
-1,12,32:18.6
-1,13,32:18.6
-2,14,32:18.6
-1,14,32:18.6
-2,15,32:18.6
-2,16,32:18.6
1,-15,33:18.4
1,-14,33:18.4
1,-13,33:18.4
-2,-12,33:18.6
1,-12,33:18.4
-3,-11,33:18.6
-2,-11,33:18.6
-1,-11,33:18.6
0,-11,33:18.6
1,-11,33:18.4
12,-11,33:18.6
13,-11,33:18.6
-4,-10,33:18.6
-3,-10,33:18.6
-2,-10,33:18.6
0,-10,33:18.6
1,-10,33:18.6
14,-10,33:18.6
15,-10,33:18.6
-5,-9,33:18.6
-4,-9,33:18.6
1,-9,33:18.6
2,-9,33:18.6
14,-9,33:18.6
15,-9,33:18.6
-6,-8,33:18.6
-5,-8,33:18.6
1,-8,33:18.4
2,-8,33:18.6
3,-8,33:18.6
15,-8,33:18.6
-6,-7,33:18.6
1,-7,33:18.4
5,-7,33:18.6
-7,-6,33:18.6
-6,-6,33:18.6
1,-6,33:18.4
-8,-5,33:18.6
-7,-5,33:18.6
1,-5,33:18.4
15,-5,33:18.6
-9,-4,33:18.6
-8,-4,33:18.6
1,-4,33:18.4
15,-4,33:18.6
16,-4,33:18.6
-10,-3,33:18.6
-9,-3,33:18.6
-1,-3,33:17.0
0,-3,33:17.0
1,-3,33:18.4
2,-3,33:18.4
3,-3,33:18.4
4,-3,33:18.4
16,-3,33:18.6
-8,-2,33:18.6
-1,-2,33:17.0
1,-2,33:18.4
2,-2,33:17.0
4,-2,33:18.4
5,-2,33:18.4
6,-2,33:18.4
7,-2,33:18.4
16,-2,33:18.6
-8,-1,33:18.6
-7,-1,33:18.6
-1,-1,33:17.0
1,-1,33:18.4
2,-1,33:17.0
8,-1,33:18.4
9,-1,33:18.4
10,-1,33:18.4
11,-1,33:18.4
16,-1,33:18.6
-10,0,33:18.6
-7,0,33:18.6
-6,0,33:18.6
-1,0,33:17.0
0,0,33:17.0
1,0,33:17.0
11,0,33:18.4
12,0,33:18.4
13,0,33:18.4
14,0,33:18.4
16,0,33:18.6
17,0,33:18.6
-6,1,33:18.6
1,1,33:18.4
14,1,33:18.4
15,1,33:18.4
16,1,33:18.6
17,1,33:18.6
-5,2,33:18.6
1,2,33:18.4
15,2,33:18.6
16,2,33:18.6
-4,3,33:18.6
1,3,33:18.4
13,3,33:18.6
14,3,33:18.6
15,3,33:18.6
-14,4,33:18.6
-13,4,33:18.6
-3,4,33:18.6
1,4,33:18.4
11,4,33:18.6
12,4,33:18.6
-9,5,33:18.6
-8,5,33:18.6
1,5,33:18.4
11,5,33:18.6
-7,6,33:18.6
1,6,33:18.4
-6,7,33:18.6
-5,7,33:18.6
-1,7,33:18.6
1,7,33:18.4
5,7,33:18.6
-5,8,33:18.6
-4,8,33:18.6
0,8,33:18.6
1,8,33:18.4
3,8,33:18.6
4,8,33:18.6
5,8,33:18.6
-3,9,33:18.6
1,9,33:18.6
2,9,33:18.6
3,9,33:18.6
-1,10,33:18.6
-1,11,33:18.6
-1,12,33:18.6
-1,13,33:18.6
-2,14,33:18.6
-2,15,33:18.6
2,-17,34:18.6
1,-16,34:18.6
2,-16,34:18.6
3,-16,34:18.6
0,-15,34:18.6
1,-15,34:18.6
2,-15,34:18.4
4,-15,34:18.6
5,-15,34:18.6
-1,-14,34:18.6
0,-14,34:18.6
2,-14,34:18.4
6,-14,34:18.6
7,-14,34:18.6
-1,-13,34:18.6
1,-13,34:18.4
2,-13,34:18.4
8,-13,34:18.6
-2,-12,34:18.6
1,-12,34:18.4
2,-12,34:18.4
10,-12,34:18.6
11,-12,34:18.6
-3,-11,34:18.6
-2,-11,34:18.6
1,-11,34:18.4
11,-11,34:18.6
12,-11,34:18.6
13,-11,34:18.6
-4,-10,34:18.6
-3,-10,34:18.6
1,-10,34:18.4
13,-10,34:18.6
14,-10,34:18.6
15,-10,34:18.6
-5,-9,34:18.6
-4,-9,34:18.6
1,-9,34:18.4
14,-9,34:18.6
-5,-8,34:18.6
-4,-8,34:18.6
1,-8,34:18.4
2,-8,34:18.6
3,-8,34:18.6
14,-8,34:18.6
-6,-7,34:18.6
-5,-7,34:18.6
1,-7,34:18.4
14,-7,34:18.6
-7,-6,34:18.6
-6,-6,34:18.6
1,-6,34:18.4
14,-6,34:18.6
15,-6,34:18.6
-8,-5,34:18.6
-7,-5,34:18.6
1,-5,34:18.4
14,-5,34:18.6
15,-5,34:18.6
-9,-4,34:18.6
-8,-4,34:18.6
1,-4,34:18.4
15,-4,34:18.6
-11,-3,34:18.6
-10,-3,34:18.6
-9,-3,34:18.6
-1,-3,34:17.0
0,-3,34:17.0
1,-3,34:18.4
2,-3,34:18.4
3,-3,34:18.4
4,-3,34:18.4
15,-3,34:18.6
-8,-2,34:18.6
-1,-2,34:17.0
1,-2,34:18.4
2,-2,34:17.0
4,-2,34:18.4
5,-2,34:18.4
6,-2,34:18.4
7,-2,34:18.4
15,-2,34:18.6
-7,-1,34:18.6
-1,-1,34:17.0
1,-1,34:18.4
2,-1,34:17.0
8,-1,34:18.4
9,-1,34:18.4
10,-1,34:18.4
11,-1,34:18.4
15,-1,34:18.6
16,-1,34:18.6
-7,0,34:18.6
-6,0,34:18.6
-1,0,34:17.0
0,0,34:17.0
1,0,34:17.0
11,0,34:18.4
12,0,34:18.4
13,0,34:18.4
14,0,34:18.4
15,0,34:18.6
16,0,34:18.6
-6,1,34:18.6
-5,1,34:18.6
1,1,34:18.4
15,1,34:18.6
16,1,34:18.6
17,1,34:18.6
-5,2,34:18.6
1,2,34:18.4
14,2,34:18.6
15,2,34:18.6
17,2,34:18.6
-4,3,34:18.6
1,3,34:18.4
12,3,34:18.6
13,3,34:18.6
-3,4,34:18.6
1,4,34:18.4
11,4,34:18.6
12,4,34:18.6
-7,5,34:18.6
-3,5,34:18.6
-2,5,34:18.6
1,5,34:18.4
9,5,34:18.6
-7,6,34:18.6
-2,6,34:18.6
-1,6,34:18.6
1,6,34:18.4
7,6,34:18.6
8,6,34:18.6
-5,7,34:18.6
-1,7,34:18.6
0,7,34:18.6
1,7,34:18.4
5,7,34:18.6
6,7,34:18.6
0,8,34:18.6
1,8,34:18.4
3,8,34:18.6
4,8,34:18.6
5,8,34:18.6
1,9,34:18.6
2,9,34:18.6
3,9,34:18.6
1,10,34:18.6
-1,12,34:18.6
-1,13,34:18.6
-1,14,34:18.6
1,-17,35:18.6
1,-16,35:18.6
2,-16,35:18.6
3,-16,35:18.6
0,-15,35:18.6
1,-15,35:18.6
2,-15,35:18.4
3,-15,35:18.6
4,-15,35:18.6
0,-14,35:18.6
2,-14,35:18.4
5,-14,35:18.6
6,-14,35:18.6
-1,-13,35:18.6
2,-13,35:18.4
6,-13,35:18.6
7,-13,35:18.6
8,-13,35:18.6
-2,-12,35:18.6
-1,-12,35:18.6
2,-12,35:18.4
8,-12,35:18.6
9,-12,35:18.6
10,-12,35:18.6
-2,-11,35:18.6
2,-11,35:18.4
10,-11,35:18.6
11,-11,35:18.6
12,-11,35:18.6
-3,-10,35:18.6
2,-10,35:18.4
12,-10,35:18.6
13,-10,35:18.6
14,-10,35:18.6
-4,-9,35:18.6
1,-9,35:18.4
2,-9,35:18.4
14,-9,35:18.6
-5,-8,35:18.6
1,-8,35:18.4
2,-8,35:18.4
14,-8,35:18.6
-6,-7,35:18.6
1,-7,35:18.4
14,-7,35:18.6
-7,-6,35:18.6
1,-6,35:18.4
14,-6,35:18.6
-8,-5,35:18.6
1,-5,35:18.4
14,-5,35:18.6
-9,-4,35:18.6
1,-4,35:18.4
14,-4,35:18.6
-12,-3,35:18.6
-11,-3,35:18.6
-10,-3,35:18.6
-9,-3,35:18.6
-8,-3,35:18.6
-1,-3,35:17.0
0,-3,35:17.0
1,-3,35:18.4
2,-3,35:18.4
3,-3,35:18.4
4,-3,35:18.4
14,-3,35:18.6
-8,-2,35:18.6
-1,-2,35:17.0
1,-2,35:18.4
2,-2,35:17.0
5,-2,35:18.4
6,-2,35:18.4
7,-2,35:18.4
8,-2,35:18.4
14,-2,35:18.6
15,-2,35:18.6
-7,-1,35:18.6
-1,-1,35:17.0
1,-1,35:17.0
8,-1,35:18.4
9,-1,35:18.4
10,-1,35:18.4
11,-1,35:18.4
14,-1,35:18.6
15,-1,35:18.6
-6,0,35:18.6
-1,0,35:17.0
0,0,35:17.0
1,0,35:17.0
11,0,35:18.4
12,0,35:18.4
13,0,35:18.4
14,0,35:18.4
15,0,35:18.6
-6,1,35:18.6
-5,1,35:18.6
1,1,35:18.4
14,1,35:18.6
15,1,35:18.6
16,1,35:18.6
17,1,35:18.6
-5,2,35:18.6
-4,2,35:18.6
1,2,35:18.4
12,2,35:18.6
13,2,35:18.6
14,2,35:18.6
17,2,35:18.6
-4,3,35:18.6
-3,3,35:18.6
1,3,35:18.4
11,3,35:18.6
12,3,35:18.6
-3,4,35:18.6
1,4,35:18.4
10,4,35:18.6
11,4,35:18.6
-2,5,35:18.6
1,5,35:18.4
8,5,35:18.6
9,5,35:18.6
-1,6,35:18.6
1,6,35:18.4
6,6,35:18.6
7,6,35:18.6
8,6,35:18.6
-1,7,35:18.6
0,7,35:18.6
1,7,35:18.4
4,7,35:18.6
5,7,35:18.6
6,7,35:18.6
0,8,35:18.6
1,8,35:18.6
2,8,35:18.6
3,8,35:18.6
4,8,35:18.6
1,9,35:18.6
2,9,35:18.6
1,10,35:18.6
-1,12,35:18.6
-1,13,35:18.6
-1,14,35:18.6
1,-17,36:18.6
1,-16,36:18.6
2,-16,36:18.6
1,-15,36:18.6
2,-15,36:18.4
3,-15,36:18.6
4,-15,36:18.6
0,-14,36:18.6
2,-14,36:18.4
4,-14,36:18.6
5,-14,36:18.6
-1,-13,36:18.6
0,-13,36:18.6
2,-13,36:18.4
6,-13,36:18.6
7,-13,36:18.6
-1,-12,36:18.6
2,-12,36:18.4
7,-12,36:18.6
8,-12,36:18.6
9,-12,36:18.6
-2,-11,36:18.6
2,-11,36:18.4
9,-11,36:18.6
10,-11,36:18.6
11,-11,36:18.6
-3,-10,36:18.6
2,-10,36:18.4
11,-10,36:18.6
12,-10,36:18.6
13,-10,36:18.6
14,-10,36:18.6
15,-10,36:18.6
-4,-9,36:18.6
2,-9,36:18.4
13,-9,36:18.6
-5,-8,36:18.6
2,-8,36:18.4
13,-8,36:18.6
-6,-7,36:18.6
-5,-7,36:18.6
2,-7,36:18.4
13,-7,36:18.6
-7,-6,36:18.6
-6,-6,36:18.6
-5,-6,36:18.6
-4,-6,36:18.6
-3,-6,36:18.6
-2,-6,36:18.6
2,-6,36:18.4
13,-6,36:18.6
14,-6,36:18.6
-8,-5,36:18.6
-7,-5,36:18.6
-6,-5,36:18.6
-5,-5,36:18.6
-4,-5,36:18.6
-3,-5,36:18.6
-2,-5,36:18.6
-1,-5,36:18.6
0,-5,36:18.6
1,-5,36:18.4
2,-5,36:18.4
13,-5,36:18.6
14,-5,36:18.6
-10,-4,36:18.6
-9,-4,36:18.6
-8,-4,36:18.6
-7,-4,36:18.6
-6,-4,36:18.6
-5,-4,36:18.6
-4,-4,36:18.6
-3,-4,36:18.6
-2,-4,36:18.6
-1,-4,36:18.6
0,-4,36:18.6
1,-4,36:18.6
2,-4,36:18.6
3,-4,36:18.6
13,-4,36:18.6
14,-4,36:18.6
-13,-3,36:18.6
-12,-3,36:18.6
-11,-3,36:18.6
-9,-3,36:18.6
-8,-3,36:18.6
-7,-3,36:18.6
-6,-3,36:18.6
-5,-3,36:18.6
-4,-3,36:18.6
-3,-3,36:18.6
-2,-3,36:18.6
-1,-3,36:18.6
0,-3,36:18.6
1,-3,36:18.6
2,-3,36:18.4
3,-3,36:18.4
4,-3,36:18.4
14,-3,36:18.6
-8,-2,36:18.6
-7,-2,36:18.6
-6,-2,36:18.6
-5,-2,36:18.6
-4,-2,36:18.6
-3,-2,36:18.6
-2,-2,36:18.6
-1,-2,36:17.0
0,-2,36:18.6
1,-2,36:17.0
2,-2,36:18.4
5,-2,36:18.4
6,-2,36:18.4
7,-2,36:18.4
8,-2,36:18.4
14,-2,36:18.6
-7,-1,36:18.6
-6,-1,36:18.6
-5,-1,36:18.6
-4,-1,36:18.6
-3,-1,36:18.6
-2,-1,36:18.6
-1,-1,36:17.0
1,-1,36:17.0
8,-1,36:18.4
9,-1,36:18.4
10,-1,36:18.4
11,-1,36:18.4
14,-1,36:18.6
-6,0,36:18.6
-5,0,36:18.6
-4,0,36:18.6
-1,0,36:17.0
0,0,36:17.0
1,0,36:18.4
12,0,36:18.4
13,0,36:18.4
14,0,36:18.6
-5,1,36:18.6
1,1,36:18.4
13,1,36:18.6
14,1,36:18.6
15,1,36:18.6
16,1,36:18.6
-4,2,36:18.6
1,2,36:18.4
11,2,36:18.6
12,2,36:18.6
13,2,36:18.6
17,2,36:18.6
-4,3,36:18.6
-3,3,36:18.6
1,3,36:18.4
10,3,36:18.6
11,3,36:18.6
-3,4,36:18.6
-2,4,36:18.6
1,4,36:18.4
8,4,36:18.6
9,4,36:18.6
10,4,36:18.6
-2,5,36:18.6
-1,5,36:18.6
1,5,36:18.4
7,5,36:18.6
8,5,36:18.6
-1,6,36:18.6
0,6,36:18.6
1,6,36:18.4
5,6,36:18.6
6,6,36:18.6
7,6,36:18.6
0,7,36:18.6
1,7,36:18.4
4,7,36:18.6
5,7,36:18.6
1,8,36:18.6
2,8,36:18.6
3,8,36:18.6
1,9,36:18.6
1,10,36:18.6
1,-17,37:18.6
1,-16,37:18.6
1,-15,37:18.6
2,-15,37:18.6
3,-15,37:18.6
0,-14,37:18.6
1,-14,37:18.6
2,-14,37:18.4
3,-14,37:18.6
4,-14,37:18.6
5,-14,37:18.6
0,-13,37:18.6
2,-13,37:18.4
5,-13,37:18.6
6,-13,37:18.6
-1,-12,37:18.6
2,-12,37:18.4
7,-12,37:18.6
8,-12,37:18.6
-2,-11,37:18.6
-1,-11,37:18.6
0,-11,37:18.6
2,-11,37:18.4
8,-11,37:18.6
9,-11,37:18.6
10,-11,37:18.6
-3,-10,37:18.6
-2,-10,37:18.6
-1,-10,37:18.6
0,-10,37:18.6
1,-10,37:18.6
2,-10,37:18.4
3,-10,37:18.6
10,-10,37:18.6
11,-10,37:18.6
12,-10,37:18.6
14,-10,37:18.6
15,-10,37:18.6
-4,-9,37:18.6
-3,-9,37:18.6
-2,-9,37:18.6
-1,-9,37:18.6
0,-9,37:18.6
1,-9,37:18.6
2,-9,37:18.6
3,-9,37:18.6
4,-9,37:18.6
5,-9,37:18.6
6,-9,37:18.6
7,-9,37:18.6
12,-9,37:18.6
13,-9,37:18.6
-5,-8,37:18.6
-4,-8,37:18.6
-3,-8,37:18.6
-2,-8,37:18.6
-1,-8,37:18.6
0,-8,37:18.6
1,-8,37:18.6
2,-8,37:18.6
3,-8,37:18.6
4,-8,37:18.6
5,-8,37:18.6
6,-8,37:18.6
7,-8,37:18.6
8,-8,37:18.6
9,-8,37:18.6
10,-8,37:18.6
13,-8,37:18.6
-6,-7,37:18.6
-5,-7,37:18.6
-4,-7,37:18.6
-3,-7,37:18.6
-2,-7,37:18.6
-1,-7,37:18.6
0,-7,37:18.6
1,-7,37:18.6
2,-7,37:18.6
3,-7,37:18.6
4,-7,37:18.6
5,-7,37:18.6
6,-7,37:18.6
7,-7,37:18.6
8,-7,37:18.6
9,-7,37:18.6
10,-7,37:18.6
11,-7,37:18.6
13,-7,37:18.6
-7,-6,37:18.6
-6,-6,37:18.6
-2,-6,37:18.6
-1,-6,37:18.6
0,-6,37:18.6
1,-6,37:18.6
2,-6,37:18.6
3,-6,37:18.6
4,-6,37:18.6
5,-6,37:18.6
7,-6,37:18.6
8,-6,37:18.6
9,-6,37:18.6
10,-6,37:18.6
11,-6,37:18.6
12,-6,37:18.6
13,-6,37:18.6
-8,-5,37:18.6
-7,-5,37:18.6
0,-5,37:18.6
1,-5,37:18.6
2,-5,37:18.6
3,-5,37:18.6
4,-5,37:18.6
5,-5,37:18.6
6,-5,37:18.6
7,-5,37:18.6
8,-5,37:18.6
9,-5,37:18.6
10,-5,37:18.6
11,-5,37:18.6
12,-5,37:18.6
13,-5,37:18.6
-9,-4,37:18.6
-8,-4,37:18.6
3,-4,37:18.6
4,-4,37:18.6
5,-4,37:18.6
6,-4,37:18.6
7,-4,37:18.6
8,-4,37:18.6
9,-4,37:18.6
10,-4,37:18.6
11,-4,37:18.6
12,-4,37:18.6
13,-4,37:18.6
-13,-3,37:18.6
-12,-3,37:18.6
-11,-3,37:18.6
-10,-3,37:18.6
-8,-3,37:18.6
-1,-3,37:17.0
0,-3,37:17.0
1,-3,37:17.0
4,-3,37:18.6
5,-3,37:18.6
6,-3,37:18.6
7,-3,37:18.6
8,-3,37:18.6
9,-3,37:18.6
10,-3,37:18.6
11,-3,37:18.6
12,-3,37:18.6
13,-3,37:18.6
-8,-2,37:18.6
-7,-2,37:18.6
-1,-2,37:17.0
1,-2,37:17.0
2,-2,37:18.6
3,-2,37:18.6
4,-2,37:18.6
5,-2,37:18.6
6,-2,37:18.6
7,-2,37:18.6
8,-2,37:18.6
9,-2,37:18.6
10,-2,37:18.6
11,-2,37:18.6
12,-2,37:18.6
13,-2,37:18.6
-7,-1,37:18.6
-6,-1,37:18.6
-2,-1,37:18.6
-1,-1,37:17.0
0,-1,37:18.6
1,-1,37:17.0
2,-1,37:18.6
3,-1,37:18.6
4,-1,37:18.6
5,-1,37:18.6
6,-1,37:18.6
7,-1,37:18.6
8,-1,37:18.6
9,-1,37:18.6
10,-1,37:18.6
11,-1,37:18.6
12,-1,37:18.6
13,-1,37:18.6
-6,0,37:18.6
-5,0,37:18.6
-4,0,37:18.6
-3,0,37:18.6
-2,0,37:18.6
-1,0,37:18.6
0,0,37:17.0
1,0,37:18.6
2,0,37:18.6
3,0,37:18.6
4,0,37:18.6
5,0,37:18.6
6,0,37:18.6
7,0,37:18.6
8,0,37:18.6
9,0,37:18.6
10,0,37:18.6
11,0,37:18.6
12,0,37:18.6
13,0,37:18.6
14,0,37:18.6
-5,1,37:18.6
-4,1,37:18.6
-3,1,37:18.6
-2,1,37:18.6
-1,1,37:18.6
0,1,37:18.6
1,1,37:18.6
2,1,37:18.6
3,1,37:18.6
4,1,37:18.6
5,1,37:18.6
6,1,37:18.6
7,1,37:18.6
8,1,37:18.6
9,1,37:18.6
10,1,37:18.6
11,1,37:18.6
12,1,37:18.6
13,1,37:18.6
15,1,37:18.6
16,1,37:18.6
-4,2,37:18.6
-3,2,37:18.6
-2,2,37:18.6
-1,2,37:18.6
0,2,37:18.6
1,2,37:18.6
2,2,37:18.6
3,2,37:18.6
4,2,37:18.6
5,2,37:18.6
6,2,37:18.6
7,2,37:18.6
8,2,37:18.6
9,2,37:18.6
10,2,37:18.6
11,2,37:18.6
17,2,37:18.6
18,2,37:18.6
-3,3,37:18.6
-2,3,37:18.6
-1,3,37:18.6
0,3,37:18.6
1,3,37:18.6
2,3,37:18.6
3,3,37:18.6
4,3,37:18.6
5,3,37:18.6
6,3,37:18.6
7,3,37:18.6
8,3,37:18.6
9,3,37:18.6
10,3,37:18.6
-2,4,37:18.6
-1,4,37:18.6
0,4,37:18.6
1,4,37:18.6
2,4,37:18.6
7,4,37:18.6
8,4,37:18.6
9,4,37:18.6
-2,5,37:18.6
-1,5,37:18.6
1,5,37:18.4
6,5,37:18.6
7,5,37:18.6
-1,6,37:18.6
0,6,37:18.6
1,6,37:18.4
4,6,37:18.6
5,6,37:18.6
6,6,37:18.6
0,7,37:18.6
1,7,37:18.6
3,7,37:18.6
4,7,37:18.6
1,8,37:18.6
2,8,37:18.6
1,9,37:18.6
1,10,37:18.6
1,11,37:18.6
0,-18,38:18.6
1,-17,38:18.6
1,-16,38:18.6
1,-15,38:18.6
2,-15,38:18.6
0,-14,38:18.6
1,-14,38:18.6
2,-14,38:18.6
3,-14,38:18.6
4,-14,38:18.6
0,-13,38:18.6
1,-13,38:18.6
2,-13,38:18.6
3,-13,38:18.6
4,-13,38:18.6
5,-13,38:18.6
6,-13,38:18.6
-1,-12,38:18.6
0,-12,38:18.6
1,-12,38:18.6
2,-12,38:18.6
3,-12,38:18.6
4,-12,38:18.6
5,-12,38:18.6
6,-12,38:18.6
7,-12,38:18.6
-2,-11,38:18.6
-1,-11,38:18.6
0,-11,38:18.6
1,-11,38:18.6
2,-11,38:18.6
3,-11,38:18.6
4,-11,38:18.6
5,-11,38:18.6
6,-11,38:18.6
7,-11,38:18.6
8,-11,38:18.6
9,-11,38:18.6
-3,-10,38:18.6
-2,-10,38:18.6
2,-10,38:18.6
3,-10,38:18.6
4,-10,38:18.6
5,-10,38:18.6
6,-10,38:18.6
7,-10,38:18.6
8,-10,38:18.6
9,-10,38:18.6
10,-10,38:18.6
11,-10,38:18.6
14,-10,38:18.6
15,-10,38:18.6
-4,-9,38:18.6
-3,-9,38:18.6
6,-9,38:18.6
7,-9,38:18.6
8,-9,38:18.6
9,-9,38:18.6
10,-9,38:18.6
11,-9,38:18.6
12,-9,38:18.6
13,-9,38:18.6
-5,-8,38:18.6
-4,-8,38:18.6
10,-8,38:18.6
11,-8,38:18.6
12,-8,38:18.6
13,-8,38:18.6
-6,-7,38:18.6
-5,-7,38:18.6
11,-7,38:18.6
12,-7,38:18.6
13,-7,38:18.6
-7,-6,38:18.6
-6,-6,38:18.6
12,-6,38:18.6
13,-6,38:18.6
-7,-5,38:18.6
12,-5,38:18.6
13,-5,38:18.6
-9,-4,38:18.6
-8,-4,38:18.6
12,-4,38:18.6
13,-4,38:18.6
-13,-3,38:18.6
-12,-3,38:18.6
-11,-3,38:18.6
-10,-3,38:18.6
-9,-3,38:18.6
-8,-3,38:18.6
-1,-3,38:17.0
0,-3,38:17.0
1,-3,38:17.0
12,-3,38:18.6
13,-3,38:18.6
-7,-2,38:18.6
-1,-2,38:17.0
1,-2,38:17.0
12,-2,38:18.6
13,-2,38:18.6
-6,-1,38:18.6
-1,-1,38:17.0
1,-1,38:17.0
12,-1,38:18.6
13,-1,38:18.6
-6,0,38:18.6
-5,0,38:18.6
0,0,38:17.0
12,0,38:18.6
13,0,38:18.6
14,0,38:18.6
-5,1,38:18.6
-4,1,38:18.6
10,1,38:18.6
11,1,38:18.6
12,1,38:18.6
14,1,38:18.6
15,1,38:18.6
16,1,38:18.6
-4,2,38:18.6
-3,2,38:18.6
9,2,38:18.6
10,2,38:18.6
17,2,38:18.6
18,2,38:18.6
-3,3,38:18.6
-2,3,38:18.6
6,3,38:18.6
7,3,38:18.6
8,3,38:18.6
9,3,38:18.6
-2,4,38:18.6
1,4,38:18.6
2,4,38:18.6
3,4,38:18.6
4,4,38:18.6
5,4,38:18.6
6,4,38:18.6
7,4,38:18.6
-1,5,38:18.6
0,5,38:18.6
1,5,38:18.6
2,5,38:18.6
3,5,38:18.6
4,5,38:18.6
5,5,38:18.6
6,5,38:18.6
0,6,38:18.6
1,6,38:18.6
2,6,38:18.6
3,6,38:18.6
4,6,38:18.6
5,6,38:18.6
1,7,38:18.6
2,7,38:18.6
3,7,38:18.6
1,8,38:18.6
2,8,38:18.6
1,9,38:18.6
1,10,38:18.6
1,11,38:18.6
1,12,38:18.6
0,-18,39:18.6
0,-17,39:18.6
1,-17,39:18.6
1,-16,39:18.6
1,-15,39:18.6
1,-14,39:18.6
2,-14,39:18.6
3,-14,39:18.6
0,-13,39:18.6
1,-13,39:18.6
3,-13,39:18.6
4,-13,39:18.6
5,-13,39:18.6
-1,-12,39:18.6
0,-12,39:18.6
5,-12,39:18.6
6,-12,39:18.6
-2,-11,39:18.6
-1,-11,39:18.6
6,-11,39:18.6
7,-11,39:18.6
8,-11,39:18.6
-3,-10,39:18.6
-2,-10,39:18.6
8,-10,39:18.6
9,-10,39:18.6
10,-10,39:18.6
14,-10,39:18.6
15,-10,39:18.6
-4,-9,39:18.6
-3,-9,39:18.6
10,-9,39:18.6
11,-9,39:18.6
12,-9,39:18.6
13,-9,39:18.6
-4,-8,39:18.6
11,-8,39:18.6
12,-8,39:18.6
-5,-7,39:18.6
11,-7,39:18.6
12,-7,39:18.6
-6,-6,39:18.6
11,-6,39:18.6
12,-6,39:18.6
-7,-5,39:18.6
-6,-5,39:18.6
12,-5,39:18.6
-8,-4,39:18.6
-7,-4,39:18.6
12,-4,39:18.6
-13,-3,39:18.6
-12,-3,39:18.6
-11,-3,39:18.6
-10,-3,39:18.6
-9,-3,39:18.6
-8,-3,39:18.6
-7,-3,39:18.6
-1,-3,39:17.0
0,-3,39:17.0
12,-3,39:18.6
-7,-2,39:18.6
-6,-2,39:18.6
-1,-2,39:17.0
1,-2,39:17.0
12,-2,39:18.6
-6,-1,39:18.6
-1,-1,39:17.0
0,-1,39:17.0
1,-1,39:17.0
12,-1,39:18.6
-5,0,39:18.6
0,0,39:17.0
11,0,39:18.6
12,0,39:18.6
13,0,39:18.6
14,0,39:18.6
-4,1,39:18.6
10,1,39:18.6
11,1,39:18.6
14,1,39:18.6
15,1,39:18.6
16,1,39:18.6
-4,2,39:18.6
-3,2,39:18.6
8,2,39:18.6
9,2,39:18.6
16,2,39:18.6
17,2,39:18.6
18,2,39:18.6
-3,3,39:18.6
-2,3,39:18.6
7,3,39:18.6
8,3,39:18.6
18,3,39:18.6
-2,4,39:18.6
-1,4,39:18.6
5,4,39:18.6
6,4,39:18.6
7,4,39:18.6
-1,5,39:18.6
0,5,39:18.6
4,5,39:18.6
5,5,39:18.6
0,6,39:18.6
1,6,39:18.6
2,6,39:18.6
3,6,39:18.6
4,6,39:18.6
1,7,39:18.6
2,7,39:18.6
1,8,39:18.6
1,9,39:18.6
1,10,39:18.6
1,11,39:18.6
0,12,39:18.6
0,-18,40:18.6
0,-17,40:18.6
1,-16,40:18.6
1,-15,40:18.6
1,-14,40:18.6
2,-14,40:18.6
0,-13,40:18.6
1,-13,40:18.6
2,-13,40:18.6
3,-13,40:18.6
0,-12,40:18.6
3,-12,40:18.6
4,-12,40:18.6
5,-12,40:18.6
-1,-11,40:18.6
5,-11,40:18.6
6,-11,40:18.6
7,-11,40:18.6
-2,-10,40:18.6
7,-10,40:18.6
8,-10,40:18.6
14,-10,40:18.6
15,-10,40:18.6
-3,-9,40:18.6
8,-9,40:18.6
9,-9,40:18.6
10,-9,40:18.6
12,-9,40:18.6
13,-9,40:18.6
-4,-8,40:18.6
-3,-8,40:18.6
10,-8,40:18.6
11,-8,40:18.6
-5,-7,40:18.6
-4,-7,40:18.6
11,-7,40:18.6
-6,-6,40:18.6
-5,-6,40:18.6
11,-6,40:18.6
-7,-5,40:18.6
-6,-5,40:18.6
11,-5,40:18.6
-7,-4,40:18.6
11,-4,40:18.6
-11,-3,40:18.6
-10,-3,40:18.6
-9,-3,40:18.6
-8,-3,40:18.6
-7,-3,40:18.6
-1,-3,40:17.0
0,-3,40:17.0
11,-3,40:18.6
-7,-2,40:18.6
-6,-2,40:18.6
-1,-2,40:17.0
1,-2,40:17.0
11,-2,40:18.6
-6,-1,40:18.6
-5,-1,40:18.6
-1,-1,40:17.0
0,-1,40:17.0
1,-1,40:17.0
11,-1,40:18.6
-5,0,40:18.6
-4,0,40:18.6
10,0,40:18.6
11,0,40:18.6
12,0,40:18.6
13,0,40:18.6
-4,1,40:18.6
9,1,40:18.6
10,1,40:18.6
14,1,40:18.6
15,1,40:18.6
16,1,40:18.6
-3,2,40:18.6
7,2,40:18.6
8,2,40:18.6
9,2,40:18.6
16,2,40:18.6
17,2,40:18.6
18,2,40:18.6
-2,3,40:18.6
6,3,40:18.6
7,3,40:18.6
18,3,40:18.6
-2,4,40:18.6
-1,4,40:18.6
4,4,40:18.6
5,4,40:18.6
6,4,40:18.6
-1,5,40:18.6
0,5,40:18.6
3,5,40:18.6
4,5,40:18.6
0,6,40:18.6
1,6,40:18.6
2,6,40:18.6
3,6,40:18.6
1,7,40:18.6
1,8,40:18.6
1,9,40:18.6
1,10,40:18.6
0,11,40:18.6
1,11,40:18.6
0,12,40:18.6
0,-17,41:18.6
0,-16,41:18.6
0,-15,41:18.6
1,-15,41:18.6
1,-14,41:18.6
1,-13,41:18.6
2,-13,41:18.6
0,-12,41:18.6
2,-12,41:18.6
3,-12,41:18.6
4,-12,41:18.6
-1,-11,41:18.6
0,-11,41:18.6
4,-11,41:18.6
5,-11,41:18.6
-2,-10,41:18.6
-1,-10,41:18.6
5,-10,41:18.6
6,-10,41:18.6
7,-10,41:18.6
14,-10,41:18.6
15,-10,41:18.6
-3,-9,41:18.6
-2,-9,41:18.6
7,-9,41:18.6
8,-9,41:18.6
9,-9,41:18.6
12,-9,41:18.6
13,-9,41:18.6
-4,-8,41:18.6
-3,-8,41:18.6
9,-8,41:18.6
10,-8,41:18.6
11,-8,41:18.6
-4,-7,41:18.6
10,-7,41:18.6
-5,-6,41:18.6
10,-6,41:18.6
-6,-5,41:18.6
10,-5,41:18.6
-7,-4,41:18.6
-6,-4,41:18.6
10,-4,41:18.6
11,-4,41:18.6
-11,-3,41:18.6
-10,-3,41:18.6
-9,-3,41:18.6
-8,-3,41:18.6
-7,-3,41:18.6
-1,-3,41:17.0
0,-3,41:17.0
10,-3,41:18.6
11,-3,41:18.6
-6,-2,41:18.6
-1,-2,41:17.0
1,-2,41:17.0
10,-2,41:18.6
11,-2,41:18.6
-6,-1,41:18.6
-5,-1,41:18.6
-1,-1,41:17.0
0,-1,41:17.0
1,-1,41:17.0
10,-1,41:18.6
11,-1,41:18.6
-5,0,41:18.6
-4,0,41:18.6
9,0,41:18.6
10,0,41:18.6
11,0,41:18.6
12,0,41:18.6
13,0,41:18.6
-4,1,41:18.6
-3,1,41:18.6
8,1,41:18.6
9,1,41:18.6
13,1,41:18.6
14,1,41:18.6
15,1,41:18.6
-3,2,41:18.6
-2,2,41:18.6
6,2,41:18.6
7,2,41:18.6
8,2,41:18.6
16,2,41:18.6
17,2,41:18.6
-2,3,41:18.6
-1,3,41:18.6
5,3,41:18.6
6,3,41:18.6
18,3,41:18.6
19,3,41:18.6
-1,4,41:18.6
3,4,41:18.6
4,4,41:18.6
5,4,41:18.6
0,5,41:18.6
2,5,41:18.6
3,5,41:18.6
1,6,41:18.6
2,6,41:18.6
1,7,41:18.6
1,8,41:18.6
1,9,41:18.6
0,10,41:18.6
0,11,41:18.6
0,12,41:18.6
0,-16,42:18.6
0,-15,42:18.6
0,-14,42:18.6
1,-14,42:18.6
1,-13,42:18.6
0,-12,42:18.6
1,-12,42:18.6
2,-12,42:18.6
-1,-11,42:18.6
0,-11,42:18.6
2,-11,42:18.6
3,-11,42:18.6
4,-11,42:18.6
-1,-10,42:18.6
4,-10,42:18.6
5,-10,42:18.6
6,-10,42:18.6
14,-10,42:18.6
15,-10,42:18.6
-2,-9,42:18.6
6,-9,42:18.6
7,-9,42:18.6
8,-9,42:18.6
12,-9,42:18.6
13,-9,42:18.6
-3,-8,42:18.6
8,-8,42:18.6
9,-8,42:18.6
10,-8,42:18.6
11,-8,42:18.6
-4,-7,42:18.6
-3,-7,42:18.6
9,-7,42:18.6
10,-7,42:18.6
-5,-6,42:18.6
-4,-6,42:18.6
9,-6,42:18.6
10,-6,42:18.6
-6,-5,42:18.6
-5,-5,42:18.6
9,-5,42:18.6
10,-5,42:18.6
-7,-4,42:18.6
-6,-4,42:18.6
9,-4,42:18.6
10,-4,42:18.6
-11,-3,42:18.6
-10,-3,42:18.6
-8,-3,42:18.6
-7,-3,42:18.6
-6,-3,42:18.6
-1,-3,42:17.0
0,-3,42:17.0
9,-3,42:18.6
10,-3,42:18.6
-6,-2,42:18.6
-1,-2,42:17.0
0,-2,42:17.0
1,-2,42:17.0
10,-2,42:18.6
-5,-1,42:18.6
-1,-1,42:17.0
0,-1,42:17.0
1,-1,42:17.0
10,-1,42:18.6
-4,0,42:18.6
8,0,42:18.6
9,0,42:18.6
10,0,42:18.6
11,0,42:18.6
12,0,42:18.6
-3,1,42:18.6
7,1,42:18.6
8,1,42:18.6
13,1,42:18.6
14,1,42:18.6
15,1,42:18.6
-3,2,42:18.6
-2,2,42:18.6
5,2,42:18.6
6,2,42:18.6
7,2,42:18.6
15,2,42:18.6
16,2,42:18.6
17,2,42:18.6
-2,3,42:18.6
-1,3,42:18.6
4,3,42:18.6
5,3,42:18.6
18,3,42:18.6
19,3,42:18.6
-1,4,42:18.6
0,4,42:18.6
3,4,42:18.6
4,4,42:18.6
0,5,42:18.6
1,5,42:18.6
2,5,42:18.6
1,6,42:18.6
1,7,42:18.6
0,8,42:18.6
1,8,42:18.6
0,9,42:18.6
0,11,42:18.6
0,-15,43:18.6
0,-14,43:18.6
0,-13,43:18.6
1,-13,43:18.6
1,-12,43:18.6
0,-11,43:18.6
1,-11,43:18.6
2,-11,43:18.6
3,-11,43:18.6
-1,-10,43:18.6
0,-10,43:18.6
3,-10,43:18.6
4,-10,43:18.6
5,-10,43:18.6
14,-10,43:18.6
15,-10,43:18.6
-2,-9,43:18.6
-1,-9,43:18.6
5,-9,43:18.6
6,-9,43:18.6
12,-9,43:18.6
13,-9,43:18.6
-3,-8,43:18.6
-2,-8,43:18.6
6,-8,43:18.6
7,-8,43:18.6
8,-8,43:18.6
10,-8,43:18.6
11,-8,43:18.6
-4,-7,43:18.6
-3,-7,43:18.6
8,-7,43:18.6
9,-7,43:18.6
-4,-6,43:18.6
9,-6,43:18.6
-5,-5,43:18.6
9,-5,43:18.6
-6,-4,43:18.6
9,-4,43:18.6
-7,-3,43:18.6
-6,-3,43:18.6
-1,-3,43:17.0
0,-3,43:17.0
9,-3,43:18.6
-6,-2,43:18.6
-5,-2,43:18.6
-1,-2,43:17.0
0,-2,43:17.0
1,-2,43:17.0
9,-2,43:18.6
-5,-1,43:18.6
-4,-1,43:18.6
-1,-1,43:17.0
0,-1,43:17.0
9,-1,43:18.6
-4,0,43:18.6
-3,0,43:18.6
7,0,43:18.6
8,0,43:18.6
9,0,43:18.6
10,0,43:18.6
11,0,43:18.6
12,0,43:18.6
-3,1,43:18.6
6,1,43:18.6
7,1,43:18.6
12,1,43:18.6
13,1,43:18.6
14,1,43:18.6
-2,2,43:18.6
5,2,43:18.6
6,2,43:18.6
15,2,43:18.6
16,2,43:18.6
17,2,43:18.6
-1,3,43:18.6
3,3,43:18.6
4,3,43:18.6
17,3,43:18.6
18,3,43:18.6
19,3,43:18.6
-1,4,43:18.6
0,4,43:18.6
2,4,43:18.6
3,4,43:18.6
0,5,43:18.6
1,5,43:18.6
2,5,43:18.6
0,6,43:18.6
1,6,43:18.6
0,7,43:18.6
0,8,43:18.6
0,9,43:18.6
0,-14,44:18.6
0,-12,44:18.6
0,-11,44:18.6
1,-11,44:18.6
2,-11,44:18.6
-1,-10,44:18.6
0,-10,44:18.6
2,-10,44:18.6
3,-10,44:18.6
14,-10,44:18.6
-1,-9,44:18.6
3,-9,44:18.6
4,-9,44:18.6
5,-9,44:18.6
12,-9,44:18.6
-2,-8,44:18.6
5,-8,44:18.6
6,-8,44:18.6
7,-8,44:18.6
10,-8,44:18.6
11,-8,44:18.6
-3,-7,44:18.6
7,-7,44:18.6
8,-7,44:18.6
9,-7,44:18.6
-4,-6,44:18.6
-3,-6,44:18.6
8,-6,44:18.6
-5,-5,44:18.6
-4,-5,44:18.6
8,-5,44:18.6
-6,-4,44:18.6
-5,-4,44:18.6
8,-4,44:18.6
-7,-3,44:18.6
-6,-3,44:18.6
-1,-3,44:17.0
0,-3,44:17.0
8,-3,44:18.6
-5,-2,44:18.6
-1,-2,44:17.0
0,-2,44:17.0
8,-2,44:18.6
-5,-1,44:18.6
-4,-1,44:18.6
-1,-1,44:17.0
0,-1,44:17.0
8,-1,44:18.6
9,-1,44:18.6
-4,0,44:18.6
-3,0,44:18.6
7,0,44:18.6
8,0,44:18.6
9,0,44:18.6
10,0,44:18.6
11,0,44:18.6
-3,1,44:18.6
-2,1,44:18.6
5,1,44:18.6
6,1,44:18.6
12,1,44:18.6
13,1,44:18.6
14,1,44:18.6
-2,2,44:18.6
-1,2,44:18.6
4,2,44:18.6
5,2,44:18.6
14,2,44:18.6
15,2,44:18.6
16,2,44:18.6
-1,3,44:18.6
2,3,44:18.6
3,3,44:18.6
17,3,44:18.6
18,3,44:18.6
19,3,44:18.6
0,4,44:18.6
1,4,44:18.6
2,4,44:18.6
0,5,44:18.6
1,5,44:18.6
0,6,44:18.6
0,8,44:18.6
0,9,44:18.6
0,-14,45:18.6
0,-11,45:18.6
0,-10,45:18.6
1,-10,45:18.6
2,-10,45:18.6
-1,-9,45:18.6
0,-9,45:18.6
2,-9,45:18.6
3,-9,45:18.6
4,-9,45:18.6
12,-9,45:18.6
-2,-8,45:18.6
-1,-8,45:18.6
4,-8,45:18.6
5,-8,45:18.6
11,-8,45:18.6
-3,-7,45:18.6
-2,-7,45:18.6
5,-7,45:18.6
6,-7,45:18.6
7,-7,45:18.6
8,-7,45:18.6
-4,-6,45:18.6
-3,-6,45:18.6
7,-6,45:18.6
8,-6,45:18.6
-4,-5,45:18.6
7,-5,45:18.6
8,-5,45:18.6
-5,-4,45:18.6
7,-4,45:18.6
8,-4,45:18.6
-7,-3,45:18.6
-6,-3,45:18.6
-5,-3,45:18.6
-1,-3,45:17.0
0,-3,45:17.0
7,-3,45:18.6
8,-3,45:18.6
-5,-2,45:18.6
-1,-2,45:17.0
0,-2,45:17.0
7,-2,45:18.6
8,-2,45:18.6
-4,-1,45:18.6
-1,-1,45:17.0
0,-1,45:17.0
7,-1,45:18.6
8,-1,45:18.6
-3,0,45:18.6
6,0,45:18.6
7,0,45:18.6
9,0,45:18.6
-3,1,45:18.6
-2,1,45:18.6
4,1,45:18.6
5,1,45:18.6
13,1,45:18.6
-2,2,45:18.6
-1,2,45:18.6
3,2,45:18.6
4,2,45:18.6
14,2,45:18.6
15,2,45:18.6
-1,3,45:18.6
0,3,45:18.6
1,3,45:18.6
2,3,45:18.6
3,3,45:18.6
17,3,45:18.6
18,3,45:18.6
0,4,45:18.6
1,4,45:18.6
0,5,45:18.6
0,9,45:18.6
0,-11,46:18.6
0,-10,46:18.6
1,-10,46:18.6
-1,-9,46:18.6
0,-9,46:18.6
1,-9,46:18.6
2,-9,46:18.6
-1,-8,46:18.6
2,-8,46:18.6
3,-8,46:18.6
4,-8,46:18.6
11,-8,46:18.6
-2,-7,46:18.6
4,-7,46:18.6
5,-7,46:18.6
6,-7,46:18.6
8,-7,46:18.6
-3,-6,46:18.6
7,-6,46:18.6
-4,-5,46:18.6
-3,-5,46:18.6
6,-5,46:18.6
7,-5,46:18.6
-5,-4,46:18.6
-4,-4,46:18.6
6,-4,46:18.6
7,-4,46:18.6
-7,-3,46:18.6
-6,-3,46:18.6
-5,-3,46:18.6
-1,-3,46:17.0
0,-3,46:17.0
7,-3,46:18.6
-5,-2,46:18.6
-4,-2,46:18.6
-1,-2,46:17.0
0,-2,46:17.0
7,-2,46:18.6
-4,-1,46:18.6
-3,-1,46:18.6
-1,-1,46:17.0
0,-1,46:17.0
6,-1,46:18.6
7,-1,46:18.6
8,-1,46:18.6
-3,0,46:18.6
5,0,46:18.6
6,0,46:18.6
8,0,46:18.6
9,0,46:18.6
-2,1,46:18.6
3,1,46:18.6
4,1,46:18.6
5,1,46:18.6
13,1,46:18.6
-1,2,46:18.6
2,2,46:18.6
3,2,46:18.6
13,2,46:18.6
14,2,46:18.6
-1,3,46:18.6
0,3,46:18.6
1,3,46:18.6
2,3,46:18.6
0,4,46:18.6
0,5,46:18.6
0,-10,47:18.6
0,-9,47:18.6
1,-9,47:18.6
-1,-8,47:18.6
0,-8,47:18.6
1,-8,47:18.6
2,-8,47:18.6
3,-8,47:18.6
11,-8,47:18.6
-2,-7,47:18.6
-1,-7,47:18.6
3,-7,47:18.6
4,-7,47:18.6
8,-7,47:18.6
-3,-6,47:18.6
-2,-6,47:18.6
4,-6,47:18.6
5,-6,47:18.6
7,-6,47:18.6
-4,-5,47:18.6
-3,-5,47:18.6
6,-5,47:18.6
-5,-4,47:18.6
-4,-4,47:18.6
6,-4,47:18.6
-7,-3,47:18.6
-6,-3,47:18.6
-5,-3,47:18.6
-1,-3,47:17.0
6,-3,47:18.6
-5,-2,47:18.6
-4,-2,47:18.6
-2,-2,47:18.6
-1,-2,47:17.0
0,-2,47:17.0
6,-2,47:18.6
-4,-1,47:18.6
-3,-1,47:18.6
-1,-1,47:17.0
0,-1,47:17.0
5,-1,47:18.6
6,-1,47:18.6
7,-1,47:18.6
-3,0,47:18.6
-2,0,47:18.6
4,0,47:18.6
5,0,47:18.6
8,0,47:18.6
9,0,47:18.6
-2,1,47:18.6
-1,1,47:18.6
2,1,47:18.6
3,1,47:18.6
4,1,47:18.6
-1,2,47:18.6
1,2,47:18.6
2,2,47:18.6
13,2,47:18.6
14,2,47:18.6
0,3,47:18.6
1,3,47:18.6
0,4,47:18.6
0,5,47:18.6
-4,-10,48:18.6
-2,-10,48:18.6
0,-10,48:18.6
0,-9,48:18.6
-1,-8,48:18.6
0,-8,48:18.6
1,-8,48:18.6
2,-8,48:18.6
-1,-7,48:18.6
2,-7,48:18.6
3,-7,48:18.6
-2,-6,48:18.6
3,-6,48:18.6
4,-6,48:18.6
5,-6,48:18.6
7,-6,48:18.6
-3,-5,48:18.6
5,-5,48:18.6
-4,-4,48:18.6
5,-4,48:18.6
-6,-3,48:18.6
-5,-3,48:18.6
-4,-3,48:18.6
-1,-3,48:17.0
1,-3,48:18.6
2,-3,48:18.6
3,-3,48:18.6
-3,-2,48:18.6
-2,-2,48:18.6
-1,-2,48:17.0
0,-2,48:17.0
1,-2,48:18.6
-6,-1,48:18.6
-5,-1,48:18.6
-4,-1,48:18.6
-3,-1,48:18.6
-1,-1,48:17.0
0,-1,48:17.0
5,-1,48:18.6
6,-1,48:18.6
7,-1,48:18.6
-2,0,48:18.6
4,0,48:18.6
7,0,48:18.6
8,0,48:18.6
9,0,48:18.6
-2,1,48:18.6
-1,1,48:18.6
1,1,48:18.6
2,1,48:18.6
-1,2,48:18.6
0,2,48:18.6
1,2,48:18.6
13,2,48:18.6
14,2,48:18.6
0,3,48:18.6
0,4,48:18.6
0,5,48:18.6
-3,-11,49:18.6
-4,-10,49:18.6
-3,-10,49:18.6
-2,-10,49:18.6
-4,-9,49:18.6
-2,-9,49:18.6
-1,-9,49:18.6
0,-9,49:18.6
-5,-8,49:18.6
-4,-8,49:18.6
0,-8,49:18.6
1,-8,49:18.6
-6,-7,49:18.6
-5,-7,49:18.6
1,-7,49:18.6
2,-7,49:18.6
-6,-6,49:18.6
-2,-6,49:18.6
2,-6,49:18.6
3,-6,49:18.6
4,-6,49:18.6
7,-6,49:18.6
-6,-5,49:18.6
-3,-5,49:18.6
4,-5,49:18.6
5,-5,49:18.6
-7,-4,49:18.6
-4,-4,49:18.6
-3,-4,49:18.6
4,-4,49:18.6
5,-4,49:18.6
-5,-3,49:18.6
-4,-3,49:18.6
-1,-3,49:17.0
1,-3,49:18.6
2,-3,49:18.6
3,-3,49:18.6
4,-3,49:18.6
-4,-2,49:18.6
-3,-2,49:18.6
-2,-2,49:18.6
-1,-2,49:17.0
0,-2,49:17.0
1,-2,49:18.6
4,-2,49:18.6
-7,-1,49:18.6
-6,-1,49:18.6
-5,-1,49:18.6
-4,-1,49:18.6
-3,-1,49:18.6
-1,-1,49:17.0
4,-1,49:18.6
5,-1,49:18.6
6,-1,49:18.6
-2,0,49:18.6
3,0,49:18.6
7,0,49:18.6
8,0,49:18.6
9,0,49:18.6
-1,1,49:18.6
1,1,49:18.6
2,1,49:18.6
0,2,49:18.6
0,3,49:18.6
-3,-11,50:18.6
-3,-10,50:18.6
-4,-9,50:18.6
-3,-9,50:18.6
-2,-9,50:18.6
-4,-8,50:18.6
-2,-8,50:18.6
-1,-8,50:18.6
0,-8,50:18.6
-5,-7,50:18.6
-4,-7,50:18.6
-1,-7,50:18.6
0,-7,50:18.6
1,-7,50:18.6
-6,-6,50:18.6
-5,-6,50:18.6
-2,-6,50:18.6
-1,-6,50:18.6
1,-6,50:18.6
2,-6,50:18.6
3,-6,50:18.6
-6,-5,50:18.6
-2,-5,50:18.6
2,-5,50:18.6
3,-5,50:18.6
4,-5,50:18.6
5,-5,50:18.6
-7,-4,50:18.6
-6,-4,50:18.6
-3,-4,50:18.6
4,-4,50:18.6
5,-4,50:18.6
-7,-3,50:18.6
-5,-3,50:18.6
-4,-3,50:18.6
-1,-3,50:17.0
1,-3,50:18.6
2,-3,50:18.6
3,-3,50:18.6
4,-3,50:18.6
5,-3,50:18.6
-8,-2,50:18.6
-7,-2,50:18.6
-4,-2,50:18.6
-3,-2,50:18.6
-2,-2,50:18.6
-1,-2,50:17.0
0,-2,50:18.6
4,-2,50:18.6
5,-2,50:18.6
-8,-1,50:18.6
-7,-1,50:18.6
-6,-1,50:18.6
-5,-1,50:18.6
-4,-1,50:18.6
-3,-1,50:18.6
-2,-1,50:18.6
3,-1,50:18.6
4,-1,50:18.6
5,-1,50:18.6
6,-1,50:18.6
-8,0,50:18.6
-2,0,50:18.6
-1,0,50:18.6
1,0,50:18.6
2,0,50:18.6
3,0,50:18.6
4,0,50:18.6
8,0,50:18.6
-8,1,50:18.6
-7,1,50:18.6
-1,1,50:18.6
0,1,50:18.6
1,1,50:18.6
3,1,50:18.6
4,1,50:18.6
-6,2,50:18.6
-5,2,50:18.6
0,2,50:18.6
3,2,50:18.6
-5,3,50:18.6
-4,3,50:18.6
-1,3,50:18.6
2,3,50:18.6
-4,4,50:18.6
-3,4,50:18.6
-2,4,50:18.6
1,4,50:18.6
2,4,50:18.6
-2,5,50:18.6
-1,5,50:18.6
1,5,50:18.6
0,6,50:18.6
1,6,50:18.6
-3,-10,51:18.6
-3,-9,51:18.6
-4,-8,51:18.6
-3,-8,51:18.6
-2,-8,51:18.6
-1,-8,51:18.6
-4,-7,51:18.6
-1,-7,51:18.6
0,-7,51:18.6
-5,-6,51:18.6
-4,-6,51:18.6
-1,-6,51:18.6
0,-6,51:18.6
1,-6,51:18.6
2,-6,51:18.6
-5,-5,51:18.6
-2,-5,51:18.6
-1,-5,51:18.6
1,-5,51:18.6
2,-5,51:18.6
3,-5,51:18.6
4,-5,51:18.6
-6,-4,51:18.6
-5,-4,51:18.6
-3,-4,51:18.6
-2,-4,51:18.6
3,-4,51:18.6
4,-4,51:18.6
5,-4,51:18.6
-7,-3,51:18.6
-6,-3,51:18.6
-4,-3,51:18.6
-3,-3,51:18.6
1,-3,51:18.6
2,-3,51:18.6
3,-3,51:18.6
4,-3,51:18.6
5,-3,51:18.6
6,-3,51:18.6
-7,-2,51:18.6
-3,-2,51:18.6
-2,-2,51:18.6
-1,-2,51:17.0
0,-2,51:18.6
3,-2,51:18.6
4,-2,51:18.6
-8,-1,51:18.6
-7,-1,51:18.6
-6,-1,51:18.6
-5,-1,51:18.6
-4,-1,51:18.6
-3,-1,51:18.6
-2,-1,51:18.6
2,-1,51:18.6
3,-1,51:18.6
4,-1,51:18.6
5,-1,51:18.6
-9,0,51:18.6
-8,0,51:18.6
-7,0,51:18.6
-2,0,51:18.6
-1,0,51:18.6
0,0,51:18.6
1,0,51:18.6
2,0,51:18.6
3,0,51:18.6
-7,1,51:18.6
-6,1,51:18.6
-5,1,51:18.6
-1,1,51:18.6
0,1,51:18.6
2,1,51:18.6
3,1,51:18.6
-5,2,51:18.6
-4,2,51:18.6
-1,2,51:18.6
2,2,51:18.6
-4,3,51:18.6
-3,3,51:18.6
-2,3,51:18.6
1,3,51:18.6
2,3,51:18.6
-3,4,51:18.6
-2,4,51:18.6
-1,4,51:18.6
1,4,51:18.6
-1,5,51:18.6
0,5,51:18.6
1,5,51:18.6
0,6,51:18.6
-3,-10,52:18.6
-3,-9,52:18.6
-3,-8,52:18.6
-2,-8,52:18.6
-3,-7,52:18.6
-2,-7,52:18.6
-1,-7,52:18.6
-4,-6,52:18.6
-3,-6,52:18.6
-1,-6,52:18.6
0,-6,52:18.6
-5,-5,52:18.6
-4,-5,52:18.6
-2,-5,52:18.6
-1,-5,52:18.6
0,-5,52:18.6
1,-5,52:18.6
2,-5,52:18.6
-5,-4,52:18.6
-2,-4,52:18.6
1,-4,52:18.6
2,-4,52:18.6
3,-4,52:18.6
4,-4,52:18.6
-6,-3,52:18.6
-5,-3,52:18.6
-4,-3,52:18.6
-3,-3,52:18.6
1,-3,52:18.6
2,-3,52:18.6
3,-3,52:18.6
4,-3,52:18.6
5,-3,52:18.6
6,-3,52:18.6
-7,-2,52:18.6
-6,-2,52:18.6
-4,-2,52:18.6
-3,-2,52:18.6
-2,-2,52:18.6
-1,-2,52:17.0
0,-2,52:18.6
2,-2,52:18.6
3,-2,52:18.6
4,-2,52:18.6
-7,-1,52:18.6
-6,-1,52:18.6
-5,-1,52:18.6
-4,-1,52:18.6
-2,-1,52:18.6
1,-1,52:18.6
2,-1,52:18.6
3,-1,52:18.6
-8,0,52:18.6
-7,0,52:18.6
-6,0,52:18.6
-5,0,52:18.6
-1,0,52:18.6
0,0,52:18.6
1,0,52:18.6
2,0,52:18.6
3,0,52:18.6
-5,1,52:18.6
-4,1,52:18.6
-1,1,52:18.6
1,1,52:18.6
2,1,52:18.6
-4,2,52:18.6
-3,2,52:18.6
1,2,52:18.6
-2,3,52:18.6
-1,3,52:18.6
0,3,52:18.6
1,3,52:18.6
-1,4,52:18.6
0,4,52:18.6
-3,-10,53:18.6
-3,-9,53:18.6
-3,-8,53:18.6
-3,-7,53:18.6
-2,-7,53:18.6
-3,-6,53:18.6
-2,-6,53:18.6
-1,-6,53:18.6
-4,-5,53:18.6
-3,-5,53:18.6
-1,-5,53:18.6
0,-5,53:18.6
1,-5,53:18.6
-5,-4,53:18.6
-4,-4,53:18.6
-2,-4,53:18.6
-1,-4,53:18.6
0,-4,53:18.6
1,-4,53:18.6
2,-4,53:18.6
3,-4,53:18.6
-5,-3,53:18.6
-3,-3,53:18.6
-2,-3,53:18.6
0,-3,53:18.6
1,-3,53:18.6
2,-3,53:18.6
3,-3,53:18.6
4,-3,53:18.6
5,-3,53:18.6
-6,-2,53:18.6
-5,-2,53:18.6
-4,-2,53:18.6
-3,-2,53:18.6
-2,-2,53:18.6
-1,-2,53:17.0
0,-2,53:18.6
1,-2,53:18.6
2,-2,53:18.6
3,-2,53:18.6
-7,-1,53:18.6
-6,-1,53:18.6
-5,-1,53:18.6
-4,-1,53:18.6
-2,-1,53:18.6
-1,-1,53:18.6
0,-1,53:18.6
1,-1,53:18.6
2,-1,53:18.6
3,-1,53:18.6
-8,0,53:18.6
-7,0,53:18.6
-6,0,53:18.6
-5,0,53:18.6
-4,0,53:18.6
-1,0,53:18.6
0,0,53:18.6
1,0,53:18.6
2,0,53:18.6
-4,1,53:18.6
-3,1,53:18.6
1,1,53:18.6
-3,2,53:18.6
-2,2,53:18.6
-1,2,53:18.6
0,2,53:18.6
1,2,53:18.6
-1,3,53:18.6
0,3,53:18.6
-3,-9,54:18.6
-3,-8,54:18.6
-3,-7,54:18.6
-2,-7,54:18.6
-3,-6,54:18.6
-2,-6,54:18.6
-3,-5,54:18.6
-2,-5,54:18.6
-1,-5,54:18.6
0,-5,54:18.6
-4,-4,54:18.6
-3,-4,54:18.6
-2,-4,54:18.6
-1,-4,54:18.6
0,-4,54:18.6
1,-4,54:18.6
-4,-3,54:18.6
-2,-3,54:18.6
0,-3,54:18.6
1,-3,54:18.6
2,-3,54:18.6
3,-3,54:18.6
4,-3,54:18.6
5,-3,54:18.6
-5,-2,54:18.6
-4,-2,54:18.6
-3,-2,54:18.6
-2,-2,54:18.6
-1,-2,54:17.0
0,-2,54:18.6
1,-2,54:18.6
2,-2,54:18.6
5,-2,54:18.6
6,-2,54:18.6
-6,-1,54:18.6
-5,-1,54:18.6
-4,-1,54:18.6
-2,-1,54:18.6
-1,-1,54:18.6
0,-1,54:18.6
1,-1,54:18.6
-8,0,54:18.6
-7,0,54:18.6
-6,0,54:18.6
-4,0,54:18.6
-3,0,54:18.6
0,0,54:18.6
1,0,54:18.6
-8,1,54:18.6
-3,1,54:18.6
-2,1,54:18.6
-1,1,54:18.6
0,1,54:18.6
-2,2,54:18.6
-1,2,54:18.6
0,2,54:18.6
-3,-9,55:18.6
-3,-8,55:18.6
-3,-7,55:18.6
-2,-6,55:18.6
-2,-5,55:18.6
-1,-5,55:18.6
-3,-4,55:18.6
-2,-4,55:18.6
-1,-4,55:18.6
0,-4,55:18.6
-4,-3,55:18.6
-3,-3,55:18.6
-2,-3,55:18.6
-1,-3,55:18.6
0,-3,55:18.6
1,-3,55:18.6
2,-3,55:18.6
3,-3,55:18.6
-4,-2,55:18.6
-3,-2,55:18.6
-2,-2,55:18.6
-1,-2,55:18.6
0,-2,55:18.6
1,-2,55:18.6
3,-2,55:18.6
4,-2,55:18.6
5,-2,55:18.6
6,-2,55:18.6
-6,-1,55:18.6
-5,-1,55:18.6
-4,-1,55:18.6
-3,-1,55:18.6
-1,-1,55:18.6
0,-1,55:18.6
1,-1,55:18.6
-7,0,55:18.6
-6,0,55:18.6
-3,0,55:18.6
-2,0,55:18.6
-1,0,55:18.6
0,0,55:18.6
-8,1,55:18.6
-2,1,55:18.6
-1,1,55:18.6
0,1,55:18.6
-3,-8,56:18.6
-3,-7,56:18.6
-2,-6,56:18.6
-2,-5,56:18.6
-2,-4,56:18.6
-1,-4,56:18.6
-3,-3,56:18.6
-2,-3,56:18.6
-1,-3,56:18.6
0,-3,56:18.6
1,-3,56:18.6
-4,-2,56:18.6
-3,-2,56:18.6
-2,-2,56:18.6
-1,-2,56:18.6
0,-2,56:18.6
1,-2,56:18.6
2,-2,56:18.6
3,-2,56:18.6
4,-2,56:18.6
5,-2,56:18.6
-5,-1,56:18.6
-4,-1,56:18.6
-3,-1,56:18.6
-2,-1,56:18.6
-1,-1,56:18.6
0,-1,56:18.6
-6,0,56:18.6
-5,0,56:18.6
-2,0,56:18.6
-1,0,56:18.6
-7,1,56:18.6
