[META]
version=2.0
spawnOnBlockType=2
spawnSunlight=True
spawnDarkness=True
spawnWater=False
spawnLava=False
underFill=False
randomRotation=True
dig=True
tree=False
branch=False
needsFoundation=True
rarity=100
collisionPercentage=20
spawnElevationMin=0
spawnElevationMax=200
spawnInBiome=Custom
[DATA]
7,-5,-8:17.13
6,-3,-8:17.13
9,-3,-8:17.13
7,-1,-8:17.13
6,-5,-7:17.13
6,-3,-7:17.13
8,-3,-7:17.13
7,-1,-7:17.13
6,-4,-6:17.13
6,-3,-6:17.13
8,-2,-6:17.13
7,-1,-6:17.13
6,-3,-5:17.13
7,-2,-5:17.13
6,-3,-4:17.13
7,-2,-4:17.13
6,-3,-3:17.13
7,-2,-3:17.13
6,-3,-2:17.13
7,-3,-2:17.13
6,-2,-2:17.13
7,-2,-2:17.13
6,-3,-1:17.13
7,-3,-1:17.13
6,-2,-1:17.13
7,-2,-1:17.13
6,-3,0:17.13
7,-3,0:17.13
6,-2,0:17.13
7,-2,0:17.13
6,-3,1:17.13
7,-3,1:17.13
6,-2,1:17.13
7,-2,1:17.13
6,-3,2:17.13
7,-3,2:17.13
6,-2,2:17.13
7,-2,2:17.13
6,-3,3:17.13
7,-3,3:17.13
6,-2,3:17.13
7,-2,3:17.13
6,-3,4:17.13
7,-3,4:17.13
5,-2,4:17.13
6,-2,4:17.13
7,-2,4:17.13
6,-3,5:17.13
7,-3,5:17.13
6,-2,5:17.13
7,-2,5:17.13
6,-3,6:17.13
7,-3,6:17.13
6,-2,6:17.13
7,-2,6:17.13
7,-5,7:18.12
6,-4,7:18.12
6,-3,7:17.13
7,-3,7:17.13
6,-2,7:17.13
7,-2,7:17.13
6,-8,8:18.12
5,-7,8:18.12
6,-7,8:18.12
5,-6,8:18.12
6,-6,8:18.12
7,-6,8:18.12
8,-6,8:18.12
5,-5,8:18.12
6,-5,8:18.12
7,-5,8:18.12
8,-5,8:18.12
5,-4,8:18.12
6,-4,8:18.12
7,-4,8:18.12
6,-3,8:18.12
7,-3,8:17.13
5,-2,8:17.13
6,-2,8:17.13
7,-2,8:17.13
5,-7,9:18.12
4,-6,9:18.12
5,-6,9:18.12
5,-5,9:18.12
7,-5,9:18.12
8,-5,9:18.12
5,-4,9:18.12
6,-4,9:18.12
7,-4,9:18.12
5,-3,9:18.12
6,-3,9:17.13
7,-3,9:17.13
4,-2,9:18.12
5,-2,9:18.12
6,-2,9:17.13
7,-2,9:17.13
4,-1,9:18.12
5,-8,10:18.12
4,-7,10:18.12
5,-7,10:18.12
4,-6,10:18.12
5,-6,10:18.12
4,-5,10:18.12
5,-5,10:18.12
5,-4,10:18.12
6,-4,10:18.12
5,-3,10:18.12
6,-3,10:17.13
7,-3,10:18.12
8,-3,10:18.12
9,-3,10:18.12
4,-2,10:18.12
5,-2,10:18.12
6,-2,10:17.13
7,-2,10:17.13
9,-2,10:18.12
4,-1,10:18.12
5,-1,10:18.12
4,0,10:18.12
4,-9,11:18.12
5,-9,11:18.12
4,-8,11:18.12
5,-8,11:18.12
2,-7,11:18.12
3,-7,11:18.12
4,-7,11:18.12
5,-7,11:18.12
2,-6,11:18.12
3,-6,11:18.12
4,-6,11:18.12
5,-6,11:18.12
3,-5,11:18.12
4,-5,11:18.12
5,-5,11:18.12
6,-5,11:18.12
7,-5,11:18.12
4,-4,11:18.12
5,-4,11:18.12
6,-4,11:18.12
7,-4,11:18.12
8,-4,11:18.12
9,-4,11:18.12
5,-3,11:18.12
6,-3,11:17.13
7,-3,11:18.12
8,-3,11:18.12
9,-3,11:18.12
10,-3,11:18.12
5,-2,11:18.12
6,-2,11:17.13
7,-2,11:17.13
9,-2,11:18.12
3,-1,11:18.12
4,-1,11:18.12
5,-1,11:18.12
6,-1,11:18.12
5,0,11:18.12
3,-7,12:18.12
4,-7,12:18.12
2,-6,12:18.12
4,-6,12:18.12
5,-6,12:18.12
3,-5,12:18.12
4,-5,12:17.13
5,-5,12:18.12
3,-4,12:18.12
4,-4,12:18.12
5,-4,12:18.12
6,-4,12:18.12
7,-4,12:18.12
8,-4,12:18.12
9,-4,12:18.12
10,-4,12:18.12
4,-3,12:18.12
5,-3,12:18.12
6,-3,12:17.13
7,-3,12:17.13
8,-3,12:18.12
5,-2,12:18.12
6,-2,12:17.13
7,-2,12:18.12
5,-1,12:18.12
6,-1,12:18.12
7,-1,12:18.12
8,-1,12:18.12
5,0,12:18.12
6,0,12:18.12
7,0,12:18.12
8,0,12:18.12
9,0,12:18.12
5,1,12:18.12
6,1,12:18.12
8,-6,13:18.12
3,-5,13:18.12
4,-5,13:18.12
5,-5,13:18.12
6,-5,13:18.12
7,-5,13:18.12
8,-5,13:18.12
3,-4,13:18.12
4,-4,13:18.12
7,-4,13:18.12
8,-4,13:18.12
3,-3,13:18.12
4,-3,13:18.12
5,-3,13:18.12
6,-3,13:17.13
7,-3,13:18.12
8,-3,13:18.12
3,-2,13:18.12
4,-2,13:18.12
5,-2,13:18.12
6,-2,13:17.13
7,-2,13:18.12
8,-2,13:18.12
6,-1,13:18.12
7,-1,13:18.12
8,-1,13:18.12
9,-1,13:18.12
5,0,13:18.12
6,0,13:18.12
7,0,13:18.12
8,0,13:18.12
9,0,13:18.12
5,1,13:18.12
7,-6,14:18.12
8,-6,14:18.12
4,-5,14:18.12
6,-5,14:18.12
7,-5,14:18.12
8,-5,14:18.12
3,-4,14:18.12
6,-4,14:18.12
7,-4,14:18.12
8,-4,14:18.12
2,-3,14:18.12
3,-3,14:18.12
4,-3,14:18.12
5,-3,14:18.12
6,-3,14:18.12
7,-3,14:18.12
8,-3,14:18.12
9,-3,14:18.12
2,-2,14:18.12
3,-2,14:18.12
4,-2,14:18.12
5,-2,14:18.12
6,-2,14:17.13
7,-2,14:18.12
8,-2,14:18.12
9,-2,14:18.12
5,-1,14:18.12
6,-1,14:18.12
9,-1,14:18.12
10,-1,14:18.12
6,0,14:18.12
7,0,14:18.12
8,0,14:18.12
10,0,14:18.12
8,1,14:18.12
9,1,14:18.12
6,-6,15:18.12
7,-6,15:18.12
9,-5,15:18.12
6,-4,15:18.12
7,-4,15:18.12
2,-3,15:18.12
4,-3,15:18.12
5,-3,15:18.12
6,-3,15:18.12
7,-3,15:18.12
2,-2,15:18.12
4,-2,15:18.12
6,-2,15:17.13
7,-2,15:18.12
2,-1,15:18.12
3,-1,15:18.12
4,-1,15:18.12
5,-1,15:18.12
6,-1,15:18.12
7,-1,15:18.12
7,0,15:18.12
8,0,15:18.12
6,-4,16:18.12
7,-4,16:18.12
6,-3,16:18.12
7,-3,16:18.12
6,-2,16:17.13
7,-2,16:18.12
8,-2,16:18.12
5,-1,16:18.12
6,-1,16:18.12
7,-1,16:18.12
8,-1,16:18.12
6,0,16:18.12
7,0,16:18.12
8,0,16:18.12
5,-4,17:18.12
6,-4,17:18.12
5,-3,17:18.12
6,-3,17:18.12
5,-2,17:18.12
6,-2,17:18.12
7,-2,17:18.12
8,-2,17:18.12
6,-1,17:18.12
7,-1,17:18.12
8,-1,17:18.12
9,-1,17:18.12
7,0,17:18.12
8,0,17:18.12
5,-4,18:18.12
6,-4,18:18.12
5,-3,18:18.12
6,-3,18:18.12
7,-3,18:18.12
5,-2,18:18.12
6,-2,18:18.12
7,-2,18:18.12
8,-2,18:18.12
5,-1,18:18.12
6,-1,18:18.12
7,-1,18:18.12
8,-1,18:18.12
6,-3,19:18.12
7,-3,19:18.12
5,-2,19:18.12
6,-2,19:18.12
7,-2,19:18.12
5,-1,19:18.12
6,-1,19:18.12
6,-3,20:18.12
7,-3,20:18.12
6,-2,20:17.13
7,-2,20:18.12
