[META]
version=2.0
spawnOnBlockType=2
spawnSunlight=True
spawnDarkness=True
spawnWater=False
spawnLava=False
underFill=False
randomRotation=True
dig=True
tree=False
branch=False
needsFoundation=True
rarity=100
collisionPercentage=20
spawnElevationMin=0
spawnElevationMax=200
spawnInBiome=Custom
[DATA]
3,-4,-8:17.13
0,-3,-8:17.13
0,0,-8:17.13
3,2,-8:17.13
1,-3,-7:17.13
3,-3,-7:17.13
0,-1,-7:17.13
3,1,-7:17.13
2,-3,-6:17.13
1,-1,-6:17.13
3,1,-6:17.13
2,-2,-5:17.13
1,-1,-5:17.13
3,0,-5:17.13
2,-2,-4:17.13
2,0,-4:17.13
3,0,-4:17.13
2,-2,-3:17.13
2,-1,-3:17.13
2,0,-3:17.13
2,-3,-2:17.13
1,-2,-2:17.13
2,-2,-2:17.13
1,-1,-2:17.13
2,-1,-2:17.13
1,-2,-1:17.13
2,-2,-1:17.13
1,-1,-1:17.13
2,-1,-1:17.13
1,-2,0:17.13
2,-2,0:17.13
1,-1,0:17.13
2,-1,0:17.13
1,-2,1:17.13
2,-2,1:17.13
1,-1,1:17.13
2,-1,1:17.13
1,-2,2:17.13
2,-2,2:17.13
1,-1,2:17.13
2,-1,2:17.13
1,-2,3:17.13
2,-2,3:17.13
1,-1,3:17.13
2,-1,3:17.13
1,-2,4:17.13
2,-2,4:17.13
0,-1,4:17.13
1,-1,4:17.13
2,-1,4:17.13
1,-2,5:17.13
2,-2,5:17.13
1,-1,5:17.13
2,-1,5:17.13
1,-2,6:17.13
2,-2,6:17.13
3,-2,6:17.13
1,-1,6:17.13
2,-1,6:17.13
4,-1,6:17.13
2,-3,7:17.13
1,-2,7:17.13
2,-2,7:17.13
1,-1,7:17.13
2,-1,7:17.13
1,-2,8:17.13
2,-2,8:17.13
1,-1,8:17.13
2,-1,8:17.13
1,-2,9:17.13
2,-2,9:17.13
1,-1,9:17.13
2,-1,9:17.13
1,-2,10:17.13
2,-2,10:17.13
-1,-1,10:17.13
0,-1,10:17.13
1,-1,10:17.13
2,-1,10:17.13
1,-2,11:17.13
2,-2,11:17.13
3,-2,11:17.13
1,-1,11:18.12
2,-1,11:17.13
4,-1,11:17.13
1,0,11:18.12
2,0,11:18.12
0,1,11:18.12
1,1,11:17.13
2,1,11:18.12
-1,2,11:18.12
1,2,11:18.12
1,3,11:18.12
-1,5,11:18.12
1,-2,12:17.13
2,-2,12:17.13
1,-1,12:18.12
2,-1,12:18.12
0,0,12:18.12
1,0,12:18.12
2,0,12:18.12
-2,1,12:18.12
0,1,12:18.12
1,1,12:18.12
2,1,12:18.12
-2,2,12:18.12
-1,2,12:18.12
0,2,12:18.12
1,2,12:18.12
2,2,12:18.12
-1,3,12:18.12
0,3,12:18.12
1,3,12:18.12
2,3,12:18.12
-1,4,12:18.12
0,4,12:18.12
1,4,12:18.12
2,4,12:18.12
-1,5,12:18.12
0,5,12:18.12
1,5,12:18.12
2,5,12:18.12
0,6,12:18.4
2,-3,13:17.13
6,-3,13:18.12
1,-2,13:17.13
2,-2,13:17.13
1,-1,13:18.12
2,-1,13:17.13
3,-1,13:18.12
5,-1,13:18.12
-1,0,13:18.12
0,0,13:18.12
1,0,13:18.12
2,0,13:18.12
3,0,13:18.12
-2,1,13:18.12
0,1,13:18.12
2,1,13:18.12
2,2,13:18.12
0,3,13:18.12
2,3,13:18.12
2,4,13:18.12
0,5,13:18.12
2,5,13:18.12
6,-3,14:18.12
1,-2,14:17.13
2,-2,14:17.13
3,-2,14:17.13
4,-2,14:17.13
5,-2,14:18.12
6,-2,14:17.13
1,-1,14:17.13
2,-1,14:17.13
2,0,14:17.13
2,1,14:18.12
2,2,14:18.12
3,2,14:18.12
3,3,14:18.12
1,4,14:18.12
1,6,14:18.4
-2,-4,15:18.12
5,-4,15:18.12
6,-4,15:18.12
-2,-3,15:18.12
4,-3,15:18.12
5,-3,15:18.12
6,-3,15:18.12
7,-3,15:18.12
-2,-2,15:18.12
-1,-2,15:18.12
0,-2,15:18.12
1,-2,15:17.13
2,-2,15:17.13
3,-2,15:17.13
5,-2,15:18.12
6,-2,15:18.12
-2,-1,15:18.12
1,-1,15:18.12
2,-1,15:17.13
3,-1,15:18.12
4,-1,15:18.12
5,-1,15:18.12
1,0,15:18.12
2,0,15:18.12
3,0,15:18.12
1,1,15:18.12
2,1,15:18.12
2,2,15:18.12
3,2,15:18.12
2,3,15:18.12
3,3,15:18.12
1,4,15:18.12
2,4,15:18.12
0,5,15:18.12
1,5,15:18.12
2,5,15:18.12
0,6,15:18.4
1,6,15:18.4
4,6,15:18.4
5,6,15:18.4
0,7,15:18.4
5,-5,16:18.12
-3,-4,16:18.12
-2,-4,16:18.12
4,-4,16:18.12
5,-4,16:18.12
6,-4,16:18.12
-3,-3,16:18.12
-2,-3,16:18.12
-1,-3,16:18.12
4,-3,16:18.12
5,-3,16:18.12
-3,-2,16:18.12
-2,-2,16:18.12
-1,-2,16:18.12
0,-2,16:17.13
1,-2,16:17.13
2,-2,16:17.13
3,-2,16:17.13
6,-2,16:18.12
7,-2,16:18.12
0,-1,16:18.12
1,-1,16:18.12
2,-1,16:17.13
3,-1,16:18.12
4,-1,16:18.12
0,0,16:18.12
1,0,16:18.12
2,0,16:18.12
3,0,16:18.12
4,0,16:18.12
0,1,16:18.12
1,1,16:18.12
3,1,16:18.12
0,2,16:18.12
1,2,16:18.12
2,2,16:18.12
3,2,16:18.12
4,2,16:18.12
2,3,16:18.12
3,3,16:18.12
0,4,16:18.12
1,4,16:18.12
2,4,16:18.12
3,4,16:18.12
4,4,16:18.12
0,5,16:18.12
1,5,16:18.12
2,5,16:18.4
3,5,16:18.4
4,5,16:18.4
5,5,16:18.4
0,6,16:18.4
1,6,16:18.4
2,6,16:18.4
3,6,16:18.4
4,6,16:18.4
5,6,16:18.4
6,6,16:18.4
-1,7,16:18.4
0,7,16:18.4
1,7,16:18.4
2,7,16:18.4
4,7,16:18.4
2,-6,17:18.12
2,-5,17:18.12
5,-5,17:18.12
-2,-4,17:18.12
-1,-4,17:18.12
2,-4,17:18.12
4,-4,17:18.12
5,-4,17:18.12
-2,-3,17:18.12
-1,-3,17:18.12
0,-3,17:18.12
2,-3,17:17.13
3,-3,17:18.12
4,-3,17:17.13
-4,-2,17:18.12
-3,-2,17:18.12
-1,-2,17:18.12
0,-2,17:18.12
1,-2,17:17.13
2,-2,17:17.13
3,-2,17:17.13
-4,-1,17:18.12
-3,-1,17:18.12
-2,-1,17:18.12
-1,-1,17:18.12
0,-1,17:18.12
1,-1,17:18.12
2,-1,17:17.13
3,-1,17:18.12
1,0,17:18.12
2,0,17:18.12
3,0,17:18.12
4,0,17:18.12
0,1,17:18.12
2,1,17:18.12
3,1,17:18.12
4,1,17:18.12
3,2,17:18.12
4,2,17:18.12
1,3,17:18.12
2,3,17:18.12
4,3,17:18.12
5,3,17:18.12
2,4,17:18.12
3,4,17:18.12
4,4,17:18.12
5,4,17:18.12
0,5,17:18.12
2,5,17:18.4
3,5,17:18.4
4,5,17:18.4
5,5,17:18.4
0,6,17:18.4
2,6,17:18.4
3,6,17:18.4
5,6,17:18.4
3,7,17:18.4
0,-7,18:18.12
0,-6,18:18.12
1,-6,18:18.12
2,-6,18:18.12
4,-6,18:18.12
5,-6,18:18.12
1,-5,18:18.12
2,-5,18:18.12
3,-5,18:18.12
4,-5,18:18.12
5,-5,18:18.12
6,-5,18:18.12
1,-4,18:18.12
2,-4,18:18.12
3,-4,18:18.12
4,-4,18:18.12
5,-4,18:18.12
-4,-3,18:18.12
1,-3,18:18.12
2,-3,18:18.12
3,-3,18:18.12
5,-3,18:18.12
1,-2,18:17.13
2,-2,18:17.13
3,-2,18:17.13
5,-2,18:18.12
-4,-1,18:18.12
-3,-1,18:18.12
-1,-1,18:18.12
0,-1,18:18.12
1,-1,18:17.13
2,-1,18:17.13
3,-1,18:18.12
4,-1,18:18.12
-2,0,18:18.12
-1,0,18:18.12
0,0,18:18.12
1,0,18:18.12
3,0,18:18.12
4,0,18:18.12
1,1,18:18.12
2,1,18:18.12
3,1,18:18.12
4,1,18:18.12
2,2,18:18.12
3,2,18:18.12
4,2,18:18.12
5,2,18:18.12
1,3,18:18.12
4,3,18:18.12
5,3,18:18.12
2,4,18:18.12
5,4,18:18.12
1,5,18:18.12
5,5,18:18.4
2,6,18:18.4
0,-7,19:18.12
1,-7,19:17.13
0,-6,19:18.12
1,-6,19:18.12
2,-6,19:18.12
3,-6,19:18.12
4,-6,19:18.12
6,-6,19:18.12
0,-5,19:18.12
1,-5,19:18.12
2,-5,19:18.12
3,-5,19:18.12
6,-5,19:18.12
0,-4,19:18.12
1,-4,19:18.12
3,-4,19:18.12
6,-4,19:18.12
1,-3,19:18.12
3,-3,19:18.12
0,-2,19:18.12
1,-2,19:18.12
2,-2,19:17.13
3,-2,19:17.13
5,-2,19:18.12
-1,-1,19:18.12
0,-1,19:18.12
1,-1,19:18.12
2,-1,19:17.13
3,-1,19:18.12
4,-1,19:18.12
5,-1,19:18.12
6,-1,19:18.12
-2,0,19:18.12
-1,0,19:18.12
0,0,19:18.12
4,0,19:18.12
5,0,19:18.12
-2,1,19:18.12
0,1,19:18.12
1,1,19:18.12
4,1,19:18.12
5,1,19:18.12
-2,2,19:18.12
1,2,19:18.12
2,2,19:18.12
3,2,19:18.12
4,2,19:18.12
5,2,19:18.12
3,3,19:18.12
4,3,19:18.12
5,3,19:18.12
0,-8,20:18.12
-1,-7,20:18.12
0,-7,20:18.12
1,-7,20:18.12
-1,-6,20:18.12
0,-6,20:18.12
1,-6,20:18.12
2,-6,20:18.12
3,-6,20:18.12
-1,-5,20:18.12
0,-5,20:18.12
3,-5,20:18.12
4,-5,20:18.12
-1,-4,20:18.12
0,-4,20:18.12
3,-4,20:18.12
4,-4,20:18.12
-1,-3,20:18.12
0,-3,20:18.12
4,-3,20:18.12
-2,-2,20:18.12
-1,-2,20:18.12
0,-2,20:18.12
2,-2,20:17.13
3,-2,20:17.13
-2,-1,20:18.12
-1,-1,20:18.12
1,-1,20:17.13
2,-1,20:17.13
3,-1,20:17.13
4,-1,20:17.13
5,-1,20:18.12
6,-1,20:18.12
-2,0,20:18.12
-1,0,20:18.12
0,0,20:18.12
1,0,20:18.12
5,0,20:18.12
6,0,20:18.12
7,0,20:18.12
-3,1,20:17.13
-2,1,20:18.12
0,1,20:18.12
5,1,20:18.12
6,1,20:18.12
-2,2,20:18.12
5,2,20:18.12
6,2,20:18.12
3,3,20:18.12
6,3,20:18.12
3,4,20:18.4
4,4,20:18.4
0,-8,21:18.12
1,-8,21:18.12
1,-7,21:18.12
2,-7,21:18.12
-2,-6,21:18.12
-2,-5,21:18.12
2,-4,21:18.12
-1,-3,21:18.12
1,-3,21:18.12
2,-3,21:17.13
3,-3,21:18.12
4,-3,21:18.12
-2,-2,21:18.12
1,-2,21:18.12
2,-2,21:17.13
3,-2,21:17.13
5,-2,21:18.12
6,-2,21:18.12
0,-1,21:18.12
1,-1,21:18.12
2,-1,21:18.12
3,-1,21:18.12
4,-1,21:18.12
5,-1,21:18.12
6,-1,21:18.12
7,-1,21:18.12
-2,0,21:18.12
0,0,21:18.12
1,0,21:18.12
4,0,21:18.12
5,0,21:18.12
6,0,21:18.12
7,0,21:18.12
8,0,21:18.12
-3,1,21:18.12
-2,1,21:18.12
0,1,21:18.12
1,1,21:18.12
5,1,21:18.12
6,1,21:18.12
7,1,21:18.12
-2,2,21:18.12
-1,2,21:18.12
0,2,21:18.12
5,2,21:18.12
7,2,21:18.12
1,-6,22:18.12
1,-5,22:18.12
2,-5,22:18.12
2,-4,22:18.12
3,-4,22:18.12
0,-3,22:18.12
1,-3,22:18.12
2,-3,22:18.12
3,-3,22:18.12
4,-3,22:18.12
0,-2,22:18.12
1,-2,22:18.12
2,-2,22:17.13
3,-2,22:17.13
5,-2,22:18.12
6,-2,22:18.12
0,-1,22:18.12
1,-1,22:18.12
2,-1,22:18.12
4,-1,22:18.12
5,-1,22:18.12
7,-1,22:18.12
8,-1,22:18.12
-3,0,22:18.12
0,0,22:18.12
1,0,22:18.12
4,0,22:18.12
8,0,22:18.12
-3,1,22:18.12
0,1,22:18.12
4,1,22:18.12
5,1,22:18.12
7,1,22:18.12
0,2,22:18.12
-1,3,22:18.12
1,-6,23:18.12
2,-6,23:17.13
1,-5,23:18.12
2,-5,23:18.12
3,-5,23:18.12
1,-4,23:18.12
2,-4,23:18.12
3,-4,23:18.12
4,-4,23:18.12
1,-3,23:18.12
4,-3,23:18.12
2,-2,23:17.13
3,-2,23:17.13
0,-1,23:18.12
2,-1,23:18.12
0,0,23:18.12
1,0,23:18.12
2,0,23:18.12
0,-6,24:18.12
1,-6,24:18.12
2,-6,24:18.12
0,-5,24:18.12
1,-5,24:18.12
2,-5,24:18.12
3,-5,24:18.12
0,-4,24:18.12
1,-4,24:18.12
4,-4,24:18.12
1,-3,24:18.12
2,-3,24:17.13
2,-2,24:17.13
3,-2,24:17.13
0,-1,24:18.12
2,-1,24:17.13
3,-1,24:18.12
0,0,24:18.12
2,0,24:18.12
1,1,24:18.12
2,1,24:18.12
1,-7,25:18.12
0,-6,25:18.12
2,-6,25:18.12
0,-5,25:18.12
3,-5,25:18.12
0,-4,25:18.12
1,-4,25:18.12
2,-4,25:18.12
3,-4,25:18.12
1,-3,25:18.12
2,-3,25:18.12
3,-3,25:18.12
2,-2,25:18.12
3,-2,25:17.13
2,-1,25:18.12
3,-1,25:18.12
2,0,25:18.12
3,0,25:18.12
2,1,25:18.12
3,2,25:18.12
0,-4,26:18.12
1,-4,26:18.12
2,-4,26:18.12
3,-4,26:18.12
1,-3,26:18.12
3,-3,26:18.12
5,-3,26:18.12
1,-2,26:18.12
2,-2,26:17.13
3,-2,26:18.12
5,-2,26:18.12
1,-1,26:18.12
2,-1,26:18.12
3,-1,26:18.12
4,-1,26:18.12
1,0,26:18.12
2,0,26:18.12
3,0,26:18.12
2,1,26:18.12
3,1,26:18.12
2,2,26:18.12
1,-5,27:18.12
2,-5,27:18.12
0,-4,27:18.12
0,-3,27:18.12
2,-3,27:18.12
3,-3,27:18.12
4,-3,27:18.12
5,-3,27:18.12
2,-2,27:17.13
3,-2,27:17.13
5,-2,27:17.13
4,-1,27:18.12
1,0,27:18.12
3,0,27:18.12
4,0,27:18.12
1,1,27:18.12
3,1,27:18.12
3,-4,28:18.12
4,-4,28:18.12
2,-3,28:18.12
3,-3,28:18.12
4,-3,28:18.12
5,-3,28:18.12
1,-2,28:18.12
2,-2,28:18.12
3,-2,28:17.13
5,-2,28:18.12
1,-1,28:18.12
2,-1,28:18.12
3,-1,28:18.12
4,-1,28:18.12
4,-4,29:18.12
2,-3,29:18.12
1,-2,29:18.12
2,-2,29:18.12
3,-2,29:17.13
5,-2,29:18.12
1,-1,29:18.12
2,-1,29:18.12
3,-1,29:18.12
1,-2,30:18.12
3,-2,30:17.13
1,-1,30:18.12
2,-1,30:18.12
