[META]
version=2.0
spawnOnBlockType=2
spawnSunlight=True
spawnDarkness=True
spawnWater=False
spawnLava=False
underFill=False
randomRotation=True
dig=True
tree=False
branch=False
needsFoundation=True
rarity=100
collisionPercentage=20
spawnElevationMin=0
spawnElevationMax=200
spawnInBiome=Custom
[DATA]
4,-5,-8:17.13
4,-4,-8:17.13
4,-3,-8:17.13
4,-4,-7:17.13
5,-4,-7:17.13
3,-3,-7:17.13
4,-3,-7:17.13
4,-5,-6:17.13
5,-5,-6:17.13
3,-4,-6:17.13
4,-4,-6:17.13
5,-4,-6:17.13
4,-3,-6:17.13
5,-3,-6:17.13
4,-5,-5:17.13
5,-5,-5:17.13
4,-4,-5:17.13
5,-4,-5:17.13
6,-4,-5:17.13
4,-3,-5:17.13
4,-5,-4:17.13
5,-4,-4:17.13
6,-4,-4:17.13
5,-5,-3:17.13
5,-4,-3:17.13
6,-4,-3:17.13
5,-3,-3:17.13
5,-5,-2:17.13
6,-5,-2:17.13
4,-4,-2:17.13
5,-4,-2:17.13
6,-4,-2:17.13
4,-3,-2:17.13
5,-3,-2:17.13
6,-3,-2:17.13
5,-5,-1:17.13
4,-4,-1:17.13
5,-4,-1:17.13
6,-4,-1:17.13
4,-3,-1:17.13
5,-3,-1:17.13
6,-3,-1:17.13
5,-5,0:17.13
4,-4,0:17.13
5,-4,0:17.13
6,-4,0:17.13
5,-3,0:17.13
6,-3,0:17.13
5,-5,1:17.13
4,-4,1:17.13
5,-4,1:17.13
6,-4,1:17.13
5,-3,1:17.13
6,-3,1:17.13
4,-4,2:17.13
5,-4,2:17.13
6,-4,2:17.13
5,-3,2:17.13
6,-3,2:17.13
4,-5,3:17.13
4,-4,3:17.13
5,-4,3:17.13
6,-4,3:17.13
5,-3,3:17.13
6,-3,3:17.13
4,-5,4:17.13
4,-4,4:17.13
5,-4,4:17.13
6,-4,4:17.13
4,-3,4:18.12
5,-3,4:17.13
6,-3,4:17.13
3,-2,4:18.12
4,-2,4:17.13
3,-1,4:18.12
4,-1,4:18.12
4,0,4:18.12
5,-8,5:18.12
6,-8,5:18.12
5,-7,5:18.12
5,-6,5:18.12
5,-5,5:17.13
6,-5,5:17.13
5,-4,5:17.13
6,-4,5:17.13
4,-3,5:18.12
5,-3,5:17.13
6,-3,5:17.13
3,-2,5:18.12
4,-2,5:18.12
5,-2,5:18.12
7,-2,5:18.12
3,-1,5:18.12
4,-1,5:18.12
3,0,5:18.12
4,0,5:18.12
4,1,5:18.12
7,-11,6:18.4
3,-10,6:18.4
4,-10,6:18.4
6,-10,6:18.4
7,-10,6:18.4
4,-9,6:18.12
5,-9,6:18.12
6,-9,6:18.12
7,-9,6:18.12
5,-8,6:18.12
6,-8,6:18.12
5,-7,6:18.12
6,-7,6:18.12
5,-6,6:18.12
6,-6,6:18.12
4,-5,6:18.12
5,-5,6:18.12
6,-5,6:18.12
5,-4,6:17.13
6,-4,6:17.13
3,-3,6:18.12
5,-3,6:17.13
6,-3,6:17.13
7,-3,6:18.12
8,-3,6:18.12
3,-2,6:18.12
7,-2,6:18.12
8,-2,6:18.12
9,-2,6:18.12
5,-1,6:18.12
8,-1,6:18.12
11,-1,6:18.12
3,0,6:18.12
5,0,6:18.12
8,0,6:18.12
9,0,6:18.12
3,1,6:18.12
4,1,6:18.12
5,1,6:18.12
4,-11,7:18.4
6,-11,7:18.12
8,-11,7:18.12
3,-10,7:18.4
4,-10,7:18.4
5,-10,7:18.4
6,-10,7:18.12
7,-10,7:18.12
3,-9,7:18.12
4,-9,7:18.12
5,-9,7:18.12
7,-9,7:18.12
4,-8,7:18.12
5,-8,7:18.12
4,-7,7:18.12
5,-7,7:18.12
6,-7,7:18.12
4,-6,7:18.12
7,-6,7:18.12
1,-5,7:17.13
4,-5,7:18.12
3,-4,7:17.13
4,-4,7:17.13
5,-4,7:17.13
6,-4,7:17.13
4,-3,7:18.12
5,-3,7:17.13
6,-3,7:17.13
7,-3,7:18.12
8,-3,7:18.12
9,-3,7:18.12
3,-2,7:18.12
7,-2,7:18.12
8,-2,7:18.12
9,-2,7:18.12
10,-2,7:18.12
11,-2,7:18.12
12,-2,7:18.12
13,-2,7:18.4
8,-1,7:18.12
9,-1,7:18.12
10,-1,7:18.12
11,-1,7:18.12
12,-1,7:18.12
8,0,7:18.12
9,0,7:18.12
10,0,7:18.12
11,0,7:18.12
12,0,7:18.4
13,0,7:18.4
8,1,7:18.12
9,1,7:18.12
11,1,7:18.12
12,1,7:18.4
3,-10,8:18.4
5,-10,8:18.4
3,-9,8:18.12
5,-9,8:18.12
6,-9,8:18.12
3,-8,8:18.12
5,-8,8:18.12
6,-8,8:18.12
3,-7,8:18.12
5,-7,8:18.12
3,-6,8:18.12
5,-6,8:18.12
5,-5,8:18.12
0,-4,8:17.13
1,-4,8:17.13
2,-4,8:17.13
5,-4,8:17.13
6,-4,8:17.13
7,-4,8:18.12
8,-4,8:18.12
3,-3,8:18.12
4,-3,8:17.13
5,-3,8:17.13
6,-3,8:17.13
7,-3,8:18.12
8,-3,8:18.12
9,-3,8:18.12
10,-3,8:18.12
11,-3,8:18.12
0,-2,8:18.12
1,-2,8:18.12
2,-2,8:18.12
3,-2,8:18.12
4,-2,8:18.12
7,-2,8:18.12
8,-2,8:18.12
11,-2,8:18.12
12,-2,8:18.12
-1,-1,8:18.12
0,-1,8:18.12
1,-1,8:18.12
2,-1,8:18.12
7,-1,8:18.12
8,-1,8:18.12
10,-1,8:18.12
12,-1,8:18.12
7,0,8:18.12
8,0,8:18.12
8,1,8:18.12
5,-8,9:18.12
3,-7,9:18.12
4,-7,9:18.12
5,-7,9:18.12
4,-6,9:18.12
5,-6,9:18.12
8,-6,9:18.12
4,-5,9:18.12
5,-5,9:17.13
8,-5,9:18.12
3,-4,9:18.12
4,-4,9:18.12
5,-4,9:17.13
6,-4,9:17.13
7,-4,9:18.12
9,-4,9:18.12
2,-3,9:18.12
3,-3,9:18.12
5,-3,9:17.13
6,-3,9:17.13
-2,-2,9:18.12
-1,-2,9:18.12
0,-2,9:18.12
1,-2,9:18.12
2,-2,9:18.12
3,-2,9:18.12
4,-2,9:18.12
5,-2,9:18.12
-2,-1,9:18.12
-1,-1,9:18.12
0,-1,9:18.12
1,-1,9:18.12
2,-1,9:18.12
3,-1,9:18.12
4,-1,9:18.12
-2,0,9:18.12
-1,0,9:18.12
0,0,9:18.12
1,0,9:18.12
2,0,9:18.12
0,1,9:18.12
1,1,9:18.12
2,1,9:18.12
0,2,9:18.4
1,2,9:18.4
2,2,9:18.4
3,-8,10:18.12
4,-8,10:18.12
3,-7,10:18.12
4,-7,10:18.12
5,-7,10:18.12
6,-7,10:18.12
10,-7,10:18.12
3,-6,10:18.12
4,-6,10:18.12
5,-6,10:18.12
8,-6,10:18.12
9,-6,10:18.12
4,-5,10:18.12
5,-5,10:18.12
6,-5,10:18.12
8,-5,10:17.13
9,-5,10:18.12
10,-5,10:18.12
2,-4,10:18.12
4,-4,10:18.12
5,-4,10:17.13
6,-4,10:17.13
7,-4,10:18.12
8,-4,10:18.12
9,-4,10:18.12
10,-4,10:18.12
5,-3,10:17.13
6,-3,10:17.13
10,-3,10:18.12
-1,-2,10:18.12
2,-2,10:18.12
0,-1,10:18.12
1,-1,10:18.12
2,-1,10:18.12
3,-1,10:18.12
4,-1,10:18.12
0,0,10:18.12
1,0,10:18.12
2,0,10:18.12
3,0,10:18.12
4,0,10:18.12
0,1,10:18.12
1,1,10:18.12
2,1,10:18.12
1,2,10:18.4
10,-9,11:17.13
3,-8,11:18.12
4,-8,11:18.12
9,-8,11:18.12
10,-8,11:18.12
11,-8,11:18.12
12,-8,11:18.12
2,-7,11:18.12
3,-7,11:18.12
8,-7,11:18.12
9,-7,11:18.12
10,-7,11:18.12
11,-7,11:18.12
12,-7,11:18.12
5,-6,11:18.12
7,-6,11:18.12
8,-6,11:18.12
9,-6,11:18.12
10,-6,11:18.12
11,-6,11:18.12
12,-6,11:18.12
2,-5,11:18.12
3,-5,11:18.12
4,-5,11:18.12
5,-5,11:18.12
6,-5,11:18.12
8,-5,11:18.12
9,-5,11:18.12
10,-5,11:18.12
11,-5,11:18.12
4,-4,11:18.12
5,-4,11:17.13
6,-4,11:17.13
7,-4,11:18.12
8,-4,11:18.12
9,-4,11:18.12
10,-4,11:18.12
11,-4,11:18.12
5,-3,11:17.13
6,-3,11:17.13
7,-3,11:17.13
8,-3,11:18.12
9,-3,11:18.12
10,-3,11:18.12
11,-3,11:18.12
7,-2,11:18.12
8,-2,11:18.12
10,-9,12:18.12
9,-8,12:18.12
11,-8,12:18.12
8,-7,12:18.12
4,-6,12:18.12
10,-6,12:18.12
2,-5,12:18.12
3,-5,12:18.12
4,-5,12:18.12
5,-5,12:18.12
3,-4,12:18.12
4,-4,12:18.12
5,-4,12:17.13
6,-4,12:17.13
7,-4,12:18.12
8,-4,12:18.12
4,-3,12:18.12
5,-3,12:17.13
6,-3,12:17.13
7,-3,12:18.12
8,-3,12:18.12
9,-3,12:18.12
10,-3,12:18.12
5,-2,12:18.12
6,-2,12:18.12
7,-2,12:18.12
8,-2,12:18.12
9,-2,12:18.12
5,-1,12:18.12
6,-1,12:18.12
4,0,12:18.12
5,0,12:18.12
6,0,12:18.12
2,-6,13:18.12
3,-6,13:18.12
4,-6,13:18.12
5,-6,13:18.12
1,-5,13:18.12
2,-5,13:18.12
3,-5,13:18.12
1,-4,13:18.12
2,-4,13:18.12
3,-4,13:18.12
4,-4,13:18.12
5,-4,13:17.13
6,-4,13:17.13
8,-4,13:18.12
9,-4,13:18.12
3,-3,13:18.12
4,-3,13:18.12
5,-3,13:17.13
6,-3,13:17.13
5,-2,13:18.12
6,-2,13:18.12
8,-2,13:18.12
9,-2,13:18.12
10,-2,13:18.12
5,-1,13:18.12
6,-1,13:18.12
7,-1,13:18.12
4,0,13:18.12
5,0,13:18.12
6,0,13:18.12
4,1,13:18.12
5,1,13:18.12
6,1,13:18.12
1,-6,14:18.12
2,-6,14:18.12
3,-6,14:18.12
5,-5,14:18.12
6,-5,14:18.12
8,-5,14:18.12
1,-4,14:18.12
3,-4,14:18.12
4,-4,14:18.12
5,-4,14:18.12
6,-4,14:18.12
7,-4,14:18.12
2,-3,14:18.12
5,-3,14:18.12
6,-3,14:17.13
7,-3,14:18.12
5,-2,14:18.12
7,-2,14:18.12
4,-1,14:18.12
5,-1,14:18.12
6,-1,14:18.12
7,-1,14:18.12
4,0,14:18.12
5,0,14:18.12
7,0,14:18.12
5,1,14:18.12
6,1,14:18.12
7,1,14:18.12
6,2,14:18.4
8,-6,15:18.12
5,-5,15:18.12
6,-5,15:18.12
8,-5,15:18.12
3,-4,15:18.12
4,-4,15:18.12
5,-4,15:18.12
6,-4,15:18.12
7,-4,15:18.12
8,-4,15:18.12
4,-3,15:18.12
5,-3,15:18.12
6,-3,15:17.13
7,-3,15:18.12
7,-2,15:18.12
6,-6,16:18.12
7,-6,16:18.12
8,-6,16:18.12
4,-5,16:18.12
6,-5,16:18.12
8,-5,16:18.12
3,-4,16:18.12
4,-4,16:18.12
6,-4,16:17.1
8,-4,16:18.12
3,-3,16:18.12
4,-3,16:18.12
5,-3,16:17.1
6,-3,16:17.1
8,-3,16:18.12
7,-2,16:18.12
6,-6,17:18.12
7,-6,17:18.12
8,-6,17:18.12
6,-5,17:18.12
8,-5,17:18.12
5,-4,17:18.12
6,-4,17:18.12
7,-4,17:18.12
8,-4,17:18.12
4,-3,17:18.12
5,-3,17:18.12
6,-3,17:18.12
7,-3,17:18.12
3,-2,17:18.12
4,-2,17:18.12
5,-2,17:18.12
6,-2,17:18.12
6,-6,18:18.12
5,-5,18:18.12
6,-5,18:18.12
4,-4,18:18.12
5,-4,18:18.12
6,-4,18:18.12
3,-3,18:18.12
4,-3,18:18.12
5,-3,18:18.12
6,-3,18:18.12
3,-2,18:18.12
4,-2,18:18.12
5,-2,18:18.12
6,-2,18:18.12
7,-2,18:18.12
5,-4,19:18.12
6,-4,19:18.12
7,-4,19:18.12
5,-3,19:18.12
6,-3,19:17.1
7,-3,19:18.12
6,-2,19:18.12
7,-2,19:18.12
5,-4,20:18.4
6,-4,20:18.4
5,-3,20:18.4
6,-3,20:17.1
6,-2,20:18.4
7,-2,20:18.4
5,-4,21:18.4
