[META]
version=2.0
spawnOnBlockType=2
spawnSunlight=True
spawnDarkness=True
spawnWater=False
spawnLava=False
underFill=False
randomRotation=True
dig=True
tree=False
branch=False
needsFoundation=True
rarity=100
collisionPercentage=20
spawnElevationMin=0
spawnElevationMax=200
spawnInBiome=Custom
[DATA]
5,-5,-8:17.13
5,-4,-8:17.13
4,-5,-7:17.13
6,-5,-7:17.13
5,-4,-7:17.13
5,-5,-6:17.13
4,-4,-6:17.13
5,-4,-6:17.13
6,-4,-6:17.13
5,-3,-6:17.13
4,-4,-5:17.13
5,-4,-5:17.13
6,-4,-5:17.13
5,-3,-5:17.13
5,-4,-4:17.13
6,-4,-4:17.13
5,-3,-4:17.13
6,-3,-4:17.13
5,-5,-3:17.13
5,-4,-3:17.13
6,-4,-3:17.13
4,-5,-2:17.13
5,-5,-2:17.13
6,-5,-2:17.13
4,-4,-2:17.13
5,-4,-2:17.13
5,-5,-1:17.13
4,-4,-1:17.13
5,-4,-1:17.13
6,-4,-1:17.13
5,-3,-1:17.13
5,-5,0:17.13
4,-4,0:17.13
5,-4,0:17.13
6,-4,0:17.13
5,-3,0:17.13
5,-5,1:17.13
5,-4,1:17.13
6,-4,1:17.13
5,-3,1:17.13
5,-5,2:17.13
5,-4,2:17.13
6,-4,2:17.13
5,-3,2:17.13
5,-5,3:17.13
5,-4,3:17.13
6,-4,3:17.13
5,-3,3:17.13
5,-5,4:17.13
5,-4,4:17.13
6,-4,4:17.13
5,-3,4:17.13
5,-5,5:17.13
5,-4,5:17.13
6,-4,5:17.13
5,-3,5:17.13
5,-5,6:17.13
6,-5,6:17.13
5,-4,6:17.13
6,-4,6:17.13
5,-3,6:17.13
4,-5,7:17.13
5,-5,7:17.13
6,-5,7:17.13
5,-4,7:17.13
6,-4,7:17.13
5,-3,7:17.13
5,-5,8:17.13
5,-4,8:17.13
6,-4,8:17.13
5,-3,8:17.13
5,-5,9:17.13
5,-4,9:17.13
6,-4,9:17.13
5,-3,9:17.13
5,-5,10:17.13
5,-4,10:17.13
6,-4,10:17.13
5,-3,10:17.13
6,-3,10:18.12
5,-5,11:17.13
6,-5,11:17.13
5,-4,11:17.13
6,-4,11:17.13
6,-3,11:18.12
7,-3,11:18.12
6,-2,11:18.12
7,-2,11:18.12
6,-1,11:18.12
8,-1,11:18.12
6,0,11:18.12
8,0,11:18.12
8,1,11:18.12
5,-5,12:17.13
6,-5,12:17.13
5,-4,12:17.13
6,-4,12:18.12
7,-4,12:18.12
6,-3,12:18.12
7,-3,12:18.12
6,-2,12:18.12
7,-2,12:18.12
8,-2,12:18.12
5,-1,12:18.12
6,-1,12:18.12
7,-1,12:18.12
8,-1,12:18.12
9,-1,12:18.12
10,-1,12:18.12
5,0,12:18.12
6,0,12:18.12
7,0,12:18.12
8,0,12:18.12
9,0,12:18.12
10,0,12:18.12
6,1,12:18.12
8,1,12:18.12
9,1,12:18.12
7,-7,13:18.12
7,-6,13:18.12
4,-5,13:17.13
5,-5,13:17.13
6,-5,13:18.12
5,-4,13:17.13
6,-4,13:17.13
7,-4,13:18.12
6,-3,13:18.12
5,-2,13:18.12
6,-2,13:18.12
8,-2,13:18.12
9,-2,13:18.12
5,-1,13:18.12
10,-1,13:18.12
5,0,13:18.12
7,-8,14:18.12
6,-7,14:18.12
7,-7,14:18.12
6,-6,14:18.12
7,-6,14:18.12
5,-5,14:17.13
6,-5,14:18.12
5,-4,14:17.13
6,-4,14:17.13
2,-3,14:18.12
4,-3,14:18.12
6,-3,14:17.13
7,-3,14:17.13
8,-2,14:18.12
9,-2,14:18.12
9,-1,14:18.12
9,0,14:18.12
10,0,14:18.12
5,-8,15:18.12
6,-8,15:18.12
7,-8,15:18.12
8,-8,15:18.12
5,-7,15:18.12
6,-7,15:18.12
7,-7,15:18.12
8,-7,15:18.12
5,-6,15:18.12
6,-6,15:18.12
5,-5,15:17.13
6,-5,15:18.12
7,-5,15:18.12
4,-4,15:17.13
5,-4,15:17.13
6,-4,15:17.13
7,-4,15:18.12
2,-3,15:18.12
4,-3,15:17.13
5,-3,15:18.12
6,-3,15:18.12
7,-3,15:18.12
9,-3,15:18.12
12,-3,15:18.4
2,-2,15:18.12
3,-2,15:18.12
4,-2,15:18.12
5,-2,15:18.12
6,-2,15:18.12
7,-2,15:18.12
8,-2,15:18.12
9,-2,15:18.12
10,-2,15:18.12
11,-2,15:18.12
12,-2,15:18.4
3,-1,15:18.12
7,-1,15:18.12
8,-1,15:18.12
9,-1,15:18.12
10,-1,15:18.12
11,-1,15:18.12
12,-1,15:18.4
9,0,15:18.12
10,0,15:18.12
11,0,15:18.12
9,1,15:18.12
10,1,15:18.12
11,1,15:18.12
10,2,15:18.4
11,2,15:18.4
10,3,15:18.4
5,-8,16:18.12
5,-7,16:18.12
6,-7,16:18.12
3,-6,16:18.12
5,-6,16:17.13
6,-6,16:18.12
5,-5,16:17.13
6,-5,16:17.13
5,-4,16:17.13
6,-4,16:17.13
7,-4,16:18.12
8,-4,16:18.12
9,-4,16:18.12
10,-4,16:18.12
1,-3,16:18.12
2,-3,16:18.12
3,-3,16:18.12
4,-3,16:18.12
5,-3,16:18.12
6,-3,16:18.12
7,-3,16:18.12
9,-3,16:18.12
10,-3,16:18.12
11,-3,16:18.12
12,-3,16:18.4
1,-2,16:18.12
2,-2,16:18.12
3,-2,16:18.12
4,-2,16:18.12
5,-2,16:18.12
6,-2,16:18.12
8,-2,16:18.12
9,-2,16:18.12
10,-2,16:18.12
11,-2,16:18.12
12,-2,16:18.4
2,-1,16:18.12
3,-1,16:18.12
4,-1,16:18.12
6,-1,16:18.12
7,-1,16:18.12
9,-1,16:18.12
10,-1,16:18.12
11,-1,16:18.12
12,-1,16:18.4
2,0,16:18.12
11,0,16:18.12
9,1,16:18.12
10,1,16:18.12
10,2,16:18.4
4,-9,17:18.12
5,-9,17:18.12
4,-8,17:18.12
5,-8,17:18.12
4,-7,17:18.12
5,-7,17:18.12
6,-7,17:18.12
1,-6,17:18.12
2,-6,17:18.12
3,-6,17:18.12
4,-6,17:18.12
5,-6,17:18.12
6,-6,17:18.12
3,-5,17:18.12
4,-5,17:18.12
5,-5,17:17.13
6,-5,17:18.12
7,-5,17:18.12
4,-4,17:18.12
5,-4,17:17.13
6,-4,17:17.13
7,-4,17:18.12
8,-4,17:18.12
9,-4,17:18.12
10,-4,17:18.12
5,-3,17:17.13
6,-3,17:18.12
7,-3,17:18.12
9,-3,17:18.12
10,-3,17:18.12
11,-3,17:18.12
12,-3,17:18.4
5,-2,17:18.12
6,-2,17:18.12
7,-2,17:18.12
8,-2,17:18.12
2,-1,17:18.12
4,-1,17:18.12
5,-1,17:18.12
8,-1,17:18.12
9,-1,17:18.12
10,-1,17:18.12
2,0,17:18.12
3,0,17:18.12
6,0,17:18.12
10,0,17:18.12
11,0,17:18.12
5,-9,18:18.12
3,-8,18:18.12
5,-8,18:18.12
6,-8,18:18.12
3,-7,18:18.12
4,-7,18:18.12
8,-7,18:18.12
1,-6,18:18.12
2,-6,18:18.12
3,-6,18:18.12
4,-6,18:18.12
5,-6,18:18.12
7,-6,18:18.12
8,-6,18:18.12
1,-5,18:18.12
2,-5,18:18.12
3,-5,18:18.12
5,-5,18:17.13
6,-5,18:17.13
7,-5,18:18.12
8,-5,18:18.12
9,-5,18:18.12
10,-5,18:18.12
3,-4,18:18.12
4,-4,18:18.12
5,-4,18:17.13
6,-4,18:17.13
8,-4,18:18.12
9,-4,18:18.12
10,-4,18:18.12
4,-3,18:18.12
5,-3,18:18.12
6,-3,18:18.12
9,-3,18:18.12
10,-3,18:18.12
4,-2,18:18.12
5,-2,18:18.12
6,-2,18:18.12
7,-2,18:18.12
4,-1,18:18.12
5,-1,18:18.12
5,0,18:18.12
3,-7,19:18.12
4,-7,19:18.12
5,-7,19:18.12
9,-7,19:18.12
0,-6,19:18.12
1,-6,19:18.12
2,-6,19:18.12
5,-6,19:18.12
6,-6,19:18.12
7,-6,19:18.12
8,-6,19:18.12
9,-6,19:18.12
10,-6,19:18.12
0,-5,19:18.12
1,-5,19:18.12
2,-5,19:18.12
5,-5,19:17.13
6,-5,19:18.12
7,-5,19:18.12
8,-5,19:18.12
9,-5,19:18.12
10,-5,19:18.12
1,-4,19:18.12
2,-4,19:18.12
3,-4,19:18.12
5,-4,19:17.13
6,-4,19:17.13
3,-3,19:18.12
4,-3,19:18.12
5,-3,19:18.12
6,-3,19:18.12
10,-3,19:18.12
3,-2,19:18.12
4,-2,19:18.12
5,-2,19:18.12
6,-2,19:18.12
9,-2,19:18.12
10,-2,19:18.12
4,-1,19:18.12
5,-1,19:18.12
6,-1,19:18.12
5,0,19:18.12
6,0,19:18.12
9,-8,20:18.12
10,-8,20:18.12
1,-7,20:18.12
2,-7,20:18.12
7,-7,20:18.12
8,-7,20:18.12
9,-7,20:18.12
10,-7,20:18.12
3,-6,20:18.12
4,-6,20:18.12
5,-6,20:18.12
6,-6,20:18.12
7,-6,20:18.12
8,-6,20:18.12
9,-6,20:18.12
10,-6,20:18.12
4,-5,20:18.12
5,-5,20:17.13
6,-5,20:17.13
7,-5,20:18.12
8,-5,20:18.12
9,-5,20:18.12
4,-4,20:18.12
5,-4,20:17.13
6,-4,20:18.12
9,-4,20:18.12
5,-3,20:18.12
6,-3,20:18.12
5,-2,20:18.12
6,-2,20:18.12
7,-2,20:18.12
4,-1,20:18.12
6,-1,20:18.12
7,-1,20:18.12
4,0,20:18.12
5,0,20:18.12
6,0,20:18.12
7,0,20:18.12
5,1,20:18.12
6,1,20:18.12
9,-8,21:18.12
10,-7,21:18.12
2,-6,21:18.12
3,-6,21:18.12
4,-6,21:18.12
5,-6,21:18.12
6,-6,21:18.12
10,-6,21:18.12
3,-5,21:18.12
4,-5,21:18.12
5,-5,21:17.13
6,-5,21:17.13
4,-4,21:18.12
5,-4,21:18.12
6,-4,21:18.12
4,-3,21:18.12
5,-3,21:18.12
6,-3,21:18.12
5,-2,21:17.13
6,-2,21:18.12
4,0,21:18.12
4,-7,22:18.12
5,-7,22:18.12
6,-7,22:18.12
2,-6,22:18.12
3,-6,22:18.12
2,-5,22:18.12
3,-5,22:18.12
4,-5,22:18.12
5,-5,22:17.13
6,-5,22:17.13
3,-4,22:18.12
4,-4,22:18.12
5,-4,22:17.13
6,-4,22:18.12
5,-3,22:18.12
6,-3,22:18.12
7,-3,22:18.12
5,-2,22:18.12
6,-2,22:18.12
3,-7,23:18.12
2,-6,23:18.12
3,-6,23:18.12
4,-6,23:18.12
5,-6,23:18.12
6,-6,23:18.12
1,-5,23:18.12
2,-5,23:18.12
3,-5,23:18.12
4,-5,23:18.12
5,-5,23:18.12
6,-5,23:18.12
2,-4,23:18.12
3,-4,23:18.12
5,-4,23:18.12
6,-4,23:18.12
7,-4,23:18.12
7,-3,23:18.12
6,-7,24:18.12
4,-6,24:18.12
5,-6,24:18.12
6,-6,24:18.12
7,-6,24:18.12
3,-5,24:18.12
4,-5,24:18.12
5,-5,24:18.12
6,-5,24:18.12
7,-5,24:18.12
3,-4,24:18.12
4,-4,24:18.12
5,-4,24:18.12
6,-4,24:18.12
7,-4,24:18.12
5,-3,24:18.12
6,-3,24:18.12
7,-3,24:18.12
6,-7,25:18.12
3,-6,25:18.12
5,-6,25:18.12
6,-6,25:18.12
7,-6,25:18.12
3,-5,25:18.12
5,-5,25:18.12
6,-5,25:18.12
7,-5,25:18.12
3,-4,25:18.12
4,-4,25:18.12
5,-4,25:18.12
7,-4,25:18.12
8,-4,25:18.12
6,-2,25:18.12
5,-7,26:18.12
6,-7,26:18.12
7,-7,26:18.12
5,-6,26:18.12
7,-6,26:18.12
4,-5,26:18.12
5,-5,26:18.12
6,-5,26:17.13
5,-4,26:18.12
6,-4,26:18.12
5,-3,26:18.12
6,-5,27:17.13
5,-4,27:18.12
6,-4,27:18.12
5,-3,27:18.12
6,-5,28:17.13
5,-4,28:18.12
