[META]
version=2.0
spawnOnBlockType=2
spawnSunlight=True
spawnDarkness=True
spawnWater=False
spawnLava=False
underFill=False
randomRotation=True
dig=True
tree=False
branch=False
needsFoundation=True
rarity=100
collisionPercentage=20
spawnElevationMin=0
spawnElevationMax=200
spawnInBiome=Custom
[DATA]
-13,8,-8:17.13
-13,10,-8:17.13
-14,5,-7:17.13
-14,8,-7:17.13
-13,9,-7:17.13
-12,9,-7:17.13
-13,10,-7:17.13
-12,10,-7:17.13
-13,5,-6:17.13
-13,6,-6:17.13
-12,6,-6:17.13
-13,7,-6:17.13
-14,9,-6:17.13
-13,9,-6:17.13
-12,9,-6:17.13
-14,10,-6:17.13
-13,10,-6:17.13
-13,4,-5:17.13
-13,6,-5:17.13
-12,6,-5:17.13
-14,7,-5:17.13
-13,7,-5:17.13
-12,7,-5:17.13
-14,9,-5:17.13
-14,10,-5:17.13
-13,10,-5:17.13
-12,10,-5:17.13
-13,11,-5:17.13
-13,5,-4:17.13
-12,5,-4:17.13
-13,6,-4:17.13
-12,6,-4:17.13
-11,6,-4:17.13
-13,7,-4:17.13
-12,7,-4:17.13
-11,7,-4:17.13
-13,8,-4:17.13
-12,8,-4:17.13
-13,9,-4:17.13
-12,9,-4:17.13
-14,10,-4:17.13
-13,10,-4:17.13
-12,10,-4:17.13
-14,6,-3:17.13
-12,6,-3:17.13
-14,7,-3:17.13
-13,7,-3:17.13
-12,7,-3:17.13
-14,8,-3:17.13
-12,8,-3:17.13
-15,9,-3:17.13
-14,9,-3:17.13
-14,10,-3:17.13
-13,10,-3:17.13
-14,6,-2:17.13
-13,6,-2:17.13
-12,6,-2:17.13
-14,7,-2:17.13
-13,7,-2:17.13
-12,7,-2:17.13
-15,8,-2:17.13
-14,8,-2:17.13
-13,8,-2:17.13
-12,8,-2:17.13
-15,9,-2:17.13
-14,9,-2:17.13
-13,9,-2:17.13
-14,10,-2:17.13
-13,6,-1:17.13
-14,7,-1:17.13
-13,7,-1:17.13
-12,7,-1:17.13
-14,8,-1:17.13
-13,8,-1:17.13
-12,8,-1:17.13
-14,9,-1:17.13
-13,9,-1:17.13
-13,7,0:17.13
-14,8,0:17.13
-13,8,0:17.13
-14,9,0:17.13
-13,9,0:17.13
-13,7,1:17.13
-14,8,1:17.13
-13,8,1:17.13
-12,8,1:17.13
-14,9,1:17.13
-13,9,1:17.13
-14,8,2:17.13
-13,8,2:17.13
-12,8,2:17.13
-14,9,2:17.13
-13,9,2:17.13
-14,8,3:17.13
-13,8,3:17.13
-12,8,3:17.13
-14,9,3:17.13
-13,9,3:17.13
-13,6,4:17.13
-13,7,4:17.13
-14,8,4:17.13
-13,8,4:17.13
-12,8,4:17.13
-14,9,4:17.13
-13,9,4:17.13
-12,9,4:17.13
-16,11,4:18.12
-11,6,5:18.12
-9,6,5:18.12
-12,7,5:17.13
-11,7,5:18.12
-16,8,5:18.12
-15,8,5:18.12
-14,8,5:17.13
-13,8,5:17.13
-12,8,5:17.13
-17,9,5:17.13
-16,9,5:18.12
-15,9,5:17.13
-14,9,5:17.13
-13,9,5:17.13
-12,9,5:17.13
-17,10,5:18.12
-16,11,5:18.12
-15,11,5:18.12
-15,12,5:18.12
-10,5,6:18.12
-9,5,6:18.12
-8,5,6:18.12
-7,5,6:18.12
-6,5,6:18.4
-11,6,6:18.12
-10,6,6:18.12
-9,6,6:18.12
-8,6,6:18.12
-15,7,6:18.12
-12,7,6:18.12
-11,7,6:18.12
-16,8,6:18.12
-15,8,6:18.12
-14,8,6:17.13
-13,8,6:17.13
-12,8,6:17.13
-11,8,6:18.12
-17,9,6:18.12
-16,9,6:18.12
-15,9,6:18.12
-14,9,6:17.13
-13,9,6:17.13
-12,9,6:17.13
-17,10,6:18.12
-16,10,6:18.12
-15,10,6:18.12
-13,10,6:18.12
-17,11,6:18.12
-16,11,6:18.12
-15,11,6:18.12
-14,11,6:18.12
-13,11,6:18.12
-12,11,6:18.12
-15,12,6:18.12
-14,12,6:18.12
-13,12,6:18.12
-11,12,6:18.12
-11,14,6:18.12
-10,4,7:18.12
-9,4,7:18.12
-8,4,7:18.12
-7,4,7:18.4
-6,4,7:18.4
-11,5,7:18.12
-10,5,7:18.12
-9,5,7:18.12
-8,5,7:18.12
-7,5,7:18.12
-6,5,7:18.4
-12,6,7:18.12
-11,6,7:18.12
-10,6,7:18.12
-9,6,7:18.12
-8,6,7:18.12
-7,6,7:18.12
-6,6,7:18.4
-15,7,7:18.12
-14,7,7:17.13
-13,7,7:18.12
-12,7,7:18.12
-10,7,7:18.12
-14,8,7:17.13
-13,8,7:17.13
-12,8,7:17.13
-11,8,7:18.12
-10,8,7:18.12
-18,9,7:18.12
-17,9,7:18.12
-14,9,7:17.13
-13,9,7:17.13
-12,9,7:17.13
-11,9,7:18.12
-13,10,7:17.13
-12,10,7:18.12
-17,11,7:18.12
-16,11,7:18.12
-13,11,7:17.13
-12,11,7:18.12
-14,12,7:18.12
-13,12,7:18.12
-12,12,7:18.12
-11,12,7:18.12
-15,13,7:18.12
-14,13,7:18.12
-13,13,7:18.12
-12,13,7:18.12
-11,13,7:18.12
-14,14,7:18.12
-13,14,7:18.12
-12,14,7:18.12
-11,14,7:18.12
-11,15,7:18.12
-10,15,7:18.12
-12,16,7:18.12
-11,16,7:18.12
-14,4,8:17.13
-11,4,8:18.12
-10,4,8:18.12
-8,4,8:18.12
-15,5,8:17.13
-14,5,8:17.13
-12,5,8:18.12
-11,5,8:18.12
-10,5,8:18.12
-9,5,8:18.12
-8,5,8:18.12
-17,6,8:18.12
-14,6,8:17.13
-12,6,8:18.12
-10,6,8:18.12
-9,6,8:18.12
-16,7,8:18.12
-14,7,8:17.13
-12,7,8:18.12
-17,8,8:18.12
-16,8,8:18.12
-15,8,8:18.12
-14,8,8:17.13
-13,8,8:17.13
-12,8,8:17.13
-14,9,8:17.13
-13,9,8:17.13
-12,9,8:18.12
-11,9,8:18.12
-13,10,8:18.12
-12,10,8:18.12
-11,10,8:18.12
-13,11,8:18.12
-12,11,8:18.12
-11,11,8:18.12
-14,12,8:18.12
-13,12,8:18.12
-12,12,8:18.12
-11,12,8:18.12
-14,13,8:18.12
-12,13,8:18.12
-11,13,8:18.12
-10,13,8:18.12
-15,14,8:18.12
-14,14,8:18.12
-13,14,8:18.12
-12,14,8:18.12
-11,14,8:18.12
-9,14,8:18.12
-11,15,8:18.12
-10,15,8:18.12
-9,15,8:18.12
-11,16,8:18.12
-10,16,8:18.12
-19,5,9:18.12
-12,5,9:18.12
-19,6,9:18.12
-18,6,9:18.12
-17,6,9:18.12
-12,6,9:18.12
-11,6,9:18.12
-10,6,9:18.12
-18,7,9:18.12
-17,7,9:18.12
-16,7,9:18.12
-15,7,9:18.12
-14,7,9:18.12
-13,7,9:18.12
-12,7,9:18.12
-19,8,9:18.12
-18,8,9:18.12
-17,8,9:18.12
-16,8,9:18.12
-15,8,9:18.12
-14,8,9:18.12
-13,8,9:17.13
-12,8,9:17.13
-14,9,9:18.12
-13,9,9:17.13
-12,9,9:17.13
-11,9,9:18.12
-13,11,9:18.12
-10,11,9:18.12
-14,12,9:18.12
-14,13,9:18.12
-19,4,10:18.12
-11,4,10:18.12
-20,5,10:18.4
-19,5,10:18.12
-18,5,10:18.12
-12,5,10:18.12
-11,5,10:18.12
-10,5,10:18.12
-19,6,10:18.12
-18,6,10:18.12
-17,6,10:18.12
-15,6,10:18.12
-14,6,10:18.12
-12,6,10:18.12
-11,6,10:18.12
-10,6,10:18.12
-19,7,10:18.12
-18,7,10:18.12
-17,7,10:18.12
-16,7,10:18.12
-15,7,10:18.12
-14,7,10:18.12
-13,7,10:18.12
-12,7,10:18.12
-11,7,10:18.12
-20,8,10:18.4
-19,8,10:18.12
-18,8,10:18.12
-17,8,10:18.12
-16,8,10:18.12
-13,8,10:17.13
-12,8,10:17.13
-20,9,10:18.4
-19,9,10:18.12
-18,9,10:18.12
-17,9,10:18.12
-16,9,10:18.12
-15,9,10:18.12
-14,9,10:18.12
-13,9,10:17.13
-12,9,10:17.13
-11,9,10:17.13
-10,9,10:18.12
-9,9,10:18.12
-10,10,10:18.12
-9,10,10:18.12
-8,10,10:18.12
-7,10,10:18.12
-10,11,10:18.12
-9,11,10:18.12
-10,12,10:18.12
-9,12,10:18.12
-12,4,11:18.12
-11,4,11:18.12
-10,4,11:18.12
-12,5,11:18.12
-18,6,11:18.12
-13,6,11:18.12
-12,6,11:18.12
-11,6,11:18.12
-10,6,11:18.12
-19,7,11:18.12
-18,7,11:18.12
-17,7,11:18.12
-16,7,11:18.12
-13,7,11:18.12
-12,7,11:18.12
-11,7,11:18.12
-18,8,11:18.12
-13,8,11:17.13
-12,8,11:18.12
-11,8,11:18.12
-10,8,11:18.12
-19,9,11:18.12
-18,9,11:18.12
-17,9,11:18.12
-16,9,11:18.12
-13,9,11:17.13
-12,9,11:18.12
-11,9,11:18.12
-10,9,11:18.12
-9,9,11:18.12
-8,9,11:18.12
-7,9,11:18.12
-6,9,11:18.4
-17,10,11:18.12
-16,10,11:18.12
-13,10,11:18.12
-11,10,11:18.12
-10,10,11:18.12
-9,10,11:18.12
-8,10,11:18.12
-7,10,11:18.12
-6,10,11:18.4
-12,11,11:18.12
-11,11,11:18.12
-10,11,11:18.12
-9,11,11:18.12
-8,11,11:18.12
-7,11,11:18.12
-6,11,11:18.12
-5,11,11:18.12
-11,12,11:18.12
-10,12,11:18.12
-9,12,11:18.12
-8,12,11:18.12
-6,12,11:18.12
-9,13,11:18.12
-10,4,12:18.12
-9,4,12:18.12
-14,5,12:18.12
-10,5,12:18.12
-14,6,12:18.12
-13,6,12:18.12
-13,7,12:18.12
-12,7,12:18.12
-13,8,12:17.13
-12,8,12:18.12
-11,8,12:18.12
-10,8,12:18.12
-9,8,12:18.12
-8,8,12:18.12
-6,8,12:18.4
-13,9,12:17.13
-12,9,12:17.13
-11,9,12:18.12
-7,9,12:18.12
-6,9,12:18.4
-14,10,12:18.12
-13,10,12:18.12
-12,10,12:18.12
-11,10,12:18.12
-8,10,12:18.12
-6,10,12:18.4
-5,10,12:18.4
-12,11,12:18.12
-11,11,12:18.12
-10,11,12:18.12
-11,12,12:18.12
-10,12,12:18.12
-14,5,13:18.12
-13,5,13:18.12
-14,6,13:18.12
-13,6,13:18.12
-12,6,13:18.12
-11,6,13:18.12
-14,7,13:18.12
-13,7,13:18.12
-12,7,13:18.12
-11,7,13:18.12
-14,8,13:18.12
-13,8,13:17.13
-12,8,13:17.13
-11,8,13:18.12
-13,9,13:17.13
-12,9,13:17.13
-16,10,13:18.12
-15,10,13:18.12
-14,10,13:18.12
-13,10,13:18.12
-11,10,13:18.12
-16,11,13:18.12
-15,11,13:18.12
-14,11,13:18.12
-13,11,13:18.12
-11,11,13:18.12
-10,11,13:18.12
-15,12,13:18.12
-12,12,13:18.12
-11,12,13:18.12
-10,12,13:18.12
-11,13,13:18.12
-14,4,14:18.12
-13,4,14:18.12
-15,5,14:18.12
-14,5,14:18.12
-13,5,14:18.12
-15,6,14:18.12
-14,6,14:18.12
-15,7,14:18.12
-14,7,14:18.12
-13,7,14:18.12
-13,8,14:17.13
-12,8,14:18.12
-13,9,14:17.13
-12,9,14:17.13
-11,9,14:18.12
-16,10,14:18.12
-15,10,14:18.12
-14,10,14:18.12
-13,10,14:18.12
-12,10,14:18.12
-11,10,14:18.12
-10,10,14:18.12
-17,11,14:18.12
-16,11,14:18.12
-15,11,14:18.12
-14,11,14:18.12
-13,11,14:18.12
-16,12,14:18.12
-15,12,14:18.12
-14,12,14:18.12
-15,13,14:18.12
-14,7,15:18.12
-13,7,15:18.12
-12,7,15:18.12
-13,8,15:18.12
-12,8,15:18.12
-11,8,15:18.12
-13,9,15:17.13
-12,9,15:17.13
-11,9,15:18.12
-10,9,15:18.12
-9,9,15:18.12
-15,10,15:18.12
-14,10,15:18.12
-12,10,15:18.12
-11,10,15:18.12
-10,10,15:18.12
-16,12,15:18.12
-14,12,15:18.12
-15,13,15:18.12
-14,7,16:18.12
-13,7,16:18.12
-12,7,16:18.12
-14,8,16:18.12
-13,8,16:18.12
-11,8,16:18.12
-10,8,16:18.12
-13,9,16:17.13
-12,9,16:17.13
-11,9,16:18.12
-10,9,16:18.12
-9,9,16:18.12
-12,10,16:18.12
-11,10,16:18.12
-10,10,16:18.12
-12,11,16:18.12
-11,11,16:18.12
-14,8,17:18.12
-13,8,17:18.12
-11,8,17:18.12
-10,8,17:18.12
-9,8,17:18.12
-14,9,17:18.12
-12,9,17:18.12
-11,9,17:18.12
-9,9,17:18.12
-13,10,17:18.12
-12,10,17:18.12
-11,10,17:18.12
-10,10,17:18.12
-9,10,17:18.12
-15,8,18:18.12
-14,8,18:18.12
-13,8,18:18.12
-12,8,18:18.12
-11,8,18:18.12
-10,8,18:18.12
-14,9,18:18.12
-12,9,18:17.13
-11,9,18:18.12
-10,9,18:18.12
-13,10,18:18.12
-12,10,18:18.12
-11,10,18:18.12
-13,11,18:18.12
-12,11,18:18.12
-14,7,19:18.12
-13,7,19:18.12
-15,8,19:18.12
-12,8,19:18.12
-11,8,19:18.12
-14,9,19:18.12
-12,9,19:18.12
-11,9,19:18.12
-10,9,19:18.12
-14,10,19:18.12
-13,10,19:18.12
-12,10,19:18.12
-11,10,19:18.12
-13,11,19:17.13
-12,11,19:18.12
-12,8,20:18.12
-12,9,20:18.12
-11,9,20:18.12
-13,10,20:18.12
-11,10,20:18.12
-13,11,20:18.12
-12,11,20:18.12
-11,11,20:18.12
-13,8,21:18.12
-12,8,21:18.12
-12,9,21:17.13
