[META]
version=2.0
spawnOnBlockType=2
spawnSunlight=True
spawnDarkness=True
spawnWater=False
spawnLava=False
underFill=False
randomRotation=True
dig=True
tree=False
branch=False
needsFoundation=True
rarity=100
collisionPercentage=20
spawnElevationMin=0
spawnElevationMax=200
spawnInBiome=Custom
[DATA]
1,-5,-8:17.12
4,-5,-8:17.12
-2,-4,-8:17.12
4,-4,-8:17.12
-2,-2,-8:17.12
-3,-1,-8:17.12
4,-1,-8:17.12
5,-1,-8:17.12
-3,0,-8:17.12
0,1,-8:17.12
3,1,-8:17.12
0,-5,-7:17.12
-2,-4,-7:17.12
3,-4,-7:17.12
4,-4,-7:17.12
-2,-2,-7:17.12
4,-1,-7:17.12
-3,0,-7:17.12
-2,0,-7:17.12
1,1,-7:17.12
3,1,-7:17.12
-1,-5,-6:17.12
0,-5,-6:17.12
-2,-4,-6:17.12
-1,-4,-6:17.12
2,-4,-6:17.12
3,-4,-6:17.12
-2,-2,-6:17.12
4,-1,-6:17.12
-2,0,-6:17.12
3,0,-6:17.12
1,1,-6:17.12
3,1,-6:17.12
-1,-5,-5:17.12
-1,-4,-5:17.12
2,-4,-5:17.12
2,-3,-5:17.12
-2,-2,-5:17.12
-1,-2,-5:17.12
3,-1,-5:17.12
4,-1,-5:17.12
-2,0,-5:17.12
-1,0,-5:17.12
1,0,-5:17.12
3,0,-5:17.12
1,1,-5:17.12
-1,-4,-4:17.12
-1,-3,-4:17.12
2,-3,-4:17.12
3,-3,-4:17.12
0,-2,-4:17.12
3,-1,-4:17.12
-1,0,-4:17.12
1,0,-4:17.12
-1,1,-4:17.12
1,-4,-3:17.12
-1,-3,-3:17.12
2,-3,-3:17.12
0,-2,-3:17.12
-2,-1,-3:17.12
3,-1,-3:17.12
-1,0,-3:17.12
1,0,-3:17.12
3,0,-3:17.12
-1,1,-3:17.12
0,1,-3:17.12
0,-4,-2:17.12
1,-4,-2:17.12
-1,-3,-2:17.12
0,-3,-2:17.12
1,-3,-2:17.12
2,-3,-2:17.12
-1,-2,-2:17.12
2,-2,-2:17.12
3,-2,-2:17.12
-2,-1,-2:17.12
3,-1,-2:17.12
-1,0,-2:17.12
0,0,-2:17.12
1,0,-2:17.12
2,0,-2:17.12
3,0,-2:17.12
-1,1,-2:17.12
0,1,-2:17.12
0,-5,-1:18.14
-2,-4,-1:18.14
-1,-4,-1:18.14
0,-4,-1:18.14
-1,-3,-1:18.14
0,-3,-1:17.12
1,-3,-1:17.12
2,-3,-1:17.12
-1,-2,-1:17.12
0,-2,-1:17.12
2,-2,-1:17.12
3,-2,-1:17.12
-1,-1,-1:17.12
2,-1,-1:17.12
-1,0,-1:17.12
0,0,-1:17.12
1,0,-1:17.12
2,0,-1:17.12
-1,-5,0:18.14
-2,-4,0:18.14
-1,-4,0:18.14
0,-4,0:18.14
-2,-3,0:18.14
-1,-3,0:18.14
0,-3,0:17.12
1,-3,0:17.12
0,-2,0:17.12
1,-2,0:17.12
2,-2,0:17.12
-1,-1,0:17.12
1,-1,0:17.12
2,-1,0:17.12
0,0,0:17.12
1,0,0:17.12
2,0,0:18.14
-1,-4,1:18.14
0,-2,1:17.12
1,-2,1:17.12
2,-2,1:17.12
0,-1,1:17.12
1,-1,1:17.12
2,-1,1:17.12
3,-1,1:17.12
0,0,1:17.12
1,0,1:17.12
2,-2,2:17.12
3,-2,2:17.12
8,-2,2:18.12
9,-2,2:18.12
0,-1,2:17.12
1,-1,2:17.12
2,-1,2:17.12
3,-1,2:17.12
0,0,2:17.12
1,0,2:17.12
3,-4,3:18.12
4,-4,3:18.12
5,-4,3:18.12
6,-4,3:18.12
2,-3,3:18.12
3,-3,3:18.12
4,-3,3:18.12
5,-3,3:18.12
6,-3,3:18.12
7,-3,3:18.12
1,-2,3:18.12
2,-2,3:18.12
3,-2,3:18.12
4,-2,3:18.12
5,-2,3:18.12
6,-2,3:18.12
7,-2,3:18.12
8,-2,3:18.12
9,-2,3:18.12
0,-1,3:17.12
1,-1,3:17.12
2,-1,3:18.12
3,-1,3:17.12
4,-1,3:18.12
5,-1,3:18.12
6,-1,3:18.12
7,-1,3:18.12
0,0,3:17.12
1,0,3:17.12
2,0,3:18.12
3,0,3:18.12
4,0,3:18.12
5,0,3:18.12
6,0,3:18.12
3,1,3:18.12
4,1,3:18.12
5,1,3:18.12
6,1,3:18.12
5,2,3:18.12
6,3,3:18.12
6,-9,4:18.4
6,-8,4:18.4
5,-7,4:18.12
6,-7,4:18.4
3,-6,4:18.12
4,-6,4:18.12
5,-6,4:18.12
2,-5,4:18.12
3,-5,4:18.12
5,-5,4:18.12
6,-5,4:18.12
1,-4,4:18.12
2,-4,4:18.12
3,-4,4:18.12
5,-4,4:18.12
6,-4,4:18.12
7,-4,4:18.12
-1,-3,4:18.12
0,-3,4:18.12
1,-3,4:18.12
2,-3,4:18.12
7,-3,4:18.12
8,-3,4:18.12
-2,-2,4:18.12
-1,-2,4:18.12
0,-2,4:18.12
1,-2,4:18.12
8,-2,4:18.12
9,-2,4:18.12
10,-2,4:18.4
11,-2,4:18.4
-2,-1,4:18.12
-1,-1,4:18.12
0,-1,4:18.12
1,-1,4:18.12
2,-1,4:18.12
3,-1,4:17.12
4,-1,4:17.12
7,-1,4:18.12
8,-1,4:18.12
-2,0,4:18.12
-1,0,4:18.12
0,0,4:18.12
1,0,4:18.12
2,0,4:18.12
7,0,4:18.12
8,0,4:18.12
-1,1,4:18.12
0,1,4:18.12
1,1,4:18.12
2,1,4:18.12
3,1,4:18.12
6,1,4:18.12
7,1,4:18.12
1,2,4:18.12
2,2,4:18.12
3,2,4:18.12
4,2,4:18.12
5,2,4:18.12
6,2,4:18.12
4,3,4:18.12
5,3,4:18.12
6,3,4:18.12
7,4,4:18.4
-7,-8,5:18.4
6,-8,5:18.4
7,-8,5:18.4
-7,-7,5:18.4
-6,-7,5:18.4
6,-7,5:18.4
-6,-6,5:18.4
1,-6,5:18.12
2,-6,5:18.12
3,-6,5:18.12
4,-6,5:18.12
5,-6,5:18.12
6,-6,5:18.12
-1,-5,5:18.12
0,-5,5:18.12
1,-5,5:18.12
2,-5,5:18.12
6,-5,5:18.12
7,-5,5:18.12
-3,-4,5:18.12
-2,-4,5:18.12
-1,-4,5:18.12
0,-4,5:18.12
1,-4,5:18.12
7,-4,5:18.12
8,-4,5:18.12
-4,-3,5:18.12
-3,-3,5:18.12
-2,-3,5:18.12
-1,-3,5:18.12
0,-3,5:18.12
1,-3,5:18.12
2,-3,5:18.12
8,-3,5:18.12
9,-3,5:18.12
10,-3,5:18.4
-4,-2,5:18.12
-3,-2,5:18.12
-2,-2,5:18.12
-1,-2,5:18.12
1,-2,5:18.12
2,-2,5:18.12
3,-2,5:18.12
5,-2,5:18.12
6,-2,5:18.12
9,-2,5:18.12
10,-2,5:18.4
11,-2,5:18.4
-3,-1,5:18.12
-2,-1,5:18.12
-1,-1,5:18.12
0,-1,5:17.12
2,-1,5:18.12
3,-1,5:18.12
4,-1,5:17.12
5,-1,5:18.12
6,-1,5:18.12
7,-1,5:18.12
8,-1,5:18.12
9,-1,5:18.12
-3,0,5:18.12
-2,0,5:18.12
-1,0,5:18.12
0,0,5:17.12
2,0,5:18.12
3,0,5:18.12
5,0,5:18.12
6,0,5:18.12
7,0,5:18.12
8,0,5:18.12
9,0,5:18.12
-3,1,5:18.12
-2,1,5:18.12
-1,1,5:18.12
0,1,5:18.12
1,1,5:18.12
2,1,5:18.12
6,1,5:18.12
7,1,5:18.12
8,1,5:18.12
9,1,5:18.12
10,1,5:18.4
-3,2,5:18.12
-2,2,5:18.12
-1,2,5:18.12
0,2,5:18.12
1,2,5:18.12
2,2,5:18.12
7,2,5:18.12
8,2,5:18.12
9,2,5:18.12
10,2,5:18.4
11,2,5:18.4
-3,3,5:18.12
-2,3,5:18.12
-1,3,5:18.12
0,3,5:18.12
1,3,5:18.12
2,3,5:18.12
3,3,5:18.12
4,3,5:18.12
5,3,5:18.12
6,3,5:18.12
7,3,5:18.12
11,3,5:18.4
-3,4,5:18.12
1,4,5:18.12
7,4,5:18.4
-3,5,5:18.4
0,5,5:18.4
8,5,5:18.4
7,-8,6:18.4
-6,-7,6:18.4
7,-7,6:18.4
-6,-6,6:18.4
-1,-6,6:18.12
0,-6,6:18.12
1,-6,6:18.12
2,-6,6:18.12
3,-6,6:18.12
4,-6,6:18.12
5,-6,6:18.12
6,-6,6:18.12
7,-6,6:18.12
-5,-5,6:18.4
-3,-5,6:18.12
-2,-5,6:18.12
-1,-5,6:18.12
0,-5,6:18.12
7,-5,6:18.12
8,-5,6:18.12
-5,-4,6:18.4
-4,-4,6:18.12
-3,-4,6:18.12
-2,-4,6:18.12
-1,-4,6:18.12
0,-4,6:18.12
1,-4,6:18.12
8,-4,6:18.12
9,-4,6:18.12
10,-4,6:18.4
-4,-3,6:18.12
-2,-3,6:18.12
2,-3,6:18.12
9,-3,6:18.12
10,-3,6:18.4
11,-3,6:18.4
-5,-2,6:18.4
-4,-2,6:18.12
-3,-2,6:18.12
-2,-2,6:18.12
3,-2,6:18.12
4,-2,6:18.12
5,-2,6:18.12
6,-2,6:18.12
7,-2,6:18.12
8,-2,6:18.12
9,-2,6:18.12
10,-2,6:18.4
11,-2,6:18.4
-5,-1,6:18.4
-4,-1,6:18.12
-3,-1,6:18.12
-2,-1,6:18.12
0,-1,6:17.12
1,-1,6:17.12
4,-1,6:18.12
5,-1,6:17.12
8,-1,6:18.12
9,-1,6:18.12
10,-1,6:18.4
11,-1,6:18.4
-5,0,6:18.4
-4,0,6:18.12
-2,0,6:18.12
-1,0,6:18.12
0,0,6:17.12
1,0,6:17.12
4,0,6:18.12
5,0,6:18.12
9,0,6:18.12
10,0,6:18.4
11,0,6:18.4
-4,1,6:18.12
-1,1,6:18.12
0,1,6:18.12
5,1,6:18.12
6,1,6:18.12
-4,2,6:18.12
-3,2,6:18.12
0,2,6:18.12
5,2,6:18.12
6,2,6:18.12
7,2,6:18.12
8,2,6:18.12
9,2,6:18.12
-3,3,6:18.12
-2,3,6:18.12
-1,3,6:18.12
0,3,6:18.12
1,3,6:18.12
2,3,6:18.12
3,3,6:18.12
4,3,6:18.12
5,3,6:18.12
6,3,6:18.12
7,3,6:18.12
8,3,6:18.12
-3,4,6:18.12
-2,4,6:18.12
-1,4,6:18.12
0,4,6:18.12
1,4,6:18.12
2,4,6:18.12
4,4,6:18.12
5,4,6:18.12
6,4,6:18.4
7,4,6:18.4
8,4,6:18.4
-3,5,6:18.4
0,5,6:18.4
1,5,6:18.4
8,5,6:18.4
-4,6,6:18.4
0,6,6:18.4
9,-10,7:18.4
8,-9,7:18.4
9,-9,7:18.4
-2,-8,7:18.4
8,-8,7:18.4
-2,-7,7:18.4
7,-7,7:18.4
8,-7,7:18.4
-6,-6,7:18.4
-5,-6,7:18.4
-1,-6,7:18.4
2,-6,7:18.4
3,-6,7:18.4
4,-6,7:18.4
5,-6,7:18.4
6,-6,7:18.4
7,-6,7:18.4
8,-6,7:18.4
-5,-5,7:18.4
-3,-5,7:18.12
-2,-5,7:18.12
-1,-5,7:18.12
0,-5,7:18.12
1,-5,7:18.12
2,-5,7:18.12
3,-5,7:18.12
8,-5,7:18.12
9,-5,7:18.12
-5,-4,7:18.4
-4,-4,7:18.12
-3,-4,7:18.12
-1,-4,7:18.12
10,-4,7:18.4
11,-4,7:18.4
-5,-3,7:18.4
-4,-3,7:18.12
-2,-3,7:18.12
8,-3,7:18.12
9,-3,7:18.12
10,-3,7:18.4
11,-3,7:18.4
12,-3,7:18.4
-5,-2,7:18.4
-2,-2,7:18.12
5,-2,7:18.12
6,-2,7:18.12
7,-2,7:18.12
8,-2,7:18.12
10,-2,7:18.4
11,-2,7:18.4
-5,-1,7:18.4
-4,-1,7:18.12
-3,-1,7:18.12
-2,-1,7:18.12
5,-1,7:18.12
11,-1,7:18.4
12,-1,7:18.4
-9,0,7:18.4
-8,0,7:18.4
-7,0,7:18.4
-6,0,7:18.4
-5,0,7:18.4
-2,0,7:18.12
1,0,7:17.12
5,0,7:18.12
-9,1,7:18.4
-5,1,7:18.4
-4,1,7:18.12
-1,1,7:18.12
5,1,7:18.12
-4,2,7:18.12
0,2,7:18.12
5,2,7:18.12
-4,3,7:18.12
-3,3,7:18.12
1,3,7:18.12
6,3,7:18.12
7,3,7:18.12
8,3,7:18.12
-3,4,7:18.12
-2,4,7:18.12
-1,4,7:18.12
0,4,7:18.12
1,4,7:18.12
2,4,7:18.12
4,4,7:18.12
5,4,7:18.12
6,4,7:18.4
7,4,7:18.4
8,4,7:18.4
9,4,7:18.4
-3,5,7:18.4
0,5,7:18.4
1,5,7:18.4
2,5,7:18.4
3,5,7:18.4
4,5,7:18.4
7,5,7:18.4
8,5,7:18.4
-4,6,7:18.4
1,6,7:18.4
10,-10,8:18.4
9,-9,8:18.4
-2,-8,8:18.4
9,-8,8:18.4
-6,-7,8:18.4
-2,-7,8:18.4
-1,-7,8:18.4
8,-7,8:18.4
9,-7,8:18.4
-6,-6,8:18.4
-2,-6,8:18.4
-1,-6,8:18.4
0,-6,8:18.4
5,-6,8:18.4
6,-6,8:18.4
7,-6,8:18.4
8,-6,8:18.4
9,-6,8:18.4
10,-6,8:18.4
-5,-5,8:18.4
-3,-5,8:18.12
-2,-5,8:18.12
-1,-5,8:18.12
0,-5,8:18.12
1,-5,8:18.12
2,-5,8:18.12
3,-5,8:18.12
5,-5,8:18.12
-4,-4,8:18.12
-3,-4,8:18.12
-1,-4,8:18.12
-5,-3,8:18.4
-1,-3,8:18.12
7,-3,8:18.12
8,-3,8:18.12
9,-3,8:18.12
10,-3,8:18.4
11,-3,8:18.4
12,-3,8:18.4
-5,-2,8:18.4
-2,-2,8:18.12
5,-2,8:18.12
6,-2,8:18.12
7,-2,8:18.12
-6,-1,8:18.4
-5,-1,8:18.4
-4,-1,8:18.12
-3,-1,8:18.12
-2,-1,8:18.12
5,-1,8:18.12
-8,0,8:18.4
-7,0,8:18.4
-6,0,8:18.4
-5,0,8:18.4
-2,0,8:18.12
5,0,8:18.12
-9,1,8:18.4
-8,1,8:18.4
-5,1,8:18.4
-1,1,8:18.12
5,1,8:18.12
-5,2,8:18.4
-4,2,8:18.12
0,2,8:18.12
5,2,8:18.12
-4,3,8:18.12
0,3,8:18.12
1,3,8:18.12
5,3,8:18.12
6,3,8:18.12
-3,4,8:18.12
1,4,8:18.12
2,4,8:18.12
6,4,8:18.4
-3,5,8:18.4
-2,5,8:18.4
-1,5,8:18.4
0,5,8:18.4
1,5,8:18.4
2,5,8:18.4
3,5,8:18.4
4,5,8:18.4
6,5,8:18.4
7,5,8:18.4
8,5,8:18.4
-4,6,8:18.4
1,6,8:18.4
2,6,8:18.4
7,6,8:18.4
8,6,8:18.4
1,7,8:18.4
2,7,8:18.4
1,8,8:18.4
10,-10,9:18.4
10,-9,9:18.4
10,-8,9:18.4
-6,-7,9:18.4
-1,-7,9:18.4
9,-7,9:18.4
10,-7,9:18.4
-6,-6,9:18.4
-5,-6,9:18.4
-2,-6,9:18.4
0,-6,9:18.4
6,-6,9:18.4
7,-6,9:18.4
8,-6,9:18.4
10,-6,9:18.4
-5,-5,9:18.4
-3,-5,9:18.12
-2,-5,9:18.12
-1,-5,9:18.12
0,-5,9:18.12
1,-5,9:18.12
2,-5,9:18.12
3,-5,9:18.12
5,-5,9:18.12
-4,-4,9:18.12
0,-4,9:18.12
12,-4,9:18.4
13,-4,9:18.4
-5,-3,9:18.4
-1,-3,9:18.12
7,-3,9:18.12
8,-3,9:18.12
9,-3,9:18.12
10,-3,9:18.4
11,-3,9:18.4
-5,-2,9:18.4
-1,-2,9:18.12
6,-2,9:18.12
7,-2,9:18.12
-5,-1,9:18.4
-4,-1,9:18.12
-3,-1,9:18.12
-2,-1,9:18.12
5,-1,9:18.12
-7,0,9:18.4
-6,0,9:18.4
-5,0,9:18.4
-2,0,9:18.12
5,0,9:18.12
-8,1,9:18.4
-7,1,9:18.4
-6,1,9:18.4
-5,1,9:18.4
-1,1,9:18.12
5,1,9:18.12
-5,2,9:18.4
0,2,9:18.12
5,2,9:18.12
-5,3,9:18.4
-4,3,9:18.12
0,3,9:18.12
1,3,9:18.12
5,3,9:18.12
-4,4,9:18.12
-3,4,9:18.12
1,4,9:18.12
2,4,9:18.12
6,4,9:18.4
-3,5,9:18.4
-2,5,9:18.4
-1,5,9:18.4
0,5,9:18.4
2,5,9:18.4
3,5,9:18.4
6,5,9:18.4
-4,6,9:18.4
-3,6,9:18.4
-1,6,9:18.4
0,6,9:18.4
1,6,9:18.4
2,6,9:18.4
3,6,9:18.4
4,6,9:18.4
5,6,9:18.4
6,6,9:18.4
7,6,9:18.4
-4,7,9:18.4
2,7,9:18.4
3,7,9:18.4
-5,8,9:18.4
1,8,9:18.4
2,8,9:18.4
1,9,9:18.4
11,-9,10:18.4
10,-8,10:18.4
-1,-7,10:18.4
9,-7,10:18.4
10,-7,10:18.4
-2,-6,10:18.4
1,-6,10:18.4
6,-6,10:18.4
7,-6,10:18.4
8,-6,10:18.4
-5,-5,10:18.4
-4,-5,10:18.12
-3,-5,10:18.12
-2,-5,10:18.12
-1,-5,10:18.12
0,-5,10:18.12
1,-5,10:18.12
2,-5,10:18.12
3,-5,10:18.12
5,-5,10:18.12
6,-5,10:18.12
-4,-4,10:18.12
0,-4,10:18.12
1,-4,10:18.12
11,-4,10:18.4
12,-4,10:18.4
-5,-3,10:18.4
0,-3,10:18.12
8,-3,10:18.12
9,-3,10:18.12
10,-3,10:18.4
-5,-2,10:18.4
-1,-2,10:18.12
6,-2,10:18.12
7,-2,10:18.12
-6,-1,10:18.4
-1,-1,10:18.12
5,-1,10:18.12
6,-1,10:18.12
-6,0,10:18.4
-4,0,10:18.12
-3,0,10:18.12
-2,0,10:18.12
-1,0,10:18.12
5,0,10:18.12
-8,1,10:18.4
-7,1,10:18.4
-6,1,10:18.4
-1,1,10:18.12
0,1,10:18.12
5,1,10:18.12
-5,2,10:18.4
0,2,10:18.12
5,2,10:18.12
-5,3,10:18.4
-4,3,10:18.12
1,3,10:18.12
5,3,10:18.12
-4,4,10:18.12
1,4,10:18.12
2,4,10:18.12
6,4,10:18.4
-4,5,10:18.4
-3,5,10:18.4
2,5,10:18.4
3,5,10:18.4
6,5,10:18.4
-3,6,10:18.4
-2,6,10:18.4
-1,6,10:18.4
0,6,10:18.4
1,6,10:18.4
3,6,10:18.4
4,6,10:18.4
5,6,10:18.4
6,6,10:18.4
7,6,10:18.4
-4,7,10:18.4
3,7,10:18.4
4,7,10:18.4
7,7,10:18.4
-5,8,10:18.4
-4,8,10:18.4
2,8,10:18.4
3,8,10:18.4
2,9,10:18.4
9,-7,11:18.4
10,-7,11:18.4
-2,-6,11:18.4
1,-6,11:18.4
7,-6,11:18.4
8,-6,11:18.4
9,-6,11:18.4
-5,-5,11:18.4
-4,-5,11:18.4
-3,-5,11:18.4
-1,-5,11:18.4
0,-5,11:18.4
1,-5,11:18.4
2,-5,11:18.4
3,-5,11:18.4
5,-5,11:18.4
6,-5,11:18.4
-5,-4,11:18.4
-4,-4,11:18.4
1,-4,11:18.12
10,-4,11:18.4
12,-4,11:18.4
-5,-3,11:18.4
0,-3,11:18.12
1,-3,11:18.12
8,-3,11:18.4
9,-3,11:18.4
-6,-2,11:18.4
-5,-2,11:18.4
0,-2,11:18.12
6,-2,11:18.4
7,-2,11:18.4
-6,-1,11:18.4
-1,-1,11:18.12
5,-1,11:18.12
6,-1,11:18.4
-6,0,11:18.4
-2,0,11:18.12
-1,0,11:18.12
5,0,11:18.12
-7,1,11:18.4
-6,1,11:18.4
-1,1,11:18.12
0,1,11:18.12
5,1,11:18.12
-6,2,11:18.4
-5,2,11:18.4
0,2,11:18.12
5,2,11:18.12
-5,3,11:18.4
1,3,11:18.12
5,3,11:18.12
-5,4,11:18.4
-4,4,11:18.4
5,4,11:18.12
6,4,11:18.4
-4,5,11:18.4
3,5,11:18.4
6,5,11:18.4
-3,6,11:18.4
-2,6,11:18.4
-1,6,11:18.4
3,6,11:18.4
6,6,11:18.4
-4,7,11:18.4
-1,7,11:18.4
2,7,11:18.4
3,7,11:18.4
4,7,11:18.4
-5,8,11:18.4
-4,8,11:18.4
3,8,11:18.4
-5,9,11:18.4
-7,-8,12:18.4
0,-8,12:18.4
-6,-7,12:18.4
0,-7,12:18.4
1,-7,12:18.4
-6,-6,12:18.4
-5,-6,12:18.4
-3,-6,12:18.4
-2,-6,12:18.4
1,-6,12:18.4
2,-6,12:18.4
8,-6,12:18.4
-5,-5,12:18.4
-4,-5,12:18.4
-3,-5,12:18.4
-2,-5,12:18.4
-1,-5,12:18.4
0,-5,12:18.4
1,-5,12:18.4
2,-5,12:18.4
3,-5,12:18.4
5,-5,12:18.4
6,-5,12:18.4
-5,-4,12:18.4
-4,-4,12:18.4
2,-4,12:18.4
10,-4,12:18.4
-5,-3,12:18.4
1,-3,12:18.4
8,-3,12:18.4
9,-3,12:18.4
-6,-2,12:18.4
0,-2,12:18.4
1,-2,12:18.4
7,-2,12:18.4
8,-2,12:18.4
-6,-1,12:18.4
0,-1,12:18.4
6,-1,12:18.4
-6,0,12:18.4
-3,0,12:18.4
-2,0,12:18.4
-1,0,12:18.4
6,0,12:18.4
-9,1,12:18.4
-8,1,12:18.4
-7,1,12:18.4
-6,1,12:18.4
-1,1,12:18.4
0,1,12:18.4
5,1,12:18.4
6,1,12:18.4
-6,2,12:18.4
0,2,12:18.4
5,2,12:18.4
6,2,12:18.4
-5,3,12:18.4
5,3,12:18.4
-5,4,12:18.4
5,4,12:18.4
-4,5,12:18.4
-4,6,12:18.4
-3,6,12:18.4
3,6,12:18.4
6,6,12:18.4
-4,7,12:18.4
-3,7,12:18.4
-2,7,12:18.4
-1,7,12:18.4
-4,8,12:18.4
-5,9,12:18.4
-7,-8,13:18.4
0,-8,13:18.4
-6,-7,13:18.4
1,-7,13:18.4
-6,-6,13:18.4
-5,-6,13:18.4
-3,-6,13:18.4
-2,-6,13:18.4
2,-6,13:18.4
-5,-5,13:18.4
-4,-5,13:18.4
-3,-5,13:18.4
-2,-5,13:18.4
-1,-5,13:18.4
0,-5,13:18.4
1,-5,13:18.4
2,-5,13:18.4
3,-5,13:18.4
5,-5,13:18.4
6,-5,13:18.4
-5,-4,13:18.4
2,-4,13:18.4
3,-4,13:18.4
10,-4,13:18.4
11,-4,13:18.4
-5,-3,13:18.4
1,-3,13:18.4
2,-3,13:18.4
8,-3,13:18.4
9,-3,13:18.4
-6,-2,13:18.4
1,-2,13:18.4
7,-2,13:18.4
8,-2,13:18.4
-6,-1,13:18.4
0,-1,13:18.4
6,-1,13:18.4
7,-1,13:18.4
-7,0,13:18.4
-6,0,13:18.4
-4,0,13:18.4
-3,0,13:18.4
-2,0,13:18.4
-1,0,13:18.4
0,0,13:18.4
6,0,13:18.4
-10,1,13:18.4
-9,1,13:18.4
-8,1,13:18.4
-7,1,13:18.4
-6,1,13:18.4
-1,1,13:18.4
0,1,13:18.4
6,1,13:18.4
-6,2,13:18.4
0,2,13:18.4
1,2,13:18.4
6,2,13:18.4
6,3,13:18.4
6,4,13:18.4
6,5,13:18.4
-4,6,13:18.4
-4,7,13:18.4
-3,7,13:18.4
-2,7,13:18.4
-1,7,13:18.4
-4,8,13:18.4
-5,9,13:18.4
-4,9,13:18.4
-7,-8,14:18.4
0,-8,14:18.4
1,-8,14:18.4
-6,-7,14:18.4
1,-7,14:18.4
2,-7,14:18.4
-6,-6,14:18.4
-5,-6,14:18.4
-3,-6,14:18.4
2,-6,14:18.4
3,-6,14:18.4
-5,-5,14:18.4
-4,-5,14:18.4
-2,-5,14:18.4
-1,-5,14:18.4
1,-5,14:18.4
2,-5,14:18.4
3,-5,14:18.4
5,-5,14:18.4
6,-5,14:18.4
-5,-4,14:18.4
3,-4,14:18.4
10,-4,14:18.4
11,-4,14:18.4
-5,-3,14:18.4
2,-3,14:18.4
3,-3,14:18.4
9,-3,14:18.4
-6,-2,14:18.4
2,-2,14:18.4
7,-2,14:18.4
8,-2,14:18.4
-6,-1,14:18.4
1,-1,14:18.4
6,-1,14:18.4
7,-1,14:18.4
-7,0,14:18.4
0,0,14:18.4
6,0,14:18.4
-10,1,14:18.4
-9,1,14:18.4
-8,1,14:18.4
-7,1,14:18.4
-4,1,14:18.4
-3,1,14:18.4
-2,1,14:18.4
-1,1,14:18.4
0,1,14:18.4
6,1,14:18.4
-7,2,14:18.4
-6,2,14:18.4
1,2,14:18.4
6,2,14:18.4
-6,3,14:18.4
1,3,14:18.4
6,4,14:18.4
6,5,14:18.4
-4,6,14:18.4
1,-8,15:18.4
-6,-7,15:18.4
2,-7,15:18.4
-5,-6,15:18.4
-3,-6,15:18.4
3,-6,15:18.4
-5,-5,15:18.4
-4,-5,15:18.4
1,-5,15:18.4
2,-5,15:18.4
3,-5,15:18.4
5,-5,15:18.4
6,-5,15:18.4
7,-5,15:18.4
-5,-4,15:18.4
4,-4,15:18.4
-6,-3,15:18.4
-5,-3,15:18.4
3,-3,15:18.4
9,-3,15:18.4
8,-2,15:18.4
9,-2,15:18.4
6,-1,15:18.4
7,-1,15:18.4
-7,0,15:18.4
0,0,15:18.4
1,0,15:18.4
6,0,15:18.4
-10,1,15:18.4
-9,1,15:18.4
-8,1,15:18.4
-7,1,15:18.4
-3,1,15:18.4
-2,1,15:18.4
-1,1,15:18.4
0,1,15:18.4
6,1,15:18.4
-7,2,15:18.4
1,2,15:18.4
6,2,15:18.4
-6,3,15:18.4
6,4,15:18.4
6,5,15:18.4
-5,6,15:18.4
6,6,15:18.4
-7,-8,16:18.4
1,-8,16:18.4
2,-8,16:18.4
-6,-7,16:18.4
2,-7,16:18.4
3,-7,16:18.4
-5,-6,16:18.4
-3,-6,16:18.4
3,-6,16:18.4
4,-6,16:18.4
-5,-5,16:18.4
-4,-5,16:18.4
2,-5,16:18.4
3,-5,16:18.4
5,-5,16:18.4
6,-5,16:18.4
7,-5,16:18.4
-5,-4,16:18.4
4,-4,16:18.4
-5,-3,16:18.4
4,-3,16:18.4
9,-3,16:18.4
8,-2,16:18.4
9,-2,16:18.4
7,-1,16:18.4
-7,0,16:18.4
1,0,16:18.4
6,0,16:18.4
7,0,16:18.4
-11,1,16:18.4
-10,1,16:18.4
-9,1,16:18.4
-8,1,16:18.4
-7,1,16:18.4
-3,1,16:18.4
-2,1,16:18.4
-1,1,16:18.4
0,1,16:18.4
1,1,16:18.4
6,1,16:18.4
-7,2,16:18.4
1,2,16:18.4
6,2,16:18.4
6,3,16:18.4
-7,-8,17:18.4
-6,-8,17:18.4
2,-8,17:18.4
-6,-7,17:18.4
3,-7,17:18.4
-5,-6,17:18.4
-4,-6,17:18.4
4,-6,17:18.4
-5,-5,17:18.4
-4,-5,17:18.4
-3,-5,17:18.4
2,-5,17:18.4
3,-5,17:18.4
5,-5,17:18.4
6,-5,17:18.4
-5,-4,17:18.4
5,-4,17:18.4
4,-3,17:18.4
5,-3,17:18.4
8,-2,17:18.4
7,-1,17:18.4
8,-1,17:18.4
-7,0,17:18.4
7,0,17:18.4
-11,1,17:18.4
-10,1,17:18.4
-9,1,17:18.4
-8,1,17:18.4
-3,1,17:18.4
-2,1,17:18.4
-1,1,17:18.4
0,1,17:18.4
1,1,17:18.4
7,1,17:18.4
-7,2,17:18.4
-1,2,17:18.4
1,2,17:18.4
-6,-8,18:18.4
-6,-7,18:18.4
-5,-7,18:18.4
3,-7,18:18.4
4,-7,18:18.4
-5,-6,18:18.4
4,-6,18:18.4
5,-6,18:18.4
-2,-5,18:18.4
5,-5,18:18.4
6,-5,18:18.4
-5,-4,18:18.4
6,-4,18:18.4
-10,1,18:18.4
-9,1,18:18.4
-8,1,18:18.4
-8,2,18:18.4
-1,2,18:18.4
-6,-7,19:18.4
