[META]
version=2.0
spawnOnBlockType=2
spawnSunlight=True
spawnDarkness=True
spawnWater=False
spawnLava=False
underFill=False
randomRotation=True
dig=True
tree=False
branch=False
needsFoundation=True
rarity=100
collisionPercentage=20
spawnElevationMin=0
spawnElevationMax=200
spawnInBiome=Custom
[DATA]
3,-5,-8:17.12
-1,-4,-8:17.12
3,-6,-7:17.12
-3,-5,-7:17.12
-1,-5,-7:17.12
2,-5,-7:17.12
3,-5,-7:17.12
4,-5,-7:17.12
-2,-4,-7:17.12
2,-4,-7:17.12
4,-4,-7:17.12
2,-6,-6:17.12
3,-6,-6:17.12
-2,-5,-6:17.12
-1,-5,-6:17.12
0,-5,-6:17.12
1,-5,-6:17.12
2,-5,-6:17.12
-3,-4,-6:17.12
-2,-4,-6:17.12
-1,-4,-6:17.12
0,-4,-6:17.12
1,-4,-6:17.12
3,-4,-6:17.12
-2,-3,-6:17.12
-1,-3,-6:17.12
0,-3,-6:17.12
2,-3,-6:17.12
1,-5,-5:17.12
2,-5,-5:17.12
-2,-4,-5:17.12
-1,-4,-5:17.12
1,-4,-5:17.12
2,-4,-5:17.12
3,-4,-5:17.12
-1,-3,-5:17.12
0,-3,-5:17.12
3,-3,-5:17.12
-1,-2,-5:17.12
0,-6,-4:17.12
-1,-5,-4:17.12
0,-5,-4:17.12
2,-5,-4:17.12
1,-4,-4:17.12
-1,-3,-4:17.12
0,-3,-4:17.12
1,-3,-4:17.12
2,-3,-4:17.12
-1,-6,-3:17.12
0,-6,-3:17.12
1,-6,-3:17.12
-1,-5,-3:17.12
0,-5,-3:17.12
1,-5,-3:17.12
0,-4,-3:17.12
1,-4,-3:17.12
2,-4,-3:17.12
-1,-6,-2:17.12
0,-6,-2:17.12
1,-6,-2:17.12
2,-6,-2:17.12
-1,-5,-2:17.12
0,-5,-2:17.12
1,-5,-2:17.12
2,-5,-2:17.12
-1,-4,-2:17.12
0,-4,-2:17.12
1,-4,-2:17.12
2,-4,-2:17.12
0,-3,-2:17.12
1,-3,-2:17.12
-1,-6,-1:17.12
0,-6,-1:17.12
1,-6,-1:17.12
-1,-5,-1:17.12
0,-5,-1:17.12
1,-5,-1:17.12
2,-5,-1:17.12
-1,-4,-1:17.12
0,-4,-1:17.12
1,-4,-1:17.12
-1,-6,0:17.12
0,-6,0:17.12
1,-6,0:17.12
-1,-5,0:17.12
1,-5,0:17.12
2,-5,0:17.12
0,-4,0:17.12
1,-4,0:17.12
0,-6,1:17.12
1,-6,1:17.12
-1,-5,1:17.12
0,-5,1:17.12
1,-5,1:17.12
2,-5,1:17.12
0,-4,1:17.12
1,-4,1:17.12
0,-6,2:17.12
1,-6,2:17.12
-1,-5,2:17.12
0,-5,2:17.12
1,-5,2:17.12
2,-5,2:17.12
0,-4,2:17.12
1,-4,2:17.12
0,-6,3:17.12
1,-6,3:17.12
-1,-5,3:17.12
0,-5,3:17.12
1,-5,3:17.12
0,-4,3:17.12
1,-4,3:17.12
0,-6,4:17.12
1,-6,4:17.12
-1,-5,4:17.12
0,-5,4:17.12
1,-5,4:17.12
0,-4,4:17.12
1,-4,4:17.12
0,-6,5:17.12
1,-6,5:17.12
-1,-5,5:17.12
0,-5,5:17.12
1,-5,5:17.12
2,-5,5:17.12
0,-4,5:17.12
1,-4,5:17.12
0,-6,6:17.12
1,-6,6:17.12
-1,-5,6:17.12
0,-5,6:17.12
1,-5,6:17.12
2,-5,6:17.12
0,-4,6:17.12
1,-4,6:17.12
3,-7,7:18.13
0,-6,7:17.12
1,-6,7:17.12
0,-5,7:17.12
1,-5,7:17.12
2,-5,7:17.12
0,-4,7:17.12
1,-4,7:17.12
-1,-8,8:18.5
-2,-7,8:18.5
-1,-7,8:18.5
0,-7,8:18.5
1,-7,8:18.5
2,-7,8:18.5
3,-7,8:18.5
4,-7,8:18.5
1,-6,8:17.12
3,-6,8:18.5
-1,-5,8:18.5
0,-5,8:17.12
1,-5,8:17.12
2,-5,8:17.12
3,-5,8:18.5
-1,-4,8:18.5
0,-4,8:17.12
1,-4,8:17.12
3,-4,8:18.5
-2,-3,8:18.5
-1,-3,8:18.5
0,-3,8:18.5
1,-3,8:18.5
2,-3,8:18.5
3,-3,8:18.5
3,-2,8:18.5
-1,-8,9:18.5
2,-8,9:18.5
-2,-7,9:18.5
-1,-7,9:18.5
0,-7,9:18.5
1,-7,9:18.5
2,-7,9:18.5
3,-7,9:18.5
-1,-6,9:18.5
1,-6,9:17.12
2,-6,9:18.5
3,-6,9:18.5
-1,-5,9:18.5
0,-5,9:17.12
1,-5,9:17.12
2,-5,9:17.12
3,-5,9:18.5
-1,-4,9:18.5
0,-4,9:17.12
1,-4,9:17.12
3,-4,9:18.5
-2,-3,9:18.5
-1,-3,9:18.5
0,-3,9:18.5
1,-3,9:18.5
2,-3,9:18.5
3,-3,9:18.5
-1,-2,9:18.5
3,-2,9:18.5
-1,-8,10:18.5
-2,-7,10:18.5
-1,-7,10:18.5
0,-7,10:18.5
1,-7,10:18.5
2,-7,10:18.5
3,-7,10:18.5
-2,-6,10:18.5
-1,-6,10:18.5
0,-6,10:18.5
1,-6,10:18.5
2,-6,10:18.5
3,-6,10:18.5
-1,-5,10:18.5
0,-5,10:17.12
1,-5,10:17.12
2,-5,10:18.5
-1,-4,10:18.5
0,-4,10:17.12
1,-4,10:17.12
2,-4,10:18.5
3,-4,10:18.5
-2,-3,10:18.5
-1,-3,10:18.5
0,-3,10:18.5
1,-3,10:18.5
2,-3,10:18.5
3,-3,10:18.5
-1,-2,10:18.5
3,-2,10:18.5
-1,-8,11:18.5
-1,-7,11:18.5
-1,-6,11:18.5
0,-6,11:18.5
1,-6,11:18.5
2,-6,11:18.5
3,-6,11:18.5
4,-6,11:18.5
-1,-5,11:18.5
0,-5,11:17.12
1,-5,11:17.12
2,-5,11:18.5
-1,-4,11:18.5
0,-4,11:18.5
1,-4,11:17.12
2,-4,11:18.5
-2,-3,11:18.5
-1,-3,11:18.5
0,-3,11:18.5
1,-3,11:18.5
2,-3,11:18.5
3,-3,11:18.5
2,-2,11:18.5
-1,-8,12:18.5
0,-8,12:18.5
-1,-7,12:18.5
0,-7,12:18.5
-4,-6,12:18.5
0,-6,12:18.5
1,-6,12:18.5
2,-6,12:18.5
3,-6,12:18.5
4,-6,12:18.5
-4,-5,12:18.5
0,-5,12:17.12
1,-5,12:17.12
2,-5,12:18.5
5,-5,12:18.5
-3,-4,12:18.5
-2,-4,12:18.5
-1,-4,12:18.5
0,-4,12:18.5
1,-4,12:17.12
2,-4,12:18.5
-2,-3,12:18.5
2,-3,12:18.5
2,-2,12:18.5
0,-8,13:18.5
-2,-7,13:18.5
0,-7,13:18.5
3,-7,13:18.5
4,-7,13:18.5
-4,-6,13:18.5
-3,-6,13:18.5
-2,-6,13:18.5
0,-6,13:18.5
1,-6,13:18.5
2,-6,13:18.5
3,-6,13:18.5
4,-6,13:18.5
5,-6,13:18.5
-4,-5,13:18.5
-3,-5,13:18.5
0,-5,13:17.12
1,-5,13:17.12
2,-5,13:18.5
5,-5,13:18.5
-3,-4,13:18.5
-2,-4,13:18.5
-1,-4,13:18.5
0,-4,13:18.5
1,-4,13:17.12
2,-4,13:18.5
4,-4,13:18.5
5,-4,13:18.5
-2,-3,13:18.5
2,-3,13:18.5
3,-3,13:18.5
4,-3,13:18.5
2,-2,13:18.5
0,-9,14:18.5
2,-9,14:18.5
-1,-8,14:18.5
0,-8,14:18.5
2,-8,14:18.5
3,-8,14:18.5
-1,-7,14:18.5
0,-7,14:18.5
1,-7,14:18.5
3,-7,14:18.5
-2,-6,14:18.5
0,-6,14:18.5
1,-6,14:18.5
3,-6,14:18.5
4,-6,14:18.5
5,-6,14:18.5
-3,-5,14:18.5
-2,-5,14:18.5
-1,-5,14:18.5
0,-5,14:18.5
1,-5,14:18.5
2,-5,14:18.5
3,-5,14:18.5
4,-5,14:18.5
5,-5,14:18.5
-3,-4,14:18.5
-2,-4,14:18.5
-1,-4,14:18.5
0,-4,14:18.5
1,-4,14:18.5
2,-4,14:18.5
3,-4,14:18.5
4,-4,14:18.5
5,-4,14:18.5
-2,-3,14:18.5
-1,-3,14:18.5
0,-3,14:18.5
1,-3,14:18.5
2,-3,14:18.5
3,-3,14:18.5
-1,-2,14:18.5
0,-2,14:18.5
2,-2,14:18.5
3,-2,14:18.5
0,-1,14:18.5
1,-1,14:18.5
2,-1,14:18.5
1,0,14:18.5
1,-10,15:18.5
2,-10,15:18.5
0,-9,15:18.5
1,-9,15:18.5
0,-8,15:18.5
2,-8,15:18.5
-1,-7,15:18.5
0,-7,15:18.5
1,-7,15:18.5
2,-7,15:18.5
3,-7,15:18.5
-3,-6,15:18.5
-2,-6,15:18.5
-1,-6,15:18.5
0,-6,15:18.5
1,-6,15:18.5
3,-6,15:18.5
4,-6,15:18.5
-3,-5,15:18.5
-2,-5,15:18.5
-1,-5,15:18.5
0,-5,15:18.5
1,-5,15:18.5
2,-5,15:18.5
3,-5,15:18.5
4,-5,15:18.5
5,-5,15:18.5
-3,-4,15:18.5
-2,-4,15:18.5
-1,-4,15:18.5
1,-4,15:18.5
3,-4,15:18.5
4,-4,15:18.5
5,-4,15:18.5
-1,-3,15:18.5
0,-3,15:18.5
1,-3,15:18.5
2,-3,15:18.5
3,-3,15:18.5
0,-2,15:18.5
1,-2,15:18.5
2,-2,15:18.5
0,-1,15:18.5
1,-1,15:18.5
2,-1,15:18.5
0,0,15:18.5
1,0,15:18.5
2,-10,16:18.5
0,-9,16:18.5
1,-9,16:18.5
2,-9,16:18.5
0,-8,16:18.5
1,-8,16:18.5
2,-8,16:18.5
0,-7,16:18.5
2,-7,16:18.5
-3,-6,16:18.5
-1,-6,16:18.5
1,-6,16:18.5
3,-6,16:18.5
-3,-5,16:18.5
-2,-5,16:18.5
-1,-5,16:18.5
0,-5,16:17.0
1,-5,16:17.0
2,-5,16:18.5
3,-5,16:18.5
4,-5,16:18.5
-1,-4,16:18.5
1,-4,16:17.0
3,-4,16:18.5
4,-4,16:18.5
5,-4,16:18.5
-1,-3,16:18.5
0,-3,16:18.5
1,-3,16:18.5
2,-3,16:18.5
0,-2,16:18.5
1,-2,16:18.5
2,-2,16:18.5
1,-1,16:18.5
0,0,16:18.5
2,0,16:18.5
0,-9,17:18.5
1,-9,17:18.5
2,-9,17:18.5
1,-8,17:18.5
0,-7,17:18.5
1,-7,17:18.5
2,-7,17:18.5
-3,-6,17:18.5
-2,-6,17:18.5
-1,-6,17:18.5
0,-6,17:18.5
2,-6,17:18.5
3,-6,17:18.5
-2,-5,17:18.5
-1,-5,17:18.5
0,-5,17:17.0
1,-5,17:17.0
3,-5,17:18.5
-1,-4,17:18.5
0,-4,17:18.5
1,-4,17:17.0
2,-4,17:18.5
4,-4,17:18.5
5,-4,17:18.5
0,-3,17:18.5
1,-3,17:18.5
2,-3,17:18.5
1,-2,17:18.5
0,-1,17:18.5
1,-1,17:18.5
2,-9,18:18.5
1,-8,18:18.5
2,-8,18:18.5
0,-7,18:18.5
1,-7,18:18.5
-3,-6,18:18.5
-2,-6,18:18.5
0,-6,18:18.5
2,-6,18:18.5
-1,-5,18:18.5
0,-5,18:18.5
1,-5,18:17.0
2,-5,18:18.5
3,-5,18:18.5
0,-4,18:18.5
1,-4,18:17.0
2,-4,18:18.5
3,-4,18:18.5
4,-4,18:18.5
1,-3,18:18.5
2,-3,18:18.5
0,-2,18:18.5
1,-2,18:18.5
0,-1,18:18.5
2,-8,19:18.5
1,-7,19:18.5
2,-7,19:18.5
3,-7,19:18.5
4,-7,19:18.5
-2,-6,19:18.5
-1,-6,19:18.5
0,-6,19:18.5
1,-6,19:18.5
2,-6,19:18.5
3,-6,19:18.5
-1,-5,19:18.5
0,-5,19:18.5
1,-5,19:17.0
2,-5,19:18.5
3,-5,19:18.5
-1,-4,19:18.5
0,-4,19:18.5
1,-4,19:18.5
2,-4,19:18.5
3,-4,19:18.5
4,-4,19:18.5
-2,-3,19:18.5
-1,-3,19:18.5
1,-3,19:18.5
4,-3,19:18.5
-1,-2,19:18.5
0,-2,19:18.5
0,-1,19:18.5
2,-8,20:18.5
3,-8,20:18.5
-1,-7,20:18.5
0,-7,20:18.5
1,-7,20:18.5
2,-7,20:18.5
3,-7,20:18.5
4,-7,20:18.5
-2,-6,20:18.5
-1,-6,20:18.5
1,-6,20:18.5
2,-6,20:18.5
3,-6,20:18.5
-1,-5,20:18.5
0,-5,20:18.5
1,-5,20:17.0
2,-5,20:18.5
3,-5,20:18.5
-1,-4,20:18.5
0,-4,20:18.5
1,-4,20:18.5
2,-4,20:18.5
3,-4,20:18.5
-2,-3,20:18.5
-1,-3,20:18.5
0,-3,20:18.5
1,-3,20:18.5
2,-3,20:18.5
3,-3,20:18.5
4,-3,20:18.5
-1,-2,20:18.5
0,-2,20:18.5
3,-2,20:18.5
-1,-8,21:18.5
-1,-7,21:18.5
0,-7,21:18.5
1,-7,21:18.5
2,-7,21:18.5
3,-7,21:18.5
4,-7,21:18.5
-1,-6,21:18.5
0,-6,21:18.5
1,-6,21:18.5
2,-6,21:18.5
3,-6,21:18.5
-1,-5,21:18.5
0,-5,21:18.5
1,-5,21:18.5
2,-5,21:18.5
3,-5,21:18.5
-1,-4,21:18.5
0,-4,21:18.5
1,-4,21:18.5
2,-4,21:18.5
3,-4,21:18.5
-2,-3,21:18.5
-1,-3,21:18.5
0,-3,21:18.5
1,-3,21:18.5
2,-3,21:18.5
3,-3,21:18.5
4,-3,21:18.5
-1,-2,21:18.5
3,-2,21:18.5
-1,-7,22:18.5
0,-7,22:18.5
1,-7,22:18.5
-1,-6,22:18.5
0,-6,22:18.5
1,-6,22:18.5
2,-6,22:18.5
3,-6,22:18.5
4,-6,22:18.5
-1,-5,22:18.5
0,-5,22:18.5
1,-5,22:17.0
2,-5,22:18.5
3,-5,22:18.5
0,-4,22:18.5
3,-4,22:18.5
-2,-3,22:18.5
-1,-3,22:18.5
0,-3,22:18.5
1,-3,22:18.5
2,-3,22:18.5
3,-3,22:18.5
3,-2,22:18.5
-1,-7,23:18.5
0,-7,23:18.5
0,-6,23:18.5
1,-6,23:18.5
2,-6,23:18.5
3,-6,23:18.5
4,-6,23:18.5
0,-5,23:18.5
1,-5,23:17.0
2,-5,23:18.5
-1,-4,23:18.5
0,-4,23:18.5
1,-4,23:18.5
2,-4,23:18.5
3,-4,23:18.5
-1,-3,23:18.5
2,-3,23:18.5
3,-3,23:18.5
3,-2,23:18.5
0,-7,24:18.5
0,-6,24:18.5
1,-6,24:18.5
2,-6,24:18.5
3,-6,24:18.5
0,-5,24:18.5
1,-5,24:17.0
2,-5,24:18.5
-1,-4,24:18.5
0,-4,24:18.5
1,-4,24:18.5
2,-4,24:18.5
2,-3,24:18.5
0,-7,25:18.5
0,-6,25:18.5
1,-6,25:18.5
2,-6,25:18.5
3,-6,25:18.5
-1,-5,25:18.5
0,-5,25:18.5
1,-5,25:18.5
2,-5,25:18.5
3,-5,25:18.5
-1,-4,25:18.5
0,-4,25:18.5
1,-4,25:18.5
2,-4,25:18.5
2,-3,25:18.5
1,-7,26:18.5
2,-7,26:18.5
0,-6,26:18.5
1,-6,26:18.5
2,-6,26:18.5
-1,-5,26:18.5
0,-5,26:18.5
1,-5,26:18.5
2,-5,26:18.5
3,-5,26:18.5
-1,-4,26:18.5
0,-4,26:18.5
1,-4,26:18.5
2,-4,26:18.5
3,-4,26:18.5
1,-3,26:18.5
2,-3,26:18.5
1,-6,27:18.5
2,-6,27:18.5
0,-5,27:18.5
1,-5,27:17.0
2,-5,27:18.5
0,-4,27:18.5
1,-4,27:18.5
2,-4,27:18.5
1,-3,27:18.5
1,-6,28:18.5
0,-5,28:18.5
1,-5,28:18.5
2,-5,28:18.5
1,-4,28:18.5
2,-4,28:18.5
1,-5,29:18.5
2,-5,29:18.5
1,-4,29:18.5
1,-5,30:18.5
1,-5,31:17.0
