[META]
version=2.0
spawnOnBlockType=2
spawnSunlight=True
spawnDarkness=True
spawnWater=False
spawnLava=False
underFill=False
randomRotation=True
dig=True
tree=False
branch=False
needsFoundation=True
rarity=100
collisionPercentage=20
spawnElevationMin=0
spawnElevationMax=200
spawnInBiome=Custom
[DATA]
-4,-4,-8:17.12
-8,2,-8:17.12
2,3,-8:17.12
0,4,-8:17.12
-4,8,-8:17.12
-4,9,-8:17.12
0,9,-8:17.12
-3,-4,-7:17.12
-5,-3,-7:17.12
-4,-3,-7:17.12
-3,-3,-7:17.12
-4,-2,-7:17.12
-10,2,-7:17.12
-9,2,-7:17.12
0,2,-7:17.12
1,2,-7:17.12
2,2,-7:17.12
3,2,-7:17.12
-9,3,-7:17.12
0,3,-7:17.12
2,3,-7:17.12
-1,4,-7:17.12
0,4,-7:17.12
3,4,-7:17.12
-4,7,-7:17.12
-3,7,-7:17.12
-5,8,-7:17.12
-4,8,-7:17.12
-3,8,-7:17.12
-1,8,-7:17.12
0,8,-7:17.12
1,8,-7:17.12
-4,9,-7:17.12
-3,9,-7:17.12
0,9,-7:17.12
1,9,-7:17.12
-4,-4,-6:17.12
-5,-3,-6:17.12
-4,-3,-6:17.12
-3,-3,-6:17.12
-5,-2,-6:17.12
-4,-2,-6:17.12
-5,-1,-6:17.12
-4,0,-6:17.12
-9,1,-6:17.12
1,1,-6:17.12
-9,2,-6:17.12
-8,2,-6:17.12
-7,2,-6:17.12
0,2,-6:17.12
2,2,-6:17.12
-7,3,-6:17.12
-6,3,-6:17.12
-5,3,-6:17.12
-1,3,-6:17.12
1,3,-6:17.12
2,3,-6:17.12
3,3,-6:17.12
-7,4,-6:17.12
2,4,-6:17.12
-4,6,-6:17.12
-5,7,-6:17.12
-4,7,-6:17.12
-3,7,-6:17.12
-5,8,-6:17.12
-4,8,-6:17.12
-3,8,-6:17.12
0,8,-6:17.12
-4,9,-6:17.12
-3,9,-6:17.12
-5,-2,-5:17.12
-4,-1,-5:17.12
-3,-1,-5:17.12
-5,0,-5:17.12
1,1,-5:17.12
2,1,-5:17.12
-7,2,-5:17.12
-6,2,-5:17.12
0,2,-5:17.12
1,2,-5:17.12
2,2,-5:17.12
3,2,-5:17.12
-8,3,-5:17.12
-7,3,-5:17.12
-6,3,-5:17.12
-5,3,-5:17.12
1,3,-5:17.12
2,3,-5:17.12
-8,4,-5:17.12
-7,4,-5:17.12
-6,4,-5:17.12
-5,6,-5:17.12
-4,6,-5:17.12
0,6,-5:17.12
-5,7,-5:17.12
-4,7,-5:17.12
-3,7,-5:17.12
-1,7,-5:17.12
1,7,-5:17.12
-5,8,-5:17.12
-4,8,-5:17.12
-3,8,-5:17.12
0,8,-5:17.12
1,8,-5:17.12
0,9,-5:17.12
-4,-1,-4:17.12
-3,-1,-4:17.12
-5,0,-4:17.12
-4,0,-4:17.12
-3,0,-4:17.12
1,1,-4:17.12
-7,2,-4:17.12
-6,2,-4:17.12
-5,2,-4:17.12
0,2,-4:17.12
1,2,-4:17.12
2,2,-4:17.12
-7,3,-4:17.12
-6,3,-4:17.12
-5,3,-4:17.12
0,3,-4:17.12
2,3,-4:17.12
-6,4,-4:17.12
-5,4,-4:17.12
0,5,-4:17.12
-4,6,-4:17.12
-3,6,-4:17.12
-1,6,-4:17.12
0,6,-4:17.12
-4,7,-4:17.12
-3,7,-4:17.12
0,7,-4:17.12
1,7,-4:17.12
-4,8,-4:17.12
0,8,-4:17.12
0,9,-4:17.12
-3,-1,-3:17.12
-5,0,-3:17.12
-4,0,-3:17.12
-3,0,-3:17.12
-8,1,-3:17.12
-4,1,-3:17.12
-2,1,-3:17.12
-1,1,-3:17.12
-8,2,-3:17.12
-7,2,-3:17.12
-6,2,-3:17.12
-1,2,-3:17.12
0,2,-3:17.12
1,2,-3:17.12
2,2,-3:17.12
-6,3,-3:17.12
-5,3,-3:17.12
0,3,-3:17.12
-7,4,-3:17.12
-5,4,-3:17.12
0,5,-3:17.12
1,5,-3:17.12
-7,6,-3:17.12
-1,6,-3:17.12
0,6,-3:17.12
1,6,-3:17.12
-5,7,-3:17.12
-4,7,-3:17.12
-3,7,-3:17.12
-5,8,-3:17.12
-4,8,-3:17.12
0,8,-3:17.12
-4,-2,-2:17.12
-6,-1,-2:17.12
-5,-1,-2:17.12
-4,-1,-2:17.12
-3,-1,-2:17.12
-2,-1,-2:17.12
-1,-1,-2:17.12
0,-1,-2:17.12
-7,0,-2:17.12
-6,0,-2:17.12
-5,0,-2:17.12
-4,0,-2:17.12
-3,0,-2:17.12
-2,0,-2:17.12
-1,0,-2:17.12
0,0,-2:17.12
-8,1,-2:17.12
-7,1,-2:17.12
-6,1,-2:17.12
-5,1,-2:17.12
-4,1,-2:17.12
-3,1,-2:17.12
-2,1,-2:17.12
-1,1,-2:17.12
0,1,-2:17.12
1,1,-2:17.12
-8,2,-2:17.12
-7,2,-2:17.12
-6,2,-2:17.12
-5,2,-2:17.12
-4,2,-2:17.12
-3,2,-2:17.12
-2,2,-2:17.12
-1,2,-2:17.12
0,2,-2:17.12
1,2,-2:17.12
-8,3,-2:17.12
-7,3,-2:17.12
-6,3,-2:17.12
-5,3,-2:17.12
-4,3,-2:17.12
-3,3,-2:17.12
-2,3,-2:17.12
-1,3,-2:17.12
0,3,-2:17.12
1,3,-2:17.12
-8,4,-2:17.12
-7,4,-2:17.12
-6,4,-2:17.12
-5,4,-2:17.12
-4,4,-2:17.12
-3,4,-2:17.12
-2,4,-2:17.12
-1,4,-2:17.12
0,4,-2:17.12
1,4,-2:17.12
-8,5,-2:17.12
-7,5,-2:17.12
-6,5,-2:17.12
-5,5,-2:17.12
-4,5,-2:17.12
-3,5,-2:17.12
-2,5,-2:17.12
-1,5,-2:17.12
0,5,-2:17.12
1,5,-2:17.12
-7,6,-2:17.12
-6,6,-2:17.12
-5,6,-2:17.12
-4,6,-2:17.12
-3,6,-2:17.12
-2,6,-2:17.12
-1,6,-2:17.12
0,6,-2:17.12
1,6,-2:17.12
-6,7,-2:17.12
-5,7,-2:17.12
-4,7,-2:17.12
-3,7,-2:17.12
-2,7,-2:17.12
-1,7,-2:17.12
0,7,-2:17.12
-5,8,-2:17.12
-4,8,-2:17.12
-3,8,-2:17.12
-2,8,-2:17.12
-5,-1,-1:17.12
-4,-1,-1:17.12
-3,-1,-1:17.12
-2,-1,-1:17.12
-1,-1,-1:17.12
-7,0,-1:17.12
-6,0,-1:17.12
-5,0,-1:17.12
-1,0,-1:17.12
0,0,-1:17.12
-7,1,-1:17.12
-2,1,-1:17.12
-1,1,-1:17.12
0,1,-1:17.12
1,1,-1:17.12
-8,2,-1:17.12
-7,2,-1:17.12
-1,2,-1:17.12
1,2,-1:17.12
-8,3,-1:17.12
-6,3,-1:17.12
1,3,-1:17.12
-8,4,-1:17.12
-6,4,-1:17.12
1,4,-1:17.12
-7,5,-1:17.12
0,5,-1:17.12
1,5,-1:17.12
-7,6,-1:17.12
-1,6,-1:17.12
0,6,-1:17.12
1,6,-1:17.12
-6,7,-1:17.12
-5,7,-1:17.12
-4,7,-1:17.12
-2,7,-1:17.12
-1,7,-1:17.12
0,7,-1:17.12
-4,8,-1:17.12
-3,8,-1:17.12
-2,8,-1:17.12
-5,-1,0:17.12
-4,-1,0:17.12
-3,-1,0:17.12
-2,-1,0:17.12
-7,0,0:17.12
-6,0,0:17.12
-5,0,0:17.12
-2,0,0:17.12
-1,0,0:17.12
0,0,0:17.12
-7,1,0:17.12
0,1,0:17.12
-7,2,0:17.12
0,2,0:17.12
1,2,0:17.12
-8,3,0:17.12
-7,3,0:17.12
1,3,0:17.12
-8,4,0:17.12
-7,4,0:17.12
1,4,0:17.12
-7,5,0:17.12
0,5,0:17.12
1,5,0:17.12
-7,6,0:17.12
-6,6,0:17.12
0,6,0:17.12
-6,7,0:17.12
-5,7,0:17.12
-4,7,0:17.12
-2,7,0:17.12
-1,7,0:17.12
-3,8,0:17.12
-4,-1,1:17.12
-3,-1,1:17.12
-6,0,1:17.12
-5,0,1:17.12
-3,0,1:17.12
-2,0,1:17.12
-1,0,1:17.12
-7,1,1:17.12
-6,1,1:17.12
0,1,1:17.12
-7,2,1:17.12
0,2,1:17.12
1,2,1:17.12
-7,3,1:17.12
1,3,1:17.12
-7,4,1:17.12
0,4,1:17.12
1,4,1:17.12
-7,5,1:17.12
0,5,1:17.12
-6,6,1:17.12
-1,6,1:17.12
0,6,1:17.12
-6,7,1:17.12
-5,7,1:17.12
-4,7,1:17.12
-3,7,1:17.12
-2,7,1:17.12
-1,7,1:17.12
-6,0,2:17.12
-5,0,2:17.12
-4,0,2:17.12
-3,0,2:17.12
-2,0,2:17.12
-1,0,2:17.12
-7,1,2:17.12
-6,1,2:17.12
-1,1,2:17.12
0,1,2:17.12
-7,2,2:17.12
0,2,2:17.12
-7,3,2:17.12
0,3,2:17.12
1,3,2:17.12
-7,4,2:17.12
0,4,2:17.12
-7,5,2:17.12
0,5,2:17.12
-6,6,2:17.12
-1,6,2:17.12
0,6,2:17.12
-6,7,2:17.12
-5,7,2:17.12
-4,7,2:17.12
-3,7,2:17.12
-2,7,2:17.12
-1,7,2:17.12
-5,0,3:17.12
-4,0,3:17.12
-3,0,3:17.12
-2,0,3:17.12
-1,0,3:17.12
-6,1,3:17.12
-5,1,3:17.12
-1,1,3:17.12
-7,2,3:17.12
0,2,3:17.12
-7,3,3:17.12
0,3,3:17.12
-7,4,3:17.12
0,4,3:17.12
-7,5,3:17.12
-6,5,3:17.12
0,5,3:17.12
-6,6,3:17.12
-1,6,3:17.12
0,6,3:17.12
-5,7,3:17.12
-4,7,3:17.12
-3,7,3:17.12
-2,7,3:17.12
-5,0,4:17.12
-4,0,4:17.12
-3,0,4:17.12
-2,0,4:17.12
-1,0,4:17.12
-6,1,4:17.12
-5,1,4:17.12
-1,1,4:17.12
-7,2,4:17.12
-6,2,4:17.12
0,2,4:17.12
-7,3,4:17.12
0,3,4:17.12
-7,4,4:17.12
0,4,4:17.12
-7,5,4:17.12
-6,5,4:17.12
0,5,4:17.12
-6,6,4:17.12
-1,6,4:17.12
0,6,4:17.12
-5,7,4:17.12
-4,7,4:17.12
-3,7,4:17.12
-2,7,4:17.12
-4,0,5:17.12
-3,0,5:17.12
-2,0,5:17.12
-6,1,5:17.12
-5,1,5:17.12
-1,1,5:17.12
-6,2,5:17.12
0,2,5:17.12
-7,3,5:17.12
0,3,5:17.12
-7,4,5:17.12
0,4,5:17.12
-6,5,5:17.12
0,5,5:17.12
-6,6,5:17.12
-1,6,5:17.12
0,6,5:17.12
-5,7,5:17.12
-4,7,5:17.12
-3,7,5:17.12
-2,7,5:17.12
-4,0,6:17.12
-3,0,6:17.12
-2,0,6:17.12
-6,1,6:17.12
-5,1,6:17.12
-2,1,6:17.12
-1,1,6:17.12
-6,2,6:17.12
-1,2,6:17.12
0,2,6:17.12
-7,3,6:17.12
-6,3,6:17.12
0,3,6:17.12
-7,4,6:17.12
-6,4,6:17.12
0,4,6:17.12
-6,5,6:17.12
0,5,6:17.12
-6,6,6:17.12
-5,6,6:17.12
-1,6,6:17.12
0,6,6:17.12
-5,7,6:17.12
-4,7,6:17.12
-3,7,6:17.12
-2,7,6:17.12
-4,0,7:17.12
-3,0,7:17.12
-6,1,7:17.12
-5,1,7:17.12
-4,1,7:17.12
-2,1,7:17.12
-1,1,7:17.12
-6,2,7:17.12
-1,2,7:17.12
0,2,7:17.12
-6,3,7:17.12
0,3,7:17.12
-6,4,7:17.12
0,4,7:17.12
-6,5,7:17.12
0,5,7:17.12
-6,6,7:17.12
-5,6,7:17.12
-1,6,7:17.12
0,6,7:17.12
-5,7,7:17.12
-4,7,7:17.12
-3,7,7:17.12
-2,7,7:17.12
-6,1,8:17.12
-5,1,8:17.12
-4,1,8:17.12
-3,1,8:17.12
-2,1,8:17.12
-1,1,8:17.12
-6,2,8:17.12
-1,2,8:17.12
0,2,8:17.12
-6,3,8:17.12
0,3,8:17.12
-6,4,8:17.12
0,4,8:17.12
-6,5,8:17.12
0,5,8:17.12
-5,6,8:17.12
-2,6,8:17.12
-1,6,8:17.12
0,6,8:17.12
-4,7,8:17.12
-3,7,8:17.12
-2,7,8:17.12
-5,1,9:17.12
-4,1,9:17.12
-3,1,9:17.12
-2,1,9:17.12
-1,1,9:17.12
-6,2,9:17.12
-1,2,9:17.12
0,2,9:17.12
-6,3,9:17.12
0,3,9:17.12
-6,4,9:17.12
0,4,9:17.12
-6,5,9:17.12
0,5,9:17.12
-5,6,9:17.12
-4,6,9:17.12
-2,6,9:17.12
-1,6,9:17.12
0,6,9:17.12
-4,7,9:17.12
-3,7,9:17.12
-2,7,9:17.12
-5,1,10:17.12
-4,1,10:17.12
-3,1,10:17.12
-2,1,10:17.12
-1,1,10:17.12
-6,2,10:17.12
-1,2,10:17.12
-6,3,10:17.12
0,3,10:17.12
-6,4,10:17.12
0,4,10:17.12
-6,5,10:17.12
0,5,10:17.12
-5,6,10:17.12
-4,6,10:17.12
-3,6,10:17.12
-2,6,10:17.12
-1,6,10:17.12
-4,7,10:17.12
-3,7,10:17.12
-5,1,11:17.12
-4,1,11:17.12
-3,1,11:17.12
-2,1,11:17.12
-1,1,11:17.12
-6,2,11:17.12
-5,2,11:17.12
-1,2,11:17.12
-6,3,11:17.12
0,3,11:17.12
-6,4,11:17.12
0,4,11:17.12
-6,5,11:17.12
-5,5,11:17.12
0,5,11:17.12
-5,6,11:17.12
-4,6,11:17.12
-3,6,11:17.12
-2,6,11:17.12
-1,6,11:17.12
-5,1,12:17.12
-4,1,12:17.12
-3,1,12:17.12
-2,1,12:17.12
-1,1,12:17.12
-6,2,12:17.12
-5,2,12:17.12
-1,2,12:17.12
-6,3,12:17.12
-1,3,12:17.12
0,3,12:17.12
-6,4,12:17.12
0,4,12:17.12
-5,5,12:17.12
0,5,12:17.12
-5,6,12:17.12
-4,6,12:17.12
-3,6,12:17.12
-2,6,12:17.12
-1,6,12:17.12
-4,1,13:17.12
-3,1,13:17.12
-2,1,13:17.12
-1,1,13:17.12
-6,2,13:17.12
-5,2,13:17.12
-1,2,13:17.12
-6,3,13:17.12
-1,3,13:17.12
-5,4,13:17.12
-1,4,13:17.12
0,4,13:17.12
-5,5,13:17.12
0,5,13:17.12
-5,6,13:17.12
-4,6,13:17.12
-3,6,13:17.12
-2,6,13:17.12
-1,6,13:17.12
-3,1,14:17.12
-2,1,14:17.12
-1,1,14:17.12
-5,2,14:17.12
-4,2,14:17.12
-1,2,14:17.12
-5,3,14:17.12
-1,3,14:17.12
-5,4,14:17.12
-1,4,14:17.12
0,4,14:17.12
-5,5,14:17.12
0,5,14:17.12
-5,6,14:17.12
-4,6,14:17.12
-3,6,14:17.12
-2,6,14:17.12
-1,6,14:17.12
0,-3,15:18.13
-2,1,15:17.12
-5,2,15:17.12
-4,2,15:17.12
-3,2,15:17.12
-2,2,15:17.12
-1,2,15:17.12
-5,3,15:17.12
-1,3,15:17.12
-5,4,15:17.12
-1,4,15:17.12
-5,5,15:17.12
-1,5,15:17.12
0,5,15:17.12
-5,6,15:17.12
-4,6,15:17.12
-3,6,15:17.12
-2,6,15:17.12
-1,6,15:17.12
-1,-3,16:18.13
0,-3,16:18.13
-6,-2,16:18.13
3,0,16:18.13
2,1,16:18.13
3,1,16:18.13
-5,2,16:17.12
-4,2,16:17.12
-3,2,16:17.12
-2,2,16:17.12
-1,2,16:17.12
2,2,16:18.13
-5,3,16:17.12
-1,3,16:17.12
2,3,16:18.13
-5,4,16:17.12
-1,4,16:17.12
3,4,16:18.13
-5,5,16:17.12
-1,5,16:17.12
3,5,16:18.13
4,5,16:18.13
-5,6,16:17.12
-4,6,16:17.12
-3,6,16:17.12
-2,6,16:17.12
-1,6,16:17.12
4,6,16:18.13
1,9,16:18.13
-5,10,16:18.13
-1,-3,17:18.13
0,-3,17:18.13
-6,-2,17:18.13
-5,-2,17:18.13
-2,-2,17:18.13
-1,-2,17:18.13
3,0,17:18.13
-9,1,17:18.13
0,1,17:18.13
2,1,17:18.13
3,1,17:18.13
-9,2,17:18.13
-8,2,17:18.13
-5,2,17:17.12
-4,2,17:17.12
-3,2,17:17.12
-2,2,17:17.12
-1,2,17:17.12
1,2,17:18.13
2,2,17:18.13
-8,3,17:18.13
-5,3,17:17.12
-1,3,17:17.12
2,3,17:18.13
-7,4,17:18.13
-5,4,17:17.12
-1,4,17:17.12
3,4,17:18.13
-7,5,17:18.13
-5,5,17:17.12
-4,5,17:17.12
-1,5,17:17.12
3,5,17:18.13
4,5,17:18.13
-8,6,17:18.13
-4,6,17:17.12
-3,6,17:17.12
-2,6,17:17.12
-1,6,17:17.12
4,6,17:18.13
-8,7,17:18.13
0,8,17:18.13
-4,9,17:18.13
0,9,17:18.13
1,9,17:18.13
-6,-2,18:18.13
-5,-2,18:18.13
-2,-2,18:18.13
-1,-2,18:18.13
-4,-1,18:18.13
3,0,18:18.13
-9,1,18:18.13
-5,1,18:18.13
-1,1,18:18.13
0,1,18:18.13
3,1,18:18.13
-8,2,18:18.13
-5,2,18:17.12
-4,2,18:17.12
-3,2,18:17.12
-2,2,18:17.12
-1,2,18:17.12
0,2,18:18.13
1,2,18:18.13
2,2,18:18.13
-8,3,18:18.13
-6,3,18:18.13
-5,3,18:17.12
-1,3,18:17.12
1,3,18:18.13
2,3,18:18.13
-7,4,18:18.13
-5,4,18:17.12
-1,4,18:17.12
1,4,18:18.13
3,4,18:18.13
-7,5,18:18.13
-6,5,18:18.13
-5,5,18:18.13
-4,5,18:17.12
-1,5,18:17.12
0,5,18:18.13
3,5,18:18.13
4,5,18:18.13
-8,6,18:18.13
-7,6,18:18.13
-5,6,18:18.13
-4,6,18:17.12
-3,6,18:17.12
-2,6,18:17.12
0,6,18:18.13
-8,7,18:18.13
-1,8,18:18.13
0,8,18:18.13
3,8,18:18.13
4,8,18:18.13
-4,9,18:18.13
-3,9,18:18.13
0,9,18:18.13
1,9,18:18.13
-4,10,18:18.13
-6,-2,19:18.13
-5,-2,19:18.13
-2,-2,19:18.13
-1,-2,19:18.13
-5,-1,19:18.13
-4,-1,19:18.13
-3,-1,19:18.13
-4,0,19:18.13
-2,0,19:18.13
-1,0,19:17.12
3,0,19:18.13
-5,1,19:18.13
-4,1,19:18.13
-1,1,19:18.13
0,1,19:18.13
3,1,19:18.13
-8,2,19:18.13
-5,2,19:18.13
-4,2,19:17.12
-3,2,19:17.12
-2,2,19:17.12
-1,2,19:17.12
0,2,19:18.13
1,2,19:18.13
2,2,19:18.13
-8,3,19:18.13
-6,3,19:18.13
-5,3,19:17.12
-1,3,19:17.12
1,3,19:18.13
2,3,19:18.13
-7,4,19:18.13
-6,4,19:18.13
-4,4,19:17.12
-1,4,19:17.12
1,4,19:18.13
3,4,19:18.13
-7,5,19:18.13
-6,5,19:18.13
-5,5,19:18.13
-4,5,19:17.12
-1,5,19:17.12
0,5,19:18.13
3,5,19:18.13
-7,6,19:18.13
-5,6,19:18.13
-4,6,19:17.12
-3,6,19:17.12
-2,6,19:17.12
0,6,19:18.13
-8,7,19:18.13
-7,7,19:18.13
-1,7,19:18.13
-2,8,19:18.13
-1,8,19:18.13
0,8,19:18.13
-4,9,19:18.13
-3,9,19:18.13
1,9,19:18.13
-6,-2,20:18.13
-2,-2,20:18.13
-1,-2,20:18.13
-6,-1,20:18.13
-5,-1,20:18.13
-4,-1,20:18.13
-3,-1,20:18.13
-4,0,20:18.13
-3,0,20:18.13
-2,0,20:18.13
-1,0,20:17.12
3,0,20:18.13
-4,1,20:18.13
-1,1,20:18.13
0,1,20:18.13
3,1,20:18.13
-8,2,20:18.13
-5,2,20:18.13
-4,2,20:17.12
-3,2,20:17.12
-2,2,20:17.12
-1,2,20:17.12
0,2,20:18.13
1,2,20:18.13
2,2,20:18.13
-8,3,20:18.13
-7,3,20:18.13
-6,3,20:18.13
-5,3,20:18.13
-4,3,20:17.12
-1,3,20:17.12
1,3,20:18.13
2,3,20:18.13
-7,4,20:18.13
-6,4,20:18.13
-4,4,20:17.12
-1,4,20:17.12
1,4,20:18.13
3,4,20:18.13
-7,5,20:18.13
-6,5,20:18.13
-5,5,20:18.13
-4,5,20:17.12
-2,5,20:17.12
-1,5,20:17.12
0,5,20:18.13
3,5,20:18.13
4,5,20:18.13
-7,6,20:18.13
-4,6,20:18.13
-3,6,20:17.12
-2,6,20:17.12
-1,6,20:18.13
0,6,20:18.13
-7,7,20:18.13
-3,7,20:18.13
-1,7,20:18.13
4,7,20:18.13
-2,8,20:18.13
-1,8,20:18.13
0,8,20:18.13
4,8,20:18.13
-4,9,20:18.13
-3,9,20:18.13
1,9,20:18.13
-2,-2,21:18.13
-1,-2,21:18.13
-6,-1,21:18.13
-5,-1,21:18.13
-4,-1,21:18.13
-3,-1,21:18.13
-2,-1,21:18.13
-3,0,21:18.13
-2,0,21:18.13
-1,0,21:17.12
3,0,21:18.13
-4,1,21:18.13
-1,1,21:18.13
3,1,21:18.13
-8,2,21:18.13
-5,2,21:18.13
-4,2,21:17.12
-3,2,21:17.12
-2,2,21:17.12
-1,2,21:17.12
0,2,21:18.13
1,2,21:18.13
2,2,21:18.13
-8,3,21:18.13
-7,3,21:18.13
-5,3,21:18.13
-4,3,21:17.12
-1,3,21:17.12
1,3,21:18.13
2,3,21:18.13
-7,4,21:18.13
-6,4,21:18.13
-4,4,21:17.12
-1,4,21:17.12
1,4,21:18.13
2,4,21:18.13
3,4,21:18.13
-7,5,21:18.13
-6,5,21:18.13
-5,5,21:18.13
-4,5,21:17.12
-2,5,21:17.12
-1,5,21:17.12
0,5,21:18.13
3,5,21:18.13
-7,6,21:18.13
-4,6,21:18.13
-3,6,21:17.12
-2,6,21:17.12
-1,6,21:18.13
0,6,21:18.13
-7,7,21:18.13
-3,7,21:18.13
-2,7,21:18.13
-1,7,21:18.13
-2,8,21:18.13
-1,8,21:18.13
0,8,21:18.13
-4,9,21:18.13
-3,9,21:18.13
1,9,21:18.13
-1,-2,22:18.13
-6,-1,22:18.13
-5,-1,22:18.13
-4,-1,22:18.13
-3,-1,22:18.13
-2,-1,22:18.13
-3,0,22:18.13
-2,0,22:18.13
3,0,22:18.13
-4,1,22:18.13
-3,1,22:18.13
-2,1,22:18.13
-1,1,22:18.13
3,1,22:18.13
-8,2,22:18.13
-4,2,22:18.13
-3,2,22:17.12
-2,2,22:17.12
-1,2,22:17.12
0,2,22:18.13
2,2,22:18.13
3,2,22:18.13
-7,3,22:18.13
-5,3,22:18.13
-4,3,22:17.12
-1,3,22:17.12
1,3,22:18.13
2,3,22:18.13
-7,4,22:18.13
-6,4,22:18.13
-5,4,22:18.13
-4,4,22:17.12
-1,4,22:17.12
0,4,22:17.12
1,4,22:18.13
2,4,22:18.13
3,4,22:18.13
-7,5,22:18.13
-6,5,22:18.13
-5,5,22:18.13
-4,5,22:17.12
-2,5,22:17.12
-1,5,22:17.12
0,5,22:18.13
3,5,22:18.13
-7,6,22:18.13
-4,6,22:18.13
-3,6,22:18.13
-2,6,22:17.12
-1,6,22:18.13
0,6,22:18.13
-7,7,22:18.13
-3,7,22:18.13
-2,7,22:18.13
-1,7,22:18.13
-2,8,22:18.13
-1,8,22:18.13
0,8,22:18.13
1,8,22:18.13
-4,9,22:18.13
-3,9,22:18.13
-2,9,22:18.13
1,9,22:18.13
-1,-2,23:18.13
-6,-1,23:18.13
-5,-1,23:18.13
-4,-1,23:18.13
-3,-1,23:18.13
-2,-1,23:18.13
-3,0,23:18.13
-2,0,23:18.13
3,0,23:18.13
4,0,23:18.13
-4,1,23:18.13
-3,1,23:18.13
-2,1,23:18.13
-1,1,23:18.13
3,1,23:18.13
-4,2,23:18.13
-3,2,23:17.12
-2,2,23:17.12
-1,2,23:17.12
0,2,23:18.13
2,2,23:18.13
-7,3,23:18.13
-5,3,23:18.13
-4,3,23:17.12
-1,3,23:17.12
0,3,23:18.13
1,3,23:18.13
2,3,23:18.13
-6,4,23:18.13
-5,4,23:18.13
-4,4,23:17.12
0,4,23:17.12
1,4,23:18.13
2,4,23:18.13
3,4,23:18.13
-7,5,23:18.13
-6,5,23:18.13
-5,5,23:18.13
-4,5,23:17.12
-2,5,23:17.12
-1,5,23:17.12
0,5,23:18.13
3,5,23:18.13
-7,6,23:18.13
-4,6,23:18.13
-3,6,23:18.13
-1,6,23:18.13
4,6,23:18.13
-7,7,23:18.13
-2,7,23:18.13
-1,7,23:18.13
-2,8,23:18.13
-1,8,23:18.13
0,8,23:18.13
1,8,23:18.13
-3,9,23:18.13
-2,9,23:18.13
1,9,23:18.13
-1,-2,24:18.13
0,-2,24:18.13
-5,-1,24:18.13
-4,-1,24:18.13
-2,-1,24:18.13
-1,-1,24:18.13
-3,0,24:18.13
-2,0,24:18.13
3,0,24:18.13
4,0,24:18.13
-3,1,24:18.13
-2,1,24:18.13
-1,1,24:18.13
3,1,24:18.13
-8,2,24:18.13
-7,2,24:18.13
-4,2,24:18.13
-3,2,24:17.12
-2,2,24:17.12
-1,2,24:17.12
0,2,24:18.13
2,2,24:18.13
-7,3,24:18.13
-5,3,24:18.13
-4,3,24:17.12
-1,3,24:17.12
0,3,24:18.13
1,3,24:18.13
-6,4,24:18.13
-5,4,24:18.13
-4,4,24:17.12
0,4,24:17.12
1,4,24:18.13
2,4,24:18.13
3,4,24:18.13
-6,5,24:18.13
-5,5,24:18.13
-4,5,24:18.13
-3,5,24:17.12
-2,5,24:17.12
-1,5,24:17.12
0,5,24:18.13
3,5,24:18.13
-7,6,24:18.13
-6,6,24:18.13
-3,6,24:18.13
-1,6,24:18.13
4,6,24:18.13
-7,7,24:18.13
-2,7,24:18.13
-1,7,24:18.13
-2,8,24:18.13
-1,8,24:18.13
0,8,24:18.13
1,8,24:18.13
-4,9,24:18.13
-3,9,24:18.13
1,9,24:18.13
-1,-2,25:18.13
0,-2,25:18.13
-5,-1,25:18.13
-4,-1,25:18.13
-2,-1,25:18.13
-1,-1,25:18.13
-3,0,25:18.13
-2,0,25:18.13
4,0,25:18.13
-3,1,25:18.13
-2,1,25:18.13
3,1,25:18.13
-8,2,25:18.13
-7,2,25:18.13
-4,2,25:17.12
-3,2,25:18.13
-2,2,25:17.12
-1,2,25:17.12
0,2,25:18.13
2,2,25:18.13
-7,3,25:18.13
-6,3,25:18.13
-4,3,25:18.13
0,3,25:18.13
1,3,25:18.13
-6,4,25:18.13
-5,4,25:18.13
-4,4,25:17.12
0,4,25:17.12
1,4,25:18.13
2,4,25:18.13
3,4,25:18.13
-6,5,25:18.13
-5,5,25:18.13
-4,5,25:18.13
-3,5,25:17.12
-2,5,25:17.12
-1,5,25:17.12
0,5,25:18.13
3,5,25:18.13
-7,6,25:18.13
-6,6,25:18.13
-3,6,25:18.13
-2,6,25:18.13
-1,6,25:18.13
4,6,25:18.13
-7,7,25:18.13
-2,7,25:18.13
-1,7,25:18.13
-2,8,25:18.13
-1,8,25:18.13
0,8,25:18.13
1,8,25:18.13
-4,9,25:18.13
-3,9,25:18.13
0,-2,26:18.13
7,-2,26:18.13
-5,-1,26:18.13
-4,-1,26:18.13
-1,-1,26:18.13
-4,0,26:18.13
-3,0,26:18.13
-2,0,26:18.13
-3,1,26:18.13
-2,1,26:18.13
3,1,26:18.13
-8,2,26:18.13
-7,2,26:18.13
-4,2,26:17.12
-3,2,26:18.13
-2,2,26:17.12
-1,2,26:18.13
0,2,26:17.12
2,2,26:18.13
-7,3,26:18.13
-6,3,26:18.13
-4,3,26:18.13
0,3,26:18.13
1,3,26:18.13
-5,4,26:18.13
-4,4,26:18.13
-3,4,26:17.12
0,4,26:18.13
1,4,26:18.13
2,4,26:18.13
-6,5,26:18.13
-5,5,26:18.13
-4,5,26:18.13
-3,5,26:17.12
-2,5,26:17.12
-1,5,26:17.12
0,5,26:17.12
3,5,26:18.13
-6,6,26:18.13
-3,6,26:18.13
-2,6,26:18.13
-1,6,26:18.13
-7,7,26:18.13
-2,7,26:18.13
-1,7,26:18.13
-2,8,26:18.13
-1,8,26:18.13
0,8,26:18.13
1,8,26:18.13
-4,9,26:18.13
-3,9,26:18.13
0,-2,27:18.13
-4,-1,27:18.13
-1,-1,27:18.13
6,-1,27:18.13
7,-1,27:18.13
-4,0,27:18.13
-3,0,27:18.13
-2,0,27:18.13
-1,0,27:18.13
6,0,27:18.13
-3,1,27:18.13
-2,1,27:18.13
3,1,27:18.13
-7,2,27:18.13
-4,2,27:17.12
-3,2,27:18.13
-2,2,27:17.12
-1,2,27:18.13
0,2,27:17.12
2,2,27:18.13
-7,3,27:18.13
-6,3,27:18.13
-4,3,27:18.13
-3,3,27:18.13
0,3,27:18.13
1,3,27:18.13
-5,4,27:18.13
-4,4,27:18.13
-3,4,27:17.12
0,4,27:18.13
1,4,27:18.13
2,4,27:18.13
-5,5,27:18.13
-4,5,27:18.13
-3,5,27:17.12
-2,5,27:17.12
-1,5,27:17.12
0,5,27:17.12
2,5,27:18.13
3,5,27:18.13
-6,6,27:18.13
-2,6,27:18.13
-1,6,27:18.13
-2,7,27:18.13
-1,7,27:18.13
-2,8,27:18.13
0,8,27:18.13
1,8,27:18.13
-3,9,27:18.13
1,-6,28:18.5
2,-6,28:18.5
-4,-1,28:18.13
-1,-1,28:18.13
0,-1,28:18.13
6,-1,28:18.13
7,-1,28:18.13
-4,0,28:18.13
-3,0,28:18.13
-1,0,28:18.13
5,0,28:18.13
6,0,28:18.13
-3,1,28:18.13
-2,1,28:18.13
2,1,28:18.13
-7,2,28:18.13
-3,2,28:17.12
-2,2,28:18.13
-1,2,28:18.13
0,2,28:17.12
2,2,28:18.13
-7,3,28:18.13
-6,3,28:18.13
-5,3,28:18.13
-3,3,28:18.13
-1,3,28:18.13
0,3,28:18.13
1,3,28:18.13
-5,4,28:18.13
-4,4,28:18.13
-3,4,28:17.12
0,4,28:18.13
1,4,28:18.13
2,4,28:18.13
-5,5,28:18.13
-4,5,28:18.13
-3,5,28:18.13
-2,5,28:17.12
-1,5,28:17.12
0,5,28:17.12
2,5,28:18.13
3,5,28:18.13
7,5,28:18.13
-6,6,28:18.13
-5,6,28:18.13
-2,6,28:18.13
-1,6,28:18.13
-2,7,28:18.13
-1,7,28:18.13
0,7,28:18.13
-3,8,28:18.13
-2,8,28:18.13
0,8,28:18.13
1,8,28:18.13
-3,9,28:18.13
-6,14,28:18.5
0,-6,29:18.5
1,-6,29:18.5
-7,-5,29:18.5
6,-2,29:18.13
-1,-1,29:18.13
0,-1,29:18.13
6,-1,29:18.13
-4,0,29:18.13
-3,0,29:18.13
-1,0,29:18.13
6,0,29:18.13
-3,1,29:18.13
-2,1,29:18.13
-1,1,29:18.13
6,1,29:18.13
-7,2,29:18.13
-3,2,29:17.12
-2,2,29:18.13
-1,2,29:17.12
0,2,29:17.12
1,2,29:18.13
2,2,29:18.13
4,2,29:18.13
-6,3,29:18.13
-5,3,29:18.13
-3,3,29:18.13
-1,3,29:18.13
0,3,29:18.13
1,3,29:18.13
-5,4,29:18.13
-4,4,29:18.13
-3,4,29:17.12
0,4,29:18.13
1,4,29:18.13
-5,5,29:18.13
-4,5,29:18.13
-3,5,29:17.12
-2,5,29:17.12
-1,5,29:18.13
0,5,29:17.12
2,5,29:18.13
3,5,29:18.13
-6,6,29:18.13
-5,6,29:18.13
-2,6,29:18.13
-1,6,29:18.13
-2,7,29:18.13
-1,7,29:18.13
0,7,29:18.13
-3,8,29:18.13
-2,8,29:18.13
0,8,29:18.13
1,8,29:18.13
-3,9,29:18.13
3,12,29:18.5
4,12,29:18.5
-5,13,29:18.5
0,-6,30:18.5
1,-6,30:18.5
0,-5,30:18.5
-8,-4,30:18.5
-7,-4,30:18.5
-6,-4,30:18.5
6,-2,30:18.13
0,-1,30:18.13
6,-1,30:18.13
-4,0,30:18.13
-1,0,30:18.13
2,0,30:18.13
6,0,30:18.13
-3,1,30:18.13
-2,1,30:18.13
-1,1,30:18.13
2,1,30:18.13
3,1,30:18.13
6,1,30:18.13
-11,2,30:18.5
-3,2,30:17.12
-2,2,30:18.13
-1,2,30:17.12
0,2,30:17.12
1,2,30:18.13
2,2,30:18.13
4,2,30:18.13
-6,3,30:18.13
-5,3,30:18.13
-3,3,30:17.12
-2,3,30:18.13
-1,3,30:18.13
0,3,30:17.12
1,3,30:18.13
5,3,30:18.13
-4,4,30:18.13
-3,4,30:18.13
0,4,30:18.13
1,4,30:18.13
6,4,30:18.13
-4,5,30:18.13
-3,5,30:17.12
-2,5,30:18.13
-1,5,30:18.13
0,5,30:17.12
2,5,30:18.13
3,5,30:18.13
6,5,30:18.13
-5,6,30:18.13
-2,6,30:18.13
-1,6,30:18.13
-10,7,30:18.5
-6,7,30:18.13
-2,7,30:18.13
-1,7,30:18.13
0,7,30:18.13
-10,8,30:18.5
-3,8,30:18.13
-2,8,30:18.13
1,8,30:18.13
-3,9,30:18.13
2,12,30:18.5
3,12,30:18.5
4,12,30:18.5
-5,13,30:18.5
-4,13,30:18.5
1,-6,31:18.5
-1,-5,31:18.5
0,-5,31:18.5
1,-5,31:18.5
-7,-4,31:18.5
-6,-4,31:18.5
-5,-4,31:18.5
6,-2,31:18.5
0,-1,31:18.13
1,-1,31:18.13
6,-1,31:18.13
-12,0,31:18.5
-5,0,31:18.13
-4,0,31:18.13
-1,0,31:18.13
0,0,31:18.13
1,0,31:18.13
2,0,31:18.13
6,0,31:18.13
-12,1,31:18.5
-11,1,31:18.5
-4,1,31:18.13
-3,1,31:18.13
-1,1,31:18.13
2,1,31:18.13
3,1,31:18.13
5,1,31:18.13
6,1,31:18.13
-11,2,31:18.5
-6,2,31:18.13
-3,2,31:17.12
-2,2,31:18.13
-1,2,31:17.12
0,2,31:17.12
1,2,31:18.13
2,2,31:18.13
4,2,31:18.13
-6,3,31:18.13
-5,3,31:18.13
-3,3,31:17.12
-2,3,31:18.13
-1,3,31:18.13
0,3,31:17.12
1,3,31:18.13
5,3,31:18.13
-4,4,31:18.13
-3,4,31:18.13
0,4,31:18.13
1,4,31:18.13
4,4,31:18.13
6,4,31:18.13
-9,5,31:18.5
-4,5,31:18.13
-3,5,31:18.13
-2,5,31:18.13
-1,5,31:18.13
0,5,31:17.12
1,5,31:18.13
2,5,31:18.13
3,5,31:18.13
6,5,31:18.13
-10,6,31:18.5
-8,6,31:18.13
-5,6,31:18.13
-4,6,31:18.13
-2,6,31:18.13
-1,6,31:18.13
3,6,31:18.13
-10,7,31:18.5
-6,7,31:18.13
-5,7,31:18.13
-2,7,31:18.13
0,7,31:18.13
2,7,31:18.13
-10,8,31:18.5
-3,8,31:18.13
1,8,31:18.13
-10,9,31:18.5
-3,9,31:18.13
2,12,31:18.5
3,12,31:18.5
-5,13,31:18.5
-4,13,31:18.5
-1,-5,32:18.5
0,-5,32:18.5
1,-5,32:18.5
-7,-4,32:18.5
-6,-4,32:18.5
-5,-4,32:18.5
6,-2,32:18.5
0,-1,32:18.13
6,-1,32:18.5
-12,0,32:18.5
-6,0,32:18.13
-5,0,32:18.13
-4,0,32:18.13
0,0,32:18.13
1,0,32:18.13
2,0,32:18.13
6,0,32:18.5
-11,1,32:18.5
-6,1,32:18.13
-4,1,32:18.13
-3,1,32:18.13
-1,1,32:18.13
2,1,32:18.13
3,1,32:18.13
5,1,32:18.13
-11,2,32:18.5
-10,2,32:18.5
-6,2,32:18.13
-3,2,32:17.12
-2,2,32:18.13
-1,2,32:18.13
0,2,32:17.12
1,2,32:18.13
2,2,32:18.13
3,2,32:18.13
4,2,32:18.13
-10,3,32:18.5
-6,3,32:18.13
-5,3,32:18.13
-4,3,32:18.13
-3,3,32:17.12
-2,3,32:18.13
-1,3,32:18.13
0,3,32:17.12
1,3,32:18.13
4,3,32:18.13
5,3,32:18.13
-4,4,32:18.13
-3,4,32:18.13
-2,4,32:18.13
-1,4,32:18.13
0,4,32:18.13
1,4,32:18.13
4,4,32:18.13
6,4,32:18.13
-9,5,32:18.5
-8,5,32:18.5
-4,5,32:18.13
-3,5,32:18.13
-2,5,32:18.13
-1,5,32:18.13
0,5,32:17.12
1,5,32:18.13
2,5,32:18.13
3,5,32:18.13
6,5,32:18.13
-9,6,32:18.5
-8,6,32:18.5
-7,6,32:18.13
-5,6,32:18.13
-4,6,32:18.13
-2,6,32:18.13
-1,6,32:18.13
0,6,32:18.13
3,6,32:18.13
-10,7,32:18.5
-9,7,32:18.5
-6,7,32:18.13
-5,7,32:18.13
-2,7,32:18.13
0,7,32:18.13
1,7,32:18.13
2,7,32:18.13
-10,8,32:18.5
-5,8,32:18.13
-3,8,32:18.13
1,8,32:18.13
2,8,32:18.13
-10,9,32:18.5
-3,9,32:18.13
-10,10,32:18.5
1,11,32:18.5
2,11,32:18.5
3,11,32:18.5
-3,12,32:18.5
2,12,32:18.5
3,12,32:18.5
-5,13,32:18.5
-4,13,32:18.5
-1,-5,33:18.5
0,-5,33:18.5
1,-5,33:18.5
-7,-4,33:18.5
-6,-4,33:18.5
-5,-4,33:18.5
-4,-4,33:18.5
-1,-4,33:18.5
-4,-3,33:18.5
-3,-3,33:18.5
-4,-2,33:18.13
6,-2,33:18.5
-5,-1,33:18.13
6,-1,33:18.5
-6,0,33:18.13
-5,0,33:18.13
-4,0,33:18.13
0,0,33:18.13
1,0,33:18.13
2,0,33:18.13
5,0,33:18.13
6,0,33:18.5
-11,1,33:18.5
-6,1,33:18.13
-4,1,33:18.13
-3,1,33:18.13
-1,1,33:18.13
0,1,33:18.13
2,1,33:18.13
3,1,33:18.13
5,1,33:18.13
-11,2,33:18.5
-10,2,33:18.5
-6,2,33:18.13
-3,2,33:18.13
-2,2,33:17.12
-1,2,33:18.13
0,2,33:17.12
1,2,33:18.13
2,2,33:18.13
3,2,33:18.13
4,2,33:18.13
-10,3,33:18.5
-8,3,33:18.5
-7,3,33:18.13
-5,3,33:18.13
-4,3,33:18.13
-3,3,33:17.12
-2,3,33:18.13
-1,3,33:18.13
0,3,33:17.12
1,3,33:18.13
4,3,33:18.13
5,3,33:18.13
-9,4,33:18.5
-8,4,33:18.5
-4,4,33:18.13
-3,4,33:18.13
-2,4,33:18.13
-1,4,33:18.13
0,4,33:18.13
1,4,33:17.12
4,4,33:18.13
6,4,33:18.13
-9,5,33:18.5
-8,5,33:18.5
-4,5,33:18.13
-3,5,33:18.13
-2,5,33:17.12
-1,5,33:18.13
0,5,33:17.12
1,5,33:18.13
2,5,33:18.13
3,5,33:18.13
6,5,33:18.13
-9,6,33:18.5
-8,6,33:18.5
-7,6,33:18.13
-4,6,33:18.13
-2,6,33:18.13
-1,6,33:18.13
0,6,33:18.13
2,6,33:18.13
3,6,33:18.13
-9,7,33:18.5
-6,7,33:18.13
-5,7,33:18.13
-2,7,33:18.13
0,7,33:18.13
1,7,33:18.13
2,7,33:18.13
-10,8,33:18.5
-9,8,33:18.5
-5,8,33:18.13
-3,8,33:18.13
1,8,33:18.13
2,8,33:18.13
-10,9,33:18.5
1,11,33:18.5
2,11,33:18.5
3,11,33:18.5
4,11,33:18.5
-4,12,33:18.5
-3,12,33:18.5
-4,13,33:18.5
0,-5,34:18.5
1,-5,34:18.5
-7,-4,34:18.5
-6,-4,34:18.5
-5,-4,34:18.5
-4,-4,34:18.5
-3,-4,34:18.5
-1,-4,34:18.5
-3,-3,34:18.5
-4,-2,34:18.13
-2,-2,34:18.13
-1,-2,34:18.13
6,-2,34:18.5
-5,-1,34:18.13
-4,-1,34:18.13
6,-1,34:18.13
-5,0,34:18.13
0,0,34:18.13
1,0,34:18.13
5,0,34:18.13
6,0,34:18.13
-11,1,34:18.5
-6,1,34:18.13
-4,1,34:18.13
-3,1,34:18.13
0,1,34:18.13
2,1,34:18.13
5,1,34:18.13
-10,2,34:18.5
-6,2,34:18.13
-3,2,34:18.13
-2,2,34:17.12
-1,2,34:18.13
0,2,34:17.12
1,2,34:18.13
3,2,34:18.13
4,2,34:18.13
-10,3,34:18.5
-7,3,34:18.13
-5,3,34:18.13
-4,3,34:18.13
-3,3,34:17.12
-2,3,34:18.13
-1,3,34:18.13
0,3,34:18.13
1,3,34:18.13
4,3,34:18.13
5,3,34:18.13
-9,4,34:18.5
-8,4,34:18.5
-3,4,34:18.13
-2,4,34:18.13
-1,4,34:18.13
0,4,34:18.13
1,4,34:17.12
3,4,34:18.13
4,4,34:18.13
5,4,34:18.13
-9,5,34:18.5
-8,5,34:18.5
-7,5,34:18.13
-3,5,34:18.13
-2,5,34:17.12
-1,5,34:18.13
0,5,34:17.12
1,5,34:18.13
2,5,34:18.13
3,5,34:18.13
-9,6,34:18.5
-7,6,34:18.13
-6,6,34:18.13
-4,6,34:18.13
-2,6,34:18.13
-1,6,34:18.13
0,6,34:18.13
2,6,34:18.13
3,6,34:18.13
-9,7,34:18.5
-6,7,34:18.13
-5,7,34:18.13
-2,7,34:18.13
1,7,34:18.13
2,7,34:18.13
-9,8,34:18.5
-5,8,34:18.13
-4,8,34:18.13
-3,8,34:18.13
1,8,34:18.13
-10,9,34:18.5
-9,9,34:18.5
0,9,34:18.13
1,9,34:18.13
-1,11,34:18.5
0,11,34:18.5
1,11,34:18.5
2,11,34:18.5
3,11,34:18.5
4,11,34:18.5
-4,12,34:18.5
-3,12,34:18.5
-2,12,34:18.5
0,-5,35:18.5
1,-5,35:18.5
-7,-4,35:18.5
-6,-4,35:18.5
-5,-4,35:18.5
-4,-4,35:18.5
-2,-4,35:18.5
-1,-4,35:18.5
0,-4,35:18.5
-6,-3,35:18.5
-5,-3,35:18.5
-4,-3,35:18.5
-3,-3,35:18.5
-2,-3,35:18.5
-4,-2,35:18.13
-3,-2,35:18.13
-2,-2,35:18.13
-1,-2,35:18.13
-4,-1,35:18.13
-1,-1,35:18.13
0,-1,35:18.13
6,-1,35:18.13
-5,0,35:18.13
0,0,35:18.13
1,0,35:18.13
5,0,35:18.13
-10,1,35:18.5
-5,1,35:18.13
0,1,35:18.13
1,1,35:18.13
2,1,35:18.13
5,1,35:18.13
-10,2,35:18.5
-6,2,35:18.13
-3,2,35:18.13
-2,2,35:17.12
-1,2,35:17.12
0,2,35:17.12
3,2,35:18.13
-10,3,35:18.5
-9,3,35:18.5
-7,3,35:18.13
-4,3,35:18.13
-3,3,35:18.13
-2,3,35:18.13
-1,3,35:18.13
0,3,35:18.13
1,3,35:17.12
4,3,35:18.13
5,3,35:18.13
-9,4,35:18.5
-8,4,35:18.5
-7,4,35:18.13
-3,4,35:18.13
-2,4,35:18.13
-1,4,35:18.13
0,4,35:18.13
1,4,35:17.12
3,4,35:18.13
4,4,35:18.13
5,4,35:18.13
-8,5,35:18.5
-7,5,35:18.13
-3,5,35:18.13
-2,5,35:17.12
-1,5,35:18.13
0,5,35:17.12
1,5,35:18.13
2,5,35:18.13
3,5,35:18.13
-9,6,35:18.5
-7,6,35:18.13
-6,6,35:18.13
-3,6,35:18.13
-2,6,35:18.13
0,6,35:18.13
2,6,35:18.13
-9,7,35:18.5
-6,7,35:18.13
-5,7,35:18.13
-3,7,35:18.13
-2,7,35:18.13
1,7,35:18.13
2,7,35:18.13
-9,8,35:18.5
-5,8,35:18.13
-4,8,35:18.13
1,8,35:18.13
-9,9,35:18.5
-3,9,35:18.13
0,9,35:18.13
1,9,35:18.13
-2,10,35:18.5
-1,11,35:18.5
0,11,35:18.5
1,11,35:18.5
2,11,35:18.5
3,11,35:18.5
-4,12,35:18.5
-3,12,35:18.5
-2,12,35:18.5
-2,-4,36:18.5
-1,-4,36:18.5
0,-4,36:18.5
-7,-3,36:18.5
-6,-3,36:18.5
-5,-3,36:18.5
-4,-3,36:18.5
-3,-3,36:18.5
-2,-3,36:18.5
-3,-2,36:18.13
-2,-2,36:18.13
-1,-2,36:18.13
-4,-1,36:18.13
-1,-1,36:18.13
0,-1,36:18.13
5,-1,36:18.13
6,-1,36:18.13
-5,0,36:18.13
-4,0,36:18.13
0,0,36:18.13
1,0,36:18.13
5,0,36:18.13
-10,1,36:18.5
-5,1,36:18.13
1,1,36:18.13
2,1,36:18.13
5,1,36:18.13
-10,2,36:18.5
-6,2,36:18.13
-2,2,36:17.12
-1,2,36:17.12
0,2,36:18.13
2,2,36:18.13
3,2,36:18.13
4,2,36:18.13
-9,3,36:18.5
-7,3,36:18.13
-6,3,36:18.13
-4,3,36:18.13
-3,3,36:18.13
-2,3,36:18.13
-1,3,36:18.13
0,3,36:18.13
1,3,36:17.12
4,3,36:18.13
-9,4,36:18.5
-8,4,36:18.5
-7,4,36:18.13
-3,4,36:18.13
-2,4,36:18.13
-1,4,36:18.13
0,4,36:18.13
1,4,36:17.12
3,4,36:18.13
5,4,36:18.13
-8,5,36:18.5
-7,5,36:18.13
-3,5,36:18.13
-2,5,36:18.13
-1,5,36:18.13
0,5,36:18.13
1,5,36:18.13
2,5,36:18.13
3,5,36:18.13
-9,6,36:18.5
-8,6,36:18.5
-6,6,36:18.13
-2,6,36:18.13
0,6,36:18.13
2,6,36:18.13
-9,7,36:18.5
-5,7,36:18.13
-2,7,36:18.13
1,7,36:18.13
2,7,36:18.13
-9,8,36:18.5
-4,8,36:18.13
-3,8,36:18.13
1,8,36:18.13
-9,9,36:18.5
-3,9,36:18.13
-2,9,36:18.13
0,9,36:18.13
-2,10,36:18.5
-1,10,36:18.5
-2,11,36:18.5
-1,11,36:18.5
0,11,36:18.5
1,11,36:18.5
2,11,36:18.5
3,11,36:18.5
-4,12,36:18.5
-3,12,36:18.5
-2,12,36:18.5
-1,-4,37:18.5
0,-4,37:18.5
-7,-3,37:18.5
-6,-3,37:18.5
-5,-3,37:18.5
-4,-3,37:18.5
-3,-3,37:18.5
-2,-3,37:18.5
-3,-2,37:18.13
-2,-2,37:18.13
-4,-1,37:18.13
-3,-1,37:18.13
-1,-1,37:18.13
5,-1,37:18.13
-4,0,37:18.13
0,0,37:18.13
1,0,37:18.13
5,0,37:18.13
-5,1,37:18.13
1,1,37:18.13
2,1,37:18.13
5,1,37:18.13
-10,2,37:18.5
-6,2,37:18.13
-5,2,37:18.13
-2,2,37:17.12
-1,2,37:17.12
0,2,37:17.12
1,2,37:17.12
2,2,37:18.13
3,2,37:18.13
4,2,37:18.13
-9,3,37:18.5
-6,3,37:18.13
-2,3,37:17.12
-1,3,37:18.13
1,3,37:17.12
4,3,37:18.13
-9,4,37:18.5
-8,4,37:18.5
-7,4,37:18.13
-2,4,37:17.12
-1,4,37:18.13
1,4,37:17.12
3,4,37:18.13
4,4,37:18.13
5,4,37:18.13
-8,5,37:18.5
-7,5,37:18.13
-6,5,37:18.13
-2,5,37:18.13
-1,5,37:17.12
0,5,37:17.12
1,5,37:17.12
2,5,37:18.13
3,5,37:18.13
6,5,37:18.13
-8,6,37:18.5
-6,6,37:18.13
-5,6,37:18.13
-2,6,37:18.13
2,6,37:18.13
6,6,37:18.13
-9,7,37:18.5
-8,7,37:18.5
-5,7,37:18.13
-4,7,37:18.13
1,7,37:18.13
-9,8,37:18.5
-4,8,37:18.13
-3,8,37:18.13
0,8,37:18.13
1,8,37:18.13
-9,9,37:18.5
-3,9,37:18.13
-2,9,37:18.13
0,9,37:18.13
-2,10,37:18.5
-1,10,37:18.5
-2,11,37:18.5
-1,11,37:18.5
0,11,37:18.5
1,11,37:18.5
2,11,37:18.5
3,11,37:18.5
-4,12,37:18.5
-3,12,37:18.5
-1,-4,38:18.5
0,-4,38:18.5
-7,-3,38:18.5
-6,-3,38:18.5
-5,-3,38:18.5
-4,-3,38:18.5
-3,-3,38:18.5
-2,-3,38:18.5
-1,-3,38:18.5
-3,-2,38:18.13
-2,-2,38:18.13
-3,-1,38:18.13
-2,-1,38:18.13
-1,-1,38:18.13
5,-1,38:18.13
-4,0,38:18.13
-1,0,38:18.13
0,0,38:18.13
5,0,38:18.13
-5,1,38:18.13
-4,1,38:18.13
1,1,38:18.13
5,1,38:18.13
-5,2,38:18.13
-2,2,38:17.12
-1,2,38:17.12
0,2,38:17.12
1,2,38:17.12
2,2,38:18.13
4,2,38:18.13
-9,3,38:18.5
-6,3,38:18.13
-2,3,38:17.12
1,3,38:17.12
4,3,38:18.13
-8,4,38:18.5
-7,4,38:18.13
-6,4,38:18.13
-2,4,38:17.12
-1,4,38:18.13
1,4,38:17.12
3,4,38:18.13
4,4,38:18.13
5,4,38:18.13
-7,5,38:18.13
-6,5,38:18.13
-2,5,38:17.12
-1,5,38:17.12
0,5,38:17.12
1,5,38:17.12
2,5,38:18.13
6,5,38:18.5
-8,6,38:18.5
-6,6,38:18.13
-5,6,38:18.13
2,6,38:18.13
6,6,38:18.5
-8,7,38:18.5
-5,7,38:18.13
-4,7,38:18.13
1,7,38:18.13
-9,8,38:18.5
-8,8,38:18.5
-3,8,38:18.13
0,8,38:18.13
1,8,38:18.13
-9,9,38:18.5
-2,9,38:18.13
-1,9,38:18.13
0,9,38:18.13
-1,10,38:18.5
-2,11,38:18.5
-1,11,38:18.5
0,11,38:18.5
1,11,38:18.5
2,11,38:18.5
3,11,38:18.5
-3,12,38:18.5
0,-4,39:18.5
1,-4,39:18.5
-6,-3,39:18.5
-5,-3,39:18.5
-4,-3,39:18.5
-3,-3,39:18.5
-2,-3,39:18.5
-1,-3,39:18.5
-3,-2,39:18.13
-2,-2,39:18.13
-3,-1,39:18.13
-2,-1,39:18.13
-1,-1,39:18.13
-4,0,39:18.13
-3,0,39:18.13
-1,0,39:18.13
0,0,39:18.13
5,0,39:18.13
-4,1,39:18.13
0,1,39:18.13
1,1,39:18.13
5,1,39:18.13
-9,2,39:18.5
-5,2,39:18.13
-2,2,39:17.12
-1,2,39:17.12
0,2,39:17.12
1,2,39:17.12
2,2,39:18.13
4,2,39:18.13
-9,3,39:18.5
-6,3,39:18.13
-5,3,39:18.13
-2,3,39:17.12
1,3,39:17.12
4,3,39:18.13
-8,4,39:18.5
-7,4,39:18.5
-6,4,39:18.13
-2,4,39:17.12
1,4,39:17.12
3,4,39:18.13
4,4,39:18.13
5,4,39:18.13
-7,5,39:18.5
-6,5,39:18.13
-2,5,39:17.12
-1,5,39:17.12
0,5,39:17.12
1,5,39:17.12
2,5,39:18.13
5,5,39:18.13
6,5,39:18.5
-8,6,39:18.5
-7,6,39:18.5
-5,6,39:18.13
1,6,39:18.13
2,6,39:18.13
6,6,39:18.5
-8,7,39:18.5
-4,7,39:18.13
-3,7,39:18.13
1,7,39:18.13
-8,8,39:18.5
-3,8,39:18.13
-2,8,39:18.13
0,8,39:18.13
-8,9,39:18.5
-2,9,39:18.13
-1,9,39:18.13
0,9,39:18.13
-1,10,39:18.5
-2,11,39:18.5
-1,11,39:18.5
0,11,39:18.5
1,11,39:18.5
2,11,39:18.5
3,11,39:18.5
-4,12,39:18.5
0,-4,40:18.5
1,-4,40:18.5
-6,-3,40:18.5
-5,-3,40:18.5
-4,-3,40:18.5
-1,-3,40:18.5
0,-3,40:18.5
-3,-2,40:18.13
-2,-2,40:18.13
-3,-1,40:18.13
-2,-1,40:18.13
-1,-1,40:18.13
-3,0,40:18.13
-1,0,40:18.13
0,0,40:18.13
5,0,40:18.13
-9,1,40:18.5
-4,1,40:18.13
0,1,40:18.13
1,1,40:18.13
5,1,40:18.13
-9,2,40:18.5
-5,2,40:18.13
-4,2,40:18.13
-2,2,40:17.12
-1,2,40:17.12
0,2,40:17.12
1,2,40:18.13
2,2,40:18.13
4,2,40:18.13
-9,3,40:18.5
-8,3,40:18.5
-5,3,40:18.13
-2,3,40:17.12
1,3,40:17.12
2,3,40:18.13
4,3,40:18.13
-8,4,40:18.5
-7,4,40:18.5
-6,4,40:18.13
-2,4,40:17.12
1,4,40:17.12
2,4,40:18.13
3,4,40:18.13
4,4,40:18.13
5,4,40:18.13
-7,5,40:18.5
-6,5,40:18.13
-5,5,40:18.13
-2,5,40:17.12
-1,5,40:17.12
0,5,40:17.12
1,5,40:17.12
2,5,40:18.13
5,5,40:18.13
6,5,40:18.5
-8,6,40:18.5
-7,6,40:18.5
-5,6,40:18.13
-4,6,40:18.13
1,6,40:18.13
2,6,40:18.13
6,6,40:18.5
-8,7,40:18.5
-4,7,40:18.13
-3,7,40:18.13
1,7,40:18.13
6,7,40:18.5
-8,8,40:18.5
-3,8,40:18.13
-2,8,40:18.13
0,8,40:18.13
-2,9,40:18.13
-1,9,40:18.13
0,9,40:18.13
-1,10,40:18.5
-3,11,40:18.5
-2,11,40:18.5
-1,11,40:18.5
1,11,40:18.5
2,11,40:18.5
3,11,40:18.5
-4,12,40:18.5
1,-4,41:18.5
-5,-3,41:18.5
-4,-3,41:18.5
-1,-3,41:18.5
0,-3,41:18.5
1,-3,41:18.5
-5,-2,41:18.13
-4,-2,41:18.13
-3,-2,41:18.13
-2,-2,41:18.13
-1,-2,41:18.13
-3,-1,41:18.13
-2,-1,41:18.13
-3,0,41:18.13
-2,0,41:18.13
-1,0,41:18.13
-9,1,41:18.5
-4,1,41:18.13
-3,1,41:18.13
0,1,41:18.13
5,1,41:18.13
-9,2,41:18.5
-4,2,41:18.13
-2,2,41:17.12
-1,2,41:17.12
0,2,41:17.12
1,2,41:18.13
2,2,41:18.13
4,2,41:18.13
-8,3,41:18.5
-5,3,41:18.13
-2,3,41:17.12
1,3,41:17.12
2,3,41:18.13
-8,4,41:18.5
-7,4,41:18.5
-6,4,41:18.13
-5,4,41:18.13
-2,4,41:17.12
1,4,41:17.12
2,4,41:18.13
3,4,41:18.13
4,4,41:18.13
-7,5,41:18.5
-6,5,41:18.13
-5,5,41:18.13
-2,5,41:17.12
-1,5,41:17.12
0,5,41:17.12
1,5,41:17.12
2,5,41:18.13
5,5,41:18.13
-7,6,41:18.5
-5,6,41:18.13
-4,6,41:18.13
1,6,41:18.13
6,6,41:18.5
-8,7,41:18.5
-4,7,41:18.13
-3,7,41:18.13
0,7,41:18.13
1,7,41:18.13
6,7,41:18.5
-8,8,41:18.5
-2,8,41:18.13
0,8,41:18.13
-1,9,41:18.13
0,9,41:18.13
-1,10,41:18.5
1,10,41:18.5
2,10,41:18.5
-3,11,41:18.5
-2,11,41:18.5
-4,12,41:18.5
-7,-6,42:18.5
-1,-3,42:18.5
0,-3,42:18.5
1,-3,42:18.5
-5,-2,42:18.13
-4,-2,42:18.13
-3,-2,42:18.13
-1,-2,42:18.13
-3,-1,42:18.13
-2,-1,42:18.13
-3,0,42:18.13
-2,0,42:18.13
-1,0,42:18.13
-12,1,42:18.5
-11,1,42:18.5
-9,1,42:18.5
-3,1,42:18.13
-1,1,42:18.13
0,1,42:18.13
5,1,42:18.13
-9,2,42:18.5
-8,2,42:18.5
-4,2,42:18.13
-2,2,42:17.12
-1,2,42:17.12
0,2,42:17.12
1,2,42:18.13
4,2,42:18.13
-8,3,42:18.5
-5,3,42:18.13
-4,3,42:18.13
-2,3,42:17.12
1,3,42:17.12
2,3,42:18.13
-7,4,42:18.5
-6,4,42:18.13
-5,4,42:18.13
-2,4,42:17.12
1,4,42:17.12
2,4,42:18.13
3,4,42:18.13
4,4,42:18.13
-6,5,42:18.13
-5,5,42:18.13
-2,5,42:17.12
-1,5,42:17.12
0,5,42:17.12
1,5,42:17.12
2,5,42:18.13
5,5,42:18.13
-7,6,42:18.5
-6,6,42:18.13
-4,6,42:18.13
1,6,42:18.13
6,6,42:18.5
-8,7,42:18.5
-7,7,42:18.5
-3,7,42:18.13
-2,7,42:18.13
0,7,42:18.13
1,7,42:18.13
8,7,42:18.13
9,7,42:18.13
-2,8,42:18.13
-1,8,42:18.13
0,8,42:18.13
-1,9,42:18.13
0,9,42:18.13
-2,10,42:18.5
-1,10,42:18.5
1,10,42:18.5
2,10,42:18.5
-4,11,42:18.5
-3,11,42:18.5
-2,11,42:18.5
-4,12,42:18.5
4,13,42:18.5
4,14,42:18.5
-7,-7,43:18.5
-6,-7,43:18.5
-7,-6,43:18.5
-7,-5,43:18.5
-7,-4,43:18.5
-1,-3,43:18.5
0,-3,43:18.5
1,-3,43:18.5
-4,-2,43:18.13
-3,-2,43:18.13
-1,-2,43:18.13
-8,-1,43:18.5
-3,-1,43:18.13
-2,-1,43:18.13
-1,-1,43:18.13
-10,0,43:18.5
-8,0,43:18.5
-2,0,43:18.13
-1,0,43:18.13
-12,1,43:18.5
-11,1,43:18.5
-3,1,43:18.13
-1,1,43:18.13
0,1,43:18.13
4,1,43:18.13
-13,2,43:18.5
-12,2,43:18.5
-8,2,43:18.5
-4,2,43:18.13
-3,2,43:18.13
-1,2,43:17.12
0,2,43:17.12
1,2,43:18.13
3,2,43:18.13
4,2,43:18.13
-8,3,43:18.5
-7,3,43:18.5
-4,3,43:18.13
-2,3,43:17.12
1,3,43:17.12
2,3,43:18.13
-7,4,43:18.5
-6,4,43:18.13
-5,4,43:18.13
-2,4,43:17.12
1,4,43:17.12
2,4,43:18.13
3,4,43:18.13
4,4,43:18.13
-6,5,43:18.13
-5,5,43:18.13
-4,5,43:18.13
-1,5,43:17.12
0,5,43:17.12
1,5,43:18.13
2,5,43:18.13
4,5,43:18.13
5,5,43:18.13
-7,6,43:18.5
-6,6,43:18.13
-4,6,43:18.13
-3,6,43:18.13
1,6,43:18.13
5,6,43:18.13
9,6,43:18.13
10,6,43:18.13
-7,7,43:18.5
-3,7,43:18.13
-2,7,43:18.13
0,7,43:18.13
8,7,43:18.13
9,7,43:18.13
-2,8,43:18.13
-1,8,43:18.13
0,8,43:18.13
5,8,43:18.13
7,8,43:18.5
-1,9,43:18.13
0,9,43:18.13
5,9,43:18.13
-2,10,43:18.5
-1,10,43:18.5
1,10,43:18.5
2,10,43:18.5
-3,11,43:18.5
-2,11,43:18.5
4,12,43:18.5
4,13,43:18.5
4,14,43:18.5
3,15,43:18.5
4,15,43:18.5
-6,-7,44:18.5
-7,-6,44:18.5
-6,-6,44:18.5
-7,-5,44:18.5
-7,-4,44:18.5
-7,-3,44:18.5
0,-3,44:18.5
-4,-2,44:18.13
-1,-2,44:18.13
0,-2,44:18.13
-8,-1,44:18.5
-3,-1,44:18.13
-1,-1,44:18.13
-10,0,44:18.5
-9,0,44:18.5
-8,0,44:18.5
-2,0,44:18.13
-1,0,44:18.13
-12,1,44:18.5
-11,1,44:18.5
-10,1,44:18.5
-8,1,44:18.5
-3,1,44:18.13
-2,1,44:18.13
-1,1,44:18.13
0,1,44:18.13
4,1,44:18.13
-13,2,44:18.5
-12,2,44:18.5
-8,2,44:18.5
-3,2,44:18.13
-1,2,44:17.12
0,2,44:18.13
1,2,44:18.13
3,2,44:18.13
4,2,44:18.13
-8,3,44:18.5
-7,3,44:18.5
-4,3,44:18.13
-2,3,44:17.12
-1,3,44:17.12
1,3,44:18.13
2,3,44:18.13
-7,4,44:18.5
-6,4,44:18.13
-5,4,44:18.13
-4,4,44:18.13
-2,4,44:17.12
1,4,44:17.12
2,4,44:18.13
3,4,44:18.13
10,4,44:18.5
-6,5,44:18.13
-5,5,44:18.13
-4,5,44:18.13
-1,5,44:17.12
0,5,44:17.12
1,5,44:18.13
4,5,44:18.13
5,5,44:18.13
-6,6,44:18.13
-4,6,44:18.13
-3,6,44:18.13
0,6,44:18.13
1,6,44:18.13
5,6,44:18.13
9,6,44:18.5
10,6,44:18.5
-7,7,44:18.5
-3,7,44:18.13
-2,7,44:18.13
0,7,44:18.13
5,7,44:18.13
7,7,44:18.5
8,7,44:18.5
-1,8,44:18.13
0,8,44:18.13
5,8,44:18.13
6,8,44:18.5
7,8,44:18.5
-1,9,44:18.13
0,9,44:18.13
1,9,44:18.13
5,9,44:18.13
6,9,44:18.5
-2,10,44:18.5
1,10,44:18.5
2,10,44:18.5
-3,11,44:18.5
-2,11,44:18.5
5,11,44:18.5
4,12,44:18.5
4,13,44:18.5
4,14,44:18.5
-6,-6,45:18.5
-7,-5,45:18.5
-7,-4,45:18.5
-7,-3,45:18.5
0,-3,45:18.5
1,-3,45:18.5
-4,-2,45:18.13
-1,-2,45:18.13
0,-2,45:18.13
-8,-1,45:18.5
-4,-1,45:18.13
-3,-1,45:18.13
-1,-1,45:18.13
-10,0,45:18.5
-9,0,45:18.5
-8,0,45:18.5
-3,0,45:18.13
-2,0,45:18.13
-1,0,45:18.13
-11,1,45:18.5
-10,1,45:18.5
-8,1,45:18.5
-2,1,45:18.13
-1,1,45:18.13
10,1,45:18.5
-13,2,45:18.5
-12,2,45:18.5
-8,2,45:18.5
-3,2,45:18.13
-1,2,45:17.12
0,2,45:18.13
3,2,45:18.13
4,2,45:18.13
-8,3,45:18.5
-7,3,45:18.5
-4,3,45:18.13
-3,3,45:18.13
-2,3,45:17.12
-1,3,45:17.12
1,3,45:18.13
2,3,45:18.13
-6,4,45:18.13
-5,4,45:18.13
-4,4,45:18.13
-2,4,45:17.12
-1,4,45:17.12
1,4,45:17.12
2,4,45:18.13
3,4,45:18.13
10,4,45:18.5
-5,5,45:18.13
-4,5,45:18.13
-1,5,45:17.12
0,5,45:17.12
1,5,45:18.13
4,5,45:18.13
5,5,45:18.13
-6,6,45:18.13
-5,6,45:18.13
-3,6,45:18.13
-2,6,45:18.13
0,6,45:18.13
1,6,45:18.13
9,6,45:18.5
10,6,45:18.5
-7,7,45:18.5
-6,7,45:18.13
-2,7,45:18.13
-1,7,45:18.13
0,7,45:18.13
5,7,45:18.13
7,7,45:18.5
8,7,45:18.5
-1,8,45:18.13
0,8,45:18.13
5,8,45:18.13
6,8,45:18.5
7,8,45:18.5
-1,9,45:18.13
0,9,45:18.13
1,9,45:18.13
5,9,45:18.13
-2,10,45:18.5
1,10,45:18.5
2,10,45:18.5
-3,11,45:18.5
-2,11,45:18.5
4,11,45:18.5
5,11,45:18.5
4,12,45:18.5
4,13,45:18.5
4,14,45:18.5
-6,-6,46:18.5
-7,-5,46:18.5
-7,-4,46:18.5
-7,-3,46:18.5
-7,-2,46:18.5
-4,-2,46:18.13
0,-2,46:18.13
-8,-1,46:18.5
-7,-1,46:18.5
-4,-1,46:18.13
-3,-1,46:18.13
-1,-1,46:18.13
0,-1,46:18.13
-9,0,46:18.5
-8,0,46:18.5
-3,0,46:18.13
-2,0,46:18.13
-1,0,46:18.13
-11,1,46:18.5
-10,1,46:18.5
-8,1,46:18.5
-2,1,46:18.13
-1,1,46:18.13
4,1,46:18.13
10,1,46:18.5
-12,2,46:18.5
-11,2,46:18.5
-8,2,46:18.5
-3,2,46:18.13
-2,2,46:18.13
-1,2,46:18.13
0,2,46:18.13
3,2,46:18.13
4,2,46:18.13
-8,3,46:18.5
-7,3,46:18.5
-6,3,46:18.13
-3,3,46:18.13
-2,3,46:17.12
-1,3,46:17.12
0,3,46:18.13
1,3,46:18.13
2,3,46:18.13
-6,4,46:18.13
-5,4,46:18.13
-4,4,46:18.13
-2,4,46:17.12
-1,4,46:17.12
1,4,46:17.12
2,4,46:18.13
3,4,46:18.13
-5,5,46:18.13
-4,5,46:18.13
-3,5,46:18.13
-1,5,46:17.12
0,5,46:17.12
1,5,46:18.13
3,5,46:18.13
4,5,46:18.13
-6,6,46:18.13
-5,6,46:18.13
-3,6,46:18.13
-2,6,46:18.13
0,6,46:18.13
5,6,46:18.13
9,6,46:18.5
-6,7,46:18.13
-2,7,46:18.13
-1,7,46:18.13
0,7,46:18.13
5,7,46:18.13
7,7,46:18.5
8,7,46:18.5
-1,8,46:18.13
0,8,46:18.13
5,8,46:18.13
6,8,46:18.5
7,8,46:18.5
-2,9,46:18.13
-1,9,46:18.13
0,9,46:18.13
1,9,46:18.13
3,9,46:18.13
4,9,46:18.13
5,9,46:18.13
-2,10,46:18.5
2,10,46:18.5
5,10,46:18.5
-3,11,46:18.5
4,11,46:18.5
5,11,46:18.5
4,12,46:18.5
4,13,46:18.5
-7,-4,47:18.5
-6,-4,47:18.5
-7,-3,47:18.5
-7,-2,47:18.5
0,-2,47:18.13
-7,-1,47:18.5
-6,-1,47:18.13
-5,-1,47:18.13
-4,-1,47:18.13
-3,-1,47:18.13
-1,-1,47:18.13
0,-1,47:18.13
-9,0,47:18.5
-8,0,47:18.5
-7,0,47:18.5
-3,0,47:18.13
-2,0,47:18.13
-1,0,47:18.13
-11,1,47:18.5
-10,1,47:18.5
-9,1,47:18.5
-7,1,47:18.5
-2,1,47:18.13
-1,1,47:18.13
4,1,47:18.13
-12,2,47:18.5
-11,2,47:18.5
-8,2,47:18.5
-7,2,47:18.5
-2,2,47:18.13
-1,2,47:18.13
0,2,47:18.13
3,2,47:18.13
-8,3,47:18.5
-7,3,47:18.5
-6,3,47:18.13
-3,3,47:18.13
-2,3,47:17.12
-1,3,47:17.12
0,3,47:18.13
1,3,47:18.13
2,3,47:18.13
-8,4,47:18.5
-5,4,47:18.13
-4,4,47:18.13
-3,4,47:18.13
-2,4,47:17.12
-1,4,47:17.12
1,4,47:18.13
2,4,47:18.13
5,4,47:18.13
-8,5,47:18.5
-5,5,47:18.13
-4,5,47:18.13
-3,5,47:18.13
-1,5,47:17.12
0,5,47:17.12
1,5,47:18.13
3,5,47:18.13
4,5,47:18.13
5,5,47:18.13
-5,6,47:18.13
-3,6,47:18.13
-2,6,47:18.13
0,6,47:18.13
5,6,47:18.13
8,6,47:18.5
9,6,47:18.5
-6,7,47:18.13
-1,7,47:18.13
0,7,47:18.13
5,7,47:18.13
7,7,47:18.5
8,7,47:18.5
-1,8,47:18.13
0,8,47:18.13
4,8,47:18.13
5,8,47:18.13
6,8,47:18.5
-2,9,47:18.13
-1,9,47:18.13
1,9,47:18.13
2,9,47:18.13
3,9,47:18.13
4,9,47:18.13
5,9,47:18.13
-2,10,47:18.5
5,10,47:18.5
4,11,47:18.5
4,12,47:18.5
4,13,47:18.5
-6,-4,48:18.5
-7,-3,48:18.5
-7,-2,48:18.5
-2,-2,48:18.13
-7,-1,48:18.5
-6,-1,48:18.13
-5,-1,48:18.13
-4,-1,48:18.13
0,-1,48:18.13
-9,0,48:18.5
-8,0,48:18.5
-7,0,48:18.5
-6,0,48:18.13
-3,0,48:18.13
-1,0,48:18.13
0,0,48:18.13
-10,1,48:18.5
-9,1,48:18.5
-7,1,48:18.5
-2,1,48:18.13
-1,1,48:18.13
4,1,48:18.13
-12,2,48:18.5
-11,2,48:18.5
-7,2,48:18.5
-2,2,48:18.13
-1,2,48:18.13
0,2,48:18.13
3,2,48:18.13
-12,3,48:18.5
-7,3,48:18.5
-6,3,48:18.13
-3,3,48:18.13
-2,3,48:18.13
-1,3,48:17.12
0,3,48:18.13
1,3,48:17.12
2,3,48:18.13
5,3,48:18.13
-7,4,48:18.5
-5,4,48:18.13
-4,4,48:18.13
-3,4,48:18.13
-1,4,48:17.12
1,4,48:18.13
2,4,48:18.13
5,4,48:18.13
-7,5,48:18.5
-4,5,48:18.13
-3,5,48:18.13
-1,5,48:17.12
0,5,48:17.12
1,5,48:18.13
3,5,48:18.13
4,5,48:18.13
5,5,48:18.13
-5,6,48:18.13
-2,6,48:18.13
-1,6,48:18.13
0,6,48:18.13
4,6,48:18.13
5,6,48:18.13
8,6,48:18.5
9,6,48:18.5
-6,7,48:18.13
-5,7,48:18.13
-1,7,48:18.13
0,7,48:18.13
5,7,48:18.13
7,7,48:18.5
8,7,48:18.5
-1,8,48:18.13
0,8,48:18.13
1,8,48:18.13
4,8,48:18.13
5,8,48:18.13
6,8,48:18.5
-2,9,48:18.13
1,9,48:18.13
2,9,48:18.13
3,9,48:18.13
4,9,48:18.13
5,9,48:18.13
-2,10,48:18.5
-1,10,48:18.5
4,10,48:18.5
5,10,48:18.5
4,11,48:18.5
4,12,48:18.5
4,13,48:18.5
-6,-4,49:18.5
-7,-3,49:18.5
-6,-3,49:18.5
-7,-2,49:18.5
-2,-2,49:18.13
-1,-2,49:18.13
-7,-1,49:18.5
-5,-1,49:18.13
-4,-1,49:18.13
0,-1,49:18.13
-8,0,49:18.5
-7,0,49:18.5
-6,0,49:18.13
-4,0,49:18.13
-3,0,49:18.13
0,0,49:18.13
-10,1,49:18.5
-9,1,49:18.5
-7,1,49:18.5
-3,1,49:18.13
-2,1,49:18.13
-1,1,49:18.13
3,1,49:18.13
4,1,49:18.13
-11,2,49:18.5
-10,2,49:18.5
-7,2,49:18.5
-2,2,49:18.13
-1,2,49:18.13
3,2,49:18.13
-12,3,49:18.5
-7,3,49:18.5
-6,3,49:18.13
-5,3,49:18.13
-2,3,49:18.13
-1,3,49:17.12
0,3,49:18.13
1,3,49:17.12
2,3,49:18.13
5,3,49:18.13
-7,4,49:18.5
-5,4,49:18.13
-4,4,49:18.13
-3,4,49:18.13
-1,4,49:17.12
1,4,49:18.13
2,4,49:18.13
5,4,49:18.13
-7,5,49:18.5
-4,5,49:18.13
-3,5,49:18.13
-2,5,49:18.13
-1,5,49:17.12
0,5,49:17.12
1,5,49:17.12
2,5,49:18.13
3,5,49:18.13
4,5,49:18.13
5,5,49:18.13
-5,6,49:18.13
-4,6,49:18.13
-2,6,49:18.13
-1,6,49:18.13
0,6,49:18.13
4,6,49:18.13
5,6,49:18.13
8,6,49:18.5
9,6,49:18.5
-6,7,49:18.13
-5,7,49:18.13
-1,7,49:18.13
0,7,49:18.13
5,7,49:18.13
7,7,49:18.5
8,7,49:18.5
-2,8,49:18.13
-1,8,49:18.13
0,8,49:18.13
1,8,49:18.13
3,8,49:18.13
4,8,49:18.13
5,8,49:18.13
6,8,49:18.5
-2,9,49:18.13
1,9,49:18.13
2,9,49:18.13
3,9,49:18.13
5,9,49:18.13
-2,10,49:18.5
-1,10,49:18.5
4,10,49:18.5
5,10,49:18.5
4,11,49:18.5
4,12,49:18.5
4,13,49:18.5
-6,-4,50:18.5
-6,-3,50:18.5
-7,-2,50:18.5
-6,-2,50:18.5
-2,-2,50:18.5
-1,-2,50:18.5
0,-2,50:18.5
-7,-1,50:18.5
-5,-1,50:18.13
-4,-1,50:18.13
-3,-1,50:18.13
-2,-1,50:18.13
0,-1,50:18.13
1,-1,50:18.13
-8,0,50:18.5
-7,0,50:18.5
-6,0,50:18.13
-5,0,50:18.13
-4,0,50:18.13
-3,0,50:18.13
0,0,50:18.13
-10,1,50:18.5
-9,1,50:18.5
-8,1,50:18.5
-7,1,50:18.5
-3,1,50:18.13
-2,1,50:18.13
-1,1,50:18.13
0,1,50:18.13
3,1,50:18.13
4,1,50:18.13
-11,2,50:18.5
-10,2,50:18.5
-7,2,50:18.5
-2,2,50:18.13
-1,2,50:18.13
2,2,50:18.13
3,2,50:18.13
-12,3,50:18.5
-11,3,50:18.5
-7,3,50:18.5
-6,3,50:18.13
-5,3,50:18.13
-2,3,50:18.13
-1,3,50:17.12
0,3,50:18.13
1,3,50:17.12
2,3,50:18.13
5,3,50:18.13
-7,4,50:18.5
-4,4,50:18.13
-3,4,50:18.13
-2,4,50:18.13
-1,4,50:17.12
0,4,50:18.13
1,4,50:18.13
2,4,50:18.13
5,4,50:18.13
-7,5,50:18.5
-4,5,50:18.13
-3,5,50:18.13
-2,5,50:18.13
-1,5,50:17.12
0,5,50:18.13
1,5,50:17.12
2,5,50:18.13
3,5,50:18.13
4,5,50:18.13
5,5,50:18.13
-5,6,50:18.13
-4,6,50:18.13
-2,6,50:18.13
-1,6,50:18.13
0,6,50:18.13
4,6,50:18.13
5,6,50:18.13
8,6,50:18.5
9,6,50:18.5
-5,7,50:18.13
-1,7,50:18.13
0,7,50:18.13
4,7,50:18.13
6,7,50:18.5
7,7,50:18.5
-6,8,50:18.13
-2,8,50:18.13
-1,8,50:18.13
1,8,50:18.13
2,8,50:18.13
3,8,50:18.13
4,8,50:18.13
5,8,50:18.13
6,8,50:18.5
-2,9,50:18.13
0,9,50:18.13
1,9,50:18.13
2,9,50:18.13
3,9,50:18.13
5,9,50:18.13
-3,10,50:18.5
-2,10,50:18.5
-1,10,50:18.5
4,10,50:18.5
4,11,50:18.5
4,12,50:18.5
-6,-4,51:18.5
-6,-3,51:18.5
-6,-2,51:18.5
-1,-2,51:18.5
0,-2,51:18.5
-7,-1,51:18.5
-4,-1,51:18.13
-3,-1,51:18.13
-2,-1,51:18.13
1,-1,51:18.13
-8,0,51:18.5
-7,0,51:18.5
-6,0,51:18.13
-5,0,51:18.13
-4,0,51:18.13
-3,0,51:18.13
0,0,51:18.13
-9,1,51:18.5
-8,1,51:18.5
-6,1,51:18.13
-3,1,51:18.13
-2,1,51:18.13
0,1,51:18.13
-11,2,51:18.5
-10,2,51:18.5
-6,2,51:18.13
-2,2,51:18.13
-1,2,51:18.13
2,2,51:18.13
3,2,51:18.13
-11,3,51:18.5
-7,3,51:18.5
-6,3,51:18.13
-5,3,51:18.13
-4,3,51:18.13
-2,3,51:18.13
-1,3,51:17.12
0,3,51:18.13
1,3,51:17.12
2,3,51:18.13
4,3,51:18.13
5,3,51:18.13
-7,4,51:18.5
-6,4,51:18.13
-4,4,51:18.13
-3,4,51:18.13
-2,4,51:18.13
-1,4,51:17.12
0,4,51:18.13
1,4,51:18.13
4,4,51:18.13
-7,5,51:18.5
-3,5,51:18.13
-2,5,51:18.13
-1,5,51:17.12
0,5,51:18.13
1,5,51:17.12
2,5,51:18.13
3,5,51:18.13
4,5,51:18.13
-4,6,51:18.13
-1,6,51:18.13
0,6,51:18.13
3,6,51:18.13
4,6,51:18.13
8,6,51:18.5
9,6,51:18.5
-5,7,51:18.13
-1,7,51:18.13
0,7,51:18.13
1,7,51:18.13
4,7,51:18.13
6,7,51:18.5
7,7,51:18.5
-2,8,51:18.13
1,8,51:18.13
2,8,51:18.13
3,8,51:18.13
4,8,51:18.13
5,8,51:18.13
6,8,51:18.5
-2,9,51:18.13
-1,9,51:18.13
0,9,51:18.13
1,9,51:18.13
2,9,51:18.13
4,9,51:18.13
-3,10,51:18.5
-2,10,51:18.5
-1,10,51:18.5
4,10,51:18.5
-5,11,51:18.5
-4,11,51:18.5
4,11,51:18.5
4,12,51:18.5
-6,-3,52:18.5
-6,-2,52:18.5
-1,-2,52:18.5
0,-2,52:18.5
1,-2,52:18.5
2,-2,52:18.5
-6,-1,52:18.5
-3,-1,52:18.13
-2,-1,52:18.13
-1,-1,52:18.13
-6,0,52:18.5
-5,0,52:18.13
-4,0,52:18.13
0,0,52:18.13
1,0,52:18.13
-9,1,52:18.5
-8,1,52:18.5
-7,1,52:18.5
-6,1,52:18.5
-3,1,52:18.13
0,1,52:18.13
-10,2,52:18.5
-9,2,52:18.5
-6,2,52:18.5
-2,2,52:18.13
-1,2,52:18.13
0,2,52:18.13
2,2,52:18.13
-11,3,52:18.5
-6,3,52:18.5
-5,3,52:18.13
-4,3,52:18.13
-1,3,52:18.13
0,3,52:17.12
1,3,52:17.12
2,3,52:18.13
4,3,52:18.13
-6,4,52:18.5
-4,4,52:18.13
-3,4,52:18.13
-2,4,52:18.13
-1,4,52:17.12
0,4,52:18.13
1,4,52:18.13
4,4,52:18.13
-6,5,52:18.5
-3,5,52:18.13
-2,5,52:18.13
-1,5,52:17.12
0,5,52:18.13
1,5,52:17.12
2,5,52:18.13
3,5,52:18.13
4,5,52:18.13
-6,6,52:18.5
-4,6,52:18.13
-3,6,52:18.13
-1,6,52:18.13
0,6,52:18.13
3,6,52:18.13
4,6,52:18.13
7,6,52:18.5
8,6,52:18.5
-4,7,52:18.13
-1,7,52:18.13
0,7,52:18.13
1,7,52:18.13
4,7,52:18.13
6,7,52:18.5
7,7,52:18.5
-7,8,52:18.5
-6,8,52:18.5
-2,8,52:18.13
1,8,52:18.13
2,8,52:18.13
3,8,52:18.13
4,8,52:18.13
5,8,52:18.13
6,8,52:18.5
-2,9,52:18.13
-1,9,52:18.13
0,9,52:18.13
1,9,52:18.13
2,9,52:18.13
4,9,52:18.13
-4,10,52:18.5
-3,10,52:18.5
-2,10,52:18.5
4,10,52:18.5
-6,11,52:18.5
-5,11,52:18.5
-5,13,52:18.5
-5,14,52:18.5
-4,15,52:18.5
1,-7,53:18.5
2,-7,53:18.5
2,-6,53:18.5
3,-5,53:18.5
3,-3,53:18.5
4,-3,53:18.5
-6,-2,53:18.5
0,-2,53:18.5
1,-2,53:18.5
2,-2,53:18.5
8,-2,53:18.5
9,-2,53:18.5
-6,-1,53:18.5
-2,-1,53:18.13
-1,-1,53:18.13
0,-1,53:18.13
10,-1,53:18.5
-6,0,53:18.5
-5,0,53:18.13
-4,0,53:18.13
-3,0,53:18.13
4,0,53:18.13
-8,1,53:18.5
-7,1,53:18.5
-6,1,53:18.5
-3,1,53:18.13
0,1,53:18.13
-10,2,53:18.5
-9,2,53:18.5
-6,2,53:18.5
-2,2,53:18.13
0,2,53:18.13
4,2,53:18.13
-10,3,53:18.5
-6,3,53:18.5
-4,3,53:18.13
-1,3,53:18.13
0,3,53:17.12
1,3,53:18.13
2,3,53:18.13
4,3,53:18.13
-6,4,53:18.5
-3,4,53:18.13
-2,4,53:18.13
-1,4,53:18.13
0,4,53:18.13
1,4,53:17.12
4,4,53:18.13
-6,5,53:18.5
-3,5,53:18.13
-2,5,53:18.13
-1,5,53:18.13
0,5,53:18.13
1,5,53:18.13
2,5,53:18.13
4,5,53:18.13
-6,6,53:18.5
-3,6,53:18.13
-1,6,53:18.13
0,6,53:18.13
4,6,53:18.13
7,6,53:18.5
8,6,53:18.5
-6,7,53:18.5
-2,7,53:18.13
-1,7,53:18.13
1,7,53:18.13
4,7,53:18.13
5,7,53:18.13
6,7,53:18.5
7,7,53:18.5
-6,8,53:18.5
-2,8,53:18.13
1,8,53:18.13
2,8,53:18.13
3,8,53:18.13
4,8,53:18.13
5,8,53:18.13
-6,9,53:18.5
-2,9,53:18.13
-1,9,53:18.13
0,9,53:18.13
1,9,53:18.13
4,9,53:18.13
-12,10,53:18.5
-11,10,53:18.5
-10,10,53:18.5
-9,10,53:18.5
-5,10,53:18.5
-4,10,53:18.5
-3,10,53:18.5
-2,10,53:18.5
4,10,53:18.5
-6,11,53:18.5
-5,11,53:18.5
4,11,53:18.5
-6,12,53:18.5
-5,13,53:18.5
-5,14,53:18.5
-4,14,53:18.5
-4,15,53:18.5
1,-7,54:18.5
2,-7,54:18.5
2,-6,54:18.5
3,-5,54:18.5
3,-4,54:18.5
-5,-3,54:18.5
4,-3,54:18.5
-6,-2,54:18.5
1,-2,54:18.5
2,-2,54:18.5
3,-2,54:18.5
7,-2,54:18.5
8,-2,54:18.5
9,-2,54:18.5
-6,-1,54:18.5
-2,-1,54:18.13
-1,-1,54:18.13
0,-1,54:18.13
4,-1,54:18.13
9,-1,54:18.5
10,-1,54:18.5
-6,0,54:18.5
-4,0,54:18.13
-3,0,54:18.13
-2,0,54:18.13
4,0,54:18.13
-8,1,54:18.5
-7,1,54:18.5
-6,1,54:18.5
-5,1,54:18.13
0,1,54:18.13
4,1,54:18.13
-10,2,54:18.5
-9,2,54:18.5
-6,2,54:18.5
-2,2,54:18.13
0,2,54:18.13
4,2,54:18.13
-10,3,54:18.5
-6,3,54:18.5
-4,3,54:18.13
-3,3,54:18.13
-2,3,54:18.13
-1,3,54:18.13
0,3,54:17.0
1,3,54:18.13
4,3,54:18.13
-6,4,54:18.5
-3,4,54:18.13
-2,4,54:18.13
-1,4,54:18.13
0,4,54:18.13
1,4,54:17.0
4,4,54:18.13
-6,5,54:18.5
-2,5,54:18.13
-1,5,54:18.13
0,5,54:18.13
1,5,54:18.13
2,5,54:18.13
4,5,54:18.13
-6,6,54:18.5
-3,6,54:18.13
-1,6,54:18.13
0,6,54:18.13
1,6,54:18.13
4,6,54:18.13
7,6,54:18.5
8,6,54:18.5
-6,7,54:18.5
-2,7,54:18.13
-1,7,54:18.13
4,7,54:18.13
5,7,54:18.13
6,7,54:18.5
7,7,54:18.5
-6,8,54:18.5
-2,8,54:18.13
1,8,54:18.13
2,8,54:18.13
3,8,54:18.13
4,8,54:18.13
-12,9,54:18.5
-6,9,54:18.5
-2,9,54:18.13
-1,9,54:18.13
0,9,54:18.13
4,9,54:18.13
-12,10,54:18.5
-11,10,54:18.5
-10,10,54:18.5
-9,10,54:18.5
-8,10,54:18.5
-6,10,54:18.5
-5,10,54:18.5
-4,10,54:18.5
-3,10,54:18.5
4,10,54:18.5
-6,11,54:18.5
4,11,54:18.5
-6,12,54:18.5
-5,12,54:18.5
3,12,54:18.5
-5,13,54:18.5
-4,14,54:18.5
-4,15,54:18.5
-3,15,54:18.5
1,-7,55:18.5
2,-6,55:18.5
2,-5,55:18.5
3,-5,55:18.5
-5,-4,55:18.5
3,-4,55:18.5
4,-4,55:18.5
-5,-3,55:18.5
4,-3,55:18.5
-6,-2,55:18.5
-5,-2,55:18.5
2,-2,55:18.5
3,-2,55:18.5
4,-2,55:18.5
6,-2,55:18.5
7,-2,55:18.5
8,-2,55:18.5
-6,-1,55:18.5
-1,-1,55:18.13
0,-1,55:18.13
1,-1,55:18.13
4,-1,55:18.13
8,-1,55:18.5
9,-1,55:18.5
-6,0,55:18.5
-4,0,55:18.13
-3,0,55:18.13
-2,0,55:18.13
4,0,55:18.13
-8,1,55:18.5
-7,1,55:18.5
-6,1,55:18.5
-5,1,55:18.13
-4,1,55:18.13
4,1,55:18.13
-9,2,55:18.5
-8,2,55:18.5
-5,2,55:18.13
0,2,55:18.13
4,2,55:18.13
-6,3,55:18.5
-5,3,55:18.13
-2,3,55:18.13
-1,3,55:17.0
0,3,55:18.13
1,3,55:17.0
4,3,55:18.13
-6,4,55:18.5
-5,4,55:18.13
-3,4,55:18.13
-2,4,55:18.13
-1,4,55:18.13
0,4,55:18.13
1,4,55:17.0
4,4,55:18.13
-6,5,55:18.5
-5,5,55:18.13
-2,5,55:18.13
-1,5,55:18.13
0,5,55:18.13
1,5,55:18.13
4,5,55:18.13
-6,6,55:18.5
-1,6,55:18.13
0,6,55:18.13
4,6,55:18.13
7,6,55:18.5
-6,7,55:18.5
-2,7,55:18.13
3,7,55:18.13
4,7,55:18.13
5,7,55:18.13
6,7,55:18.5
-6,8,55:18.5
0,8,55:18.13
1,8,55:18.13
2,8,55:18.13
3,8,55:18.13
4,8,55:18.13
-11,9,55:18.5
-6,9,55:18.5
-3,9,55:18.13
-2,9,55:18.13
-1,9,55:18.13
0,9,55:18.13
4,9,55:18.13
-11,10,55:18.5
-10,10,55:18.5
-9,10,55:18.5
-8,10,55:18.5
-7,10,55:18.5
-6,10,55:18.5
-5,10,55:18.5
-4,10,55:18.5
-3,10,55:18.5
4,10,55:18.5
-6,11,55:18.5
3,11,55:18.5
4,11,55:18.5
-5,12,55:18.5
3,12,55:18.5
-5,13,55:18.5
-4,13,55:18.5
-4,14,55:18.5
-3,15,55:18.5
1,-6,56:18.5
2,-6,56:18.5
2,-5,56:18.5
3,-5,56:18.5
3,-4,56:18.5
-5,-3,56:18.5
4,-3,56:18.5
-5,-2,56:18.5
2,-2,56:18.5
3,-2,56:18.5
4,-2,56:18.5
5,-2,56:18.5
6,-2,56:18.5
7,-2,56:18.5
-6,-1,56:18.5
-5,-1,56:18.5
0,-1,56:18.13
1,-1,56:18.13
2,-1,56:18.13
4,-1,56:18.13
8,-1,56:18.5
-5,0,56:18.13
-3,0,56:18.13
-2,0,56:18.13
-1,0,56:18.13
4,0,56:18.13
-7,1,56:18.5
-6,1,56:18.5
-5,1,56:18.13
-4,1,56:18.13
4,1,56:18.13
-9,2,56:18.5
-8,2,56:18.5
-5,2,56:18.13
4,2,56:18.13
-5,3,56:18.13
-1,3,56:17.0
0,3,56:17.0
1,3,56:17.0
4,3,56:18.13
-5,4,56:18.13
-1,4,56:18.13
0,4,56:18.13
1,4,56:17.0
4,4,56:18.13
-5,5,56:18.13
-1,5,56:18.13
0,5,56:17.0
1,5,56:17.0
4,5,56:18.13
-5,6,56:18.13
3,6,56:18.13
4,6,56:18.13
7,6,56:18.5
-5,7,56:18.13
3,7,56:18.13
4,7,56:18.13
5,7,56:18.13
6,7,56:18.5
-6,8,56:18.5
-5,8,56:18.13
0,8,56:18.13
1,8,56:18.13
2,8,56:18.13
3,8,56:18.13
4,8,56:18.13
-6,9,56:18.5
-5,9,56:18.13
-3,9,56:18.13
-2,9,56:18.13
-1,9,56:18.13
4,9,56:18.13
-10,10,56:18.5
-9,10,56:18.5
-8,10,56:18.5
-7,10,56:18.5
-6,10,56:18.5
-5,10,56:18.5
-4,10,56:18.5
4,10,56:18.5
-6,11,56:18.5
-5,11,56:18.5
3,11,56:18.5
-5,12,56:18.5
3,12,56:18.5
-4,13,56:18.5
-4,14,56:18.5
-3,14,56:18.5
-3,15,56:18.5
1,-6,57:18.5
2,-6,57:18.5
2,-5,57:18.5
3,-4,57:18.5
-5,-3,57:18.5
3,-3,57:18.5
4,-3,57:18.5
-5,-2,57:18.5
3,-2,57:18.5
4,-2,57:18.5
5,-2,57:18.5
6,-2,57:18.5
-5,-1,57:18.5
0,-1,57:18.13
1,-1,57:18.13
2,-1,57:18.13
4,-1,57:18.13
7,-1,57:18.5
8,-1,57:18.5
-5,0,57:18.5
-2,0,57:18.13
-1,0,57:18.13
0,0,57:18.13
4,0,57:18.13
-7,1,57:18.5
-6,1,57:18.5
-5,1,57:18.5
-4,1,57:18.13
-3,1,57:18.13
4,1,57:18.13
-9,2,57:18.5
-8,2,57:18.5
-7,2,57:18.5
-5,2,57:18.5
4,2,57:18.13
-5,3,57:18.5
-1,3,57:17.0
0,3,57:17.0
1,3,57:17.0
4,3,57:18.13
-5,4,57:18.5
-1,4,57:17.0
1,4,57:17.0
3,4,57:18.13
4,4,57:18.13
-5,5,57:18.5
-1,5,57:17.0
0,5,57:17.0
1,5,57:17.0
3,5,57:18.13
-5,6,57:18.5
3,6,57:18.13
7,6,57:18.5
-5,7,57:18.5
2,7,57:18.13
3,7,57:18.13
4,7,57:18.13
5,7,57:18.13
6,7,57:18.5
-5,8,57:18.5
-1,8,57:18.13
0,8,57:18.13
1,8,57:18.13
2,8,57:18.13
3,8,57:18.13
4,8,57:18.13
-10,9,57:18.5
-5,9,57:18.5
-4,9,57:18.5
-3,9,57:18.5
-2,9,57:18.5
-1,9,57:18.5
4,9,57:18.5
-9,10,57:18.5
-8,10,57:18.5
-7,10,57:18.5
-6,10,57:18.5
-5,10,57:18.5
-4,10,57:18.5
4,10,57:18.5
-5,11,57:18.5
3,11,57:18.5
-5,12,57:18.5
-4,12,57:18.5
3,12,57:18.5
-4,13,57:18.5
-3,14,57:18.5
-3,15,57:18.5
1,-6,58:18.5
2,-5,58:18.5
2,-4,58:18.5
3,-4,58:18.5
-5,-3,58:18.5
-4,-3,58:18.5
3,-3,58:18.5
4,-3,58:18.5
-5,-2,58:18.5
4,-2,58:18.5
5,-2,58:18.5
6,-2,58:18.5
-5,-1,58:18.5
1,-1,58:18.5
2,-1,58:18.5
3,-1,58:18.5
4,-1,58:18.5
6,-1,58:18.5
7,-1,58:18.5
8,-1,58:18.5
-5,0,58:18.5
-2,0,58:18.5
-1,0,58:18.5
0,0,58:18.5
4,0,58:18.5
-5,1,58:18.5
-4,1,58:18.5
-3,1,58:18.5
-2,1,58:18.5
3,1,58:18.5
4,1,58:18.5
-8,2,58:18.5
-7,2,58:18.5
-6,2,58:18.5
-5,2,58:18.5
3,2,58:18.5
4,2,58:18.5
-5,3,58:18.5
-1,3,58:17.0
0,3,58:17.0
1,3,58:17.0
-5,4,58:18.5
-1,4,58:17.0
1,4,58:17.0
3,4,58:18.5
-5,5,58:18.5
-1,5,58:17.0
0,5,58:17.0
1,5,58:17.0
3,5,58:18.5
-5,6,58:18.5
3,6,58:18.5
-5,7,58:18.5
2,7,58:18.5
3,7,58:18.5
4,7,58:18.5
5,7,58:18.5
6,7,58:18.5
-5,8,58:18.5
-1,8,58:18.5
0,8,58:18.5
1,8,58:18.5
3,8,58:18.5
-10,9,58:18.5
-9,9,58:18.5
-5,9,58:18.5
-4,9,58:18.5
-3,9,58:18.5
-2,9,58:18.5
4,9,58:18.5
-8,10,58:18.5
-7,10,58:18.5
-6,10,58:18.5
-5,10,58:18.5
3,10,58:18.5
4,10,58:18.5
-5,11,58:18.5
3,11,58:18.5
-5,12,58:18.5
-4,12,58:18.5
3,12,58:18.5
-4,13,58:18.5
-3,13,58:18.5
-3,14,58:18.5
1,-5,59:18.5
2,-5,59:18.5
2,-4,59:18.5
3,-4,59:18.5
3,-3,59:18.5
-5,-2,59:18.5
3,-2,59:18.5
4,-2,59:18.5
5,-2,59:18.5
-5,-1,59:18.5
2,-1,59:18.5
3,-1,59:18.5
4,-1,59:18.5
5,-1,59:18.5
6,-1,59:18.5
7,-1,59:18.5
-5,0,59:18.5
-1,0,59:18.5
0,0,59:18.5
1,0,59:18.5
3,0,59:18.5
-5,1,59:18.5
-4,1,59:18.5
-3,1,59:18.5
-2,1,59:18.5
-1,1,59:18.5
3,1,59:18.5
-7,2,59:18.5
-6,2,59:18.5
-5,2,59:18.5
-4,2,59:18.5
3,2,59:18.5
-4,3,59:18.5
-1,3,59:17.0
0,3,59:17.0
1,3,59:17.0
-5,4,59:18.5
-4,4,59:18.5
-1,4,59:17.0
1,4,59:17.0
3,4,59:18.5
-5,5,59:18.5
-4,5,59:18.5
-1,5,59:17.0
0,5,59:17.0
1,5,59:17.0
3,5,59:18.5
-5,6,59:18.5
3,6,59:18.5
6,6,59:18.5
-5,7,59:18.5
1,7,59:18.5
2,7,59:18.5
3,7,59:18.5
4,7,59:18.5
5,7,59:18.5
6,7,59:18.5
-5,8,59:18.5
-2,8,59:18.5
-1,8,59:18.5
0,8,59:18.5
1,8,59:18.5
3,8,59:18.5
-9,9,59:18.5
-8,9,59:18.5
-5,9,59:18.5
-4,9,59:18.5
-3,9,59:18.5
-2,9,59:18.5
3,9,59:18.5
4,9,59:18.5
-8,10,59:18.5
-7,10,59:18.5
-6,10,59:18.5
-5,10,59:18.5
3,10,59:18.5
-5,11,59:18.5
-4,11,59:18.5
-4,12,59:18.5
-4,13,59:18.5
-3,13,59:18.5
-3,14,59:18.5
1,-5,60:18.5
2,-5,60:18.5
2,-4,60:18.5
3,-3,60:18.5
3,-2,60:18.5
-5,-1,60:18.5
2,-1,60:18.5
3,-1,60:18.5
4,-1,60:18.5
5,-1,60:18.5
6,-1,60:18.5
-5,0,60:18.5
-4,0,60:18.5
0,0,60:18.5
1,0,60:18.5
2,0,60:18.5
3,0,60:18.5
-4,1,60:18.5
-3,1,60:18.5
-2,1,60:18.5
-1,1,60:18.5
3,1,60:18.5
-7,2,60:18.5
-6,2,60:18.5
-5,2,60:18.5
-4,2,60:18.5
-3,2,60:18.5
3,2,60:18.5
-4,3,60:18.5
-1,3,60:17.0
0,3,60:17.0
1,3,60:17.0
-4,4,60:18.5
-1,4,60:17.0
1,4,60:17.0
3,4,60:18.5
-4,5,60:18.5
-1,5,60:17.0
0,5,60:17.0
1,5,60:17.0
3,5,60:18.5
-4,6,60:18.5
3,6,60:18.5
-4,7,60:18.5
1,7,60:18.5
2,7,60:18.5
3,7,60:18.5
4,7,60:18.5
5,7,60:18.5
-5,8,60:18.5
-4,8,60:18.5
-2,8,60:18.5
-1,8,60:18.5
0,8,60:18.5
3,8,60:18.5
-8,9,60:18.5
-5,9,60:18.5
-4,9,60:18.5
-3,9,60:18.5
3,9,60:18.5
-7,10,60:18.5
-6,10,60:18.5
-5,10,60:18.5
-4,10,60:18.5
3,10,60:18.5
-4,11,60:18.5
-4,12,60:18.5
-3,12,60:18.5
-3,13,60:18.5
1,-5,61:18.5
2,-4,61:18.5
2,-3,61:18.5
3,-3,61:18.5
-4,-2,61:18.5
3,-2,61:18.5
-5,-1,61:18.5
-4,-1,61:18.5
3,-1,61:18.5
4,-1,61:18.5
5,-1,61:18.5
6,-1,61:18.5
-4,0,61:18.5
0,0,61:18.5
1,0,61:18.5
2,0,61:18.5
3,0,61:18.5
7,0,61:18.5
-4,1,61:18.5
-2,1,61:18.5
-1,1,61:18.5
0,1,61:18.5
3,1,61:18.5
-7,2,61:18.5
-6,2,61:18.5
-5,2,61:18.5
-4,2,61:18.5
-3,2,61:18.5
3,2,61:18.5
-4,3,61:18.5
-1,3,61:17.0
0,3,61:17.0
1,3,61:17.0
-4,4,61:18.5
-1,4,61:17.0
1,4,61:17.0
3,4,61:18.5
-4,5,61:18.5
-1,5,61:17.0
0,5,61:17.0
1,5,61:17.0
3,5,61:18.5
-4,6,61:18.5
3,6,61:18.5
5,6,61:18.5
-4,7,61:18.5
0,7,61:18.5
1,7,61:18.5
2,7,61:18.5
3,7,61:18.5
4,7,61:18.5
5,7,61:18.5
-4,8,61:18.5
-3,8,61:18.5
-2,8,61:18.5
-1,8,61:18.5
0,8,61:18.5
3,8,61:18.5
-9,9,61:18.5
-8,9,61:18.5
-7,9,61:18.5
-6,9,61:18.5
-5,9,61:18.5
-4,9,61:18.5
-3,9,61:18.5
3,9,61:18.5
-4,10,61:18.5
3,10,61:18.5
-4,11,61:18.5
-4,12,61:18.5
-3,12,61:18.5
-3,13,61:18.5
2,-4,62:18.5
2,-3,62:18.5
3,-3,62:18.5
3,-2,62:18.5
-4,-1,62:18.5
3,-1,62:18.5
4,-1,62:18.5
5,-1,62:18.5
6,-1,62:18.5
-4,0,62:18.5
1,0,62:18.5
2,0,62:18.5
3,0,62:18.5
4,0,62:18.5
6,0,62:18.5
7,0,62:18.5
-4,1,62:18.5
-2,1,62:18.5
-1,1,62:18.5
0,1,62:18.5
1,1,62:18.5
3,1,62:18.5
-6,2,62:18.5
-5,2,62:18.5
-4,2,62:18.5
-3,2,62:18.5
-2,2,62:18.5
3,2,62:18.5
-4,3,62:18.5
-1,3,62:17.0
0,3,62:17.0
1,3,62:17.0
-4,4,62:18.5
-1,4,62:17.0
1,4,62:17.0
3,4,62:18.5
-4,5,62:18.5
-1,5,62:17.0
0,5,62:17.0
1,5,62:17.0
3,5,62:18.5
-4,6,62:18.5
2,6,62:18.5
3,6,62:18.5
4,6,62:18.5
5,6,62:18.5
-4,7,62:18.5
0,7,62:18.5
1,7,62:18.5
2,7,62:18.5
3,7,62:18.5
-4,8,62:18.5
-3,8,62:18.5
-2,8,62:18.5
-1,8,62:18.5
3,8,62:18.5
-9,9,62:18.5
-8,9,62:18.5
-7,9,62:18.5
-6,9,62:18.5
-5,9,62:18.5
-4,9,62:18.5
3,9,62:18.5
-4,10,62:18.5
3,10,62:18.5
-4,11,62:18.5
-3,12,62:18.5
2,-3,63:18.5
3,-2,63:18.5
-4,-1,63:18.5
3,-1,63:18.5
5,-1,63:18.5
-4,0,63:18.5
2,0,63:18.5
3,0,63:18.5
4,0,63:18.5
5,0,63:18.5
6,0,63:18.5
7,0,63:18.5
8,0,63:18.5
-4,1,63:18.5
-1,1,63:18.5
0,1,63:18.5
1,1,63:18.5
3,1,63:18.5
-6,2,63:18.5
-5,2,63:18.5
-4,2,63:18.5
-3,2,63:18.5
-2,2,63:18.5
-1,2,63:18.5
3,2,63:18.5
-6,3,63:18.5
-3,3,63:18.5
-1,3,63:17.0
0,3,63:17.0
1,3,63:17.0
-4,4,63:18.5
-3,4,63:18.5
-1,4,63:17.0
1,4,63:17.0
2,4,63:18.5
3,4,63:18.5
-4,5,63:18.5
-3,5,63:18.5
-1,5,63:17.0
0,5,63:17.0
1,5,63:17.0
2,5,63:18.5
-4,6,63:18.5
-3,6,63:18.5
2,6,63:18.5
3,6,63:18.5
4,6,63:18.5
5,6,63:18.5
-4,7,63:18.5
-1,7,63:18.5
0,7,63:18.5
1,7,63:18.5
2,7,63:18.5
3,7,63:18.5
-9,8,63:18.5
-4,8,63:18.5
-3,8,63:18.5
-2,8,63:18.5
-1,8,63:18.5
3,8,63:18.5
-8,9,63:18.5
-7,9,63:18.5
-6,9,63:18.5
-5,9,63:18.5
-4,9,63:18.5
3,9,63:18.5
-4,10,63:18.5
-4,11,63:18.5
-3,11,63:18.5
-3,12,63:18.5
2,-3,64:18.5
2,-2,64:18.5
3,-2,64:18.5
3,-1,64:18.5
-4,0,64:18.5
2,0,64:18.5
3,0,64:18.5
4,0,64:18.5
5,0,64:18.5
6,0,64:18.5
7,0,64:18.5
-4,1,64:18.5
-3,1,64:18.5
0,1,64:18.5
1,1,64:18.5
2,1,64:18.5
3,1,64:18.5
-3,2,64:18.5
-2,2,64:18.5
-1,2,64:18.5
2,2,64:18.5
3,2,64:18.5
-6,3,64:18.5
-5,3,64:18.5
-4,3,64:18.5
-3,3,64:18.5
-1,3,64:17.0
0,3,64:17.0
1,3,64:17.0
2,3,64:18.5
-3,4,64:18.5
-1,4,64:17.0
1,4,64:17.0
2,4,64:18.5
-3,5,64:18.5
-1,5,64:17.0
0,5,64:17.0
1,5,64:17.0
2,5,64:18.5
-3,6,64:18.5
2,6,64:18.5
3,6,64:18.5
4,6,64:18.5
5,6,64:18.5
-3,7,64:18.5
-1,7,64:18.5
0,7,64:18.5
1,7,64:18.5
2,7,64:18.5
-8,8,64:18.5
-4,8,64:18.5
-3,8,64:18.5
-2,8,64:18.5
3,8,64:18.5
-8,9,64:18.5
-7,9,64:18.5
-6,9,64:18.5
-5,9,64:18.5
-3,9,64:18.5
3,9,64:18.5
-3,10,64:18.5
-3,11,64:18.5
2,-2,65:18.5
2,-1,65:18.5
-4,0,65:18.5
-3,0,65:18.5
2,0,65:18.5
3,0,65:18.5
4,0,65:18.5
5,0,65:18.5
6,0,65:18.5
-3,1,65:18.5
0,1,65:18.5
1,1,65:18.5
2,1,65:18.5
3,1,65:18.5
-3,2,65:18.5
-2,2,65:18.5
-1,2,65:18.5
0,2,65:18.5
2,2,65:18.5
-6,3,65:18.5
-5,3,65:18.5
-4,3,65:18.5
-3,3,65:18.5
-1,3,65:17.0
0,3,65:17.0
1,3,65:17.0
2,3,65:18.5
-3,4,65:18.5
-1,4,65:17.0
1,4,65:17.0
2,4,65:18.5
-3,5,65:18.5
-1,5,65:17.0
0,5,65:17.0
1,5,65:17.0
2,5,65:18.5
-3,6,65:18.5
1,6,65:18.5
2,6,65:18.5
3,6,65:18.5
4,6,65:18.5
5,6,65:18.5
-3,7,65:18.5
-2,7,65:18.5
-1,7,65:18.5
0,7,65:18.5
1,7,65:18.5
2,7,65:18.5
-5,8,65:18.5
-4,8,65:18.5
-3,8,65:18.5
-2,8,65:18.5
2,8,65:18.5
3,8,65:18.5
-7,9,65:18.5
-6,9,65:18.5
-5,9,65:18.5
-3,9,65:18.5
3,9,65:18.5
-3,10,65:18.5
-3,11,65:18.5
2,-2,66:18.5
2,-1,66:18.5
-3,0,66:18.5
2,0,66:18.5
4,0,66:18.5
5,0,66:18.5
6,0,66:18.5
-3,1,66:18.5
1,1,66:18.5
2,1,66:18.5
3,1,66:18.5
4,1,66:18.5
6,1,66:18.5
-3,2,66:18.5
-1,2,66:18.5
0,2,66:18.5
1,2,66:18.5
2,2,66:18.5
-6,3,66:18.5
-5,3,66:18.5
-4,3,66:18.5
-3,3,66:18.5
-2,3,66:18.5
-1,3,66:17.0
0,3,66:17.0
1,3,66:17.0
2,3,66:18.5
-3,4,66:18.5
-1,4,66:17.0
1,4,66:17.0
2,4,66:18.5
-3,5,66:18.5
-1,5,66:17.0
0,5,66:17.0
1,5,66:17.0
2,5,66:18.5
-3,6,66:18.5
1,6,66:18.5
2,6,66:18.5
3,6,66:18.5
4,6,66:18.5
5,6,66:18.5
-3,7,66:18.5
-2,7,66:18.5
-1,7,66:18.5
0,7,66:18.5
2,7,66:18.5
-7,8,66:18.5
-6,8,66:18.5
-5,8,66:18.5
-4,8,66:18.5
-3,8,66:18.5
2,8,66:18.5
-6,9,66:18.5
-3,9,66:18.5
3,9,66:18.5
-3,10,66:18.5
2,-1,67:18.5
-3,0,67:18.5
2,0,67:18.5
-3,1,67:18.5
2,1,67:18.5
3,1,67:18.5
4,1,67:18.5
5,1,67:18.5
-3,2,67:18.5
-1,2,67:18.5
0,2,67:18.5
1,2,67:18.5
2,2,67:18.5
-6,3,67:18.5
-5,3,67:18.5
-4,3,67:18.5
-3,3,67:18.5
-2,3,67:18.5
-1,3,67:18.5
0,3,67:17.0
1,3,67:17.0
2,3,67:18.5
-2,4,67:18.5
-1,4,67:17.0
1,4,67:17.0
2,4,67:18.5
-3,5,67:18.5
-2,5,67:18.5
-1,5,67:17.0
0,5,67:17.0
1,5,67:17.0
2,5,67:18.5
-3,6,67:18.5
-2,6,67:18.5
0,6,67:18.5
1,6,67:18.5
2,6,67:18.5
3,6,67:18.5
4,6,67:18.5
5,6,67:18.5
6,6,67:18.5
-3,7,67:18.5
-2,7,67:18.5
-1,7,67:18.5
0,7,67:18.5
2,7,67:18.5
-6,8,67:18.5
-5,8,67:18.5
-4,8,67:18.5
-3,8,67:18.5
2,8,67:18.5
-3,9,67:18.5
-2,9,67:18.5
2,9,67:18.5
-3,10,67:18.5
2,-1,68:18.5
-3,0,68:18.5
2,0,68:18.5
-3,1,68:18.5
2,1,68:18.5
3,1,68:18.5
4,1,68:18.5
5,1,68:18.5
-7,2,68:18.5
-3,2,68:18.5
-2,2,68:18.5
0,2,68:18.5
1,2,68:18.5
2,2,68:18.5
-7,3,68:18.5
-6,3,68:18.5
-5,3,68:18.5
-4,3,68:18.5
-3,3,68:18.5
-2,3,68:18.5
-1,3,68:18.5
0,3,68:17.0
1,3,68:17.0
2,3,68:18.5
4,3,68:18.5
-2,4,68:18.5
-1,4,68:17.0
1,4,68:17.0
2,4,68:18.5
-5,5,68:18.5
-2,5,68:18.5
0,5,68:17.0
1,5,68:17.0
2,5,68:18.5
6,5,68:18.5
-6,6,68:18.5
-2,6,68:18.5
0,6,68:18.5
1,6,68:18.5
2,6,68:18.5
3,6,68:18.5
4,6,68:18.5
5,6,68:18.5
6,6,68:18.5
-6,7,68:18.5
-3,7,68:18.5
-2,7,68:18.5
-1,7,68:18.5
2,7,68:18.5
6,7,68:18.5
-6,8,68:18.5
-5,8,68:18.5
-4,8,68:18.5
-2,8,68:18.5
2,8,68:18.5
-2,9,68:18.5
2,9,68:18.5
-2,10,68:18.5
2,-1,69:18.5
-3,0,69:18.5
2,0,69:18.5
-3,1,69:18.5
-2,1,69:18.5
2,1,69:18.5
4,1,69:18.5
5,1,69:18.5
-7,2,69:18.5
-2,2,69:18.5
1,2,69:18.5
2,2,69:18.5
3,2,69:18.5
-7,3,69:18.5
-6,3,69:18.5
-5,3,69:18.5
-4,3,69:18.5
-3,3,69:18.5
-2,3,69:18.5
-1,3,69:18.5
0,3,69:18.5
1,3,69:17.0
2,3,69:18.5
4,3,69:18.5
5,3,69:18.5
-6,4,69:18.5
-5,4,69:18.5
-4,4,69:18.5
-2,4,69:18.5
-1,4,69:17.0
1,4,69:17.0
2,4,69:18.5
4,4,69:18.5
-5,5,69:18.5
-2,5,69:18.5
0,5,69:17.0
1,5,69:17.0
2,5,69:18.5
4,5,69:18.5
5,5,69:18.5
-6,6,69:18.5
-5,6,69:18.5
-2,6,69:18.5
-1,6,69:18.5
0,6,69:18.5
1,6,69:18.5
2,6,69:18.5
3,6,69:18.5
4,6,69:18.5
6,6,69:18.5
-6,7,69:18.5
-4,7,69:18.5
-3,7,69:18.5
-2,7,69:18.5
-1,7,69:18.5
2,7,69:18.5
6,7,69:18.5
-6,8,69:18.5
-5,8,69:18.5
-4,8,69:18.5
-2,8,69:18.5
2,8,69:18.5
-2,9,69:18.5
2,9,69:18.5
-2,10,69:18.5
1,-1,70:18.5
2,-1,70:18.5
1,0,70:18.5
2,0,70:18.5
-2,1,70:18.5
1,1,70:18.5
2,1,70:18.5
5,1,70:18.5
-7,2,70:18.5
-2,2,70:18.5
1,2,70:18.5
2,2,70:18.5
3,2,70:18.5
4,2,70:18.5
-7,3,70:18.5
-6,3,70:18.5
-2,3,70:18.5
-1,3,70:18.5
0,3,70:18.5
1,3,70:18.5
2,3,70:18.5
4,3,70:18.5
5,3,70:18.5
-6,4,70:18.5
-5,4,70:18.5
-4,4,70:18.5
-3,4,70:18.5
-2,4,70:18.5
-1,4,70:17.0
0,4,70:17.0
1,4,70:17.0
4,4,70:18.5
-5,5,70:18.5
-2,5,70:18.5
0,5,70:17.0
1,5,70:17.0
3,5,70:18.5
4,5,70:18.5
5,5,70:18.5
-5,6,70:18.5
-4,6,70:18.5
-2,6,70:18.5
-1,6,70:18.5
0,6,70:18.5
1,6,70:18.5
2,6,70:18.5
3,6,70:18.5
6,6,70:18.5
-6,7,70:18.5
-5,7,70:18.5
-4,7,70:18.5
-3,7,70:18.5
-2,7,70:18.5
2,7,70:18.5
-6,8,70:18.5
-5,8,70:18.5
-2,8,70:18.5
2,8,70:18.5
-2,9,70:18.5
-2,10,70:18.5
1,-1,71:18.5
1,0,71:18.5
-2,1,71:18.5
1,1,71:18.5
5,1,71:18.5
-3,2,71:18.5
-2,2,71:18.5
1,2,71:18.5
2,2,71:18.5
3,2,71:18.5
4,2,71:18.5
-6,3,71:18.5
-2,3,71:18.5
-1,3,71:18.5
0,3,71:18.5
1,3,71:18.5
2,3,71:18.5
4,3,71:18.5
5,3,71:18.5
-6,4,71:18.5
-4,4,71:18.5
-3,4,71:18.5
-2,4,71:18.5
-1,4,71:18.5
0,4,71:17.0
1,4,71:18.5
4,4,71:18.5
5,4,71:18.5
-5,5,71:18.5
-2,5,71:18.5
-1,5,71:18.5
0,5,71:17.0
1,5,71:18.5
2,5,71:18.5
3,5,71:18.5
4,5,71:18.5
5,5,71:18.5
-5,6,71:18.5
-4,6,71:18.5
-2,6,71:18.5
-1,6,71:18.5
0,6,71:18.5
1,6,71:18.5
5,6,71:18.5
6,6,71:18.5
-6,7,71:18.5
-5,7,71:18.5
-4,7,71:18.5
-3,7,71:18.5
-2,7,71:18.5
-1,7,71:18.5
1,7,71:18.5
2,7,71:18.5
-6,8,71:18.5
-2,8,71:18.5
-1,8,71:18.5
2,8,71:18.5
-2,9,71:18.5
-1,9,71:18.5
-1,10,71:18.5
2,-2,72:18.5
1,-1,72:18.5
1,0,72:18.5
-2,1,72:18.5
1,1,72:18.5
5,1,72:18.5
-3,2,72:18.5
-2,2,72:18.5
1,2,72:18.5
2,2,72:18.5
3,2,72:18.5
4,2,72:18.5
-6,3,72:18.5
-1,3,72:18.5
0,3,72:18.5
1,3,72:18.5
2,3,72:18.5
4,3,72:18.5
5,3,72:18.5
-6,4,72:18.5
-5,4,72:18.5
-4,4,72:18.5
-3,4,72:18.5
-2,4,72:18.5
-1,4,72:18.5
0,4,72:17.0
1,4,72:17.0
4,4,72:18.5
5,4,72:18.5
-5,5,72:18.5
-4,5,72:18.5
-1,5,72:18.5
0,5,72:17.0
1,5,72:18.5
2,5,72:18.5
3,5,72:18.5
4,5,72:18.5
5,5,72:18.5
-5,6,72:18.5
-4,6,72:18.5
-3,6,72:18.5
-2,6,72:18.5
-1,6,72:18.5
0,6,72:18.5
1,6,72:18.5
5,6,72:18.5
6,6,72:18.5
-5,7,72:18.5
-4,7,72:18.5
-3,7,72:18.5
-2,7,72:18.5
-1,7,72:18.5
1,7,72:18.5
2,7,72:18.5
-6,8,72:18.5
-5,8,72:18.5
-1,8,72:18.5
2,8,72:18.5
-1,9,72:18.5
-1,10,72:18.5
3,10,72:18.5
-3,11,72:18.5
-2,11,72:18.5
1,-2,73:18.5
2,-2,73:18.5
-4,-1,73:18.5
-3,-1,73:18.5
-2,1,73:18.5
1,1,73:18.5
5,1,73:18.5
-3,2,73:18.5
-2,2,73:18.5
-1,2,73:18.5
1,2,73:18.5
2,2,73:18.5
-6,3,73:18.5
-3,3,73:18.5
-1,3,73:18.5
1,3,73:18.5
2,3,73:18.5
4,3,73:18.5
-6,4,73:18.5
-5,4,73:18.5
-4,4,73:18.5
-3,4,73:18.5
-2,4,73:18.5
-1,4,73:18.5
0,4,73:17.0
1,4,73:17.0
4,4,73:18.5
5,4,73:18.5
-5,5,73:18.5
-4,5,73:18.5
-1,5,73:18.5
0,5,73:17.0
1,5,73:18.5
2,5,73:18.5
3,5,73:18.5
5,5,73:18.5
-5,6,73:18.5
-4,6,73:18.5
-3,6,73:18.5
-2,6,73:18.5
-1,6,73:18.5
0,6,73:18.5
1,6,73:18.5
3,6,73:18.5
5,6,73:18.5
-5,7,73:18.5
-4,7,73:18.5
-3,7,73:18.5
-2,7,73:18.5
-1,7,73:18.5
1,7,73:18.5
2,7,73:18.5
-5,8,73:18.5
-1,8,73:18.5
1,8,73:18.5
2,8,73:18.5
1,9,73:18.5
2,10,73:18.5
3,10,73:18.5
-3,11,73:18.5
-2,11,73:18.5
-1,11,73:18.5
1,-2,74:18.5
2,-2,74:18.5
-4,-1,74:18.5
-3,-1,74:18.5
-2,-1,74:18.5
1,-1,74:18.5
-1,0,74:18.5
-2,1,74:18.5
0,1,74:18.5
1,1,74:18.5
5,1,74:18.5
-3,2,74:18.5
-2,2,74:18.5
-1,2,74:18.5
1,2,74:18.5
2,2,74:18.5
-6,3,74:18.5
-3,3,74:18.5
-1,3,74:18.5
1,3,74:18.5
2,3,74:18.5
4,3,74:18.5
-5,4,74:18.5
-4,4,74:18.5
-3,4,74:18.5
-2,4,74:18.5
-1,4,74:18.5
0,4,74:17.0
1,4,74:18.5
3,4,74:18.5
4,4,74:18.5
-5,5,74:18.5
-4,5,74:18.5
-1,5,74:18.5
0,5,74:17.0
1,5,74:18.5
2,5,74:18.5
3,5,74:18.5
5,5,74:18.5
-5,6,74:18.5
-4,6,74:18.5
-3,6,74:18.5
-2,6,74:18.5
-1,6,74:18.5
1,6,74:18.5
2,6,74:18.5
3,6,74:18.5
5,6,74:18.5
-5,7,74:18.5
-3,7,74:18.5
-2,7,74:18.5
-1,7,74:18.5
1,7,74:18.5
2,7,74:18.5
-5,8,74:18.5
-1,8,74:18.5
1,8,74:18.5
2,8,74:18.5
1,9,74:18.5
-1,10,74:18.5
1,10,74:18.5
2,10,74:18.5
3,10,74:18.5
-2,11,74:18.5
2,-2,75:18.5
-4,-1,75:18.5
-3,-1,75:18.5
-2,-1,75:18.5
0,-1,75:18.5
1,-1,75:18.5
-1,0,75:18.5
0,0,75:18.5
-2,1,75:18.5
-1,1,75:18.5
0,1,75:18.5
1,1,75:18.5
5,1,75:18.5
-2,2,75:18.5
1,2,75:18.5
2,2,75:18.5
4,2,75:18.5
-3,3,75:18.5
-1,3,75:18.5
1,3,75:18.5
2,3,75:18.5
4,3,75:18.5
-5,4,75:18.5
-4,4,75:18.5
-3,4,75:18.5
-2,4,75:18.5
-1,4,75:18.5
0,4,75:17.0
1,4,75:18.5
2,4,75:18.5
3,4,75:18.5
4,4,75:18.5
-5,5,75:18.5
-4,5,75:18.5
-1,5,75:18.5
0,5,75:18.5
1,5,75:18.5
2,5,75:18.5
3,5,75:18.5
5,5,75:18.5
-5,6,75:18.5
-4,6,75:18.5
-3,6,75:18.5
-2,6,75:18.5
-1,6,75:18.5
0,6,75:18.5
1,6,75:18.5
2,6,75:18.5
3,6,75:18.5
-5,7,75:18.5
-2,7,75:18.5
0,7,75:18.5
2,7,75:18.5
-5,8,75:18.5
-1,8,75:18.5
1,8,75:18.5
0,9,75:18.5
1,9,75:18.5
-1,10,75:18.5
1,10,75:18.5
2,10,75:18.5
3,10,75:18.5
-2,11,75:18.5
-4,-1,76:18.5
-3,-1,76:18.5
0,-1,76:18.5
1,-1,76:18.5
-2,0,76:18.5
-1,0,76:18.5
0,0,76:18.5
-2,1,76:18.5
-1,1,76:18.5
0,1,76:18.5
1,1,76:18.5
5,1,76:18.5
-2,2,76:18.5
1,2,76:18.5
2,2,76:18.5
4,2,76:18.5
-3,3,76:18.5
-2,3,76:18.5
0,3,76:18.5
2,3,76:18.5
4,3,76:18.5
-5,4,76:18.5
-3,4,76:18.5
0,4,76:17.0
1,4,76:17.0
2,4,76:18.5
3,4,76:18.5
4,4,76:18.5
-4,5,76:18.5
-3,5,76:18.5
-1,5,76:18.5
0,5,76:18.5
1,5,76:17.0
3,5,76:18.5
4,5,76:18.5
5,5,76:18.5
-5,6,76:18.5
-4,6,76:18.5
-3,6,76:18.5
-2,6,76:18.5
0,6,76:18.5
2,6,76:18.5
5,6,76:18.5
-5,7,76:18.5
-2,7,76:18.5
-1,7,76:18.5
2,7,76:18.5
-5,8,76:18.5
-1,8,76:18.5
0,8,76:18.5
1,8,76:18.5
0,9,76:18.5
1,9,76:18.5
2,9,76:18.5
-2,10,76:18.5
-1,10,76:18.5
2,10,76:18.5
3,10,76:18.5
4,10,76:18.5
-4,-1,77:18.5
0,-1,77:18.5
1,-1,77:18.5
-3,0,77:18.5
-2,0,77:18.5
-1,0,77:18.5
0,0,77:18.5
-1,1,77:18.5
0,1,77:18.5
-2,2,77:18.5
1,2,77:18.5
2,2,77:18.5
4,2,77:18.5
-5,3,77:18.5
-3,3,77:18.5
-2,3,77:18.5
2,3,77:18.5
4,3,77:18.5
-5,4,77:18.5
-3,4,77:18.5
0,4,77:17.0
1,4,77:17.0
3,4,77:18.5
4,4,77:18.5
-4,5,77:18.5
-3,5,77:18.5
0,5,77:17.0
1,5,77:17.0
3,5,77:18.5
4,5,77:18.5
5,5,77:18.5
-4,6,77:18.5
-3,6,77:18.5
-2,6,77:18.5
2,6,77:18.5
5,6,77:18.5
-5,7,77:18.5
-4,7,77:18.5
-2,7,77:18.5
-1,7,77:18.5
1,7,77:18.5
2,7,77:18.5
-1,8,77:18.5
0,8,77:18.5
1,8,77:18.5
0,9,77:18.5
1,9,77:18.5
2,9,77:18.5
3,9,77:18.5
-2,10,77:18.5
-1,10,77:18.5
3,10,77:18.5
1,-1,78:18.5
-3,0,78:18.5
-2,0,78:18.5
-1,0,78:18.5
0,0,78:18.5
-1,1,78:18.5
0,1,78:18.5
-2,2,78:18.5
-1,2,78:18.5
1,2,78:18.5
4,2,78:18.5
-5,3,78:18.5
-2,3,78:18.5
2,3,78:18.5
4,3,78:18.5
-5,4,78:18.5
-4,4,78:18.5
-3,4,78:18.5
-2,4,78:18.5
0,4,78:17.0
1,4,78:17.0
3,4,78:18.5
4,4,78:18.5
-4,5,78:18.5
-3,5,78:18.5
0,5,78:17.0
1,5,78:17.0
2,5,78:18.5
3,5,78:18.5
4,5,78:18.5
5,5,78:18.5
-4,6,78:18.5
-3,6,78:18.5
-2,6,78:18.5
2,6,78:18.5
5,6,78:18.5
-4,7,78:18.5
-2,7,78:18.5
-1,7,78:18.5
1,7,78:18.5
2,7,78:18.5
-1,8,78:18.5
0,8,78:18.5
1,8,78:18.5
0,9,78:18.5
1,9,78:18.5
2,9,78:18.5
3,9,78:18.5
-1,10,78:18.5
1,-1,79:18.5
-3,0,79:18.5
-2,0,79:18.5
-1,0,79:18.5
0,0,79:18.5
-1,1,79:18.5
0,1,79:18.5
-1,2,79:18.5
0,2,79:18.5
1,2,79:18.5
4,2,79:18.5
-5,3,79:18.5
-2,3,79:18.5
1,3,79:18.5
2,3,79:18.5
4,3,79:18.5
-5,4,79:18.5
-4,4,79:18.5
-3,4,79:18.5
-2,4,79:18.5
0,4,79:17.0
1,4,79:17.0
2,4,79:18.5
3,4,79:18.5
-4,5,79:18.5
-3,5,79:18.5
0,5,79:17.0
1,5,79:17.0
2,5,79:18.5
3,5,79:18.5
4,5,79:18.5
5,5,79:18.5
-4,6,79:18.5
-2,6,79:18.5
2,6,79:18.5
5,6,79:18.5
-4,7,79:18.5
-1,7,79:18.5
1,7,79:18.5
2,7,79:18.5
0,8,79:18.5
1,8,79:18.5
0,9,79:18.5
1,9,79:18.5
2,9,79:18.5
3,9,79:18.5
-1,10,79:18.5
1,-1,80:18.5
2,-1,80:18.5
-3,0,80:18.5
-2,0,80:18.5
-1,0,80:18.5
0,0,80:18.5
1,0,80:18.5
-1,1,80:18.5
0,1,80:18.5
-1,2,80:18.5
0,2,80:18.5
1,2,80:18.5
-5,3,80:18.5
-2,3,80:18.5
-1,3,80:18.5
1,3,80:18.5
2,3,80:18.5
4,3,80:18.5
-5,4,80:18.5
-4,4,80:18.5
-2,4,80:18.5
0,4,80:17.0
1,4,80:17.0
2,4,80:18.5
3,4,80:18.5
-3,5,80:18.5
-2,5,80:18.5
0,5,80:17.0
1,5,80:17.0
2,5,80:18.5
3,5,80:18.5
4,5,80:18.5
-4,6,80:18.5
-3,6,80:18.5
-2,6,80:18.5
-1,6,80:18.5
2,6,80:18.5
5,6,80:18.5
-4,7,80:18.5
-1,7,80:18.5
0,7,80:18.5
1,7,80:18.5
0,8,80:18.5
1,8,80:18.5
0,9,80:18.5
1,9,80:18.5
2,9,80:18.5
3,9,80:18.5
-2,10,80:18.5
-1,10,80:18.5
2,-1,81:18.5
-3,0,81:18.5
-2,0,81:18.5
-1,0,81:18.5
0,0,81:18.5
1,0,81:18.5
-1,1,81:18.5
0,1,81:18.5
-1,2,81:18.5
0,2,81:18.5
1,2,81:18.5
-2,3,81:18.5
-1,3,81:18.5
1,3,81:18.5
2,3,81:18.5
4,3,81:18.5
-4,4,81:18.5
-2,4,81:18.5
0,4,81:17.0
1,4,81:17.0
2,4,81:18.5
3,4,81:18.5
-3,5,81:18.5
-2,5,81:18.5
0,5,81:17.0
1,5,81:17.0
2,5,81:18.5
3,5,81:18.5
4,5,81:18.5
-4,6,81:18.5
-3,6,81:18.5
-2,6,81:18.5
-1,6,81:18.5
2,6,81:18.5
5,6,81:18.5
-1,7,81:18.5
0,7,81:18.5
1,7,81:18.5
0,8,81:18.5
1,8,81:18.5
-1,9,81:18.5
0,9,81:18.5
1,9,81:18.5
2,9,81:18.5
3,9,81:18.5
-1,10,81:18.5
-2,0,82:18.5
0,0,82:18.5
1,0,82:18.5
2,0,82:18.5
-1,1,82:18.5
0,1,82:18.5
-1,2,82:18.5
0,2,82:18.5
-1,3,82:18.5
1,3,82:18.5
2,3,82:18.5
4,3,82:18.5
-4,4,82:18.5
-3,4,82:18.5
-2,4,82:18.5
0,4,82:17.0
1,4,82:17.0
2,4,82:18.5
3,4,82:18.5
-3,5,82:18.5
-2,5,82:18.5
0,5,82:17.0
1,5,82:17.0
2,5,82:18.5
3,5,82:18.5
4,5,82:18.5
-3,6,82:18.5
-2,6,82:18.5
-1,6,82:18.5
1,6,82:18.5
2,6,82:18.5
4,6,82:18.5
-1,7,82:18.5
0,7,82:18.5
1,7,82:18.5
0,8,82:18.5
1,8,82:18.5
-1,9,82:18.5
0,9,82:18.5
2,9,82:18.5
3,9,82:18.5
-2,10,82:18.5
-1,10,82:18.5
1,0,83:18.5
-2,1,83:18.5
-1,1,83:18.5
0,1,83:18.5
-1,2,83:18.5
0,2,83:18.5
-1,3,83:18.5
1,3,83:18.5
-4,4,83:18.5
-3,4,83:18.5
-2,4,83:18.5
-1,4,83:18.5
0,4,83:17.0
1,4,83:17.0
2,4,83:18.5
3,4,83:18.5
-3,5,83:18.5
-2,5,83:18.5
0,5,83:17.0
1,5,83:17.0
2,5,83:18.5
3,5,83:18.5
4,5,83:18.5
-3,6,83:18.5
-1,6,83:18.5
1,6,83:18.5
2,6,83:18.5
0,7,83:18.5
1,7,83:18.5
0,8,83:18.5
1,8,83:18.5
-1,9,83:18.5
0,9,83:18.5
2,9,83:18.5
1,0,84:18.5
-2,1,84:18.5
-1,1,84:18.5
0,1,84:18.5
1,1,84:18.5
-1,2,84:18.5
0,2,84:18.5
-1,3,84:18.5
0,3,84:18.5
1,3,84:18.5
-4,4,84:18.5
-3,4,84:18.5
-1,4,84:18.5
0,4,84:17.0
1,4,84:17.0
2,4,84:18.5
3,4,84:18.5
-2,5,84:18.5
0,5,84:17.0
1,5,84:17.0
2,5,84:18.5
3,5,84:18.5
4,5,84:18.5
-3,6,84:18.5
-2,6,84:18.5
-1,6,84:18.5
0,6,84:18.5
1,6,84:18.5
0,7,84:18.5
1,7,84:18.5
0,8,84:18.5
1,8,84:18.5
2,8,84:18.5
-1,9,84:18.5
0,9,84:18.5
2,9,84:18.5
1,0,85:18.5
-1,1,85:18.5
0,1,85:18.5
1,1,85:18.5
-1,2,85:18.5
0,2,85:18.5
-1,3,85:18.5
0,3,85:18.5
1,3,85:18.5
4,3,85:18.5
-3,4,85:18.5
-1,4,85:18.5
0,4,85:17.0
1,4,85:17.0
2,4,85:18.5
3,4,85:18.5
-2,5,85:18.5
-1,5,85:18.5
0,5,85:17.0
1,5,85:17.0
2,5,85:18.5
3,5,85:18.5
4,5,85:18.5
-3,6,85:18.5
-2,6,85:18.5
-1,6,85:18.5
0,6,85:18.5
1,6,85:18.5
-3,7,85:18.5
0,7,85:18.5
1,7,85:18.5
0,8,85:18.5
1,8,85:18.5
2,8,85:18.5
-1,9,85:18.5
0,9,85:18.5
-1,1,86:18.5
1,1,86:18.5
-1,2,86:18.5
0,2,86:18.5
0,3,86:18.5
1,3,86:18.5
-3,4,86:18.5
-2,4,86:18.5
-1,4,86:18.5
0,4,86:17.0
1,4,86:17.0
2,4,86:18.5
3,4,86:18.5
-2,5,86:18.5
-1,5,86:18.5
0,5,86:17.0
1,5,86:17.0
2,5,86:18.5
3,5,86:18.5
-3,6,86:18.5
-2,6,86:18.5
-1,6,86:18.5
0,6,86:18.5
1,6,86:18.5
4,6,86:18.5
-3,7,86:18.5
0,7,86:18.5
1,7,86:18.5
0,8,86:18.5
1,8,86:18.5
2,8,86:18.5
1,1,87:18.5
-1,2,87:18.5
0,2,87:18.5
1,2,87:18.5
0,3,87:18.5
1,3,87:18.5
-3,4,87:18.5
-2,4,87:18.5
-1,4,87:18.5
0,4,87:18.5
1,4,87:18.5
2,4,87:18.5
3,4,87:18.5
-2,5,87:18.5
-1,5,87:18.5
0,5,87:17.0
1,5,87:17.0
2,5,87:18.5
3,5,87:18.5
-2,6,87:18.5
0,6,87:18.5
1,6,87:18.5
4,6,87:18.5
-3,7,87:18.5
0,7,87:18.5
1,7,87:18.5
0,8,87:18.5
2,8,87:18.5
1,1,88:18.5
-1,2,88:18.5
1,2,88:18.5
0,3,88:18.5
-3,4,88:18.5
-2,4,88:18.5
-1,4,88:18.5
0,4,88:18.5
1,4,88:18.5
2,4,88:18.5
-1,5,88:18.5
0,5,88:17.0
1,5,88:17.0
2,5,88:18.5
3,5,88:18.5
-2,6,88:18.5
0,6,88:18.5
1,6,88:18.5
3,6,88:18.5
-3,7,88:18.5
0,7,88:18.5
1,7,88:18.5
2,7,88:18.5
0,8,88:18.5
2,8,88:18.5
-1,2,89:18.5
1,2,89:18.5
-1,3,89:18.5
0,3,89:18.5
1,3,89:18.5
-3,4,89:18.5
-2,4,89:18.5
0,4,89:18.5
1,4,89:18.5
2,4,89:18.5
-1,5,89:18.5
0,5,89:18.5
1,5,89:17.0
2,5,89:18.5
3,5,89:18.5
-2,6,89:18.5
-1,6,89:18.5
0,6,89:18.5
1,6,89:18.5
3,6,89:18.5
0,7,89:18.5
1,7,89:18.5
2,7,89:18.5
0,8,89:18.5
2,8,89:18.5
-2,2,90:18.5
-1,2,90:18.5
1,2,90:18.5
-1,3,90:18.5
0,3,90:18.5
1,3,90:18.5
-3,4,90:18.5
-2,4,90:18.5
-1,4,90:18.5
0,4,90:18.5
1,4,90:18.5
2,4,90:18.5
-1,5,90:18.5
0,5,90:18.5
1,5,90:18.5
2,5,90:18.5
3,5,90:18.5
-2,6,90:18.5
-1,6,90:18.5
0,6,90:18.5
1,6,90:18.5
3,6,90:18.5
4,6,90:18.5
0,7,90:18.5
1,7,90:18.5
2,7,90:18.5
0,8,90:18.5
2,8,90:18.5
-1,1,91:18.5
-1,2,91:18.5
1,2,91:18.5
-2,3,91:18.5
-1,3,91:18.5
0,3,91:18.5
1,3,91:18.5
-3,4,91:18.5
-2,4,91:18.5
-1,4,91:18.5
0,4,91:18.5
1,4,91:18.5
2,4,91:18.5
-2,5,91:18.5
-1,5,91:18.5
0,5,91:18.5
1,5,91:18.5
2,5,91:18.5
3,5,91:18.5
-1,6,91:18.5
0,6,91:18.5
1,6,91:18.5
3,6,91:18.5
4,6,91:18.5
0,7,91:18.5
1,7,91:18.5
2,7,91:18.5
2,8,91:18.5
1,1,92:18.5
-1,2,92:18.5
2,2,92:18.5
-1,3,92:18.5
0,3,92:18.5
1,3,92:18.5
2,3,92:18.5
4,3,92:18.5
-3,4,92:18.5
-2,4,92:18.5
-1,4,92:18.5
0,4,92:18.5
1,4,92:18.5
2,4,92:18.5
-1,5,92:18.5
0,5,92:18.5
1,5,92:18.5
2,5,92:18.5
4,5,92:18.5
-1,6,92:18.5
0,6,92:18.5
1,6,92:18.5
2,6,92:18.5
3,6,92:18.5
-3,7,92:18.5
-1,7,92:18.5
0,7,92:18.5
1,7,92:18.5
2,7,92:18.5
-1,8,92:18.5
0,8,92:18.5
2,8,92:18.5
-1,2,93:18.5
2,2,93:18.5
-1,3,93:18.5
0,3,93:18.5
1,3,93:18.5
2,3,93:18.5
4,3,93:18.5
-3,4,93:18.5
-2,4,93:18.5
-1,4,93:18.5
0,4,93:18.5
1,4,93:18.5
2,4,93:18.5
-1,5,93:18.5
0,5,93:18.5
1,5,93:18.5
2,5,93:18.5
-1,6,93:18.5
0,6,93:18.5
1,6,93:18.5
2,6,93:18.5
3,6,93:18.5
-3,7,93:18.5
-2,7,93:18.5
-1,7,93:18.5
0,7,93:18.5
1,7,93:18.5
2,7,93:18.5
-1,8,93:18.5
0,8,93:18.5
1,2,94:18.5
2,2,94:18.5
-1,3,94:18.5
0,3,94:18.5
1,3,94:18.5
2,3,94:18.5
4,3,94:18.5
-2,4,94:18.5
-1,4,94:18.5
0,4,94:18.5
1,4,94:17.0
2,4,94:18.5
-1,5,94:18.5
0,5,94:18.5
1,5,94:17.0
2,5,94:18.5
-1,6,94:18.5
1,6,94:18.5
2,6,94:18.5
3,6,94:18.5
-2,7,94:18.5
-1,7,94:18.5
0,7,94:18.5
2,7,94:18.5
0,8,94:18.5
1,2,95:18.5
2,2,95:18.5
-1,3,95:18.5
0,3,95:18.5
1,3,95:18.5
2,3,95:18.5
-2,4,95:18.5
-1,4,95:18.5
0,4,95:18.5
1,4,95:17.0
2,4,95:18.5
-1,5,95:18.5
1,5,95:17.0
2,5,95:18.5
3,5,95:18.5
-2,6,95:18.5
-1,6,95:18.5
1,6,95:18.5
2,6,95:18.5
3,6,95:18.5
-2,7,95:18.5
-1,7,95:18.5
0,7,95:18.5
2,7,95:18.5
0,8,95:18.5
1,2,96:18.5
-1,3,96:18.5
1,3,96:18.5
2,3,96:18.5
-2,4,96:18.5
-1,4,96:18.5
0,4,96:18.5
1,4,96:17.0
2,4,96:18.5
-1,5,96:18.5
1,5,96:17.0
2,5,96:18.5
3,5,96:18.5
-2,6,96:18.5
-1,6,96:18.5
0,6,96:18.5
1,6,96:18.5
2,6,96:18.5
3,6,96:18.5
-1,7,96:18.5
0,7,96:18.5
2,7,96:18.5
0,8,96:18.5
1,2,97:18.5
-1,3,97:18.5
1,3,97:18.5
2,3,97:18.5
-1,4,97:18.5
0,4,97:18.5
1,4,97:18.5
2,4,97:18.5
3,4,97:18.5
-1,5,97:18.5
1,5,97:17.0
2,5,97:18.5
3,5,97:18.5
-1,6,97:18.5
0,6,97:18.5
1,6,97:18.5
2,6,97:18.5
3,6,97:18.5
0,7,97:18.5
2,7,97:18.5
1,3,98:18.5
2,3,98:18.5
-1,4,98:18.5
0,4,98:18.5
1,4,98:18.5
2,4,98:18.5
3,4,98:18.5
-1,5,98:18.5
0,5,98:18.5
1,5,98:17.0
2,5,98:18.5
-1,6,98:18.5
0,6,98:18.5
1,6,98:18.5
2,6,98:18.5
0,7,98:18.5
1,3,99:18.5
2,3,99:18.5
-1,4,99:18.5
0,4,99:18.5
1,4,99:18.5
2,4,99:18.5
0,5,99:18.5
1,5,99:17.0
2,5,99:18.5
-1,6,99:18.5
0,6,99:18.5
1,6,99:18.5
2,6,99:18.5
0,7,99:18.5
1,3,100:18.5
0,4,100:18.5
1,4,100:18.5
2,4,100:18.5
0,5,100:18.5
1,5,100:17.0
2,5,100:18.5
0,6,100:18.5
1,6,100:18.5
2,6,100:18.5
0,7,100:18.5
0,4,101:18.5
1,4,101:18.5
2,4,101:18.5
0,5,101:18.5
1,5,101:17.0
2,5,101:18.5
0,6,101:18.5
1,6,101:18.5
2,6,101:18.5
0,4,102:18.5
1,4,102:18.5
2,4,102:18.5
0,5,102:18.5
1,5,102:17.0
2,5,102:18.5
0,6,102:18.5
1,6,102:18.5
2,6,102:18.5
0,4,103:18.5
1,4,103:18.5
2,4,103:18.5
0,5,103:18.5
1,5,103:17.0
2,5,103:18.5
0,6,103:18.5
1,6,103:18.5
2,6,103:18.5
1,4,104:18.5
0,5,104:18.5
1,5,104:18.5
2,5,104:18.5
0,6,104:18.5
1,6,104:18.5
1,5,105:18.5
1,6,105:18.5
1,5,106:18.5
1,5,107:18.5
1,5,108:17.0
1,5,109:17.0
1,5,110:17.0
1,5,111:17.0
