[META]
version=2.0
spawnOnBlockType=2
spawnSunlight=True
spawnDarkness=True
spawnWater=False
spawnLava=False
underFill=False
randomRotation=True
dig=True
tree=False
branch=False
needsFoundation=True
rarity=100
collisionPercentage=20
spawnElevationMin=0
spawnElevationMax=200
spawnInBiome=Custom
[DATA]
-6,7,-8:17.12
-5,8,-8:17.12
-1,10,-8:17.12
-1,11,-8:17.12
-5,6,-7:17.12
-5,7,-7:17.12
-4,7,-7:17.12
-1,10,-7:17.12
-1,11,-7:17.12
-2,12,-7:17.12
-1,12,-7:17.12
-5,6,-6:17.12
-6,7,-6:17.12
-5,7,-6:17.12
-4,7,-6:17.12
-6,8,-6:17.12
-5,8,-6:17.12
-2,9,-6:17.12
-1,9,-6:17.12
-1,10,-6:17.12
-2,11,-6:17.12
-1,11,-6:17.12
-6,6,-5:17.12
-5,6,-5:17.12
-4,6,-5:17.12
-6,7,-5:17.12
-5,7,-5:17.12
-4,7,-5:17.12
-5,8,-5:17.12
-3,8,-5:17.12
-3,9,-5:17.12
-2,9,-5:17.12
-3,10,-5:17.12
-2,10,-5:17.12
-1,10,-5:17.12
-5,6,-4:17.12
-5,7,-4:17.12
-3,7,-4:17.12
-6,8,-4:17.12
-5,8,-4:17.12
-2,8,-4:17.12
-3,9,-4:17.12
-2,9,-4:17.12
-1,9,-4:17.12
-2,10,-4:17.12
-5,6,-3:17.12
-5,7,-3:17.12
-6,8,-3:17.12
-5,8,-3:17.12
-4,8,-3:17.12
-2,8,-3:17.12
-1,8,-3:17.12
-5,9,-3:17.12
-4,9,-3:17.12
-3,9,-3:17.12
-2,9,-3:17.12
-3,10,-3:17.12
-2,10,-3:17.12
-1,10,-3:17.12
-5,6,-2:17.12
-4,6,-2:17.12
-3,6,-2:17.12
-2,6,-2:17.12
-6,7,-2:17.12
-5,7,-2:17.12
-4,7,-2:17.12
-3,7,-2:17.12
-2,7,-2:17.12
-1,7,-2:17.12
-6,8,-2:17.12
-5,8,-2:17.12
-4,8,-2:17.12
-3,8,-2:17.12
-2,8,-2:17.12
-1,8,-2:17.12
-6,9,-2:17.12
-5,9,-2:17.12
-4,9,-2:17.12
-3,9,-2:17.12
-2,9,-2:17.12
-1,9,-2:17.12
-5,10,-2:17.12
-4,10,-2:17.12
-3,10,-2:17.12
-2,10,-2:17.12
-1,10,-2:17.12
-5,6,-1:17.12
-4,6,-1:17.12
-3,6,-1:17.12
-2,6,-1:17.12
-5,7,-1:17.12
-2,7,-1:17.12
-1,7,-1:17.12
-6,8,-1:17.12
-5,8,-1:17.12
-1,8,-1:17.12
-5,9,-1:17.12
-3,9,-1:17.12
-2,9,-1:17.12
-5,10,-1:17.12
-4,10,-1:17.12
-3,10,-1:17.12
-2,10,-1:17.12
-5,6,0:17.12
-4,6,0:17.12
-3,6,0:17.12
-2,6,0:17.12
-5,7,0:17.12
-2,7,0:17.12
-5,8,0:17.12
-2,8,0:17.12
-1,8,0:17.12
-5,9,0:17.12
-4,9,0:17.12
-3,9,0:17.12
-2,9,0:17.12
-3,10,0:17.12
-4,6,1:17.12
-3,6,1:17.12
-2,6,1:17.12
-5,7,1:17.12
-2,7,1:17.12
-5,8,1:17.12
-2,8,1:17.12
-5,9,1:17.12
-4,9,1:17.12
-3,9,1:17.12
-2,9,1:17.12
-4,6,2:17.12
-3,6,2:17.12
-5,7,2:17.12
-2,7,2:17.12
-5,8,2:17.12
-2,8,2:17.12
-5,9,2:17.12
-4,9,2:17.12
-3,9,2:17.12
-2,9,2:17.12
-4,6,3:17.12
-3,6,3:17.12
-5,7,3:17.12
-3,7,3:17.12
-2,7,3:17.12
-5,8,3:17.12
-2,8,3:17.12
-5,9,3:17.12
-4,9,3:17.12
-3,9,3:17.12
-2,9,3:17.12
-4,6,4:17.12
-3,6,4:17.12
-5,7,4:17.12
-4,7,4:17.12
-3,7,4:17.12
-5,8,4:17.12
-3,8,4:17.12
-2,8,4:17.12
-5,9,4:17.12
-4,9,4:17.12
-3,9,4:17.12
-5,7,5:17.12
-4,7,5:17.12
-3,7,5:17.12
-5,8,5:17.12
-3,8,5:17.12
-5,9,5:17.12
-4,9,5:17.12
-3,9,5:17.12
-5,7,6:17.12
-4,7,6:17.12
-3,7,6:17.12
-5,8,6:17.12
-3,8,6:17.12
-5,9,6:17.12
-4,9,6:17.12
-3,9,6:17.12
-5,7,7:17.12
-4,7,7:17.12
-3,7,7:17.12
-5,8,7:17.12
-3,8,7:17.12
-5,9,7:17.12
-4,9,7:17.12
-3,9,7:17.12
-5,7,8:17.12
-4,7,8:17.12
-3,7,8:17.12
-5,8,8:17.12
-3,8,8:17.12
-5,9,8:17.12
-4,9,8:17.12
-3,9,8:17.12
-9,7,9:18.13
-6,7,9:17.12
-5,7,9:17.12
-4,7,9:17.12
-3,7,9:17.12
-6,8,9:17.12
-5,8,9:17.12
-3,8,9:17.12
-5,9,9:17.12
-4,9,9:17.12
-3,9,9:17.12
-9,10,9:18.13
-4,3,10:18.13
-3,3,10:18.13
-7,4,10:18.13
0,5,10:18.13
-9,6,10:18.13
-7,6,10:18.13
-6,6,10:18.13
0,6,10:18.13
-9,7,10:18.13
-6,7,10:17.12
-5,7,10:17.12
-4,7,10:17.12
-3,7,10:17.12
-1,7,10:18.13
-8,8,10:18.13
-6,8,10:17.12
-3,8,10:17.12
-9,9,10:18.13
-8,9,10:18.13
-7,9,10:18.13
-5,9,10:17.12
-4,9,10:17.12
-3,9,10:17.12
0,9,10:18.13
-9,10,10:18.13
-6,10,10:18.13
1,10,10:18.13
-9,11,10:18.13
-5,12,10:18.13
-3,12,10:18.13
-2,12,10:18.13
-6,13,10:18.13
-4,3,11:18.13
-3,3,11:18.13
-7,4,11:18.13
-5,4,11:18.13
-6,5,11:18.13
-5,5,11:18.13
-4,5,11:18.13
0,5,11:18.13
-9,6,11:18.13
-6,6,11:18.13
-3,6,11:18.13
-2,6,11:18.13
-1,6,11:18.13
0,6,11:18.13
-9,7,11:18.13
-7,7,11:18.13
-6,7,11:17.12
-5,7,11:17.12
-4,7,11:17.12
-2,7,11:18.13
-1,7,11:18.13
-8,8,11:18.13
-7,8,11:18.13
-6,8,11:17.12
-4,8,11:17.12
-3,8,11:17.12
-2,8,11:18.13
-1,8,11:18.13
0,8,11:18.13
-8,9,11:18.13
-7,9,11:18.13
-6,9,11:18.13
-5,9,11:17.12
-4,9,11:17.12
-3,9,11:18.13
-2,9,11:18.13
0,9,11:18.13
-9,10,11:18.13
-6,10,11:18.13
-3,10,11:18.13
-9,11,11:18.13
-5,11,11:18.13
-4,11,11:18.13
-6,12,11:18.13
-5,12,11:18.13
-4,12,11:18.13
-3,12,11:18.13
-2,12,11:18.13
-6,13,11:18.13
-4,3,12:18.13
-3,3,12:18.13
-7,4,12:18.13
-5,4,12:18.13
-4,4,12:18.13
-6,5,12:18.13
-5,5,12:18.13
-4,5,12:18.13
-1,5,12:18.13
0,5,12:18.13
-6,6,12:18.13
-4,6,12:18.13
-3,6,12:18.13
-1,6,12:18.13
-9,7,12:18.13
-7,7,12:18.13
-6,7,12:17.12
-5,7,12:17.12
-4,7,12:17.12
-2,7,12:18.13
-1,7,12:18.13
-8,8,12:18.13
-7,8,12:18.13
-6,8,12:17.12
-4,8,12:17.12
-3,8,12:17.12
-2,8,12:18.13
-1,8,12:18.13
0,8,12:18.13
-8,9,12:18.13
-7,9,12:18.13
-6,9,12:18.13
-5,9,12:17.12
-4,9,12:17.12
-3,9,12:18.13
-2,9,12:18.13
0,9,12:18.13
-9,10,12:18.13
-6,10,12:18.13
-5,10,12:18.13
-4,10,12:18.13
-3,10,12:18.13
-9,11,12:18.13
-5,11,12:18.13
-4,11,12:18.13
-6,12,12:18.13
-5,12,12:18.13
-4,12,12:18.13
-3,12,12:18.13
-2,12,12:18.13
-8,0,13:18.5
-8,1,13:18.5
-4,3,13:18.13
-3,3,13:18.13
-7,4,13:18.13
-5,4,13:18.13
-4,4,13:18.13
-11,5,13:18.5
-9,5,13:18.13
-5,5,13:18.13
-4,5,13:18.13
-1,5,13:18.13
-12,6,13:18.5
-11,6,13:18.5
-9,6,13:18.13
-6,6,13:18.13
-4,6,13:18.13
-3,6,13:18.13
-1,6,13:18.13
-9,7,13:18.13
-8,7,13:18.13
-7,7,13:18.13
-6,7,13:17.12
-5,7,13:17.12
-4,7,13:17.12
-3,7,13:18.13
-2,7,13:18.13
-1,7,13:18.13
-8,8,13:18.13
-7,8,13:18.13
-6,8,13:17.12
-4,8,13:17.12
-3,8,13:18.13
-2,8,13:18.13
-1,8,13:18.13
-8,9,13:18.13
-6,9,13:18.13
-5,9,13:17.12
-4,9,13:17.12
-3,9,13:18.13
0,9,13:18.13
-9,10,13:18.13
-8,10,13:18.13
-5,10,13:18.13
-4,10,13:18.13
-5,11,13:18.13
-4,11,13:18.13
-3,11,13:18.13
-6,12,13:18.13
-5,12,13:18.13
-3,12,13:18.13
-2,12,13:18.13
-8,1,14:18.5
-8,2,14:18.5
-9,3,14:18.13
-4,3,14:18.13
-3,3,14:18.13
-9,4,14:18.13
-7,4,14:18.13
-4,4,14:18.13
-11,5,14:18.5
-10,5,14:18.13
-9,5,14:18.13
-6,5,14:18.13
-5,5,14:18.13
-1,5,14:18.13
-12,6,14:18.5
-11,6,14:18.5
-9,6,14:18.13
-6,6,14:18.13
-5,6,14:18.13
-4,6,14:18.13
-1,6,14:18.13
-9,7,14:18.13
-8,7,14:18.13
-6,7,14:18.13
-5,7,14:17.12
-4,7,14:17.12
-3,7,14:18.13
-2,7,14:18.13
-7,8,14:18.13
-6,8,14:17.12
-4,8,14:17.12
-3,8,14:18.13
-2,8,14:18.13
-1,8,14:18.13
-8,9,14:18.13
-7,9,14:18.13
-6,9,14:18.13
-5,9,14:17.12
-4,9,14:18.13
-3,9,14:18.13
0,9,14:18.13
2,9,14:18.5
3,9,14:18.5
-8,10,14:18.13
-5,10,14:18.13
-4,10,14:18.13
0,10,14:18.13
1,10,14:18.13
2,10,14:18.5
-5,11,14:18.13
-4,11,14:18.13
-3,11,14:18.13
0,11,14:18.13
-6,12,14:18.13
-5,12,14:18.13
-2,12,14:18.13
-1,13,14:18.13
-1,14,14:18.5
-2,15,14:18.5
-1,15,14:18.5
-8,2,15:18.5
-9,3,15:18.13
-8,3,15:18.13
-4,3,15:18.13
-3,3,15:18.13
-9,4,15:18.13
-8,4,15:18.13
-7,4,15:18.13
-5,4,15:18.13
-4,4,15:18.13
-10,5,15:18.13
-9,5,15:18.13
-8,5,15:18.13
-6,5,15:18.13
-5,5,15:18.13
-4,5,15:18.13
-1,5,15:18.13
-12,6,15:18.5
-11,6,15:18.5
-9,6,15:18.13
-5,6,15:18.13
-4,6,15:18.13
-2,6,15:18.13
-1,6,15:18.13
-9,7,15:18.13
-8,7,15:18.13
-7,7,15:18.13
-6,7,15:18.13
-5,7,15:17.12
-4,7,15:17.12
-3,7,15:18.13
-2,7,15:18.13
-1,7,15:18.13
-9,8,15:18.13
-7,8,15:18.13
-6,8,15:18.13
-4,8,15:17.12
-3,8,15:18.13
-2,8,15:18.13
-1,8,15:18.13
-8,9,15:18.13
-7,9,15:18.13
-6,9,15:18.13
-5,9,15:18.13
-4,9,15:18.13
-1,9,15:18.13
0,9,15:18.13
2,9,15:18.5
3,9,15:18.5
-8,10,15:18.13
-5,10,15:18.13
-4,10,15:18.13
0,10,15:18.13
1,10,15:18.13
2,10,15:18.5
-6,11,15:18.13
-5,11,15:18.13
-3,11,15:18.13
-2,11,15:18.13
-1,11,15:18.13
0,11,15:18.13
-6,12,15:18.13
-1,12,15:18.13
-1,13,15:18.13
-2,14,15:18.5
-1,14,15:18.5
-3,0,16:18.5
-2,1,16:18.5
-8,2,16:18.5
-8,3,16:18.13
-3,3,16:18.13
-2,3,16:18.13
-9,4,16:18.13
-7,4,16:18.13
-5,4,16:18.13
-4,4,16:18.13
-10,5,16:18.13
-9,5,16:18.13
-8,5,16:18.13
-7,5,16:18.13
-6,5,16:18.13
-5,5,16:18.13
-4,5,16:18.13
-1,5,16:18.13
-12,6,16:18.5
-11,6,16:18.5
-10,6,16:18.13
-9,6,16:18.13
-8,6,16:18.13
-5,6,16:18.13
-2,6,16:18.13
-12,7,16:18.5
-9,7,16:18.13
-8,7,16:18.13
-7,7,16:18.13
-6,7,16:18.13
-5,7,16:17.12
-4,7,16:18.13
-3,7,16:18.13
-1,7,16:18.13
-9,8,16:18.13
-7,8,16:18.13
-6,8,16:18.13
-5,8,16:17.12
-4,8,16:17.12
-3,8,16:18.13
-2,8,16:18.13
-1,8,16:18.13
-8,9,16:18.13
-7,9,16:18.13
-5,9,16:18.13
-4,9,16:18.13
-1,9,16:18.13
1,9,16:18.13
2,9,16:18.5
-8,10,16:18.13
-5,10,16:18.13
-4,10,16:18.13
-3,10,16:18.13
0,10,16:18.13
1,10,16:18.13
-12,11,16:18.5
-6,11,16:18.13
-5,11,16:18.13
-4,11,16:18.13
-3,11,16:18.13
-2,11,16:18.13
-1,11,16:18.13
-6,12,16:18.13
-5,12,16:18.13
-1,12,16:18.13
-2,13,16:18.13
-1,13,16:18.13
-2,14,16:18.5
-3,0,17:18.5
-3,1,17:18.5
-2,1,17:18.5
-8,2,17:18.5
-2,2,17:18.5
-8,3,17:18.13
-2,3,17:18.13
-1,3,17:18.13
0,3,17:18.13
-9,4,17:18.13
-8,4,17:18.13
-7,4,17:18.13
-5,4,17:18.13
-4,4,17:18.13
-3,4,17:18.13
-1,4,17:18.13
1,4,17:18.5
2,4,17:18.5
3,4,17:18.5
-10,5,17:18.13
-9,5,17:18.13
-8,5,17:18.13
-7,5,17:18.13
-6,5,17:18.13
-4,5,17:18.13
-2,5,17:18.13
-1,5,17:18.13
-11,6,17:18.5
-10,6,17:18.13
-8,6,17:18.13
-6,6,17:18.13
-5,6,17:18.13
-3,6,17:18.13
-2,6,17:18.13
-1,6,17:18.13
-12,7,17:18.5
-8,7,17:18.13
-7,7,17:18.13
-6,7,17:18.13
-5,7,17:18.13
-4,7,17:18.13
-3,7,17:18.13
-1,7,17:18.13
-8,8,17:18.13
-6,8,17:18.13
-5,8,17:18.13
-4,8,17:18.13
-3,8,17:18.13
-2,8,17:18.13
-1,8,17:18.13
-8,9,17:18.13
-7,9,17:18.13
-5,9,17:18.13
-4,9,17:18.13
-2,9,17:18.13
-1,9,17:18.13
1,9,17:18.5
2,9,17:18.5
-8,10,17:18.13
-6,10,17:18.13
-5,10,17:18.13
-4,10,17:18.13
-3,10,17:18.13
-2,10,17:18.13
0,10,17:18.13
1,10,17:18.5
-12,11,17:18.5
-11,11,17:18.5
-8,11,17:18.13
-6,11,17:18.13
-5,11,17:18.13
-4,11,17:18.13
-3,11,17:18.13
-2,11,17:18.13
-1,11,17:18.13
-11,12,17:18.5
-8,12,17:18.13
-7,12,17:18.13
-6,12,17:18.13
-1,12,17:18.13
-8,13,17:18.13
-2,13,17:18.13
-8,14,17:18.5
-7,14,17:18.5
-7,15,17:18.5
-3,1,18:18.5
-8,2,18:18.5
-3,2,18:18.5
-2,2,18:18.5
-8,3,18:18.13
-2,3,18:18.13
-1,3,18:18.13
-8,4,18:18.13
-5,4,18:18.13
-4,4,18:18.13
-3,4,18:18.13
-2,4,18:18.13
-1,4,18:18.13
0,4,18:18.13
1,4,18:18.5
2,4,18:18.5
-9,5,18:18.13
-8,5,18:18.13
-7,5,18:18.13
-6,5,18:18.13
-5,5,18:18.13
-4,5,18:18.13
-2,5,18:18.13
-11,6,18:18.5
-10,6,18:18.13
-8,6,18:18.13
-6,6,18:18.13
-5,6,18:18.13
-4,6,18:18.13
-3,6,18:18.13
-2,6,18:18.13
-8,7,18:18.13
-7,7,18:18.13
-6,7,18:18.13
-5,7,18:18.13
-4,7,18:18.13
-2,7,18:18.13
-8,8,18:18.13
-6,8,18:18.13
-5,8,18:18.13
-4,8,18:18.13
-3,8,18:18.13
-2,8,18:18.13
-8,9,18:18.13
-7,9,18:18.13
-6,9,18:18.13
-5,9,18:18.13
-4,9,18:18.13
-2,9,18:18.13
0,9,18:18.13
1,9,18:18.5
-8,10,18:18.13
-6,10,18:18.13
-4,10,18:18.13
-3,10,18:18.13
-2,10,18:18.13
0,10,18:18.13
-11,11,18:18.5
-10,11,18:18.13
-8,11,18:18.13
-7,11,18:18.13
-6,11,18:18.13
-5,11,18:18.13
-4,11,18:18.13
-2,11,18:18.13
-1,11,18:18.13
-9,12,18:18.13
-8,12,18:18.13
-2,12,18:18.13
-8,13,18:18.13
-7,13,18:18.13
-2,13,18:18.13
-7,14,18:18.5
-7,15,18:18.5
-4,1,19:18.5
-3,1,19:18.5
-8,2,19:18.5
-3,2,19:18.5
-8,3,19:18.13
-2,3,19:18.13
-8,4,19:18.13
-4,4,19:18.13
-3,4,19:18.13
-2,4,19:18.13
-1,4,19:18.13
0,4,19:18.13
1,4,19:18.5
-8,5,19:18.13
-7,5,19:18.13
-6,5,19:18.13
-5,5,19:18.13
-4,5,19:18.13
-2,5,19:18.13
-10,6,19:18.13
-9,6,19:18.13
-8,6,19:18.13
-6,6,19:18.13
-4,6,19:18.13
-2,6,19:18.13
-8,7,19:18.13
-6,7,19:18.13
-5,7,19:18.13
-4,7,19:17.12
-2,7,19:18.13
-8,8,19:18.13
-6,8,19:17.12
-5,8,19:18.13
-4,8,19:18.13
-3,8,19:18.13
-2,8,19:18.13
-8,9,19:18.13
-6,9,19:18.13
-4,9,19:18.13
-2,9,19:18.13
-1,9,19:18.13
0,9,19:18.13
1,9,19:18.5
-8,10,19:18.13
-6,10,19:18.13
-5,10,19:18.13
-4,10,19:18.13
-3,10,19:18.13
-2,10,19:18.13
-11,11,19:18.5
-10,11,19:18.13
-9,11,19:18.13
-8,11,19:18.13
-7,11,19:18.13
-6,11,19:18.13
-5,11,19:18.13
-2,11,19:18.13
-8,12,19:18.13
-2,12,19:18.13
-8,13,19:18.5
-7,13,19:18.5
-2,13,19:18.5
-7,14,19:18.5
-6,14,19:18.5
-4,1,20:18.5
-3,2,20:18.5
-8,3,20:18.13
-3,3,20:18.13
-8,4,20:18.13
-3,4,20:18.13
-2,4,20:18.13
-1,4,20:18.13
0,4,20:18.13
-8,5,20:18.13
-7,5,20:18.13
-6,5,20:18.13
-5,5,20:18.13
-4,5,20:18.13
-3,5,20:18.13
-2,5,20:18.13
-10,6,20:18.13
-9,6,20:18.13
-8,6,20:18.13
-7,6,20:18.13
-3,6,20:18.13
-2,6,20:18.13
-8,7,20:18.13
-7,7,20:18.13
-6,7,20:17.12
-5,7,20:17.12
-4,7,20:17.12
-3,7,20:18.13
-2,7,20:18.13
-8,8,20:18.13
-7,8,20:18.13
-6,8,20:17.12
-5,8,20:17.12
-4,8,20:17.12
-3,8,20:18.13
-2,8,20:18.13
-8,9,20:18.13
-7,9,20:18.13
-3,9,20:18.13
-2,9,20:18.13
-1,9,20:18.13
0,9,20:18.13
-8,10,20:18.13
-7,10,20:18.13
-6,10,20:18.13
-5,10,20:18.13
-4,10,20:18.13
-3,10,20:18.13
-2,10,20:18.13
-10,11,20:18.13
-9,11,20:18.13
-8,11,20:18.13
-7,11,20:18.13
-2,11,20:18.13
-8,12,20:18.13
-7,12,20:18.13
-2,12,20:18.13
-7,13,20:18.5
-7,14,20:18.5
-6,14,20:18.5
-3,2,21:18.5
-8,3,21:18.13
-3,3,21:18.13
-8,4,21:18.13
-7,4,21:18.13
-3,4,21:18.13
-2,4,21:18.13
-1,4,21:18.13
0,4,21:18.13
-7,5,21:18.13
-5,5,21:18.13
-4,5,21:18.13
-3,5,21:18.13
-2,5,21:18.13
0,5,21:18.13
1,5,21:18.5
-9,6,21:18.13
-8,6,21:18.13
-7,6,21:18.13
-6,6,21:18.13
-3,6,21:18.13
-7,7,21:18.13
-6,7,21:17.12
-5,7,21:17.12
-4,7,21:17.12
-3,7,21:18.13
-7,8,21:18.13
-6,8,21:17.12
-5,8,21:17.12
-4,8,21:17.12
-3,8,21:18.13
-7,9,21:18.13
-5,9,21:18.13
-4,9,21:18.13
-3,9,21:18.13
-2,9,21:18.13
-1,9,21:18.13
-11,10,21:18.5
-10,10,21:18.13
-8,10,21:18.13
-7,10,21:18.13
-6,10,21:18.13
-5,10,21:18.13
-3,10,21:18.13
-10,11,21:18.13
-9,11,21:18.13
-8,11,21:18.13
-7,11,21:18.13
-3,11,21:18.13
-2,11,21:18.13
-7,12,21:18.13
-7,13,21:18.5
-3,3,22:18.13
-7,4,22:18.13
-4,4,22:18.13
-3,4,22:18.13
-7,5,22:18.13
-4,5,22:18.13
-3,5,22:18.13
-2,5,22:18.13
-1,5,22:18.13
0,5,22:18.13
-9,6,22:18.13
-8,6,22:18.13
-7,6,22:18.13
-6,6,22:18.13
-5,6,22:18.13
-4,6,22:18.13
-3,6,22:18.13
-7,7,22:18.13
-6,7,22:17.12
-5,7,22:17.12
-4,7,22:18.13
-3,7,22:18.13
-7,8,22:18.13
-6,8,22:17.12
-5,8,22:17.12
-4,8,22:17.12
-3,8,22:18.13
-7,9,22:18.13
-6,9,22:18.13
-5,9,22:18.13
-4,9,22:18.13
-3,9,22:18.13
-2,9,22:18.13
-1,9,22:18.13
-10,10,22:18.13
-9,10,22:18.13
-8,10,22:18.13
-7,10,22:18.13
-6,10,22:18.13
-3,10,22:18.13
-7,11,22:18.13
-3,11,22:18.13
-7,12,22:18.13
-4,3,23:18.13
-7,4,23:18.13
-4,4,23:18.13
-7,5,23:18.13
-4,5,23:18.13
-3,5,23:18.13
-2,5,23:18.13
-1,5,23:18.13
-8,6,23:18.13
-7,6,23:18.13
-6,6,23:18.13
-5,6,23:18.13
-4,6,23:18.13
-3,6,23:18.13
-9,7,23:18.13
-8,7,23:18.13
-7,7,23:18.13
-6,7,23:17.12
-5,7,23:17.12
-4,7,23:18.13
-7,8,23:18.13
-6,8,23:17.12
-5,8,23:17.12
-4,8,23:18.13
-3,8,23:18.13
-2,8,23:18.13
-1,8,23:18.13
-8,9,23:18.13
-7,9,23:18.13
-6,9,23:18.13
-5,9,23:18.13
-4,9,23:18.13
-3,9,23:18.13
-9,10,23:18.13
-8,10,23:18.13
-7,10,23:18.13
-4,10,23:18.13
-3,10,23:18.13
-7,11,23:18.13
-3,11,23:18.13
-4,3,24:18.13
-7,4,24:18.13
-4,4,24:18.13
-7,5,24:18.13
-4,5,24:18.13
-2,5,24:18.13
-1,5,24:18.13
-10,6,24:18.13
-6,6,24:18.13
-5,6,24:18.13
-4,6,24:18.13
-3,6,24:18.13
-2,6,24:18.13
-1,6,24:18.13
-9,7,24:18.13
-8,7,24:18.13
-7,7,24:18.13
-6,7,24:18.13
-5,7,24:17.12
-4,7,24:18.13
-2,7,24:18.13
-9,8,24:18.13
-8,8,24:18.13
-6,8,24:18.13
-5,8,24:17.12
-4,8,24:18.13
-3,8,24:18.13
-2,8,24:18.13
-1,8,24:18.13
-9,9,24:18.13
-8,9,24:18.13
-7,9,24:18.13
-6,9,24:18.13
-5,9,24:18.13
-4,9,24:18.13
-1,9,24:18.13
-9,10,24:18.13
-6,10,24:18.13
-4,10,24:18.13
-6,11,24:18.13
-4,11,24:18.13
-8,3,25:18.13
-4,3,25:18.13
-7,4,25:18.13
-5,4,25:18.13
-7,5,25:18.13
-6,5,25:18.13
-5,5,25:18.13
-4,5,25:18.13
-2,5,25:18.13
-9,6,25:18.13
-7,6,25:18.13
-6,6,25:18.13
-5,6,25:18.13
-4,6,25:18.13
-3,6,25:18.13
-2,6,25:18.13
-9,7,25:18.13
-8,7,25:18.13
-7,7,25:18.13
-6,7,25:18.13
-5,7,25:18.13
-4,7,25:18.13
-3,7,25:18.13
-2,7,25:18.13
-9,8,25:18.13
-8,8,25:18.13
-7,8,25:18.13
-6,8,25:18.13
-5,8,25:18.13
-4,8,25:18.13
-3,8,25:18.13
-2,8,25:18.13
-1,8,25:18.13
-9,9,25:18.13
-8,9,25:18.13
-7,9,25:18.13
-6,9,25:18.13
-4,9,25:18.13
-3,9,25:18.13
-1,9,25:18.13
-9,10,25:18.13
-6,10,25:18.13
-4,10,25:18.13
-6,11,25:18.13
-3,11,25:18.13
-7,12,25:18.13
-6,12,25:18.13
-5,3,26:18.13
-4,3,26:18.13
-8,4,26:18.13
-7,4,26:18.13
-5,4,26:18.13
-7,5,26:18.13
-6,5,26:18.13
-5,5,26:18.13
-4,5,26:18.13
-2,5,26:18.13
-9,6,26:18.13
-7,6,26:18.13
-6,6,26:18.13
-5,6,26:18.13
-4,6,26:18.13
-3,6,26:18.13
-2,6,26:18.13
-9,7,26:18.13
-8,7,26:18.13
-7,7,26:18.13
-6,7,26:18.13
-5,7,26:18.13
-4,7,26:18.13
-3,7,26:18.13
-2,7,26:18.13
-9,8,26:18.13
-8,8,26:18.13
-7,8,26:18.13
-6,8,26:18.13
-5,8,26:18.13
-4,8,26:18.13
-3,8,26:18.13
-2,8,26:18.13
-1,8,26:18.13
-9,9,26:18.13
-7,9,26:18.13
-6,9,26:18.13
-5,9,26:18.13
-4,9,26:18.13
-9,10,26:18.13
-6,10,26:18.13
-5,10,26:18.13
-4,10,26:18.13
-6,11,26:18.13
-5,11,26:18.13
-4,11,26:18.13
-3,11,26:18.13
-7,12,26:18.13
-4,3,27:18.13
-8,4,27:18.13
-7,4,27:18.13
-5,4,27:18.13
-6,5,27:18.13
-5,5,27:18.13
-2,5,27:18.13
-9,6,27:18.13
-7,6,27:18.13
-4,6,27:18.13
-3,6,27:18.13
-2,6,27:18.13
-9,7,27:18.13
-8,7,27:18.13
-7,7,27:18.13
-6,7,27:17.12
-5,7,27:17.12
-3,7,27:18.13
-2,7,27:18.13
-8,8,27:18.13
-7,8,27:18.13
-6,8,27:17.12
-5,8,27:17.12
-4,8,27:18.13
-3,8,27:18.13
-2,8,27:18.13
-9,9,27:18.13
-7,9,27:18.13
-6,9,27:18.13
-4,9,27:18.13
-6,10,27:18.13
-5,10,27:18.13
-6,11,27:18.13
-5,11,27:18.13
-4,11,27:18.13
-3,11,27:18.13
-4,3,28:18.13
-7,4,28:18.13
-5,4,28:18.13
-6,5,28:18.13
-5,5,28:18.13
-9,6,28:18.13
-7,6,28:18.13
-6,6,28:18.13
-5,6,28:18.13
-4,6,28:18.13
-3,6,28:18.13
-2,6,28:18.13
-9,7,28:18.13
-8,7,28:18.13
-7,7,28:18.13
-6,7,28:17.12
-5,7,28:17.12
-4,7,28:18.13
-3,7,28:18.13
-8,8,28:18.13
-7,8,28:18.13
-6,8,28:17.12
-5,8,28:17.12
-4,8,28:18.13
-2,8,28:18.13
-8,9,28:18.13
-6,9,28:18.13
-5,9,28:18.13
-4,9,28:18.13
-6,10,28:18.13
-5,10,28:18.13
-4,10,28:18.13
-6,11,28:18.13
-4,11,28:18.13
-3,11,28:18.13
-7,4,29:18.13
-5,4,29:18.13
-4,4,29:18.13
-6,5,29:18.13
-5,5,29:18.13
-6,6,29:18.13
-5,6,29:18.13
-3,6,29:18.13
-8,7,29:18.13
-7,7,29:18.13
-6,7,29:17.12
-5,7,29:17.12
-4,7,29:18.13
-3,7,29:18.13
-8,8,29:18.13
-7,8,29:18.13
-6,8,29:18.13
-5,8,29:18.13
-4,8,29:18.13
-3,8,29:18.13
-2,8,29:18.13
-6,9,29:18.13
-5,9,29:18.13
-6,10,29:18.13
-5,10,29:18.13
-4,10,29:18.13
-7,11,29:18.13
-6,11,29:18.13
-5,4,30:18.13
-7,5,30:18.13
-6,5,30:18.13
-5,5,30:18.13
-6,6,30:18.13
-5,6,30:18.13
-4,6,30:18.13
-3,6,30:18.13
-8,7,30:18.13
-7,7,30:18.13
-6,7,30:17.12
-5,7,30:18.13
-4,7,30:18.13
-8,8,30:18.13
-7,8,30:18.13
-6,8,30:18.13
-5,8,30:18.13
-3,8,30:18.13
-8,9,30:18.13
-6,9,30:18.13
-5,9,30:18.13
-6,10,30:18.13
-5,10,30:18.13
-4,10,30:18.13
-7,5,31:18.13
-5,5,31:18.13
-8,6,31:18.13
-6,6,31:18.13
-5,6,31:18.13
-4,6,31:18.13
-3,6,31:18.13
-8,7,31:18.13
-7,7,31:18.13
-6,7,31:18.13
-5,7,31:18.13
-4,7,31:18.13
-8,8,31:18.13
-7,8,31:18.13
-6,8,31:18.13
-5,8,31:18.13
-4,8,31:18.13
-3,8,31:18.13
-8,9,31:18.13
-6,9,31:18.13
-5,9,31:18.13
-4,9,31:18.13
-6,10,31:18.13
-7,4,32:18.13
-7,5,32:18.13
-5,5,32:18.13
-8,6,32:18.13
-7,6,32:18.13
-6,6,32:18.13
-5,6,32:18.13
-4,6,32:18.13
-8,7,32:18.13
-7,7,32:18.13
-6,7,32:18.13
-5,7,32:18.13
-4,7,32:18.13
-7,8,32:18.13
-6,8,32:18.13
-5,8,32:18.13
-4,8,32:18.13
-3,8,32:18.13
-8,9,32:18.13
-7,9,32:18.13
-6,9,32:18.13
-5,9,32:18.13
-4,9,32:18.13
-4,10,32:18.13
-7,5,33:18.13
-5,5,33:18.13
-8,6,33:18.13
-7,6,33:18.13
-6,6,33:18.13
-5,6,33:18.13
-4,6,33:18.13
-3,6,33:18.13
-8,7,33:18.13
-7,7,33:18.13
-6,7,33:18.13
-5,7,33:18.13
-4,7,33:18.13
-8,8,33:18.13
-7,8,33:18.13
-6,8,33:18.13
-5,8,33:18.13
-4,8,33:18.13
-3,8,33:18.13
-8,9,33:18.13
-7,9,33:18.13
-6,9,33:18.13
-5,9,33:18.13
-4,9,33:18.13
-6,10,33:18.13
-5,5,34:18.13
-7,6,34:18.13
-6,6,34:18.13
-5,6,34:18.13
-4,6,34:18.13
-8,7,34:18.13
-7,7,34:18.13
-6,7,34:17.0
-5,7,34:18.13
-4,7,34:18.13
-8,8,34:18.13
-7,8,34:18.13
-6,8,34:18.13
-5,8,34:18.13
-4,8,34:18.13
-7,9,34:18.13
-6,9,34:18.13
-5,9,34:18.13
-7,6,35:18.5
-6,6,35:18.5
-5,6,35:18.5
-7,7,35:18.5
-6,7,35:17.0
-5,7,35:18.5
-7,8,35:18.5
-6,8,35:18.5
-5,8,35:18.5
-6,9,35:18.5
-6,6,36:18.5
-5,6,36:18.5
-7,7,36:18.5
-6,7,36:18.5
-5,7,36:18.5
-7,8,36:18.5
-6,8,36:18.5
-5,8,36:18.5
-6,7,37:18.5
-5,7,37:18.5
-6,7,38:18.5
-6,7,39:17.0
-6,7,40:17.0
