[META]
version=2.0
spawnOnBlockType=2
spawnSunlight=True
spawnDarkness=True
spawnWater=False
spawnLava=False
underFill=False
randomRotation=True
dig=True
tree=False
branch=False
needsFoundation=True
rarity=100
collisionPercentage=20
spawnElevationMin=0
spawnElevationMax=200
spawnInBiome=Custom
[DATA]
2,-11,-8:17.12
2,-10,-8:17.12
3,-10,-8:17.12
8,-9,-8:17.12
9,-9,-8:17.12
2,-5,-8:17.12
2,-4,-8:17.12
3,-4,-8:17.12
9,-4,-8:17.12
10,-4,-8:17.12
2,-3,-8:17.12
10,-3,-8:17.12
2,-11,-7:17.12
3,-11,-7:17.12
2,-10,-7:17.12
3,-10,-7:17.12
6,-10,-7:17.12
7,-10,-7:17.12
8,-10,-7:17.12
1,-9,-7:17.12
2,-9,-7:17.12
3,-9,-7:17.12
8,-9,-7:17.12
7,-8,-7:17.12
2,-5,-7:17.12
8,-5,-7:17.12
9,-5,-7:17.12
1,-4,-7:17.12
2,-4,-7:17.12
3,-4,-7:17.12
8,-4,-7:17.12
9,-4,-7:17.12
11,-4,-7:17.12
2,-3,-7:17.12
10,-3,-7:17.12
11,-3,-7:17.12
9,-2,-7:17.12
2,-10,-6:17.12
3,-10,-6:17.12
4,-10,-6:17.12
6,-10,-6:17.12
7,-10,-6:17.12
8,-10,-6:17.12
2,-9,-6:17.12
3,-9,-6:17.12
5,-9,-6:17.12
6,-9,-6:17.12
7,-9,-6:17.12
8,-9,-6:17.12
9,-9,-6:17.12
8,-8,-6:17.12
2,-5,-6:17.12
3,-5,-6:17.12
9,-5,-6:17.12
10,-5,-6:17.12
1,-4,-6:17.12
2,-4,-6:17.12
8,-4,-6:17.12
9,-4,-6:17.12
10,-4,-6:17.12
2,-3,-6:17.12
9,-3,-6:17.12
10,-3,-6:17.12
3,-10,-5:17.12
4,-10,-5:17.12
5,-10,-5:17.12
7,-10,-5:17.12
3,-9,-5:17.12
4,-9,-5:17.12
5,-9,-5:17.12
6,-9,-5:17.12
7,-9,-5:17.12
3,-8,-5:17.12
4,-8,-5:17.12
5,-8,-5:17.12
4,-7,-5:17.12
7,-6,-5:17.12
8,-6,-5:17.12
9,-6,-5:17.12
2,-5,-5:17.12
3,-5,-5:17.12
4,-5,-5:17.12
7,-5,-5:17.12
8,-5,-5:17.12
9,-5,-5:17.12
2,-4,-5:17.12
3,-4,-5:17.12
8,-4,-5:17.12
10,-4,-5:17.12
4,-10,-4:17.12
6,-10,-4:17.12
7,-10,-4:17.12
8,-10,-4:17.12
6,-9,-4:17.12
7,-9,-4:17.12
8,-9,-4:17.12
3,-8,-4:17.12
4,-8,-4:17.12
5,-8,-4:17.12
6,-8,-4:17.12
7,-8,-4:17.12
8,-8,-4:17.12
4,-7,-4:17.12
3,-6,-4:17.12
4,-6,-4:17.12
7,-6,-4:17.12
8,-6,-4:17.12
3,-5,-4:17.12
4,-5,-4:17.12
5,-5,-4:17.12
7,-5,-4:17.12
8,-5,-4:17.12
9,-5,-4:17.12
2,-4,-4:17.12
3,-4,-4:17.12
4,-4,-4:17.12
5,-4,-4:17.12
8,-4,-4:17.12
9,-4,-4:17.12
3,-3,-4:17.12
9,-10,-3:17.12
4,-9,-3:17.12
5,-9,-3:17.12
6,-9,-3:17.12
7,-9,-3:17.12
8,-9,-3:17.12
4,-8,-3:17.12
5,-8,-3:17.12
6,-8,-3:17.12
7,-8,-3:17.12
8,-8,-3:17.12
9,-8,-3:17.12
5,-7,-3:17.12
8,-7,-3:17.12
3,-6,-3:17.12
4,-6,-3:17.12
8,-6,-3:17.12
2,-5,-3:17.12
3,-5,-3:17.12
4,-5,-3:17.12
5,-5,-3:17.12
6,-5,-3:17.12
7,-5,-3:17.12
8,-5,-3:17.12
9,-5,-3:17.12
3,-4,-3:17.12
4,-4,-3:17.12
8,-4,-3:17.12
4,-10,-2:17.12
5,-10,-2:17.12
6,-10,-2:17.12
7,-10,-2:17.12
3,-9,-2:17.12
4,-9,-2:17.12
5,-9,-2:17.12
6,-9,-2:17.12
7,-9,-2:17.12
8,-9,-2:17.12
9,-9,-2:17.12
2,-8,-2:17.12
3,-8,-2:17.12
4,-8,-2:17.12
5,-8,-2:17.12
6,-8,-2:17.12
7,-8,-2:17.12
8,-8,-2:17.12
9,-8,-2:17.12
2,-7,-2:17.12
3,-7,-2:17.12
4,-7,-2:17.12
5,-7,-2:17.12
6,-7,-2:17.12
7,-7,-2:17.12
8,-7,-2:17.12
9,-7,-2:17.12
2,-6,-2:17.12
3,-6,-2:17.12
4,-6,-2:17.12
5,-6,-2:17.12
6,-6,-2:17.12
7,-6,-2:17.12
8,-6,-2:17.12
9,-6,-2:17.12
2,-5,-2:17.12
3,-5,-2:17.12
4,-5,-2:17.12
5,-5,-2:17.12
6,-5,-2:17.12
7,-5,-2:17.12
8,-5,-2:17.12
9,-5,-2:17.12
2,-4,-2:17.12
3,-4,-2:17.12
4,-4,-2:17.12
5,-4,-2:17.12
6,-4,-2:17.12
7,-4,-2:17.12
8,-4,-2:17.12
3,-3,-2:17.12
4,-3,-2:17.12
5,-3,-2:17.12
6,-3,-2:17.12
7,-3,-2:17.12
4,-10,-1:17.12
5,-10,-1:17.12
6,-10,-1:17.12
3,-9,-1:17.12
4,-9,-1:17.12
5,-9,-1:17.12
6,-9,-1:17.12
7,-9,-1:17.12
2,-8,-1:17.12
3,-8,-1:17.12
8,-8,-1:17.12
2,-7,-1:17.12
8,-7,-1:17.12
9,-7,-1:17.12
2,-6,-1:17.12
3,-6,-1:17.12
7,-6,-1:17.12
8,-6,-1:17.12
9,-6,-1:17.12
2,-5,-1:17.12
3,-5,-1:17.12
4,-5,-1:17.12
6,-5,-1:17.12
8,-5,-1:17.12
9,-5,-1:17.12
2,-4,-1:17.12
3,-4,-1:17.12
7,-4,-1:17.12
8,-4,-1:17.12
4,-3,-1:17.12
5,-3,-1:17.12
6,-3,-1:17.12
7,-3,-1:17.12
3,-9,0:17.12
4,-9,0:17.12
5,-9,0:17.12
6,-9,0:17.12
7,-9,0:17.12
2,-8,0:17.12
3,-8,0:17.12
7,-8,0:17.12
8,-8,0:17.12
2,-7,0:17.12
8,-7,0:17.12
2,-6,0:17.12
8,-6,0:17.12
2,-5,0:17.12
8,-5,0:17.12
3,-4,0:17.12
7,-4,0:17.12
8,-4,0:17.12
4,-3,0:17.12
5,-3,0:17.12
6,-3,0:17.12
7,-3,0:17.12
3,-9,1:17.12
4,-9,1:17.12
5,-9,1:17.12
6,-9,1:17.12
3,-8,1:17.12
7,-8,1:17.12
2,-7,1:17.12
8,-7,1:17.12
2,-6,1:17.12
8,-6,1:17.12
2,-5,1:17.12
7,-5,1:17.12
8,-5,1:17.12
3,-4,1:17.12
7,-4,1:17.12
4,-3,1:17.12
5,-3,1:17.12
6,-3,1:17.12
4,-9,2:17.12
5,-9,2:17.12
6,-9,2:17.12
3,-8,2:17.12
6,-8,2:17.12
7,-8,2:17.12
2,-7,2:17.12
3,-7,2:17.12
7,-7,2:17.12
8,-7,2:17.12
2,-6,2:17.12
8,-6,2:17.12
2,-5,2:17.12
7,-5,2:17.12
8,-5,2:17.12
3,-4,2:17.12
7,-4,2:17.12
4,-3,2:17.12
5,-3,2:17.12
6,-3,2:17.12
3,-8,3:17.12
4,-8,3:17.12
5,-8,3:17.12
6,-8,3:17.12
7,-8,3:17.12
2,-7,3:17.12
3,-7,3:17.12
7,-7,3:17.12
8,-7,3:17.12
2,-6,3:17.12
3,-6,3:17.12
8,-6,3:17.12
2,-5,3:17.12
3,-5,3:17.12
7,-5,3:17.12
8,-5,3:17.12
3,-4,3:17.12
4,-4,3:17.12
7,-4,3:17.12
4,-3,3:17.12
5,-3,3:17.12
6,-3,3:17.12
3,-8,4:17.12
4,-8,4:17.12
5,-8,4:17.12
6,-8,4:17.12
7,-8,4:17.12
3,-7,4:17.12
7,-7,4:17.12
8,-7,4:17.12
3,-6,4:17.12
8,-6,4:17.12
3,-5,4:17.12
7,-5,4:17.12
8,-5,4:17.12
3,-4,4:17.12
4,-4,4:17.12
7,-4,4:17.12
4,-3,4:17.12
5,-3,4:17.12
6,-3,4:17.12
4,-8,5:17.12
5,-8,5:17.12
6,-8,5:17.12
3,-7,5:17.12
4,-7,5:17.12
7,-7,5:17.12
3,-6,5:17.12
8,-6,5:17.12
3,-5,5:17.12
7,-5,5:17.12
3,-4,5:17.12
4,-4,5:17.12
7,-4,5:17.12
5,-3,5:17.12
6,-3,5:17.12
4,-8,6:17.12
5,-8,6:17.12
6,-8,6:17.12
3,-7,6:17.12
4,-7,6:17.12
6,-7,6:17.12
7,-7,6:17.12
3,-6,6:17.12
8,-6,6:17.12
3,-5,6:17.12
7,-5,6:17.12
3,-4,6:17.12
4,-4,6:17.12
5,-4,6:17.12
7,-4,6:17.12
5,-3,6:17.12
6,-3,6:17.12
5,-8,7:17.12
4,-7,7:17.12
6,-7,7:17.12
7,-7,7:17.12
4,-6,7:17.12
8,-6,7:17.12
3,-5,7:17.12
7,-5,7:17.12
4,-4,7:17.12
5,-4,7:17.12
7,-4,7:17.12
5,-3,7:17.12
6,-3,7:17.12
4,-7,8:17.12
5,-7,8:17.12
6,-7,8:17.12
7,-7,8:17.12
4,-6,8:17.12
7,-6,8:17.12
8,-6,8:17.12
4,-5,8:17.12
7,-5,8:17.12
4,-4,8:17.12
5,-4,8:17.12
7,-4,8:17.12
6,-3,8:17.12
7,-3,8:17.12
4,-7,9:17.12
5,-7,9:17.12
6,-7,9:17.12
4,-6,9:17.12
7,-6,9:17.12
8,-6,9:17.12
4,-5,9:17.12
7,-5,9:17.12
4,-4,9:17.12
5,-4,9:17.12
6,-4,9:17.12
7,-4,9:17.12
6,-3,9:17.12
7,-3,9:17.12
5,-7,10:17.12
6,-7,10:17.12
4,-6,10:17.12
5,-6,10:17.12
7,-6,10:17.12
8,-6,10:17.12
4,-5,10:17.12
7,-5,10:17.12
4,-4,10:17.12
5,-4,10:17.12
6,-4,10:17.12
7,-4,10:17.12
6,-3,10:17.12
7,-3,10:17.12
5,-7,11:17.12
6,-7,11:17.12
5,-6,11:17.12
7,-6,11:17.12
8,-6,11:17.12
4,-5,11:17.12
7,-5,11:17.12
8,-5,11:17.12
4,-4,11:17.12
5,-4,11:17.12
6,-4,11:17.12
7,-4,11:17.12
6,-3,11:17.12
7,-3,11:17.12
5,-7,12:17.12
6,-7,12:17.12
5,-6,12:17.12
7,-6,12:17.12
8,-6,12:17.12
4,-5,12:17.12
5,-5,12:17.12
8,-5,12:17.12
4,-4,12:17.12
5,-4,12:17.12
6,-4,12:17.12
7,-4,12:17.12
6,-3,12:17.12
7,-3,12:17.12
5,-7,13:17.12
6,-7,13:17.12
5,-6,13:17.12
7,-6,13:17.12
8,-6,13:17.12
4,-5,13:17.12
5,-5,13:17.12
8,-5,13:17.12
4,-4,13:17.12
5,-4,13:17.12
6,-4,13:17.12
7,-4,13:17.12
8,-4,13:17.12
6,-3,13:17.12
7,-3,13:17.12
5,-7,14:17.12
6,-7,14:17.12
7,-7,14:17.12
5,-6,14:17.12
7,-6,14:17.12
8,-6,14:17.12
5,-5,14:17.12
8,-5,14:17.12
4,-4,14:17.12
5,-4,14:17.12
6,-4,14:17.12
8,-4,14:17.12
6,-3,14:17.12
7,-3,14:17.12
5,-7,15:17.12
6,-7,15:17.12
7,-7,15:17.12
5,-6,15:17.12
7,-6,15:17.12
8,-6,15:17.12
5,-5,15:17.12
8,-5,15:17.12
4,-4,15:17.12
5,-4,15:17.12
6,-4,15:17.12
8,-4,15:17.12
6,-3,15:17.12
7,-3,15:17.12
8,-3,15:17.12
13,-11,16:18.5
5,-7,16:17.12
6,-7,16:17.12
7,-7,16:17.12
5,-6,16:17.12
7,-6,16:17.12
8,-6,16:17.12
9,-6,16:17.12
5,-5,16:17.12
8,-5,16:17.12
14,-5,16:18.5
5,-4,16:17.12
6,-4,16:17.12
8,-4,16:17.12
12,-4,16:18.13
13,-4,16:18.13
6,-3,16:17.12
7,-3,16:17.12
8,-3,16:17.12
12,-3,16:18.13
12,-1,16:18.13
12,0,16:18.13
0,1,16:18.5
1,1,16:18.5
12,1,16:18.13
6,2,16:18.5
7,3,16:18.5
6,-13,17:18.5
6,-12,17:18.5
7,-12,17:18.5
1,-11,17:18.13
11,-11,17:18.13
12,-11,17:18.5
1,-10,17:18.13
11,-10,17:18.13
12,-10,17:18.13
13,-10,17:18.13
1,-7,17:18.13
5,-7,17:17.12
6,-7,17:17.12
7,-7,17:17.12
10,-7,17:18.13
0,-6,17:18.13
1,-6,17:18.13
5,-6,17:17.12
7,-6,17:17.12
8,-6,17:17.12
9,-6,17:17.12
11,-6,17:18.13
14,-6,17:18.5
15,-6,17:18.5
-1,-5,17:18.5
0,-5,17:18.13
5,-5,17:17.12
8,-5,17:17.12
11,-5,17:18.13
14,-5,17:18.5
-1,-4,17:18.5
5,-4,17:17.12
8,-4,17:17.12
11,-4,17:18.13
12,-4,17:18.13
13,-4,17:18.13
6,-3,17:17.12
7,-3,17:17.12
8,-3,17:17.12
11,-3,17:18.13
12,-3,17:18.13
10,-2,17:18.13
8,-1,17:18.13
12,-1,17:18.13
12,0,17:18.13
1,1,17:18.5
2,1,17:18.13
12,1,17:18.13
6,2,17:18.5
7,2,17:18.5
7,3,17:18.5
6,-13,18:18.5
6,-12,18:18.5
7,-12,18:18.5
1,-11,18:18.13
8,-11,18:18.13
1,-10,18:18.13
7,-10,18:18.13
8,-10,18:18.13
11,-10,18:18.13
12,-10,18:18.13
1,-9,18:18.13
5,-9,18:18.13
6,-9,18:18.13
5,-8,18:18.13
1,-7,18:18.13
2,-7,18:18.13
3,-7,18:18.13
6,-7,18:17.12
7,-7,18:17.12
10,-7,18:18.13
0,-6,18:18.13
1,-6,18:18.13
2,-6,18:18.13
5,-6,18:17.12
7,-6,18:17.12
8,-6,18:17.12
9,-6,18:17.12
10,-6,18:18.13
14,-6,18:18.5
-1,-5,18:18.5
0,-5,18:18.13
2,-5,18:18.13
5,-5,18:17.12
8,-5,18:17.12
11,-5,18:18.13
14,-5,18:18.5
-1,-4,18:18.5
2,-4,18:18.13
3,-4,18:18.13
5,-4,18:17.12
8,-4,18:17.12
11,-4,18:18.13
13,-4,18:18.13
3,-3,18:18.13
6,-3,18:17.12
7,-3,18:17.12
8,-3,18:17.12
11,-3,18:18.13
12,-3,18:18.13
9,-2,18:18.13
10,-2,18:18.13
12,-2,18:18.13
7,-1,18:18.13
8,-1,18:18.13
12,-1,18:18.13
5,0,18:18.13
6,0,18:18.13
12,0,18:18.13
1,1,18:18.5
2,1,18:18.13
3,1,18:18.13
5,1,18:18.13
12,1,18:18.13
6,2,18:18.5
7,2,18:18.5
7,3,18:18.5
8,3,18:18.5
6,-13,19:18.5
6,-12,19:18.5
7,-12,19:18.5
7,-11,19:18.13
8,-11,19:18.13
1,-10,19:18.13
8,-10,19:18.13
9,-10,19:18.13
10,-10,19:18.13
11,-10,19:18.13
12,-10,19:18.13
1,-9,19:18.13
6,-9,19:18.13
7,-9,19:18.13
8,-9,19:18.13
9,-9,19:18.13
1,-8,19:18.13
4,-8,19:18.13
5,-8,19:18.13
6,-8,19:18.13
1,-7,19:18.13
2,-7,19:18.13
3,-7,19:18.13
6,-7,19:17.12
10,-7,19:18.13
0,-6,19:18.13
1,-6,19:18.13
2,-6,19:18.13
5,-6,19:17.12
6,-6,19:17.12
7,-6,19:17.12
8,-6,19:17.12
10,-6,19:18.13
14,-6,19:18.5
15,-6,19:18.5
0,-5,19:18.13
2,-5,19:18.13
3,-5,19:18.13
5,-5,19:17.12
8,-5,19:17.12
10,-5,19:18.13
11,-5,19:18.13
14,-5,19:18.5
-1,-4,19:18.5
3,-4,19:18.13
5,-4,19:17.12
8,-4,19:17.12
11,-4,19:18.13
13,-4,19:18.13
3,-3,19:18.13
6,-3,19:17.12
7,-3,19:17.12
8,-3,19:17.12
10,-3,19:18.13
11,-3,19:18.13
12,-3,19:18.13
4,-2,19:18.13
8,-2,19:18.13
9,-2,19:18.13
10,-2,19:18.13
12,-2,19:18.13
4,-1,19:18.13
7,-1,19:18.13
8,-1,19:18.13
12,-1,19:18.13
5,0,19:18.13
6,0,19:18.13
12,0,19:18.13
1,1,19:18.5
2,1,19:18.13
3,1,19:18.13
4,1,19:18.13
5,1,19:18.13
6,2,19:18.5
7,2,19:18.5
7,3,19:18.5
8,3,19:18.5
6,-12,20:18.5
7,-12,20:18.5
7,-11,20:18.13
8,-11,20:18.13
1,-10,20:18.13
8,-10,20:18.13
9,-10,20:18.13
10,-10,20:18.13
11,-10,20:18.13
12,-10,20:18.13
1,-9,20:18.13
7,-9,20:18.13
8,-9,20:18.13
9,-9,20:18.13
1,-8,20:18.13
5,-8,20:18.13
6,-8,20:18.13
2,-7,20:18.13
3,-7,20:18.13
4,-7,20:18.13
6,-7,20:17.12
9,-7,20:18.13
10,-7,20:18.13
1,-6,20:18.13
2,-6,20:18.13
3,-6,20:18.13
5,-6,20:17.12
6,-6,20:17.12
7,-6,20:17.12
8,-6,20:17.12
10,-6,20:18.13
14,-6,20:18.5
0,-5,20:18.5
3,-5,20:18.13
5,-5,20:17.12
8,-5,20:17.12
9,-5,20:17.12
10,-5,20:18.13
14,-5,20:18.5
-1,-4,20:18.5
3,-4,20:18.13
5,-4,20:17.12
8,-4,20:17.12
10,-4,20:18.13
11,-4,20:18.13
12,-4,20:18.13
13,-4,20:18.13
3,-3,20:18.13
4,-3,20:18.13
6,-3,20:17.12
7,-3,20:17.12
8,-3,20:17.12
10,-3,20:18.13
11,-3,20:18.13
12,-3,20:18.13
4,-2,20:18.13
8,-2,20:18.13
9,-2,20:18.13
11,-2,20:18.13
12,-2,20:18.13
4,-1,20:18.13
5,-1,20:18.13
6,-1,20:18.13
7,-1,20:18.13
8,-1,20:18.13
12,-1,20:18.13
4,0,20:18.13
5,0,20:18.13
6,0,20:18.13
12,0,20:18.13
2,1,20:18.13
3,1,20:18.13
4,1,20:18.13
5,1,20:18.13
6,2,20:18.5
7,2,20:18.5
7,3,20:18.5
8,3,20:18.5
6,-12,21:18.5
7,-11,21:18.13
8,-11,21:18.13
8,-10,21:18.13
9,-10,21:18.13
10,-10,21:18.13
11,-10,21:18.13
12,-10,21:18.13
1,-9,21:18.13
2,-9,21:18.13
8,-9,21:18.13
9,-9,21:18.13
1,-8,21:18.13
2,-8,21:18.13
6,-8,21:18.13
7,-8,21:18.13
2,-7,21:18.13
4,-7,21:18.13
5,-7,21:18.13
6,-7,21:17.12
9,-7,21:18.13
1,-6,21:18.13
2,-6,21:18.13
3,-6,21:18.13
6,-6,21:17.12
7,-6,21:17.12
8,-6,21:17.12
9,-6,21:18.13
10,-6,21:18.13
14,-6,21:18.5
0,-5,21:18.5
1,-5,21:18.13
3,-5,21:18.13
5,-5,21:17.12
8,-5,21:17.12
9,-5,21:17.12
10,-5,21:18.13
14,-5,21:18.5
-1,-4,21:18.5
0,-4,21:18.5
3,-4,21:18.13
4,-4,21:18.13
5,-4,21:17.12
8,-4,21:17.12
10,-4,21:18.13
12,-4,21:18.13
13,-4,21:18.13
4,-3,21:18.13
6,-3,21:17.12
7,-3,21:17.12
8,-3,21:17.12
9,-3,21:18.13
10,-3,21:18.13
11,-3,21:18.13
4,-2,21:18.13
5,-2,21:18.13
8,-2,21:18.13
9,-2,21:18.13
11,-2,21:18.13
5,-1,21:18.13
6,-1,21:18.13
7,-1,21:18.13
12,-1,21:18.13
4,0,21:18.13
5,0,21:18.13
12,0,21:18.13
2,1,21:18.13
3,1,21:18.13
4,1,21:18.13
5,1,21:18.13
6,1,21:18.13
12,1,21:18.13
6,2,21:18.5
7,2,21:18.5
7,3,21:18.5
8,3,21:18.5
14,3,21:18.5
15,3,21:18.5
8,6,21:18.5
7,7,21:18.5
-2,-14,22:18.5
-1,-14,22:18.5
6,-12,22:18.5
7,-11,22:18.13
8,-11,22:18.13
2,-10,22:18.13
8,-10,22:18.13
10,-10,22:18.13
11,-10,22:18.13
12,-10,22:18.13
2,-9,22:18.13
8,-9,22:18.13
9,-9,22:18.13
10,-9,22:18.13
2,-8,22:18.13
6,-8,22:18.13
7,-8,22:18.13
8,-8,22:18.13
2,-7,22:18.13
3,-7,22:18.13
4,-7,22:18.13
5,-7,22:18.13
6,-7,22:18.13
9,-7,22:18.13
2,-6,22:18.13
3,-6,22:18.13
4,-6,22:18.13
6,-6,22:17.12
7,-6,22:17.12
8,-6,22:17.12
9,-6,22:18.13
0,-5,22:18.5
1,-5,22:18.13
2,-5,22:18.13
3,-5,22:18.13
4,-5,22:18.13
5,-5,22:17.12
8,-5,22:17.12
9,-5,22:18.13
10,-5,22:18.13
13,-5,22:18.13
14,-5,22:18.5
-1,-4,22:18.5
0,-4,22:18.5
4,-4,22:18.13
5,-4,22:17.12
8,-4,22:17.12
10,-4,22:18.13
11,-4,22:18.13
12,-4,22:18.13
13,-4,22:18.13
4,-3,22:18.13
5,-3,22:18.13
6,-3,22:17.12
7,-3,22:17.12
8,-3,22:17.12
9,-3,22:18.13
10,-3,22:18.13
11,-3,22:18.13
5,-2,22:18.13
7,-2,22:18.13
8,-2,22:18.13
9,-2,22:18.13
11,-2,22:18.13
5,-1,22:18.13
6,-1,22:18.13
7,-1,22:18.13
11,-1,22:18.13
12,-1,22:18.13
4,0,22:18.13
5,0,22:18.13
6,0,22:18.13
12,0,22:18.13
1,1,22:18.5
2,1,22:18.13
3,1,22:18.13
6,1,22:18.13
12,1,22:18.13
6,2,22:18.5
7,2,22:18.5
11,2,22:18.5
7,3,22:18.5
11,3,22:18.5
12,3,22:18.5
13,3,22:18.5
14,3,22:18.5
15,3,22:18.5
16,3,22:18.5
7,6,22:18.5
8,6,22:18.5
6,7,22:18.5
7,7,22:18.5
-2,-14,23:18.5
-3,-12,23:18.5
-2,-12,23:18.5
-1,-12,23:18.5
0,-12,23:18.5
1,-12,23:18.5
3,-12,23:18.5
6,-12,23:18.5
2,-11,23:18.13
3,-11,23:18.13
6,-11,23:18.13
7,-11,23:18.13
2,-10,23:18.13
7,-10,23:18.13
8,-10,23:18.13
11,-10,23:18.13
2,-9,23:18.13
8,-9,23:18.13
9,-9,23:18.13
10,-9,23:18.13
11,-9,23:18.13
12,-9,23:18.13
13,-9,23:18.13
2,-8,23:18.13
7,-8,23:18.13
8,-8,23:18.13
2,-7,23:18.13
3,-7,23:18.13
5,-7,23:18.13
6,-7,23:18.13
7,-7,23:18.13
8,-7,23:18.13
9,-7,23:18.13
3,-6,23:18.13
4,-6,23:18.13
5,-6,23:18.13
6,-6,23:17.12
7,-6,23:17.12
8,-6,23:17.12
9,-6,23:18.13
0,-5,23:18.5
1,-5,23:18.13
2,-5,23:18.13
3,-5,23:18.13
4,-5,23:18.13
5,-5,23:17.12
6,-5,23:17.12
8,-5,23:17.12
9,-5,23:18.13
13,-5,23:18.13
14,-5,23:18.5
0,-4,23:18.5
4,-4,23:18.13
5,-4,23:17.12
8,-4,23:17.12
9,-4,23:18.13
10,-4,23:18.13
11,-4,23:18.13
12,-4,23:18.13
13,-4,23:18.13
4,-3,23:18.13
5,-3,23:18.13
6,-3,23:17.12
7,-3,23:17.12
8,-3,23:17.12
9,-3,23:18.13
10,-3,23:18.13
5,-2,23:18.13
7,-2,23:18.13
8,-2,23:18.13
10,-2,23:18.13
11,-2,23:18.13
5,-1,23:18.13
6,-1,23:18.13
11,-1,23:18.13
1,0,23:18.13
3,0,23:18.13
4,0,23:18.13
6,0,23:18.13
12,0,23:18.13
2,1,23:18.13
3,1,23:18.13
6,1,23:18.13
11,1,23:18.13
12,1,23:18.13
6,2,23:18.13
7,2,23:18.13
11,2,23:18.13
10,3,23:18.5
11,3,23:18.5
12,3,23:18.5
13,3,23:18.5
14,3,23:18.5
15,3,23:18.5
16,3,23:18.5
8,5,23:18.5
9,5,23:18.5
7,6,23:18.5
8,6,23:18.5
6,7,23:18.5
7,7,23:18.5
5,-14,24:18.5
-2,-12,24:18.5
-1,-12,24:18.5
0,-12,24:18.5
1,-12,24:18.5
2,-12,24:18.5
3,-12,24:18.5
-3,-11,24:18.5
3,-11,24:18.13
6,-11,24:18.13
7,-11,24:18.13
2,-10,24:18.13
7,-10,24:18.13
2,-9,24:18.13
7,-9,24:18.13
8,-9,24:18.13
10,-9,24:18.13
11,-9,24:18.13
12,-9,24:18.13
1,-8,24:18.13
2,-8,24:18.13
3,-8,24:18.13
8,-8,24:18.13
3,-7,24:18.13
6,-7,24:18.13
7,-7,24:18.13
8,-7,24:18.13
3,-6,24:18.13
4,-6,24:18.13
5,-6,24:18.13
6,-6,24:17.12
7,-6,24:17.12
8,-6,24:18.13
9,-6,24:18.13
1,-5,24:18.13
2,-5,24:18.13
3,-5,24:18.13
4,-5,24:18.13
5,-5,24:17.12
6,-5,24:17.12
8,-5,24:17.12
9,-5,24:18.13
13,-5,24:18.13
0,-4,24:18.5
1,-4,24:18.13
4,-4,24:18.13
5,-4,24:17.12
8,-4,24:17.12
9,-4,24:18.13
10,-4,24:18.13
11,-4,24:18.13
12,-4,24:18.13
13,-4,24:18.13
5,-3,24:18.13
6,-3,24:17.12
7,-3,24:17.12
8,-3,24:17.12
9,-3,24:18.13
10,-3,24:18.13
5,-2,24:18.13
6,-2,24:18.13
7,-2,24:18.13
8,-2,24:18.13
10,-2,24:18.13
11,-2,24:18.13
13,-2,24:18.13
5,-1,24:18.13
6,-1,24:18.13
11,-1,24:18.13
12,-1,24:18.13
2,0,24:18.13
3,0,24:18.13
4,0,24:18.13
6,0,24:18.13
11,0,24:18.13
12,0,24:18.13
2,1,24:18.13
4,1,24:18.13
6,1,24:18.13
7,1,24:18.13
11,1,24:18.13
12,1,24:18.13
7,2,24:18.13
8,2,24:18.13
9,2,24:18.13
10,2,24:18.13
11,2,24:18.13
16,2,24:18.5
10,3,24:18.5
11,3,24:18.5
12,3,24:18.5
13,3,24:18.5
14,3,24:18.5
15,3,24:18.5
9,4,24:18.5
10,4,24:18.5
8,5,24:18.5
9,5,24:18.5
7,6,24:18.5
8,6,24:18.5
7,7,24:18.5
5,-14,25:18.5
6,-14,25:18.5
4,-13,25:18.5
5,-13,25:18.5
0,-12,25:18.5
1,-12,25:18.5
2,-12,25:18.5
3,-12,25:18.5
4,-12,25:18.5
-2,-11,25:18.5
-1,-11,25:18.5
0,-11,25:18.5
3,-11,25:18.13
4,-11,25:18.13
5,-11,25:18.13
6,-11,25:18.13
7,-11,25:18.13
2,-10,25:18.13
3,-10,25:18.13
7,-10,25:18.13
9,-10,25:18.13
10,-10,25:18.13
2,-9,25:18.13
7,-9,25:18.13
10,-9,25:18.13
11,-9,25:18.13
12,-9,25:18.13
1,-8,25:18.13
2,-8,25:18.13
3,-8,25:18.13
7,-8,25:18.13
8,-8,25:18.13
10,-8,25:18.13
1,-7,25:18.13
3,-7,25:18.13
7,-7,25:18.13
8,-7,25:18.13
1,-6,25:18.13
4,-6,25:18.13
5,-6,25:18.13
6,-6,25:18.13
7,-6,25:17.12
8,-6,25:18.13
2,-5,25:18.13
3,-5,25:18.13
4,-5,25:18.13
5,-5,25:18.13
6,-5,25:17.12
8,-5,25:17.12
9,-5,25:18.13
13,-5,25:18.13
0,-4,25:18.5
1,-4,25:18.13
2,-4,25:18.13
5,-4,25:18.13
8,-4,25:17.12
9,-4,25:18.13
10,-4,25:18.13
11,-4,25:18.13
12,-4,25:18.13
5,-3,25:18.13
6,-3,25:17.12
7,-3,25:17.12
8,-3,25:18.13
9,-3,25:18.13
10,-3,25:18.13
6,-2,25:18.13
7,-2,25:18.13
10,-2,25:18.13
13,-2,25:18.13
4,-1,25:18.13
5,-1,25:18.13
6,-1,25:18.13
10,-1,25:18.13
11,-1,25:18.13
12,-1,25:18.13
2,0,25:18.13
3,0,25:18.13
4,0,25:18.13
6,0,25:18.13
7,0,25:18.13
11,0,25:18.13
12,0,25:18.13
3,1,25:18.13
4,1,25:18.13
5,1,25:18.13
7,1,25:18.13
11,1,25:18.13
7,2,25:18.13
8,2,25:18.13
9,2,25:18.13
10,2,25:18.13
11,2,25:18.13
15,2,25:18.5
16,2,25:18.5
10,3,25:18.5
11,3,25:18.5
12,3,25:18.5
13,3,25:18.5
14,3,25:18.5
9,4,25:18.5
10,4,25:18.5
8,5,25:18.5
9,5,25:18.5
7,6,25:18.5
6,-14,26:18.5
5,-13,26:18.5
4,-12,26:18.5
-2,-11,26:18.5
-1,-11,26:18.5
0,-11,26:18.5
1,-11,26:18.5
2,-11,26:18.5
3,-11,26:18.5
4,-11,26:18.5
5,-11,26:18.5
6,-11,26:18.5
3,-10,26:18.13
6,-10,26:18.13
7,-10,26:18.13
9,-10,26:18.13
10,-10,26:18.13
2,-9,26:18.13
3,-9,26:18.13
7,-9,26:18.13
10,-9,26:18.13
11,-9,26:18.13
2,-8,26:18.13
3,-8,26:18.13
7,-8,26:18.13
10,-8,26:18.13
11,-8,26:18.13
1,-7,26:18.13
2,-7,26:18.13
3,-7,26:18.13
4,-7,26:18.13
7,-7,26:18.13
8,-7,26:18.13
9,-7,26:18.13
1,-6,26:18.13
4,-6,26:18.13
6,-6,26:18.13
7,-6,26:18.13
8,-6,26:18.13
3,-5,26:18.13
4,-5,26:18.13
5,-5,26:18.13
6,-5,26:17.12
8,-5,26:17.12
9,-5,26:17.12
12,-5,26:18.13
13,-5,26:18.13
1,-4,26:18.13
2,-4,26:18.13
3,-4,26:18.13
5,-4,26:18.13
6,-4,26:17.12
8,-4,26:17.12
9,-4,26:18.13
10,-4,26:18.13
11,-4,26:18.13
12,-4,26:18.13
5,-3,26:18.13
6,-3,26:17.12
7,-3,26:17.12
8,-3,26:18.13
9,-3,26:18.13
13,-3,26:18.13
5,-2,26:18.13
6,-2,26:18.13
7,-2,26:18.13
10,-2,26:18.13
12,-2,26:18.13
13,-2,26:18.13
4,-1,26:18.13
5,-1,26:18.13
6,-1,26:18.13
7,-1,26:18.13
10,-1,26:18.13
11,-1,26:18.13
12,-1,26:18.13
-1,0,26:18.5
0,0,26:18.5
1,0,26:18.13
2,0,26:18.13
3,0,26:18.13
7,0,26:18.13
11,0,26:18.13
3,1,26:18.13
4,1,26:18.13
5,1,26:18.13
6,1,26:18.13
7,1,26:18.13
10,1,26:18.13
11,1,26:18.13
7,2,26:18.13
8,2,26:18.13
9,2,26:18.13
10,2,26:18.13
11,2,26:18.13
13,2,26:18.5
14,2,26:18.5
15,2,26:18.5
16,2,26:18.5
10,3,26:18.5
11,3,26:18.5
12,3,26:18.5
13,3,26:18.5
-1,4,26:18.5
9,4,26:18.5
8,5,26:18.5
7,6,26:18.5
6,-14,27:18.5
7,-14,27:18.5
5,-13,27:18.5
6,-13,27:18.5
15,-13,27:18.5
4,-12,27:18.5
5,-12,27:18.5
15,-12,27:18.5
-2,-11,27:18.5
-1,-11,27:18.5
0,-11,27:18.5
1,-11,27:18.5
2,-11,27:18.5
3,-11,27:18.5
4,-11,27:18.5
6,-11,27:18.5
15,-11,27:18.5
3,-10,27:18.13
4,-10,27:18.13
5,-10,27:18.13
6,-10,27:18.13
7,-10,27:18.13
8,-10,27:18.13
3,-9,27:18.13
7,-9,27:18.13
9,-9,27:18.13
10,-9,27:18.13
11,-9,27:18.13
12,-9,27:18.13
13,-9,27:18.13
2,-8,27:18.13
3,-8,27:18.13
7,-8,27:18.13
10,-8,27:18.13
11,-8,27:18.13
13,-8,27:18.13
14,-8,27:18.5
15,-8,27:18.5
2,-7,27:18.13
4,-7,27:18.13
7,-7,27:18.13
8,-7,27:18.13
9,-7,27:18.13
10,-7,27:18.13
1,-6,27:18.13
2,-6,27:18.13
4,-6,27:18.13
5,-6,27:18.13
6,-6,27:17.12
7,-6,27:18.13
8,-6,27:18.13
-6,-5,27:18.5
1,-5,27:18.13
4,-5,27:18.13
5,-5,27:18.13
6,-5,27:18.13
7,-5,27:17.12
8,-5,27:17.12
9,-5,27:17.12
12,-5,27:18.13
13,-5,27:18.13
14,-5,27:18.5
18,-5,27:18.5
19,-5,27:18.5
-5,-4,27:18.5
1,-4,27:18.13
2,-4,27:18.13
3,-4,27:18.13
4,-4,27:18.13
5,-4,27:18.13
6,-4,27:18.13
8,-4,27:17.12
9,-4,27:18.13
10,-4,27:18.13
11,-4,27:18.13
19,-4,27:18.5
20,-4,27:18.5
-4,-3,27:18.5
0,-3,27:18.5
6,-3,27:18.13
7,-3,27:18.13
8,-3,27:18.13
9,-3,27:18.13
13,-3,27:18.13
20,-3,27:18.5
5,-2,27:18.13
6,-2,27:18.13
7,-2,27:18.13
8,-2,27:17.12
9,-2,27:18.13
10,-2,27:18.13
12,-2,27:18.13
-1,-1,27:18.5
3,-1,27:18.13
4,-1,27:18.13
5,-1,27:18.13
7,-1,27:18.13
10,-1,27:18.13
11,-1,27:18.13
12,-1,27:18.13
-1,0,27:18.5
0,0,27:18.5
1,0,27:18.13
2,0,27:18.13
3,0,27:18.13
4,0,27:18.13
7,0,27:18.13
10,0,27:18.13
11,0,27:18.13
-1,1,27:18.5
4,1,27:18.13
5,1,27:18.13
6,1,27:18.13
7,1,27:18.13
8,1,27:18.13
10,1,27:18.13
-1,2,27:18.5
8,2,27:18.13
9,2,27:18.13
10,2,27:18.13
11,2,27:18.13
12,2,27:18.13
13,2,27:18.5
14,2,27:18.5
15,2,27:18.5
-1,3,27:18.5
9,3,27:18.5
10,3,27:18.5
12,3,27:18.5
-1,4,27:18.5
8,4,27:18.5
9,4,27:18.5
-1,5,27:18.5
8,5,27:18.5
5,-13,28:18.5
6,-13,28:18.5
15,-13,28:18.5
5,-12,28:18.5
15,-12,28:18.5
-1,-11,28:18.5
0,-11,28:18.5
1,-11,28:18.5
2,-11,28:18.5
3,-11,28:18.5
4,-11,28:18.5
15,-11,28:18.5
-1,-10,28:18.5
3,-10,28:18.13
4,-10,28:18.13
5,-10,28:18.13
6,-10,28:18.13
7,-10,28:18.13
15,-10,28:18.5
3,-9,28:18.13
4,-9,28:18.13
6,-9,28:18.13
7,-9,28:18.13
8,-9,28:18.13
9,-9,28:18.13
10,-9,28:18.13
11,-9,28:18.13
15,-9,28:18.5
3,-8,28:18.13
4,-8,28:18.13
7,-8,28:18.13
11,-8,28:18.13
12,-8,28:18.13
13,-8,28:18.13
14,-8,28:18.5
15,-8,28:18.5
2,-7,28:18.13
3,-7,28:18.13
4,-7,28:18.13
7,-7,28:18.13
9,-7,28:18.13
10,-7,28:18.13
11,-7,28:18.13
2,-6,28:18.13
5,-6,28:18.13
6,-6,28:17.12
7,-6,28:18.13
8,-6,28:18.13
9,-6,28:18.13
14,-6,28:18.5
17,-6,28:18.5
-6,-5,28:18.5
1,-5,28:18.13
2,-5,28:18.13
5,-5,28:18.13
6,-5,28:18.13
7,-5,28:18.13
8,-5,28:17.12
11,-5,28:18.13
12,-5,28:18.13
13,-5,28:18.13
14,-5,28:18.5
18,-5,28:18.5
-5,-4,28:18.5
1,-4,28:18.13
2,-4,28:18.13
3,-4,28:18.13
4,-4,28:18.13
5,-4,28:18.13
6,-4,28:18.13
8,-4,28:18.13
9,-4,28:18.13
10,-4,28:18.13
11,-4,28:18.13
13,-4,28:18.13
18,-4,28:18.5
19,-4,28:18.5
-4,-3,28:18.5
-3,-3,28:18.5
0,-3,28:18.5
2,-3,28:18.13
6,-3,28:18.13
7,-3,28:18.13
8,-3,28:18.13
9,-3,28:18.13
12,-3,28:18.13
13,-3,28:18.13
-3,-2,28:18.5
-2,-2,28:18.5
0,-2,28:18.5
5,-2,28:18.13
6,-2,28:18.13
7,-2,28:18.13
8,-2,28:17.12
9,-2,28:18.13
12,-2,28:18.13
-1,-1,28:18.5
0,-1,28:18.5
3,-1,28:18.13
4,-1,28:18.13
7,-1,28:18.13
10,-1,28:18.13
11,-1,28:18.13
-1,0,28:18.5
0,0,28:18.5
1,0,28:18.13
2,0,28:18.13
3,0,28:18.13
4,0,28:18.13
5,0,28:18.13
7,0,28:18.13
10,0,28:18.13
11,0,28:18.13
-1,1,28:18.5
5,1,28:18.13
6,1,28:18.13
7,1,28:18.13
8,1,28:18.13
9,1,28:18.13
10,1,28:18.13
-1,2,28:18.5
8,2,28:18.13
9,2,28:18.13
10,2,28:18.13
11,2,28:18.13
12,2,28:18.13
13,2,28:18.5
14,2,28:18.5
15,2,28:18.5
-1,3,28:18.5
9,3,28:18.5
-1,4,28:18.5
0,4,28:18.5
8,4,28:18.5
9,4,28:18.5
8,5,28:18.5
6,-13,29:18.5
7,-13,29:18.5
14,-13,29:18.5
5,-12,29:18.5
14,-12,29:18.5
15,-12,29:18.5
2,-11,29:18.5
5,-11,29:18.5
15,-11,29:18.5
-1,-10,29:18.5
0,-10,29:18.5
1,-10,29:18.5
2,-10,29:18.13
3,-10,29:18.13
4,-10,29:18.13
5,-10,29:18.13
6,-10,29:18.13
15,-10,29:18.5
4,-9,29:18.13
5,-9,29:18.13
6,-9,29:18.13
7,-9,29:18.13
8,-9,29:18.13
9,-9,29:18.13
15,-9,29:18.5
3,-8,29:18.13
4,-8,29:18.13
6,-8,29:18.13
7,-8,29:18.13
10,-8,29:18.13
11,-8,29:18.13
12,-8,29:18.13
13,-8,29:18.13
14,-8,29:18.5
15,-8,29:18.5
3,-7,29:18.13
4,-7,29:18.13
5,-7,29:18.13
7,-7,29:18.13
10,-7,29:18.13
11,-7,29:18.13
14,-7,29:18.5
15,-7,29:18.5
16,-7,29:18.5
2,-6,29:18.13
3,-6,29:18.13
5,-6,29:18.13
6,-6,29:17.12
7,-6,29:18.13
8,-6,29:18.13
9,-6,29:18.13
10,-6,29:18.13
14,-6,29:18.5
16,-6,29:18.5
17,-6,29:18.5
2,-5,29:18.13
5,-5,29:18.13
6,-5,29:18.13
7,-5,29:18.13
8,-5,29:18.13
11,-5,29:18.13
12,-5,29:18.13
13,-5,29:18.13
17,-5,29:18.5
18,-5,29:18.5
-5,-4,29:18.5
-4,-4,29:18.5
1,-4,29:18.5
2,-4,29:18.13
3,-4,29:18.13
4,-4,29:18.13
5,-4,29:18.13
6,-4,29:18.13
8,-4,29:18.13
9,-4,29:18.13
10,-4,29:18.13
12,-4,29:18.13
13,-4,29:18.13
18,-4,29:18.5
-4,-3,29:18.5
-3,-3,29:18.5
2,-3,29:18.13
3,-3,29:18.13
6,-3,29:18.13
7,-3,29:18.13
8,-3,29:18.13
9,-3,29:18.13
12,-3,29:18.13
-3,-2,29:18.5
-2,-2,29:18.5
0,-2,29:18.5
1,-2,29:18.5
4,-2,29:18.13
5,-2,29:18.13
6,-2,29:18.13
7,-2,29:18.13
8,-2,29:17.12
9,-2,29:18.13
11,-2,29:18.13
12,-2,29:18.13
-2,-1,29:18.5
-1,-1,29:18.5
0,-1,29:18.5
1,-1,29:18.5
3,-1,29:18.13
4,-1,29:18.13
7,-1,29:18.13
9,-1,29:18.13
10,-1,29:18.13
11,-1,29:18.13
-1,0,29:18.5
2,0,29:18.13
3,0,29:18.13
4,0,29:18.13
5,0,29:18.13
6,0,29:18.13
8,0,29:18.13
10,0,29:18.13
-1,1,29:18.5
6,1,29:18.13
7,1,29:18.13
8,1,29:18.13
9,1,29:18.13
10,1,29:18.13
-1,2,29:18.5
0,2,29:18.5
9,2,29:18.13
10,2,29:18.13
11,2,29:18.13
12,2,29:18.13
13,2,29:18.5
14,2,29:18.5
0,3,29:18.5
9,3,29:18.5
0,4,29:18.5
8,4,29:18.5
9,4,29:18.5
0,5,29:18.5
8,5,29:18.5
6,-13,30:18.5
7,-13,30:18.5
14,-13,30:18.5
5,-12,30:18.5
6,-12,30:18.5
14,-12,30:18.5
5,-11,30:18.5
14,-11,30:18.5
0,-10,30:18.5
1,-10,30:18.5
2,-10,30:18.13
3,-10,30:18.13
5,-10,30:18.13
14,-10,30:18.5
15,-10,30:18.5
4,-9,30:18.13
5,-9,30:18.13
6,-9,30:18.13
7,-9,30:18.13
14,-9,30:18.5
15,-9,30:18.5
4,-8,30:18.13
7,-8,30:18.13
8,-8,30:18.13
10,-8,30:18.13
11,-8,30:18.13
12,-8,30:18.13
14,-8,30:18.5
15,-8,30:18.5
3,-7,30:18.13
4,-7,30:18.13
5,-7,30:18.13
7,-7,30:18.13
12,-7,30:18.13
13,-7,30:18.13
14,-7,30:18.5
15,-7,30:18.5
3,-6,30:18.13
5,-6,30:18.13
6,-6,30:17.12
7,-6,30:18.13
9,-6,30:18.13
10,-6,30:18.13
13,-6,30:18.13
14,-6,30:18.5
16,-6,30:18.5
2,-5,30:18.13
3,-5,30:18.13
6,-5,30:18.13
7,-5,30:18.13
8,-5,30:18.13
9,-5,30:18.13
13,-5,30:18.13
17,-5,30:18.5
-4,-4,30:18.5
2,-4,30:18.13
5,-4,30:18.13
6,-4,30:18.13
7,-4,30:18.13
8,-4,30:18.13
9,-4,30:18.13
12,-4,30:18.13
18,-4,30:18.5
-3,-3,30:18.5
2,-3,30:18.13
4,-3,30:18.13
6,-3,30:18.13
7,-3,30:18.13
8,-3,30:18.13
11,-3,30:18.13
12,-3,30:18.13
-2,-2,30:18.5
1,-2,30:18.5
4,-2,30:18.13
5,-2,30:18.13
7,-2,30:18.13
8,-2,30:18.13
9,-2,30:18.13
11,-2,30:18.13
-1,-1,30:18.5
0,-1,30:18.5
1,-1,30:18.5
2,-1,30:18.13
3,-1,30:18.13
8,-1,30:18.13
9,-1,30:18.13
10,-1,30:18.13
11,-1,30:18.13
0,0,30:18.5
3,0,30:18.13
4,0,30:18.13
5,0,30:18.13
6,0,30:18.13
7,0,30:18.13
10,0,30:18.13
0,1,30:18.5
8,1,30:18.13
9,1,30:18.13
10,1,30:18.13
11,1,30:18.13
0,2,30:18.5
9,2,30:18.13
11,2,30:18.13
12,2,30:18.13
13,2,30:18.5
14,2,30:18.5
0,3,30:18.5
9,3,30:18.5
0,4,30:18.5
8,4,30:18.5
7,-13,31:18.5
6,-12,31:18.5
7,-12,31:18.5
14,-12,31:18.5
5,-11,31:18.5
6,-11,31:18.5
14,-11,31:18.5
0,-10,31:18.5
1,-10,31:18.5
2,-10,31:18.13
3,-10,31:18.13
5,-10,31:18.13
14,-10,31:18.5
3,-9,31:18.13
4,-9,31:18.13
5,-9,31:18.13
14,-9,31:18.5
4,-8,31:18.13
5,-8,31:18.13
6,-8,31:18.13
7,-8,31:18.13
8,-8,31:18.13
10,-8,31:18.13
14,-8,31:18.5
4,-7,31:18.13
10,-7,31:18.13
11,-7,31:18.13
12,-7,31:18.13
13,-7,31:18.13
14,-7,31:18.5
3,-6,31:18.13
4,-6,31:18.13
7,-6,31:18.13
13,-6,31:18.13
14,-6,31:18.5
15,-6,31:18.5
16,-6,31:18.5
3,-5,31:18.13
6,-5,31:17.12
7,-5,31:17.12
8,-5,31:17.12
9,-5,31:18.13
12,-5,31:18.13
13,-5,31:18.13
16,-5,31:18.5
17,-5,31:18.5
2,-4,31:18.13
3,-4,31:18.13
6,-4,31:17.12
7,-4,31:18.13
8,-4,31:17.12
12,-4,31:18.13
-3,-3,31:18.5
-2,-3,31:18.5
2,-3,31:18.13
6,-3,31:17.12
7,-3,31:18.13
8,-3,31:17.12
11,-3,31:18.13
12,-3,31:18.13
-2,-2,31:18.5
-1,-2,31:18.5
1,-2,31:18.5
7,-2,31:18.13
8,-2,31:17.12
11,-2,31:18.13
0,-1,31:18.5
1,-1,31:18.5
2,-1,31:18.13
3,-1,31:18.13
4,-1,31:18.13
10,-1,31:18.13
0,0,31:18.5
4,0,31:18.13
5,0,31:18.13
6,0,31:18.13
7,0,31:18.13
8,0,31:18.13
9,0,31:18.13
10,0,31:18.13
0,1,31:18.5
9,1,31:18.13
10,1,31:18.13
11,1,31:18.13
0,2,31:18.5
9,2,31:18.13
11,2,31:18.13
12,2,31:18.13
13,2,31:18.5
0,3,31:18.5
8,3,31:18.5
9,3,31:18.5
0,4,31:18.5
8,4,31:18.5
7,-13,32:18.5
8,-13,32:18.5
6,-12,32:18.5
7,-12,32:18.5
14,-12,32:18.5
6,-11,32:18.5
14,-11,32:18.5
1,-10,32:18.5
2,-10,32:18.13
5,-10,32:18.13
6,-10,32:18.13
14,-10,32:18.5
2,-9,32:18.13
3,-9,32:18.13
4,-9,32:18.13
5,-9,32:18.13
14,-9,32:18.5
4,-8,32:18.13
5,-8,32:18.13
6,-8,32:18.13
7,-8,32:18.13
8,-8,32:18.13
14,-8,32:18.5
4,-7,32:18.13
5,-7,32:18.13
8,-7,32:18.13
9,-7,32:18.13
10,-7,32:18.13
11,-7,32:18.13
12,-7,32:18.13
13,-7,32:18.5
14,-7,32:18.5
4,-6,32:18.13
13,-6,32:18.5
14,-6,32:18.5
15,-6,32:18.5
3,-5,32:18.13
4,-5,32:18.13
6,-5,32:17.12
7,-5,32:17.12
8,-5,32:17.12
12,-5,32:18.13
16,-5,32:18.5
3,-4,32:18.13
6,-4,32:17.12
7,-4,32:18.13
8,-4,32:17.12
11,-4,32:18.13
12,-4,32:18.13
17,-4,32:18.5
-2,-3,32:18.5
2,-3,32:18.13
6,-3,32:17.12
7,-3,32:17.12
8,-3,32:17.12
11,-3,32:18.13
-1,-2,32:18.5
0,-2,32:18.5
1,-2,32:18.5
2,-2,32:18.13
8,-2,32:17.12
10,-2,32:18.13
11,-2,32:18.13
1,-1,32:18.5
2,-1,32:18.13
3,-1,32:18.13
4,-1,32:18.13
5,-1,32:18.13
10,-1,32:18.13
1,0,32:18.5
5,0,32:18.13
6,0,32:18.13
7,0,32:18.13
8,0,32:18.13
9,0,32:18.13
0,1,32:18.5
9,1,32:18.13
10,1,32:18.13
11,1,32:18.13
12,1,32:18.13
0,2,32:18.5
1,2,32:18.5
9,2,32:18.13
12,2,32:18.13
1,3,32:18.5
8,3,32:18.5
8,4,32:18.5
7,-12,33:18.5
6,-11,33:18.5
6,-10,33:18.13
13,-10,33:18.5
14,-10,33:18.5
2,-9,33:18.13
3,-9,33:18.13
5,-9,33:18.13
6,-9,33:18.13
14,-9,33:18.5
4,-8,33:18.13
5,-8,33:18.13
6,-8,33:18.13
13,-8,33:18.5
14,-8,33:18.5
5,-7,33:18.13
6,-7,33:18.13
7,-7,33:18.13
8,-7,33:18.13
9,-7,33:18.13
10,-7,33:18.13
11,-7,33:18.13
13,-7,33:18.5
4,-6,33:18.13
5,-6,33:18.13
11,-6,33:18.13
12,-6,33:18.13
13,-6,33:18.5
14,-6,33:18.5
15,-6,33:18.5
4,-5,33:18.13
6,-5,33:17.12
7,-5,33:17.12
8,-5,33:17.12
12,-5,33:18.13
15,-5,33:18.5
16,-5,33:18.5
-3,-4,33:18.5
3,-4,33:18.13
6,-4,33:17.12
8,-4,33:17.12
11,-4,33:18.13
12,-4,33:18.13
16,-4,33:18.5
17,-4,33:18.5
-2,-3,33:18.5
-1,-3,33:18.5
3,-3,33:18.13
6,-3,33:17.12
7,-3,33:17.12
8,-3,33:17.12
11,-3,33:18.13
17,-3,33:18.5
-1,-2,33:18.5
0,-2,33:18.5
1,-2,33:18.5
2,-2,33:18.13
8,-2,33:17.12
10,-2,33:18.13
2,-1,33:18.13
3,-1,33:18.13
4,-1,33:18.13
5,-1,33:18.13
6,-1,33:18.13
7,-1,33:18.13
9,-1,33:18.13
10,-1,33:18.13
1,0,33:18.5
7,0,33:18.13
8,0,33:18.13
9,0,33:18.13
10,0,33:18.13
1,1,33:18.5
9,1,33:18.13
10,1,33:18.13
11,1,33:18.13
12,1,33:18.13
1,2,33:18.5
8,2,33:18.13
1,3,33:18.5
8,3,33:18.5
7,4,33:18.5
8,4,33:18.5
6,-11,34:18.5
7,-11,34:18.5
6,-10,34:18.13
13,-10,34:18.5
2,-9,34:18.13
3,-9,34:18.13
6,-9,34:18.13
13,-9,34:18.5
3,-8,34:18.13
4,-8,34:18.13
5,-8,34:18.13
6,-8,34:18.13
13,-8,34:18.5
5,-7,34:18.13
6,-7,34:18.13
7,-7,34:18.13
8,-7,34:18.13
9,-7,34:18.13
13,-7,34:18.5
5,-6,34:18.13
9,-6,34:18.13
10,-6,34:18.13
11,-6,34:18.13
12,-6,34:18.13
13,-6,34:18.5
4,-5,34:18.13
6,-5,34:17.12
7,-5,34:17.12
8,-5,34:17.12
11,-5,34:18.13
12,-5,34:18.13
13,-5,34:18.5
14,-5,34:18.5
15,-5,34:18.5
-3,-4,34:18.5
-2,-4,34:18.5
4,-4,34:18.13
6,-4,34:17.12
8,-4,34:17.12
11,-4,34:18.13
16,-4,34:18.5
-2,-3,34:18.5
-1,-3,34:18.5
3,-3,34:18.13
6,-3,34:17.12
7,-3,34:17.12
8,-3,34:17.12
10,-3,34:18.13
11,-3,34:18.13
17,-3,34:18.5
-1,-2,34:18.5
0,-2,34:18.5
1,-2,34:18.5
2,-2,34:18.13
3,-2,34:18.13
8,-2,34:17.12
10,-2,34:18.13
2,-1,34:18.13
3,-1,34:18.13
4,-1,34:18.13
5,-1,34:18.13
6,-1,34:18.13
7,-1,34:18.13
8,-1,34:18.13
9,-1,34:18.13
1,0,34:18.5
2,0,34:18.13
8,0,34:18.13
9,0,34:18.13
10,0,34:18.13
1,1,34:18.5
8,1,34:18.13
9,1,34:18.13
11,1,34:18.13
12,1,34:18.13
1,2,34:18.5
8,2,34:18.13
8,3,34:18.5
6,-10,35:18.5
7,-10,35:18.5
6,-9,35:18.13
13,-9,35:18.5
3,-8,35:18.13
4,-8,35:18.13
6,-8,35:18.13
13,-8,35:18.5
4,-7,35:18.13
5,-7,35:18.13
6,-7,35:18.13
7,-7,35:18.13
12,-7,35:18.13
13,-7,35:18.5
5,-6,35:18.13
6,-6,35:18.13
7,-6,35:18.13
8,-6,35:18.13
9,-6,35:18.13
10,-6,35:18.13
11,-6,35:18.13
12,-6,35:18.13
5,-5,35:18.13
7,-5,35:17.12
11,-5,35:18.13
12,-5,35:18.13
13,-5,35:18.5
14,-5,35:18.5
15,-5,35:18.5
4,-4,35:18.13
6,-4,35:17.12
8,-4,35:17.12
10,-4,35:18.13
11,-4,35:18.13
15,-4,35:18.5
16,-4,35:18.5
-1,-3,35:18.5
0,-3,35:18.5
3,-3,35:18.13
4,-3,35:18.13
6,-3,35:17.12
7,-3,35:17.12
8,-3,35:17.12
10,-3,35:18.13
0,-2,35:18.5
1,-2,35:18.5
2,-2,35:18.13
3,-2,35:18.13
4,-2,35:18.13
7,-2,35:17.12
8,-2,35:17.12
9,-2,35:18.13
10,-2,35:18.13
2,-1,35:18.13
3,-1,35:18.13
5,-1,35:18.13
6,-1,35:18.13
7,-1,35:18.13
8,-1,35:18.13
9,-1,35:18.13
2,0,35:18.13
8,0,35:18.13
9,0,35:18.13
10,0,35:18.13
11,0,35:18.13
1,1,35:18.5
2,1,35:18.13
8,1,35:18.13
11,1,35:18.13
12,1,35:18.13
8,2,35:18.13
8,3,35:18.5
7,-10,36:18.5
6,-9,36:18.13
7,-9,36:18.13
2,-8,36:18.13
3,-8,36:18.13
6,-8,36:18.13
12,-8,36:18.13
13,-8,36:18.5
4,-7,36:18.13
5,-7,36:18.13
6,-7,36:18.13
12,-7,36:18.13
5,-6,36:18.13
6,-6,36:18.13
7,-6,36:18.13
8,-6,36:18.13
9,-6,36:18.13
10,-6,36:18.13
11,-6,36:18.13
12,-6,36:18.13
5,-5,36:18.13
7,-5,36:17.12
10,-5,36:18.13
11,-5,36:18.13
12,-5,36:18.13
13,-5,36:18.5
14,-5,36:18.5
4,-4,36:18.13
5,-4,36:18.13
6,-4,36:17.12
8,-4,36:17.12
10,-4,36:18.13
11,-4,36:18.13
14,-4,36:18.5
15,-4,36:18.5
-1,-3,36:18.5
0,-3,36:18.5
4,-3,36:18.13
6,-3,36:17.12
7,-3,36:17.12
8,-3,36:17.12
10,-3,36:18.13
1,-2,36:18.5
2,-2,36:18.13
3,-2,36:18.13
4,-2,36:18.13
5,-2,36:18.13
6,-2,36:18.13
7,-2,36:17.12
8,-2,36:17.12
9,-2,36:18.13
3,-1,36:18.13
6,-1,36:18.13
7,-1,36:18.13
8,-1,36:18.13
9,-1,36:18.13
2,0,36:18.13
3,0,36:18.13
8,0,36:18.13
10,0,36:18.13
11,0,36:18.13
2,1,36:18.13
8,1,36:18.13
12,1,36:18.13
8,2,36:18.13
7,3,36:18.5
7,-10,37:18.5
7,-9,37:18.13
2,-8,37:18.13
7,-8,37:18.13
12,-8,37:18.13
3,-7,37:18.13
4,-7,37:18.13
5,-7,37:18.13
6,-7,37:18.13
12,-7,37:18.13
5,-6,37:18.13
6,-6,37:18.13
7,-6,37:18.13
8,-6,37:18.13
11,-6,37:18.13
5,-5,37:18.13
6,-5,37:18.13
7,-5,37:17.12
8,-5,37:18.13
9,-5,37:18.13
10,-5,37:18.13
11,-5,37:18.13
12,-5,37:18.13
5,-4,37:18.13
6,-4,37:17.0
7,-4,37:17.12
8,-4,37:17.12
10,-4,37:18.13
12,-4,37:18.13
13,-4,37:18.5
14,-4,37:18.5
0,-3,37:18.5
2,-3,37:18.13
4,-3,37:18.13
5,-3,37:18.13
6,-3,37:17.0
7,-3,37:17.0
8,-3,37:17.12
9,-3,37:18.13
10,-3,37:18.13
2,-2,37:18.13
3,-2,37:18.13
4,-2,37:18.13
5,-2,37:18.13
6,-2,37:18.13
7,-2,37:18.13
8,-2,37:17.0
9,-2,37:18.13
3,-1,37:18.13
4,-1,37:18.13
7,-1,37:18.13
8,-1,37:18.13
9,-1,37:18.13
10,-1,37:18.13
3,0,37:18.13
8,0,37:18.13
10,0,37:18.13
11,0,37:18.13
12,0,37:18.13
3,1,37:18.13
8,1,37:18.13
12,1,37:18.13
7,2,37:18.13
8,2,37:18.13
7,-9,38:18.13
2,-8,38:18.13
7,-8,38:18.13
12,-8,38:18.13
2,-7,38:18.13
3,-7,38:18.13
4,-7,38:18.13
7,-7,38:18.13
11,-7,38:18.13
12,-7,38:18.13
4,-6,38:18.13
5,-6,38:18.13
6,-6,38:18.13
7,-6,38:18.13
11,-6,38:18.13
2,-5,38:18.13
6,-5,38:18.13
7,-5,38:18.13
8,-5,38:18.13
9,-5,38:18.13
10,-5,38:18.13
11,-5,38:18.13
1,-4,38:18.5
5,-4,38:18.13
6,-4,38:18.13
7,-4,38:17.0
8,-4,38:17.0
9,-4,38:18.13
10,-4,38:18.13
11,-4,38:18.13
12,-4,38:18.13
13,-4,38:18.5
14,-4,38:18.5
0,-3,38:18.5
2,-3,38:18.13
3,-3,38:18.13
5,-3,38:18.13
6,-3,38:17.0
7,-3,38:17.0
8,-3,38:17.0
9,-3,38:18.13
13,-3,38:18.5
14,-3,38:18.5
4,-2,38:18.13
5,-2,38:18.13
6,-2,38:18.13
7,-2,38:18.13
8,-2,38:18.13
9,-2,38:18.13
12,-2,38:18.13
13,-2,38:18.5
4,-1,38:18.13
8,-1,38:18.13
9,-1,38:18.13
10,-1,38:18.13
3,0,38:18.13
4,0,38:18.13
8,0,38:18.13
11,0,38:18.13
12,0,38:18.13
3,1,38:18.13
7,1,38:18.13
8,1,38:18.13
12,1,38:18.13
7,2,38:18.13
12,2,38:18.13
2,-9,39:18.5
7,-9,39:18.13
2,-8,39:18.13
7,-8,39:18.13
11,-8,39:18.13
12,-8,39:18.13
2,-7,39:18.13
3,-7,39:18.13
7,-7,39:18.13
11,-7,39:18.13
4,-6,39:18.13
5,-6,39:18.13
7,-6,39:18.13
10,-6,39:18.13
11,-6,39:18.13
2,-5,39:18.13
3,-5,39:18.13
6,-5,39:18.13
7,-5,39:18.13
8,-5,39:18.13
9,-5,39:18.13
10,-5,39:18.13
11,-5,39:18.13
1,-4,39:18.5
2,-4,39:18.13
3,-4,39:18.13
6,-4,39:18.13
7,-4,39:17.0
8,-4,39:17.0
9,-4,39:18.13
10,-4,39:18.13
11,-4,39:18.13
12,-4,39:18.13
13,-4,39:18.5
14,-4,39:18.5
0,-3,39:18.5
2,-3,39:18.13
3,-3,39:18.13
4,-3,39:18.13
5,-3,39:18.13
6,-3,39:17.0
7,-3,39:17.0
8,-3,39:17.0
9,-3,39:18.13
12,-3,39:18.13
13,-3,39:18.5
14,-3,39:18.5
4,-2,39:18.13
5,-2,39:18.13
6,-2,39:18.13
7,-2,39:18.13
8,-2,39:18.13
9,-2,39:18.13
12,-2,39:18.13
13,-2,39:18.5
4,-1,39:18.13
5,-1,39:18.13
8,-1,39:18.13
9,-1,39:18.13
10,-1,39:18.13
11,-1,39:18.13
12,-1,39:18.13
4,0,39:18.13
7,0,39:18.13
8,0,39:18.13
9,0,39:18.13
11,0,39:18.13
12,0,39:18.13
3,1,39:18.13
4,1,39:18.13
7,1,39:18.13
12,1,39:18.13
3,2,39:18.13
7,2,39:18.13
12,2,39:18.13
2,-8,40:18.13
8,-8,40:18.13
11,-8,40:18.13
12,-8,40:18.13
13,-8,40:18.5
2,-7,40:18.13
6,-7,40:18.13
7,-7,40:18.13
11,-7,40:18.13
2,-6,40:18.13
3,-6,40:18.13
4,-6,40:18.13
7,-6,40:18.13
10,-6,40:18.13
2,-5,40:18.13
3,-5,40:18.13
4,-5,40:18.13
5,-5,40:18.13
6,-5,40:18.13
7,-5,40:18.13
9,-5,40:18.13
10,-5,40:18.13
11,-5,40:18.13
1,-4,40:18.5
2,-4,40:18.13
3,-4,40:18.13
6,-4,40:18.13
7,-4,40:17.0
8,-4,40:18.13
9,-4,40:18.13
10,-4,40:18.13
11,-4,40:18.13
14,-4,40:18.5
2,-3,40:18.13
3,-3,40:18.13
4,-3,40:18.13
5,-3,40:18.13
6,-3,40:18.13
7,-3,40:17.0
8,-3,40:17.0
9,-3,40:18.13
11,-3,40:18.13
12,-3,40:18.13
13,-3,40:18.5
14,-3,40:18.5
4,-2,40:18.13
5,-2,40:18.13
6,-2,40:18.13
7,-2,40:18.13
8,-2,40:18.13
9,-2,40:18.13
12,-2,40:18.13
13,-2,40:18.5
5,-1,40:18.13
8,-1,40:18.13
9,-1,40:18.13
10,-1,40:18.13
11,-1,40:18.13
12,-1,40:18.13
4,0,40:18.13
5,0,40:18.13
7,0,40:18.13
8,0,40:18.13
9,0,40:18.13
12,0,40:18.13
4,1,40:18.13
7,1,40:18.13
8,1,40:18.13
12,1,40:18.13
1,2,40:18.5
2,2,40:18.5
3,2,40:18.13
6,2,40:18.13
7,3,40:18.5
8,4,40:18.5
7,-10,41:18.5
8,-10,41:18.5
8,-9,41:18.5
3,-8,41:18.5
8,-8,41:18.5
11,-8,41:18.5
12,-8,41:18.5
13,-8,41:18.5
3,-7,41:18.5
6,-7,41:18.5
7,-7,41:18.5
8,-7,41:18.5
10,-7,41:18.5
3,-6,41:18.5
5,-6,41:18.5
6,-6,41:18.5
7,-6,41:18.5
8,-6,41:18.5
10,-6,41:18.5
3,-5,41:18.5
4,-5,41:18.5
5,-5,41:18.5
6,-5,41:18.5
7,-5,41:18.5
9,-5,41:18.5
10,-5,41:18.5
11,-5,41:18.5
2,-4,41:18.5
3,-4,41:18.5
4,-4,41:18.5
6,-4,41:18.5
7,-4,41:18.5
8,-4,41:18.5
9,-4,41:18.5
11,-4,41:18.5
14,-4,41:18.5
3,-3,41:18.5
4,-3,41:18.5
5,-3,41:18.5
6,-3,41:18.5
7,-3,41:18.5
8,-3,41:18.5
9,-3,41:18.5
10,-3,41:18.5
11,-3,41:18.5
13,-3,41:18.5
14,-3,41:18.5
4,-2,41:18.5
6,-2,41:18.5
7,-2,41:17.0
8,-2,41:18.5
9,-2,41:18.5
11,-2,41:18.5
12,-2,41:18.5
13,-2,41:18.5
4,-1,41:18.5
5,-1,41:18.5
6,-1,41:18.5
7,-1,41:18.5
10,-1,41:18.5
11,-1,41:18.5
12,-1,41:18.5
5,0,41:18.5
7,0,41:18.5
8,0,41:18.5
9,0,41:18.5
12,0,41:18.5
5,1,41:18.5
6,1,41:18.5
7,1,41:18.5
8,1,41:18.5
12,1,41:18.5
2,2,41:18.5
3,2,41:18.5
4,2,41:18.5
6,2,41:18.5
6,3,41:18.5
7,3,41:18.5
8,4,41:18.5
7,-10,42:18.5
8,-9,42:18.5
9,-9,42:18.5
10,-8,42:18.5
11,-8,42:18.5
12,-8,42:18.5
3,-7,42:18.5
7,-7,42:18.5
8,-7,42:18.5
9,-7,42:18.5
10,-7,42:18.5
3,-6,42:18.5
5,-6,42:18.5
6,-6,42:18.5
7,-6,42:18.5
10,-6,42:18.5
3,-5,42:18.5
4,-5,42:18.5
5,-5,42:18.5
9,-5,42:18.5
10,-5,42:18.5
2,-4,42:18.5
3,-4,42:18.5
4,-4,42:18.5
6,-4,42:18.5
7,-4,42:18.5
8,-4,42:18.5
9,-4,42:18.5
10,-4,42:18.5
11,-4,42:18.5
14,-4,42:18.5
2,-3,42:18.5
4,-3,42:18.5
5,-3,42:18.5
6,-3,42:18.5
7,-3,42:18.5
8,-3,42:18.5
9,-3,42:18.5
10,-3,42:18.5
11,-3,42:18.5
13,-3,42:18.5
1,-2,42:18.5
4,-2,42:18.5
5,-2,42:18.5
6,-2,42:18.5
7,-2,42:18.5
8,-2,42:17.0
11,-2,42:18.5
12,-2,42:18.5
13,-2,42:18.5
5,-1,42:18.5
9,-1,42:18.5
10,-1,42:18.5
11,-1,42:18.5
12,-1,42:18.5
5,0,42:18.5
8,0,42:18.5
9,0,42:18.5
12,0,42:18.5
5,1,42:18.5
6,1,42:18.5
7,1,42:18.5
12,1,42:18.5
3,2,42:18.5
4,2,42:18.5
5,2,42:18.5
6,2,42:18.5
7,3,42:18.5
8,3,42:18.5
8,4,42:18.5
7,-10,43:18.5
7,-9,43:18.5
8,-9,43:18.5
10,-8,43:18.5
11,-8,43:18.5
12,-8,43:18.5
3,-7,43:18.5
8,-7,43:18.5
9,-7,43:18.5
3,-6,43:18.5
6,-6,43:18.5
7,-6,43:18.5
9,-6,43:18.5
10,-6,43:18.5
3,-5,43:18.5
4,-5,43:18.5
5,-5,43:18.5
6,-5,43:18.5
10,-5,43:18.5
2,-4,43:18.5
3,-4,43:18.5
4,-4,43:18.5
7,-4,43:17.0
8,-4,43:17.0
10,-4,43:18.5
2,-3,43:18.5
4,-3,43:18.5
5,-3,43:18.5
7,-3,43:17.0
8,-3,43:17.0
10,-3,43:18.5
11,-3,43:18.5
13,-3,43:18.5
1,-2,43:18.5
5,-2,43:18.5
7,-2,43:17.0
8,-2,43:17.0
11,-2,43:18.5
12,-2,43:18.5
5,-1,43:18.5
9,-1,43:18.5
10,-1,43:18.5
11,-1,43:18.5
5,0,43:18.5
6,0,43:18.5
7,0,43:18.5
8,0,43:18.5
12,0,43:18.5
5,1,43:18.5
6,1,43:18.5
7,1,43:18.5
12,1,43:18.5
3,2,43:18.5
4,2,43:18.5
5,2,43:18.5
6,2,43:18.5
7,2,43:18.5
7,3,43:18.5
8,3,43:18.5
7,-9,44:18.5
8,-9,44:18.5
8,-8,44:18.5
10,-8,44:18.5
11,-8,44:18.5
3,-7,44:18.5
8,-7,44:18.5
9,-7,44:18.5
10,-7,44:18.5
11,-7,44:18.5
3,-6,44:18.5
7,-6,44:18.5
8,-6,44:18.5
9,-6,44:18.5
4,-5,44:18.5
5,-5,44:18.5
6,-5,44:18.5
9,-5,44:18.5
10,-5,44:18.5
3,-4,44:18.5
4,-4,44:18.5
5,-4,44:18.5
7,-4,44:17.0
8,-4,44:17.0
10,-4,44:18.5
2,-3,44:18.5
5,-3,44:18.5
7,-3,44:17.0
8,-3,44:17.0
10,-3,44:18.5
13,-3,44:18.5
5,-2,44:18.5
7,-2,44:17.0
8,-2,44:17.0
10,-2,44:18.5
11,-2,44:18.5
12,-2,44:18.5
5,-1,44:18.5
6,-1,44:18.5
8,-1,44:18.5
9,-1,44:18.5
10,-1,44:18.5
11,-1,44:18.5
6,0,44:18.5
7,0,44:18.5
8,0,44:18.5
11,0,44:18.5
12,0,44:18.5
3,1,44:18.5
4,1,44:18.5
5,1,44:18.5
6,1,44:18.5
11,1,44:18.5
12,1,44:18.5
6,2,44:18.5
7,2,44:18.5
7,3,44:18.5
8,3,44:18.5
7,-9,45:18.5
8,-8,45:18.5
3,-7,45:18.5
4,-7,45:18.5
9,-7,45:18.5
10,-7,45:18.5
11,-7,45:18.5
12,-7,45:18.5
3,-6,45:18.5
4,-6,45:18.5
8,-6,45:18.5
9,-6,45:18.5
4,-5,45:18.5
6,-5,45:18.5
7,-5,45:18.5
9,-5,45:18.5
4,-4,45:18.5
5,-4,45:18.5
6,-4,45:18.5
7,-4,45:17.0
8,-4,45:17.0
9,-4,45:18.5
10,-4,45:18.5
2,-3,45:18.5
3,-3,45:18.5
5,-3,45:18.5
7,-3,45:17.0
8,-3,45:17.0
10,-3,45:18.5
12,-3,45:18.5
5,-2,45:18.5
6,-2,45:18.5
7,-2,45:17.0
8,-2,45:17.0
10,-2,45:18.5
11,-2,45:18.5
12,-2,45:18.5
6,-1,45:18.5
8,-1,45:18.5
9,-1,45:18.5
10,-1,45:18.5
11,-1,45:18.5
6,0,45:18.5
7,0,45:18.5
8,0,45:18.5
11,0,45:18.5
3,1,45:18.5
4,1,45:18.5
5,1,45:18.5
6,1,45:18.5
7,1,45:18.5
11,1,45:18.5
7,2,45:18.5
8,3,45:18.5
7,-8,46:18.5
8,-8,46:18.5
8,-7,46:18.5
10,-7,46:18.5
11,-7,46:18.5
12,-7,46:18.5
4,-6,46:18.5
8,-6,46:18.5
9,-6,46:18.5
10,-6,46:18.5
4,-5,46:18.5
5,-5,46:18.5
7,-5,46:18.5
8,-5,46:18.5
9,-5,46:18.5
5,-4,46:18.5
6,-4,46:18.5
7,-4,46:17.0
9,-4,46:18.5
3,-3,46:18.5
4,-3,46:18.5
5,-3,46:18.5
7,-3,46:17.0
8,-3,46:17.0
9,-3,46:18.5
10,-3,46:18.5
12,-3,46:18.5
6,-2,46:18.5
7,-2,46:17.0
8,-2,46:17.0
9,-2,46:18.5
10,-2,46:18.5
11,-2,46:18.5
6,-1,46:18.5
8,-1,46:18.5
9,-1,46:18.5
10,-1,46:18.5
11,-1,46:18.5
6,0,46:18.5
7,0,46:18.5
11,0,46:18.5
4,1,46:18.5
5,1,46:18.5
6,1,46:18.5
7,1,46:18.5
7,2,46:18.5
8,-8,47:18.5
8,-7,47:18.5
11,-7,47:18.5
4,-6,47:18.5
8,-6,47:18.5
9,-6,47:18.5
10,-6,47:18.5
11,-6,47:18.5
4,-5,47:18.5
5,-5,47:18.5
7,-5,47:18.5
8,-5,47:18.5
9,-5,47:18.5
5,-4,47:18.5
6,-4,47:18.5
7,-4,47:18.5
9,-4,47:18.5
3,-3,47:18.5
4,-3,47:18.5
5,-3,47:18.5
6,-3,47:18.5
7,-3,47:17.0
8,-3,47:17.0
9,-3,47:18.5
11,-3,47:18.5
12,-3,47:18.5
6,-2,47:18.5
7,-2,47:17.0
8,-2,47:17.0
9,-2,47:18.5
10,-2,47:18.5
11,-2,47:18.5
6,-1,47:18.5
7,-1,47:18.5
8,-1,47:18.5
9,-1,47:18.5
10,-1,47:18.5
6,0,47:18.5
7,0,47:18.5
11,0,47:18.5
4,1,47:18.5
5,1,47:18.5
7,1,47:18.5
7,2,47:18.5
8,-7,48:18.5
8,-6,48:18.5
10,-6,48:18.5
11,-6,48:18.5
5,-5,48:18.5
8,-5,48:18.5
9,-5,48:18.5
5,-4,48:18.5
6,-4,48:18.5
7,-4,48:18.5
8,-4,48:18.5
9,-4,48:18.5
4,-3,48:18.5
5,-3,48:18.5
6,-3,48:18.5
7,-3,48:17.0
8,-3,48:17.0
9,-3,48:18.5
11,-3,48:18.5
12,-3,48:18.5
3,-2,48:18.5
6,-2,48:18.5
7,-2,48:17.0
8,-2,48:17.0
9,-2,48:18.5
10,-2,48:18.5
7,-1,48:18.5
8,-1,48:18.5
10,-1,48:18.5
5,0,48:18.5
6,0,48:18.5
7,0,48:18.5
10,0,48:18.5
11,0,48:18.5
5,1,48:18.5
7,1,48:18.5
8,1,48:18.5
8,2,48:18.5
7,-7,49:18.5
8,-7,49:18.5
8,-6,49:18.5
10,-6,49:18.5
11,-6,49:18.5
5,-5,49:18.5
8,-5,49:18.5
9,-5,49:18.5
10,-5,49:18.5
6,-4,49:18.5
7,-4,49:18.5
8,-4,49:18.5
9,-4,49:18.5
5,-3,49:18.5
6,-3,49:18.5
7,-3,49:17.0
8,-3,49:17.0
9,-3,49:18.5
10,-3,49:18.5
11,-3,49:18.5
12,-3,49:18.5
3,-2,49:18.5
4,-2,49:18.5
7,-2,49:18.5
8,-2,49:17.0
9,-2,49:18.5
10,-2,49:18.5
6,-1,49:18.5
7,-1,49:18.5
8,-1,49:18.5
9,-1,49:18.5
10,-1,49:18.5
5,0,49:18.5
6,0,49:18.5
7,0,49:18.5
8,0,49:18.5
10,0,49:18.5
8,1,49:18.5
8,2,49:18.5
7,-7,50:18.5
7,-6,50:18.5
8,-6,50:18.5
5,-5,50:18.5
6,-5,50:18.5
8,-5,50:18.5
10,-5,50:18.5
6,-4,50:18.5
8,-4,50:18.5
9,-4,50:18.5
6,-3,50:18.5
7,-3,50:18.5
8,-3,50:18.5
10,-3,50:18.5
11,-3,50:18.5
4,-2,50:18.5
5,-2,50:18.5
7,-2,50:18.5
8,-2,50:18.5
9,-2,50:18.5
6,-1,50:18.5
7,-1,50:18.5
8,-1,50:18.5
9,-1,50:18.5
10,-1,50:18.5
5,0,50:18.5
6,0,50:18.5
8,0,50:18.5
9,0,50:18.5
10,0,50:18.5
11,0,50:18.5
8,1,50:18.5
7,2,50:18.5
8,2,50:18.5
8,-7,51:18.5
7,-6,51:18.5
4,-5,51:18.5
5,-5,51:18.5
6,-5,51:18.5
7,-5,51:18.5
8,-5,51:18.5
9,-5,51:18.5
11,-5,51:18.5
6,-4,51:18.5
8,-4,51:18.5
9,-4,51:18.5
10,-4,51:18.5
11,-4,51:18.5
5,-3,51:18.5
6,-3,51:18.5
7,-3,51:18.5
8,-3,51:18.5
9,-3,51:18.5
10,-3,51:18.5
12,-3,51:18.5
6,-2,51:18.5
7,-2,51:18.5
8,-2,51:18.5
9,-2,51:18.5
10,-2,51:18.5
13,-2,51:18.5
5,-1,51:18.5
6,-1,51:18.5
7,-1,51:18.5
8,-1,51:18.5
9,-1,51:18.5
10,-1,51:18.5
5,0,51:18.5
6,0,51:18.5
7,0,51:18.5
8,0,51:18.5
9,0,51:18.5
10,0,51:18.5
11,0,51:18.5
5,1,51:18.5
8,1,51:18.5
8,2,51:18.5
7,-6,52:18.5
8,-6,52:18.5
11,-6,52:18.5
5,-5,52:18.5
6,-5,52:18.5
7,-5,52:18.5
11,-5,52:18.5
6,-4,52:18.5
7,-4,52:18.5
8,-4,52:18.5
9,-4,52:18.5
10,-4,52:18.5
11,-4,52:18.5
3,-3,52:18.5
6,-3,52:18.5
7,-3,52:18.5
8,-3,52:18.5
9,-3,52:18.5
10,-3,52:18.5
11,-3,52:18.5
12,-3,52:18.5
3,-2,52:18.5
4,-2,52:18.5
5,-2,52:18.5
7,-2,52:18.5
8,-2,52:18.5
10,-2,52:18.5
12,-2,52:18.5
5,-1,52:18.5
6,-1,52:18.5
7,-1,52:18.5
8,-1,52:18.5
9,-1,52:18.5
10,-1,52:18.5
5,0,52:18.5
7,0,52:18.5
8,0,52:18.5
9,0,52:18.5
10,0,52:18.5
5,1,52:18.5
8,1,52:18.5
5,-5,53:18.5
6,-5,53:18.5
7,-5,53:18.5
10,-5,53:18.5
6,-4,53:18.5
7,-4,53:18.5
8,-4,53:18.5
9,-4,53:18.5
10,-4,53:18.5
6,-3,53:18.5
8,-3,53:17.0
10,-3,53:18.5
11,-3,53:18.5
4,-2,53:18.5
5,-2,53:18.5
6,-2,53:18.5
7,-2,53:17.0
8,-2,53:17.0
10,-2,53:18.5
12,-2,53:18.5
5,-1,53:18.5
6,-1,53:18.5
7,-1,53:18.5
9,-1,53:18.5
5,0,53:18.5
8,0,53:18.5
9,0,53:18.5
10,0,53:18.5
8,1,53:18.5
7,-5,54:18.5
8,-5,54:18.5
10,-5,54:18.5
5,-4,54:18.5
6,-4,54:18.5
7,-4,54:18.5
8,-4,54:18.5
9,-4,54:18.5
10,-4,54:18.5
6,-3,54:18.5
8,-3,54:17.0
9,-3,54:18.5
10,-3,54:18.5
11,-3,54:18.5
5,-2,54:18.5
6,-2,54:18.5
7,-2,54:17.0
8,-2,54:17.0
9,-2,54:18.5
10,-2,54:18.5
11,-2,54:18.5
5,-1,54:18.5
6,-1,54:18.5
7,-1,54:18.5
8,-1,54:18.5
9,-1,54:18.5
6,0,54:18.5
8,0,54:18.5
9,0,54:18.5
10,0,54:18.5
6,-4,55:18.5
7,-4,55:18.5
8,-4,55:18.5
10,-4,55:18.5
6,-3,55:18.5
7,-3,55:18.5
8,-3,55:17.0
9,-3,55:18.5
10,-3,55:18.5
5,-2,55:18.5
6,-2,55:18.5
7,-2,55:17.0
8,-2,55:17.0
9,-2,55:18.5
6,-1,55:18.5
7,-1,55:18.5
8,-1,55:18.5
9,-1,55:18.5
6,0,55:18.5
7,-4,56:18.5
7,-3,56:18.5
8,-3,56:18.5
9,-3,56:18.5
10,-3,56:18.5
6,-2,56:18.5
7,-2,56:18.5
8,-2,56:17.0
9,-2,56:18.5
6,-1,56:18.5
7,-1,56:18.5
8,-1,56:18.5
9,-1,56:18.5
7,-3,57:18.5
8,-3,57:18.5
9,-3,57:18.5
6,-2,57:18.5
7,-2,57:18.5
8,-2,57:17.0
9,-2,57:18.5
7,-1,57:18.5
8,-1,57:18.5
9,-1,57:18.5
8,-3,58:18.5
7,-2,58:18.5
8,-2,58:17.0
9,-2,58:18.5
8,-1,58:18.5
7,-2,59:18.5
8,-2,59:18.5
8,-1,59:18.5
8,-2,60:17.0
8,-2,61:17.0
8,-2,62:17.0
8,-2,63:17.0
