[META]
version=2.0
spawnOnBlockType=2
spawnSunlight=True
spawnDarkness=True
spawnWater=False
spawnLava=False
underFill=False
randomRotation=True
dig=True
tree=False
branch=False
needsFoundation=True
rarity=100
collisionPercentage=20
spawnElevationMin=0
spawnElevationMax=200
spawnInBiome=Custom
[DATA]
1,-6,-8:17.12
2,-6,-8:17.12
3,-6,-8:17.12
7,-2,-8:17.12
1,-7,-7:17.12
2,-7,-7:17.12
1,-6,-7:17.12
2,-6,-7:17.12
3,-6,-7:17.12
4,-6,-7:17.12
1,-5,-7:17.12
2,-5,-7:17.12
3,-5,-7:17.12
2,-3,-7:17.12
3,-3,-7:17.12
6,-3,-7:17.12
7,-3,-7:17.12
2,-2,-7:17.12
6,-2,-7:17.12
7,-2,-7:17.12
2,-7,-6:17.12
3,-7,-6:17.12
4,-7,-6:17.12
1,-6,-6:17.12
2,-6,-6:17.12
3,-6,-6:17.12
4,-6,-6:17.12
2,-5,-6:17.12
2,-4,-6:17.12
3,-4,-6:17.12
2,-3,-6:17.12
3,-3,-6:17.12
4,-3,-6:17.12
2,-2,-6:17.12
3,-2,-6:17.12
6,-2,-6:17.12
1,-1,-6:17.12
2,-1,-6:17.12
6,-1,-6:17.12
2,-7,-5:17.12
3,-7,-5:17.12
4,-7,-5:17.12
1,-6,-5:17.12
2,-6,-5:17.12
3,-6,-5:17.12
2,-5,-5:17.12
3,-5,-5:17.12
4,-5,-5:17.12
3,-4,-5:17.12
4,-4,-5:17.12
6,-4,-5:17.12
2,-3,-5:17.12
3,-3,-5:17.12
4,-3,-5:17.12
6,-3,-5:17.12
7,-3,-5:17.12
1,-2,-5:17.12
2,-2,-5:17.12
5,-2,-5:17.12
6,-2,-5:17.12
7,-2,-5:17.12
2,-1,-5:17.12
6,-1,-5:17.12
7,-1,-5:17.12
1,-7,-4:17.12
2,-7,-4:17.12
3,-7,-4:17.12
0,-6,-4:17.12
2,-6,-4:17.12
3,-6,-4:17.12
4,-6,-4:17.12
1,-5,-4:17.12
2,-5,-4:17.12
5,-5,-4:17.12
6,-5,-4:17.12
3,-4,-4:17.12
6,-4,-4:17.12
3,-3,-4:17.12
4,-3,-4:17.12
5,-3,-4:17.12
7,-3,-4:17.12
8,-3,-4:17.12
3,-2,-4:17.12
4,-2,-4:17.12
5,-2,-4:17.12
6,-2,-4:17.12
7,-2,-4:17.12
8,-2,-4:17.12
6,-1,-4:17.12
1,-7,-3:17.12
2,-7,-3:17.12
0,-6,-3:17.12
1,-6,-3:17.12
2,-6,-3:17.12
3,-6,-3:17.12
2,-5,-3:17.12
3,-5,-3:17.12
5,-5,-3:17.12
6,-5,-3:17.12
7,-5,-3:17.12
8,-5,-3:17.12
4,-4,-3:17.12
5,-4,-3:17.12
6,-4,-3:17.12
8,-4,-3:17.12
9,-4,-3:17.12
3,-3,-3:17.12
5,-3,-3:17.12
6,-3,-3:17.12
7,-3,-3:17.12
8,-3,-3:17.12
4,-2,-3:17.12
5,-2,-3:17.12
6,-2,-3:17.12
7,-2,-3:17.12
8,-2,-3:17.12
6,-1,-3:17.12
7,-1,-3:17.12
0,-7,-2:17.12
1,-7,-2:17.12
2,-7,-2:17.12
0,-6,-2:17.12
1,-6,-2:17.12
2,-6,-2:17.12
1,-5,-2:17.12
2,-5,-2:17.12
6,-5,-2:17.12
7,-5,-2:17.12
8,-5,-2:17.12
4,-4,-2:17.12
5,-4,-2:17.12
6,-4,-2:17.12
8,-4,-2:17.12
4,-3,-2:17.12
5,-3,-2:17.12
6,-3,-2:17.12
7,-3,-2:17.12
8,-3,-2:17.12
4,-2,-2:17.12
5,-2,-2:17.12
6,-2,-2:17.12
6,-1,-2:17.12
1,-7,-1:17.12
2,-7,-1:17.12
0,-6,-1:17.12
1,-6,-1:17.12
2,-6,-1:17.12
7,-5,-1:17.12
5,-4,-1:17.12
6,-4,-1:17.12
7,-4,-1:17.12
8,-4,-1:17.12
4,-3,-1:17.12
5,-3,-1:17.12
6,-3,-1:17.12
7,-3,-1:17.12
8,-3,-1:17.12
5,-2,-1:17.12
1,-7,0:17.12
2,-7,0:17.12
1,-6,0:17.12
2,-6,0:17.12
6,-4,0:17.12
7,-4,0:17.12
8,-4,0:17.12
4,-3,0:17.12
5,-3,0:17.12
7,-3,0:17.12
8,-3,0:17.12
5,-2,0:17.12
1,-7,1:17.12
1,-6,1:17.12
2,-6,1:17.12
7,-4,1:17.12
8,-4,1:17.12
4,-3,1:17.12
5,-3,1:17.12
7,-3,1:17.12
8,-3,1:17.12
5,-2,1:17.12
1,-7,2:17.12
1,-6,2:17.12
7,-4,2:17.12
8,-4,2:17.12
4,-3,2:17.12
5,-3,2:17.12
7,-3,2:17.12
-1,-11,3:18.12
-1,-10,3:18.12
0,-10,3:18.12
1,-7,3:17.12
7,-7,3:18.13
1,-6,3:17.12
7,-6,3:18.13
-2,-5,3:18.12
1,-5,3:18.13
2,-5,3:18.13
6,-5,3:18.13
3,-4,3:18.13
6,-4,3:18.13
7,-4,3:17.12
8,-4,3:17.12
3,-3,3:18.12
4,-3,3:17.12
5,-3,3:17.12
7,-3,3:17.12
8,-3,3:17.12
4,-2,3:18.13
3,-1,3:18.13
3,0,3:18.13
2,1,3:18.13
-1,-11,4:18.12
-1,-10,4:18.12
0,-10,4:18.12
0,-9,4:18.12
11,-9,4:18.4
1,-8,4:18.12
5,-8,4:18.12
10,-8,4:18.12
0,-7,4:18.12
2,-7,4:18.12
3,-7,4:18.12
4,-7,4:18.12
7,-7,4:18.13
-1,-6,4:18.12
0,-6,4:18.12
1,-6,4:18.12
2,-6,4:18.12
7,-6,4:18.13
-3,-5,4:18.12
-2,-5,4:18.12
1,-5,4:18.13
2,-5,4:18.12
6,-5,4:18.13
2,-4,4:18.12
3,-4,4:18.13
4,-4,4:18.13
5,-4,4:18.13
6,-4,4:18.13
7,-4,4:17.12
8,-4,4:17.12
3,-3,4:18.12
4,-3,4:18.13
5,-3,4:18.13
6,-3,4:18.13
7,-3,4:17.12
8,-3,4:17.12
3,-2,4:18.12
4,-2,4:18.13
5,-2,4:18.13
6,-2,4:18.13
3,-1,4:18.13
6,-1,4:18.13
7,-1,4:18.13
3,0,4:18.13
8,0,4:18.13
2,1,4:18.13
4,1,4:18.12
0,-10,5:18.12
11,-10,5:18.4
0,-9,5:18.12
11,-9,5:18.4
0,-8,5:18.12
1,-8,5:18.12
5,-8,5:18.12
10,-8,5:18.12
0,-7,5:18.12
2,-7,5:18.12
3,-7,5:18.12
4,-7,5:18.12
10,-7,5:18.12
-1,-6,5:18.12
0,-6,5:18.12
1,-6,5:18.12
2,-6,5:18.12
4,-6,5:18.12
9,-6,5:18.12
-3,-5,5:18.12
-2,-5,5:18.12
1,-5,5:18.12
2,-5,5:18.12
6,-5,5:18.13
7,-5,5:18.12
8,-5,5:18.12
9,-5,5:18.12
2,-4,5:18.12
3,-4,5:18.13
4,-4,5:18.13
5,-4,5:18.13
6,-4,5:18.12
7,-4,5:17.12
8,-4,5:17.12
9,-4,5:18.12
3,-3,5:18.12
4,-3,5:18.13
5,-3,5:17.12
6,-3,5:18.12
7,-3,5:17.12
8,-3,5:17.12
9,-3,5:18.12
3,-2,5:18.12
4,-2,5:18.13
5,-2,5:18.13
6,-2,5:18.12
7,-2,5:18.12
8,-2,5:18.12
9,-2,5:18.12
3,-1,5:18.13
5,-1,5:18.13
6,-1,5:18.13
7,-1,5:18.13
10,-1,5:18.12
11,-1,5:18.12
3,0,5:18.13
6,0,5:18.13
8,0,5:18.13
11,0,5:18.12
12,0,5:18.12
4,1,5:18.12
4,2,5:18.12
11,-10,6:18.4
11,-9,6:18.4
0,-8,6:18.12
1,-8,6:18.12
10,-8,6:18.12
0,-7,6:18.12
2,-7,6:18.12
3,-7,6:18.12
10,-7,6:18.12
-1,-6,6:18.12
0,-6,6:18.12
1,-6,6:18.12
2,-6,6:18.12
3,-6,6:18.12
4,-6,6:18.12
5,-6,6:18.12
9,-6,6:18.12
1,-5,6:18.12
2,-5,6:18.12
4,-5,6:18.13
5,-5,6:18.12
6,-5,6:18.12
7,-5,6:18.12
8,-5,6:18.12
9,-5,6:18.12
1,-4,6:18.12
4,-4,6:18.13
5,-4,6:18.13
6,-4,6:18.13
7,-4,6:18.12
8,-4,6:18.12
9,-4,6:18.12
4,-3,6:18.13
5,-3,6:18.13
6,-3,6:18.12
7,-3,6:18.12
8,-3,6:18.12
9,-3,6:18.12
2,-2,6:18.13
3,-2,6:18.13
4,-2,6:18.13
5,-2,6:18.13
6,-2,6:18.12
7,-2,6:18.12
8,-2,6:18.12
9,-2,6:18.12
10,-2,6:18.12
5,-1,6:18.13
6,-1,6:18.12
10,-1,6:18.12
11,-1,6:18.12
11,0,6:18.12
12,0,6:18.12
4,1,6:18.12
4,2,6:18.4
3,3,6:18.4
1,-9,7:18.12
1,-8,7:18.12
10,-8,7:18.12
-2,-7,7:18.12
-1,-7,7:18.12
0,-7,7:18.12
2,-7,7:18.12
3,-7,7:18.12
10,-7,7:18.12
1,-6,7:18.12
2,-6,7:18.12
3,-6,7:18.12
4,-6,7:18.12
5,-6,7:18.12
9,-6,7:18.12
1,-5,7:18.12
4,-5,7:18.13
5,-5,7:18.12
6,-5,7:18.12
7,-5,7:18.12
8,-5,7:18.12
9,-5,7:18.12
1,-4,7:18.12
4,-4,7:18.13
6,-4,7:18.13
7,-4,7:18.13
8,-4,7:17.12
9,-4,7:18.12
1,-3,7:18.12
4,-3,7:18.13
5,-3,7:18.13
6,-3,7:18.12
7,-3,7:18.12
8,-3,7:18.12
9,-3,7:18.12
2,-2,7:18.13
3,-2,7:18.13
5,-2,7:18.13
6,-2,7:18.12
9,-2,7:18.12
10,-2,7:18.12
5,-1,7:18.12
6,-1,7:18.12
10,-1,7:18.12
11,-1,7:18.12
12,0,7:18.12
4,1,7:18.12
4,2,7:18.4
1,-10,8:18.4
1,-9,8:18.4
1,-8,8:18.4
-4,-7,8:18.4
-3,-7,8:18.4
-2,-7,8:18.4
-1,-7,8:18.4
0,-7,8:18.12
1,-6,8:18.12
2,-6,8:18.12
4,-6,8:18.12
5,-6,8:18.12
9,-6,8:18.12
1,-5,8:18.12
4,-5,8:18.13
5,-5,8:18.12
6,-5,8:18.12
7,-5,8:18.12
8,-5,8:18.12
9,-5,8:18.12
1,-4,8:18.12
4,-4,8:18.13
5,-4,8:18.13
6,-4,8:18.13
7,-4,8:17.12
8,-4,8:17.12
1,-3,8:18.12
4,-3,8:18.13
5,-3,8:18.13
6,-3,8:18.12
7,-3,8:18.12
8,-3,8:18.12
2,-2,8:18.13
3,-2,8:18.13
4,-2,8:18.13
5,-2,8:18.13
6,-2,8:18.12
8,-2,8:18.12
9,-2,8:18.12
6,-1,8:18.12
8,-1,8:18.12
9,-1,8:18.12
9,0,8:18.12
9,1,8:18.12
1,-10,9:18.4
2,-10,9:18.4
1,-9,9:18.4
2,-9,9:18.4
1,-8,9:18.4
-4,-7,9:18.4
-3,-7,9:18.4
-2,-7,9:18.4
-1,-7,9:18.4
0,-7,9:18.12
2,-7,9:18.12
7,-7,9:18.13
0,-6,9:18.12
1,-6,9:18.12
2,-6,9:18.12
3,-6,9:18.12
4,-6,9:18.12
5,-6,9:18.12
6,-6,9:18.13
7,-6,9:18.12
1,-5,9:18.12
2,-5,9:18.13
5,-5,9:18.13
6,-5,9:18.13
7,-5,9:18.12
10,-5,9:18.12
1,-4,9:18.12
3,-4,9:18.13
4,-4,9:18.13
5,-4,9:18.13
7,-4,9:17.12
8,-4,9:18.12
1,-3,9:18.12
4,-3,9:18.13
5,-3,9:18.12
6,-3,9:18.12
7,-3,9:18.12
8,-3,9:18.12
1,-2,9:18.12
3,-2,9:18.13
4,-2,9:18.12
5,-2,9:18.13
6,-2,9:18.13
8,-2,9:18.12
2,-1,9:18.13
3,-1,9:18.13
9,-1,9:18.12
1,0,9:18.13
2,0,9:18.13
9,0,9:18.12
2,-11,10:18.4
2,-10,10:18.4
1,-9,10:18.4
2,-9,10:18.4
1,-8,10:18.4
6,-8,10:18.12
-2,-7,10:18.4
-1,-7,10:18.4
0,-7,10:18.12
2,-7,10:18.12
6,-7,10:18.12
7,-7,10:18.13
0,-6,10:18.12
1,-6,10:18.12
2,-6,10:18.12
3,-6,10:18.12
4,-6,10:18.12
5,-6,10:18.12
6,-6,10:18.13
7,-6,10:18.12
12,-6,10:18.12
1,-5,10:18.12
2,-5,10:18.13
5,-5,10:18.13
6,-5,10:18.13
7,-5,10:18.12
9,-5,10:18.12
10,-5,10:18.12
11,-5,10:18.12
1,-4,10:18.12
3,-4,10:18.13
4,-4,10:18.13
5,-4,10:18.13
7,-4,10:17.12
8,-4,10:18.12
9,-4,10:18.12
1,-3,10:18.12
4,-3,10:18.13
5,-3,10:18.12
6,-3,10:18.12
7,-3,10:18.12
8,-3,10:18.12
0,-2,10:18.12
3,-2,10:18.13
4,-2,10:18.12
5,-2,10:18.13
6,-2,10:18.13
8,-2,10:18.12
2,-1,10:18.13
3,-1,10:18.13
8,-1,10:18.12
9,-1,10:18.12
1,0,10:18.13
2,0,10:18.13
1,1,10:18.13
1,-9,11:18.4
1,-8,11:18.4
5,-8,11:18.12
6,-8,11:18.12
-2,-7,11:18.4
-1,-7,11:18.4
0,-7,11:18.12
6,-7,11:18.12
0,-6,11:18.12
1,-6,11:18.12
2,-6,11:18.12
3,-6,11:18.12
4,-6,11:18.12
6,-6,11:18.13
7,-6,11:18.12
12,-6,11:18.12
0,-5,11:18.12
1,-5,11:18.12
2,-5,11:18.13
5,-5,11:18.13
6,-5,11:18.13
7,-5,11:18.12
9,-5,11:18.12
10,-5,11:18.12
11,-5,11:18.12
0,-4,11:18.12
3,-4,11:18.13
4,-4,11:18.13
5,-4,11:18.13
7,-4,11:18.12
8,-4,11:18.12
9,-4,11:18.12
4,-3,11:18.13
5,-3,11:18.12
6,-3,11:18.12
7,-3,11:18.12
8,-3,11:18.12
3,-2,11:18.13
4,-2,11:18.12
5,-2,11:18.13
6,-2,11:18.13
8,-2,11:18.12
2,-1,11:18.13
3,-1,11:18.13
10,1,11:18.4
1,-10,12:18.4
4,-10,12:18.4
1,-9,12:18.4
5,-9,12:18.4
1,-8,12:18.4
5,-8,12:18.12
6,-8,12:18.12
-4,-7,12:18.4
-3,-7,12:18.4
-2,-7,12:18.4
-1,-7,12:18.4
0,-7,12:18.12
6,-7,12:18.12
0,-6,12:18.12
1,-6,12:18.12
2,-6,12:18.12
3,-6,12:18.13
4,-6,12:18.12
5,-6,12:18.12
7,-6,12:18.12
12,-6,12:18.12
0,-5,12:18.12
3,-5,12:18.13
5,-5,12:18.12
7,-5,12:18.12
8,-5,12:18.12
9,-5,12:18.12
10,-5,12:18.12
11,-5,12:18.12
12,-5,12:18.12
0,-4,12:18.12
4,-4,12:18.13
5,-4,12:18.13
6,-4,12:18.12
7,-4,12:18.12
8,-4,12:18.12
9,-4,12:18.12
10,-4,12:18.12
0,-3,12:18.12
3,-3,12:18.13
4,-3,12:17.12
5,-3,12:18.12
6,-3,12:18.12
7,-3,12:18.12
8,-3,12:18.12
9,-3,12:18.12
0,-2,12:18.12
1,-2,12:18.13
2,-2,12:18.13
3,-2,12:18.12
4,-2,12:18.12
5,-2,12:18.13
8,-2,12:18.12
2,-1,12:18.12
5,-1,12:18.13
9,-1,12:18.12
6,0,12:18.13
9,0,12:18.12
10,1,12:18.4
10,2,12:18.4
11,2,12:18.4
1,-9,13:18.4
5,-9,13:18.4
1,-8,13:18.4
5,-8,13:18.12
6,-8,13:18.12
-4,-7,13:18.4
-3,-7,13:18.4
-2,-7,13:18.4
-1,-7,13:18.4
0,-7,13:18.12
6,-7,13:18.12
0,-6,13:18.12
1,-6,13:18.12
2,-6,13:18.12
3,-6,13:18.12
4,-6,13:18.12
5,-6,13:18.12
7,-6,13:18.12
13,-6,13:18.4
0,-5,13:18.12
3,-5,13:18.13
6,-5,13:18.12
7,-5,13:18.12
8,-5,13:18.12
10,-5,13:18.12
11,-5,13:18.12
12,-5,13:18.12
13,-5,13:18.4
0,-4,13:18.12
4,-4,13:18.13
5,-4,13:18.13
6,-4,13:18.13
7,-4,13:18.12
8,-4,13:17.12
9,-4,13:18.12
10,-4,13:18.12
0,-3,13:18.12
3,-3,13:18.13
4,-3,13:18.13
5,-3,13:18.13
6,-3,13:18.12
7,-3,13:18.12
8,-3,13:18.12
9,-3,13:18.12
0,-2,13:18.12
1,-2,13:18.13
2,-2,13:18.13
3,-2,13:18.12
4,-2,13:18.12
5,-2,13:18.13
8,-2,13:18.12
2,-1,13:18.12
3,-1,13:18.12
5,-1,13:18.13
9,-1,13:18.12
6,0,13:18.13
9,0,13:18.12
10,0,13:18.12
10,1,13:18.4
11,2,13:18.4
0,-7,14:18.12
6,-7,14:18.12
0,-6,14:18.12
1,-6,14:18.12
2,-6,14:18.12
4,-6,14:18.12
5,-6,14:18.13
6,-6,14:18.12
7,-6,14:18.12
13,-6,14:18.4
0,-5,14:18.12
4,-5,14:18.13
6,-5,14:18.12
7,-5,14:18.12
8,-5,14:18.12
10,-5,14:18.12
11,-5,14:18.12
12,-5,14:18.12
0,-4,14:18.12
4,-4,14:18.13
6,-4,14:18.13
7,-4,14:18.12
8,-4,14:17.12
9,-4,14:18.12
10,-4,14:18.12
0,-3,14:18.12
3,-3,14:18.13
4,-3,14:18.13
5,-3,14:18.13
6,-3,14:18.12
7,-3,14:18.12
8,-3,14:18.12
0,-2,14:18.12
3,-2,14:18.12
4,-2,14:18.12
5,-2,14:18.13
8,-2,14:18.12
2,-1,14:18.12
3,-1,14:18.13
5,-1,14:18.13
9,-1,14:18.12
3,0,14:18.13
9,0,14:18.12
10,0,14:18.12
10,1,14:18.4
11,2,14:18.4
-1,-8,15:18.4
2,-8,15:18.4
0,-7,15:18.12
6,-7,15:18.12
0,-6,15:18.12
1,-6,15:18.12
5,-6,15:18.13
6,-6,15:18.12
7,-6,15:18.12
-1,-5,15:18.4
2,-5,15:18.12
4,-5,15:18.13
7,-5,15:18.12
8,-5,15:18.12
10,-5,15:18.12
11,-5,15:18.12
2,-4,15:18.13
3,-4,15:18.13
4,-4,15:18.13
7,-4,15:18.12
8,-4,15:18.12
9,-4,15:18.12
10,-4,15:18.12
4,-3,15:18.13
5,-3,15:18.12
6,-3,15:18.12
7,-3,15:18.12
8,-3,15:18.12
3,-2,15:18.13
4,-2,15:18.13
8,-2,15:18.12
3,-1,15:18.13
9,-1,15:18.12
3,0,15:18.13
9,0,15:18.12
9,1,15:18.4
-2,-9,16:18.4
-1,-9,16:18.4
5,-9,16:18.4
-1,-8,16:18.4
2,-8,16:18.4
5,-8,16:18.12
0,-7,16:18.12
6,-7,16:18.12
0,-6,16:18.12
1,-6,16:18.12
6,-6,16:18.12
-1,-5,16:18.4
2,-5,16:18.12
4,-5,16:18.13
7,-5,16:18.12
10,-5,16:18.12
11,-5,16:18.12
2,-4,16:18.13
3,-4,16:18.13
4,-4,16:18.13
7,-4,16:18.12
8,-4,16:18.12
9,-4,16:18.12
3,-3,16:18.12
4,-3,16:18.13
5,-3,16:18.12
6,-3,16:18.12
7,-3,16:17.0
8,-3,16:18.12
2,-2,16:18.12
3,-2,16:18.13
4,-2,16:18.13
8,-2,16:18.12
3,-1,16:18.13
8,-1,16:18.12
9,-1,16:18.12
3,0,16:18.13
9,0,16:18.12
9,1,16:18.4
9,2,16:18.4
10,2,16:18.4
10,3,16:18.4
5,-9,17:18.4
2,-8,17:18.4
5,-8,17:18.12
6,-8,17:18.12
0,-7,17:18.4
6,-7,17:18.12
0,-6,17:18.4
1,-6,17:18.4
6,-6,17:18.12
7,-6,17:18.12
12,-6,17:18.12
-1,-5,17:18.4
2,-5,17:18.4
5,-5,17:18.13
7,-5,17:18.12
10,-5,17:18.12
11,-5,17:18.12
3,-4,17:18.5
4,-4,17:18.13
5,-4,17:18.13
7,-4,17:18.12
8,-4,17:18.12
9,-4,17:18.12
3,-3,17:18.5
4,-3,17:18.13
5,-3,17:18.12
6,-3,17:18.12
7,-3,17:17.0
8,-3,17:18.12
2,-2,17:18.4
3,-2,17:18.4
4,-2,17:18.12
5,-2,17:18.13
8,-2,17:18.12
8,-1,17:18.12
9,-1,17:18.12
9,0,17:18.12
9,1,17:18.4
10,2,17:18.4
10,3,17:18.4
5,-10,18:18.4
5,-9,18:18.4
0,-8,18:18.4
5,-8,18:18.4
6,-8,18:18.4
0,-7,18:18.4
2,-7,18:18.4
3,-7,18:18.4
6,-7,18:18.4
-1,-6,18:18.4
0,-6,18:18.4
1,-6,18:18.4
6,-6,18:18.4
7,-6,18:18.4
1,-5,18:18.4
2,-5,18:18.5
5,-5,18:18.5
7,-5,18:18.4
10,-5,18:18.4
11,-5,18:18.4
3,-4,18:18.5
4,-4,18:18.5
5,-4,18:18.5
7,-4,18:18.4
8,-4,18:18.4
9,-4,18:18.4
3,-3,18:18.5
4,-3,18:18.5
5,-3,18:18.4
6,-3,18:18.4
7,-3,18:18.4
8,-3,18:18.4
2,-2,18:18.4
3,-2,18:18.4
5,-2,18:18.5
8,-2,18:18.4
9,-1,18:18.4
9,0,18:18.4
9,1,18:18.4
10,2,18:18.4
10,3,18:18.4
0,-7,19:18.4
2,-7,19:18.4
6,-7,19:18.4
-1,-6,19:18.4
0,-6,19:18.4
1,-6,19:18.4
1,-5,19:18.4
2,-5,19:18.5
7,-5,19:18.4
3,-4,19:18.5
4,-4,19:18.5
7,-4,19:18.4
8,-4,19:18.4
3,-3,19:18.5
4,-3,19:18.5
5,-3,19:18.4
6,-3,19:18.4
7,-3,19:18.4
8,-3,19:18.4
2,-2,19:18.4
3,-2,19:18.4
4,-2,19:18.4
5,-2,19:18.5
8,-2,19:18.4
9,0,19:18.4
10,3,19:18.4
7,-5,20:18.4
3,-4,20:18.5
7,-4,20:18.4
8,-4,20:17.0
3,-3,20:18.5
4,-3,20:17.0
7,-3,20:18.4
8,-3,20:17.0
10,-3,20:18.4
9,-8,21:18.4
8,-7,21:18.4
8,-6,21:18.4
5,-5,21:18.4
8,-5,21:18.4
6,-4,21:18.4
7,-4,21:18.4
8,-4,21:18.4
7,-3,21:18.4
8,-3,21:18.4
9,-3,21:18.4
10,-3,21:18.4
11,-3,21:18.4
7,-2,21:18.4
7,-1,21:18.4
6,0,21:18.4
6,1,21:18.4
9,-8,22:18.4
8,-7,22:18.4
8,-6,22:18.4
5,-5,22:18.4
8,-5,22:18.4
6,-4,22:18.4
7,-4,22:18.4
8,-4,22:18.4
7,-3,22:18.4
8,-3,22:18.4
9,-3,22:18.4
10,-3,22:18.4
11,-3,22:18.4
12,-3,22:18.4
7,-2,22:18.4
7,-1,22:18.4
6,0,22:18.4
6,1,22:18.4
8,-6,23:18.4
4,-5,23:18.4
5,-5,23:18.4
8,-5,23:18.4
6,-4,23:18.4
7,-4,23:18.4
8,-4,23:18.4
7,-3,23:18.4
8,-3,23:17.0
9,-3,23:18.4
10,-3,23:18.4
7,-2,23:18.4
7,-1,23:18.4
6,0,23:18.4
6,1,23:18.4
8,-5,24:18.4
8,-4,24:18.4
8,-3,24:17.0
6,-5,25:18.4
9,-5,25:18.4
7,-4,25:18.4
8,-4,25:18.4
6,-3,25:18.4
7,-3,25:18.4
8,-3,25:18.4
9,-3,25:18.4
6,-2,25:18.4
9,-2,25:18.4
10,-2,25:18.4
5,-6,26:18.4
6,-5,26:18.4
7,-4,26:18.4
8,-4,26:18.4
7,-3,26:18.4
8,-3,26:18.4
9,-3,26:18.4
6,-2,26:18.4
10,-2,26:18.4
8,-4,27:17.0
