[META]
version=2.0
spawnOnBlockType=2
spawnSunlight=True
spawnDarkness=True
spawnWater=False
spawnLava=False
underFill=False
randomRotation=True
dig=True
tree=False
branch=False
needsFoundation=True
rarity=100
collisionPercentage=20
spawnElevationMin=0
spawnElevationMax=200
spawnInBiome=Custom
[DATA]
2,-4,-8:17.12
3,-4,-8:17.12
4,-4,-8:17.12
3,-3,-8:17.12
3,-2,-8:17.12
2,-3,-7:17.12
3,-3,-7:17.12
1,-2,-7:17.12
3,-5,-6:17.12
1,-4,-6:17.12
3,-4,-6:17.12
4,-4,-6:17.12
5,-4,-6:17.12
2,-3,-6:17.12
3,-3,-6:17.12
4,-3,-6:17.12
5,-3,-6:17.12
2,-2,-6:17.12
3,-2,-6:17.12
4,-2,-6:17.12
2,-1,-6:17.12
3,-1,-6:17.12
2,-5,-5:17.12
3,-5,-5:17.12
4,-5,-5:17.12
3,-4,-5:17.12
4,-4,-5:17.12
1,-3,-5:17.12
2,-3,-5:17.12
3,-3,-5:17.12
4,-3,-5:17.12
1,-2,-5:17.12
3,-2,-5:17.12
4,-2,-5:17.12
5,-2,-5:17.12
1,-1,-5:17.12
2,-1,-5:17.12
3,-1,-5:17.12
4,-1,-5:17.12
2,1,-5:17.12
3,-5,-4:17.12
4,-5,-4:17.12
1,-4,-4:17.12
2,-4,-4:17.12
3,-4,-4:17.12
4,-4,-4:17.12
5,-4,-4:17.12
1,-3,-4:17.12
2,-3,-4:17.12
3,-3,-4:17.12
4,-3,-4:17.12
5,-3,-4:17.12
1,-2,-4:17.12
2,-2,-4:17.12
3,-2,-4:17.12
4,-2,-4:17.12
0,-1,-4:17.12
2,-1,-4:17.12
3,-1,-4:17.12
4,-1,-4:17.12
1,0,-4:17.12
2,1,-4:17.12
3,-5,-3:17.12
4,-5,-3:17.12
3,-4,-3:17.12
2,-3,-3:17.12
3,-3,-3:17.12
4,-3,-3:17.12
5,-3,-3:17.12
2,-2,-3:17.12
3,-2,-3:17.12
4,-2,-3:17.12
5,-2,-3:17.12
3,-1,-3:17.12
1,1,-3:17.12
2,1,-3:17.12
3,1,-3:17.12
3,-5,-2:17.12
4,-5,-2:17.12
2,-4,-2:17.12
3,-4,-2:17.12
4,-4,-2:17.12
5,-4,-2:17.12
1,-3,-2:17.12
2,-3,-2:17.12
3,-3,-2:17.12
5,-3,-2:17.12
0,-2,-2:17.12
1,-2,-2:17.12
2,-2,-2:17.12
3,-2,-2:17.12
4,-2,-2:17.12
5,-2,-2:17.12
1,-1,-2:17.12
2,-1,-2:17.12
3,-1,-2:17.12
4,-1,-2:17.12
1,0,-2:17.12
2,0,-2:17.12
1,1,-2:17.12
2,1,-2:17.12
3,-4,-1:17.12
4,-4,-1:17.12
5,-4,-1:17.12
0,-3,-1:17.12
1,-3,-1:17.12
3,-3,-1:17.12
5,-3,-1:17.12
0,-2,-1:17.12
1,-2,-1:17.12
3,-2,-1:17.12
4,-2,-1:17.12
5,-2,-1:17.12
1,0,-1:17.12
2,0,-1:17.12
-1,-4,0:18.14
3,-4,0:17.12
4,-4,0:17.12
5,-4,0:17.12
-1,-3,0:18.14
0,-3,0:17.12
1,-3,0:17.12
3,-3,0:17.12
5,-3,0:17.12
-1,-2,0:18.14
0,-2,0:17.12
1,-2,0:17.12
2,-2,0:18.14
3,-2,0:17.12
4,-2,0:17.12
5,-2,0:17.12
1,0,0:17.12
2,0,0:17.12
-1,-4,1:18.14
0,-4,1:18.14
1,-4,1:18.14
4,-4,1:17.12
5,-4,1:17.12
-1,-3,1:18.14
0,-3,1:18.14
1,-3,1:18.14
2,-3,1:18.14
3,-3,1:17.12
4,-3,1:17.12
5,-3,1:17.12
-1,-2,1:18.14
0,-2,1:18.14
1,-2,1:18.14
2,-2,1:18.14
4,-2,1:17.12
5,-2,1:17.12
-2,-1,1:18.14
-1,-1,1:18.14
0,-1,1:18.14
1,-1,1:18.14
2,-1,1:18.14
2,0,1:17.12
-1,-4,2:18.14
0,-4,2:18.14
1,-4,2:18.14
2,-4,2:18.14
4,-4,2:17.12
5,-4,2:17.12
-2,-3,2:18.14
-1,-3,2:18.14
0,-3,2:18.14
1,-3,2:18.14
2,-3,2:18.14
3,-3,2:18.12
4,-3,2:17.12
5,-3,2:17.12
-2,-2,2:18.14
-1,-2,2:18.14
0,-2,2:18.14
1,-2,2:18.14
2,-2,2:18.14
3,-2,2:18.12
4,-2,2:17.12
5,-2,2:17.12
-1,-1,2:18.14
0,-1,2:18.14
1,-1,2:18.14
2,0,2:17.12
0,2,2:18.12
0,3,2:18.12
-1,4,2:18.12
0,-5,3:18.14
-1,-4,3:18.14
0,-4,3:18.14
1,-4,3:18.14
4,-4,3:17.12
5,-4,3:17.12
-2,-3,3:18.14
-1,-3,3:18.14
0,-3,3:18.14
1,-3,3:18.14
2,-3,3:18.14
3,-3,3:18.12
4,-3,3:17.12
5,-3,3:17.12
-2,-2,3:18.12
-1,-2,3:18.14
0,-2,3:18.14
1,-2,3:18.14
3,-2,3:18.12
4,-2,3:17.12
5,-2,3:17.12
-1,-1,3:18.14
0,-1,3:18.12
1,-1,3:18.12
2,-1,3:18.12
3,-1,3:18.12
0,0,3:18.14
1,0,3:18.12
2,0,3:18.12
1,1,3:18.12
2,1,3:18.12
3,1,3:18.12
0,2,3:18.12
3,2,3:18.12
4,2,3:18.12
0,3,3:18.12
-1,4,3:18.12
-1,-5,4:18.14
0,-5,4:18.14
-1,-4,4:18.14
0,-4,4:18.14
1,-4,4:18.14
4,-4,4:17.12
5,-4,4:17.12
-2,-3,4:18.14
-1,-3,4:18.14
0,-3,4:18.14
1,-3,4:18.14
2,-3,4:18.14
4,-3,4:17.12
5,-3,4:17.12
-2,-2,4:18.12
-1,-2,4:18.14
0,-2,4:18.14
1,-2,4:18.14
3,-2,4:18.12
4,-2,4:17.12
5,-2,4:17.12
0,-1,4:18.14
1,-1,4:18.14
2,-1,4:18.12
3,-1,4:18.12
1,0,4:18.12
2,0,4:18.12
1,1,4:18.12
2,1,4:18.12
3,1,4:18.12
0,2,4:18.12
2,2,4:18.12
3,2,4:18.12
4,2,4:18.12
0,3,4:18.12
3,3,4:18.12
6,-7,5:18.12
7,-7,5:18.12
6,-6,5:18.12
7,-6,5:18.12
8,-6,5:18.12
-1,-5,5:18.14
7,-5,5:18.12
-1,-4,5:18.14
0,-4,5:18.14
1,-4,5:18.14
2,-4,5:18.14
4,-4,5:17.12
5,-4,5:17.12
8,-4,5:18.12
-2,-3,5:18.14
-1,-3,5:18.14
0,-3,5:18.14
1,-3,5:18.14
2,-3,5:18.14
4,-3,5:17.12
5,-3,5:17.12
8,-3,5:18.12
-2,-2,5:18.14
-1,-2,5:18.14
0,-2,5:18.14
1,-2,5:18.14
4,-2,5:17.12
5,-2,5:17.12
0,-1,5:18.14
1,-1,5:18.12
2,-1,5:18.12
3,-1,5:18.12
1,0,5:18.12
2,0,5:18.12
3,0,5:18.12
4,0,5:18.12
5,0,5:18.12
6,0,5:18.12
-1,1,5:18.12
0,1,5:18.12
1,1,5:18.12
2,1,5:18.12
3,1,5:18.12
2,2,5:18.12
5,-10,6:18.4
6,-9,6:18.4
6,-8,6:18.12
7,-7,6:18.12
3,-6,6:18.12
4,-6,6:18.12
5,-6,6:18.12
6,-6,6:18.12
7,-6,6:18.12
8,-6,6:18.12
0,-5,6:18.14
7,-5,6:18.12
8,-5,6:18.12
9,-5,6:18.12
-1,-4,6:18.14
0,-4,6:18.14
1,-4,6:18.14
5,-4,6:17.12
9,-4,6:18.12
10,-4,6:18.4
-2,-3,6:18.14
-1,-3,6:18.14
0,-3,6:18.14
1,-3,6:18.14
2,-3,6:18.14
4,-3,6:17.12
5,-3,6:17.12
7,-3,6:18.12
8,-3,6:18.12
-1,-2,6:18.14
0,-2,6:18.14
1,-2,6:18.12
2,-2,6:18.12
4,-2,6:17.12
5,-2,6:17.12
8,-2,6:18.12
0,-1,6:18.14
1,-1,6:18.12
2,-1,6:18.12
3,-1,6:18.12
4,-1,6:18.12
8,-1,6:18.12
1,0,6:18.12
2,0,6:18.12
3,0,6:18.12
4,0,6:18.12
5,0,6:18.12
6,0,6:18.12
7,0,6:18.12
8,0,6:18.12
-1,1,6:18.12
0,1,6:18.12
2,1,6:18.12
3,1,6:18.12
3,2,6:18.12
3,3,6:18.12
4,3,6:18.12
4,4,6:18.12
6,-9,7:18.4
6,-8,7:18.12
6,-7,7:18.12
7,-7,7:18.12
1,-6,7:18.12
2,-6,7:18.12
3,-6,7:18.12
4,-6,7:18.12
5,-6,7:18.12
6,-6,7:18.12
7,-6,7:18.12
1,-5,7:18.12
6,-5,7:18.12
7,-5,7:18.12
8,-5,7:18.12
-1,-4,7:18.6
0,-4,7:18.14
1,-4,7:18.12
2,-4,7:18.12
5,-4,7:17.12
8,-4,7:18.12
9,-4,7:18.12
-1,-3,7:18.6
0,-3,7:18.14
1,-3,7:18.14
2,-3,7:18.12
4,-3,7:17.12
5,-3,7:17.12
7,-3,7:18.12
0,-2,7:18.14
1,-2,7:18.12
2,-2,7:18.12
4,-2,7:17.12
5,-2,7:17.12
7,-2,7:18.12
8,-2,7:18.12
1,-1,7:18.12
2,-1,7:18.12
3,-1,7:18.12
4,-1,7:18.12
5,-1,7:18.12
8,-1,7:18.12
9,-1,7:18.12
10,-1,7:18.4
11,-1,7:18.4
1,0,7:18.12
2,0,7:18.12
3,0,7:18.12
4,0,7:18.12
5,0,7:18.12
6,0,7:18.12
7,0,7:18.12
8,0,7:18.12
9,0,7:18.12
-1,1,7:18.4
0,1,7:18.12
1,1,7:18.12
2,1,7:18.12
3,1,7:18.12
7,1,7:18.12
-2,2,7:18.4
2,2,7:18.12
3,2,7:18.12
3,3,7:18.4
4,3,7:18.4
4,-8,8:18.12
6,-8,8:18.12
3,-7,8:18.12
6,-7,8:18.12
1,-6,8:18.12
2,-6,8:18.12
6,-6,8:18.12
0,-5,8:18.12
1,-5,8:18.12
2,-5,8:18.12
3,-5,8:18.12
4,-5,8:18.12
5,-5,8:18.12
6,-5,8:18.12
7,-5,8:18.12
-1,-4,8:18.6
0,-4,8:18.14
1,-4,8:18.14
2,-4,8:18.12
8,-4,8:18.12
-1,-3,8:18.6
0,-3,8:18.14
1,-3,8:18.14
2,-3,8:18.12
4,-3,8:17.12
5,-3,8:17.12
7,-3,8:18.12
-1,-2,8:18.6
0,-2,8:18.14
1,-2,8:18.12
2,-2,8:18.12
3,-2,8:18.12
4,-2,8:17.12
5,-2,8:17.12
7,-2,8:18.12
11,-2,8:18.4
1,-1,8:18.12
2,-1,8:18.12
3,-1,8:18.12
4,-1,8:18.12
5,-1,8:18.12
6,-1,8:18.12
7,-1,8:18.12
8,-1,8:18.12
9,-1,8:18.12
10,-1,8:18.4
1,0,8:18.12
2,0,8:18.12
3,0,8:18.12
6,0,8:18.12
7,0,8:18.12
-1,1,8:18.4
0,1,8:18.12
1,1,8:18.12
2,1,8:18.12
3,1,8:18.12
6,1,8:18.12
-2,2,8:18.4
2,2,8:18.12
3,2,8:18.12
4,2,8:18.12
5,2,8:18.12
6,2,8:18.12
3,3,8:18.4
6,-8,9:18.12
3,-7,9:18.12
4,-7,9:18.12
5,-7,9:18.12
6,-7,9:18.12
2,-6,9:18.12
3,-6,9:18.12
6,-6,9:18.12
0,-5,9:18.12
1,-5,9:18.12
2,-5,9:18.12
3,-5,9:18.12
4,-5,9:18.12
5,-5,9:18.12
6,-5,9:18.12
-2,-4,9:18.4
-1,-4,9:18.4
0,-4,9:18.14
1,-4,9:18.14
2,-4,9:18.12
3,-4,9:18.12
6,-4,9:18.12
8,-4,9:18.12
-1,-3,9:18.6
0,-3,9:18.14
1,-3,9:18.14
3,-3,9:18.12
4,-3,9:17.12
5,-3,9:17.12
6,-3,9:18.12
7,-3,9:18.12
0,-2,9:18.12
1,-2,9:18.12
2,-2,9:18.12
3,-2,9:18.12
4,-2,9:17.12
5,-2,9:17.12
7,-2,9:18.12
10,-2,9:18.4
1,-1,9:18.12
3,-1,9:18.12
4,-1,9:18.12
5,-1,9:18.12
6,-1,9:18.12
7,-1,9:18.12
8,-1,9:18.12
9,-1,9:18.12
10,-1,9:18.4
0,0,9:18.12
1,0,9:18.12
2,0,9:18.12
3,0,9:18.12
4,0,9:18.12
6,0,9:18.12
7,0,9:18.12
-1,1,9:18.4
0,1,9:18.12
2,1,9:18.12
3,1,9:18.12
4,1,9:18.12
5,1,9:18.12
6,1,9:18.12
2,2,9:18.12
4,2,9:18.12
5,2,9:18.12
6,2,9:18.12
2,3,9:18.4
3,3,9:18.4
7,3,9:18.4
3,4,9:18.4
10,4,9:18.4
3,-8,10:18.12
7,-8,10:18.12
8,-8,10:18.12
3,-7,10:18.12
4,-7,10:18.12
5,-7,10:18.12
6,-7,10:18.12
3,-6,10:18.12
4,-6,10:18.12
5,-6,10:18.12
6,-6,10:18.12
2,-5,10:18.12
3,-5,10:18.12
6,-5,10:18.12
7,-5,10:18.12
0,-4,10:18.12
1,-4,10:18.12
2,-4,10:18.12
3,-4,10:18.12
4,-4,10:18.12
5,-4,10:18.12
6,-4,10:18.12
8,-4,10:18.12
9,-4,10:18.12
0,-3,10:18.12
1,-3,10:18.12
3,-3,10:18.12
4,-3,10:17.12
5,-3,10:17.12
6,-3,10:18.12
9,-3,10:18.12
0,-2,10:18.12
3,-2,10:18.12
4,-2,10:18.12
5,-2,10:17.12
6,-2,10:18.12
7,-2,10:18.12
8,-2,10:18.12
9,-2,10:18.12
1,-1,10:18.12
2,-1,10:18.12
3,-1,10:18.12
4,-1,10:18.12
5,-1,10:18.12
6,-1,10:18.12
7,-1,10:18.12
8,-1,10:18.12
9,-1,10:18.12
0,0,10:18.12
1,0,10:18.12
2,0,10:18.12
3,0,10:18.12
4,0,10:18.12
5,0,10:18.12
6,0,10:18.12
7,0,10:18.12
-2,1,10:18.4
-1,1,10:18.4
0,1,10:18.12
2,1,10:18.12
4,1,10:18.12
5,1,10:18.12
6,1,10:18.12
2,2,10:18.12
3,2,10:18.12
4,2,10:18.12
5,2,10:18.12
6,2,10:18.12
7,2,10:18.12
2,3,10:18.4
3,3,10:18.4
7,3,10:18.4
8,3,10:18.4
9,3,10:18.4
3,4,10:18.4
10,4,10:18.4
0,-9,11:18.4
1,-8,11:18.12
2,-8,11:18.12
8,-8,11:18.12
3,-7,11:18.12
4,-7,11:18.12
5,-7,11:18.12
6,-7,11:18.12
7,-7,11:18.12
4,-6,11:18.12
5,-6,11:18.12
6,-6,11:18.12
3,-5,11:18.12
4,-5,11:18.12
5,-5,11:18.12
6,-5,11:18.12
7,-5,11:18.12
1,-4,11:18.12
2,-4,11:18.12
3,-4,11:18.12
4,-4,11:18.12
5,-4,11:18.12
6,-4,11:18.12
8,-4,11:18.12
10,-4,11:18.4
0,-3,11:18.12
1,-3,11:18.12
4,-3,11:18.12
5,-3,11:17.12
6,-3,11:18.12
7,-3,11:18.12
9,-3,11:18.12
0,-2,11:18.12
1,-2,11:18.12
3,-2,11:18.12
4,-2,11:18.12
5,-2,11:18.12
6,-2,11:18.12
7,-2,11:18.12
8,-2,11:18.12
9,-2,11:18.12
1,-1,11:18.12
2,-1,11:18.12
3,-1,11:18.12
4,-1,11:18.12
5,-1,11:18.12
6,-1,11:18.12
7,-1,11:18.12
8,-1,11:18.12
0,0,11:18.12
1,0,11:18.12
2,0,11:18.12
3,0,11:18.12
4,0,11:18.12
5,0,11:18.12
6,0,11:18.12
7,0,11:18.12
-2,1,11:18.4
-1,1,11:18.4
0,1,11:18.12
2,1,11:18.12
5,1,11:18.12
6,1,11:18.12
2,2,11:18.12
3,2,11:18.12
4,2,11:18.12
6,2,11:18.12
7,2,11:18.12
2,3,11:18.4
7,3,11:18.4
8,3,11:18.4
9,3,11:18.4
3,4,11:18.4
1,-8,12:18.4
2,-8,12:18.4
2,-7,12:18.12
3,-7,12:18.12
5,-7,12:18.12
6,-7,12:18.12
7,-7,12:18.12
4,-6,12:18.12
5,-6,12:18.12
11,-6,12:18.4
3,-5,12:18.12
4,-5,12:18.12
5,-5,12:18.12
6,-5,12:18.12
10,-5,12:18.4
11,-5,12:18.4
0,-4,12:18.12
2,-4,12:18.12
3,-4,12:18.12
4,-4,12:18.12
5,-4,12:18.12
6,-4,12:18.12
8,-4,12:18.12
10,-4,12:18.4
0,-3,12:18.12
1,-3,12:18.12
2,-3,12:18.12
3,-3,12:18.12
4,-3,12:18.12
5,-3,12:18.12
6,-3,12:18.12
8,-3,12:18.12
9,-3,12:18.12
0,-2,12:18.12
1,-2,12:18.12
2,-2,12:18.12
4,-2,12:18.12
5,-2,12:18.12
6,-2,12:18.12
7,-2,12:18.12
8,-2,12:18.12
9,-2,12:18.12
0,-1,12:18.12
2,-1,12:18.12
3,-1,12:18.12
4,-1,12:18.12
5,-1,12:18.12
6,-1,12:18.12
7,-1,12:18.12
9,-1,12:18.12
-1,0,12:18.4
0,0,12:18.12
1,0,12:18.12
2,0,12:18.12
3,0,12:18.12
4,0,12:18.12
5,0,12:18.12
6,0,12:18.12
9,0,12:18.12
-1,1,12:18.4
1,1,12:18.12
4,1,12:18.12
5,1,12:18.12
6,1,12:18.12
9,1,12:18.12
-2,2,12:18.4
1,2,12:18.12
2,2,12:18.12
3,2,12:18.12
4,2,12:18.12
7,2,12:18.12
8,3,12:18.4
9,3,12:18.4
1,-8,13:18.4
1,-7,13:18.12
2,-7,13:18.12
3,-7,13:18.12
6,-7,13:18.12
7,-7,13:18.12
11,-7,13:18.4
0,-6,13:18.12
3,-6,13:18.12
4,-6,13:18.12
5,-6,13:18.12
6,-6,13:18.12
11,-6,13:18.4
0,-5,13:18.12
4,-5,13:18.12
5,-5,13:18.12
10,-5,13:18.4
0,-4,13:18.12
3,-4,13:18.12
4,-4,13:18.12
5,-4,13:18.12
6,-4,13:18.12
9,-4,13:18.12
10,-4,13:18.4
0,-3,13:18.12
1,-3,13:18.12
2,-3,13:18.12
3,-3,13:18.12
4,-3,13:17.12
5,-3,13:17.12
7,-3,13:18.12
8,-3,13:18.12
9,-3,13:18.12
1,-2,13:18.12
2,-2,13:18.12
4,-2,13:17.12
5,-2,13:17.12
7,-2,13:18.12
8,-2,13:18.12
-1,-1,13:18.4
0,-1,13:18.12
1,-1,13:18.12
2,-1,13:18.12
3,-1,13:18.12
4,-1,13:18.12
6,-1,13:18.12
7,-1,13:18.12
8,-1,13:18.12
-1,0,13:18.4
0,0,13:18.12
1,0,13:18.12
2,0,13:18.12
3,0,13:18.12
4,0,13:18.12
5,0,13:18.12
6,0,13:18.12
8,0,13:18.12
-1,1,13:18.4
1,1,13:18.12
4,1,13:18.12
6,1,13:18.12
7,1,13:18.12
-1,2,13:18.4
1,2,13:18.12
2,2,13:18.12
3,2,13:18.12
7,2,13:18.12
8,2,13:18.12
0,3,13:18.4
8,3,13:18.4
9,3,13:18.4
1,-7,14:18.12
2,-7,14:18.12
3,-6,14:18.12
6,-6,14:18.12
7,-6,14:18.12
11,-6,14:18.4
0,-5,14:18.12
4,-5,14:18.12
5,-5,14:18.12
10,-5,14:18.4
0,-4,14:18.12
1,-4,14:18.12
4,-4,14:18.12
5,-4,14:18.12
6,-4,14:18.12
9,-4,14:18.12
10,-4,14:18.4
1,-3,14:18.12
2,-3,14:18.12
3,-3,14:18.12
4,-3,14:17.12
5,-3,14:17.12
6,-3,14:18.12
7,-3,14:18.12
8,-3,14:18.12
2,-2,14:18.12
3,-2,14:18.12
4,-2,14:17.12
5,-2,14:17.12
6,-2,14:18.12
7,-2,14:18.12
8,-2,14:18.12
0,-1,14:18.12
1,-1,14:18.12
2,-1,14:18.12
3,-1,14:18.12
4,-1,14:18.12
5,-1,14:18.12
6,-1,14:18.12
7,-1,14:18.12
8,-1,14:18.12
0,0,14:18.12
1,0,14:18.12
2,0,14:18.12
4,0,14:18.12
5,0,14:18.12
6,0,14:18.12
7,0,14:18.12
8,0,14:18.12
-1,1,14:18.4
1,1,14:18.12
3,1,14:18.12
4,1,14:18.12
6,1,14:18.12
7,1,14:18.12
-1,2,14:18.4
7,2,14:18.12
8,2,14:18.12
2,-6,15:18.12
3,-6,15:18.12
6,-6,15:18.12
11,-6,15:18.4
0,-5,15:18.12
1,-5,15:18.12
3,-5,15:18.12
4,-5,15:18.12
5,-5,15:18.12
6,-5,15:18.12
9,-5,15:18.12
10,-5,15:18.4
1,-4,15:18.12
4,-4,15:18.12
5,-4,15:18.12
8,-4,15:18.12
9,-4,15:18.12
2,-3,15:18.12
3,-3,15:18.12
4,-3,15:18.12
5,-3,15:17.12
6,-3,15:18.12
7,-3,15:18.12
8,-3,15:18.12
2,-2,15:18.12
3,-2,15:18.12
4,-2,15:17.12
5,-2,15:17.12
6,-2,15:18.12
7,-2,15:18.12
0,-1,15:18.12
1,-1,15:18.12
2,-1,15:18.12
4,-1,15:18.12
5,-1,15:18.12
6,-1,15:18.12
7,-1,15:18.12
0,0,15:18.12
1,0,15:18.12
2,0,15:18.12
3,0,15:18.12
4,0,15:18.12
5,0,15:18.12
6,0,15:18.12
0,1,15:18.12
1,1,15:18.12
2,1,15:18.12
3,1,15:18.12
7,1,15:18.12
8,2,15:18.12
3,-5,16:18.12
5,-5,16:18.12
6,-5,16:18.12
7,-5,16:18.12
9,-5,16:18.12
10,-5,16:18.4
1,-4,16:18.12
2,-4,16:18.12
4,-4,16:18.12
5,-4,16:18.12
6,-4,16:18.12
8,-4,16:18.12
9,-4,16:18.12
2,-3,16:18.12
3,-3,16:18.12
4,-3,16:18.12
5,-3,16:18.12
6,-3,16:18.12
7,-3,16:18.12
8,-3,16:18.12
2,-2,16:18.12
3,-2,16:18.12
4,-2,16:18.12
5,-2,16:17.12
6,-2,16:18.12
2,-1,16:18.12
3,-1,16:18.12
4,-1,16:18.12
5,-1,16:18.12
6,-1,16:18.12
1,0,16:18.12
2,0,16:18.12
3,0,16:18.12
4,0,16:18.12
5,0,16:18.12
6,0,16:18.12
7,0,16:18.12
0,1,16:18.12
4,1,16:18.12
7,1,16:18.12
8,1,16:18.12
4,-7,17:18.12
5,-6,17:18.12
6,-6,17:18.12
2,-5,17:18.12
3,-5,17:18.12
4,-5,17:18.12
5,-5,17:18.12
6,-5,17:18.12
7,-5,17:18.12
8,-5,17:18.12
9,-5,17:18.12
2,-4,17:18.12
3,-4,17:18.12
4,-4,17:18.12
5,-4,17:18.12
6,-4,17:18.12
8,-4,17:18.12
2,-3,17:18.12
3,-3,17:18.12
4,-3,17:18.12
5,-3,17:18.12
6,-3,17:18.12
7,-3,17:18.12
2,-2,17:18.12
3,-2,17:18.12
4,-2,17:18.12
5,-2,17:18.12
6,-2,17:18.12
7,-2,17:18.12
8,-2,17:18.12
2,-1,17:18.12
3,-1,17:18.12
4,-1,17:18.12
5,-1,17:18.12
6,-1,17:18.12
8,-1,17:18.12
-1,0,17:18.4
0,0,17:18.12
1,0,17:18.12
2,0,17:18.12
3,0,17:18.12
4,0,17:18.12
5,0,17:18.12
6,0,17:18.12
7,0,17:18.12
8,0,17:18.12
4,1,17:18.12
7,1,17:18.12
5,2,17:18.12
4,-6,18:18.12
5,-6,18:18.12
5,-5,18:18.12
6,-5,18:18.12
8,-5,18:18.12
2,-4,18:18.12
3,-4,18:18.12
4,-4,18:18.12
5,-4,18:18.12
6,-4,18:18.12
8,-4,18:18.12
9,-4,18:18.12
10,-4,18:18.4
1,-3,18:18.12
2,-3,18:18.12
3,-3,18:18.12
7,-3,18:18.12
3,-2,18:18.12
4,-2,18:17.12
5,-2,18:17.12
7,-2,18:18.12
3,-1,18:18.12
7,-1,18:18.12
8,-1,18:18.12
0,0,18:18.12
1,0,18:18.12
2,0,18:18.12
3,0,18:18.12
4,0,18:18.12
5,0,18:18.12
6,0,18:18.12
7,0,18:18.12
8,0,18:18.12
4,1,18:18.12
5,1,18:18.12
8,1,18:18.12
5,2,18:18.12
2,-7,19:18.12
2,-6,19:18.12
4,-6,19:18.12
2,-5,19:18.12
4,-5,19:18.12
5,-5,19:18.12
2,-4,19:18.12
3,-4,19:18.12
4,-4,19:18.12
5,-4,19:18.12
6,-4,19:18.12
8,-4,19:18.12
9,-4,19:18.12
10,-4,19:18.4
1,-3,19:18.12
2,-3,19:18.12
3,-3,19:18.12
6,-3,19:18.12
9,-3,19:18.12
1,-2,19:18.12
3,-2,19:18.12
4,-2,19:17.12
5,-2,19:17.12
6,-2,19:18.12
7,-2,19:18.12
8,-2,19:18.12
9,-2,19:18.12
0,-1,19:18.12
3,-1,19:18.12
4,-1,19:18.12
5,-1,19:18.12
6,-1,19:18.12
7,-1,19:18.12
8,-1,19:18.12
0,0,19:18.12
1,0,19:18.12
2,0,19:18.12
3,0,19:18.12
4,0,19:18.12
5,0,19:18.12
6,0,19:18.12
7,0,19:18.12
5,1,19:18.12
7,1,19:18.12
7,2,19:18.12
7,3,19:18.4
3,-7,20:18.4
2,-6,20:18.12
3,-6,20:18.12
2,-5,20:18.12
3,-5,20:18.12
4,-5,20:18.12
5,-5,20:18.12
3,-4,20:18.12
4,-4,20:18.12
5,-4,20:18.12
6,-4,20:18.12
8,-4,20:18.12
9,-4,20:18.12
2,-3,20:18.12
3,-3,20:18.12
4,-3,20:18.12
5,-3,20:18.12
6,-3,20:18.12
8,-3,20:18.12
9,-3,20:18.12
1,-2,20:18.12
3,-2,20:18.12
4,-2,20:18.12
5,-2,20:17.12
6,-2,20:18.12
7,-2,20:18.12
8,-2,20:18.12
1,-1,20:18.12
2,-1,20:18.12
3,-1,20:18.12
4,-1,20:18.12
5,-1,20:18.12
6,-1,20:18.12
7,-1,20:18.12
1,0,20:18.12
2,0,20:18.12
4,0,20:18.12
5,0,20:18.12
7,0,20:18.12
5,1,20:18.12
7,1,20:18.12
7,2,20:18.12
3,-6,21:18.12
3,-5,21:18.12
3,-4,21:18.12
4,-4,21:18.12
5,-4,21:18.12
8,-4,21:18.12
3,-3,21:18.12
4,-3,21:18.12
5,-3,21:18.12
6,-3,21:18.12
7,-3,21:18.12
8,-3,21:18.12
2,-2,21:18.12
3,-2,21:18.12
4,-2,21:18.12
5,-2,21:17.0
6,-2,21:18.12
7,-2,21:18.12
1,-1,21:18.12
2,-1,21:18.12
3,-1,21:18.12
4,-1,21:18.12
5,-1,21:18.12
6,-1,21:18.12
5,0,21:18.12
6,0,21:18.12
6,1,21:18.12
7,1,21:18.12
6,2,21:18.12
7,2,21:18.12
3,-5,22:18.12
3,-4,22:18.12
4,-4,22:18.12
4,-3,22:18.12
5,-3,22:18.12
6,-3,22:18.12
7,-3,22:18.12
8,-3,22:18.12
2,-2,22:18.12
3,-2,22:18.12
4,-2,22:18.12
5,-2,22:18.12
6,-2,22:18.12
2,-1,22:18.12
3,-1,22:18.12
4,-1,22:18.12
5,-1,22:18.12
6,-1,22:18.12
5,0,22:18.12
6,0,22:18.12
6,1,22:18.12
4,-4,23:18.12
4,-3,23:18.12
3,-2,23:18.12
4,-2,23:18.12
5,-2,23:18.12
6,-2,23:18.12
3,-1,23:18.12
4,-1,23:18.12
5,-1,23:18.12
5,0,23:18.12
5,-2,24:17.0
