[META]
version=2.0
spawnOnBlockType=2
spawnSunlight=True
spawnDarkness=True
spawnWater=False
spawnLava=False
underFill=False
randomRotation=True
dig=True
tree=False
branch=False
needsFoundation=True
rarity=100
collisionPercentage=20
spawnElevationMin=0
spawnElevationMax=200
spawnInBiome=Custom
[DATA]
3,-12,-8:17.12
2,-11,-8:17.12
4,-11,-8:17.12
1,-10,-8:17.12
3,-10,-8:17.12
4,-10,-8:17.12
2,-9,-8:17.12
7,-7,-8:17.12
9,-7,-8:17.12
3,-4,-8:17.12
4,-13,-7:17.12
3,-12,-7:17.12
4,-12,-7:17.12
0,-11,-7:17.12
3,-11,-7:17.12
4,-11,-7:17.12
5,-11,-7:17.12
-1,-10,-7:17.12
0,-10,-7:17.12
2,-10,-7:17.12
4,-10,-7:17.12
5,-10,-7:17.12
0,-9,-7:17.12
1,-9,-7:17.12
4,-9,-7:17.12
5,-9,-7:17.12
7,-9,-7:17.12
-1,-8,-7:17.12
1,-8,-7:17.12
8,-8,-7:17.12
2,-7,-7:17.12
3,-7,-7:17.12
4,-7,-7:17.12
6,-7,-7:17.12
7,-7,-7:17.12
8,-7,-7:17.12
3,-6,-7:17.12
4,-6,-7:17.12
7,-6,-7:17.12
8,-6,-7:17.12
3,-5,-7:17.12
2,-4,-7:17.12
3,-4,-7:17.12
6,-4,-7:17.12
3,-3,-7:17.12
5,-3,-7:17.12
4,-13,-6:17.12
1,-12,-6:17.12
2,-12,-6:17.12
3,-12,-6:17.12
5,-12,-6:17.12
6,-12,-6:17.12
0,-11,-6:17.12
1,-11,-6:17.12
2,-11,-6:17.12
3,-11,-6:17.12
4,-11,-6:17.12
2,-10,-6:17.12
3,-10,-6:17.12
4,-10,-6:17.12
5,-10,-6:17.12
7,-10,-6:17.12
-2,-9,-6:17.12
0,-9,-6:17.12
3,-9,-6:17.12
4,-9,-6:17.12
5,-9,-6:17.12
-2,-8,-6:17.12
-1,-8,-6:17.12
1,-8,-6:17.12
2,-8,-6:17.12
3,-8,-6:17.12
4,-8,-6:17.12
5,-8,-6:17.12
6,-8,-6:17.12
8,-8,-6:17.12
0,-7,-6:17.12
3,-7,-6:17.12
5,-7,-6:17.12
6,-7,-6:17.12
7,-7,-6:17.12
8,-7,-6:17.12
9,-7,-6:17.12
0,-6,-6:17.12
1,-6,-6:17.12
2,-6,-6:17.12
3,-6,-6:17.12
5,-6,-6:17.12
6,-6,-6:17.12
7,-6,-6:17.12
8,-6,-6:17.12
2,-5,-6:17.12
3,-5,-6:17.12
4,-5,-6:17.12
2,-4,-6:17.12
3,-4,-6:17.12
4,-4,-6:17.12
5,-4,-6:17.12
6,-4,-6:17.12
8,-4,-6:17.12
5,-3,-6:17.12
6,-3,-6:17.12
8,-3,-6:17.12
5,-2,-6:17.12
7,-2,-6:17.12
2,-12,-5:17.12
3,-12,-5:17.12
5,-12,-5:17.12
0,-11,-5:17.12
2,-11,-5:17.12
3,-11,-5:17.12
2,-10,-5:17.12
3,-10,-5:17.12
4,-10,-5:17.12
5,-10,-5:17.12
6,-10,-5:17.12
-1,-9,-5:17.12
0,-9,-5:17.12
1,-9,-5:17.12
2,-9,-5:17.12
3,-9,-5:17.12
4,-9,-5:17.12
5,-9,-5:17.12
6,-9,-5:17.12
-2,-8,-5:17.12
0,-8,-5:17.12
1,-8,-5:17.12
2,-8,-5:17.12
3,-8,-5:17.12
4,-8,-5:17.12
6,-8,-5:17.12
7,-8,-5:17.12
-2,-7,-5:17.12
-1,-7,-5:17.12
0,-7,-5:17.12
1,-7,-5:17.12
2,-7,-5:17.12
3,-7,-5:17.12
4,-7,-5:17.12
5,-7,-5:17.12
6,-7,-5:17.12
8,-7,-5:17.12
9,-7,-5:17.12
-1,-6,-5:17.12
0,-6,-5:17.12
1,-6,-5:17.12
2,-6,-5:17.12
3,-6,-5:17.12
4,-6,-5:17.12
5,-6,-5:17.12
6,-6,-5:17.12
-1,-5,-5:17.12
0,-5,-5:17.12
1,-5,-5:17.12
2,-5,-5:17.12
3,-5,-5:17.12
5,-5,-5:17.12
6,-5,-5:17.12
7,-5,-5:17.12
1,-4,-5:17.12
2,-4,-5:17.12
3,-4,-5:17.12
4,-4,-5:17.12
5,-4,-5:17.12
6,-4,-5:17.12
7,-4,-5:17.12
8,-4,-5:17.12
2,-3,-5:17.12
4,-3,-5:17.12
5,-3,-5:17.12
6,-3,-5:17.12
8,-3,-5:17.12
2,-2,-5:17.12
4,-12,-4:17.12
5,-12,-4:17.12
1,-11,-4:17.12
2,-11,-4:17.12
3,-11,-4:17.12
5,-11,-4:17.12
5,-10,-4:17.12
7,-10,-4:17.12
-1,-9,-4:17.12
0,-9,-4:17.12
1,-9,-4:17.12
2,-9,-4:17.12
3,-9,-4:17.12
4,-9,-4:17.12
-2,-8,-4:17.12
-1,-8,-4:17.12
0,-8,-4:17.12
1,-8,-4:17.12
2,-8,-4:17.12
3,-8,-4:17.12
4,-8,-4:17.12
5,-8,-4:17.12
6,-8,-4:17.12
7,-8,-4:17.12
8,-8,-4:17.12
-2,-7,-4:17.12
-1,-7,-4:17.12
0,-7,-4:17.12
1,-7,-4:17.12
2,-7,-4:17.12
6,-7,-4:17.12
7,-7,-4:17.12
8,-7,-4:17.12
-1,-6,-4:17.12
0,-6,-4:17.12
1,-6,-4:17.12
2,-6,-4:17.12
3,-6,-4:17.12
4,-6,-4:17.12
5,-6,-4:17.12
7,-6,-4:17.12
8,-6,-4:17.12
9,-6,-4:17.12
0,-5,-4:17.12
1,-5,-4:17.12
2,-5,-4:17.12
3,-5,-4:17.12
4,-5,-4:17.12
5,-5,-4:17.12
6,-5,-4:17.12
7,-5,-4:17.12
0,-4,-4:17.12
1,-4,-4:17.12
2,-4,-4:17.12
3,-4,-4:17.12
4,-4,-4:17.12
5,-4,-4:17.12
6,-4,-4:17.12
7,-4,-4:17.12
8,-4,-4:17.12
1,-3,-4:17.12
2,-3,-4:17.12
4,-3,-4:17.12
6,-3,-4:17.12
1,-2,-4:17.12
3,-2,-4:17.12
5,-2,-4:17.12
7,-2,-4:17.12
1,-12,-3:17.12
2,-12,-3:17.12
3,-12,-3:17.12
3,-11,-3:17.12
4,-11,-3:17.12
5,-11,-3:17.12
-1,-10,-3:17.12
0,-10,-3:17.12
-1,-9,-3:17.12
0,-9,-3:17.12
6,-9,-3:17.12
7,-9,-3:17.12
0,-8,-3:17.12
1,-8,-3:17.12
2,-8,-3:17.12
3,-8,-3:17.12
4,-8,-3:17.12
5,-8,-3:17.12
6,-8,-3:17.12
7,-8,-3:17.12
8,-8,-3:17.12
-2,-7,-3:17.12
-1,-7,-3:17.12
0,-7,-3:17.12
1,-7,-3:17.12
3,-7,-3:17.12
5,-7,-3:17.12
6,-7,-3:17.12
7,-7,-3:17.12
9,-7,-3:17.12
-2,-6,-3:17.12
-1,-6,-3:17.12
0,-6,-3:17.12
1,-6,-3:17.12
2,-6,-3:17.12
3,-6,-3:17.12
4,-6,-3:17.12
8,-6,-3:17.12
-1,-5,-3:17.12
0,-5,-3:17.12
3,-5,-3:17.12
4,-5,-3:17.12
5,-5,-3:17.12
6,-5,-3:17.12
7,-5,-3:17.12
8,-5,-3:17.12
-1,-4,-3:17.12
0,-4,-3:17.12
2,-4,-3:17.12
3,-4,-3:17.12
5,-4,-3:17.12
6,-4,-3:17.12
7,-4,-3:17.12
1,-3,-3:17.12
5,-3,-3:17.12
6,-3,-3:17.12
1,-2,-3:17.12
3,-2,-3:17.12
5,-2,-3:17.12
1,-12,-2:17.12
2,-12,-2:17.12
3,-12,-2:17.12
4,-12,-2:17.12
0,-11,-2:17.12
1,-11,-2:17.12
2,-11,-2:17.12
4,-11,-2:17.12
5,-11,-2:17.12
6,-11,-2:17.12
-2,-10,-2:17.12
-1,-10,-2:17.12
0,-10,-2:17.12
6,-10,-2:17.12
7,-10,-2:17.12
-2,-9,-2:17.12
7,-9,-2:17.12
8,-9,-2:17.12
-2,-8,-2:17.12
0,-8,-2:17.12
7,-8,-2:17.12
8,-8,-2:17.12
-2,-7,-2:17.12
-1,-7,-2:17.12
1,-7,-2:17.12
2,-7,-2:17.12
7,-7,-2:17.12
8,-7,-2:17.12
-2,-6,-2:17.12
0,-6,-2:17.12
1,-6,-2:17.12
2,-6,-2:17.12
7,-6,-2:17.12
8,-6,-2:17.12
-2,-5,-2:17.12
2,-5,-2:17.12
6,-5,-2:17.12
7,-5,-2:17.12
8,-5,-2:17.12
-2,-4,-2:17.12
2,-4,-2:17.12
7,-4,-2:17.12
8,-4,-2:17.12
-1,-3,-2:17.12
0,-3,-2:17.12
2,-3,-2:17.12
5,-3,-2:17.12
6,-3,-2:17.12
7,-3,-2:17.12
1,-2,-2:17.12
2,-2,-2:17.12
4,-2,-2:17.12
5,-2,-2:17.12
2,-1,-2:17.12
3,-1,-2:17.12
1,-11,-1:17.12
2,-11,-1:17.12
3,-11,-1:17.12
4,-11,-1:17.12
0,-10,-1:17.12
1,-10,-1:17.12
2,-10,-1:17.12
4,-10,-1:17.12
5,-10,-1:17.12
6,-10,-1:17.12
-2,-9,-1:17.12
-1,-9,-1:17.12
0,-9,-1:17.12
5,-9,-1:17.12
6,-9,-1:17.12
7,-9,-1:17.12
-2,-8,-1:17.12
-1,-8,-1:17.12
7,-8,-1:17.12
-2,-7,-1:17.12
-1,-7,-1:17.12
7,-7,-1:17.12
-2,-6,-1:17.12
-1,-6,-1:17.12
7,-6,-1:17.12
-2,-5,-1:17.12
-1,-5,-1:17.12
7,-5,-1:17.12
-2,-4,-1:17.12
-1,-4,-1:17.12
7,-4,-1:17.12
-1,-3,-1:17.12
0,-3,-1:17.12
1,-3,-1:17.12
5,-3,-1:17.12
6,-3,-1:17.12
1,-2,-1:17.12
2,-2,-1:17.12
3,-2,-1:17.12
4,-2,-1:17.12
5,-2,-1:17.12
3,-1,-1:17.12
2,-10,0:17.12
3,-10,0:17.12
4,-10,0:17.12
0,-9,0:17.12
1,-9,0:17.12
2,-9,0:17.12
4,-9,0:17.12
5,-9,0:17.12
6,-9,0:17.12
-1,-8,0:17.12
0,-8,0:17.12
5,-8,0:17.12
6,-8,0:17.12
7,-8,0:17.12
-1,-7,0:17.12
7,-7,0:17.12
-1,-6,0:17.12
7,-6,0:17.12
-1,-5,0:17.12
7,-5,0:17.12
-1,-4,0:17.12
0,-4,0:17.12
6,-4,0:17.12
7,-4,0:17.12
0,-3,0:17.12
1,-3,0:17.12
5,-3,0:17.12
6,-3,0:17.12
2,-2,0:17.12
3,-2,0:17.12
4,-2,0:17.12
2,-9,1:17.12
3,-9,1:17.12
4,-9,1:17.12
0,-8,1:17.12
1,-8,1:17.12
2,-8,1:17.12
4,-8,1:17.12
5,-8,1:17.12
6,-8,1:17.12
0,-7,1:17.12
6,-7,1:17.12
0,-6,1:17.12
6,-6,1:17.12
0,-5,1:17.12
6,-5,1:17.12
0,-4,1:17.12
6,-4,1:17.12
0,-3,1:17.12
1,-3,1:17.12
2,-3,1:17.12
4,-3,1:17.12
5,-3,1:17.12
6,-3,1:17.12
2,-2,1:17.12
3,-2,1:17.12
4,-2,1:17.12
2,-8,2:17.12
3,-8,2:17.12
4,-8,2:17.12
5,-8,2:17.12
0,-7,2:17.12
1,-7,2:17.12
5,-7,2:17.12
6,-7,2:17.12
0,-6,2:17.12
1,-6,2:17.12
6,-6,2:17.12
0,-5,2:17.12
1,-5,2:17.12
6,-5,2:17.12
0,-4,2:17.12
1,-4,2:17.12
6,-4,2:17.12
1,-3,2:17.12
2,-3,2:17.12
4,-3,2:17.12
5,-3,2:17.12
6,-3,2:17.12
3,-2,2:17.12
4,-2,2:17.12
2,-8,3:17.12
3,-8,3:17.12
4,-8,3:17.12
1,-7,3:17.12
2,-7,3:17.12
5,-7,3:17.12
6,-7,3:17.12
1,-6,3:17.12
6,-6,3:17.12
1,-5,3:17.12
6,-5,3:17.12
1,-4,3:17.12
6,-4,3:17.12
1,-3,3:17.12
2,-3,3:17.12
4,-3,3:17.12
5,-3,3:17.12
6,-3,3:17.12
3,-2,3:17.12
4,-2,3:17.12
3,-8,4:17.12
4,-8,4:17.12
1,-7,4:17.12
2,-7,4:17.12
3,-7,4:17.12
4,-7,4:17.12
5,-7,4:17.12
1,-6,4:17.12
6,-6,4:17.12
1,-5,4:17.12
6,-5,4:17.12
1,-4,4:17.12
6,-4,4:17.12
1,-3,4:17.12
2,-3,4:17.12
4,-3,4:17.12
5,-3,4:17.12
6,-3,4:17.12
3,-2,4:17.12
4,-2,4:17.12
2,-7,5:17.12
3,-7,5:17.12
4,-7,5:17.12
5,-7,5:17.12
1,-6,5:17.12
2,-6,5:17.12
5,-6,5:17.12
6,-6,5:17.12
1,-5,5:17.12
6,-5,5:17.12
1,-4,5:17.12
6,-4,5:17.12
1,-3,5:17.12
2,-3,5:17.12
3,-3,5:17.12
4,-3,5:17.12
5,-3,5:17.12
6,-3,5:17.12
3,-2,5:17.12
4,-2,5:17.12
3,-7,6:17.12
4,-7,6:17.12
1,-6,6:17.12
2,-6,6:17.12
5,-6,6:17.12
6,-6,6:17.12
1,-5,6:17.12
6,-5,6:17.12
1,-4,6:17.12
6,-4,6:17.12
2,-3,6:17.12
3,-3,6:17.12
4,-3,6:17.12
5,-3,6:17.12
6,-3,6:17.12
3,-2,6:17.12
4,-2,6:17.12
3,-7,7:17.12
4,-7,7:17.12
2,-6,7:17.12
3,-6,7:17.12
4,-6,7:17.12
5,-6,7:17.12
2,-5,7:17.12
6,-5,7:17.12
2,-4,7:17.12
6,-4,7:17.12
2,-3,7:17.12
3,-3,7:17.12
4,-3,7:17.12
5,-3,7:17.12
6,-3,7:17.12
3,-2,7:17.12
4,-2,7:17.12
2,-6,8:17.12
3,-6,8:17.12
4,-6,8:17.12
5,-6,8:17.12
2,-5,8:17.12
5,-5,8:17.12
6,-5,8:17.12
2,-4,8:17.12
5,-4,8:17.12
6,-4,8:17.12
2,-3,8:17.12
3,-3,8:17.12
4,-3,8:17.12
5,-3,8:17.12
3,-2,8:17.12
4,-2,8:17.12
6,6,8:18.6
7,6,8:18.6
0,-15,9:18.6
5,-15,9:18.6
0,-14,9:18.6
2,-14,9:18.6
3,-6,9:17.12
4,-6,9:17.12
5,-6,9:17.12
2,-5,9:17.12
5,-5,9:17.12
2,-4,9:17.12
5,-4,9:17.12
2,-3,9:17.12
3,-3,9:17.12
4,-3,9:17.12
5,-3,9:17.12
4,-2,9:17.12
4,5,9:18.6
5,5,9:18.6
6,5,9:18.6
1,6,9:18.6
2,6,9:18.6
6,6,9:18.6
7,6,9:18.6
0,7,9:18.6
1,7,9:18.6
-1,8,9:18.6
0,-15,10:18.6
5,-15,10:18.6
6,-15,10:18.6
0,-14,10:18.6
1,-14,10:18.6
2,-14,10:18.6
3,-14,10:18.6
5,-14,10:18.6
2,-13,10:18.6
3,-13,10:18.6
2,-12,10:18.6
2,-11,10:18.14
6,-11,10:18.14
3,-6,10:17.12
4,-6,10:17.12
5,-6,10:17.12
2,-5,10:17.12
5,-5,10:17.12
2,-4,10:17.12
5,-4,10:17.12
2,-3,10:17.12
3,-3,10:17.12
4,-3,10:17.12
5,-3,10:17.12
4,-2,10:17.12
6,2,10:18.14
1,3,10:18.6
3,4,10:18.6
4,4,10:18.6
2,5,10:18.6
3,5,10:18.6
4,5,10:18.6
5,5,10:18.6
6,5,10:18.6
7,5,10:18.6
1,6,10:18.6
2,6,10:18.6
10,6,10:18.6
0,7,10:18.6
1,7,10:18.6
-1,8,10:18.6
7,-16,11:18.6
8,-16,11:18.6
6,-15,11:18.6
7,-15,11:18.6
0,-14,11:18.6
1,-14,11:18.6
2,-14,11:18.6
5,-14,11:18.6
6,-14,11:18.6
0,-13,11:18.6
1,-13,11:18.6
2,-13,11:18.6
3,-13,11:18.6
4,-13,11:18.6
4,-12,11:18.6
5,-12,11:18.6
2,-11,11:18.14
5,-11,11:18.14
6,-11,11:18.14
0,-10,11:18.14
1,-10,11:18.14
7,-10,11:18.14
8,-9,11:18.14
3,-6,11:17.12
4,-6,11:17.12
5,-6,11:17.12
2,-5,11:17.12
5,-5,11:17.12
2,-4,11:17.12
5,-4,11:17.12
2,-3,11:17.12
3,-3,11:17.12
4,-3,11:17.12
5,-3,11:17.12
3,-2,11:17.12
4,-2,11:17.12
11,-2,11:18.6
10,-1,11:18.14
8,0,11:18.14
9,0,11:18.14
7,1,11:18.14
8,1,11:18.14
0,2,11:18.14
1,2,11:18.14
6,2,11:18.14
1,3,11:18.6
2,3,11:18.6
3,4,11:18.6
4,4,11:18.6
5,4,11:18.6
2,5,11:18.6
3,5,11:18.6
5,5,11:18.6
6,5,11:18.6
7,5,11:18.6
8,5,11:18.6
1,6,11:18.6
2,6,11:18.6
9,6,11:18.6
10,6,11:18.6
0,7,11:18.6
-3,9,11:18.6
-4,10,11:18.6
8,-16,12:18.6
9,-16,12:18.6
7,-15,12:18.6
8,-15,12:18.6
-3,-14,12:18.6
-2,-14,12:18.6
5,-14,12:18.6
6,-14,12:18.6
-1,-13,12:18.6
0,-13,12:18.6
1,-13,12:18.6
2,-13,12:18.6
3,-13,12:18.6
4,-13,12:18.6
5,-13,12:18.6
3,-12,12:18.6
4,-12,12:18.6
5,-12,12:18.6
2,-11,12:18.6
5,-11,12:18.6
6,-11,12:18.6
0,-10,12:18.14
1,-10,12:18.14
2,-10,12:18.14
6,-10,12:18.14
7,-10,12:18.14
-1,-9,12:18.14
0,-9,12:18.14
7,-9,12:18.14
8,-9,12:18.14
-2,-8,12:18.14
9,-8,12:18.14
10,-7,12:18.14
11,-7,12:18.6
3,-6,12:17.12
4,-6,12:17.12
5,-6,12:17.12
11,-6,12:18.6
2,-5,12:17.12
5,-5,12:17.12
2,-4,12:17.12
5,-4,12:17.12
2,-3,12:17.12
3,-3,12:17.12
4,-3,12:17.12
5,-3,12:17.12
3,-2,12:17.12
4,-2,12:17.12
10,-2,12:18.14
11,-2,12:18.6
9,-1,12:18.14
10,-1,12:18.14
-1,0,12:18.14
8,0,12:18.14
9,0,12:18.14
-1,1,12:18.14
0,1,12:18.14
6,1,12:18.14
7,1,12:18.14
1,2,12:18.14
2,2,12:18.14
5,2,12:18.14
6,2,12:18.14
2,3,12:18.6
3,3,12:18.6
4,3,12:18.6
5,3,12:18.6
3,4,12:18.6
4,4,12:18.6
5,4,12:18.6
6,4,12:18.6
2,5,12:18.6
3,5,12:18.6
6,5,12:18.6
7,5,12:18.6
8,5,12:18.6
9,5,12:18.6
0,6,12:18.6
1,6,12:18.6
-1,7,12:18.6
0,7,12:18.6
-2,8,12:18.6
-1,8,12:18.6
-3,9,12:18.6
-4,10,12:18.6
10,-17,13:18.6
9,-16,13:18.6
7,-15,13:18.6
8,-15,13:18.6
-3,-14,13:18.6
-2,-14,13:18.6
-1,-14,13:18.6
6,-14,13:18.6
7,-14,13:18.6
-3,-13,13:18.6
-2,-13,13:18.6
-1,-13,13:18.6
0,-13,13:18.6
1,-13,13:18.6
5,-13,13:18.6
2,-12,13:18.6
3,-12,13:18.6
4,-12,13:18.6
2,-11,13:18.6
3,-11,13:18.6
4,-11,13:18.6
5,-11,13:18.6
1,-10,13:18.14
2,-10,13:18.14
6,-10,13:18.14
-1,-9,13:18.14
0,-9,13:18.14
1,-9,13:18.14
7,-9,13:18.14
8,-9,13:18.14
-2,-8,13:18.14
0,-8,13:18.14
8,-8,13:18.14
9,-8,13:18.14
14,-8,13:18.6
-3,-7,13:18.6
-2,-7,13:18.14
9,-7,13:18.14
10,-7,13:18.6
14,-7,13:18.6
-3,-6,13:18.6
3,-6,13:17.12
4,-6,13:17.12
10,-6,13:18.6
11,-6,13:18.6
13,-6,13:18.6
14,-6,13:18.6
2,-5,13:17.12
5,-5,13:17.12
13,-5,13:18.6
2,-4,13:17.12
5,-4,13:17.12
2,-3,13:17.12
3,-3,13:17.12
4,-3,13:17.12
5,-3,13:17.12
11,-3,13:18.6
12,-3,13:18.6
14,-3,13:18.6
-4,-2,13:18.6
-3,-2,13:18.6
3,-2,13:17.12
4,-2,13:17.12
10,-2,13:18.6
11,-2,13:18.6
15,-2,13:18.14
-3,-1,13:18.6
-2,-1,13:18.14
9,-1,13:18.14
-1,0,13:18.14
7,0,13:18.14
8,0,13:18.14
0,1,13:18.14
1,1,13:18.14
6,1,13:18.14
7,1,13:18.14
1,2,13:18.14
2,2,13:18.14
5,2,13:18.14
6,2,13:18.14
2,3,13:18.6
3,3,13:18.6
4,3,13:18.6
3,4,13:18.6
4,4,13:18.6
5,4,13:18.6
6,4,13:18.6
7,4,13:18.6
8,4,13:18.6
2,5,13:18.6
8,5,13:18.6
9,5,13:18.6
0,6,13:18.6
1,6,13:18.6
12,6,13:18.6
-1,7,13:18.6
0,7,13:18.6
-2,8,13:18.6
-1,8,13:18.6
-3,9,13:18.6
9,-16,14:18.6
10,-16,14:18.6
8,-15,14:18.6
9,-15,14:18.6
6,-14,14:18.6
7,-14,14:18.6
-3,-13,14:18.6
-2,-13,14:18.6
-1,-13,14:18.6
0,-13,14:18.6
5,-13,14:18.6
6,-13,14:18.6
-1,-12,14:18.6
0,-12,14:18.6
1,-12,14:18.6
2,-12,14:18.6
3,-12,14:18.6
4,-12,14:18.6
5,-12,14:18.6
3,-11,14:18.6
4,-11,14:18.6
5,-11,14:18.6
2,-10,14:18.14
3,-10,14:18.14
5,-10,14:18.14
6,-10,14:18.14
0,-9,14:18.14
1,-9,14:18.14
6,-9,14:18.14
7,-9,14:18.14
0,-8,14:18.14
8,-8,14:18.14
14,-8,14:18.6
-3,-7,14:18.6
-2,-7,14:18.14
-1,-7,14:18.14
9,-7,14:18.14
10,-7,14:18.6
13,-7,14:18.6
14,-7,14:18.6
-3,-6,14:18.6
3,-6,14:17.12
4,-6,14:17.12
10,-6,14:18.6
11,-6,14:18.6
13,-6,14:18.6
2,-5,14:17.12
3,-5,14:17.12
5,-5,14:17.12
11,-5,14:18.6
12,-5,14:18.6
13,-5,14:18.6
2,-4,14:17.12
5,-4,14:17.12
12,-4,14:18.6
13,-4,14:18.6
2,-3,14:17.12
3,-3,14:17.12
5,-3,14:17.12
11,-3,14:18.6
12,-3,14:18.6
13,-3,14:18.6
14,-3,14:18.14
-3,-2,14:18.6
3,-2,14:17.12
4,-2,14:17.12
10,-2,14:18.6
14,-2,14:18.14
15,-2,14:18.14
-3,-1,14:18.6
-2,-1,14:18.14
8,-1,14:18.14
9,-1,14:18.14
15,-1,14:18.14
-1,0,14:18.14
0,0,14:18.14
7,0,14:18.14
8,0,14:18.14
0,1,14:18.14
1,1,14:18.14
6,1,14:18.14
7,1,14:18.14
2,2,14:18.14
3,2,14:18.14
4,2,14:18.14
5,2,14:18.14
3,3,14:18.6
4,3,14:18.6
5,3,14:18.6
2,4,14:18.6
3,4,14:18.6
6,4,14:18.6
7,4,14:18.6
8,4,14:18.6
1,5,14:18.6
2,5,14:18.6
10,5,14:18.6
11,5,14:18.6
0,6,14:18.6
1,6,14:18.6
-1,7,14:18.6
0,7,14:18.6
-2,8,14:18.6
-5,10,14:18.6
12,-18,15:18.6
11,-17,15:18.6
12,-17,15:18.6
10,-16,15:18.6
11,-16,15:18.6
8,-15,15:18.6
9,-15,15:18.6
7,-14,15:18.6
8,-14,15:18.6
-4,-13,15:18.6
-3,-13,15:18.6
-2,-13,15:18.6
6,-13,15:18.6
7,-13,15:18.6
-1,-12,15:18.6
0,-12,15:18.6
1,-12,15:18.6
5,-12,15:18.6
2,-11,15:18.6
3,-11,15:18.6
4,-11,15:18.6
5,-11,15:18.6
2,-10,15:18.14
3,-10,15:18.14
4,-10,15:18.14
5,-10,15:18.14
1,-9,15:18.14
2,-9,15:18.14
6,-9,15:18.14
7,-9,15:18.14
0,-8,15:18.14
1,-8,15:18.14
7,-8,15:18.14
8,-8,15:18.14
-2,-7,15:18.14
-1,-7,15:18.14
8,-7,15:18.14
9,-7,15:18.14
13,-7,15:18.6
-3,-6,15:18.6
-2,-6,15:18.14
3,-6,15:17.12
4,-6,15:17.12
9,-6,15:18.14
10,-6,15:18.6
12,-6,15:18.6
13,-6,15:18.6
-4,-5,15:18.6
-3,-5,15:18.6
2,-5,15:17.12
3,-5,15:17.12
5,-5,15:17.12
11,-5,15:18.6
12,-5,15:18.6
2,-4,15:17.12
5,-4,15:17.12
12,-4,15:18.6
13,-4,15:18.6
-6,-3,15:18.6
2,-3,15:17.12
3,-3,15:17.12
5,-3,15:17.12
10,-3,15:18.6
11,-3,15:18.6
13,-3,15:18.6
14,-3,15:18.14
-6,-2,15:18.6
-3,-2,15:18.6
-2,-2,15:18.14
3,-2,15:17.12
4,-2,15:17.12
10,-2,15:18.6
13,-2,15:18.5
14,-2,15:18.14
-6,-1,15:18.6
-2,-1,15:18.14
-1,-1,15:18.14
8,-1,15:18.14
9,-1,15:18.14
15,-1,15:18.14
-6,0,15:18.6
-1,0,15:18.14
0,0,15:18.14
7,0,15:18.14
8,0,15:18.14
1,1,15:18.14
2,1,15:18.14
5,1,15:18.14
6,1,15:18.14
2,2,15:18.14
3,2,15:18.14
4,2,15:18.14
5,2,15:18.14
3,3,15:18.6
4,3,15:18.6
5,3,15:18.6
6,3,15:18.6
7,3,15:18.6
2,4,15:18.6
3,4,15:18.6
7,4,15:18.6
8,4,15:18.6
9,4,15:18.6
1,5,15:18.6
2,5,15:18.6
10,5,15:18.6
0,6,15:18.6
1,6,15:18.6
-1,7,15:18.6
-2,8,15:18.6
-4,9,15:18.6
-3,9,15:18.6
10,-16,16:18.6
11,-16,16:18.6
9,-15,16:18.6
10,-15,16:18.6
8,-14,16:18.6
9,-14,16:18.6
-4,-13,16:18.6
-3,-13,16:18.6
6,-13,16:18.6
7,-13,16:18.6
-3,-12,16:18.6
-2,-12,16:18.6
-1,-12,16:18.6
0,-12,16:18.6
5,-12,16:18.6
6,-12,16:18.6
2,-11,16:18.6
3,-11,16:18.6
4,-11,16:18.6
5,-11,16:18.6
14,-11,16:18.6
3,-10,16:18.14
4,-10,16:18.14
5,-10,16:18.14
13,-10,16:18.6
2,-9,16:18.14
3,-9,16:18.14
5,-9,16:18.14
6,-9,16:18.14
13,-9,16:18.6
0,-8,16:18.14
1,-8,16:18.14
7,-8,16:18.14
13,-8,16:18.6
-1,-7,16:18.14
0,-7,16:18.14
8,-7,16:18.14
9,-7,16:18.14
12,-7,16:18.6
13,-7,16:18.6
-2,-6,16:18.14
-1,-6,16:18.14
3,-6,16:17.12
4,-6,16:17.12
9,-6,16:18.14
10,-6,16:18.6
12,-6,16:18.6
-6,-5,16:18.6
-4,-5,16:18.6
-3,-5,16:18.6
2,-5,16:17.12
3,-5,16:17.12
5,-5,16:17.12
10,-5,16:18.6
11,-5,16:18.6
12,-5,16:18.6
-6,-4,16:18.6
-5,-4,16:18.6
-4,-4,16:18.6
2,-4,16:17.12
5,-4,16:17.12
11,-4,16:18.6
12,-4,16:18.6
-5,-3,16:18.6
-4,-3,16:18.6
-3,-3,16:18.6
2,-3,16:17.12
3,-3,16:17.12
5,-3,16:17.12
10,-3,16:18.6
11,-3,16:18.6
13,-3,16:18.14
-6,-2,16:18.6
-5,-2,16:18.6
-3,-2,16:18.6
-2,-2,16:18.14
3,-2,16:17.12
4,-2,16:17.12
10,-2,16:18.6
13,-2,16:18.13
14,-2,16:18.14
-6,-1,16:18.6
-5,-1,16:18.6
-1,-1,16:18.14
0,-1,16:18.14
8,-1,16:18.14
9,-1,16:18.14
14,-1,16:18.14
15,-1,16:18.14
-6,0,16:18.6
0,0,16:18.14
1,0,16:18.14
6,0,16:18.14
7,0,16:18.14
15,0,16:18.14
16,0,16:18.14
1,1,16:18.14
2,1,16:18.14
5,1,16:18.14
6,1,16:18.14
16,1,16:18.14
3,2,16:18.14
4,2,16:18.14
5,2,16:18.14
3,3,16:18.6
4,3,16:18.6
5,3,16:18.6
6,3,16:18.6
7,3,16:18.6
8,3,16:18.6
2,4,16:18.6
3,4,16:18.6
8,4,16:18.6
9,4,16:18.6
10,4,16:18.6
1,5,16:18.6
2,5,16:18.6
0,6,16:18.6
-2,7,16:18.6
-1,7,16:18.6
-2,8,16:18.6
11,-16,17:18.6
10,-15,17:18.6
8,-14,17:18.6
9,-14,17:18.6
7,-13,17:18.6
8,-13,17:18.6
-3,-12,17:18.6
6,-12,17:18.6
-1,-11,17:18.6
5,-11,17:18.6
13,-11,17:18.6
1,-10,17:18.14
2,-10,17:18.14
3,-10,17:18.14
4,-10,17:18.14
5,-10,17:18.14
13,-10,17:18.6
2,-9,17:18.14
3,-9,17:18.14
5,-9,17:18.14
6,-9,17:18.14
12,-9,17:18.6
13,-9,17:18.6
1,-8,17:18.14
2,-8,17:18.14
6,-8,17:18.14
7,-8,17:18.14
12,-8,17:18.6
0,-7,17:18.14
1,-7,17:18.14
7,-7,17:18.14
8,-7,17:18.14
12,-7,17:18.6
-6,-6,17:18.6
-2,-6,17:18.14
-1,-6,17:18.14
3,-6,17:17.12
4,-6,17:17.12
8,-6,17:18.14
9,-6,17:18.14
11,-6,17:18.6
12,-6,17:18.6
-6,-5,17:18.6
-5,-5,17:18.6
-3,-5,17:18.6
-2,-5,17:18.14
2,-5,17:17.12
3,-5,17:17.12
5,-5,17:17.12
10,-5,17:18.6
11,-5,17:18.6
-5,-4,17:18.6
-4,-4,17:18.6
-3,-4,17:18.6
2,-4,17:17.12
5,-4,17:17.12
11,-4,17:18.6
12,-4,17:18.6
-5,-3,17:18.6
-4,-3,17:18.6
-3,-3,17:18.6
2,-3,17:17.12
3,-3,17:17.12
5,-3,17:17.12
10,-3,17:18.6
11,-3,17:18.6
12,-3,17:18.6
13,-3,17:18.14
-5,-2,17:18.6
-2,-2,17:18.14
-1,-2,17:18.14
3,-2,17:17.12
4,-2,17:17.12
13,-2,17:18.14
-5,-1,17:18.6
-1,-1,17:18.14
0,-1,17:18.14
7,-1,17:18.14
8,-1,17:18.14
14,-1,17:18.14
-5,0,17:18.6
0,0,17:18.14
1,0,17:18.14
6,0,17:18.14
7,0,17:18.14
15,0,17:18.14
-5,1,17:18.6
2,1,17:18.14
3,1,17:18.14
5,1,17:18.14
6,1,17:18.14
16,1,17:18.14
-5,2,17:18.6
3,2,17:18.14
4,2,17:18.14
5,2,17:18.14
6,2,17:18.14
-5,3,17:18.6
3,3,17:18.6
6,3,17:18.6
7,3,17:18.6
8,3,17:18.6
9,3,17:18.6
2,4,17:18.6
10,4,17:18.6
1,5,17:18.6
-1,6,17:18.6
0,6,17:18.6
-2,7,17:18.6
-1,7,17:18.6
-2,8,17:18.6
11,-16,18:18.6
10,-15,18:18.6
11,-15,18:18.6
9,-14,18:18.6
10,-14,18:18.6
7,-13,18:18.6
8,-13,18:18.6
6,-12,18:18.6
7,-12,18:18.6
-3,-11,18:18.6
-2,-11,18:18.6
-1,-11,18:18.6
5,-11,18:18.6
6,-11,18:18.6
0,-10,18:18.14
1,-10,18:18.14
2,-10,18:18.14
3,-10,18:18.14
4,-10,18:18.14
5,-10,18:18.14
3,-9,18:18.14
4,-9,18:18.14
5,-9,18:18.14
12,-9,18:18.6
2,-8,18:18.14
3,-8,18:18.14
6,-8,18:18.14
12,-8,18:18.6
0,-7,18:18.14
1,-7,18:18.14
7,-7,18:18.14
8,-7,18:18.14
11,-7,18:18.6
12,-7,18:18.6
-6,-6,18:18.6
-1,-6,18:18.14
0,-6,18:18.14
3,-6,18:17.12
4,-6,18:17.12
8,-6,18:18.14
9,-6,18:18.14
11,-6,18:18.6
-6,-5,18:18.6
-5,-5,18:18.6
-2,-5,18:18.14
-1,-5,18:18.14
2,-5,18:17.12
3,-5,18:17.12
4,-5,18:17.12
5,-5,18:17.12
9,-5,18:18.14
10,-5,18:18.6
11,-5,18:18.6
-5,-4,18:18.6
-4,-4,18:18.6
-3,-4,18:18.6
2,-4,18:17.12
5,-4,18:17.12
10,-4,18:18.6
11,-4,18:18.6
-4,-3,18:18.6
-3,-3,18:18.6
-2,-3,18:18.14
2,-3,18:17.12
3,-3,18:17.12
5,-3,18:17.12
10,-3,18:18.6
11,-3,18:18.6
12,-3,18:18.6
-4,-2,18:18.6
-2,-2,18:18.14
-1,-2,18:18.14
3,-2,18:17.12
4,-2,18:17.12
8,-2,18:18.14
13,-2,18:18.14
-5,-1,18:18.6
-4,-1,18:18.6
0,-1,18:18.14
1,-1,18:18.14
7,-1,18:18.14
8,-1,18:18.14
14,-1,18:18.14
-5,0,18:18.6
-4,0,18:18.6
1,0,18:18.14
2,0,18:18.14
6,0,18:18.14
7,0,18:18.14
14,0,18:18.14
15,0,18:18.14
-5,1,18:18.6
2,1,18:18.14
3,1,18:18.14
5,1,18:18.14
15,1,18:18.14
16,1,18:18.14
-5,2,18:18.6
3,2,18:18.14
4,2,18:18.14
5,2,18:18.14
6,2,18:18.14
7,2,18:18.14
16,2,18:18.14
17,2,18:18.14
-5,3,18:18.6
3,3,18:18.6
7,3,18:18.6
8,3,18:18.6
9,3,18:18.6
10,3,18:18.6
17,3,18:18.14
2,4,18:18.6
0,5,18:18.6
1,5,18:18.6
-1,6,18:18.6
0,6,18:18.6
-2,7,18:18.6
-1,7,18:18.6
0,-15,19:18.6
11,-15,19:18.6
1,-14,19:18.6
9,-14,19:18.6
10,-14,19:18.6
2,-13,19:18.6
6,-13,19:18.6
7,-13,19:18.6
8,-13,19:18.6
9,-13,19:18.6
5,-12,19:18.6
6,-12,19:18.6
7,-12,19:18.6
8,-12,19:18.6
13,-12,19:18.6
-2,-11,19:18.6
6,-11,19:18.6
12,-11,19:18.6
-2,-10,19:18.6
-1,-10,19:18.14
0,-10,19:18.14
1,-10,19:18.14
2,-10,19:18.14
5,-10,19:18.14
6,-10,19:18.14
12,-10,19:18.6
2,-9,19:18.14
3,-9,19:18.14
4,-9,19:18.14
5,-9,19:18.14
11,-9,19:18.6
12,-9,19:18.6
2,-8,19:18.14
3,-8,19:18.14
4,-8,19:18.14
5,-8,19:18.14
6,-8,19:18.14
11,-8,19:18.6
-7,-7,19:18.6
-6,-7,19:18.6
1,-7,19:18.14
2,-7,19:18.14
6,-7,19:18.14
7,-7,19:18.14
11,-7,19:18.6
-6,-6,19:18.6
-5,-6,19:18.6
0,-6,19:18.14
1,-6,19:18.14
3,-6,19:17.12
4,-6,19:17.12
7,-6,19:18.14
8,-6,19:18.14
10,-6,19:18.6
11,-6,19:18.6
-5,-5,19:18.6
-4,-5,19:18.6
-2,-5,19:18.14
-1,-5,19:18.14
2,-5,19:17.12
3,-5,19:17.12
4,-5,19:17.12
5,-5,19:17.12
9,-5,19:18.14
10,-5,19:18.6
11,-5,19:18.6
-4,-4,19:18.6
-3,-4,19:18.6
-2,-4,19:18.14
2,-4,19:17.12
5,-4,19:17.12
10,-4,19:18.6
11,-4,19:18.6
-4,-3,19:18.6
-3,-3,19:18.6
-2,-3,19:18.14
2,-3,19:17.12
3,-3,19:17.12
5,-3,19:17.12
9,-3,19:18.14
10,-3,19:18.6
11,-3,19:18.6
12,-3,19:18.6
-4,-2,19:18.6
-1,-2,19:18.14
0,-2,19:18.14
3,-2,19:17.12
4,-2,19:17.12
8,-2,19:18.14
12,-2,19:18.6
13,-2,19:18.14
-4,-1,19:18.6
0,-1,19:18.14
1,-1,19:18.14
7,-1,19:18.14
8,-1,19:18.14
13,-1,19:18.14
14,-1,19:18.14
-4,0,19:18.6
2,0,19:18.14
3,0,19:18.14
5,0,19:18.14
6,0,19:18.14
14,0,19:18.6
15,0,19:18.14
-4,1,19:18.6
3,1,19:18.14
5,1,19:18.14
15,1,19:18.14
-4,2,19:18.6
3,2,19:18.14
4,2,19:18.14
5,2,19:18.14
6,2,19:18.14
7,2,19:18.14
8,2,19:18.14
16,2,19:18.14
-4,3,19:18.6
2,3,19:18.6
3,3,19:18.6
9,3,19:18.6
10,3,19:18.6
-4,4,19:18.6
1,4,19:18.6
2,4,19:18.6
0,5,19:18.6
1,5,19:18.6
-1,6,19:18.6
0,6,19:18.6
2,6,19:18.6
-2,7,19:18.6
0,7,19:18.6
5,7,19:18.6
6,8,19:18.6
7,8,19:18.6
7,9,19:18.6
0,-15,20:18.6
0,-14,20:18.6
1,-14,20:18.6
10,-14,20:18.6
11,-14,20:18.6
1,-13,20:18.6
2,-13,20:18.6
8,-13,20:18.6
9,-13,20:18.6
10,-13,20:18.6
3,-12,20:18.6
4,-12,20:18.6
5,-12,20:18.6
6,-12,20:18.6
7,-12,20:18.6
8,-12,20:18.6
6,-11,20:18.6
7,-11,20:18.6
-2,-10,20:18.6
-1,-10,20:18.14
0,-10,20:18.14
1,-10,20:18.14
5,-10,20:18.14
6,-10,20:18.14
11,-10,20:18.6
0,-9,20:18.14
1,-9,20:18.14
2,-9,20:18.14
3,-9,20:18.14
4,-9,20:18.14
5,-9,20:18.14
6,-9,20:18.14
7,-9,20:18.14
11,-9,20:18.6
-7,-8,20:18.6
3,-8,20:18.14
4,-8,20:18.14
5,-8,20:18.14
11,-8,20:18.6
-7,-7,20:18.6
-6,-7,20:18.6
2,-7,20:18.14
3,-7,20:18.14
6,-7,20:18.14
7,-7,20:18.14
10,-7,20:18.6
11,-7,20:18.6
-6,-6,20:18.6
-5,-6,20:18.6
0,-6,20:18.14
1,-6,20:18.14
4,-6,20:17.12
7,-6,20:18.14
8,-6,20:18.14
10,-6,20:18.6
-4,-5,20:18.6
-1,-5,20:18.14
0,-5,20:18.14
2,-5,20:17.12
3,-5,20:17.12
4,-5,20:17.12
5,-5,20:17.12
8,-5,20:18.14
9,-5,20:18.14
10,-5,20:18.6
-3,-4,20:18.6
-2,-4,20:18.14
-1,-4,20:18.14
2,-4,20:17.12
5,-4,20:17.12
9,-4,20:18.14
10,-4,20:18.6
-3,-3,20:18.6
-2,-3,20:18.14
-1,-3,20:18.14
2,-3,20:17.12
3,-3,20:17.12
5,-3,20:17.12
9,-3,20:18.14
10,-3,20:18.6
11,-3,20:18.6
-3,-2,20:18.6
-1,-2,20:18.14
0,-2,20:18.14
3,-2,20:17.12
4,-2,20:17.12
8,-2,20:18.14
12,-2,20:18.6
13,-2,20:18.6
-4,-1,20:18.6
-3,-1,20:18.6
1,-1,20:18.14
2,-1,20:18.14
6,-1,20:18.14
7,-1,20:18.14
13,-1,20:18.6
-4,0,20:18.6
-3,0,20:18.6
2,0,20:18.14
3,0,20:18.14
5,0,20:18.14
6,0,20:18.14
14,0,20:18.6
-4,1,20:18.6
3,1,20:18.14
5,1,20:18.14
6,1,20:18.14
15,1,20:18.14
-4,2,20:18.6
3,2,20:18.14
4,2,20:18.14
6,2,20:18.14
7,2,20:18.14
8,2,20:18.14
9,2,20:18.14
10,2,20:18.6
16,2,20:18.14
-4,3,20:18.6
1,3,20:18.6
2,3,20:18.6
3,3,20:18.6
6,3,20:18.6
10,3,20:18.6
16,3,20:18.14
1,4,20:18.6
2,4,20:18.6
6,4,20:18.6
0,5,20:18.6
1,5,20:18.6
3,5,20:18.6
-1,6,20:18.6
0,6,20:18.6
1,6,20:18.6
2,6,20:18.6
3,6,20:18.6
4,6,20:18.6
5,6,20:18.6
-3,7,20:18.6
-2,7,20:18.6
5,7,20:18.6
6,7,20:18.6
6,8,20:18.6
7,8,20:18.6
7,9,20:18.6
-4,-17,21:18.6
-3,-17,21:18.6
-3,-16,21:18.6
-2,-16,21:18.6
0,-14,21:18.6
1,-14,21:18.6
10,-14,21:18.6
1,-13,21:18.6
2,-13,21:18.6
9,-13,21:18.6
10,-13,21:18.6
11,-13,21:18.6
2,-12,21:18.6
3,-12,21:18.6
5,-12,21:18.6
6,-12,21:18.6
7,-12,21:18.6
8,-12,21:18.6
9,-12,21:18.6
3,-11,21:18.6
4,-11,21:18.6
5,-11,21:18.6
7,-11,21:18.6
-2,-10,21:18.6
1,-10,21:18.14
2,-10,21:18.14
6,-10,21:18.14
11,-10,21:18.6
-7,-9,21:18.6
-1,-9,21:18.14
0,-9,21:18.14
1,-9,21:18.14
2,-9,21:18.14
5,-9,21:18.14
6,-9,21:18.14
7,-9,21:18.14
10,-9,21:18.6
11,-9,21:18.6
-7,-8,21:18.6
-6,-8,21:18.6
2,-8,21:18.14
3,-8,21:18.14
4,-8,21:18.14
5,-8,21:18.14
7,-8,21:18.14
8,-8,21:18.14
10,-8,21:18.6
-6,-7,21:18.6
-5,-7,21:18.6
2,-7,21:18.14
3,-7,21:18.14
4,-7,21:18.14
5,-7,21:18.14
6,-7,21:18.14
8,-7,21:18.14
9,-7,21:18.14
10,-7,21:18.6
-5,-6,21:18.6
1,-6,21:18.14
2,-6,21:18.14
4,-6,21:17.12
6,-6,21:18.14
7,-6,21:18.14
10,-6,21:18.6
-4,-5,21:18.6
-3,-5,21:18.6
0,-5,21:18.14
1,-5,21:18.14
2,-5,21:17.12
3,-5,21:17.12
4,-5,21:17.12
5,-5,21:17.12
8,-5,21:18.14
9,-5,21:18.14
10,-5,21:18.6
-3,-4,21:18.6
-2,-4,21:18.14
-1,-4,21:18.14
2,-4,21:17.12
5,-4,21:17.12
9,-4,21:18.14
10,-4,21:18.6
-2,-3,21:18.14
-1,-3,21:18.14
0,-3,21:18.14
2,-3,21:17.12
3,-3,21:17.12
5,-3,21:17.12
8,-3,21:18.14
9,-3,21:18.14
10,-3,21:18.6
11,-3,21:18.6
-3,-2,21:18.6
-2,-2,21:18.14
0,-2,21:18.14
1,-2,21:18.14
3,-2,21:17.12
4,-2,21:17.12
7,-2,21:18.14
8,-2,21:18.14
11,-2,21:18.6
12,-2,21:18.6
-3,-1,21:18.6
1,-1,21:18.14
2,-1,21:18.14
6,-1,21:18.14
7,-1,21:18.14
12,-1,21:18.6
13,-1,21:18.6
-3,0,21:18.6
3,0,21:18.14
4,0,21:18.14
5,0,21:18.14
6,0,21:18.14
13,0,21:18.6
14,0,21:18.14
-3,1,21:18.6
5,1,21:18.14
6,1,21:18.14
7,1,21:18.14
8,1,21:18.14
14,1,21:18.14
15,1,21:18.14
-3,2,21:18.6
3,2,21:18.14
7,2,21:18.14
8,2,21:18.14
9,2,21:18.14
15,2,21:18.14
16,2,21:18.14
-3,3,21:18.6
1,3,21:18.6
2,3,21:18.6
6,3,21:18.6
7,3,21:18.6
1,4,21:18.6
2,4,21:18.6
5,4,21:18.6
0,5,21:18.6
1,5,21:18.6
2,5,21:18.6
3,5,21:18.6
4,5,21:18.6
-2,6,21:18.6
-1,6,21:18.6
0,6,21:18.6
1,6,21:18.6
4,6,21:18.6
5,6,21:18.6
5,7,21:18.6
6,7,21:18.6
7,8,21:18.6
10,10,21:18.14
-4,-17,22:18.6
-3,-17,22:18.6
-3,-16,22:18.6
-2,-16,22:18.6
-2,-15,22:18.6
-1,-15,22:18.6
0,-14,22:18.6
1,-14,22:18.6
1,-13,22:18.6
2,-13,22:18.6
10,-13,22:18.6
2,-12,22:18.6
3,-12,22:18.6
7,-12,22:18.6
8,-12,22:18.6
9,-12,22:18.6
10,-12,22:18.6
3,-11,22:18.6
4,-11,22:18.6
5,-11,22:18.6
6,-11,22:18.6
7,-11,22:18.6
2,-10,22:18.14
3,-10,22:18.14
4,-10,22:18.14
5,-10,22:18.14
6,-10,22:18.14
7,-10,22:18.14
-7,-9,22:18.6
-1,-9,22:18.14
0,-9,22:18.14
1,-9,22:18.14
2,-9,22:18.14
5,-9,22:18.14
6,-9,22:18.14
10,-9,22:18.6
-6,-8,22:18.6
0,-8,22:18.14
1,-8,22:18.14
2,-8,22:18.14
3,-8,22:18.14
4,-8,22:18.14
5,-8,22:18.14
7,-8,22:18.14
10,-8,22:18.6
-6,-7,22:18.6
-5,-7,22:18.6
-1,-7,22:18.14
3,-7,22:18.14
4,-7,22:18.14
5,-7,22:18.14
6,-7,22:18.14
8,-7,22:18.14
9,-7,22:18.14
10,-7,22:18.6
-5,-6,22:18.6
-4,-6,22:18.6
2,-6,22:18.14
3,-6,22:18.14
4,-6,22:17.12
6,-6,22:18.14
7,-6,22:18.14
9,-6,22:18.14
10,-6,22:18.6
-4,-5,22:18.6
-3,-5,22:18.6
0,-5,22:18.14
1,-5,22:18.14
2,-5,22:17.12
3,-5,22:17.12
4,-5,22:17.12
5,-5,22:17.12
7,-5,22:18.14
8,-5,22:18.14
9,-5,22:18.14
10,-5,22:18.6
11,-5,22:18.6
-2,-4,22:18.14
-1,-4,22:18.14
0,-4,22:18.14
2,-4,22:17.12
5,-4,22:17.12
8,-4,22:18.14
9,-4,22:18.14
-2,-3,22:18.14
-1,-3,22:18.14
0,-3,22:18.14
2,-3,22:17.12
5,-3,22:17.12
8,-3,22:18.14
9,-3,22:18.14
10,-3,22:18.6
-2,-2,22:18.14
0,-2,22:18.14
1,-2,22:18.14
3,-2,22:17.12
4,-2,22:17.12
7,-2,22:18.14
8,-2,22:18.14
11,-2,22:18.6
12,-2,22:18.6
-3,-1,22:18.6
-2,-1,22:18.14
2,-1,22:18.14
3,-1,22:18.14
6,-1,22:18.14
7,-1,22:18.14
10,-1,22:18.6
11,-1,22:18.6
12,-1,22:18.6
13,-1,22:18.6
-3,0,22:18.6
-2,0,22:18.14
3,0,22:18.14
4,0,22:18.14
5,0,22:18.14
9,0,22:18.14
10,0,22:18.6
13,0,22:18.6
-3,1,22:18.6
-2,1,22:18.14
-1,1,22:18.14
0,1,22:18.14
3,1,22:18.14
5,1,22:18.14
6,1,22:18.14
7,1,22:18.14
8,1,22:18.14
9,1,22:18.14
14,1,22:18.14
-3,2,22:18.6
0,2,22:18.14
1,2,22:18.14
3,2,22:18.14
7,2,22:18.14
10,2,22:18.6
11,2,22:18.6
15,2,22:18.14
-3,3,22:18.6
1,3,22:18.6
2,3,22:18.6
5,3,22:18.6
6,3,22:18.6
3,4,22:18.6
4,4,22:18.6
5,4,22:18.6
0,5,22:18.6
1,5,22:18.6
2,5,22:18.6
3,5,22:18.6
4,5,22:18.6
-3,6,22:18.6
-2,6,22:18.6
-1,6,22:18.6
5,6,22:18.6
6,7,22:18.6
7,7,22:18.6
7,8,22:18.6
8,8,22:18.6
9,9,22:18.14
10,10,22:18.14
-5,-18,23:18.6
-3,-16,23:18.6
-2,-16,23:18.6
-2,-15,23:18.6
-1,-15,23:18.6
-1,-14,23:18.6
0,-14,23:18.6
12,-14,23:18.6
1,-13,23:18.6
10,-13,23:18.6
11,-13,23:18.6
12,-13,23:18.6
2,-12,23:18.6
3,-12,23:18.6
8,-12,23:18.6
9,-12,23:18.6
10,-12,23:18.6
3,-11,23:18.6
4,-11,23:18.6
5,-11,23:18.6
6,-11,23:18.6
7,-11,23:18.6
8,-11,23:18.6
2,-10,23:18.14
3,-10,23:18.14
4,-10,23:18.14
5,-10,23:18.14
7,-10,23:18.14
10,-10,23:18.6
-7,-9,23:18.6
-6,-9,23:18.6
1,-9,23:18.14
2,-9,23:18.14
5,-9,23:18.14
6,-9,23:18.14
7,-9,23:18.14
10,-9,23:18.6
-6,-8,23:18.6
-5,-8,23:18.6
0,-8,23:18.14
1,-8,23:18.14
5,-8,23:18.14
6,-8,23:18.14
7,-8,23:18.14
9,-8,23:18.14
-5,-7,23:18.6
-2,-7,23:18.14
-1,-7,23:18.14
2,-7,23:18.14
3,-7,23:18.14
4,-7,23:18.14
5,-7,23:18.14
7,-7,23:18.14
8,-7,23:18.14
9,-7,23:18.14
-4,-6,23:18.6
-3,-6,23:18.6
-2,-6,23:18.14
3,-6,23:18.14
4,-6,23:18.14
5,-6,23:18.14
6,-6,23:18.14
9,-6,23:18.14
10,-6,23:18.6
16,-6,23:18.14
-3,-5,23:18.6
-2,-5,23:18.14
1,-5,23:18.14
2,-5,23:18.14
3,-5,23:17.12
4,-5,23:17.12
5,-5,23:17.12
7,-5,23:18.14
9,-5,23:18.14
10,-5,23:18.6
11,-5,23:18.6
15,-5,23:18.14
-2,-4,23:18.14
-1,-4,23:18.14
0,-4,23:18.14
1,-4,23:18.14
2,-4,23:17.12
5,-4,23:17.12
8,-4,23:18.14
9,-4,23:18.14
11,-4,23:18.6
14,-4,23:18.14
-1,-3,23:18.14
0,-3,23:18.14
1,-3,23:18.14
2,-3,23:17.12
5,-3,23:17.12
8,-3,23:18.14
9,-3,23:18.14
10,-3,23:18.6
-2,-2,23:18.14
-1,-2,23:18.14
1,-2,23:18.14
2,-2,23:18.14
3,-2,23:17.12
4,-2,23:17.12
7,-2,23:18.14
10,-2,23:18.6
11,-2,23:18.6
13,-2,23:18.6
-3,-1,23:18.6
-2,-1,23:18.14
2,-1,23:18.14
3,-1,23:18.14
6,-1,23:18.14
10,-1,23:18.6
11,-1,23:18.6
12,-1,23:18.6
13,-1,23:18.6
-2,0,23:18.14
-1,0,23:18.14
4,0,23:18.14
5,0,23:18.14
6,0,23:18.14
9,0,23:18.14
10,0,23:18.6
13,0,23:18.6
-2,1,23:18.14
-1,1,23:18.14
0,1,23:18.14
3,1,23:18.14
6,1,23:18.14
7,1,23:18.14
8,1,23:18.14
9,1,23:18.14
10,1,23:18.6
14,1,23:18.14
-2,2,23:18.6
1,2,23:18.14
2,2,23:18.14
3,2,23:18.14
6,2,23:18.14
7,2,23:18.14
10,2,23:18.6
-2,3,23:18.6
2,3,23:18.6
3,3,23:18.6
5,3,23:18.6
6,3,23:18.6
1,4,23:18.6
2,4,23:18.6
3,4,23:18.6
4,4,23:18.6
-2,5,23:18.6
-1,5,23:18.6
0,5,23:18.6
1,5,23:18.6
2,5,23:18.6
4,5,23:18.6
5,5,23:18.6
-3,6,23:18.6
-2,6,23:18.6
-1,6,23:18.6
5,6,23:18.6
6,6,23:18.6
-3,7,23:18.6
6,7,23:18.6
7,7,23:18.6
8,8,23:18.6
9,9,23:18.14
10,9,23:18.14
10,10,23:18.14
-5,-18,24:18.6
-5,-17,24:18.6
-4,-17,24:18.6
-4,-16,24:18.6
-3,-16,24:18.6
-1,-15,24:18.6
-1,-14,24:18.6
0,-14,24:18.6
0,-13,24:18.6
1,-13,24:18.6
11,-13,24:18.6
2,-12,24:18.6
9,-12,24:18.6
10,-12,24:18.6
11,-12,24:18.6
12,-12,24:18.6
3,-11,24:18.6
6,-11,24:18.6
7,-11,24:18.6
8,-11,24:18.6
9,-11,24:18.6
3,-10,24:18.14
4,-10,24:18.14
5,-10,24:18.14
7,-10,24:18.14
8,-10,24:18.14
-6,-9,24:18.6
2,-9,24:18.14
3,-9,24:18.14
5,-9,24:18.14
6,-9,24:18.14
7,-9,24:18.14
9,-9,24:18.14
-6,-8,24:18.6
-5,-8,24:18.6
-2,-8,24:18.14
0,-8,24:18.14
1,-8,24:18.14
6,-8,24:18.14
7,-8,24:18.14
9,-8,24:18.14
-6,-7,24:18.6
-5,-7,24:18.6
-4,-7,24:18.6
-1,-7,24:18.14
0,-7,24:18.14
1,-7,24:18.14
2,-7,24:18.14
3,-7,24:18.14
4,-7,24:18.14
5,-7,24:18.14
7,-7,24:18.14
8,-7,24:18.14
16,-7,24:18.14
-4,-6,24:18.6
-3,-6,24:18.6
-2,-6,24:18.14
3,-6,24:18.14
4,-6,24:18.14
5,-6,24:18.14
6,-6,24:18.14
8,-6,24:18.14
9,-6,24:18.14
15,-6,24:18.14
16,-6,24:18.14
-6,-5,24:18.6
-3,-5,24:18.6
-2,-5,24:18.14
2,-5,24:18.14
3,-5,24:17.12
4,-5,24:17.12
5,-5,24:17.12
6,-5,24:18.14
7,-5,24:18.14
8,-5,24:18.14
9,-5,24:18.14
10,-5,24:18.6
14,-5,24:18.14
15,-5,24:18.14
-1,-4,24:18.14
0,-4,24:18.14
1,-4,24:18.14
2,-4,24:17.12
5,-4,24:17.12
7,-4,24:18.14
8,-4,24:18.14
9,-4,24:18.14
11,-4,24:18.6
13,-4,24:18.6
14,-4,24:18.14
0,-3,24:18.14
1,-3,24:18.14
2,-3,24:17.12
5,-3,24:17.12
7,-3,24:18.14
8,-3,24:18.14
9,-3,24:18.14
12,-3,24:18.6
13,-3,24:18.6
-7,-2,24:18.6
-3,-2,24:18.6
-1,-2,24:18.14
0,-2,24:18.14
2,-2,24:18.14
3,-2,24:17.12
4,-2,24:17.12
5,-2,24:17.12
6,-2,24:18.14
7,-2,24:18.14
10,-2,24:18.6
11,-2,24:18.6
12,-2,24:18.6
13,-2,24:18.6
-3,-1,24:18.6
-2,-1,24:18.14
-1,-1,24:18.14
3,-1,24:18.14
4,-1,24:18.14
6,-1,24:18.14
9,-1,24:18.14
10,-1,24:18.6
11,-1,24:18.6
13,-1,24:18.6
-2,0,24:18.14
-1,0,24:18.14
0,0,24:18.14
4,0,24:18.14
5,0,24:18.14
6,0,24:18.14
7,0,24:18.14
8,0,24:18.14
9,0,24:18.14
12,0,24:18.6
13,0,24:18.6
-2,1,24:18.14
0,1,24:18.14
1,1,24:18.14
3,1,24:18.14
7,1,24:18.14
8,1,24:18.14
9,1,24:18.14
13,1,24:18.6
-2,2,24:18.6
1,2,24:18.14
2,2,24:18.14
3,2,24:18.14
5,2,24:18.14
6,2,24:18.14
14,2,24:18.14
1,3,24:18.6
2,3,24:18.6
3,3,24:18.6
4,3,24:18.6
5,3,24:18.6
15,3,24:18.6
0,4,24:18.6
1,4,24:18.6
2,4,24:18.6
3,4,24:18.6
4,4,24:18.6
-2,5,24:18.6
-1,5,24:18.6
0,5,24:18.6
5,5,24:18.6
6,6,24:18.6
7,7,24:18.6
8,7,24:18.6
8,8,24:18.6
9,8,24:18.6
9,9,24:18.6
-4,-17,25:18.6
-4,-16,25:18.6
-3,-16,25:18.6
-3,-15,25:18.6
-2,-15,25:18.6
-1,-14,25:18.6
0,-14,25:18.6
0,-13,25:18.6
1,-13,25:18.6
1,-12,25:18.6
2,-12,25:18.6
10,-12,25:18.6
11,-12,25:18.6
3,-11,25:18.6
7,-11,25:18.6
8,-11,25:18.6
9,-11,25:18.6
10,-11,25:18.6
3,-10,25:18.14
4,-10,25:18.14
5,-10,25:18.14
6,-10,25:18.14
7,-10,25:18.14
8,-10,25:18.14
9,-10,25:18.6
-6,-9,25:18.6
2,-9,25:18.14
3,-9,25:18.14
4,-9,25:18.14
5,-9,25:18.14
7,-9,25:18.14
8,-9,25:18.14
9,-9,25:18.14
-5,-8,25:18.6
1,-8,25:18.14
2,-8,25:18.14
5,-8,25:18.14
6,-8,25:18.14
7,-8,25:18.14
8,-8,25:18.14
-6,-7,25:18.6
-5,-7,25:18.6
-4,-7,25:18.6
-1,-7,25:18.14
0,-7,25:18.14
1,-7,25:18.14
2,-7,25:18.14
3,-7,25:18.14
5,-7,25:18.14
6,-7,25:18.14
7,-7,25:18.14
8,-7,25:18.14
-6,-6,25:18.6
-5,-6,25:18.6
-2,-6,25:18.14
-1,-6,25:18.14
2,-6,25:18.14
3,-6,25:18.14
4,-6,25:18.14
5,-6,25:18.14
8,-6,25:18.14
9,-6,25:18.14
15,-6,25:18.14
-5,-5,25:18.6
-3,-5,25:18.6
-2,-5,25:18.14
-1,-5,25:18.14
2,-5,25:17.12
3,-5,25:18.14
4,-5,25:17.12
5,-5,25:17.12
6,-5,25:18.14
8,-5,25:18.14
9,-5,25:18.14
10,-5,25:18.6
14,-5,25:18.14
-5,-4,25:18.6
-4,-4,25:18.6
-1,-4,25:18.14
0,-4,25:18.14
1,-4,25:18.14
2,-4,25:18.14
5,-4,25:17.12
7,-4,25:18.14
8,-4,25:18.14
10,-4,25:18.6
11,-4,25:18.6
13,-4,25:18.6
-6,-3,25:18.6
-5,-3,25:18.6
-4,-3,25:18.6
0,-3,25:18.14
1,-3,25:18.14
2,-3,25:17.12
5,-3,25:17.12
7,-3,25:18.14
8,-3,25:18.14
9,-3,25:18.14
11,-3,25:18.6
12,-3,25:18.6
-7,-2,25:18.6
-6,-2,25:18.6
-3,-2,25:18.6
-2,-2,25:18.14
0,-2,25:18.14
2,-2,25:18.14
3,-2,25:18.14
4,-2,25:17.12
5,-2,25:17.12
6,-2,25:18.14
7,-2,25:18.14
10,-2,25:18.6
11,-2,25:18.6
12,-2,25:18.6
-8,-1,25:18.6
-7,-1,25:18.6
-2,-1,25:18.14
-1,-1,25:18.14
0,-1,25:18.14
3,-1,25:18.14
4,-1,25:18.14
6,-1,25:18.14
9,-1,25:18.14
10,-1,25:18.6
11,-1,25:18.6
12,-1,25:18.6
-9,0,25:18.6
-8,0,25:18.6
-1,0,25:18.14
0,0,25:18.14
4,0,25:18.14
5,0,25:18.14
6,0,25:18.14
7,0,25:18.14
8,0,25:18.14
12,0,25:18.6
13,0,25:18.6
-1,1,25:18.14
0,1,25:18.14
1,1,25:18.14
3,1,25:18.14
6,1,25:18.14
7,1,25:18.14
13,1,25:18.6
-1,2,25:18.14
2,2,25:18.14
3,2,25:18.14
5,2,25:18.14
6,2,25:18.14
14,2,25:18.14
-1,3,25:18.6
1,3,25:18.6
2,3,25:18.6
3,3,25:18.6
4,3,25:18.6
5,3,25:18.6
-2,4,25:18.6
-1,4,25:18.6
0,4,25:18.6
1,4,25:18.6
2,4,25:18.6
4,4,25:18.6
5,4,25:18.6
-4,5,25:18.6
-3,5,25:18.6
5,5,25:18.6
6,6,25:18.6
7,6,25:18.6
7,7,25:18.6
8,7,25:18.6
9,8,25:18.6
10,9,25:18.14
11,9,25:18.14
-3,-16,26:18.6
-3,-15,26:18.6
-2,-15,26:18.6
-1,-14,26:18.6
0,-13,26:18.6
1,-13,26:18.6
1,-12,26:18.6
2,-12,26:18.6
2,-11,26:18.6
3,-11,26:18.6
8,-11,26:18.6
9,-11,26:18.6
10,-11,26:18.6
-5,-10,26:18.6
3,-10,26:18.14
4,-10,26:18.14
5,-10,26:18.14
6,-10,26:18.14
7,-10,26:18.14
8,-10,26:18.14
9,-10,26:18.6
-5,-9,26:18.6
3,-9,26:18.14
4,-9,26:18.14
5,-9,26:18.14
7,-9,26:18.14
8,-9,26:18.14
17,-9,26:18.14
-5,-8,26:18.6
-4,-8,26:18.6
1,-8,26:18.14
2,-8,26:18.14
5,-8,26:18.14
6,-8,26:18.14
7,-8,26:18.14
8,-8,26:18.14
16,-8,26:18.14
17,-8,26:18.14
-5,-7,26:18.6
-4,-7,26:18.6
-3,-7,26:18.6
0,-7,26:18.14
1,-7,26:18.14
6,-7,26:18.14
7,-7,26:18.14
8,-7,26:18.14
15,-7,26:18.14
16,-7,26:18.14
-5,-6,26:18.6
-3,-6,26:18.6
-2,-6,26:18.14
-1,-6,26:18.14
1,-6,26:18.14
2,-6,26:18.14
3,-6,26:18.14
4,-6,26:18.14
5,-6,26:18.14
7,-6,26:18.14
8,-6,26:18.14
14,-6,26:18.14
15,-6,26:18.14
-5,-5,26:18.6
-3,-5,26:18.6
-2,-5,26:18.14
-1,-5,26:18.14
0,-5,26:18.14
2,-5,26:17.12
3,-5,26:17.12
4,-5,26:18.14
5,-5,26:18.14
6,-5,26:18.14
7,-5,26:18.14
8,-5,26:18.14
9,-5,26:18.14
10,-5,26:18.6
13,-5,26:18.6
14,-5,26:18.14
-5,-4,26:18.6
-4,-4,26:18.6
-3,-4,26:18.6
0,-4,26:18.14
1,-4,26:18.14
2,-4,26:18.14
3,-4,26:18.14
5,-4,26:17.12
6,-4,26:18.14
7,-4,26:18.14
8,-4,26:18.14
10,-4,26:18.6
11,-4,26:18.6
12,-4,26:18.6
13,-4,26:18.6
-6,-3,26:18.6
-5,-3,26:18.6
-4,-3,26:18.6
-3,-3,26:18.6
1,-3,26:18.14
2,-3,26:18.14
5,-3,26:17.12
7,-3,26:18.14
8,-3,26:18.14
11,-3,26:18.6
12,-3,26:18.6
-7,-2,26:18.6
-6,-2,26:18.6
-3,-2,26:18.6
-2,-2,26:18.14
0,-2,26:18.14
1,-2,26:18.14
3,-2,26:18.14
4,-2,26:17.12
5,-2,26:17.12
6,-2,26:18.14
10,-2,26:18.6
11,-2,26:18.6
12,-2,26:18.6
-8,-1,26:18.6
-7,-1,26:18.6
-2,-1,26:18.14
-1,-1,26:18.14
0,-1,26:18.14
4,-1,26:18.14
6,-1,26:18.14
7,-1,26:18.14
8,-1,26:18.14
9,-1,26:18.14
10,-1,26:18.6
11,-1,26:18.6
12,-1,26:18.6
-8,0,26:18.6
-1,0,26:18.14
0,0,26:18.14
1,0,26:18.14
4,0,26:18.14
7,0,26:18.14
8,0,26:18.14
11,0,26:18.6
12,0,26:18.6
-1,1,26:18.14
0,1,26:18.14
1,1,26:18.14
2,1,26:18.14
3,1,26:18.14
6,1,26:18.14
7,1,26:18.14
12,1,26:18.6
-1,2,26:18.14
2,2,26:18.14
3,2,26:18.14
4,2,26:18.14
5,2,26:18.14
12,2,26:18.14
0,3,26:18.6
1,3,26:18.6
2,3,26:18.6
3,3,26:18.6
4,3,26:18.6
-3,4,26:18.6
-2,4,26:18.6
-1,4,26:18.6
0,4,26:18.6
4,4,26:18.6
5,4,26:18.6
6,5,26:18.6
6,6,26:18.6
7,6,26:18.6
8,7,26:18.6
9,7,26:18.6
9,8,26:18.6
10,8,26:18.14
10,9,26:18.14
-3,-16,27:18.6
-3,-15,27:18.6
-2,-15,27:18.6
-2,-14,27:18.6
-1,-14,27:18.6
0,-13,27:18.6
1,-12,27:18.6
2,-12,27:18.6
-5,-11,27:18.6
2,-11,27:18.6
10,-11,27:18.6
-5,-10,27:18.6
3,-10,27:18.6
6,-10,27:18.6
7,-10,27:18.6
8,-10,27:18.6
9,-10,27:18.6
-5,-9,27:18.6
3,-9,27:18.14
4,-9,27:18.14
5,-9,27:18.14
6,-9,27:18.14
8,-9,27:18.14
17,-9,27:18.14
-5,-8,27:18.6
-4,-8,27:18.6
2,-8,27:18.14
3,-8,27:18.14
5,-8,27:18.14
6,-8,27:18.14
7,-8,27:18.14
8,-8,27:18.14
16,-8,27:18.14
-5,-7,27:18.6
-4,-7,27:18.6
-3,-7,27:18.6
0,-7,27:18.14
1,-7,27:18.14
6,-7,27:18.14
7,-7,27:18.14
15,-7,27:18.14
-5,-6,27:18.6
-4,-6,27:18.6
-2,-6,27:18.14
-1,-6,27:18.14
0,-6,27:18.14
2,-6,27:18.14
3,-6,27:18.14
5,-6,27:18.14
6,-6,27:18.14
7,-6,27:18.14
8,-6,27:18.14
14,-6,27:18.14
-5,-5,27:18.6
-4,-5,27:18.6
-3,-5,27:18.6
-2,-5,27:18.14
-1,-5,27:18.14
0,-5,27:18.14
2,-5,27:17.12
3,-5,27:17.12
4,-5,27:18.14
5,-5,27:18.14
7,-5,27:18.14
8,-5,27:18.14
9,-5,27:18.14
13,-5,27:18.6
14,-5,27:18.14
-4,-4,27:18.6
-3,-4,27:18.6
0,-4,27:18.14
1,-4,27:18.14
2,-4,27:17.12
3,-4,27:18.14
4,-4,27:18.14
5,-4,27:17.12
6,-4,27:18.14
7,-4,27:18.14
10,-4,27:18.6
11,-4,27:18.6
12,-4,27:18.6
13,-4,27:18.6
-5,-3,27:18.6
-4,-3,27:18.6
-3,-3,27:18.6
2,-3,27:18.14
3,-3,27:18.14
5,-3,27:17.12
6,-3,27:18.14
7,-3,27:18.14
8,-3,27:18.14
10,-3,27:18.6
11,-3,27:18.6
-6,-2,27:18.6
-2,-2,27:18.14
-1,-2,27:18.14
1,-2,27:18.14
2,-2,27:18.14
3,-2,27:17.12
4,-2,27:18.14
5,-2,27:18.14
6,-2,27:18.14
8,-2,27:18.14
10,-2,27:18.6
11,-2,27:18.6
-7,-1,27:18.6
-1,-1,27:18.14
0,-1,27:18.14
1,-1,27:18.14
4,-1,27:18.14
6,-1,27:18.14
7,-1,27:18.14
8,-1,27:18.14
9,-1,27:18.14
10,-1,27:18.6
11,-1,27:18.6
-8,0,27:18.6
0,0,27:18.14
1,0,27:18.14
3,0,27:18.14
4,0,27:18.14
6,0,27:18.14
7,0,27:18.14
11,0,27:18.6
12,0,27:18.6
-9,1,27:18.6
2,1,27:18.14
3,1,27:18.14
5,1,27:18.14
6,1,27:18.14
12,1,27:18.6
-10,2,27:18.6
2,2,27:18.14
3,2,27:18.14
4,2,27:18.14
5,2,27:18.14
12,2,27:18.14
-10,3,27:18.6
-1,3,27:18.6
0,3,27:18.6
1,3,27:18.6
2,3,27:18.6
3,3,27:18.6
4,3,27:18.6
5,3,27:18.6
12,3,27:18.14
13,3,27:18.14
-2,4,27:18.6
5,4,27:18.6
6,5,27:18.6
7,5,27:18.6
7,6,27:18.6
8,6,27:18.6
8,7,27:18.6
9,7,27:18.6
10,8,27:18.14
-3,-15,28:18.6
-2,-15,28:18.6
-2,-14,28:18.6
-1,-14,28:18.6
-1,-13,28:18.6
0,-13,28:18.6
1,-12,28:18.6
2,-11,28:18.6
18,-11,28:18.14
3,-10,28:18.6
7,-10,28:18.6
8,-10,28:18.6
9,-10,28:18.6
10,-10,28:18.6
17,-10,28:18.14
18,-10,28:18.14
-4,-9,28:18.6
3,-9,28:18.14
4,-9,28:18.14
5,-9,28:18.14
6,-9,28:18.14
7,-9,28:18.14
16,-9,28:18.14
17,-9,28:18.14
-4,-8,28:18.6
2,-8,28:18.14
3,-8,28:18.14
4,-8,28:18.14
5,-8,28:18.14
8,-8,28:18.14
15,-8,28:18.14
16,-8,28:18.14
-4,-7,28:18.6
1,-7,28:18.14
2,-7,28:18.14
6,-7,28:18.14
7,-7,28:18.14
14,-7,28:18.6
15,-7,28:18.14
-4,-6,28:18.6
-2,-6,28:18.14
-1,-6,28:18.14
0,-6,28:18.14
6,-6,28:18.14
7,-6,28:18.14
8,-6,28:18.14
13,-6,28:18.6
14,-6,28:18.14
-4,-5,28:18.6
-2,-5,28:18.14
-1,-5,28:18.14
0,-5,28:18.14
1,-5,28:18.14
2,-5,28:18.14
3,-5,28:17.12
4,-5,28:18.14
5,-5,28:18.14
6,-5,28:18.14
7,-5,28:18.14
8,-5,28:18.14
9,-5,28:18.14
13,-5,28:18.6
-4,-4,28:18.6
-3,-4,28:18.6
-2,-4,28:18.14
1,-4,28:18.14
2,-4,28:18.14
3,-4,28:18.14
4,-4,28:18.14
5,-4,28:17.12
6,-4,28:18.14
7,-4,28:18.14
9,-4,28:18.14
10,-4,28:18.6
11,-4,28:18.6
12,-4,28:18.6
-5,-3,28:18.6
-4,-3,28:18.6
-3,-3,28:18.6
-2,-3,28:18.14
2,-3,28:17.12
3,-3,28:18.14
5,-3,28:17.12
6,-3,28:18.14
7,-3,28:18.14
10,-3,28:18.6
11,-3,28:18.6
-6,-2,28:18.6
-5,-2,28:18.6
-2,-2,28:18.14
-1,-2,28:18.14
2,-2,28:18.14
3,-2,28:17.12
4,-2,28:18.14
5,-2,28:18.14
6,-2,28:18.14
8,-2,28:18.14
10,-2,28:18.6
11,-2,28:18.6
-7,-1,28:18.6
-6,-1,28:18.6
0,-1,28:18.14
1,-1,28:18.14
2,-1,28:18.14
4,-1,28:18.14
6,-1,28:18.14
7,-1,28:18.14
8,-1,28:18.14
9,-1,28:18.14
10,-1,28:18.6
11,-1,28:18.6
-8,0,28:18.6
-7,0,28:18.6
1,0,28:18.14
2,0,28:18.14
3,0,28:18.14
4,0,28:18.14
6,0,28:18.14
7,0,28:18.14
10,0,28:18.6
11,0,28:18.6
-9,1,28:18.6
-8,1,28:18.6
2,1,28:18.14
3,1,28:18.14
5,1,28:18.14
6,1,28:18.14
11,1,28:18.6
-10,2,28:18.6
-9,2,28:18.6
1,2,28:18.14
2,2,28:18.14
3,2,28:18.14
4,2,28:18.14
12,2,28:18.6
-10,3,28:18.6
-3,3,28:18.6
-2,3,28:18.6
-1,3,28:18.6
0,3,28:18.6
1,3,28:18.6
4,3,28:18.6
5,3,28:18.6
5,4,28:18.6
6,4,28:18.6
6,5,28:18.6
7,5,28:18.6
7,6,28:18.6
8,6,28:18.6
9,7,28:18.6
10,8,28:18.6
11,8,28:18.14
-3,-15,29:18.6
9,-15,29:18.6
-2,-14,29:18.6
-1,-14,29:18.6
-1,-13,29:18.6
0,-13,29:18.6
-4,-12,29:18.6
0,-12,29:18.6
1,-12,29:18.6
-4,-11,29:18.6
2,-11,29:18.6
-4,-10,29:18.6
2,-10,29:18.6
3,-10,29:18.6
9,-10,29:18.6
10,-10,29:18.6
17,-10,29:18.14
-4,-9,29:18.6
3,-9,29:18.14
4,-9,29:18.14
5,-9,29:18.14
6,-9,29:18.14
7,-9,29:18.14
8,-9,29:18.14
16,-9,29:18.14
-4,-8,29:18.6
3,-8,29:18.14
4,-8,29:18.14
5,-8,29:18.14
15,-8,29:18.14
-4,-7,29:18.6
1,-7,29:18.14
2,-7,29:18.14
5,-7,29:18.14
6,-7,29:18.14
14,-7,29:18.6
15,-7,29:18.14
-4,-6,29:18.6
-1,-6,29:18.14
0,-6,29:18.14
1,-6,29:18.14
6,-6,29:18.14
7,-6,29:18.14
13,-6,29:18.6
14,-6,29:18.14
-4,-5,29:18.6
-3,-5,29:18.6
-2,-5,29:18.14
-1,-5,29:18.14
0,-5,29:18.14
1,-5,29:18.14
2,-5,29:18.14
3,-5,29:17.12
4,-5,29:17.12
5,-5,29:17.12
6,-5,29:18.14
8,-5,29:18.14
9,-5,29:18.14
12,-5,29:18.6
13,-5,29:18.6
-3,-4,29:18.6
-2,-4,29:18.14
2,-4,29:18.14
3,-4,29:18.14
4,-4,29:18.14
5,-4,29:18.14
6,-4,29:18.14
9,-4,29:18.14
10,-4,29:18.6
11,-4,29:18.6
12,-4,29:18.6
-4,-3,29:18.6
-3,-3,29:18.6
-2,-3,29:18.14
-1,-3,29:18.14
2,-3,29:17.12
3,-3,29:18.14
4,-3,29:18.14
5,-3,29:17.12
6,-3,29:18.14
7,-3,29:18.14
9,-3,29:18.14
10,-3,29:18.6
-5,-2,29:18.6
-1,-2,29:18.14
0,-2,29:18.14
2,-2,29:18.14
3,-2,29:18.14
4,-2,29:17.12
5,-2,29:18.14
6,-2,29:18.14
7,-2,29:18.14
8,-2,29:18.14
10,-2,29:18.6
-6,-1,29:18.6
0,-1,29:18.14
1,-1,29:18.14
2,-1,29:18.14
4,-1,29:18.14
7,-1,29:18.14
8,-1,29:18.14
10,-1,29:18.6
-7,0,29:18.6
1,0,29:18.14
2,0,29:18.14
3,0,29:18.14
5,0,29:18.14
6,0,29:18.14
10,0,29:18.6
11,0,29:18.6
-8,1,29:18.6
3,1,29:18.14
5,1,29:18.14
11,1,29:18.6
-1,2,29:18.14
0,2,29:18.14
1,2,29:18.14
2,2,29:18.14
3,2,29:18.14
4,2,29:18.14
5,2,29:18.14
11,2,29:18.6
-2,3,29:18.6
-1,3,29:18.6
5,3,29:18.6
11,3,29:18.6
6,4,29:18.6
12,4,29:18.6
7,5,29:18.6
12,5,29:18.6
8,6,29:18.6
9,6,29:18.6
9,7,29:18.6
10,7,29:18.6
10,8,29:18.6
-3,-15,30:18.6
8,-15,30:18.6
9,-15,30:18.6
-2,-14,30:18.6
7,-14,30:18.6
-1,-13,30:18.6
0,-13,30:18.6
0,-12,30:18.6
1,-12,30:18.6
2,-11,30:18.6
-4,-10,30:18.6
2,-10,30:18.6
3,-10,30:18.6
10,-10,30:18.6
16,-10,30:18.14
-4,-9,30:18.6
3,-9,30:18.14
6,-9,30:18.14
7,-9,30:18.14
8,-9,30:18.14
9,-9,30:18.14
16,-9,30:18.14
-4,-8,30:18.6
-3,-8,30:18.6
3,-8,30:18.14
4,-8,30:18.14
5,-8,30:18.14
6,-8,30:18.14
14,-8,30:18.6
15,-8,30:18.14
-3,-7,30:18.6
2,-7,30:18.14
3,-7,30:18.14
5,-7,30:18.14
6,-7,30:18.14
8,-7,30:18.14
13,-7,30:18.6
14,-7,30:18.6
-3,-6,30:18.6
0,-6,30:18.14
1,-6,30:18.14
6,-6,30:18.14
7,-6,30:18.14
13,-6,30:18.6
-3,-5,30:18.6
-1,-5,30:18.14
0,-5,30:18.14
1,-5,30:18.14
2,-5,30:17.12
3,-5,30:17.12
4,-5,30:17.12
5,-5,30:17.12
6,-5,30:18.14
7,-5,30:18.14
8,-5,30:18.14
11,-5,30:18.6
12,-5,30:18.6
-3,-4,30:18.6
-2,-4,30:18.14
-1,-4,30:18.14
2,-4,30:18.14
3,-4,30:18.14
4,-4,30:18.14
5,-4,30:18.14
6,-4,30:18.14
8,-4,30:18.14
9,-4,30:18.14
10,-4,30:18.6
11,-4,30:18.6
-4,-3,30:18.6
-3,-3,30:18.6
-2,-3,30:18.14
-1,-3,30:18.14
2,-3,30:17.12
3,-3,30:18.14
4,-3,30:18.14
5,-3,30:18.14
6,-3,30:18.14
9,-3,30:18.14
10,-3,30:18.6
-5,-2,30:18.6
-4,-2,30:18.6
0,-2,30:18.14
3,-2,30:17.12
4,-2,30:17.12
5,-2,30:18.14
6,-2,30:18.14
7,-2,30:18.14
8,-2,30:18.14
10,-2,30:18.6
-6,-1,30:18.6
-5,-1,30:18.6
1,-1,30:18.14
2,-1,30:18.14
3,-1,30:18.14
4,-1,30:18.14
6,-1,30:18.14
7,-1,30:18.14
8,-1,30:18.14
9,-1,30:18.14
10,-1,30:18.6
-7,0,30:18.6
-6,0,30:18.6
2,0,30:18.14
3,0,30:18.14
5,0,30:18.14
6,0,30:18.14
9,0,30:18.14
10,0,30:18.6
-8,1,30:18.6
-7,1,30:18.6
1,1,30:18.14
2,1,30:18.14
3,1,30:18.14
5,1,30:18.14
10,1,30:18.6
-9,2,30:18.6
-8,2,30:18.6
-2,2,30:18.6
-1,2,30:18.14
0,2,30:18.14
1,2,30:18.14
2,2,30:18.14
4,2,30:18.14
5,2,30:18.14
10,2,30:18.6
11,2,30:18.6
-10,3,30:18.6
-9,3,30:18.6
5,3,30:18.6
6,3,30:18.6
11,3,30:18.6
-10,4,30:18.6
6,4,30:18.6
7,4,30:18.6
7,5,30:18.6
8,5,30:18.6
8,6,30:18.6
9,6,30:18.6
10,7,30:18.6
8,-15,31:18.6
7,-14,31:18.6
8,-14,31:18.6
-4,-13,31:18.6
-1,-13,31:18.6
6,-13,31:18.6
0,-12,31:18.6
1,-12,31:18.6
2,-12,31:18.6
2,-11,31:18.6
-3,-10,31:18.6
2,-10,31:18.6
5,-10,31:18.6
-3,-9,31:18.6
3,-9,31:18.14
8,-9,31:18.14
9,-9,31:18.14
15,-9,31:18.14
16,-9,31:18.14
-3,-8,31:18.6
3,-8,31:18.14
4,-8,31:18.14
5,-8,31:18.14
6,-8,31:18.14
7,-8,31:18.14
9,-8,31:18.14
14,-8,31:18.6
15,-8,31:18.14
-3,-7,31:18.6
2,-7,31:18.14
3,-7,31:18.14
4,-7,31:18.14
5,-7,31:18.14
8,-7,31:18.14
9,-7,31:18.14
13,-7,31:18.6
14,-7,31:18.6
-3,-6,31:18.6
0,-6,31:18.14
1,-6,31:18.14
2,-6,31:18.14
5,-6,31:18.14
6,-6,31:18.14
7,-6,31:18.14
8,-6,31:18.14
12,-6,31:18.6
13,-6,31:18.6
-3,-5,31:18.6
-2,-5,31:18.14
-1,-5,31:18.14
0,-5,31:18.14
1,-5,31:18.14
2,-5,31:18.14
3,-5,31:17.0
4,-5,31:17.0
5,-5,31:18.14
6,-5,31:18.14
7,-5,31:18.14
8,-5,31:18.14
11,-5,31:18.6
12,-5,31:18.6
-2,-4,31:18.14
-1,-4,31:18.14
2,-4,31:18.14
3,-4,31:18.14
4,-4,31:18.14
5,-4,31:17.0
6,-4,31:18.14
8,-4,31:18.14
9,-4,31:18.14
10,-4,31:18.6
-3,-3,31:18.6
-2,-3,31:18.14
-1,-3,31:18.14
0,-3,31:18.14
2,-3,31:17.0
3,-3,31:18.14
4,-3,31:18.14
5,-3,31:18.14
6,-3,31:18.14
8,-3,31:18.14
9,-3,31:18.14
-5,-2,31:18.6
-4,-2,31:18.6
0,-2,31:18.14
1,-2,31:18.14
3,-2,31:17.0
4,-2,31:18.14
5,-2,31:18.14
6,-2,31:18.14
7,-2,31:18.14
8,-2,31:18.14
-6,-1,31:18.6
-5,-1,31:18.6
1,-1,31:18.14
2,-1,31:18.14
3,-1,31:18.14
4,-1,31:18.14
6,-1,31:18.14
7,-1,31:18.14
8,-1,31:18.14
9,-1,31:18.14
-6,0,31:18.6
2,0,31:18.14
3,0,31:18.14
4,0,31:18.14
5,0,31:18.14
9,0,31:18.14
10,0,31:18.6
-7,1,31:18.6
-1,1,31:18.14
0,1,31:18.14
1,1,31:18.14
2,1,31:18.14
3,1,31:18.14
5,1,31:18.14
10,1,31:18.6
-8,2,31:18.6
-2,2,31:18.6
-1,2,31:18.14
1,2,31:18.14
5,2,31:18.14
10,2,31:18.6
6,3,31:18.6
10,3,31:18.6
6,4,31:18.6
7,4,31:18.6
7,5,31:18.6
8,5,31:18.6
8,6,31:18.6
9,6,31:18.6
10,6,31:18.6
-1,7,31:18.6
-2,8,31:18.6
11,-17,32:18.6
12,-17,32:18.6
10,-16,32:18.6
9,-15,32:18.6
7,-14,32:18.6
8,-14,32:18.6
-4,-13,32:18.6
6,-13,32:18.6
7,-13,32:18.6
-3,-12,32:18.6
-2,-12,32:18.6
0,-12,32:18.6
1,-12,32:18.6
5,-12,32:18.6
2,-11,32:18.6
4,-11,32:18.6
-3,-10,32:18.6
2,-10,32:18.6
5,-10,32:18.6
6,-10,32:18.6
-3,-9,32:18.6
1,-9,32:18.14
2,-9,32:18.14
3,-9,32:18.14
6,-9,32:18.14
15,-9,32:18.14
-3,-8,32:18.6
-2,-8,32:18.6
3,-8,32:18.14
4,-8,32:18.14
5,-8,32:18.14
6,-8,32:18.14
14,-8,32:18.6
-3,-7,32:18.6
-2,-7,32:18.14
3,-7,32:18.14
4,-7,32:18.14
5,-7,32:18.14
13,-7,32:18.6
-2,-6,32:18.14
1,-6,32:18.14
2,-6,32:18.14
3,-6,32:18.14
5,-6,32:18.14
6,-6,32:18.14
12,-6,32:18.6
-2,-5,32:18.14
0,-5,32:18.14
1,-5,32:18.14
2,-5,32:17.0
3,-5,32:17.0
4,-5,32:17.0
5,-5,32:17.0
7,-5,32:18.14
10,-5,32:18.6
11,-5,32:18.6
-2,-4,32:18.14
-1,-4,32:18.14
0,-4,32:18.14
2,-4,32:17.0
4,-4,32:18.14
5,-4,32:17.0
8,-4,32:18.14
9,-4,32:18.14
10,-4,32:18.6
-3,-3,32:18.6
-2,-3,32:18.14
-1,-3,32:18.14
0,-3,32:18.14
2,-3,32:17.0
3,-3,32:17.0
4,-3,32:17.0
5,-3,32:17.0
8,-3,32:18.14
9,-3,32:18.14
-4,-2,32:18.6
-3,-2,32:18.6
1,-2,32:18.14
2,-2,32:18.14
3,-2,32:17.0
4,-2,32:17.0
6,-2,32:18.14
7,-2,32:18.14
8,-2,32:18.14
-5,-1,32:18.6
-4,-1,32:18.6
2,-1,32:18.14
3,-1,32:18.14
6,-1,32:18.14
8,-1,32:18.14
9,-1,32:18.14
-6,0,32:18.6
-5,0,32:18.6
2,0,32:18.14
3,0,32:18.14
4,0,32:18.14
5,0,32:18.14
9,0,32:18.14
-7,1,32:18.6
-6,1,32:18.6
-1,1,32:18.14
0,1,32:18.14
1,1,32:18.14
2,1,32:18.14
5,1,32:18.14
9,1,32:18.14
-8,2,32:18.6
-7,2,32:18.6
2,2,32:18.14
5,2,32:18.14
6,2,32:18.14
9,2,32:18.6
10,2,32:18.6
6,3,32:18.6
10,3,32:18.6
6,4,32:18.6
7,4,32:18.6
1,5,32:18.6
6,5,32:18.6
7,5,32:18.6
8,5,32:18.6
0,6,32:18.6
1,6,32:18.6
9,6,32:18.6
-1,7,32:18.6
11,-17,33:18.6
12,-17,33:18.6
10,-16,33:18.6
11,-16,33:18.6
9,-15,33:18.6
10,-15,33:18.6
7,-14,33:18.6
8,-14,33:18.6
-2,-13,33:18.6
-1,-13,33:18.6
6,-13,33:18.6
7,-13,33:18.6
-4,-12,33:18.6
-3,-12,33:18.6
-2,-12,33:18.6
-1,-12,33:18.6
0,-12,33:18.6
5,-12,33:18.6
6,-12,33:18.6
2,-11,33:18.6
4,-11,33:18.6
-2,-10,33:18.6
1,-10,33:18.6
2,-10,33:18.6
4,-10,33:18.6
5,-10,33:18.6
-2,-9,33:18.6
1,-9,33:18.14
2,-9,33:18.14
3,-9,33:18.14
5,-9,33:18.14
6,-9,33:18.14
10,-9,33:18.6
14,-9,33:18.6
-2,-8,33:18.6
0,-8,33:18.6
3,-8,33:18.14
4,-8,33:18.14
6,-8,33:18.14
7,-8,33:18.14
8,-8,33:18.14
9,-8,33:18.14
10,-8,33:18.6
13,-8,33:18.6
14,-8,33:18.6
-2,-7,33:18.6
3,-7,33:18.14
4,-7,33:18.14
5,-7,33:18.14
6,-7,33:18.14
12,-7,33:18.6
13,-7,33:18.6
-2,-6,33:18.6
2,-6,33:18.14
3,-6,33:18.14
5,-6,33:18.14
6,-6,33:18.14
11,-6,33:18.6
12,-6,33:18.6
-1,-5,33:18.6
1,-5,33:18.14
2,-5,33:17.0
3,-5,33:17.0
4,-5,33:17.0
5,-5,33:17.0
6,-5,33:18.14
7,-5,33:18.14
10,-5,33:18.6
11,-5,33:18.6
-1,-4,33:18.6
0,-4,33:18.6
2,-4,33:17.0
5,-4,33:17.0
7,-4,33:18.14
8,-4,33:18.14
9,-4,33:18.14
-2,-3,33:18.6
-1,-3,33:18.6
0,-3,33:18.6
1,-3,33:18.14
2,-3,33:17.0
3,-3,33:17.0
4,-3,33:17.0
5,-3,33:17.0
7,-3,33:18.14
8,-3,33:18.14
-4,-2,33:18.6
-3,-2,33:18.6
1,-2,33:18.14
2,-2,33:18.14
3,-2,33:17.0
6,-2,33:18.14
7,-2,33:18.14
8,-2,33:18.14
-5,-1,33:18.6
-4,-1,33:18.6
3,-1,33:18.14
4,-1,33:18.14
6,-1,33:18.14
8,-1,33:18.14
-6,0,33:18.6
-5,0,33:18.6
0,0,33:18.6
2,0,33:18.14
3,0,33:18.14
4,0,33:18.14
5,0,33:18.14
8,0,33:18.14
9,0,33:18.14
-7,1,33:18.6
-6,1,33:18.6
-2,1,33:18.6
1,1,33:18.14
5,1,33:18.14
6,1,33:18.14
8,1,33:18.14
9,1,33:18.14
-7,2,33:18.6
1,2,33:18.6
2,2,33:18.6
5,2,33:18.6
6,2,33:18.6
9,2,33:18.6
3,3,33:18.6
5,3,33:18.6
6,3,33:18.6
7,3,33:18.6
9,3,33:18.6
2,4,33:18.6
5,4,33:18.6
6,4,33:18.6
7,4,33:18.6
8,4,33:18.6
0,5,33:18.6
1,5,33:18.6
9,5,33:18.6
-1,6,33:18.6
0,6,33:18.6
10,6,33:18.6
-5,9,33:18.6
-5,10,33:18.6
10,-16,34:18.6
11,-16,34:18.6
9,-15,34:18.6
10,-15,34:18.6
8,-14,34:18.6
6,-13,34:18.6
7,-13,34:18.6
-3,-12,34:18.6
-2,-12,34:18.6
-1,-12,34:18.6
0,-12,34:18.6
5,-12,34:18.6
6,-12,34:18.6
-2,-11,34:18.6
-1,-11,34:18.6
2,-11,34:18.6
4,-11,34:18.6
1,-10,34:18.6
2,-10,34:18.6
3,-10,34:18.6
4,-10,34:18.6
5,-10,34:18.6
-2,-9,34:18.6
1,-9,34:18.14
2,-9,34:18.14
5,-9,34:18.14
6,-9,34:18.14
-2,-8,34:18.6
0,-8,34:18.6
1,-8,34:18.14
3,-8,34:18.14
7,-8,34:18.14
8,-8,34:18.14
9,-8,34:18.14
-2,-7,34:18.6
-1,-7,34:18.6
4,-7,34:18.14
5,-7,34:18.14
6,-7,34:18.14
7,-7,34:18.14
8,-7,34:18.14
9,-7,34:18.14
12,-7,34:18.6
-3,-6,34:18.6
-2,-6,34:18.6
-1,-6,34:18.6
2,-6,34:18.14
3,-6,34:18.14
4,-6,34:18.14
5,-6,34:18.14
9,-6,34:18.14
10,-6,34:18.6
11,-6,34:18.6
-1,-5,34:18.6
0,-5,34:18.6
1,-5,34:18.14
2,-5,34:17.0
4,-5,34:17.0
5,-5,34:17.0
6,-5,34:18.14
7,-5,34:18.14
9,-5,34:18.14
10,-5,34:18.6
0,-4,34:18.6
1,-4,34:18.14
2,-4,34:17.0
4,-4,34:17.0
5,-4,34:17.0
7,-4,34:18.14
8,-4,34:18.14
9,-4,34:18.14
-2,-3,34:18.6
-1,-3,34:18.6
1,-3,34:18.14
2,-3,34:17.0
3,-3,34:17.0
4,-3,34:17.0
7,-3,34:18.14
8,-3,34:18.14
-3,-2,34:18.6
-2,-2,34:18.6
2,-2,34:18.14
3,-2,34:18.14
5,-2,34:18.14
6,-2,34:18.14
8,-2,34:18.14
-4,-1,34:18.6
3,-1,34:18.14
4,-1,34:18.14
7,-1,34:18.14
8,-1,34:18.14
-5,0,34:18.6
-2,0,34:18.6
-1,0,34:18.6
0,0,34:18.6
1,0,34:18.6
2,0,34:18.6
3,0,34:18.6
4,0,34:18.6
5,0,34:18.6
6,0,34:18.6
7,0,34:18.6
8,0,34:18.6
-6,1,34:18.6
1,1,34:18.6
2,1,34:18.6
5,1,34:18.6
6,1,34:18.6
8,1,34:18.6
-7,2,34:18.6
2,2,34:18.6
3,2,34:18.6
6,2,34:18.6
7,2,34:18.6
3,3,34:18.6
5,3,34:18.6
6,3,34:18.6
7,3,34:18.6
1,4,34:18.6
2,4,34:18.6
6,4,34:18.6
7,4,34:18.6
8,4,34:18.6
9,4,34:18.6
0,5,34:18.6
1,5,34:18.6
9,5,34:18.6
10,5,34:18.6
11,5,34:18.6
-1,6,34:18.6
0,6,34:18.6
10,6,34:18.6
-3,7,34:18.6
-2,7,34:18.6
-4,8,34:18.6
-5,9,34:18.6
-4,9,34:18.6
9,-15,35:18.6
10,-15,35:18.6
8,-14,35:18.6
9,-14,35:18.6
6,-13,35:18.6
7,-13,35:18.6
-4,-12,35:18.6
5,-12,35:18.6
6,-12,35:18.6
-2,-11,35:18.6
-1,-11,35:18.6
4,-11,35:18.6
5,-11,35:18.6
-1,-10,35:18.6
1,-10,35:18.6
2,-10,35:18.6
3,-10,35:18.6
4,-10,35:18.6
-9,-9,35:18.6
-1,-9,35:18.6
1,-9,35:18.6
2,-9,35:18.6
3,-9,35:18.6
4,-9,35:18.6
5,-9,35:18.6
13,-9,35:18.6
14,-9,35:18.6
-8,-8,35:18.6
0,-8,35:18.6
1,-8,35:18.6
3,-8,35:18.6
6,-8,35:18.6
7,-8,35:18.6
12,-8,35:18.6
13,-8,35:18.6
-1,-7,35:18.6
0,-7,35:18.6
3,-7,35:18.6
4,-7,35:18.6
5,-7,35:18.6
6,-7,35:18.6
7,-7,35:18.6
8,-7,35:18.6
11,-7,35:18.6
12,-7,35:18.6
-3,-6,35:18.6
-2,-6,35:18.6
-1,-6,35:18.6
0,-6,35:18.6
3,-6,35:17.0
4,-6,35:18.6
5,-6,35:18.6
9,-6,35:18.6
10,-6,35:18.6
11,-6,35:18.6
-3,-5,35:18.6
0,-5,35:18.6
2,-5,35:18.6
3,-5,35:18.6
4,-5,35:17.0
5,-5,35:18.6
6,-5,35:18.6
9,-5,35:18.6
10,-5,35:18.6
0,-4,35:18.6
1,-4,35:18.6
2,-4,35:17.0
4,-4,35:17.0
7,-4,35:18.6
8,-4,35:18.6
-3,-3,35:18.6
-1,-3,35:18.6
0,-3,35:18.6
1,-3,35:18.6
2,-3,35:18.6
3,-3,35:17.0
4,-3,35:17.0
6,-3,35:18.6
7,-3,35:18.6
8,-3,35:18.6
9,-3,35:18.6
10,-3,35:18.6
-3,-2,35:18.6
-2,-2,35:18.6
-1,-2,35:18.6
2,-2,35:18.6
3,-2,35:18.6
5,-2,35:18.6
6,-2,35:18.6
7,-2,35:18.6
8,-2,35:18.6
-1,-1,35:18.6
0,-1,35:18.6
1,-1,35:18.6
2,-1,35:18.6
3,-1,35:18.6
4,-1,35:18.6
7,-1,35:18.6
8,-1,35:18.6
-1,0,35:18.6
0,0,35:18.6
1,0,35:18.6
5,0,35:18.6
6,0,35:18.6
7,0,35:18.6
1,1,35:18.6
2,1,35:18.6
5,1,35:18.6
6,1,35:18.6
7,1,35:18.6
8,1,35:18.6
3,2,35:18.6
4,2,35:18.6
6,2,35:18.6
7,2,35:18.6
8,2,35:18.6
3,3,35:18.6
5,3,35:18.6
6,3,35:18.6
7,3,35:18.6
8,3,35:18.6
1,4,35:18.6
7,4,35:18.6
8,4,35:18.6
9,4,35:18.6
10,4,35:18.6
-1,5,35:18.6
0,5,35:18.6
10,5,35:18.6
11,5,35:18.6
-2,6,35:18.6
-1,6,35:18.6
-3,7,35:18.6
-2,7,35:18.6
-4,8,35:18.6
11,-16,36:18.6
9,-15,36:18.6
10,-15,36:18.6
8,-14,36:18.6
9,-14,36:18.6
7,-13,36:18.6
5,-12,36:18.6
6,-12,36:18.6
-3,-11,36:18.6
-2,-11,36:18.6
-1,-11,36:18.6
4,-11,36:18.6
5,-11,36:18.6
-1,-10,36:18.6
0,-10,36:18.6
1,-10,36:18.6
2,-10,36:18.6
3,-10,36:18.6
4,-10,36:18.6
-1,-9,36:18.6
1,-9,36:18.6
2,-9,36:18.6
3,-9,36:18.6
4,-9,36:18.6
5,-9,36:18.6
12,-9,36:18.6
-8,-8,36:18.6
-7,-8,36:18.6
0,-8,36:18.6
1,-8,36:18.6
2,-8,36:18.6
3,-8,36:18.6
5,-8,36:18.6
6,-8,36:18.6
12,-8,36:18.6
-7,-7,36:18.6
-1,-7,36:18.6
0,-7,36:18.6
3,-7,36:18.6
4,-7,36:18.6
6,-7,36:18.6
7,-7,36:18.6
8,-7,36:18.6
11,-7,36:18.6
12,-7,36:18.6
-6,-6,36:18.6
-2,-6,36:18.6
-1,-6,36:18.6
0,-6,36:18.6
2,-6,36:17.0
3,-6,36:17.0
4,-6,36:18.6
5,-6,36:18.6
6,-6,36:18.6
8,-6,36:18.6
9,-6,36:18.6
10,-6,36:18.6
11,-6,36:18.6
-3,-5,36:18.6
0,-5,36:18.6
1,-5,36:18.6
2,-5,36:17.0
3,-5,36:18.6
4,-5,36:17.0
5,-5,36:18.6
6,-5,36:18.6
8,-5,36:18.6
9,-5,36:18.6
1,-4,36:18.6
2,-4,36:17.0
4,-4,36:17.0
6,-4,36:18.6
7,-4,36:18.6
8,-4,36:18.6
-3,-3,36:18.6
-1,-3,36:18.6
0,-3,36:18.6
2,-3,36:18.6
3,-3,36:17.0
4,-3,36:17.0
6,-3,36:18.6
7,-3,36:18.6
9,-3,36:18.6
10,-3,36:18.6
-5,-2,36:18.6
-2,-2,36:18.6
-1,-2,36:18.6
3,-2,36:18.6
4,-2,36:18.6
5,-2,36:18.6
7,-2,36:18.6
8,-2,36:18.6
-5,-1,36:18.6
-3,-1,36:18.6
-2,-1,36:18.6
-1,-1,36:18.6
0,-1,36:18.6
1,-1,36:18.6
2,-1,36:18.6
3,-1,36:18.6
4,-1,36:18.6
6,-1,36:18.6
7,-1,36:18.6
-5,0,36:18.6
-4,0,36:18.6
1,0,36:18.6
5,0,36:18.6
6,0,36:18.6
7,0,36:18.6
-5,1,36:18.6
2,1,36:18.6
3,1,36:18.6
5,1,36:18.6
6,1,36:18.6
7,1,36:18.6
-6,2,36:18.6
3,2,36:18.6
4,2,36:18.6
5,2,36:18.6
6,2,36:18.6
7,2,36:18.6
8,2,36:18.6
1,3,36:18.6
2,3,36:18.6
6,3,36:18.6
7,3,36:18.6
8,3,36:18.6
9,3,36:18.6
0,4,36:18.6
1,4,36:18.6
9,4,36:18.6
10,4,36:18.6
-1,5,36:18.6
0,5,36:18.6
-3,6,36:18.6
-2,6,36:18.6
-4,7,36:18.6
-3,7,36:18.6
9,-15,37:18.6
10,-15,37:18.6
-1,-14,37:18.6
8,-14,37:18.6
9,-14,37:18.6
7,-13,37:18.6
8,-13,37:18.6
-10,-12,37:18.6
5,-12,37:18.6
6,-12,37:18.6
-10,-11,37:18.6
-2,-11,37:18.6
4,-11,37:18.6
5,-11,37:18.6
-9,-10,37:18.6
-2,-10,37:18.6
-1,-10,37:18.6
0,-10,37:18.6
1,-10,37:18.6
2,-10,37:18.6
3,-10,37:18.6
4,-10,37:18.6
-8,-9,37:18.6
1,-9,37:18.6
2,-9,37:18.6
3,-9,37:18.6
4,-9,37:18.6
5,-9,37:18.6
-7,-8,37:18.6
0,-8,37:18.6
1,-8,37:18.6
2,-8,37:18.6
3,-8,37:18.6
5,-8,37:18.6
6,-8,37:18.6
11,-8,37:18.6
12,-8,37:18.6
-7,-7,37:18.6
-6,-7,37:18.6
-1,-7,37:18.6
0,-7,37:18.6
3,-7,37:18.6
6,-7,37:18.6
7,-7,37:18.6
10,-7,37:18.6
11,-7,37:18.6
-6,-6,37:18.6
-5,-6,37:18.6
-2,-6,37:18.6
-1,-6,37:18.6
0,-6,37:18.6
1,-6,37:18.6
2,-6,37:17.0
3,-6,37:17.0
4,-6,37:18.6
5,-6,37:18.6
6,-6,37:18.6
7,-6,37:18.6
8,-6,37:18.6
9,-6,37:18.6
10,-6,37:18.6
11,-6,37:18.6
-4,-5,37:18.6
-3,-5,37:18.6
-2,-5,37:18.6
1,-5,37:18.6
2,-5,37:17.0
3,-5,37:18.6
4,-5,37:17.0
5,-5,37:18.6
6,-5,37:18.6
8,-5,37:18.6
9,-5,37:18.6
-4,-4,37:18.6
1,-4,37:18.6
2,-4,37:18.6
4,-4,37:17.0
6,-4,37:18.6
7,-4,37:18.6
9,-4,37:18.6
10,-4,37:18.6
-4,-3,37:18.6
-2,-3,37:18.6
0,-3,37:18.6
1,-3,37:18.6
2,-3,37:18.6
3,-3,37:18.6
5,-3,37:18.6
6,-3,37:18.6
7,-3,37:18.6
8,-3,37:18.6
9,-3,37:18.6
12,-3,37:18.6
-5,-2,37:18.6
-4,-2,37:18.6
-2,-2,37:18.6
-1,-2,37:18.6
0,-2,37:18.6
1,-2,37:18.6
2,-2,37:18.6
3,-2,37:18.6
4,-2,37:18.6
5,-2,37:18.6
6,-2,37:18.6
7,-2,37:18.6
8,-2,37:18.6
13,-2,37:18.6
-5,-1,37:18.6
-3,-1,37:18.6
-2,-1,37:18.6
0,-1,37:18.6
1,-1,37:18.6
6,-1,37:18.6
7,-1,37:18.6
14,-1,37:18.6
-5,0,37:18.6
-4,0,37:18.6
-3,0,37:18.6
1,0,37:18.6
2,0,37:18.6
4,0,37:18.6
5,0,37:18.6
6,0,37:18.6
15,0,37:18.6
2,1,37:18.6
3,1,37:18.6
6,1,37:18.6
7,1,37:18.6
2,2,37:18.6
3,2,37:18.6
4,2,37:18.6
5,2,37:18.6
6,2,37:18.6
7,2,37:18.6
1,3,37:18.6
2,3,37:18.6
7,3,37:18.6
8,3,37:18.6
9,3,37:18.6
-1,4,37:18.6
0,4,37:18.6
-2,5,37:18.6
-1,5,37:18.6
-3,6,37:18.6
-2,6,37:18.6
-4,7,37:18.6
-4,-16,38:18.6
0,-14,38:18.6
8,-14,38:18.6
9,-14,38:18.6
0,-13,38:18.6
1,-13,38:18.6
7,-13,38:18.6
8,-13,38:18.6
-10,-12,38:18.6
6,-12,38:18.6
7,-12,38:18.6
8,-12,38:18.6
12,-12,38:18.6
-10,-11,38:18.6
-9,-11,38:18.6
5,-11,38:18.6
11,-11,38:18.6
-9,-10,38:18.6
-8,-10,38:18.6
-2,-10,38:18.6
-1,-10,38:18.6
0,-10,38:18.6
1,-10,38:18.6
4,-10,38:18.6
11,-10,38:18.6
-8,-9,38:18.6
-7,-9,38:18.6
1,-9,38:18.6
2,-9,38:18.6
3,-9,38:18.6
4,-9,38:18.6
11,-9,38:18.6
-7,-8,38:18.6
-6,-8,38:18.6
1,-8,38:18.6
2,-8,38:18.6
4,-8,38:18.6
5,-8,38:18.6
6,-8,38:18.6
10,-8,38:18.6
11,-8,38:18.6
-6,-7,38:18.6
0,-7,38:18.6
1,-7,38:18.6
3,-7,38:18.6
6,-7,38:18.6
7,-7,38:18.6
10,-7,38:18.6
11,-7,38:18.6
-5,-6,38:18.6
-2,-6,38:18.6
-1,-6,38:18.6
1,-6,38:18.6
2,-6,38:17.0
3,-6,38:17.0
4,-6,38:18.6
5,-6,38:18.6
6,-6,38:18.6
7,-6,38:18.6
8,-6,38:18.6
9,-6,38:18.6
10,-6,38:18.6
-4,-5,38:18.6
-3,-5,38:18.6
-2,-5,38:18.6
1,-5,38:18.6
2,-5,38:18.6
3,-5,38:18.6
4,-5,38:18.6
5,-5,38:18.6
7,-5,38:18.6
8,-5,38:18.6
9,-5,38:18.6
10,-5,38:18.6
-4,-4,38:18.6
-3,-4,38:18.6
2,-4,38:18.6
3,-4,38:18.6
4,-4,38:17.0
5,-4,38:18.6
6,-4,38:18.6
7,-4,38:18.6
9,-4,38:18.6
10,-4,38:18.6
-4,-3,38:18.6
-2,-3,38:18.6
-1,-3,38:18.6
0,-3,38:18.6
1,-3,38:18.6
2,-3,38:18.6
3,-3,38:18.6
4,-3,38:18.6
5,-3,38:18.6
6,-3,38:18.6
7,-3,38:18.6
8,-3,38:18.6
9,-3,38:18.6
12,-3,38:18.6
-4,-2,38:18.6
-1,-2,38:18.6
0,-2,38:18.6
1,-2,38:18.6
2,-2,38:18.6
3,-2,38:18.6
4,-2,38:18.6
5,-2,38:18.6
6,-2,38:18.6
7,-2,38:18.6
12,-2,38:18.6
13,-2,38:18.6
-4,-1,38:18.6
-2,-1,38:18.6
-1,-1,38:18.6
0,-1,38:18.6
1,-1,38:18.6
6,-1,38:18.6
13,-1,38:18.6
14,-1,38:18.6
2,0,38:18.6
3,0,38:18.6
4,0,38:18.6
6,0,38:18.6
14,0,38:18.6
-5,1,38:18.6
2,1,38:18.6
3,1,38:18.6
5,1,38:18.6
7,1,38:18.6
2,2,38:18.6
6,2,38:18.6
7,2,38:18.6
8,2,38:18.6
1,3,38:18.6
9,3,38:18.6
10,3,38:18.6
-1,4,38:18.6
0,4,38:18.6
-2,5,38:18.6
-3,6,38:18.6
-4,-16,39:18.6
-3,-16,39:18.6
-2,-15,39:18.6
9,-14,39:18.6
0,-13,39:18.6
1,-13,39:18.6
7,-13,39:18.6
8,-13,39:18.6
1,-12,39:18.6
6,-12,39:18.6
7,-12,39:18.6
11,-12,39:18.6
-9,-11,39:18.6
5,-11,39:18.6
6,-11,39:18.6
11,-11,39:18.6
-8,-10,39:18.6
-2,-10,39:18.6
-1,-10,39:18.6
0,-10,39:18.6
4,-10,39:18.6
10,-10,39:18.6
11,-10,39:18.6
-7,-9,39:18.6
0,-9,39:18.6
1,-9,39:18.6
2,-9,39:18.6
3,-9,39:18.6
4,-9,39:18.6
10,-9,39:18.6
-7,-8,39:18.6
-6,-8,39:18.6
1,-8,39:18.6
2,-8,39:18.6
4,-8,39:18.6
5,-8,39:18.6
10,-8,39:18.6
-6,-7,39:18.6
-5,-7,39:18.6
0,-7,39:18.6
1,-7,39:18.6
2,-7,39:18.6
3,-7,39:18.6
5,-7,39:18.6
6,-7,39:18.6
9,-7,39:18.6
10,-7,39:18.6
-5,-6,39:18.6
-4,-6,39:18.6
-1,-6,39:18.6
0,-6,39:18.6
1,-6,39:18.6
2,-6,39:17.0
3,-6,39:17.0
4,-6,39:18.6
7,-6,39:18.6
8,-6,39:18.6
9,-6,39:18.6
10,-6,39:18.6
-4,-5,39:18.6
-3,-5,39:18.6
-2,-5,39:18.6
1,-5,39:17.0
2,-5,39:18.6
3,-5,39:18.6
4,-5,39:18.6
5,-5,39:18.6
6,-5,39:18.6
7,-5,39:18.6
8,-5,39:18.6
9,-5,39:18.6
-3,-4,39:18.6
-2,-4,39:18.6
1,-4,39:17.0
2,-4,39:17.0
3,-4,39:18.6
4,-4,39:17.0
5,-4,39:18.6
6,-4,39:18.6
8,-4,39:18.6
9,-4,39:18.6
10,-4,39:18.6
-4,-3,39:18.6
-2,-3,39:18.6
-1,-3,39:18.6
1,-3,39:18.6
2,-3,39:18.6
3,-3,39:18.6
4,-3,39:18.6
5,-3,39:18.6
6,-3,39:18.6
7,-3,39:18.6
8,-3,39:18.6
11,-3,39:18.6
-4,-2,39:18.6
-1,-2,39:18.6
0,-2,39:18.6
1,-2,39:18.6
5,-2,39:18.6
6,-2,39:18.6
12,-2,39:18.6
-4,-1,39:18.6
-1,-1,39:18.6
1,-1,39:18.6
2,-1,39:18.6
4,-1,39:18.6
6,-1,39:18.6
13,-1,39:18.6
-4,0,39:18.6
2,0,39:18.6
3,0,39:18.6
4,0,39:18.6
14,0,39:18.6
-4,1,39:18.6
2,1,39:18.6
3,1,39:18.6
5,1,39:18.6
6,1,39:18.6
7,1,39:18.6
15,1,39:18.6
-5,2,39:18.6
-4,2,39:18.6
1,2,39:18.6
2,2,39:18.6
7,2,39:18.6
8,2,39:18.6
9,2,39:18.6
-5,3,39:18.6
0,3,39:18.6
-2,4,39:18.6
-1,4,39:18.6
-3,5,39:18.6
-2,5,39:18.6
-4,-16,40:18.6
-3,-15,40:18.6
-2,-15,40:18.6
-2,-14,40:18.6
-1,-14,40:18.6
9,-14,40:18.6
0,-13,40:18.6
7,-13,40:18.6
8,-13,40:18.6
-9,-12,40:18.6
1,-12,40:18.6
2,-12,40:18.6
6,-12,40:18.6
7,-12,40:18.6
-9,-11,40:18.6
-8,-11,40:18.6
5,-11,40:18.6
6,-11,40:18.6
10,-11,40:18.6
-8,-10,40:18.6
-7,-10,40:18.6
-2,-10,40:18.6
2,-10,40:18.6
4,-10,40:18.6
5,-10,40:18.6
10,-10,40:18.6
-7,-9,40:18.6
-2,-9,40:18.6
-1,-9,40:18.6
0,-9,40:18.6
1,-9,40:18.6
2,-9,40:18.6
3,-9,40:18.6
4,-9,40:18.6
5,-9,40:18.6
9,-9,40:18.6
10,-9,40:18.6
-6,-8,40:18.6
1,-8,40:18.6
2,-8,40:18.6
3,-8,40:18.6
4,-8,40:18.6
5,-8,40:18.6
9,-8,40:18.6
-5,-7,40:18.6
0,-7,40:18.6
1,-7,40:18.6
2,-7,40:18.6
3,-7,40:18.6
5,-7,40:18.6
6,-7,40:18.6
9,-7,40:18.6
-5,-6,40:18.6
-4,-6,40:18.6
-1,-6,40:18.6
0,-6,40:18.6
1,-6,40:17.0
2,-6,40:17.0
3,-6,40:18.6
4,-6,40:17.0
6,-6,40:18.6
7,-6,40:18.6
8,-6,40:18.6
9,-6,40:18.6
-4,-5,40:18.6
-3,-5,40:18.6
-2,-5,40:18.6
-1,-5,40:18.6
1,-5,40:17.0
3,-5,40:18.6
4,-5,40:18.6
5,-5,40:18.6
6,-5,40:18.6
7,-5,40:18.6
8,-5,40:18.6
9,-5,40:18.6
-3,-4,40:18.6
-2,-4,40:18.6
-1,-4,40:18.6
1,-4,40:17.0
2,-4,40:17.0
3,-4,40:18.6
4,-4,40:18.6
5,-4,40:18.6
6,-4,40:18.6
7,-4,40:18.6
8,-4,40:18.6
9,-4,40:18.6
10,-4,40:18.6
-3,-3,40:18.6
-1,-3,40:18.6
0,-3,40:18.6
1,-3,40:18.6
2,-3,40:18.6
3,-3,40:18.6
4,-3,40:18.6
5,-3,40:18.6
6,-3,40:18.6
7,-3,40:18.6
10,-3,40:18.6
11,-3,40:18.6
-4,-2,40:18.6
-3,-2,40:18.6
0,-2,40:18.6
1,-2,40:18.6
5,-2,40:18.6
6,-2,40:18.6
11,-2,40:18.6
12,-2,40:18.6
-4,-1,40:18.6
1,-1,40:18.6
2,-1,40:18.6
3,-1,40:18.6
4,-1,40:18.6
6,-1,40:18.6
12,-1,40:18.6
13,-1,40:18.6
-4,0,40:18.6
2,0,40:18.6
3,0,40:18.6
4,0,40:18.6
5,0,40:18.6
7,0,40:18.6
13,0,40:18.6
14,0,40:18.6
-4,1,40:18.6
1,1,40:18.6
2,1,40:18.6
6,1,40:18.6
7,1,40:18.6
8,1,40:18.6
14,1,40:18.6
15,1,40:18.6
-4,2,40:18.6
0,2,40:18.6
1,2,40:18.6
15,2,40:18.6
16,2,40:18.6
-1,3,40:18.6
0,3,40:18.6
1,3,40:18.6
16,3,40:18.6
17,3,40:18.6
-2,4,40:18.6
-1,4,40:18.6
0,4,40:18.6
-3,5,40:18.6
-3,-15,41:18.6
-2,-14,41:18.6
-1,-14,41:18.6
-1,-13,41:18.6
0,-13,41:18.6
8,-13,41:18.6
1,-12,41:18.6
6,-12,41:18.6
7,-12,41:18.6
8,-12,41:18.6
9,-12,41:18.6
10,-12,41:18.6
5,-11,41:18.6
6,-11,41:18.6
7,-11,41:18.6
9,-11,41:18.6
-7,-10,41:18.6
2,-10,41:18.6
3,-10,41:18.6
4,-10,41:18.6
5,-10,41:18.6
9,-10,41:18.6
-7,-9,41:18.6
-6,-9,41:18.6
-2,-9,41:18.6
-1,-9,41:18.6
0,-9,41:18.6
1,-9,41:18.6
2,-9,41:18.6
3,-9,41:18.6
4,-9,41:18.6
5,-9,41:18.6
9,-9,41:18.6
-6,-8,41:18.6
-5,-8,41:18.6
0,-8,41:18.6
1,-8,41:18.6
2,-8,41:18.6
3,-8,41:18.6
4,-8,41:18.6
8,-8,41:18.6
9,-8,41:18.6
-5,-7,41:18.6
-4,-7,41:18.6
1,-7,41:18.6
2,-7,41:18.6
4,-7,41:18.6
5,-7,41:18.6
8,-7,41:18.6
9,-7,41:18.6
-4,-6,41:18.6
-3,-6,41:18.6
-1,-6,41:18.6
0,-6,41:18.6
1,-6,41:17.0
2,-6,41:17.0
3,-6,41:18.6
4,-6,41:17.0
6,-6,41:18.6
7,-6,41:18.6
8,-6,41:18.6
-3,-5,41:18.6
-2,-5,41:18.6
-1,-5,41:18.6
1,-5,41:17.0
3,-5,41:18.6
4,-5,41:18.6
5,-5,41:18.6
6,-5,41:18.6
7,-5,41:18.6
8,-5,41:18.6
-3,-4,41:18.6
-2,-4,41:18.6
-1,-4,41:18.6
1,-4,41:17.0
2,-4,41:17.0
3,-4,41:17.0
4,-4,41:18.6
5,-4,41:18.6
7,-4,41:18.6
8,-4,41:18.6
9,-4,41:18.6
10,-4,41:18.6
-3,-3,41:18.6
-1,-3,41:18.6
0,-3,41:18.6
1,-3,41:18.6
2,-3,41:18.6
3,-3,41:18.6
5,-3,41:18.6
6,-3,41:18.6
10,-3,41:18.6
11,-3,41:18.6
-3,-2,41:18.6
1,-2,41:18.6
2,-2,41:18.6
4,-2,41:18.6
5,-2,41:18.6
6,-2,41:18.6
11,-2,41:18.6
12,-2,41:18.6
-3,-1,41:18.6
0,-1,41:18.6
2,-1,41:18.6
3,-1,41:18.6
4,-1,41:18.6
6,-1,41:18.6
7,-1,41:18.6
12,-1,41:18.6
13,-1,41:18.6
-4,0,41:18.6
2,0,41:18.6
3,0,41:18.6
4,0,41:18.6
5,0,41:18.6
6,0,41:18.6
7,0,41:18.6
8,0,41:18.6
13,0,41:18.6
14,0,41:18.6
-4,1,41:18.6
1,1,41:18.6
2,1,41:18.6
5,1,41:18.6
7,1,41:18.6
8,1,41:18.6
14,1,41:18.6
15,1,41:18.6
-4,2,41:18.6
0,2,41:18.6
1,2,41:18.6
4,2,41:18.6
15,2,41:18.6
-4,3,41:18.6
-2,3,41:18.6
-1,3,41:18.6
0,3,41:18.6
1,3,41:18.6
16,3,41:18.6
-4,4,41:18.6
-3,4,41:18.6
-2,4,41:18.6
6,5,41:18.6
7,6,41:18.6
8,7,41:18.6
-3,-15,42:18.6
-2,-14,42:18.6
-1,-13,42:18.6
0,-13,42:18.6
8,-13,42:18.6
0,-12,42:18.6
1,-12,42:18.6
7,-12,42:18.6
8,-12,42:18.6
9,-12,42:18.6
10,-12,42:18.6
2,-11,42:18.6
5,-11,42:18.6
6,-11,42:18.6
7,-11,42:18.6
8,-11,42:18.6
-7,-10,42:18.6
2,-10,42:18.6
3,-10,42:18.6
4,-10,42:18.6
5,-10,42:18.6
8,-10,42:18.6
9,-10,42:18.6
-6,-9,42:18.6
-2,-9,42:18.6
-1,-9,42:18.6
0,-9,42:18.6
1,-9,42:18.6
2,-9,42:18.6
4,-9,42:18.6
5,-9,42:18.6
8,-9,42:18.6
-5,-8,42:18.6
0,-8,42:18.6
1,-8,42:18.6
2,-8,42:18.6
3,-8,42:18.6
4,-8,42:18.6
5,-8,42:18.6
6,-8,42:18.6
8,-8,42:18.6
-4,-7,42:18.6
-2,-7,42:18.6
-1,-7,42:18.6
1,-7,42:18.6
2,-7,42:18.6
4,-7,42:18.6
5,-7,42:18.6
7,-7,42:18.6
8,-7,42:18.6
-4,-6,42:18.6
-3,-6,42:18.6
-2,-6,42:18.6
0,-6,42:18.6
1,-6,42:17.0
2,-6,42:17.0
3,-6,42:17.0
5,-6,42:18.6
6,-6,42:18.6
7,-6,42:18.6
8,-6,42:18.6
-2,-5,42:18.6
-1,-5,42:18.6
1,-5,42:17.0
3,-5,42:17.0
7,-5,42:18.6
8,-5,42:18.6
-2,-4,42:18.6
-1,-4,42:18.6
0,-4,42:18.6
2,-4,42:17.0
3,-4,42:17.0
4,-4,42:18.6
6,-4,42:18.6
7,-4,42:18.6
8,-4,42:18.6
9,-4,42:18.6
-3,-3,42:18.6
0,-3,42:18.6
1,-3,42:18.6
3,-3,42:18.6
5,-3,42:18.6
6,-3,42:18.6
9,-3,42:18.6
10,-3,42:18.6
-3,-2,42:18.6
-1,-2,42:18.6
1,-2,42:18.6
2,-2,42:18.6
3,-2,42:18.6
4,-2,42:18.6
11,-2,42:18.6
-3,-1,42:18.6
0,-1,42:18.6
2,-1,42:18.6
3,-1,42:18.6
4,-1,42:18.6
12,-1,42:18.6
-3,0,42:18.6
1,0,42:18.6
2,0,42:18.6
5,0,42:18.6
6,0,42:18.6
7,0,42:18.6
8,0,42:18.6
13,0,42:18.6
-3,1,42:18.6
1,1,42:18.6
2,1,42:18.6
5,1,42:18.6
8,1,42:18.6
14,1,42:18.6
-1,2,42:18.6
0,2,42:18.6
1,2,42:18.6
2,2,42:18.6
3,2,42:18.6
15,2,42:18.6
-4,3,42:18.6
-3,3,42:18.6
-2,3,42:18.6
-1,3,42:18.6
0,3,42:18.6
1,3,42:18.6
4,3,42:18.6
-3,4,42:18.6
-2,4,42:18.6
5,4,42:18.6
6,4,42:18.6
6,5,42:18.6
7,5,42:18.6
7,6,42:18.6
-3,-15,43:18.6
-3,-14,43:18.6
-2,-14,43:18.6
-1,-13,43:18.6
0,-13,43:18.6
0,-12,43:18.6
1,-12,43:18.6
7,-12,43:18.6
8,-12,43:18.6
9,-12,43:18.6
2,-11,43:18.6
5,-11,43:18.6
6,-11,43:18.6
7,-11,43:18.6
8,-11,43:18.6
-6,-10,43:18.6
3,-10,43:18.6
4,-10,43:18.6
5,-10,43:18.6
7,-10,43:18.6
8,-10,43:18.6
-6,-9,43:18.6
-5,-9,43:18.6
1,-9,43:18.6
2,-9,43:18.6
3,-9,43:18.6
4,-9,43:18.6
5,-9,43:18.6
7,-9,43:18.6
8,-9,43:18.6
-5,-8,43:18.6
-4,-8,43:18.6
0,-8,43:18.6
1,-8,43:18.6
2,-8,43:18.6
3,-8,43:18.6
5,-8,43:18.6
6,-8,43:18.6
7,-8,43:18.6
-4,-7,43:18.6
-3,-7,43:18.6
-2,-7,43:18.6
-1,-7,43:18.6
1,-7,43:18.6
2,-7,43:18.6
3,-7,43:18.6
4,-7,43:18.6
5,-7,43:18.6
6,-7,43:18.6
7,-7,43:18.6
-3,-6,43:18.6
-2,-6,43:18.6
0,-6,43:18.6
1,-6,43:18.6
2,-6,43:17.0
3,-6,43:17.0
5,-6,43:18.6
6,-6,43:18.6
7,-6,43:18.6
8,-6,43:18.6
-2,-5,43:18.6
-1,-5,43:18.6
0,-5,43:18.6
1,-5,43:17.0
3,-5,43:17.0
6,-5,43:18.6
7,-5,43:18.6
9,-5,43:18.6
-3,-4,43:18.6
-2,-4,43:18.6
-1,-4,43:18.6
0,-4,43:18.6
2,-4,43:17.0
3,-4,43:17.0
5,-4,43:18.6
6,-4,43:18.6
7,-4,43:18.6
8,-4,43:18.6
9,-4,43:18.6
-3,-3,43:18.6
-2,-3,43:18.6
1,-3,43:18.6
2,-3,43:18.6
4,-3,43:18.6
5,-3,43:18.6
9,-3,43:18.6
10,-3,43:18.6
-3,-2,43:18.6
-2,-2,43:18.6
-1,-2,43:18.6
2,-2,43:18.6
3,-2,43:18.6
4,-2,43:18.6
7,-2,43:18.6
8,-2,43:18.6
10,-2,43:18.6
11,-2,43:18.6
-3,-1,43:18.6
0,-1,43:18.6
2,-1,43:18.6
3,-1,43:18.6
4,-1,43:18.6
6,-1,43:18.6
7,-1,43:18.6
11,-1,43:18.6
12,-1,43:18.6
-3,0,43:18.6
1,0,43:18.6
2,0,43:18.6
4,0,43:18.6
5,0,43:18.6
6,0,43:18.6
7,0,43:18.6
8,0,43:18.6
12,0,43:18.6
13,0,43:18.6
-3,1,43:18.6
0,1,43:18.6
1,1,43:18.6
2,1,43:18.6
3,1,43:18.6
13,1,43:18.6
-3,2,43:18.6
-2,2,43:18.6
-1,2,43:18.6
0,2,43:18.6
1,2,43:18.6
2,2,43:18.6
3,2,43:18.6
-3,3,43:18.6
-2,3,43:18.6
4,3,43:18.6
5,3,43:18.6
5,4,43:18.6
6,4,43:18.6
6,5,43:18.6
7,5,43:18.6
8,6,43:18.6
10,8,43:18.6
-2,-14,44:18.6
-2,-13,44:18.6
-1,-13,44:18.6
-4,-12,44:18.6
0,-12,44:18.6
8,-12,44:18.6
2,-11,44:18.6
6,-11,44:18.6
7,-11,44:18.6
8,-11,44:18.6
9,-11,44:18.6
-6,-10,44:18.6
2,-10,44:18.6
3,-10,44:18.6
4,-10,44:18.6
5,-10,44:18.6
6,-10,44:18.6
7,-10,44:18.6
-5,-9,44:18.6
-4,-9,44:18.6
1,-9,44:18.6
2,-9,44:18.6
3,-9,44:18.6
4,-9,44:18.6
6,-9,44:18.6
7,-9,44:18.6
-4,-8,44:18.6
-2,-8,44:18.6
0,-8,44:18.6
1,-8,44:18.6
2,-8,44:18.6
3,-8,44:18.6
4,-8,44:18.6
5,-8,44:18.6
6,-8,44:18.6
7,-8,44:18.6
-4,-7,44:18.6
-3,-7,44:18.6
-1,-7,44:18.6
0,-7,44:18.6
2,-7,44:18.6
3,-7,44:18.6
4,-7,44:18.6
6,-7,44:18.6
7,-7,44:18.6
-4,-6,44:18.6
-3,-6,44:18.6
-2,-6,44:18.6
0,-6,44:18.6
1,-6,44:18.6
3,-6,44:17.0
4,-6,44:18.6
5,-6,44:18.6
6,-6,44:18.6
7,-6,44:18.6
8,-6,44:18.6
-1,-5,44:18.6
0,-5,44:18.6
1,-5,44:17.0
2,-5,44:17.0
3,-5,44:17.0
6,-5,44:18.6
7,-5,44:18.6
9,-5,44:18.6
-3,-4,44:18.6
-2,-4,44:18.6
-1,-4,44:18.6
0,-4,44:18.6
1,-4,44:18.6
2,-4,44:17.0
5,-4,44:18.6
6,-4,44:18.6
7,-4,44:18.6
8,-4,44:18.6
-6,-3,44:18.6
-2,-3,44:18.6
-1,-3,44:18.6
1,-3,44:18.6
2,-3,44:18.6
3,-3,44:18.6
4,-3,44:18.6
8,-3,44:18.6
9,-3,44:18.6
-7,-2,44:18.6
-2,-2,44:18.6
-1,-2,44:18.6
0,-2,44:18.6
2,-2,44:18.6
3,-2,44:18.6
4,-2,44:18.6
5,-2,44:18.6
6,-2,44:18.6
7,-2,44:18.6
8,-2,44:18.6
10,-2,44:18.6
-8,-1,44:18.6
-7,-1,44:18.6
-3,-1,44:18.6
-2,-1,44:18.6
0,-1,44:18.6
1,-1,44:18.6
2,-1,44:18.6
6,-1,44:18.6
7,-1,44:18.6
11,-1,44:18.6
-3,0,44:18.6
1,0,44:18.6
2,0,44:18.6
4,0,44:18.6
5,0,44:18.6
12,0,44:18.6
-1,1,44:18.6
0,1,44:18.6
1,1,44:18.6
2,1,44:18.6
3,1,44:18.6
-3,2,44:18.6
-2,2,44:18.6
-1,2,44:18.6
0,2,44:18.6
4,2,44:18.6
-2,3,44:18.6
4,3,44:18.6
5,3,44:18.6
6,4,44:18.6
7,5,44:18.6
8,5,44:18.6
8,6,44:18.6
9,6,44:18.6
9,7,44:18.6
10,7,44:18.6
10,8,44:18.6
-2,-13,45:18.6
-1,-13,45:18.6
-4,-12,45:18.6
-1,-12,45:18.6
0,-12,45:18.6
7,-12,45:18.6
8,-12,45:18.6
-4,-11,45:18.6
2,-11,45:18.6
6,-11,45:18.6
7,-11,45:18.6
8,-11,45:18.6
9,-11,45:18.6
-4,-10,45:18.6
2,-10,45:18.6
3,-10,45:18.6
4,-10,45:18.6
5,-10,45:18.6
6,-10,45:18.6
-5,-9,45:18.6
-4,-9,45:18.6
2,-9,45:18.6
3,-9,45:18.6
4,-9,45:18.6
5,-9,45:18.6
6,-9,45:18.6
-4,-8,45:18.6
0,-8,45:18.6
1,-8,45:18.6
3,-8,45:18.6
4,-8,45:18.6
5,-8,45:18.6
6,-8,45:18.6
13,-8,45:18.6
-4,-7,45:18.6
-3,-7,45:18.6
-2,-7,45:18.6
-1,-7,45:18.6
0,-7,45:18.6
1,-7,45:18.6
2,-7,45:18.6
3,-7,45:18.6
4,-7,45:18.6
5,-7,45:18.6
6,-7,45:18.6
12,-7,45:18.6
-4,-6,45:18.6
-3,-6,45:18.6
-2,-6,45:18.6
-1,-6,45:18.6
1,-6,45:18.6
2,-6,45:18.6
3,-6,45:17.0
4,-6,45:18.6
5,-6,45:18.6
6,-6,45:18.6
7,-6,45:18.6
8,-6,45:18.6
11,-6,45:18.6
-4,-5,45:18.6
-3,-5,45:18.6
-1,-5,45:18.6
0,-5,45:18.6
1,-5,45:17.0
2,-5,45:17.0
3,-5,45:17.0
5,-5,45:18.6
6,-5,45:18.6
8,-5,45:18.6
9,-5,45:18.6
-5,-4,45:18.6
-3,-4,45:18.6
-2,-4,45:18.6
-1,-4,45:18.6
0,-4,45:18.6
1,-4,45:18.6
2,-4,45:17.0
4,-4,45:18.6
5,-4,45:18.6
7,-4,45:18.6
8,-4,45:18.6
-6,-3,45:18.6
-5,-3,45:18.6
-2,-3,45:18.6
-1,-3,45:18.6
2,-3,45:18.6
3,-3,45:18.6
4,-3,45:18.6
7,-3,45:18.6
8,-3,45:18.6
9,-3,45:18.6
-7,-2,45:18.6
-6,-2,45:18.6
-2,-2,45:18.6
-1,-2,45:18.6
0,-2,45:18.6
2,-2,45:18.6
3,-2,45:18.6
4,-2,45:18.6
5,-2,45:18.6
6,-2,45:18.6
7,-2,45:18.6
10,-2,45:18.6
-2,-1,45:18.6
1,-1,45:18.6
2,-1,45:18.6
4,-1,45:18.6
7,-1,45:18.6
8,-1,45:18.6
10,-1,45:18.6
11,-1,45:18.6
-2,0,45:18.6
0,0,45:18.6
1,0,45:18.6
2,0,45:18.6
3,0,45:18.6
4,0,45:18.6
11,0,45:18.6
12,0,45:18.6
-3,1,45:18.6
-2,1,45:18.6
-1,1,45:18.6
0,1,45:18.6
1,1,45:18.6
2,1,45:18.6
3,1,45:18.6
-2,2,45:18.6
4,2,45:18.6
5,2,45:18.6
5,3,45:18.6
6,3,45:18.6
6,4,45:18.6
7,4,45:18.6
7,5,45:18.6
8,5,45:18.6
8,6,45:18.6
9,6,45:18.6
-2,-13,46:18.6
-1,-12,46:18.6
0,-12,46:18.6
-4,-11,46:18.6
6,-11,46:18.6
7,-11,46:18.6
-5,-10,46:18.6
-4,-10,46:18.6
2,-10,46:18.6
5,-10,46:18.6
6,-10,46:18.6
7,-10,46:18.6
-4,-9,46:18.6
2,-9,46:18.6
3,-9,46:18.6
4,-9,46:18.6
5,-9,46:18.6
-4,-8,46:18.6
-3,-8,46:18.6
0,-8,46:18.6
1,-8,46:18.6
3,-8,46:18.6
4,-8,46:18.6
5,-8,46:18.6
12,-8,46:18.6
-4,-7,46:18.6
-3,-7,46:18.6
-2,-7,46:18.6
-1,-7,46:18.6
0,-7,46:18.6
1,-7,46:18.6
2,-7,46:18.6
3,-7,46:18.6
5,-7,46:18.6
6,-7,46:18.6
11,-7,46:18.6
12,-7,46:18.6
-4,-6,46:18.6
-3,-6,46:18.6
-2,-6,46:18.6
-1,-6,46:18.6
1,-6,46:18.6
2,-6,46:18.6
3,-6,46:17.0
4,-6,46:18.6
5,-6,46:18.6
6,-6,46:18.6
7,-6,46:18.6
10,-6,46:18.6
11,-6,46:18.6
-4,-5,46:18.6
-3,-5,46:18.6
0,-5,46:18.6
1,-5,46:17.0
2,-5,46:17.0
3,-5,46:17.0
5,-5,46:18.6
6,-5,46:18.6
8,-5,46:18.6
9,-5,46:18.6
-5,-4,46:18.6
-4,-4,46:18.6
-2,-4,46:18.6
-1,-4,46:18.6
0,-4,46:18.6
1,-4,46:18.6
2,-4,46:18.6
3,-4,46:18.6
4,-4,46:18.6
6,-4,46:18.6
7,-4,46:18.6
8,-4,46:18.6
9,-4,46:18.6
-6,-3,46:18.6
-5,-3,46:18.6
-1,-3,46:18.6
0,-3,46:18.6
2,-3,46:18.6
3,-3,46:18.6
4,-3,46:18.6
5,-3,46:18.6
6,-3,46:18.6
7,-3,46:18.6
8,-3,46:18.6
9,-3,46:18.6
-7,-2,46:18.6
-6,-2,46:18.6
0,-2,46:18.6
1,-2,46:18.6
2,-2,46:18.6
4,-2,46:18.6
5,-2,46:18.6
6,-2,46:18.6
7,-2,46:18.6
10,-2,46:18.6
-8,-1,46:18.6
-7,-1,46:18.6
-2,-1,46:18.6
0,-1,46:18.6
1,-1,46:18.6
2,-1,46:18.6
3,-1,46:18.6
4,-1,46:18.6
10,-1,46:18.6
11,-1,46:18.6
-9,0,46:18.6
-8,0,46:18.6
-2,0,46:18.6
-1,0,46:18.6
0,0,46:18.6
1,0,46:18.6
2,0,46:18.6
3,0,46:18.6
11,0,46:18.6
-10,1,46:18.6
-9,1,46:18.6
-2,1,46:18.6
-1,1,46:18.6
3,1,46:18.6
-10,2,46:18.6
-2,2,46:18.6
4,2,46:18.6
5,2,46:18.6
5,3,46:18.6
6,3,46:18.6
6,4,46:18.6
7,4,46:18.6
8,5,46:18.6
9,6,46:18.6
-2,-13,47:18.6
-1,-12,47:18.6
0,-12,47:18.6
14,-11,47:18.6
15,-11,47:18.6
-4,-10,47:18.6
-3,-10,47:18.6
1,-10,47:18.6
2,-10,47:18.6
5,-10,47:18.6
6,-10,47:18.6
7,-10,47:18.6
13,-10,47:18.6
14,-10,47:18.6
-4,-9,47:18.6
-3,-9,47:18.6
2,-9,47:18.6
3,-9,47:18.6
4,-9,47:18.6
5,-9,47:18.6
12,-9,47:18.6
13,-9,47:18.6
-3,-8,47:18.6
-2,-8,47:18.6
1,-8,47:18.6
2,-8,47:18.6
3,-8,47:18.6
4,-8,47:18.6
5,-8,47:18.6
11,-8,47:18.6
12,-8,47:18.6
-3,-7,47:18.6
-2,-7,47:18.6
-1,-7,47:18.6
0,-7,47:18.6
1,-7,47:18.6
2,-7,47:17.0
3,-7,47:18.6
4,-7,47:18.6
5,-7,47:18.6
6,-7,47:18.6
10,-7,47:18.6
11,-7,47:18.6
-3,-6,47:18.6
-2,-6,47:18.6
-1,-6,47:18.6
0,-6,47:18.6
1,-6,47:17.0
2,-6,47:18.6
3,-6,47:18.6
4,-6,47:18.6
5,-6,47:18.6
6,-6,47:18.6
7,-6,47:18.6
9,-6,47:18.6
10,-6,47:18.6
-4,-5,47:18.6
-3,-5,47:18.6
-2,-5,47:18.6
0,-5,47:18.6
1,-5,47:18.6
2,-5,47:17.0
3,-5,47:17.0
4,-5,47:18.6
5,-5,47:18.6
7,-5,47:18.6
8,-5,47:18.6
9,-5,47:18.6
-5,-4,47:18.6
-4,-4,47:18.6
-2,-4,47:18.6
-1,-4,47:18.6
0,-4,47:18.6
2,-4,47:18.6
3,-4,47:18.6
4,-4,47:18.6
6,-4,47:18.6
7,-4,47:18.6
8,-4,47:18.6
-6,-3,47:18.6
-5,-3,47:18.6
-1,-3,47:18.6
0,-3,47:18.6
2,-3,47:18.6
3,-3,47:18.6
4,-3,47:18.6
5,-3,47:18.6
6,-3,47:18.6
7,-3,47:18.6
8,-3,47:18.6
9,-3,47:18.6
-7,-2,47:18.6
-6,-2,47:18.6
-1,-2,47:18.6
1,-2,47:18.6
2,-2,47:18.6
4,-2,47:18.6
5,-2,47:18.6
6,-2,47:18.6
8,-2,47:18.6
-8,-1,47:18.6
-7,-1,47:18.6
-2,-1,47:18.6
-1,-1,47:18.6
0,-1,47:18.6
1,-1,47:18.6
2,-1,47:18.6
3,-1,47:18.6
4,-1,47:18.6
9,-1,47:18.6
10,-1,47:18.6
-8,0,47:18.6
-2,0,47:18.6
-1,0,47:18.6
0,0,47:18.6
3,0,47:18.6
10,0,47:18.6
-9,1,47:18.6
5,2,47:18.6
6,3,47:18.6
7,4,47:18.6
8,4,47:18.6
8,5,47:18.6
9,5,47:18.6
9,6,47:18.6
-2,-13,48:18.6
-2,-12,48:18.6
-1,-12,48:18.6
-3,-11,48:18.6
14,-11,48:18.6
-3,-10,48:18.6
1,-10,48:18.6
5,-10,48:18.6
6,-10,48:18.6
7,-10,48:18.6
12,-10,48:18.6
13,-10,48:18.6
-3,-9,48:18.6
2,-9,48:18.6
3,-9,48:18.6
4,-9,48:18.6
5,-9,48:18.6
12,-9,48:18.6
-3,-8,48:18.6
-2,-8,48:18.6
1,-8,48:18.6
2,-8,48:18.6
3,-8,48:18.6
4,-8,48:18.6
11,-8,48:18.6
-3,-7,48:18.6
-2,-7,48:18.6
-1,-7,48:18.6
0,-7,48:18.6
1,-7,48:17.0
2,-7,48:17.0
3,-7,48:18.6
4,-7,48:18.6
5,-7,48:18.6
10,-7,48:18.6
-3,-6,48:18.6
-2,-6,48:18.6
-1,-6,48:18.6
0,-6,48:18.6
1,-6,48:18.6
2,-6,48:18.6
3,-6,48:18.6
4,-6,48:18.6
6,-6,48:18.6
7,-6,48:18.6
9,-6,48:18.6
-3,-5,48:18.6
-2,-5,48:18.6
1,-5,48:18.6
2,-5,48:17.0
3,-5,48:18.6
4,-5,48:18.6
5,-5,48:18.6
7,-5,48:18.6
8,-5,48:18.6
-4,-4,48:18.6
-1,-4,48:18.6
0,-4,48:18.6
2,-4,48:18.6
3,-4,48:18.6
4,-4,48:18.6
5,-4,48:18.6
6,-4,48:18.6
7,-4,48:18.6
8,-4,48:18.6
-5,-3,48:18.6
-1,-3,48:18.6
0,-3,48:18.6
1,-3,48:18.6
2,-3,48:18.6
4,-3,48:18.6
5,-3,48:18.6
6,-3,48:18.6
7,-3,48:18.6
8,-3,48:18.6
-6,-2,48:18.6
-1,-2,48:18.6
0,-2,48:18.6
1,-2,48:18.6
2,-2,48:18.6
3,-2,48:18.6
4,-2,48:18.6
8,-2,48:18.6
-7,-1,48:18.6
-2,-1,48:18.6
-1,-1,48:18.6
0,-1,48:18.6
1,-1,48:18.6
2,-1,48:18.6
3,-1,48:18.6
9,-1,48:18.6
10,-1,48:18.6
-8,0,48:18.6
3,0,48:18.6
4,0,48:18.6
9,0,48:18.6
5,1,48:18.6
9,1,48:18.6
10,1,48:18.6
5,2,48:18.6
6,2,48:18.6
10,2,48:18.6
6,3,48:18.6
7,3,48:18.6
7,4,48:18.6
-2,-12,49:18.6
-1,-12,49:18.6
-1,-11,49:18.6
13,-11,49:18.6
-3,-10,49:18.6
0,-10,49:18.6
1,-10,49:18.6
6,-10,49:18.6
7,-10,49:18.6
12,-10,49:18.6
-3,-9,49:18.6
1,-9,49:18.6
2,-9,49:18.6
3,-9,49:18.6
4,-9,49:18.6
5,-9,49:18.6
6,-9,49:18.6
11,-9,49:18.6
12,-9,49:18.6
-3,-8,49:18.6
1,-8,49:18.6
2,-8,49:18.6
3,-8,49:18.6
4,-8,49:18.6
10,-8,49:18.6
11,-8,49:18.6
-3,-7,49:18.6
-1,-7,49:18.6
0,-7,49:18.6
1,-7,49:17.0
2,-7,49:17.0
3,-7,49:18.6
4,-7,49:18.6
5,-7,49:18.6
9,-7,49:18.6
10,-7,49:18.6
-2,-6,49:18.6
-1,-6,49:18.6
0,-6,49:18.6
1,-6,49:18.6
2,-6,49:18.6
3,-6,49:18.6
4,-6,49:18.6
5,-6,49:18.6
6,-6,49:18.6
8,-6,49:18.6
9,-6,49:18.6
-3,-5,49:18.6
-2,-5,49:18.6
-1,-5,49:18.6
1,-5,49:18.6
2,-5,49:18.6
3,-5,49:18.6
4,-5,49:18.6
6,-5,49:18.6
7,-5,49:18.6
-4,-4,49:18.6
-1,-4,49:18.6
0,-4,49:18.6
1,-4,49:18.6
2,-4,49:18.6
3,-4,49:18.6
4,-4,49:18.6
5,-4,49:18.6
6,-4,49:18.6
7,-4,49:18.6
-5,-3,49:18.6
0,-3,49:18.6
1,-3,49:18.6
3,-3,49:18.6
4,-3,49:18.6
5,-3,49:18.6
6,-3,49:18.6
7,-3,49:18.6
8,-3,49:18.6
-6,-2,49:18.6
-1,-2,49:18.6
0,-2,49:18.6
1,-2,49:18.6
2,-2,49:18.6
3,-2,49:18.6
7,-2,49:18.6
8,-2,49:18.6
-7,-1,49:18.6
-2,-1,49:18.6
-1,-1,49:18.6
0,-1,49:18.6
3,-1,49:18.6
8,-1,49:18.6
-8,0,49:18.6
3,0,49:18.6
4,0,49:18.6
8,0,49:18.6
9,0,49:18.6
5,1,49:18.6
9,1,49:18.6
5,2,49:18.6
6,2,49:18.6
9,2,49:18.6
7,3,49:18.6
-2,-12,50:18.6
-1,-11,50:18.6
4,-11,50:18.6
-3,-10,50:18.6
0,-10,50:18.6
1,-10,50:18.6
11,-10,50:18.6
-3,-9,50:18.6
-2,-9,50:18.6
1,-9,50:18.6
2,-9,50:18.6
3,-9,50:18.6
4,-9,50:18.6
5,-9,50:18.6
6,-9,50:18.6
10,-9,50:18.6
11,-9,50:18.6
-3,-8,50:18.6
-2,-8,50:18.6
1,-8,50:18.6
2,-8,50:18.6
3,-8,50:18.6
4,-8,50:18.6
5,-8,50:18.6
9,-8,50:18.6
10,-8,50:18.6
-2,-7,50:18.6
-1,-7,50:18.6
0,-7,50:18.6
1,-7,50:17.0
2,-7,50:17.0
3,-7,50:18.6
4,-7,50:18.6
8,-7,50:18.6
9,-7,50:18.6
-2,-6,50:18.6
-1,-6,50:18.6
0,-6,50:18.6
1,-6,50:18.6
2,-6,50:18.6
3,-6,50:18.6
5,-6,50:18.6
6,-6,50:18.6
7,-6,50:18.6
8,-6,50:18.6
-3,-5,50:18.6
-2,-5,50:18.6
-1,-5,50:18.6
1,-5,50:18.6
2,-5,50:18.6
3,-5,50:18.6
4,-5,50:18.6
5,-5,50:18.6
6,-5,50:18.6
7,-5,50:18.6
-4,-4,50:18.6
-3,-4,50:18.6
0,-4,50:18.6
1,-4,50:18.6
2,-4,50:18.6
4,-4,50:18.6
5,-4,50:18.6
6,-4,50:18.6
-5,-3,50:18.6
-4,-3,50:18.6
0,-3,50:18.6
1,-3,50:18.6
2,-3,50:18.6
3,-3,50:18.6
4,-3,50:18.6
6,-3,50:18.6
7,-3,50:18.6
-6,-2,50:18.6
-5,-2,50:18.6
-2,-2,50:18.6
-1,-2,50:18.6
0,-2,50:18.6
1,-2,50:18.6
2,-2,50:18.6
3,-2,50:18.6
7,-2,50:18.6
-6,-1,50:18.6
3,-1,50:18.6
7,-1,50:18.6
8,-1,50:18.6
4,0,50:18.6
8,0,50:18.6
5,1,50:18.6
8,1,50:18.6
6,2,50:18.6
7,2,50:18.6
7,3,50:18.6
-2,-12,51:18.6
-1,-11,51:18.6
3,-11,51:18.6
4,-11,51:18.6
-2,-10,51:18.6
0,-10,51:18.6
1,-10,51:18.6
2,-10,51:18.6
3,-10,51:18.6
10,-10,51:18.6
-2,-9,51:18.6
1,-9,51:18.6
5,-9,51:18.6
6,-9,51:18.6
9,-9,51:18.6
10,-9,51:18.6
-2,-8,51:18.6
1,-8,51:18.6
2,-8,51:18.6
3,-8,51:18.6
4,-8,51:18.6
8,-8,51:18.6
9,-8,51:18.6
-2,-7,51:18.6
0,-7,51:18.6
1,-7,51:17.0
2,-7,51:17.0
3,-7,51:18.6
4,-7,51:18.6
7,-7,51:18.6
8,-7,51:18.6
-2,-6,51:18.6
-1,-6,51:18.6
0,-6,51:18.6
1,-6,51:17.0
2,-6,51:17.0
3,-6,51:18.6
4,-6,51:18.6
5,-6,51:18.6
6,-6,51:18.6
7,-6,51:18.6
-3,-5,51:18.6
-2,-5,51:18.6
-1,-5,51:18.6
0,-5,51:18.6
2,-5,51:18.6
3,-5,51:18.6
4,-5,51:18.6
5,-5,51:18.6
6,-5,51:18.6
-4,-4,51:18.6
-3,-4,51:18.6
0,-4,51:18.6
1,-4,51:18.6
3,-4,51:18.6
4,-4,51:18.6
5,-4,51:18.6
6,-4,51:18.6
-5,-3,51:18.6
-4,-3,51:18.6
-1,-3,51:18.6
0,-3,51:18.6
1,-3,51:18.6
2,-3,51:18.6
3,-3,51:18.6
5,-3,51:18.6
6,-3,51:18.6
-6,-2,51:18.6
-5,-2,51:18.6
-2,-2,51:18.6
-1,-2,51:18.6
0,-2,51:18.6
2,-2,51:18.6
3,-2,51:18.6
6,-2,51:18.6
7,-2,51:18.6
3,-1,51:18.6
4,-1,51:18.6
7,-1,51:18.6
4,0,51:18.6
5,0,51:18.6
7,0,51:18.6
5,1,51:18.6
6,1,51:18.6
6,2,51:18.6
7,-14,52:18.6
6,-13,52:18.6
-3,-11,52:18.6
-2,-11,52:18.6
-1,-11,52:18.6
3,-11,52:18.6
-1,-10,52:18.6
0,-10,52:18.6
1,-10,52:18.6
2,-10,52:18.6
-2,-9,52:18.6
0,-9,52:18.6
1,-9,52:18.6
3,-9,52:18.6
5,-9,52:18.6
6,-9,52:18.6
9,-9,52:18.6
-2,-8,52:18.6
0,-8,52:18.6
1,-8,52:18.6
2,-8,52:18.6
3,-8,52:18.6
4,-8,52:18.6
8,-8,52:18.6
-2,-7,52:18.6
-1,-7,52:18.6
0,-7,52:18.6
1,-7,52:17.0
2,-7,52:17.0
3,-7,52:18.6
4,-7,52:18.6
6,-7,52:18.6
7,-7,52:18.6
-1,-6,52:18.6
0,-6,52:18.6
1,-6,52:17.0
2,-6,52:17.0
4,-6,52:18.6
5,-6,52:18.6
6,-6,52:18.6
-3,-5,52:18.6
-2,-5,52:18.6
0,-5,52:18.6
4,-5,52:18.6
5,-5,52:18.6
-4,-4,52:18.6
-3,-4,52:18.6
1,-4,52:18.6
2,-4,52:18.6
3,-4,52:18.6
5,-4,52:18.6
-5,-3,52:18.6
-4,-3,52:18.6
-2,-3,52:18.6
-1,-3,52:18.6
0,-3,52:18.6
1,-3,52:18.6
2,-3,52:18.6
5,-3,52:18.6
6,-3,52:18.6
-5,-2,52:18.6
3,-2,52:18.6
5,-2,52:18.6
6,-2,52:18.6
4,-1,52:18.6
6,-1,52:18.6
5,0,52:18.6
6,1,52:18.6
-1,2,52:18.6
5,-13,53:18.6
6,-13,53:18.6
4,-12,53:18.6
5,-12,53:18.6
-3,-11,53:18.6
-2,-11,53:18.6
-1,-11,53:18.6
3,-11,53:18.6
4,-11,53:18.6
-2,-10,53:18.6
-1,-10,53:18.6
0,-10,53:18.6
1,-10,53:18.6
2,-10,53:18.6
-2,-9,53:18.6
0,-9,53:18.6
1,-9,53:18.6
2,-9,53:18.6
3,-9,53:18.6
8,-9,53:18.6
9,-9,53:18.6
-2,-8,53:18.6
0,-8,53:18.6
1,-8,53:18.6
2,-8,53:18.6
3,-8,53:18.6
4,-8,53:18.6
5,-8,53:18.6
8,-8,53:18.6
-5,-7,53:18.6
-2,-7,53:18.6
-1,-7,53:18.6
0,-7,53:17.0
1,-7,53:18.6
2,-7,53:17.0
3,-7,53:18.6
5,-7,53:18.6
6,-7,53:18.6
7,-7,53:18.6
-4,-6,53:18.6
-1,-6,53:18.6
0,-6,53:18.6
1,-6,53:17.0
2,-6,53:17.0
4,-6,53:18.6
5,-6,53:18.6
6,-6,53:18.6
-2,-5,53:18.6
-1,-5,53:18.6
0,-5,53:18.6
1,-5,53:18.6
3,-5,53:18.6
4,-5,53:18.6
5,-5,53:18.6
-3,-4,53:18.6
-2,-4,53:18.6
-1,-4,53:18.6
0,-4,53:18.6
1,-4,53:18.6
2,-4,53:18.6
3,-4,53:18.6
4,-4,53:18.6
5,-4,53:18.6
-4,-3,53:18.6
-1,-3,53:18.6
2,-3,53:18.6
3,-3,53:18.6
4,-3,53:18.6
5,-3,53:18.6
0,-2,53:18.6
3,-2,53:18.6
4,-2,53:18.6
5,-2,53:18.6
2,-1,53:18.6
4,-1,53:18.6
0,0,53:18.6
1,0,53:18.6
2,0,53:18.6
3,0,53:18.6
5,0,53:18.6
6,0,53:18.6
0,1,53:18.6
6,1,53:18.6
5,-13,54:18.6
6,-13,54:18.6
4,-12,54:18.6
5,-12,54:18.6
-2,-11,54:18.6
3,-11,54:18.6
4,-11,54:18.6
-7,-10,54:18.6
-1,-10,54:18.6
0,-10,54:18.6
1,-10,54:18.6
2,-10,54:18.6
8,-10,54:18.6
-1,-9,54:18.6
0,-9,54:18.6
1,-9,54:18.6
2,-9,54:18.6
3,-9,54:18.6
7,-9,54:18.6
8,-9,54:18.6
0,-8,54:18.6
1,-8,54:18.6
2,-8,54:18.6
3,-8,54:18.6
4,-8,54:18.6
6,-8,54:18.6
7,-8,54:18.6
-5,-7,54:18.6
-4,-7,54:18.6
-2,-7,54:18.6
-1,-7,54:18.6
0,-7,54:17.0
1,-7,54:18.6
2,-7,54:18.6
3,-7,54:18.6
4,-7,54:18.6
5,-7,54:18.6
6,-7,54:18.6
7,-7,54:18.6
-4,-6,54:18.6
-1,-6,54:18.6
0,-6,54:18.6
1,-6,54:17.0
2,-6,54:17.0
3,-6,54:18.6
4,-6,54:18.6
5,-6,54:18.6
7,-6,54:18.6
-4,-5,54:18.6
-3,-5,54:18.6
-2,-5,54:18.6
-1,-5,54:18.6
0,-5,54:18.6
1,-5,54:18.6
2,-5,54:18.6
3,-5,54:18.6
4,-5,54:18.6
-4,-4,54:18.6
-3,-4,54:18.6
-2,-4,54:18.6
-1,-4,54:18.6
0,-4,54:18.6
1,-4,54:18.6
2,-4,54:18.6
3,-4,54:18.6
4,-4,54:18.6
5,-4,54:18.6
-4,-3,54:18.6
-1,-3,54:18.6
0,-3,54:18.6
3,-3,54:18.6
4,-3,54:18.6
0,-2,54:18.6
2,-2,54:18.6
3,-2,54:18.6
4,-2,54:18.6
1,-1,54:18.6
2,-1,54:18.6
4,-1,54:18.6
0,0,54:18.6
1,0,54:18.6
3,0,54:18.6
5,0,54:18.6
6,0,54:18.6
4,-12,55:18.6
5,-12,55:18.6
-2,-11,55:18.6
3,-11,55:18.6
-7,-10,55:18.6
-6,-10,55:18.6
-1,-10,55:18.6
0,-10,55:18.6
1,-10,55:18.6
2,-10,55:18.6
-6,-9,55:18.6
0,-9,55:18.6
1,-9,55:18.6
2,-9,55:18.6
3,-9,55:18.6
-5,-8,55:18.6
0,-8,55:18.6
1,-8,55:18.6
3,-8,55:18.6
4,-8,55:18.6
5,-8,55:18.6
6,-8,55:18.6
-4,-7,55:18.6
-2,-7,55:18.6
0,-7,55:18.6
1,-7,55:18.6
2,-7,55:18.6
3,-7,55:18.6
4,-7,55:18.6
5,-7,55:18.6
6,-7,55:18.6
7,-7,55:18.6
-4,-6,55:18.6
-3,-6,55:18.6
-1,-6,55:18.6
0,-6,55:18.6
1,-6,55:18.6
2,-6,55:18.6
3,-6,55:18.6
4,-6,55:18.6
6,-6,55:18.6
-3,-5,55:18.6
-2,-5,55:18.6
-1,-5,55:18.6
0,-5,55:18.6
1,-5,55:18.6
2,-5,55:18.6
3,-5,55:18.6
5,-5,55:18.6
7,-5,55:18.6
-4,-4,55:18.6
-3,-4,55:18.6
-2,-4,55:18.6
-1,-4,55:18.6
2,-4,55:18.6
3,-4,55:18.6
4,-4,55:18.6
5,-4,55:18.6
8,-4,55:18.6
-1,-3,55:18.6
0,-3,55:18.6
3,-3,55:18.6
4,-3,55:18.6
0,-2,55:18.6
1,-2,55:18.6
2,-2,55:18.6
4,-2,55:18.6
0,-1,55:18.6
1,-1,55:18.6
2,-1,55:18.6
3,-1,55:18.6
4,-1,55:18.6
-1,0,55:18.6
0,0,55:18.6
4,0,55:18.6
6,0,55:18.6
-2,1,55:18.6
-3,2,55:18.6
5,-13,56:18.6
4,-12,56:18.6
-3,-11,56:18.6
-2,-11,56:18.6
3,-11,56:18.6
7,-11,56:18.6
-6,-10,56:18.6
-1,-10,56:18.6
0,-10,56:18.6
1,-10,56:18.6
2,-10,56:18.6
6,-10,56:18.6
7,-10,56:18.6
-6,-9,56:18.6
-5,-9,56:18.6
-1,-9,56:18.6
0,-9,56:18.6
1,-9,56:18.6
2,-9,56:18.6
6,-9,56:18.6
-5,-8,56:18.6
-4,-8,56:18.6
0,-8,56:18.6
1,-8,56:17.0
3,-8,56:18.6
4,-8,56:18.6
5,-8,56:18.6
6,-8,56:18.6
-4,-7,56:18.6
-2,-7,56:18.6
0,-7,56:18.6
1,-7,56:18.6
2,-7,56:18.6
3,-7,56:18.6
4,-7,56:18.6
5,-7,56:18.6
6,-7,56:18.6
-3,-6,56:18.6
0,-6,56:18.6
1,-6,56:18.6
2,-6,56:18.6
3,-6,56:18.6
5,-6,56:18.6
6,-6,56:18.6
-3,-5,56:18.6
-2,-5,56:18.6
-1,-5,56:18.6
0,-5,56:18.6
1,-5,56:18.6
2,-5,56:18.6
3,-5,56:18.6
4,-5,56:18.6
5,-5,56:18.6
6,-5,56:18.6
7,-5,56:18.6
-1,-4,56:18.6
2,-4,56:18.6
3,-4,56:18.6
4,-4,56:18.6
0,-3,56:18.6
2,-3,56:18.6
3,-3,56:18.6
1,-2,56:18.6
2,-2,56:18.6
-1,-1,56:18.6
0,-1,56:18.6
2,-1,56:18.6
3,-1,56:18.6
4,-1,56:18.6
-2,0,56:18.6
-1,0,56:18.6
5,0,56:18.6
6,0,56:18.6
-3,1,56:18.6
-2,1,56:18.6
-3,2,56:18.6
4,-12,57:18.6
3,-11,57:18.6
6,-11,57:18.6
-6,-10,57:18.6
-2,-10,57:18.6
-1,-10,57:18.6
0,-10,57:18.6
1,-10,57:18.6
2,-10,57:18.6
6,-10,57:18.6
-5,-9,57:18.6
0,-9,57:18.6
1,-9,57:18.6
2,-9,57:18.6
6,-9,57:18.6
-5,-8,57:18.6
-4,-8,57:18.6
0,-8,57:18.6
1,-8,57:17.0
3,-8,57:18.6
4,-8,57:18.6
6,-8,57:18.6
-4,-7,57:18.6
-3,-7,57:18.6
-2,-7,57:18.6
0,-7,57:17.0
1,-7,57:18.6
2,-7,57:18.6
3,-7,57:18.6
4,-7,57:18.6
5,-7,57:18.6
6,-7,57:18.6
-3,-6,57:18.6
-2,-6,57:18.6
-1,-6,57:18.6
0,-6,57:18.6
1,-6,57:18.6
2,-6,57:18.6
5,-6,57:18.6
6,-6,57:18.6
-3,-5,57:18.6
-2,-5,57:18.6
-1,-5,57:18.6
2,-5,57:18.6
3,-5,57:18.6
4,-5,57:18.6
6,-5,57:18.6
7,-5,57:18.6
-3,-4,57:18.6
-2,-4,57:18.6
-1,-4,57:18.6
0,-4,57:18.6
2,-4,57:18.6
3,-4,57:18.6
8,-4,57:18.6
-4,-3,57:18.6
0,-3,57:18.6
1,-3,57:18.6
2,-3,57:18.6
-4,-2,57:18.6
0,-2,57:18.6
1,-2,57:18.6
2,-2,57:18.6
3,-2,57:18.6
-1,-1,57:18.6
0,-1,57:18.6
3,-1,57:18.6
4,-1,57:18.6
-2,0,57:18.6
-3,1,57:18.6
2,-11,58:18.6
3,-11,58:18.6
-6,-10,58:18.6
-1,-10,58:18.6
0,-10,58:18.6
1,-10,58:18.6
2,-10,58:18.6
6,-10,58:18.6
-5,-9,58:18.6
0,-9,58:18.6
1,-9,58:18.6
2,-9,58:18.6
5,-9,58:18.6
6,-9,58:18.6
-4,-8,58:18.6
0,-8,58:17.0
1,-8,58:17.0
3,-8,58:18.6
5,-8,58:18.6
-3,-7,58:18.6
-2,-7,58:18.6
0,-7,58:17.0
1,-7,58:17.0
2,-7,58:18.6
4,-7,58:18.6
5,-7,58:18.6
-3,-6,58:18.6
-2,-6,58:18.6
1,-6,58:18.6
4,-6,58:18.6
5,-6,58:18.6
6,-6,58:18.6
-3,-5,58:18.6
-2,-5,58:18.6
-1,-5,58:18.6
1,-5,58:18.6
3,-5,58:18.6
4,-5,58:18.6
6,-5,58:18.6
7,-5,58:18.6
-3,-4,58:18.6
-1,-4,58:18.6
0,-4,58:18.6
1,-4,58:18.6
2,-4,58:18.6
3,-4,58:18.6
7,-4,58:18.6
8,-4,58:18.6
-3,-3,58:18.6
0,-3,58:18.6
1,-3,58:18.6
2,-3,58:18.6
8,-3,58:18.6
9,-3,58:18.6
-4,-2,58:18.6
-1,-2,58:18.6
0,-2,58:18.6
2,-2,58:18.6
3,-2,58:18.6
4,-2,58:18.6
-2,-1,58:18.6
-1,-1,58:18.6
-3,0,58:18.6
2,-11,59:18.6
3,-11,59:18.6
5,-11,59:18.6
-5,-10,59:18.6
-1,-10,59:18.6
0,-10,59:18.6
1,-10,59:18.6
2,-10,59:18.6
5,-10,59:18.6
-5,-9,59:18.6
-4,-9,59:18.6
0,-9,59:18.6
1,-9,59:18.6
2,-9,59:18.6
5,-9,59:18.6
-4,-8,59:18.6
-3,-8,59:18.6
-2,-8,59:18.6
0,-8,59:17.0
1,-8,59:17.0
2,-8,59:18.6
3,-8,59:18.6
5,-8,59:18.6
-3,-7,59:18.6
-2,-7,59:18.6
0,-7,59:17.0
1,-7,59:17.0
4,-7,59:18.6
5,-7,59:18.6
-3,-6,59:18.6
-2,-6,59:18.6
3,-6,59:18.6
4,-6,59:18.6
5,-6,59:18.6
-3,-5,59:18.6
-1,-5,59:18.6
2,-5,59:18.6
3,-5,59:18.6
6,-5,59:18.6
-3,-4,59:18.6
0,-4,59:18.6
1,-4,59:18.6
2,-4,59:18.6
7,-4,59:18.6
-3,-3,59:18.6
0,-3,59:18.6
1,-3,59:18.6
2,-3,59:18.6
3,-3,59:18.6
8,-3,59:18.6
-2,-2,59:18.6
-1,-2,59:18.6
3,-2,59:18.6
4,-2,59:18.6
5,-2,59:18.6
-2,-1,59:18.6
2,-11,60:18.6
3,-11,60:18.6
-1,-10,60:18.6
0,-10,60:18.6
1,-10,60:18.6
2,-10,60:18.6
5,-10,60:18.6
-4,-9,60:18.6
0,-9,60:18.6
1,-9,60:18.6
2,-9,60:18.6
4,-9,60:18.6
-4,-8,60:18.6
-3,-8,60:18.6
-2,-8,60:18.6
0,-8,60:17.0
1,-8,60:17.0
2,-8,60:18.6
3,-8,60:18.6
4,-8,60:18.6
-3,-7,60:18.6
-2,-7,60:18.6
0,-7,60:17.0
1,-7,60:17.0
4,-7,60:18.6
-3,-6,60:18.6
-2,-6,60:18.6
-1,-6,60:18.6
3,-6,60:18.6
4,-6,60:18.6
5,-6,60:18.6
-3,-5,60:18.6
-1,-5,60:18.6
0,-5,60:18.6
1,-5,60:18.6
2,-5,60:18.6
6,-5,60:18.6
-3,-4,60:18.6
0,-4,60:18.6
1,-4,60:18.6
2,-4,60:18.6
7,-4,60:18.6
-3,-3,60:18.6
-1,-3,60:18.6
0,-3,60:18.6
2,-3,60:18.6
3,-3,60:18.6
-2,-2,60:18.6
-1,-2,60:18.6
2,-11,61:18.6
-1,-10,61:18.6
0,-10,61:18.6
1,-10,61:18.6
2,-10,61:18.6
-4,-9,61:18.6
-1,-9,61:18.6
0,-9,61:18.6
1,-9,61:18.6
2,-9,61:18.6
4,-9,61:18.6
-3,-8,61:18.6
-2,-8,61:18.6
0,-8,61:17.0
1,-8,61:17.0
2,-8,61:18.6
3,-8,61:18.6
4,-8,61:18.6
-2,-7,61:18.6
0,-7,61:17.0
1,-7,61:17.0
3,-7,61:18.6
4,-7,61:18.6
-3,-6,61:18.6
-2,-6,61:18.6
-1,-6,61:18.6
2,-6,61:18.6
3,-6,61:18.6
4,-6,61:18.6
5,-6,61:18.6
-3,-5,61:18.6
0,-5,61:18.6
1,-5,61:18.6
2,-5,61:18.6
5,-5,61:18.6
6,-5,61:18.6
0,-4,61:18.6
1,-4,61:18.6
2,-4,61:18.6
6,-4,61:18.6
7,-4,61:18.6
-2,-3,61:18.6
-1,-3,61:18.6
7,-3,61:18.6
2,-11,62:18.6
-1,-10,62:18.6
0,-10,62:18.6
1,-10,62:18.6
-4,-9,62:18.6
-3,-9,62:18.6
-1,-9,62:18.6
0,-9,62:18.6
1,-9,62:18.6
2,-9,62:18.6
3,-9,62:18.6
4,-9,62:18.6
-3,-8,62:18.6
-2,-8,62:18.6
0,-8,62:17.0
1,-8,62:17.0
2,-8,62:18.6
3,-8,62:18.6
-2,-7,62:18.6
-1,-7,62:18.6
2,-7,62:18.6
3,-7,62:18.6
4,-7,62:18.6
-2,-6,62:18.6
-1,-6,62:18.6
0,-6,62:18.6
1,-6,62:18.6
2,-6,62:18.6
4,-6,62:18.6
5,-6,62:18.6
-3,-5,62:18.6
0,-5,62:18.6
1,-5,62:18.6
5,-5,62:18.6
6,-5,62:18.6
-1,-4,62:18.6
0,-4,62:18.6
2,-4,62:18.6
3,-4,62:18.6
-2,-3,62:18.6
2,-11,63:18.6
-1,-10,63:18.6
0,-10,63:18.6
1,-10,63:18.6
-3,-9,63:18.6
-1,-9,63:18.6
0,-9,63:18.6
1,-9,63:18.6
3,-9,63:18.6
-3,-8,63:18.6
-2,-8,63:18.6
0,-8,63:17.0
1,-8,63:17.0
2,-8,63:18.6
3,-8,63:18.6
-2,-7,63:18.6
-1,-7,63:18.6
2,-7,63:18.6
3,-7,63:18.6
4,-7,63:18.6
-2,-6,63:18.6
-1,-6,63:18.6
0,-6,63:18.6
1,-6,63:18.6
4,-6,63:18.6
5,-6,63:18.6
-1,-5,63:18.6
0,-5,63:18.6
1,-5,63:18.6
2,-5,63:18.6
-2,-4,63:18.6
-1,-4,63:18.6
-1,-10,64:18.6
0,-10,64:18.6
1,-10,64:18.6
-3,-9,64:18.6
-1,-9,64:18.6
0,-9,64:18.6
1,-9,64:18.6
2,-9,64:18.6
3,-9,64:18.6
-2,-8,64:18.6
0,-8,64:17.0
1,-8,64:17.0
2,-8,64:18.6
3,-8,64:18.6
-2,-7,64:18.6
-1,-7,64:18.6
1,-7,64:18.6
2,-7,64:18.6
3,-7,64:18.6
-2,-6,64:18.6
0,-6,64:18.6
1,-6,64:18.6
4,-6,64:18.6
-1,-5,64:18.6
0,-5,64:18.6
1,-5,64:18.6
2,-5,64:18.6
-1,-10,65:18.6
0,-10,65:18.6
1,-10,65:18.6
-1,-9,65:18.6
0,-9,65:17.0
1,-9,65:18.6
2,-9,65:18.6
-2,-8,65:18.6
0,-8,65:17.0
1,-8,65:18.6
2,-8,65:18.6
-2,-7,65:18.6
-1,-7,65:18.6
0,-7,65:18.6
1,-7,65:18.6
3,-7,65:18.6
-1,-6,65:18.6
0,-6,65:18.6
1,-6,65:18.6
0,-10,66:18.6
2,-10,66:18.6
-2,-9,66:18.6
-1,-9,66:18.6
0,-9,66:17.0
1,-9,66:18.6
2,-9,66:18.6
-2,-8,66:18.6
0,-8,66:17.0
1,-8,66:18.6
2,-8,66:18.6
-2,-7,66:18.6
-1,-7,66:18.6
0,-7,66:18.6
1,-7,66:18.6
-1,-6,66:18.6
1,-6,66:18.6
-2,-9,67:18.6
-1,-9,67:18.6
0,-9,67:17.0
1,-9,67:18.6
0,-8,67:18.6
1,-8,67:18.6
2,-8,67:18.6
0,-7,67:18.6
2,-7,67:18.6
-1,-9,68:18.6
0,-9,68:18.6
1,-9,68:18.6
0,-8,68:18.6
-1,-9,69:18.6
0,-9,69:18.6
0,-8,69:18.6
-1,-9,70:18.6
0,-9,70:18.6
-1,-9,71:17.0
0,-9,71:17.0
-1,-10,72:17.0
-1,-9,72:17.0
-1,-10,73:17.0
-1,-9,73:17.0
-1,-10,74:17.0
-1,-10,75:17.0
