[META]
version=2.0
spawnOnBlockType=2
spawnSunlight=True
spawnDarkness=True
spawnWater=False
spawnLava=False
underFill=False
randomRotation=True
dig=True
tree=False
branch=False
needsFoundation=True
rarity=100
collisionPercentage=20
spawnElevationMin=0
spawnElevationMax=200
spawnInBiome=Custom
[DATA]
-1,-5,-7:17.12
-2,-4,-7:17.12
-1,-4,-7:17.12
-2,-3,-7:17.12
-1,-3,-7:17.12
1,-2,-7:17.12
2,-2,-7:17.12
1,-1,-7:17.12
2,-1,-7:17.12
3,-1,-7:17.12
2,0,-7:17.12
-2,-6,-6:17.12
-1,-6,-6:17.12
-4,-5,-6:17.12
-3,-5,-6:17.12
-3,-4,-6:17.12
-2,-4,-6:17.12
-1,-4,-6:17.12
0,-4,-6:17.12
-4,-3,-6:17.12
-2,-3,-6:17.12
0,-3,-6:17.12
1,-3,-6:17.12
-3,-2,-6:17.12
-1,-2,-6:17.12
3,-2,-6:17.12
1,-1,-6:17.12
2,-1,-6:17.12
3,0,-6:17.12
2,1,-6:17.12
-1,-6,-5:17.12
-4,-5,-5:17.12
-2,-5,-5:17.12
-1,-5,-5:17.12
0,-5,-5:17.12
-4,-4,-5:17.12
-3,-4,-5:17.12
-2,-4,-5:17.12
-1,-4,-5:17.12
0,-4,-5:17.12
1,-4,-5:17.12
-3,-3,-5:17.12
-2,-3,-5:17.12
0,-3,-5:17.12
1,-3,-5:17.12
2,-3,-5:17.12
1,-2,-5:17.12
2,-2,-5:17.12
3,-2,-5:17.12
4,-2,-5:17.12
0,-1,-5:17.12
1,-1,-5:17.12
2,-1,-5:17.12
3,-1,-5:17.12
1,0,-5:17.12
3,0,-5:17.12
2,1,-5:17.12
-4,-5,-4:17.12
-3,-5,-4:17.12
-2,-5,-4:17.12
-1,-5,-4:17.12
2,-5,-4:17.12
-2,-4,-4:17.12
-1,-4,-4:17.12
0,-4,-4:17.12
1,-4,-4:17.12
2,-4,-4:17.12
3,-4,-4:17.12
-4,-3,-4:17.12
-2,-3,-4:17.12
-1,-3,-4:17.12
1,-3,-4:17.12
2,-3,-4:17.12
3,-3,-4:17.12
0,-2,-4:17.12
1,-2,-4:17.12
2,-2,-4:17.12
3,-2,-4:17.12
4,-2,-4:17.12
0,-1,-4:17.12
1,-1,-4:17.12
2,-1,-4:17.12
3,-1,-4:17.12
2,0,-4:17.12
4,0,-4:17.12
1,1,-4:17.12
2,1,-4:17.12
3,1,-4:17.12
-1,-6,-3:17.12
-3,-5,-3:17.12
-2,-5,-3:17.12
-1,-5,-3:17.12
0,-5,-3:17.12
1,-5,-3:17.12
2,-5,-3:17.12
-3,-4,-3:17.12
-2,-4,-3:17.12
-1,-4,-3:17.12
0,-4,-3:17.12
1,-4,-3:17.12
2,-4,-3:17.12
-3,-3,-3:17.12
-1,-3,-3:17.12
0,-3,-3:17.12
1,-3,-3:17.12
2,-3,-3:17.12
3,-3,-3:17.12
-1,-2,-3:17.12
1,-2,-3:17.12
2,-2,-3:17.12
0,-1,-3:17.12
1,-1,-3:17.12
2,-1,-3:17.12
0,0,-3:17.12
2,0,-3:17.12
4,0,-3:17.12
2,1,-3:17.12
-3,-5,-2:17.12
-1,-5,-2:17.12
0,-5,-2:17.12
1,-5,-2:17.12
2,-5,-2:17.12
-1,-4,-2:17.12
0,-4,-2:17.12
-3,-3,-2:17.12
-2,-3,-2:17.12
-1,-3,-2:17.12
0,-3,-2:17.12
1,-3,-2:17.12
2,-3,-2:17.12
3,-3,-2:17.12
4,-3,-2:17.12
-2,-2,-2:17.12
-1,-2,-2:17.12
1,-2,-2:17.12
3,-2,-2:17.12
4,-2,-2:17.12
-1,-1,-2:17.12
0,-1,-2:17.12
1,-1,-2:17.12
2,-1,-2:17.12
4,-1,-2:17.12
0,0,-2:17.12
1,0,-2:17.12
2,1,-2:17.12
3,1,-2:17.12
-2,-5,-1:17.12
-1,-5,-1:17.12
-3,-4,-1:17.12
0,-4,-1:17.12
1,-4,-1:17.12
2,-4,-1:17.12
3,-4,-1:17.12
-2,-3,-1:17.12
0,-3,-1:17.12
1,-3,-1:17.12
2,-3,-1:17.12
3,-3,-1:17.12
4,-3,-1:17.12
-2,-2,-1:17.12
0,-2,-1:17.12
1,-2,-1:17.12
4,-2,-1:17.12
5,-2,-1:17.12
-1,-1,-1:17.12
0,-1,-1:17.12
1,-1,-1:17.12
2,-1,-1:17.12
3,-1,-1:17.12
4,-1,-1:17.12
5,-1,-1:17.12
-1,0,-1:17.12
0,0,-1:17.12
1,0,-1:17.12
2,0,-1:17.12
4,0,-1:17.12
0,1,-1:17.12
1,1,-1:17.12
2,1,-1:17.12
3,1,-1:17.12
4,1,-1:17.12
1,2,-1:17.12
2,2,-1:17.12
-3,-5,0:17.12
-2,-5,0:17.12
-1,-5,0:17.12
0,-5,0:17.12
-3,-4,0:17.12
0,-4,0:17.12
2,-4,0:17.12
3,-4,0:17.12
-3,-3,0:17.12
-2,-3,0:17.12
-1,-3,0:17.12
0,-3,0:17.12
1,-3,0:17.12
2,-3,0:17.12
3,-3,0:17.12
4,-3,0:17.12
-2,-2,0:17.12
-1,-2,0:17.12
0,-2,0:17.12
4,-2,0:17.12
0,-1,0:17.12
4,-1,0:17.12
0,0,0:17.12
1,0,0:17.12
4,0,0:17.12
1,1,0:17.12
2,1,0:17.12
3,1,0:17.12
-2,-5,1:17.12
-1,-5,1:17.12
-3,-4,1:17.12
-2,-4,1:17.12
0,-4,1:17.12
-2,-3,1:17.12
-1,-3,1:17.12
0,-3,1:17.12
1,-3,1:17.12
2,-3,1:17.12
3,-3,1:17.12
0,-2,1:17.12
4,-2,1:17.12
5,-2,1:18.12
-2,-1,1:18.14
0,-1,1:17.12
4,-1,1:17.12
-1,0,1:18.14
0,0,1:18.14
1,0,1:17.12
2,0,1:18.14
3,0,1:18.14
4,0,1:18.14
-2,1,1:18.14
-1,1,1:18.14
0,1,1:18.14
1,1,1:18.14
2,1,1:17.12
3,1,1:18.14
4,1,1:18.14
-1,2,1:18.14
3,2,1:18.14
-2,-5,2:17.12
-1,-5,2:17.12
-2,-4,2:17.12
-1,-4,2:17.12
-2,-3,2:17.12
-1,-3,2:18.14
1,-3,2:17.12
2,-3,2:17.12
3,-3,2:17.12
-2,-2,2:18.14
-1,-2,2:18.14
0,-2,2:18.14
1,-2,2:17.12
3,-2,2:17.12
4,-2,2:17.12
-1,-1,2:18.14
0,-1,2:17.12
1,-1,2:17.12
4,-1,2:17.12
-2,0,2:18.14
-1,0,2:18.14
0,0,2:18.14
1,0,2:17.12
2,0,2:17.12
3,0,2:17.12
4,0,2:18.14
-2,1,2:18.14
-1,1,2:18.14
0,1,2:18.14
3,1,2:18.14
4,1,2:18.14
-2,-5,3:17.12
-1,-5,3:17.12
-2,-4,3:17.12
-1,-4,3:17.12
-2,-3,3:17.12
1,-3,3:17.12
2,-3,3:17.12
3,-3,3:17.12
-2,-2,3:18.14
1,-2,3:17.12
3,-2,3:17.12
4,-2,3:17.12
-1,-1,3:18.14
0,-1,3:17.12
1,-1,3:17.12
3,-1,3:17.12
4,-1,3:17.12
1,0,3:17.12
2,0,3:17.12
3,0,3:17.12
-2,-5,4:17.12
-1,-5,4:17.12
-2,-4,4:17.12
-1,-4,4:17.12
1,-3,4:17.12
2,-3,4:17.12
3,-3,4:17.12
1,-2,4:17.12
3,-2,4:17.12
4,-2,4:17.12
1,-1,4:17.12
3,-1,4:17.12
1,0,4:17.12
2,0,4:17.12
3,0,4:17.12
-2,-5,5:17.12
-1,-5,5:17.12
-2,-4,5:17.12
-1,-4,5:17.12
1,-3,5:17.12
2,-3,5:17.12
3,-3,5:17.12
1,-2,5:17.12
3,-2,5:17.12
1,-1,5:17.12
3,-1,5:17.12
2,0,5:17.12
-2,-5,6:17.12
-1,-5,6:17.12
-2,-4,6:17.12
-1,-4,6:17.12
1,-3,6:17.12
2,-3,6:17.12
3,-3,6:17.12
1,-2,6:17.12
3,-2,6:17.12
1,-1,6:17.12
2,-1,6:17.12
3,-1,6:17.12
2,0,6:17.12
1,-12,7:18.5
1,-11,7:18.5
-2,-5,7:17.12
-1,-5,7:17.12
-2,-4,7:17.12
-1,-4,7:17.12
1,-3,7:17.12
2,-3,7:17.12
3,-3,7:17.12
1,-2,7:17.12
3,-2,7:17.12
1,-1,7:17.12
2,-1,7:17.12
3,-1,7:17.12
1,-12,8:18.5
1,-11,8:18.5
1,-10,8:18.5
0,-9,8:18.13
0,-8,8:18.13
-8,-7,8:18.5
-2,-5,8:17.12
-1,-5,8:17.12
-2,-4,8:17.12
-1,-4,8:17.12
1,-3,8:17.12
2,-3,8:17.12
3,-3,8:17.12
1,-2,8:17.12
3,-2,8:17.12
1,-1,8:17.12
2,-1,8:17.12
3,-1,8:17.12
-4,3,8:18.5
1,-12,9:18.5
1,-11,9:18.5
1,-10,9:18.5
0,-9,9:18.13
0,-8,9:18.13
-8,-7,9:18.5
-7,-7,9:18.5
-6,-7,9:18.13
0,-7,9:18.13
-6,-6,9:18.13
-5,-6,9:18.13
-4,-6,9:18.13
-3,-6,9:18.13
-2,-6,9:18.13
-1,-6,9:18.13
0,-6,9:18.13
-3,-5,9:18.13
-2,-5,9:17.12
-1,-5,9:17.12
0,-5,9:18.13
-3,-4,9:18.13
-2,-4,9:17.12
-1,-4,9:17.12
0,-4,9:18.13
1,-4,9:18.13
-2,-3,9:18.13
-1,-3,9:18.13
0,-3,9:18.13
1,-3,9:18.13
2,-3,9:17.12
3,-3,9:17.12
-2,-2,9:18.13
1,-2,9:17.12
3,-2,9:17.12
4,-2,9:18.13
5,-2,9:18.13
1,-1,9:17.12
2,-1,9:17.12
3,-1,9:17.12
-3,0,9:18.13
-3,1,9:18.13
-3,2,9:18.13
1,-11,10:18.5
1,-10,10:18.5
0,-9,10:18.13
0,-8,10:18.13
-8,-7,10:18.5
-7,-7,10:18.5
-6,-7,10:18.13
0,-7,10:18.13
-6,-6,10:18.13
-5,-6,10:18.13
-4,-6,10:18.13
-3,-6,10:18.13
-2,-6,10:18.13
-1,-6,10:18.13
0,-6,10:18.13
-3,-5,10:18.13
-2,-5,10:18.13
-1,-5,10:18.13
0,-5,10:18.13
-2,-4,10:18.13
-1,-4,10:18.13
0,-4,10:18.13
1,-4,10:18.13
-2,-3,10:18.13
-1,-3,10:18.13
1,-3,10:17.12
2,-3,10:17.12
3,-3,10:18.13
-2,-2,10:18.13
1,-2,10:17.12
3,-2,10:17.12
4,-2,10:18.13
5,-2,10:18.13
1,-1,10:17.12
2,-1,10:17.12
3,-1,10:17.12
-3,0,10:18.13
-3,1,10:18.13
-3,2,10:18.13
0,-9,11:18.13
0,-8,11:18.13
-7,-7,11:18.5
-6,-7,11:18.13
0,-7,11:18.13
-5,-6,11:18.13
-4,-6,11:18.13
-3,-6,11:18.13
-2,-6,11:18.13
-1,-6,11:18.13
0,-6,11:18.13
-2,-5,11:17.12
-1,-5,11:17.12
0,-5,11:18.13
-2,-4,11:18.13
-1,-4,11:18.13
0,-4,11:18.13
1,-4,11:18.13
-2,-3,11:18.13
0,-3,11:18.13
1,-3,11:17.12
2,-3,11:17.12
3,-3,11:18.13
-2,-2,11:18.13
1,-2,11:17.12
3,-2,11:17.12
4,-2,11:18.13
5,-2,11:18.13
-2,-1,11:18.13
1,-1,11:17.12
2,-1,11:17.12
3,-1,11:17.12
-3,0,11:18.13
-3,1,11:18.13
-3,2,11:18.13
0,-8,12:18.13
0,-7,12:18.13
-5,-6,12:18.13
-4,-6,12:18.13
-3,-6,12:18.13
-2,-6,12:18.13
-1,-6,12:18.13
0,-6,12:18.13
-2,-5,12:18.13
-1,-5,12:17.12
0,-5,12:18.13
15,-5,12:18.5
-2,-4,12:18.13
-1,-4,12:18.13
0,-4,12:18.13
1,-4,12:18.13
-3,-3,12:18.13
-2,-3,12:18.13
0,-3,12:18.13
1,-3,12:17.12
2,-3,12:17.12
3,-3,12:18.13
-2,-2,12:18.13
1,-2,12:17.12
3,-2,12:17.12
-2,-1,12:18.13
2,-1,12:17.12
3,-1,12:17.12
-3,0,12:18.13
-1,-16,13:18.5
-1,-15,13:18.5
-4,-9,13:18.13
3,-9,13:18.13
-4,-8,13:18.13
-3,-8,13:18.13
2,-8,13:18.13
3,-8,13:18.13
-3,-7,13:18.13
-2,-7,13:18.13
1,-7,13:18.13
-2,-6,13:18.13
-1,-6,13:18.13
0,-6,13:18.13
16,-6,13:18.5
-2,-5,13:17.12
-1,-5,13:17.12
13,-5,13:18.5
14,-5,13:18.5
15,-5,13:18.5
-3,-4,13:18.13
-2,-4,13:18.13
-1,-4,13:18.13
0,-4,13:18.13
1,-4,13:18.13
12,-4,13:18.5
-4,-3,13:18.13
-3,-3,13:18.13
0,-3,13:18.13
1,-3,13:17.12
2,-3,13:17.12
3,-3,13:17.12
-5,-2,13:18.13
-4,-2,13:18.13
-2,-2,13:18.13
1,-2,13:17.12
3,-2,13:17.12
2,-1,13:17.12
3,-1,13:17.12
-11,1,13:18.5
-10,1,13:18.5
-13,2,13:18.5
-12,2,13:18.5
-1,-16,14:18.5
-1,-15,14:18.5
0,-14,14:18.5
0,-13,14:18.5
0,-12,14:18.5
1,-10,14:18.13
-4,-9,14:18.13
1,-9,14:18.13
3,-9,14:18.13
-3,-8,14:18.13
2,-8,14:18.13
3,-8,14:18.13
-3,-7,14:18.13
-2,-7,14:18.13
1,-7,14:18.13
-2,-6,14:18.13
-1,-6,14:18.13
0,-6,14:18.13
16,-6,14:18.5
18,-6,14:18.5
-2,-5,14:17.12
-1,-5,14:17.12
13,-5,14:18.5
14,-5,14:18.5
15,-5,14:18.5
-3,-4,14:18.13
-2,-4,14:18.13
-1,-4,14:18.13
0,-4,14:18.13
10,-4,14:18.5
11,-4,14:18.5
12,-4,14:18.5
-4,-3,14:18.13
-3,-3,14:18.13
0,-3,14:18.13
1,-3,14:17.12
2,-3,14:17.12
3,-3,14:17.12
8,-3,14:18.5
9,-3,14:18.5
-5,-2,14:18.13
1,-2,14:17.12
3,-2,14:17.12
-6,-1,14:18.13
-5,-1,14:18.13
-4,-1,14:18.13
2,-1,14:17.12
-8,0,14:18.5
-7,0,14:18.5
-6,0,14:18.5
-11,1,14:18.5
-10,1,14:18.5
-9,1,14:18.5
0,-14,15:18.5
0,-13,15:18.5
0,-12,15:18.5
1,-11,15:18.5
1,-10,15:18.13
-4,-9,15:18.13
1,-9,15:18.13
3,-9,15:18.13
-3,-8,15:18.13
1,-8,15:18.13
2,-8,15:18.13
-3,-7,15:18.13
-2,-7,15:18.13
1,-7,15:18.13
2,-7,15:18.13
-2,-6,15:18.13
-1,-6,15:18.13
0,-6,15:18.13
2,-6,15:18.13
16,-6,15:18.5
-2,-5,15:18.13
-1,-5,15:17.12
1,-5,15:18.13
2,-5,15:18.13
3,-5,15:18.13
13,-5,15:18.5
14,-5,15:18.5
15,-5,15:18.5
-3,-4,15:18.13
-2,-4,15:18.13
-1,-4,15:18.13
0,-4,15:18.13
1,-4,15:18.13
4,-4,15:18.13
10,-4,15:18.5
11,-4,15:18.5
12,-4,15:18.5
-4,-3,15:18.13
-3,-3,15:18.13
-1,-3,15:18.13
0,-3,15:18.13
1,-3,15:17.12
2,-3,15:17.12
3,-3,15:17.12
5,-3,15:18.13
6,-3,15:18.13
7,-3,15:18.13
8,-3,15:18.5
9,-3,15:18.5
-5,-2,15:18.13
-3,-2,15:18.13
-2,-2,15:18.13
-1,-2,15:18.13
1,-2,15:17.12
2,-2,15:17.12
3,-2,15:17.12
5,-2,15:18.13
6,-2,15:18.13
-6,-1,15:18.13
-5,-1,15:18.13
-4,-1,15:18.13
-1,-1,15:18.13
0,-1,15:18.13
2,-1,15:17.12
5,-1,15:18.13
-9,0,15:18.5
-8,0,15:18.5
-7,0,15:18.5
-6,0,15:18.5
0,0,15:18.13
1,0,15:18.13
4,0,15:18.13
-11,1,15:18.5
-10,1,15:18.5
-9,1,15:18.5
2,1,15:18.13
3,1,15:18.13
2,3,15:18.13
3,5,15:18.5
3,9,15:18.5
3,10,15:18.5
-1,-17,16:18.5
-1,-16,16:18.5
-1,-15,16:18.5
0,-14,16:18.5
0,-13,16:18.5
0,-12,16:18.5
0,-11,16:18.5
1,-11,16:18.5
1,-10,16:18.13
1,-9,16:18.13
-3,-8,16:18.13
1,-8,16:18.13
2,-8,16:18.13
-2,-7,16:18.13
0,-7,16:18.13
1,-7,16:18.13
2,-7,16:18.13
-2,-6,16:18.13
-1,-6,16:18.13
0,-6,16:18.13
2,-6,16:18.13
16,-6,16:18.5
-2,-5,16:18.13
-1,-5,16:17.12
0,-5,16:18.13
1,-5,16:18.13
2,-5,16:18.13
3,-5,16:18.13
12,-5,16:18.5
13,-5,16:18.5
14,-5,16:18.5
-3,-4,16:18.13
-2,-4,16:18.13
0,-4,16:18.13
1,-4,16:18.13
2,-4,16:18.13
3,-4,16:18.13
4,-4,16:18.13
9,-4,16:18.5
10,-4,16:18.5
11,-4,16:18.5
12,-4,16:18.5
-4,-3,16:18.13
-1,-3,16:18.13
0,-3,16:18.13
1,-3,16:17.12
2,-3,16:17.12
3,-3,16:17.12
4,-3,16:18.13
5,-3,16:18.13
6,-3,16:18.13
7,-3,16:18.13
8,-3,16:18.5
9,-3,16:18.5
-3,-2,16:18.13
-2,-2,16:18.13
-1,-2,16:18.13
0,-2,16:18.13
1,-2,16:17.12
2,-2,16:17.12
3,-2,16:17.12
4,-2,16:18.13
5,-2,16:18.13
6,-2,16:18.13
-6,-1,16:18.13
-5,-1,16:18.13
-4,-1,16:18.13
-1,-1,16:18.13
0,-1,16:18.13
1,-1,16:18.13
2,-1,16:17.12
3,-1,16:18.13
4,-1,16:18.13
5,-1,16:18.13
-8,0,16:18.5
-7,0,16:18.5
-6,0,16:18.5
0,0,16:18.13
1,0,16:18.13
2,0,16:18.13
3,0,16:18.13
4,0,16:18.13
-12,1,16:18.5
-11,1,16:18.5
-10,1,16:18.5
1,1,16:18.13
2,1,16:18.13
3,1,16:18.13
-13,2,16:18.5
2,3,16:18.13
3,3,16:18.13
3,5,16:18.5
3,6,16:18.5
3,7,16:18.5
3,8,16:18.5
3,9,16:18.5
-1,-16,17:18.5
-1,-15,17:18.5
0,-14,17:18.5
0,-13,17:18.5
0,-12,17:18.5
1,-12,17:18.5
0,-11,17:18.5
1,-11,17:18.5
0,-10,17:18.13
1,-10,17:18.13
0,-9,17:18.13
1,-9,17:18.13
-7,-8,17:18.5
-6,-8,17:18.13
0,-8,17:18.13
1,-8,17:18.13
2,-8,17:18.13
-5,-7,17:18.13
-4,-7,17:18.13
-2,-7,17:18.13
-1,-7,17:18.13
0,-7,17:18.13
2,-7,17:18.13
-3,-6,17:18.13
-2,-6,17:18.13
-1,-6,17:18.13
0,-6,17:18.13
2,-6,17:18.13
-2,-5,17:17.12
-1,-5,17:17.12
0,-5,17:18.13
1,-5,17:18.13
2,-5,17:18.13
3,-5,17:18.13
13,-5,17:18.5
-2,-4,17:18.13
0,-4,17:18.13
1,-4,17:18.13
2,-4,17:18.13
3,-4,17:18.13
4,-4,17:18.13
9,-4,17:18.5
10,-4,17:18.5
11,-4,17:18.5
-2,-3,17:18.13
-1,-3,17:18.13
0,-3,17:18.13
1,-3,17:18.13
2,-3,17:18.13
3,-3,17:18.13
5,-3,17:18.13
6,-3,17:18.13
7,-3,17:18.13
8,-3,17:18.5
-3,-2,17:18.13
-2,-2,17:18.13
-1,-2,17:18.13
0,-2,17:18.13
1,-2,17:18.13
2,-2,17:18.13
3,-2,17:18.13
4,-2,17:18.13
5,-2,17:18.13
6,-2,17:18.13
-6,-1,17:18.13
-5,-1,17:18.13
-4,-1,17:18.13
0,-1,17:18.13
1,-1,17:18.13
2,-1,17:18.13
3,-1,17:18.13
4,-1,17:18.13
5,-1,17:18.13
-9,0,17:18.5
-8,0,17:18.5
-7,0,17:18.5
-6,0,17:18.5
1,0,17:18.13
2,0,17:18.13
3,0,17:18.13
4,0,17:18.13
-11,1,17:18.5
-10,1,17:18.5
2,1,17:18.13
3,1,17:18.13
3,3,17:18.13
3,5,17:18.5
3,6,17:18.5
3,7,17:18.5
3,8,17:18.5
3,9,17:18.5
0,-13,18:18.5
0,-12,18:18.5
1,-12,18:18.5
1,-11,18:18.5
0,-10,18:18.13
1,-10,18:18.13
0,-9,18:18.13
1,-9,18:18.13
-7,-8,18:18.5
-6,-8,18:18.13
-5,-8,18:18.13
0,-8,18:18.13
1,-8,18:18.13
-5,-7,18:18.13
-4,-7,18:18.13
-3,-7,18:18.13
-1,-7,18:18.13
2,-7,18:18.13
-3,-6,18:18.13
-2,-6,18:18.13
-1,-6,18:17.12
2,-6,18:18.13
-2,-5,18:17.12
-1,-5,18:18.13
0,-5,18:18.13
1,-5,18:18.13
2,-5,18:18.13
3,-5,18:18.13
12,-5,18:18.5
-2,-4,18:18.13
0,-4,18:18.13
1,-4,18:18.13
2,-4,18:18.13
3,-4,18:18.13
4,-4,18:18.13
9,-4,18:18.5
10,-4,18:18.5
11,-4,18:18.5
-2,-3,18:18.13
-1,-3,18:18.13
0,-3,18:18.13
1,-3,18:17.12
2,-3,18:17.12
3,-3,18:17.12
5,-3,18:18.13
6,-3,18:18.13
7,-3,18:18.13
8,-3,18:18.5
-3,-2,18:18.13
-2,-2,18:18.13
-1,-2,18:18.13
0,-2,18:18.13
1,-2,18:17.12
2,-2,18:17.12
3,-2,18:17.12
5,-2,18:18.13
-6,-1,18:18.13
-5,-1,18:18.13
-4,-1,18:18.13
0,-1,18:18.13
1,-1,18:18.13
4,-1,18:18.13
-7,0,18:18.5
-4,0,18:18.5
1,0,18:18.13
2,0,18:18.13
3,0,18:18.13
4,0,18:18.13
-12,1,18:18.5
-10,1,18:18.5
-4,1,18:18.5
2,1,18:18.13
3,1,18:18.13
3,3,18:18.13
3,5,18:18.5
-1,6,18:18.5
3,6,18:18.5
3,7,18:18.5
3,8,18:18.5
3,9,18:18.5
3,10,18:18.5
4,11,18:18.5
0,-13,19:18.5
0,-12,19:18.5
1,-12,19:18.5
1,-11,19:18.5
0,-10,19:18.13
1,-10,19:18.13
0,-9,19:18.13
1,-9,19:18.13
-7,-8,19:18.5
-6,-8,19:18.13
-5,-8,19:18.13
0,-8,19:18.13
1,-8,19:18.13
-5,-7,19:18.13
-4,-7,19:18.13
-3,-7,19:18.13
-1,-7,19:18.13
2,-7,19:18.13
-3,-6,19:18.13
-2,-6,19:18.13
-1,-6,19:17.12
2,-6,19:18.13
-1,-5,19:18.13
0,-5,19:18.13
1,-5,19:18.13
2,-5,19:18.13
3,-5,19:18.13
-2,-4,19:18.13
0,-4,19:18.13
1,-4,19:18.13
2,-4,19:18.13
3,-4,19:18.13
4,-4,19:18.13
8,-4,19:18.5
9,-4,19:18.5
10,-4,19:18.5
-2,-3,19:18.13
-1,-3,19:18.13
0,-3,19:18.13
1,-3,19:17.12
2,-3,19:17.12
3,-3,19:17.12
4,-3,19:18.13
5,-3,19:18.13
6,-3,19:18.13
7,-3,19:18.13
8,-3,19:18.5
-3,-2,19:18.13
-2,-2,19:18.13
-1,-2,19:18.13
0,-2,19:18.13
1,-2,19:17.12
2,-2,19:17.12
3,-2,19:17.12
5,-2,19:18.13
-6,-1,19:18.13
-5,-1,19:18.13
-4,-1,19:18.13
0,-1,19:18.13
1,-1,19:18.13
4,-1,19:18.13
-8,0,19:18.5
-7,0,19:18.5
-4,0,19:18.5
1,0,19:18.13
2,0,19:18.13
3,0,19:18.13
-4,1,19:18.5
0,1,19:18.13
2,1,19:18.13
3,2,19:18.13
0,3,19:18.13
3,3,19:18.13
0,4,19:18.5
-1,5,19:18.5
3,5,19:18.5
-1,6,19:18.5
3,7,19:18.5
3,8,19:18.5
3,9,19:18.5
3,10,19:18.5
1,-11,20:18.5
0,-10,20:18.13
1,-10,20:18.13
0,-9,20:18.13
1,-9,20:18.13
-7,-8,20:18.5
-6,-8,20:18.13
-5,-8,20:18.13
0,-8,20:18.13
1,-8,20:18.13
-4,-7,20:18.13
-3,-7,20:18.13
-1,-7,20:18.13
2,-7,20:18.13
-7,-6,20:18.5
-2,-6,20:18.13
-1,-6,20:17.12
2,-6,20:18.13
-1,-5,20:18.13
0,-5,20:18.13
1,-5,20:18.13
2,-5,20:18.13
3,-5,20:18.13
-2,-4,20:18.13
-1,-4,20:18.13
1,-4,20:18.13
2,-4,20:17.12
3,-4,20:18.13
4,-4,20:18.13
8,-4,20:18.5
9,-4,20:18.5
10,-4,20:18.5
-2,-3,20:18.13
0,-3,20:18.13
1,-3,20:17.12
2,-3,20:17.12
3,-3,20:17.12
4,-3,20:18.13
5,-3,20:18.13
6,-3,20:18.13
7,-3,20:18.13
8,-3,20:18.5
-3,-2,20:18.13
-2,-2,20:18.13
-1,-2,20:18.13
0,-2,20:18.13
1,-2,20:17.12
2,-2,20:17.12
3,-2,20:17.12
4,-2,20:18.13
5,-2,20:18.13
-6,-1,20:18.13
-5,-1,20:18.13
-4,-1,20:18.13
0,-1,20:18.13
1,-1,20:18.13
3,-1,20:18.13
4,-1,20:18.13
-9,0,20:18.5
-4,0,20:18.5
1,0,20:18.13
2,0,20:18.13
3,0,20:18.13
-4,1,20:18.5
0,1,20:18.13
2,1,20:18.13
-5,2,20:18.5
0,2,20:18.13
3,2,20:18.13
0,3,20:18.13
3,3,20:18.13
-1,4,20:18.5
0,4,20:18.5
-1,5,20:18.5
3,5,20:18.5
-1,6,20:18.5
3,6,20:18.5
3,7,20:18.5
0,-9,21:18.13
1,-9,21:18.13
-5,-8,21:18.13
0,-8,21:18.13
1,-8,21:18.13
-4,-7,21:18.13
-3,-7,21:18.13
-1,-7,21:18.13
2,-7,21:18.13
-8,-6,21:18.5
-7,-6,21:18.5
-2,-6,21:18.13
-1,-6,21:17.12
2,-6,21:18.13
4,-6,21:18.13
-6,-5,21:18.13
-5,-5,21:18.13
-4,-5,21:18.13
-1,-5,21:18.13
0,-5,21:18.13
1,-5,21:18.13
2,-5,21:18.13
3,-5,21:18.13
-3,-4,21:18.13
-2,-4,21:18.13
-1,-4,21:18.13
1,-4,21:18.13
2,-4,21:17.12
3,-4,21:18.13
4,-4,21:18.13
8,-4,21:18.5
-2,-3,21:18.13
0,-3,21:18.13
1,-3,21:17.12
2,-3,21:18.13
3,-3,21:17.12
4,-3,21:18.13
5,-3,21:18.13
6,-3,21:18.13
7,-3,21:18.13
-3,-2,21:18.13
-2,-2,21:18.13
-1,-2,21:18.13
0,-2,21:18.13
1,-2,21:18.13
2,-2,21:17.12
3,-2,21:17.12
4,-2,21:18.13
5,-2,21:18.13
-5,-1,21:18.13
-4,-1,21:18.13
1,-1,21:18.13
3,-1,21:18.13
4,-1,21:18.13
-4,0,21:18.5
1,0,21:18.13
2,0,21:18.13
3,0,21:18.13
-4,1,21:18.5
0,1,21:18.13
2,1,21:18.13
0,2,21:18.13
3,2,21:18.13
0,3,21:18.5
3,3,21:18.5
-1,4,21:18.5
0,4,21:18.5
-1,5,21:18.5
3,5,21:18.5
-1,6,21:18.5
3,6,21:18.5
6,-12,22:18.5
5,-11,22:18.5
-5,-10,22:18.13
-4,-10,22:18.13
5,-10,22:18.5
-4,-9,22:18.13
-3,-9,22:18.13
5,-9,22:18.5
4,-8,22:18.13
-3,-7,22:18.13
-1,-7,22:18.13
4,-7,22:18.13
-8,-6,22:18.5
-7,-6,22:18.5
-6,-6,22:18.13
-2,-6,22:18.13
-1,-6,22:17.12
4,-6,22:18.13
-6,-5,22:18.13
-5,-5,22:18.13
-4,-5,22:18.13
-3,-5,22:18.13
-1,-5,22:17.12
0,-5,22:18.13
3,-5,22:18.13
-3,-4,22:18.13
-2,-4,22:18.13
2,-4,22:17.12
3,-4,22:18.13
0,-3,22:18.13
1,-3,22:18.13
2,-3,22:18.13
3,-3,22:18.13
-3,-2,22:18.13
1,-2,22:18.13
2,-2,22:17.12
3,-2,22:17.12
4,-2,22:18.13
5,-2,22:18.13
6,-2,22:18.13
1,-1,22:18.13
7,-1,22:18.13
8,-1,22:18.5
1,0,22:18.13
11,0,22:18.5
0,1,22:18.13
0,2,22:18.13
3,2,22:18.13
0,3,22:18.5
3,3,22:18.5
-1,4,22:18.5
0,4,22:18.5
6,-12,23:18.5
5,-11,23:18.5
-4,-10,23:18.13
5,-10,23:18.5
-4,-9,23:18.13
-3,-9,23:18.13
3,-9,23:18.13
4,-9,23:18.5
5,-9,23:18.5
-3,-8,23:18.13
-2,-8,23:18.13
2,-8,23:18.13
3,-8,23:18.13
4,-8,23:18.13
-2,-7,23:18.13
-1,-7,23:18.13
0,-7,23:18.13
1,-7,23:18.13
4,-7,23:18.13
-7,-6,23:18.5
-6,-6,23:18.5
-2,-6,23:18.13
-1,-6,23:17.12
0,-6,23:18.13
4,-6,23:18.13
-6,-5,23:18.5
-5,-5,23:18.13
-4,-5,23:18.13
-3,-5,23:18.13
-2,-5,23:18.13
-1,-5,23:18.13
0,-5,23:18.13
3,-5,23:18.13
-4,-4,23:18.13
-3,-4,23:18.13
-2,-4,23:18.13
-1,-4,23:18.13
0,-4,23:18.13
1,-4,23:18.13
2,-4,23:17.12
3,-4,23:18.13
-5,-3,23:18.13
-4,-3,23:18.13
0,-3,23:18.13
1,-3,23:18.13
2,-3,23:18.13
3,-3,23:18.13
-5,-2,23:18.13
1,-2,23:18.13
2,-2,23:17.12
3,-2,23:18.13
4,-2,23:18.13
6,-2,23:18.13
1,-1,23:18.13
7,-1,23:18.13
8,-1,23:18.5
9,-1,23:18.5
1,0,23:18.13
10,0,23:18.5
11,0,23:18.5
0,1,23:18.13
1,1,23:18.13
0,2,23:18.13
0,3,23:18.5
-1,4,23:18.5
5,-11,24:18.5
5,-10,24:18.5
-4,-9,24:18.13
-3,-9,24:18.13
3,-9,24:18.13
4,-9,24:18.5
5,-9,24:18.5
-3,-8,24:18.13
-2,-8,24:18.13
2,-8,24:18.13
4,-8,24:18.13
-2,-7,24:18.13
-1,-7,24:18.13
0,-7,24:18.13
1,-7,24:18.13
4,-7,24:18.13
-8,-6,24:18.5
-7,-6,24:18.5
-6,-6,24:18.5
-2,-6,24:18.13
-1,-6,24:17.12
0,-6,24:18.13
3,-6,24:18.13
4,-6,24:18.13
-4,-5,24:18.13
-3,-5,24:18.13
-2,-5,24:18.13
-1,-5,24:18.13
0,-5,24:18.13
3,-5,24:18.13
-4,-4,24:18.13
-3,-4,24:18.13
-2,-4,24:18.13
-1,-4,24:18.13
0,-4,24:18.13
1,-4,24:18.13
2,-4,24:17.12
3,-4,24:18.13
-5,-3,24:18.13
-4,-3,24:18.13
0,-3,24:18.13
1,-3,24:18.13
2,-3,24:18.13
3,-3,24:18.13
4,-3,24:18.13
-5,-2,24:18.13
1,-2,24:18.13
2,-2,24:17.12
3,-2,24:18.13
4,-2,24:18.13
5,-2,24:18.13
6,-2,24:18.13
1,-1,24:18.13
7,-1,24:18.13
8,-1,24:18.5
9,-1,24:18.5
1,0,24:18.13
10,0,24:18.5
11,0,24:18.5
12,0,24:18.5
0,1,24:18.13
0,2,24:18.13
0,3,24:18.5
6,-13,25:18.5
6,-12,25:18.5
5,-11,25:18.5
5,-10,25:18.5
-2,-8,25:18.13
2,-8,25:18.13
4,-8,25:18.13
-1,-7,25:18.13
0,-7,25:18.13
1,-7,25:18.13
3,-7,25:18.13
4,-7,25:18.13
-7,-6,25:18.5
-6,-6,25:18.5
-2,-6,25:18.13
-1,-6,25:17.12
0,-6,25:18.13
3,-6,25:18.13
4,-6,25:18.13
-5,-5,25:18.13
-3,-5,25:18.13
-2,-5,25:18.13
-1,-5,25:18.13
0,-5,25:18.13
3,-5,25:18.13
-4,-4,25:18.13
-3,-4,25:18.13
-2,-4,25:18.13
-1,-4,25:18.13
0,-4,25:18.13
1,-4,25:18.13
2,-4,25:17.12
3,-4,25:18.13
-4,-3,25:18.13
1,-3,25:18.13
2,-3,25:18.13
3,-3,25:18.13
4,-3,25:18.13
1,-2,25:18.13
2,-2,25:17.12
3,-2,25:17.12
4,-2,25:18.13
5,-2,25:18.13
6,-2,25:18.13
7,-2,25:18.13
1,-1,25:18.13
7,-1,25:18.13
8,-1,25:18.5
9,-1,25:18.5
1,0,25:18.13
10,0,25:18.5
11,0,25:18.5
0,1,25:18.13
1,1,25:18.13
0,2,25:18.13
-1,-11,26:18.5
5,-11,26:18.5
-1,-10,26:18.13
5,-10,26:18.5
-1,-9,26:18.13
5,-9,26:18.5
-1,-8,26:18.13
-3,-7,26:18.13
-1,-7,26:18.13
2,-7,26:18.13
3,-7,26:18.13
4,-7,26:18.13
-2,-6,26:18.13
-1,-6,26:17.12
0,-6,26:18.13
1,-6,26:18.13
2,-6,26:18.13
3,-6,26:18.13
4,-6,26:18.13
-5,-5,26:18.13
-4,-5,26:18.13
-3,-5,26:18.13
-2,-5,26:18.13
-1,-5,26:18.13
3,-5,26:18.13
-2,-4,26:18.13
-1,-4,26:18.13
0,-4,26:18.13
1,-4,26:18.13
2,-4,26:17.12
3,-4,26:18.13
-1,-3,26:18.13
1,-3,26:18.13
2,-3,26:18.13
3,-3,26:17.12
4,-3,26:18.13
1,-2,26:18.13
2,-2,26:17.12
3,-2,26:17.12
4,-2,26:18.13
5,-2,26:18.13
6,-2,26:18.13
7,-2,26:18.13
1,-1,26:18.13
8,-1,26:18.5
9,-1,26:18.5
1,0,26:18.13
10,0,26:18.5
11,0,26:18.5
12,0,26:18.5
-1,-11,27:18.5
-1,-10,27:18.13
-1,-9,27:18.13
4,-9,27:18.5
-1,-8,27:18.13
4,-8,27:18.13
-5,-7,27:18.13
-4,-7,27:18.13
-3,-7,27:18.13
-2,-7,27:18.13
-1,-7,27:18.13
1,-7,27:18.13
2,-7,27:18.13
3,-7,27:18.13
4,-7,27:18.13
-1,-6,27:18.13
0,-6,27:18.13
1,-6,27:18.13
3,-6,27:18.13
-4,-5,27:18.13
-1,-5,27:18.13
3,-5,27:18.13
-2,-4,27:18.13
-1,-4,27:18.13
0,-4,27:18.13
1,-4,27:17.12
2,-4,27:17.12
3,-4,27:18.13
-1,-3,27:18.13
1,-3,27:17.12
2,-3,27:18.13
3,-3,27:18.13
4,-3,27:18.13
-1,-2,27:18.13
1,-2,27:18.13
2,-2,27:17.12
3,-2,27:17.12
5,-2,27:18.13
6,-2,27:18.13
7,-2,27:18.13
-1,-1,27:18.13
1,-1,27:18.13
8,-1,27:18.5
9,-1,27:18.5
1,0,27:18.13
11,0,27:18.5
-1,-11,28:18.5
-1,-10,28:18.13
-1,-9,28:18.13
-1,-8,28:18.13
-5,-7,28:18.13
-4,-7,28:18.13
-3,-7,28:18.13
-2,-7,28:18.13
-1,-7,28:18.13
1,-7,28:18.13
2,-7,28:18.13
3,-7,28:18.13
4,-7,28:18.13
-1,-6,28:18.13
0,-6,28:18.13
3,-6,28:18.13
-4,-5,28:18.13
-3,-5,28:18.13
-1,-5,28:18.13
3,-5,28:18.13
-2,-4,28:18.13
-1,-4,28:18.13
0,-4,28:18.13
1,-4,28:18.13
2,-4,28:17.12
3,-4,28:18.13
-1,-3,28:18.13
1,-3,28:17.12
2,-3,28:18.13
3,-3,28:18.13
4,-3,28:18.13
-1,-2,28:18.13
1,-2,28:18.13
2,-2,28:17.12
3,-2,28:17.12
5,-2,28:18.13
6,-2,28:18.13
7,-2,28:18.13
-1,-1,28:18.13
8,-1,28:18.5
9,-1,28:18.5
4,4,28:18.5
4,5,28:18.5
-1,-10,29:18.13
-1,-9,29:18.13
-1,-8,29:18.13
4,-8,29:18.13
-4,-7,29:18.13
-3,-7,29:18.13
-2,-7,29:18.13
-1,-7,29:18.13
0,-7,29:18.13
1,-7,29:18.13
2,-7,29:18.13
4,-7,29:18.13
-1,-6,29:18.13
2,-6,29:18.13
3,-6,29:18.13
-1,-5,29:18.13
2,-5,29:18.13
3,-5,29:18.13
-1,-4,29:18.13
1,-4,29:17.12
2,-4,29:17.12
3,-4,29:18.13
4,-4,29:18.13
5,-4,29:18.13
-3,-3,29:18.13
-2,-3,29:18.13
-1,-3,29:18.13
0,-3,29:18.13
1,-3,29:17.12
2,-3,29:18.13
3,-3,29:17.12
4,-3,29:18.13
-11,-2,29:18.5
-1,-2,29:18.13
2,-2,29:18.13
3,-2,29:17.12
5,-2,29:18.13
6,-2,29:18.13
7,-2,29:18.13
-1,-1,29:18.13
2,-1,29:18.13
8,-1,29:18.5
3,0,29:18.13
3,1,29:18.13
3,2,29:18.13
3,3,29:18.5
1,-16,30:18.5
1,-15,30:18.5
1,-14,30:18.5
1,-13,30:18.5
1,-12,30:18.5
1,-11,30:18.5
0,-10,30:18.13
2,-10,30:18.13
0,-9,30:18.13
2,-9,30:18.13
0,-8,30:18.13
2,-8,30:18.13
-3,-7,30:18.13
-2,-7,30:18.13
-1,-7,30:18.13
0,-7,30:18.13
2,-7,30:18.13
-1,-6,30:17.12
0,-6,30:18.13
1,-6,30:18.13
2,-6,30:18.13
12,-6,30:18.5
13,-6,30:18.5
14,-6,30:18.5
15,-6,30:18.5
-1,-5,30:18.13
2,-5,30:18.13
7,-5,30:18.13
8,-5,30:18.5
9,-5,30:18.5
10,-5,30:18.5
11,-5,30:18.5
-1,-4,30:18.13
1,-4,30:17.12
2,-4,30:17.12
3,-4,30:17.12
4,-4,30:18.13
-5,-3,30:18.13
-4,-3,30:18.13
-3,-3,30:18.13
-2,-3,30:18.13
-1,-3,30:18.13
0,-3,30:18.13
1,-3,30:17.12
2,-3,30:18.13
3,-3,30:17.12
-13,-2,30:18.5
-12,-2,30:18.5
-11,-2,30:18.5
-10,-2,30:18.5
-9,-2,30:18.5
-8,-2,30:18.5
-7,-2,30:18.5
-6,-2,30:18.5
2,-2,30:17.12
2,-1,30:18.13
3,0,30:18.13
3,1,30:18.13
3,2,30:18.13
3,3,30:18.5
4,4,30:18.5
1,-15,31:18.5
1,-14,31:18.5
1,-13,31:18.5
1,-12,31:18.5
1,-11,31:18.5
0,-10,31:18.13
2,-10,31:18.13
0,-9,31:18.13
2,-9,31:18.13
-4,-8,31:18.13
-3,-8,31:18.13
0,-8,31:18.13
2,-8,31:18.13
-2,-7,31:18.13
-1,-7,31:18.13
0,-7,31:18.13
2,-7,31:18.13
-1,-6,31:18.13
0,-6,31:18.13
1,-6,31:18.13
2,-6,31:18.13
12,-6,31:18.5
13,-6,31:18.5
2,-5,31:18.13
7,-5,31:18.13
8,-5,31:18.5
9,-5,31:18.5
10,-5,31:18.5
11,-5,31:18.5
1,-4,31:17.12
2,-4,31:17.12
3,-4,31:18.13
4,-4,31:18.13
5,-4,31:18.13
6,-4,31:18.13
-6,-3,31:18.5
-5,-3,31:18.13
-4,-3,31:18.13
-3,-3,31:18.13
-2,-3,31:18.13
0,-3,31:18.13
1,-3,31:18.13
2,-3,31:18.13
3,-3,31:17.12
-11,-2,31:18.5
-10,-2,31:18.5
-9,-2,31:18.5
-8,-2,31:18.5
-7,-2,31:18.5
2,-2,31:18.13
2,-1,31:18.13
3,0,31:18.13
3,1,31:18.13
3,2,31:18.13
3,3,31:18.5
4,4,31:18.5
1,-15,32:18.5
1,-14,32:18.5
1,-13,32:18.5
1,-12,32:18.5
1,-11,32:18.5
1,-10,32:18.13
2,-10,32:18.13
0,-9,32:18.13
2,-9,32:18.13
-4,-8,32:18.13
-3,-8,32:18.13
-2,-8,32:18.13
0,-8,32:18.13
2,-8,32:18.13
-2,-7,32:18.13
-1,-7,32:18.13
0,-7,32:18.13
2,-7,32:18.13
-2,-6,32:18.13
-1,-6,32:18.13
0,-6,32:18.13
1,-6,32:18.13
2,-6,32:18.13
11,-6,32:18.5
12,-6,32:18.5
13,-6,32:18.5
14,-6,32:18.5
15,-6,32:18.5
-2,-5,32:18.13
2,-5,32:18.13
7,-5,32:18.13
8,-5,32:18.5
9,-5,32:18.5
10,-5,32:18.5
11,-5,32:18.5
-3,-4,32:18.13
1,-4,32:17.12
2,-4,32:17.12
3,-4,32:18.13
4,-4,32:18.13
5,-4,32:18.13
6,-4,32:18.13
-7,-3,32:18.5
-6,-3,32:18.5
-5,-3,32:18.13
-4,-3,32:18.13
-3,-3,32:18.13
-2,-3,32:18.13
-1,-3,32:18.13
0,-3,32:18.13
1,-3,32:18.13
2,-3,32:17.12
3,-3,32:17.12
-11,-2,32:18.5
-10,-2,32:18.5
-9,-2,32:18.5
-8,-2,32:18.5
-7,-2,32:18.5
2,-2,32:18.13
2,-1,32:18.13
3,-1,32:18.13
3,0,32:18.13
3,1,32:18.13
3,3,32:18.5
4,3,32:18.5
4,4,32:18.5
4,5,32:18.5
1,-14,33:18.5
1,-13,33:18.5
2,-10,33:18.13
0,-9,33:18.13
2,-9,33:18.13
-4,-8,33:18.13
-3,-8,33:18.13
-2,-8,33:18.13
0,-8,33:18.13
2,-8,33:18.13
-2,-7,33:18.13
-1,-7,33:18.13
0,-7,33:18.13
2,-7,33:18.13
16,-7,33:18.5
-2,-6,33:18.13
-1,-6,33:18.13
1,-6,33:18.13
2,-6,33:18.13
11,-6,33:18.5
12,-6,33:18.5
13,-6,33:18.5
14,-6,33:18.5
-2,-5,33:18.13
2,-5,33:18.13
6,-5,33:18.13
7,-5,33:18.13
8,-5,33:18.5
9,-5,33:18.5
10,-5,33:18.5
-3,-4,33:18.13
1,-4,33:17.12
2,-4,33:17.12
3,-4,33:18.13
4,-4,33:18.13
5,-4,33:18.13
6,-4,33:18.13
-6,-3,33:18.5
-5,-3,33:18.13
-4,-3,33:18.13
-3,-3,33:18.13
-2,-3,33:18.13
-1,-3,33:18.13
0,-3,33:18.13
1,-3,33:18.13
2,-3,33:17.12
3,-3,33:17.12
-10,-2,33:18.5
-9,-2,33:18.5
2,-2,33:18.13
2,-1,33:18.13
3,-1,33:18.13
3,0,33:18.13
3,1,33:18.13
3,2,33:18.13
4,4,33:18.5
1,-17,34:18.5
1,-16,34:18.5
1,-15,34:18.5
1,-14,34:18.5
1,-13,34:18.5
1,-12,34:18.5
1,-11,34:18.5
2,-10,34:18.13
2,-9,34:18.13
-3,-8,34:18.13
-2,-8,34:18.13
0,-8,34:18.13
2,-8,34:18.13
-1,-7,34:18.13
0,-7,34:18.13
2,-7,34:18.13
-2,-6,34:18.13
-1,-6,34:18.13
1,-6,34:18.13
2,-6,34:18.13
11,-6,34:18.5
12,-6,34:18.5
13,-6,34:18.5
14,-6,34:18.5
-2,-5,34:18.13
2,-5,34:18.13
6,-5,34:18.13
7,-5,34:18.13
8,-5,34:18.5
9,-5,34:18.5
10,-5,34:18.5
1,-4,34:17.12
2,-4,34:17.12
3,-4,34:18.13
4,-4,34:18.13
5,-4,34:18.13
-8,-3,34:18.5
-7,-3,34:18.5
-6,-3,34:18.5
-5,-3,34:18.13
-4,-3,34:18.13
-3,-3,34:18.13
-2,-3,34:18.13
-1,-3,34:18.13
0,-3,34:18.13
1,-3,34:18.13
2,-3,34:17.12
3,-3,34:17.0
-14,-2,34:18.5
-13,-2,34:18.5
-12,-2,34:18.5
-11,-2,34:18.5
-10,-2,34:18.5
-9,-2,34:18.5
2,-2,34:18.13
2,-1,34:18.13
3,-1,34:18.13
3,0,34:18.13
4,4,34:18.5
1,-15,35:18.5
1,-13,35:18.5
1,-12,35:18.5
2,-9,35:18.5
-2,-8,35:18.13
2,-8,35:18.13
-1,-7,35:18.13
2,-7,35:18.13
-1,-6,35:18.13
2,-6,35:18.13
11,-6,35:18.5
12,-6,35:18.5
14,-6,35:18.5
2,-5,35:18.13
6,-5,35:18.13
7,-5,35:18.13
1,-4,35:17.0
2,-4,35:17.0
3,-4,35:17.0
4,-4,35:18.13
5,-4,35:18.13
-8,-3,35:18.5
-5,-3,35:18.5
-4,-3,35:18.5
-3,-3,35:18.13
-2,-3,35:18.13
-1,-3,35:18.13
0,-3,35:18.13
1,-3,35:18.13
2,-3,35:17.0
3,-3,35:17.0
-11,-2,35:18.5
2,-2,35:18.13
3,-1,35:18.13
3,0,35:18.13
3,1,35:18.13
3,2,35:18.5
1,-16,36:18.5
1,-13,36:18.5
1,-12,36:18.5
1,-11,36:18.5
2,-10,36:18.5
2,-9,36:18.5
2,-8,36:18.13
2,-7,36:18.13
2,-6,36:18.13
11,-6,36:18.5
12,-6,36:18.5
2,-5,36:18.13
6,-5,36:18.13
7,-5,36:18.13
8,-5,36:18.5
9,-5,36:18.5
2,-4,36:17.0
3,-4,36:18.13
4,-4,36:18.13
5,-4,36:18.13
-8,-3,36:18.5
-7,-3,36:18.5
-6,-3,36:18.5
-5,-3,36:18.5
-4,-3,36:18.5
-3,-3,36:18.13
-1,-3,36:18.13
0,-3,36:18.13
1,-3,36:18.13
2,-3,36:17.0
3,-3,36:17.0
-12,-2,36:18.5
2,-2,36:18.13
3,-1,36:18.13
3,0,36:18.13
3,1,36:18.13
3,2,36:18.5
2,-10,37:18.5
2,-9,37:18.5
2,-8,37:18.5
2,-7,37:18.5
2,-6,37:18.5
11,-6,37:18.5
2,-5,37:18.5
5,-5,37:18.5
6,-5,37:18.5
7,-5,37:18.5
1,-4,37:18.5
2,-4,37:17.0
3,-4,37:17.0
4,-4,37:18.5
5,-4,37:18.5
-7,-3,37:18.5
-6,-3,37:18.5
-4,-3,37:18.5
-3,-3,37:18.5
-2,-3,37:18.5
-1,-3,37:18.5
0,-3,37:18.5
1,-3,37:18.5
2,-3,37:17.0
3,-3,37:17.0
2,-2,37:18.5
3,-1,37:18.5
3,0,37:18.5
5,-14,38:18.5
5,-13,38:18.5
2,-10,38:18.5
2,-9,38:18.5
2,-8,38:18.5
2,-7,38:18.5
2,-6,38:18.5
2,-5,38:18.5
5,-5,38:18.5
6,-5,38:18.5
7,-5,38:18.5
8,-5,38:18.5
9,-5,38:18.5
1,-4,38:18.5
2,-4,38:17.0
3,-4,38:17.0
4,-4,38:18.5
-5,-3,38:18.5
-4,-3,38:18.5
-3,-3,38:18.5
-2,-3,38:18.5
-1,-3,38:18.5
0,-3,38:18.5
2,-3,38:17.0
3,-3,38:17.0
2,-2,38:18.5
5,-14,39:18.5
5,-13,39:18.5
5,-12,39:18.5
5,-11,39:18.5
5,-10,39:18.5
4,-9,39:18.5
-7,-7,39:18.5
2,-7,39:18.5
2,-6,39:18.5
2,-5,39:17.0
5,-5,39:18.5
2,-4,39:17.0
3,-4,39:17.0
-2,-3,39:18.5
2,-3,39:17.0
3,-3,39:17.0
0,6,39:18.5
5,-14,40:18.5
5,-13,40:18.5
5,-12,40:18.5
5,-11,40:18.5
4,-10,40:18.5
5,-10,40:18.5
4,-9,40:18.5
4,-8,40:18.5
-8,-7,40:18.5
-7,-7,40:18.5
-6,-7,40:18.5
4,-7,40:18.5
-6,-6,40:18.5
-5,-6,40:18.5
-4,-6,40:18.5
-3,-6,40:18.5
-2,-6,40:18.5
2,-6,40:18.5
3,-6,40:18.5
4,-6,40:18.5
-1,-5,40:18.5
0,-5,40:18.5
1,-5,40:18.5
2,-5,40:17.0
4,-5,40:18.5
0,-4,40:18.5
2,-4,40:17.0
3,-4,40:17.0
2,-3,40:17.0
3,-3,40:17.0
5,-3,40:18.5
1,-2,40:18.5
3,-2,40:18.5
4,-2,40:18.5
6,-2,40:18.5
1,-1,40:18.5
8,-1,40:18.5
9,-1,40:18.5
1,0,40:18.5
10,0,40:18.5
11,0,40:18.5
1,1,40:18.5
0,2,40:18.5
0,3,40:18.5
0,4,40:18.5
0,5,40:18.5
0,6,40:18.5
5,-12,41:18.5
5,-11,41:18.5
4,-10,41:18.5
4,-9,41:18.5
4,-8,41:18.5
-7,-7,41:18.5
-6,-7,41:18.5
4,-7,41:18.5
-6,-6,41:18.5
-5,-6,41:18.5
-4,-6,41:18.5
-3,-6,41:18.5
-2,-6,41:18.5
2,-6,41:18.5
3,-6,41:18.5
4,-6,41:18.5
-1,-5,41:18.5
0,-5,41:18.5
1,-5,41:18.5
2,-5,41:17.0
4,-5,41:18.5
0,-4,41:18.5
2,-4,41:17.0
3,-4,41:17.0
4,-4,41:18.5
5,-4,41:18.5
1,-3,41:18.5
2,-3,41:17.0
3,-3,41:17.0
5,-3,41:18.5
1,-2,41:18.5
2,-2,41:18.5
3,-2,41:18.5
4,-2,41:18.5
5,-2,41:18.5
6,-2,41:18.5
7,-2,41:18.5
1,-1,41:18.5
2,-1,41:18.5
7,-1,41:18.5
8,-1,41:18.5
9,-1,41:18.5
1,0,41:18.5
10,0,41:18.5
11,0,41:18.5
1,1,41:18.5
0,2,41:18.5
1,2,41:18.5
0,3,41:18.5
0,4,41:18.5
0,5,41:18.5
0,6,41:18.5
5,-12,42:18.5
5,-11,42:18.5
4,-10,42:18.5
4,-9,42:18.5
4,-8,42:18.5
-7,-7,42:18.5
-6,-7,42:18.5
4,-7,42:18.5
-5,-6,42:18.5
-4,-6,42:18.5
-3,-6,42:18.5
-2,-6,42:18.5
2,-6,42:18.5
3,-6,42:18.5
4,-6,42:18.5
-1,-5,42:18.5
0,-5,42:18.5
1,-5,42:18.5
2,-5,42:17.0
4,-5,42:18.5
0,-4,42:18.5
1,-4,42:18.5
2,-4,42:17.0
3,-4,42:17.0
4,-4,42:18.5
1,-3,42:18.5
2,-3,42:17.0
4,-3,42:18.5
5,-3,42:18.5
1,-2,42:18.5
2,-2,42:18.5
3,-2,42:18.5
4,-2,42:18.5
5,-2,42:18.5
6,-2,42:18.5
7,-2,42:18.5
1,-1,42:18.5
8,-1,42:18.5
9,-1,42:18.5
1,0,42:18.5
10,0,42:18.5
11,0,42:18.5
1,1,42:18.5
1,2,42:18.5
0,3,42:18.5
0,4,42:18.5
0,5,42:18.5
0,6,42:18.5
5,-11,43:18.5
4,-10,43:18.5
4,-9,43:18.5
4,-8,43:18.5
-6,-7,43:18.5
4,-7,43:18.5
-5,-6,43:18.5
-4,-6,43:18.5
-3,-6,43:18.5
-2,-6,43:18.5
2,-6,43:18.5
3,-6,43:18.5
4,-6,43:18.5
-1,-5,43:18.5
0,-5,43:18.5
1,-5,43:18.5
2,-5,43:17.0
4,-5,43:18.5
1,-4,43:18.5
2,-4,43:17.0
3,-4,43:17.0
4,-4,43:18.5
1,-3,43:18.5
2,-3,43:17.0
4,-3,43:18.5
5,-3,43:18.5
1,-2,43:18.5
2,-2,43:18.5
3,-2,43:18.5
4,-2,43:18.5
5,-2,43:18.5
6,-2,43:18.5
7,-2,43:18.5
1,-1,43:18.5
8,-1,43:18.5
9,-1,43:18.5
1,0,43:18.5
11,0,43:18.5
1,1,43:18.5
1,2,43:18.5
0,3,43:18.5
0,4,43:18.5
0,5,43:18.5
4,-9,44:18.5
4,-8,44:18.5
4,-7,44:18.5
-5,-6,44:18.5
-4,-6,44:18.5
-3,-6,44:18.5
-2,-6,44:18.5
2,-6,44:18.5
3,-6,44:18.5
4,-6,44:18.5
-1,-5,44:18.5
0,-5,44:18.5
1,-5,44:18.5
2,-5,44:17.0
4,-5,44:18.5
1,-4,44:18.5
2,-4,44:17.0
3,-4,44:17.0
4,-4,44:18.5
1,-3,44:18.5
3,-3,44:18.5
4,-3,44:18.5
5,-3,44:18.5
1,-2,44:18.5
2,-2,44:18.5
3,-2,44:18.5
6,-2,44:18.5
7,-2,44:18.5
1,-1,44:18.5
8,-1,44:18.5
9,-1,44:18.5
1,0,44:18.5
1,1,44:18.5
1,2,44:18.5
0,4,44:18.5
4,-7,45:18.5
-2,-6,45:18.5
3,-6,45:18.5
4,-6,45:18.5
-1,-5,45:18.5
0,-5,45:18.5
1,-5,45:18.5
2,-5,45:17.0
4,-5,45:18.5
1,-4,45:18.5
2,-4,45:17.0
3,-4,45:17.0
4,-4,45:18.5
1,-3,45:18.5
3,-3,45:18.5
4,-3,45:18.5
5,-3,45:18.5
1,-2,45:18.5
2,-2,45:18.5
4,-2,45:18.5
6,-2,45:18.5
7,-2,45:18.5
1,-1,45:18.5
1,0,45:18.5
1,1,45:18.5
6,1,45:18.5
1,2,45:18.5
7,2,45:18.5
0,3,45:18.5
9,-9,46:18.5
1,-7,46:18.5
2,-6,46:18.5
4,-6,46:18.5
2,-5,46:17.0
3,-5,46:18.5
4,-5,46:18.5
1,-4,46:18.5
2,-4,46:18.5
3,-4,46:17.0
-1,-3,46:18.5
0,-3,46:18.5
3,-3,46:18.5
-3,-2,46:18.5
-2,-2,46:18.5
4,-2,46:18.5
4,-1,46:18.5
5,-1,46:18.5
5,0,46:18.5
6,0,46:18.5
6,1,46:18.5
-1,-11,47:18.5
0,-10,47:18.5
0,-9,47:18.5
9,-9,47:18.5
1,-8,47:18.5
7,-8,47:18.5
8,-8,47:18.5
1,-7,47:18.5
6,-7,47:18.5
7,-7,47:18.5
2,-6,47:18.5
4,-6,47:18.5
5,-6,47:18.5
2,-5,47:18.5
3,-5,47:18.5
1,-4,47:18.5
2,-4,47:18.5
3,-4,47:17.0
-1,-3,47:18.5
0,-3,47:18.5
3,-3,47:18.5
-3,-2,47:18.5
-2,-2,47:18.5
4,-2,47:18.5
-5,-1,47:18.5
-4,-1,47:18.5
5,-1,47:18.5
-7,0,47:18.5
-6,0,47:18.5
5,0,47:18.5
6,0,47:18.5
6,1,47:18.5
7,2,47:18.5
-1,-11,48:18.5
0,-10,48:18.5
0,-9,48:18.5
9,-9,48:18.5
10,-9,48:18.5
1,-8,48:18.5
7,-8,48:18.5
8,-8,48:18.5
1,-7,48:18.5
6,-7,48:18.5
7,-7,48:18.5
2,-6,48:18.5
4,-6,48:18.5
5,-6,48:18.5
2,-5,48:18.5
3,-5,48:18.5
1,-4,48:18.5
2,-4,48:18.5
3,-4,48:17.0
-1,-3,48:18.5
0,-3,48:18.5
3,-3,48:18.5
-4,-2,48:18.5
-3,-2,48:18.5
-2,-2,48:18.5
4,-2,48:18.5
-6,-1,48:18.5
-5,-1,48:18.5
-4,-1,48:18.5
5,-1,48:18.5
-7,0,48:18.5
-6,0,48:18.5
6,0,48:18.5
6,1,48:18.5
0,-10,49:18.5
0,-9,49:18.5
9,-9,49:18.5
1,-8,49:18.5
7,-8,49:18.5
8,-8,49:18.5
1,-7,49:18.5
5,-7,49:18.5
6,-7,49:18.5
7,-7,49:18.5
2,-6,49:18.5
4,-6,49:18.5
5,-6,49:18.5
2,-5,49:18.5
3,-5,49:18.5
1,-4,49:18.5
2,-4,49:18.5
3,-4,49:18.5
-2,-3,49:18.5
-1,-3,49:18.5
0,-3,49:18.5
3,-3,49:18.5
-4,-2,49:18.5
-3,-2,49:18.5
-2,-2,49:18.5
4,-2,49:18.5
-6,-1,49:18.5
-5,-1,49:18.5
5,-1,49:18.5
-7,0,49:18.5
5,0,49:18.5
6,0,49:18.5
6,1,49:18.5
7,1,49:18.5
-1,-12,50:18.5
-1,-11,50:18.5
0,-10,50:18.5
0,-9,50:18.5
9,-9,50:18.5
10,-9,50:18.5
1,-8,50:18.5
7,-8,50:18.5
8,-8,50:18.5
1,-7,50:18.5
5,-7,50:18.5
6,-7,50:18.5
2,-6,50:18.5
4,-6,50:18.5
5,-6,50:18.5
2,-5,50:18.5
3,-5,50:18.5
0,-4,50:18.5
1,-4,50:18.5
2,-4,50:18.5
3,-4,50:18.5
-2,-3,50:18.5
-1,-3,50:18.5
0,-3,50:18.5
3,-3,50:18.5
4,-3,50:18.5
-3,-2,50:18.5
-2,-2,50:18.5
4,-2,50:18.5
-6,-1,50:18.5
-5,-1,50:18.5
-4,-1,50:18.5
5,-1,50:18.5
-8,0,50:18.5
-7,0,50:18.5
6,0,50:18.5
7,1,50:18.5
-1,-11,51:18.5
1,-8,51:18.5
7,-8,51:18.5
8,-8,51:18.5
1,-7,51:18.5
5,-7,51:18.5
6,-7,51:18.5
2,-6,51:18.5
4,-6,51:18.5
5,-6,51:18.5
2,-5,51:18.5
3,-5,51:18.5
0,-4,51:18.5
1,-4,51:18.5
2,-4,51:18.5
3,-4,51:18.5
-2,-3,51:18.5
-1,-3,51:18.5
0,-3,51:18.5
3,-3,51:18.5
4,-3,51:18.5
-4,-2,51:18.5
-3,-2,51:18.5
-2,-2,51:18.5
4,-2,51:18.5
-5,-1,51:18.5
5,-1,51:18.5
-7,0,51:18.5
6,0,51:18.5
0,-9,52:18.5
1,-8,52:18.5
7,-8,52:18.5
1,-7,52:18.5
6,-7,52:18.5
2,-6,52:18.5
4,-6,52:18.5
5,-6,52:18.5
2,-5,52:18.5
3,-5,52:18.5
0,-4,52:18.5
1,-4,52:18.5
2,-4,52:18.5
3,-4,52:18.5
-2,-3,52:18.5
-1,-3,52:18.5
0,-3,52:18.5
3,-3,52:18.5
4,-3,52:18.5
-4,-2,52:18.5
-3,-2,52:18.5
4,-2,52:18.5
-5,-1,52:18.5
6,0,52:18.5
1,-8,53:18.5
1,-7,53:18.5
5,-7,53:18.5
2,-6,53:18.5
4,-6,53:18.5
8,-6,53:18.5
9,-6,53:18.5
2,-5,53:17.0
3,-5,53:18.5
4,-5,53:18.5
5,-5,53:18.5
0,-4,53:18.5
1,-4,53:18.5
2,-4,53:17.0
3,-4,53:18.5
-2,-3,53:18.5
-1,-3,53:18.5
0,-3,53:18.5
3,-3,53:18.5
4,-3,53:18.5
-3,-2,53:18.5
-5,-1,53:18.5
5,-1,53:18.5
7,-6,54:18.5
8,-6,54:18.5
9,-6,54:18.5
2,-5,54:17.0
3,-5,54:18.5
4,-5,54:18.5
5,-5,54:18.5
6,-5,54:18.5
2,-4,54:18.5
3,-4,54:18.5
3,-3,54:18.5
3,-2,54:18.5
3,-1,54:18.5
3,0,54:18.5
3,1,54:18.5
3,2,54:18.5
2,-7,55:18.5
2,-6,55:18.5
6,-6,55:18.5
7,-6,55:18.5
8,-6,55:18.5
0,-5,55:18.5
1,-5,55:18.5
2,-5,55:17.0
3,-5,55:18.5
4,-5,55:18.5
5,-5,55:18.5
6,-5,55:18.5
2,-4,55:18.5
3,-4,55:18.5
3,-3,55:18.5
3,-2,55:18.5
3,-1,55:18.5
3,0,55:18.5
3,1,55:18.5
3,2,55:18.5
2,-10,56:18.5
2,-9,56:18.5
2,-8,56:18.5
2,-7,56:18.5
2,-6,56:18.5
6,-6,56:18.5
7,-6,56:18.5
8,-6,56:18.5
9,-6,56:18.5
-3,-5,56:18.5
-2,-5,56:18.5
-1,-5,56:18.5
0,-5,56:18.5
1,-5,56:18.5
2,-5,56:17.0
3,-5,56:18.5
4,-5,56:18.5
5,-5,56:18.5
6,-5,56:18.5
3,-4,56:18.5
3,-3,56:18.5
3,-2,56:18.5
3,-1,56:18.5
3,0,56:18.5
3,1,56:18.5
2,-10,57:18.5
2,-9,57:18.5
2,-8,57:18.5
2,-7,57:18.5
2,-6,57:18.5
6,-6,57:18.5
7,-6,57:18.5
8,-6,57:18.5
9,-6,57:18.5
-3,-5,57:18.5
-2,-5,57:18.5
-1,-5,57:18.5
0,-5,57:18.5
1,-5,57:18.5
2,-5,57:18.5
3,-5,57:18.5
4,-5,57:18.5
5,-5,57:18.5
3,-4,57:18.5
3,-3,57:18.5
3,-2,57:18.5
3,-1,57:18.5
3,0,57:18.5
3,1,57:18.5
3,2,57:18.5
2,-10,58:18.5
2,-9,58:18.5
2,-8,58:18.5
2,-7,58:18.5
2,-6,58:18.5
6,-6,58:18.5
7,-6,58:18.5
-3,-5,58:18.5
-2,-5,58:18.5
-1,-5,58:18.5
0,-5,58:18.5
1,-5,58:18.5
2,-5,58:18.5
3,-5,58:18.5
4,-5,58:18.5
5,-5,58:18.5
3,-4,58:18.5
3,-3,58:18.5
3,-2,58:18.5
3,0,58:18.5
3,1,58:18.5
2,-12,59:18.5
2,-10,59:18.5
2,-9,59:18.5
2,-8,59:18.5
2,-7,59:18.5
-3,-6,59:18.5
2,-6,59:18.5
5,-6,59:18.5
6,-6,59:18.5
7,-6,59:18.5
-3,-5,59:18.5
-2,-5,59:18.5
-1,-5,59:18.5
0,-5,59:18.5
1,-5,59:18.5
2,-5,59:17.0
3,-5,59:18.5
4,-5,59:18.5
3,-4,59:18.5
3,-3,59:18.5
3,-2,59:18.5
3,-1,59:18.5
2,-9,60:18.5
2,-8,60:18.5
2,-7,60:18.5
-3,-6,60:18.5
2,-6,60:18.5
5,-6,60:18.5
6,-6,60:18.5
0,-5,60:18.5
1,-5,60:18.5
2,-5,60:18.5
3,-5,60:18.5
4,-5,60:18.5
3,-4,60:18.5
3,-3,60:18.5
3,-2,60:18.5
2,-10,61:18.5
2,-9,61:18.5
2,-8,61:18.5
2,-7,61:18.5
-2,-6,61:18.5
-1,-6,61:18.5
0,-6,61:18.5
1,-6,61:18.5
2,-6,61:18.5
1,-5,61:18.5
2,-5,61:18.5
3,-5,61:18.5
4,-5,61:18.5
3,-4,61:18.5
3,-3,61:18.5
3,-2,61:18.5
3,-1,61:18.5
2,-9,62:18.5
2,-8,62:18.5
2,-7,62:18.5
-1,-6,62:18.5
0,-6,62:18.5
1,-6,62:18.5
2,-6,62:18.5
2,-5,62:17.0
2,-5,63:17.0
2,-5,64:17.0
2,-5,65:17.0
2,-5,66:17.0
