[META]
version=2.0
spawnOnBlockType=2
spawnSunlight=True
spawnDarkness=True
spawnWater=False
spawnLava=False
underFill=False
randomRotation=True
dig=True
tree=False
branch=False
needsFoundation=True
rarity=100
collisionPercentage=20
spawnElevationMin=0
spawnElevationMax=200
spawnInBiome=Custom
[DATA]
-3,3,-8:17.12
-2,3,-8:17.12
-3,4,-8:17.12
-4,2,-7:17.12
-3,2,-7:17.12
-2,2,-7:17.12
-4,4,-7:17.12
-2,4,-7:17.12
-1,4,-7:17.12
-5,5,-7:17.12
-3,6,-7:17.12
-3,7,-7:17.12
-3,2,-6:17.12
-2,2,-6:17.12
-4,3,-6:17.12
-3,3,-6:17.12
-5,4,-6:17.12
-4,4,-6:17.12
-3,4,-6:17.12
-1,4,-6:17.12
-5,5,-6:17.12
-4,5,-6:17.12
-3,5,-6:17.12
-2,5,-6:17.12
-5,6,-6:17.12
-4,6,-6:17.12
-2,6,-6:17.12
-3,7,-6:17.12
-5,3,-5:17.12
-3,3,-5:17.12
-5,4,-5:17.12
-3,4,-5:17.12
-5,5,-5:17.12
-3,5,-5:17.12
-5,6,-5:17.12
-4,7,-5:17.12
-3,7,-5:17.12
-4,4,-4:17.12
-3,4,-4:17.12
-4,5,-4:17.12
-5,6,-4:17.12
-5,7,-4:17.12
-4,7,-4:17.12
-3,7,-4:17.12
-5,2,-3:17.12
-3,4,-3:17.12
-5,6,-3:17.12
-3,6,-3:17.12
-5,7,-3:17.12
-4,7,-3:17.12
-3,7,-3:17.12
-2,7,-3:17.12
-5,2,-2:17.12
-4,2,-2:17.12
-3,2,-2:17.12
-2,2,-2:17.12
-5,3,-2:17.12
-4,3,-2:17.12
-3,3,-2:17.12
-2,3,-2:17.12
-1,3,-2:17.12
-5,4,-2:17.12
-4,4,-2:17.12
-3,4,-2:17.12
-2,4,-2:17.12
-1,4,-2:17.12
0,4,-2:17.12
-5,5,-2:17.12
-4,5,-2:17.12
-3,5,-2:17.12
-2,5,-2:17.12
-1,5,-2:17.12
-5,6,-2:17.12
-4,6,-2:17.12
-3,6,-2:17.12
-2,6,-2:17.12
-1,6,-2:17.12
-6,7,-2:17.12
-5,7,-2:17.12
-4,7,-2:17.12
-3,7,-2:17.12
-2,7,-2:17.12
-5,8,-2:17.12
-4,2,-1:17.12
-3,2,-1:17.12
-2,2,-1:17.12
-5,3,-1:17.12
-4,3,-1:17.12
-2,3,-1:17.12
-1,3,-1:17.12
-5,4,-1:17.12
-2,4,-1:18.14
-1,4,-1:17.12
-6,5,-1:18.14
-5,5,-1:17.12
-4,5,-1:17.12
-2,5,-1:18.14
-1,5,-1:17.12
-6,6,-1:18.14
-5,6,-1:17.12
-4,6,-1:17.12
-3,6,-1:17.12
-2,6,-1:17.12
-1,6,-1:17.12
-6,7,-1:17.12
-5,7,-1:17.12
-4,7,-1:17.12
-3,7,-1:17.12
-2,7,-1:17.12
-3,2,0:17.12
-5,3,0:17.12
-4,3,0:17.12
-3,3,0:17.12
-2,3,0:17.12
-1,3,0:17.12
-5,4,0:17.12
-2,4,0:17.12
-1,4,0:17.12
-5,5,0:17.12
-4,5,0:17.12
-3,5,0:18.14
-2,5,0:17.12
-1,5,0:17.12
-6,6,0:18.14
-5,6,0:18.14
-4,6,0:17.12
-3,6,0:17.12
-2,6,0:17.12
-1,6,0:17.12
-6,7,0:18.14
-5,7,0:17.12
-4,7,0:17.12
-3,7,0:17.12
-4,3,1:17.12
-3,3,1:17.12
-2,3,1:17.12
-5,4,1:17.12
-2,4,1:17.12
-1,4,1:17.12
-5,5,1:17.12
-4,5,1:17.12
-3,5,1:17.12
-2,5,1:17.12
-1,5,1:18.14
-4,6,1:17.12
-3,6,1:17.12
-5,7,1:18.14
-4,7,1:18.14
-4,3,2:17.12
-3,3,2:17.12
-5,4,2:17.12
-2,4,2:17.12
-5,5,2:17.12
-4,5,2:17.12
-3,5,2:17.12
-2,5,2:17.12
-1,5,2:18.14
-4,6,2:17.12
-3,6,2:17.12
-4,3,3:17.12
-3,3,3:17.12
-5,4,3:17.12
-2,4,3:17.12
-5,5,3:17.12
-4,5,3:17.12
-3,5,3:17.12
-2,5,3:17.12
-4,6,3:17.12
-4,3,4:17.12
-3,3,4:17.12
-5,4,4:17.12
-3,4,4:17.12
-2,4,4:17.12
-5,5,4:17.12
-4,5,4:17.12
-3,5,4:17.12
-4,6,4:17.12
-4,3,5:17.12
-3,3,5:17.12
-5,4,5:17.12
-3,4,5:17.12
-5,5,5:17.12
-4,5,5:17.12
-3,5,5:17.12
-4,6,5:17.12
-4,3,6:17.12
-5,4,6:17.12
-4,4,6:17.12
-3,4,6:17.12
-5,5,6:17.12
-4,5,6:17.12
-3,5,6:17.12
-5,4,7:17.12
-4,4,7:17.12
-3,4,7:17.12
-5,5,7:17.12
-4,5,7:17.12
-3,5,7:17.12
-5,4,8:17.12
-4,4,8:17.12
-3,4,8:17.12
-5,5,8:17.12
-4,5,8:17.12
-3,5,8:17.12
-5,4,9:17.12
-4,4,9:17.12
-3,4,9:17.12
-5,5,9:17.12
-4,5,9:17.12
-3,5,9:17.12
-5,4,10:17.12
-4,4,10:17.12
-5,5,10:17.12
-4,5,10:17.12
-8,15,10:18.5
-8,16,10:18.13
0,-8,11:18.13
0,-7,11:18.13
0,-6,11:18.13
-16,0,11:18.13
-15,0,11:18.13
-14,1,11:18.13
-13,1,11:18.13
-5,4,11:17.12
-4,4,11:17.12
-5,5,11:17.12
-4,5,11:17.12
-7,10,11:18.13
-7,11,11:18.13
-7,12,11:18.13
-8,13,11:18.13
-7,13,11:18.13
-8,14,11:18.13
-8,15,11:18.13
-8,16,11:18.13
0,-7,12:18.13
-1,-6,12:18.13
0,-6,12:18.13
-1,-5,12:18.13
-1,-4,12:18.13
-1,-3,12:18.13
-2,-1,12:18.13
-15,0,12:18.13
-2,0,12:18.13
-14,1,12:18.13
-13,1,12:18.13
-12,1,12:18.13
-11,2,12:18.13
-10,2,12:18.13
-9,2,12:18.13
-8,3,12:18.13
-7,3,12:18.13
-7,4,12:18.13
-5,4,12:17.12
-4,4,12:17.12
-7,5,12:18.13
-5,5,12:17.12
-4,5,12:17.12
-6,7,12:18.13
-5,7,12:18.13
-6,8,12:18.13
-7,9,12:18.13
-6,9,12:18.13
-7,10,12:18.13
-7,11,12:18.13
-7,12,12:18.13
-8,13,12:18.13
-8,14,12:18.13
-8,15,12:18.13
-8,16,12:18.13
-9,17,12:18.13
0,-9,13:18.13
0,-8,13:18.13
0,-7,13:18.13
-1,-6,13:18.13
-1,-5,13:18.13
-1,-4,13:18.13
-1,-3,13:18.13
-2,-2,13:18.13
-2,-1,13:18.13
-17,0,13:18.13
-16,0,13:18.13
-2,0,13:18.13
-15,1,13:18.13
-14,1,13:18.13
-13,1,13:18.13
-12,1,13:18.13
-3,1,13:18.13
-2,1,13:18.13
-12,2,13:18.13
-11,2,13:18.13
-10,2,13:18.13
-9,2,13:18.13
-5,2,13:18.13
-4,2,13:18.13
-3,2,13:18.13
-8,3,13:18.13
-7,3,13:18.13
-6,3,13:18.13
-5,3,13:18.13
-2,3,13:18.13
-7,4,13:18.13
-5,4,13:17.12
-4,4,13:17.12
-2,4,13:18.13
-7,5,13:18.13
-6,5,13:18.13
-5,5,13:17.12
-4,5,13:17.12
-2,5,13:18.13
-7,6,13:18.13
-6,6,13:18.13
-2,6,13:18.13
-6,7,13:18.13
-5,7,13:18.13
-4,7,13:18.13
-3,7,13:18.13
-2,7,13:18.13
-1,7,13:18.13
0,7,13:18.13
-6,8,13:18.13
1,8,13:18.13
-7,9,13:18.13
3,9,13:18.13
4,9,13:18.13
-7,10,13:18.13
-7,11,13:18.13
-7,12,13:18.13
-8,13,13:18.13
-8,14,13:18.13
-8,15,13:18.13
-9,16,13:18.13
0,-7,14:18.13
-1,-6,14:18.13
-1,-5,14:18.13
-1,-4,14:18.13
-2,-3,14:18.13
-2,-2,14:18.13
-2,-1,14:18.13
-16,0,14:18.13
-2,0,14:18.13
-14,1,14:18.13
-13,1,14:18.13
-12,1,14:18.13
-3,1,14:18.13
-12,2,14:18.13
-11,2,14:18.13
-10,2,14:18.13
-9,2,14:18.13
-5,2,14:18.13
-4,2,14:18.13
-3,2,14:18.13
-9,3,14:18.13
-8,3,14:18.13
-7,3,14:18.13
-6,3,14:18.13
-5,3,14:18.13
-4,3,14:18.13
-3,3,14:18.13
-7,4,14:18.13
-6,4,14:18.13
-5,4,14:18.13
-4,4,14:18.13
-3,4,14:18.13
-2,4,14:18.13
-7,5,14:18.13
-6,5,14:18.13
-5,5,14:17.12
-4,5,14:17.12
-3,5,14:18.13
-2,5,14:18.13
-7,6,14:18.13
-6,6,14:18.13
-5,6,14:18.13
-4,6,14:18.13
-3,6,14:18.13
-2,6,14:18.13
-6,7,14:18.13
-5,7,14:18.13
-4,7,14:18.13
-3,7,14:18.13
-1,7,14:18.13
0,7,14:18.13
-6,8,14:18.13
1,8,14:18.13
2,8,14:18.13
-7,9,14:18.13
3,9,14:18.13
4,9,14:18.13
-7,10,14:18.13
5,10,14:18.13
-7,11,14:18.13
-7,12,14:18.13
-8,14,14:18.13
-9,16,14:18.13
-1,-5,15:18.13
-1,-4,15:18.13
-2,-3,15:18.13
-2,-2,15:18.13
-2,-1,15:18.13
-3,0,15:18.13
-2,0,15:18.13
-13,1,15:18.13
-3,1,15:18.13
-12,2,15:18.13
-11,2,15:18.13
-10,2,15:18.13
-9,2,15:18.13
-4,2,15:18.13
-3,2,15:18.13
-9,3,15:18.13
-8,3,15:18.13
-7,3,15:18.13
-6,3,15:18.13
-5,3,15:18.13
-3,3,15:18.13
-7,4,15:18.13
-6,4,15:17.12
-5,4,15:17.12
-4,4,15:17.12
-3,4,15:18.13
-7,5,15:18.13
-6,5,15:17.12
-5,5,15:17.12
-4,5,15:17.12
-2,5,15:18.13
-7,6,15:18.13
-6,6,15:18.13
-5,6,15:17.12
-3,6,15:18.13
-2,6,15:18.13
-6,7,15:18.13
-5,7,15:18.13
-4,7,15:18.13
-1,7,15:18.13
0,7,15:18.13
-6,8,15:18.13
1,8,15:18.13
2,8,15:18.13
-7,9,15:18.13
3,9,15:18.13
4,9,15:18.13
-7,10,15:18.13
5,10,15:18.13
-7,11,15:18.13
0,11,15:18.13
-8,12,15:18.13
-7,12,15:18.13
-8,13,15:18.13
-8,14,15:18.13
-2,-4,16:18.13
-2,-3,16:18.13
-2,-2,16:18.13
-2,-1,16:18.13
-3,0,16:18.13
-14,1,16:18.13
-13,1,16:18.13
-3,1,16:18.13
-12,2,16:18.13
-11,2,16:18.13
-10,2,16:18.13
-4,2,16:18.13
-3,2,16:18.13
-9,3,16:18.13
-8,3,16:18.13
-7,3,16:18.13
-6,3,16:18.13
-5,3,16:18.13
-4,3,16:18.13
-3,3,16:18.13
-7,4,16:18.13
-6,4,16:17.12
-5,4,16:17.12
-4,4,16:17.12
-3,4,16:18.13
-7,5,16:18.13
-6,5,16:17.12
-5,5,16:17.12
-4,5,16:17.12
-3,5,16:18.13
-7,6,16:18.13
-6,6,16:18.13
-5,6,16:17.12
-4,6,16:18.13
-3,6,16:18.13
-2,6,16:18.13
-6,7,16:18.13
-5,7,16:18.13
-4,7,16:18.13
-1,7,16:18.13
0,7,16:18.13
-7,8,16:18.13
-6,8,16:18.13
-3,8,16:18.13
0,8,16:18.13
1,8,16:18.13
2,8,16:18.13
-7,9,16:18.13
-2,9,16:18.13
3,9,16:18.13
4,9,16:18.13
-12,10,16:18.13
-7,10,16:18.13
-1,10,16:18.13
5,10,16:18.13
-7,11,16:18.13
-1,11,16:18.13
0,11,16:18.13
0,12,16:18.13
-8,13,16:18.13
-8,14,16:18.13
-2,-3,17:18.13
-2,-2,17:18.13
-2,-1,17:18.13
-3,0,17:18.13
-3,1,17:18.13
-12,2,17:18.13
-11,2,17:18.13
-10,2,17:18.13
-3,2,17:18.13
-9,3,17:18.13
-8,3,17:18.13
-7,3,17:18.13
-6,3,17:18.13
-5,3,17:18.13
-4,3,17:18.13
-3,3,17:18.13
-7,4,17:18.13
-6,4,17:17.12
-5,4,17:17.12
-4,4,17:17.12
-3,4,17:18.13
-7,5,17:18.13
-6,5,17:17.12
-5,5,17:17.12
-4,5,17:17.12
-3,5,17:18.13
-7,6,17:18.13
-6,6,17:18.13
-5,6,17:18.13
-4,6,17:18.13
-3,6,17:18.13
-2,6,17:18.13
-8,7,17:18.13
-6,7,17:18.13
-5,7,17:18.13
-4,7,17:18.13
-2,7,17:18.13
-1,7,17:18.13
0,7,17:18.13
-9,8,17:18.13
-7,8,17:18.13
-6,8,17:18.13
-3,8,17:18.13
1,8,17:18.13
2,8,17:18.13
-11,9,17:18.13
-10,9,17:18.13
-7,9,17:18.13
-2,9,17:18.13
-12,10,17:18.13
-7,10,17:18.13
-2,10,17:18.13
-1,10,17:18.13
-7,11,17:18.13
-1,11,17:18.13
0,11,17:18.13
-8,12,17:18.13
-3,0,18:18.13
-3,1,18:18.13
-4,2,18:18.13
-3,2,18:18.13
-9,3,18:18.13
-8,3,18:18.13
-7,3,18:18.13
-6,3,18:18.13
-5,3,18:18.13
-4,3,18:18.13
-3,3,18:18.13
-7,4,18:18.13
-6,4,18:17.12
-5,4,18:17.12
-4,4,18:18.13
-3,4,18:18.13
-7,5,18:18.13
-6,5,18:17.12
-5,5,18:17.12
-4,5,18:17.12
-3,5,18:18.13
-7,6,18:18.13
-6,6,18:18.13
-5,6,18:18.13
-4,6,18:18.13
-3,6,18:18.13
-2,6,18:18.13
-8,7,18:18.13
-6,7,18:18.13
-5,7,18:18.13
-4,7,18:18.13
-2,7,18:18.13
-1,7,18:18.13
0,7,18:18.13
-10,8,18:18.13
-9,8,18:18.13
-3,8,18:18.13
0,8,18:18.13
1,8,18:18.13
-11,9,18:18.13
-10,9,18:18.13
-7,9,18:18.13
-3,9,18:18.13
-2,9,18:18.13
-12,10,18:18.13
-7,10,18:18.13
-2,10,18:18.13
-1,10,18:18.13
-1,11,18:18.13
-10,-2,19:18.13
-9,-1,19:18.13
-9,0,19:18.13
-8,0,19:18.13
-8,1,19:18.13
-7,2,19:18.13
-2,2,19:18.13
-6,3,19:18.13
-4,3,19:18.13
-3,3,19:18.13
-6,4,19:17.12
-5,4,19:18.13
-4,4,19:18.13
-6,5,19:17.12
-5,5,19:17.12
-4,5,19:17.12
-7,6,19:18.13
-6,6,19:18.13
-5,6,19:18.13
-9,7,19:18.13
-8,7,19:18.13
-4,7,19:18.13
-1,7,19:18.13
-10,8,19:18.13
-9,8,19:18.13
-3,8,19:18.13
-11,9,19:18.13
-10,9,19:18.13
-3,9,19:18.13
-2,9,19:18.13
-12,10,19:18.13
-2,10,19:18.13
-9,-1,20:18.13
2,-1,20:18.13
-9,0,20:18.13
-8,0,20:18.13
1,0,20:18.13
-8,1,20:18.13
-1,1,20:18.13
0,1,20:18.13
-7,2,20:18.13
-2,2,20:18.13
-7,3,20:18.13
-6,3,20:18.13
-4,3,20:18.13
-3,3,20:18.13
-6,4,20:18.13
-5,4,20:18.13
-4,4,20:18.13
-6,5,20:17.12
-5,5,20:17.12
-7,6,20:18.13
-6,6,20:18.13
-5,6,20:18.13
-9,7,20:18.13
-8,7,20:18.13
-4,7,20:18.13
-10,8,20:18.13
-9,8,20:18.13
-4,8,20:18.13
-3,8,20:18.13
-11,9,20:18.13
-3,9,20:18.13
-2,9,20:18.13
-12,10,20:18.13
-2,10,20:18.13
-10,-2,21:18.13
-10,-1,21:18.13
-9,-1,21:18.13
-9,0,21:18.13
0,0,21:18.13
1,0,21:18.13
-8,1,21:18.13
-1,1,21:18.13
0,1,21:18.13
-7,2,21:18.13
-2,2,21:18.13
-7,3,21:18.13
-6,3,21:18.13
-4,3,21:18.13
-3,3,21:18.13
-6,4,21:18.13
-5,4,21:18.13
-4,4,21:18.13
-6,5,21:17.12
-5,5,21:17.12
-7,6,21:18.13
-6,6,21:18.13
-5,6,21:18.13
-9,7,21:18.13
-8,7,21:18.13
-4,7,21:18.13
-9,8,21:18.13
-4,8,21:18.13
-3,8,21:18.13
-11,9,21:18.13
-3,9,21:18.13
-12,10,21:18.13
-11,-3,22:18.13
-10,-1,22:18.13
-9,0,22:18.13
0,0,22:18.13
1,0,22:18.13
-8,1,22:18.13
-1,1,22:18.13
0,1,22:18.13
-7,2,22:18.13
-2,2,22:18.13
-7,3,22:18.13
-6,3,22:18.13
-4,3,22:18.13
-3,3,22:18.13
-6,4,22:18.13
-5,4,22:18.13
-4,4,22:18.13
-6,5,22:17.12
-5,5,22:17.12
-7,6,22:18.13
-6,6,22:17.12
-5,6,22:18.13
-9,7,22:18.13
-8,7,22:18.13
-5,7,22:18.13
-4,7,22:18.13
-10,8,22:18.13
-9,8,22:18.13
-4,8,22:18.13
-11,9,22:18.13
2,-1,23:18.13
-9,0,23:18.13
0,0,23:18.13
1,0,23:18.13
-8,1,23:18.13
-1,1,23:18.13
0,1,23:18.13
-8,2,23:18.13
-7,2,23:18.13
-2,2,23:18.13
-7,3,23:18.13
-4,3,23:18.13
-3,3,23:18.13
-6,4,23:18.13
-5,4,23:18.13
-4,4,23:18.13
-6,5,23:18.13
-5,5,23:17.12
-8,6,23:18.13
-7,6,23:18.13
-6,6,23:17.12
-5,6,23:18.13
-9,7,23:18.13
-8,7,23:18.13
-5,7,23:18.13
-4,7,23:18.13
-10,8,23:18.13
-11,9,23:18.13
-9,0,24:18.13
-1,1,24:18.13
-8,2,24:18.13
-2,2,24:18.13
-7,3,24:18.13
-4,3,24:18.13
-3,3,24:18.13
-6,4,24:17.12
-5,4,24:18.13
-4,4,24:18.13
-7,5,24:17.12
-6,5,24:18.13
-5,5,24:17.12
-8,6,24:18.13
-7,6,24:18.13
-6,6,24:17.12
-5,6,24:18.13
-9,7,24:18.13
-8,7,24:18.13
0,7,24:18.13
-8,9,24:18.13
-11,15,24:18.5
-12,16,24:18.13
-16,0,25:18.5
-15,0,25:18.13
-14,1,25:18.13
-13,1,25:18.13
-1,1,25:18.13
-11,2,25:18.13
-8,2,25:18.13
-3,2,25:18.13
-2,2,25:18.13
-9,3,25:18.13
-7,3,25:18.13
-5,3,25:18.13
-4,3,25:18.13
-3,3,25:18.13
-7,4,25:18.13
-6,4,25:18.13
-5,4,25:18.13
-7,5,25:17.12
-6,5,25:18.13
-5,5,25:17.12
-6,6,25:18.13
-5,6,25:18.13
-4,6,25:18.13
-3,6,25:18.13
-7,7,25:18.13
-2,7,25:18.13
-1,7,25:18.13
0,7,25:18.13
-7,8,25:18.13
-8,9,25:18.13
-9,10,25:18.13
-9,11,25:18.13
-10,12,25:18.13
-10,13,25:18.13
-11,14,25:18.13
-11,15,25:18.13
-2,-5,26:18.5
-4,-1,26:18.5
-15,0,26:18.13
-14,1,26:18.13
-13,1,26:18.13
-5,1,26:18.13
-12,2,26:18.13
-11,2,26:18.13
-5,2,26:18.13
-10,3,26:18.13
-9,3,26:18.13
-6,3,26:18.13
-5,3,26:18.13
-8,4,26:18.13
-7,4,26:18.13
-6,4,26:18.13
-7,5,26:17.12
-6,5,26:18.13
-5,5,26:17.12
-7,6,26:18.13
-6,6,26:17.12
-5,6,26:18.13
-4,6,26:18.13
-3,6,26:18.13
-7,7,26:18.13
-2,7,26:18.13
-1,7,26:18.13
0,7,26:18.13
-8,8,26:18.13
-8,9,26:18.13
-9,10,26:18.13
-9,11,26:18.13
-10,12,26:18.13
-10,13,26:18.13
-11,14,26:18.13
-11,15,26:18.13
-2,-6,27:18.5
-2,-5,27:18.5
-3,-4,27:18.5
-3,-3,27:18.13
-4,-2,27:18.13
-3,-2,27:18.13
-4,-1,27:18.13
-16,0,27:18.5
-15,0,27:18.5
-4,0,27:18.13
-14,1,27:18.5
-13,1,27:18.13
-5,1,27:18.13
-12,2,27:18.13
-11,2,27:18.13
-5,2,27:18.13
-10,3,27:18.13
-9,3,27:18.13
-8,4,27:18.13
-7,4,27:18.13
-6,4,27:17.12
-7,5,27:17.12
-6,5,27:18.13
-5,5,27:17.12
-7,6,27:18.13
-6,6,27:17.12
-5,6,27:18.13
-4,6,27:18.13
-3,6,27:18.13
-7,7,27:18.13
-2,7,27:18.13
-1,7,27:18.13
0,7,27:18.13
-8,8,27:18.13
-8,9,27:18.13
-9,10,27:18.13
-9,11,27:18.13
-10,12,27:18.13
-11,13,27:18.13
-10,13,27:18.13
-11,14,27:18.5
-2,-6,28:18.5
-2,-5,28:18.5
-3,-4,28:18.5
-3,-3,28:18.13
-4,-2,28:18.13
-4,-1,28:18.13
-15,0,28:18.5
-4,0,28:18.13
-14,1,28:18.5
-13,1,28:18.5
-5,1,28:18.13
-12,2,28:18.13
-11,2,28:18.13
-5,2,28:18.13
-11,3,28:18.13
-10,3,28:18.13
-9,3,28:18.13
-6,3,28:18.13
-9,4,28:18.13
-8,4,28:18.13
-7,4,28:18.13
-6,4,28:18.13
-7,5,28:17.12
-6,5,28:18.13
-5,5,28:17.12
-7,6,28:18.13
-6,6,28:17.12
-5,6,28:18.13
-4,6,28:18.13
-3,6,28:18.13
-7,7,28:18.13
-3,7,28:18.13
-2,7,28:18.13
-1,7,28:18.13
0,7,28:18.13
-8,8,28:18.13
0,8,28:18.13
1,8,28:18.13
2,8,28:18.5
-8,9,28:18.13
-9,10,28:18.13
-10,11,28:18.13
-9,11,28:18.13
-10,12,28:18.5
-11,14,28:18.5
-12,15,28:18.5
-12,16,28:18.5
-13,17,28:18.5
-13,18,28:18.5
-3,-5,29:18.5
-2,-5,29:18.5
-3,-4,29:18.5
-3,-3,29:18.5
-4,-2,29:18.5
-4,-1,29:18.5
-16,0,29:18.5
-15,0,29:18.5
-5,0,29:18.13
-4,0,29:18.13
-15,1,29:18.5
-14,1,29:18.5
-5,1,29:18.13
-13,2,29:18.5
-12,2,29:18.5
-11,2,29:18.13
-5,2,29:18.13
-11,3,29:18.13
-10,3,29:18.13
-9,3,29:18.13
-6,3,29:18.13
-9,4,29:18.13
-8,4,29:18.13
-7,4,29:18.13
-6,4,29:18.13
-7,5,29:17.12
-6,5,29:17.12
-7,6,29:18.13
-6,6,29:17.12
-5,6,29:18.13
-4,6,29:18.13
-7,7,29:18.13
-2,7,29:18.13
-1,7,29:18.13
-8,8,29:18.13
0,8,29:18.13
-8,9,29:18.13
-9,10,29:18.13
-10,12,29:18.5
-11,13,29:18.5
-11,14,29:18.5
-12,15,29:18.5
-2,-7,30:18.5
-2,-6,30:18.5
-3,-5,30:18.5
-3,-4,30:18.5
-3,-3,30:18.5
-4,-2,30:18.5
-4,-1,30:18.5
-16,0,30:18.5
-15,0,30:18.5
-5,0,30:18.13
-14,1,30:18.5
-5,1,30:18.13
-5,2,30:18.13
-11,3,30:18.13
-10,3,30:18.13
-9,3,30:18.13
-6,3,30:18.13
-9,4,30:18.13
-8,4,30:18.13
-7,4,30:18.13
-6,4,30:18.13
-7,5,30:17.12
-6,5,30:17.12
-7,6,30:18.13
-6,6,30:17.12
-5,6,30:18.13
-4,6,30:18.13
-3,6,30:18.13
-8,7,30:18.13
-7,7,30:18.13
-3,7,30:18.13
-2,7,30:18.13
-1,7,30:18.13
-8,8,30:18.13
-9,9,30:18.13
-8,9,30:18.13
-9,10,30:18.13
-10,11,30:18.5
-9,11,30:18.5
-10,12,30:18.5
-11,13,30:18.5
-11,14,30:18.5
-12,16,30:18.5
-3,-5,31:18.5
-3,-3,31:18.5
-4,-1,31:18.5
-16,0,31:18.5
-5,0,31:18.13
-14,1,31:18.5
-5,1,31:18.13
-13,2,31:18.5
-12,2,31:18.5
-6,2,31:18.13
-5,2,31:18.13
-11,3,31:18.13
-10,3,31:18.13
-6,3,31:18.13
-9,4,31:18.13
-8,4,31:18.13
-7,4,31:18.13
-6,4,31:18.13
-7,5,31:17.12
-6,5,31:17.12
-7,6,31:18.13
-6,6,31:18.13
-5,6,31:18.13
-4,6,31:18.13
-8,7,31:18.13
-7,7,31:18.13
-3,7,31:18.13
-2,7,31:18.13
-8,8,31:18.13
-9,9,31:18.13
-9,10,31:18.13
-10,11,31:18.5
-10,12,31:18.5
-4,-3,32:18.5
-4,-2,32:18.5
-4,-1,32:18.5
-5,0,32:18.5
-5,1,32:18.13
-13,2,32:18.5
-6,2,32:18.13
-11,3,32:18.13
-10,3,32:18.13
-6,3,32:18.13
-9,4,32:18.13
-8,4,32:18.13
-6,4,32:18.13
-7,5,32:18.13
-6,5,32:17.12
-7,6,32:18.13
-6,6,32:18.13
-5,6,32:18.13
-4,6,32:18.13
-8,7,32:18.13
-3,7,32:18.13
-8,8,32:18.13
-9,9,32:18.13
-9,10,32:18.13
-10,11,32:18.5
-13,-2,33:18.5
-12,-2,33:18.5
-12,-1,33:18.5
-5,0,33:18.5
-5,1,33:18.13
-6,2,33:18.13
-11,3,33:18.13
-10,3,33:18.13
-6,3,33:18.13
-9,4,33:18.13
-8,4,33:18.13
-6,4,33:18.13
-7,5,33:17.12
-6,5,33:17.12
-7,6,33:17.12
-6,6,33:18.13
-5,6,33:18.13
-8,7,33:18.13
-8,8,33:18.13
-14,11,33:18.5
-13,-2,34:18.5
-12,-2,34:18.5
-12,-1,34:18.5
-11,-1,34:18.5
-11,0,34:18.5
-10,0,34:18.5
-10,1,34:18.5
-9,1,34:18.5
-9,2,34:18.5
-7,5,34:17.12
-6,5,34:17.12
-7,6,34:17.12
-10,7,34:18.5
-11,8,34:18.5
-12,9,34:18.5
-3,10,34:18.5
-2,10,34:18.5
-14,11,34:18.5
-2,11,34:18.5
-1,11,34:18.5
-1,12,34:18.5
-13,-2,35:18.5
-12,-1,35:18.5
-11,0,35:18.5
-10,1,35:18.5
0,1,35:18.5
-9,2,35:18.5
-8,2,35:18.5
-2,2,35:18.5
-8,3,35:18.5
-7,3,35:18.5
-6,3,35:18.5
-4,3,35:18.5
-3,3,35:18.5
-8,4,35:18.5
-6,4,35:18.5
-5,4,35:18.5
-4,4,35:18.5
-9,5,35:18.5
-8,5,35:18.5
-7,5,35:17.12
-6,5,35:17.12
-5,5,35:18.5
-9,6,35:18.5
-8,6,35:18.5
-7,6,35:17.12
-5,6,35:18.5
-10,7,35:18.5
-9,7,35:18.5
-8,7,35:18.5
-7,7,35:18.5
-6,7,35:18.5
-5,7,35:18.5
-11,8,35:18.5
-10,8,35:18.5
-5,8,35:18.5
-12,9,35:18.5
-11,9,35:18.5
-4,9,35:18.5
-3,10,35:18.5
-14,11,35:18.5
-2,11,35:18.5
-1,12,35:18.5
-12,-1,36:18.5
-11,0,36:18.5
-10,1,36:18.5
-1,1,36:18.5
0,1,36:18.5
-9,2,36:18.5
-2,2,36:18.5
-1,2,36:18.5
-8,3,36:18.5
-7,3,36:18.5
-4,3,36:18.5
-3,3,36:18.5
-8,4,36:18.5
-6,4,36:18.5
-5,4,36:18.5
-4,4,36:18.5
-9,5,36:18.5
-8,5,36:18.5
-7,5,36:17.0
-6,5,36:17.12
-5,5,36:18.5
-9,6,36:18.5
-8,6,36:18.5
-7,6,36:17.12
-5,6,36:18.5
-10,7,36:18.5
-9,7,36:18.5
-8,7,36:18.5
-7,7,36:18.5
-6,7,36:18.5
-5,7,36:18.5
-11,8,36:18.5
-10,8,36:18.5
-5,8,36:18.5
-12,9,36:18.5
-4,9,36:18.5
-3,10,36:18.5
-14,11,36:18.5
-2,11,36:18.5
-1,12,36:18.5
0,13,36:18.5
-11,0,37:18.5
-10,1,37:18.5
-1,1,37:18.5
0,1,37:18.5
-10,2,37:18.5
-9,2,37:18.5
-2,2,37:18.5
-1,2,37:18.5
-9,3,37:18.5
-8,3,37:18.5
-7,3,37:18.5
-4,3,37:18.5
-3,3,37:18.5
-8,4,37:18.5
-7,4,37:18.5
-6,4,37:18.5
-5,4,37:18.5
-4,4,37:18.5
-9,5,37:18.5
-8,5,37:18.5
-7,5,37:17.0
-5,5,37:18.5
-9,6,37:18.5
-8,6,37:18.5
-7,6,37:17.0
-6,6,37:18.5
-5,6,37:18.5
-10,7,37:18.5
-9,7,37:18.5
-7,7,37:18.5
-6,7,37:18.5
-11,8,37:18.5
-10,8,37:18.5
-5,8,37:18.5
-12,9,37:18.5
-4,9,37:18.5
-3,10,37:18.5
-2,11,37:18.5
-1,12,37:18.5
-10,1,38:18.5
0,1,38:18.5
-10,2,38:18.5
-9,2,38:18.5
-2,2,38:18.5
-9,3,38:18.5
-8,3,38:18.5
-4,3,38:18.5
-3,3,38:18.5
-8,4,38:18.5
-7,4,38:18.5
-6,4,38:18.5
-5,4,38:18.5
-4,4,38:18.5
-8,5,38:18.5
-7,5,38:17.0
-6,5,38:18.5
-5,5,38:18.5
-9,6,38:18.5
-8,6,38:18.5
-7,6,38:17.0
-6,6,38:18.5
-10,7,38:18.5
-9,7,38:18.5
-7,7,38:18.5
-6,7,38:18.5
-11,8,38:18.5
-10,8,38:18.5
-5,8,38:18.5
-4,9,38:18.5
-3,10,38:18.5
-2,11,38:18.5
-2,2,39:18.5
-8,3,39:18.5
-4,3,39:18.5
-3,3,39:18.5
-8,4,39:18.5
-7,4,39:18.5
-6,4,39:18.5
-5,4,39:18.5
-4,4,39:18.5
-8,5,39:17.0
-7,5,39:17.0
-6,5,39:18.5
-5,5,39:18.5
-1,5,39:18.5
-9,6,39:18.5
-8,6,39:18.5
-7,6,39:17.0
-6,6,39:18.5
-10,7,39:18.5
-8,7,39:18.5
-7,7,39:18.5
-6,7,39:18.5
-8,8,39:18.5
-5,8,39:18.5
-8,9,39:18.5
-4,9,39:18.5
-3,10,39:18.5
-9,14,39:18.5
-8,3,40:18.5
-14,4,40:18.5
-8,4,40:18.5
-13,5,40:18.5
-12,5,40:18.5
-11,5,40:18.5
-10,5,40:18.5
-9,5,40:18.5
-8,5,40:18.5
-7,5,40:17.0
-6,5,40:18.5
-5,5,40:18.5
-4,5,40:18.5
-3,5,40:18.5
-2,5,40:18.5
-1,5,40:18.5
-8,6,40:18.5
-7,6,40:17.0
-8,7,40:18.5
-8,8,40:18.5
-8,9,40:18.5
-8,10,40:18.5
-8,11,40:18.5
-9,12,40:18.5
-8,12,40:18.5
-9,13,40:18.5
-9,14,40:18.5
-7,-2,41:18.5
-8,-1,41:18.5
-8,0,41:18.5
-8,1,41:18.5
-8,2,41:18.5
-8,3,41:18.5
-8,4,41:18.5
-13,5,41:18.5
-12,5,41:18.5
-11,5,41:18.5
-10,5,41:18.5
-9,5,41:18.5
-8,5,41:18.5
-7,5,41:17.0
-6,5,41:18.5
-5,5,41:18.5
-4,5,41:18.5
-3,5,41:18.5
-2,5,41:18.5
-1,5,41:18.5
-8,6,41:18.5
-7,6,41:17.0
-8,7,41:18.5
-8,8,41:18.5
-8,9,41:18.5
-8,10,41:18.5
-8,11,41:18.5
-9,12,41:18.5
-9,13,41:18.5
-9,14,41:18.5
-9,15,41:18.5
-8,-2,42:18.5
-8,-1,42:18.5
-8,0,42:18.5
-8,1,42:18.5
-8,2,42:18.5
-8,3,42:18.5
-8,4,42:18.5
-13,5,42:18.5
-12,5,42:18.5
-11,5,42:18.5
-10,5,42:18.5
-9,5,42:18.5
-8,5,42:18.5
-7,5,42:17.0
-6,5,42:18.5
-5,5,42:18.5
-4,5,42:18.5
-2,5,42:18.5
-1,5,42:18.5
-8,6,42:18.5
-7,6,42:17.0
-8,7,42:18.5
-8,8,42:18.5
-8,9,42:18.5
-8,10,42:18.5
-9,11,42:18.5
-8,11,42:18.5
-9,13,42:18.5
-9,14,42:18.5
-9,15,42:18.5
-8,-2,43:18.5
-8,-1,43:18.5
-8,0,43:18.5
-8,1,43:18.5
-8,2,43:18.5
-8,3,43:18.5
-8,4,43:18.5
-14,5,43:18.5
-13,5,43:18.5
-12,5,43:18.5
-11,5,43:18.5
-10,5,43:18.5
-9,5,43:18.5
-8,5,43:18.5
-7,5,43:18.5
-6,5,43:18.5
-5,5,43:18.5
-3,5,43:18.5
-2,5,43:18.5
-1,5,43:18.5
-8,6,43:18.5
-7,6,43:18.5
-8,7,43:18.5
-8,8,43:18.5
-8,9,43:18.5
-8,10,43:18.5
-9,12,43:18.5
-9,13,43:18.5
-9,14,43:18.5
-8,-2,44:18.5
-8,-1,44:18.5
-8,0,44:18.5
-8,1,44:18.5
-8,2,44:18.5
-8,3,44:18.5
-8,4,44:18.5
-14,5,44:18.5
-13,5,44:18.5
-12,5,44:18.5
-11,5,44:18.5
-10,5,44:18.5
-9,5,44:18.5
-8,5,44:18.5
-7,5,44:18.5
-6,5,44:18.5
-5,5,44:18.5
-4,5,44:18.5
-8,6,44:18.5
-7,6,44:18.5
-8,7,44:18.5
-8,8,44:18.5
-8,9,44:18.5
-9,10,44:18.5
-9,11,44:18.5
-9,12,44:18.5
-9,13,44:18.5
-9,15,44:18.5
-8,0,45:18.5
-8,1,45:18.5
-8,2,45:18.5
-8,3,45:18.5
-8,4,45:18.5
-13,5,45:18.5
-12,5,45:18.5
-11,5,45:18.5
-10,5,45:18.5
-9,5,45:18.5
-8,5,45:18.5
-7,5,45:18.5
-6,5,45:18.5
-5,5,45:18.5
-3,5,45:18.5
-8,6,45:18.5
-7,6,45:18.5
-8,7,45:18.5
-8,8,45:18.5
-9,9,45:18.5
-8,9,45:18.5
-9,10,45:18.5
-9,12,45:18.5
-8,1,46:18.5
-8,2,46:18.5
-8,3,46:18.5
-8,4,46:18.5
-7,4,46:18.5
-12,5,46:18.5
-11,5,46:18.5
-10,5,46:18.5
-9,5,46:18.5
-8,5,46:18.5
-6,5,46:18.5
-4,5,46:18.5
-8,6,46:17.0
-7,6,46:18.5
-8,8,46:18.5
-3,8,46:18.5
-9,9,46:18.5
-6,0,47:18.5
-6,1,47:18.5
-7,2,47:18.5
-7,3,47:18.5
-7,4,47:18.5
-8,5,47:18.5
-9,6,47:18.5
-8,6,47:17.0
-7,6,47:18.5
-6,7,47:18.5
-5,7,47:18.5
-4,8,47:18.5
-3,8,47:18.5
-6,1,48:18.5
-7,2,48:18.5
-13,3,48:18.5
-7,3,48:18.5
-12,4,48:18.5
-11,4,48:18.5
-8,4,48:18.5
-7,4,48:18.5
-10,5,48:18.5
-9,5,48:18.5
-8,5,48:18.5
-9,6,48:18.5
-8,6,48:18.5
-7,6,48:18.5
-10,7,48:18.5
-6,7,48:18.5
-5,7,48:18.5
-11,8,48:18.5
-10,8,48:18.5
-4,8,48:18.5
-3,8,48:18.5
-11,9,48:18.5
-12,10,48:18.5
-6,0,49:18.5
-6,1,49:18.5
-7,2,49:18.5
-13,3,49:18.5
-7,3,49:18.5
-12,4,49:18.5
-11,4,49:18.5
-8,4,49:18.5
-10,5,49:18.5
-9,5,49:18.5
-8,5,49:18.5
-9,6,49:18.5
-8,6,49:18.5
-7,6,49:18.5
-10,7,49:18.5
-6,7,49:18.5
-5,7,49:18.5
-11,8,49:18.5
-10,8,49:18.5
-4,8,49:18.5
-3,8,49:18.5
-11,9,49:18.5
-6,0,50:18.5
-7,1,50:18.5
-7,2,50:18.5
-13,3,50:18.5
-7,3,50:18.5
-12,4,50:18.5
-11,4,50:18.5
-8,4,50:18.5
-10,5,50:18.5
-9,5,50:18.5
-8,5,50:18.5
-9,6,50:18.5
-8,6,50:18.5
-7,6,50:18.5
-10,7,50:18.5
-6,7,50:18.5
-5,7,50:18.5
-11,8,50:18.5
-10,8,50:18.5
-4,8,50:18.5
-11,9,50:18.5
-7,2,51:18.5
-14,3,51:18.5
-13,3,51:18.5
-7,3,51:18.5
-12,4,51:18.5
-11,4,51:18.5
-8,4,51:18.5
-11,5,51:18.5
-10,5,51:18.5
-9,5,51:18.5
-8,5,51:18.5
-9,6,51:18.5
-8,6,51:18.5
-7,6,51:18.5
-10,7,51:18.5
-6,7,51:18.5
-5,7,51:18.5
-11,8,51:18.5
-10,8,51:18.5
-12,9,51:18.5
-11,9,51:18.5
-12,10,51:18.5
-7,2,52:18.5
-14,3,52:18.5
-13,3,52:18.5
-8,3,52:18.5
-13,4,52:18.5
-12,4,52:18.5
-11,4,52:18.5
-8,4,52:18.5
-11,5,52:18.5
-10,5,52:18.5
-9,5,52:18.5
-8,5,52:18.5
-9,6,52:18.5
-8,6,52:18.5
-7,6,52:18.5
-10,7,52:18.5
-7,7,52:18.5
-6,7,52:18.5
-11,8,52:18.5
-11,9,52:18.5
-12,4,53:18.5
-8,4,53:18.5
-11,5,53:18.5
-10,5,53:18.5
-9,5,53:18.5
-8,5,53:18.5
-10,6,53:18.5
-9,6,53:18.5
-8,6,53:18.5
-7,6,53:18.5
-10,7,53:18.5
-6,7,53:18.5
-11,8,53:18.5
-12,4,54:18.5
-11,5,54:18.5
-10,5,54:18.5
-9,6,54:17.0
-10,7,54:18.5
-11,8,54:18.5
-9,6,55:17.0
-9,6,56:17.0
-9,6,57:17.0
