[META]
version=2.0
spawnOnBlockType=2
spawnSunlight=True
spawnDarkness=True
spawnWater=False
spawnLava=False
underFill=False
randomRotation=True
dig=True
tree=False
branch=False
needsFoundation=True
rarity=100
collisionPercentage=20
spawnElevationMin=0
spawnElevationMax=200
spawnInBiome=Custom
[DATA]
9,-6,-8:17.12
9,-5,-8:17.12
10,-5,-8:17.12
9,-1,-8:17.12
9,0,-8:17.12
12,-10,-7:17.12
9,-9,-7:17.12
11,-9,-7:17.12
13,-9,-7:17.12
11,-8,-7:17.12
13,-8,-7:17.12
8,-7,-7:17.12
10,-5,-7:17.12
11,-5,-7:17.12
11,-4,-7:17.12
9,-3,-7:17.12
1,-2,-7:17.12
8,-2,-7:17.12
9,-2,-7:17.12
0,-1,-7:17.12
1,-1,-7:17.12
8,-1,-7:17.12
9,-1,-7:17.12
10,-1,-7:17.12
9,0,-7:17.12
10,0,-7:17.12
12,-11,-6:17.12
9,-9,-6:17.12
12,-9,-6:17.12
13,-9,-6:17.12
10,-8,-6:17.12
7,-7,-6:17.12
8,-7,-6:17.12
9,-7,-6:17.12
12,-7,-6:17.12
8,-5,-6:17.12
9,-5,-6:17.12
10,-5,-6:17.12
11,-5,-6:17.12
8,-4,-6:17.12
9,-4,-6:17.12
10,-4,-6:17.12
8,-3,-6:17.12
9,-3,-6:17.12
10,-3,-6:17.12
1,-2,-6:17.12
2,-2,-6:17.12
11,-2,-6:17.12
1,-1,-6:17.12
2,-1,-6:17.12
7,-1,-6:17.12
8,-1,-6:17.12
9,-1,-6:17.12
10,-1,-6:17.12
11,-1,-6:17.12
0,0,-6:17.12
1,0,-6:17.12
8,0,-6:17.12
9,0,-6:17.12
12,-11,-5:17.12
13,-11,-5:17.12
10,-10,-5:17.12
11,-10,-5:17.12
13,-10,-5:17.12
14,-10,-5:17.12
9,-9,-5:17.12
11,-9,-5:17.12
12,-9,-5:17.12
14,-9,-5:17.12
9,-8,-5:17.12
11,-8,-5:17.12
12,-8,-5:17.12
7,-7,-5:17.12
11,-7,-5:17.12
12,-7,-5:17.12
7,-6,-5:17.12
9,-6,-5:17.12
7,-5,-5:17.12
9,-5,-5:17.12
10,-5,-5:17.12
11,-5,-5:17.12
7,-4,-5:17.12
10,-4,-5:17.12
11,-4,-5:17.12
12,-4,-5:17.12
2,-3,-5:17.12
8,-3,-5:17.12
9,-3,-5:17.12
1,-2,-5:17.12
2,-2,-5:17.12
8,-2,-5:17.12
11,-2,-5:17.12
1,-1,-5:17.12
2,-1,-5:17.12
8,-1,-5:17.12
9,-1,-5:17.12
10,-1,-5:17.12
11,-1,-5:17.12
12,-1,-5:17.12
8,0,-5:17.12
9,0,-5:17.12
7,1,-5:17.12
8,1,-5:17.12
7,2,-5:17.12
12,-11,-4:17.12
13,-11,-4:17.12
10,-10,-4:17.12
12,-10,-4:17.12
12,-9,-4:17.12
14,-9,-4:17.12
8,-8,-4:17.12
9,-8,-4:17.12
7,-7,-4:17.12
12,-7,-4:17.12
8,-6,-4:17.12
10,-6,-4:17.12
8,-5,-4:17.12
9,-5,-4:17.12
10,-5,-4:17.12
8,-4,-4:17.12
9,-4,-4:17.12
10,-4,-4:17.12
11,-4,-4:17.12
2,-3,-4:17.12
3,-3,-4:17.12
8,-3,-4:17.12
10,-3,-4:17.12
11,-3,-4:17.12
0,-2,-4:17.12
1,-2,-4:17.12
2,-2,-4:17.12
3,-2,-4:17.12
4,-2,-4:17.12
10,-2,-4:17.12
11,-2,-4:17.12
12,-2,-4:17.12
1,-1,-4:17.12
2,-1,-4:17.12
7,-1,-4:17.12
8,-1,-4:17.12
9,-1,-4:17.12
10,-1,-4:17.12
11,-1,-4:17.12
12,-1,-4:17.12
8,0,-4:17.12
9,0,-4:17.12
11,0,-4:17.12
12,0,-4:17.12
6,1,-4:17.12
7,1,-4:17.12
8,1,-4:17.12
6,2,-4:17.12
7,2,-4:17.12
10,-10,-3:17.12
11,-10,-3:17.12
12,-10,-3:17.12
11,-9,-3:17.12
12,-9,-3:17.12
8,-8,-3:17.12
9,-8,-3:17.12
10,-8,-3:17.12
12,-8,-3:17.12
7,-7,-3:17.12
8,-7,-3:17.12
9,-7,-3:17.12
10,-7,-3:17.12
11,-7,-3:17.12
7,-6,-3:17.12
9,-6,-3:17.12
11,-6,-3:17.12
7,-5,-3:17.12
8,-5,-3:17.12
9,-5,-3:17.12
10,-5,-3:17.12
11,-5,-3:17.12
7,-4,-3:17.12
8,-4,-3:17.12
9,-4,-3:17.12
10,-4,-3:17.12
11,-4,-3:17.12
12,-4,-3:17.12
3,-3,-3:17.12
8,-3,-3:17.12
9,-3,-3:17.12
10,-3,-3:17.12
2,-2,-3:17.12
3,-2,-3:17.12
4,-2,-3:17.12
9,-2,-3:17.12
10,-2,-3:17.12
11,-2,-3:17.12
2,-1,-3:17.12
3,-1,-3:17.12
4,-1,-3:17.12
9,-1,-3:17.12
10,-1,-3:17.12
11,-1,-3:17.12
12,-1,-3:17.12
5,0,-3:17.12
6,0,-3:17.12
7,0,-3:17.12
8,0,-3:17.12
10,0,-3:17.12
11,0,-3:17.12
4,1,-3:17.12
5,1,-3:17.12
6,1,-3:17.12
7,1,-3:17.12
8,1,-3:17.12
5,2,-3:17.12
6,2,-3:17.12
4,3,-3:17.12
6,3,-3:17.12
10,-10,-2:17.12
11,-10,-2:17.12
12,-10,-2:17.12
13,-10,-2:17.12
10,-9,-2:17.12
12,-9,-2:17.12
13,-9,-2:17.12
10,-8,-2:17.12
11,-8,-2:17.12
12,-8,-2:17.12
13,-8,-2:17.12
8,-7,-2:17.12
9,-7,-2:17.12
10,-7,-2:17.12
11,-7,-2:17.12
7,-6,-2:17.12
11,-6,-2:17.12
7,-5,-2:17.12
11,-5,-2:17.12
8,-4,-2:17.12
9,-4,-2:17.12
10,-4,-2:17.12
11,-4,-2:17.12
3,-3,-2:17.12
4,-3,-2:17.12
8,-3,-2:17.12
10,-3,-2:17.12
11,-3,-2:17.12
2,-2,-2:17.12
3,-2,-2:17.12
4,-2,-2:17.12
8,-2,-2:17.12
9,-2,-2:17.12
10,-2,-2:17.12
11,-2,-2:17.12
2,-1,-2:17.12
3,-1,-2:17.12
4,-1,-2:17.12
8,-1,-2:17.12
9,-1,-2:17.12
10,-1,-2:17.12
11,-1,-2:17.12
2,0,-2:17.12
3,0,-2:17.12
4,0,-2:17.12
5,0,-2:17.12
6,0,-2:17.12
3,1,-2:17.12
4,1,-2:17.12
5,1,-2:17.12
4,2,-2:17.12
5,2,-2:17.12
6,2,-2:17.12
10,-10,-1:17.12
11,-10,-1:17.12
10,-9,-1:17.12
12,-9,-1:18.14
11,-8,-1:17.12
12,-8,-1:18.14
13,-8,-1:18.14
14,-8,-1:18.14
8,-7,-1:17.12
9,-7,-1:17.12
10,-7,-1:17.12
11,-7,-1:18.14
12,-7,-1:18.14
13,-7,-1:18.14
7,-6,-1:17.12
8,-6,-1:17.12
10,-6,-1:18.14
11,-6,-1:18.14
12,-6,-1:18.14
13,-6,-1:18.14
7,-5,-1:17.12
8,-5,-1:17.12
10,-5,-1:17.12
11,-5,-1:18.14
12,-5,-1:18.14
13,-5,-1:18.14
8,-4,-1:17.12
9,-4,-1:17.12
10,-4,-1:17.12
12,-4,-1:18.14
8,-3,-1:17.12
9,-3,-1:17.12
10,-3,-1:17.12
3,-2,-1:17.12
4,-2,-1:17.12
8,-2,-1:17.12
10,-2,-1:17.12
11,-2,-1:17.12
2,-1,-1:17.12
3,-1,-1:17.12
4,-1,-1:17.12
8,-1,-1:17.12
9,-1,-1:17.12
10,-1,-1:17.12
11,-1,-1:17.12
3,0,-1:17.12
4,0,-1:17.12
5,0,-1:17.12
10,0,-1:17.12
4,1,-1:17.12
5,1,-1:17.12
6,1,-1:17.12
4,2,-1:17.12
5,2,-1:17.12
12,-11,0:18.14
13,-11,0:18.14
14,-11,0:18.14
11,-10,0:17.12
12,-10,0:18.14
13,-10,0:18.14
14,-10,0:18.14
10,-9,0:17.12
11,-9,0:17.12
12,-9,0:17.12
13,-9,0:18.14
14,-9,0:18.14
15,-9,0:18.14
11,-8,0:17.12
12,-8,0:18.14
13,-8,0:18.14
14,-8,0:18.14
15,-8,0:18.14
8,-7,0:17.12
9,-7,0:17.12
10,-7,0:17.12
11,-7,0:18.14
12,-7,0:18.14
8,-6,0:17.12
10,-6,0:17.12
11,-6,0:18.14
12,-6,0:18.14
4,-5,0:17.12
5,-5,0:17.12
8,-5,0:17.12
10,-5,0:17.12
11,-5,0:18.14
12,-5,0:18.14
5,-4,0:17.12
8,-4,0:17.12
9,-4,0:17.12
10,-4,0:17.12
2,-3,0:17.12
3,-3,0:17.12
4,-3,0:17.12
7,-3,0:18.14
8,-3,0:18.14
9,-3,0:17.12
10,-3,0:17.12
2,-2,0:17.12
3,-2,0:17.12
4,-2,0:17.12
8,-2,0:18.14
9,-2,0:17.12
10,-2,0:17.12
11,-2,0:17.12
3,-1,0:17.12
4,-1,0:17.12
5,-1,0:17.12
10,-1,0:17.12
3,0,0:17.12
4,0,0:17.12
5,0,0:17.12
3,1,0:17.12
4,1,0:17.12
4,2,0:17.12
11,-10,1:17.12
12,-10,1:17.12
13,-10,1:18.14
14,-10,1:18.14
11,-9,1:17.12
12,-9,1:17.12
13,-9,1:18.14
14,-9,1:18.14
11,-8,1:17.12
12,-8,1:18.14
14,-8,1:18.14
9,-7,1:17.12
10,-7,1:17.12
8,-6,1:17.12
10,-6,1:17.12
4,-5,1:17.12
5,-5,1:17.12
8,-5,1:17.12
10,-5,1:17.12
9,-4,1:17.12
10,-4,1:17.12
3,-3,1:17.12
4,-3,1:17.12
9,-3,1:17.12
10,-3,1:17.12
2,-2,1:17.12
3,-2,1:17.12
4,-2,1:17.12
9,-2,1:17.12
10,-2,1:17.12
11,-2,1:17.12
3,-1,1:17.12
10,-1,1:17.12
4,0,1:17.12
4,1,1:17.12
5,1,1:17.12
4,2,1:17.12
5,2,1:17.12
11,-10,2:17.12
12,-10,2:17.12
11,-9,2:17.12
12,-9,2:17.12
11,-8,2:17.12
9,-7,2:17.12
10,-7,2:17.12
8,-6,2:17.12
10,-6,2:17.12
4,-5,2:17.12
5,-5,2:17.12
8,-5,2:17.12
9,-5,2:17.12
10,-5,2:17.12
9,-3,2:17.12
10,-3,2:17.12
11,-3,2:17.12
3,-2,2:17.12
4,-2,2:17.12
9,-2,2:17.12
10,-2,2:17.12
11,-2,2:17.12
3,-1,2:17.12
4,1,2:17.12
5,1,2:17.12
4,2,2:17.12
5,2,2:17.12
11,-10,3:17.12
11,-9,3:17.12
12,-9,3:17.12
6,-7,3:18.12
9,-7,3:17.12
10,-7,3:17.12
2,-6,3:18.12
3,-6,3:18.12
5,-6,3:18.12
8,-6,3:17.12
10,-6,3:17.12
4,-5,3:18.12
5,-5,3:18.12
8,-5,3:17.12
9,-5,3:17.12
10,-5,3:17.12
4,-4,3:18.12
5,-4,3:18.12
6,-4,3:18.12
7,-4,3:18.12
3,-3,3:18.12
10,-3,3:17.12
11,-3,3:17.12
3,-2,3:17.12
4,-2,3:17.12
9,-2,3:17.12
10,-2,3:17.12
11,-2,3:17.12
3,-1,3:17.12
4,1,3:17.12
5,1,3:17.12
4,2,3:17.12
5,2,3:17.12
11,-10,4:17.12
11,-9,4:17.12
12,-9,4:17.12
6,-7,4:18.12
9,-7,4:17.12
10,-7,4:17.12
3,-6,4:18.12
4,-6,4:18.12
5,-6,4:18.12
8,-6,4:17.12
9,-6,4:17.12
10,-6,4:17.12
4,-5,4:18.12
5,-5,4:18.12
8,-5,4:17.12
9,-5,4:17.12
10,-5,4:17.12
3,-4,4:18.12
4,-4,4:18.12
5,-4,4:18.12
6,-4,4:18.12
3,-3,4:18.12
10,-3,4:17.12
11,-3,4:17.12
3,-2,4:17.12
10,-2,4:17.12
11,-2,4:17.12
3,-1,4:17.12
4,1,4:17.12
5,1,4:17.12
5,2,4:17.12
18,-12,5:18.4
11,-10,5:17.12
11,-9,5:17.12
12,-9,5:17.12
6,-7,5:18.12
9,-7,5:17.12
4,-6,5:18.12
6,-6,5:18.12
8,-6,5:17.12
9,-6,5:17.12
10,-6,5:17.12
4,-5,5:18.12
5,-5,5:18.12
8,-5,5:17.12
9,-5,5:17.12
10,-5,5:17.12
3,-4,5:18.12
5,-4,5:18.12
10,-3,5:17.12
11,-3,5:17.12
3,-2,5:17.12
5,-2,5:18.12
10,-2,5:17.12
11,-2,5:17.12
3,-1,5:17.12
5,-1,5:18.12
2,0,5:18.12
4,1,5:18.12
5,1,5:17.12
4,2,5:18.12
5,2,5:18.12
7,2,5:18.12
5,3,5:18.12
4,4,5:18.12
9,-16,6:18.4
9,-14,6:18.12
10,-14,6:18.12
19,-13,6:18.4
18,-12,6:18.4
19,-12,6:18.4
16,-11,6:18.12
17,-11,6:18.4
11,-10,6:17.12
14,-10,6:18.12
11,-9,6:17.12
12,-9,6:17.12
7,-8,6:18.12
10,-8,6:18.12
3,-7,6:18.12
4,-7,6:18.12
6,-7,6:18.12
7,-7,6:18.12
1,-6,6:18.12
4,-6,6:18.12
5,-6,6:18.12
6,-6,6:18.12
7,-6,6:18.12
8,-6,6:17.12
9,-6,6:17.12
10,-6,6:17.12
1,-5,6:18.12
2,-5,6:18.12
4,-5,6:18.12
5,-5,6:18.12
9,-5,6:17.12
10,-5,6:17.12
12,-5,6:18.12
2,-4,6:18.12
3,-4,6:18.12
4,-4,6:18.12
5,-4,6:18.12
3,-3,6:18.12
5,-3,6:18.12
6,-3,6:18.12
7,-3,6:18.12
10,-3,6:17.12
11,-3,6:17.12
2,-2,6:18.12
3,-2,6:17.12
4,-2,6:18.12
5,-2,6:18.12
6,-2,6:18.12
10,-2,6:17.12
11,-2,6:17.12
0,-1,6:18.12
1,-1,6:18.12
2,-1,6:18.12
3,-1,6:17.12
4,-1,6:18.12
5,-1,6:18.12
15,-1,6:18.12
16,-1,6:18.12
-1,0,6:18.12
2,0,6:18.12
3,0,6:18.12
4,0,6:18.12
5,0,6:18.12
16,0,6:18.12
17,0,6:18.4
3,1,6:18.12
4,1,6:18.12
5,1,6:18.12
4,2,6:18.12
5,2,6:18.12
6,2,6:18.12
7,2,6:18.12
8,2,6:18.12
4,3,6:18.12
5,3,6:18.12
8,3,6:18.12
4,4,6:18.12
5,4,6:18.12
6,4,6:18.12
3,5,6:18.12
8,-17,7:18.4
8,-16,7:18.4
9,-16,7:18.4
9,-15,7:18.4
9,-14,7:18.12
10,-14,7:18.12
10,-13,7:18.12
10,-12,7:18.12
18,-12,7:18.4
19,-12,7:18.4
11,-11,7:18.12
15,-11,7:18.12
16,-11,7:18.12
17,-11,7:18.4
10,-10,7:18.12
11,-10,7:18.12
12,-10,7:18.12
13,-10,7:18.12
14,-10,7:18.12
15,-10,7:18.12
9,-9,7:18.12
10,-9,7:18.12
11,-9,7:17.12
12,-9,7:18.12
13,-9,7:18.12
14,-9,7:18.12
7,-8,7:18.12
8,-8,7:18.12
9,-8,7:18.12
10,-8,7:18.12
11,-8,7:18.12
12,-8,7:18.12
14,-8,7:18.12
4,-7,7:18.12
6,-7,7:18.12
7,-7,7:18.12
11,-7,7:18.12
12,-7,7:18.12
13,-7,7:18.12
14,-7,7:18.12
1,-6,7:18.12
4,-6,7:18.12
5,-6,7:18.12
6,-6,7:18.12
8,-6,7:17.12
9,-6,7:17.12
10,-6,7:17.12
12,-6,7:18.12
13,-6,7:18.12
1,-5,7:18.12
2,-5,7:18.12
4,-5,7:18.12
5,-5,7:18.12
9,-5,7:17.12
10,-5,7:17.12
12,-5,7:18.12
13,-5,7:18.12
2,-4,7:18.12
3,-4,7:18.12
5,-4,7:18.12
11,-4,7:18.12
12,-4,7:18.12
13,-4,7:18.12
2,-3,7:18.12
3,-3,7:18.12
6,-3,7:18.12
7,-3,7:18.12
8,-3,7:18.12
11,-3,7:17.12
12,-3,7:18.12
13,-3,7:18.12
2,-2,7:18.12
3,-2,7:18.12
4,-2,7:18.12
5,-2,7:18.12
6,-2,7:18.12
10,-2,7:17.12
11,-2,7:17.12
12,-2,7:17.12
13,-2,7:18.12
0,-1,7:18.12
1,-1,7:18.12
2,-1,7:18.12
3,-1,7:18.12
4,-1,7:18.12
10,-1,7:18.12
11,-1,7:18.12
12,-1,7:18.12
13,-1,7:18.12
14,-1,7:18.12
15,-1,7:18.12
16,-1,7:18.12
-2,0,7:18.4
-1,0,7:18.12
0,0,7:18.12
2,0,7:18.12
3,0,7:18.12
4,0,7:18.12
5,0,7:18.12
17,0,7:18.4
18,0,7:18.4
3,1,7:18.12
4,1,7:18.12
5,1,7:18.12
4,2,7:18.12
5,2,7:18.12
6,2,7:18.12
7,2,7:18.12
4,3,7:18.12
5,3,7:18.12
9,3,7:18.12
8,-17,8:18.4
8,-16,8:18.4
9,-16,8:18.4
9,-15,8:18.4
9,-14,8:18.12
10,-13,8:18.12
10,-12,8:18.12
18,-12,8:18.4
19,-12,8:18.4
11,-11,8:18.12
15,-11,8:18.12
16,-11,8:18.12
17,-11,8:18.4
10,-10,8:18.12
11,-10,8:18.12
12,-10,8:18.12
13,-10,8:18.12
14,-10,8:18.12
15,-10,8:18.12
9,-9,8:18.12
10,-9,8:18.12
11,-9,8:17.12
12,-9,8:17.12
13,-9,8:18.12
15,-9,8:18.12
8,-8,8:18.12
9,-8,8:18.12
10,-8,8:18.12
11,-8,8:18.12
12,-8,8:18.12
14,-8,8:18.12
4,-7,8:18.12
6,-7,8:18.12
7,-7,8:18.12
12,-7,8:18.12
14,-7,8:18.12
1,-6,8:18.12
4,-6,8:18.12
5,-6,8:18.12
6,-6,8:18.12
7,-6,8:18.12
8,-6,8:17.12
9,-6,8:17.12
10,-6,8:17.12
12,-6,8:18.12
13,-6,8:18.12
1,-5,8:18.12
3,-5,8:18.12
4,-5,8:18.12
5,-5,8:18.12
9,-5,8:17.12
10,-5,8:17.12
12,-5,8:18.12
13,-5,8:18.12
2,-4,8:18.12
3,-4,8:18.12
5,-4,8:18.12
6,-4,8:18.12
7,-4,8:18.12
8,-4,8:18.12
9,-4,8:18.12
10,-4,8:18.12
11,-4,8:18.12
12,-4,8:18.12
13,-4,8:18.12
2,-3,8:18.12
3,-3,8:18.12
7,-3,8:18.12
8,-3,8:18.12
9,-3,8:18.12
10,-3,8:18.12
11,-3,8:18.12
12,-3,8:18.12
13,-3,8:18.12
0,-2,8:18.12
1,-2,8:18.12
2,-2,8:18.12
3,-2,8:18.12
4,-2,8:18.12
5,-2,8:18.12
6,-2,8:18.12
10,-2,8:18.12
11,-2,8:17.12
12,-2,8:18.12
13,-2,8:18.12
1,-1,8:18.12
2,-1,8:18.12
3,-1,8:17.12
4,-1,8:18.12
10,-1,8:18.12
11,-1,8:18.12
12,-1,8:18.12
13,-1,8:18.12
14,-1,8:18.12
15,-1,8:18.12
16,-1,8:18.12
-1,0,8:18.12
0,0,8:18.12
3,0,8:18.12
4,0,8:18.12
6,0,8:18.12
10,0,8:18.12
17,0,8:18.4
18,0,8:18.4
19,0,8:18.4
20,0,8:18.4
4,1,8:18.12
5,1,8:18.12
10,1,8:18.12
4,2,8:18.12
5,2,8:18.12
9,2,8:18.12
3,3,8:18.12
6,3,8:18.12
9,3,8:18.12
9,4,8:18.12
8,5,8:18.12
4,-16,9:18.4
5,-16,9:18.4
8,-16,9:18.4
9,-16,9:18.4
5,-14,9:18.4
6,-14,9:18.4
9,-14,9:18.12
10,-13,9:18.12
10,-12,9:18.12
11,-11,9:18.12
10,-10,9:18.12
11,-10,9:18.12
12,-10,9:18.12
13,-10,9:18.12
14,-10,9:18.12
15,-10,9:18.12
10,-9,9:18.12
11,-9,9:17.12
12,-9,9:18.12
13,-9,9:18.12
15,-9,9:18.12
18,-9,9:18.4
8,-8,9:18.12
9,-8,9:18.12
10,-8,9:18.12
11,-8,9:18.12
12,-8,9:18.12
14,-8,9:18.12
7,-7,9:18.12
12,-7,9:18.12
14,-7,9:18.12
5,-6,9:18.12
8,-6,9:17.12
9,-6,9:17.12
10,-6,9:17.12
12,-6,9:18.12
13,-6,9:18.12
3,-5,9:18.12
4,-5,9:18.12
5,-5,9:18.12
6,-5,9:18.12
9,-5,9:17.12
10,-5,9:17.12
12,-5,9:18.12
13,-5,9:18.12
4,-4,9:18.12
6,-4,9:18.12
7,-4,9:18.12
8,-4,9:18.12
9,-4,9:18.12
10,-4,9:18.12
11,-4,9:18.12
12,-4,9:18.12
13,-4,9:18.12
2,-3,9:18.12
3,-3,9:18.12
10,-3,9:18.12
11,-3,9:17.12
12,-3,9:17.12
13,-3,9:18.12
-1,-2,9:18.12
0,-2,9:18.12
1,-2,9:18.12
3,-2,9:18.12
5,-2,9:18.12
10,-2,9:18.12
11,-2,9:17.12
12,-2,9:17.12
13,-2,9:18.12
1,-1,9:18.12
2,-1,9:18.12
3,-1,9:17.12
4,-1,9:18.12
7,-1,9:18.12
10,-1,9:18.12
11,-1,9:18.12
12,-1,9:18.12
13,-1,9:18.12
14,-1,9:18.12
15,-1,9:18.12
16,-1,9:18.12
3,0,9:18.12
6,0,9:18.12
10,0,9:18.12
17,0,9:18.4
18,0,9:18.4
4,1,9:18.12
5,1,9:18.12
10,1,9:18.12
3,2,9:18.12
4,2,9:18.12
5,2,9:18.12
10,2,9:18.12
12,2,9:18.12
2,3,9:18.12
3,3,9:18.12
6,3,9:18.12
9,3,9:18.12
13,3,9:18.4
7,4,9:18.12
9,4,9:18.12
9,5,9:18.12
14,5,9:18.4
8,6,9:18.4
4,-16,10:18.4
5,-16,10:18.4
5,-15,10:18.4
5,-14,10:18.4
6,-14,10:18.4
6,-12,10:18.4
7,-12,10:18.12
10,-12,10:18.12
11,-11,10:18.12
7,-10,10:18.12
8,-10,10:18.12
11,-10,10:18.12
12,-10,10:18.12
14,-10,10:18.12
19,-10,10:18.4
8,-9,10:18.12
10,-9,10:18.12
11,-9,10:17.12
12,-9,10:17.12
13,-9,10:18.12
17,-9,10:18.4
18,-9,10:18.4
19,-9,10:18.4
8,-8,10:18.12
9,-8,10:18.12
10,-8,10:18.12
11,-8,10:18.12
12,-8,10:18.12
15,-8,10:18.12
16,-8,10:18.12
7,-7,10:18.12
10,-7,10:18.12
11,-7,10:18.12
12,-7,10:18.12
13,-7,10:18.12
14,-7,10:18.12
5,-6,10:18.12
8,-6,10:17.12
9,-6,10:17.12
10,-6,10:17.12
12,-6,10:18.12
13,-6,10:18.12
16,-6,10:18.12
3,-5,10:18.12
4,-5,10:18.12
5,-5,10:18.12
6,-5,10:18.12
9,-5,10:17.12
10,-5,10:18.12
11,-5,10:18.12
13,-5,10:18.12
15,-5,10:18.12
16,-5,10:18.12
2,-4,10:18.12
3,-4,10:18.12
4,-4,10:18.12
6,-4,10:18.12
7,-4,10:18.12
8,-4,10:18.12
9,-4,10:18.12
10,-4,10:18.12
11,-4,10:18.12
12,-4,10:18.12
13,-4,10:18.12
14,-4,10:18.12
15,-4,10:18.12
3,-3,10:18.12
9,-3,10:18.12
10,-3,10:18.12
11,-3,10:17.12
12,-3,10:17.12
13,-3,10:18.12
3,-2,10:18.12
10,-2,10:18.12
11,-2,10:17.12
12,-2,10:17.12
13,-2,10:18.12
1,-1,10:18.12
2,-1,10:18.12
3,-1,10:17.12
4,-1,10:18.12
5,-1,10:18.12
7,-1,10:18.12
10,-1,10:18.12
11,-1,10:18.12
12,-1,10:18.12
13,-1,10:18.12
14,-1,10:18.12
15,-1,10:18.12
3,0,10:18.12
4,0,10:18.12
5,0,10:18.12
6,0,10:18.12
7,0,10:18.12
10,0,10:18.12
11,0,10:18.12
3,1,10:18.12
4,1,10:18.12
5,1,10:18.12
10,1,10:18.12
12,1,10:18.12
3,2,10:18.12
4,2,10:18.12
5,2,10:18.12
10,2,10:18.12
12,2,10:18.12
2,3,10:18.12
3,3,10:18.12
6,3,10:18.12
9,3,10:18.4
13,3,10:18.4
7,4,10:18.4
9,4,10:18.4
13,4,10:18.4
9,5,10:18.4
14,5,10:18.4
4,-18,11:18.4
4,-17,11:18.4
4,-16,11:18.4
5,-16,11:18.4
5,-15,11:18.4
5,-14,11:18.4
7,-12,11:18.12
12,-12,11:18.12
7,-11,11:18.12
12,-11,11:18.12
6,-10,11:18.12
7,-10,11:18.12
8,-10,11:18.12
11,-10,11:18.12
19,-10,11:18.4
8,-9,11:18.12
9,-9,11:18.12
10,-9,11:18.12
11,-9,11:17.12
12,-9,11:18.12
14,-9,11:18.12
15,-9,11:18.12
17,-9,11:18.4
18,-9,11:18.4
19,-9,11:18.4
8,-8,11:18.12
9,-8,11:18.12
10,-8,11:18.12
11,-8,11:18.12
15,-8,11:18.12
16,-8,11:18.12
7,-7,11:18.12
8,-7,11:18.12
9,-7,11:18.12
10,-7,11:18.12
11,-7,11:18.12
13,-7,11:18.12
14,-7,11:18.12
4,-6,11:18.12
5,-6,11:18.12
7,-6,11:18.12
8,-6,11:17.12
9,-6,11:17.12
10,-6,11:17.12
11,-6,11:18.12
12,-6,11:18.12
4,-5,11:18.12
5,-5,11:18.12
6,-5,11:18.12
7,-5,11:18.12
8,-5,11:18.12
9,-5,11:17.12
10,-5,11:18.12
11,-5,11:18.12
13,-5,11:18.12
15,-5,11:18.12
16,-5,11:18.12
2,-4,11:18.12
3,-4,11:18.12
4,-4,11:18.12
7,-4,11:18.12
8,-4,11:18.12
9,-4,11:18.12
10,-4,11:18.12
11,-4,11:18.12
12,-4,11:18.12
13,-4,11:18.12
14,-4,11:18.12
15,-4,11:18.12
0,-3,11:18.12
1,-3,11:18.12
3,-3,11:18.12
9,-3,11:18.12
10,-3,11:18.12
11,-3,11:18.12
12,-3,11:17.12
13,-3,11:18.12
14,-3,11:18.12
3,-2,11:18.12
10,-2,11:18.12
11,-2,11:18.12
12,-2,11:17.12
13,-2,11:18.12
-1,-1,11:18.12
2,-1,11:18.12
3,-1,11:17.12
4,-1,11:18.12
11,-1,11:18.12
12,-1,11:18.12
13,-1,11:18.12
3,0,11:18.12
4,0,11:18.12
5,0,11:18.12
6,0,11:18.12
7,0,11:18.12
11,0,11:18.12
14,0,11:18.12
3,1,11:18.12
4,1,11:18.12
5,1,11:18.12
10,1,11:18.12
12,1,11:18.12
14,1,11:18.12
3,2,11:18.12
4,2,11:18.12
5,2,11:18.12
12,2,11:18.12
2,3,11:18.12
3,3,11:18.12
6,3,11:18.12
13,3,11:18.4
13,4,11:18.4
14,5,11:18.4
14,6,11:18.4
4,-17,12:18.4
4,-16,12:18.4
5,-16,12:18.4
5,-15,12:18.4
5,-14,12:18.4
12,-14,12:18.4
12,-13,12:18.12
6,-12,12:18.4
7,-12,12:18.12
12,-12,12:18.12
7,-11,12:18.12
12,-11,12:18.12
6,-10,12:18.12
7,-10,12:18.12
8,-10,12:18.12
9,-10,12:18.12
11,-10,12:18.12
19,-10,12:18.4
20,-10,12:18.4
8,-9,12:18.12
9,-9,12:18.12
10,-9,12:18.12
11,-9,12:17.12
12,-9,12:18.12
13,-9,12:18.12
14,-9,12:18.12
15,-9,12:18.12
17,-9,12:18.4
18,-9,12:18.4
19,-9,12:18.4
8,-8,12:18.12
9,-8,12:18.12
11,-8,12:18.12
15,-8,12:18.12
16,-8,12:18.12
7,-7,12:18.12
8,-7,12:18.12
9,-7,12:18.12
10,-7,12:18.12
11,-7,12:18.12
13,-7,12:18.12
14,-7,12:18.12
7,-6,12:18.12
8,-6,12:18.12
9,-6,12:18.12
10,-6,12:18.12
11,-6,12:18.12
12,-6,12:18.12
4,-5,12:18.12
5,-5,12:18.12
6,-5,12:18.12
7,-5,12:18.12
8,-5,12:18.12
9,-5,12:18.12
10,-5,12:18.12
11,-5,12:18.12
2,-4,12:18.12
3,-4,12:18.12
4,-4,12:18.12
7,-4,12:18.12
8,-4,12:18.12
9,-4,12:18.12
10,-4,12:18.12
11,-4,12:18.12
14,-4,12:18.12
15,-4,12:18.12
0,-3,12:18.12
1,-3,12:18.12
3,-3,12:18.12
9,-3,12:18.12
10,-3,12:18.12
11,-3,12:18.12
12,-3,12:17.12
13,-3,12:18.12
14,-3,12:18.12
2,-2,12:18.12
3,-2,12:18.12
10,-2,12:18.12
11,-2,12:18.12
12,-2,12:17.12
13,-2,12:18.12
-3,-1,12:18.4
-2,-1,12:18.4
-1,-1,12:18.12
0,-1,12:18.12
1,-1,12:18.12
2,-1,12:18.12
3,-1,12:18.12
4,-1,12:18.12
10,-1,12:18.12
11,-1,12:18.12
13,-1,12:18.12
2,0,12:18.12
3,0,12:18.12
4,0,12:18.12
5,0,12:18.12
6,0,12:18.12
7,0,12:18.12
8,0,12:18.12
9,0,12:18.12
11,0,12:18.12
14,0,12:18.12
2,1,12:18.12
3,1,12:18.12
4,1,12:18.12
5,1,12:18.12
6,1,12:18.12
12,1,12:18.12
14,1,12:18.12
15,1,12:18.12
2,2,12:18.12
3,2,12:18.12
4,2,12:18.12
5,2,12:18.12
12,2,12:18.12
15,2,12:18.12
16,2,12:18.12
2,3,12:18.12
3,3,12:18.12
6,3,12:18.12
13,3,12:18.4
2,4,12:18.4
7,4,12:18.4
13,4,12:18.4
14,5,12:18.4
4,-17,13:18.4
4,-16,13:18.4
5,-16,13:18.4
12,-16,13:18.4
5,-15,13:18.4
12,-15,13:18.4
5,-14,13:18.4
12,-14,13:18.4
12,-13,13:18.12
6,-12,13:18.4
12,-12,13:18.12
7,-11,13:18.12
12,-11,13:18.12
6,-10,13:18.12
7,-10,13:18.12
8,-10,13:18.12
9,-10,13:18.12
11,-10,13:18.12
12,-10,13:18.12
19,-10,13:18.4
20,-10,13:18.4
8,-9,13:18.12
9,-9,13:18.12
10,-9,13:18.12
11,-9,13:17.12
12,-9,13:18.12
13,-9,13:18.12
14,-9,13:18.12
17,-9,13:18.4
18,-9,13:18.4
19,-9,13:18.4
8,-8,13:18.12
9,-8,13:18.12
11,-8,13:18.12
15,-8,13:18.12
16,-8,13:18.12
18,-8,13:18.4
8,-7,13:18.12
10,-7,13:18.12
11,-7,13:18.12
13,-7,13:18.12
14,-7,13:18.12
18,-7,13:18.4
4,-6,13:18.12
7,-6,13:18.12
8,-6,13:17.12
9,-6,13:17.12
10,-6,13:17.12
11,-6,13:18.12
12,-6,13:18.12
3,-5,13:18.12
5,-5,13:18.12
6,-5,13:18.12
7,-5,13:18.12
9,-5,13:17.12
10,-5,13:18.12
11,-5,13:18.12
2,-4,13:18.12
3,-4,13:18.12
4,-4,13:18.12
8,-4,13:18.12
9,-4,13:18.12
10,-4,13:18.12
11,-4,13:18.12
14,-4,13:18.12
15,-4,13:18.12
-1,-3,13:18.12
0,-3,13:18.12
1,-3,13:18.12
3,-3,13:18.12
9,-3,13:18.12
10,-3,13:18.12
11,-3,13:18.12
12,-3,13:17.12
13,-3,13:18.12
14,-3,13:18.12
2,-2,13:18.12
3,-2,13:18.12
10,-2,13:18.12
11,-2,13:18.12
12,-2,13:17.12
13,-2,13:18.12
-2,-1,13:18.4
-1,-1,13:18.12
0,-1,13:18.12
1,-1,13:18.12
2,-1,13:18.12
3,-1,13:18.12
4,-1,13:18.12
7,-1,13:18.12
10,-1,13:18.12
11,-1,13:18.12
13,-1,13:18.12
2,0,13:18.12
3,0,13:18.12
4,0,13:18.12
5,0,13:18.12
6,0,13:18.12
7,0,13:18.12
8,0,13:18.12
9,0,13:18.12
11,0,13:18.12
14,0,13:18.12
2,1,13:18.12
3,1,13:18.12
4,1,13:18.12
5,1,13:18.12
6,1,13:18.12
12,1,13:18.12
15,1,13:18.12
2,2,13:18.12
4,2,13:18.12
5,2,13:18.12
12,2,13:18.12
16,2,13:18.12
2,3,13:18.12
6,3,13:18.12
16,3,13:18.4
2,4,13:18.12
7,4,13:18.12
4,-16,14:18.4
5,-16,14:18.4
12,-16,14:18.4
12,-15,14:18.4
12,-14,14:18.4
12,-13,14:18.12
6,-12,14:18.4
12,-12,14:18.12
7,-11,14:18.12
12,-11,14:18.12
5,-10,14:18.12
6,-10,14:18.12
7,-10,14:18.12
8,-10,14:18.12
9,-10,14:18.12
10,-10,14:18.12
11,-10,14:18.12
12,-10,14:18.12
19,-10,14:18.4
8,-9,14:18.12
9,-9,14:18.12
10,-9,14:18.12
11,-9,14:17.12
12,-9,14:18.12
13,-9,14:18.12
14,-9,14:18.12
15,-9,14:18.12
17,-9,14:18.4
18,-9,14:18.4
8,-8,14:18.12
9,-8,14:18.12
10,-8,14:18.12
11,-8,14:18.12
12,-8,14:18.12
13,-8,14:18.12
14,-8,14:18.12
15,-8,14:18.12
16,-8,14:18.12
17,-8,14:18.4
18,-8,14:18.4
19,-8,14:18.4
4,-7,14:18.12
5,-7,14:18.12
8,-7,14:18.12
9,-7,14:18.12
10,-7,14:18.12
11,-7,14:18.12
13,-7,14:18.12
14,-7,14:18.12
18,-7,14:18.4
7,-6,14:18.12
8,-6,14:17.12
9,-6,14:17.12
10,-6,14:17.12
11,-6,14:18.12
12,-6,14:18.12
17,-6,14:18.12
3,-5,14:18.12
5,-5,14:18.12
6,-5,14:18.12
7,-5,14:18.12
8,-5,14:17.12
9,-5,14:17.12
10,-5,14:18.12
11,-5,14:18.12
16,-5,14:18.12
2,-4,14:18.12
3,-4,14:18.12
4,-4,14:18.12
8,-4,14:18.12
9,-4,14:18.12
10,-4,14:18.12
11,-4,14:18.12
-1,-3,14:18.12
0,-3,14:18.12
1,-3,14:18.12
3,-3,14:18.12
9,-3,14:18.12
10,-3,14:18.12
11,-3,14:18.12
12,-3,14:18.12
13,-3,14:17.12
14,-3,14:18.12
3,-2,14:18.12
10,-2,14:18.12
11,-2,14:18.12
12,-2,14:18.12
13,-2,14:18.12
-1,-1,14:18.12
0,-1,14:18.12
1,-1,14:18.12
2,-1,14:18.12
3,-1,14:18.12
4,-1,14:18.12
5,-1,14:18.12
10,-1,14:18.12
11,-1,14:18.12
13,-1,14:18.12
14,-1,14:18.12
2,0,14:18.12
3,0,14:18.12
4,0,14:18.12
5,0,14:18.12
6,0,14:18.12
9,0,14:18.12
11,0,14:18.12
14,0,14:18.12
2,1,14:18.12
3,1,14:18.12
4,1,14:18.12
5,1,14:18.12
6,1,14:18.12
8,1,14:18.12
15,1,14:18.12
3,2,14:18.12
5,2,14:18.12
12,2,14:18.12
16,2,14:18.12
3,3,14:18.12
5,3,14:18.12
12,-16,15:18.4
12,-15,15:18.4
12,-14,15:18.4
12,-13,15:18.12
12,-12,15:18.12
12,-11,15:18.12
4,-10,15:18.12
5,-10,15:18.12
6,-10,15:18.12
7,-10,15:18.12
8,-10,15:18.12
9,-10,15:18.12
10,-10,15:18.12
11,-10,15:18.12
12,-10,15:18.12
8,-9,15:18.12
10,-9,15:18.12
11,-9,15:17.12
12,-9,15:18.12
13,-9,15:18.12
8,-8,15:18.12
9,-8,15:18.12
10,-8,15:18.12
11,-8,15:18.12
12,-8,15:18.12
13,-8,15:18.12
14,-8,15:18.12
15,-8,15:18.12
16,-8,15:18.4
19,-8,15:18.4
1,-7,15:18.4
2,-7,15:18.4
3,-7,15:18.4
4,-7,15:18.12
5,-7,15:18.12
8,-7,15:18.12
9,-7,15:18.12
10,-7,15:18.12
11,-7,15:18.12
13,-7,15:18.12
14,-7,15:18.12
17,-7,15:18.12
18,-7,15:18.4
19,-7,15:18.4
7,-6,15:18.12
8,-6,15:18.12
9,-6,15:17.12
10,-6,15:17.12
11,-6,15:18.12
12,-6,15:18.12
17,-6,15:18.12
18,-6,15:18.4
5,-5,15:18.12
6,-5,15:18.12
7,-5,15:18.12
8,-5,15:18.12
9,-5,15:17.12
10,-5,15:18.12
11,-5,15:18.12
16,-5,15:18.12
2,-4,15:18.12
4,-4,15:18.12
8,-4,15:18.12
9,-4,15:18.12
10,-4,15:18.12
11,-4,15:18.12
13,-4,15:18.12
15,-4,15:18.12
4,-3,15:18.12
10,-3,15:18.12
11,-3,15:18.12
12,-3,15:18.12
13,-3,15:17.12
14,-3,15:18.12
-2,-2,15:18.4
3,-2,15:18.12
5,-2,15:18.12
10,-2,15:18.12
12,-2,15:18.12
13,-2,15:17.12
14,-2,15:18.12
-1,-1,15:18.12
0,-1,15:18.12
1,-1,15:18.12
2,-1,15:18.12
3,-1,15:18.12
5,-1,15:18.12
10,-1,15:18.12
11,-1,15:18.12
13,-1,15:18.12
14,-1,15:18.12
3,0,15:18.12
4,0,15:18.12
5,0,15:18.12
6,0,15:18.12
7,0,15:18.12
8,0,15:18.12
9,0,15:18.12
10,0,15:18.12
14,0,15:18.12
3,1,15:18.12
4,1,15:18.12
5,1,15:18.12
6,1,15:18.12
8,1,15:18.12
15,1,15:18.12
3,2,15:18.12
5,2,15:18.12
16,2,15:18.12
3,3,15:18.12
5,3,15:18.12
17,3,15:18.4
5,4,15:18.12
12,-14,16:18.4
12,-13,16:18.12
12,-12,16:18.12
10,-11,16:18.12
12,-11,16:18.12
5,-10,16:18.12
6,-10,16:18.12
7,-10,16:18.12
8,-10,16:18.12
9,-10,16:18.12
10,-10,16:18.12
11,-10,16:18.12
12,-10,16:18.12
8,-9,16:18.12
10,-9,16:18.12
11,-9,16:17.12
12,-9,16:18.12
13,-9,16:18.12
14,-9,16:18.12
8,-8,16:18.12
9,-8,16:18.12
10,-8,16:18.12
11,-8,16:18.12
12,-8,16:18.12
13,-8,16:18.12
14,-8,16:18.12
15,-8,16:18.12
16,-8,16:18.4
19,-8,16:18.4
1,-7,16:18.4
2,-7,16:18.4
3,-7,16:18.4
4,-7,16:18.12
5,-7,16:18.12
6,-7,16:18.12
8,-7,16:18.12
9,-7,16:18.12
10,-7,16:18.12
11,-7,16:18.12
13,-7,16:18.12
14,-7,16:18.12
17,-7,16:18.12
18,-7,16:18.4
19,-7,16:18.4
7,-6,16:18.12
8,-6,16:18.12
9,-6,16:17.12
10,-6,16:17.12
11,-6,16:18.12
17,-6,16:18.12
18,-6,16:18.4
4,-5,16:18.12
5,-5,16:18.12
6,-5,16:18.12
7,-5,16:18.12
8,-5,16:18.12
9,-5,16:17.12
10,-5,16:18.12
11,-5,16:18.12
16,-5,16:18.12
4,-4,16:18.12
10,-4,16:18.12
11,-4,16:18.12
12,-4,16:18.12
13,-4,16:18.12
15,-4,16:18.12
16,-4,16:18.12
4,-3,16:18.12
10,-3,16:18.12
11,-3,16:18.12
12,-3,16:18.12
13,-3,16:17.12
14,-3,16:18.12
15,-3,16:18.12
-3,-2,16:18.4
3,-2,16:18.12
10,-2,16:18.12
11,-2,16:18.12
12,-2,16:18.12
13,-2,16:17.12
14,-2,16:18.12
-2,-1,16:18.4
-1,-1,16:18.12
0,-1,16:18.12
1,-1,16:18.12
3,-1,16:18.12
10,-1,16:18.12
11,-1,16:18.12
12,-1,16:18.12
13,-1,16:18.12
14,-1,16:18.12
2,0,16:18.12
3,0,16:18.12
4,0,16:18.12
5,0,16:18.12
6,0,16:18.12
7,0,16:18.12
8,0,16:18.12
9,0,16:18.12
10,0,16:18.12
14,0,16:18.12
15,0,16:18.12
3,1,16:18.12
4,1,16:18.12
5,1,16:18.12
8,1,16:18.12
9,1,16:18.12
15,1,16:18.12
16,1,16:18.12
3,2,16:18.12
4,2,16:18.12
5,2,16:18.12
7,2,16:18.12
8,2,16:18.12
16,2,16:18.12
17,2,16:18.12
2,3,16:18.12
3,3,16:18.12
7,3,16:18.12
17,3,16:18.4
18,4,16:18.4
10,-13,17:18.12
12,-13,17:18.12
10,-12,17:18.12
12,-12,17:18.12
10,-11,17:18.12
12,-11,17:18.12
7,-10,17:18.12
8,-10,17:18.12
9,-10,17:18.12
10,-10,17:18.12
11,-10,17:18.12
12,-10,17:18.12
10,-9,17:18.12
11,-9,17:17.12
12,-9,17:18.12
13,-9,17:18.12
14,-9,17:18.12
15,-9,17:18.12
9,-8,17:18.12
10,-8,17:18.12
11,-8,17:18.12
12,-8,17:18.12
13,-8,17:18.12
14,-8,17:18.12
2,-7,17:18.4
3,-7,17:18.4
4,-7,17:18.12
6,-7,17:18.12
9,-7,17:18.12
10,-7,17:18.12
11,-7,17:18.12
18,-7,17:18.4
19,-7,17:18.4
6,-6,17:18.12
7,-6,17:18.12
8,-6,17:18.12
9,-6,17:17.12
10,-6,17:17.12
11,-6,17:18.12
17,-6,17:18.12
18,-6,17:18.4
4,-5,17:18.12
9,-5,17:17.12
10,-5,17:18.12
11,-5,17:18.12
12,-5,17:18.12
13,-5,17:18.12
14,-5,17:18.12
16,-5,17:18.12
17,-5,17:18.12
18,-5,17:18.4
4,-4,17:18.12
9,-4,17:18.12
10,-4,17:18.12
12,-4,17:18.12
13,-4,17:18.12
15,-4,17:18.12
16,-4,17:18.12
4,-3,17:18.12
12,-3,17:18.12
13,-3,17:17.12
14,-3,17:18.12
15,-3,17:18.12
-3,-2,17:18.4
3,-2,17:18.12
11,-2,17:18.12
12,-2,17:18.12
13,-2,17:17.12
14,-2,17:18.12
-2,-1,17:18.4
-1,-1,17:18.12
0,-1,17:18.12
1,-1,17:18.12
3,-1,17:18.12
9,-1,17:18.12
11,-1,17:18.12
12,-1,17:18.12
13,-1,17:18.12
14,-1,17:18.12
2,0,17:18.12
3,0,17:17.12
4,0,17:18.12
5,0,17:18.12
6,0,17:18.12
7,0,17:18.12
8,0,17:18.12
10,0,17:18.12
14,0,17:18.12
15,0,17:18.12
3,1,17:18.12
4,1,17:18.12
5,1,17:18.12
8,1,17:18.12
9,1,17:18.12
15,1,17:18.12
16,1,17:18.12
4,2,17:18.12
5,2,17:18.12
6,2,17:18.12
8,2,17:18.12
16,2,17:18.12
17,2,17:18.12
7,3,17:18.12
10,-14,18:18.4
12,-14,18:18.4
10,-13,18:18.12
12,-13,18:18.12
10,-12,18:18.12
12,-12,18:18.12
10,-11,18:18.12
11,-11,18:18.12
7,-10,18:18.12
8,-10,18:18.12
9,-10,18:18.12
10,-10,18:18.12
11,-10,18:18.12
10,-9,18:18.12
11,-9,18:17.12
12,-9,18:18.12
13,-9,18:18.12
14,-9,18:18.12
15,-9,18:18.12
9,-8,18:18.12
10,-8,18:18.12
11,-8,18:18.12
4,-7,18:18.12
5,-7,18:18.12
6,-7,18:18.12
9,-7,18:18.12
10,-7,18:18.12
11,-7,18:18.12
6,-6,18:18.12
7,-6,18:18.12
8,-6,18:18.12
9,-6,18:18.12
10,-6,18:17.12
11,-6,18:18.12
18,-6,18:18.4
20,-6,18:18.4
4,-5,18:18.12
9,-5,18:17.12
10,-5,18:18.12
11,-5,18:18.12
12,-5,18:18.12
13,-5,18:18.12
14,-5,18:18.12
17,-5,18:18.12
18,-5,18:18.4
19,-5,18:18.4
4,-4,18:18.12
9,-4,18:18.12
10,-4,18:18.12
12,-4,18:18.12
13,-4,18:18.12
15,-4,18:18.12
16,-4,18:18.12
17,-4,18:18.12
4,-3,18:18.12
9,-3,18:18.12
12,-3,18:18.12
13,-3,18:17.12
14,-3,18:18.12
15,-3,18:18.12
12,-2,18:18.12
13,-2,18:17.12
14,-2,18:18.12
3,-1,18:18.12
9,-1,18:18.12
11,-1,18:18.12
12,-1,18:18.12
13,-1,18:18.12
14,-1,18:18.12
2,0,18:18.12
3,0,18:17.12
4,0,18:18.12
8,0,18:18.12
10,0,18:18.12
15,0,18:18.12
2,1,18:18.12
5,1,18:17.12
9,1,18:18.12
15,1,18:18.12
1,2,18:18.12
8,2,18:18.12
7,3,18:18.12
12,-16,19:18.4
12,-15,19:18.4
12,-14,19:18.4
10,-13,19:18.12
12,-13,19:18.12
10,-12,19:18.12
11,-12,19:18.12
12,-12,19:18.12
5,-11,19:18.4
6,-11,19:18.4
11,-11,19:18.12
7,-10,19:18.12
8,-10,19:18.12
9,-10,19:18.12
10,-10,19:18.12
11,-10,19:18.12
10,-9,19:18.12
11,-9,19:17.12
12,-9,19:18.12
13,-9,19:18.12
14,-9,19:18.12
15,-9,19:18.12
9,-8,19:18.12
10,-8,19:18.12
11,-8,19:18.12
16,-8,19:18.4
5,-7,19:18.12
6,-7,19:18.12
9,-7,19:18.12
10,-7,19:18.12
11,-7,19:18.12
6,-6,19:18.12
7,-6,19:18.12
8,-6,19:18.12
9,-6,19:18.12
10,-6,19:17.12
11,-6,19:18.12
19,-6,19:18.4
20,-6,19:18.4
9,-5,19:17.12
10,-5,19:18.12
11,-5,19:18.12
12,-5,19:18.12
13,-5,19:18.12
14,-5,19:18.12
17,-5,19:18.12
18,-5,19:18.4
19,-5,19:18.4
9,-4,19:18.12
10,-4,19:18.12
12,-4,19:18.12
13,-4,19:18.12
15,-4,19:18.12
16,-4,19:18.12
17,-4,19:18.12
1,-3,19:18.12
9,-3,19:18.12
12,-3,19:18.12
13,-3,19:18.12
14,-3,19:18.12
15,-3,19:18.12
1,-2,19:18.12
12,-2,19:18.12
13,-2,19:18.12
14,-2,19:17.12
2,-1,19:18.12
4,-1,19:18.12
5,-1,19:18.12
8,-1,19:18.12
9,-1,19:18.12
11,-1,19:18.12
12,-1,19:18.12
13,-1,19:18.12
14,-1,19:18.12
2,0,19:18.12
3,0,19:18.12
8,0,19:18.12
10,0,19:18.12
11,0,19:18.12
15,0,19:18.12
2,1,19:18.12
4,1,19:18.12
8,1,19:18.12
15,1,19:18.12
1,2,19:18.12
4,2,19:18.12
5,2,19:18.12
8,2,19:18.12
16,2,19:18.12
12,-17,20:18.4
12,-16,20:18.4
12,-15,20:18.4
10,-14,20:18.4
12,-14,20:18.4
10,-13,20:18.12
12,-13,20:18.12
10,-12,20:18.12
11,-12,20:18.12
12,-12,20:18.12
5,-11,20:18.4
6,-11,20:18.4
10,-11,20:18.12
11,-11,20:18.12
7,-10,20:18.12
8,-10,20:18.12
9,-10,20:18.12
10,-10,20:18.12
11,-10,20:18.12
10,-9,20:18.12
11,-9,20:17.12
12,-9,20:18.12
13,-9,20:18.12
14,-9,20:18.12
9,-8,20:18.12
10,-8,20:18.12
11,-8,20:18.12
1,-7,20:18.4
9,-7,20:18.12
10,-7,20:18.12
11,-7,20:18.12
22,-7,20:18.4
6,-6,20:18.12
7,-6,20:18.12
8,-6,20:18.12
9,-6,20:18.12
10,-6,20:17.12
11,-6,20:18.12
19,-6,20:18.4
20,-6,20:18.4
9,-5,20:17.12
10,-5,20:18.12
11,-5,20:18.12
12,-5,20:18.12
13,-5,20:18.12
15,-5,20:18.12
18,-5,20:18.4
19,-5,20:18.4
9,-4,20:18.12
10,-4,20:18.12
12,-4,20:18.12
16,-4,20:18.12
17,-4,20:18.12
18,-4,20:18.4
0,-3,20:18.12
1,-3,20:18.12
9,-3,20:18.12
13,-3,20:18.12
14,-3,20:18.12
15,-3,20:18.12
1,-2,20:18.12
13,-2,20:17.12
14,-2,20:17.12
2,-1,20:18.12
4,-1,20:18.12
5,-1,20:18.12
9,-1,20:18.12
12,-1,20:18.12
13,-1,20:18.12
14,-1,20:18.12
2,0,20:18.12
3,0,20:18.12
4,0,20:18.12
8,0,20:18.12
11,0,20:18.12
15,0,20:18.12
2,1,20:18.12
3,1,20:18.12
4,1,20:18.12
8,1,20:18.12
10,1,20:18.12
15,1,20:18.12
16,1,20:18.12
1,2,20:18.12
4,2,20:18.12
5,2,20:18.12
8,2,20:18.12
16,2,20:18.12
5,3,20:18.12
17,3,20:18.4
18,4,20:18.4
12,-16,21:18.4
12,-15,21:18.4
10,-14,21:18.4
12,-14,21:18.4
10,-13,21:18.12
12,-13,21:18.12
10,-12,21:18.12
12,-12,21:18.12
5,-11,21:18.4
6,-11,21:18.4
10,-11,21:18.12
11,-11,21:18.12
7,-10,21:18.12
8,-10,21:18.12
9,-10,21:18.12
10,-10,21:18.12
11,-10,21:18.12
10,-9,21:18.12
11,-9,21:17.12
12,-9,21:18.12
14,-9,21:18.12
9,-8,21:18.12
11,-8,21:18.12
-1,-7,21:18.4
0,-7,21:18.4
1,-7,21:18.4
2,-7,21:18.4
3,-7,21:18.4
9,-7,21:18.12
11,-7,21:18.12
21,-7,21:18.4
7,-6,21:18.12
8,-6,21:18.12
9,-6,21:18.12
10,-6,21:17.12
11,-6,21:18.12
20,-6,21:18.4
9,-5,21:17.12
10,-5,21:18.12
11,-5,21:18.12
12,-5,21:18.12
13,-5,21:18.12
14,-5,21:18.12
15,-5,21:18.12
16,-5,21:18.12
17,-5,21:18.12
19,-5,21:18.4
9,-4,21:18.12
10,-4,21:18.12
13,-4,21:18.12
16,-4,21:18.12
17,-4,21:18.12
18,-4,21:18.4
0,-3,21:18.12
9,-3,21:18.12
13,-3,21:18.12
14,-3,21:18.12
15,-3,21:18.12
16,-3,21:18.12
1,-2,21:18.12
13,-2,21:18.12
14,-2,21:17.12
2,-1,21:18.12
4,-1,21:18.12
5,-1,21:18.12
8,-1,21:18.12
9,-1,21:18.12
12,-1,21:18.12
13,-1,21:18.12
14,-1,21:18.12
15,-1,21:18.12
2,0,21:18.12
3,0,21:18.12
4,0,21:18.12
8,0,21:18.12
11,0,21:18.12
12,0,21:18.12
15,0,21:18.12
2,1,21:18.12
3,1,21:18.12
8,1,21:18.12
10,1,21:18.12
16,1,21:18.12
8,2,21:18.12
9,2,21:18.12
17,2,21:18.12
8,3,21:18.12
17,3,21:18.4
18,4,21:18.4
10,-15,22:18.4
10,-14,22:18.4
10,-13,22:18.12
10,-12,22:18.12
5,-11,22:18.4
10,-11,22:18.12
11,-11,22:18.12
9,-10,22:18.12
10,-10,22:18.12
11,-10,22:18.12
10,-9,22:18.12
11,-9,22:17.12
9,-8,22:18.12
10,-8,22:18.12
11,-8,22:18.12
-1,-7,22:18.4
0,-7,22:18.4
1,-7,22:18.4
2,-7,22:18.4
7,-7,22:18.12
8,-7,22:18.12
9,-7,22:18.12
10,-7,22:18.12
11,-7,22:18.12
21,-7,22:18.4
2,-6,22:18.4
3,-6,22:18.4
4,-6,22:18.12
5,-6,22:18.12
6,-6,22:18.12
7,-6,22:18.12
8,-6,22:18.12
9,-6,22:17.12
10,-6,22:17.12
11,-6,22:18.12
20,-6,22:18.4
21,-6,22:18.4
7,-5,22:18.12
9,-5,22:17.12
10,-5,22:17.12
11,-5,22:18.12
12,-5,22:18.12
13,-5,22:18.12
14,-5,22:18.12
15,-5,22:18.12
16,-5,22:18.12
17,-5,22:18.12
18,-5,22:18.4
19,-5,22:18.4
8,-4,22:18.12
9,-4,22:18.12
10,-4,22:18.12
11,-4,22:18.12
12,-4,22:18.12
13,-4,22:18.12
16,-4,22:18.12
17,-4,22:18.12
21,-4,22:18.4
8,-3,22:18.12
9,-3,22:18.12
13,-3,22:18.12
14,-3,22:18.12
15,-3,22:18.12
16,-3,22:18.12
8,-2,22:18.12
14,-2,22:18.12
3,-1,22:18.12
8,-1,22:18.12
9,-1,22:18.12
12,-1,22:18.12
13,-1,22:18.12
14,-1,22:18.12
15,-1,22:18.12
3,0,22:18.12
4,0,22:18.12
7,0,22:18.12
8,0,22:18.12
11,0,22:18.12
12,0,22:18.12
15,0,22:18.12
16,0,22:18.12
0,1,22:18.12
1,1,22:18.12
2,1,22:18.12
3,1,22:18.12
7,1,22:18.12
8,1,22:18.12
10,1,22:18.12
16,1,22:18.12
3,2,22:18.12
7,2,22:18.12
8,2,22:18.12
9,2,22:18.12
17,2,22:18.12
7,3,22:18.12
8,3,22:18.12
17,3,22:18.4
18,4,22:18.4
10,-15,23:18.4
10,-14,23:18.4
10,-13,23:18.4
10,-12,23:18.4
10,-11,23:18.4
13,-11,23:18.4
10,-10,23:18.12
11,-10,23:18.12
12,-10,23:18.12
10,-9,23:18.12
11,-9,23:17.12
9,-8,23:18.12
10,-8,23:18.12
12,-8,23:18.12
13,-8,23:18.12
-3,-7,23:18.4
-2,-7,23:18.4
-1,-7,23:18.4
0,-7,23:18.4
1,-7,23:18.4
7,-7,23:18.12
8,-7,23:18.12
9,-7,23:18.12
10,-7,23:18.12
11,-7,23:18.12
13,-7,23:18.12
2,-6,23:18.4
3,-6,23:18.4
4,-6,23:18.12
5,-6,23:18.12
6,-6,23:18.12
7,-6,23:18.12
8,-6,23:17.12
9,-6,23:17.12
10,-6,23:17.12
11,-6,23:18.12
7,-5,23:18.12
9,-5,23:17.12
10,-5,23:17.12
11,-5,23:18.12
12,-5,23:18.12
13,-5,23:18.12
14,-5,23:18.12
15,-5,23:18.4
16,-5,23:18.4
17,-5,23:18.4
18,-5,23:18.4
19,-5,23:18.4
8,-4,23:18.12
9,-4,23:18.12
10,-4,23:18.12
11,-4,23:18.12
13,-4,23:18.12
20,-4,23:18.4
8,-3,23:18.12
9,-3,23:18.12
14,-3,23:18.12
15,-3,23:18.4
16,-3,23:18.4
8,-2,23:18.12
14,-2,23:18.12
15,-2,23:17.12
3,-1,23:18.4
8,-1,23:18.12
13,-1,23:18.12
15,-1,23:18.4
3,0,23:18.4
4,0,23:18.4
5,0,23:18.4
7,0,23:18.4
8,0,23:18.4
11,0,23:18.4
12,0,23:18.4
1,1,23:18.4
2,1,23:18.4
3,1,23:18.4
7,1,23:18.4
10,1,23:18.4
11,1,23:18.4
16,1,23:18.4
7,2,23:18.4
9,2,23:18.4
17,2,23:18.4
7,3,23:18.4
8,3,23:18.4
18,3,23:18.4
18,4,23:18.4
10,-16,24:18.4
10,-15,24:18.4
10,-14,24:18.4
10,-13,24:18.4
10,-12,24:18.4
14,-12,24:18.4
10,-11,24:18.4
13,-11,24:18.4
14,-11,24:18.4
10,-10,24:18.12
11,-10,24:18.12
12,-10,24:18.12
10,-9,24:18.12
11,-9,24:18.12
9,-8,24:18.12
10,-8,24:18.12
12,-8,24:18.12
13,-8,24:18.4
-2,-7,24:18.4
-1,-7,24:18.4
0,-7,24:18.4
7,-7,24:18.12
8,-7,24:18.12
9,-7,24:18.12
10,-7,24:18.12
13,-7,24:18.4
14,-7,24:18.4
1,-6,24:18.4
2,-6,24:18.4
3,-6,24:18.4
4,-6,24:18.12
5,-6,24:18.12
6,-6,24:18.12
7,-6,24:18.12
8,-6,24:17.12
9,-6,24:17.12
10,-6,24:17.12
11,-6,24:18.12
14,-6,24:18.4
7,-5,24:18.12
8,-5,24:18.12
9,-5,24:17.12
10,-5,24:17.12
11,-5,24:18.12
12,-5,24:18.12
13,-5,24:18.4
14,-5,24:18.4
15,-5,24:18.4
16,-5,24:18.4
17,-5,24:18.4
18,-5,24:18.4
19,-5,24:18.4
8,-4,24:18.12
9,-4,24:18.12
10,-4,24:18.12
8,-3,24:18.12
9,-3,24:18.12
14,-3,24:18.4
15,-3,24:18.4
16,-3,24:18.4
8,-2,24:18.12
14,-2,24:17.12
15,-2,24:17.12
8,-1,24:18.4
13,-1,24:18.4
15,-1,24:18.4
8,0,24:18.4
3,1,24:17.12
7,1,24:18.4
11,1,24:18.4
7,2,24:18.4
9,2,24:18.4
7,3,24:18.4
7,4,24:18.4
10,-15,25:18.4
10,-14,25:18.4
10,-13,25:18.4
10,-12,25:18.4
14,-12,25:18.4
15,-12,25:18.4
10,-11,25:18.4
13,-11,25:18.4
14,-11,25:18.4
10,-10,25:18.12
11,-10,25:18.12
12,-10,25:18.12
10,-9,25:18.12
11,-9,25:18.12
9,-8,25:18.12
10,-8,25:18.12
12,-8,25:18.12
13,-8,25:18.4
-1,-7,25:18.4
8,-7,25:18.12
9,-7,25:18.12
10,-7,25:18.12
13,-7,25:18.4
14,-7,25:18.4
2,-6,25:18.4
3,-6,25:18.4
4,-6,25:18.12
5,-6,25:18.12
6,-6,25:18.12
7,-6,25:18.12
9,-6,25:17.12
10,-6,25:17.12
11,-6,25:18.12
14,-6,25:18.4
7,-5,25:18.12
8,-5,25:18.12
9,-5,25:17.12
10,-5,25:17.12
11,-5,25:18.12
12,-5,25:18.12
13,-5,25:18.4
14,-5,25:18.4
15,-5,25:18.4
16,-5,25:18.4
8,-4,25:18.12
9,-4,25:18.12
10,-4,25:18.12
15,-4,25:18.4
8,-3,25:18.12
9,-3,25:18.12
15,-3,25:18.4
8,-2,25:18.12
14,-2,25:17.12
15,-2,25:17.12
16,-2,25:18.4
17,-2,25:18.4
18,-2,25:18.4
19,-2,25:18.4
8,-1,25:18.4
20,-1,25:18.4
21,-1,25:18.4
8,0,25:18.4
3,1,25:17.12
7,1,25:18.4
7,2,25:18.4
7,3,25:18.4
10,-13,26:18.4
10,-11,26:18.4
10,-10,26:18.12
11,-10,26:18.12
12,-10,26:18.12
10,-9,26:18.12
11,-9,26:18.12
2,-8,26:18.4
10,-8,26:18.12
12,-8,26:18.12
3,-7,26:18.4
4,-7,26:18.12
8,-7,26:18.12
9,-7,26:18.12
10,-7,26:18.12
5,-6,26:18.12
6,-6,26:18.12
7,-6,26:18.12
8,-6,26:18.12
9,-6,26:17.12
10,-6,26:18.12
11,-6,26:18.12
15,-6,26:18.4
8,-5,26:18.12
9,-5,26:17.12
10,-5,26:18.12
11,-5,26:18.12
12,-5,26:18.12
13,-5,26:18.4
14,-5,26:18.4
15,-5,26:18.4
8,-4,26:18.12
9,-4,26:18.12
10,-4,26:18.12
15,-4,26:18.4
8,-3,26:18.12
9,-3,26:18.12
15,-3,26:18.4
8,-2,26:18.12
12,-2,26:18.12
13,-2,26:18.4
14,-2,26:18.4
15,-2,26:17.12
16,-2,26:18.4
17,-2,26:18.4
18,-2,26:18.4
19,-2,26:18.4
8,-1,26:18.4
15,-1,26:18.4
20,-1,26:18.4
21,-1,26:18.4
8,0,26:18.4
15,0,26:18.4
3,1,26:17.12
7,1,26:18.4
14,1,26:18.4
11,-12,27:18.4
10,-10,27:18.12
13,-10,27:18.4
10,-9,27:18.12
11,-9,27:18.12
12,-9,27:18.12
2,-8,27:18.4
10,-8,27:18.12
3,-7,27:18.4
4,-7,27:18.12
5,-7,27:18.12
9,-7,27:18.12
10,-7,27:18.12
12,-7,27:18.12
15,-7,27:18.4
5,-6,27:18.12
6,-6,27:18.12
7,-6,27:18.12
8,-6,27:18.12
9,-6,27:17.12
10,-6,27:18.12
11,-6,27:18.12
15,-6,27:18.4
8,-5,27:18.12
9,-5,27:17.12
10,-5,27:17.12
11,-5,27:18.12
13,-5,27:18.4
14,-5,27:18.4
15,-5,27:18.4
16,-5,27:18.4
8,-4,27:18.12
9,-4,27:18.12
15,-4,27:18.4
8,-3,27:18.12
9,-3,27:18.12
15,-3,27:18.4
8,-2,27:18.12
10,-2,27:18.12
11,-2,27:18.12
12,-2,27:18.12
13,-2,27:18.4
14,-2,27:18.4
15,-2,27:17.12
16,-2,27:18.4
17,-2,27:18.4
18,-2,27:18.4
19,-2,27:18.4
9,-1,27:18.4
15,-1,27:18.4
20,-1,27:18.4
21,-1,27:18.4
8,0,27:18.4
15,0,27:18.4
15,1,27:18.4
15,2,27:18.4
11,-13,28:18.4
10,-12,28:18.4
11,-12,28:18.4
11,-11,28:18.4
10,-10,28:18.12
11,-10,28:18.12
12,-10,28:18.12
13,-10,28:18.4
8,-9,28:18.12
9,-9,28:18.12
10,-9,28:18.12
11,-9,28:18.12
12,-9,28:18.12
-1,-8,28:18.4
0,-8,28:18.4
1,-8,28:18.4
2,-8,28:18.4
10,-8,28:18.12
11,-8,28:18.12
12,-8,28:18.12
3,-7,28:18.4
4,-7,28:18.12
5,-7,28:18.12
6,-7,28:18.12
12,-7,28:18.12
6,-6,28:18.12
7,-6,28:18.12
8,-6,28:18.12
9,-6,28:17.12
10,-6,28:18.12
12,-6,28:18.12
15,-6,28:18.4
9,-5,28:17.12
13,-5,28:18.4
14,-5,28:18.4
15,-5,28:18.4
16,-5,28:18.4
17,-5,28:18.4
9,-4,28:18.12
15,-4,28:18.4
9,-3,28:18.12
15,-3,28:18.4
10,-2,28:18.12
11,-2,28:18.12
12,-2,28:18.12
13,-2,28:18.4
14,-2,28:18.4
15,-2,28:17.0
16,-2,28:18.4
17,-2,28:18.4
9,-1,28:18.4
15,-1,28:18.4
8,0,28:18.4
15,0,28:18.4
15,1,28:18.4
15,2,28:18.4
11,-14,29:18.4
10,-13,29:18.4
11,-13,29:18.4
10,-12,29:18.4
11,-12,29:18.4
11,-11,29:18.4
10,-10,29:18.4
11,-10,29:18.4
-2,-9,29:18.4
8,-9,29:18.4
9,-9,29:18.4
10,-9,29:18.4
11,-9,29:18.4
-1,-8,29:18.4
0,-8,29:18.4
1,-8,29:18.4
2,-8,29:18.4
10,-8,29:18.4
11,-8,29:18.4
5,-7,29:18.4
6,-7,29:18.4
10,-7,29:18.4
12,-7,29:18.4
6,-6,29:18.4
7,-6,29:18.4
8,-6,29:18.4
9,-6,29:17.12
10,-6,29:18.4
11,-6,29:18.4
12,-6,29:18.4
9,-5,29:17.12
12,-5,29:18.4
13,-5,29:18.4
14,-5,29:18.4
15,-5,29:18.4
16,-5,29:18.4
17,-5,29:18.4
18,-5,29:18.4
19,-5,29:18.4
9,-4,29:18.4
9,-3,29:18.4
10,-2,29:18.4
12,-2,29:18.4
14,-2,29:18.4
15,-2,29:18.4
16,-2,29:17.0
8,-1,29:18.4
9,-1,29:18.4
15,-1,29:18.4
8,0,29:18.4
8,2,29:18.4
12,-15,30:18.4
11,-14,30:18.4
11,-13,30:18.4
10,-10,30:18.4
10,-9,30:18.4
11,-9,30:17.12
-1,-8,30:18.4
1,-8,30:18.4
2,-8,30:18.4
10,-8,30:18.4
3,-7,30:18.4
4,-7,30:18.4
5,-7,30:18.4
6,-7,30:18.4
10,-7,30:18.4
6,-6,30:18.4
7,-6,30:18.4
8,-6,30:18.4
9,-6,30:17.12
10,-6,30:18.4
11,-6,30:18.4
12,-6,30:18.4
9,-5,30:18.4
12,-5,30:18.4
13,-5,30:18.4
16,-5,30:18.4
17,-5,30:18.4
18,-5,30:18.4
19,-5,30:18.4
9,-4,30:18.4
17,-4,30:18.4
9,-3,30:18.4
14,-3,30:18.4
16,-3,30:18.4
15,-2,30:18.4
16,-2,30:18.4
8,-1,30:18.4
17,-1,30:18.4
8,0,30:18.4
15,0,30:18.4
18,0,30:18.4
8,1,30:18.4
11,-14,31:18.4
11,-13,31:18.4
11,-12,31:18.4
11,-11,31:18.4
10,-10,31:18.4
-3,-9,31:18.4
-2,-9,31:18.4
10,-9,31:18.4
11,-9,31:17.0
-1,-8,31:18.4
0,-8,31:18.4
1,-8,31:18.4
2,-8,31:18.4
10,-8,31:18.4
3,-7,31:18.4
4,-7,31:18.4
5,-7,31:18.4
6,-7,31:18.4
10,-7,31:18.4
6,-6,31:18.4
7,-6,31:18.4
8,-6,31:18.4
9,-6,31:17.0
10,-6,31:18.4
11,-6,31:18.4
12,-6,31:18.4
9,-5,31:18.4
12,-5,31:18.4
13,-5,31:18.4
14,-5,31:18.4
15,-5,31:18.4
16,-5,31:18.4
17,-5,31:18.4
18,-5,31:18.4
19,-5,31:18.4
9,-4,31:18.4
17,-4,31:18.4
20,-4,31:18.4
21,-4,31:18.4
9,-3,31:18.4
14,-3,31:18.4
16,-3,31:18.4
15,-2,31:18.4
16,-2,31:18.4
8,-1,31:18.4
15,-1,31:18.4
16,-1,31:18.4
17,-1,31:18.4
18,-1,31:18.4
8,0,31:18.4
15,0,31:18.4
18,0,31:18.4
19,0,31:18.4
8,1,31:18.4
14,1,31:18.4
12,-16,32:18.4
12,-15,32:18.4
11,-12,32:18.4
11,-11,32:18.4
10,-10,32:18.4
-3,-9,32:18.4
-2,-9,32:18.4
10,-9,32:18.4
11,-9,32:17.0
-1,-8,32:18.4
0,-8,32:18.4
1,-8,32:18.4
2,-8,32:18.4
10,-8,32:18.4
3,-7,32:18.4
4,-7,32:18.4
5,-7,32:18.4
10,-7,32:18.4
7,-6,32:18.4
8,-6,32:18.4
9,-6,32:17.0
10,-6,32:18.4
11,-6,32:18.4
12,-6,32:18.4
9,-5,32:18.4
12,-5,32:18.4
13,-5,32:18.4
14,-5,32:18.4
15,-5,32:18.4
16,-5,32:18.4
17,-5,32:18.4
18,-5,32:18.4
19,-5,32:18.4
16,-2,32:18.4
16,-1,32:18.4
17,-1,32:18.4
15,0,32:18.4
14,1,32:18.4
15,1,32:18.4
14,2,32:18.4
11,-14,33:18.4
11,-13,33:18.4
11,-12,33:18.4
11,-11,33:18.4
10,-10,33:18.4
-2,-9,33:18.4
-1,-8,33:18.4
10,-8,33:18.4
3,-7,33:18.4
10,-7,33:18.4
7,-6,33:18.4
8,-6,33:18.4
9,-6,33:17.0
10,-6,33:18.4
11,-6,33:18.4
12,-6,33:18.4
9,-5,33:18.4
15,-5,33:18.4
16,-5,33:18.4
9,-4,33:18.4
16,-2,33:17.0
11,-12,34:18.4
10,-8,34:18.4
10,-7,34:18.4
7,-6,34:18.4
8,-6,34:18.4
9,-6,34:17.0
10,-6,34:18.4
11,-6,34:18.4
9,-5,34:17.0
9,-4,34:18.4
17,-2,34:17.0
9,-6,35:17.0
9,-5,35:17.0
6,-3,35:18.4
7,-3,35:18.4
17,-2,35:17.0
6,-11,36:18.4
6,-10,36:18.4
7,-9,36:18.4
12,-8,36:18.4
8,-7,36:18.4
11,-7,36:18.4
9,-6,36:17.0
10,-6,36:18.4
8,-5,36:18.4
9,-5,36:17.0
10,-5,36:18.4
7,-4,36:18.4
8,-4,36:18.4
11,-4,36:18.4
6,-3,36:18.4
7,-3,36:18.4
12,-3,36:18.4
5,-2,36:18.4
6,-2,36:18.4
13,-2,36:18.4
5,-1,36:18.4
4,-13,37:18.4
5,-12,37:18.4
6,-11,37:18.4
6,-10,37:18.4
7,-9,37:18.4
13,-9,37:18.4
14,-9,37:18.4
7,-8,37:18.4
8,-8,37:18.4
12,-8,37:18.4
13,-8,37:18.4
8,-7,37:18.4
11,-7,37:18.4
9,-6,37:17.0
10,-6,37:18.4
8,-5,37:18.4
9,-5,37:17.0
10,-5,37:18.4
7,-4,37:18.4
8,-4,37:18.4
11,-4,37:18.4
6,-3,37:18.4
12,-3,37:18.4
5,-2,37:18.4
6,-2,37:18.4
12,-2,37:18.4
13,-2,37:18.4
14,-1,37:18.4
4,-13,38:18.4
5,-12,38:18.4
5,-11,38:18.4
6,-11,38:18.4
6,-10,38:18.4
7,-9,38:18.4
13,-9,38:18.4
14,-9,38:18.4
7,-8,38:18.4
8,-8,38:18.4
12,-8,38:18.4
13,-8,38:18.4
8,-7,38:18.4
11,-7,38:18.4
9,-6,38:17.0
10,-6,38:18.4
8,-5,38:18.4
9,-5,38:18.4
10,-5,38:18.4
7,-4,38:18.4
8,-4,38:18.4
11,-4,38:18.4
6,-3,38:18.4
7,-3,38:18.4
12,-3,38:18.4
5,-2,38:18.4
6,-2,38:18.4
13,-2,38:18.4
5,-1,38:18.4
13,-1,38:18.4
14,-1,38:18.4
4,-13,39:18.4
5,-12,39:18.4
5,-11,39:18.4
6,-11,39:18.4
6,-10,39:18.4
7,-9,39:18.4
14,-9,39:18.4
7,-8,39:18.4
8,-8,39:18.4
12,-8,39:18.4
13,-8,39:18.4
8,-7,39:18.4
11,-7,39:18.4
9,-6,39:17.0
10,-6,39:18.4
8,-5,39:18.4
9,-5,39:18.4
10,-5,39:18.4
7,-4,39:18.4
11,-4,39:18.4
6,-3,39:18.4
7,-3,39:18.4
12,-3,39:18.4
5,-2,39:18.4
6,-2,39:18.4
13,-2,39:18.4
5,-1,39:18.4
14,-1,39:18.4
4,-13,40:18.4
13,-9,40:18.4
14,-9,40:18.4
8,-8,40:18.4
12,-8,40:18.4
8,-7,40:18.4
11,-7,40:18.4
9,-6,40:17.0
10,-6,40:18.4
8,-5,40:18.4
10,-5,40:18.4
8,-4,40:18.4
11,-4,40:18.4
9,-6,41:17.0
10,-6,41:18.4
9,-6,42:17.0
5,-5,42:18.4
6,-5,42:18.4
7,-5,42:18.4
8,-5,42:18.4
9,-5,42:18.4
10,-4,42:18.4
10,-3,42:18.4
9,-10,43:18.4
9,-9,43:18.4
9,-8,43:18.4
9,-7,43:18.4
12,-7,43:18.4
13,-7,43:18.4
14,-7,43:18.4
9,-6,43:17.0
10,-6,43:18.4
11,-6,43:18.4
5,-5,43:18.4
6,-5,43:18.4
7,-5,43:18.4
8,-5,43:18.4
9,-5,43:18.4
10,-5,43:18.4
4,-4,43:18.4
10,-4,43:18.4
10,-3,43:18.4
9,-11,44:18.4
9,-10,44:18.4
9,-9,44:18.4
9,-8,44:18.4
9,-7,44:18.4
12,-7,44:18.4
13,-7,44:18.4
14,-7,44:18.4
8,-6,44:18.4
9,-6,44:18.4
10,-6,44:18.4
11,-6,44:18.4
5,-5,44:18.4
6,-5,44:18.4
7,-5,44:18.4
8,-5,44:18.4
9,-5,44:18.4
4,-4,44:18.4
10,-4,44:18.4
10,-3,44:18.4
9,-10,45:18.4
9,-9,45:18.4
9,-8,45:18.4
9,-7,45:18.4
12,-7,45:18.4
13,-7,45:18.4
14,-7,45:18.4
9,-6,45:18.4
10,-6,45:18.4
11,-6,45:18.4
8,-5,45:18.4
9,-5,45:18.4
9,-6,46:17.0
9,-6,47:17.0
9,-6,48:17.0
9,-6,49:17.0
9,-6,50:17.0
