[META]
version=2.0
spawnOnBlockType=2
spawnSunlight=True
spawnDarkness=True
spawnWater=False
spawnLava=False
underFill=False
randomRotation=True
dig=True
tree=False
branch=False
needsFoundation=True
rarity=100
collisionPercentage=20
spawnElevationMin=0
spawnElevationMax=200
spawnInBiome=Custom
[DATA]
-3,-6,-8:17.12
-2,-6,-8:17.12
-2,-5,-8:17.12
-3,-4,-8:17.12
-1,-4,-8:17.12
-2,-7,-7:17.12
-3,-6,-7:17.12
-1,-6,-7:17.12
-4,-5,-7:17.12
-2,-5,-7:17.12
0,-5,-7:17.12
-3,-3,-7:17.12
0,-8,-6:17.12
-6,-7,-6:17.12
-5,-7,-6:17.12
-3,-7,-6:17.12
-2,-7,-6:17.12
-6,-6,-6:17.12
-3,-6,-6:17.12
-2,-6,-6:17.12
-1,-6,-6:17.12
0,-6,-6:17.12
-6,-5,-6:17.12
-4,-5,-6:17.12
-3,-5,-6:17.12
-2,-5,-6:17.12
-1,-5,-6:17.12
2,-5,-6:17.12
-4,-4,-6:17.12
-3,-4,-6:17.12
-2,-4,-6:17.12
-1,-4,-6:17.12
1,-4,-6:17.12
-6,-3,-6:17.12
-5,-3,-6:17.12
-4,-3,-6:17.12
-2,-3,-6:17.12
-1,-3,-6:17.12
0,-3,-6:17.12
-5,-2,-6:17.12
-4,-2,-6:17.12
-3,-2,-6:17.12
-6,-1,-6:17.12
-5,-1,-6:17.12
-4,-1,-6:17.12
-3,-1,-6:17.12
-2,-1,-6:17.12
-4,0,-6:17.12
-2,0,-6:17.12
-5,-9,-5:17.12
-1,-9,-5:17.12
-7,-8,-5:17.12
-6,-8,-5:17.12
-5,-8,-5:17.12
-4,-8,-5:17.12
-2,-8,-5:17.12
-1,-8,-5:17.12
1,-8,-5:17.12
2,-8,-5:17.12
-6,-7,-5:17.12
-5,-7,-5:17.12
-3,-7,-5:17.12
-1,-7,-5:17.12
1,-7,-5:17.12
2,-7,-5:17.12
-8,-6,-5:17.12
-6,-6,-5:17.12
-3,-6,-5:17.12
-2,-6,-5:17.12
-1,-6,-5:17.12
0,-6,-5:17.12
-6,-5,-5:17.12
-5,-5,-5:17.12
-4,-5,-5:17.12
-3,-5,-5:17.12
-2,-5,-5:17.12
-1,-5,-5:17.12
0,-5,-5:17.12
1,-5,-5:17.12
2,-5,-5:17.12
-7,-4,-5:17.12
-6,-4,-5:17.12
-5,-4,-5:17.12
-3,-4,-5:17.12
-2,-4,-5:17.12
-1,-4,-5:17.12
0,-4,-5:17.12
1,-4,-5:17.12
2,-4,-5:17.12
3,-4,-5:17.12
-5,-3,-5:17.12
-4,-3,-5:17.12
-3,-3,-5:17.12
-2,-3,-5:17.12
-1,-3,-5:17.12
0,-3,-5:17.12
1,-3,-5:17.12
3,-3,-5:17.12
-7,-2,-5:17.12
-6,-2,-5:17.12
-5,-2,-5:17.12
-4,-2,-5:17.12
-3,-2,-5:17.12
0,-2,-5:17.12
-6,-1,-5:17.12
-5,-1,-5:17.12
-4,-1,-5:17.12
-5,0,-5:17.12
-4,0,-5:17.12
-3,0,-5:17.12
-3,1,-5:17.12
-2,1,-5:17.12
-6,-10,-4:17.12
-5,-10,-4:17.12
-5,-9,-4:17.12
-1,-9,-4:17.12
0,-9,-4:17.12
2,-9,-4:17.12
3,-9,-4:17.12
-5,-8,-4:17.12
-3,-8,-4:17.12
-2,-8,-4:17.12
-1,-8,-4:17.12
0,-8,-4:17.12
1,-8,-4:17.12
2,-8,-4:17.12
-8,-7,-4:17.12
-7,-7,-4:17.12
-6,-7,-4:17.12
-5,-7,-4:17.12
-4,-7,-4:17.12
-3,-7,-4:17.12
-2,-7,-4:17.12
-1,-7,-4:17.12
0,-7,-4:17.12
1,-7,-4:17.12
2,-7,-4:17.12
-8,-6,-4:17.12
-6,-6,-4:17.12
-5,-6,-4:17.12
-4,-6,-4:17.12
-3,-6,-4:17.12
-2,-6,-4:17.12
-1,-6,-4:17.12
0,-6,-4:17.12
1,-6,-4:17.12
2,-6,-4:17.12
-8,-5,-4:17.12
-7,-5,-4:17.12
-6,-5,-4:17.12
-5,-5,-4:17.12
-4,-5,-4:17.12
-3,-5,-4:17.12
-2,-5,-4:17.12
-1,-5,-4:17.12
0,-5,-4:17.12
1,-5,-4:17.12
2,-5,-4:17.12
3,-5,-4:17.12
-7,-4,-4:17.12
-6,-4,-4:17.12
-5,-4,-4:17.12
-4,-4,-4:17.12
-3,-4,-4:17.12
-2,-4,-4:17.12
-1,-4,-4:17.12
0,-4,-4:17.12
1,-4,-4:17.12
2,-4,-4:17.12
-5,-3,-4:17.12
-4,-3,-4:17.12
-3,-3,-4:17.12
-2,-3,-4:17.12
-1,-3,-4:17.12
0,-3,-4:17.12
-7,-2,-4:17.12
-5,-2,-4:17.12
-4,-2,-4:17.12
-3,-2,-4:17.12
-1,-2,-4:17.12
0,-2,-4:17.12
1,-2,-4:17.12
2,-2,-4:17.12
-7,-1,-4:17.12
-6,-1,-4:17.12
-5,-1,-4:17.12
-4,-1,-4:17.12
-3,-1,-4:17.12
-2,-1,-4:17.12
-1,-1,-4:17.12
-6,0,-4:17.12
-5,0,-4:17.12
-4,0,-4:17.12
-3,0,-4:17.12
-1,0,-4:17.12
-3,1,-4:17.12
-2,1,-4:17.12
-5,-10,-3:17.12
-4,-10,-3:17.12
-6,-9,-3:17.12
-5,-9,-3:17.12
0,-9,-3:17.12
1,-9,-3:17.12
-7,-8,-3:17.12
-6,-8,-3:17.12
-5,-8,-3:17.12
-4,-8,-3:17.12
-3,-8,-3:17.12
-2,-8,-3:17.12
1,-8,-3:17.12
2,-8,-3:17.12
3,-8,-3:17.12
-6,-7,-3:17.12
-5,-7,-3:17.12
-4,-7,-3:17.12
-3,-7,-3:17.12
-2,-7,-3:17.12
-1,-7,-3:17.12
0,-7,-3:17.12
1,-7,-3:17.12
2,-7,-3:17.12
-8,-6,-3:17.12
-7,-6,-3:17.12
-6,-6,-3:17.12
-5,-6,-3:17.12
-4,-6,-3:17.12
-3,-6,-3:17.12
-2,-6,-3:17.12
-1,-6,-3:17.12
0,-6,-3:17.12
-7,-5,-3:17.12
-4,-5,-3:17.12
-3,-5,-3:17.12
-2,-5,-3:17.12
-1,-5,-3:17.12
0,-5,-3:17.12
1,-5,-3:17.12
-4,-4,-3:17.12
-2,-4,-3:17.12
-1,-4,-3:17.12
0,-4,-3:17.12
1,-4,-3:17.12
3,-4,-3:17.12
-5,-3,-3:17.12
-3,-3,-3:17.12
-2,-3,-3:17.12
-1,-3,-3:17.12
1,-3,-3:17.12
-7,-2,-3:17.12
-5,-2,-3:17.12
-4,-2,-3:17.12
-2,-2,-3:17.12
-1,-2,-3:17.12
0,-2,-3:17.12
1,-2,-3:17.12
-6,-1,-3:17.12
-5,-1,-3:17.12
-3,-1,-3:17.12
-2,-1,-3:17.12
-5,0,-3:17.12
-4,0,-3:17.12
-2,0,-3:17.12
-3,1,-3:17.12
-4,-11,-2:17.12
-3,-11,-2:17.12
-4,-10,-2:17.12
-3,-10,-2:17.12
-2,-10,-2:17.12
0,-10,-2:17.12
1,-10,-2:17.12
-5,-9,-2:17.12
-4,-9,-2:17.12
-3,-9,-2:17.12
-2,-9,-2:17.12
-1,-9,-2:17.12
0,-9,-2:17.12
1,-9,-2:17.12
2,-9,-2:17.12
3,-9,-2:17.12
-8,-8,-2:17.12
-7,-8,-2:17.12
-6,-8,-2:17.12
-5,-8,-2:17.12
-3,-8,-2:17.12
-1,-8,-2:17.12
0,-8,-2:17.12
1,-8,-2:17.12
2,-8,-2:17.12
3,-8,-2:17.12
4,-8,-2:17.12
-9,-7,-2:17.12
-8,-7,-2:17.12
-5,-7,-2:17.12
-4,-7,-2:17.12
-2,-7,-2:17.12
-1,-7,-2:17.12
2,-7,-2:17.12
3,-7,-2:17.12
-8,-6,-2:17.12
-7,-6,-2:17.12
-6,-6,-2:17.12
-5,-6,-2:17.12
-4,-6,-2:17.12
-3,-6,-2:17.12
-2,-6,-2:17.12
-1,-6,-2:17.12
1,-6,-2:17.12
-7,-5,-2:17.12
-6,-5,-2:17.12
-5,-5,-2:17.12
-4,-5,-2:17.12
-3,-5,-2:17.12
-2,-5,-2:17.12
-1,-5,-2:17.12
0,-5,-2:17.12
1,-5,-2:17.12
-7,-4,-2:17.12
-6,-4,-2:17.12
-4,-4,-2:17.12
-3,-4,-2:17.12
-2,-4,-2:17.12
0,-4,-2:17.12
1,-4,-2:17.12
2,-4,-2:17.12
-8,-3,-2:17.12
-7,-3,-2:17.12
-6,-3,-2:17.12
-5,-3,-2:17.12
-4,-3,-2:17.12
-2,-3,-2:17.12
0,-3,-2:17.12
1,-3,-2:17.12
2,-3,-2:17.12
-7,-2,-2:17.12
-6,-2,-2:17.12
-5,-2,-2:17.12
-4,-2,-2:17.12
-1,-2,-2:17.12
0,-2,-2:17.12
1,-2,-2:17.12
2,-2,-2:17.12
-6,-1,-2:17.12
-5,-1,-2:17.12
-2,-1,-2:17.12
-4,0,-2:17.12
-3,0,-2:17.12
-2,0,-2:17.12
-4,1,-2:17.12
-3,1,-2:17.12
-3,2,-2:17.12
-4,-10,-1:17.12
-3,-10,-1:17.12
-4,-9,-1:17.12
-3,-9,-1:17.12
-2,-9,-1:17.12
1,-9,-1:17.12
2,-9,-1:17.12
-8,-8,-1:17.12
-7,-8,-1:17.12
-6,-8,-1:17.12
-5,-8,-1:17.12
-4,-8,-1:17.12
-2,-8,-1:17.12
-1,-8,-1:17.12
0,-8,-1:17.12
1,-8,-1:17.12
2,-8,-1:17.12
3,-8,-1:17.12
-9,-7,-1:17.12
-8,-7,-1:17.12
-4,-7,-1:17.12
-3,-7,-1:17.12
-2,-7,-1:17.12
1,-7,-1:17.12
2,-7,-1:17.12
-8,-6,-1:17.12
-7,-6,-1:17.12
-6,-6,-1:17.12
-4,-6,-1:17.12
-3,-6,-1:17.12
1,-6,-1:17.12
-6,-5,-1:17.12
-3,-5,-1:17.12
-2,-5,-1:17.12
-1,-5,-1:17.12
1,-5,-1:17.12
-7,-4,-1:17.12
-6,-4,-1:17.12
-2,-4,-1:17.12
-1,-4,-1:17.12
1,-4,-1:17.12
2,-4,-1:17.12
-7,-3,-1:17.12
-6,-3,-1:17.12
-5,-3,-1:17.12
1,-3,-1:17.12
2,-3,-1:17.12
-7,-2,-1:17.12
-6,-2,-1:17.12
-5,-2,-1:17.12
-4,-2,-1:17.12
-2,-2,-1:17.12
-1,-2,-1:17.12
0,-2,-1:17.12
1,-2,-1:17.12
-7,-1,-1:18.14
-5,-1,-1:17.12
-4,-1,-1:17.12
-3,-1,-1:17.12
-2,-1,-1:17.12
-6,0,-1:18.14
-5,0,-1:18.14
-4,0,-1:17.12
-3,0,-1:17.12
-2,0,-1:17.12
-4,1,-1:17.12
-3,1,-1:17.12
-7,-9,0:18.14
-6,-9,0:18.14
-5,-9,0:18.14
-4,-9,0:18.14
-3,-9,0:17.12
-2,-9,0:17.12
-1,-9,0:18.14
0,-9,0:18.14
-8,-8,0:17.12
-7,-8,0:18.14
-6,-8,0:18.14
-5,-8,0:18.14
-4,-8,0:18.14
-3,-8,0:18.14
-2,-8,0:17.12
-1,-8,0:18.14
0,-8,0:18.14
1,-8,0:17.12
2,-8,0:17.12
3,-8,0:17.12
-8,-7,0:18.14
-7,-7,0:18.14
-5,-7,0:17.12
-4,-7,0:18.14
-3,-7,0:18.14
-1,-7,0:18.14
0,-7,0:18.14
1,-7,0:18.14
2,-7,0:18.14
-8,-6,0:18.14
-7,-6,0:18.14
-6,-6,0:18.14
-5,-6,0:18.14
1,-6,0:18.14
2,-6,0:18.14
-8,-5,0:18.14
-7,-5,0:18.14
-6,-5,0:18.14
-5,-5,0:18.14
2,-5,0:18.14
-7,-4,0:18.14
-6,-4,0:18.14
-5,-4,0:18.14
1,-4,0:17.12
-7,-3,0:18.14
-6,-3,0:18.14
-5,-3,0:17.12
-4,-3,0:18.14
0,-3,0:17.12
1,-3,0:17.12
-7,-2,0:18.14
-6,-2,0:18.14
-5,-2,0:18.14
-4,-2,0:17.12
-3,-2,0:17.12
-2,-2,0:18.14
-1,-2,0:18.14
-7,-1,0:18.14
-4,-1,0:18.14
-3,-1,0:17.12
-2,-1,0:18.14
0,-1,0:18.14
-6,0,0:18.14
-5,0,0:18.14
-4,0,0:17.12
-3,0,0:17.12
-2,0,0:18.14
-4,1,0:18.14
-3,1,0:17.12
-7,-9,1:18.14
-6,-9,1:18.14
-5,-9,1:18.14
-4,-9,1:18.14
-2,-9,1:18.14
-1,-9,1:18.14
0,-9,1:18.14
-8,-8,1:17.12
-7,-8,1:18.14
-6,-8,1:18.14
-5,-8,1:18.14
-4,-8,1:18.14
-3,-8,1:18.14
-2,-8,1:17.12
-1,-8,1:18.14
0,-8,1:18.14
1,-8,1:17.12
2,-8,1:17.12
-8,-7,1:17.12
-7,-7,1:17.12
-6,-7,1:17.12
-5,-7,1:17.12
-4,-7,1:17.12
-3,-7,1:18.14
-1,-7,1:18.14
0,-7,1:17.12
1,-7,1:17.12
2,-7,1:18.14
-7,-6,1:18.14
-6,-6,1:18.14
-5,-6,1:17.12
-1,-6,1:18.14
0,-6,1:18.14
1,-6,1:18.14
2,-6,1:18.14
-8,-5,1:18.14
-7,-5,1:18.14
-6,-5,1:18.14
-5,-5,1:17.12
-1,-5,1:18.14
0,-5,1:18.14
1,-5,1:18.14
2,-5,1:18.14
-7,-4,1:18.14
-6,-4,1:18.14
-5,-4,1:17.12
-1,-4,1:18.14
0,-4,1:18.14
1,-4,1:18.14
2,-4,1:18.14
-7,-3,1:18.14
-6,-3,1:18.14
-5,-3,1:17.12
-4,-3,1:17.12
-1,-3,1:17.12
0,-3,1:17.12
1,-3,1:18.14
2,-3,1:18.14
-6,-2,1:18.14
-5,-2,1:18.14
-4,-2,1:18.14
-3,-2,1:17.12
-2,-2,1:17.12
-1,-2,1:18.14
0,-2,1:18.14
1,-2,1:18.14
-5,-1,1:18.14
-4,-1,1:18.14
-3,-1,1:17.12
-2,-1,1:18.14
-1,-1,1:18.14
0,-1,1:18.14
-5,0,1:18.14
-4,0,1:18.14
-3,0,1:18.14
-2,0,1:18.14
-1,0,1:18.14
-6,-9,2:18.14
-5,-9,2:18.14
-7,-8,2:18.14
-6,-8,2:18.14
-5,-8,2:18.14
-4,-8,2:18.14
-3,-8,2:17.12
-2,-8,2:17.12
-1,-8,2:18.14
-5,-7,2:17.12
-4,-7,2:17.12
-3,-7,2:17.12
-2,-7,2:17.12
-1,-7,2:17.12
0,-7,2:18.14
1,-7,2:17.12
-7,-6,2:18.14
-6,-6,2:18.14
-5,-6,2:17.12
-1,-6,2:18.14
0,-6,2:18.14
1,-6,2:18.14
-7,-5,2:18.14
-6,-5,2:18.14
-5,-5,2:17.12
0,-5,2:18.14
1,-5,2:18.14
2,-5,2:18.14
-7,-4,2:18.14
-5,-4,2:17.12
-1,-4,2:18.14
0,-4,2:17.12
1,-4,2:18.14
2,-4,2:18.14
-4,-3,2:17.12
-3,-3,2:17.12
-2,-3,2:17.12
-1,-3,2:17.12
0,-3,2:17.12
1,-3,2:18.14
2,-3,2:18.14
-3,-2,2:17.12
-2,-2,2:17.12
-1,-2,2:18.14
0,-2,2:18.14
-2,-1,2:18.14
-1,-1,2:18.14
0,-1,2:18.14
-1,0,2:18.14
-3,3,2:18.12
-3,10,2:18.4
2,10,2:18.4
-6,12,2:18.4
-3,-20,3:18.4
-3,-17,3:18.4
-3,-15,3:18.4
-3,-14,3:18.12
-3,-13,3:18.12
-3,-11,3:18.12
-20,-9,3:18.4
13,-9,3:18.4
-3,-8,3:17.12
-5,-7,3:17.12
-4,-7,3:17.12
-2,-7,3:17.12
-1,-7,3:17.12
0,-7,3:18.12
-5,-6,3:17.12
-1,-6,3:18.12
0,-6,3:17.12
-6,-5,3:18.12
-5,-5,3:17.12
-1,-5,3:17.12
0,-5,3:17.12
-5,-4,3:17.12
-1,-4,3:17.12
0,-4,3:17.12
-4,-3,3:17.12
-3,-3,3:17.12
-2,-3,3:17.12
-1,-3,3:17.12
-3,-2,3:17.12
-20,-1,3:18.4
13,-1,3:18.4
-20,0,3:18.4
-3,0,3:18.12
-16,1,3:18.4
-3,3,3:18.12
-2,3,3:18.12
-2,5,3:18.12
-16,6,3:18.4
9,6,3:18.4
-15,7,3:18.4
-3,9,3:18.4
-3,10,3:18.4
2,10,3:18.4
-6,12,3:18.4
-1,12,3:18.4
-3,-21,4:18.4
-3,-20,4:18.4
-3,-19,4:18.4
-15,-18,4:18.4
-3,-18,4:18.4
8,-18,4:18.4
-3,-17,4:18.4
-17,-16,4:18.4
-3,-16,4:18.4
-3,-15,4:18.4
-17,-14,4:18.4
-3,-14,4:18.4
-17,-13,4:18.4
-3,-13,4:18.12
-20,-12,4:18.4
-3,-11,4:18.12
-20,-9,4:18.4
13,-9,4:18.4
-5,-8,4:18.12
-4,-8,4:17.12
-3,-8,4:17.12
-2,-8,4:18.12
-5,-7,4:17.12
-4,-7,4:17.12
-2,-7,4:17.12
-1,-7,4:17.12
0,-7,4:18.12
1,-7,4:18.12
-6,-6,4:18.12
-5,-6,4:17.12
-1,-6,4:17.12
-6,-5,4:18.12
-5,-5,4:17.12
-1,-5,4:17.12
-20,-4,4:18.4
-6,-4,4:18.12
-5,-4,4:17.12
-4,-4,4:17.12
-1,-4,4:17.12
0,-4,4:18.12
-4,-3,4:17.12
-3,-3,4:17.12
-2,-3,4:17.12
-20,-1,4:18.4
-13,-1,4:18.4
13,-1,4:18.4
-20,0,4:18.4
-3,0,4:18.12
-16,1,4:18.4
-15,1,4:18.4
-17,2,4:18.4
-16,2,4:18.4
11,2,4:18.4
-18,3,4:18.4
-2,3,4:18.12
-2,4,4:18.12
-2,5,4:18.12
-16,6,4:18.4
-3,6,4:18.4
9,6,4:18.4
-15,7,4:18.4
-3,7,4:18.4
6,8,4:18.4
-3,9,4:18.4
-10,10,4:18.4
-9,10,4:18.4
-3,10,4:18.4
2,10,4:18.4
-8,11,4:18.4
-3,11,4:18.4
-6,12,4:18.4
-1,12,4:18.4
-3,-23,5:18.4
-8,-22,5:18.4
-7,-22,5:18.4
-3,-22,5:18.4
0,-22,5:18.4
1,-22,5:18.4
-3,-21,5:18.4
-3,-20,5:18.4
-3,-19,5:18.4
6,-19,5:18.4
-15,-18,5:18.4
-14,-18,5:18.4
-3,-18,5:18.4
8,-18,5:18.4
-3,-17,5:18.4
10,-17,5:18.12
-18,-16,5:18.4
-17,-16,5:18.4
-3,-16,5:18.4
11,-16,5:18.12
-3,-15,5:18.4
-19,-14,5:18.4
-18,-14,5:18.4
-17,-14,5:18.4
-3,-14,5:18.4
-17,-13,5:18.4
-3,-13,5:18.4
10,-13,5:18.14
-20,-12,5:18.4
-14,-12,5:18.4
-13,-12,5:18.4
-3,-12,5:18.12
-11,-11,5:18.12
-3,-11,5:18.12
-3,-10,5:18.12
5,-10,5:18.12
-20,-9,5:18.4
13,-9,5:18.4
-20,-8,5:18.4
-5,-8,5:18.12
-4,-8,5:18.12
-3,-8,5:18.12
-2,-8,5:18.12
2,-8,5:18.12
-20,-7,5:18.4
-5,-7,5:17.12
-4,-7,5:17.12
-3,-7,5:17.12
-2,-7,5:17.12
-1,-7,5:18.12
0,-7,5:18.12
1,-7,5:18.12
13,-7,5:18.4
-6,-6,5:18.12
-5,-6,5:17.12
-1,-6,5:18.12
-6,-5,5:18.12
-5,-5,5:17.12
-1,-5,5:17.12
-20,-4,5:18.4
-8,-4,5:18.12
-6,-4,5:18.12
-5,-4,5:17.12
-4,-4,5:17.12
-2,-4,5:17.12
-1,-4,5:18.12
0,-4,5:18.12
13,-4,5:18.4
-10,-3,5:18.12
-4,-3,5:18.12
-3,-3,5:18.12
-2,-3,5:18.12
1,-3,5:18.12
2,-3,5:18.12
-12,-2,5:18.4
-11,-2,5:18.4
13,-2,5:18.4
-20,-1,5:18.4
-13,-1,5:18.4
-12,-1,5:18.4
5,-1,5:18.4
13,-1,5:18.4
-20,0,5:18.4
-3,0,5:18.12
7,0,5:18.4
13,0,5:18.4
-20,1,5:18.4
-16,1,5:18.4
-15,1,5:18.4
-3,1,5:18.12
9,1,5:18.4
13,1,5:18.4
-20,2,5:18.4
-17,2,5:18.4
-16,2,5:18.4
-2,2,5:18.12
11,2,5:18.4
13,2,5:18.4
-20,3,5:18.4
-19,3,5:18.4
-18,3,5:18.4
-2,3,5:18.12
11,3,5:18.4
12,3,5:18.12
13,3,5:18.12
-19,4,5:18.4
-3,4,5:18.4
-2,4,5:18.4
-18,5,5:18.4
-3,5,5:18.4
11,5,5:18.12
-17,6,5:18.4
-16,6,5:18.4
-3,6,5:18.4
9,6,5:18.4
10,6,5:18.4
-15,7,5:18.4
-3,7,5:18.4
8,7,5:18.4
-12,8,5:18.4
6,8,5:18.4
-3,9,5:18.4
-10,10,5:18.4
-9,10,5:18.4
-3,10,5:18.4
2,10,5:18.4
-8,11,5:18.4
-3,11,5:18.4
-6,12,5:18.4
-5,12,5:18.4
-1,12,5:18.4
-3,13,5:18.4
-3,-24,6:18.4
-3,-23,6:18.4
-2,-23,6:18.4
-1,-23,6:18.4
-8,-22,6:18.4
-7,-22,6:18.4
-3,-22,6:18.4
0,-22,6:18.4
1,-22,6:18.4
-3,-21,6:18.4
-3,-20,6:18.4
4,-20,6:18.4
-13,-19,6:18.12
-3,-19,6:18.4
6,-19,6:18.4
-15,-18,6:18.4
-14,-18,6:18.4
-3,-18,6:18.4
7,-18,6:18.4
8,-18,6:18.4
-3,-17,6:18.4
10,-17,6:18.12
-18,-16,6:18.4
-17,-16,6:18.4
-3,-16,6:18.4
11,-16,6:18.12
-3,-15,6:18.4
-19,-14,6:18.4
-18,-14,6:18.4
-17,-14,6:18.4
-3,-14,6:18.4
10,-14,6:18.14
11,-14,6:18.12
-17,-13,6:18.4
-15,-13,6:18.4
-3,-13,6:18.4
10,-13,6:18.14
-20,-12,6:18.4
-15,-12,6:18.4
-14,-12,6:18.4
-13,-12,6:18.4
-3,-12,6:18.12
9,-12,6:18.4
13,-12,6:18.12
-13,-11,6:18.4
-12,-11,6:18.4
-11,-11,6:18.4
-3,-11,6:18.12
7,-11,6:18.4
-11,-10,6:18.4
-9,-10,6:18.12
-3,-10,6:18.12
5,-10,6:18.12
-20,-9,6:18.4
-9,-9,6:18.12
-8,-9,6:18.12
-3,-9,6:18.12
13,-9,6:18.4
-20,-8,6:18.4
-7,-8,6:18.12
-5,-8,6:18.12
-4,-8,6:18.12
-3,-8,6:18.12
-2,-8,6:18.12
2,-8,6:18.12
3,-8,6:18.12
13,-8,6:18.4
-20,-7,6:18.4
-5,-7,6:17.12
-3,-7,6:17.12
-2,-7,6:17.12
-1,-7,6:18.12
0,-7,6:18.12
1,-7,6:18.12
13,-7,6:18.4
-6,-6,6:18.12
-2,-6,6:17.12
-1,-6,6:18.12
0,-6,6:18.12
-20,-5,6:18.4
-6,-5,6:18.12
-5,-5,6:17.12
-2,-5,6:17.12
-1,-5,6:18.12
13,-5,6:18.4
-20,-4,6:18.4
-8,-4,6:18.12
-6,-4,6:18.12
-5,-4,6:18.12
-4,-4,6:17.12
-3,-4,6:17.12
-2,-4,6:17.12
-1,-4,6:18.12
0,-4,6:18.12
13,-4,6:18.4
-10,-3,6:18.12
-9,-3,6:18.12
-4,-3,6:18.12
-3,-3,6:18.12
-2,-3,6:18.12
0,-3,6:18.12
1,-3,6:18.12
2,-3,6:18.12
-11,-2,6:18.4
-10,-2,6:18.12
-3,-2,6:18.12
2,-2,6:18.12
3,-2,6:18.12
13,-2,6:18.4
-20,-1,6:18.4
-13,-1,6:18.4
-12,-1,6:18.4
-3,-1,6:18.12
5,-1,6:18.4
13,-1,6:18.4
-20,0,6:18.4
-14,0,6:18.4
-13,0,6:18.4
-3,0,6:18.12
-2,0,6:18.12
6,0,6:18.4
7,0,6:18.4
13,0,6:18.4
-20,1,6:18.4
-16,1,6:18.4
-15,1,6:18.4
-2,1,6:18.12
8,1,6:18.4
9,1,6:18.4
-20,2,6:18.4
-17,2,6:18.4
-16,2,6:18.4
-3,2,6:18.12
-2,2,6:18.12
10,2,6:18.4
11,2,6:18.4
13,2,6:18.4
-20,3,6:18.4
-19,3,6:18.4
-18,3,6:18.4
-3,3,6:18.4
11,3,6:18.4
12,3,6:18.12
13,3,6:18.12
-20,4,6:18.4
-19,4,6:18.4
-3,4,6:18.4
12,4,6:18.12
-19,5,6:18.4
-18,5,6:18.4
-3,5,6:18.4
11,5,6:18.12
-16,6,6:18.4
-3,6,6:18.4
9,6,6:18.4
10,6,6:18.4
-15,7,6:18.4
-3,7,6:18.4
8,7,6:18.4
-13,8,6:18.4
-12,8,6:18.4
-3,8,6:18.4
5,8,6:18.4
6,8,6:18.4
-12,9,6:18.4
-3,9,6:18.4
4,9,6:18.4
-10,10,6:18.4
-9,10,6:18.4
-3,10,6:18.4
2,10,6:18.4
3,10,6:18.4
-8,11,6:18.4
-3,11,6:18.4
-6,12,6:18.4
-5,12,6:18.4
-1,12,6:18.4
-4,13,6:18.4
-3,13,6:18.4
-5,-24,7:18.4
-4,-24,7:18.4
-3,-24,7:18.4
-2,-24,7:18.4
-6,-23,7:18.4
-5,-23,7:18.4
-3,-23,7:18.4
-2,-23,7:18.4
-1,-23,7:18.4
-8,-22,7:18.4
-7,-22,7:18.4
-3,-22,7:18.4
0,-22,7:18.4
1,-22,7:18.4
-3,-21,7:18.4
-11,-20,7:18.12
-10,-20,7:18.4
-3,-20,7:18.4
4,-20,7:18.4
-13,-19,7:18.12
-12,-19,7:18.14
-3,-19,7:18.4
6,-19,7:18.4
-15,-18,7:18.4
-14,-18,7:18.4
-13,-18,7:18.4
-3,-18,7:18.4
7,-18,7:18.4
8,-18,7:18.4
-15,-17,7:18.4
-3,-17,7:18.4
10,-17,7:18.12
-18,-16,7:18.4
-17,-16,7:18.4
-3,-16,7:18.4
-19,-15,7:18.4
-3,-15,7:18.4
-19,-14,7:18.4
-18,-14,7:18.4
-17,-14,7:18.4
-3,-14,7:18.4
11,-14,7:18.12
12,-14,7:18.12
-17,-13,7:18.4
-16,-13,7:18.4
-15,-13,7:18.4
-3,-13,7:18.4
9,-13,7:18.6
10,-13,7:18.12
11,-13,7:18.14
12,-13,7:18.14
13,-13,7:18.12
-20,-12,7:18.4
-15,-12,7:18.4
-14,-12,7:18.4
-13,-12,7:18.4
-3,-12,7:18.12
8,-12,7:18.4
9,-12,7:18.4
13,-12,7:18.12
-20,-11,7:18.4
-13,-11,7:18.4
-12,-11,7:18.4
-11,-11,7:18.4
-3,-11,7:18.12
6,-11,7:18.4
7,-11,7:18.4
-20,-10,7:18.4
-11,-10,7:18.4
-9,-10,7:18.12
-3,-10,7:18.12
5,-10,7:18.4
6,-10,7:18.4
13,-10,7:18.12
-20,-9,7:18.4
-9,-9,7:18.12
-8,-9,7:18.12
-7,-9,7:18.12
-3,-9,7:18.12
4,-9,7:18.12
13,-9,7:18.4
-20,-8,7:18.4
-7,-8,7:18.12
-6,-8,7:18.12
-5,-8,7:18.12
-4,-8,7:18.12
-3,-8,7:17.12
-2,-8,7:18.12
2,-8,7:18.12
3,-8,7:18.12
13,-8,7:18.4
-20,-7,7:18.4
-5,-7,7:17.12
-4,-7,7:17.12
-3,-7,7:17.12
-2,-7,7:17.12
-1,-7,7:18.12
0,-7,7:18.12
1,-7,7:18.12
13,-7,7:18.4
-20,-6,7:18.4
-6,-6,7:18.12
-1,-6,7:18.12
0,-6,7:18.12
13,-6,7:18.4
-20,-5,7:18.4
-6,-5,7:18.12
-2,-5,7:17.12
-1,-5,7:18.12
13,-5,7:18.4
-20,-4,7:18.4
-8,-4,7:18.12
-7,-4,7:18.12
-6,-4,7:18.12
-5,-4,7:17.12
-4,-4,7:17.12
-2,-4,7:17.12
-1,-4,7:18.12
0,-4,7:18.12
13,-4,7:18.4
-10,-3,7:18.12
-9,-3,7:18.12
-4,-3,7:18.12
-3,-3,7:18.12
-2,-3,7:18.12
0,-3,7:18.12
1,-3,7:18.12
2,-3,7:18.12
-20,-2,7:18.4
-11,-2,7:18.4
-10,-2,7:18.12
-3,-2,7:18.12
2,-2,7:18.12
3,-2,7:18.12
13,-2,7:18.4
-20,-1,7:18.4
-13,-1,7:18.4
-12,-1,7:18.4
-3,-1,7:18.12
-2,-1,7:18.12
4,-1,7:18.12
5,-1,7:18.4
13,-1,7:18.4
-20,0,7:18.4
-14,0,7:18.4
-13,0,7:18.4
-3,0,7:18.12
-2,0,7:18.12
6,0,7:18.4
7,0,7:18.4
13,0,7:18.4
-20,1,7:18.4
-16,1,7:18.4
-15,1,7:18.4
-3,1,7:18.12
8,1,7:18.4
9,1,7:18.4
13,1,7:18.4
-20,2,7:18.4
-17,2,7:18.4
-16,2,7:18.4
-3,2,7:18.12
9,2,7:18.4
10,2,7:18.4
11,2,7:18.4
13,2,7:18.12
-20,3,7:18.4
-19,3,7:18.4
-18,3,7:18.4
-3,3,7:18.4
11,3,7:18.4
12,3,7:18.12
13,3,7:18.12
-20,4,7:18.4
-19,4,7:18.4
-3,4,7:18.4
10,4,7:18.6
11,4,7:18.14
12,4,7:18.12
-19,5,7:18.4
-18,5,7:18.4
-17,5,7:18.4
-3,5,7:18.4
10,5,7:18.4
11,5,7:18.12
-17,6,7:18.4
-16,6,7:18.4
-3,6,7:18.4
9,6,7:18.4
10,6,7:18.4
-15,7,7:18.4
-14,7,7:18.4
-3,7,7:18.4
8,7,7:18.4
-13,8,7:18.4
-12,8,7:18.4
-3,8,7:18.4
5,8,7:18.4
6,8,7:18.4
-12,9,7:18.4
-11,9,7:18.4
-10,9,7:18.4
-3,9,7:18.4
4,9,7:18.4
5,9,7:18.4
-10,10,7:18.4
-9,10,7:18.4
-3,10,7:18.4
2,10,7:18.4
3,10,7:18.4
-8,11,7:18.4
-7,11,7:18.4
-3,11,7:18.4
1,11,7:18.4
-6,12,7:18.4
-5,12,7:18.4
-1,12,7:18.4
-4,13,7:18.4
-3,13,7:18.4
-2,13,7:18.4
-5,-24,8:18.4
-4,-24,8:18.4
-3,-24,8:18.4
-2,-24,8:18.4
-6,-23,8:18.4
-5,-23,8:18.4
-4,-23,8:18.4
-3,-23,8:18.4
-2,-23,8:18.4
-1,-23,8:18.4
-8,-22,8:18.4
-7,-22,8:18.4
-6,-22,8:18.4
-5,-22,8:18.4
-4,-22,8:18.4
-3,-22,8:18.4
-2,-22,8:18.4
-1,-22,8:18.4
0,-22,8:18.4
1,-22,8:18.4
-9,-21,8:18.4
-8,-21,8:18.4
-6,-21,8:18.4
-5,-21,8:18.4
-4,-21,8:18.4
-3,-21,8:18.4
-2,-21,8:18.4
-1,-21,8:18.4
2,-21,8:18.4
3,-21,8:18.4
-11,-20,8:18.12
-10,-20,8:18.4
-5,-20,8:18.4
-4,-20,8:18.4
-3,-20,8:18.4
-2,-20,8:18.4
-1,-20,8:18.4
3,-20,8:18.4
4,-20,8:18.4
5,-20,8:18.4
-13,-19,8:18.12
-12,-19,8:18.12
-5,-19,8:18.4
-4,-19,8:18.4
-3,-19,8:18.4
-2,-19,8:18.4
6,-19,8:18.4
-15,-18,8:18.4
-14,-18,8:18.4
-13,-18,8:18.4
-12,-18,8:18.6
-4,-18,8:18.4
-3,-18,8:18.4
-2,-18,8:18.4
7,-18,8:18.4
8,-18,8:18.4
-16,-17,8:18.4
-15,-17,8:18.4
-4,-17,8:18.4
-3,-17,8:18.4
-2,-17,8:18.4
9,-17,8:18.4
10,-17,8:18.12
-18,-16,8:18.4
-17,-16,8:18.4
-4,-16,8:18.4
-3,-16,8:18.4
-2,-16,8:18.4
-20,-15,8:18.4
-19,-15,8:18.4
-4,-15,8:18.4
-3,-15,8:18.4
-2,-15,8:18.4
-20,-14,8:18.4
-19,-14,8:18.4
-18,-14,8:18.4
-3,-14,8:18.4
11,-14,8:18.12
12,-14,8:18.12
-20,-13,8:18.4
-17,-13,8:18.4
-16,-13,8:18.4
-3,-13,8:18.4
9,-13,8:18.6
10,-13,8:18.12
13,-13,8:18.12
-20,-12,8:18.4
-15,-12,8:18.4
-14,-12,8:18.4
-3,-12,8:18.12
8,-12,8:18.4
9,-12,8:18.4
13,-12,8:18.12
-20,-11,8:18.4
-13,-11,8:18.4
-12,-11,8:18.4
-11,-11,8:18.4
-3,-11,8:18.12
6,-11,8:18.4
7,-11,8:18.4
13,-11,8:18.12
-20,-10,8:18.4
-11,-10,8:18.4
-9,-10,8:18.12
-3,-10,8:18.12
5,-10,8:18.4
6,-10,8:18.4
13,-10,8:18.12
-20,-9,8:18.4
-9,-9,8:18.12
-8,-9,8:18.12
-7,-9,8:18.12
-3,-9,8:18.12
3,-9,8:18.12
4,-9,8:18.4
13,-9,8:18.4
-20,-8,8:18.4
-7,-8,8:18.12
-6,-8,8:18.12
-5,-8,8:18.12
-4,-8,8:17.12
-3,-8,8:17.12
-2,-8,8:18.12
2,-8,8:18.12
3,-8,8:18.12
13,-8,8:18.4
-20,-7,8:18.4
-5,-7,8:17.12
-2,-7,8:17.12
-1,-7,8:18.12
0,-7,8:18.12
1,-7,8:18.12
13,-7,8:18.4
-20,-6,8:18.4
-6,-6,8:18.12
-1,-6,8:17.12
0,-6,8:18.12
13,-6,8:18.4
-20,-5,8:18.4
-7,-5,8:18.12
-6,-5,8:18.12
-1,-5,8:17.12
13,-5,8:18.4
-20,-4,8:18.4
-15,-4,8:18.4
-14,-4,8:18.4
-13,-4,8:18.4
-12,-4,8:18.4
-11,-4,8:18.4
-10,-4,8:18.12
-9,-4,8:18.12
-8,-4,8:18.12
-7,-4,8:18.12
-6,-4,8:18.12
-5,-4,8:18.12
-4,-4,8:18.12
-2,-4,8:17.12
-1,-4,8:18.12
0,-4,8:18.12
12,-4,8:18.4
13,-4,8:18.4
-20,-3,8:18.4
-19,-3,8:18.4
-18,-3,8:18.4
-17,-3,8:18.4
-16,-3,8:18.4
-15,-3,8:18.4
-14,-3,8:18.4
-13,-3,8:18.4
-12,-3,8:18.4
-11,-3,8:18.4
-10,-3,8:18.12
-9,-3,8:18.12
-8,-3,8:18.12
-7,-3,8:18.12
-4,-3,8:18.12
-3,-3,8:18.12
-2,-3,8:18.12
0,-3,8:18.12
1,-3,8:18.12
2,-3,8:18.12
3,-3,8:18.12
4,-3,8:18.4
5,-3,8:18.4
6,-3,8:18.4
7,-3,8:18.4
8,-3,8:18.4
9,-3,8:18.4
10,-3,8:18.4
11,-3,8:18.4
12,-3,8:18.4
13,-3,8:18.4
-20,-2,8:18.4
-19,-2,8:18.4
-18,-2,8:18.4
-17,-2,8:18.4
-16,-2,8:18.4
-15,-2,8:18.4
-14,-2,8:18.4
-13,-2,8:18.4
-12,-2,8:18.4
-11,-2,8:18.4
-10,-2,8:18.12
-9,-2,8:18.12
-8,-2,8:18.12
-7,-2,8:18.12
-3,-2,8:18.12
1,-2,8:18.12
2,-2,8:18.12
3,-2,8:18.12
4,-2,8:18.4
5,-2,8:18.4
6,-2,8:18.4
7,-2,8:18.4
8,-2,8:18.4
9,-2,8:18.4
10,-2,8:18.4
11,-2,8:18.4
12,-2,8:18.4
13,-2,8:18.4
-20,-1,8:18.4
-19,-1,8:18.4
-17,-1,8:18.4
-16,-1,8:18.4
-15,-1,8:18.4
-14,-1,8:18.4
-13,-1,8:18.4
-12,-1,8:18.4
-11,-1,8:18.4
-10,-1,8:18.12
-9,-1,8:18.12
-8,-1,8:18.12
-3,-1,8:18.12
-2,-1,8:18.12
2,-1,8:18.12
3,-1,8:18.12
4,-1,8:18.4
5,-1,8:18.4
6,-1,8:18.4
7,-1,8:18.4
8,-1,8:18.4
9,-1,8:18.4
10,-1,8:18.4
11,-1,8:18.4
12,-1,8:18.4
13,-1,8:18.4
-20,0,8:18.4
-19,0,8:18.4
-18,0,8:18.4
-17,0,8:18.4
-16,0,8:18.4
-15,0,8:18.4
-14,0,8:18.4
-13,0,8:18.4
-12,0,8:18.4
-11,0,8:18.4
-10,0,8:18.4
-9,0,8:18.12
-8,0,8:18.12
-3,0,8:18.12
3,0,8:18.12
4,0,8:18.4
5,0,8:18.4
6,0,8:18.4
7,0,8:18.4
8,0,8:18.4
9,0,8:18.4
10,0,8:18.4
11,0,8:18.4
12,0,8:18.4
13,0,8:18.4
-20,1,8:18.4
-19,1,8:18.4
-18,1,8:18.4
-17,1,8:18.4
-16,1,8:18.4
-15,1,8:18.4
-14,1,8:18.4
-13,1,8:18.4
-12,1,8:18.4
-11,1,8:18.4
-10,1,8:18.4
-9,1,8:18.4
-3,1,8:18.12
3,1,8:18.4
4,1,8:18.4
5,1,8:18.4
6,1,8:18.4
7,1,8:18.4
8,1,8:18.4
9,1,8:18.4
10,1,8:18.4
11,1,8:18.4
12,1,8:18.12
13,1,8:18.12
-20,2,8:18.4
-19,2,8:18.4
-17,2,8:18.4
-16,2,8:18.4
-15,2,8:18.4
-14,2,8:18.4
-13,2,8:18.4
-12,2,8:18.4
-11,2,8:18.4
-10,2,8:18.4
-3,2,8:18.4
4,2,8:18.4
6,2,8:18.4
7,2,8:18.4
8,2,8:18.4
9,2,8:18.4
10,2,8:18.4
11,2,8:18.4
12,2,8:18.12
13,2,8:18.12
-20,3,8:18.4
-19,3,8:18.4
-18,3,8:18.4
-17,3,8:18.4
-16,3,8:18.4
-15,3,8:18.4
-14,3,8:18.4
-13,3,8:18.4
-12,3,8:18.4
-11,3,8:18.4
-10,3,8:18.4
-3,3,8:18.4
4,3,8:18.4
5,3,8:18.4
6,3,8:18.4
8,3,8:18.4
9,3,8:18.4
10,3,8:18.4
11,3,8:18.4
12,3,8:18.12
13,3,8:18.12
-19,4,8:18.4
-18,4,8:18.4
-17,4,8:18.4
-16,4,8:18.4
-15,4,8:18.4
-14,4,8:18.4
-13,4,8:18.4
-12,4,8:18.4
-11,4,8:18.4
-3,4,8:18.4
5,4,8:18.4
6,4,8:18.4
7,4,8:18.4
8,4,8:18.4
9,4,8:18.4
10,4,8:18.14
11,4,8:18.12
12,4,8:18.12
-18,5,8:18.4
-17,5,8:18.4
-16,5,8:18.4
-15,5,8:18.4
-14,5,8:18.4
-13,5,8:18.4
-12,5,8:18.4
-11,5,8:18.4
-3,5,8:18.4
5,5,8:18.4
6,5,8:18.4
7,5,8:18.4
8,5,8:18.4
9,5,8:18.4
10,5,8:18.12
11,5,8:18.12
-17,6,8:18.4
-16,6,8:18.4
-15,6,8:18.4
-14,6,8:18.4
-13,6,8:18.4
-12,6,8:18.4
-3,6,8:18.4
6,6,8:18.4
7,6,8:18.4
8,6,8:18.4
9,6,8:18.4
10,6,8:18.12
-15,7,8:18.4
-14,7,8:18.4
-13,7,8:18.4
-3,7,8:18.4
6,7,8:18.4
7,7,8:18.4
8,7,8:18.4
-13,8,8:18.4
-12,8,8:18.4
-3,8,8:18.4
5,8,8:18.4
6,8,8:18.4
-12,9,8:18.4
-11,9,8:18.4
-10,9,8:18.4
-3,9,8:18.4
4,9,8:18.4
5,9,8:18.4
-10,10,8:18.4
-9,10,8:18.4
-3,10,8:18.4
2,10,8:18.4
3,10,8:18.4
-8,11,8:18.4
-7,11,8:18.4
-3,11,8:18.4
0,11,8:18.4
1,11,8:18.4
-6,12,8:18.4
-5,12,8:18.4
-2,12,8:18.4
-1,12,8:18.4
0,12,8:18.4
-5,13,8:18.4
-4,13,8:18.4
-3,13,8:18.4
-2,13,8:18.4
-4,-24,9:18.4
-3,-24,9:18.4
-6,-23,9:18.4
-5,-23,9:18.4
-4,-23,9:18.4
-3,-23,9:18.4
-2,-23,9:18.4
-1,-23,9:18.4
-8,-22,9:18.4
-7,-22,9:18.4
-6,-22,9:18.4
-1,-22,9:18.4
0,-22,9:18.4
1,-22,9:18.4
-9,-21,9:18.4
-8,-21,9:18.4
-7,-21,9:18.4
-6,-21,9:18.4
-1,-21,9:18.4
0,-21,9:18.4
1,-21,9:18.4
2,-21,9:18.4
3,-21,9:18.4
-11,-20,9:18.12
-10,-20,9:18.4
-8,-20,9:18.4
-7,-20,9:18.4
-6,-20,9:18.4
-1,-20,9:18.4
0,-20,9:18.4
1,-20,9:18.4
2,-20,9:18.4
3,-20,9:18.4
4,-20,9:18.4
5,-20,9:18.4
-13,-19,9:18.12
-12,-19,9:18.12
-11,-19,9:18.12
-10,-19,9:18.4
-9,-19,9:18.4
-8,-19,9:18.4
-7,-19,9:18.4
-6,-19,9:18.4
-5,-19,9:18.4
-1,-19,9:18.4
0,-19,9:18.4
1,-19,9:18.4
2,-19,9:18.4
3,-19,9:18.4
4,-19,9:18.4
5,-19,9:18.4
6,-19,9:18.4
7,-19,9:18.4
-15,-18,9:18.4
-14,-18,9:18.4
-13,-18,9:18.12
-12,-18,9:18.12
-11,-18,9:18.12
-10,-18,9:18.4
-9,-18,9:18.4
-8,-18,9:18.4
-7,-18,9:18.4
-6,-18,9:18.4
-5,-18,9:18.4
-1,-18,9:18.4
0,-18,9:18.4
1,-18,9:18.4
2,-18,9:18.4
3,-18,9:18.4
4,-18,9:18.4
5,-18,9:18.4
6,-18,9:18.4
7,-18,9:18.4
8,-18,9:18.4
-16,-17,9:18.4
-15,-17,9:18.4
-14,-17,9:18.4
-13,-17,9:18.4
-12,-17,9:18.4
-11,-17,9:18.4
-10,-17,9:18.4
-9,-17,9:18.4
-8,-17,9:18.4
-7,-17,9:18.4
-6,-17,9:18.4
-5,-17,9:18.4
-2,-17,9:18.4
-1,-17,9:18.4
0,-17,9:18.4
1,-17,9:18.4
2,-17,9:18.4
3,-17,9:18.4
4,-17,9:18.4
5,-17,9:18.4
6,-17,9:18.4
7,-17,9:18.4
8,-17,9:18.4
9,-17,9:18.4
10,-17,9:18.12
-18,-16,9:18.4
-17,-16,9:18.4
-16,-16,9:18.4
-15,-16,9:18.4
-14,-16,9:18.4
-13,-16,9:18.4
-12,-16,9:18.4
-11,-16,9:18.4
-10,-16,9:18.4
-9,-16,9:18.4
-8,-16,9:18.4
-7,-16,9:18.4
-6,-16,9:18.4
-5,-16,9:18.4
-4,-16,9:18.4
-2,-16,9:18.4
-1,-16,9:18.4
0,-16,9:18.4
1,-16,9:18.4
2,-16,9:18.4
3,-16,9:18.4
4,-16,9:18.4
5,-16,9:18.4
6,-16,9:18.4
7,-16,9:18.4
8,-16,9:18.4
9,-16,9:18.4
10,-16,9:18.12
-20,-15,9:18.4
-19,-15,9:18.4
-18,-15,9:18.4
-17,-15,9:18.4
-16,-15,9:18.4
-15,-15,9:18.4
-14,-15,9:18.4
-13,-15,9:18.4
-11,-15,9:18.4
-10,-15,9:18.4
-9,-15,9:18.4
-8,-15,9:18.4
-7,-15,9:18.4
-6,-15,9:18.4
-5,-15,9:18.4
-4,-15,9:18.4
-2,-15,9:18.4
-1,-15,9:18.4
0,-15,9:18.4
1,-15,9:18.4
2,-15,9:18.4
3,-15,9:18.4
4,-15,9:18.4
5,-15,9:18.4
6,-15,9:18.4
7,-15,9:18.4
8,-15,9:18.4
9,-15,9:18.4
10,-15,9:18.12
-20,-14,9:18.4
-19,-14,9:18.4
-18,-14,9:18.4
-17,-14,9:18.4
-16,-14,9:18.4
-15,-14,9:18.4
-14,-14,9:18.4
-13,-14,9:18.4
-12,-14,9:18.4
-11,-14,9:18.4
-10,-14,9:18.4
-9,-14,9:18.4
-8,-14,9:18.4
-7,-14,9:18.4
-6,-14,9:18.4
-5,-14,9:18.4
-4,-14,9:18.4
-2,-14,9:18.4
-1,-14,9:18.4
0,-14,9:18.4
1,-14,9:18.4
2,-14,9:18.4
3,-14,9:18.4
4,-14,9:18.4
5,-14,9:18.4
6,-14,9:18.4
7,-14,9:18.4
8,-14,9:18.4
9,-14,9:18.4
10,-14,9:18.12
11,-14,9:18.12
12,-14,9:18.12
13,-14,9:18.12
-20,-13,9:18.4
-19,-13,9:18.4
-18,-13,9:18.4
-17,-13,9:18.4
-16,-13,9:18.4
-15,-13,9:18.4
-14,-13,9:18.4
-13,-13,9:18.4
-12,-13,9:18.4
-11,-13,9:18.4
-10,-13,9:18.4
-9,-13,9:18.4
-8,-13,9:18.4
-7,-13,9:18.4
-6,-13,9:18.4
-5,-13,9:18.4
-4,-13,9:18.4
-2,-13,9:18.4
-1,-13,9:18.4
0,-13,9:18.4
1,-13,9:18.4
2,-13,9:18.4
3,-13,9:18.4
4,-13,9:18.4
5,-13,9:18.4
6,-13,9:18.4
7,-13,9:18.4
8,-13,9:18.4
9,-13,9:18.4
10,-13,9:18.4
11,-13,9:18.4
12,-13,9:18.12
13,-13,9:18.12
-20,-12,9:18.4
-19,-12,9:18.4
-18,-12,9:18.4
-17,-12,9:18.4
-16,-12,9:18.4
-15,-12,9:18.4
-14,-12,9:18.4
-13,-12,9:18.4
-12,-12,9:18.4
-11,-12,9:18.4
-10,-12,9:18.4
-9,-12,9:18.12
-7,-12,9:18.12
-6,-12,9:18.12
-5,-12,9:18.12
-4,-12,9:18.12
-2,-12,9:18.12
-1,-12,9:18.12
0,-12,9:18.12
1,-12,9:18.12
2,-12,9:18.12
3,-12,9:18.4
4,-12,9:18.4
5,-12,9:18.4
6,-12,9:18.4
7,-12,9:18.4
8,-12,9:18.4
9,-12,9:18.4
10,-12,9:18.4
11,-12,9:18.4
12,-12,9:18.12
13,-12,9:18.12
-20,-11,9:18.4
-19,-11,9:18.4
-18,-11,9:18.4
-17,-11,9:18.4
-16,-11,9:18.4
-15,-11,9:18.4
-14,-11,9:18.4
-13,-11,9:18.4
-12,-11,9:18.4
-11,-11,9:18.4
-10,-11,9:18.4
-9,-11,9:18.12
-8,-11,9:18.12
-7,-11,9:18.12
-6,-11,9:18.12
-5,-11,9:18.12
-4,-11,9:18.12
-3,-11,9:18.12
-2,-11,9:18.12
-1,-11,9:18.12
0,-11,9:18.12
1,-11,9:18.12
2,-11,9:18.12
3,-11,9:18.4
4,-11,9:18.4
5,-11,9:18.4
6,-11,9:18.4
7,-11,9:18.4
8,-11,9:18.4
9,-11,9:18.4
10,-11,9:18.4
11,-11,9:18.4
12,-11,9:18.12
13,-11,9:18.12
-20,-10,9:18.4
-19,-10,9:18.4
-18,-10,9:18.4
-17,-10,9:18.4
-16,-10,9:18.4
-15,-10,9:18.4
-14,-10,9:18.4
-13,-10,9:18.4
-12,-10,9:18.4
-11,-10,9:18.4
-9,-10,9:18.12
-8,-10,9:18.12
-7,-10,9:18.12
-6,-10,9:18.12
-5,-10,9:18.12
-4,-10,9:18.12
-3,-10,9:18.12
-2,-10,9:18.12
-1,-10,9:18.12
0,-10,9:18.12
1,-10,9:18.12
2,-10,9:18.12
3,-10,9:18.12
4,-10,9:18.4
5,-10,9:18.4
6,-10,9:18.4
7,-10,9:18.4
8,-10,9:18.4
9,-10,9:18.4
10,-10,9:18.4
11,-10,9:18.4
12,-10,9:18.12
13,-10,9:18.12
-20,-9,9:18.4
-19,-9,9:18.4
-18,-9,9:18.4
-17,-9,9:18.4
-16,-9,9:18.4
-15,-9,9:18.4
-14,-9,9:18.4
-13,-9,9:18.4
-12,-9,9:18.4
-11,-9,9:18.4
-10,-9,9:18.12
-9,-9,9:18.12
-8,-9,9:18.12
-7,-9,9:18.12
-6,-9,9:18.12
-5,-9,9:18.12
-4,-9,9:18.12
-3,-9,9:18.12
-2,-9,9:18.12
-1,-9,9:18.12
0,-9,9:18.12
1,-9,9:18.12
2,-9,9:18.12
3,-9,9:18.12
4,-9,9:18.4
5,-9,9:18.4
6,-9,9:18.4
7,-9,9:18.4
8,-9,9:18.4
9,-9,9:18.4
10,-9,9:18.4
11,-9,9:18.4
12,-9,9:18.4
13,-9,9:18.4
-20,-8,9:18.4
-19,-8,9:18.4
-18,-8,9:18.4
-17,-8,9:18.4
-16,-8,9:18.4
-15,-8,9:18.4
-14,-8,9:18.4
-13,-8,9:18.4
-12,-8,9:18.4
-11,-8,9:18.4
-10,-8,9:18.12
-9,-8,9:18.12
-8,-8,9:18.12
-7,-8,9:18.12
-6,-8,9:18.12
-5,-8,9:17.12
-4,-8,9:17.12
-3,-8,9:17.12
-2,-8,9:17.12
-1,-8,9:18.12
0,-8,9:18.12
1,-8,9:18.12
2,-8,9:18.12
3,-8,9:18.12
4,-8,9:18.4
5,-8,9:18.4
6,-8,9:18.4
7,-8,9:18.4
8,-8,9:18.4
9,-8,9:18.4
10,-8,9:18.4
11,-8,9:18.4
12,-8,9:18.4
13,-8,9:18.4
-20,-7,9:18.4
-19,-7,9:18.4
-18,-7,9:18.4
-17,-7,9:18.4
-16,-7,9:18.4
-15,-7,9:18.4
-14,-7,9:18.4
-13,-7,9:18.4
-12,-7,9:18.4
-11,-7,9:18.4
-10,-7,9:18.12
-9,-7,9:18.12
-8,-7,9:18.12
-7,-7,9:18.12
-5,-7,9:18.12
-2,-7,9:17.12
-1,-7,9:18.12
0,-7,9:18.12
1,-7,9:18.12
2,-7,9:18.12
3,-7,9:18.12
4,-7,9:18.4
5,-7,9:18.4
6,-7,9:18.4
7,-7,9:18.4
8,-7,9:18.4
9,-7,9:18.4
10,-7,9:18.4
11,-7,9:18.4
12,-7,9:18.4
13,-7,9:18.4
-20,-6,9:18.4
-19,-6,9:18.4
-18,-6,9:18.4
-17,-6,9:18.4
-16,-6,9:18.4
-15,-6,9:18.4
-14,-6,9:18.4
-13,-6,9:18.4
-12,-6,9:18.4
-11,-6,9:18.4
-10,-6,9:18.12
-9,-6,9:18.12
-8,-6,9:18.12
-7,-6,9:18.12
-6,-6,9:17.12
-4,-6,9:18.12
-3,-6,9:18.12
-2,-6,9:18.12
-1,-6,9:17.12
0,-6,9:18.12
1,-6,9:18.12
2,-6,9:18.12
3,-6,9:18.12
4,-6,9:18.4
5,-6,9:18.4
6,-6,9:18.4
7,-6,9:18.4
8,-6,9:18.4
9,-6,9:18.4
10,-6,9:18.4
11,-6,9:18.4
12,-6,9:18.4
13,-6,9:18.4
-20,-5,9:18.4
-19,-5,9:18.4
-18,-5,9:18.4
-17,-5,9:18.4
-16,-5,9:18.4
-15,-5,9:18.4
-14,-5,9:18.4
-13,-5,9:18.4
-12,-5,9:18.4
-11,-5,9:18.4
-10,-5,9:18.12
-9,-5,9:18.12
-8,-5,9:18.12
-7,-5,9:18.12
-6,-5,9:17.12
-3,-5,9:18.12
-1,-5,9:17.12
0,-5,9:18.12
1,-5,9:18.12
2,-5,9:18.12
3,-5,9:18.12
4,-5,9:18.4
5,-5,9:18.4
6,-5,9:18.4
7,-5,9:18.4
8,-5,9:18.4
9,-5,9:18.4
10,-5,9:18.4
11,-5,9:18.4
12,-5,9:18.4
13,-5,9:18.4
-19,-4,9:18.4
-18,-4,9:18.4
-17,-4,9:18.4
-16,-4,9:18.4
-15,-4,9:18.4
-14,-4,9:18.4
-13,-4,9:18.4
-12,-4,9:18.4
-11,-4,9:18.4
-10,-4,9:18.12
-9,-4,9:18.12
-6,-4,9:18.12
-5,-4,9:17.12
-4,-4,9:17.12
-3,-4,9:18.12
-2,-4,9:17.12
-1,-4,9:17.12
0,-4,9:18.12
1,-4,9:18.12
2,-4,9:18.12
3,-4,9:18.12
4,-4,9:18.4
5,-4,9:18.4
6,-4,9:18.4
7,-4,9:18.4
8,-4,9:18.4
9,-4,9:18.4
10,-4,9:18.4
11,-4,9:18.4
12,-4,9:18.4
13,-4,9:18.4
-19,-3,9:18.4
-7,-3,9:18.12
-6,-3,9:18.12
-5,-3,9:18.12
-4,-3,9:18.12
-3,-3,9:17.12
-2,-3,9:17.12
-1,-3,9:18.12
0,-3,9:18.12
4,-3,9:18.4
12,-3,9:18.4
13,-3,9:18.4
-19,-2,9:18.4
-7,-2,9:18.12
-6,-2,9:18.12
-5,-2,9:18.12
-4,-2,9:18.12
-3,-2,9:18.12
-2,-2,9:18.12
-1,-2,9:18.12
0,-2,9:18.12
1,-2,9:18.12
12,-2,9:18.4
13,-2,9:18.4
-19,-1,9:18.4
-7,-1,9:18.12
-6,-1,9:18.12
-5,-1,9:18.12
-4,-1,9:18.12
-3,-1,9:18.12
-2,-1,9:18.12
-1,-1,9:18.12
0,-1,9:18.12
1,-1,9:18.12
2,-1,9:18.12
12,-1,9:18.4
13,-1,9:18.4
-19,0,9:18.4
-8,0,9:18.12
-7,0,9:18.12
-6,0,9:18.12
-5,0,9:18.12
-4,0,9:18.12
-3,0,9:18.12
-2,0,9:18.12
-1,0,9:18.12
0,0,9:18.12
1,0,9:18.12
2,0,9:18.12
12,0,9:18.4
13,0,9:18.4
-19,1,9:18.4
-8,1,9:18.4
-7,1,9:18.12
-6,1,9:18.12
-5,1,9:18.12
-4,1,9:18.12
-3,1,9:18.12
-2,1,9:18.12
-1,1,9:18.12
0,1,9:18.12
1,1,9:18.12
2,1,9:18.12
3,1,9:18.4
12,1,9:18.12
-19,2,9:18.4
-9,2,9:18.4
-8,2,9:18.4
-7,2,9:18.4
-6,2,9:18.4
-5,2,9:18.4
-4,2,9:18.4
-3,2,9:18.4
-2,2,9:18.4
-1,2,9:18.4
0,2,9:18.4
1,2,9:18.4
2,2,9:18.4
3,2,9:18.4
10,2,9:18.6
11,2,9:18.6
12,2,9:18.12
-19,3,9:18.4
-18,3,9:18.4
-10,3,9:18.4
-9,3,9:18.4
-8,3,9:18.4
-7,3,9:18.4
-6,3,9:18.4
-5,3,9:18.4
-4,3,9:18.4
-3,3,9:18.4
-2,3,9:18.4
-1,3,9:18.4
0,3,9:18.4
1,3,9:18.4
2,3,9:18.4
3,3,9:18.4
4,3,9:18.4
9,3,9:18.6
12,3,9:18.12
-19,4,9:18.4
-18,4,9:18.4
-17,4,9:18.4
-10,4,9:18.4
-9,4,9:18.4
-8,4,9:18.4
-7,4,9:18.4
-6,4,9:18.4
-5,4,9:18.4
-4,4,9:18.4
-3,4,9:18.4
-2,4,9:18.4
-1,4,9:18.4
0,4,9:18.4
1,4,9:18.4
2,4,9:18.4
3,4,9:18.4
4,4,9:18.4
9,4,9:18.6
10,4,9:18.14
11,4,9:18.12
12,4,9:18.12
-17,5,9:18.4
-16,5,9:18.4
-11,5,9:18.4
-10,5,9:18.4
-9,5,9:18.4
-8,5,9:18.4
-7,5,9:18.4
-6,5,9:18.4
-5,5,9:18.4
-4,5,9:18.4
-3,5,9:18.4
-2,5,9:18.4
-1,5,9:18.4
0,5,9:18.4
1,5,9:18.4
2,5,9:18.4
3,5,9:18.4
4,5,9:18.4
5,5,9:18.4
9,5,9:18.4
10,5,9:18.12
-16,6,9:18.4
-15,6,9:18.4
-14,6,9:18.4
-12,6,9:18.4
-11,6,9:18.4
-10,6,9:18.4
-9,6,9:18.4
-8,6,9:18.4
-7,6,9:18.4
-6,6,9:18.4
-5,6,9:18.4
-4,6,9:18.4
-3,6,9:18.4
-2,6,9:18.4
-1,6,9:18.4
0,6,9:18.4
1,6,9:18.4
2,6,9:18.4
3,6,9:18.4
4,6,9:18.4
5,6,9:18.4
8,6,9:18.4
9,6,9:18.4
-14,7,9:18.4
-13,7,9:18.4
-12,7,9:18.4
-11,7,9:18.4
-10,7,9:18.4
-9,7,9:18.4
-8,7,9:18.4
-7,7,9:18.4
-6,7,9:18.4
-5,7,9:18.4
-4,7,9:18.4
-3,7,9:18.4
-2,7,9:18.4
-1,7,9:18.4
0,7,9:18.4
1,7,9:18.4
2,7,9:18.4
3,7,9:18.4
4,7,9:18.4
5,7,9:18.4
6,7,9:18.4
7,7,9:18.4
8,7,9:18.4
-13,8,9:18.4
-12,8,9:18.4
-11,8,9:18.4
-10,8,9:18.4
-9,8,9:18.4
-8,8,9:18.4
-7,8,9:18.4
-6,8,9:18.4
-5,8,9:18.4
-4,8,9:18.4
-3,8,9:18.4
-2,8,9:18.4
-1,8,9:18.4
0,8,9:18.4
1,8,9:18.4
2,8,9:18.4
3,8,9:18.4
4,8,9:18.4
5,8,9:18.4
6,8,9:18.4
-11,9,9:18.4
-10,9,9:18.4
-9,9,9:18.4
-8,9,9:18.4
-7,9,9:18.4
-6,9,9:18.4
-5,9,9:18.4
-4,9,9:18.4
-3,9,9:18.4
-2,9,9:18.4
-1,9,9:18.4
0,9,9:18.4
1,9,9:18.4
2,9,9:18.4
3,9,9:18.4
4,9,9:18.4
-10,10,9:18.4
-9,10,9:18.4
-8,10,9:18.4
-7,10,9:18.4
-6,10,9:18.4
-5,10,9:18.4
-4,10,9:18.4
-3,10,9:18.4
-2,10,9:18.4
-1,10,9:18.4
0,10,9:18.4
1,10,9:18.4
2,10,9:18.4
3,10,9:18.4
-8,11,9:18.4
-7,11,9:18.4
-6,11,9:18.4
-5,11,9:18.4
-4,11,9:18.4
-3,11,9:18.4
-2,11,9:18.4
-1,11,9:18.4
0,11,9:18.4
1,11,9:18.4
-6,12,9:18.4
-5,12,9:18.4
-2,12,9:18.4
-1,12,9:18.4
0,12,9:18.4
-5,13,9:18.4
-4,13,9:18.4
-3,13,9:18.4
-2,13,9:18.4
-4,-24,10:18.4
-4,-23,10:18.4
-3,-23,10:18.4
-6,-22,10:18.4
-5,-22,10:18.4
-4,-22,10:18.4
-3,-22,10:18.4
-2,-22,10:18.4
-1,-22,10:18.4
-8,-21,10:18.4
-7,-21,10:18.4
-6,-21,10:18.4
-1,-21,10:18.4
0,-21,10:18.4
1,-21,10:18.4
-10,-20,10:18.4
-8,-20,10:18.4
1,-20,10:18.4
2,-20,10:18.4
3,-20,10:18.4
-11,-19,10:18.12
-10,-19,10:18.4
3,-19,10:18.4
4,-19,10:18.4
5,-19,10:18.4
-14,-18,10:18.4
-13,-18,10:18.12
-12,-18,10:18.12
5,-18,10:18.4
6,-18,10:18.4
7,-18,10:18.4
-16,-17,10:18.4
-15,-17,10:18.4
-14,-17,10:18.4
7,-17,10:18.4
8,-17,10:18.4
9,-17,10:18.4
10,-17,10:18.12
-18,-16,10:18.4
-17,-16,10:18.4
-16,-16,10:18.4
9,-16,10:18.4
10,-16,10:18.12
11,-16,10:18.12
-19,-15,10:18.4
-18,-15,10:18.4
-17,-15,10:18.4
10,-15,10:18.14
11,-15,10:18.12
12,-15,10:18.12
13,-15,10:18.12
-20,-14,10:18.4
-19,-14,10:18.4
-18,-14,10:18.4
-17,-14,10:18.4
10,-14,10:18.12
11,-14,10:18.12
12,-14,10:18.12
13,-14,10:18.12
-20,-13,10:18.4
-19,-13,10:18.4
-18,-13,10:18.4
-17,-13,10:18.4
-16,-13,10:18.4
9,-13,10:18.4
10,-13,10:18.4
11,-13,10:18.4
12,-13,10:18.12
13,-13,10:18.12
-20,-12,10:18.4
-19,-12,10:18.4
-15,-12,10:18.4
-14,-12,10:18.4
7,-12,10:18.4
8,-12,10:18.4
12,-12,10:18.12
13,-12,10:18.12
-19,-11,10:18.4
-14,-11,10:18.4
-13,-11,10:18.4
-12,-11,10:18.4
6,-11,10:18.4
7,-11,10:18.4
12,-11,10:18.12
-19,-10,10:18.4
-12,-10,10:18.4
-11,-10,10:18.4
4,-10,10:18.4
5,-10,10:18.4
12,-10,10:18.12
-19,-9,10:18.4
-10,-9,10:18.12
-9,-9,10:18.12
2,-9,10:18.12
3,-9,10:18.12
4,-9,10:18.4
12,-9,10:18.4
-19,-8,10:18.4
-8,-8,10:18.12
-7,-8,10:18.12
-4,-8,10:17.12
-3,-8,10:17.12
1,-8,10:18.12
2,-8,10:18.12
12,-8,10:18.4
-19,-7,10:18.4
-5,-7,10:17.12
-4,-7,10:17.12
-2,-7,10:17.12
-1,-7,10:18.12
0,-7,10:18.12
12,-7,10:18.4
-19,-6,10:18.4
-6,-6,10:17.12
-5,-6,10:17.12
-4,-6,10:18.12
-3,-6,10:18.12
-2,-6,10:18.12
-1,-6,10:17.12
12,-6,10:18.4
-19,-5,10:18.4
-6,-5,10:17.12
-5,-5,10:17.12
-3,-5,10:18.12
-1,-5,10:17.12
12,-5,10:18.4
-19,-4,10:18.4
-18,-4,10:18.4
-5,-4,10:17.12
-4,-4,10:17.12
-3,-4,10:18.12
-2,-4,10:17.12
-1,-4,10:17.12
12,-4,10:18.4
-19,-3,10:18.4
-18,-3,10:18.4
-3,-3,10:17.12
-2,-3,10:17.12
12,-3,10:18.4
-19,-2,10:18.4
-18,-2,10:18.4
-3,-2,10:18.12
12,-2,10:18.4
-19,-1,10:18.4
-3,-1,10:18.12
12,-1,10:18.4
-18,0,10:18.4
-3,0,10:18.12
12,0,10:18.4
-18,1,10:18.4
-3,1,10:18.12
11,1,10:18.12
12,1,10:18.12
-3,2,10:18.4
9,2,10:18.6
10,2,10:18.6
11,2,10:18.14
12,2,10:18.14
-18,3,10:18.4
-3,3,10:18.4
9,3,10:18.6
11,3,10:18.12
12,3,10:18.12
-18,4,10:18.4
-17,4,10:18.4
-16,4,10:18.4
-3,4,10:18.4
9,4,10:18.12
10,4,10:18.12
11,4,10:18.12
-16,5,10:18.4
-15,5,10:18.4
-3,5,10:18.4
8,5,10:18.4
9,5,10:18.12
-15,6,10:18.4
-14,6,10:18.4
-13,6,10:18.4
-3,6,10:18.4
6,6,10:18.4
7,6,10:18.4
8,6,10:18.12
-13,7,10:18.4
-12,7,10:18.4
-3,7,10:18.4
5,7,10:18.4
6,7,10:18.4
-12,8,10:18.4
-11,8,10:18.4
-10,8,10:18.4
-3,8,10:18.4
3,8,10:18.4
4,8,10:18.4
5,8,10:18.4
-10,9,10:18.4
-9,9,10:18.4
-3,9,10:18.4
2,9,10:18.4
3,9,10:18.4
-9,10,10:18.4
-8,10,10:18.4
-7,10,10:18.4
-3,10,10:18.4
1,10,10:18.4
2,10,10:18.4
-7,11,10:18.4
-6,11,10:18.4
-4,11,10:18.4
-3,11,10:18.4
-1,11,10:18.4
0,11,10:18.4
-6,12,10:18.4
-5,12,10:18.4
-4,12,10:18.4
-2,12,10:18.4
-1,12,10:18.4
-4,13,10:18.4
-3,13,10:18.4
-2,13,10:18.4
-4,-23,11:18.4
-4,-22,11:18.4
-3,-22,11:18.4
-6,-21,11:18.4
-5,-21,11:18.4
-4,-21,11:18.4
-3,-21,11:18.4
-2,-21,11:18.4
-1,-21,11:18.4
-8,-20,11:18.4
-7,-20,11:18.4
-6,-20,11:18.4
-1,-20,11:18.4
0,-20,11:18.4
1,-20,11:18.4
2,-20,11:18.4
-10,-19,11:18.4
-9,-19,11:18.4
-8,-19,11:18.4
1,-19,11:18.4
2,-19,11:18.4
3,-19,11:18.4
4,-19,11:18.4
-12,-18,11:18.12
-11,-18,11:18.12
-10,-18,11:18.4
3,-18,11:18.4
4,-18,11:18.4
5,-18,11:18.4
6,-18,11:18.4
-14,-17,11:18.4
-13,-17,11:18.4
-12,-17,11:18.4
5,-17,11:18.4
6,-17,11:18.4
7,-17,11:18.4
-16,-16,11:18.4
-15,-16,11:18.4
-14,-16,11:18.4
8,-16,11:18.4
9,-16,11:18.4
10,-16,11:18.4
-18,-15,11:18.4
-17,-15,11:18.4
-16,-15,11:18.4
10,-15,11:18.4
11,-15,11:18.12
12,-15,11:18.12
13,-15,11:18.12
-19,-14,11:18.4
-18,-14,11:18.4
10,-14,11:18.6
11,-14,11:18.12
12,-14,11:18.12
-19,-13,11:18.4
-18,-13,11:18.4
-17,-13,11:18.4
-16,-13,11:18.4
9,-13,11:18.4
10,-13,11:18.4
11,-13,11:18.12
12,-13,11:18.12
-19,-12,11:18.4
-18,-12,11:18.4
-16,-12,11:18.4
-15,-12,11:18.4
-14,-12,11:18.4
7,-12,11:18.4
8,-12,11:18.4
11,-12,11:18.12
12,-12,11:18.12
-19,-11,11:18.4
-18,-11,11:18.4
-14,-11,11:18.4
-13,-11,11:18.4
-12,-11,11:18.4
6,-11,11:18.4
7,-11,11:18.4
11,-11,11:18.4
12,-11,11:18.12
-18,-10,11:18.4
-12,-10,11:18.4
-11,-10,11:18.4
4,-10,11:18.4
5,-10,11:18.4
11,-10,11:18.4
12,-10,11:18.12
-19,-9,11:18.4
-18,-9,11:18.4
-10,-9,11:18.12
-9,-9,11:18.12
2,-9,11:18.12
3,-9,11:18.12
4,-9,11:18.4
11,-9,11:18.4
12,-9,11:18.4
-18,-8,11:18.4
-8,-8,11:18.12
-7,-8,11:18.12
-3,-8,11:17.12
1,-8,11:18.12
2,-8,11:18.12
11,-8,11:18.4
12,-8,11:18.4
-18,-7,11:18.4
-5,-7,11:17.12
-4,-7,11:17.12
-3,-7,11:17.12
-2,-7,11:17.12
-1,-7,11:18.12
0,-7,11:18.12
11,-7,11:18.4
12,-7,11:18.4
-18,-6,11:18.4
-5,-6,11:17.12
-4,-6,11:18.12
-3,-6,11:18.12
-2,-6,11:18.12
-1,-6,11:17.12
11,-6,11:18.4
12,-6,11:18.4
-18,-5,11:18.4
-5,-5,11:17.12
-3,-5,11:18.12
-2,-5,11:17.12
11,-5,11:18.4
-18,-4,11:18.4
-4,-4,11:17.12
-3,-4,11:17.12
-2,-4,11:17.12
11,-4,11:18.4
-18,-3,11:18.4
-3,-3,11:18.12
11,-3,11:18.4
-18,-2,11:18.4
-3,-2,11:18.12
11,-2,11:18.4
-17,-1,11:18.4
-3,-1,11:18.12
11,-1,11:18.4
-18,0,11:18.4
-17,0,11:18.4
-3,0,11:18.12
11,0,11:18.4
-18,1,11:18.4
-17,1,11:18.4
-3,1,11:18.12
11,1,11:18.12
-17,2,11:18.4
-3,2,11:18.4
8,2,11:18.6
9,2,11:18.6
10,2,11:18.14
11,2,11:18.12
-18,3,11:18.4
-17,3,11:18.4
-16,3,11:18.4
-3,3,11:18.4
8,3,11:18.6
9,3,11:18.14
10,3,11:18.12
11,3,11:18.12
12,3,11:18.12
-16,4,11:18.4
-15,4,11:18.4
-3,4,11:18.4
8,4,11:18.4
9,4,11:18.12
10,4,11:18.14
-15,5,11:18.4
-14,5,11:18.4
-13,5,11:18.4
-3,5,11:18.4
6,5,11:18.4
7,5,11:18.4
8,5,11:18.4
-13,6,11:18.4
-12,6,11:18.4
-3,6,11:18.4
5,6,11:18.4
6,6,11:18.4
7,6,11:18.4
-12,7,11:18.4
-11,7,11:18.4
-10,7,11:18.4
-3,7,11:18.4
4,7,11:18.4
5,7,11:18.4
-10,8,11:18.4
-9,8,11:18.4
-3,8,11:18.4
2,8,11:18.4
3,8,11:18.4
4,8,11:18.4
-9,9,11:18.4
-8,9,11:18.4
-7,9,11:18.4
-3,9,11:18.4
1,9,11:18.4
2,9,11:18.4
-7,10,11:18.4
-6,10,11:18.4
-3,10,11:18.4
-1,10,11:18.4
0,10,11:18.4
1,10,11:18.4
-6,11,11:18.4
-5,11,11:18.4
-4,11,11:18.4
-3,11,11:18.4
-2,11,11:18.4
-1,11,11:18.4
-4,12,11:18.4
-2,12,11:18.4
-5,-23,12:18.4
-4,-23,12:18.4
-4,-22,12:18.4
-5,-21,12:18.4
-4,-21,12:18.4
-3,-21,12:18.4
-2,-21,12:18.4
-6,-20,12:18.4
-5,-20,12:18.4
-4,-20,12:18.4
-2,-20,12:18.4
-1,-20,12:18.4
0,-20,12:18.4
-8,-19,12:18.4
-7,-19,12:18.4
-6,-19,12:18.4
0,-19,12:18.4
1,-19,12:18.4
2,-19,12:18.4
-10,-18,12:18.4
-9,-18,12:18.4
-8,-18,12:18.4
2,-18,12:18.4
3,-18,12:18.4
4,-18,12:18.4
-12,-17,12:18.4
-11,-17,12:18.4
-10,-17,12:18.4
4,-17,12:18.4
5,-17,12:18.4
6,-17,12:18.4
-14,-16,12:18.4
-13,-16,12:18.4
-12,-16,12:18.4
6,-16,12:18.4
7,-16,12:18.4
8,-16,12:18.4
-16,-15,12:18.4
-15,-15,12:18.4
-14,-15,12:18.4
8,-15,12:18.4
9,-15,12:18.4
10,-15,12:18.4
-19,-14,12:18.4
-18,-14,12:18.4
-17,-14,12:18.4
-16,-14,12:18.4
10,-14,12:18.4
11,-14,12:18.12
-18,-13,12:18.4
-17,-13,12:18.4
-16,-13,12:18.4
9,-13,12:18.4
10,-13,12:18.4
11,-13,12:18.12
-18,-12,12:18.4
-16,-12,12:18.4
-15,-12,12:18.4
-14,-12,12:18.4
7,-12,12:18.4
8,-12,12:18.4
11,-12,12:18.12
-18,-11,12:18.4
-17,-11,12:18.4
-14,-11,12:18.4
-13,-11,12:18.4
-12,-11,12:18.4
6,-11,12:18.4
7,-11,12:18.4
11,-11,12:18.4
-18,-10,12:18.4
-17,-10,12:18.4
-12,-10,12:18.4
-11,-10,12:18.4
4,-10,12:18.4
5,-10,12:18.4
11,-10,12:18.4
-18,-9,12:18.4
-17,-9,12:18.4
-10,-9,12:18.12
-9,-9,12:18.12
2,-9,12:18.12
3,-9,12:18.12
10,-9,12:18.4
11,-9,12:18.4
-18,-8,12:18.4
-17,-8,12:18.4
-8,-8,12:18.12
-7,-8,12:18.12
1,-8,12:18.12
2,-8,12:18.12
10,-8,12:18.4
11,-8,12:18.4
-18,-7,12:18.4
-17,-7,12:18.4
-5,-7,12:18.12
-4,-7,12:17.12
-3,-7,12:17.12
-2,-7,12:17.12
-1,-7,12:18.12
0,-7,12:18.12
10,-7,12:18.4
11,-7,12:18.4
-18,-6,12:18.4
-17,-6,12:18.4
-5,-6,12:17.12
-4,-6,12:18.12
-3,-6,12:18.12
-2,-6,12:17.12
-1,-6,12:18.12
10,-6,12:18.4
11,-6,12:18.4
-18,-5,12:18.4
-17,-5,12:18.4
-5,-5,12:17.12
-4,-5,12:17.12
-3,-5,12:18.12
-2,-5,12:17.12
10,-5,12:18.4
11,-5,12:18.4
-17,-4,12:18.4
-4,-4,12:17.12
-3,-4,12:17.12
-2,-4,12:17.12
10,-4,12:18.4
11,-4,12:18.4
-17,-3,12:18.4
-3,-3,12:18.12
10,-3,12:18.4
11,-3,12:18.4
-17,-2,12:18.4
-3,-2,12:18.12
10,-2,12:18.4
11,-2,12:18.4
-17,-1,12:18.4
-3,-1,12:18.12
10,-1,12:18.4
11,-1,12:18.4
-17,0,12:18.4
-3,0,12:18.12
10,0,12:18.4
-17,1,12:18.4
-3,1,12:18.12
10,1,12:18.12
-17,2,12:18.4
-16,2,12:18.4
-3,2,12:18.4
9,2,12:18.6
10,2,12:18.12
-18,3,12:18.4
-17,3,12:18.4
-16,3,12:18.4
-15,3,12:18.4
-3,3,12:18.4
8,3,12:18.4
9,3,12:18.14
10,3,12:18.12
11,3,12:18.12
12,3,12:18.12
-15,4,12:18.4
-14,4,12:18.4
-3,4,12:18.4
7,4,12:18.4
8,4,12:18.4
-14,5,12:18.4
-13,5,12:18.4
-12,5,12:18.4
-3,5,12:18.4
5,5,12:18.4
6,5,12:18.4
7,5,12:18.12
-12,6,12:18.4
-11,6,12:18.4
-3,6,12:18.4
4,6,12:18.4
5,6,12:18.4
-11,7,12:18.4
-10,7,12:18.4
-9,7,12:18.4
-3,7,12:18.4
2,7,12:18.4
3,7,12:18.4
4,7,12:18.4
-9,8,12:18.4
-8,8,12:18.4
-7,8,12:18.4
-3,8,12:18.4
1,8,12:18.4
2,8,12:18.4
-8,9,12:18.4
-7,9,12:18.4
-6,9,12:18.4
-3,9,12:18.4
-1,9,12:18.4
0,9,12:18.4
1,9,12:18.4
-6,10,12:18.4
-5,10,12:18.4
-4,10,12:18.4
-3,10,12:18.4
-2,10,12:18.4
-1,10,12:18.4
-4,11,12:18.4
-3,11,12:18.4
-2,11,12:18.4
-4,12,12:18.4
-5,-23,13:18.4
-4,-22,13:18.4
-4,-21,13:18.4
-5,-20,13:18.4
-4,-20,13:18.4
-3,-20,13:18.4
-2,-20,13:18.4
-7,-19,13:18.4
-6,-19,13:18.4
-5,-19,13:18.4
-2,-19,13:18.4
-1,-19,13:18.4
0,-19,13:18.4
-9,-18,13:18.4
-8,-18,13:18.4
-7,-18,13:18.4
0,-18,13:18.4
1,-18,13:18.4
2,-18,13:18.4
-11,-17,13:18.4
-10,-17,13:18.4
-9,-17,13:18.4
-8,-17,13:18.4
2,-17,13:18.4
3,-17,13:18.4
4,-17,13:18.4
-12,-16,13:18.4
-11,-16,13:18.4
-10,-16,13:18.4
4,-16,13:18.4
5,-16,13:18.4
6,-16,13:18.4
-14,-15,13:18.4
-13,-15,13:18.4
6,-15,13:18.4
7,-15,13:18.4
8,-15,13:18.4
-18,-14,13:18.4
-16,-14,13:18.4
-15,-14,13:18.4
-14,-14,13:18.4
8,-14,13:18.4
9,-14,13:18.4
10,-14,13:18.4
11,-14,13:18.12
-17,-13,13:18.4
-16,-13,13:18.4
9,-13,13:18.4
10,-13,13:18.4
-17,-12,13:18.4
-16,-12,13:18.4
-15,-12,13:18.4
-14,-12,13:18.4
7,-12,13:18.4
8,-12,13:18.4
10,-12,13:18.4
-17,-11,13:18.4
-14,-11,13:18.4
-13,-11,13:18.4
-12,-11,13:18.4
6,-11,13:18.4
7,-11,13:18.4
10,-11,13:18.4
-17,-10,13:18.4
-12,-10,13:18.4
-11,-10,13:18.4
4,-10,13:18.4
5,-10,13:18.4
10,-10,13:18.4
-17,-9,13:18.4
-10,-9,13:18.12
-9,-9,13:18.12
2,-9,13:18.12
3,-9,13:18.12
10,-9,13:18.4
-17,-8,13:18.4
-16,-8,13:18.4
-8,-8,13:18.12
-7,-8,13:18.12
1,-8,13:18.12
2,-8,13:18.12
10,-8,13:18.4
-17,-7,13:18.4
-16,-7,13:18.4
-5,-7,13:18.12
-4,-7,13:17.12
-3,-7,13:17.12
-1,-7,13:18.12
0,-7,13:18.12
10,-7,13:18.4
-17,-6,13:18.4
-16,-6,13:18.4
-5,-6,13:17.12
-4,-6,13:18.12
-3,-6,13:18.12
-2,-6,13:18.12
-1,-6,13:18.12
10,-6,13:18.4
-17,-5,13:18.4
-16,-5,13:18.4
-5,-5,13:17.12
-4,-5,13:17.12
-3,-5,13:18.12
-2,-5,13:17.12
10,-5,13:18.4
-17,-4,13:18.4
-16,-4,13:18.4
-3,-4,13:17.12
10,-4,13:18.4
-17,-3,13:18.4
-16,-3,13:18.4
-3,-3,13:18.12
10,-3,13:18.4
-17,-2,13:18.4
-16,-2,13:18.4
-3,-2,13:18.12
10,-2,13:18.4
-16,-1,13:18.4
-3,-1,13:18.12
9,-1,13:18.4
10,-1,13:18.4
-16,0,13:18.4
-3,0,13:18.12
9,0,13:18.4
10,0,13:18.4
-16,1,13:18.4
-3,1,13:18.12
9,1,13:18.4
10,1,13:18.12
-17,2,13:18.4
-16,2,13:18.4
-15,2,13:18.4
-3,2,13:18.4
8,2,13:18.4
9,2,13:18.4
10,2,13:18.12
-15,3,13:18.4
-14,3,13:18.4
-3,3,13:18.4
8,3,13:18.4
9,3,13:18.14
10,3,13:18.14
11,3,13:18.12
12,3,13:18.12
-14,4,13:18.4
-13,4,13:18.4
-12,4,13:18.4
-3,4,13:18.4
5,4,13:18.4
6,4,13:18.4
7,4,13:18.4
-12,5,13:18.4
-11,5,13:18.4
-3,5,13:18.4
4,5,13:18.4
5,5,13:18.4
-11,6,13:18.4
-10,6,13:18.4
-9,6,13:18.4
-3,6,13:18.4
2,6,13:18.4
3,6,13:18.4
4,6,13:18.4
-9,7,13:18.4
-8,7,13:18.4
-7,7,13:18.4
-3,7,13:18.4
1,7,13:18.4
2,7,13:18.4
-8,8,13:18.4
-7,8,13:18.4
-6,8,13:18.4
-3,8,13:18.4
-1,8,13:18.4
0,8,13:18.4
1,8,13:18.4
-6,9,13:18.4
-5,9,13:18.4
-4,9,13:18.4
-3,9,13:18.4
-2,9,13:18.4
-1,9,13:18.4
-4,10,13:18.4
-3,10,13:18.4
-2,10,13:18.4
-4,11,13:18.4
-5,-23,14:18.4
-5,-22,14:18.4
-4,-21,14:18.4
-4,-20,14:18.4
-5,-19,14:18.4
-4,-19,14:18.4
-3,-19,14:18.4
-2,-19,14:18.4
-7,-18,14:18.4
-6,-18,14:18.4
-5,-18,14:18.4
-4,-18,14:18.4
-3,-18,14:18.4
-2,-18,14:18.4
-1,-18,14:18.4
0,-18,14:18.4
-9,-17,14:18.4
-8,-17,14:18.4
-7,-17,14:18.4
0,-17,14:18.4
1,-17,14:18.4
2,-17,14:18.4
-11,-16,14:18.4
-10,-16,14:18.4
-9,-16,14:18.4
2,-16,14:18.4
3,-16,14:18.4
4,-16,14:18.4
-13,-15,14:18.4
-11,-15,14:18.4
4,-15,14:18.4
5,-15,14:18.4
6,-15,14:18.4
12,-15,14:18.12
-18,-14,14:18.4
-17,-14,14:18.4
-15,-14,14:18.4
-14,-14,14:18.4
-13,-14,14:18.4
-12,-14,14:18.4
6,-14,14:18.4
7,-14,14:18.4
8,-14,14:18.4
10,-14,14:18.4
11,-14,14:18.12
-17,-13,14:18.4
-16,-13,14:18.4
-15,-13,14:18.4
-14,-13,14:18.4
8,-13,14:18.4
9,-13,14:18.4
10,-13,14:18.4
-16,-12,14:18.4
-15,-12,14:18.4
-14,-12,14:18.4
7,-12,14:18.4
8,-12,14:18.4
9,-12,14:18.4
-16,-11,14:18.4
-14,-11,14:18.4
-13,-11,14:18.4
-12,-11,14:18.4
5,-11,14:18.4
6,-11,14:18.4
7,-11,14:18.4
9,-11,14:18.4
-16,-10,14:18.4
-12,-10,14:18.4
-11,-10,14:18.4
4,-10,14:18.4
5,-10,14:18.4
9,-10,14:18.4
-16,-9,14:18.4
-10,-9,14:18.12
-9,-9,14:18.12
2,-9,14:18.12
3,-9,14:18.12
9,-9,14:18.4
-16,-8,14:18.4
-8,-8,14:18.12
-7,-8,14:18.12
1,-8,14:18.12
2,-8,14:18.12
9,-8,14:18.4
-16,-7,14:18.4
-5,-7,14:18.12
-4,-7,14:17.12
-3,-7,14:17.12
-1,-7,14:18.12
0,-7,14:18.12
9,-7,14:18.4
-16,-6,14:18.4
-5,-6,14:18.12
-4,-6,14:17.12
-3,-6,14:17.12
-2,-6,14:18.12
9,-6,14:18.4
-16,-5,14:18.4
-5,-5,14:17.12
-4,-5,14:17.12
-3,-5,14:17.12
9,-5,14:18.4
-16,-4,14:18.4
-15,-4,14:18.4
-3,-4,14:18.12
9,-4,14:18.4
-16,-3,14:18.4
-15,-3,14:18.4
-3,-3,14:18.12
9,-3,14:18.4
-16,-2,14:18.4
-15,-2,14:18.4
-3,-2,14:18.12
9,-2,14:18.4
-16,-1,14:18.4
-15,-1,14:18.4
-3,-1,14:18.12
8,-1,14:18.4
9,-1,14:18.4
-16,0,14:18.4
-15,0,14:18.4
-3,0,14:18.12
8,0,14:18.4
9,0,14:18.4
-16,1,14:18.4
-15,1,14:18.4
-3,1,14:18.12
8,1,14:18.4
9,1,14:18.4
-17,2,14:18.4
-16,2,14:18.4
-15,2,14:18.4
-14,2,14:18.4
-3,2,14:18.4
7,2,14:18.4
8,2,14:18.4
9,2,14:18.4
10,2,14:18.12
-14,3,14:18.4
-13,3,14:18.4
-12,3,14:18.4
-3,3,14:18.4
5,3,14:18.4
6,3,14:18.4
10,3,14:18.14
11,3,14:18.12
-13,4,14:18.4
-12,4,14:18.4
-11,4,14:18.4
-3,4,14:18.4
4,4,14:18.4
5,4,14:18.4
6,4,14:18.4
-11,5,14:18.4
-10,5,14:18.4
-9,5,14:18.4
-3,5,14:18.4
2,5,14:18.4
3,5,14:18.4
4,5,14:18.4
-9,6,14:18.4
-8,6,14:18.4
-7,6,14:18.4
-3,6,14:18.4
0,6,14:18.4
1,6,14:18.4
2,6,14:18.4
-8,7,14:18.4
-7,7,14:18.4
-6,7,14:18.4
-3,7,14:18.4
-1,7,14:18.4
0,7,14:18.4
1,7,14:18.4
-6,8,14:18.4
-5,8,14:18.4
-4,8,14:18.4
-3,8,14:18.4
-2,8,14:18.4
-1,8,14:18.4
-4,9,14:18.4
-3,9,14:18.4
-2,9,14:18.4
-4,10,14:18.4
-4,11,14:18.4
-4,-20,15:18.4
-4,-19,15:18.4
-4,-18,15:18.4
-3,-18,15:18.4
-7,-17,15:18.4
-6,-17,15:18.4
-5,-17,15:18.4
-4,-17,15:18.4
-3,-17,15:18.4
-2,-17,15:18.4
-1,-17,15:18.4
0,-17,15:18.4
-9,-16,15:18.4
-8,-16,15:18.4
-7,-16,15:18.4
-6,-16,15:18.4
-5,-16,15:18.4
-4,-16,15:18.4
-3,-16,15:18.4
-2,-16,15:18.4
-1,-16,15:18.4
0,-16,15:18.4
1,-16,15:18.4
2,-16,15:18.4
-11,-15,15:18.4
-10,-15,15:18.4
-9,-15,15:18.4
-8,-15,15:18.4
-7,-15,15:18.4
-6,-15,15:18.4
-5,-15,15:18.4
-4,-15,15:18.4
-3,-15,15:18.4
-2,-15,15:18.4
-1,-15,15:18.4
0,-15,15:18.4
1,-15,15:18.4
2,-15,15:18.4
3,-15,15:18.4
4,-15,15:18.4
-17,-14,15:18.4
-13,-14,15:18.4
-12,-14,15:18.4
-11,-14,15:18.4
-10,-14,15:18.4
-9,-14,15:18.4
-8,-14,15:18.4
-7,-14,15:18.4
-1,-14,15:18.4
0,-14,15:18.4
1,-14,15:18.4
2,-14,15:18.4
3,-14,15:18.4
4,-14,15:18.4
5,-14,15:18.4
6,-14,15:18.4
10,-14,15:18.4
11,-14,15:18.12
-17,-13,15:18.4
-16,-13,15:18.4
-15,-13,15:18.4
-14,-13,15:18.4
-13,-13,15:18.4
-12,-13,15:18.4
-11,-13,15:18.4
-10,-13,15:18.4
-9,-13,15:18.4
2,-13,15:18.4
3,-13,15:18.4
4,-13,15:18.4
5,-13,15:18.4
6,-13,15:18.4
7,-13,15:18.4
8,-13,15:18.4
9,-13,15:18.4
10,-13,15:18.4
-16,-12,15:18.4
-15,-12,15:18.4
-14,-12,15:18.4
-13,-12,15:18.4
-12,-12,15:18.4
4,-12,15:18.4
5,-12,15:18.4
6,-12,15:18.4
7,-12,15:18.4
8,-12,15:18.4
9,-12,15:18.4
-15,-11,15:18.4
-14,-11,15:18.4
-13,-11,15:18.4
5,-11,15:18.4
6,-11,15:18.4
7,-11,15:18.4
8,-11,15:18.4
-15,-10,15:18.4
-14,-10,15:18.4
-12,-10,15:18.4
-11,-10,15:18.4
4,-10,15:18.4
5,-10,15:18.4
6,-10,15:18.4
7,-10,15:18.4
8,-10,15:18.4
-15,-9,15:18.4
-14,-9,15:18.4
-10,-9,15:18.4
-9,-9,15:18.12
2,-9,15:18.12
3,-9,15:18.12
6,-9,15:18.4
7,-9,15:18.4
8,-9,15:18.4
-15,-8,15:18.4
-14,-8,15:18.4
-8,-8,15:18.12
-7,-8,15:18.12
0,-8,15:18.12
1,-8,15:18.12
2,-8,15:18.12
6,-8,15:18.4
7,-8,15:18.4
8,-8,15:18.4
-15,-7,15:18.4
-14,-7,15:18.4
-13,-7,15:18.4
-7,-7,15:18.12
-5,-7,15:18.12
-1,-7,15:18.12
0,-7,15:18.12
6,-7,15:18.4
7,-7,15:18.4
8,-7,15:18.4
-15,-6,15:18.4
-14,-6,15:18.4
-13,-6,15:18.4
-5,-6,15:18.12
-4,-6,15:17.12
-3,-6,15:17.12
-2,-6,15:18.12
6,-6,15:18.4
7,-6,15:18.4
8,-6,15:18.4
-15,-5,15:18.4
-14,-5,15:18.4
-13,-5,15:18.4
-4,-5,15:17.12
-3,-5,15:17.12
6,-5,15:18.4
7,-5,15:18.4
8,-5,15:18.4
-15,-4,15:18.4
-14,-4,15:18.4
-13,-4,15:18.4
-3,-4,15:18.12
6,-4,15:18.4
7,-4,15:18.4
8,-4,15:18.4
-15,-3,15:18.4
-14,-3,15:18.4
-13,-3,15:18.4
-3,-3,15:18.12
6,-3,15:18.4
7,-3,15:18.4
8,-3,15:18.4
-15,-2,15:18.4
-14,-2,15:18.4
-13,-2,15:18.4
-3,-2,15:18.12
6,-2,15:18.4
7,-2,15:18.4
8,-2,15:18.4
-15,-1,15:18.4
-14,-1,15:18.4
-13,-1,15:18.4
-12,-1,15:18.4
-3,-1,15:18.12
6,-1,15:18.4
7,-1,15:18.4
8,-1,15:18.4
-15,0,15:18.4
-14,0,15:18.4
-13,0,15:18.4
-12,0,15:18.4
-3,0,15:18.12
5,0,15:18.4
6,0,15:18.4
7,0,15:18.4
8,0,15:18.4
-15,1,15:18.4
-14,1,15:18.4
-13,1,15:18.4
-12,1,15:18.4
-11,1,15:18.4
-10,1,15:18.4
-3,1,15:18.4
3,1,15:18.4
4,1,15:18.4
5,1,15:18.4
6,1,15:18.4
7,1,15:18.4
8,1,15:18.4
9,1,15:18.4
-17,2,15:18.4
-16,2,15:18.4
-14,2,15:18.4
-13,2,15:18.4
-12,2,15:18.4
-11,2,15:18.4
-10,2,15:18.4
-9,2,15:18.4
-3,2,15:18.4
2,2,15:18.4
3,2,15:18.4
4,2,15:18.4
6,2,15:18.4
7,2,15:18.4
9,2,15:18.4
10,2,15:18.12
-12,3,15:18.4
-11,3,15:18.4
-10,3,15:18.4
-9,3,15:18.4
-8,3,15:18.4
-7,3,15:18.4
-3,3,15:18.4
1,3,15:18.4
2,3,15:18.4
3,3,15:18.4
4,3,15:18.4
5,3,15:18.4
10,3,15:18.12
-11,4,15:18.4
-10,4,15:18.4
-9,4,15:18.4
-8,4,15:18.4
-7,4,15:18.4
-6,4,15:18.4
-3,4,15:18.4
-1,4,15:18.4
0,4,15:18.4
1,4,15:18.4
2,4,15:18.4
3,4,15:18.4
4,4,15:18.4
-9,5,15:18.4
-8,5,15:18.4
-7,5,15:18.4
-6,5,15:18.4
-5,5,15:18.4
-4,5,15:18.4
-3,5,15:18.4
-2,5,15:18.4
-1,5,15:18.4
0,5,15:18.4
1,5,15:18.4
2,5,15:18.4
-7,6,15:18.4
-6,6,15:18.4
-5,6,15:18.4
-4,6,15:18.4
-3,6,15:18.4
-2,6,15:18.4
-1,6,15:18.4
0,6,15:18.4
1,6,15:18.4
-6,7,15:18.4
-5,7,15:18.4
-4,7,15:18.4
-3,7,15:18.4
-2,7,15:18.4
-1,7,15:18.4
-4,8,15:18.4
-3,8,15:18.4
-4,9,15:18.4
-4,10,15:18.4
-4,-19,16:18.4
-4,-18,16:18.4
-4,-17,16:18.4
-3,-17,16:18.4
-3,-16,16:18.4
-4,-15,16:18.4
-3,-15,16:18.4
-17,-14,16:18.4
-7,-14,16:18.4
-6,-14,16:18.4
-5,-14,16:18.4
-4,-14,16:18.4
-3,-14,16:18.4
-2,-14,16:18.4
-1,-14,16:18.4
0,-14,16:18.4
-16,-13,16:18.4
-15,-13,16:18.4
-10,-13,16:18.4
-9,-13,16:18.4
-8,-13,16:18.4
-7,-13,16:18.4
-6,-13,16:18.4
-5,-13,16:18.4
-4,-13,16:18.4
-3,-13,16:18.4
-2,-13,16:18.4
-1,-13,16:18.4
0,-13,16:18.4
1,-13,16:18.4
2,-13,16:18.4
-15,-12,16:18.4
-14,-12,16:18.4
-12,-12,16:18.4
-11,-12,16:18.4
-10,-12,16:18.4
-9,-12,16:18.4
-7,-12,16:18.4
-6,-12,16:18.4
-5,-12,16:18.4
-4,-12,16:18.4
-3,-12,16:18.4
-2,-12,16:18.4
-1,-12,16:18.4
0,-12,16:18.4
1,-12,16:18.4
2,-12,16:18.4
3,-12,16:18.4
4,-12,16:18.4
5,-12,16:18.4
8,-12,16:18.4
9,-12,16:18.4
-14,-11,16:18.4
-13,-11,16:18.4
-12,-11,16:18.4
-11,-11,16:18.4
-10,-11,16:18.4
-9,-11,16:18.4
-8,-11,16:18.12
-7,-11,16:18.12
-6,-11,16:18.12
-1,-11,16:18.12
0,-11,16:18.12
1,-11,16:18.12
2,-11,16:18.12
3,-11,16:18.4
4,-11,16:18.4
5,-11,16:18.4
6,-11,16:18.4
7,-11,16:18.4
8,-11,16:18.4
-13,-10,16:18.4
-12,-10,16:18.4
-11,-10,16:18.4
-9,-10,16:18.12
2,-10,16:18.12
3,-10,16:18.4
4,-10,16:18.4
5,-10,16:18.4
6,-10,16:18.4
-13,-9,16:18.4
-12,-9,16:18.4
-11,-9,16:18.4
-10,-9,16:18.4
-9,-9,16:18.12
2,-9,16:18.12
3,-9,16:18.4
4,-9,16:18.4
5,-9,16:18.4
6,-9,16:18.4
-13,-8,16:18.4
-12,-8,16:18.4
-11,-8,16:18.4
-9,-8,16:18.12
-8,-8,16:18.12
-7,-8,16:18.12
0,-8,16:18.12
1,-8,16:18.12
2,-8,16:18.12
3,-8,16:18.4
4,-8,16:18.4
5,-8,16:18.4
6,-8,16:18.4
-13,-7,16:18.4
-12,-7,16:18.4
-11,-7,16:18.4
-10,-7,16:18.4
-7,-7,16:18.12
-5,-7,16:18.12
-1,-7,16:18.12
0,-7,16:18.12
3,-7,16:18.4
4,-7,16:18.4
5,-7,16:18.4
6,-7,16:18.4
-13,-6,16:18.4
-12,-6,16:18.4
-11,-6,16:18.4
-10,-6,16:18.4
-5,-6,16:18.12
-4,-6,16:18.12
-3,-6,16:18.12
-2,-6,16:18.12
3,-6,16:18.4
4,-6,16:18.4
5,-6,16:18.4
6,-6,16:18.4
-13,-5,16:18.4
-12,-5,16:18.4
-11,-5,16:18.4
-10,-5,16:18.4
-4,-5,16:17.12
-3,-5,16:18.12
3,-5,16:18.4
4,-5,16:18.4
5,-5,16:18.4
6,-5,16:18.4
-12,-4,16:18.4
-11,-4,16:18.4
-10,-4,16:18.4
-3,-4,16:18.12
3,-4,16:18.4
4,-4,16:18.4
5,-4,16:18.4
-12,-3,16:18.4
-11,-3,16:18.4
-10,-3,16:18.4
-3,-3,16:18.12
3,-3,16:18.4
4,-3,16:18.4
5,-3,16:18.4
-12,-2,16:18.4
-11,-2,16:18.4
-10,-2,16:18.4
-9,-2,16:18.12
-3,-2,16:18.12
3,-2,16:18.4
4,-2,16:18.4
5,-2,16:18.4
-12,-1,16:18.4
-11,-1,16:18.4
-10,-1,16:18.4
-9,-1,16:18.12
-8,-1,16:18.12
-3,-1,16:18.12
1,-1,16:18.12
2,-1,16:18.12
3,-1,16:18.4
4,-1,16:18.4
5,-1,16:18.4
-13,0,16:18.4
-12,0,16:18.4
-11,0,16:18.4
-10,0,16:18.4
-9,0,16:18.4
-8,0,16:18.12
-7,0,16:18.12
-3,0,16:18.12
0,0,16:18.12
1,0,16:18.12
2,0,16:18.12
3,0,16:18.4
4,0,16:18.4
5,0,16:18.4
6,0,16:18.4
7,0,16:18.4
-15,1,16:18.4
-14,1,16:18.4
-10,1,16:18.4
-9,1,16:18.4
-8,1,16:18.4
-7,1,16:18.4
-6,1,16:18.4
-5,1,16:18.4
-3,1,16:18.4
-2,1,16:18.4
-1,1,16:18.4
0,1,16:18.4
1,1,16:18.4
2,1,16:18.4
3,1,16:18.4
7,1,16:18.4
8,1,16:18.4
-16,2,16:18.4
-9,2,16:18.4
-8,2,16:18.4
-7,2,16:18.4
-6,2,16:18.4
-5,2,16:18.4
-4,2,16:18.4
-3,2,16:18.4
-2,2,16:18.4
-1,2,16:18.4
0,2,16:18.4
1,2,16:18.4
2,2,16:18.4
9,2,16:18.4
-7,3,16:18.4
-6,3,16:18.4
-5,3,16:18.4
-4,3,16:18.4
-3,3,16:18.4
-2,3,16:18.4
-1,3,16:18.4
0,3,16:18.4
-6,4,16:18.4
-5,4,16:18.4
-4,4,16:18.4
-3,4,16:18.4
-2,4,16:18.4
-1,4,16:18.4
-4,5,16:18.4
-3,5,16:18.4
-2,5,16:18.4
-3,6,16:18.4
-4,7,16:18.4
-3,7,16:18.4
-4,8,16:18.4
-4,9,16:18.4
-4,-16,17:18.4
-4,-15,17:18.4
-4,-14,17:18.4
-3,-14,17:18.4
-3,-13,17:18.4
-14,-12,17:18.4
-4,-12,17:18.4
-3,-12,17:18.4
-13,-11,17:18.4
-12,-11,17:18.4
-7,-11,17:18.12
-6,-11,17:18.12
-5,-11,17:18.12
-4,-11,17:18.12
-3,-11,17:18.12
-2,-11,17:18.12
-1,-11,17:18.12
0,-11,17:18.12
-12,-10,17:18.4
-11,-10,17:18.4
-9,-10,17:18.12
-8,-10,17:18.12
-7,-10,17:18.12
-6,-10,17:18.12
-5,-10,17:18.12
-4,-10,17:18.12
-3,-10,17:18.12
-2,-10,17:18.12
-1,-10,17:18.12
0,-10,17:18.12
1,-10,17:18.12
2,-10,17:18.4
5,-10,17:18.4
6,-10,17:18.4
-10,-9,17:18.4
-9,-9,17:18.12
-8,-9,17:18.12
-7,-9,17:18.12
-6,-9,17:18.12
-5,-9,17:18.12
-4,-9,17:18.12
-3,-9,17:18.12
-2,-9,17:18.12
-1,-9,17:18.12
0,-9,17:18.12
1,-9,17:18.12
2,-9,17:18.12
3,-9,17:18.4
4,-9,17:18.4
5,-9,17:18.4
-10,-8,17:18.4
-9,-8,17:18.12
-8,-8,17:18.12
-7,-8,17:18.12
-6,-8,17:18.12
-1,-8,17:18.12
0,-8,17:18.12
1,-8,17:18.12
2,-8,17:18.12
3,-8,17:18.4
-10,-7,17:18.4
-9,-7,17:18.12
-8,-7,17:18.12
-7,-7,17:18.12
-5,-7,17:18.12
-1,-7,17:18.12
0,-7,17:18.12
1,-7,17:18.12
2,-7,17:18.12
3,-7,17:18.4
-10,-6,17:18.4
-9,-6,17:18.12
-8,-6,17:18.12
-7,-6,17:18.12
-5,-6,17:18.12
-4,-6,17:18.12
-3,-6,17:18.12
-2,-6,17:18.12
0,-6,17:18.12
1,-6,17:18.12
2,-6,17:18.12
3,-6,17:18.4
-10,-5,17:18.4
-9,-5,17:18.12
-8,-5,17:18.12
-7,-5,17:18.12
-3,-5,17:18.12
0,-5,17:18.12
1,-5,17:18.12
2,-5,17:18.12
3,-5,17:18.4
-9,-4,17:18.12
-8,-4,17:18.12
-7,-4,17:18.12
-3,-4,17:18.12
0,-4,17:18.12
1,-4,17:18.12
2,-4,17:18.12
3,-4,17:18.4
-9,-3,17:18.12
-8,-3,17:18.12
-7,-3,17:18.12
-6,-3,17:18.12
-3,-3,17:18.12
-1,-3,17:18.12
0,-3,17:18.12
1,-3,17:18.12
2,-3,17:18.12
-10,-2,17:18.4
-9,-2,17:18.12
-8,-2,17:18.12
-7,-2,17:18.12
-6,-2,17:18.12
-5,-2,17:18.12
-4,-2,17:18.12
-3,-2,17:18.12
-2,-2,17:18.12
-1,-2,17:18.12
0,-2,17:18.12
1,-2,17:18.12
2,-2,17:18.12
3,-2,17:18.4
-11,-1,17:18.4
-10,-1,17:18.4
-8,-1,17:18.12
-7,-1,17:18.12
-6,-1,17:18.12
-5,-1,17:18.12
-4,-1,17:18.12
-3,-1,17:18.12
-2,-1,17:18.12
-1,-1,17:18.12
0,-1,17:18.12
1,-1,17:18.12
4,-1,17:18.4
5,-1,17:18.4
-13,0,17:18.4
-12,0,17:18.4
-6,0,17:18.12
-5,0,17:18.12
-4,0,17:18.12
-3,0,17:18.12
-2,0,17:18.12
-1,0,17:18.12
0,0,17:18.12
6,0,17:18.4
-14,1,17:18.4
-5,1,17:18.4
-4,1,17:18.4
-3,1,17:18.4
-2,1,17:18.4
-4,2,17:18.4
-3,2,17:18.4
-3,3,17:18.4
-3,4,17:18.4
-3,5,17:18.4
-4,6,17:18.4
-4,7,17:18.4
-4,-14,18:18.4
-4,-13,18:18.4
-3,-12,18:18.4
-3,-11,18:18.12
-11,-10,18:18.4
-3,-10,18:18.12
-10,-9,18:18.4
-9,-9,18:18.12
-4,-9,18:18.12
-3,-9,18:18.12
-8,-8,18:18.12
-7,-8,18:18.12
-6,-8,18:18.12
-5,-8,18:18.12
-4,-8,18:18.12
-3,-8,18:18.12
-2,-8,18:18.12
-1,-8,18:18.12
0,-8,18:18.12
1,-8,18:18.12
2,-8,18:18.4
-7,-7,18:18.12
-5,-7,18:18.12
-4,-7,18:18.12
-3,-7,18:18.12
-2,-7,18:18.12
-1,-7,18:18.12
0,-7,18:18.12
-7,-6,18:18.12
-6,-6,18:18.12
-5,-6,18:18.12
-4,-6,18:18.12
-3,-6,18:18.12
-2,-6,18:18.12
-1,-6,18:18.12
0,-6,18:18.12
-7,-5,18:18.12
-6,-5,18:18.12
-5,-5,18:18.12
-4,-5,18:18.12
-3,-5,18:18.12
-2,-5,18:18.12
-1,-5,18:18.12
0,-5,18:18.12
-6,-4,18:18.12
-5,-4,18:18.12
-4,-4,18:18.12
-3,-4,18:18.12
-2,-4,18:18.12
-1,-4,18:18.12
0,-4,18:18.12
-8,-3,18:18.12
-7,-3,18:18.12
-6,-3,18:18.12
-5,-3,18:18.12
-4,-3,18:18.12
-3,-3,18:18.12
-2,-3,18:18.12
-1,-3,18:18.12
1,-3,18:18.12
-9,-2,18:18.12
-4,-2,18:18.12
-3,-2,18:18.12
-2,-2,18:18.12
-10,-1,18:18.4
-3,-1,18:18.12
-3,0,18:18.4
-3,1,18:18.4
-3,2,18:18.4
-3,3,18:18.4
-4,-6,19:18.12
-3,-6,19:18.12
-4,-5,19:18.12
-3,-5,19:18.12
