[META]
version=2.0
spawnOnBlockType=2
spawnSunlight=True
spawnDarkness=True
spawnWater=False
spawnLava=False
underFill=False
randomRotation=True
dig=True
tree=False
branch=False
needsFoundation=True
rarity=100
collisionPercentage=20
spawnElevationMin=0
spawnElevationMax=200
spawnInBiome=Custom
[DATA]
5,-8,-8:17.12
6,-8,-8:17.12
5,-7,-8:17.12
5,-10,-7:17.12
6,-10,-7:17.12
6,-9,-7:17.12
6,-8,-7:17.12
6,-7,-7:17.12
8,-7,-7:17.12
5,-6,-7:17.12
7,-6,-7:17.12
6,-10,-6:17.12
7,-10,-6:17.12
6,-9,-6:17.12
4,-8,-6:17.12
5,-8,-6:17.12
6,-8,-6:17.12
8,-8,-6:17.12
5,-7,-6:17.12
6,-7,-6:17.12
8,-7,-6:17.12
5,-6,-6:17.12
6,-10,-5:17.12
7,-9,-5:17.12
6,-8,-5:17.12
5,-7,-5:17.12
7,-6,-5:17.12
6,-9,-4:17.12
5,-8,-4:17.12
6,-8,-4:17.12
7,-8,-4:17.12
6,-7,-4:17.12
6,-9,-3:17.12
7,-9,-3:17.12
5,-8,-3:17.12
6,-8,-3:17.12
7,-8,-3:17.12
5,-7,-3:17.12
6,-7,-3:17.12
5,-9,-2:17.12
6,-9,-2:17.12
7,-9,-2:17.12
5,-8,-2:17.12
6,-8,-2:17.12
7,-8,-2:17.12
5,-7,-2:17.12
6,-7,-2:17.12
7,-7,-2:17.12
5,-10,-1:18.14
4,-9,-1:18.14
5,-9,-1:18.14
6,-9,-1:17.12
7,-9,-1:17.12
4,-8,-1:18.14
5,-8,-1:18.14
6,-8,-1:18.14
7,-8,-1:17.12
8,-8,-1:18.14
3,-7,-1:18.14
4,-7,-1:18.14
6,-7,-1:18.14
7,-7,-1:18.14
8,-7,-1:18.14
3,-6,-1:18.14
4,-6,-1:18.14
5,-6,-1:18.14
6,-6,-1:18.14
7,-6,-1:18.14
5,-5,-1:18.14
6,-5,-1:18.14
6,-9,0:17.12
7,-9,0:17.12
4,-8,0:18.14
5,-8,0:18.14
6,-8,0:17.12
7,-8,0:17.12
4,-7,0:18.14
5,-7,0:18.14
6,-7,0:18.14
4,-6,0:18.14
5,-6,0:18.14
6,-6,0:18.14
6,-5,0:18.14
6,-9,1:17.12
7,-9,1:17.12
6,-8,1:17.12
7,-8,1:17.12
5,-7,1:18.14
6,-7,1:18.14
6,-9,2:17.12
7,-9,2:17.12
6,-8,2:17.12
7,-8,2:17.12
6,-9,3:17.12
7,-9,3:17.12
6,-8,3:17.12
7,-8,3:17.12
9,-14,4:18.5
9,-13,4:18.13
8,-12,4:18.13
8,-11,4:18.13
8,-10,4:18.13
6,-9,4:17.12
7,-9,4:17.12
6,-8,4:17.12
7,-8,4:17.12
9,-7,4:18.13
10,-7,4:18.13
10,-6,4:18.13
11,-6,4:18.13
12,-6,4:18.5
13,-6,4:18.5
5,-4,4:18.13
4,-3,4:18.5
4,-2,4:18.5
9,-14,5:18.5
9,-13,5:18.13
8,-12,5:18.13
2,-11,5:18.13
3,-11,5:18.13
8,-11,5:18.13
4,-10,5:18.13
5,-10,5:18.13
7,-10,5:18.13
5,-9,5:18.13
6,-9,5:18.13
7,-9,5:17.12
8,-9,5:18.13
6,-8,5:18.13
7,-8,5:17.12
8,-8,5:18.13
6,-7,5:18.13
7,-7,5:18.13
8,-7,5:18.13
9,-7,5:18.13
10,-7,5:18.13
11,-7,5:18.13
5,-6,5:18.13
10,-6,5:18.13
11,-6,5:18.13
12,-6,5:18.5
5,-5,5:18.13
5,-4,5:18.13
4,-3,5:18.5
9,-13,6:18.13
8,-12,6:18.13
2,-11,6:18.13
3,-11,6:18.13
8,-11,6:18.13
3,-10,6:18.13
4,-10,6:18.13
5,-10,6:18.13
7,-10,6:18.13
8,-10,6:18.13
5,-9,6:18.13
6,-9,6:18.13
7,-9,6:18.13
8,-9,6:18.13
6,-8,6:18.13
7,-8,6:17.12
8,-8,6:18.13
6,-7,6:18.13
7,-7,6:18.13
8,-7,6:18.13
9,-7,6:18.13
10,-7,6:18.13
5,-6,6:18.13
6,-6,6:18.13
11,-6,6:18.13
5,-5,6:18.13
5,-4,6:18.13
5,-12,7:18.13
8,-12,7:18.13
3,-11,7:18.13
5,-11,7:18.13
8,-11,7:18.13
10,-11,7:18.13
4,-10,7:18.13
5,-10,7:18.13
6,-10,7:18.13
8,-10,7:18.13
9,-10,7:18.13
10,-10,7:18.13
5,-9,7:18.13
6,-9,7:18.13
7,-9,7:18.13
8,-9,7:18.13
6,-8,7:18.13
7,-8,7:17.12
8,-8,7:18.13
6,-7,7:18.13
7,-7,7:18.13
8,-7,7:18.13
9,-7,7:18.13
10,-7,7:18.13
6,-6,7:18.13
11,-6,7:18.13
5,-5,7:18.13
5,-4,7:18.13
5,-11,8:18.13
6,-11,8:18.13
10,-11,8:18.13
11,-11,8:18.13
4,-10,8:18.13
5,-10,8:18.13
6,-10,8:18.13
9,-10,8:18.13
10,-10,8:18.13
6,-9,8:18.13
7,-9,8:18.13
8,-9,8:18.13
6,-8,8:18.13
7,-8,8:17.12
8,-8,8:18.13
5,-7,8:18.13
6,-7,8:18.13
8,-7,8:18.13
9,-7,8:18.13
8,-6,8:18.13
9,-6,8:18.13
9,-5,8:18.13
9,-4,8:18.13
6,-11,9:18.13
6,-10,9:18.13
9,-10,9:18.13
10,-10,9:18.13
7,-9,9:18.13
8,-9,9:18.13
6,-8,9:18.13
7,-8,9:18.13
5,-7,9:18.13
6,-7,9:18.13
8,-7,9:18.13
3,-6,9:18.13
4,-6,9:18.13
8,-6,9:18.13
9,-6,9:18.13
9,-5,9:18.13
9,-10,10:18.13
10,-10,10:18.13
7,-9,10:18.13
8,-9,10:18.13
6,-8,10:18.13
7,-8,10:18.13
8,-8,10:18.13
5,-7,10:18.13
6,-7,10:18.13
8,-7,10:18.13
4,-6,10:18.13
8,-6,10:18.13
9,-6,10:18.13
9,-5,10:18.13
11,-14,11:18.5
10,-13,11:18.5
9,-12,11:18.13
9,-11,11:18.13
4,-10,11:18.13
5,-10,11:18.13
8,-10,11:18.13
5,-9,11:18.13
6,-9,11:18.13
7,-9,11:18.13
8,-9,11:18.13
6,-8,11:18.13
7,-8,11:18.13
8,-8,11:18.13
5,-7,11:18.13
6,-7,11:18.13
7,-7,11:18.13
8,-7,11:18.13
9,-7,11:18.13
10,-7,11:18.13
9,-6,11:18.13
11,-6,11:18.13
12,-6,11:18.5
11,-14,12:18.5
10,-13,12:18.5
9,-12,12:18.13
10,-12,12:18.13
9,-11,12:18.13
4,-10,12:18.13
5,-10,12:18.13
8,-10,12:18.13
6,-9,12:18.13
7,-9,12:18.13
8,-9,12:18.13
7,-8,12:18.13
8,-8,12:18.13
7,-7,12:18.13
9,-7,12:18.13
10,-7,12:18.13
6,-6,12:18.13
11,-6,12:18.13
12,-6,12:18.5
6,-5,12:18.13
5,-4,12:18.13
5,-3,12:18.5
11,-14,13:18.5
10,-13,13:18.5
10,-12,13:18.5
9,-11,13:18.5
4,-10,13:18.5
5,-10,13:18.5
8,-10,13:18.5
9,-10,13:18.5
6,-9,13:18.5
7,-9,13:18.5
8,-9,13:18.5
7,-8,13:18.5
8,-8,13:18.5
9,-8,13:18.5
7,-7,13:18.5
9,-7,13:18.5
10,-7,13:18.5
6,-6,13:18.5
11,-6,13:18.5
12,-6,13:18.5
6,-5,13:18.5
5,-4,13:18.5
6,-4,13:18.5
5,-3,13:18.5
10,-12,14:18.5
9,-11,14:18.5
5,-10,14:18.5
8,-10,14:18.5
9,-10,14:18.5
6,-9,14:18.5
7,-9,14:18.5
8,-9,14:18.5
7,-8,14:18.5
8,-8,14:18.5
9,-8,14:18.5
7,-7,14:18.5
9,-7,14:18.5
10,-7,14:18.5
6,-6,14:18.5
7,-6,14:18.5
11,-6,14:18.5
12,-6,14:18.5
6,-5,14:18.5
6,-4,14:18.5
9,-11,15:18.5
11,-11,15:18.5
8,-10,15:18.5
9,-10,15:18.5
6,-9,15:18.5
7,-9,15:18.5
8,-9,15:18.5
7,-8,15:18.5
8,-8,15:18.5
9,-8,15:18.5
7,-7,15:18.5
9,-7,15:18.5
10,-7,15:18.5
7,-6,15:18.5
6,-5,15:18.5
10,-5,15:18.5
5,-12,16:18.5
6,-11,16:18.5
11,-11,16:18.5
6,-10,16:18.5
7,-10,16:18.5
10,-10,16:18.5
7,-9,16:18.5
8,-9,16:18.5
9,-9,16:18.5
6,-8,16:18.5
7,-8,16:18.5
8,-8,16:18.5
4,-7,16:18.5
5,-7,16:18.5
8,-7,16:18.5
9,-7,16:18.5
9,-6,16:18.5
10,-6,16:18.5
10,-5,16:18.5
5,-12,17:18.5
6,-11,17:18.5
11,-11,17:18.5
6,-10,17:18.5
7,-10,17:18.5
10,-10,17:18.5
7,-9,17:18.5
8,-9,17:18.5
9,-9,17:18.5
6,-8,17:18.5
7,-8,17:18.5
8,-8,17:18.5
4,-7,17:18.5
5,-7,17:18.5
6,-7,17:18.5
8,-7,17:18.5
9,-7,17:18.5
9,-6,17:18.5
10,-6,17:18.5
6,-11,18:18.5
7,-10,18:18.5
10,-10,18:18.5
7,-9,18:18.5
8,-9,18:18.5
9,-9,18:18.5
5,-8,18:18.5
6,-8,18:18.5
7,-8,18:18.5
8,-8,18:18.5
5,-7,18:18.5
6,-7,18:18.5
8,-7,18:18.5
9,-7,18:18.5
9,-13,19:18.5
9,-12,19:18.5
8,-11,19:18.5
9,-11,19:18.5
8,-10,19:18.5
6,-9,19:18.5
7,-9,19:18.5
8,-9,19:18.5
5,-8,19:18.5
6,-8,19:18.5
8,-8,19:18.5
9,-8,19:18.5
10,-8,19:18.5
11,-8,19:18.5
8,-7,19:18.5
8,-6,19:18.5
8,-5,19:18.5
9,-13,20:18.5
9,-12,20:18.5
9,-11,20:18.5
8,-10,20:18.5
7,-9,20:18.5
8,-9,20:18.5
5,-8,20:18.5
6,-8,20:18.5
8,-8,20:18.5
9,-8,20:18.5
10,-8,20:18.5
11,-8,20:18.5
8,-7,20:18.5
8,-6,20:18.5
8,-5,20:18.5
9,-12,21:18.5
9,-11,21:18.5
8,-10,21:18.5
9,-10,21:18.5
7,-9,21:18.5
8,-9,21:18.5
6,-8,21:18.5
8,-8,21:18.5
9,-8,21:18.5
10,-8,21:18.5
11,-8,21:18.5
8,-7,21:18.5
8,-6,21:18.5
6,-10,22:18.5
7,-9,22:18.5
8,-9,22:18.5
8,-8,22:18.5
9,-8,22:18.5
7,-7,22:18.5
8,-7,22:18.5
7,-6,22:18.5
6,-10,23:18.5
9,-10,23:18.5
10,-10,23:18.5
7,-9,23:18.5
8,-9,23:18.5
9,-9,23:18.5
8,-8,23:18.5
9,-8,23:18.5
10,-8,23:18.5
8,-7,23:18.5
10,-7,23:18.5
11,-7,23:18.5
7,-6,23:18.5
6,-10,24:18.5
10,-10,24:18.5
7,-9,24:18.5
8,-9,24:18.5
9,-9,24:18.5
8,-8,24:18.5
9,-8,24:18.5
10,-8,24:18.5
8,-7,24:18.5
11,-7,24:18.5
7,-6,24:18.5
10,-10,25:18.5
7,-9,25:18.5
8,-9,25:18.5
9,-9,25:18.5
8,-8,25:18.5
9,-8,25:18.5
10,-8,25:18.5
9,-9,26:18.5
