[META]
version=2.0
spawnOnBlockType=2
spawnSunlight=True
spawnDarkness=True
spawnWater=False
spawnLava=False
underFill=False
randomRotation=True
dig=True
tree=False
branch=False
needsFoundation=True
rarity=100
collisionPercentage=20
spawnElevationMin=0
spawnElevationMax=200
spawnInBiome=Custom
[DATA]
-1,-1,-8:17.12
-1,0,-8:17.12
-2,-2,-7:17.12
-1,-2,-7:17.12
-3,-1,-7:17.12
-2,-1,-7:17.12
1,-1,-7:17.12
-3,0,-7:17.12
-2,0,-7:17.12
-3,1,-7:17.12
1,1,-7:17.12
-2,-2,-6:17.12
-1,-2,-6:17.12
-1,-1,-6:17.12
0,-1,-6:17.12
1,-1,-6:17.12
-3,0,-6:17.12
-2,0,-6:17.12
-1,0,-6:17.12
-1,1,-6:17.12
0,1,-6:17.12
-2,2,-6:17.12
-1,2,-6:17.12
0,2,-6:17.12
-2,-2,-5:17.12
-1,-2,-5:17.12
-2,-1,-5:17.12
-1,-1,-5:17.12
-3,0,-5:17.12
-2,0,-5:17.12
-1,0,-5:17.12
0,0,-5:17.12
1,0,-5:17.12
-1,2,-5:17.12
0,2,-5:17.12
-1,-2,-4:17.12
-1,-1,-4:17.12
-3,0,-4:17.12
-2,0,-4:17.12
-1,0,-4:17.12
0,0,-4:17.12
1,0,-4:17.12
-3,1,-4:17.12
-1,1,-4:17.12
0,1,-4:17.12
1,1,-4:17.12
-1,2,-4:17.12
0,2,-4:17.12
-2,-2,-3:17.12
-1,-2,-3:17.12
-2,-1,-3:17.12
-1,-1,-3:17.12
-3,0,-3:17.12
-1,0,-3:17.12
0,0,-3:17.12
-1,1,-3:17.12
1,1,-3:17.12
-2,2,-3:17.12
-1,2,-3:17.12
-2,-2,-2:17.12
-1,-2,-2:17.12
0,-2,-2:17.12
-3,-1,-2:17.12
-2,-1,-2:17.12
0,-1,-2:17.12
1,-1,-2:17.12
-3,0,-2:17.12
-1,0,-2:17.12
0,0,-2:17.12
1,0,-2:17.12
-2,1,-2:17.12
0,1,-2:17.12
1,1,-2:17.12
-2,2,-2:17.12
-1,2,-2:17.12
0,2,-2:17.12
-1,-2,-1:17.12
0,-2,-1:17.12
-2,-1,-1:17.12
0,-1,-1:17.12
-3,0,-1:17.12
-2,0,-1:17.12
0,0,-1:17.12
1,0,-1:17.12
-2,1,-1:17.12
-1,1,-1:17.12
0,1,-1:17.12
-1,2,-1:17.12
-2,-1,0:17.12
-1,-1,0:17.12
0,-1,0:17.12
-2,0,0:17.12
0,0,0:17.12
-2,1,0:17.12
-1,1,0:17.12
0,1,0:17.12
-2,-1,1:17.12
-1,-1,1:17.12
0,-1,1:17.12
-2,0,1:17.12
0,0,1:17.12
-2,1,1:17.12
-1,1,1:17.12
0,1,1:17.12
-2,-1,2:17.12
-1,-1,2:17.12
0,-1,2:17.12
-2,0,2:17.12
0,0,2:17.12
-2,1,2:17.12
-1,1,2:17.12
-2,-1,3:17.12
-1,-1,3:17.12
0,-1,3:17.12
-2,0,3:17.12
0,0,3:17.12
-2,1,3:17.12
-1,1,3:17.12
-2,-1,4:17.12
-1,-1,4:17.12
-2,0,4:17.12
-1,0,4:17.12
0,0,4:17.12
-1,1,4:17.12
-2,-1,5:17.12
-1,-1,5:17.12
-2,0,5:17.12
-1,0,5:17.12
-2,-1,6:17.12
-1,-1,6:17.12
-2,0,6:17.12
-1,0,6:17.12
-2,-1,7:17.12
-1,-1,7:17.12
-2,0,7:17.12
-1,0,7:17.12
3,-7,8:18.4
-2,-1,8:17.12
-1,-1,8:17.12
-2,0,8:17.12
-1,0,8:17.12
4,-9,9:18.4
3,-8,9:18.4
4,-8,9:18.4
3,-7,9:18.4
-9,-6,9:18.4
2,-6,9:18.4
3,-6,9:18.4
-8,-5,9:18.4
-7,-4,9:18.4
-6,-4,9:18.12
-3,-2,9:18.12
-2,-1,9:17.12
-1,-1,9:17.12
-2,0,9:17.12
-1,0,9:17.12
-5,5,9:18.4
-6,6,9:18.4
-6,7,9:18.4
-7,8,9:18.4
4,-10,10:18.4
5,-10,10:18.4
4,-9,10:18.4
3,-8,10:18.4
3,-7,10:18.4
-10,-6,10:18.4
-9,-6,10:18.4
2,-6,10:18.4
-8,-5,10:18.4
-7,-5,10:18.4
2,-5,10:18.12
-7,-4,10:18.4
-6,-4,10:18.12
1,-4,10:18.12
-5,-3,10:18.12
-4,-3,10:18.12
1,-3,10:18.12
-3,-2,10:18.12
-2,-2,10:18.12
-1,-2,10:18.12
0,-2,10:18.12
1,-2,10:18.12
-3,-1,10:18.12
-2,-1,10:17.12
-1,-1,10:17.12
0,-1,10:18.12
1,-1,10:18.12
-3,0,10:18.12
-2,0,10:17.12
-1,0,10:17.12
1,0,10:18.12
-3,1,10:18.12
-2,1,10:18.12
-1,1,10:18.12
0,1,10:18.12
1,1,10:18.12
-4,2,10:18.12
1,2,10:18.12
-4,3,10:18.12
3,3,10:18.12
-5,4,10:18.12
3,4,10:18.12
4,4,10:18.4
-5,5,10:18.4
-6,6,10:18.4
-6,7,10:18.4
-7,8,10:18.4
4,-9,11:18.4
3,-8,11:18.4
3,-7,11:18.4
-10,-6,11:18.4
-9,-6,11:18.4
2,-6,11:18.4
-8,-5,11:18.4
2,-5,11:18.12
-6,-4,11:18.12
1,-4,11:18.12
-5,-3,11:18.12
-4,-3,11:18.12
1,-3,11:18.12
-3,-2,11:18.12
-2,-2,11:18.12
-1,-2,11:18.12
0,-2,11:18.12
-3,-1,11:18.12
-2,-1,11:18.12
-1,-1,11:18.12
0,-1,11:18.12
-3,0,11:18.12
-2,0,11:18.12
-1,0,11:18.12
0,0,11:18.12
-3,1,11:18.12
-2,1,11:18.12
-1,1,11:18.12
0,1,11:18.12
-4,2,11:18.12
-3,2,11:18.12
1,2,11:18.12
2,2,11:18.12
-4,3,11:18.12
2,3,11:18.12
3,3,11:18.12
-5,4,11:18.12
-4,4,11:18.12
3,4,11:18.12
4,4,11:18.4
-5,5,11:18.4
5,5,11:18.4
-6,6,11:18.4
-6,7,11:18.4
-7,8,11:18.4
-7,9,11:18.4
3,-7,12:18.4
-10,-6,12:18.4
-9,-6,12:18.4
2,-6,12:18.4
-8,-5,12:18.4
-7,-5,12:18.4
1,-5,12:18.12
2,-5,12:18.12
-7,-4,12:18.4
-6,-4,12:18.12
1,-4,12:18.12
-5,-3,12:18.12
-4,-3,12:18.12
0,-3,12:18.12
1,-3,12:18.12
-3,-2,12:18.12
-2,-2,12:18.12
-1,-2,12:18.12
0,-2,12:18.12
-3,-1,12:18.12
-2,-1,12:17.12
-1,-1,12:17.12
0,-1,12:18.12
-3,0,12:18.12
-2,0,12:17.12
-1,0,12:17.12
0,0,12:18.12
-3,1,12:18.12
-2,1,12:18.12
-1,1,12:18.12
0,1,12:18.12
-4,2,12:18.12
-3,2,12:18.12
1,2,12:18.12
2,2,12:18.12
-4,3,12:18.12
2,3,12:18.12
3,3,12:18.12
-5,4,12:18.12
4,4,12:18.4
-5,5,12:18.4
5,5,12:18.4
-6,6,12:18.4
6,6,12:18.4
-6,7,12:18.4
-7,8,12:18.4
-7,-4,13:18.12
-6,-4,13:18.12
1,-4,13:18.12
-5,-3,13:18.12
-4,-3,13:18.12
0,-3,13:18.12
1,-3,13:18.12
-3,-2,13:18.12
-2,-2,13:18.12
-1,-2,13:18.12
0,-2,13:18.12
-3,-1,13:18.12
-2,-1,13:17.12
-1,-1,13:17.12
0,-1,13:18.12
-3,0,13:18.12
-2,0,13:17.12
-1,0,13:17.12
0,0,13:18.12
-3,1,13:18.12
-2,1,13:18.12
-1,1,13:18.12
0,1,13:18.12
1,1,13:18.12
-4,2,13:18.12
-3,2,13:18.12
1,2,13:18.12
2,2,13:18.12
-4,3,13:18.12
2,3,13:18.12
3,3,13:18.12
-5,4,13:18.12
3,4,13:18.12
4,4,13:18.4
-5,5,13:18.4
5,5,13:18.4
-6,6,13:18.4
-7,8,13:18.4
1,-4,14:18.12
-5,-3,14:18.12
-4,-3,14:18.12
0,-3,14:18.12
-3,-2,14:18.12
-2,-2,14:18.12
-1,-2,14:18.12
0,-2,14:18.12
-3,-1,14:18.12
-2,-1,14:17.12
-1,-1,14:17.12
0,-1,14:18.12
-3,0,14:18.12
-2,0,14:17.12
-1,0,14:17.12
0,0,14:18.12
-3,1,14:18.12
-2,1,14:18.12
-1,1,14:18.12
0,1,14:18.12
-4,2,14:18.12
1,2,14:18.12
2,2,14:18.12
-4,3,14:18.12
0,3,14:18.12
3,3,14:18.12
0,4,14:18.12
1,5,14:18.4
5,5,14:18.4
1,6,14:18.4
-3,-2,15:18.12
0,-2,15:18.12
-2,-1,15:17.12
-1,-1,15:17.12
-3,0,15:18.12
-2,0,15:18.12
-1,0,15:17.12
-6,1,15:18.12
-5,1,15:18.12
-3,1,15:18.12
-1,1,15:18.12
0,1,15:18.12
-7,2,15:18.12
-1,2,15:18.12
1,2,15:18.12
0,3,15:18.12
0,4,15:18.12
1,5,15:18.4
1,6,15:18.4
-3,-5,16:18.12
-3,-4,16:18.12
2,-3,16:18.12
3,-3,16:18.12
-2,-2,16:18.12
0,-2,16:18.12
1,-2,16:18.12
-2,-1,16:17.12
-1,-1,16:17.12
-4,0,16:18.12
-3,0,16:18.12
-2,0,16:18.12
-1,0,16:17.12
-6,1,16:18.12
-5,1,16:18.12
-1,1,16:18.12
-8,2,16:18.4
-7,2,16:18.12
-1,2,16:18.12
0,4,16:18.12
1,5,16:18.4
-4,-7,17:18.4
-4,-6,17:18.12
-4,-5,17:18.12
-3,-5,17:18.12
-3,-4,17:18.12
-3,-3,17:18.12
2,-3,17:18.12
3,-3,17:18.12
-2,-2,17:18.12
0,-2,17:18.12
1,-2,17:18.12
-3,-1,17:17.12
-2,-1,17:17.12
-1,-1,17:17.12
-4,0,17:18.12
-3,0,17:18.12
-2,0,17:18.12
-1,0,17:17.12
-5,1,17:18.12
-1,1,17:18.12
-8,2,17:18.4
-7,2,17:18.12
-1,2,17:18.12
0,3,17:18.12
0,4,17:18.12
-5,-8,18:18.4
-4,-7,18:18.4
-4,-6,18:18.12
-3,-4,18:18.12
4,-4,18:18.4
-3,-3,18:18.12
2,-3,18:18.12
3,-3,18:18.12
-2,-2,18:18.12
-1,-2,18:18.12
0,-2,18:18.12
1,-2,18:18.12
-3,-1,18:17.12
-2,-1,18:18.12
-1,-1,18:17.12
-5,0,18:18.12
-4,0,18:18.12
-3,0,18:18.12
-2,0,18:18.12
-7,1,18:18.12
-6,1,18:18.12
-5,1,18:18.12
-1,1,18:18.12
-9,2,18:18.4
-8,2,18:18.4
-7,2,18:18.12
-1,2,18:18.12
-6,-9,19:18.4
-6,-8,19:18.4
-5,-8,19:18.4
-5,-7,19:18.4
-4,-7,19:18.4
-4,-6,19:18.12
-4,-5,19:18.12
-3,-5,19:18.12
-3,-4,19:18.12
4,-4,19:18.4
5,-4,19:18.4
-3,-3,19:18.12
2,-3,19:18.12
3,-3,19:18.12
-2,-2,19:18.12
-1,-2,19:18.12
0,-2,19:18.12
1,-2,19:18.12
-3,-1,19:17.12
-2,-1,19:18.12
-1,-1,19:17.12
-5,0,19:18.12
-4,0,19:18.12
-3,0,19:18.12
-2,0,19:18.12
-7,1,19:18.12
-6,1,19:18.12
-5,1,19:18.12
-1,1,19:18.12
-9,2,19:18.4
-8,2,19:18.4
1,5,19:18.4
2,6,19:18.4
-7,-10,20:18.4
-6,-9,20:18.4
-6,-8,20:18.4
-5,-8,20:18.4
-5,-7,20:18.4
-4,-7,20:18.4
-4,-6,20:18.12
-4,-5,20:18.12
-3,-5,20:18.12
-3,-4,20:18.12
4,-4,20:18.4
5,-4,20:18.4
-3,-3,20:18.12
-2,-3,20:18.12
-1,-3,20:18.12
1,-3,20:18.12
2,-3,20:18.12
3,-3,20:18.12
4,-3,20:18.4
-3,-2,20:18.12
-2,-2,20:18.12
-1,-2,20:18.12
0,-2,20:18.12
1,-2,20:18.12
-4,-1,20:18.12
-3,-1,20:17.12
-2,-1,20:18.12
-1,-1,20:17.12
0,-1,20:18.12
-5,0,20:18.12
-4,0,20:18.12
-3,0,20:18.12
-2,0,20:18.12
0,0,20:18.12
-7,1,20:18.12
-6,1,20:18.12
-3,1,20:18.12
-2,1,20:18.12
-1,1,20:18.12
-9,2,20:18.4
-8,2,20:18.4
-1,2,20:18.12
-10,3,20:18.4
0,3,20:18.12
1,4,20:18.12
1,5,20:18.4
2,6,20:18.4
2,7,20:18.4
3,8,20:18.4
-6,-9,21:18.4
-6,-8,21:18.4
-5,-8,21:18.4
-5,-7,21:18.4
-4,-6,21:18.12
-4,-5,21:18.12
-3,-5,21:18.12
-3,-4,21:18.12
4,-4,21:18.4
5,-4,21:18.4
6,-4,21:18.4
-3,-3,21:18.12
-2,-3,21:18.12
-1,-3,21:18.12
2,-3,21:18.12
3,-3,21:18.12
4,-3,21:18.4
5,-3,21:18.4
-3,-2,21:18.12
-2,-2,21:17.12
-1,-2,21:18.12
0,-2,21:18.12
1,-2,21:18.12
2,-2,21:18.12
-4,-1,21:18.12
-3,-1,21:17.12
-2,-1,21:18.12
-1,-1,21:17.12
0,-1,21:18.12
-5,0,21:18.12
-4,0,21:18.12
-3,0,21:18.12
-2,0,21:17.12
-1,0,21:18.12
0,0,21:18.12
-7,1,21:18.12
-6,1,21:18.12
-2,1,21:18.12
-1,1,21:18.12
-9,2,21:18.4
-8,2,21:18.4
-1,2,21:18.12
-10,3,21:18.4
0,3,21:18.12
-11,4,21:18.4
0,4,21:18.12
1,4,21:18.12
-12,5,21:18.4
1,5,21:18.4
-13,6,21:18.4
2,6,21:18.4
-13,7,21:18.4
2,7,21:18.4
-5,-7,22:18.4
-4,-6,22:18.12
-4,-5,22:18.12
-3,-4,22:18.12
6,-4,22:18.4
-3,-3,22:18.12
-2,-3,22:18.12
3,-3,22:18.12
4,-3,22:18.4
5,-3,22:18.4
-3,-2,22:18.12
-2,-2,22:17.12
-1,-2,22:18.12
0,-2,22:18.12
1,-2,22:18.12
2,-2,22:18.12
-4,-1,22:18.12
-3,-1,22:17.12
-2,-1,22:17.12
-1,-1,22:17.12
0,-1,22:18.12
-6,0,22:18.12
-5,0,22:18.12
-4,0,22:18.12
-3,0,22:18.12
-2,0,22:17.12
-1,0,22:18.12
-7,1,22:18.12
-6,1,22:18.12
-2,1,22:18.12
-1,1,22:18.12
-9,2,22:18.4
-8,2,22:18.4
-1,2,22:18.12
-10,3,22:18.4
0,3,22:18.12
-11,4,22:18.4
0,4,22:18.12
1,4,22:18.12
-12,5,22:18.4
1,5,22:18.4
-13,6,22:18.4
2,6,22:18.4
-13,7,22:18.4
2,7,22:18.4
3,8,22:18.4
-4,-5,23:18.12
-3,-4,23:18.12
5,-4,23:18.4
6,-4,23:18.4
-3,-3,23:18.12
-2,-3,23:18.12
1,-3,23:18.12
2,-3,23:18.12
3,-3,23:18.12
4,-3,23:18.4
5,-3,23:18.4
-3,-2,23:18.12
-2,-2,23:17.12
-1,-2,23:18.12
0,-2,23:18.12
1,-2,23:18.12
2,-2,23:18.12
-4,-1,23:18.12
-3,-1,23:17.12
-2,-1,23:17.12
-1,-1,23:18.12
0,-1,23:18.12
-6,0,23:18.12
-5,0,23:18.12
-4,0,23:18.12
-3,0,23:18.12
-2,0,23:18.12
-1,0,23:18.12
-7,1,23:18.12
-6,1,23:18.12
-2,1,23:18.12
-1,1,23:18.12
-8,2,23:18.4
-1,2,23:18.12
0,2,23:18.12
-11,3,23:18.4
-10,3,23:18.4
0,3,23:18.12
-11,4,23:18.4
0,4,23:18.12
1,4,23:18.12
-12,5,23:18.4
1,5,23:18.4
-13,6,23:18.4
2,6,23:18.4
2,7,23:18.4
-5,-7,24:18.4
-4,-5,24:18.12
-3,-4,24:18.12
3,-4,24:18.12
-3,-3,24:18.12
-2,-3,24:18.12
1,-3,24:18.12
2,-3,24:18.12
3,-3,24:18.12
4,-3,24:18.4
-3,-2,24:18.12
-2,-2,24:17.12
-1,-2,24:18.12
0,-2,24:18.12
1,-2,24:18.12
2,-2,24:18.12
-4,-1,24:18.12
-3,-1,24:17.12
-2,-1,24:17.12
-1,-1,24:18.12
0,-1,24:18.12
-7,0,24:18.12
-6,0,24:18.12
-5,0,24:18.12
-4,0,24:18.12
-3,0,24:18.12
-2,0,24:18.12
-1,0,24:18.12
-8,1,24:18.4
-2,1,24:18.12
-1,1,24:18.12
-1,2,24:18.12
0,2,24:18.12
-1,3,24:18.12
0,3,24:18.12
-11,4,24:18.4
0,4,24:18.12
-12,5,24:18.4
0,5,24:18.4
1,5,24:18.4
-13,6,24:18.4
-13,7,24:18.4
-5,-7,25:18.4
-5,-6,25:18.12
-4,-5,25:18.12
-4,-4,25:18.12
3,-4,25:18.12
-3,-3,25:18.12
1,-3,25:18.12
2,-3,25:18.12
-3,-2,25:18.12
-2,-2,25:17.12
-1,-2,25:18.12
0,-2,25:18.12
1,-2,25:18.12
-4,-1,25:18.12
-3,-1,25:17.12
-2,-1,25:17.12
-7,0,25:18.12
-6,0,25:18.12
-5,0,25:18.12
-2,0,25:18.12
-1,0,25:18.12
-8,1,25:18.4
-1,1,25:18.12
-1,2,25:18.12
-1,3,25:18.12
-11,4,25:18.4
0,4,25:18.12
-12,5,25:18.4
0,5,25:18.4
-13,6,25:18.12
0,6,25:18.4
-13,7,25:18.12
-6,-9,26:18.4
-6,-8,26:18.4
-5,-7,26:18.4
-5,-6,26:18.12
-4,-5,26:18.12
-4,-4,26:18.12
3,-4,26:18.12
-3,-3,26:18.12
2,-3,26:18.12
-3,-2,26:18.12
-2,-2,26:17.12
-1,-2,26:18.12
0,-2,26:18.12
-5,-1,26:18.12
-4,-1,26:18.12
-3,-1,26:17.12
-2,-1,26:17.12
-7,0,26:18.12
-6,0,26:18.12
-5,0,26:18.12
-2,0,26:18.12
-10,1,26:18.4
-9,1,26:18.4
-8,1,26:18.4
-1,1,26:18.12
-10,2,26:18.4
-1,2,26:18.12
-1,3,26:18.12
-1,4,26:18.12
0,4,26:18.12
0,5,26:18.4
0,6,26:18.4
1,7,26:18.4
1,8,26:18.4
-7,-11,27:18.4
-6,-9,27:18.4
-6,-8,27:18.4
-5,-7,27:18.4
-4,-5,27:18.12
-4,-4,27:18.12
3,-4,27:18.4
4,-4,27:18.4
-3,-3,27:18.12
1,-3,27:18.12
2,-3,27:18.12
-3,-2,27:18.12
-2,-2,27:17.12
-1,-2,27:18.12
0,-2,27:18.12
-5,-1,27:18.12
-4,-1,27:18.12
-3,-1,27:18.12
-2,-1,27:17.12
-6,0,27:18.12
-5,0,27:18.12
-2,0,27:18.12
-10,1,27:18.4
-9,1,27:18.4
-8,1,27:18.4
-2,1,27:18.12
-1,1,27:18.12
-11,2,27:18.4
-1,2,27:18.12
-1,3,27:18.12
0,5,27:18.4
0,6,27:18.4
1,7,27:18.4
1,8,27:18.4
-7,-10,28:18.4
-6,-9,28:18.4
-6,-8,28:18.4
-5,-7,28:18.4
-5,-6,28:18.12
-4,-5,28:18.12
-4,-4,28:18.12
3,-4,28:18.4
-3,-3,28:18.12
1,-3,28:18.12
2,-3,28:18.12
-3,-2,28:18.12
-2,-2,28:17.12
-1,-2,28:18.12
0,-2,28:18.12
-5,-1,28:18.12
-4,-1,28:18.12
-3,-1,28:18.12
-2,-1,28:18.12
-7,0,28:18.12
-6,0,28:18.12
-2,0,28:18.12
-10,1,28:18.4
-9,1,28:18.4
-8,1,28:18.4
-2,1,28:18.12
-1,1,28:18.12
-1,2,28:18.12
-1,3,28:18.12
-1,4,28:18.4
0,5,28:18.4
0,6,28:18.4
1,8,28:18.4
-7,-10,29:18.4
-6,-9,29:18.4
-6,-8,29:18.4
-5,-7,29:18.4
-5,-6,29:18.12
-4,-5,29:18.12
-4,-4,29:18.12
3,-4,29:18.4
-3,-3,29:18.12
0,-3,29:18.12
1,-3,29:18.12
-3,-2,29:18.12
-2,-2,29:17.12
-1,-2,29:18.12
0,-2,29:18.12
-5,-1,29:18.12
-4,-1,29:18.12
-3,-1,29:18.12
-2,-1,29:18.12
-7,0,29:18.12
-6,0,29:18.12
-2,0,29:18.12
-10,1,29:18.4
-9,1,29:18.4
-2,1,29:18.12
-12,2,29:18.4
-11,2,29:18.4
-1,2,29:18.12
-1,3,29:18.12
-1,4,29:18.4
0,5,29:18.4
0,6,29:18.4
1,8,29:18.4
1,9,29:18.4
-5,-7,30:18.4
-5,-6,30:18.12
-4,-4,30:18.12
-3,-3,30:18.12
1,-3,30:18.12
-3,-2,30:18.12
-2,-2,30:18.12
-1,-2,30:18.12
-4,-1,30:18.12
-3,-1,30:17.12
-2,-1,30:17.12
-7,0,30:18.12
-6,0,30:18.12
-2,0,30:18.12
-10,1,30:18.4
-9,1,30:18.4
-2,1,30:18.12
-12,2,30:18.4
-1,3,30:18.12
-1,4,30:18.4
0,5,30:18.4
0,6,30:18.4
0,7,30:18.4
1,7,30:18.4
1,8,30:18.4
-4,-4,31:18.12
-3,-3,31:18.12
-3,-2,31:18.12
-2,-2,31:17.12
-1,-2,31:18.12
-5,-1,31:18.12
-4,-1,31:18.12
-3,-1,31:17.12
-2,-1,31:17.12
-2,0,31:18.12
-2,1,31:18.12
0,5,31:18.4
1,8,31:18.4
-3,-2,32:17.12
-2,-2,32:17.12
-3,-1,32:17.12
-2,-1,32:17.12
0,-1,32:18.12
1,-1,32:18.12
-2,-6,33:18.12
-2,-5,33:18.12
-2,-4,33:18.12
-6,-3,33:18.12
-5,-3,33:18.12
-2,-3,33:18.12
-5,-2,33:18.12
-4,-2,33:18.12
-3,-2,33:18.12
-2,-2,33:17.12
-3,-1,33:18.12
-2,-1,33:18.12
-1,-1,33:18.12
0,-1,33:18.12
1,-1,33:18.12
2,-1,33:18.12
3,-1,33:18.4
-3,0,33:18.12
-4,1,33:18.12
-4,2,33:18.12
-4,3,33:18.12
-5,4,33:18.4
-1,-8,34:18.4
-1,-7,34:18.4
-2,-6,34:18.12
-2,-5,34:18.12
-2,-4,34:18.12
-7,-3,34:18.12
-6,-3,34:18.12
-5,-3,34:18.12
-2,-3,34:18.12
-5,-2,34:18.12
-4,-2,34:18.12
-3,-2,34:18.12
-2,-2,34:17.12
-3,-1,34:18.12
-2,-1,34:18.12
-1,-1,34:18.12
0,-1,34:18.12
1,-1,34:18.12
2,-1,34:18.12
3,-1,34:18.4
-3,0,34:18.12
-4,1,34:18.12
-4,2,34:18.12
-4,3,34:18.12
-5,4,34:18.4
-5,5,34:18.4
-1,-8,35:18.4
-1,-7,35:18.4
-2,-6,35:18.12
-2,-5,35:18.12
-8,-4,35:18.4
-2,-4,35:18.12
-7,-3,35:18.12
-6,-3,35:18.12
-5,-3,35:18.12
-3,-3,35:18.12
-2,-3,35:18.12
-5,-2,35:18.12
-4,-2,35:18.12
-3,-2,35:18.12
-2,-2,35:17.12
-3,-1,35:18.12
-2,-1,35:18.12
-1,-1,35:18.12
0,-1,35:18.12
1,-1,35:18.12
2,-1,35:18.12
3,-1,35:18.4
-3,0,35:18.12
-4,1,35:18.12
-4,2,35:18.12
-4,3,35:18.12
-5,4,35:18.4
-5,5,35:18.4
-1,-8,36:18.4
-2,-6,36:18.12
-2,-5,36:18.12
-8,-4,36:18.4
-2,-4,36:18.12
-7,-3,36:18.12
-6,-3,36:18.12
-5,-3,36:18.12
-3,-3,36:18.12
-2,-3,36:18.12
-4,-2,36:18.12
-3,-2,36:18.12
-3,-1,36:18.12
-2,-1,36:18.12
-1,-1,36:18.12
0,-1,36:18.12
1,-1,36:18.12
2,-1,36:18.12
3,-1,36:18.4
-3,0,36:18.12
-4,1,36:18.12
-4,2,36:18.12
-5,3,36:18.12
-4,3,36:18.12
-5,4,36:18.4
-5,5,36:18.4
-6,6,36:18.4
-4,-2,37:18.12
-3,-2,37:18.12
-3,-1,37:17.12
-2,-1,37:18.12
-4,1,37:18.12
-2,-3,38:18.12
-3,-2,38:17.12
-3,-1,38:17.12
-1,0,38:18.12
-6,-4,39:18.12
-5,-4,39:18.12
-2,-4,39:18.12
-1,-4,39:18.12
-5,-3,39:18.12
-4,-3,39:18.12
-2,-3,39:18.12
-3,-2,39:18.12
-2,-2,39:18.12
-4,-1,39:18.12
-2,-1,39:18.12
-5,0,39:18.12
-1,0,39:18.12
0,0,39:18.12
0,1,39:18.12
1,1,39:18.12
-7,-5,40:18.12
-6,-5,40:18.12
-6,-4,40:18.12
-5,-4,40:18.12
-1,-4,40:18.12
-5,-3,40:18.12
-4,-3,40:18.12
-2,-3,40:18.12
-4,-2,40:18.12
-3,-2,40:18.12
-4,-1,40:18.12
-2,-1,40:18.12
-6,0,40:18.12
-5,0,40:18.12
-1,0,40:18.12
0,0,40:18.12
-6,1,40:18.12
0,1,40:18.12
1,1,40:18.12
-7,-5,41:18.12
-6,-4,41:18.12
-5,-4,41:18.12
-5,-3,41:18.12
-4,-3,41:18.12
-4,-2,41:18.12
-3,-2,41:18.12
-4,-1,41:18.12
-2,-1,41:18.12
-5,0,41:18.12
-1,0,41:18.12
-6,1,41:18.12
-3,-2,42:17.12
-3,-2,43:17.12
-3,-2,44:17.12
-3,-2,45:17.12
