[META]
version=2.0
spawnOnBlockType=2
spawnSunlight=True
spawnDarkness=True
spawnWater=False
spawnLava=False
underFill=False
randomRotation=True
dig=True
tree=False
branch=False
needsFoundation=True
rarity=100
collisionPercentage=20
spawnElevationMin=0
spawnElevationMax=200
spawnInBiome=Custom
[DATA]
-1,-3,-8:17.12
-4,-2,-8:17.12
-3,-2,-8:17.12
-3,-1,-8:17.12
-4,5,-8:17.12
-3,5,-8:17.12
-3,6,-8:17.12
-5,-3,-7:17.12
-3,-3,-7:17.12
-5,-2,-7:17.12
-3,-2,-7:17.12
-2,-2,-7:17.12
-4,-1,-7:17.12
-3,-1,-7:17.12
-2,0,-7:17.12
-3,5,-7:17.12
-3,6,-7:17.12
-4,-4,-6:17.12
-3,-4,-6:17.12
-2,-4,-6:17.12
-4,-3,-6:17.12
-3,-3,-6:17.12
-2,-3,-6:17.12
-3,-2,-6:17.12
-2,-2,-6:17.12
-1,-1,-6:17.12
-3,0,-6:17.12
-2,0,-6:17.12
-3,3,-6:17.12
-5,4,-6:17.12
-5,5,-6:17.12
-4,5,-6:17.12
-3,5,-6:17.12
-2,5,-6:17.12
-4,6,-6:17.12
-3,6,-6:17.12
-2,6,-6:17.12
-3,7,-6:17.12
-2,-4,-5:17.12
-3,-3,-5:17.12
-2,-3,-5:17.12
-5,-2,-5:17.12
-4,-2,-5:17.12
-3,-2,-5:17.12
-2,-2,-5:17.12
-5,-1,-5:17.12
-3,-1,-5:17.12
-1,-1,-5:17.12
-4,0,-5:17.12
-2,0,-5:17.12
-4,4,-5:17.12
-3,4,-5:17.12
-1,4,-5:17.12
-5,5,-5:17.12
-4,5,-5:17.12
-3,5,-5:17.12
-2,5,-5:17.12
-5,6,-5:17.12
-2,6,-5:17.12
-3,7,-5:17.12
-3,-4,-4:17.12
-5,-3,-4:17.12
-1,-3,-4:17.12
-5,-2,-4:17.12
-4,-2,-4:17.12
-3,-2,-4:17.12
-2,-2,-4:17.12
-1,-2,-4:17.12
-4,-1,-4:17.12
-3,0,-4:17.12
-2,0,-4:17.12
-3,4,-4:17.12
-2,4,-4:17.12
-5,5,-4:17.12
-3,5,-4:17.12
-1,5,-4:17.12
-5,6,-4:17.12
-3,6,-4:17.12
-2,6,-4:17.12
-1,6,-4:17.12
-5,-4,-3:17.12
-4,-4,-3:17.12
-3,-4,-3:17.12
-2,-4,-3:17.12
-5,-3,-3:17.12
-4,-3,-3:17.12
-3,-3,-3:17.12
-2,-3,-3:17.12
-1,-3,-3:17.12
-5,-2,-3:17.12
-4,-2,-3:17.12
-3,-2,-3:17.12
-2,-2,-3:17.12
-1,-2,-3:17.12
-5,-1,-3:17.12
-4,-1,-3:17.12
-3,-1,-3:17.12
-2,-1,-3:17.12
-4,0,-3:17.12
-3,0,-3:17.12
-2,0,-3:17.12
-5,2,-3:17.12
-3,3,-3:17.12
-6,4,-3:17.12
-4,4,-3:17.12
-3,4,-3:17.12
-2,4,-3:17.12
-1,4,-3:17.12
-5,5,-3:17.12
-4,5,-3:17.12
-3,5,-3:17.12
0,5,-3:17.12
-4,6,-3:17.12
-3,6,-3:17.12
-2,6,-3:17.12
-1,6,-3:17.12
0,6,-3:17.12
-2,7,-3:17.12
-4,-4,-2:17.12
-3,-4,-2:17.12
-2,-4,-2:17.12
-5,-3,-2:17.12
-2,-3,-2:17.12
-5,-2,-2:17.12
-2,-2,-2:17.12
-5,-1,-2:17.12
-4,-1,-2:17.12
-3,-1,-2:17.12
-2,-1,-2:17.12
-5,2,-2:17.12
-6,3,-2:17.12
-5,3,-2:17.12
-4,3,-2:17.12
-6,4,-2:17.12
-5,4,-2:17.12
-4,4,-2:17.12
-3,4,-2:17.12
-6,5,-2:17.12
-5,5,-2:17.12
-4,5,-2:17.12
-3,5,-2:17.12
-2,5,-2:17.12
-4,6,-2:17.12
-2,6,-2:17.12
-1,6,-2:17.12
0,6,-2:17.12
-4,7,-2:17.12
-4,-4,-1:17.12
-3,-4,-1:17.12
-5,-3,-1:17.12
-4,-3,-1:17.12
-3,-3,-1:17.12
-2,-3,-1:17.12
-5,-2,-1:17.12
-2,-2,-1:17.12
-4,-1,-1:17.12
-3,-1,-1:17.12
-2,-1,-1:17.12
-5,1,-1:17.12
-5,2,-1:17.12
-4,2,-1:17.12
-5,3,-1:17.12
-4,3,-1:17.12
-3,3,-1:17.12
-5,4,-1:17.12
-4,4,-1:17.12
-3,4,-1:17.12
-2,4,-1:17.12
-1,4,-1:17.12
-5,5,-1:17.12
-4,5,-1:17.12
-2,5,-1:17.12
-1,5,-1:17.12
-4,6,-1:17.12
-1,6,-1:17.12
-4,7,-1:17.12
-3,7,-1:17.12
-2,7,-1:17.12
-1,7,-1:17.12
-2,8,-1:17.12
-6,-3,0:18.14
-5,-3,0:18.14
-4,-3,0:18.14
-3,-3,0:17.12
-2,-3,0:17.12
-5,-2,0:18.14
-4,-2,0:18.14
-3,-2,0:18.14
-2,-2,0:17.12
-4,-1,0:17.12
-3,-1,0:18.14
-2,-1,0:18.14
-3,0,0:18.14
-3,1,0:18.14
-2,1,0:18.14
-4,2,0:17.12
-4,3,0:17.12
-4,4,0:17.12
-3,4,0:17.12
-2,4,0:17.12
-4,5,0:17.12
-1,5,0:17.12
-4,6,0:17.12
-1,6,0:17.12
-4,7,0:17.12
-3,7,0:17.12
-2,7,0:17.12
-4,-3,1:17.12
-3,-3,1:17.12
-2,-3,1:17.12
-5,-2,1:18.14
-4,-2,1:18.14
-3,-2,1:18.14
-2,-2,1:17.12
-6,-1,1:18.14
-5,-1,1:18.14
-4,-1,1:18.14
-3,-1,1:18.14
-2,-1,1:18.14
-5,0,1:18.14
-4,0,1:18.14
-3,0,1:18.14
-4,1,1:18.14
-3,1,1:18.14
-4,2,1:18.14
-4,3,1:18.14
-3,3,1:18.14
-2,3,1:18.14
-4,4,1:18.14
-3,4,1:17.12
-2,4,1:18.14
-1,4,1:18.14
-4,5,1:17.12
-3,5,1:17.12
-2,5,1:17.12
-1,5,1:17.12
0,5,1:18.14
1,5,1:18.14
-4,6,1:17.12
-3,6,1:17.12
-2,6,1:17.12
-1,6,1:17.12
0,6,1:18.14
1,6,1:18.14
2,6,1:18.14
-4,7,1:17.12
-3,7,1:17.12
-2,7,1:17.12
0,7,1:18.14
1,7,1:18.14
1,8,1:18.14
-4,-3,2:17.12
-3,-3,2:17.12
-4,-2,2:17.12
-3,-2,2:17.12
-2,-2,2:17.12
-5,-1,2:18.14
-4,-1,2:18.14
-3,-1,2:18.14
-5,0,2:18.14
-4,0,2:18.14
-3,0,2:18.14
-4,1,2:18.14
-4,3,2:18.14
-3,3,2:18.14
-2,3,2:18.14
-4,4,2:18.14
-3,4,2:18.14
-2,4,2:18.14
-4,5,2:17.12
-3,5,2:17.12
-2,5,2:17.12
-1,5,2:18.14
0,5,2:18.14
1,5,2:18.14
-4,6,2:17.12
-3,6,2:17.12
-2,6,2:17.12
-1,6,2:17.12
0,6,2:18.14
1,6,2:18.14
-4,7,2:18.14
-3,7,2:18.14
-2,7,2:17.12
-1,7,2:18.14
0,7,2:18.14
1,7,2:18.14
-3,8,2:18.14
-2,8,2:18.14
-1,8,2:18.14
0,8,2:18.14
-2,9,2:18.14
-1,9,2:18.14
0,9,2:18.14
-1,10,2:18.14
-4,-3,3:17.12
-3,-3,3:17.12
-4,-2,3:17.12
-3,-2,3:17.12
-3,4,3:17.12
-4,5,3:17.12
-3,5,3:17.12
-2,5,3:17.12
-1,5,3:18.14
0,5,3:18.14
-4,6,3:17.12
-3,6,3:17.12
-2,6,3:17.12
-1,6,3:18.14
0,6,3:18.14
-3,7,3:17.12
-2,7,3:17.12
-1,7,3:18.14
0,7,3:18.14
-3,8,3:18.14
-2,8,3:18.14
-1,8,3:18.14
0,8,3:18.14
-4,-3,4:17.12
-3,-3,4:17.12
-4,-2,4:17.12
-3,-2,4:17.12
-4,5,4:17.12
-3,5,4:17.12
-2,5,4:17.12
-3,6,4:17.12
-2,6,4:17.12
-4,-3,5:17.12
-3,-3,5:17.12
-4,-2,5:17.12
-3,-2,5:17.12
-3,5,5:17.12
-2,5,5:17.12
-3,6,5:17.12
-2,6,5:17.12
-4,-3,6:17.12
-3,-3,6:17.12
-4,-2,6:17.12
-3,-2,6:17.12
-3,5,6:17.12
-2,5,6:17.12
-3,6,6:17.12
-2,6,6:17.12
1,-9,7:18.4
-4,-3,7:17.12
-3,-3,7:17.12
-4,-2,7:17.12
-3,-2,7:17.12
-8,5,7:18.12
-3,5,7:17.12
-2,5,7:17.12
-3,6,7:17.12
-2,6,7:17.12
2,-11,8:18.4
2,-10,8:18.4
1,-9,8:18.4
1,-8,8:18.4
-10,-7,8:18.4
-9,-6,8:18.4
-4,-3,8:17.12
-3,-3,8:17.12
-4,-2,8:17.12
-3,-2,8:17.12
-7,3,8:18.12
-8,4,8:18.12
-8,5,8:18.12
-3,5,8:17.12
-2,5,8:17.12
-9,6,8:18.4
-3,6,8:17.12
-2,6,8:17.12
3,-12,9:18.4
2,-11,9:18.4
2,-10,9:18.4
1,-9,9:18.4
-11,-8,9:18.4
0,-8,9:18.4
1,-8,9:18.4
-11,-7,9:18.4
-10,-7,9:18.4
0,-7,9:18.12
-9,-6,9:18.4
-8,-6,9:18.12
-1,-6,9:18.12
0,-6,9:18.12
-7,-5,9:18.12
-6,-5,9:18.12
-1,-5,9:18.12
-5,-4,9:18.12
-4,-4,9:18.12
-3,-4,9:18.12
-2,-4,9:18.12
-1,-4,9:18.12
-5,-3,9:18.12
-4,-3,9:17.12
-3,-3,9:17.12
-1,-3,9:18.12
-5,-2,9:18.12
-4,-2,9:17.12
-3,-2,9:17.12
-1,-2,9:18.12
-5,-1,9:18.12
-1,-1,9:18.12
5,-1,9:18.5
-6,0,9:18.12
-5,0,9:18.12
-4,0,9:18.12
-3,0,9:18.12
-2,0,9:18.12
-1,0,9:18.12
4,0,9:18.5
5,0,9:18.5
-6,1,9:18.12
1,1,9:18.12
3,1,9:18.5
-7,2,9:18.12
-6,2,9:18.12
1,2,9:18.12
2,2,9:18.12
-7,3,9:18.12
-8,4,9:18.4
-7,4,9:18.12
-8,5,9:18.4
-3,5,9:17.12
-2,5,9:17.12
-9,6,9:18.4
-3,6,9:17.12
-2,6,9:17.12
-8,10,9:18.5
-10,11,9:18.5
-9,11,9:18.5
2,-11,10:18.4
2,-10,10:18.4
1,-9,10:18.4
-12,-8,10:18.4
-11,-8,10:18.4
-11,-7,10:18.4
-10,-7,10:18.4
0,-7,10:18.12
-9,-6,10:18.4
-8,-6,10:18.12
-1,-6,10:18.12
0,-6,10:18.12
-7,-5,10:18.12
-6,-5,10:18.12
-1,-5,10:18.12
-6,-4,10:18.12
-5,-4,10:18.12
-4,-4,10:18.12
-3,-4,10:18.12
-2,-4,10:18.12
-1,-4,10:18.12
-5,-3,10:18.12
-4,-3,10:18.12
-3,-3,10:18.12
-2,-3,10:18.12
-1,-3,10:18.12
-8,-2,10:18.13
-5,-2,10:18.12
-4,-2,10:17.12
-3,-2,10:17.12
-2,-2,10:18.12
-1,-2,10:18.12
-8,-1,10:18.13
-7,-1,10:18.13
-5,-1,10:18.12
-4,-1,10:18.12
-3,-1,10:18.12
-2,-1,10:18.12
-1,-1,10:18.12
-7,0,10:18.13
-6,0,10:18.13
-5,0,10:18.12
-4,0,10:18.12
-3,0,10:18.12
-2,0,10:18.12
-1,0,10:18.12
4,0,10:18.5
-6,1,10:18.12
0,1,10:18.12
1,1,10:18.12
3,1,10:18.5
4,1,10:18.5
-7,2,10:18.12
-6,2,10:18.12
-5,2,10:18.13
1,2,10:18.12
2,2,10:18.13
3,2,10:18.5
-7,3,10:18.12
-4,3,10:18.13
-3,3,10:18.13
2,3,10:18.12
3,3,10:18.4
-8,4,10:18.4
-4,4,10:18.13
-2,4,10:18.13
-1,4,10:18.13
0,4,10:18.13
1,4,10:18.13
-8,5,10:18.4
-4,5,10:18.13
-3,5,10:17.12
-2,5,10:17.12
-1,5,10:18.13
0,5,10:18.13
-9,6,10:18.4
-5,6,10:18.13
-3,6,10:17.12
-2,6,10:17.12
-1,6,10:18.13
-9,7,10:18.4
-5,7,10:18.13
-4,7,10:18.13
-3,7,10:18.13
-1,7,10:18.13
-6,8,10:18.13
-2,8,10:18.13
-1,8,10:18.13
-8,9,10:18.5
-7,9,10:18.13
-1,9,10:18.13
0,9,10:18.13
-9,10,10:18.5
-8,10,10:18.5
-9,11,10:18.5
1,11,10:18.5
1,12,10:18.5
2,-11,11:18.4
2,-10,11:18.4
1,-9,11:18.4
-12,-8,11:18.4
-11,-8,11:18.4
0,-8,11:18.4
1,-8,11:18.4
-10,-7,11:18.4
0,-7,11:18.12
-9,-6,11:18.4
-8,-6,11:18.12
-1,-6,11:18.12
-7,-5,11:18.12
-6,-5,11:18.12
-1,-5,11:18.12
-6,-4,11:18.12
-5,-4,11:18.12
-4,-4,11:18.12
-3,-4,11:18.12
-2,-4,11:18.12
-5,-3,11:18.12
-4,-3,11:17.12
-3,-3,11:17.12
-2,-3,11:18.12
-8,-2,11:18.13
-5,-2,11:18.12
-4,-2,11:17.12
-3,-2,11:17.12
-2,-2,11:18.12
-8,-1,11:18.13
-7,-1,11:18.13
-5,-1,11:18.12
-4,-1,11:18.12
-3,-1,11:18.12
-2,-1,11:18.12
5,-1,11:18.5
-7,0,11:18.13
-6,0,11:18.13
-5,0,11:18.12
-1,0,11:18.12
4,0,11:18.5
5,0,11:18.5
-6,1,11:18.12
-5,1,11:18.13
0,1,11:18.12
1,1,11:18.12
3,1,11:18.5
-6,2,11:18.12
-5,2,11:18.13
2,2,11:18.13
3,2,11:18.5
-7,3,11:18.12
-4,3,11:18.13
-3,3,11:18.13
2,3,11:18.12
3,3,11:18.4
-8,4,11:18.4
-7,4,11:18.12
-4,4,11:18.13
-3,4,11:18.13
-2,4,11:18.13
-1,4,11:18.13
0,4,11:18.13
4,4,11:18.4
-8,5,11:18.4
-3,5,11:17.12
-2,5,11:17.12
-1,5,11:18.13
0,5,11:18.13
-9,6,11:18.4
-5,6,11:18.13
-4,6,11:18.13
-3,6,11:17.12
-2,6,11:17.12
-1,6,11:18.13
-9,7,11:18.4
-5,7,11:18.13
-4,7,11:18.13
-3,7,11:18.13
-1,7,11:18.13
-6,8,11:18.13
-2,8,11:18.13
-1,8,11:18.13
-7,9,11:18.13
-1,9,11:18.13
-8,10,11:18.5
0,10,11:18.13
-10,11,11:18.5
-9,11,11:18.5
0,11,11:18.5
1,11,11:18.5
-10,12,11:18.5
1,12,11:18.5
2,13,11:18.5
1,-9,12:18.4
-12,-8,12:18.4
0,-8,12:18.4
-10,-7,12:18.4
0,-7,12:18.12
-9,-6,12:18.4
-8,-6,12:18.12
-1,-6,12:18.12
-8,-5,12:18.12
-7,-5,12:18.12
-6,-5,12:18.12
-1,-5,12:18.12
-6,-4,12:18.12
-5,-4,12:18.12
-4,-4,12:18.12
-3,-4,12:18.12
-2,-4,12:18.12
-5,-3,12:18.12
-4,-3,12:17.12
-3,-3,12:17.12
-2,-3,12:18.12
-8,-2,12:18.13
-5,-2,12:18.12
-4,-2,12:17.12
-3,-2,12:17.12
-2,-2,12:18.12
-8,-1,12:18.13
-7,-1,12:18.13
-5,-1,12:18.12
-4,-1,12:18.12
-3,-1,12:18.12
-2,-1,12:18.12
-7,0,12:18.13
-6,0,12:18.13
-5,0,12:18.12
-1,0,12:18.12
0,0,12:18.12
-6,1,12:18.12
0,1,12:18.12
1,1,12:18.12
3,1,12:18.5
-6,2,12:18.12
-5,2,12:18.13
-2,2,12:18.12
1,2,12:18.12
2,2,12:18.13
-7,3,12:18.12
-4,3,12:18.13
2,3,12:18.12
3,3,12:18.4
-4,4,12:18.13
-3,4,12:18.13
-2,4,12:18.13
-1,4,12:18.13
0,4,12:18.13
4,4,12:18.4
-4,5,12:18.13
-3,5,12:17.12
-2,5,12:17.12
-1,5,12:18.13
0,5,12:18.13
-9,6,12:18.4
-5,6,12:18.13
-4,6,12:18.13
-3,6,12:17.12
-2,6,12:17.12
-1,6,12:18.13
-5,7,12:18.13
-4,7,12:18.13
-3,7,12:18.13
-2,7,12:18.13
-1,7,12:18.13
-6,8,12:18.13
-2,8,12:18.13
-1,8,12:18.13
-7,9,12:18.13
-1,9,12:18.13
0,9,12:18.13
-8,10,12:18.5
0,10,12:18.13
-9,11,12:18.5
0,11,12:18.5
1,11,12:18.5
-2,12,12:18.5
1,12,12:18.5
2,13,12:18.5
-1,-6,13:18.12
-7,-5,13:18.12
-6,-5,13:18.12
-1,-5,13:18.12
-6,-4,13:18.12
-5,-4,13:18.12
-4,-4,13:18.12
-3,-4,13:18.12
-2,-4,13:18.12
-5,-3,13:18.12
-4,-3,13:17.12
-3,-3,13:17.12
-2,-3,13:18.12
-5,-2,13:18.12
-4,-2,13:17.12
-3,-2,13:17.12
-2,-2,13:18.12
-5,-1,13:18.12
-4,-1,13:18.12
-3,-1,13:18.12
-2,-1,13:18.12
-7,0,13:18.13
-6,0,13:18.13
-5,0,13:18.12
-1,0,13:18.12
0,0,13:18.12
-6,1,13:18.13
-2,1,13:18.12
0,1,13:18.12
3,1,13:18.5
-5,2,13:18.13
-2,2,13:18.12
1,2,13:18.12
2,2,13:18.13
-4,3,13:18.13
-1,3,13:18.12
-4,4,13:18.13
-3,4,13:18.13
-2,4,13:18.13
-1,4,13:18.12
0,4,13:18.13
-4,5,13:18.13
-3,5,13:17.12
-2,5,13:17.12
-1,5,13:18.13
0,5,13:18.12
-4,6,13:18.13
-3,6,13:17.12
-2,6,13:17.12
-1,6,13:18.13
-5,7,13:18.13
-4,7,13:18.13
-3,7,13:18.13
-2,7,13:18.13
-1,7,13:18.13
-6,8,13:18.13
-3,8,13:18.13
-1,8,13:18.13
-7,9,13:18.13
-3,9,13:18.13
-1,9,13:18.13
0,9,13:18.13
-8,10,13:18.5
-2,10,13:18.13
0,10,13:18.13
-2,11,13:18.5
1,11,13:18.5
-2,12,13:18.5
1,12,13:18.5
2,13,13:18.5
-6,-4,14:18.12
-5,-4,14:18.12
-3,-4,14:18.12
-2,-4,14:18.12
-5,-3,14:18.12
-4,-3,14:17.12
-3,-3,14:17.12
-5,-2,14:18.12
-4,-2,14:17.12
-3,-2,14:17.12
-2,-2,14:18.12
-7,-1,14:18.12
-5,-1,14:18.12
-4,-1,14:18.12
-3,-1,14:18.12
-2,-1,14:18.12
-8,0,14:18.12
-5,0,14:18.12
-3,0,14:18.12
-1,0,14:18.12
-6,1,14:18.13
-2,1,14:18.12
-5,2,14:18.13
-2,2,14:18.12
-4,3,14:18.13
-1,3,14:18.12
-4,4,14:18.13
-3,4,14:18.13
-2,4,14:18.13
-1,4,14:18.12
0,4,14:18.13
-4,5,14:18.13
-3,5,14:17.12
-2,5,14:17.12
0,5,14:18.12
-10,6,14:18.5
-9,6,14:18.5
-8,6,14:18.5
-7,6,14:18.13
-6,6,14:18.13
-5,6,14:18.13
-4,6,14:18.13
-3,6,14:17.12
-2,6,14:17.12
-1,6,14:18.13
-5,7,14:18.13
-4,7,14:18.13
-3,7,14:18.13
-2,7,14:18.13
-1,7,14:18.13
-6,8,14:18.13
-3,8,14:18.13
-1,8,14:18.13
-7,9,14:18.13
-3,9,14:18.13
-1,9,14:18.13
0,9,14:18.13
-2,10,14:18.13
0,10,14:18.13
-2,11,14:18.5
1,11,14:18.5
-2,12,14:18.5
-5,-7,15:18.12
-5,-6,15:18.12
-4,-4,15:18.12
0,-4,15:18.12
-4,-3,15:17.12
-3,-3,15:17.12
-2,-3,15:18.12
-5,-2,15:18.12
-4,-2,15:18.12
-3,-2,15:17.12
-7,-1,15:18.12
-6,-1,15:18.12
-3,-1,15:18.12
-9,0,15:18.4
-8,0,15:18.12
-3,0,15:18.12
-10,1,15:18.4
-3,1,15:18.13
-2,1,15:18.12
-5,2,15:18.13
-2,2,15:18.12
-3,3,15:18.13
-1,3,15:18.12
-3,4,15:18.13
-1,4,15:18.12
-3,5,15:17.12
-2,5,15:18.13
-1,5,15:18.13
0,5,15:18.13
1,5,15:18.13
-9,6,15:18.5
-8,6,15:18.5
-7,6,15:18.13
-6,6,15:18.13
-5,6,15:18.13
-4,6,15:18.13
-3,6,15:17.12
-2,6,15:17.12
-3,7,15:18.13
-2,7,15:18.13
-6,8,15:18.13
-3,8,15:18.13
-1,8,15:18.13
-3,9,15:18.13
-1,9,15:18.13
-2,10,15:18.13
-2,11,15:18.5
-6,-8,16:18.4
-5,-7,16:18.12
-5,-6,16:18.12
-5,-5,16:18.12
-4,-5,16:18.12
1,-5,16:18.12
-4,-4,16:18.12
-1,-4,16:18.12
0,-4,16:18.12
1,-4,16:18.12
-4,-3,16:17.12
-3,-3,16:18.12
-2,-3,16:18.12
-5,-2,16:18.12
-4,-2,16:18.12
-3,-2,16:17.12
-7,-1,16:18.12
-6,-1,16:18.12
-5,-1,16:18.12
-3,-1,16:18.12
-9,0,16:18.4
-8,0,16:18.12
-3,0,16:18.12
-10,1,16:18.4
-3,1,16:18.13
-2,1,16:18.12
-2,2,16:18.12
-3,3,16:18.13
-3,4,16:18.13
-3,5,16:17.12
-2,5,16:18.13
-1,5,16:18.13
0,5,16:18.13
1,5,16:18.13
2,5,16:18.13
3,5,16:18.5
4,5,16:18.5
-9,6,16:18.5
-8,6,16:18.5
-7,6,16:18.13
-6,6,16:18.13
-5,6,16:18.13
-4,6,16:18.13
-3,6,16:17.12
-2,6,16:17.12
-3,7,16:18.13
-3,8,16:18.13
-3,9,16:18.13
-2,10,16:18.13
-6,-8,17:18.4
-5,-7,17:18.12
-5,-6,17:18.12
-5,-5,17:18.12
-4,-5,17:18.12
1,-5,17:18.12
2,-5,17:18.4
3,-5,17:18.4
-4,-4,17:18.12
-1,-4,17:18.12
0,-4,17:18.12
1,-4,17:18.12
-4,-3,17:17.12
-3,-3,17:18.12
-2,-3,17:18.12
-1,-3,17:18.12
-5,-2,17:18.12
-4,-2,17:18.12
-3,-2,17:17.12
-7,-1,17:18.12
-6,-1,17:18.12
-5,-1,17:18.12
-3,-1,17:18.12
-9,0,17:18.4
-8,0,17:18.12
-3,0,17:18.12
-11,1,17:18.4
-10,1,17:18.4
-3,1,17:18.13
-2,1,17:18.12
-3,3,17:18.13
-3,4,17:18.13
-3,5,17:17.12
-2,5,17:18.13
-1,5,17:18.13
0,5,17:18.13
1,5,17:18.13
2,5,17:18.13
3,5,17:18.5
4,5,17:18.5
-9,6,17:18.5
-8,6,17:18.5
-7,6,17:18.13
-6,6,17:18.13
-5,6,17:18.13
-4,6,17:18.13
-3,6,17:17.12
-2,6,17:17.12
-3,7,17:18.13
-3,8,17:18.13
-3,9,17:18.13
-8,-11,18:18.4
-7,-9,18:18.4
-6,-9,18:18.4
-6,-8,18:18.4
-5,-7,18:18.12
-5,-6,18:18.12
-5,-5,18:18.12
-4,-5,18:18.12
1,-5,18:18.12
2,-5,18:18.4
3,-5,18:18.4
-4,-4,18:18.12
-1,-4,18:18.12
0,-4,18:18.12
-4,-3,18:18.12
-3,-3,18:18.12
-2,-3,18:18.12
-1,-3,18:18.12
-5,-2,18:18.12
-4,-2,18:18.12
-3,-2,18:17.12
-7,-1,18:18.12
-6,-1,18:18.12
-5,-1,18:18.12
-3,-1,18:18.12
-9,0,18:18.4
-8,0,18:18.12
-3,0,18:18.12
-10,1,18:18.4
-3,1,18:18.13
-3,3,18:18.13
-3,4,18:18.13
0,4,18:18.12
-3,5,18:17.12
-2,5,18:18.13
-1,5,18:18.13
0,5,18:18.13
1,5,18:18.13
2,5,18:18.13
3,5,18:18.5
4,5,18:18.5
-8,6,18:18.5
-7,6,18:18.13
-6,6,18:18.13
-5,6,18:18.13
-4,6,18:18.13
-3,6,18:18.13
-2,6,18:17.12
1,6,18:18.12
-3,7,18:18.13
-3,8,18:18.13
-8,-11,19:18.4
-7,-10,19:18.4
-7,-9,19:18.4
-6,-9,19:18.4
-6,-8,19:18.4
-6,-7,19:18.12
-5,-7,19:18.12
-5,-6,19:18.12
-5,-5,19:18.12
-4,-5,19:18.12
1,-5,19:18.12
2,-5,19:18.4
3,-5,19:18.4
-4,-4,19:18.12
-3,-4,19:18.12
-2,-4,19:18.12
-1,-4,19:18.12
0,-4,19:18.12
1,-4,19:18.12
2,-4,19:18.4
3,-4,19:18.4
-5,-3,19:18.12
-4,-3,19:18.12
-3,-3,19:17.12
-2,-3,19:18.12
-1,-3,19:18.12
-6,-2,19:18.12
-5,-2,19:18.12
-4,-2,19:17.12
-3,-2,19:17.12
-7,-1,19:18.12
-6,-1,19:18.12
-5,-1,19:18.12
-4,-1,19:18.12
-3,-1,19:18.12
-2,-1,19:18.12
-9,0,19:18.4
-8,0,19:18.12
-3,0,19:18.12
-10,1,19:18.4
-3,1,19:18.13
-2,1,19:18.12
-3,3,19:18.13
-1,3,19:18.12
-3,4,19:18.13
0,4,19:18.12
-3,5,19:17.12
-2,5,19:18.13
-1,5,19:18.13
0,5,19:18.13
1,5,19:18.13
2,5,19:18.13
-8,6,19:18.5
-7,6,19:18.13
-6,6,19:18.13
-5,6,19:18.13
-4,6,19:18.13
-3,6,19:17.12
-2,6,19:17.12
1,6,19:18.12
-3,7,19:18.13
-2,7,19:18.13
0,9,19:18.13
-8,-12,20:18.4
-8,-11,20:18.4
-7,-10,20:18.4
-7,-9,20:18.4
-6,-9,20:18.4
-6,-8,20:18.4
-6,-7,20:18.12
-5,-7,20:18.12
-5,-6,20:18.12
-4,-5,20:18.12
3,-5,20:18.4
4,-5,20:18.4
5,-5,20:18.4
-4,-4,20:18.12
-3,-4,20:18.12
-2,-4,20:18.12
0,-4,20:18.12
1,-4,20:18.12
2,-4,20:18.4
3,-4,20:18.4
-5,-3,20:18.12
-4,-3,20:17.12
-3,-3,20:17.12
-2,-3,20:18.12
-1,-3,20:18.12
0,-3,20:18.12
-6,-2,20:18.12
-5,-2,20:18.12
-4,-2,20:17.12
-3,-2,20:17.12
-2,-2,20:18.12
-1,-2,20:18.12
-7,-1,20:18.12
-6,-1,20:18.12
-5,-1,20:18.12
-4,-1,20:18.12
-2,-1,20:18.12
-9,0,20:18.4
-8,0,20:18.12
-3,0,20:18.12
-2,0,20:18.12
-11,1,20:18.4
-10,1,20:18.4
-2,1,20:18.12
-12,2,20:18.4
-11,2,20:18.4
-2,2,20:18.12
-1,2,20:18.12
-3,3,20:18.13
-1,3,20:18.12
-3,4,20:18.13
0,4,20:18.12
-3,5,20:17.12
-2,5,20:18.13
-1,5,20:18.13
0,5,20:18.13
1,5,20:18.13
-5,6,20:18.13
-4,6,20:18.13
-3,6,20:17.12
-2,6,20:17.12
1,6,20:18.12
-6,7,20:18.13
-5,7,20:18.13
-2,7,20:18.13
-7,8,20:18.13
-6,8,20:18.13
-1,8,20:18.13
-9,9,20:18.5
-8,9,20:18.5
0,9,20:18.13
-11,10,20:18.5
-10,10,20:18.5
-12,11,20:18.5
-8,-11,21:18.4
-7,-10,21:18.4
-7,-9,21:18.4
-6,-8,21:18.4
-6,-7,21:18.12
-5,-7,21:18.12
-5,-6,21:18.12
-4,-5,21:18.12
4,-5,21:18.4
5,-5,21:18.4
-4,-4,21:18.12
-3,-4,21:18.12
-2,-4,21:18.12
1,-4,21:18.12
3,-4,21:18.4
-5,-3,21:18.12
-4,-3,21:18.12
-3,-3,21:17.12
-2,-3,21:18.12
-1,-3,21:18.12
0,-3,21:18.12
-6,-2,21:18.12
-5,-2,21:18.12
-4,-2,21:17.12
-3,-2,21:17.12
-2,-2,21:18.12
-7,-1,21:18.12
-6,-1,21:18.12
-5,-1,21:18.12
-4,-1,21:18.12
-2,-1,21:18.12
-9,0,21:18.4
-8,0,21:18.12
-6,0,21:18.13
-3,0,21:18.12
-11,1,21:18.4
-10,1,21:18.4
-5,1,21:18.13
-2,1,21:18.12
3,1,21:18.5
-12,2,21:18.4
-5,2,21:18.13
-2,2,21:18.12
-1,2,21:18.12
1,2,21:18.13
2,2,21:18.13
-4,3,21:18.13
-1,3,21:18.12
0,3,21:18.13
-4,4,21:18.13
-3,4,21:18.13
-1,4,21:18.13
0,4,21:18.12
-3,5,21:17.12
-2,5,21:18.13
0,5,21:18.12
-4,6,21:18.13
-3,6,21:17.12
-2,6,21:17.12
1,6,21:18.12
-6,7,21:18.13
-5,7,21:18.13
-2,7,21:18.13
-7,8,21:18.13
-6,8,21:18.13
-1,8,21:18.13
-9,9,21:18.5
-8,9,21:18.5
0,9,21:18.13
-11,10,21:18.5
-10,10,21:18.5
-6,-8,22:18.4
-6,-7,22:18.12
-5,-7,22:18.12
-5,-6,22:18.12
-5,-5,22:18.12
-4,-5,22:18.12
4,-5,22:18.4
5,-5,22:18.4
-4,-4,22:18.12
-3,-4,22:18.12
0,-4,22:18.12
1,-4,22:18.12
2,-4,22:18.4
3,-4,22:18.4
-5,-3,22:18.12
-4,-3,22:17.12
-3,-3,22:17.12
-2,-3,22:18.12
-1,-3,22:18.12
0,-3,22:18.12
-7,-2,22:18.13
-6,-2,22:18.12
-5,-2,22:18.12
-4,-2,22:17.12
-3,-2,22:17.12
-2,-2,22:18.12
-7,-1,22:18.12
-6,-1,22:18.12
-5,-1,22:18.12
-4,-1,22:18.12
-3,-1,22:18.12
-2,-1,22:18.12
-9,0,22:18.4
-8,0,22:18.12
-6,0,22:18.13
-3,0,22:18.12
-2,0,22:18.12
4,0,22:18.5
-11,1,22:18.4
-10,1,22:18.4
-6,1,22:18.13
-5,1,22:18.13
-2,1,22:18.12
3,1,22:18.5
-12,2,22:18.4
-5,2,22:18.13
-1,2,22:18.12
1,2,22:18.13
2,2,22:18.13
-4,3,22:18.13
-1,3,22:18.12
0,3,22:18.13
-4,4,22:18.13
-3,4,22:18.13
-1,4,22:18.13
0,4,22:18.12
-3,5,22:18.13
-2,5,22:18.13
-4,6,22:18.13
-3,6,22:17.12
-2,6,22:17.12
1,6,22:18.12
-6,7,22:18.13
-5,7,22:18.13
-2,7,22:18.13
-7,8,22:18.13
-6,8,22:18.13
-1,8,22:18.13
-9,9,22:18.5
-8,9,22:18.5
0,9,22:18.13
-10,10,22:18.5
0,10,22:18.13
1,10,22:18.13
-5,-6,23:18.12
-4,-5,23:18.12
-4,-4,23:18.12
-3,-4,23:18.12
0,-4,23:18.12
1,-4,23:18.12
2,-4,23:18.4
-5,-3,23:18.12
-4,-3,23:18.12
-3,-3,23:17.12
-2,-3,23:18.12
-1,-3,23:18.12
0,-3,23:18.12
-5,-2,23:18.12
-4,-2,23:17.12
-3,-2,23:17.12
-2,-2,23:18.12
-7,-1,23:18.12
-6,-1,23:18.12
-4,-1,23:18.12
-3,-1,23:18.12
-2,-1,23:18.12
-9,0,23:18.4
-6,0,23:18.13
-3,0,23:18.12
-2,0,23:18.12
4,0,23:18.5
-5,1,23:18.13
-2,1,23:18.12
3,1,23:18.5
-5,2,23:18.13
-2,2,23:18.12
1,2,23:18.13
2,2,23:18.13
-4,3,23:18.13
-2,3,23:18.12
0,3,23:18.13
-4,4,23:18.13
-3,4,23:18.13
-1,4,23:18.13
0,4,23:18.12
-3,5,23:18.13
-2,5,23:18.13
-4,6,23:18.13
-3,6,23:18.13
-2,6,23:17.12
-6,7,23:18.13
-5,7,23:18.13
-2,7,23:18.13
-7,8,23:18.13
-6,8,23:18.13
-1,8,23:18.13
-9,9,23:18.5
-8,9,23:18.5
0,9,23:18.13
-11,10,23:18.5
-10,10,23:18.5
-12,11,23:18.5
-6,-8,24:18.4
-6,-7,24:18.12
-6,-6,24:18.12
-5,-6,24:18.12
-5,-5,24:18.12
1,-5,24:18.12
-4,-4,24:18.12
-1,-4,24:18.12
0,-4,24:18.12
1,-4,24:18.12
-4,-3,24:18.12
-3,-3,24:17.12
-2,-3,24:18.12
-1,-3,24:18.12
0,-3,24:18.12
-7,-2,24:18.13
-5,-2,24:18.12
-4,-2,24:17.12
-3,-2,24:18.12
-2,-2,24:18.12
-8,-1,24:18.12
-7,-1,24:18.12
-6,-1,24:18.12
-4,-1,24:18.12
-3,-1,24:18.12
-9,0,24:18.4
-6,0,24:18.13
-3,0,24:18.12
4,0,24:18.5
-5,1,24:18.13
-2,1,24:18.12
3,1,24:18.5
-5,2,24:18.13
-2,2,24:18.12
2,2,24:18.13
-4,3,24:18.13
-2,3,24:18.12
0,3,24:18.13
-4,4,24:18.13
-3,4,24:18.13
-1,4,24:18.13
-3,5,24:18.13
-2,5,24:18.13
-1,5,24:18.12
-4,6,24:18.13
-3,6,24:18.13
-2,6,24:17.12
-6,7,24:18.13
-5,7,24:18.13
-2,7,24:18.13
-7,8,24:18.13
-6,8,24:18.13
-1,8,24:18.13
-9,9,24:18.5
-11,10,24:18.5
-10,10,24:18.5
-7,-10,25:18.4
-7,-9,25:18.4
-6,-8,25:18.4
-6,-7,25:18.12
-5,-6,25:18.12
-5,-5,25:18.12
1,-5,25:18.12
2,-5,25:18.4
-5,-4,25:18.12
0,-4,25:18.12
1,-4,25:18.12
-4,-3,25:18.12
-3,-3,25:17.12
-2,-3,25:18.12
-1,-3,25:18.12
-6,-2,25:18.12
-5,-2,25:18.12
-4,-2,25:17.12
-3,-2,25:18.12
-9,-1,25:18.4
-8,-1,25:18.12
-7,-1,25:18.12
-3,-1,25:18.12
-10,0,25:18.4
-9,0,25:18.4
-6,0,25:18.13
-3,0,25:18.12
-5,1,25:18.13
-2,1,25:18.12
-5,2,25:18.13
-2,2,25:18.12
2,2,25:18.13
-4,3,25:18.13
-2,3,25:18.12
0,3,25:18.13
-4,4,25:18.13
-3,4,25:18.13
-2,4,25:18.13
-1,4,25:18.13
-3,5,25:18.13
-2,5,25:18.13
-1,5,25:18.12
-4,6,25:18.13
-3,6,25:18.13
-2,6,25:17.12
-1,6,25:18.12
-5,7,25:18.13
-2,7,25:18.13
0,7,25:18.12
-7,8,25:18.13
-1,8,25:18.13
-9,9,25:18.5
-8,9,25:18.5
0,9,25:18.13
-8,-11,26:18.4
-7,-10,26:18.4
-7,-9,26:18.4
-6,-8,26:18.4
-6,-7,26:18.12
-5,-6,26:18.12
-5,-5,26:18.12
1,-5,26:18.12
2,-5,26:18.4
3,-5,26:18.4
-5,-4,26:18.12
-4,-4,26:18.12
-1,-4,26:18.12
0,-4,26:18.12
1,-4,26:18.12
-4,-3,26:18.12
-3,-3,26:17.12
-2,-3,26:18.12
-1,-3,26:18.12
-6,-2,26:18.12
-5,-2,26:18.12
-4,-2,26:17.12
-3,-2,26:18.12
-8,-1,26:18.12
-7,-1,26:18.12
-3,-1,26:18.12
-11,0,26:18.4
-10,0,26:18.4
-9,0,26:18.4
-3,0,26:18.12
-12,1,26:18.4
-2,1,26:18.12
-5,2,26:18.13
-4,3,26:18.13
0,3,26:18.13
-4,4,26:18.13
-3,4,26:18.13
-1,4,26:18.13
-3,5,26:18.13
-2,5,26:18.13
-1,5,26:18.12
-4,6,26:18.13
-3,6,26:17.12
-2,6,26:17.12
-1,6,26:18.12
-6,7,26:18.13
-5,7,26:18.13
-2,7,26:18.13
0,7,26:18.12
-7,8,26:18.13
-1,13,26:18.5
-8,-12,27:18.4
-8,-11,27:18.4
-7,-10,27:18.4
-7,-9,27:18.4
-6,-8,27:18.4
-5,-6,27:18.12
-5,-5,27:18.12
2,-5,27:18.4
-5,-4,27:18.12
-4,-4,27:18.12
-1,-4,27:18.12
0,-4,27:18.12
-4,-3,27:18.12
-3,-3,27:17.12
-2,-3,27:18.12
-1,-3,27:18.12
-6,-2,27:18.12
-5,-2,27:18.12
-4,-2,27:17.12
-3,-2,27:18.12
-7,-1,27:18.12
-4,-1,27:18.13
-3,-1,27:18.12
-11,0,27:18.4
-10,0,27:18.4
-9,0,27:18.4
-3,0,27:18.12
-12,1,27:18.4
-3,1,27:18.13
-2,1,27:18.12
-2,2,27:18.12
-2,3,27:18.12
-3,4,27:18.13
-1,4,27:18.12
-3,5,27:17.12
-2,5,27:17.12
-1,5,27:18.12
-9,6,27:18.5
-8,6,27:18.5
-6,6,27:18.13
-3,6,27:17.12
-2,6,27:17.12
-1,6,27:18.12
0,7,27:18.12
-2,9,27:18.13
-2,10,27:18.13
-2,11,27:18.5
-2,12,27:18.5
-1,13,27:18.5
-8,-11,28:18.4
-7,-10,28:18.4
-7,-9,28:18.4
-6,-8,28:18.4
-6,-7,28:18.12
-5,-6,28:18.12
-5,-5,28:18.12
1,-5,28:18.12
2,-5,28:18.4
-5,-4,28:18.12
-4,-4,28:18.12
-1,-4,28:18.12
0,-4,28:18.12
-4,-3,28:18.12
-3,-3,28:17.12
-2,-3,28:18.12
-1,-3,28:18.12
-6,-2,28:18.12
-5,-2,28:18.12
-4,-2,28:18.12
-3,-2,28:18.12
-8,-1,28:18.12
-7,-1,28:18.12
-4,-1,28:18.13
-3,-1,28:18.12
-11,0,28:18.4
-10,0,28:18.4
-3,0,28:18.13
-13,1,28:18.4
-3,1,28:18.13
-2,1,28:18.12
-2,2,28:18.12
-3,3,28:18.13
-2,3,28:18.12
-3,4,28:18.13
-2,4,28:18.13
-1,4,28:18.12
-4,5,28:18.13
-3,5,28:17.12
-2,5,28:18.13
-1,5,28:18.13
-9,6,28:18.5
-8,6,28:18.5
-7,6,28:18.13
-6,6,28:18.13
-5,6,28:18.13
-4,6,28:18.13
-3,6,28:17.12
-2,6,28:17.12
-1,6,28:18.13
0,6,28:18.13
1,6,28:18.13
2,6,28:18.13
3,6,28:18.5
4,6,28:18.5
-3,7,28:18.13
-2,7,28:18.13
0,7,28:18.12
-3,8,28:18.13
-2,8,28:18.13
0,8,28:18.12
-2,9,28:18.13
-2,10,28:18.13
-2,11,28:18.5
-2,12,28:18.5
-1,13,28:18.5
-8,-11,29:18.4
-6,-8,29:18.4
-6,-7,29:18.12
-5,-6,29:18.12
-5,-5,29:18.12
-5,-4,29:18.12
-4,-4,29:18.12
0,-4,29:18.12
-4,-3,29:18.12
-3,-3,29:18.12
-2,-3,29:18.12
-6,-2,29:18.12
-5,-2,29:18.12
-4,-2,29:17.12
-3,-2,29:17.12
-8,-1,29:18.12
-7,-1,29:18.12
-3,-1,29:18.12
-11,0,29:18.4
-10,0,29:18.4
-9,0,29:18.4
-3,0,29:18.12
-13,1,29:18.4
-12,1,29:18.4
-3,1,29:18.13
-2,2,29:18.12
-3,3,29:18.13
-2,3,29:18.12
-3,4,29:18.13
-2,4,29:18.13
-1,4,29:18.12
-4,5,29:18.13
-3,5,29:17.12
-2,5,29:18.13
-1,5,29:18.13
-9,6,29:18.5
-8,6,29:18.5
-7,6,29:18.13
-6,6,29:18.13
-5,6,29:18.13
-4,6,29:18.13
-3,6,29:17.12
-2,6,29:18.13
-1,6,29:18.13
0,6,29:18.13
1,6,29:18.13
2,6,29:18.13
3,6,29:18.5
4,6,29:18.5
-3,7,29:18.13
-2,7,29:18.13
0,7,29:18.12
-3,8,29:18.13
-2,8,29:18.13
0,8,29:18.12
-2,9,29:18.13
-2,10,29:18.13
-2,11,29:18.5
-5,-5,30:18.12
-5,-4,30:18.12
-4,-4,30:18.12
-4,-3,30:18.12
-3,-3,30:18.12
-2,-3,30:18.12
-6,-2,30:18.12
-5,-2,30:18.12
-4,-2,30:17.12
-3,-2,30:18.12
-8,-1,30:18.12
-3,-1,30:18.12
-11,0,30:18.4
-3,0,30:18.12
-12,1,30:18.4
-3,1,30:18.13
-3,3,30:18.13
-3,4,30:18.13
-2,4,30:18.13
-1,4,30:18.12
-4,5,30:18.13
-3,5,30:18.13
-2,5,30:18.13
-1,5,30:18.13
-8,6,30:18.5
-7,6,30:18.13
-6,6,30:18.13
-5,6,30:18.13
-4,6,30:18.13
-3,6,30:17.12
-2,6,30:18.13
-1,6,30:18.13
0,6,30:18.13
1,6,30:18.13
2,6,30:18.13
-3,7,30:18.13
-2,7,30:18.13
-2,8,30:18.13
-2,9,30:18.13
-2,10,30:18.13
-2,11,30:18.5
-4,-3,31:17.12
-5,-2,31:18.12
-4,-2,31:17.12
-3,-2,31:17.12
0,-2,31:18.12
-3,3,31:18.13
-3,4,31:18.13
-4,5,31:18.13
-3,5,31:17.12
-2,5,31:18.13
-6,6,31:18.13
-5,6,31:18.13
-4,6,31:18.13
-3,6,31:18.13
-2,6,31:18.13
-1,6,31:18.13
0,6,31:18.13
1,6,31:18.13
-3,7,31:18.13
0,7,31:18.13
1,7,31:18.13
-2,8,31:18.13
1,8,31:18.13
2,8,31:18.13
-2,9,31:18.13
-3,-6,32:18.12
-3,-4,32:18.12
-6,-3,32:18.12
-4,-3,32:18.12
-3,-3,32:18.12
-4,-2,32:17.12
-3,-2,32:17.12
-2,-2,32:18.12
-1,-2,32:18.12
0,-2,32:18.12
1,-2,32:18.12
-4,-1,32:18.12
2,-1,32:18.4
-5,1,32:18.12
0,1,32:18.13
-5,2,32:18.12
-1,2,32:18.13
-6,3,32:18.13
-5,3,32:18.13
-1,3,32:18.13
-5,4,32:18.13
-4,4,32:18.13
-2,4,32:18.13
-4,5,32:18.13
-3,5,32:18.13
-2,5,32:18.13
-3,6,32:18.13
-2,6,32:18.13
-4,7,32:18.13
-1,7,32:18.13
0,7,32:18.13
1,7,32:18.13
-5,8,32:18.13
1,8,32:18.13
2,8,32:18.13
-6,9,32:18.13
-5,9,32:18.13
-7,10,32:18.13
-6,10,32:18.13
-7,11,32:18.5
-2,-8,33:18.4
-2,-7,33:18.4
-3,-6,33:18.12
-3,-5,33:18.12
-8,-4,33:18.12
-7,-4,33:18.12
-3,-4,33:18.12
-6,-3,33:18.12
-5,-3,33:18.12
-4,-3,33:18.12
-3,-3,33:18.12
-4,-2,33:18.12
-3,-2,33:18.12
-2,-2,33:18.12
-1,-2,33:18.12
0,-2,33:18.12
1,-2,33:18.12
-4,-1,33:18.12
2,-1,33:18.4
-4,0,33:18.12
-5,1,33:18.12
0,1,33:18.13
-5,2,33:18.12
-1,2,33:18.13
0,2,33:18.13
-6,3,33:18.13
-5,3,33:18.13
-1,3,33:18.13
-6,4,33:18.12
-5,4,33:18.13
-4,4,33:18.13
-2,4,33:18.13
-6,5,33:18.12
-4,5,33:18.13
-3,5,33:18.13
-2,5,33:18.13
-3,6,33:18.13
-2,6,33:18.13
-1,6,33:18.13
-4,7,33:18.13
-1,7,33:18.13
0,7,33:18.13
1,7,33:18.13
-5,8,33:18.13
1,8,33:18.13
2,8,33:18.5
-6,9,33:18.13
-5,9,33:18.13
-7,10,33:18.13
-6,10,33:18.13
-7,11,33:18.5
-2,-9,34:18.4
-2,-8,34:18.4
-2,-7,34:18.4
-3,-6,34:18.12
-3,-5,34:18.12
-8,-4,34:18.12
-7,-4,34:18.12
-3,-4,34:18.12
-6,-3,34:18.12
-5,-3,34:18.12
-4,-3,34:18.12
-3,-3,34:18.12
-4,-2,34:18.12
-3,-2,34:18.12
-2,-2,34:18.12
-1,-2,34:18.12
0,-2,34:18.12
1,-2,34:18.12
-4,-1,34:18.12
2,-1,34:18.4
-5,0,34:18.12
-4,0,34:18.12
-5,1,34:18.12
0,1,34:18.13
-5,2,34:18.12
-1,2,34:18.13
-6,3,34:18.13
-5,3,34:18.13
-1,3,34:18.13
-6,4,34:18.12
-5,4,34:18.13
-4,4,34:18.13
-2,4,34:18.13
-6,5,34:18.12
-4,5,34:18.13
-3,5,34:18.13
-2,5,34:18.13
-7,6,34:18.12
-3,6,34:18.13
-2,6,34:18.13
-1,6,34:18.13
-4,7,34:18.13
-1,7,34:18.13
0,7,34:18.13
-5,8,34:18.13
2,8,34:18.5
-6,9,34:18.13
-7,10,34:18.13
-6,10,34:18.13
-7,11,34:18.5
-8,12,34:18.5
-2,-9,35:18.4
-2,-8,35:18.4
-2,-7,35:18.4
-3,-6,35:18.12
-3,-5,35:18.12
-9,-4,35:18.4
-8,-4,35:18.12
-7,-4,35:18.12
-3,-4,35:18.12
-6,-3,35:18.12
-5,-3,35:18.12
-4,-3,35:18.12
-3,-3,35:18.12
-4,-2,35:18.12
-3,-2,35:18.12
-2,-2,35:18.12
-1,-2,35:18.12
0,-2,35:18.12
-4,-1,35:18.12
2,-1,35:18.4
-4,0,35:18.12
-5,1,35:18.12
0,1,35:18.13
-5,2,35:18.12
-1,2,35:18.13
-6,3,35:18.13
-5,3,35:18.13
-1,3,35:18.13
-6,4,35:18.12
-5,4,35:18.13
-4,4,35:18.13
-2,4,35:18.13
-6,5,35:18.12
-4,5,35:18.13
-3,5,35:18.13
-2,5,35:18.13
-3,6,35:18.13
-2,6,35:18.13
-1,6,35:18.13
-4,7,35:18.13
-1,7,35:18.13
0,7,35:18.13
1,7,35:18.13
-5,8,35:18.13
-6,9,35:18.13
-5,9,35:18.13
-7,11,35:18.5
-8,-4,36:18.12
-7,-4,36:18.12
-3,-4,36:18.12
-5,-3,36:18.12
-4,-3,36:18.12
-4,-2,36:17.12
-3,-2,36:17.12
-2,-2,36:18.12
-4,-1,36:18.12
-4,0,36:18.12
-1,2,36:18.13
-6,3,36:18.4
-5,3,36:18.5
-1,3,36:18.5
-5,4,36:18.5
-4,4,36:18.5
-2,4,36:18.5
-4,5,36:18.5
-3,5,36:18.5
-2,5,36:18.5
-3,6,36:18.5
-2,6,36:18.5
-1,6,36:18.5
-4,7,36:18.5
-2,7,36:18.5
0,7,36:18.5
-5,8,36:18.5
-6,9,36:18.5
-4,-2,37:17.0
-3,-2,37:17.0
0,3,37:18.5
-1,4,37:18.5
0,4,37:18.5
-3,5,37:17.0
-2,5,37:18.5
-3,6,37:17.0
-2,6,37:18.5
-2,7,37:18.5
-1,8,37:18.5
-1,9,37:18.5
-2,-5,38:18.12
-6,-4,38:18.12
-2,-4,38:18.12
-3,-3,38:18.12
-4,-2,38:17.0
-3,-2,38:18.12
-5,-1,38:18.12
-2,-1,38:18.12
-1,0,38:18.12
0,1,38:18.12
-5,2,38:18.13
-4,3,38:18.5
0,3,38:18.5
-4,4,38:18.5
-1,4,38:18.5
0,4,38:18.5
-3,5,38:18.5
-2,5,38:18.5
-1,5,38:18.5
-5,6,38:18.5
-4,6,38:18.5
-3,6,38:18.5
-2,6,38:18.5
-6,7,38:18.5
-2,7,38:18.5
-1,8,38:18.5
-1,9,38:18.5
-7,-5,39:18.12
-2,-5,39:18.12
-6,-4,39:18.12
-5,-4,39:18.12
-2,-4,39:18.12
-5,-3,39:18.12
-4,-3,39:18.12
-3,-3,39:18.12
-5,-2,39:18.12
-4,-2,39:18.12
-3,-2,39:18.12
-6,-1,39:18.12
-5,-1,39:18.12
-2,-1,39:18.12
-7,0,39:18.12
-6,0,39:18.12
-1,0,39:18.12
0,1,39:18.12
-5,2,39:18.13
-5,3,39:18.5
-4,3,39:18.5
0,3,39:18.5
-4,4,39:18.5
-1,4,39:18.5
0,4,39:18.5
-3,5,39:18.5
-2,5,39:18.5
-1,5,39:18.5
-5,6,39:18.5
-4,6,39:18.5
-3,6,39:18.5
-2,6,39:18.5
-7,7,39:18.5
-6,7,39:18.5
-2,7,39:18.5
-1,8,39:18.5
-1,9,39:18.5
-7,-5,40:18.12
-6,-4,40:18.12
-5,-4,40:18.12
-5,-3,40:18.12
-4,-3,40:18.12
-3,-3,40:18.12
-4,-2,40:18.12
-3,-2,40:18.12
-6,-1,40:18.12
-5,-1,40:18.12
-2,-1,40:18.12
-7,0,40:18.12
-6,0,40:18.12
-7,1,40:18.12
-5,2,40:18.13
-4,3,40:18.5
-4,4,40:18.5
-1,4,40:18.5
0,4,40:18.5
-3,5,40:18.5
-2,5,40:18.5
-1,5,40:18.5
-5,6,40:18.5
-4,6,40:18.5
-3,6,40:18.5
-2,6,40:18.5
-6,7,40:18.5
-2,7,40:18.5
-1,8,40:18.5
-4,-3,41:18.4
-4,-2,41:17.0
-5,2,41:18.5
-4,3,41:18.5
-4,4,41:18.5
-1,4,41:18.5
-3,5,41:18.5
-2,5,41:18.5
-5,6,41:18.5
-4,6,41:18.5
-3,6,41:18.5
-2,6,41:18.5
-6,7,41:18.5
-2,7,41:18.5
-1,8,41:18.5
-4,-2,42:17.0
-4,3,42:18.5
-4,4,42:18.5
-3,5,42:18.5
-2,5,42:18.5
-5,6,42:18.5
-4,6,42:18.5
-3,6,42:17.0
-2,7,42:18.5
-4,-2,43:17.0
-4,4,43:18.5
-4,6,43:18.5
-3,6,43:17.0
