[META]
version=2.0
spawnOnBlockType=2
spawnSunlight=True
spawnDarkness=True
spawnWater=False
spawnLava=False
underFill=False
randomRotation=True
dig=True
tree=False
branch=False
needsFoundation=True
rarity=100
collisionPercentage=20
spawnElevationMin=0
spawnElevationMax=200
spawnInBiome=Custom
[DATA]
16,-13,-8:17.12
16,-12,-8:17.12
15,-14,-7:17.12
16,-14,-7:17.12
15,-13,-7:17.12
16,-13,-7:17.12
15,-12,-7:17.12
16,-12,-7:17.12
17,-12,-7:17.12
15,-14,-6:17.12
16,-14,-6:17.12
14,-13,-6:17.12
15,-13,-6:17.12
15,-12,-6:17.12
15,-14,-5:17.12
14,-13,-5:17.12
15,-13,-5:17.12
15,-12,-5:17.12
15,-14,-4:17.12
16,-14,-4:17.12
14,-13,-4:17.12
15,-13,-4:17.12
17,-13,-4:17.12
16,-12,-4:17.12
14,-14,-3:17.12
15,-14,-3:17.12
16,-14,-3:17.12
15,-13,-3:17.12
16,-13,-3:17.12
14,-12,-3:17.12
15,-12,-3:17.12
16,-12,-3:17.12
14,-14,-2:17.12
15,-14,-2:17.12
14,-13,-2:17.12
15,-13,-2:17.12
16,-13,-2:17.12
14,-12,-2:17.12
15,-12,-2:17.12
14,-14,-1:17.12
15,-14,-1:17.12
14,-13,-1:17.12
15,-13,-1:17.12
14,-14,0:17.12
15,-14,0:17.12
14,-13,0:17.12
15,-13,0:17.12
14,-14,1:17.12
15,-14,1:17.12
14,-13,1:17.12
15,-13,1:17.12
13,-15,2:18.14
14,-14,2:18.14
15,-14,2:18.14
14,-13,2:18.14
15,-13,2:18.14
13,-12,2:18.14
14,-12,2:18.14
16,-12,2:18.14
9,-17,3:18.6
13,-15,3:18.14
15,-15,3:18.14
13,-14,3:18.14
14,-14,3:18.14
15,-14,3:18.14
16,-14,3:18.14
13,-13,3:18.14
14,-13,3:18.14
15,-13,3:18.14
16,-13,3:18.14
13,-12,3:18.14
14,-12,3:18.14
15,-12,3:18.14
16,-12,3:18.14
13,-11,3:18.14
17,-11,3:18.14
18,-11,3:18.14
12,-10,3:18.14
18,-10,3:18.14
12,-9,3:18.14
19,-9,3:18.14
20,-9,3:18.6
11,-8,3:18.6
9,-17,4:18.6
10,-17,4:18.14
10,-16,4:18.14
11,-16,4:18.14
12,-16,4:18.14
12,-15,4:18.14
13,-15,4:18.14
14,-15,4:18.14
15,-15,4:18.14
16,-15,4:18.14
13,-14,4:18.14
14,-14,4:18.14
15,-14,4:18.14
16,-14,4:18.14
13,-13,4:18.14
14,-13,4:18.14
15,-13,4:18.14
16,-13,4:18.14
13,-12,4:18.14
14,-12,4:18.14
15,-12,4:18.14
16,-12,4:18.14
13,-11,4:18.14
17,-11,4:18.14
18,-11,4:18.14
12,-10,4:18.14
18,-10,4:18.14
19,-10,4:18.14
12,-9,4:18.14
19,-9,4:18.14
20,-9,4:18.6
11,-8,4:18.6
20,-8,4:18.6
8,-17,5:18.6
9,-17,5:18.6
10,-16,5:18.14
11,-16,5:18.14
16,-16,5:18.14
12,-15,5:18.14
13,-15,5:18.14
14,-15,5:18.14
15,-15,5:18.14
16,-15,5:18.14
13,-14,5:18.14
14,-14,5:18.14
15,-14,5:18.14
16,-14,5:18.14
13,-13,5:18.14
14,-13,5:18.14
15,-13,5:17.12
16,-13,5:18.14
13,-12,5:18.14
14,-12,5:18.14
15,-12,5:18.14
16,-12,5:18.14
13,-11,5:18.14
17,-11,5:18.14
18,-11,5:18.14
12,-10,5:18.14
13,-10,5:18.14
18,-10,5:18.14
19,-10,5:18.14
12,-9,5:18.14
19,-9,5:18.14
20,-9,5:18.6
11,-8,5:18.6
20,-8,5:18.6
10,-16,6:18.6
11,-16,6:18.14
16,-16,6:18.14
17,-16,6:18.14
11,-15,6:18.14
12,-15,6:18.14
13,-15,6:18.14
16,-15,6:18.14
13,-14,6:18.14
14,-14,6:18.14
15,-14,6:18.14
16,-14,6:18.14
14,-13,6:18.14
15,-13,6:17.12
16,-13,6:18.14
13,-12,6:18.14
14,-12,6:18.14
15,-12,6:18.14
16,-12,6:18.14
13,-11,6:18.14
17,-11,6:18.14
18,-11,6:18.14
12,-10,6:18.14
18,-10,6:18.14
19,-10,6:18.14
19,-9,6:18.14
17,-16,7:18.14
12,-15,7:18.14
14,-15,7:18.14
16,-15,7:18.14
17,-15,7:18.14
18,-15,7:18.14
14,-14,7:18.14
15,-14,7:18.14
16,-14,7:18.14
17,-14,7:18.14
13,-13,7:18.14
14,-13,7:18.14
15,-13,7:18.14
11,-12,7:18.14
12,-12,7:18.14
13,-12,7:18.14
14,-12,7:18.14
15,-12,7:18.14
16,-12,7:18.14
13,-11,7:18.14
15,-11,7:18.14
17,-11,7:18.14
16,-10,7:18.14
18,-10,7:18.14
16,-9,7:18.14
13,-16,8:18.14
14,-15,8:18.14
17,-15,8:18.14
18,-15,8:18.14
19,-15,8:18.14
14,-14,8:18.14
15,-14,8:18.14
16,-14,8:18.14
17,-14,8:18.14
13,-13,8:18.14
14,-13,8:18.14
15,-13,8:17.12
11,-12,8:18.14
12,-12,8:18.14
13,-12,8:18.14
15,-12,8:18.14
15,-11,8:18.14
16,-10,8:18.14
16,-9,8:18.14
13,-17,9:18.14
13,-16,9:18.14
14,-15,9:18.14
18,-15,9:18.14
19,-15,9:18.14
14,-14,9:18.14
15,-14,9:18.14
16,-14,9:18.14
17,-14,9:18.14
18,-14,9:18.14
19,-14,9:18.14
12,-13,9:18.14
13,-13,9:18.14
14,-13,9:18.14
15,-13,9:17.12
11,-12,9:18.14
15,-12,9:18.14
15,-11,9:18.14
16,-10,9:18.14
14,-15,10:18.14
14,-14,10:18.14
15,-14,10:18.14
16,-14,10:18.14
17,-14,10:18.14
18,-14,10:18.14
13,-13,10:18.14
14,-13,10:18.14
15,-13,10:18.14
13,-12,10:18.14
14,-12,10:18.14
15,-12,10:18.14
16,-12,10:18.14
17,-12,10:18.14
12,-11,10:18.14
13,-11,10:18.14
15,-11,10:18.14
11,-10,10:18.14
12,-10,10:18.14
11,-9,10:18.14
18,-18,11:18.6
17,-17,11:18.14
11,-16,11:18.14
12,-16,11:18.14
16,-16,11:18.14
12,-15,11:18.14
13,-15,11:18.14
15,-15,11:18.14
16,-15,11:18.14
13,-14,11:18.14
14,-14,11:18.14
15,-14,11:18.14
14,-13,11:18.14
15,-13,11:18.14
13,-12,11:18.14
14,-12,11:18.14
16,-12,11:18.14
17,-12,11:18.14
18,-12,11:18.14
12,-11,11:18.14
13,-11,11:18.14
11,-10,11:18.14
12,-10,11:18.14
11,-9,11:18.14
18,-18,12:18.6
17,-17,12:18.14
11,-16,12:18.14
12,-16,12:18.14
16,-16,12:18.14
12,-15,12:18.14
13,-15,12:18.14
15,-15,12:18.14
16,-15,12:18.14
13,-14,12:18.14
14,-14,12:18.14
15,-14,12:18.14
14,-13,12:18.14
15,-13,12:18.14
16,-13,12:18.14
17,-13,12:18.14
13,-12,12:18.14
14,-12,12:18.14
16,-12,12:18.14
12,-11,12:18.14
13,-11,12:18.14
12,-10,12:18.14
11,-9,12:18.14
12,-9,12:18.14
17,-17,13:18.14
11,-16,13:18.14
16,-16,13:18.14
12,-15,13:18.14
13,-15,13:18.14
15,-15,13:18.14
16,-15,13:18.14
13,-14,13:18.14
14,-14,13:18.14
15,-14,13:18.14
14,-13,13:18.14
15,-13,13:18.14
16,-13,13:18.14
13,-12,13:18.14
14,-12,13:18.14
13,-11,13:18.14
12,-10,13:18.14
13,-10,13:18.14
13,-17,14:18.14
13,-16,14:18.14
13,-15,14:18.14
14,-15,14:18.14
15,-15,14:18.14
16,-15,14:18.14
18,-15,14:18.14
13,-14,14:18.14
14,-14,14:18.14
15,-14,14:18.14
18,-14,14:18.14
14,-13,14:18.14
15,-13,14:17.12
12,-12,14:18.14
14,-12,14:18.14
15,-12,14:18.14
13,-11,14:18.14
16,-11,14:18.14
16,-10,14:18.14
13,-17,15:18.14
13,-16,15:18.14
14,-15,15:18.14
18,-15,15:18.14
19,-15,15:18.14
14,-14,15:18.14
15,-14,15:18.14
16,-14,15:18.14
17,-14,15:18.14
18,-14,15:18.14
13,-13,15:18.14
14,-13,15:18.14
15,-13,15:18.14
11,-12,15:18.14
12,-12,15:18.14
15,-12,15:18.14
16,-11,15:18.14
16,-10,15:18.14
17,-9,15:18.14
13,-16,16:18.14
14,-15,16:18.14
18,-15,16:18.14
14,-14,16:18.14
15,-14,16:18.14
16,-14,16:18.14
17,-14,16:18.14
18,-14,16:18.14
13,-13,16:18.14
14,-13,16:18.14
15,-13,16:18.14
17,-13,16:18.14
18,-13,16:18.14
12,-12,16:18.14
15,-12,16:18.14
16,-11,16:18.14
15,-16,17:18.14
15,-15,17:18.14
12,-14,17:18.14
13,-14,17:18.14
14,-14,17:18.14
15,-14,17:18.14
14,-13,17:18.14
15,-13,17:18.14
16,-13,17:18.14
17,-13,17:18.14
18,-13,17:18.14
14,-12,17:18.14
14,-11,17:18.14
13,-10,17:18.14
15,-17,18:18.14
15,-16,18:18.14
15,-15,18:18.14
12,-14,18:18.14
13,-14,18:18.14
14,-14,18:18.14
15,-14,18:18.14
14,-13,18:18.14
15,-13,18:18.14
16,-13,18:18.14
17,-13,18:18.14
18,-13,18:18.14
14,-12,18:18.14
14,-11,18:18.14
13,-10,18:18.14
13,-9,18:18.14
15,-16,19:18.6
15,-15,19:18.6
12,-14,19:18.6
13,-14,19:18.6
14,-14,19:18.6
15,-14,19:18.6
14,-13,19:18.6
15,-13,19:18.6
16,-13,19:18.6
14,-12,19:18.6
14,-11,19:18.6
13,-10,19:18.6
15,-15,20:18.6
16,-15,20:18.6
13,-14,20:18.6
14,-14,20:18.6
15,-14,20:18.6
14,-13,20:18.6
15,-13,20:18.6
16,-12,20:18.6
13,-15,21:18.6
16,-15,21:18.6
13,-14,21:18.6
14,-14,21:18.6
15,-14,21:18.6
14,-13,21:18.6
15,-13,21:18.6
13,-12,21:18.6
16,-12,21:18.6
13,-15,22:18.6
13,-14,22:18.6
14,-14,22:18.6
15,-14,22:18.6
14,-13,22:18.6
15,-13,22:18.6
13,-12,22:18.6
16,-12,22:18.6
13,-14,23:18.6
14,-14,23:18.6
15,-14,23:18.6
14,-13,23:18.6
15,-13,23:18.6
13,-12,23:18.6
