[META]
version=2.0
spawnOnBlockType=2
spawnSunlight=True
spawnDarkness=True
spawnWater=False
spawnLava=False
underFill=False
randomRotation=True
dig=True
tree=False
branch=False
needsFoundation=True
rarity=100
collisionPercentage=20
spawnElevationMin=0
spawnElevationMax=200
spawnInBiome=Custom
[DATA]
10,-9,-8:17.12
9,-8,-8:17.12
10,-8,-8:17.12
11,-8,-8:17.12
10,-7,-8:17.12
11,-9,-7:17.12
9,-8,-7:17.12
10,-8,-7:17.12
11,-8,-7:17.12
10,-7,-7:17.12
11,-7,-7:17.12
10,-9,-6:17.12
9,-8,-6:17.12
10,-8,-6:17.12
10,-9,-5:17.12
9,-8,-5:17.12
10,-8,-5:17.12
11,-8,-5:17.12
10,-7,-5:17.12
11,-7,-5:17.12
10,-9,-4:17.12
10,-8,-4:17.12
11,-8,-4:17.12
10,-7,-4:17.12
11,-7,-4:17.12
9,-9,-3:17.12
10,-9,-3:17.12
9,-8,-3:17.12
10,-8,-3:17.12
11,-8,-3:17.12
9,-7,-3:17.12
10,-7,-3:17.12
9,-9,-2:17.12
10,-9,-2:17.12
9,-8,-2:17.12
10,-8,-2:17.12
11,-8,-2:17.12
9,-7,-2:17.12
10,-7,-2:17.12
9,-9,-1:17.12
10,-9,-1:17.12
9,-8,-1:17.12
10,-8,-1:17.12
11,-8,-1:17.12
9,-7,-1:17.12
10,-7,-1:17.12
10,-9,0:17.12
9,-8,0:17.12
10,-8,0:17.12
11,-8,0:17.12
9,-7,0:17.12
10,-7,0:17.12
10,-9,1:17.12
9,-8,1:17.12
10,-8,1:17.12
11,-8,1:17.12
9,-7,1:17.12
10,-7,1:17.12
11,-16,2:18.6
9,-8,2:17.12
10,-8,2:17.12
10,-7,2:17.12
8,-16,3:18.6
9,-16,3:18.6
10,-16,3:18.6
9,-15,3:18.6
10,-15,3:18.6
11,-15,3:18.6
11,-14,3:18.6
12,-14,3:18.6
5,-13,3:18.14
15,-13,3:18.6
4,-12,3:18.6
5,-12,3:18.14
15,-12,3:18.14
16,-12,3:18.6
4,-11,3:18.6
5,-11,3:18.14
5,-10,3:18.14
9,-8,3:17.12
10,-8,3:17.12
10,-7,3:17.12
4,-5,3:18.6
16,-5,3:18.6
4,-4,3:18.6
15,-4,3:18.14
16,-4,3:18.6
11,-2,3:18.6
12,-2,3:18.6
6,-16,4:18.6
7,-16,4:18.6
8,-16,4:18.6
7,-15,4:18.6
8,-15,4:18.6
9,-15,4:18.6
6,-14,4:18.6
8,-14,4:18.6
9,-14,4:18.6
10,-14,4:18.6
11,-14,4:18.6
6,-13,4:18.6
7,-13,4:18.6
10,-13,4:18.6
11,-13,4:18.6
12,-13,4:18.6
13,-13,4:18.6
14,-13,4:18.6
6,-12,4:18.14
7,-12,4:18.14
12,-12,4:18.14
13,-12,4:18.14
14,-12,4:18.14
15,-12,4:18.14
6,-11,4:18.14
7,-11,4:18.14
14,-11,4:18.14
15,-11,4:18.14
16,-11,4:18.6
6,-10,4:18.14
16,-10,4:18.6
17,-10,4:18.6
6,-9,4:18.14
9,-8,4:17.12
10,-8,4:17.12
17,-8,4:18.6
18,-8,4:18.6
10,-7,4:17.12
16,-7,4:18.6
17,-7,4:18.6
5,-6,4:18.14
15,-6,4:18.14
16,-6,4:18.6
17,-6,4:18.6
5,-5,4:18.14
6,-5,4:18.14
14,-5,4:18.14
15,-5,4:18.14
5,-4,4:18.14
6,-4,4:18.14
12,-4,4:18.14
13,-4,4:18.14
14,-4,4:18.14
15,-4,4:18.14
6,-3,4:18.14
10,-3,4:18.14
11,-3,4:18.14
12,-3,4:18.14
13,-3,4:18.14
6,-2,4:18.6
7,-2,4:18.6
9,-2,4:18.6
10,-2,4:18.6
11,-2,4:18.6
7,-1,4:18.6
9,-1,4:18.6
7,-15,5:18.6
7,-14,5:18.6
8,-14,5:18.6
7,-13,5:18.6
8,-13,5:18.6
9,-13,5:18.6
10,-13,5:18.6
7,-12,5:18.14
8,-12,5:18.14
9,-12,5:18.14
10,-12,5:18.14
11,-12,5:18.14
12,-12,5:18.14
13,-12,5:18.14
7,-11,5:18.14
8,-11,5:18.14
11,-11,5:18.14
12,-11,5:18.14
13,-11,5:18.14
14,-11,5:18.14
7,-10,5:18.14
8,-10,5:18.14
14,-10,5:18.14
15,-10,5:18.14
16,-10,5:18.6
7,-9,5:18.14
15,-9,5:18.14
16,-9,5:18.6
17,-9,5:18.6
18,-9,5:18.6
7,-8,5:18.14
9,-8,5:17.12
10,-8,5:17.12
15,-8,5:18.14
16,-8,5:18.6
17,-8,5:18.6
5,-7,5:18.14
6,-7,5:18.14
7,-7,5:18.14
10,-7,5:17.12
15,-7,5:18.14
16,-7,5:18.6
5,-6,5:18.14
6,-6,5:18.14
7,-6,5:18.14
13,-6,5:18.14
14,-6,5:18.14
15,-6,5:18.14
6,-5,5:18.14
7,-5,5:18.14
11,-5,5:18.14
12,-5,5:18.14
13,-5,5:18.14
14,-5,5:18.14
7,-4,5:18.14
8,-4,5:18.14
9,-4,5:18.14
10,-4,5:18.14
11,-4,5:18.14
12,-4,5:18.14
13,-4,5:18.14
7,-3,5:18.14
8,-3,5:18.14
9,-3,5:18.14
10,-3,5:18.14
7,-2,5:18.6
8,-2,5:18.6
9,-2,5:18.6
7,-1,5:18.6
8,-1,5:18.6
9,-12,6:18.14
11,-12,6:18.14
9,-11,6:18.14
10,-11,6:18.14
11,-11,6:18.14
12,-11,6:18.14
13,-11,6:18.14
8,-10,6:18.14
9,-10,6:18.14
11,-10,6:18.14
12,-10,6:18.14
13,-10,6:18.14
8,-9,6:18.14
13,-9,6:18.14
14,-9,6:18.14
15,-9,6:18.6
6,-8,6:18.14
7,-8,6:18.14
8,-8,6:18.14
9,-8,6:17.12
10,-8,6:17.12
13,-8,6:18.14
14,-8,6:18.14
15,-8,6:18.6
6,-7,6:18.14
7,-7,6:18.14
10,-7,6:17.12
13,-7,6:18.14
7,-6,6:18.14
8,-6,6:18.14
11,-6,6:18.14
12,-6,6:18.14
13,-6,6:18.14
8,-5,6:18.14
9,-5,6:18.14
10,-5,6:18.14
11,-5,6:18.14
12,-5,6:18.14
13,-5,6:18.14
8,-4,6:18.14
9,-4,6:18.14
11,-4,6:18.14
12,-4,6:18.14
11,-12,7:18.14
11,-11,7:18.14
9,-10,7:18.14
10,-10,7:18.14
11,-10,7:18.14
12,-10,7:18.14
9,-9,7:18.14
10,-9,7:18.14
11,-9,7:18.14
12,-9,7:18.14
13,-9,7:18.14
7,-8,7:18.14
8,-8,7:18.14
9,-8,7:18.14
10,-8,7:17.12
12,-8,7:18.14
13,-8,7:18.14
8,-7,7:18.14
10,-7,7:17.12
12,-7,7:18.14
13,-7,7:18.14
8,-6,7:18.14
9,-6,7:18.14
10,-6,7:18.14
11,-6,7:18.14
12,-6,7:18.14
9,-5,7:18.14
10,-5,7:18.14
11,-5,7:18.14
12,-5,7:18.14
11,-10,8:18.14
4,-9,8:18.6
10,-9,8:18.14
11,-9,8:18.14
12,-9,8:18.14
9,-8,8:17.12
10,-8,8:17.12
12,-8,8:18.14
9,-7,8:18.14
10,-7,8:18.14
11,-7,8:18.14
12,-7,8:18.14
9,-6,8:18.14
10,-6,8:18.14
11,-6,8:18.14
11,-5,8:18.14
13,-5,8:18.14
5,-4,8:18.14
6,-4,8:18.14
7,-4,8:18.14
14,-4,8:18.14
6,-3,8:18.6
7,-3,8:18.6
6,-10,9:18.14
7,-10,9:18.14
5,-9,9:18.14
6,-9,9:18.14
11,-9,9:18.14
4,-8,9:18.6
5,-8,9:18.14
10,-8,9:17.12
11,-8,9:18.14
3,-7,9:18.6
4,-7,9:18.6
10,-7,9:18.14
11,-7,9:18.14
4,-6,9:18.6
13,-6,9:18.14
4,-5,9:18.6
5,-5,9:18.14
6,-5,9:18.14
7,-5,9:18.14
8,-5,9:18.14
13,-5,9:18.14
5,-4,9:18.14
6,-4,9:18.14
7,-4,9:18.14
8,-4,9:18.14
13,-4,9:18.14
13,-3,9:18.6
14,-3,9:18.6
7,-10,10:18.14
8,-10,10:18.14
9,-10,10:18.14
6,-9,10:18.14
7,-9,10:18.14
8,-9,10:18.14
6,-8,10:18.14
7,-8,10:18.14
10,-8,10:17.12
11,-8,10:18.14
12,-8,10:18.14
5,-7,10:18.14
6,-7,10:18.14
12,-7,10:18.14
4,-6,10:18.6
5,-6,10:18.14
6,-6,10:18.14
7,-6,10:18.14
8,-6,10:18.14
9,-6,10:18.14
10,-6,10:18.14
12,-6,10:18.14
13,-6,10:18.14
6,-5,10:18.14
7,-5,10:18.14
8,-5,10:18.14
9,-5,10:18.14
10,-5,10:18.14
13,-5,10:18.14
13,-4,10:18.14
13,-3,10:18.6
13,-2,10:18.6
9,-1,10:18.6
11,-14,11:18.6
7,-13,11:18.6
12,-13,11:18.6
13,-13,11:18.6
7,-12,11:18.14
13,-12,11:18.14
8,-9,11:18.14
9,-9,11:18.14
7,-8,11:18.14
8,-8,11:18.14
9,-8,11:18.14
10,-8,11:17.12
11,-8,11:18.14
7,-7,11:18.14
8,-7,11:18.14
9,-7,11:18.14
10,-7,11:18.14
12,-7,11:18.14
8,-6,11:18.14
9,-6,11:18.14
10,-6,11:18.14
12,-6,11:18.14
12,-5,11:18.14
12,-4,11:18.14
13,-4,11:18.14
8,-3,11:18.6
9,-3,11:18.6
13,-3,11:18.6
9,-2,11:18.6
10,-2,11:18.6
11,-2,11:18.6
12,-2,11:18.6
13,-2,11:18.6
9,-1,11:18.6
11,-1,11:18.6
12,-1,11:18.6
13,-1,11:18.6
13,0,11:18.6
10,-15,12:18.6
8,-14,12:18.6
9,-14,12:18.6
10,-14,12:18.6
11,-14,12:18.6
8,-13,12:18.6
9,-13,12:18.6
10,-13,12:18.6
11,-13,12:18.6
12,-13,12:18.6
7,-12,12:18.14
8,-12,12:18.14
11,-12,12:18.14
12,-12,12:18.14
7,-11,12:18.14
8,-11,12:18.14
12,-11,12:18.14
13,-11,12:18.14
7,-10,12:18.14
13,-10,12:18.14
13,-9,12:18.14
9,-8,12:18.14
10,-8,12:17.12
11,-8,12:18.14
11,-7,12:18.14
11,-6,12:18.14
12,-6,12:18.14
7,-5,12:18.14
8,-5,12:18.14
12,-5,12:18.14
8,-4,12:18.14
9,-4,12:18.14
10,-4,12:18.14
12,-4,12:18.14
9,-3,12:18.6
10,-3,12:18.6
11,-3,12:18.6
12,-3,12:18.6
11,-2,12:18.6
12,-2,12:18.6
9,-13,13:18.6
10,-13,13:18.6
9,-12,13:18.14
10,-12,13:18.14
11,-12,13:18.14
8,-11,13:18.14
9,-11,13:18.14
10,-11,13:18.14
11,-11,13:18.14
12,-11,13:18.14
8,-10,13:18.14
9,-10,13:18.14
11,-10,13:18.14
12,-10,13:18.14
7,-9,13:18.14
8,-9,13:18.14
12,-9,13:18.14
13,-9,13:18.14
15,-9,13:18.14
10,-8,13:17.12
11,-8,13:18.14
15,-8,13:18.14
16,-8,13:18.6
11,-7,13:18.14
8,-6,13:18.14
9,-6,13:18.14
11,-6,13:18.14
8,-5,13:18.14
9,-5,13:18.14
10,-5,13:18.14
11,-5,13:18.14
10,-4,13:18.14
11,-4,13:18.14
12,-4,13:18.14
13,-4,13:18.14
13,-3,13:18.6
6,-12,14:18.14
10,-11,14:18.14
9,-10,14:18.14
10,-10,14:18.14
11,-10,14:18.14
9,-9,14:18.14
10,-9,14:18.14
11,-9,14:18.14
13,-9,14:18.14
14,-9,14:18.14
9,-8,14:18.14
10,-8,14:17.12
11,-8,14:17.12
14,-8,14:18.14
15,-8,14:18.14
9,-7,14:18.14
10,-7,14:18.14
11,-7,14:18.14
15,-7,14:18.14
9,-6,14:18.14
10,-6,14:18.14
11,-6,14:18.14
15,-6,14:18.14
10,-5,14:18.14
11,-5,14:18.14
12,-5,14:18.14
13,-5,14:18.14
14,-5,14:18.14
15,-5,14:18.14
16,-5,14:18.6
11,-4,14:18.14
12,-4,14:18.14
13,-4,14:18.14
14,-4,14:18.14
7,-12,15:18.14
5,-11,15:18.6
6,-11,15:18.14
7,-11,15:18.14
8,-11,15:18.14
9,-11,15:18.14
4,-10,15:18.6
5,-10,15:18.6
6,-10,15:18.14
12,-10,15:18.14
10,-9,15:18.14
12,-9,15:18.14
13,-9,15:18.14
4,-8,15:18.6
5,-8,15:18.6
10,-8,15:17.12
11,-8,15:17.12
12,-8,15:18.14
13,-8,15:18.14
5,-7,15:18.6
6,-7,15:18.14
10,-7,15:18.14
13,-7,15:18.14
5,-6,15:18.6
6,-6,15:18.14
7,-6,15:18.14
10,-6,15:18.14
11,-6,15:18.14
12,-6,15:18.14
13,-6,15:18.14
14,-6,15:18.14
15,-6,15:18.14
10,-5,15:18.14
11,-5,15:18.14
12,-5,15:18.14
12,-13,16:18.6
11,-12,16:18.14
12,-12,16:18.14
8,-11,16:18.14
9,-11,16:18.14
10,-11,16:18.14
15,-11,16:18.14
4,-10,16:18.6
5,-10,16:18.6
6,-10,16:18.14
7,-10,16:18.14
8,-10,16:18.14
9,-10,16:18.14
10,-10,16:18.14
15,-10,16:18.14
4,-9,16:18.6
5,-9,16:18.6
6,-9,16:18.14
7,-9,16:18.14
11,-9,16:18.14
15,-9,16:18.14
5,-8,16:18.6
6,-8,16:18.14
7,-8,16:18.14
10,-8,16:17.0
11,-8,16:18.14
12,-8,16:18.14
6,-7,16:18.14
7,-7,16:18.14
8,-7,16:18.14
10,-7,16:18.14
11,-7,16:18.14
12,-7,16:18.14
13,-7,16:18.14
7,-6,16:18.14
8,-6,16:18.14
9,-6,16:18.14
11,-3,16:18.6
11,-12,17:18.14
12,-12,17:18.14
13,-12,17:18.14
14,-12,17:18.14
15,-12,17:18.14
10,-11,17:18.14
11,-11,17:18.14
12,-11,17:18.14
13,-11,17:18.14
14,-11,17:18.14
15,-11,17:18.14
9,-10,17:18.14
10,-10,17:18.14
14,-10,17:18.14
15,-10,17:18.14
7,-9,17:18.14
8,-9,17:18.14
9,-9,17:18.14
10,-9,17:18.14
14,-9,17:18.14
7,-8,17:18.14
8,-8,17:18.14
9,-8,17:18.14
10,-8,17:17.0
11,-8,17:17.0
13,-8,17:18.14
14,-8,17:18.14
7,-7,17:18.14
8,-7,17:18.14
9,-7,17:18.14
13,-7,17:18.14
7,-6,17:18.14
6,-5,17:18.14
7,-5,17:18.14
12,-5,17:18.14
7,-4,17:18.14
10,-4,17:18.14
11,-4,17:18.14
12,-4,17:18.14
7,-3,17:18.6
8,-3,17:18.6
9,-3,17:18.6
10,-3,17:18.6
11,-3,17:18.6
8,-2,17:18.6
12,-11,18:18.14
13,-11,18:18.14
10,-10,18:18.14
11,-10,18:18.14
12,-10,18:18.14
13,-10,18:18.14
10,-9,18:18.14
11,-9,18:18.14
12,-9,18:18.14
13,-9,18:18.14
7,-8,18:18.14
8,-8,18:18.14
9,-8,18:18.14
10,-8,18:17.0
11,-8,18:17.0
12,-8,18:18.14
13,-8,18:18.14
7,-7,18:18.14
8,-7,18:18.14
12,-7,18:18.14
13,-7,18:18.14
8,-6,18:18.14
9,-6,18:18.14
11,-6,18:18.14
12,-6,18:18.14
8,-5,18:18.14
9,-5,18:18.14
10,-5,18:18.14
11,-5,18:18.14
8,-4,18:18.14
9,-4,18:18.14
10,-4,18:18.14
8,-3,18:18.6
9,-3,18:18.6
12,-12,19:18.14
8,-11,19:18.14
12,-11,19:18.14
7,-10,19:18.14
8,-10,19:18.14
9,-10,19:18.14
7,-9,19:18.14
10,-9,19:18.14
11,-9,19:18.14
12,-9,19:18.14
7,-8,19:18.14
9,-8,19:18.14
10,-8,19:17.0
11,-8,19:18.14
12,-8,19:18.14
7,-7,19:18.14
8,-7,19:18.14
9,-7,19:18.14
10,-7,19:18.14
11,-7,19:18.14
9,-6,19:18.14
10,-6,19:18.14
11,-6,19:18.14
9,-5,19:18.14
10,-13,20:18.6
9,-12,20:18.6
10,-12,20:18.6
11,-12,20:18.6
8,-11,20:18.6
9,-11,20:18.6
10,-11,20:18.6
11,-11,20:18.6
12,-11,20:18.6
8,-10,20:18.6
9,-10,20:18.6
10,-10,20:18.6
11,-10,20:18.6
12,-10,20:18.6
7,-9,20:18.6
8,-9,20:18.6
9,-9,20:18.6
10,-9,20:18.6
12,-9,20:18.6
7,-8,20:18.6
8,-8,20:18.6
9,-8,20:18.6
10,-8,20:17.0
11,-8,20:17.0
8,-7,20:18.6
9,-7,20:18.6
10,-7,20:18.6
9,-6,20:18.6
12,-6,20:18.6
9,-5,20:18.6
10,-5,20:18.6
11,-5,20:18.6
12,-5,20:18.6
10,-4,20:18.6
10,-11,21:18.6
9,-10,21:18.6
10,-10,21:18.6
11,-10,21:18.6
9,-9,21:18.6
10,-9,21:18.6
11,-9,21:18.6
12,-9,21:18.6
9,-8,21:18.6
10,-8,21:18.6
11,-8,21:18.6
12,-8,21:18.6
9,-7,21:18.6
10,-7,21:18.6
11,-7,21:18.6
12,-7,21:18.6
9,-6,21:18.6
10,-6,21:18.6
11,-6,21:18.6
10,-5,21:18.6
11,-5,21:18.6
10,-9,22:18.6
10,-8,22:18.6
11,-8,22:18.6
7,-7,22:18.6
10,-7,22:18.6
9,-5,22:18.6
10,-5,22:18.6
9,-9,23:18.6
8,-8,23:18.6
9,-8,23:18.6
10,-8,23:17.0
11,-8,23:17.0
8,-7,23:18.6
9,-7,23:18.6
10,-7,23:18.6
11,-7,23:18.6
7,-6,23:18.6
8,-6,23:18.6
9,-6,23:18.6
10,-6,23:18.6
11,-6,23:18.6
11,-11,24:18.6
12,-11,24:18.6
13,-11,24:18.6
10,-10,24:18.6
11,-10,24:18.6
12,-10,24:18.6
13,-10,24:18.6
12,-9,24:18.6
13,-9,24:18.6
10,-8,24:18.6
11,-8,24:17.0
12,-8,24:18.6
13,-8,24:18.6
9,-7,24:18.6
10,-7,24:18.6
11,-10,25:18.6
12,-10,25:18.6
10,-9,25:18.6
11,-9,25:18.6
12,-9,25:18.6
10,-8,25:17.0
11,-8,25:18.6
12,-8,25:18.6
10,-8,26:17.0
11,-8,26:17.0
12,-8,26:18.6
11,-7,26:18.6
12,-7,26:18.6
10,-8,27:17.0
11,-8,27:18.6
11,-7,27:18.6
12,-7,27:18.6
10,-10,28:18.6
9,-9,28:18.6
10,-9,28:18.6
11,-9,28:18.6
10,-8,28:18.6
11,-8,28:17.0
11,-8,29:17.0
11,-8,30:17.0
11,-8,31:17.0
