[META]
version=2.0
spawnOnBlockType=2
spawnSunlight=True
spawnDarkness=True
spawnWater=False
spawnLava=False
underFill=False
randomRotation=True
dig=True
tree=False
branch=False
needsFoundation=True
rarity=100
collisionPercentage=20
spawnElevationMin=0
spawnElevationMax=200
spawnInBiome=Custom
[DATA]
2,-7,-8:17.12
3,-6,-8:17.12
3,-8,-7:17.12
0,-7,-7:17.12
2,-7,-7:17.12
1,-6,-7:17.12
3,-6,-7:17.12
3,-5,-7:17.12
4,-5,-7:17.12
4,0,-7:17.12
3,1,-7:17.12
0,-8,-6:17.12
1,-8,-6:17.12
2,-8,-6:17.12
2,-7,-6:17.12
3,-7,-6:17.12
4,-7,-6:17.12
0,-6,-6:17.12
2,-6,-6:17.12
3,-6,-6:17.12
4,-6,-6:17.12
0,-5,-6:17.12
1,-5,-6:17.12
2,-5,-6:17.12
3,-5,-6:17.12
4,-5,-6:17.12
1,-4,-6:17.12
4,-2,-6:17.12
5,-2,-6:17.12
3,0,-6:17.12
5,0,-6:17.12
4,2,-6:17.12
5,2,-6:17.12
0,-9,-5:17.12
1,-9,-5:17.12
0,-8,-5:17.12
2,-8,-5:17.12
3,-8,-5:17.12
0,-7,-5:17.12
1,-7,-5:17.12
2,-7,-5:17.12
3,-7,-5:17.12
-1,-6,-5:17.12
0,-6,-5:17.12
1,-6,-5:17.12
2,-6,-5:17.12
3,-6,-5:17.12
4,-6,-5:17.12
3,-5,-5:17.12
4,-5,-5:17.12
3,-4,-5:17.12
3,-2,-5:17.12
4,-2,-5:17.12
5,-2,-5:17.12
2,-1,-5:17.12
5,-1,-5:17.12
6,-1,-5:17.12
2,0,-5:17.12
3,0,-5:17.12
4,0,-5:17.12
5,0,-5:17.12
6,0,-5:17.12
3,1,-5:17.12
4,1,-5:17.12
5,1,-5:17.12
5,2,-5:17.12
0,-9,-4:17.12
1,-9,-4:17.12
-1,-8,-4:17.12
2,-8,-4:17.12
3,-8,-4:17.12
0,-7,-4:17.12
1,-7,-4:17.12
2,-7,-4:17.12
3,-7,-4:17.12
-1,-6,-4:17.12
0,-6,-4:17.12
1,-6,-4:17.12
2,-6,-4:17.12
3,-6,-4:17.12
0,-5,-4:17.12
1,-5,-4:17.12
2,-5,-4:17.12
2,-4,-4:17.12
3,-2,-4:17.12
2,-1,-4:17.12
3,-1,-4:17.12
6,-1,-4:17.12
3,0,-4:17.12
4,0,-4:17.12
3,1,-4:17.12
4,1,-4:17.12
5,1,-4:17.12
-1,-8,-3:17.12
0,-8,-3:17.12
1,-8,-3:17.12
2,-8,-3:17.12
-1,-7,-3:17.12
0,-7,-3:17.12
1,-7,-3:17.12
3,-7,-3:17.12
-1,-6,-3:17.12
0,-6,-3:17.12
1,-6,-3:17.12
2,-6,-3:17.12
2,-4,-3:17.12
4,-2,-3:17.12
4,0,-3:17.12
3,1,-3:17.12
4,1,-3:17.12
5,1,-3:17.12
6,1,-3:17.12
0,-8,-2:17.12
1,-8,-2:17.12
2,-8,-2:17.12
3,-8,-2:17.12
-1,-7,-2:17.12
0,-7,-2:17.12
1,-7,-2:17.12
3,-7,-2:17.12
-1,-6,-2:17.12
0,-6,-2:17.12
1,-6,-2:17.12
2,-6,-2:17.12
3,-6,-2:17.12
0,-5,-2:17.12
1,-5,-2:17.12
2,-5,-2:17.12
3,-5,-2:17.12
1,-4,-2:17.12
2,-4,-2:17.12
4,-2,-2:17.12
2,-1,-2:17.12
5,-1,-2:17.12
3,0,-2:17.12
4,0,-2:17.12
6,0,-2:17.12
2,1,-2:17.12
4,1,-2:17.12
6,1,-2:17.12
3,2,-2:17.12
4,2,-2:17.12
0,-8,-1:17.12
1,-8,-1:17.12
2,-8,-1:17.12
3,-8,-1:17.12
0,-7,-1:17.12
3,-7,-1:17.12
0,-6,-1:17.12
3,-6,-1:17.12
0,-5,-1:17.12
1,-5,-1:17.12
2,-5,-1:17.12
3,-5,-1:17.12
1,-4,-1:17.12
4,-2,-1:17.12
5,-2,-1:17.12
2,-1,-1:17.12
3,-1,-1:17.12
4,-1,-1:17.12
5,-1,-1:17.12
6,-1,-1:17.12
2,0,-1:17.12
3,0,-1:17.12
4,0,-1:17.12
5,0,-1:17.12
2,1,-1:17.12
3,1,-1:17.12
4,1,-1:17.12
5,1,-1:17.12
6,1,-1:17.12
0,-8,0:17.12
1,-8,0:17.12
2,-8,0:17.12
0,-7,0:17.12
3,-7,0:17.12
0,-6,0:17.12
3,-6,0:17.12
0,-5,0:17.12
1,-5,0:17.12
2,-5,0:17.12
3,-5,0:17.12
2,-1,0:17.12
3,-1,0:17.12
4,-1,0:17.12
2,0,0:17.12
4,0,0:17.12
5,0,0:17.12
3,1,0:17.12
4,1,0:17.12
5,1,0:17.12
-5,-19,1:18.6
-5,-18,1:18.6
-4,-18,1:18.6
-4,-17,1:18.6
-3,-17,1:18.6
6,-15,1:18.6
7,-15,1:18.6
1,-8,1:17.12
2,-8,1:17.12
0,-7,1:17.12
2,-7,1:17.12
3,-7,1:17.12
0,-6,1:17.12
3,-6,1:17.12
0,-5,1:17.12
1,-5,1:17.12
2,-5,1:17.12
2,-1,1:17.12
3,-1,1:17.12
4,-1,1:17.12
2,0,1:17.12
5,0,1:17.12
3,1,1:17.12
4,1,1:17.12
-5,-19,2:18.6
-5,-18,2:18.6
-4,-18,2:18.6
-4,-17,2:18.6
-3,-17,2:18.6
-3,-16,2:18.6
-2,-16,2:18.6
6,-15,2:18.6
7,-15,2:18.6
0,-14,2:18.6
1,-14,2:18.6
5,-14,2:18.6
6,-14,2:18.6
0,-13,2:18.6
1,-13,2:18.6
2,-13,2:18.6
2,-12,2:18.14
3,-12,2:18.14
1,-8,2:17.12
2,-8,2:17.12
0,-7,2:17.12
2,-7,2:17.12
3,-7,2:17.12
0,-6,2:17.12
3,-6,2:17.12
1,-5,2:17.12
2,-5,2:17.12
2,-1,2:18.14
3,-1,2:17.12
4,-1,2:17.12
2,0,2:18.14
3,0,2:17.12
4,0,2:17.12
5,0,2:17.12
3,1,2:17.12
4,1,2:17.12
5,3,2:18.14
6,4,2:18.14
-4,-17,3:18.6
-4,-16,3:18.6
-3,-16,3:18.6
-2,-16,3:18.6
-2,-15,3:18.6
-1,-15,3:18.6
-1,-14,3:18.6
0,-14,3:18.6
5,-14,3:18.6
6,-14,3:18.6
0,-13,3:18.6
1,-13,3:18.6
2,-13,3:18.6
3,-13,3:18.6
4,-13,3:18.6
-1,-12,3:18.14
0,-12,3:18.14
1,-12,3:18.14
2,-12,3:18.14
3,-12,3:18.14
-1,-11,3:18.14
0,-11,3:18.14
1,-11,3:18.14
2,-11,3:18.14
3,-11,3:18.14
4,-11,3:18.14
1,-10,3:18.14
2,-10,3:18.14
3,-10,3:18.14
4,-10,3:18.14
1,-8,3:17.12
2,-8,3:17.12
0,-7,3:17.12
2,-7,3:17.12
3,-7,3:17.12
0,-6,3:17.12
2,-6,3:17.12
3,-6,3:17.12
1,-5,3:17.12
2,-5,3:17.12
3,-3,3:18.14
4,-3,3:18.14
5,-3,3:18.14
-1,-2,3:18.14
0,-2,3:18.14
1,-2,3:18.14
4,-2,3:18.14
5,-2,3:18.14
0,-1,3:18.14
1,-1,3:18.14
2,-1,3:18.14
3,-1,3:18.14
4,-1,3:17.12
1,0,3:18.14
2,0,3:18.14
3,0,3:17.12
4,0,3:17.12
5,0,3:17.12
2,1,3:18.14
3,1,3:18.14
4,1,3:17.12
4,2,3:18.14
5,3,3:18.14
6,3,3:18.14
6,4,3:18.14
-4,-17,4:18.6
-4,-16,4:18.6
-3,-16,4:18.6
-2,-15,4:18.6
-1,-15,4:18.6
-1,-14,4:18.6
0,-14,4:18.6
5,-14,4:18.6
6,-14,4:18.6
0,-13,4:18.6
1,-13,4:18.6
2,-13,4:18.6
3,-13,4:18.6
4,-13,4:18.6
5,-13,4:18.6
0,-12,4:18.14
1,-12,4:18.14
2,-12,4:18.14
-1,-11,4:18.14
0,-11,4:18.14
2,-11,4:18.14
3,-11,4:18.14
-3,-10,4:18.14
-2,-10,4:18.14
-1,-10,4:18.14
0,-10,4:18.14
1,-10,4:18.14
2,-10,4:18.14
3,-10,4:18.14
4,-10,4:18.14
5,-10,4:18.14
-4,-9,4:18.14
-3,-9,4:18.14
-2,-9,4:18.14
-1,-9,4:18.14
0,-9,4:18.14
1,-9,4:18.14
2,-9,4:18.14
3,-9,4:18.14
4,-9,4:18.14
5,-9,4:18.14
6,-9,4:18.14
0,-8,4:18.14
1,-8,4:17.12
2,-8,4:18.14
3,-8,4:18.14
4,-8,4:18.14
5,-8,4:18.14
6,-8,4:18.14
7,-8,4:18.14
0,-7,4:17.12
2,-7,4:17.12
3,-7,4:17.12
0,-6,4:17.12
2,-6,4:17.12
3,-6,4:17.12
1,-5,4:17.12
2,-5,4:17.12
5,-5,4:18.14
6,-5,4:18.14
7,-5,4:18.14
8,-5,4:18.14
-2,-4,4:18.14
-1,-4,4:18.14
0,-4,4:18.14
2,-4,4:18.14
3,-4,4:18.14
4,-4,4:18.14
5,-4,4:18.14
6,-4,4:18.14
7,-4,4:18.14
-2,-3,4:18.14
-1,-3,4:18.14
0,-3,4:18.14
1,-3,4:18.14
2,-3,4:18.14
3,-3,4:18.14
4,-3,4:18.14
5,-3,4:18.14
6,-3,4:18.14
-1,-2,4:18.14
0,-2,4:18.14
3,-2,4:18.14
4,-2,4:18.14
6,-2,4:18.14
7,-2,4:18.14
8,-2,4:18.14
9,-2,4:18.14
0,-1,4:18.14
1,-1,4:18.14
2,-1,4:18.14
3,-1,4:17.12
4,-1,4:17.12
9,-1,4:18.14
-1,0,4:18.14
0,0,4:18.14
1,0,4:18.14
2,0,4:18.14
3,0,4:17.12
4,0,4:17.12
3,1,4:18.14
4,1,4:17.12
1,2,4:18.14
4,2,4:18.14
5,2,4:18.14
2,3,4:18.14
3,3,4:18.14
5,3,4:18.14
6,3,4:18.14
5,4,4:18.14
5,5,4:18.14
-3,-15,5:18.6
-2,-15,5:18.6
-1,-14,5:18.6
-6,-13,5:18.6
0,-13,5:18.6
1,-13,5:18.6
3,-13,5:18.6
4,-13,5:18.6
5,-13,5:18.6
1,-12,5:18.14
2,-12,5:18.14
3,-12,5:18.14
-1,-11,5:18.14
0,-11,5:18.14
1,-11,5:18.14
2,-11,5:18.14
3,-11,5:18.14
13,-11,5:18.6
-2,-10,5:18.14
-1,-10,5:18.14
3,-10,5:18.14
4,-10,5:18.14
12,-10,5:18.6
-4,-9,5:18.14
-3,-9,5:18.14
-2,-9,5:18.14
4,-9,5:18.14
5,-9,5:18.14
-4,-8,5:18.14
-2,-8,5:18.14
-1,-8,5:18.14
0,-8,5:18.14
1,-8,5:17.12
2,-8,5:18.14
3,-8,5:18.14
4,-8,5:18.14
5,-8,5:18.14
6,-8,5:18.14
7,-8,5:18.14
-4,-7,5:18.14
-3,-7,5:18.14
-2,-7,5:18.14
-1,-7,5:18.14
0,-7,5:18.14
1,-7,5:18.14
2,-7,5:18.14
3,-7,5:18.14
4,-7,5:18.14
5,-7,5:18.14
6,-7,5:18.14
7,-7,5:18.14
8,-7,5:18.6
9,-7,5:18.6
-3,-6,5:18.14
-2,-6,5:18.14
-1,-6,5:18.14
0,-6,5:17.12
1,-6,5:18.14
2,-6,5:18.14
3,-6,5:18.14
4,-6,5:18.14
5,-6,5:18.14
6,-6,5:18.14
7,-6,5:18.14
8,-6,5:18.6
9,-6,5:18.6
-3,-5,5:18.14
-2,-5,5:18.14
-1,-5,5:18.14
0,-5,5:18.14
1,-5,5:17.12
2,-5,5:17.12
3,-5,5:18.14
4,-5,5:18.14
5,-5,5:18.14
6,-5,5:18.14
7,-5,5:18.14
8,-5,5:18.14
9,-5,5:18.6
-3,-4,5:18.14
-2,-4,5:18.14
-1,-4,5:18.14
0,-4,5:18.14
1,-4,5:18.14
2,-4,5:18.14
3,-4,5:18.14
4,-4,5:18.14
5,-4,5:18.14
6,-4,5:18.14
-2,-3,5:18.14
-1,-3,5:18.14
0,-3,5:18.14
1,-3,5:18.14
2,-3,5:18.14
3,-3,5:18.14
4,-3,5:18.14
5,-3,5:18.14
6,-3,5:18.14
9,-3,5:18.14
-1,-2,5:18.14
0,-2,5:18.14
1,-2,5:18.14
2,-2,5:18.14
3,-2,5:18.14
4,-2,5:18.14
5,-2,5:18.14
6,-2,5:18.14
7,-2,5:18.14
8,-2,5:18.14
9,-2,5:18.14
-1,-1,5:18.14
0,-1,5:18.14
1,-1,5:18.14
2,-1,5:18.14
3,-1,5:17.12
4,-1,5:17.12
6,-1,5:18.14
8,-1,5:18.14
9,-1,5:18.14
10,-1,5:18.14
-2,0,5:18.14
-1,0,5:18.14
1,0,5:18.14
2,0,5:18.14
3,0,5:17.12
4,0,5:17.12
6,0,5:18.14
10,0,5:18.14
1,1,5:18.14
3,1,5:18.14
4,1,5:18.14
6,1,5:18.14
0,2,5:18.14
1,2,5:18.14
2,2,5:18.14
3,2,5:18.14
4,2,5:18.14
5,2,5:18.14
6,2,5:18.14
7,2,5:18.14
1,3,5:18.14
5,3,5:18.14
6,3,5:18.14
7,3,5:18.14
2,4,5:18.14
5,4,5:18.14
-4,-16,6:18.6
-3,-15,6:18.6
-2,-15,6:18.6
-2,-14,6:18.6
-1,-14,6:18.6
-6,-13,6:18.6
-1,-13,6:18.6
0,-13,6:18.6
5,-13,6:18.6
6,-13,6:18.6
1,-12,6:18.14
2,-12,6:18.14
3,-12,6:18.14
4,-12,6:18.14
5,-12,6:18.14
13,-12,6:18.6
0,-11,6:18.14
1,-11,6:18.14
2,-11,6:18.14
12,-11,6:18.6
13,-11,6:18.6
-1,-10,6:18.14
0,-10,6:18.14
3,-10,6:18.14
11,-10,6:18.6
12,-10,6:18.6
-3,-9,6:18.14
-2,-9,6:18.14
4,-9,6:18.14
5,-9,6:18.14
10,-9,6:18.6
11,-9,6:18.6
-4,-8,6:18.14
1,-8,6:17.12
2,-8,6:17.12
5,-8,6:18.14
6,-8,6:18.14
9,-8,6:18.6
10,-8,6:18.6
-4,-7,6:18.14
0,-7,6:17.12
2,-7,6:17.12
6,-7,6:18.14
7,-7,6:18.14
8,-7,6:18.6
9,-7,6:18.6
-4,-6,6:18.14
-3,-6,6:18.14
-2,-6,6:18.14
0,-6,6:17.12
2,-6,6:17.12
7,-6,6:18.14
8,-6,6:18.6
-4,-5,6:18.14
-3,-5,6:18.14
1,-5,6:17.12
2,-5,6:17.12
5,-5,6:18.14
6,-5,6:18.14
7,-5,6:18.14
8,-5,6:18.14
-2,-4,6:18.14
2,-4,6:18.14
4,-4,6:18.14
5,-4,6:18.14
6,-4,6:18.14
8,-4,6:18.14
-1,-3,6:18.14
0,-3,6:18.14
1,-3,6:18.14
2,-3,6:18.14
3,-3,6:18.14
4,-3,6:18.14
6,-3,6:18.14
8,-3,6:18.14
9,-3,6:18.14
0,-2,6:18.14
1,-2,6:18.14
2,-2,6:18.14
3,-2,6:18.14
4,-2,6:18.14
5,-2,6:18.14
6,-2,6:18.14
7,-2,6:18.14
8,-2,6:18.14
9,-2,6:18.14
-2,-1,6:18.14
-1,-1,6:18.14
0,-1,6:18.14
1,-1,6:18.14
2,-1,6:18.14
3,-1,6:17.12
4,-1,6:17.12
5,-1,6:18.14
6,-1,6:18.14
7,-1,6:18.14
8,-1,6:18.14
9,-1,6:18.14
1,0,6:18.14
2,0,6:18.14
3,0,6:17.12
4,0,6:17.12
5,0,6:18.14
6,0,6:18.14
9,0,6:18.14
10,0,6:18.14
0,1,6:18.14
1,1,6:18.14
2,1,6:18.14
3,1,6:17.12
4,1,6:18.14
5,1,6:18.14
6,1,6:18.14
0,2,6:18.14
1,2,6:18.14
2,2,6:18.14
3,2,6:18.14
4,2,6:18.14
5,2,6:18.14
6,2,6:18.14
7,2,6:18.14
1,3,6:18.14
2,3,6:18.14
5,3,6:18.14
6,3,6:18.14
2,4,6:18.14
5,4,6:18.14
-3,-15,7:18.6
-2,-14,7:18.6
-1,-14,7:18.6
-1,-13,7:18.6
0,-13,7:18.6
-6,-12,7:18.6
0,-12,7:18.14
1,-12,7:18.14
3,-12,7:18.14
4,-12,7:18.14
5,-12,7:18.14
-5,-11,7:18.6
1,-11,7:18.14
2,-11,7:18.14
3,-11,7:18.14
12,-11,7:18.6
-5,-10,7:18.6
-1,-10,7:18.14
0,-10,7:18.14
2,-10,7:18.14
3,-10,7:18.14
11,-10,7:18.6
-5,-9,7:18.6
-2,-9,7:18.14
-1,-9,7:18.14
3,-9,7:18.14
4,-9,7:18.14
10,-9,7:18.6
-5,-8,7:18.6
-4,-8,7:18.14
-2,-8,7:18.14
1,-8,7:17.12
2,-8,7:17.12
5,-8,7:18.14
9,-8,7:18.6
-4,-7,7:18.14
0,-7,7:17.12
2,-7,7:17.12
6,-7,7:18.14
7,-7,7:18.14
8,-7,7:18.6
-4,-6,7:18.14
0,-6,7:17.12
2,-6,7:17.12
6,-6,7:18.14
7,-6,7:18.14
-4,-5,7:18.14
-3,-5,7:18.14
-2,-5,7:18.14
1,-5,7:17.12
2,-5,7:17.12
5,-5,7:18.14
6,-5,7:18.14
7,-5,7:18.14
8,-5,7:18.14
-2,-4,7:18.14
-1,-4,7:18.14
2,-4,7:18.14
4,-4,7:18.14
5,-4,7:18.14
7,-4,7:18.14
8,-4,7:18.14
-1,-3,7:18.14
0,-3,7:18.14
2,-3,7:18.14
3,-3,7:18.14
5,-3,7:18.14
6,-3,7:18.14
7,-3,7:18.14
8,-3,7:18.14
-1,-2,7:18.14
0,-2,7:18.14
1,-2,7:18.14
2,-2,7:18.14
3,-2,7:18.14
4,-2,7:18.14
5,-2,7:18.14
7,-2,7:18.14
8,-2,7:18.14
9,-2,7:18.14
-4,-1,7:18.6
-2,-1,7:18.14
-1,-1,7:18.14
0,-1,7:18.14
2,-1,7:18.14
3,-1,7:18.14
4,-1,7:18.14
5,-1,7:18.14
6,-1,7:18.14
7,-1,7:18.14
8,-1,7:18.14
9,-1,7:18.14
1,0,7:18.14
2,0,7:18.14
3,0,7:17.12
4,0,7:17.12
5,0,7:18.14
6,0,7:18.14
0,1,7:18.14
1,1,7:18.14
2,1,7:18.14
3,1,7:18.14
4,1,7:18.14
5,1,7:18.14
7,1,7:18.14
2,2,7:18.14
3,2,7:18.14
4,2,7:18.14
5,2,7:18.14
6,2,7:18.14
7,2,7:18.14
2,3,7:18.14
5,3,7:18.14
5,4,7:18.14
7,-18,8:18.6
8,-18,8:18.6
6,-17,8:18.6
-5,-16,8:18.6
-4,-16,8:18.6
-5,-15,8:18.6
-4,-15,8:18.6
-3,-15,8:18.6
-3,-14,8:18.6
-2,-14,8:18.6
-1,-13,8:18.6
0,-13,8:18.6
0,-12,8:18.14
4,-12,8:18.14
5,-12,8:18.14
6,-12,8:18.14
7,-12,8:18.6
-5,-11,8:18.6
1,-11,8:18.14
2,-11,8:18.14
3,-11,8:18.14
4,-11,8:18.14
-5,-10,8:18.6
0,-10,8:18.14
1,-10,8:18.14
2,-10,8:18.14
3,-10,8:18.14
10,-10,8:18.6
11,-10,8:18.6
-5,-9,8:18.6
-2,-9,8:18.14
-1,-9,8:18.14
3,-9,8:18.14
4,-9,8:18.14
9,-9,8:18.6
10,-9,8:18.6
-5,-8,8:18.6
-2,-8,8:18.14
1,-8,8:17.12
2,-8,8:17.12
4,-8,8:18.14
5,-8,8:18.14
8,-8,8:18.6
9,-8,8:18.6
-5,-7,8:18.6
-4,-7,8:18.14
-3,-7,8:18.14
0,-7,8:17.12
2,-7,8:17.12
5,-7,8:18.14
6,-7,8:18.14
7,-7,8:18.14
8,-7,8:18.6
-5,-6,8:18.6
-4,-6,8:18.14
-3,-6,8:18.14
0,-6,8:17.12
2,-6,8:17.12
6,-6,8:18.14
7,-6,8:18.14
-5,-5,8:18.6
-3,-5,8:18.14
-2,-5,8:18.14
1,-5,8:17.12
2,-5,8:17.12
5,-5,8:18.14
6,-5,8:18.14
7,-5,8:18.14
-1,-4,8:18.14
3,-4,8:18.14
4,-4,8:18.14
7,-4,8:18.14
0,-3,8:18.14
1,-3,8:18.14
2,-3,8:18.14
3,-3,8:18.14
7,-3,8:18.14
8,-3,8:18.14
-2,-2,8:18.14
-1,-2,8:18.14
0,-2,8:18.14
1,-2,8:18.14
2,-2,8:18.14
3,-2,8:18.14
5,-2,8:18.14
8,-2,8:18.14
-4,-1,8:18.6
0,-1,8:18.14
1,-1,8:18.14
2,-1,8:18.14
3,-1,8:18.14
4,-1,8:18.14
5,-1,8:18.14
6,-1,8:18.14
7,-1,8:18.14
1,0,8:18.14
2,0,8:18.14
3,0,8:18.14
4,0,8:17.12
5,0,8:18.14
6,0,8:18.14
0,1,8:18.14
1,1,8:18.14
2,1,8:18.14
3,1,8:18.14
4,1,8:18.14
5,1,8:18.14
6,1,8:18.14
7,1,8:18.14
2,2,8:18.14
4,2,8:18.14
5,2,8:18.14
6,2,8:18.14
7,2,8:18.14
5,3,8:18.14
7,3,8:18.14
7,-18,9:18.6
6,-17,9:18.6
7,-17,9:18.6
-5,-16,9:18.6
-4,-16,9:18.6
5,-16,9:18.6
6,-16,9:18.6
-5,-15,9:18.6
-4,-15,9:18.6
-3,-15,9:18.6
-4,-14,9:18.6
-3,-14,9:18.6
-2,-14,9:18.6
2,-14,9:18.6
-2,-13,9:18.6
-1,-13,9:18.6
1,-13,9:18.6
2,-13,9:18.6
-5,-12,9:18.6
-1,-12,9:18.14
0,-12,9:18.14
6,-12,9:18.14
7,-12,9:18.6
-5,-11,9:18.6
0,-11,9:18.14
1,-11,9:18.14
2,-11,9:18.14
3,-11,9:18.14
4,-11,9:18.14
5,-11,9:18.14
6,-11,9:18.14
11,-11,9:18.6
-5,-10,9:18.6
-4,-10,9:18.14
1,-10,9:18.14
2,-10,9:18.14
10,-10,9:18.6
-5,-9,9:18.6
-4,-9,9:18.14
-1,-9,9:18.14
0,-9,9:18.14
2,-9,9:18.14
3,-9,9:18.14
9,-9,9:18.6
-5,-8,9:18.6
-4,-8,9:18.14
-2,-8,9:18.14
-1,-8,9:18.14
1,-8,9:17.12
2,-8,9:17.12
4,-8,9:18.14
8,-8,9:18.6
9,-8,9:18.6
-4,-7,9:18.14
-3,-7,9:18.14
0,-7,9:17.12
2,-7,9:17.12
5,-7,9:18.14
6,-7,9:18.14
7,-7,9:18.6
8,-7,9:18.6
-5,-6,9:18.6
-4,-6,9:18.14
-3,-6,9:18.14
0,-6,9:17.12
2,-6,9:17.12
5,-6,9:18.14
6,-6,9:18.14
-5,-5,9:18.6
-2,-5,9:18.14
-1,-5,9:18.14
1,-5,9:17.12
2,-5,9:17.12
4,-5,9:18.14
5,-5,9:18.14
6,-5,9:18.14
-1,-4,9:18.14
0,-4,9:18.14
2,-4,9:18.14
3,-4,9:18.14
4,-4,9:18.14
6,-4,9:18.14
7,-4,9:18.14
0,-3,9:18.14
1,-3,9:18.14
2,-3,9:18.14
3,-3,9:18.14
4,-3,9:18.14
5,-3,9:18.14
6,-3,9:18.14
7,-3,9:18.14
-4,-2,9:18.14
-3,-2,9:18.14
-2,-2,9:18.14
-1,-2,9:18.14
0,-2,9:18.14
1,-2,9:18.14
2,-2,9:18.14
3,-2,9:18.14
4,-2,9:18.14
5,-2,9:18.14
7,-2,9:18.14
-5,-1,9:18.6
-4,-1,9:18.6
1,-1,9:18.14
2,-1,9:18.14
3,-1,9:18.14
4,-1,9:18.14
5,-1,9:18.14
6,-1,9:18.14
7,-1,9:18.14
1,0,9:18.14
2,0,9:18.14
3,0,9:18.14
4,0,9:18.14
5,0,9:18.14
6,0,9:18.14
0,1,9:18.14
1,1,9:18.14
2,1,9:18.14
3,1,9:18.14
4,1,9:18.14
5,1,9:18.14
6,1,9:18.14
3,2,9:18.14
4,2,9:18.14
6,2,9:18.14
7,2,9:18.14
2,3,9:18.14
3,3,9:18.14
4,3,9:18.14
7,3,9:18.14
5,4,9:18.14
6,-17,10:18.6
5,-16,10:18.6
6,-16,10:18.6
-4,-15,10:18.6
4,-15,10:18.6
5,-15,10:18.6
-4,-14,10:18.6
-3,-14,10:18.6
-2,-14,10:18.6
2,-14,10:18.6
3,-14,10:18.6
-2,-13,10:18.6
-1,-13,10:18.6
0,-13,10:18.6
1,-13,10:18.6
2,-13,10:18.6
-4,-12,10:18.6
-1,-12,10:18.14
0,-12,10:18.14
1,-12,10:18.14
2,-12,10:18.14
3,-12,10:18.14
-5,-11,10:18.6
-4,-11,10:18.14
0,-11,10:18.14
1,-11,10:18.14
3,-11,10:18.14
4,-11,10:18.14
5,-11,10:18.14
6,-11,10:18.14
-5,-10,10:18.6
-4,-10,10:18.14
1,-10,10:18.14
2,-10,10:18.14
3,-10,10:18.14
4,-10,10:18.14
9,-10,10:18.6
-4,-9,10:18.14
0,-9,10:18.14
1,-9,10:18.14
2,-9,10:18.14
3,-9,10:18.14
8,-9,10:18.6
9,-9,10:18.6
-4,-8,10:18.14
-2,-8,10:18.14
-1,-8,10:18.14
1,-8,10:17.12
2,-8,10:17.12
3,-8,10:18.14
4,-8,10:18.14
7,-8,10:18.6
8,-8,10:18.6
-4,-7,10:18.14
-3,-7,10:18.14
-2,-7,10:18.14
0,-7,10:17.12
2,-7,10:17.12
5,-7,10:18.14
6,-7,10:18.14
7,-7,10:18.6
-5,-6,10:18.6
-4,-6,10:18.14
-3,-6,10:18.14
-2,-6,10:18.14
0,-6,10:17.12
2,-6,10:17.12
5,-6,10:18.14
6,-6,10:18.14
-6,-5,10:18.6
-5,-5,10:18.6
-4,-5,10:18.14
-1,-5,10:18.14
1,-5,10:17.12
2,-5,10:17.12
3,-5,10:18.14
4,-5,10:18.14
5,-5,10:18.14
6,-5,10:18.14
-6,-4,10:18.6
0,-4,10:18.14
2,-4,10:18.14
3,-4,10:18.14
6,-4,10:18.14
-6,-3,10:18.6
-1,-3,10:18.14
0,-3,10:18.14
1,-3,10:18.14
2,-3,10:18.14
3,-3,10:18.14
4,-3,10:18.14
5,-3,10:18.14
6,-3,10:18.14
-4,-2,10:18.14
-3,-2,10:18.14
-2,-2,10:18.14
-1,-2,10:18.14
0,-2,10:18.14
2,-2,10:18.14
3,-2,10:18.14
4,-2,10:18.14
0,-1,10:18.14
1,-1,10:18.14
2,-1,10:18.14
3,-1,10:18.14
4,-1,10:18.14
5,-1,10:18.14
6,-1,10:18.14
0,0,10:18.14
1,0,10:18.14
2,0,10:18.14
3,0,10:18.14
4,0,10:18.14
5,0,10:18.14
6,0,10:18.14
-1,1,10:18.14
1,1,10:18.14
2,1,10:18.14
3,1,10:18.14
4,1,10:18.14
5,1,10:18.14
6,1,10:18.14
-2,2,10:18.6
3,2,10:18.14
4,2,10:18.14
6,2,10:18.14
-3,3,10:18.6
2,3,10:18.14
3,3,10:18.14
4,3,10:18.14
5,3,10:18.14
5,-16,11:18.6
6,-16,11:18.6
4,-15,11:18.6
5,-15,11:18.6
-3,-14,11:18.6
3,-14,11:18.6
-4,-13,11:18.6
-3,-13,11:18.6
-2,-13,11:18.6
-1,-13,11:18.6
0,-13,11:18.6
1,-13,11:18.6
2,-13,11:18.6
-4,-12,11:18.6
-1,-12,11:18.14
0,-12,11:18.14
1,-12,11:18.14
2,-12,11:18.14
11,-12,11:18.6
-4,-11,11:18.14
-1,-11,11:18.14
0,-11,11:18.14
3,-11,11:18.14
-4,-10,11:18.14
-1,-10,11:18.14
1,-10,11:18.14
2,-10,11:18.14
3,-10,11:18.14
4,-10,11:18.14
9,-10,11:18.6
10,-10,11:18.6
-4,-9,11:18.14
0,-9,11:18.14
1,-9,11:18.14
2,-9,11:18.14
5,-9,11:18.14
6,-9,11:18.14
8,-9,11:18.6
9,-9,11:18.6
-4,-8,11:18.14
-1,-8,11:18.14
0,-8,11:18.14
1,-8,11:17.12
2,-8,11:17.12
3,-8,11:18.14
7,-8,11:18.6
8,-8,11:18.6
-3,-7,11:18.14
-2,-7,11:18.14
0,-7,11:17.12
1,-7,11:17.12
2,-7,11:17.12
4,-7,11:18.14
5,-7,11:18.14
6,-7,11:18.14
7,-7,11:18.6
-4,-6,11:18.14
-3,-6,11:18.14
-2,-6,11:18.14
0,-6,11:17.12
2,-6,11:17.12
4,-6,11:18.14
5,-6,11:18.14
-5,-5,11:18.6
-4,-5,11:18.14
-1,-5,11:18.14
0,-5,11:18.14
1,-5,11:17.12
2,-5,11:17.12
3,-5,11:18.14
4,-5,11:18.14
5,-5,11:18.14
7,-5,11:18.6
-6,-4,11:18.6
-5,-4,11:18.6
0,-4,11:18.14
1,-4,11:18.14
2,-4,11:18.14
3,-4,11:18.14
5,-4,11:18.14
-6,-3,11:18.6
0,-3,11:18.14
1,-3,11:18.14
2,-3,11:18.14
3,-3,11:18.14
4,-3,11:18.14
5,-3,11:18.14
6,-3,11:18.14
0,-2,11:18.14
2,-2,11:18.14
3,-2,11:18.14
4,-2,11:18.14
5,-2,11:18.14
6,-2,11:18.14
1,-1,11:18.14
2,-1,11:18.14
3,-1,11:18.14
4,-1,11:18.14
6,-1,11:18.14
0,0,11:18.14
1,0,11:18.14
2,0,11:18.14
3,0,11:18.14
4,0,11:18.14
5,0,11:18.14
6,0,11:18.14
-2,1,11:18.6
-1,1,11:18.14
3,1,11:18.14
4,1,11:18.14
5,1,11:18.14
6,1,11:18.14
-3,2,11:18.6
-2,2,11:18.6
3,2,11:18.14
4,2,11:18.14
-4,3,11:18.6
-3,3,11:18.6
2,3,11:18.14
4,3,11:18.14
5,-15,12:18.6
-4,-14,12:18.6
-3,-14,12:18.6
3,-14,12:18.6
-3,-13,12:18.6
-2,-13,12:18.6
-1,-13,12:18.6
2,-13,12:18.6
3,-13,12:18.6
-4,-12,12:18.6
-2,-12,12:18.14
-1,-12,12:18.14
0,-12,12:18.14
1,-12,12:18.14
2,-12,12:18.14
-4,-11,12:18.14
0,-11,12:18.14
1,-11,12:18.14
2,-11,12:18.14
3,-11,12:18.14
9,-11,12:18.6
-4,-10,12:18.14
-3,-10,12:18.14
-2,-10,12:18.14
-1,-10,12:18.14
0,-10,12:18.14
1,-10,12:18.14
3,-10,12:18.14
4,-10,12:18.14
5,-10,12:18.14
6,-10,12:18.14
9,-10,12:18.6
-4,-9,12:18.14
-3,-9,12:18.14
-2,-9,12:18.14
1,-9,12:18.14
2,-9,12:18.14
3,-9,12:18.14
5,-9,12:18.14
6,-9,12:18.14
8,-9,12:18.6
-4,-8,12:18.14
-1,-8,12:18.14
0,-8,12:18.14
1,-8,12:17.12
2,-8,12:18.14
3,-8,12:18.14
6,-8,12:18.14
7,-8,12:18.6
-3,-7,12:18.14
-2,-7,12:18.14
-1,-7,12:18.14
0,-7,12:17.12
1,-7,12:17.12
2,-7,12:17.12
3,-7,12:18.14
4,-7,12:18.14
5,-7,12:18.14
6,-7,12:18.14
7,-7,12:18.6
8,-7,12:18.6
-5,-6,12:18.6
-4,-6,12:18.14
-3,-6,12:18.14
-2,-6,12:18.14
-1,-6,12:18.14
0,-6,12:17.12
2,-6,12:17.12
4,-6,12:18.14
5,-6,12:18.14
7,-6,12:18.6
8,-6,12:18.6
9,-6,12:18.6
-5,-5,12:18.6
-4,-5,12:18.14
-3,-5,12:18.14
-1,-5,12:18.14
0,-5,12:18.14
1,-5,12:17.12
2,-5,12:17.12
3,-5,12:18.14
4,-5,12:18.14
5,-5,12:18.14
6,-5,12:18.14
-6,-4,12:18.6
-5,-4,12:18.6
-3,-4,12:18.14
-2,-4,12:18.14
-1,-4,12:18.14
0,-4,12:18.14
1,-4,12:18.14
2,-4,12:18.14
4,-4,12:18.14
5,-4,12:18.14
-6,-3,12:18.6
-4,-3,12:18.14
-2,-3,12:18.14
-1,-3,12:18.14
2,-3,12:18.14
3,-3,12:18.14
4,-3,12:18.14
5,-3,12:18.14
11,-3,12:18.6
12,-3,12:18.6
0,-2,12:18.14
1,-2,12:18.14
2,-2,12:18.14
3,-2,12:18.14
4,-2,12:18.14
5,-2,12:18.14
12,-2,12:18.6
1,-1,12:18.14
2,-1,12:18.14
3,-1,12:18.14
4,-1,12:18.14
5,-1,12:18.14
6,-1,12:18.14
-1,0,12:18.14
0,0,12:18.14
2,0,12:18.14
3,0,12:18.14
4,0,12:18.14
5,0,12:18.14
-2,1,12:18.6
-1,1,12:18.14
1,1,12:18.14
2,1,12:18.14
3,1,12:18.14
4,1,12:18.14
5,1,12:18.14
6,1,12:18.14
-3,2,12:18.6
-2,2,12:18.6
2,2,12:18.14
3,2,12:18.14
4,2,12:18.14
6,-16,13:18.6
5,-15,13:18.6
6,-15,13:18.6
-4,-14,13:18.6
-4,-13,13:18.6
-3,-13,13:18.6
-2,-13,13:18.6
2,-13,13:18.6
3,-13,13:18.6
9,-13,13:18.6
-3,-12,13:18.14
-2,-12,13:18.14
-1,-12,13:18.14
0,-12,13:18.14
1,-12,13:18.14
2,-12,13:18.14
9,-12,13:18.6
-1,-11,13:18.14
0,-11,13:18.14
1,-11,13:18.14
2,-11,13:18.14
3,-11,13:18.14
9,-11,13:18.6
-1,-10,13:18.14
0,-10,13:18.14
3,-10,13:18.14
4,-10,13:18.14
5,-10,13:18.14
8,-10,13:18.6
9,-10,13:18.6
-3,-9,13:18.14
-2,-9,13:18.14
1,-9,13:18.14
2,-9,13:18.14
3,-9,13:18.14
4,-9,13:18.14
5,-9,13:18.14
7,-9,13:18.6
8,-9,13:18.6
-4,-8,13:18.14
-2,-8,13:18.14
0,-8,13:18.14
1,-8,13:17.12
2,-8,13:18.14
3,-8,13:18.14
6,-8,13:18.14
7,-8,13:18.6
8,-8,13:18.6
-6,-7,13:18.6
-5,-7,13:18.6
-4,-7,13:18.14
-2,-7,13:18.14
-1,-7,13:18.14
0,-7,13:17.12
1,-7,13:17.12
2,-7,13:17.12
3,-7,13:18.14
4,-7,13:18.14
5,-7,13:18.14
7,-7,13:18.6
8,-7,13:18.6
-6,-6,13:18.6
-5,-6,13:18.6
-4,-6,13:18.14
-3,-6,13:18.14
-2,-6,13:18.14
-1,-6,13:18.14
0,-6,13:17.12
2,-6,13:17.12
3,-6,13:18.14
4,-6,13:18.14
6,-6,13:18.14
7,-6,13:18.6
8,-6,13:18.6
-4,-5,13:18.14
-3,-5,13:18.14
0,-5,13:18.14
1,-5,13:17.12
2,-5,13:18.14
3,-5,13:18.14
4,-5,13:18.14
5,-5,13:18.14
6,-5,13:18.14
9,-5,13:18.6
10,-5,13:18.6
-6,-4,13:18.6
-5,-4,13:18.6
-4,-4,13:18.14
-3,-4,13:18.14
-2,-4,13:18.14
-1,-4,13:18.14
0,-4,13:18.14
1,-4,13:18.14
2,-4,13:18.14
4,-4,13:18.14
5,-4,13:18.14
10,-4,13:18.6
11,-4,13:18.6
-6,-3,13:18.6
-5,-3,13:18.6
-4,-3,13:18.14
-1,-3,13:18.14
0,-3,13:18.14
2,-3,13:18.14
3,-3,13:18.14
4,-3,13:18.14
11,-3,13:18.6
12,-3,13:18.6
-6,-2,13:18.6
0,-2,13:18.14
1,-2,13:18.14
2,-2,13:18.14
3,-2,13:18.14
4,-2,13:18.14
5,-2,13:18.14
12,-2,13:18.6
-6,-1,13:18.6
0,-1,13:18.14
1,-1,13:18.14
2,-1,13:18.14
3,-1,13:18.14
4,-1,13:18.14
5,-1,13:18.14
6,-1,13:18.14
12,-1,13:18.6
13,-1,13:18.6
-6,0,13:18.6
-1,0,13:18.14
0,0,13:18.14
2,0,13:18.14
3,0,13:18.14
4,0,13:18.14
5,0,13:18.14
6,0,13:18.14
-2,1,13:18.6
-1,1,13:18.14
1,1,13:18.14
2,1,13:18.14
3,1,13:18.14
4,1,13:18.14
5,1,13:18.14
6,1,13:18.14
-4,2,13:18.6
-3,2,13:18.6
2,2,13:18.14
3,2,13:18.14
4,2,13:18.14
5,-15,14:18.6
6,-15,14:18.6
5,-14,14:18.6
3,-13,14:18.6
4,-13,14:18.6
-3,-12,14:18.14
-2,-12,14:18.14
-1,-12,14:18.14
0,-12,14:18.14
2,-12,14:18.14
-3,-11,14:18.14
-1,-11,14:18.14
0,-11,14:18.14
1,-11,14:18.14
2,-11,14:18.14
8,-11,14:18.6
9,-11,14:18.6
-7,-10,14:18.6
-3,-10,14:18.14
-1,-10,14:18.14
0,-10,14:18.14
2,-10,14:18.14
3,-10,14:18.14
8,-10,14:18.6
-7,-9,14:18.6
-3,-9,14:18.14
-2,-9,14:18.14
-1,-9,14:18.14
0,-9,14:18.14
1,-9,14:18.14
2,-9,14:18.14
3,-9,14:18.14
4,-9,14:18.14
5,-9,14:18.14
7,-9,14:18.6
8,-9,14:18.6
-7,-8,14:18.6
-6,-8,14:18.6
-2,-8,14:18.14
0,-8,14:18.14
1,-8,14:18.14
2,-8,14:18.14
5,-8,14:18.14
6,-8,14:18.14
7,-8,14:18.6
-6,-7,14:18.6
-5,-7,14:18.6
-4,-7,14:18.14
-2,-7,14:18.14
-1,-7,14:18.14
0,-7,14:18.14
1,-7,14:17.12
2,-7,14:17.12
3,-7,14:18.14
4,-7,14:18.14
5,-7,14:18.14
6,-7,14:18.14
7,-7,14:18.6
-5,-6,14:18.6
-4,-6,14:18.14
-3,-6,14:18.14
-2,-6,14:18.14
-1,-6,14:18.14
0,-6,14:18.14
2,-6,14:17.12
3,-6,14:18.14
4,-6,14:18.14
6,-6,14:18.14
7,-6,14:18.6
8,-6,14:18.6
-5,-5,14:18.6
-4,-5,14:18.14
-3,-5,14:18.14
-2,-5,14:18.14
0,-5,14:18.14
1,-5,14:18.14
2,-5,14:18.14
3,-5,14:18.14
4,-5,14:18.14
5,-5,14:18.14
9,-5,14:18.6
10,-5,14:18.6
-6,-4,14:18.6
-5,-4,14:18.6
-4,-4,14:18.14
-2,-4,14:18.14
-1,-4,14:18.14
0,-4,14:18.14
1,-4,14:18.14
2,-4,14:18.14
3,-4,14:18.14
4,-4,14:18.14
10,-4,14:18.6
-6,-3,14:18.6
-5,-3,14:18.6
-1,-3,14:18.14
0,-3,14:18.14
2,-3,14:18.14
3,-3,14:18.14
4,-3,14:18.14
11,-3,14:18.6
-7,-2,14:18.6
-6,-2,14:18.6
-5,-2,14:18.6
1,-2,14:18.14
2,-2,14:18.14
3,-2,14:18.14
4,-2,14:18.14
11,-2,14:18.6
12,-2,14:18.6
-6,-1,14:18.6
0,-1,14:18.14
1,-1,14:18.14
2,-1,14:18.14
3,-1,14:18.14
4,-1,14:18.14
5,-1,14:18.14
6,-1,14:18.14
-1,0,14:18.14
0,0,14:18.14
2,0,14:18.14
3,0,14:17.12
4,0,14:17.12
5,0,14:18.14
-3,1,14:18.6
-2,1,14:18.6
2,1,14:18.14
3,1,14:18.14
4,1,14:18.14
5,1,14:18.14
6,1,14:18.14
-4,2,14:18.6
-3,2,14:18.6
3,2,14:18.14
4,2,14:18.14
5,2,14:18.14
7,-16,15:18.6
6,-15,15:18.6
5,-14,15:18.6
3,-13,15:18.6
4,-13,15:18.6
-5,-12,15:18.6
-4,-12,15:18.6
-3,-12,15:18.14
-2,-12,15:18.14
2,-12,15:18.14
3,-12,15:18.14
-8,-11,15:18.6
-2,-11,15:18.14
-1,-11,15:18.14
0,-11,15:18.14
1,-11,15:18.14
2,-11,15:18.14
8,-11,15:18.6
-8,-10,15:18.6
-7,-10,15:18.6
-1,-10,15:18.14
0,-10,15:18.14
1,-10,15:18.14
2,-10,15:18.14
3,-10,15:18.14
7,-10,15:18.6
-7,-9,15:18.6
-6,-9,15:18.6
-2,-9,15:18.14
-1,-9,15:18.14
0,-9,15:18.14
1,-9,15:18.14
3,-9,15:18.14
4,-9,15:18.14
6,-9,15:18.14
7,-9,15:18.6
-6,-8,15:18.6
-2,-8,15:18.14
-1,-8,15:18.14
1,-8,15:18.14
2,-8,15:18.14
3,-8,15:18.14
4,-8,15:18.14
5,-8,15:18.14
6,-8,15:18.14
7,-8,15:18.6
-5,-7,15:18.6
-4,-7,15:18.14
-3,-7,15:18.14
-1,-7,15:18.14
0,-7,15:18.14
1,-7,15:18.14
2,-7,15:17.12
3,-7,15:18.14
4,-7,15:18.14
6,-7,15:18.14
7,-7,15:18.6
-5,-6,15:18.6
-4,-6,15:18.14
-3,-6,15:18.14
-2,-6,15:18.14
-1,-6,15:18.14
0,-6,15:18.14
1,-6,15:18.14
2,-6,15:17.12
3,-6,15:18.14
5,-6,15:18.14
6,-6,15:18.14
7,-6,15:18.6
8,-6,15:18.6
-5,-5,15:18.6
-3,-5,15:18.14
-2,-5,15:18.14
-1,-5,15:18.14
0,-5,15:18.14
1,-5,15:18.14
2,-5,15:18.14
3,-5,15:18.14
4,-5,15:18.14
5,-5,15:18.14
8,-5,15:18.6
9,-5,15:18.6
-5,-4,15:18.6
-4,-4,15:18.14
-3,-4,15:18.14
-1,-4,15:18.14
0,-4,15:18.14
2,-4,15:18.14
3,-4,15:18.14
4,-4,15:18.14
9,-4,15:18.6
10,-4,15:18.6
-5,-3,15:18.6
0,-3,15:18.14
1,-3,15:18.14
2,-3,15:18.14
3,-3,15:18.14
10,-3,15:18.6
-5,-2,15:18.6
0,-2,15:18.14
1,-2,15:18.14
2,-2,15:18.14
3,-2,15:18.14
4,-2,15:18.14
0,-1,15:18.14
2,-1,15:18.14
3,-1,15:18.14
4,-1,15:18.14
5,-1,15:18.14
6,-1,15:18.14
7,-1,15:18.14
-2,0,15:18.6
-1,0,15:18.14
3,0,15:18.14
4,0,15:18.14
-3,1,15:18.6
-2,1,15:18.6
2,1,15:18.14
3,1,15:18.14
4,1,15:18.14
5,1,15:18.14
-5,2,15:18.6
-4,2,15:18.6
4,2,15:18.14
-5,3,15:18.6
-4,3,15:18.6
7,-16,16:18.6
6,-15,16:18.6
7,-15,16:18.6
5,-14,16:18.6
6,-14,16:18.6
3,-13,16:18.6
4,-13,16:18.6
-5,-12,16:18.6
-4,-12,16:18.6
2,-12,16:18.14
3,-12,16:18.14
-8,-11,16:18.6
-7,-11,16:18.6
-4,-11,16:18.14
-3,-11,16:18.14
-2,-11,16:18.14
-1,-11,16:18.14
0,-11,16:18.14
1,-11,16:18.14
2,-11,16:18.14
7,-11,16:18.6
-8,-10,16:18.6
-7,-10,16:18.6
-1,-10,16:18.14
0,-10,16:18.14
1,-10,16:18.14
2,-10,16:18.14
6,-10,16:18.14
7,-10,16:18.6
-7,-9,16:18.6
-6,-9,16:18.6
-2,-9,16:18.14
-1,-9,16:18.14
0,-9,16:18.14
3,-9,16:18.14
4,-9,16:18.14
6,-9,16:18.14
7,-9,16:18.6
-6,-8,16:18.6
-5,-8,16:18.6
-2,-8,16:18.14
-1,-8,16:18.14
1,-8,16:18.14
2,-8,16:18.14
3,-8,16:18.14
4,-8,16:18.14
5,-8,16:18.14
6,-8,16:18.14
-5,-7,16:18.6
-4,-7,16:18.14
-3,-7,16:18.14
-1,-7,16:18.14
0,-7,16:18.14
1,-7,16:18.14
2,-7,16:18.14
3,-7,16:18.14
4,-7,16:18.14
5,-7,16:18.14
6,-7,16:18.14
-4,-6,16:18.14
-3,-6,16:18.14
-2,-6,16:18.14
-1,-6,16:18.14
0,-6,16:18.14
1,-6,16:18.14
2,-6,16:18.14
3,-6,16:18.14
5,-6,16:18.14
6,-6,16:18.14
7,-6,16:18.6
8,-6,16:18.6
-5,-5,16:18.6
-4,-5,16:18.14
-3,-5,16:18.14
-2,-5,16:18.14
-1,-5,16:18.14
0,-5,16:18.14
1,-5,16:18.14
2,-5,16:18.14
3,-5,16:18.14
4,-5,16:18.14
8,-5,16:18.6
-5,-4,16:18.6
-4,-4,16:18.14
-3,-4,16:18.14
-1,-4,16:18.14
0,-4,16:18.14
2,-4,16:18.14
3,-4,16:18.14
9,-4,16:18.6
-5,-3,16:18.6
-4,-3,16:18.14
0,-3,16:18.14
1,-3,16:18.14
2,-3,16:18.14
3,-3,16:18.14
10,-3,16:18.6
-5,-2,16:18.6
0,-2,16:18.14
1,-2,16:18.14
3,-2,16:18.14
4,-2,16:18.14
5,-2,16:18.14
6,-2,16:18.14
-1,-1,16:18.14
0,-1,16:18.14
2,-1,16:18.14
3,-1,16:18.14
4,-1,16:18.14
6,-1,16:18.14
7,-1,16:18.14
-2,0,16:18.6
-1,0,16:18.14
2,0,16:18.14
3,0,16:18.14
4,0,16:18.14
5,0,16:18.14
-4,1,16:18.6
-3,1,16:18.6
-2,1,16:18.6
3,1,16:18.14
4,1,16:18.14
5,1,16:18.14
-5,2,16:18.6
-4,2,16:18.6
-5,3,16:18.6
-3,-16,17:18.6
-2,-15,17:18.6
6,-15,17:18.6
5,-14,17:18.6
6,-14,17:18.6
4,-13,17:18.6
5,-13,17:18.6
3,-12,17:18.14
-8,-11,17:18.6
-7,-11,17:18.6
-4,-11,17:18.14
-3,-11,17:18.14
-2,-11,17:18.14
-1,-11,17:18.14
2,-11,17:18.14
-7,-10,17:18.6
-1,-10,17:18.14
0,-10,17:18.14
1,-10,17:18.14
2,-10,17:18.14
6,-10,17:18.14
-6,-9,17:18.6
-1,-9,17:18.14
0,-9,17:18.14
2,-9,17:18.14
3,-9,17:18.14
6,-9,17:18.14
-5,-8,17:18.6
-2,-8,17:18.14
-1,-8,17:18.14
0,-8,17:18.14
1,-8,17:18.14
3,-8,17:18.14
4,-8,17:18.14
5,-8,17:18.14
6,-8,17:18.14
-4,-7,17:18.14
-3,-7,17:18.14
-2,-7,17:18.14
0,-7,17:18.14
1,-7,17:18.14
2,-7,17:18.14
3,-7,17:18.14
5,-7,17:18.14
6,-7,17:18.14
-4,-6,17:18.14
-3,-6,17:18.14
-2,-6,17:18.14
-1,-6,17:18.14
0,-6,17:18.14
1,-6,17:18.14
2,-6,17:18.14
5,-6,17:18.14
6,-6,17:18.14
7,-6,17:18.6
-4,-5,17:18.14
-2,-5,17:18.14
-1,-5,17:18.14
1,-5,17:17.12
2,-5,17:18.14
3,-5,17:18.14
4,-5,17:18.14
7,-5,17:18.6
8,-5,17:18.6
-4,-4,17:18.14
0,-4,17:18.14
1,-4,17:18.14
2,-4,17:18.14
3,-4,17:18.14
8,-4,17:18.14
9,-4,17:18.6
-5,-3,17:18.6
-4,-3,17:18.14
1,-3,17:18.14
2,-3,17:18.14
3,-3,17:18.14
4,-3,17:18.14
9,-3,17:18.6
10,-3,17:18.6
-5,-2,17:18.6
-4,-2,17:18.14
0,-2,17:18.14
4,-2,17:18.14
5,-2,17:18.14
6,-2,17:18.14
-1,-1,17:18.14
0,-1,17:18.14
1,-1,17:18.14
3,-1,17:18.14
4,-1,17:18.14
-3,0,17:18.6
-2,0,17:18.6
-1,0,17:18.14
2,0,17:18.14
3,0,17:18.14
4,0,17:18.14
5,0,17:18.14
-4,1,17:18.6
-3,1,17:18.6
3,1,17:18.14
4,1,17:18.14
-5,2,17:18.6
-4,2,17:18.6
5,2,17:18.14
-2,-15,18:18.6
-2,-14,18:18.6
-1,-14,18:18.6
0,-13,18:18.6
1,-13,18:18.6
3,-13,18:18.6
4,-13,18:18.6
5,-13,18:18.6
-8,-12,18:18.6
1,-12,18:18.14
2,-12,18:18.14
3,-12,18:18.14
6,-12,18:18.6
-8,-11,18:18.6
-7,-11,18:18.6
2,-11,18:18.14
3,-11,18:18.14
6,-11,18:18.14
-7,-10,18:18.6
-6,-10,18:18.6
-1,-10,18:18.14
0,-10,18:18.14
1,-10,18:18.14
2,-10,18:18.14
5,-10,18:18.14
6,-10,18:18.14
-6,-9,18:18.6
-5,-9,18:18.6
-1,-9,18:18.14
0,-9,18:18.14
1,-9,18:18.14
2,-9,18:18.14
3,-9,18:18.14
5,-9,18:18.14
-5,-8,18:18.6
-4,-8,18:18.14
-1,-8,18:18.14
0,-8,18:18.14
1,-8,18:17.12
3,-8,18:18.14
4,-8,18:18.14
5,-8,18:18.14
-4,-7,18:18.14
-3,-7,18:18.14
-2,-7,18:18.14
0,-7,18:17.12
1,-7,18:18.14
2,-7,18:18.14
3,-7,18:18.14
4,-7,18:18.14
5,-7,18:18.14
-3,-6,18:18.14
-2,-6,18:18.14
-1,-6,18:18.14
0,-6,18:18.14
1,-6,18:18.14
2,-6,18:17.12
4,-6,18:18.14
5,-6,18:18.14
6,-6,18:18.14
7,-6,18:18.6
-4,-5,18:18.14
-3,-5,18:18.14
-1,-5,18:18.14
0,-5,18:18.14
1,-5,18:17.12
2,-5,18:18.14
3,-5,18:18.14
7,-5,18:18.6
8,-5,18:18.6
-4,-4,18:18.14
-2,-4,18:18.14
0,-4,18:18.14
1,-4,18:18.14
2,-4,18:18.14
3,-4,18:18.14
8,-4,18:18.14
9,-4,18:18.6
-4,-3,18:18.14
0,-3,18:18.14
1,-3,18:18.14
2,-3,18:18.14
3,-3,18:18.14
4,-3,18:18.14
9,-3,18:18.6
-4,-2,18:18.14
0,-2,18:18.14
2,-2,18:18.14
10,-2,18:18.6
-4,-1,18:18.6
-2,-1,18:18.14
-1,-1,18:18.14
0,-1,18:18.14
1,-1,18:18.14
2,-1,18:18.14
11,-1,18:18.6
-4,0,18:18.6
-2,0,18:18.6
3,0,18:18.14
4,0,18:18.14
4,1,18:18.14
5,2,18:18.14
-2,-14,19:18.6
-1,-14,19:18.6
6,-14,19:18.6
-1,-13,19:18.6
0,-13,19:18.6
4,-13,19:18.6
5,-13,19:18.6
-8,-12,19:18.6
-7,-12,19:18.6
1,-12,19:18.14
2,-12,19:18.14
3,-12,19:18.14
4,-12,19:18.14
6,-12,19:18.6
-7,-11,19:18.6
0,-11,19:18.14
1,-11,19:18.14
2,-11,19:18.14
3,-11,19:18.14
5,-11,19:18.14
-6,-10,19:18.6
-3,-10,19:18.14
-2,-10,19:18.14
0,-10,19:18.14
2,-10,19:18.14
3,-10,19:18.14
5,-10,19:18.14
-5,-9,19:18.6
0,-9,19:18.14
1,-9,19:18.14
2,-9,19:18.14
4,-9,19:18.14
5,-9,19:18.14
-4,-8,19:18.14
-1,-8,19:18.14
0,-8,19:18.14
1,-8,19:17.12
2,-8,19:18.14
3,-8,19:18.14
4,-8,19:18.14
5,-8,19:18.14
-3,-7,19:18.14
-2,-7,19:18.14
-1,-7,19:18.14
0,-7,19:17.12
1,-7,19:17.12
2,-7,19:17.12
4,-7,19:18.14
5,-7,19:18.14
-3,-6,19:18.14
-2,-6,19:18.14
-1,-6,19:18.14
0,-6,19:17.12
1,-6,19:17.12
2,-6,19:17.12
3,-6,19:18.14
4,-6,19:18.14
5,-6,19:18.14
6,-6,19:18.14
-3,-5,19:18.14
-1,-5,19:18.14
0,-5,19:18.14
1,-5,19:17.12
2,-5,19:18.14
3,-5,19:18.14
6,-5,19:18.14
7,-5,19:18.6
-4,-4,19:18.14
-3,-4,19:18.14
1,-4,19:18.14
2,-4,19:18.14
3,-4,19:18.14
8,-4,19:18.6
-4,-3,19:18.14
0,-3,19:18.14
1,-3,19:18.14
3,-3,19:18.14
4,-3,19:18.14
5,-3,19:18.14
6,-3,19:18.14
9,-3,19:18.6
-4,-2,19:18.14
0,-2,19:18.14
1,-2,19:18.14
2,-2,19:18.14
9,-2,19:18.6
10,-2,19:18.6
-4,-1,19:18.6
-2,-1,19:18.14
-1,-1,19:18.14
0,-1,19:18.14
1,-1,19:18.14
2,-1,19:18.14
-4,0,19:18.6
-3,0,19:18.6
3,0,19:18.6
4,0,19:18.6
-4,1,19:18.6
4,1,19:18.6
5,1,19:18.6
-2,-14,20:18.6
-1,-14,20:18.6
6,-14,20:18.6
-1,-13,20:18.6
0,-13,20:18.6
5,-13,20:18.6
6,-13,20:18.6
0,-12,20:18.14
1,-12,20:18.14
2,-12,20:18.14
3,-12,20:18.14
4,-12,20:18.14
0,-11,20:18.14
1,-11,20:18.14
2,-11,20:18.14
3,-11,20:18.14
-3,-10,20:18.14
-2,-10,20:18.14
-1,-10,20:18.14
0,-10,20:18.14
2,-10,20:18.14
3,-10,20:18.14
-2,-9,20:18.14
-1,-9,20:18.14
0,-9,20:18.14
1,-9,20:18.14
2,-9,20:18.14
4,-9,20:18.14
-4,-8,20:18.14
0,-8,20:18.14
1,-8,20:17.12
2,-8,20:18.14
3,-8,20:18.14
4,-8,20:18.14
6,-8,20:18.14
-3,-7,20:18.14
-2,-7,20:18.14
-1,-7,20:18.14
0,-7,20:17.12
1,-7,20:17.12
2,-7,20:17.12
3,-7,20:18.14
4,-7,20:18.14
-2,-6,20:18.14
-1,-6,20:18.14
0,-6,20:17.12
1,-6,20:17.12
2,-6,20:17.12
3,-6,20:18.14
4,-6,20:18.14
5,-6,20:18.14
6,-6,20:18.14
-3,-5,20:18.14
-2,-5,20:18.14
0,-5,20:18.14
1,-5,20:18.14
2,-5,20:18.14
5,-5,20:18.14
6,-5,20:18.14
-1,-4,20:18.14
1,-4,20:18.14
2,-4,20:18.14
3,-4,20:18.14
4,-4,20:18.14
5,-4,20:18.14
-1,-3,20:18.14
0,-3,20:18.14
2,-3,20:18.14
3,-3,20:18.14
5,-3,20:18.14
6,-3,20:18.14
-1,-2,20:18.14
0,-2,20:18.14
1,-2,20:18.14
2,-2,20:18.14
-2,-1,20:18.14
-1,-1,20:18.14
2,-1,20:18.14
3,-1,20:18.14
-4,0,20:18.6
-3,0,20:18.6
3,0,20:18.6
4,0,20:18.6
-4,1,20:18.6
-2,-14,21:18.6
-1,-13,21:18.6
0,-13,21:18.6
-6,-12,21:18.6
0,-12,21:18.14
1,-12,21:18.14
3,-12,21:18.14
4,-12,21:18.14
5,-12,21:18.14
-6,-11,21:18.6
1,-11,21:18.14
2,-11,21:18.14
3,-11,21:18.14
4,-11,21:18.14
-5,-10,21:18.6
-1,-10,21:18.14
0,-10,21:18.14
2,-10,21:18.14
3,-10,21:18.14
4,-10,21:18.14
10,-10,21:18.6
-5,-9,21:18.6
-4,-9,21:18.14
-2,-9,21:18.14
-1,-9,21:18.14
0,-9,21:18.14
1,-9,21:18.14
2,-9,21:18.14
3,-9,21:18.14
4,-9,21:18.14
9,-9,21:18.6
10,-9,21:18.6
-2,-8,21:18.14
0,-8,21:18.14
1,-8,21:18.14
2,-8,21:18.14
3,-8,21:18.14
4,-8,21:18.14
5,-8,21:18.14
6,-8,21:18.14
-5,-7,21:18.6
-2,-7,21:18.14
-1,-7,21:18.14
0,-7,21:18.14
1,-7,21:17.12
2,-7,21:17.12
3,-7,21:18.14
4,-7,21:18.14
6,-7,21:18.14
7,-7,21:18.6
8,-7,21:18.6
-5,-6,21:18.6
-4,-6,21:18.14
-3,-6,21:18.14
-2,-6,21:18.14
-1,-6,21:18.14
0,-6,21:18.14
1,-6,21:17.12
2,-6,21:17.12
3,-6,21:18.14
4,-6,21:18.14
5,-6,21:18.14
6,-6,21:18.14
7,-6,21:18.6
-2,-5,21:18.14
0,-5,21:18.14
1,-5,21:18.14
2,-5,21:18.14
4,-5,21:18.14
5,-5,21:18.14
6,-5,21:18.14
-8,-4,21:18.6
-7,-4,21:18.6
-3,-4,21:18.14
-2,-4,21:18.14
-1,-4,21:18.14
0,-4,21:18.14
1,-4,21:18.14
2,-4,21:18.14
3,-4,21:18.14
4,-4,21:18.14
7,-4,21:18.6
8,-4,21:18.6
-8,-3,21:18.6
-1,-3,21:18.14
0,-3,21:18.14
1,-3,21:18.14
2,-3,21:18.14
3,-3,21:18.14
8,-3,21:18.6
-3,-2,21:18.14
-2,-2,21:18.14
-1,-2,21:18.14
0,-2,21:18.14
1,-2,21:18.14
2,-2,21:18.14
8,-2,21:18.6
9,-2,21:18.6
-2,-1,21:18.14
2,-1,21:18.14
3,-1,21:18.14
4,0,21:18.6
5,1,21:18.6
-2,-14,22:18.6
-2,-13,22:18.6
-1,-13,22:18.6
0,-12,22:18.14
4,-12,22:18.14
-5,-11,22:18.6
1,-11,22:18.14
2,-11,22:18.14
3,-11,22:18.14
4,-11,22:18.14
-5,-10,22:18.6
-4,-10,22:18.14
0,-10,22:18.14
1,-10,22:18.14
2,-10,22:18.14
3,-10,22:18.14
10,-10,22:18.6
-5,-9,22:18.6
-4,-9,22:18.14
-3,-9,22:18.14
-2,-9,22:18.14
-1,-9,22:18.14
2,-9,22:18.14
3,-9,22:18.14
4,-9,22:18.14
9,-9,22:18.6
-4,-8,22:18.14
-2,-8,22:18.14
-1,-8,22:18.14
0,-8,22:18.14
1,-8,22:18.14
2,-8,22:18.14
3,-8,22:18.14
4,-8,22:18.14
5,-8,22:18.14
8,-8,22:18.6
-5,-7,22:18.6
-4,-7,22:18.14
-3,-7,22:18.14
-2,-7,22:18.14
-1,-7,22:18.14
0,-7,22:18.14
1,-7,22:17.12
2,-7,22:17.12
3,-7,22:18.14
5,-7,22:18.14
6,-7,22:18.14
7,-7,22:18.6
-5,-6,22:18.6
-4,-6,22:18.14
-3,-6,22:18.14
-1,-6,22:18.14
0,-6,22:18.14
1,-6,22:17.12
2,-6,22:18.14
3,-6,22:18.14
4,-6,22:18.14
5,-6,22:18.14
6,-6,22:18.14
7,-6,22:18.6
-7,-5,22:18.6
-6,-5,22:18.6
-5,-5,22:18.6
-2,-5,22:18.14
-1,-5,22:18.14
1,-5,22:18.14
2,-5,22:18.14
3,-5,22:18.14
4,-5,22:18.14
5,-5,22:18.14
6,-5,22:18.14
7,-5,22:18.6
-8,-4,22:18.6
-7,-4,22:18.6
-6,-4,22:18.6
-2,-4,22:18.14
-1,-4,22:18.14
0,-4,22:18.14
1,-4,22:18.14
3,-4,22:18.14
4,-4,22:18.14
6,-4,22:18.14
7,-4,22:18.6
-8,-3,22:18.6
-7,-3,22:18.6
-2,-3,22:18.14
-1,-3,22:18.14
0,-3,22:18.14
1,-3,22:18.14
2,-3,22:18.14
7,-3,22:18.6
8,-3,22:18.6
-2,-2,22:18.14
-1,-2,22:18.14
0,-2,22:18.14
2,-2,22:18.14
3,-1,22:18.14
4,0,22:18.6
5,-15,23:18.6
-3,-14,23:18.6
-2,-13,23:18.6
-1,-13,23:18.6
-1,-12,23:18.14
0,-12,23:18.14
0,-11,23:18.14
1,-11,23:18.14
2,-11,23:18.14
3,-11,23:18.14
4,-11,23:18.14
5,-11,23:18.14
-4,-10,23:18.14
0,-10,23:18.14
1,-10,23:18.14
2,-10,23:18.14
3,-10,23:18.14
-4,-9,23:18.14
-3,-9,23:18.14
-1,-9,23:18.14
0,-9,23:18.14
2,-9,23:18.14
3,-9,23:18.14
8,-9,23:18.6
9,-9,23:18.6
-4,-8,23:18.14
-2,-8,23:18.14
-1,-8,23:18.14
0,-8,23:18.14
1,-8,23:18.14
2,-8,23:18.14
3,-8,23:18.14
4,-8,23:18.14
5,-8,23:18.14
7,-8,23:18.6
8,-8,23:18.6
-4,-7,23:18.14
-3,-7,23:18.14
-1,-7,23:18.14
0,-7,23:18.14
1,-7,23:17.12
2,-7,23:18.14
3,-7,23:18.14
5,-7,23:18.14
6,-7,23:18.14
7,-7,23:18.6
-5,-6,23:18.6
-4,-6,23:18.14
-3,-6,23:18.14
-2,-6,23:18.14
-1,-6,23:18.14
0,-6,23:18.14
1,-6,23:18.14
2,-6,23:18.14
3,-6,23:18.14
4,-6,23:18.14
5,-6,23:18.14
6,-6,23:18.14
-6,-5,23:18.6
-5,-5,23:18.6
-2,-5,23:18.14
-1,-5,23:18.14
0,-5,23:18.14
1,-5,23:18.14
2,-5,23:18.14
3,-5,23:18.14
4,-5,23:18.14
5,-5,23:18.14
6,-5,23:18.14
-7,-4,23:18.6
-6,-4,23:18.6
-2,-4,23:18.14
-1,-4,23:18.14
0,-4,23:18.14
1,-4,23:18.14
2,-4,23:18.14
3,-4,23:18.14
6,-4,23:18.14
7,-4,23:18.6
-7,-3,23:18.6
-2,-3,23:18.14
-1,-3,23:18.14
0,-3,23:18.14
1,-3,23:18.14
2,-3,23:18.14
-3,-2,23:18.14
-2,-2,23:18.14
2,-2,23:18.14
3,-2,23:18.14
3,-1,23:18.14
4,-1,23:18.14
4,0,23:18.6
5,0,23:18.6
-2,1,23:18.6
5,1,23:18.6
6,1,23:18.6
-3,-14,24:18.6
5,-14,24:18.6
-3,-13,24:18.6
-2,-13,24:18.6
3,-13,24:18.6
4,-13,24:18.6
-2,-12,24:18.14
-1,-12,24:18.14
0,-12,24:18.14
1,-12,24:18.14
2,-12,24:18.14
0,-11,24:18.14
1,-11,24:18.14
2,-11,24:18.14
4,-11,24:18.14
5,-11,24:18.14
-4,-10,24:18.14
1,-10,24:18.14
2,-10,24:18.14
3,-10,24:18.14
4,-10,24:18.14
9,-10,24:18.6
-4,-9,24:18.14
-2,-9,24:18.14
-1,-9,24:18.14
0,-9,24:18.14
2,-9,24:18.14
3,-9,24:18.14
8,-9,24:18.6
-4,-8,24:18.14
-2,-8,24:18.14
-1,-8,24:18.14
0,-8,24:18.14
1,-8,24:18.14
2,-8,24:18.14
3,-8,24:18.14
4,-8,24:18.14
7,-8,24:18.6
8,-8,24:18.6
-4,-7,24:18.14
-3,-7,24:18.14
-2,-7,24:18.14
-1,-7,24:18.14
0,-7,24:18.14
1,-7,24:18.14
2,-7,24:18.14
4,-7,24:18.14
5,-7,24:18.14
6,-7,24:18.14
7,-7,24:18.6
-4,-6,24:18.14
-3,-6,24:18.14
-2,-6,24:18.14
0,-6,24:18.14
1,-6,24:18.14
2,-6,24:18.14
3,-6,24:18.14
4,-6,24:18.14
5,-6,24:18.14
6,-6,24:18.14
-6,-5,24:18.6
-5,-5,24:18.6
-4,-5,24:18.14
-1,-5,24:18.14
0,-5,24:18.14
1,-5,24:18.14
3,-5,24:18.14
4,-5,24:18.14
5,-5,24:18.14
6,-5,24:18.14
-6,-4,24:18.6
-5,-4,24:18.6
-1,-4,24:18.14
0,-4,24:18.14
1,-4,24:18.14
2,-4,24:18.14
3,-4,24:18.14
6,-4,24:18.14
-2,-3,24:18.14
-1,-3,24:18.14
0,-3,24:18.14
1,-3,24:18.14
2,-3,24:18.14
6,-3,24:18.14
1,-2,24:18.14
2,-2,24:18.14
3,-2,24:18.14
1,-1,24:18.6
2,-1,24:18.6
3,-1,24:18.6
4,-1,24:18.6
-1,0,24:18.6
5,0,24:18.6
-2,1,24:18.6
-2,-13,25:18.6
3,-13,25:18.6
4,-13,25:18.6
-2,-12,25:18.6
-1,-12,25:18.6
0,-12,25:18.6
2,-12,25:18.6
3,-12,25:18.6
0,-11,25:18.14
1,-11,25:18.14
2,-11,25:18.14
-4,-10,25:18.14
0,-10,25:18.14
1,-10,25:18.14
2,-10,25:18.14
3,-10,25:18.14
4,-10,25:18.14
-3,-9,25:18.14
-2,-9,25:18.14
0,-9,25:18.14
1,-9,25:18.14
2,-9,25:18.14
3,-9,25:18.14
7,-9,25:18.6
8,-9,25:18.6
-2,-8,25:18.14
-1,-8,25:18.14
0,-8,25:18.14
1,-8,25:18.14
2,-8,25:18.14
3,-8,25:18.14
6,-8,25:18.14
7,-8,25:18.6
-3,-7,25:18.14
-2,-7,25:18.14
-1,-7,25:18.14
0,-7,25:18.14
1,-7,25:18.14
2,-7,25:18.14
4,-7,25:18.14
5,-7,25:18.14
6,-7,25:18.14
-4,-6,25:18.14
-3,-6,25:18.14
-2,-6,25:18.14
-1,-6,25:18.14
0,-6,25:18.14
1,-6,25:18.14
2,-6,25:18.14
3,-6,25:18.14
4,-6,25:18.14
5,-6,25:18.14
-5,-5,25:18.6
-4,-5,25:18.14
-1,-5,25:18.14
0,-5,25:18.14
2,-5,25:18.14
3,-5,25:18.14
4,-5,25:18.14
5,-5,25:18.14
-6,-4,25:18.6
-5,-4,25:18.6
-1,-4,25:18.14
0,-4,25:18.14
1,-4,25:18.14
2,-4,25:18.14
5,-4,25:18.14
6,-4,25:18.14
-6,-3,25:18.6
-1,-3,25:18.14
0,-3,25:18.14
2,-3,25:18.14
3,-3,25:18.14
1,-2,25:18.14
2,-2,25:18.14
3,-2,25:18.14
0,-1,25:18.6
3,-1,25:18.6
4,-1,25:18.6
-2,0,25:18.6
-1,0,25:18.6
3,-13,26:18.6
4,-13,26:18.6
-2,-12,26:18.6
2,-12,26:18.6
3,-12,26:18.6
-3,-11,26:18.14
-1,-11,26:18.14
0,-11,26:18.14
1,-11,26:18.14
2,-11,26:18.14
9,-11,26:18.6
-3,-10,26:18.14
0,-10,26:18.14
1,-10,26:18.14
2,-10,26:18.14
3,-10,26:18.14
5,-10,26:18.14
8,-10,26:18.6
9,-10,26:18.6
-3,-9,26:18.14
-1,-9,26:18.14
0,-9,26:18.14
1,-9,26:18.14
2,-9,26:18.14
3,-9,26:18.14
4,-9,26:18.14
7,-9,26:18.6
8,-9,26:18.6
-1,-8,26:18.14
0,-8,26:18.14
1,-8,26:18.14
2,-8,26:18.14
3,-8,26:18.14
5,-8,26:18.14
6,-8,26:18.14
7,-8,26:18.6
-3,-7,26:18.14
-2,-7,26:18.14
-1,-7,26:18.14
0,-7,26:18.14
1,-7,26:17.12
2,-7,26:17.12
4,-7,26:18.14
5,-7,26:18.14
6,-7,26:18.14
-4,-6,26:18.14
-3,-6,26:18.14
-2,-6,26:18.14
-1,-6,26:18.14
0,-6,26:17.12
1,-6,26:17.12
2,-6,26:17.12
3,-6,26:18.14
4,-6,26:18.14
5,-6,26:18.14
-5,-5,26:18.6
-4,-5,26:18.14
0,-5,26:18.14
1,-5,26:18.14
2,-5,26:18.14
3,-5,26:18.14
4,-5,26:18.14
5,-5,26:18.14
-6,-4,26:18.6
-5,-4,26:18.6
-2,-4,26:18.14
-1,-4,26:18.14
0,-4,26:18.14
1,-4,26:18.14
2,-4,26:18.14
3,-4,26:18.14
4,-4,26:18.14
5,-4,26:18.14
-7,-3,26:18.6
-6,-3,26:18.6
0,-3,26:18.14
1,-3,26:18.14
2,-3,26:18.14
3,-3,26:18.14
5,-3,26:18.14
-7,-2,26:18.6
0,-2,26:18.14
1,-2,26:18.14
2,-2,26:18.14
3,-2,26:18.14
4,-2,26:18.14
5,-2,26:18.14
-1,-1,26:18.6
0,-1,26:18.6
4,-1,26:18.6
5,-1,26:18.6
-1,0,26:18.6
-3,-13,27:18.6
4,-13,27:18.6
-2,-12,27:18.6
-1,-12,27:18.6
2,-12,27:18.6
3,-12,27:18.6
-2,-11,27:18.14
-1,-11,27:18.14
0,-11,27:18.14
1,-11,27:18.14
2,-11,27:18.14
-7,-10,27:18.6
-3,-10,27:18.14
0,-10,27:18.14
1,-10,27:18.14
2,-10,27:18.14
3,-10,27:18.14
4,-10,27:18.14
5,-10,27:18.14
7,-10,27:18.6
8,-10,27:18.6
-6,-9,27:18.6
-3,-9,27:18.14
-1,-9,27:18.14
0,-9,27:18.14
1,-9,27:18.14
2,-9,27:18.14
3,-9,27:18.14
4,-9,27:18.14
7,-9,27:18.6
-2,-8,27:18.14
0,-8,27:18.14
1,-8,27:18.14
2,-8,27:18.14
3,-8,27:18.14
4,-8,27:18.14
5,-8,27:18.14
6,-8,27:18.14
-4,-7,27:18.14
-3,-7,27:18.14
-2,-7,27:18.14
-1,-7,27:18.14
0,-7,27:17.12
1,-7,27:17.12
2,-7,27:17.12
3,-7,27:18.14
4,-7,27:18.14
5,-7,27:18.14
6,-7,27:18.14
7,-7,27:18.6
-4,-6,27:18.14
-3,-6,27:18.14
-2,-6,27:18.14
-1,-6,27:18.14
0,-6,27:18.14
1,-6,27:17.12
2,-6,27:17.12
3,-6,27:18.14
4,-6,27:18.14
5,-6,27:18.14
6,-6,27:18.14
7,-6,27:18.6
-4,-5,27:18.14
-3,-5,27:18.14
-2,-5,27:18.14
-1,-5,27:18.14
0,-5,27:18.14
1,-5,27:18.14
2,-5,27:18.14
4,-5,27:18.14
5,-5,27:18.14
8,-5,27:18.6
-5,-4,27:18.6
-4,-4,27:18.14
-2,-4,27:18.14
-1,-4,27:18.14
0,-4,27:18.14
1,-4,27:18.14
2,-4,27:18.14
3,-4,27:18.14
4,-4,27:18.14
9,-4,27:18.6
-6,-3,27:18.6
0,-3,27:18.14
1,-3,27:18.14
2,-3,27:18.14
3,-3,27:18.14
5,-3,27:18.14
0,-2,27:18.14
1,-2,27:18.14
2,-2,27:18.14
3,-2,27:18.14
4,-2,27:18.14
-1,-1,27:18.6
0,-1,27:18.6
4,-1,27:18.6
5,-1,27:18.6
-2,0,27:18.6
5,-13,28:18.6
-2,-12,28:18.6
3,-12,28:18.6
4,-12,28:18.6
-2,-11,28:18.14
-1,-11,28:18.14
0,-11,28:18.14
2,-11,28:18.14
3,-11,28:18.14
-7,-10,28:18.6
-2,-10,28:18.14
0,-10,28:18.14
1,-10,28:18.14
2,-10,28:18.14
7,-10,28:18.6
-6,-9,28:18.6
-2,-9,28:18.14
-1,-9,28:18.14
0,-9,28:18.14
1,-9,28:18.14
2,-9,28:18.14
3,-9,28:18.14
4,-9,28:18.14
6,-9,28:18.14
7,-9,28:18.6
-5,-8,28:18.6
-2,-8,28:18.14
-1,-8,28:18.14
0,-8,28:18.14
1,-8,28:18.14
2,-8,28:18.14
4,-8,28:18.14
5,-8,28:18.14
6,-8,28:18.14
-4,-7,28:18.14
-3,-7,28:18.14
-2,-7,28:18.14
-1,-7,28:18.14
0,-7,28:18.14
1,-7,28:17.12
2,-7,28:17.12
3,-7,28:18.14
4,-7,28:18.14
5,-7,28:18.14
6,-7,28:18.14
-4,-6,28:18.14
-3,-6,28:18.14
-2,-6,28:18.14
-1,-6,28:18.14
0,-6,28:18.14
1,-6,28:17.12
2,-6,28:17.12
3,-6,28:18.14
4,-6,28:18.14
5,-6,28:18.14
6,-6,28:18.14
7,-6,28:18.6
-4,-5,28:18.14
-3,-5,28:18.14
-2,-5,28:18.14
-1,-5,28:18.14
0,-5,28:18.14
1,-5,28:18.14
2,-5,28:18.14
3,-5,28:18.14
4,-5,28:18.14
7,-5,28:18.6
8,-5,28:18.6
-4,-4,28:18.14
-1,-4,28:18.14
0,-4,28:18.14
2,-4,28:18.14
3,-4,28:18.14
4,-4,28:18.14
8,-4,28:18.6
9,-4,28:18.6
-5,-3,28:18.6
-4,-3,28:18.14
1,-3,28:18.14
2,-3,28:18.14
3,-3,28:18.14
4,-3,28:18.14
0,-2,28:18.14
1,-2,28:18.14
3,-2,28:18.14
4,-2,28:18.14
-1,-1,28:18.6
5,-13,29:18.6
3,-12,29:18.6
4,-12,29:18.6
-2,-11,29:18.14
-1,-11,29:18.14
2,-11,29:18.14
3,-11,29:18.14
-2,-10,29:18.14
-1,-10,29:18.14
0,-10,29:18.14
1,-10,29:18.14
2,-10,29:18.14
7,-10,29:18.6
-6,-9,29:18.6
-5,-9,29:18.6
-2,-9,29:18.14
0,-9,29:18.14
1,-9,29:18.14
2,-9,29:18.14
3,-9,29:18.14
4,-9,29:18.14
6,-9,29:18.14
-5,-8,29:18.6
-4,-8,29:18.14
-2,-8,29:18.14
-1,-8,29:18.14
1,-8,29:18.14
2,-8,29:18.14
3,-8,29:18.14
4,-8,29:18.14
5,-8,29:18.14
6,-8,29:18.14
-4,-7,29:18.14
-3,-7,29:18.14
-2,-7,29:18.14
-1,-7,29:18.14
0,-7,29:18.14
1,-7,29:17.12
2,-7,29:18.14
3,-7,29:18.14
4,-7,29:18.14
5,-7,29:18.14
6,-7,29:18.14
-3,-6,29:18.14
-2,-6,29:18.14
-1,-6,29:18.14
0,-6,29:18.14
1,-6,29:17.12
2,-6,29:18.14
3,-6,29:18.14
4,-6,29:18.14
5,-6,29:18.14
6,-6,29:18.14
7,-6,29:18.6
-4,-5,29:18.14
-3,-5,29:18.14
-2,-5,29:18.14
-1,-5,29:18.14
0,-5,29:18.14
1,-5,29:18.14
2,-5,29:18.14
3,-5,29:18.14
4,-5,29:18.14
7,-5,29:18.6
-4,-4,29:18.14
-3,-4,29:18.14
0,-4,29:18.14
1,-4,29:18.14
2,-4,29:18.14
3,-4,29:18.14
8,-4,29:18.6
0,-3,29:18.14
1,-3,29:18.14
2,-3,29:18.14
3,-3,29:18.14
4,-3,29:18.14
-1,-2,29:18.14
0,-2,29:18.14
4,-2,29:18.14
5,-2,29:18.14
-2,-1,29:18.6
-1,-1,29:18.6
-3,0,29:18.6
-2,0,29:18.6
4,-12,30:18.6
2,-11,30:18.14
3,-11,30:18.14
-2,-10,30:18.14
-1,-10,30:18.14
0,-10,30:18.14
1,-10,30:18.14
2,-10,30:18.14
-5,-9,30:18.6
-1,-9,30:18.14
0,-9,30:18.14
1,-9,30:18.14
2,-9,30:18.14
5,-9,30:18.14
6,-9,30:18.14
-4,-8,30:18.14
-1,-8,30:18.14
0,-8,30:18.14
1,-8,30:18.14
2,-8,30:18.14
3,-8,30:18.14
4,-8,30:18.14
5,-8,30:18.14
-4,-7,30:18.14
-3,-7,30:18.14
-2,-7,30:18.14
-1,-7,30:18.14
0,-7,30:18.14
1,-7,30:17.12
2,-7,30:18.14
3,-7,30:18.14
4,-7,30:18.14
5,-7,30:18.14
-3,-6,30:18.14
-2,-6,30:18.14
-1,-6,30:18.14
0,-6,30:18.14
1,-6,30:18.14
2,-6,30:18.14
3,-6,30:18.14
4,-6,30:18.14
5,-6,30:18.14
6,-6,30:18.14
-3,-5,30:18.14
-2,-5,30:18.14
-1,-5,30:18.14
0,-5,30:18.14
2,-5,30:18.14
3,-5,30:18.14
6,-5,30:18.14
7,-5,30:18.6
-3,-4,30:18.14
1,-4,30:18.14
2,-4,30:18.14
3,-4,30:18.14
7,-4,30:18.6
8,-4,30:18.6
0,-3,30:18.14
1,-3,30:18.14
3,-3,30:18.14
4,-3,30:18.14
5,-3,30:18.14
-1,-2,30:18.14
0,-2,30:18.14
-2,-1,30:18.6
3,-11,31:18.14
-5,-10,31:18.6
2,-10,31:18.14
5,-10,31:18.14
-5,-9,31:18.6
-4,-9,31:18.14
-1,-9,31:18.14
0,-9,31:18.14
1,-9,31:18.14
2,-9,31:18.14
5,-9,31:18.14
-4,-8,31:18.14
-1,-8,31:18.14
0,-8,31:18.14
1,-8,31:18.14
2,-8,31:18.14
3,-8,31:18.14
4,-8,31:18.14
5,-8,31:18.14
-3,-7,31:18.14
-2,-7,31:18.14
-1,-7,31:18.14
0,-7,31:18.14
1,-7,31:18.14
2,-7,31:18.14
3,-7,31:18.14
4,-7,31:18.14
5,-7,31:18.14
-3,-6,31:18.14
-2,-6,31:18.14
-1,-6,31:18.14
0,-6,31:18.14
1,-6,31:18.14
2,-6,31:18.14
3,-6,31:18.14
4,-6,31:18.14
5,-6,31:18.14
6,-6,31:18.14
-3,-5,31:18.14
-2,-5,31:18.14
-1,-5,31:18.14
0,-5,31:18.14
1,-5,31:18.14
2,-5,31:18.14
3,-5,31:18.14
6,-5,31:18.14
7,-5,31:18.6
-3,-4,31:18.14
1,-4,31:18.14
2,-4,31:18.14
3,-4,31:18.14
7,-4,31:18.6
0,-3,31:18.14
8,-3,31:18.6
-1,-2,31:18.14
-1,-12,32:18.6
4,-12,32:18.6
5,-12,32:18.6
0,-11,32:18.14
2,-11,32:18.14
3,-11,32:18.14
4,-11,32:18.14
-5,-10,32:18.6
2,-10,32:18.14
5,-10,32:18.14
-4,-9,32:18.6
-2,-9,32:18.14
-1,-9,32:18.14
0,-9,32:18.14
1,-9,32:18.14
2,-9,32:18.14
4,-9,32:18.14
-4,-8,32:18.6
0,-8,32:18.14
1,-8,32:18.14
2,-8,32:18.14
3,-8,32:18.14
4,-8,32:18.14
-3,-7,32:18.14
-2,-7,32:18.14
-1,-7,32:18.14
0,-7,32:18.14
1,-7,32:18.14
2,-7,32:18.14
3,-7,32:18.14
4,-7,32:18.14
-2,-6,32:18.14
-1,-6,32:18.14
0,-6,32:18.14
1,-6,32:17.12
2,-6,32:18.14
3,-6,32:18.14
4,-6,32:18.14
5,-6,32:18.14
-2,-5,32:18.14
-1,-5,32:18.14
0,-5,32:18.14
1,-5,32:18.14
2,-5,32:18.14
3,-5,32:18.14
6,-5,32:18.14
-2,-4,32:18.14
0,-4,32:18.14
1,-4,32:18.14
2,-4,32:18.14
3,-4,32:18.14
4,-4,32:18.14
7,-4,32:18.6
-1,-3,32:18.14
0,-3,32:18.14
8,-3,32:18.6
-2,-2,32:18.14
-1,-2,32:18.14
2,-2,32:18.14
3,-2,32:18.14
-2,-1,32:18.6
3,-1,32:18.6
0,-11,33:18.14
1,-11,33:18.14
3,-11,33:18.14
4,-11,33:18.14
1,-10,33:18.14
2,-10,33:18.14
3,-10,33:18.14
-1,-9,33:18.14
0,-9,33:18.14
1,-9,33:18.14
2,-9,33:18.14
3,-9,33:18.14
-2,-8,33:18.14
0,-8,33:18.14
1,-8,33:18.14
2,-8,33:18.14
3,-8,33:18.14
-2,-7,33:18.14
-1,-7,33:18.14
0,-7,33:18.14
1,-7,33:17.0
2,-7,33:17.0
3,-7,33:18.14
4,-7,33:18.14
-2,-6,33:18.14
-1,-6,33:18.14
0,-6,33:18.14
1,-6,33:17.0
2,-6,33:18.14
3,-6,33:18.14
4,-6,33:18.14
5,-6,33:18.14
-2,-5,33:18.14
1,-5,33:18.14
2,-5,33:18.14
3,-5,33:18.14
0,-4,33:18.14
1,-4,33:18.14
2,-4,33:18.14
3,-4,33:18.14
4,-4,33:18.14
-1,-3,33:18.14
0,-3,33:18.14
1,-3,33:18.14
2,-3,33:18.14
-2,-2,33:18.14
-1,-2,33:18.14
2,-2,33:18.14
3,-2,33:18.14
0,-11,34:18.14
-4,-10,34:18.6
1,-10,34:18.14
2,-10,34:18.14
3,-10,34:18.14
4,-10,34:18.14
-4,-9,34:18.6
-3,-9,34:18.14
0,-9,34:18.14
1,-9,34:18.14
2,-9,34:18.14
3,-9,34:18.14
-2,-8,34:18.14
-1,-8,34:18.14
0,-8,34:18.14
1,-8,34:18.14
2,-8,34:18.14
3,-8,34:18.14
4,-8,34:18.14
6,-8,34:18.6
7,-8,34:18.6
-2,-7,34:18.14
-1,-7,34:18.14
0,-7,34:18.14
1,-7,34:17.0
2,-7,34:18.14
3,-7,34:18.14
4,-7,34:18.14
5,-7,34:18.14
6,-7,34:18.6
-3,-6,34:18.14
-2,-6,34:18.14
-1,-6,34:18.14
0,-6,34:18.14
1,-6,34:17.0
2,-6,34:18.14
3,-6,34:18.14
4,-6,34:18.14
5,-6,34:18.14
-4,-5,34:18.6
-2,-5,34:18.14
-1,-5,34:18.14
0,-5,34:18.14
1,-5,34:18.14
2,-5,34:18.14
3,-5,34:18.14
4,-5,34:18.14
5,-5,34:18.14
-2,-4,34:18.14
-1,-4,34:18.14
0,-4,34:18.14
1,-4,34:18.14
2,-4,34:18.14
6,-4,34:18.6
-2,-3,34:18.14
-1,-3,34:18.14
0,-3,34:18.14
1,-3,34:18.14
2,-3,34:18.14
3,-2,34:18.14
1,-10,35:18.14
2,-10,35:18.14
-3,-9,35:18.14
0,-9,35:18.14
1,-9,35:18.14
2,-9,35:18.14
3,-9,35:18.14
-2,-8,35:18.14
-1,-8,35:18.14
0,-8,35:18.14
1,-8,35:18.14
2,-8,35:18.14
3,-8,35:18.14
6,-8,35:18.6
-2,-7,35:18.14
-1,-7,35:18.14
0,-7,35:18.14
1,-7,35:17.0
2,-7,35:18.14
3,-7,35:18.14
4,-7,35:18.14
5,-7,35:18.14
-3,-6,35:18.14
-2,-6,35:18.14
-1,-6,35:18.14
0,-6,35:18.14
1,-6,35:18.14
2,-6,35:18.14
3,-6,35:18.14
4,-6,35:18.14
5,-6,35:18.14
-4,-5,35:18.6
-1,-5,35:18.14
0,-5,35:18.14
1,-5,35:18.14
2,-5,35:18.14
3,-5,35:18.14
4,-5,35:18.14
5,-5,35:18.14
0,-4,35:18.14
1,-4,35:18.14
2,-4,35:18.14
2,-3,35:18.14
0,-10,36:18.14
1,-10,36:18.14
2,-10,36:18.14
0,-9,36:18.14
1,-9,36:18.14
2,-9,36:18.14
3,-9,36:18.14
-2,-8,36:18.14
-1,-8,36:18.14
0,-8,36:18.14
2,-8,36:18.14
3,-8,36:18.14
6,-8,36:18.6
-2,-7,36:18.14
-1,-7,36:18.14
0,-7,36:18.14
1,-7,36:18.14
2,-7,36:18.14
4,-7,36:18.14
5,-7,36:18.14
-3,-6,36:18.14
-2,-6,36:18.14
-1,-6,36:18.14
0,-6,36:18.14
1,-6,36:18.14
2,-6,36:18.14
3,-6,36:18.14
4,-6,36:18.14
5,-6,36:18.14
0,-5,36:18.14
1,-5,36:18.14
2,-5,36:18.14
3,-5,36:18.14
5,-5,36:18.14
0,-4,36:18.14
1,-4,36:18.14
2,-4,36:18.14
2,-3,36:18.14
0,-10,37:18.6
1,-10,37:18.6
1,-9,37:18.6
2,-9,37:18.6
-2,-8,37:18.6
-1,-8,37:18.6
0,-8,37:18.6
1,-8,37:18.6
2,-8,37:18.6
3,-8,37:18.6
5,-8,37:18.6
-2,-7,37:18.6
-1,-7,37:18.6
0,-7,37:18.6
1,-7,37:18.6
2,-7,37:18.6
3,-7,37:18.6
4,-7,37:18.6
5,-7,37:18.6
-2,-6,37:18.6
-1,-6,37:18.6
0,-6,37:18.6
1,-6,37:18.6
2,-6,37:18.6
3,-6,37:18.6
4,-6,37:18.6
0,-5,37:18.6
1,-5,37:18.6
2,-5,37:18.6
3,-5,37:18.6
0,-4,37:18.6
1,-4,37:18.6
2,-4,37:18.6
-1,-10,38:18.6
0,-10,38:18.6
3,-10,38:18.6
1,-9,38:18.6
2,-9,38:18.6
3,-9,38:18.6
-2,-8,38:18.6
0,-8,38:18.6
2,-8,38:18.6
3,-8,38:18.6
5,-8,38:18.6
-2,-7,38:18.6
-1,-7,38:18.6
1,-7,38:17.0
3,-7,38:18.6
4,-7,38:18.6
5,-7,38:18.6
-2,-6,38:18.6
-1,-6,38:18.6
0,-6,38:18.6
1,-6,38:17.0
3,-6,38:18.6
4,-6,38:18.6
0,-5,38:18.6
1,-5,38:18.6
2,-5,38:18.6
-1,-4,38:18.6
0,-4,38:18.6
1,-4,38:18.6
2,-4,38:18.6
3,-3,38:18.6
0,-10,39:18.6
0,-9,39:18.6
1,-9,39:18.6
2,-9,39:18.6
3,-9,39:18.6
-1,-8,39:18.6
0,-8,39:18.6
1,-8,39:18.6
2,-8,39:18.6
5,-8,39:18.6
-1,-7,39:18.6
0,-7,39:18.6
1,-7,39:17.0
3,-7,39:18.6
4,-7,39:18.6
-2,-6,39:18.6
-1,-6,39:18.6
0,-6,39:18.6
1,-6,39:17.0
2,-6,39:18.6
3,-6,39:18.6
4,-6,39:18.6
0,-5,39:18.6
1,-5,39:18.6
2,-5,39:18.6
4,-5,39:18.6
0,-4,39:18.6
1,-4,39:18.6
2,-4,39:18.6
3,-3,39:18.6
1,-9,40:18.6
2,-9,40:18.6
-1,-8,40:18.6
0,-8,40:18.6
1,-8,40:18.6
2,-8,40:18.6
4,-8,40:18.6
5,-8,40:18.6
-1,-7,40:18.6
0,-7,40:18.6
1,-7,40:17.0
2,-7,40:18.6
3,-7,40:18.6
4,-7,40:18.6
-2,-6,40:18.6
-1,-6,40:18.6
0,-6,40:18.6
1,-6,40:17.0
2,-6,40:18.6
3,-6,40:18.6
4,-6,40:18.6
-2,-5,40:18.6
1,-5,40:18.6
2,-5,40:18.6
4,-5,40:18.6
2,-4,40:18.6
0,-9,41:18.6
0,-8,41:18.6
1,-8,41:18.6
2,-8,41:18.6
-1,-7,41:18.6
0,-7,41:18.6
1,-7,41:17.0
2,-7,41:18.6
3,-7,41:18.6
-1,-6,41:18.6
0,-6,41:18.6
1,-6,41:17.0
2,-6,41:18.6
3,-6,41:18.6
0,-5,41:18.6
1,-5,41:18.6
2,-5,41:18.6
0,-9,42:18.6
0,-8,42:18.6
1,-8,42:18.6
2,-8,42:18.6
4,-8,42:18.6
0,-7,42:18.6
1,-7,42:17.0
2,-7,42:18.6
3,-7,42:18.6
-1,-6,42:18.6
0,-6,42:18.6
1,-6,42:18.6
2,-6,42:18.6
3,-6,42:18.6
0,-5,42:18.6
1,-5,42:18.6
2,-5,42:18.6
2,-4,42:18.6
0,-8,43:18.6
1,-8,43:18.6
2,-8,43:18.6
3,-8,43:18.6
4,-8,43:18.6
0,-7,43:18.6
1,-7,43:17.0
2,-7,43:18.6
3,-7,43:18.6
-1,-6,43:18.6
0,-6,43:18.6
1,-6,43:18.6
2,-6,43:18.6
3,-6,43:18.6
1,-5,43:18.6
2,-5,43:18.6
1,-8,44:18.6
0,-7,44:18.6
1,-7,44:18.6
2,-7,44:18.6
0,-6,44:18.6
1,-6,44:18.6
2,-6,44:18.6
0,-7,45:18.6
1,-7,45:18.6
2,-7,45:18.6
1,-6,45:18.6
1,-7,46:18.6
1,-6,46:18.6
1,-7,47:17.0
1,-7,48:17.0
1,-7,49:17.0
1,-7,50:17.0
