[META]
version=2.0
spawnOnBlockType=2
spawnSunlight=True
spawnDarkness=True
spawnWater=False
spawnLava=False
underFill=False
randomRotation=True
dig=True
tree=False
branch=False
needsFoundation=True
rarity=100
collisionPercentage=20
spawnElevationMin=0
spawnElevationMax=200
spawnInBiome=Custom
[DATA]
5,-11,-8:17.12
6,-11,-8:17.12
7,-11,-8:17.12
6,-10,-8:17.12
7,-10,-8:17.12
-6,-3,-8:17.12
-4,-3,-8:17.12
7,-12,-7:17.12
8,-12,-7:17.12
4,-11,-7:17.12
5,-11,-7:17.12
6,-11,-7:17.12
7,-11,-7:17.12
4,-10,-7:17.12
6,-10,-7:17.12
7,-10,-7:17.12
8,-10,-7:17.12
-1,-9,-7:17.12
7,-9,-7:17.12
-5,-5,-7:17.12
-7,-4,-7:17.12
-6,-4,-7:17.12
-7,-3,-7:17.12
-5,-3,-7:17.12
-7,-2,-7:17.12
-6,-2,-7:17.12
-6,-1,-7:17.12
5,-13,-6:17.12
6,-13,-6:17.12
4,-12,-6:17.12
5,-12,-6:17.12
6,-12,-6:17.12
7,-12,-6:17.12
8,-12,-6:17.12
4,-11,-6:17.12
5,-11,-6:17.12
6,-11,-6:17.12
7,-11,-6:17.12
8,-11,-6:17.12
1,-10,-6:17.12
5,-10,-6:17.12
6,-10,-6:17.12
7,-10,-6:17.12
8,-10,-6:17.12
-2,-9,-6:17.12
-1,-9,-6:17.12
5,-9,-6:17.12
6,-9,-6:17.12
7,-9,-6:17.12
0,-8,-6:17.12
-1,-7,-6:17.12
-7,-4,-6:17.12
-6,-4,-6:17.12
-7,-3,-6:17.12
-6,-3,-6:17.12
-5,-3,-6:17.12
-4,-3,-6:17.12
-7,-2,-6:17.12
-5,-2,-6:17.12
-3,-2,-6:17.12
-6,-1,-6:17.12
-5,-1,-6:17.12
6,-13,-5:17.12
6,-12,-5:17.12
7,-12,-5:17.12
8,-12,-5:17.12
-1,-11,-5:17.12
4,-11,-5:17.12
5,-11,-5:17.12
6,-11,-5:17.12
7,-11,-5:17.12
8,-11,-5:17.12
-1,-10,-5:17.12
0,-10,-5:17.12
1,-10,-5:17.12
4,-10,-5:17.12
6,-10,-5:17.12
-2,-9,-5:17.12
-1,-9,-5:17.12
0,-9,-5:17.12
1,-9,-5:17.12
2,-9,-5:17.12
6,-9,-5:17.12
-1,-8,-5:17.12
1,-8,-5:17.12
0,-7,-5:17.12
-6,-5,-5:17.12
-4,-5,-5:17.12
-7,-4,-5:17.12
-5,-4,-5:17.12
-3,-4,-5:17.12
-7,-3,-5:17.12
-6,-3,-5:17.12
-5,-3,-5:17.12
-4,-3,-5:17.12
-3,-3,-5:17.12
-7,-2,-5:17.12
-6,-2,-5:17.12
-4,-2,-5:17.12
-5,-1,-5:17.12
-4,-1,-5:17.12
6,-13,-4:17.12
7,-13,-4:17.12
4,-12,-4:17.12
7,-12,-4:17.12
0,-11,-4:17.12
4,-11,-4:17.12
5,-11,-4:17.12
6,-11,-4:17.12
7,-11,-4:17.12
-2,-10,-4:17.12
4,-10,-4:17.12
6,-10,-4:17.12
7,-10,-4:17.12
8,-10,-4:17.12
-1,-9,-4:17.12
0,-9,-4:17.12
1,-9,-4:17.12
2,-9,-4:17.12
5,-9,-4:17.12
6,-9,-4:17.12
7,-9,-4:17.12
-2,-8,-4:17.12
0,-8,-4:17.12
2,-8,-4:17.12
-1,-7,-4:17.12
-5,-5,-4:17.12
-6,-4,-4:17.12
-5,-4,-4:17.12
-3,-4,-4:17.12
-6,-3,-4:17.12
-5,-3,-4:17.12
-4,-3,-4:17.12
-3,-3,-4:17.12
-6,-2,-4:17.12
-5,-2,-4:17.12
-4,-2,-4:17.12
-3,-2,-4:17.12
-5,-1,-4:17.12
-4,-1,-4:17.12
-6,0,-4:17.12
-5,0,-4:17.12
-4,0,-4:17.12
6,-12,-3:17.12
-1,-11,-3:17.12
0,-11,-3:17.12
5,-11,-3:17.12
6,-11,-3:17.12
8,-11,-3:17.12
1,-10,-3:17.12
2,-10,-3:17.12
6,-10,-3:17.12
8,-10,-3:17.12
-2,-9,-3:17.12
-1,-9,-3:17.12
0,-9,-3:17.12
1,-9,-3:17.12
5,-9,-3:17.12
-1,-8,-3:17.12
1,-8,-3:17.12
-1,-7,-3:17.12
1,-7,-3:17.12
-5,-5,-3:17.12
-6,-4,-3:17.12
-5,-4,-3:17.12
-5,-3,-3:17.12
-3,-3,-3:17.12
-5,-2,-3:17.12
-6,-1,-3:17.12
-5,-1,-3:17.12
-4,-1,-3:17.12
-3,-1,-3:17.12
-6,0,-3:17.12
-5,0,-3:17.12
6,-12,-2:17.12
7,-12,-2:17.12
5,-11,-2:17.12
6,-11,-2:17.12
7,-11,-2:17.12
8,-11,-2:17.12
-1,-10,-2:17.12
0,-10,-2:17.12
1,-10,-2:17.12
6,-10,-2:17.12
7,-10,-2:17.12
8,-10,-2:17.12
-2,-9,-2:17.12
0,-9,-2:17.12
1,-9,-2:17.12
6,-9,-2:17.12
7,-9,-2:17.12
0,-8,-2:17.12
2,-8,-2:17.12
0,-7,-2:17.12
-5,-5,-2:17.12
-4,-5,-2:17.12
-6,-4,-2:17.12
-5,-4,-2:17.12
-3,-4,-2:17.12
-6,-3,-2:17.12
-5,-3,-2:17.12
-4,-3,-2:17.12
-3,-3,-2:17.12
-6,-2,-2:17.12
-5,-2,-2:17.12
-4,-2,-2:17.12
-3,-2,-2:17.12
-5,-1,-2:17.12
-4,-1,-2:17.12
6,-12,-1:17.12
7,-12,-1:17.12
5,-11,-1:17.12
6,-11,-1:17.12
7,-11,-1:17.12
8,-11,-1:17.12
-1,-10,-1:17.12
0,-10,-1:17.12
1,-10,-1:17.12
5,-10,-1:17.12
6,-10,-1:17.12
7,-10,-1:17.12
8,-10,-1:17.12
-1,-9,-1:17.12
0,-9,-1:17.12
1,-9,-1:17.12
-1,-8,-1:17.12
0,-8,-1:17.12
1,-8,-1:17.12
-5,-5,-1:17.12
-4,-5,-1:17.12
-3,-5,-1:17.12
-6,-4,-1:17.12
-5,-4,-1:17.12
-3,-4,-1:17.12
-6,-3,-1:17.12
-5,-3,-1:17.12
-3,-3,-1:17.12
-6,-2,-1:17.12
-3,-2,-1:17.12
-5,-1,-1:17.12
-4,-1,-1:17.12
-3,-1,-1:17.12
-1,-12,0:18.13
6,-12,0:17.12
7,-12,0:17.12
-2,-11,0:18.13
5,-11,0:17.12
6,-11,0:17.12
7,-11,0:18.14
8,-11,0:18.14
9,-11,0:18.14
-3,-10,0:18.13
0,-10,0:17.12
1,-10,0:17.12
6,-10,0:17.12
7,-10,0:17.12
8,-10,0:17.12
9,-10,0:18.14
-1,-9,0:18.13
0,-9,0:17.12
1,-9,0:17.12
6,-9,0:18.14
7,-9,0:18.14
9,-9,0:18.14
0,-8,0:17.12
1,-8,0:17.12
7,-8,0:18.14
8,-8,0:18.14
9,-8,0:18.14
-6,-5,0:17.12
-5,-5,0:17.12
-4,-5,0:17.12
-7,-4,0:17.12
-6,-4,0:17.12
-3,-4,0:17.12
-6,-3,0:17.12
-3,-3,0:17.12
-6,-2,0:17.12
-5,-2,0:17.12
-3,-2,0:17.12
-5,-1,0:17.12
-4,-1,0:17.12
1,-13,1:18.13
-1,-12,1:18.13
1,-12,1:18.13
2,-12,1:18.13
7,-12,1:17.12
-2,-11,1:18.13
-1,-11,1:18.13
0,-11,1:18.13
1,-11,1:18.13
2,-11,1:18.13
3,-11,1:18.13
4,-11,1:18.13
6,-11,1:17.12
7,-11,1:17.12
8,-11,1:18.14
-3,-10,1:18.13
-2,-10,1:18.13
-1,-10,1:18.13
0,-10,1:17.12
2,-10,1:18.13
6,-10,1:17.12
7,-10,1:18.14
8,-10,1:18.14
-1,-9,1:18.13
0,-9,1:17.12
1,-9,1:17.12
2,-9,1:18.13
7,-9,1:18.14
8,-9,1:18.14
9,-9,1:18.14
-2,-8,1:18.13
-1,-8,1:18.13
0,-8,1:17.12
1,-8,1:18.13
2,-8,1:18.13
3,-8,1:18.13
4,-8,1:18.13
6,-8,1:18.14
7,-8,1:18.14
9,-8,1:18.14
-1,-7,1:18.13
0,-7,1:18.13
1,-7,1:18.13
2,-7,1:18.13
0,-6,1:18.13
2,-6,1:18.13
-7,-5,1:17.12
-6,-5,1:17.12
-5,-5,1:17.12
-4,-5,1:17.12
-7,-4,1:17.12
-6,-4,1:17.12
-3,-4,1:17.12
-6,-3,1:17.12
-3,-3,1:17.12
-6,-2,1:17.12
-5,-2,1:17.12
-4,-2,1:17.12
-3,-2,1:17.12
-1,-12,2:18.13
1,-12,2:18.13
2,-12,2:18.13
7,-12,2:17.12
-2,-11,2:18.13
-1,-11,2:18.13
0,-11,2:18.13
1,-11,2:18.13
2,-11,2:18.13
3,-11,2:18.13
6,-11,2:17.12
7,-11,2:17.12
-2,-10,2:18.13
-1,-10,2:18.13
0,-10,2:17.12
2,-10,2:18.13
6,-10,2:17.12
7,-10,2:17.12
8,-10,2:18.14
-1,-9,2:18.13
0,-9,2:17.12
1,-9,2:17.12
2,-9,2:18.13
7,-9,2:18.14
8,-9,2:18.14
9,-9,2:18.14
-2,-8,2:18.13
-1,-8,2:18.13
0,-8,2:18.13
1,-8,2:18.13
2,-8,2:18.13
3,-8,2:18.13
4,-8,2:18.13
-1,-7,2:18.13
2,-7,2:18.13
0,-6,2:18.13
-7,-5,2:17.12
-6,-5,2:17.12
-5,-5,2:17.12
-4,-5,2:17.12
-7,-4,2:17.12
-6,-4,2:17.12
-3,-4,2:17.12
-6,-3,2:17.12
-3,-3,2:17.12
-6,-2,2:17.12
-5,-2,2:17.12
-4,-2,2:17.12
-3,-2,2:17.12
-1,-12,3:18.13
1,-12,3:18.13
-1,-11,3:18.13
1,-11,3:18.13
2,-11,3:18.13
3,-11,3:18.13
6,-11,3:17.12
7,-11,3:17.12
-2,-10,3:18.13
-1,-10,3:18.13
0,-10,3:18.13
1,-10,3:18.13
6,-10,3:17.12
7,-10,3:17.12
-1,-9,3:18.13
0,-9,3:17.12
1,-9,3:18.13
2,-9,3:18.13
-4,-8,3:18.14
-2,-8,3:18.13
-1,-8,3:18.13
0,-8,3:18.13
1,-8,3:18.13
2,-8,3:18.13
3,-8,3:18.13
-8,-7,3:18.14
-7,-7,3:18.14
-6,-7,3:18.14
-5,-7,3:18.14
-1,-7,3:18.13
2,-7,3:18.13
-8,-5,3:18.14
-7,-5,3:17.12
-6,-5,3:17.12
-5,-5,3:17.12
-4,-5,3:17.12
-8,-4,3:18.14
-7,-4,3:17.12
-6,-4,3:18.14
-5,-4,3:17.12
-4,-4,3:17.12
-3,-4,3:17.12
-8,-3,3:18.14
-6,-3,3:17.12
-3,-3,3:17.12
-8,-2,3:18.14
-6,-2,3:17.12
-5,-2,3:17.12
-4,-2,3:17.12
-3,-2,3:17.12
-1,-12,4:18.13
0,-12,4:18.13
1,-12,4:18.13
-1,-11,4:18.13
0,-11,4:18.13
1,-11,4:18.13
2,-11,4:18.13
6,-11,4:17.12
7,-11,4:17.12
-2,-10,4:18.13
-1,-10,4:18.13
0,-10,4:18.13
1,-10,4:18.13
2,-10,4:18.13
6,-10,4:17.12
7,-10,4:17.12
-2,-9,4:18.13
-1,-9,4:18.13
0,-9,4:17.12
1,-9,4:18.13
2,-9,4:18.13
-4,-8,4:18.14
-2,-8,4:18.13
-1,-8,4:18.13
0,-8,4:18.13
1,-8,4:18.13
-9,-7,4:18.14
-8,-7,4:18.14
-7,-7,4:18.14
-6,-7,4:18.14
-5,-7,4:18.14
-4,-7,4:18.14
-3,-7,4:18.14
-1,-7,4:18.13
0,-7,4:18.13
1,-7,4:18.13
2,-7,4:18.13
-9,-6,4:18.14
-8,-6,4:18.14
-7,-6,4:18.14
-6,-6,4:18.14
-5,-6,4:18.14
-4,-6,4:18.14
-3,-6,4:18.14
-8,-5,4:18.14
-7,-5,4:17.12
-6,-5,4:18.14
-5,-5,4:18.14
-4,-5,4:18.14
-7,-4,4:18.14
-5,-4,4:17.12
-4,-4,4:17.12
-3,-4,4:17.12
-8,-3,4:18.14
-7,-3,4:18.14
-6,-3,4:17.12
-3,-3,4:17.12
-8,-2,4:18.14
-7,-2,4:18.14
-6,-2,4:17.12
-5,-2,4:17.12
-4,-2,4:17.12
-3,-2,4:17.12
-1,-12,5:18.13
0,-12,5:18.13
1,-12,5:18.13
-2,-11,5:18.13
-1,-11,5:18.13
0,-11,5:18.13
1,-11,5:18.13
6,-11,5:17.12
7,-11,5:17.12
-2,-10,5:18.13
-1,-10,5:18.13
0,-10,5:18.13
1,-10,5:18.13
2,-10,5:18.13
6,-10,5:17.12
7,-10,5:17.12
-2,-9,5:18.13
-1,-9,5:18.13
0,-9,5:18.13
1,-9,5:18.13
2,-9,5:18.13
3,-9,5:18.13
-4,-8,5:18.14
-2,-8,5:18.13
0,-8,5:18.13
1,-8,5:18.13
-9,-7,5:18.14
-8,-7,5:18.14
-7,-7,5:18.14
-6,-7,5:18.14
-5,-7,5:18.14
-4,-7,5:18.14
-3,-7,5:18.14
0,-7,5:18.13
1,-7,5:18.13
2,-7,5:18.13
-7,-6,5:18.14
-6,-6,5:18.14
-5,-6,5:18.14
-9,-5,5:18.14
-8,-5,5:18.14
-7,-5,5:17.12
-5,-5,5:18.14
-9,-4,5:18.14
-8,-4,5:18.14
-7,-4,5:18.14
-6,-4,5:18.14
-5,-4,5:17.12
-4,-4,5:17.12
-3,-4,5:17.12
-9,-3,5:18.14
-8,-3,5:18.14
-7,-3,5:18.14
-6,-3,5:17.12
-3,-3,5:17.12
-6,-2,5:17.12
-5,-2,5:17.12
-4,-2,5:17.12
-3,-2,5:17.12
7,-17,6:18.5
8,-17,6:18.5
7,-16,6:18.13
10,-15,6:18.13
11,-15,6:18.13
10,-14,6:18.13
11,-14,6:18.13
2,-13,6:18.13
-1,-12,6:18.13
0,-12,6:18.13
1,-12,6:18.13
2,-12,6:18.13
-2,-11,6:18.13
-1,-11,6:18.13
0,-11,6:18.13
1,-11,6:18.13
2,-11,6:18.13
6,-11,6:17.12
7,-11,6:17.12
-2,-10,6:18.13
-1,-10,6:18.13
0,-10,6:18.13
1,-10,6:18.13
2,-10,6:18.13
6,-10,6:17.12
7,-10,6:17.12
-2,-9,6:18.13
-1,-9,6:18.13
0,-9,6:18.13
1,-9,6:18.13
2,-9,6:18.13
3,-9,6:18.13
0,-8,6:18.13
1,-8,6:18.13
2,-8,6:18.13
-8,-7,6:18.14
-7,-7,6:18.14
-6,-7,6:18.14
-5,-7,6:18.14
-4,-7,6:18.14
11,-7,6:18.13
-9,-6,6:18.14
-8,-6,6:18.14
-7,-6,6:18.14
-6,-6,6:18.14
-5,-6,6:18.14
11,-6,6:18.13
-8,-5,6:18.14
-7,-5,6:18.14
-6,-5,6:18.14
-5,-5,6:18.14
7,-5,6:18.5
8,-5,6:18.5
11,-5,6:18.5
-10,-4,6:18.14
-8,-4,6:18.14
-7,-4,6:18.14
-6,-4,6:18.14
-5,-4,6:17.12
-4,-4,6:17.12
-3,-4,6:17.12
8,-4,6:18.5
9,-4,6:18.5
11,-4,6:18.5
-9,-3,6:18.14
-8,-3,6:18.14
-7,-3,6:18.14
-6,-3,6:17.12
-3,-3,6:17.12
9,-3,6:18.5
-8,-2,6:18.14
-5,-2,6:17.12
-4,-2,6:17.12
-3,-2,6:17.12
9,-17,7:18.5
10,-17,7:18.5
8,-16,7:18.5
9,-16,7:18.5
10,-16,7:18.5
7,-15,7:18.13
8,-15,7:18.13
9,-15,7:18.13
10,-15,7:18.13
9,-14,7:18.13
10,-14,7:18.13
9,-13,7:18.13
10,-13,7:18.13
0,-12,7:18.13
1,-12,7:18.13
2,-12,7:18.13
3,-12,7:18.13
-1,-11,7:18.13
0,-11,7:18.13
1,-11,7:18.13
2,-11,7:18.13
3,-11,7:18.13
6,-11,7:17.12
7,-11,7:17.12
-2,-10,7:18.13
-1,-10,7:18.13
0,-10,7:17.12
1,-10,7:18.13
2,-10,7:18.13
3,-10,7:18.13
6,-10,7:17.12
7,-10,7:17.12
-2,-9,7:18.13
-1,-9,7:18.13
0,-9,7:18.13
1,-9,7:18.13
2,-9,7:18.13
3,-9,7:18.13
-1,-8,7:18.13
0,-8,7:18.13
1,-8,7:18.13
10,-8,7:18.13
11,-8,7:18.13
-8,-7,7:18.14
-6,-7,7:18.14
10,-7,7:18.13
-7,-6,7:18.14
-6,-6,7:18.14
7,-6,7:18.13
8,-6,7:18.13
9,-6,7:18.13
10,-6,7:18.13
-10,-5,7:18.14
-9,-5,7:18.14
-8,-5,7:18.14
-7,-5,7:18.14
-6,-5,7:18.14
8,-5,7:18.5
10,-5,7:18.5
11,-5,7:18.5
-11,-4,7:18.14
-10,-4,7:18.14
-9,-4,7:18.14
-8,-4,7:18.14
-7,-4,7:18.14
-5,-4,7:17.12
-4,-4,7:17.12
-3,-4,7:17.12
9,-4,7:18.5
10,-4,7:18.5
11,-4,7:18.5
-11,-3,7:18.14
-8,-3,7:18.14
-7,-3,7:18.14
-6,-3,7:17.12
-3,-3,7:17.12
10,-3,7:18.5
11,-3,7:18.5
-5,-2,7:17.12
-4,-2,7:17.12
3,-18,8:18.5
4,-18,8:18.5
3,-17,8:18.5
4,-17,8:18.5
5,-17,8:18.5
3,-16,8:18.5
4,-16,8:18.5
5,-16,8:18.5
6,-16,8:18.5
3,-15,8:18.13
4,-15,8:18.13
5,-15,8:18.13
6,-15,8:18.13
7,-15,8:18.13
9,-15,8:18.13
4,-14,8:18.13
7,-14,8:18.13
8,-14,8:18.13
9,-14,8:18.13
4,-13,8:18.13
7,-13,8:18.13
8,-13,8:18.13
9,-13,8:18.13
0,-12,8:18.13
4,-12,8:18.13
11,-12,8:18.13
12,-12,8:18.5
13,-12,8:18.5
-1,-11,8:18.13
0,-11,8:18.13
2,-11,8:18.13
3,-11,8:18.13
4,-11,8:18.13
6,-11,8:17.12
7,-11,8:17.12
8,-11,8:18.13
12,-11,8:18.5
13,-11,8:18.5
-2,-10,8:18.13
-1,-10,8:18.13
0,-10,8:17.12
1,-10,8:18.13
2,-10,8:18.13
3,-10,8:18.13
4,-10,8:18.13
5,-10,8:18.13
6,-10,8:17.12
7,-10,8:17.12
11,-10,8:18.13
12,-10,8:18.5
13,-10,8:18.5
-2,-9,8:18.13
-1,-9,8:18.13
0,-9,8:18.13
2,-9,8:18.13
4,-9,8:18.13
6,-9,8:18.13
7,-9,8:18.13
11,-9,8:18.13
12,-9,8:18.5
-6,-8,8:18.14
0,-8,8:18.13
2,-8,8:18.13
3,-8,8:18.13
7,-8,8:18.13
8,-8,8:18.13
9,-8,8:18.13
11,-8,8:18.13
-9,-7,8:18.14
-7,-7,8:18.14
-6,-7,8:18.14
2,-7,8:18.13
3,-7,8:18.13
7,-7,8:18.13
8,-7,8:18.13
9,-7,8:18.13
12,-7,8:18.5
-9,-6,8:18.14
-8,-6,8:18.14
-7,-6,8:18.14
-6,-6,8:18.14
-5,-6,8:18.14
2,-6,8:18.13
3,-6,8:18.13
5,-6,8:18.13
6,-6,8:18.13
9,-6,8:18.13
-10,-5,8:18.14
-9,-5,8:18.14
-8,-5,8:18.14
-7,-5,8:18.14
-6,-5,8:18.14
-5,-5,8:17.12
2,-5,8:18.13
3,-5,8:18.13
4,-5,8:18.13
5,-5,8:18.5
-10,-4,8:18.14
-9,-4,8:18.14
-8,-4,8:18.14
-7,-4,8:18.14
-6,-4,8:18.14
-5,-4,8:17.12
-4,-4,8:17.12
-3,-4,8:17.12
2,-4,8:18.5
3,-4,8:18.5
4,-4,8:18.5
-11,-3,8:18.14
-10,-3,8:18.14
-9,-3,8:18.14
-8,-3,8:18.14
-6,-3,8:17.12
-3,-3,8:17.12
-11,-2,8:18.14
-10,-2,8:18.14
-9,-2,8:18.14
-5,-2,8:17.12
-4,-2,8:17.12
8,-17,9:18.5
9,-17,9:18.5
4,-16,9:18.5
6,-16,9:18.5
7,-16,9:18.5
8,-16,9:18.5
9,-16,9:18.5
4,-15,9:18.13
5,-15,9:18.13
6,-15,9:18.13
9,-15,9:18.13
10,-15,9:18.13
4,-14,9:18.13
5,-14,9:18.13
6,-14,9:18.13
7,-14,9:18.13
9,-14,9:18.13
10,-14,9:18.13
4,-13,9:18.13
5,-13,9:18.13
7,-13,9:18.13
8,-13,9:18.13
-3,-12,9:18.13
0,-12,9:18.13
1,-12,9:18.13
7,-12,9:18.13
8,-12,9:18.13
10,-12,9:18.13
11,-12,9:18.13
-4,-11,9:18.13
-1,-11,9:18.13
0,-11,9:18.13
1,-11,9:18.13
4,-11,9:18.13
5,-11,9:18.13
6,-11,9:18.13
7,-11,9:18.13
8,-11,9:18.13
10,-11,9:18.13
11,-11,9:18.13
12,-11,9:18.5
13,-11,9:18.5
-2,-10,9:18.13
-1,-10,9:18.13
0,-10,9:18.13
1,-10,9:18.13
4,-10,9:18.13
5,-10,9:18.13
6,-10,9:17.12
7,-10,9:18.13
10,-10,9:18.13
11,-10,9:18.13
12,-10,9:18.5
13,-10,9:18.5
-1,-9,9:18.13
0,-9,9:18.13
1,-9,9:18.13
6,-9,9:18.13
7,-9,9:18.13
8,-9,9:18.13
10,-9,9:18.13
11,-9,9:18.13
1,-8,9:18.13
2,-8,9:18.13
3,-8,9:18.13
4,-8,9:18.13
7,-8,9:18.13
8,-8,9:18.13
11,-8,9:18.13
-8,-7,9:18.14
-7,-7,9:18.14
-6,-7,9:18.14
-5,-7,9:18.14
2,-7,9:18.13
3,-7,9:18.13
4,-7,9:18.13
5,-7,9:18.13
6,-7,9:18.13
8,-7,9:18.13
9,-7,9:18.13
11,-7,9:18.13
-9,-6,9:18.14
-8,-6,9:18.14
-7,-6,9:18.14
-6,-6,9:18.14
-5,-6,9:18.14
3,-6,9:18.13
4,-6,9:18.13
5,-6,9:18.13
9,-6,9:18.13
10,-6,9:18.13
11,-6,9:18.13
12,-6,9:18.5
-9,-5,9:18.14
-8,-5,9:18.14
-7,-5,9:18.14
-5,-5,9:17.12
-4,-5,9:17.12
3,-5,9:18.5
11,-5,9:18.5
12,-5,9:18.5
-9,-4,9:18.14
-8,-4,9:18.14
-7,-4,9:18.14
-6,-4,9:18.14
-5,-4,9:17.12
-4,-4,9:17.12
-3,-4,9:17.12
2,-4,9:18.5
-11,-3,9:18.14
-10,-3,9:18.14
-9,-3,9:18.14
-8,-3,9:18.14
-7,-3,9:18.14
-6,-3,9:17.12
-5,-3,9:17.12
-4,-3,9:17.12
-3,-3,9:17.12
-5,-2,9:17.12
-4,-2,9:17.12
8,-16,10:18.5
2,-15,10:18.13
6,-15,10:18.13
7,-15,10:18.13
8,-15,10:18.13
9,-15,10:18.13
0,-14,10:18.13
1,-14,10:18.13
2,-14,10:18.13
5,-14,10:18.13
6,-14,10:18.13
7,-14,10:18.13
8,-14,10:18.13
9,-14,10:18.13
-1,-13,10:18.13
0,-13,10:18.13
2,-13,10:18.13
5,-13,10:18.13
6,-13,10:18.13
9,-13,10:18.13
-1,-12,10:18.13
2,-12,10:18.13
3,-12,10:18.13
5,-12,10:18.13
6,-12,10:18.13
7,-12,10:18.13
-4,-11,10:18.13
-3,-11,10:18.13
-2,-11,10:18.13
-1,-11,10:18.13
0,-11,10:18.13
1,-11,10:18.13
2,-11,10:18.13
5,-11,10:18.13
6,-11,10:18.13
7,-11,10:18.13
9,-11,10:18.13
10,-11,10:18.13
-4,-10,10:18.13
-3,-10,10:18.13
-2,-10,10:18.13
-1,-10,10:18.13
0,-10,10:18.13
1,-10,10:18.13
2,-10,10:18.13
5,-10,10:18.13
6,-10,10:18.13
7,-10,10:18.13
9,-10,10:18.13
10,-10,10:18.13
-1,-9,10:18.13
0,-9,10:18.13
1,-9,10:18.13
2,-9,10:18.13
5,-9,10:18.13
6,-9,10:18.13
7,-9,10:18.13
9,-9,10:18.13
10,-9,10:18.13
1,-8,10:18.13
2,-8,10:18.13
4,-8,10:18.13
5,-8,10:18.13
6,-8,10:18.13
7,-8,10:18.13
8,-8,10:18.13
10,-8,10:18.13
-13,-7,10:18.5
-12,-7,10:18.5
-8,-7,10:18.14
-7,-7,10:18.14
-6,-7,10:18.14
1,-7,10:18.13
2,-7,10:18.13
5,-7,10:18.13
8,-7,10:18.13
9,-7,10:18.13
10,-7,10:18.13
11,-7,10:18.13
-14,-6,10:18.5
-13,-6,10:18.5
-12,-6,10:18.5
-8,-6,10:18.14
-7,-6,10:18.14
10,-6,10:18.13
11,-6,10:18.13
-9,-5,10:18.14
-8,-5,10:18.14
-5,-5,10:17.12
-4,-5,10:17.12
-10,-4,10:18.14
-9,-4,10:18.14
-8,-4,10:18.14
-6,-4,10:17.12
-5,-4,10:17.12
-4,-4,10:17.12
-3,-4,10:17.12
-10,-3,10:18.14
-6,-3,10:17.12
-5,-3,10:17.12
-4,-3,10:17.12
-3,-3,10:17.12
-14,-1,10:18.5
-14,0,10:18.5
-13,0,10:18.5
-12,0,10:18.5
3,1,10:18.5
3,2,10:18.5
3,3,10:18.5
-3,5,10:18.5
-2,5,10:18.5
8,-15,11:18.13
9,-15,11:18.13
1,-14,11:18.13
2,-14,11:18.13
7,-14,11:18.13
8,-14,11:18.13
11,-14,11:18.13
1,-13,11:18.13
2,-13,11:18.13
6,-13,11:18.13
7,-13,11:18.13
8,-13,11:18.13
11,-13,11:18.13
-1,-12,11:18.13
0,-12,11:18.13
1,-12,11:18.13
6,-12,11:18.13
11,-12,11:18.13
-2,-11,11:18.13
-1,-11,11:18.13
0,-11,11:18.13
1,-11,11:18.13
2,-11,11:18.13
3,-11,11:18.13
5,-11,11:18.13
6,-11,11:18.13
7,-11,11:18.13
8,-11,11:18.13
-4,-10,11:18.13
-3,-10,11:18.13
-2,-10,11:18.13
-1,-10,11:18.13
0,-10,11:18.13
1,-10,11:18.13
2,-10,11:18.13
3,-10,11:18.13
5,-10,11:18.13
6,-10,11:18.13
7,-10,11:18.13
8,-10,11:18.13
-4,-9,11:18.13
-3,-9,11:18.13
-1,-9,11:18.13
0,-9,11:18.13
1,-9,11:18.13
2,-9,11:18.13
3,-9,11:18.13
5,-9,11:18.13
6,-9,11:18.13
7,-9,11:18.13
9,-9,11:18.13
0,-8,11:18.13
1,-8,11:18.13
7,-8,11:18.13
8,-8,11:18.13
9,-8,11:18.13
10,-8,11:18.13
-7,-7,11:18.14
0,-7,11:18.13
1,-7,11:18.13
6,-7,11:18.13
9,-7,11:18.13
10,-7,11:18.13
-12,-6,11:18.5
-11,-6,11:18.5
-10,-6,11:18.14
-9,-6,11:18.14
-8,-6,11:18.14
7,-6,11:18.13
10,-6,11:18.13
-17,-5,11:18.5
-16,-5,11:18.5
-15,-5,11:18.5
-14,-5,11:18.5
-13,-5,11:18.5
-12,-5,11:18.5
-10,-5,11:18.14
-9,-5,11:18.14
-8,-5,11:18.14
-7,-5,11:18.14
-5,-5,11:17.12
-4,-5,11:17.12
8,-5,11:18.5
10,-5,11:18.5
-17,-4,11:18.5
-16,-4,11:18.5
-15,-4,11:18.5
-14,-4,11:18.5
-9,-4,11:18.14
-6,-4,11:17.12
-5,-4,11:17.12
-4,-4,11:17.12
-3,-4,11:17.12
8,-4,11:18.5
-17,-3,11:18.5
-5,-3,11:17.12
-4,-3,11:17.12
-3,-3,11:17.12
-17,-2,11:18.5
-16,-2,11:18.5
-15,-2,11:18.5
-14,-2,11:18.5
-13,-2,11:18.5
-15,-1,11:18.5
-14,-1,11:18.5
-13,-1,11:18.5
-12,-1,11:18.5
-12,0,11:18.5
2,1,11:18.5
1,2,11:18.5
2,2,11:18.5
-3,3,11:18.5
2,3,11:18.5
3,3,11:18.5
-3,4,11:18.5
-1,4,11:18.5
2,4,11:18.5
3,4,11:18.5
-2,5,11:18.5
-1,5,11:18.5
0,5,11:18.5
3,5,11:18.5
0,6,11:18.5
1,6,11:18.5
8,-15,12:18.13
9,-15,12:18.13
10,-15,12:18.13
11,-15,12:18.13
1,-14,12:18.13
2,-14,12:18.13
8,-14,12:18.13
9,-14,12:18.13
10,-14,12:18.13
11,-14,12:18.13
0,-13,12:18.13
1,-13,12:18.13
2,-13,12:18.13
7,-13,12:18.13
10,-13,12:18.13
11,-13,12:18.13
-5,-12,12:18.13
0,-12,12:18.13
1,-12,12:18.13
6,-12,12:18.13
7,-12,12:18.13
8,-12,12:18.13
10,-12,12:18.13
-5,-11,12:18.13
-2,-11,12:18.13
-1,-11,12:18.13
0,-11,12:18.13
1,-11,12:18.13
4,-11,12:18.13
5,-11,12:18.13
6,-11,12:18.13
7,-11,12:18.13
-11,-10,12:18.5
-2,-10,12:18.13
-1,-10,12:18.13
0,-10,12:18.13
1,-10,12:18.13
3,-10,12:18.13
4,-10,12:18.13
5,-10,12:18.13
6,-10,12:18.13
7,-10,12:18.13
8,-10,12:18.13
-11,-9,12:18.5
-3,-9,12:18.13
-2,-9,12:18.13
-1,-9,12:18.13
0,-9,12:18.13
4,-9,12:18.13
6,-9,12:18.13
7,-9,12:18.13
8,-9,12:18.13
-4,-8,12:18.13
-3,-8,12:18.13
-1,-8,12:18.13
0,-8,12:18.13
8,-8,12:18.13
9,-8,12:18.13
-1,-7,12:18.13
0,-7,12:18.13
6,-7,12:18.13
7,-7,12:18.13
9,-7,12:18.13
-10,-6,12:18.14
-9,-6,12:18.14
-8,-6,12:18.14
0,-6,12:18.13
2,-6,12:18.13
3,-6,12:18.13
7,-6,12:18.13
9,-6,12:18.13
-12,-5,12:18.5
-11,-5,12:18.5
-10,-5,12:18.13
-8,-5,12:18.14
-5,-5,12:17.12
-4,-5,12:17.12
4,-5,12:18.5
8,-5,12:18.5
-17,-4,12:18.5
-16,-4,12:18.5
-15,-4,12:18.5
-14,-4,12:18.5
-13,-4,12:18.5
-12,-4,12:18.5
-11,-4,12:18.5
-6,-4,12:17.12
-5,-4,12:17.12
-4,-4,12:17.12
8,-4,12:18.5
9,-4,12:18.5
-17,-3,12:18.5
-16,-3,12:18.5
-15,-3,12:18.5
-13,-3,12:18.5
-12,-3,12:18.5
-5,-3,12:17.12
-4,-3,12:17.12
-3,-3,12:17.12
9,-3,12:18.5
-14,-2,12:18.5
-13,-2,12:18.5
-12,-2,12:18.5
-11,-2,12:18.5
-12,-1,12:18.5
-11,-1,12:18.5
1,0,12:18.13
-11,1,12:18.5
0,1,12:18.13
1,1,12:18.13
-3,2,12:18.13
-2,2,12:18.13
-1,2,12:18.13
0,2,12:18.13
1,2,12:18.5
-3,3,12:18.5
-2,3,12:18.5
-1,3,12:18.5
0,3,12:18.5
1,3,12:18.5
-1,4,12:18.5
0,4,12:18.5
1,4,12:18.5
2,4,12:18.5
0,5,12:18.5
1,5,12:18.5
2,5,12:18.5
2,6,12:18.5
-9,-14,13:18.5
-8,-14,13:18.5
8,-14,13:18.13
9,-14,13:18.13
10,-14,13:18.13
-10,-13,13:18.5
-8,-13,13:18.5
-7,-13,13:18.5
1,-13,13:18.13
2,-13,13:18.13
8,-13,13:18.13
9,-13,13:18.13
10,-13,13:18.13
-11,-12,13:18.5
-10,-12,13:18.5
-7,-12,13:18.5
-6,-12,13:18.13
1,-12,13:18.13
2,-12,13:18.13
3,-12,13:18.13
7,-12,13:18.13
9,-12,13:18.13
10,-12,13:18.13
-11,-11,13:18.5
-10,-11,13:18.5
-7,-11,13:18.5
-6,-11,13:18.13
-5,-11,13:18.13
-1,-11,13:18.13
1,-11,13:18.13
2,-11,13:18.13
5,-11,13:18.13
6,-11,13:18.13
7,-11,13:18.13
8,-11,13:18.13
-11,-10,13:18.5
-10,-10,13:18.5
-5,-10,13:18.13
-1,-10,13:18.13
0,-10,13:18.13
3,-10,13:18.13
5,-10,13:18.13
6,-10,13:18.13
7,-10,13:18.13
-10,-9,13:18.5
-2,-9,13:18.13
6,-9,13:18.13
7,-9,13:18.13
8,-9,13:18.13
-10,-8,13:18.13
-3,-8,13:18.13
-2,-8,13:18.13
-1,-8,13:18.13
6,-8,13:18.13
7,-8,13:18.13
8,-8,13:18.13
9,-8,13:18.13
-4,-7,13:18.13
-2,-7,13:18.13
-1,-7,13:18.13
4,-7,13:18.13
5,-7,13:18.13
7,-7,13:18.13
8,-7,13:18.13
9,-7,13:18.13
-9,-6,13:18.14
-8,-6,13:18.14
-1,-6,13:18.13
2,-6,13:18.13
7,-6,13:18.13
8,-6,13:18.13
9,-6,13:18.13
-10,-5,13:18.13
-9,-5,13:18.13
-7,-5,13:18.13
-6,-5,13:18.13
-5,-5,13:18.13
-4,-5,13:17.12
2,-5,13:18.5
3,-5,13:18.5
4,-5,13:18.5
8,-5,13:18.5
-11,-4,13:18.5
-10,-4,13:18.13
-7,-4,13:18.13
-6,-4,13:18.13
-5,-4,13:17.12
-4,-4,13:17.12
3,-4,13:18.5
4,-4,13:18.5
5,-4,13:18.5
6,-4,13:18.5
-12,-3,13:18.5
-11,-3,13:18.5
-10,-3,13:18.13
-6,-3,13:18.13
-5,-3,13:17.12
-4,-3,13:17.12
6,-3,13:18.5
7,-3,13:18.5
-11,-2,13:18.5
-10,-2,13:18.13
-5,-2,13:18.13
6,-2,13:18.5
7,-2,13:18.5
2,-1,13:18.5
3,-1,13:18.5
4,-1,13:18.5
5,-1,13:18.5
6,-1,13:18.5
-1,0,13:18.13
0,0,13:18.13
1,0,13:18.13
2,0,13:18.5
3,0,13:18.5
-11,1,13:18.5
-10,1,13:18.13
-3,1,13:18.13
-2,1,13:18.13
-1,1,13:18.13
0,1,13:18.13
-11,2,13:18.5
-10,2,13:18.5
-3,2,13:18.13
-2,2,13:18.13
-1,2,13:18.13
0,2,13:18.13
-10,3,13:18.5
0,3,13:18.5
-10,4,13:18.5
-6,4,13:18.5
-5,4,13:18.5
-7,5,13:18.5
-6,5,13:18.5
-5,5,13:18.5
-8,6,13:18.5
-7,6,13:18.5
-6,6,13:18.5
6,-16,14:18.5
8,-16,14:18.5
5,-15,14:18.13
8,-15,14:18.13
-10,-14,14:18.5
-9,-14,14:18.5
-3,-14,14:18.13
-2,-14,14:18.13
-1,-14,14:18.13
-10,-13,14:18.5
-9,-13,14:18.5
-8,-13,14:18.5
-4,-13,14:18.13
-3,-13,14:18.13
-2,-13,14:18.13
1,-13,14:18.13
8,-13,14:18.13
9,-13,14:18.13
-10,-12,14:18.5
-9,-12,14:18.5
-8,-12,14:18.5
2,-12,14:18.13
3,-12,14:18.13
4,-12,14:18.13
7,-12,14:18.13
8,-12,14:18.13
9,-12,14:18.13
-9,-11,14:18.5
-8,-11,14:18.5
-7,-11,14:18.5
-1,-11,14:18.13
2,-11,14:18.13
3,-11,14:18.13
4,-11,14:18.13
5,-11,14:18.13
6,-11,14:18.13
7,-11,14:18.13
8,-11,14:18.13
-9,-10,14:18.5
-8,-10,14:18.5
-7,-10,14:18.5
-6,-10,14:18.13
-5,-10,14:18.13
-1,-10,14:18.13
3,-10,14:18.13
4,-10,14:18.13
5,-10,14:18.13
6,-10,14:18.13
7,-10,14:18.13
-9,-9,14:18.13
-6,-9,14:18.13
-5,-9,14:18.13
3,-9,14:18.13
6,-9,14:18.13
7,-9,14:18.13
8,-9,14:18.13
10,-9,14:18.13
11,-9,14:18.13
-9,-8,14:18.13
2,-8,14:18.13
7,-8,14:18.13
8,-8,14:18.13
11,-8,14:18.13
-4,-7,14:18.13
-3,-7,14:18.13
-2,-7,14:18.13
1,-7,14:18.13
2,-7,14:18.13
3,-7,14:18.13
4,-7,14:18.13
5,-7,14:18.13
7,-7,14:18.13
8,-7,14:18.13
9,-7,14:18.13
10,-7,14:18.13
11,-7,14:18.13
-4,-6,14:18.13
-3,-6,14:18.13
-2,-6,14:18.13
1,-6,14:18.13
8,-6,14:18.13
-9,-5,14:18.13
-8,-5,14:18.13
-6,-5,14:18.13
-5,-5,14:18.13
-4,-5,14:18.13
-3,-5,14:18.13
-2,-5,14:18.13
1,-5,14:18.13
2,-5,14:18.5
-11,-4,14:18.5
-10,-4,14:18.13
-9,-4,14:18.13
-8,-4,14:18.13
-7,-4,14:18.13
-6,-4,14:18.13
-5,-4,14:17.12
-4,-4,14:17.12
-3,-4,14:18.13
1,-4,14:18.13
2,-4,14:18.5
3,-4,14:18.5
4,-4,14:18.5
-13,-3,14:18.5
-12,-3,14:18.5
-10,-3,14:18.13
-9,-3,14:18.13
-6,-3,14:18.13
-5,-3,14:17.12
-4,-3,14:17.12
-3,-3,14:18.13
2,-3,14:18.5
3,-3,14:18.5
4,-3,14:18.5
5,-3,14:18.5
6,-3,14:18.5
-15,-2,14:18.5
-14,-2,14:18.5
-9,-2,14:18.13
-8,-2,14:18.13
-5,-2,14:18.13
-4,-2,14:18.13
-3,-2,14:18.13
1,-2,14:18.13
2,-2,14:18.5
3,-2,14:18.5
4,-2,14:18.5
5,-2,14:18.5
6,-2,14:18.5
7,-2,14:18.5
-4,-1,14:18.13
-2,-1,14:18.13
-1,-1,14:18.13
1,-1,14:18.13
2,-1,14:18.5
3,-1,14:18.5
-14,0,14:18.5
-13,0,14:18.5
-9,0,14:18.13
-4,0,14:18.13
-2,0,14:18.13
-1,0,14:18.13
1,0,14:18.13
3,0,14:18.5
-13,1,14:18.5
-12,1,14:18.5
-11,1,14:18.5
-10,1,14:18.13
-9,1,14:18.13
-8,1,14:18.13
-3,1,14:18.13
-2,1,14:18.13
3,1,14:18.5
-9,2,14:18.5
-8,2,14:18.5
3,2,14:18.5
-10,3,14:18.5
-9,3,14:18.5
-7,3,14:18.5
-6,3,14:18.5
-5,3,14:18.5
3,3,14:18.5
-10,4,14:18.5
-9,4,14:18.5
-8,4,14:18.5
-7,4,14:18.5
-6,4,14:18.5
-1,4,14:18.5
1,4,14:18.5
-10,5,14:18.5
-9,5,14:18.5
-8,5,14:18.5
-7,5,14:18.5
-10,6,14:18.5
-9,6,14:18.5
-8,6,14:18.5
7,-16,15:18.5
6,-15,15:18.13
7,-15,15:18.13
8,-15,15:18.13
5,-14,15:18.13
6,-14,15:18.13
7,-14,15:18.13
8,-14,15:18.13
-2,-13,15:18.13
-1,-13,15:18.13
0,-13,15:18.13
1,-13,15:18.13
-4,-12,15:18.13
-3,-12,15:18.13
1,-12,15:18.13
7,-12,15:18.13
8,-12,15:18.13
1,-11,15:18.13
4,-11,15:18.13
5,-11,15:18.13
6,-11,15:18.13
7,-11,15:18.13
8,-11,15:18.13
-8,-10,15:18.5
-1,-10,15:18.13
1,-10,15:18.13
4,-10,15:18.13
5,-10,15:18.13
6,-10,15:18.13
7,-10,15:18.13
-8,-9,15:18.13
-7,-9,15:18.13
-6,-9,15:18.13
-5,-9,15:18.13
3,-9,15:18.13
4,-9,15:18.13
6,-9,15:18.13
7,-9,15:18.13
9,-9,15:18.13
10,-9,15:18.13
-8,-8,15:18.13
-6,-8,15:18.13
-5,-8,15:18.13
2,-8,15:18.13
3,-8,15:18.13
4,-8,15:18.13
5,-8,15:18.13
7,-8,15:18.13
8,-8,15:18.13
9,-8,15:18.13
10,-8,15:18.13
-8,-7,15:18.13
2,-7,15:18.13
3,-7,15:18.13
-4,-6,15:18.13
-3,-6,15:18.13
-9,-5,15:18.13
-6,-5,15:18.13
-5,-5,15:18.13
-4,-5,15:18.13
-3,-5,15:18.13
0,-5,15:18.13
-11,-4,15:18.5
-10,-4,15:18.13
-9,-4,15:18.13
-8,-4,15:18.13
-7,-4,15:18.13
-6,-4,15:18.13
-5,-4,15:17.12
-4,-4,15:17.12
-3,-4,15:18.13
0,-4,15:18.13
1,-4,15:18.13
-12,-3,15:18.5
-11,-3,15:18.5
-8,-3,15:18.13
-7,-3,15:18.13
-6,-3,15:18.13
-5,-3,15:17.12
-4,-3,15:17.12
-3,-3,15:18.13
1,-3,15:18.13
2,-3,15:18.5
-14,-2,15:18.5
-13,-2,15:18.5
-7,-2,15:18.13
-5,-2,15:18.13
-4,-2,15:18.13
-3,-2,15:18.13
-2,-2,15:18.13
0,-2,15:18.13
1,-2,15:18.13
2,-2,15:18.5
-16,-1,15:18.5
-15,-1,15:18.5
-14,-1,15:18.5
-4,-1,15:18.13
-3,-1,15:18.13
-2,-1,15:18.13
0,-1,15:18.13
2,-1,15:18.5
-15,0,15:18.5
-14,0,15:18.5
-13,0,15:18.5
-12,0,15:18.5
-11,0,15:18.5
-10,0,15:18.13
-9,0,15:18.13
-8,0,15:18.13
2,0,15:18.5
-9,1,15:18.13
-8,1,15:18.13
-7,1,15:18.13
2,1,15:18.5
3,1,15:18.5
-8,2,15:18.5
-7,2,15:18.5
-6,2,15:18.5
2,2,15:18.5
3,2,15:18.5
-8,3,15:18.5
-7,3,15:18.5
-2,3,15:18.5
-1,3,15:18.5
0,3,15:18.5
1,3,15:18.5
2,3,15:18.5
3,3,15:18.5
-9,4,15:18.5
-8,4,15:18.5
-1,4,15:18.5
0,4,15:18.5
1,4,15:18.5
2,4,15:18.5
3,4,15:18.5
6,-14,16:18.13
7,-14,16:18.13
9,-14,16:18.13
10,-14,16:18.13
0,-13,16:18.13
2,-13,16:18.13
6,-13,16:18.13
7,-13,16:18.13
10,-13,16:18.13
-1,-12,16:18.13
0,-12,16:18.13
10,-12,16:18.13
-4,-11,16:18.13
-3,-11,16:18.13
-2,-11,16:18.13
0,-11,16:18.13
1,-11,16:18.13
2,-11,16:18.13
6,-11,16:17.12
7,-11,16:18.13
10,-11,16:18.13
-2,-10,16:17.12
0,-10,16:18.13
1,-10,16:18.13
5,-10,16:18.13
6,-10,16:18.13
7,-10,16:17.12
8,-10,16:18.13
0,-9,16:18.13
4,-9,16:18.13
5,-9,16:18.13
6,-9,16:18.13
7,-9,16:18.13
8,-9,16:18.13
9,-9,16:18.13
-7,-8,16:18.13
-6,-8,16:18.13
-5,-8,16:18.13
3,-8,16:18.13
4,-8,16:18.13
5,-8,16:18.13
6,-8,16:18.13
8,-8,16:18.13
9,-8,16:18.13
-7,-7,16:18.13
-6,-7,16:18.13
-5,-7,16:18.13
6,-7,16:18.13
8,-7,16:18.13
9,-7,16:18.13
-7,-6,16:18.13
6,-6,16:18.13
7,-6,16:18.13
8,-6,16:18.13
-6,-5,16:18.13
-5,-5,16:18.13
-4,-5,16:18.13
-3,-5,16:18.13
-2,-5,16:18.13
-1,-5,16:18.13
7,-5,16:18.5
8,-5,16:18.5
-10,-4,16:18.13
-9,-4,16:18.13
-8,-4,16:18.13
-6,-4,16:18.13
-5,-4,16:17.12
-4,-4,16:18.13
-3,-4,16:18.13
-1,-4,16:18.13
0,-4,16:18.13
-12,-3,16:18.5
-11,-3,16:18.5
-10,-3,16:18.13
-7,-3,16:18.13
-6,-3,16:18.13
-5,-3,16:18.13
-4,-3,16:18.13
-3,-3,16:18.13
-1,-3,16:18.13
0,-3,16:18.13
1,-3,16:18.13
-14,-2,16:18.5
-13,-2,16:18.5
-12,-2,16:18.5
-5,-2,16:18.13
-4,-2,16:18.13
-3,-2,16:18.13
-2,-2,16:18.13
-1,-2,16:18.13
0,-2,16:18.13
-15,-1,16:18.5
-14,-1,16:18.5
-13,-1,16:18.5
-12,-1,16:18.5
-11,-1,16:18.5
-10,-1,16:18.13
-9,-1,16:18.13
-8,-1,16:18.13
-7,-1,16:18.13
1,-1,16:18.13
-12,0,16:18.5
-11,0,16:18.5
-10,0,16:18.13
-9,0,16:18.13
-8,0,16:18.13
-7,0,16:18.13
-6,0,16:18.13
-5,0,16:18.13
1,0,16:18.13
2,0,16:18.5
-7,1,16:18.13
-6,1,16:18.13
-5,1,16:18.13
1,1,16:18.13
2,1,16:18.5
-3,2,16:18.5
-2,2,16:18.5
-1,2,16:18.5
0,2,16:18.5
1,2,16:18.5
2,2,16:18.5
-1,3,16:18.5
0,3,16:18.5
1,3,16:18.5
2,3,16:18.5
2,-13,17:18.13
4,-13,17:18.13
8,-13,17:18.13
9,-13,17:18.13
10,-13,17:18.13
2,-12,17:18.13
3,-12,17:18.13
6,-12,17:18.13
7,-12,17:18.13
9,-12,17:18.13
10,-12,17:18.13
-2,-11,17:18.13
-1,-11,17:18.13
2,-11,17:18.13
3,-11,17:18.13
6,-11,17:18.13
7,-11,17:18.13
9,-11,17:18.13
-3,-10,17:18.13
-2,-10,17:18.13
-1,-10,17:18.13
0,-10,17:18.13
5,-10,17:18.13
6,-10,17:18.13
7,-10,17:17.12
8,-10,17:18.13
-1,-9,17:18.13
0,-9,17:18.13
4,-9,17:18.13
5,-9,17:18.13
6,-9,17:18.13
7,-9,17:18.13
8,-9,17:18.13
6,-8,17:18.13
8,-8,17:18.13
-10,-7,17:18.5
-9,-7,17:18.13
-8,-7,17:18.13
-6,-7,17:18.13
-5,-7,17:18.13
6,-7,17:18.13
7,-7,17:18.13
8,-7,17:18.13
-7,-6,17:18.13
-6,-6,17:18.13
-5,-6,17:18.13
-4,-6,17:18.13
7,-6,17:18.13
8,-6,17:18.13
-7,-5,17:18.13
-6,-5,17:18.13
-5,-5,17:18.13
-4,-5,17:18.13
-3,-5,17:18.13
7,-5,17:18.5
-9,-4,17:18.13
-8,-4,17:18.13
-6,-4,17:18.13
-5,-4,17:17.12
-4,-4,17:17.12
-3,-4,17:18.13
-2,-4,17:18.13
-1,-4,17:18.13
-11,-3,17:18.5
-10,-3,17:18.5
-9,-3,17:18.13
-6,-3,17:18.13
-5,-3,17:18.13
-4,-3,17:18.13
-3,-3,17:18.13
-2,-3,17:18.13
-1,-3,17:18.13
-13,-2,17:18.5
-12,-2,17:18.5
-11,-2,17:18.5
-6,-2,17:18.13
-4,-2,17:18.13
-2,-2,17:18.13
-13,-1,17:18.5
-12,-1,17:18.5
-11,-1,17:18.5
-10,-1,17:18.5
-9,-1,17:18.13
-8,-1,17:18.13
-7,-1,17:18.13
-6,-1,17:18.13
-5,-1,17:18.13
0,-1,17:18.13
-6,0,17:18.13
-5,0,17:18.13
0,0,17:18.13
1,0,17:18.5
-3,1,17:18.13
-2,1,17:18.13
-1,1,17:18.13
0,1,17:18.13
1,1,17:18.5
-1,2,17:18.5
0,2,17:18.5
1,2,17:18.5
5,-15,18:18.13
7,-15,18:18.13
-1,-12,18:18.13
0,-12,18:18.13
1,-12,18:18.13
2,-12,18:18.13
3,-12,18:18.13
4,-12,18:18.13
7,-12,18:18.13
8,-12,18:18.13
9,-12,18:18.13
3,-11,18:18.13
4,-11,18:18.13
6,-11,18:18.13
8,-11,18:18.13
9,-11,18:18.13
-2,-10,18:18.13
-1,-10,18:18.13
4,-10,18:18.13
6,-10,18:17.12
7,-10,18:17.12
10,-10,18:18.13
-4,-9,18:18.13
-3,-9,18:18.13
-2,-9,18:18.13
-1,-9,18:18.13
3,-9,18:18.13
4,-9,18:18.13
6,-9,18:18.13
7,-9,18:18.13
11,-9,18:18.13
-4,-8,18:18.13
-2,-8,18:18.13
-1,-8,18:18.13
3,-8,18:18.13
4,-8,18:18.13
6,-8,18:18.13
7,-8,18:18.13
9,-8,18:18.13
10,-8,18:18.13
11,-8,18:18.13
-10,-7,18:18.5
-9,-7,18:18.13
-8,-7,18:18.13
2,-7,18:18.13
3,-7,18:18.13
4,-7,18:18.13
5,-7,18:18.13
6,-7,18:18.13
7,-7,18:18.13
9,-7,18:18.13
-15,-6,18:18.5
-14,-6,18:18.5
-13,-6,18:18.5
-12,-6,18:18.5
-11,-6,18:18.5
-10,-6,18:18.5
-6,-6,18:18.13
-5,-6,18:18.13
2,-6,18:18.13
3,-6,18:18.13
4,-6,18:18.13
-6,-5,18:18.13
-5,-5,18:18.13
-4,-5,18:18.13
-3,-5,18:18.13
-15,-4,18:18.5
-14,-4,18:18.5
-8,-4,18:18.13
-7,-4,18:18.13
-6,-4,18:18.13
-5,-4,18:18.13
-4,-4,18:18.13
-3,-4,18:18.13
-2,-4,18:18.13
-13,-3,18:18.5
-12,-3,18:18.5
-10,-3,18:18.5
-9,-3,18:18.13
-6,-3,18:18.13
-5,-3,18:18.13
-4,-3,18:18.13
-3,-3,18:18.13
-12,-2,18:18.5
-11,-2,18:18.5
-10,-2,18:18.5
-9,-2,18:18.13
-8,-2,18:18.13
-7,-2,18:18.13
-6,-2,18:18.13
-5,-2,18:18.13
-4,-2,18:18.13
-1,-2,18:18.13
-11,-1,18:18.5
-10,-1,18:18.5
-7,-1,18:18.13
-1,-1,18:18.13
0,-1,18:18.13
-2,0,18:18.13
-1,0,18:18.13
0,0,18:18.13
-1,1,18:18.13
0,1,18:18.13
0,3,18:18.5
1,3,18:18.5
-5,4,18:18.5
-4,4,18:18.5
0,4,18:18.5
-3,5,18:18.5
0,5,18:18.5
5,-15,19:18.13
6,-15,19:18.13
7,-15,19:18.13
5,-14,19:18.13
6,-14,19:18.13
7,-14,19:18.13
5,-13,19:18.13
-1,-11,19:18.13
0,-11,19:18.13
1,-11,19:18.13
2,-11,19:18.13
3,-11,19:18.13
4,-11,19:18.13
5,-11,19:18.13
6,-11,19:17.12
7,-11,19:18.13
8,-11,19:18.13
3,-10,19:18.13
4,-10,19:18.13
5,-10,19:18.13
6,-10,19:17.12
7,-10,19:17.12
9,-10,19:18.13
10,-10,19:18.13
3,-9,19:18.13
4,-9,19:18.13
6,-9,19:18.13
7,-9,19:18.13
9,-9,19:18.13
10,-9,19:18.13
-4,-8,19:18.13
-3,-8,19:18.13
-2,-8,19:18.13
3,-8,19:18.13
4,-8,19:18.13
5,-8,19:18.13
7,-8,19:18.13
8,-8,19:18.13
9,-8,19:18.13
10,-8,19:18.13
-4,-7,19:18.13
-3,-7,19:18.13
-2,-7,19:18.13
2,-7,19:18.13
3,-7,19:18.13
4,-7,19:18.13
5,-7,19:18.13
-16,-6,19:18.5
-15,-6,19:18.5
-14,-6,19:18.5
-13,-6,19:18.5
-12,-6,19:18.5
-11,-6,19:18.5
-10,-6,19:18.5
-9,-6,19:18.13
-8,-6,19:18.13
-6,-6,19:18.13
-5,-6,19:18.13
2,-6,19:18.13
-16,-5,19:18.5
-15,-5,19:18.5
-14,-5,19:18.5
-6,-5,19:18.13
-5,-5,19:17.12
-4,-5,19:18.13
-3,-5,19:18.13
-14,-4,19:18.5
-13,-4,19:18.5
-8,-4,19:18.13
-7,-4,19:18.13
-6,-4,19:18.13
-5,-4,19:18.13
-4,-4,19:18.13
-3,-4,19:18.13
-2,-4,19:18.13
-13,-3,19:18.5
-12,-3,19:18.5
-11,-3,19:18.5
-10,-3,19:18.5
-9,-3,19:18.13
-8,-3,19:18.13
-7,-3,19:18.13
-6,-3,19:18.13
-5,-3,19:17.12
-4,-3,19:18.13
-3,-3,19:18.13
-2,-3,19:18.13
-11,-2,19:18.5
-10,-2,19:18.5
-9,-2,19:18.13
-8,-2,19:18.13
-7,-2,19:18.13
-6,-2,19:18.13
-5,-2,19:18.13
-2,-2,19:18.13
-1,-2,19:18.13
-3,-1,19:18.13
-2,-1,19:18.13
-1,-1,19:18.13
0,1,19:18.13
0,2,19:18.5
-5,3,19:18.5
-4,3,19:18.5
-1,3,19:18.5
0,3,19:18.5
-4,4,19:18.5
-3,4,19:18.5
-1,4,19:18.5
0,4,19:18.5
-3,5,19:18.5
-2,5,19:18.5
-1,5,19:18.5
-1,6,19:18.5
6,-14,20:18.13
5,-13,20:18.13
6,-13,20:18.13
7,-13,20:18.13
6,-12,20:18.13
5,-11,20:18.13
6,-11,20:18.13
7,-11,20:18.13
-1,-10,20:18.13
0,-10,20:18.13
1,-10,20:18.13
2,-10,20:18.13
3,-10,20:18.13
5,-10,20:18.13
6,-10,20:17.12
7,-10,20:17.12
8,-10,20:18.13
9,-10,20:18.13
2,-9,20:18.13
3,-9,20:18.13
4,-9,20:18.13
5,-9,20:18.13
6,-9,20:18.13
7,-9,20:18.13
8,-9,20:18.13
9,-9,20:18.13
2,-8,20:18.13
3,-8,20:18.13
4,-8,20:18.13
5,-8,20:18.13
-4,-7,20:18.13
-3,-7,20:18.13
2,-7,20:18.13
3,-7,20:18.13
-13,-6,20:18.5
-12,-6,20:18.5
-11,-6,20:18.5
-10,-6,20:18.5
-9,-6,20:18.13
-8,-6,20:18.13
-5,-6,20:18.13
-4,-6,20:18.13
-3,-6,20:18.13
-15,-5,20:18.5
-14,-5,20:18.5
-13,-5,20:18.5
-12,-5,20:18.5
-7,-5,20:18.13
-6,-5,20:18.13
-5,-5,20:18.13
-4,-5,20:18.13
-3,-5,20:18.13
-13,-4,20:18.5
-12,-4,20:18.5
-11,-4,20:18.5
-7,-4,20:18.13
-6,-4,20:18.13
-5,-4,20:18.13
-4,-4,20:18.13
-3,-4,20:18.13
-11,-3,20:18.5
-10,-3,20:18.5
-9,-3,20:18.13
-8,-3,20:18.13
-7,-3,20:18.13
-6,-3,20:18.13
-5,-3,20:18.13
-4,-3,20:18.13
-3,-3,20:18.13
-2,-3,20:18.13
-10,-2,20:18.5
-9,-2,20:18.13
-5,-2,20:18.13
-3,-2,20:18.13
-2,-2,20:18.13
-1,1,20:18.13
0,1,20:18.5
-5,2,20:18.5
-4,2,20:18.5
-1,2,20:18.5
-4,3,20:18.5
-3,3,20:18.5
-2,3,20:18.5
-1,3,20:18.5
-3,4,20:18.5
-1,4,20:18.5
4,-13,21:18.13
5,-13,21:18.13
-7,-12,21:18.5
-4,-12,21:18.5
3,-12,21:18.13
6,-12,21:18.13
7,-12,21:18.13
8,-12,21:18.13
9,-12,21:18.13
10,-12,21:18.13
11,-12,21:18.13
-7,-11,21:18.5
3,-11,21:18.13
6,-11,21:18.13
7,-11,21:18.13
9,-11,21:18.13
10,-11,21:18.13
-8,-10,21:18.5
-7,-10,21:18.5
-3,-10,21:18.5
5,-10,21:18.13
6,-10,21:17.12
7,-10,21:18.13
8,-10,21:18.13
9,-10,21:18.13
-8,-9,21:18.13
-3,-9,21:18.13
-2,-9,21:18.13
-1,-9,21:18.13
0,-9,21:18.5
1,-9,21:18.5
2,-9,21:18.13
5,-9,21:18.13
6,-9,21:18.13
7,-9,21:18.13
8,-9,21:18.13
-8,-8,21:18.13
-3,-8,21:18.13
1,-8,21:18.5
2,-8,21:18.13
1,-7,21:18.5
4,-7,21:18.13
-10,-6,21:18.5
-9,-6,21:18.13
-8,-6,21:18.13
-7,-6,21:18.13
-4,-6,21:18.13
-3,-6,21:18.13
4,-6,21:18.13
5,-6,21:18.13
6,-6,21:18.13
-13,-5,21:18.5
-12,-5,21:18.5
-11,-5,21:18.5
-10,-5,21:18.5
-9,-5,21:18.13
-7,-5,21:18.13
-6,-5,21:18.13
-5,-5,21:18.13
-4,-5,21:18.13
-3,-5,21:18.13
-11,-4,21:18.5
-10,-4,21:18.5
-6,-4,21:18.13
-5,-4,21:18.13
-4,-4,21:18.13
-3,-4,21:18.13
-10,-3,21:18.5
-9,-3,21:18.13
-6,-3,21:18.13
-5,-3,21:18.13
-4,-3,21:18.13
-3,-3,21:18.13
-5,-2,21:18.13
-4,-2,21:18.13
-2,0,21:18.13
-1,0,21:18.13
-5,1,21:18.13
-4,1,21:18.13
-2,1,21:18.13
-1,1,21:18.13
-4,2,21:18.5
-3,2,21:18.5
-2,2,21:18.5
-2,3,21:18.5
-5,-14,22:18.5
-6,-13,22:18.5
-5,-13,22:18.5
-7,-12,22:18.5
-6,-12,22:18.5
-5,-12,22:18.5
-4,-12,22:18.5
3,-12,22:18.13
4,-12,22:18.13
5,-12,22:18.13
8,-12,22:18.13
9,-12,22:18.13
10,-12,22:18.13
-7,-11,22:18.5
-6,-11,22:18.5
-4,-11,22:18.5
4,-11,22:18.13
6,-11,22:18.13
7,-11,22:18.13
8,-11,22:18.13
9,-11,22:18.13
10,-11,22:18.13
-7,-10,22:18.5
-4,-10,22:18.5
5,-10,22:18.13
6,-10,22:18.13
7,-10,22:18.13
8,-10,22:18.13
-8,-9,22:18.13
-7,-9,22:18.13
-3,-9,22:18.13
5,-9,22:18.13
6,-9,22:18.13
7,-9,22:18.13
-8,-8,22:18.13
-7,-8,22:18.13
-3,-8,22:18.13
-2,-8,22:18.13
-1,-8,22:18.13
0,-8,22:18.5
6,-8,22:18.13
0,-7,22:18.5
4,-7,22:18.13
5,-7,22:18.13
6,-7,22:18.13
-4,-6,22:18.13
-3,-6,22:18.13
0,-6,22:18.5
5,-6,22:18.13
-11,-5,22:18.5
-10,-5,22:18.5
-9,-5,22:18.13
-8,-5,22:18.13
-7,-5,22:18.13
-6,-5,22:18.13
-5,-5,22:18.13
-4,-5,22:18.13
-3,-5,22:18.13
-11,-4,22:18.5
-10,-4,22:18.5
-9,-4,22:18.13
-8,-4,22:18.13
-6,-4,22:18.13
-5,-4,22:18.13
-4,-4,22:18.13
-3,-4,22:18.13
-11,-3,22:18.5
-8,-3,22:18.13
-7,-3,22:18.13
-5,-3,22:18.13
-4,-3,22:18.13
-11,-2,22:18.5
-5,-2,22:18.13
-4,-2,22:18.13
3,-2,22:18.5
-12,-1,22:18.5
-11,-1,22:18.5
-2,-1,22:18.13
3,-1,22:18.5
-12,0,22:18.5
-11,0,22:18.5
-5,0,22:18.13
-4,0,22:18.13
-2,0,22:18.13
-11,1,22:18.5
-10,1,22:18.5
-9,1,22:18.13
-8,1,22:18.13
-4,1,22:18.13
-3,1,22:18.13
-2,1,22:18.13
0,2,22:18.5
-6,-13,23:18.5
-5,-13,23:18.5
-6,-12,23:18.5
-5,-12,23:18.5
4,-12,23:18.13
5,-12,23:18.13
-6,-11,23:18.5
-5,-11,23:18.5
-4,-11,23:18.5
4,-11,23:18.13
5,-11,23:18.13
6,-11,23:18.13
7,-11,23:18.13
8,-11,23:18.13
9,-11,23:18.13
-7,-10,23:18.5
-6,-10,23:18.5
-4,-10,23:18.5
5,-10,23:18.13
6,-10,23:18.13
7,-10,23:18.13
8,-10,23:18.13
-7,-9,23:18.13
-6,-9,23:18.13
-4,-9,23:18.13
6,-9,23:18.13
7,-9,23:18.13
-7,-8,23:18.13
-4,-8,23:18.13
-3,-8,23:18.13
5,-8,23:18.13
6,-8,23:18.13
-3,-7,23:18.13
-2,-7,23:18.13
-1,-7,23:18.13
5,-7,23:18.13
6,-7,23:18.13
-2,-6,23:18.13
-1,-6,23:18.13
-9,-5,23:18.13
-8,-5,23:18.13
-7,-5,23:18.13
-6,-5,23:18.13
-5,-5,23:18.13
-4,-5,23:18.13
-3,-5,23:18.13
-10,-4,23:18.5
-9,-4,23:18.13
-8,-4,23:18.13
-7,-4,23:18.13
-6,-4,23:18.13
-5,-4,23:18.13
-4,-4,23:18.13
-3,-4,23:18.13
-10,-3,23:18.5
-7,-3,23:18.13
-6,-3,23:18.13
-5,-3,23:18.13
-4,-3,23:18.13
-11,-2,23:18.5
-10,-2,23:18.5
-4,-2,23:18.13
-3,-2,23:18.13
2,-2,23:18.5
3,-2,23:18.5
-11,-1,23:18.5
-10,-1,23:18.5
-5,-1,23:18.13
-4,-1,23:18.13
-3,-1,23:18.13
2,-1,23:18.5
3,-1,23:18.5
-11,0,23:18.5
-10,0,23:18.5
-9,0,23:18.13
-8,0,23:18.13
2,0,23:18.5
3,0,23:18.5
-1,1,23:18.13
0,1,23:18.5
1,1,23:18.5
2,1,23:18.5
0,2,23:18.5
1,2,23:18.5
2,2,23:18.5
6,-14,24:18.13
7,-14,24:18.13
5,-13,24:18.13
7,-13,24:18.13
-5,-12,24:18.5
7,-12,24:18.13
8,-12,24:18.13
-6,-11,24:18.5
-5,-11,24:18.5
5,-11,24:18.13
6,-11,24:18.13
7,-11,24:18.13
8,-11,24:18.13
-6,-10,24:18.5
-5,-10,24:18.5
-4,-10,24:18.5
2,-10,24:18.13
3,-10,24:18.13
5,-10,24:18.13
6,-10,24:18.13
7,-10,24:18.13
-6,-9,24:18.13
-4,-9,24:18.13
2,-9,24:18.13
6,-9,24:18.13
7,-9,24:18.13
-6,-8,24:18.13
-4,-8,24:18.13
2,-8,24:18.13
3,-8,24:18.13
6,-8,24:18.13
-7,-7,24:18.13
9,-7,24:18.13
-4,-6,24:18.13
-3,-6,24:18.13
-2,-6,24:18.13
8,-6,24:18.13
-8,-5,24:18.13
-7,-5,24:18.13
-6,-5,24:18.13
-5,-5,24:18.13
-4,-5,24:18.13
-3,-5,24:18.13
-9,-4,24:18.13
-7,-4,24:18.13
-6,-4,24:18.13
-5,-4,24:18.13
-4,-4,24:18.13
-10,-3,24:18.5
-9,-3,24:18.13
-5,-3,24:18.13
-4,-3,24:18.13
-3,-3,24:18.13
1,-3,24:18.5
-10,-2,24:18.5
-9,-2,24:18.13
-4,-2,24:18.13
-3,-2,24:18.13
1,-2,24:18.5
-10,-1,24:18.5
-9,-1,24:18.13
-8,-1,24:18.13
1,-1,24:18.5
2,-1,24:18.5
-8,0,24:18.13
-1,0,24:18.13
0,0,24:18.5
1,0,24:18.5
2,0,24:18.5
-1,1,24:18.13
0,1,24:18.5
1,1,24:18.5
2,1,24:18.5
7,-15,25:18.5
6,-14,25:18.13
7,-14,25:18.13
5,-13,25:18.13
6,-13,25:18.13
7,-13,25:18.13
5,-12,25:18.13
7,-12,25:18.13
7,-11,25:18.13
-5,-10,25:18.5
0,-10,25:18.5
1,-10,25:18.5
3,-10,25:18.13
5,-10,25:18.13
6,-10,25:18.13
7,-10,25:18.13
-6,-9,25:18.13
-5,-9,25:18.13
-4,-9,25:18.13
2,-9,25:18.13
3,-9,25:18.13
6,-9,25:18.13
-6,-8,25:18.13
-5,-8,25:18.13
-4,-8,25:18.13
3,-8,25:18.13
4,-8,25:18.13
9,-8,25:18.13
-12,-7,25:18.5
-11,-7,25:18.5
-10,-7,25:18.5
-9,-7,25:18.13
-8,-7,25:18.13
-7,-7,25:18.13
-6,-7,25:18.13
-4,-7,25:18.13
7,-7,25:18.13
8,-7,25:18.13
9,-7,25:18.13
-6,-6,25:18.13
3,-6,25:18.13
8,-6,25:18.13
9,-6,25:18.13
-12,-5,25:18.5
-11,-5,25:18.5
-6,-5,25:18.13
-5,-5,25:18.13
-4,-5,25:18.13
-3,-5,25:18.13
-11,-4,25:18.5
-10,-4,25:18.5
-8,-4,25:18.13
-6,-4,25:18.13
-5,-4,25:18.13
-4,-4,25:18.13
-10,-3,25:18.5
-9,-3,25:18.13
-8,-3,25:18.13
-5,-3,25:18.13
-4,-3,25:18.13
-1,-3,25:18.13
0,-3,25:18.5
-9,-2,25:18.13
-8,-2,25:18.13
-7,-2,25:18.13
0,-2,25:18.5
-8,-1,25:18.13
-2,-1,25:18.13
-1,-1,25:18.13
0,-1,25:18.5
1,-1,25:18.5
-1,0,25:18.13
0,0,25:18.5
1,0,25:18.5
-2,2,25:18.5
5,-14,26:18.5
7,-14,26:18.5
6,-13,26:18.5
7,-13,26:18.5
3,-12,26:18.5
6,-12,26:18.5
7,-12,26:18.5
7,-11,26:18.5
9,-11,26:18.5
10,-11,26:18.5
4,-10,26:18.5
6,-10,26:18.5
7,-10,26:18.5
10,-10,26:18.5
-5,-9,26:18.13
-1,-9,26:18.13
0,-9,26:18.5
1,-9,26:18.5
2,-9,26:18.5
3,-9,26:18.5
4,-9,26:18.5
6,-9,26:17.12
9,-9,26:18.5
-5,-8,26:18.13
2,-8,26:18.5
3,-8,26:18.5
4,-8,26:18.5
7,-8,26:18.5
8,-8,26:18.5
-13,-7,26:18.5
-12,-7,26:18.5
-11,-7,26:18.5
-10,-7,26:18.5
-9,-7,26:18.13
-8,-7,26:18.13
-7,-7,26:18.13
-6,-7,26:18.13
-5,-7,26:18.13
-4,-7,26:18.13
2,-7,26:18.5
7,-7,26:18.5
8,-7,26:18.5
-12,-6,26:18.5
-11,-6,26:18.5
-6,-6,26:18.13
-5,-6,26:18.13
-4,-6,26:18.13
1,-6,26:18.5
2,-6,26:18.5
6,-6,26:18.5
-12,-5,26:18.5
-11,-5,26:18.5
-10,-5,26:18.5
-6,-5,26:17.12
-5,-5,26:17.12
-4,-5,26:18.13
-10,-4,26:18.5
-9,-4,26:18.13
-7,-4,26:18.13
-6,-4,26:17.12
-5,-4,26:18.13
-4,-4,26:17.12
-2,-4,26:18.13
-9,-3,26:18.13
-8,-3,26:18.13
-7,-3,26:18.13
-6,-3,26:18.13
-5,-3,26:17.12
-4,-3,26:18.13
-2,-3,26:18.13
-1,-3,26:18.13
-8,-2,26:18.13
-7,-2,26:18.13
-6,-2,26:18.13
-3,-2,26:18.13
-2,-2,26:18.13
-1,-2,26:18.13
-2,-1,26:18.13
-1,-1,26:18.13
-2,0,26:18.13
-6,1,26:18.13
-5,1,26:18.13
-2,1,26:18.13
-5,2,26:18.5
-4,2,26:18.5
-3,2,26:18.5
-2,2,26:18.5
-4,3,26:18.5
-3,3,26:18.5
4,-13,27:18.5
5,-13,27:18.5
6,-13,27:18.5
4,-12,27:18.5
6,-12,27:18.5
7,-12,27:18.5
6,-11,27:18.5
7,-11,27:18.5
9,-11,27:18.5
10,-11,27:18.5
4,-10,27:18.5
5,-10,27:18.5
6,-10,27:17.12
7,-10,27:17.12
9,-10,27:18.5
10,-10,27:18.5
-8,-9,27:18.13
-1,-9,27:18.13
4,-9,27:18.5
5,-9,27:18.5
6,-9,27:17.12
7,-9,27:18.5
8,-9,27:18.5
9,-9,27:18.5
-1,-8,27:18.13
0,-8,27:18.5
1,-8,27:18.5
2,-8,27:18.5
5,-8,27:18.5
7,-8,27:18.5
8,-8,27:18.5
-12,-7,27:18.5
-11,-7,27:18.5
-10,-7,27:18.5
-5,-7,27:18.13
1,-7,27:18.5
5,-7,27:18.5
6,-7,27:18.5
7,-7,27:18.5
-12,-6,27:18.5
-11,-6,27:18.5
-10,-6,27:18.5
-9,-6,27:18.13
-8,-6,27:18.13
-7,-6,27:18.13
-5,-6,27:18.13
-4,-6,27:18.13
0,-6,27:18.5
1,-6,27:18.5
5,-6,27:18.5
6,-6,27:18.5
-10,-5,27:18.5
-9,-5,27:18.13
-6,-5,27:17.0
-5,-5,27:18.13
-4,-5,27:17.0
-9,-4,27:18.13
-8,-4,27:18.13
-6,-4,27:18.13
-5,-4,27:18.13
-4,-4,27:17.0
-3,-4,27:18.13
-7,-3,27:18.13
-6,-3,27:18.13
-5,-3,27:18.13
-3,-3,27:18.13
-2,-3,27:18.13
-6,0,27:18.13
-5,0,27:18.13
-2,0,27:18.13
-5,1,27:18.13
-4,1,27:18.13
-3,1,27:18.13
-4,2,27:18.5
-3,2,27:18.5
-6,-13,28:18.5
5,-13,28:18.5
-7,-12,28:18.5
-6,-12,28:18.5
4,-12,28:18.5
5,-12,28:18.5
6,-12,28:18.5
-8,-11,28:18.5
-7,-11,28:18.5
-5,-11,28:18.5
6,-11,28:18.5
8,-11,28:18.5
-8,-10,28:18.5
-5,-10,28:18.5
-4,-10,28:18.5
5,-10,28:18.5
6,-10,28:18.5
7,-10,28:17.12
8,-10,28:18.5
9,-10,28:18.5
-8,-9,28:18.13
-4,-9,28:18.13
5,-9,28:18.5
6,-9,28:17.12
7,-9,28:18.5
8,-9,28:18.5
-8,-8,28:18.13
-4,-8,28:18.13
-1,-8,28:18.13
5,-8,28:18.5
6,-8,28:18.5
-2,-7,28:18.13
-1,-7,28:18.13
0,-7,28:18.5
5,-7,28:18.5
6,-7,28:18.5
-10,-6,28:18.5
-9,-6,28:18.13
-8,-6,28:18.13
-7,-6,28:18.13
-6,-6,28:18.13
-1,-6,28:18.13
0,-6,28:18.5
-9,-5,28:18.13
-8,-5,28:18.13
-6,-5,28:17.0
-5,-5,28:17.0
-4,-5,28:17.0
-8,-4,28:18.13
-7,-4,28:18.13
-6,-4,28:17.0
-5,-4,28:18.13
-4,-4,28:18.13
-10,-3,28:18.5
-10,-2,28:18.5
-11,-1,28:18.5
-5,-1,28:18.13
-4,-1,28:18.13
-3,-1,28:18.13
-5,0,28:18.13
-4,0,28:18.13
-9,1,28:18.13
-8,1,28:18.13
-4,1,28:18.13
-7,-13,29:18.5
-6,-13,29:18.5
-7,-12,29:18.5
-6,-12,29:18.5
5,-12,29:18.5
6,-12,29:18.5
-7,-11,29:18.5
-6,-11,29:18.5
-5,-11,29:18.5
5,-11,29:18.5
6,-11,29:18.5
-7,-10,29:18.5
-5,-10,29:18.5
6,-10,29:17.0
7,-10,29:17.0
8,-10,29:18.5
-8,-9,29:18.13
-7,-9,29:18.13
-5,-9,29:18.13
-4,-9,29:18.13
5,-9,29:18.5
6,-9,29:17.0
7,-9,29:18.5
8,-9,29:18.5
-8,-8,29:18.13
-7,-8,29:18.13
-4,-8,29:18.13
5,-8,29:18.5
6,-8,29:18.5
-8,-7,29:18.13
-3,-7,29:18.13
-2,-7,29:18.13
-1,-7,29:18.13
6,-7,29:18.5
-8,-6,29:18.13
-7,-6,29:18.13
-6,-6,29:18.13
-3,-6,29:18.13
-2,-6,29:18.13
-1,-6,29:18.13
-8,-5,29:18.13
-7,-5,29:18.13
-6,-5,29:17.0
-5,-5,29:17.0
-4,-5,29:17.0
-2,-5,29:18.13
-7,-4,29:18.13
-6,-4,29:18.13
-5,-4,29:17.0
-4,-4,29:17.0
2,-4,29:18.5
-10,-3,29:18.5
-9,-3,29:18.13
2,-3,29:18.5
3,-3,29:18.5
-10,-2,29:18.5
-5,-2,29:18.13
-4,-2,29:18.13
-3,-2,29:18.13
2,-2,29:18.5
3,-2,29:18.5
-10,-1,29:18.5
-4,-1,29:18.13
-11,0,29:18.5
-10,0,29:18.5
-9,0,29:18.13
-8,0,29:18.13
-7,0,29:18.13
0,0,29:18.5
1,0,29:18.5
2,0,29:18.5
-10,1,29:18.5
-9,1,29:18.13
-8,1,29:18.13
-6,-12,30:18.5
8,-12,30:18.5
-7,-11,30:18.5
-6,-11,30:18.5
5,-11,30:18.5
6,-11,30:18.5
-7,-10,30:18.5
-6,-10,30:18.5
-5,-10,30:18.5
3,-10,30:18.5
4,-10,30:18.5
6,-10,30:17.0
7,-10,30:18.5
8,-10,30:18.5
-7,-9,30:18.13
-6,-9,30:18.13
-5,-9,30:18.13
3,-9,30:18.5
5,-9,30:18.5
6,-9,30:18.5
7,-9,30:18.5
-7,-8,30:18.13
-5,-8,30:18.13
-4,-8,30:18.13
3,-8,30:18.5
4,-8,30:18.5
6,-8,30:18.5
9,-8,30:18.5
-7,-7,30:18.13
8,-7,30:18.5
-6,-6,30:18.13
-4,-6,30:18.13
-3,-6,30:18.13
-7,-5,30:18.13
-6,-5,30:18.13
-5,-5,30:17.0
-4,-5,30:17.0
-3,-5,30:18.13
-6,-4,30:18.13
-5,-4,30:17.0
-4,-4,30:17.0
1,-4,30:18.5
-9,-3,30:18.13
-8,-3,30:18.13
-5,-3,30:18.13
-4,-3,30:18.13
1,-3,30:18.5
2,-3,30:18.5
-9,-2,30:18.13
-4,-2,30:18.13
1,-2,30:18.5
2,-2,30:18.5
-10,-1,30:18.5
-9,-1,30:18.13
-8,-1,30:18.13
-7,-1,30:18.13
0,-1,30:18.5
1,-1,30:18.5
2,-1,30:18.5
-9,0,30:18.13
-8,0,30:18.13
-7,0,30:18.13
0,0,30:18.5
1,0,30:18.5
2,0,30:18.5
6,-13,31:18.5
7,-13,31:18.5
5,-12,31:18.5
6,-12,31:18.5
7,-12,31:18.5
5,-11,31:18.5
6,-11,31:18.5
7,-11,31:18.5
-6,-10,31:18.5
4,-10,31:18.5
6,-10,31:18.5
7,-10,31:18.5
-6,-9,31:18.5
-5,-9,31:18.5
3,-9,31:18.5
4,-9,31:18.5
5,-9,31:18.5
6,-9,31:18.5
7,-9,31:18.5
-6,-8,31:18.5
-5,-8,31:18.5
4,-8,31:18.5
8,-8,31:18.5
9,-8,31:18.5
-6,-7,31:18.5
-5,-7,31:18.5
-4,-7,31:18.5
7,-7,31:18.5
8,-7,31:18.5
9,-7,31:18.5
-6,-6,31:18.5
-4,-6,31:18.5
-6,-5,31:18.5
-5,-5,31:17.0
-4,-5,31:17.0
-3,-5,31:18.5
-7,-4,31:18.5
-6,-4,31:18.5
-5,-4,31:17.0
-4,-4,31:17.0
-2,-4,31:18.5
-1,-4,31:18.5
0,-4,31:18.5
-8,-3,31:18.5
-7,-3,31:18.5
-6,-3,31:18.5
-5,-3,31:18.5
-4,-3,31:18.5
0,-3,31:18.5
-8,-2,31:18.5
-7,-2,31:18.5
-1,-2,31:18.5
0,-2,31:18.5
1,-2,31:18.5
-8,-1,31:18.5
-7,-1,31:18.5
-1,-1,31:18.5
0,-1,31:18.5
1,-1,31:18.5
5,-12,32:18.5
6,-12,32:18.5
7,-12,32:18.5
-7,-11,32:18.5
3,-11,32:18.5
4,-11,32:18.5
5,-11,32:18.5
6,-11,32:18.5
7,-11,32:18.5
9,-11,32:18.5
5,-10,32:18.5
6,-10,32:17.0
7,-10,32:18.5
8,-10,32:18.5
9,-10,32:18.5
-10,-9,32:18.5
-6,-9,32:18.5
4,-9,32:18.5
5,-9,32:18.5
6,-9,32:17.0
7,-9,32:18.5
8,-9,32:18.5
-10,-8,32:18.5
-6,-8,32:18.5
-5,-8,32:18.5
0,-8,32:18.5
1,-8,32:18.5
4,-8,32:18.5
7,-8,32:18.5
8,-8,32:18.5
-6,-7,32:18.5
-5,-7,32:18.5
2,-7,32:18.5
5,-7,32:18.5
-6,-6,32:18.5
-5,-6,32:18.5
-4,-6,32:18.5
2,-6,32:18.5
6,-6,32:18.5
-6,-5,32:18.5
-5,-5,32:17.0
-4,-5,32:17.0
-3,-5,32:18.5
1,-5,32:18.5
-7,-4,32:18.5
-6,-4,32:18.5
-5,-4,32:17.0
-4,-4,32:17.0
-3,-4,32:18.5
-2,-4,32:18.5
-1,-4,32:18.5
1,-4,32:18.5
-7,-3,32:18.5
-6,-3,32:18.5
-5,-3,32:18.5
-4,-3,32:18.5
-3,-3,32:18.5
-2,-3,32:18.5
-1,-3,32:18.5
-7,-2,32:18.5
-6,-2,32:18.5
-2,-2,32:18.5
-1,-2,32:18.5
-6,-1,32:18.5
-6,0,32:18.5
-3,1,32:18.5
-4,2,32:18.5
4,-11,33:18.5
5,-11,33:18.5
6,-11,33:18.5
8,-11,33:18.5
9,-11,33:18.5
-9,-10,33:18.5
-8,-10,33:18.5
-7,-10,33:18.5
6,-10,33:17.0
8,-10,33:18.5
-10,-9,33:18.5
-9,-9,33:18.5
5,-9,33:18.5
6,-9,33:17.0
7,-9,33:18.5
8,-9,33:18.5
-10,-8,33:18.5
-9,-8,33:18.5
-1,-8,33:18.5
0,-8,33:18.5
5,-8,33:18.5
-10,-7,33:18.5
-5,-7,33:18.5
0,-7,33:18.5
1,-7,33:18.5
2,-7,33:18.5
5,-7,33:18.5
6,-7,33:18.5
7,-7,33:18.5
-5,-6,33:18.5
-4,-6,33:18.5
1,-6,33:18.5
6,-6,33:18.5
-6,-5,33:18.5
-5,-5,33:17.0
-4,-5,33:17.0
-3,-5,33:18.5
0,-5,33:18.5
1,-5,33:18.5
-6,-4,33:18.5
-5,-4,33:17.0
-4,-4,33:17.0
-3,-4,33:18.5
-2,-4,33:18.5
0,-4,33:18.5
-6,-3,33:18.5
-5,-3,33:18.5
-4,-3,33:18.5
-3,-3,33:18.5
-2,-3,33:18.5
-6,-2,33:18.5
-6,-1,33:18.5
-3,-1,33:18.5
-6,0,33:18.5
-4,0,33:18.5
-6,1,33:18.5
-4,1,33:18.5
-6,2,33:18.5
-5,2,33:18.5
-4,2,33:18.5
-6,3,33:18.5
-5,3,33:18.5
7,-12,34:18.5
4,-11,34:18.5
5,-11,34:18.5
6,-11,34:18.5
7,-11,34:18.5
8,-11,34:18.5
3,-10,34:18.5
4,-10,34:18.5
5,-10,34:18.5
6,-10,34:17.0
7,-10,34:18.5
8,-10,34:18.5
-9,-9,34:18.5
-8,-9,34:18.5
-7,-9,34:18.5
3,-9,34:18.5
5,-9,34:18.5
6,-9,34:17.0
7,-9,34:18.5
-9,-8,34:18.5
-8,-8,34:18.5
5,-8,34:18.5
6,-8,34:18.5
7,-8,34:18.5
-9,-7,34:18.5
-1,-7,34:18.5
0,-7,34:18.5
1,-7,34:18.5
8,-7,34:18.5
-6,-6,34:18.5
-5,-6,34:18.5
-4,-6,34:18.5
0,-6,34:18.5
1,-6,34:18.5
-7,-5,34:18.5
-6,-5,34:18.5
-5,-5,34:18.5
-4,-5,34:18.5
-3,-5,34:18.5
0,-5,34:18.5
-6,-4,34:18.5
-5,-4,34:18.5
-4,-4,34:18.5
-3,-4,34:18.5
0,-4,34:18.5
-6,-3,34:18.5
-6,-2,34:18.5
-6,-1,34:18.5
-4,-1,34:18.5
-3,-1,34:18.5
-6,0,34:18.5
-4,0,34:18.5
-6,1,34:18.5
-5,1,34:18.5
-4,1,34:18.5
-5,2,34:18.5
-5,3,34:18.5
5,-11,35:18.5
7,-11,35:18.5
4,-10,35:18.5
5,-10,35:18.5
6,-10,35:17.0
7,-10,35:18.5
8,-10,35:18.5
-8,-9,35:18.5
-7,-9,35:18.5
4,-9,35:18.5
6,-9,35:17.0
-8,-8,35:18.5
-7,-8,35:18.5
6,-8,35:18.5
7,-8,35:18.5
-8,-7,35:18.5
-2,-7,35:18.5
-1,-7,35:18.5
0,-7,35:18.5
-7,-6,35:18.5
-6,-6,35:18.5
-5,-6,35:18.5
-4,-6,35:18.5
-3,-6,35:18.5
-1,-6,35:18.5
0,-6,35:18.5
-7,-5,35:18.5
-6,-5,35:18.5
-5,-5,35:18.5
-4,-5,35:18.5
-3,-5,35:18.5
-1,-5,35:18.5
-6,-4,35:18.5
-5,-4,35:17.0
-4,-4,35:18.5
-3,-4,35:18.5
-6,-3,35:18.5
-5,-3,35:18.5
-4,-3,35:18.5
-6,-2,35:18.5
-5,-2,35:18.5
-4,-2,35:18.5
-3,-2,35:18.5
-6,-1,35:18.5
-5,-1,35:18.5
-4,-1,35:18.5
-5,0,35:18.5
-4,0,35:18.5
-5,1,35:18.5
7,-11,36:18.5
5,-10,36:18.5
6,-10,36:17.0
7,-10,36:18.5
8,-10,36:18.5
6,-9,36:17.0
7,-9,36:18.5
8,-9,36:18.5
-7,-8,36:18.5
-6,-8,36:18.5
5,-8,36:18.5
-7,-7,36:18.5
5,-7,36:18.5
6,-7,36:18.5
-7,-6,36:18.5
-6,-6,36:18.5
-5,-6,36:18.5
-4,-6,36:18.5
-3,-6,36:18.5
-2,-6,36:18.5
-1,-6,36:18.5
-7,-5,36:18.5
-6,-5,36:18.5
-5,-5,36:18.5
-4,-5,36:18.5
-3,-5,36:18.5
-2,-5,36:18.5
-1,-5,36:18.5
-6,-4,36:18.5
-5,-4,36:18.5
-4,-4,36:18.5
-3,-4,36:18.5
-5,-3,36:18.5
-4,-3,36:18.5
-5,-2,36:18.5
-4,-2,36:18.5
-5,-1,36:18.5
-4,-1,36:18.5
-5,0,36:18.5
-3,-12,37:18.5
-5,-11,37:18.5
-4,-11,37:18.5
-2,-11,37:18.5
4,-11,37:18.5
5,-11,37:18.5
6,-11,37:18.5
-2,-10,37:18.5
6,-10,37:18.5
7,-10,37:18.5
8,-10,37:18.5
-1,-9,37:18.5
5,-9,37:18.5
6,-9,37:18.5
7,-9,37:18.5
8,-9,37:18.5
5,-8,37:18.5
6,-8,37:18.5
-7,-7,37:18.5
-6,-7,37:18.5
6,-7,37:18.5
-7,-6,37:18.5
-6,-6,37:18.5
-5,-6,37:18.5
-4,-6,37:18.5
-3,-6,37:18.5
-2,-6,37:18.5
-6,-5,37:18.5
-5,-5,37:18.5
-4,-5,37:18.5
-3,-5,37:18.5
-2,-5,37:18.5
-6,-4,37:18.5
-5,-4,37:18.5
-4,-4,37:18.5
0,-4,37:18.5
-5,-3,37:18.5
-4,-3,37:18.5
1,-3,37:18.5
-5,-2,37:18.5
-4,-2,37:18.5
-3,-2,37:18.5
-2,-1,37:18.5
-4,-11,38:18.5
-3,-11,38:18.5
5,-11,38:18.5
6,-11,38:18.5
-5,-10,38:18.5
-4,-10,38:18.5
-3,-10,38:18.5
-2,-10,38:18.5
5,-10,38:18.5
6,-10,38:18.5
7,-10,38:18.5
-2,-9,38:18.5
5,-9,38:18.5
6,-9,38:18.5
7,-9,38:18.5
6,-8,38:18.5
-11,-6,38:18.5
-6,-6,38:18.5
-5,-6,38:18.5
-4,-6,38:18.5
-3,-6,38:18.5
-12,-5,38:18.5
-11,-5,38:18.5
-6,-5,38:18.5
-5,-5,38:18.5
-4,-5,38:18.5
-3,-5,38:18.5
-12,-4,38:18.5
-6,-4,38:18.5
-5,-4,38:18.5
-4,-4,38:18.5
0,-4,38:18.5
-11,-3,38:18.5
-10,-3,38:18.5
-5,-3,38:18.5
-4,-3,38:18.5
0,-3,38:18.5
-11,-2,38:18.5
-10,-2,38:18.5
-3,-2,38:18.5
-2,-2,38:18.5
1,-2,38:18.5
-2,-1,38:18.5
-1,-1,38:18.5
0,-1,38:18.5
1,-1,38:18.5
0,0,38:18.5
1,0,38:18.5
-5,-10,39:18.5
-4,-10,39:18.5
-3,-10,39:18.5
5,-10,39:18.5
6,-10,39:18.5
7,-10,39:18.5
-5,-9,39:18.5
-3,-9,39:18.5
-2,-9,39:18.5
5,-9,39:18.5
6,-9,39:18.5
7,-9,39:18.5
-2,-8,39:18.5
-10,-6,39:18.5
-5,-6,39:17.0
-4,-6,39:18.5
-11,-5,39:18.5
-10,-5,39:18.5
-6,-5,39:18.5
-5,-5,39:18.5
-4,-5,39:18.5
-1,-5,39:18.5
-11,-4,39:18.5
-10,-4,39:18.5
-5,-4,39:18.5
-4,-4,39:18.5
-1,-4,39:18.5
-10,-3,39:18.5
-9,-3,39:18.5
-1,-3,39:18.5
0,-3,39:18.5
-3,-2,39:18.5
-2,-2,39:18.5
0,-2,39:18.5
-1,-1,39:18.5
0,-1,39:18.5
1,-1,39:18.5
1,0,39:18.5
6,-11,40:18.5
7,-11,40:18.5
-4,-10,40:18.5
5,-10,40:18.5
6,-10,40:18.5
7,-10,40:18.5
-6,-9,40:18.5
-5,-9,40:18.5
-4,-9,40:18.5
-3,-9,40:18.5
5,-9,40:18.5
6,-9,40:18.5
-3,-8,40:18.5
5,-8,40:18.5
7,-8,40:18.5
8,-8,40:18.5
-9,-6,40:18.5
-5,-6,40:17.0
-4,-6,40:18.5
-10,-5,40:18.5
-9,-5,40:18.5
-6,-5,40:17.0
-5,-5,40:18.5
-4,-5,40:17.0
-10,-4,40:18.5
-9,-4,40:18.5
-5,-4,40:18.5
-4,-4,40:18.5
-2,-4,40:18.5
-1,-4,40:18.5
-9,-3,40:18.5
-3,-3,40:18.5
-1,-3,40:18.5
-3,-2,40:18.5
-2,-2,40:18.5
-1,-2,40:18.5
0,-2,40:18.5
-8,-1,40:18.5
-1,-1,40:18.5
0,-1,40:18.5
6,-11,41:18.5
6,-10,41:17.0
7,-10,41:18.5
-9,-9,41:18.5
-8,-9,41:18.5
-7,-9,41:18.5
-6,-9,41:18.5
-4,-9,41:18.5
5,-9,41:18.5
6,-9,41:17.0
7,-9,41:18.5
-9,-8,41:18.5
-6,-8,41:18.5
-5,-8,41:18.5
-4,-8,41:18.5
-3,-8,41:18.5
7,-8,41:18.5
-9,-7,41:18.5
-3,-7,41:18.5
0,-7,41:18.5
1,-7,41:18.5
-9,-6,41:18.5
-5,-6,41:17.0
-4,-6,41:18.5
0,-6,41:18.5
1,-6,41:18.5
-9,-5,41:18.5
-8,-5,41:18.5
-6,-5,41:17.0
-5,-5,41:18.5
-4,-5,41:17.0
-9,-4,41:18.5
-8,-4,41:18.5
-5,-4,41:17.0
-4,-4,41:17.0
-2,-4,41:18.5
1,-4,41:18.5
-4,-3,41:18.5
-3,-3,41:18.5
-2,-3,41:18.5
-1,-3,41:18.5
0,-3,41:18.5
1,-3,41:18.5
-8,-2,41:18.5
-2,-2,41:18.5
-1,-2,41:18.5
-8,-1,41:18.5
-8,0,41:18.5
-7,0,41:18.5
-6,0,41:18.5
-5,0,41:18.5
-7,1,41:18.5
-6,1,41:18.5
6,-10,42:18.5
-9,-9,42:18.5
-8,-9,42:18.5
-7,-9,42:18.5
6,-9,42:18.5
7,-9,42:18.5
-9,-8,42:18.5
-7,-8,42:18.5
-6,-8,42:18.5
-4,-8,42:18.5
-9,-7,42:18.5
-8,-7,42:18.5
-5,-7,42:18.5
-4,-7,42:18.5
-1,-7,42:18.5
0,-7,42:18.5
-8,-6,42:18.5
-5,-6,42:17.0
0,-6,42:18.5
1,-6,42:18.5
-8,-5,42:18.5
-7,-5,42:18.5
-6,-5,42:17.0
-5,-5,42:18.5
-4,-5,42:17.0
-3,-5,42:18.5
0,-5,42:18.5
1,-5,42:18.5
-8,-4,42:18.5
-7,-4,42:18.5
-5,-4,42:17.0
-4,-4,42:18.5
-3,-4,42:18.5
-2,-4,42:18.5
0,-4,42:18.5
1,-4,42:18.5
-8,-3,42:18.5
-3,-3,42:18.5
-2,-3,42:18.5
0,-3,42:18.5
-8,-2,42:18.5
-7,-2,42:18.5
-7,-1,42:18.5
-5,-1,42:18.5
-7,0,42:18.5
-6,0,42:18.5
-5,0,42:18.5
5,-11,43:18.5
6,-11,43:18.5
6,-10,43:18.5
8,-10,43:18.5
-9,-9,43:18.5
-8,-9,43:18.5
6,-9,43:17.0
7,-9,43:18.5
8,-9,43:18.5
-8,-8,43:18.5
-7,-8,43:18.5
-6,-8,43:18.5
5,-8,43:18.5
-8,-7,43:18.5
-5,-7,43:18.5
-4,-7,43:18.5
-8,-6,43:18.5
-5,-6,43:17.0
-4,-6,43:18.5
-1,-6,43:18.5
0,-6,43:18.5
-7,-5,43:18.5
-6,-5,43:17.0
-5,-5,43:18.5
-4,-5,43:17.0
-3,-5,43:18.5
-1,-5,43:18.5
0,-5,43:18.5
-6,-4,43:18.5
-5,-4,43:17.0
-4,-4,43:18.5
-3,-4,43:18.5
-1,-4,43:18.5
0,-4,43:18.5
-7,-3,43:18.5
-7,-2,43:18.5
-7,-1,43:18.5
-6,-1,43:18.5
-5,-1,43:18.5
5,-10,44:18.5
6,-10,44:18.5
5,-9,44:18.5
6,-9,44:17.0
7,-9,44:18.5
-8,-8,44:18.5
-7,-8,44:18.5
-6,-8,44:18.5
-5,-8,44:18.5
5,-8,44:18.5
6,-8,44:18.5
-8,-7,44:18.5
-7,-7,44:18.5
-6,-7,44:18.5
6,-7,44:18.5
-7,-6,44:18.5
-5,-6,44:17.0
-4,-6,44:17.0
-2,-6,44:18.5
-1,-6,44:18.5
-6,-5,44:17.0
-5,-5,44:18.5
-4,-5,44:17.0
-1,-5,44:18.5
-7,-4,44:18.5
-5,-4,44:17.0
-2,-4,44:18.5
-1,-4,44:18.5
-7,-3,44:18.5
-7,-2,44:18.5
-6,-2,44:18.5
-5,-2,44:18.5
-6,-1,44:18.5
6,-10,45:18.5
6,-9,45:18.5
7,-9,45:18.5
-6,-8,45:18.5
-5,-8,45:18.5
6,-8,45:18.5
-8,-7,45:18.5
-7,-7,45:18.5
-6,-7,45:18.5
-5,-7,45:18.5
-7,-6,45:18.5
-5,-6,45:17.0
-4,-6,45:17.0
-3,-6,45:18.5
-2,-6,45:18.5
-6,-5,45:17.0
-5,-5,45:17.0
-4,-5,45:17.0
-2,-5,45:18.5
-7,-4,45:18.5
-6,-4,45:18.5
-5,-4,45:17.0
-3,-4,45:18.5
-2,-4,45:18.5
-7,-3,45:18.5
-6,-3,45:18.5
-5,-3,45:18.5
-6,-2,45:18.5
-5,-10,46:18.5
-3,-10,46:18.5
-3,-9,46:18.5
6,-9,46:17.0
-7,-7,46:18.5
-6,-7,46:18.5
-5,-7,46:18.5
-6,-6,46:18.5
-5,-6,46:17.0
-4,-6,46:17.0
-3,-6,46:18.5
-2,-6,46:18.5
-6,-5,46:17.0
-5,-5,46:17.0
-4,-5,46:17.0
-3,-5,46:18.5
-2,-5,46:18.5
-7,-4,46:18.5
-6,-4,46:18.5
-5,-4,46:17.0
-3,-4,46:18.5
-6,-3,46:18.5
-5,-3,46:18.5
-6,-2,46:18.5
-5,-10,47:18.5
-4,-10,47:18.5
-6,-9,47:18.5
-5,-9,47:18.5
-4,-9,47:18.5
-3,-9,47:18.5
6,-9,47:17.0
-3,-8,47:18.5
-2,-8,47:18.5
-6,-7,47:18.5
-5,-7,47:18.5
-6,-6,47:18.5
-5,-6,47:17.0
-4,-6,47:17.0
-3,-6,47:18.5
-10,-5,47:18.5
-9,-5,47:18.5
-6,-5,47:17.0
-5,-5,47:17.0
-4,-5,47:18.5
-3,-5,47:18.5
-1,-5,47:18.5
-10,-4,47:18.5
-6,-4,47:18.5
-5,-4,47:18.5
-3,-4,47:18.5
-1,-4,47:18.5
-10,-3,47:18.5
-9,-3,47:18.5
-6,-3,47:18.5
0,-3,47:18.5
-9,-2,47:18.5
-4,-2,47:18.5
-3,-2,47:18.5
-2,-2,47:18.5
-1,-2,47:18.5
-5,-9,48:18.5
-4,-9,48:18.5
6,-9,48:17.0
-5,-8,48:18.5
-4,-8,48:18.5
-3,-8,48:18.5
-3,-7,48:18.5
-6,-6,48:18.5
-5,-6,48:17.0
-4,-6,48:17.0
-3,-6,48:18.5
-9,-5,48:18.5
-6,-5,48:17.0
-5,-5,48:17.0
-4,-5,48:18.5
-3,-5,48:18.5
-10,-4,48:18.5
-9,-4,48:18.5
-6,-4,48:18.5
-5,-4,48:18.5
-2,-4,48:18.5
-1,-4,48:18.5
-9,-3,48:18.5
-8,-3,48:18.5
-4,-3,48:18.5
-3,-3,48:18.5
-1,-3,48:18.5
-3,-2,48:18.5
-2,-2,48:18.5
-1,-2,48:18.5
0,-2,48:18.5
-8,-9,49:18.5
-7,-9,49:18.5
-6,-9,49:18.5
6,-9,49:17.0
-5,-8,49:18.5
-4,-8,49:18.5
-1,-8,49:18.5
-5,-7,49:18.5
-4,-7,49:18.5
-1,-7,49:18.5
-6,-6,49:18.5
-5,-6,49:17.0
-4,-6,49:17.0
-1,-6,49:18.5
-8,-5,49:18.5
-6,-5,49:17.0
-5,-5,49:17.0
-4,-5,49:18.5
-3,-5,49:18.5
-1,-5,49:18.5
-9,-4,49:18.5
-8,-4,49:18.5
-7,-4,49:18.5
-5,-4,49:18.5
-2,-4,49:18.5
-7,-3,49:18.5
-4,-3,49:18.5
-3,-3,49:18.5
-2,-3,49:18.5
-1,-3,49:18.5
-7,-2,49:18.5
-1,-2,49:18.5
-6,-1,49:18.5
-8,-9,50:18.5
-7,-9,50:18.5
-6,-9,50:18.5
6,-9,50:17.0
-9,-8,50:18.5
-8,-8,50:18.5
-7,-8,50:18.5
-1,-8,50:18.5
-5,-7,50:18.5
-4,-7,50:18.5
-2,-7,50:18.5
-1,-7,50:18.5
-5,-6,50:17.0
-4,-6,50:18.5
-2,-6,50:18.5
-1,-6,50:18.5
-7,-5,50:18.5
-6,-5,50:17.0
-5,-5,50:17.0
-4,-5,50:17.0
-3,-5,50:18.5
-2,-5,50:18.5
-7,-4,50:18.5
-4,-4,50:18.5
-3,-4,50:18.5
-2,-4,50:18.5
-7,-3,50:18.5
-3,-3,50:18.5
-2,-3,50:18.5
-6,-2,50:18.5
-6,-1,50:18.5
-5,-1,50:18.5
-5,0,50:18.5
-9,-8,51:18.5
-8,-8,51:18.5
-7,-8,51:18.5
-6,-8,51:18.5
-8,-7,51:18.5
-2,-7,51:18.5
-8,-6,51:18.5
-5,-6,51:17.0
-4,-6,51:17.0
-2,-6,51:18.5
-9,-5,51:18.5
-6,-5,51:18.5
-5,-5,51:17.0
-4,-5,51:18.5
-3,-5,51:18.5
-2,-5,51:18.5
-4,-4,51:18.5
-6,-3,51:18.5
-6,-2,51:18.5
-5,-2,51:18.5
-5,-1,51:18.5
-3,-9,52:18.5
-2,-9,52:18.5
6,-9,52:17.0
-6,-8,52:18.5
-2,-8,52:18.5
-8,-7,52:18.5
-7,-7,52:18.5
-6,-7,52:18.5
-3,-7,52:18.5
-2,-7,52:18.5
-8,-6,52:18.5
-6,-6,52:17.0
-5,-6,52:17.0
-4,-6,52:17.0
-3,-6,52:18.5
-9,-5,52:18.5
-6,-5,52:17.0
-5,-5,52:17.0
-4,-5,52:17.0
-3,-5,52:18.5
-6,-4,52:18.5
-6,-3,52:18.5
-5,-3,52:18.5
-5,-2,52:18.5
-4,-2,52:18.5
-3,-2,52:18.5
-2,-2,52:18.5
-3,-9,53:18.5
6,-9,53:17.0
-3,-8,53:18.5
-7,-7,53:18.5
-6,-7,53:18.5
-5,-7,53:18.5
-3,-7,53:18.5
-2,-7,53:18.5
-8,-6,53:18.5
-7,-6,53:18.5
-6,-6,53:17.0
-5,-6,53:17.0
-4,-6,53:18.5
-3,-6,53:18.5
-2,-6,53:18.5
-8,-5,53:18.5
-6,-5,53:17.0
-5,-5,53:17.0
-4,-5,53:18.5
-6,-4,53:18.5
-5,-4,53:18.5
-5,-3,53:18.5
-4,-3,53:18.5
-3,-3,53:18.5
-5,-2,53:18.5
-4,-2,53:18.5
-3,-2,53:18.5
-4,-8,54:18.5
-3,-8,54:18.5
-3,-7,54:18.5
-7,-6,54:18.5
-6,-6,54:18.5
-5,-6,54:17.0
-4,-6,54:18.5
-3,-6,54:18.5
-8,-5,54:18.5
-6,-5,54:17.0
-5,-5,54:17.0
-4,-5,54:18.5
-5,-4,54:18.5
-5,-3,54:18.5
-4,-3,54:18.5
-3,-3,54:18.5
-6,-9,55:18.5
-5,-9,55:18.5
-8,-8,55:18.5
-7,-8,55:18.5
-6,-8,55:18.5
-4,-8,55:18.5
-4,-7,55:18.5
-3,-7,55:18.5
-7,-6,55:18.5
-6,-6,55:18.5
-5,-6,55:17.0
-4,-6,55:18.5
-3,-6,55:18.5
-7,-5,55:18.5
-6,-5,55:17.0
-5,-5,55:17.0
-7,-4,55:18.5
-5,-4,55:18.5
-4,-4,55:18.5
-7,-3,55:18.5
-8,-8,56:18.5
-7,-8,56:18.5
-6,-8,56:18.5
-5,-8,56:18.5
-4,-7,56:18.5
-6,-6,56:18.5
-5,-6,56:17.0
-4,-6,56:18.5
-2,-6,56:18.5
-7,-5,56:18.5
-6,-5,56:18.5
-5,-5,56:17.0
-2,-5,56:18.5
-7,-4,56:18.5
-5,-4,56:18.5
-4,-4,56:18.5
-7,-3,56:18.5
-6,-3,56:18.5
-6,-2,56:18.5
-7,-8,57:18.5
-6,-8,57:18.5
-5,-8,57:18.5
-8,-7,57:18.5
-7,-7,57:18.5
-6,-7,57:18.5
-5,-7,57:18.5
-2,-7,57:18.5
-6,-6,57:18.5
-5,-6,57:17.0
-4,-6,57:18.5
-2,-6,57:18.5
-6,-5,57:18.5
-5,-5,57:17.0
-3,-5,57:18.5
-2,-5,57:18.5
-7,-4,57:18.5
-6,-4,57:18.5
-3,-4,57:18.5
-6,-3,57:18.5
-6,-2,57:18.5
-7,-7,58:18.5
-6,-7,58:18.5
-5,-7,58:18.5
-4,-7,58:18.5
-7,-6,58:18.5
-6,-6,58:18.5
-5,-6,58:17.0
-4,-6,58:18.5
-3,-6,58:18.5
-6,-5,58:18.5
-5,-5,58:17.0
-4,-5,58:18.5
-3,-5,58:18.5
-6,-4,58:18.5
-5,-4,58:18.5
-6,-3,58:18.5
-6,-7,59:18.5
-5,-7,59:18.5
-4,-7,59:18.5
-6,-6,59:18.5
-5,-6,59:17.0
-4,-6,59:18.5
-3,-6,59:18.5
-6,-5,59:18.5
-5,-5,59:18.5
-4,-5,59:18.5
-6,-4,59:18.5
-5,-4,59:18.5
-5,-8,60:18.5
-4,-8,60:18.5
-6,-7,60:18.5
-5,-7,60:18.5
-4,-7,60:18.5
-6,-6,60:18.5
-5,-6,60:17.0
-4,-6,60:18.5
-6,-5,60:18.5
-5,-5,60:18.5
-4,-5,60:18.5
-6,-8,61:18.5
-5,-8,61:18.5
-5,-7,61:18.5
-4,-7,61:18.5
-8,-6,61:18.5
-6,-6,61:18.5
-5,-6,61:17.0
-4,-6,61:18.5
-8,-5,61:18.5
-5,-5,61:18.5
-8,-4,61:18.5
-4,-4,61:18.5
-3,-4,61:18.5
-6,-7,62:18.5
-5,-7,62:18.5
-4,-7,62:18.5
-7,-6,62:18.5
-6,-6,62:17.0
-5,-6,62:17.0
-8,-5,62:18.5
-7,-5,62:18.5
-5,-5,62:18.5
-8,-4,62:18.5
-5,-4,62:18.5
-4,-4,62:18.5
-3,-4,62:18.5
-5,-7,63:18.5
-7,-6,63:18.5
-6,-6,63:17.0
-5,-6,63:17.0
-7,-5,63:18.5
-4,-5,63:18.5
-3,-5,63:18.5
-4,-4,63:18.5
-5,-7,64:18.5
-6,-6,64:18.5
-5,-6,64:17.0
-7,-5,64:18.5
-6,-5,64:18.5
-5,-5,64:18.5
-4,-5,64:18.5
-6,-6,65:18.5
-5,-6,65:17.0
-6,-5,65:18.5
-5,-5,65:18.5
-4,-5,65:18.5
-6,-6,66:17.0
-5,-6,66:17.0
-3,-6,66:18.5
-7,-5,66:18.5
-3,-5,66:18.5
-7,-4,66:18.5
-6,-4,66:18.5
-6,-3,66:18.5
-8,-8,67:18.5
-7,-8,67:18.5
-6,-8,67:18.5
-5,-8,67:18.5
-3,-7,67:18.5
-6,-6,67:17.0
-5,-6,67:17.0
-4,-6,67:18.5
-3,-6,67:18.5
-7,-5,67:18.5
-6,-5,67:18.5
-4,-5,67:18.5
-6,-4,67:18.5
-6,-3,67:18.5
-7,-8,68:18.5
-6,-8,68:18.5
-7,-7,68:18.5
-6,-7,68:18.5
-5,-7,68:18.5
-5,-6,68:17.0
-4,-6,68:18.5
-6,-5,68:18.5
-6,-4,68:18.5
-6,-7,69:18.5
-5,-7,69:18.5
-6,-6,69:18.5
-5,-6,69:17.0
-4,-6,69:18.5
-6,-5,69:18.5
-5,-5,69:18.5
-5,-7,70:17.0
-6,-6,70:18.5
-5,-6,70:18.5
-5,-7,71:17.0
-5,-6,71:17.0
-5,-7,72:17.0
-5,-6,72:17.0
-5,-7,73:17.0
-5,-6,73:17.0
-5,-7,74:17.0
-5,-6,74:17.0
-5,-7,75:17.0
-5,-6,75:17.0
-5,-7,76:17.0
-5,-6,76:17.0
-5,-7,77:17.0
-5,-7,78:17.0
-5,-7,79:17.0
-5,-7,80:17.0
