[META]
version=2.0
spawnOnBlockType=2
spawnSunlight=True
spawnDarkness=True
spawnWater=False
spawnLava=False
underFill=False
randomRotation=True
dig=True
tree=False
branch=False
needsFoundation=True
rarity=100
collisionPercentage=20
spawnElevationMin=0
spawnElevationMax=200
spawnInBiome=Custom
[DATA]
-2,0,-8:17.12
-1,0,-8:17.12
-2,2,-8:17.12
-1,-1,-7:17.12
-3,0,-7:17.12
-1,0,-7:17.12
1,0,-7:17.12
-3,1,-7:17.12
-2,1,-7:17.12
-1,2,-7:17.12
-2,-1,-6:17.12
0,-1,-6:17.12
-2,0,-6:17.12
-1,0,-6:17.12
0,0,-6:17.12
-3,1,-6:17.12
-2,1,-6:17.12
-1,1,-6:17.12
0,1,-6:17.12
-3,2,-6:17.12
-1,2,-6:17.12
-2,3,-6:17.12
-1,3,-6:17.12
0,3,-6:17.12
-1,-1,-5:17.12
-2,0,-5:17.12
-1,0,-5:17.12
0,0,-5:17.12
-3,1,-5:17.12
-2,1,-5:17.12
-1,1,-5:17.12
0,1,-5:17.12
-3,2,-5:17.12
0,2,-5:17.12
1,2,-5:17.12
-2,3,-5:17.12
0,3,-5:17.12
-2,0,-4:17.12
-1,0,-4:17.12
1,0,-4:17.12
-2,1,-4:17.12
-1,1,-4:17.12
0,1,-4:17.12
1,1,-4:17.12
-1,2,-4:17.12
0,2,-4:17.12
-2,3,-4:17.12
-1,3,-4:17.12
0,3,-4:17.12
-2,1,-3:17.12
-1,1,-3:17.12
1,1,-3:17.12
-1,2,-3:17.12
0,2,-3:17.12
1,2,-3:17.12
-2,3,-3:17.12
-1,-1,-2:17.12
-2,0,-2:17.12
0,0,-2:17.12
-2,1,-2:17.12
-1,1,-2:17.12
0,1,-2:17.12
-1,2,-2:17.12
-1,-1,-1:17.12
-2,0,-1:17.12
0,0,-1:17.12
-2,1,-1:17.12
0,1,-1:17.12
-2,2,-1:17.12
-1,2,-1:17.12
0,2,-1:17.12
-1,-1,0:17.12
-2,0,0:17.12
-1,0,0:17.12
0,0,0:17.12
-2,1,0:17.12
0,1,0:17.12
-1,2,0:17.12
0,2,0:17.12
-2,0,1:17.12
-1,0,1:17.12
0,0,1:17.12
-2,1,1:17.12
0,1,1:17.12
-1,2,1:17.12
-2,0,2:17.12
-1,0,2:17.12
0,0,2:17.12
-2,1,2:17.12
-1,1,2:17.12
0,1,2:17.12
-2,0,3:17.12
-1,0,3:17.12
0,0,3:17.12
-2,1,3:17.12
-1,1,3:17.12
0,1,3:17.12
-2,0,4:17.12
-1,0,4:17.12
0,0,4:17.12
-2,1,4:17.12
-1,1,4:17.12
0,1,4:17.12
-2,0,5:17.12
-1,0,5:17.12
0,0,5:17.12
-2,1,5:17.12
-1,1,5:17.12
0,1,5:17.12
-3,-6,6:18.5
-6,-5,6:18.5
-2,-5,6:18.5
-6,-4,6:18.13
-6,-3,6:18.13
-2,0,6:17.12
-1,0,6:17.12
0,0,6:17.12
-2,1,6:17.12
-1,1,6:17.12
0,1,6:17.12
-5,4,6:18.13
-5,5,6:18.13
-4,6,6:18.13
-3,6,6:18.13
-2,6,6:18.5
-5,-6,7:18.5
-4,-6,7:18.5
-6,-5,7:18.5
-5,-5,7:18.5
-4,-5,7:18.5
-3,-5,7:18.5
-2,-5,7:18.5
-5,-4,7:18.13
-4,-4,7:18.13
-3,-4,7:18.13
-2,-4,7:18.13
-5,-3,7:18.13
4,-2,7:18.13
4,-1,7:18.13
5,-1,7:18.5
6,-1,7:18.5
-2,0,7:17.12
-1,0,7:17.12
0,0,7:17.12
6,0,7:18.5
7,0,7:18.5
-2,1,7:17.12
-1,1,7:17.12
0,1,7:17.12
-5,2,7:18.13
4,2,7:18.13
5,2,7:18.5
6,2,7:18.5
7,2,7:18.5
-5,3,7:18.13
4,3,7:18.13
5,3,7:18.5
-6,4,7:18.13
-5,4,7:18.13
-4,4,7:18.13
-5,5,7:18.13
-4,5,7:18.13
-3,5,7:18.13
-2,5,7:18.13
-4,6,7:18.13
-3,6,7:18.13
1,-6,8:18.5
-4,-5,8:18.5
0,-5,8:18.5
-4,-4,8:18.13
-3,-4,8:18.13
-2,-4,8:18.13
3,-4,8:18.13
-5,-3,8:18.13
-4,-3,8:18.13
-3,-3,8:18.13
-2,-3,8:18.13
3,-3,8:18.13
-8,-2,8:18.5
-7,-2,8:18.5
-6,-2,8:18.13
-5,-2,8:18.13
-9,-1,8:18.5
-8,-1,8:18.5
3,-1,8:18.13
4,-1,8:18.13
-8,0,8:18.5
-7,0,8:18.5
-2,0,8:17.12
-1,0,8:17.12
0,0,8:18.13
3,0,8:18.13
4,0,8:18.13
5,0,8:18.5
6,0,8:18.5
7,0,8:18.5
-7,1,8:18.5
-6,1,8:18.13
-2,1,8:17.12
-1,1,8:17.12
0,1,8:17.12
3,1,8:18.13
4,1,8:18.13
5,1,8:18.5
6,1,8:18.5
7,1,8:18.5
8,1,8:18.5
-6,2,8:18.13
-5,2,8:18.13
-4,2,8:18.13
3,2,8:18.13
4,2,8:18.13
-4,3,8:18.13
-6,4,8:18.13
-4,4,8:18.13
-3,4,8:18.13
-2,4,8:18.13
-6,5,8:18.13
-5,5,8:18.13
-4,5,8:18.13
3,5,8:18.13
-6,6,8:18.13
-5,6,8:18.13
-1,6,8:18.5
2,-6,9:18.5
3,-6,9:18.5
-6,-5,9:18.5
-5,-5,9:18.5
-4,-5,9:18.5
-3,-5,9:18.5
-2,-5,9:18.5
0,-5,9:18.5
1,-5,9:18.5
2,-5,9:18.5
3,-5,9:18.5
-6,-4,9:18.13
0,-4,9:18.13
1,-4,9:18.13
2,-4,9:18.13
3,-4,9:18.13
-6,-3,9:18.13
-3,-3,9:18.13
-2,-3,9:18.13
2,-3,9:18.13
3,-3,9:18.13
-6,-2,9:18.13
-5,-2,9:18.13
-3,-2,9:18.13
-2,-2,9:18.13
2,-2,9:18.13
3,-2,9:18.13
4,-2,9:18.13
5,-2,9:18.5
-9,-1,9:18.5
-8,-1,9:18.5
-7,-1,9:18.5
-6,-1,9:18.13
-5,-1,9:18.13
-3,-1,9:18.13
-2,-1,9:18.13
-1,-1,9:18.13
2,-1,9:18.13
-8,0,9:18.5
-7,0,9:18.5
-6,0,9:18.13
-5,0,9:18.13
-2,0,9:18.13
-1,0,9:17.12
0,0,9:18.13
2,0,9:18.13
3,0,9:18.13
4,0,9:18.13
5,0,9:18.5
-6,1,9:18.13
-5,1,9:18.13
-3,1,9:18.13
-2,1,9:18.13
-1,1,9:17.12
0,1,9:18.13
1,1,9:18.13
2,1,9:18.13
3,1,9:18.13
4,1,9:18.13
-3,2,9:18.13
-2,2,9:18.13
-1,2,9:18.13
2,2,9:18.13
-3,3,9:18.13
-2,3,9:18.13
-6,4,9:18.13
2,4,9:18.13
3,4,9:18.13
-1,5,9:18.13
0,5,9:18.13
2,5,9:18.13
3,5,9:18.13
-1,6,9:18.5
0,6,9:18.5
1,6,9:18.5
2,6,9:18.5
3,6,9:18.5
-3,7,9:18.13
-2,7,9:18.5
0,7,9:18.5
1,7,9:18.5
2,7,9:18.5
1,8,9:18.5
-5,-5,10:18.5
-5,-4,10:18.13
-4,-4,10:18.13
-3,-4,10:18.13
-2,-4,10:18.13
1,-4,10:18.13
-5,-3,10:18.13
0,-3,10:18.13
1,-3,10:18.13
-5,-2,10:18.13
-2,-2,10:18.13
1,-2,10:18.13
2,-2,10:18.13
3,-2,10:18.13
4,-2,10:18.13
5,-2,10:18.5
6,-2,10:18.5
-5,-1,10:18.13
-4,-1,10:18.13
-3,-1,10:18.13
-2,-1,10:18.13
-1,-1,10:18.13
5,-1,10:18.5
6,-1,10:18.5
7,-1,10:18.5
-5,0,10:18.13
-4,0,10:18.13
-2,0,10:18.13
-1,0,10:17.12
0,0,10:18.13
1,0,10:18.13
2,0,10:18.13
3,0,10:18.13
4,0,10:18.13
5,0,10:18.5
-2,1,10:18.13
-1,1,10:17.12
0,1,10:18.13
1,1,10:18.13
2,1,10:18.13
3,1,10:18.13
-2,2,10:18.13
-1,2,10:18.13
-1,3,10:18.13
1,3,10:18.13
-5,4,10:18.13
-1,4,10:18.13
0,4,10:18.13
1,4,10:18.13
-5,5,10:18.13
0,5,10:18.13
1,5,10:18.13
-5,6,10:18.13
-4,6,10:18.13
-3,6,10:18.13
-2,6,10:18.5
1,6,10:18.5
2,6,10:18.5
-4,7,10:18.13
-3,7,10:18.13
1,7,10:18.5
2,7,10:18.5
2,8,10:18.5
-4,-4,11:18.13
-4,-3,11:18.13
-3,-3,11:18.13
-2,-3,11:18.13
-1,-2,11:18.13
0,-2,11:18.13
1,-2,11:18.13
2,-2,11:18.13
-3,-1,11:18.13
-1,-1,11:18.13
0,-1,11:18.13
1,-1,11:18.13
2,-1,11:18.13
3,-1,11:18.13
4,-1,11:18.13
5,-1,11:18.5
6,-1,11:18.5
-4,0,11:18.13
-3,0,11:18.13
-2,0,11:18.13
-1,0,11:18.13
0,0,11:18.13
2,0,11:18.13
3,0,11:18.13
4,0,11:18.13
-3,1,11:18.13
-2,1,11:18.13
-1,1,11:18.13
0,1,11:18.13
1,1,11:18.13
2,1,11:18.13
-1,2,11:18.13
0,2,11:18.13
1,2,11:18.13
-1,3,11:18.13
0,3,11:18.13
1,3,11:18.13
-5,4,11:18.13
-4,4,11:18.13
-5,5,11:18.13
-4,5,11:18.13
-3,5,11:18.13
-2,5,11:18.13
-5,6,11:18.13
-4,6,11:18.13
-3,6,11:18.13
-4,-6,12:18.5
-3,-6,12:18.5
-2,-6,12:18.5
-4,-5,12:18.5
-2,-5,12:18.5
-1,-5,12:18.5
0,-5,12:18.5
-4,-4,12:18.13
-4,-3,12:18.13
-3,-2,12:18.13
-2,-2,12:18.13
-4,-1,12:18.13
-3,-1,12:18.13
-1,-1,12:18.13
0,-1,12:18.13
1,-1,12:18.13
2,-1,12:18.13
3,-1,12:18.13
4,-1,12:18.5
-3,0,12:18.13
-2,0,12:18.13
-1,0,12:18.13
0,0,12:18.13
1,0,12:18.13
2,0,12:18.13
3,0,12:18.13
4,0,12:18.5
5,0,12:18.5
-3,1,12:18.13
-2,1,12:18.13
-1,1,12:18.13
0,1,12:18.13
1,1,12:18.13
5,1,12:18.5
6,1,12:18.5
-1,2,12:18.13
0,2,12:18.13
1,2,12:18.13
2,2,12:18.13
3,2,12:18.13
4,2,12:18.5
5,2,12:18.5
-7,3,12:18.13
-4,3,12:18.13
-3,3,12:18.13
-2,3,12:18.13
2,3,12:18.13
-4,4,12:18.13
-3,4,12:18.13
-2,4,12:18.13
-5,5,12:18.13
-4,5,12:18.13
-3,-5,13:18.5
-2,-5,13:18.5
-4,-4,13:18.13
-3,-4,13:18.13
-2,-4,13:18.13
-1,-4,13:18.13
-4,-3,13:18.13
-3,-3,13:18.13
-3,-1,13:18.13
-2,-1,13:18.13
-1,-1,13:18.13
0,-1,13:18.13
2,-1,13:18.13
-3,0,13:18.13
-2,0,13:18.13
-1,0,13:18.13
0,0,13:18.13
1,0,13:18.13
2,0,13:18.13
3,0,13:18.13
4,0,13:18.5
-2,1,13:18.13
-1,1,13:18.13
0,1,13:18.13
4,1,13:18.5
5,1,13:18.5
6,1,13:18.5
-6,2,13:18.13
-3,2,13:18.13
-2,2,13:18.13
-1,2,13:18.13
1,2,13:18.13
2,2,13:18.13
3,2,13:18.13
4,2,13:18.5
5,2,13:18.5
6,2,13:18.5
-7,3,13:18.13
-6,3,13:18.13
-3,3,13:18.13
-2,3,13:18.13
-6,4,13:18.13
-5,4,13:18.13
-4,4,13:18.13
-5,5,13:18.13
-4,5,13:18.13
-3,-4,14:18.13
-2,-4,14:18.13
-3,-3,14:18.13
-2,-3,14:18.13
-1,-3,14:18.13
-3,-2,14:18.13
-2,-1,14:18.13
-1,-1,14:18.13
-2,0,14:18.13
-1,0,14:18.13
0,0,14:18.13
1,0,14:18.13
2,0,14:18.13
3,0,14:18.13
-3,1,14:18.13
-2,1,14:18.13
-1,1,14:18.13
0,1,14:18.13
2,1,14:18.13
3,1,14:18.13
4,1,14:18.5
-5,2,14:18.13
-2,2,14:18.13
1,2,14:18.13
2,2,14:18.13
3,2,14:18.13
4,2,14:18.5
5,2,14:18.5
-6,3,14:18.13
-5,3,14:18.13
-4,3,14:18.13
-3,3,14:18.13
-6,4,14:18.13
-5,4,14:18.13
-4,4,14:18.13
-2,4,14:18.13
1,4,14:18.13
-6,-4,15:18.5
-5,-4,15:18.5
-4,-4,15:18.5
-6,-3,15:18.5
-5,-3,15:18.5
-4,-3,15:18.5
-2,-3,15:18.5
1,-3,15:18.5
2,-3,15:18.5
3,-3,15:18.5
-6,-2,15:18.5
-3,-2,15:18.5
-2,-2,15:18.5
-1,-2,15:18.5
2,-2,15:18.5
3,-2,15:18.5
4,-2,15:18.5
-6,-1,15:18.5
-3,-1,15:18.5
-2,-1,15:18.5
-1,-1,15:18.5
3,-1,15:18.5
4,-1,15:18.5
-2,0,15:18.5
-1,0,15:18.5
0,0,15:18.5
1,0,15:18.5
2,0,15:18.5
3,0,15:18.5
-3,1,15:18.5
-2,1,15:18.5
-1,1,15:18.5
0,1,15:18.5
1,1,15:18.5
2,1,15:18.5
3,1,15:18.5
-4,2,15:18.13
-3,2,15:18.5
-5,3,15:18.13
-4,3,15:18.13
-3,3,15:18.5
-2,3,15:18.5
0,3,15:18.5
-2,4,15:18.5
0,4,15:18.5
-2,5,15:18.5
0,5,15:18.5
-2,6,15:18.5
-1,6,15:18.5
0,6,15:18.5
-1,7,15:18.5
-5,-3,16:18.5
-4,-3,16:18.5
-5,-2,16:18.5
1,-2,16:18.5
2,-2,16:18.5
3,-2,16:18.5
-5,-1,16:18.5
-2,-1,16:18.5
-1,-1,16:18.5
2,-1,16:18.5
3,-1,16:18.5
-2,0,16:18.5
-1,0,16:18.5
0,0,16:18.5
1,0,16:18.5
2,0,16:18.5
-3,1,16:18.5
-2,1,16:18.5
-1,1,16:18.5
0,1,16:18.5
1,1,16:18.5
-3,2,16:18.5
-2,2,16:18.5
-2,3,16:18.5
0,3,16:18.5
-2,4,16:18.5
-1,4,16:18.5
0,4,16:18.5
-2,5,16:18.5
-1,5,16:18.5
-1,6,16:18.5
-2,-5,17:18.5
-1,-5,17:18.5
-3,-4,17:18.5
-2,-4,17:18.5
-1,-4,17:18.5
0,-4,17:18.5
-3,-3,17:18.5
0,-3,17:18.5
-3,-2,17:18.5
-4,-1,17:18.5
-3,-1,17:18.5
0,-1,17:18.5
1,-1,17:18.5
2,-1,17:18.5
-2,0,17:18.5
-1,0,17:18.5
0,0,17:18.5
1,0,17:18.5
2,0,17:18.5
3,0,17:18.5
-6,1,17:18.5
-2,1,17:18.5
-1,1,17:18.5
3,1,17:18.5
4,1,17:18.5
-6,2,17:18.13
-2,2,17:18.5
-1,2,17:18.5
0,2,17:18.5
1,2,17:18.5
2,2,17:18.5
3,2,17:18.5
4,2,17:18.5
-6,3,17:18.13
-2,3,17:18.5
-1,3,17:18.5
3,3,17:18.5
-5,4,17:18.13
-4,4,17:18.5
-1,4,17:18.5
-2,-4,18:18.5
-1,-4,18:18.5
-3,-3,18:18.5
-2,-3,18:18.5
-1,-3,18:18.5
-1,-2,18:18.5
-3,-1,18:18.5
0,-1,18:18.5
-3,0,18:18.5
-2,0,18:18.5
-1,0,18:18.5
0,0,18:18.5
1,0,18:18.5
2,0,18:18.5
-5,1,18:18.5
-2,1,18:17.0
-1,1,18:18.5
2,1,18:18.5
3,1,18:18.5
-6,2,18:18.13
-5,2,18:18.13
-2,2,18:18.5
-1,2,18:18.5
0,2,18:18.5
1,2,18:18.5
2,2,18:18.5
3,2,18:18.5
4,2,18:18.5
-6,3,18:18.13
-5,3,18:18.13
-4,3,18:18.5
-1,3,18:18.5
-6,-3,19:18.5
-5,-3,19:18.5
-2,-3,19:18.5
1,-3,19:18.5
2,-3,19:18.5
3,-3,19:18.5
-6,-2,19:18.5
-2,-2,19:18.5
-1,-2,19:18.5
3,-2,19:18.5
-6,-1,19:18.5
-2,-1,19:18.5
2,-1,19:18.5
3,-1,19:18.5
-6,0,19:18.5
-2,0,19:17.0
-1,0,19:17.0
0,0,19:18.5
1,0,19:18.5
-2,1,19:17.0
-1,1,19:17.0
0,1,19:18.5
1,1,19:18.5
2,1,19:18.5
-5,2,19:18.13
-4,2,19:18.5
-3,2,19:18.5
1,2,19:18.5
2,2,19:18.5
-2,3,19:18.5
1,3,19:18.5
-2,4,19:18.5
0,4,19:18.5
1,4,19:18.5
-1,5,19:18.5
0,5,19:18.5
-1,6,19:18.5
-6,-3,20:18.5
-5,-3,20:18.5
-6,-2,20:18.5
-5,-2,20:18.5
0,-2,20:18.5
1,-2,20:18.5
2,-2,20:18.5
-6,-1,20:18.5
-5,-1,20:18.5
-2,-1,20:18.5
-1,-1,20:18.5
1,-1,20:18.5
2,-1,20:18.5
-5,0,20:18.5
-2,0,20:17.0
-1,0,20:17.0
0,0,20:18.5
2,0,20:18.5
-3,1,20:18.5
-2,1,20:18.5
-1,1,20:17.0
0,1,20:18.5
1,1,20:18.5
-2,2,20:18.5
-1,2,20:18.5
0,2,20:18.5
-2,3,20:18.5
0,3,20:18.5
-1,4,20:18.5
0,4,20:18.5
-1,5,20:18.5
0,5,20:18.5
-1,6,20:18.5
0,6,20:18.5
-2,-4,21:18.5
-5,-2,21:18.5
0,-2,21:18.5
1,-2,21:18.5
-5,-1,21:18.5
-4,-1,21:18.5
-3,-1,21:18.5
-2,-1,21:18.5
-1,-1,21:18.5
0,-1,21:18.5
1,-1,21:18.5
-4,0,21:18.5
-3,0,21:18.5
-2,0,21:17.0
-1,0,21:17.0
0,0,21:18.5
-2,1,21:18.5
-1,1,21:18.5
0,1,21:18.5
-2,2,21:18.5
-1,2,21:18.5
0,2,21:18.5
-1,3,21:18.5
0,3,21:18.5
-1,4,21:18.5
-1,-5,22:18.5
-2,-4,22:18.5
-1,-4,22:18.5
0,-4,22:18.5
-2,-3,22:18.5
0,-3,22:18.5
-3,-2,22:18.5
0,-2,22:18.5
-3,-1,22:18.5
-2,-1,22:18.5
-1,-1,22:18.5
0,-1,22:18.5
-5,0,22:18.5
-3,0,22:18.5
-2,0,22:17.0
-1,0,22:17.0
0,0,22:18.5
-6,1,22:18.5
-5,1,22:18.5
-2,1,22:18.5
-1,1,22:18.5
-6,2,22:18.13
-5,2,22:18.13
-4,2,22:18.5
-1,2,22:18.5
-1,3,22:18.5
2,3,22:18.5
0,4,22:18.5
1,4,22:18.5
2,4,22:18.5
-1,-4,23:18.5
-2,-3,23:18.5
-1,-3,23:18.5
-2,-2,23:18.5
-1,-2,23:18.5
-2,-1,23:18.5
-1,-1,23:18.5
-4,0,23:18.5
-3,0,23:18.5
-2,0,23:18.5
-1,0,23:18.5
0,0,23:18.5
-5,1,23:18.5
-2,1,23:18.5
-1,1,23:18.5
0,1,23:18.5
-5,2,23:18.13
-4,2,23:18.5
1,2,23:18.5
0,3,23:18.5
1,3,23:18.5
0,4,23:18.5
1,4,23:18.5
-1,-3,24:18.5
-2,-2,24:18.5
-1,-2,24:18.5
-2,-1,24:18.5
-1,-1,24:18.5
-4,0,24:18.5
-3,0,24:18.5
-2,0,24:18.5
-1,0,24:18.5
0,0,24:18.5
-3,1,24:18.5
-2,1,24:18.5
-1,1,24:18.5
0,1,24:18.5
0,2,24:18.5
1,2,24:18.5
0,3,24:18.5
1,3,24:18.5
-5,-3,25:18.5
-4,-3,25:18.5
-5,-2,25:18.5
-3,-2,25:18.5
-2,-2,25:18.5
-1,-2,25:18.5
-5,-1,25:18.5
-2,-1,25:18.5
-1,-1,25:18.5
-5,0,25:18.5
-3,0,25:18.5
-2,0,25:18.5
-1,0,25:18.5
-3,1,25:18.5
-2,1,25:18.5
-1,1,25:18.5
0,1,25:18.5
-1,2,25:18.5
0,2,25:18.5
-4,3,25:18.5
-4,4,25:18.5
-2,4,25:18.5
-3,5,25:18.5
-5,-3,26:18.5
-4,-3,26:18.5
-5,-2,26:18.5
-3,-2,26:18.5
-2,-2,26:18.5
-5,-1,26:18.5
-4,-1,26:18.5
-2,-1,26:18.5
-1,-1,26:18.5
2,-1,26:18.5
3,-1,26:18.5
-4,0,26:18.5
-2,0,26:18.5
-1,0,26:18.5
3,0,26:18.5
-2,1,26:18.5
-1,1,26:18.5
2,1,26:18.5
3,1,26:18.5
-4,3,26:18.5
-3,3,26:18.5
-3,4,26:18.5
-2,4,26:18.5
-3,5,26:18.5
0,-4,27:18.5
-1,-3,27:18.5
1,-3,27:18.5
-3,-2,27:18.5
1,-2,27:18.5
-5,-1,27:18.5
-4,-1,27:18.5
-3,-1,27:18.5
-2,-1,27:18.5
1,-1,27:18.5
2,-1,27:18.5
-2,0,27:18.5
-1,0,27:17.0
1,0,27:18.5
2,0,27:18.5
-2,1,27:18.5
-1,1,27:17.0
1,1,27:18.5
2,1,27:18.5
-3,2,27:18.5
-3,3,27:18.5
-2,3,27:18.5
-1,3,27:18.5
0,-4,28:18.5
-1,-3,28:18.5
0,-3,28:18.5
0,-2,28:18.5
1,-2,28:18.5
-5,-1,28:18.5
-4,-1,28:18.5
-3,-1,28:18.5
-2,-1,28:18.5
0,-1,28:18.5
1,-1,28:18.5
-6,0,28:18.5
-5,0,28:18.5
-3,0,28:18.5
-2,0,28:17.0
-1,0,28:17.0
0,0,28:18.5
1,0,28:18.5
-5,1,28:18.5
-2,1,28:17.0
-1,1,28:17.0
1,1,28:18.5
-3,2,28:18.5
-2,2,28:18.5
-1,2,28:18.5
1,2,28:18.5
-1,3,28:18.5
0,3,28:18.5
1,3,28:18.5
-1,-3,29:18.5
0,-3,29:18.5
-1,-2,29:18.5
0,-2,29:18.5
-4,-1,29:18.5
-3,-1,29:18.5
-2,-1,29:18.5
0,-1,29:18.5
-5,0,29:18.5
-4,0,29:18.5
-3,0,29:18.5
-2,0,29:17.0
-1,0,29:17.0
0,0,29:18.5
-2,1,29:18.5
-1,1,29:17.0
1,1,29:18.5
-1,2,29:18.5
0,2,29:18.5
1,2,29:18.5
0,3,29:18.5
1,3,29:18.5
-1,-2,30:18.5
0,-2,30:18.5
-4,-1,30:18.5
-3,-1,30:18.5
-1,-1,30:18.5
0,-1,30:18.5
-4,0,30:18.5
-3,0,30:18.5
-2,0,30:17.0
-1,0,30:17.0
-2,1,30:17.0
-1,1,30:18.5
0,1,30:18.5
-2,2,30:18.5
-1,2,30:18.5
0,2,30:18.5
-1,-2,31:18.5
-3,-1,31:18.5
-1,-1,31:18.5
0,-1,31:18.5
-4,0,31:18.5
-3,0,31:18.5
-2,0,31:17.0
-1,0,31:17.0
-2,1,31:17.0
-1,1,31:18.5
0,1,31:18.5
-2,2,31:18.5
-1,2,31:18.5
-3,3,31:18.5
-4,-3,32:18.5
-5,-2,32:18.5
-3,-2,32:18.5
-2,-2,32:18.5
1,-2,32:18.5
-4,-1,32:18.5
-1,-1,32:18.5
1,-1,32:18.5
2,-1,32:18.5
-3,0,32:18.5
-2,0,32:17.0
-1,0,32:17.0
1,0,32:18.5
2,0,32:18.5
-2,1,32:18.5
-1,1,32:18.5
-3,2,32:18.5
-1,2,32:18.5
-3,3,32:18.5
-2,3,32:18.5
-1,3,32:18.5
-1,-3,33:18.5
-3,-2,33:18.5
0,-2,33:18.5
-4,-1,33:18.5
-3,-1,33:18.5
-2,-1,33:18.5
-1,-1,33:18.5
0,-1,33:18.5
1,-1,33:18.5
-4,0,33:18.5
-3,0,33:18.5
-2,0,33:17.0
-1,0,33:17.0
0,0,33:18.5
1,0,33:18.5
-3,1,33:18.5
-2,1,33:18.5
-1,1,33:18.5
-3,2,33:18.5
-2,2,33:18.5
-1,-3,34:18.5
-1,-2,34:18.5
0,-2,34:18.5
-4,-1,34:18.5
-3,-1,34:18.5
-2,-1,34:18.5
-1,-1,34:18.5
0,-1,34:18.5
-4,0,34:18.5
-3,0,34:18.5
-2,0,34:17.0
-1,0,34:17.0
0,0,34:18.5
-2,1,34:18.5
-1,2,34:18.5
0,2,34:18.5
1,2,34:18.5
-1,3,34:18.5
0,3,34:18.5
-3,-2,35:18.5
-2,-2,35:18.5
-1,-2,35:18.5
-1,-1,35:18.5
-3,0,35:18.5
-2,0,35:17.0
-1,0,35:17.0
1,0,35:18.5
-3,1,35:18.5
-1,1,35:18.5
0,1,35:18.5
-4,2,35:18.5
-1,2,35:18.5
0,2,35:18.5
-3,-2,36:18.5
-2,-2,36:18.5
-1,-2,36:18.5
-2,-1,36:18.5
-1,-1,36:18.5
-3,0,36:18.5
-2,0,36:17.0
-1,0,36:17.0
0,0,36:18.5
1,0,36:18.5
-3,1,36:18.5
-2,1,36:18.5
-1,1,36:18.5
0,1,36:18.5
-3,2,36:18.5
-2,-2,37:18.5
-2,-1,37:18.5
-3,0,37:18.5
-2,0,37:17.0
-1,0,37:18.5
0,0,37:18.5
-3,1,37:18.5
-1,2,37:18.5
-1,-2,38:18.5
-3,-1,38:18.5
-2,-1,38:18.5
-1,-1,38:18.5
0,-1,38:18.5
-4,0,38:18.5
-3,0,38:18.5
-2,0,38:17.0
-1,0,38:18.5
-2,1,38:18.5
0,1,38:18.5
-2,2,38:18.5
-1,2,38:18.5
0,2,38:18.5
-1,-2,39:18.5
-3,-1,39:18.5
-2,-1,39:18.5
-1,-1,39:18.5
-4,0,39:18.5
-3,0,39:18.5
-2,0,39:17.0
-1,0,39:18.5
-2,1,39:18.5
-1,1,39:18.5
0,1,39:18.5
-3,-1,40:18.5
-2,-1,40:18.5
-1,-1,40:18.5
-3,0,40:18.5
-2,0,40:17.0
-1,0,40:18.5
-3,1,40:18.5
-2,1,40:18.5
-1,1,40:18.5
-2,-1,41:18.5
-3,0,41:18.5
-2,0,41:18.5
-1,0,41:18.5
0,0,41:18.5
-3,1,41:18.5
-2,1,41:18.5
-2,-2,42:18.5
-3,-1,42:18.5
-2,-1,42:18.5
0,-1,42:18.5
-2,0,42:18.5
-1,0,42:17.0
0,0,42:18.5
-2,1,42:18.5
-3,-1,43:18.5
-2,-1,43:18.5
-1,-1,43:18.5
0,-1,43:18.5
-2,0,43:17.0
-1,0,43:18.5
-2,1,43:18.5
-3,-1,44:18.5
-2,-1,44:18.5
-1,-1,44:18.5
-2,0,44:17.0
-1,0,44:18.5
-1,-2,45:18.5
-3,-1,45:18.5
-1,-1,45:18.5
-4,0,45:18.5
-3,0,45:18.5
-2,0,45:17.0
-2,1,45:18.5
-1,1,45:18.5
-3,-1,46:18.5
-1,-1,46:18.5
-3,0,46:18.5
-2,0,46:17.0
-2,1,46:18.5
-1,1,46:18.5
0,1,46:18.5
-2,-1,47:18.5
-3,0,47:18.5
-2,0,47:18.5
-1,0,47:18.5
-2,0,48:17.0
-2,0,49:17.0
-2,0,50:17.0
-2,0,51:17.0
-2,0,52:17.0
-2,0,53:17.0
-2,0,54:17.0
-2,0,55:17.0
