[META]
version=2.0
spawnOnBlockType=2
spawnSunlight=True
spawnDarkness=True
spawnWater=False
spawnLava=False
underFill=False
randomRotation=True
dig=True
tree=False
branch=False
needsFoundation=True
rarity=100
collisionPercentage=20
spawnElevationMin=0
spawnElevationMax=200
spawnInBiome=Custom
[DATA]
-6,8,-8:17.12
-5,8,-8:17.12
-5,6,-7:17.12
-4,6,-7:17.12
-7,7,-7:17.12
-5,7,-7:17.12
-4,7,-7:17.12
-6,8,-7:17.12
-5,8,-7:17.12
-4,8,-7:17.12
-5,10,-7:17.12
-6,6,-6:17.12
-5,6,-6:17.12
-4,6,-6:17.12
-5,7,-6:17.12
-4,7,-6:17.12
-3,7,-6:17.12
-7,8,-6:17.12
-6,8,-6:17.12
-5,8,-6:17.12
-4,8,-6:17.12
-3,8,-6:17.12
-2,8,-6:17.12
-6,9,-6:17.12
-5,9,-6:17.12
-4,9,-6:17.12
-4,6,-5:17.12
-4,7,-5:17.12
-6,8,-5:17.12
-5,8,-5:17.12
-4,8,-5:17.12
-3,8,-5:17.12
-2,8,-5:17.12
-6,9,-5:17.12
-5,9,-5:17.12
-4,9,-5:17.12
-5,10,-5:17.12
-5,7,-4:17.12
-4,7,-4:17.12
-3,7,-4:17.12
-6,8,-4:17.12
-5,8,-4:17.12
-4,8,-4:17.12
-3,8,-4:17.12
-5,9,-4:17.12
-4,9,-4:17.12
-3,9,-4:17.12
-6,7,-3:17.12
-5,7,-3:17.12
-4,7,-3:17.12
-6,8,-3:17.12
-5,8,-3:17.12
-4,8,-3:17.12
-3,8,-3:17.12
-2,8,-3:17.12
-6,9,-3:17.12
-5,9,-3:17.12
-4,9,-3:17.12
-3,9,-3:17.12
-2,9,-3:17.12
-5,10,-3:17.12
-5,6,-2:17.12
-6,7,-2:17.12
-5,7,-2:17.12
-4,7,-2:17.12
-3,7,-2:18.13
-2,7,-2:18.13
-6,8,-2:17.12
-4,8,-2:17.12
-3,8,-2:18.13
-2,8,-2:18.13
-1,8,-2:18.13
-6,9,-2:17.12
-5,9,-2:17.12
-4,9,-2:17.12
-3,9,-2:18.13
-2,9,-2:18.13
-1,9,-2:18.13
-5,10,-2:17.12
-4,10,-2:18.13
-3,10,-2:18.13
-2,10,-2:18.13
-1,10,-2:18.13
-5,6,-1:17.12
-6,7,-1:17.12
-5,7,-1:17.12
-4,7,-1:17.12
-3,7,-1:18.13
-2,7,-1:18.13
-6,8,-1:17.12
-4,8,-1:17.12
-3,8,-1:18.13
-2,8,-1:18.13
-1,8,-1:18.13
-6,9,-1:17.12
-5,9,-1:17.12
-4,9,-1:17.12
-3,9,-1:18.13
-2,9,-1:18.13
-1,9,-1:18.13
-3,10,-1:18.13
-2,10,-1:18.13
-6,7,0:17.12
-5,7,0:17.12
-4,7,0:17.12
-3,7,0:18.13
-2,7,0:18.13
-6,8,0:17.12
-5,8,0:17.12
-4,8,0:17.12
-3,8,0:18.13
-2,8,0:18.13
-1,8,0:18.13
-6,9,0:17.12
-5,9,0:17.12
-4,9,0:17.12
-3,9,0:18.13
-2,9,0:18.13
-1,9,0:18.13
-3,10,0:18.13
-2,10,0:18.13
-8,5,1:18.14
-7,6,1:18.14
-6,6,1:18.14
-5,6,1:18.14
-4,6,1:18.14
-8,7,1:18.14
-7,7,1:18.14
-6,7,1:18.14
-5,7,1:18.14
-4,7,1:18.14
-7,8,1:18.14
-6,8,1:17.12
-5,8,1:17.12
-4,8,1:17.12
-3,8,1:18.13
-2,8,1:18.13
-1,8,1:18.13
-6,9,1:17.12
-5,9,1:17.12
-4,9,1:17.12
-3,9,1:18.13
-2,9,1:18.13
-1,9,1:18.13
-3,10,1:18.13
-2,10,1:18.13
-6,5,2:18.14
-5,5,2:18.14
-8,6,2:18.14
-7,6,2:18.14
-6,6,2:18.14
-5,6,2:18.14
-4,6,2:18.14
-7,7,2:18.14
-6,7,2:18.14
-5,7,2:18.14
-4,7,2:18.14
-6,8,2:18.14
-5,8,2:17.12
-4,8,2:17.12
-3,8,2:18.13
-2,8,2:18.13
-6,9,2:17.12
-5,9,2:17.12
-4,9,2:17.12
-3,9,2:18.13
-2,9,2:18.13
-1,9,2:18.13
-5,5,3:18.14
-7,6,3:18.14
-6,6,3:18.14
-5,6,3:18.14
-4,6,3:18.14
-6,7,3:18.14
-5,7,3:18.14
-4,7,3:18.14
-6,8,3:18.14
-5,8,3:17.12
-4,8,3:17.12
-3,8,3:18.13
-2,8,3:18.13
-5,9,3:17.12
-4,9,3:17.12
-3,9,3:18.13
-2,9,3:18.13
-7,5,4:18.14
-6,5,4:18.14
-5,5,4:18.14
-7,6,4:18.14
-6,6,4:18.14
-5,6,4:18.14
-4,6,4:18.14
-3,6,4:18.14
-7,7,4:18.14
-6,7,4:18.14
-5,7,4:18.14
-4,7,4:18.14
-3,7,4:18.14
-5,8,4:17.12
-4,8,4:17.12
-2,8,4:18.13
-5,9,4:17.12
-4,9,4:17.12
-2,9,4:18.13
-2,4,5:18.13
-1,4,5:18.13
0,4,5:18.13
1,4,5:18.5
2,4,5:18.5
3,4,5:18.5
-1,5,5:18.13
2,5,5:18.5
3,5,5:18.5
-7,6,5:18.14
-6,6,5:18.14
-5,6,5:18.14
-4,6,5:18.14
-3,6,5:18.14
1,6,5:18.5
2,6,5:18.5
-6,7,5:18.14
-5,7,5:18.14
1,7,5:18.5
-11,8,5:18.5
-5,8,5:17.12
-4,8,5:17.12
-2,8,5:18.13
0,8,5:18.13
1,8,5:18.5
-5,9,5:17.12
-4,9,5:17.12
-2,9,5:18.13
-2,13,5:18.13
-6,14,5:18.5
-5,14,5:18.5
-2,14,5:18.5
-5,15,5:18.5
-3,15,5:18.5
-2,15,5:18.5
-5,16,5:18.5
-4,16,5:18.5
-3,16,5:18.5
-12,4,6:18.5
-11,4,6:18.5
-10,4,6:18.5
-9,4,6:18.5
-8,4,6:18.13
2,4,6:18.5
-10,5,6:18.13
-9,5,6:18.13
-8,5,6:18.13
-2,5,6:18.13
-1,5,6:18.13
0,5,6:18.13
1,5,6:18.5
2,5,6:18.5
-12,6,6:18.5
-11,6,6:18.5
-6,6,6:18.14
-5,6,6:18.14
-1,6,6:18.13
1,6,6:18.5
-12,7,6:18.5
-11,7,6:18.5
-10,7,6:18.13
-6,7,6:18.14
-5,7,6:18.14
0,7,6:18.13
-11,8,6:18.5
-10,8,6:18.13
-5,8,6:17.12
-4,8,6:17.12
-1,8,6:18.13
0,8,6:18.13
-5,9,6:17.12
-4,9,6:17.12
1,10,6:18.5
-6,13,6:18.13
-5,13,6:18.13
-4,13,6:18.13
-3,13,6:18.13
-2,13,6:18.13
-5,14,6:18.5
-4,14,6:18.5
-3,14,6:18.5
-5,15,6:18.5
-4,15,6:18.5
-3,15,6:18.5
-4,16,6:18.5
-3,16,6:18.5
-6,2,7:18.5
-6,3,7:18.5
-3,3,7:18.5
-2,3,7:18.5
-12,4,7:18.5
-2,4,7:18.13
-12,5,7:18.5
-11,5,7:18.5
-10,5,7:18.5
-8,5,7:18.13
-11,6,7:18.5
-10,6,7:18.5
-9,6,7:18.13
-8,6,7:18.13
-7,6,7:18.13
-6,6,7:18.14
-5,6,7:18.14
-2,6,7:18.13
-1,6,7:18.13
-10,7,7:18.5
-9,7,7:18.13
-5,7,7:18.14
-4,7,7:18.13
-2,7,7:18.13
-1,7,7:18.13
-9,8,7:18.13
-8,8,7:18.13
-6,8,7:18.13
-5,8,7:17.12
-4,8,7:17.12
-2,8,7:18.13
-1,8,7:18.13
-5,9,7:17.12
-4,9,7:17.12
0,9,7:18.13
-10,10,7:18.5
-9,10,7:18.13
0,10,7:18.13
1,10,7:18.5
-10,11,7:18.5
0,11,7:18.13
1,11,7:18.5
-5,12,7:18.13
-4,12,7:18.13
-3,12,7:18.13
-2,12,7:18.13
-1,12,7:18.13
0,12,7:18.13
1,12,7:18.5
2,12,7:18.5
-9,13,7:18.13
-8,13,7:18.13
-5,13,7:18.13
-4,13,7:18.13
-2,13,7:18.13
-1,13,7:18.13
0,13,7:18.13
1,13,7:18.5
2,13,7:18.5
-1,14,7:18.5
-5,1,8:18.5
-4,1,8:18.5
-3,1,8:18.5
-6,2,8:18.5
-5,2,8:18.5
-4,2,8:18.5
-3,2,8:18.5
-6,3,8:18.5
-5,3,8:18.5
-4,3,8:18.5
-3,3,8:18.5
-1,3,8:18.5
0,3,8:18.5
-6,4,8:18.13
-5,4,8:18.13
-4,4,8:18.13
-3,4,8:18.13
1,4,8:18.5
-6,5,8:18.13
-3,5,8:18.13
2,5,8:18.5
-11,6,8:18.5
-10,6,8:18.5
-9,6,8:18.13
-8,6,8:18.13
-7,6,8:18.13
2,6,8:18.5
-9,7,8:18.13
-8,7,8:18.13
-7,7,8:18.13
-6,7,8:18.13
-5,7,8:18.13
-4,7,8:18.13
-3,7,8:18.13
-2,7,8:18.13
-11,8,8:18.5
-8,8,8:18.13
-7,8,8:18.13
-6,8,8:18.13
-5,8,8:17.12
-4,8,8:17.12
-3,8,8:18.13
-2,8,8:18.13
-11,9,8:18.5
-10,9,8:18.5
-9,9,8:18.13
-5,9,8:18.13
-4,9,8:17.12
-3,9,8:18.13
-1,9,8:18.13
-10,10,8:18.5
-9,10,8:18.13
-8,10,8:18.13
-5,10,8:18.13
-4,10,8:18.13
-1,10,8:18.13
0,10,8:18.13
-10,11,8:18.5
-9,11,8:18.13
-8,11,8:18.13
-5,11,8:18.13
-4,11,8:18.13
-3,11,8:18.13
-2,11,8:18.13
-1,11,8:18.13
0,11,8:18.13
-11,12,8:18.5
-10,12,8:18.5
-9,12,8:18.13
-8,12,8:18.13
-7,12,8:18.13
-4,12,8:18.13
-2,12,8:18.13
-1,12,8:18.13
0,12,8:18.13
-10,13,8:18.5
-9,13,8:18.13
-5,13,8:18.13
-2,13,8:18.13
-1,13,8:18.13
-5,14,8:18.5
-4,14,8:18.5
-2,14,8:18.5
-4,15,8:18.5
-3,15,8:18.5
-2,15,8:18.5
-3,16,8:18.5
-4,2,9:18.5
-5,3,9:18.5
-4,3,9:18.5
-5,4,9:18.13
-4,4,9:18.13
-1,4,9:18.13
0,4,9:18.13
1,4,9:18.5
-5,5,9:18.13
-4,5,9:18.13
-3,5,9:18.13
0,5,9:18.13
1,5,9:18.5
2,5,9:18.5
-5,6,9:18.13
-4,6,9:18.13
-3,6,9:18.13
1,6,9:18.5
-12,7,9:18.5
-11,7,9:18.5
-10,7,9:18.5
-9,7,9:18.13
-8,7,9:18.13
-7,7,9:18.13
-6,7,9:18.13
1,7,9:18.5
-11,8,9:18.5
-10,8,9:18.5
-7,8,9:18.13
-6,8,9:18.13
-5,8,9:18.13
-4,8,9:18.13
-3,8,9:18.13
-10,9,9:18.5
-9,9,9:18.13
-8,9,9:18.13
-7,9,9:18.13
-6,9,9:18.13
-5,9,9:18.13
-4,9,9:17.12
-3,9,9:18.13
-2,9,9:18.13
-8,10,9:18.13
-7,10,9:18.13
-5,10,9:18.13
-4,10,9:18.13
-3,10,9:18.13
-2,10,9:18.13
-1,10,9:18.13
-8,11,9:18.13
-7,11,9:18.13
-6,11,9:18.13
-3,11,9:18.13
-2,11,9:18.13
-1,11,9:18.13
-2,12,9:18.13
-5,13,9:18.13
-4,13,9:18.13
-3,13,9:18.13
-2,13,9:18.13
-4,14,9:18.5
-3,14,9:18.5
-2,14,9:18.5
-6,5,10:18.13
-2,5,10:18.13
-1,5,10:18.13
0,5,10:18.13
1,5,10:18.5
-5,6,10:18.13
-4,6,10:18.13
-1,6,10:18.13
-11,7,10:18.5
-10,7,10:18.5
-9,7,10:18.13
-8,7,10:18.13
-7,7,10:18.13
-6,7,10:18.13
-5,7,10:18.13
-4,7,10:18.13
-1,7,10:18.13
0,7,10:18.13
-10,8,10:18.5
-9,8,10:18.13
-5,8,10:18.13
-4,8,10:18.13
-3,8,10:18.13
-9,9,10:18.13
-8,9,10:18.13
-7,9,10:18.13
-6,9,10:18.13
-5,9,10:18.13
-4,9,10:18.13
-3,9,10:18.13
-7,10,10:18.13
-6,10,10:18.13
-5,10,10:18.13
-4,10,10:18.13
-3,10,10:18.13
-2,10,10:18.13
-5,12,10:18.13
-4,12,10:18.13
-3,12,10:18.13
-2,12,10:18.13
-4,13,10:18.13
-3,13,10:18.13
-3,14,10:18.5
-6,15,10:18.5
-4,15,10:18.5
-10,4,11:18.5
-9,4,11:18.5
-10,5,11:18.5
-8,5,11:18.13
-7,5,11:18.13
-6,5,11:18.13
1,5,11:18.5
-10,6,11:18.5
-6,6,11:18.13
-2,6,11:18.13
-1,6,11:18.13
1,6,11:18.5
2,6,11:18.5
-10,7,11:18.5
-9,7,11:18.13
-5,7,11:18.13
-4,7,11:18.13
-2,7,11:18.13
-1,7,11:18.13
3,7,11:18.5
-9,8,11:18.13
-8,8,11:18.13
-7,8,11:18.13
-6,8,11:18.13
-5,8,11:18.13
-4,8,11:18.13
-3,8,11:18.13
-2,8,11:18.13
2,8,11:18.5
3,8,11:18.5
-8,9,11:18.13
-7,9,11:18.13
-6,9,11:18.13
-5,9,11:18.13
-4,9,11:18.13
-3,9,11:18.13
1,9,11:18.5
2,9,11:18.5
-5,10,11:18.13
-4,10,11:18.13
-3,10,11:18.13
-4,11,11:18.13
-3,11,11:18.13
-4,12,11:18.13
-3,12,11:18.13
-7,13,11:18.13
-6,13,11:18.13
-3,13,11:18.13
-7,14,11:18.5
-6,14,11:18.5
-4,14,11:18.5
-3,14,11:18.5
-6,15,11:18.5
-5,15,11:18.5
-4,15,11:18.5
-11,4,12:18.5
-10,4,12:18.5
-10,5,12:18.5
-9,5,12:18.5
-8,5,12:18.13
-7,5,12:18.13
-10,6,12:18.5
-9,6,12:18.5
-7,6,12:18.13
-6,6,12:18.13
1,6,12:18.5
-9,7,12:18.5
-8,7,12:18.13
-5,7,12:18.13
-4,7,12:18.13
-3,7,12:18.13
-2,7,12:18.13
0,7,12:18.13
1,7,12:18.5
2,7,12:18.5
-8,8,12:18.13
-7,8,12:18.13
-6,8,12:18.13
-5,8,12:18.13
-4,8,12:18.13
-3,8,12:18.13
-2,8,12:18.13
1,8,12:18.5
2,8,12:18.5
-6,9,12:18.13
-5,9,12:18.13
-4,9,12:18.13
-3,9,12:18.13
1,9,12:18.5
-5,10,12:18.13
-4,10,12:18.13
-3,10,12:18.13
-4,11,12:18.13
-6,12,12:18.13
-6,13,12:18.13
-5,13,12:18.13
-4,13,12:18.13
-3,13,12:18.13
-5,14,12:18.5
-4,14,12:18.5
-3,3,13:18.5
-4,4,13:18.5
-1,4,13:18.5
-9,5,13:18.5
-8,5,13:18.13
-5,5,13:18.13
-9,6,13:18.5
-8,6,13:18.13
-7,6,13:18.13
-6,6,13:18.13
-2,6,13:18.13
-8,7,13:18.13
-7,7,13:18.13
-6,7,13:18.13
-5,7,13:18.13
-2,7,13:18.13
-1,7,13:18.13
0,7,13:18.13
1,7,13:18.5
-7,8,13:18.13
-5,8,13:18.13
-4,8,13:18.13
-3,8,13:18.13
-2,8,13:18.13
0,8,13:18.13
1,8,13:18.5
-5,9,13:18.13
-4,9,13:18.13
-3,9,13:18.13
-1,9,13:18.13
0,9,13:18.13
-5,10,13:18.13
-4,10,13:18.13
-5,11,13:18.13
-6,12,13:18.13
-5,12,13:18.13
-4,12,13:18.13
0,12,13:18.13
-5,13,13:18.13
-4,13,13:18.13
0,13,13:18.13
-3,14,13:18.5
-1,2,14:18.5
-3,3,14:18.5
-2,3,14:18.5
-1,3,14:18.5
-4,4,14:18.5
-3,4,14:18.5
-2,4,14:18.5
-1,4,14:18.5
-4,5,14:18.5
-2,5,14:18.5
-8,6,14:18.5
-7,6,14:18.5
-2,6,14:18.5
-8,7,14:18.5
-7,7,14:18.5
-6,7,14:18.5
-5,7,14:18.5
-2,7,14:18.5
-1,7,14:18.5
-10,8,14:18.5
-9,8,14:18.5
-8,8,14:18.5
-6,8,14:18.5
-5,8,14:18.5
-4,8,14:18.5
-3,8,14:18.5
-2,8,14:18.5
-1,8,14:18.5
-10,9,14:18.5
-9,9,14:18.5
-6,9,14:18.5
-5,9,14:18.5
-4,9,14:18.5
-3,9,14:18.5
-2,9,14:18.5
-1,9,14:18.5
-9,10,14:18.5
-8,10,14:18.5
-5,10,14:18.5
-4,10,14:18.5
-5,11,14:18.5
-4,11,14:18.5
-4,12,14:18.5
-1,12,14:18.5
-3,13,14:18.5
-2,13,14:18.5
-1,13,14:18.5
-3,14,14:18.5
-2,14,14:18.5
-1,14,14:18.5
-2,3,15:18.5
-3,4,15:18.5
-2,4,15:18.5
-4,5,15:18.5
-3,5,15:18.5
-2,5,15:18.5
-4,6,15:18.5
-2,6,15:18.5
-6,7,15:18.5
-3,7,15:18.5
-2,7,15:18.5
-8,8,15:18.5
-7,8,15:18.5
-6,8,15:18.5
-5,8,15:18.5
-4,8,15:18.5
-3,8,15:18.5
-2,8,15:18.5
-9,9,15:18.5
-8,9,15:18.5
-7,9,15:18.5
-5,9,15:18.5
-4,9,15:18.5
-3,9,15:18.5
-8,10,15:18.5
-7,10,15:18.5
-4,10,15:18.5
-2,11,15:18.5
-3,12,15:18.5
-2,12,15:18.5
-1,12,15:18.5
-3,13,15:18.5
-2,13,15:18.5
-8,5,16:18.5
-7,5,16:18.5
-6,5,16:18.5
-3,5,16:18.5
-2,5,16:18.5
-8,6,16:18.5
-6,6,16:18.5
-5,6,16:18.5
-3,6,16:18.5
-8,7,16:18.5
-7,7,16:18.5
-4,7,16:18.5
-3,7,16:18.5
0,7,16:18.5
1,7,16:18.5
-7,8,16:18.5
-6,8,16:18.5
-5,8,16:18.5
-4,8,16:17.0
-3,8,16:18.5
1,8,16:18.5
-7,9,16:18.5
-6,9,16:18.5
-5,9,16:17.0
-4,9,16:18.5
-3,9,16:18.5
1,9,16:18.5
2,9,16:18.5
-6,10,16:18.5
-2,10,16:18.5
0,10,16:18.5
1,10,16:18.5
-3,11,16:18.5
-2,11,16:18.5
-7,12,16:18.5
-6,12,16:18.5
-4,12,16:18.5
-3,12,16:18.5
-2,12,16:18.5
-6,13,16:18.5
-5,13,16:18.5
-4,13,16:18.5
-6,14,16:18.5
-5,14,16:18.5
-8,5,17:18.5
-7,5,17:18.5
-8,6,17:18.5
-7,6,17:18.5
-6,6,17:18.5
-5,6,17:18.5
-7,7,17:18.5
-5,7,17:18.5
-4,7,17:18.5
-3,7,17:18.5
-2,7,17:18.5
0,7,17:18.5
-7,8,17:18.5
-6,8,17:18.5
-4,8,17:18.5
-3,8,17:18.5
-1,8,17:18.5
0,8,17:18.5
1,8,17:18.5
-6,9,17:18.5
-5,9,17:18.5
-4,9,17:18.5
-3,9,17:17.0
0,9,17:18.5
1,9,17:18.5
-3,10,17:18.5
-6,11,17:18.5
-5,11,17:18.5
-6,12,17:18.5
-5,12,17:18.5
-4,12,17:18.5
-5,13,17:18.5
-3,3,18:18.5
-2,3,18:18.5
-4,4,18:18.5
-3,4,18:18.5
-2,4,18:18.5
-5,5,18:18.5
-4,5,18:18.5
-2,5,18:18.5
-7,6,18:18.5
-6,6,18:18.5
-5,6,18:18.5
-2,6,18:18.5
-6,7,18:18.5
-5,7,18:18.5
-2,7,18:18.5
-8,8,18:18.5
-6,8,18:18.5
-5,8,18:18.5
-4,8,18:17.0
-2,8,18:18.5
-1,8,18:18.5
-9,9,18:18.5
-8,9,18:18.5
-5,9,18:17.0
-4,9,18:17.0
-3,9,18:17.0
-2,9,18:18.5
-1,9,18:18.5
-9,10,18:18.5
-5,10,18:18.5
-8,11,18:18.5
-7,11,18:18.5
-5,11,18:18.5
-4,11,18:18.5
0,11,18:18.5
-5,12,18:18.5
0,12,18:18.5
-2,13,18:18.5
-1,13,18:18.5
0,13,18:18.5
-2,14,18:18.5
-1,14,18:18.5
-2,3,19:18.5
-3,4,19:18.5
-2,4,19:18.5
-4,5,19:18.5
-3,5,19:18.5
-2,5,19:18.5
-4,6,19:18.5
-3,6,19:18.5
-2,6,19:18.5
-5,7,19:18.5
-4,7,19:18.5
-3,7,19:18.5
-2,7,19:18.5
-7,8,19:18.5
-5,8,19:18.5
-4,8,19:17.0
-3,8,19:18.5
-8,9,19:18.5
-7,9,19:18.5
-5,9,19:17.0
-4,9,19:17.0
-3,9,19:17.0
-2,9,19:18.5
-9,10,19:18.5
-8,10,19:18.5
-7,10,19:18.5
-4,10,19:18.5
-7,11,19:18.5
-1,11,19:18.5
-3,12,19:18.5
-2,12,19:18.5
-1,12,19:18.5
-2,13,19:18.5
-1,13,19:18.5
-3,5,20:18.5
-4,6,20:18.5
-3,6,20:18.5
-4,7,20:18.5
-3,7,20:18.5
-5,8,20:18.5
-4,8,20:18.5
-3,8,20:18.5
-7,9,20:18.5
-6,9,20:18.5
-5,9,20:18.5
-4,9,20:17.0
-3,9,20:18.5
1,9,20:18.5
-7,10,20:18.5
-6,10,20:18.5
-5,10,20:18.5
-4,10,20:18.5
-3,10,20:18.5
-2,10,20:18.5
1,10,20:18.5
-3,11,20:18.5
-2,11,20:18.5
-4,12,20:18.5
-2,12,20:18.5
-5,13,20:18.5
-5,4,21:18.5
-4,4,21:18.5
-6,5,21:18.5
-4,7,21:18.5
-3,7,21:18.5
-4,8,21:18.5
-3,8,21:18.5
0,8,21:18.5
-6,9,21:18.5
-5,9,21:18.5
-4,9,21:17.0
-3,9,21:18.5
0,9,21:18.5
1,9,21:18.5
-6,10,21:18.5
-5,10,21:18.5
-4,10,21:18.5
-3,10,21:18.5
-1,10,21:18.5
0,10,21:18.5
1,10,21:18.5
-6,11,21:18.5
-1,11,21:18.5
-6,12,21:18.5
-5,12,21:18.5
-4,12,21:18.5
-7,13,21:18.5
-6,13,21:18.5
-5,13,21:18.5
-5,4,22:18.5
-5,5,22:18.5
-4,5,22:18.5
-6,6,22:18.5
-5,6,22:18.5
-5,8,22:18.5
-4,8,22:18.5
-3,8,22:18.5
-1,8,22:18.5
-5,9,22:18.5
-4,9,22:18.5
-3,9,22:18.5
-1,9,22:18.5
0,9,22:18.5
-5,10,22:18.5
-4,10,22:18.5
-3,10,22:18.5
-1,10,22:18.5
0,10,22:18.5
-6,11,22:18.5
-5,11,22:18.5
-4,11,22:18.5
-6,12,22:18.5
-5,12,22:18.5
-4,12,22:18.5
-6,13,22:18.5
-5,6,23:18.5
-4,6,23:18.5
-5,7,23:18.5
-4,7,23:18.5
-5,8,23:18.5
-4,8,23:18.5
-3,8,23:18.5
-2,8,23:18.5
-5,9,23:18.5
-4,9,23:18.5
-3,9,23:18.5
-2,9,23:18.5
-1,9,23:18.5
-5,10,23:18.5
-4,10,23:18.5
-3,10,23:18.5
-2,10,23:18.5
-1,10,23:18.5
-5,11,23:18.5
-4,11,23:18.5
-5,12,23:18.5
-2,5,24:18.5
-1,5,24:18.5
-4,7,24:18.5
0,7,24:18.5
-5,8,24:18.5
-4,8,24:18.5
-3,8,24:18.5
-4,9,24:18.5
-3,9,24:18.5
-2,9,24:18.5
-5,10,24:18.5
-4,10,24:18.5
-3,10,24:18.5
-5,11,24:18.5
-4,11,24:18.5
-1,11,24:18.5
-3,12,24:18.5
-1,12,24:18.5
-2,13,24:18.5
-1,13,24:18.5
-2,14,24:18.5
-7,6,25:18.5
-2,6,25:18.5
-1,6,25:18.5
-8,7,25:18.5
-7,7,25:18.5
-1,7,25:18.5
0,7,25:18.5
-8,8,25:18.5
-4,8,25:18.5
-3,8,25:18.5
-1,8,25:18.5
-8,9,25:18.5
-7,9,25:18.5
-4,9,25:18.5
-3,9,25:18.5
-4,10,25:18.5
-3,10,25:18.5
-4,11,25:18.5
-3,11,25:18.5
-1,11,25:18.5
-3,12,25:18.5
-2,12,25:18.5
-1,12,25:18.5
-2,13,25:18.5
-1,13,25:18.5
-2,14,25:18.5
-2,6,26:18.5
-1,6,26:18.5
-7,7,26:18.5
-6,7,26:18.5
-2,7,26:18.5
-1,7,26:18.5
-7,8,26:18.5
-6,8,26:18.5
-4,8,26:18.5
-3,8,26:17.0
-1,8,26:18.5
-7,9,26:18.5
-6,9,26:18.5
-4,9,26:17.0
-3,9,26:18.5
-7,10,26:18.5
-4,10,26:18.5
-2,10,26:18.5
0,10,26:18.5
-7,11,26:18.5
-3,11,26:18.5
-2,11,26:18.5
-6,12,26:18.5
-3,12,26:18.5
-2,12,26:18.5
-1,12,26:18.5
0,12,26:18.5
-2,13,26:18.5
-5,5,27:18.5
-4,5,27:18.5
-6,6,27:18.5
-5,6,27:18.5
-4,6,27:18.5
-3,6,27:18.5
-6,7,27:18.5
-3,7,27:18.5
-2,7,27:18.5
-6,8,27:18.5
-5,8,27:18.5
-3,8,27:18.5
-2,8,27:18.5
-6,9,27:18.5
-5,9,27:18.5
-4,9,27:17.0
-3,9,27:17.0
0,9,27:18.5
-7,10,27:18.5
-6,10,27:18.5
-4,10,27:17.0
-3,10,27:18.5
-2,10,27:18.5
0,10,27:18.5
-7,11,27:18.5
-6,11,27:18.5
-3,11,27:18.5
-2,11,27:18.5
-1,11,27:18.5
0,11,27:18.5
-7,12,27:18.5
-6,12,27:18.5
-5,12,27:18.5
-2,12,27:18.5
-1,12,27:18.5
-5,5,28:18.5
-5,6,28:18.5
-4,6,28:18.5
-5,7,28:18.5
-3,7,28:18.5
-5,8,28:18.5
-3,8,28:18.5
-2,8,28:18.5
-5,9,28:18.5
-4,9,28:17.0
-3,9,28:17.0
-6,10,28:18.5
-4,10,28:17.0
-3,10,28:18.5
-1,10,28:18.5
-6,11,28:18.5
-5,11,28:18.5
-3,11,28:18.5
-2,11,28:18.5
-1,11,28:18.5
-4,6,29:18.5
-5,7,29:18.5
-4,7,29:18.5
-3,7,29:18.5
-5,8,29:18.5
-3,8,29:18.5
-5,9,29:18.5
-4,9,29:17.0
-3,9,29:17.0
-5,10,29:18.5
-4,10,29:17.0
-3,10,29:17.0
-2,10,29:18.5
-1,10,29:18.5
-5,11,29:18.5
-4,11,29:18.5
-2,11,29:18.5
-4,7,30:18.5
-4,8,30:18.5
-3,8,30:18.5
-1,8,30:18.5
-5,9,30:18.5
-4,9,30:17.0
-3,9,30:17.0
-2,9,30:18.5
-5,10,30:18.5
-4,10,30:18.5
-3,10,30:17.0
-2,10,30:18.5
-1,10,30:18.5
-5,11,30:18.5
-2,11,30:18.5
-2,6,31:18.5
-1,6,31:18.5
-6,7,31:18.5
-3,7,31:18.5
-2,7,31:18.5
-1,7,31:18.5
-7,8,31:18.5
-6,8,31:18.5
-4,8,31:18.5
-3,8,31:18.5
-1,8,31:18.5
-7,9,31:18.5
-4,9,31:18.5
-3,9,31:17.0
-2,9,31:18.5
-7,10,31:18.5
-4,10,31:18.5
-3,10,31:18.5
-2,10,31:18.5
-3,11,31:18.5
-1,11,31:18.5
-3,12,31:18.5
-2,12,31:18.5
-1,12,31:18.5
-2,13,31:18.5
-2,7,32:18.5
-7,8,32:18.5
-6,8,32:18.5
-5,8,32:18.5
-4,8,32:18.5
-3,8,32:18.5
-2,8,32:18.5
-6,9,32:18.5
-4,9,32:17.0
-3,9,32:17.0
-2,9,32:18.5
0,9,32:18.5
-6,10,32:18.5
-4,10,32:18.5
-3,10,32:18.5
-2,10,32:18.5
-1,10,32:18.5
-6,11,32:18.5
-3,11,32:18.5
-2,11,32:18.5
-1,11,32:18.5
-5,12,32:18.5
-3,12,32:18.5
-2,12,32:18.5
-5,6,33:18.5
-4,6,33:18.5
-3,6,33:18.5
-4,7,33:18.5
-3,7,33:18.5
-3,8,33:18.5
-2,8,33:18.5
-5,9,33:18.5
-4,9,33:17.0
-3,9,33:17.0
-2,9,33:18.5
-1,9,33:18.5
0,9,33:18.5
-5,10,33:18.5
-3,10,33:18.5
-2,10,33:18.5
-1,10,33:18.5
-5,11,33:18.5
-3,11,33:18.5
-2,11,33:18.5
-5,12,33:18.5
-5,7,34:18.5
-4,7,34:18.5
-3,7,34:18.5
-6,8,34:18.5
-5,8,34:18.5
-3,8,34:18.5
-4,9,34:17.0
-3,9,34:17.0
-1,9,34:18.5
-5,10,34:18.5
-4,10,34:18.5
-3,10,34:17.0
-2,10,34:18.5
-1,10,34:18.5
-5,11,34:18.5
-4,11,34:18.5
-4,12,34:18.5
-3,12,34:18.5
-6,8,35:18.5
-5,8,35:18.5
-4,8,35:18.5
-3,8,35:18.5
-1,8,35:18.5
-4,9,35:17.0
-3,9,35:17.0
-2,9,35:18.5
-1,9,35:18.5
-4,10,35:18.5
-3,10,35:17.0
-2,10,35:18.5
-1,10,35:18.5
-4,11,35:18.5
-3,11,35:18.5
-3,12,35:18.5
-4,8,36:18.5
-1,8,36:18.5
-5,9,36:18.5
-4,9,36:18.5
-3,9,36:17.0
-2,9,36:18.5
-1,9,36:18.5
-4,10,36:18.5
-3,10,36:17.0
-2,10,36:18.5
-4,11,36:18.5
-3,11,36:18.5
-4,7,37:18.5
-3,7,37:18.5
-2,8,37:18.5
-4,9,37:18.5
-3,9,37:17.0
-2,9,37:18.5
-5,10,37:18.5
-3,10,37:18.5
-1,10,37:18.5
-5,11,37:18.5
-3,11,37:18.5
-2,11,37:18.5
-4,7,38:18.5
-4,8,38:18.5
-3,8,38:18.5
-2,8,38:18.5
-4,9,38:18.5
-3,9,38:17.0
-2,9,38:18.5
-5,10,38:18.5
-4,10,38:18.5
-3,10,38:18.5
-2,10,38:18.5
-1,10,38:18.5
-5,11,38:18.5
-4,11,38:18.5
-2,11,38:18.5
-4,8,39:18.5
-3,8,39:18.5
-4,9,39:18.5
-3,9,39:17.0
-2,9,39:18.5
-4,10,39:18.5
-3,10,39:18.5
-2,10,39:18.5
-2,8,40:18.5
-3,9,40:18.5
-2,9,40:18.5
-4,10,40:18.5
-3,10,40:18.5
-2,10,40:18.5
-3,8,41:18.5
-5,9,41:18.5
-4,9,41:18.5
-3,9,41:18.5
-2,9,41:18.5
-5,10,41:18.5
-3,10,41:18.5
-3,11,41:18.5
-2,11,41:18.5
-4,9,42:18.5
-3,9,42:17.0
-2,9,42:18.5
-5,10,42:18.5
-4,10,42:18.5
-3,10,42:17.0
-3,11,42:18.5
-2,11,42:18.5
-4,9,43:18.5
-3,9,43:18.5
-2,9,43:18.5
-4,10,43:18.5
-3,10,43:18.5
-2,10,43:18.5
-3,9,44:17.0
-4,10,44:18.5
-3,10,44:17.0
-2,10,44:17.0
-1,10,44:18.5
-4,11,44:18.5
-2,11,44:18.5
-4,8,45:18.5
-3,8,45:18.5
-2,8,45:18.5
-3,9,45:17.0
-2,9,45:18.5
-4,10,45:18.5
-3,10,45:17.0
-2,10,45:18.5
-1,10,45:18.5
-4,11,45:18.5
-3,8,46:18.5
-3,9,46:18.5
-2,9,46:18.5
-3,10,46:18.5
-2,10,46:18.5
-3,9,47:18.5
-3,10,47:18.5
-2,10,47:18.5
-3,10,48:17.0
-2,10,48:17.0
-3,10,49:17.0
-2,10,49:17.0
-3,10,50:17.0
-2,10,50:17.0
-3,10,51:17.0
-2,10,51:17.0
-2,10,52:17.0
-2,10,53:17.0
-2,10,54:17.0
