[META]
version=2.0
spawnOnBlockType=2
spawnSunlight=True
spawnDarkness=True
spawnWater=False
spawnLava=False
underFill=False
randomRotation=True
dig=True
tree=False
branch=False
needsFoundation=True
rarity=100
collisionPercentage=20
spawnElevationMin=0
spawnElevationMax=200
spawnInBiome=Custom
[DATA]
-2,-5,-8:17.12
-1,-5,-8:17.12
0,-5,-8:17.12
0,-4,-8:17.12
-2,-3,-8:17.12
-1,-3,-8:17.12
0,-3,-8:17.12
-5,-2,-8:17.12
-4,-2,-8:17.12
-3,-1,-8:17.12
-3,2,-8:17.12
-1,2,-8:17.12
-1,-5,-7:17.12
1,-5,-7:17.12
-5,-4,-7:17.12
-4,-4,-7:17.12
-2,-4,-7:17.12
1,-4,-7:17.12
-4,-3,-7:17.12
-3,-3,-7:17.12
-2,-3,-7:17.12
-5,-2,-7:17.12
-4,-2,-7:17.12
-2,-2,-7:17.12
-1,-2,-7:17.12
-5,-1,-7:17.12
-6,0,-7:17.12
-5,0,-7:17.12
-4,0,-7:17.12
-2,0,-7:17.12
-5,1,-7:17.12
-4,1,-7:17.12
-2,1,-7:17.12
-4,2,-7:17.12
-2,2,-7:17.12
-1,2,-7:17.12
0,2,-7:17.12
-3,4,-7:17.12
-5,-7,-6:17.12
-4,-7,-6:17.12
-2,-7,-6:17.12
-1,-7,-6:17.12
0,-7,-6:17.12
-6,-6,-6:17.12
-4,-6,-6:17.12
-2,-6,-6:17.12
-7,-5,-6:17.12
-5,-5,-6:17.12
-3,-5,-6:17.12
-2,-5,-6:17.12
-1,-5,-6:17.12
-7,-4,-6:17.12
-6,-4,-6:17.12
-5,-4,-6:17.12
-4,-4,-6:17.12
-3,-4,-6:17.12
-2,-4,-6:17.12
-1,-4,-6:17.12
0,-4,-6:17.12
1,-4,-6:17.12
-10,-3,-6:17.12
-7,-3,-6:17.12
-6,-3,-6:17.12
-5,-3,-6:17.12
-4,-3,-6:17.12
-3,-3,-6:17.12
-2,-3,-6:17.12
-1,-3,-6:17.12
0,-3,-6:17.12
-10,-2,-6:17.12
-9,-2,-6:17.12
-7,-2,-6:17.12
-6,-2,-6:17.12
-5,-2,-6:17.12
-4,-2,-6:17.12
-3,-2,-6:17.12
-2,-2,-6:17.12
-1,-2,-6:17.12
0,-2,-6:17.12
1,-2,-6:17.12
-10,-1,-6:17.12
-9,-1,-6:17.12
-8,-1,-6:17.12
-7,-1,-6:17.12
-6,-1,-6:17.12
-4,-1,-6:17.12
-3,-1,-6:17.12
-2,-1,-6:17.12
-1,-1,-6:17.12
0,-1,-6:17.12
-8,0,-6:17.12
-7,0,-6:17.12
-6,0,-6:17.12
-5,0,-6:17.12
-4,0,-6:17.12
-3,0,-6:17.12
-2,0,-6:17.12
-1,0,-6:17.12
0,0,-6:17.12
1,0,-6:17.12
-7,1,-6:17.12
-6,1,-6:17.12
-5,1,-6:17.12
-4,1,-6:17.12
-3,1,-6:17.12
-1,1,-6:17.12
-6,2,-6:17.12
-5,2,-6:17.12
-4,2,-6:17.12
-3,2,-6:17.12
-2,2,-6:17.12
-1,2,-6:17.12
-4,3,-6:17.12
-2,3,-6:17.12
-1,3,-6:17.12
-3,4,-6:17.12
-2,4,-6:17.12
-5,-8,-5:17.12
-2,-8,-5:17.12
-7,-7,-5:17.12
-6,-7,-5:17.12
-5,-7,-5:17.12
-4,-7,-5:17.12
-6,-6,-5:17.12
-5,-6,-5:17.12
-4,-6,-5:17.12
-3,-6,-5:17.12
-2,-6,-5:17.12
-1,-6,-5:17.12
0,-6,-5:17.12
1,-6,-5:17.12
-9,-5,-5:17.12
-8,-5,-5:17.12
-7,-5,-5:17.12
-6,-5,-5:17.12
-5,-5,-5:17.12
-4,-5,-5:17.12
-2,-5,-5:17.12
-1,-5,-5:17.12
-11,-4,-5:17.12
-8,-4,-5:17.12
-7,-4,-5:17.12
-6,-4,-5:17.12
-5,-4,-5:17.12
-4,-4,-5:17.12
-3,-4,-5:17.12
-2,-4,-5:17.12
-1,-4,-5:17.12
0,-4,-5:17.12
1,-4,-5:17.12
-11,-3,-5:17.12
-9,-3,-5:17.12
-6,-3,-5:17.12
-5,-3,-5:17.12
-4,-3,-5:17.12
-3,-3,-5:17.12
-2,-3,-5:17.12
-1,-3,-5:17.12
1,-3,-5:17.12
-9,-2,-5:17.12
-8,-2,-5:17.12
-7,-2,-5:17.12
-6,-2,-5:17.12
-5,-2,-5:17.12
-4,-2,-5:17.12
-3,-2,-5:17.12
-2,-2,-5:17.12
-1,-2,-5:17.12
-10,-1,-5:17.12
-9,-1,-5:17.12
-8,-1,-5:17.12
-7,-1,-5:17.12
-6,-1,-5:17.12
-5,-1,-5:17.12
-4,-1,-5:17.12
-2,-1,-5:17.12
0,-1,-5:17.12
-11,0,-5:17.12
-10,0,-5:17.12
-7,0,-5:17.12
-6,0,-5:17.12
-5,0,-5:17.12
-4,0,-5:17.12
-3,0,-5:17.12
-1,0,-5:17.12
0,0,-5:17.12
-9,1,-5:17.12
-7,1,-5:17.12
-6,1,-5:17.12
-5,1,-5:17.12
-4,1,-5:17.12
-3,1,-5:17.12
-1,1,-5:17.12
-8,2,-5:17.12
-7,2,-5:17.12
-5,2,-5:17.12
-4,2,-5:17.12
-2,2,-5:17.12
-1,2,-5:17.12
0,2,-5:17.12
-3,3,-5:17.12
-2,3,-5:17.12
-1,3,-5:17.12
-3,4,-5:17.12
-2,4,-5:17.12
-1,4,-5:17.12
-6,-9,-4:17.12
-4,-9,-4:17.12
-5,-8,-4:17.12
-3,-8,-4:17.12
-1,-8,-4:17.12
0,-8,-4:17.12
-7,-7,-4:17.12
-6,-7,-4:17.12
-5,-7,-4:17.12
-3,-7,-4:17.12
-2,-7,-4:17.12
-1,-7,-4:17.12
-7,-6,-4:17.12
-6,-6,-4:17.12
-4,-6,-4:17.12
-3,-6,-4:17.12
-2,-6,-4:17.12
-1,-6,-4:17.12
0,-6,-4:17.12
1,-6,-4:17.12
-10,-5,-4:17.12
-9,-5,-4:17.12
-8,-5,-4:17.12
-6,-5,-4:17.12
-5,-5,-4:17.12
-4,-5,-4:17.12
-3,-5,-4:17.12
-2,-5,-4:17.12
-1,-5,-4:17.12
0,-5,-4:17.12
1,-5,-4:17.12
-11,-4,-4:17.12
-10,-4,-4:17.12
-9,-4,-4:17.12
-7,-4,-4:17.12
-6,-4,-4:17.12
-5,-4,-4:17.12
-4,-4,-4:17.12
-3,-4,-4:17.12
-2,-4,-4:17.12
-1,-4,-4:17.12
0,-4,-4:17.12
1,-4,-4:17.12
-11,-3,-4:17.12
-10,-3,-4:17.12
-9,-3,-4:17.12
-8,-3,-4:17.12
-7,-3,-4:17.12
-6,-3,-4:17.12
-5,-3,-4:17.12
-4,-3,-4:17.12
-3,-3,-4:17.12
-2,-3,-4:17.12
-1,-3,-4:17.12
0,-3,-4:17.12
1,-3,-4:17.12
-11,-2,-4:17.12
-9,-2,-4:17.12
-8,-2,-4:17.12
-7,-2,-4:17.12
-6,-2,-4:17.12
-5,-2,-4:17.12
-4,-2,-4:17.12
-3,-2,-4:17.12
-2,-2,-4:17.12
-1,-2,-4:17.12
0,-2,-4:17.12
1,-2,-4:17.12
2,-2,-4:17.12
-10,-1,-4:17.12
-9,-1,-4:17.12
-8,-1,-4:17.12
-7,-1,-4:17.12
-6,-1,-4:17.12
-5,-1,-4:17.12
-4,-1,-4:17.12
-3,-1,-4:17.12
-2,-1,-4:17.12
-1,-1,-4:17.12
0,-1,-4:17.12
1,-1,-4:17.12
2,-1,-4:17.12
-10,0,-4:17.12
-9,0,-4:17.12
-8,0,-4:17.12
-7,0,-4:17.12
-6,0,-4:17.12
-5,0,-4:17.12
-4,0,-4:17.12
-3,0,-4:17.12
-1,0,-4:17.12
0,0,-4:17.12
1,0,-4:17.12
-10,1,-4:17.12
-9,1,-4:17.12
-7,1,-4:17.12
-6,1,-4:17.12
-5,1,-4:17.12
-4,1,-4:17.12
-3,1,-4:17.12
-2,1,-4:17.12
-1,1,-4:17.12
0,1,-4:17.12
1,1,-4:17.12
-7,2,-4:17.12
-6,2,-4:17.12
-5,2,-4:17.12
-4,2,-4:17.12
-3,2,-4:17.12
-2,2,-4:17.12
-1,2,-4:17.12
-6,3,-4:17.12
-4,3,-4:17.12
-3,3,-4:17.12
-1,3,-4:17.12
0,3,-4:17.12
-5,4,-4:17.12
-4,4,-4:17.12
-5,-9,-3:17.12
-4,-9,-3:17.12
-5,-8,-3:17.12
-3,-8,-3:17.12
-6,-7,-3:17.12
-5,-7,-3:17.12
-3,-7,-3:17.12
-1,-7,-3:17.12
1,-7,-3:17.12
-7,-6,-3:17.12
-6,-6,-3:17.12
-5,-6,-3:17.12
-4,-6,-3:17.12
-3,-6,-3:17.12
-2,-6,-3:17.12
-1,-6,-3:17.12
0,-6,-3:17.12
-9,-5,-3:17.12
-8,-5,-3:17.12
-6,-5,-3:17.12
-5,-5,-3:17.12
-4,-5,-3:17.12
-3,-5,-3:17.12
-1,-5,-3:17.12
-10,-4,-3:17.12
-9,-4,-3:17.12
-8,-4,-3:17.12
-6,-4,-3:17.12
-5,-4,-3:17.12
-3,-4,-3:17.12
-2,-4,-3:17.12
-1,-4,-3:17.12
0,-4,-3:17.12
1,-4,-3:17.12
-11,-3,-3:17.12
-10,-3,-3:17.12
-9,-3,-3:17.12
-8,-3,-3:17.12
-7,-3,-3:17.12
-6,-3,-3:17.12
-5,-3,-3:17.12
-4,-3,-3:17.12
-2,-3,-3:17.12
-1,-3,-3:17.12
1,-3,-3:17.12
2,-3,-3:17.12
-11,-2,-3:17.12
-10,-2,-3:17.12
-8,-2,-3:17.12
-7,-2,-3:17.12
-6,-2,-3:17.12
-5,-2,-3:17.12
-4,-2,-3:17.12
-3,-2,-3:17.12
-2,-2,-3:17.12
-1,-2,-3:17.12
0,-2,-3:17.12
2,-2,-3:17.12
-9,-1,-3:17.12
-8,-1,-3:17.12
-7,-1,-3:17.12
-5,-1,-3:17.12
-4,-1,-3:17.12
-1,-1,-3:17.12
0,-1,-3:17.12
1,-1,-3:17.12
-9,0,-3:17.12
-7,0,-3:17.12
-6,0,-3:17.12
-5,0,-3:17.12
-4,0,-3:17.12
-2,0,-3:17.12
0,0,-3:17.12
1,0,-3:17.12
-10,1,-3:17.12
-8,1,-3:17.12
-7,1,-3:17.12
-5,1,-3:17.12
-3,1,-3:17.12
-1,1,-3:17.12
0,1,-3:17.12
-9,2,-3:17.12
-8,2,-3:17.12
-7,2,-3:17.12
-6,2,-3:17.12
-5,2,-3:17.12
-4,2,-3:17.12
-3,2,-3:17.12
-1,2,-3:17.12
1,2,-3:17.12
-9,3,-3:17.12
-8,3,-3:17.12
-7,3,-3:17.12
-6,3,-3:17.12
-5,3,-3:17.12
-4,3,-3:17.12
-1,3,-3:17.12
-5,4,-3:17.12
-4,4,-3:17.12
-3,4,-3:17.12
-2,4,-3:17.12
-2,5,-3:17.12
-6,-9,-2:17.12
-7,-8,-2:17.12
-5,-8,-2:17.12
-4,-8,-2:17.12
-7,-7,-2:17.12
-6,-7,-2:17.12
-4,-7,-2:17.12
-3,-7,-2:17.12
-2,-7,-2:17.12
-1,-7,-2:17.12
0,-7,-2:17.12
1,-7,-2:17.12
-8,-6,-2:17.12
-6,-6,-2:17.12
-5,-6,-2:17.12
-4,-6,-2:17.12
-2,-6,-2:17.12
-1,-6,-2:17.12
1,-6,-2:17.12
-10,-5,-2:17.12
-9,-5,-2:17.12
-7,-5,-2:17.12
-6,-5,-2:17.12
-5,-5,-2:17.12
-4,-5,-2:17.12
-3,-5,-2:17.12
-2,-5,-2:17.12
1,-5,-2:17.12
-11,-4,-2:17.12
-10,-4,-2:17.12
-6,-4,-2:17.12
-5,-4,-2:17.12
-4,-4,-2:17.12
-3,-4,-2:17.12
-2,-4,-2:17.12
-1,-4,-2:17.12
0,-4,-2:17.12
1,-4,-2:17.12
-11,-3,-2:17.12
-10,-3,-2:17.12
-9,-3,-2:17.12
-8,-3,-2:17.12
-6,-3,-2:17.12
-4,-3,-2:17.12
-3,-3,-2:17.12
-1,-3,-2:17.12
0,-3,-2:17.12
1,-3,-2:17.12
-10,-2,-2:17.12
-9,-2,-2:17.12
-8,-2,-2:17.12
-7,-2,-2:17.12
-6,-2,-2:17.12
-5,-2,-2:17.12
-4,-2,-2:17.12
-3,-2,-2:17.12
-2,-2,-2:17.12
-1,-2,-2:17.12
0,-2,-2:17.12
1,-2,-2:17.12
2,-2,-2:17.12
-10,-1,-2:17.12
-9,-1,-2:17.12
-6,-1,-2:17.12
-1,-1,-2:17.12
0,-1,-2:17.12
1,-1,-2:17.12
2,-1,-2:17.12
3,-1,-2:17.12
-9,0,-2:17.12
-8,0,-2:17.12
-7,0,-2:17.12
-2,0,-2:17.12
1,0,-2:17.12
2,0,-2:17.12
3,0,-2:17.12
-9,1,-2:17.12
-7,1,-2:17.12
-6,1,-2:17.12
-4,1,-2:17.12
-3,1,-2:17.12
-1,1,-2:17.12
0,1,-2:17.12
1,1,-2:17.12
-9,2,-2:17.12
-6,2,-2:17.12
-5,2,-2:17.12
-3,2,-2:17.12
-1,2,-2:17.12
0,2,-2:17.12
-8,3,-2:17.12
-7,3,-2:17.12
-6,3,-2:17.12
-5,3,-2:17.12
-4,3,-2:17.12
-2,3,-2:17.12
-1,3,-2:17.12
-3,4,-2:17.12
-2,4,-2:17.12
-6,-9,-1:17.12
-5,-9,-1:17.12
-6,-8,-1:17.12
-5,-8,-1:17.12
-4,-8,-1:17.12
-4,-7,-1:17.12
-3,-7,-1:17.12
-2,-7,-1:17.12
-1,-7,-1:17.12
0,-7,-1:17.12
1,-7,-1:17.12
-8,-6,-1:17.12
-7,-6,-1:17.12
0,-6,-1:17.12
1,-6,-1:17.12
-9,-5,-1:17.12
-8,-5,-1:17.12
0,-5,-1:17.12
1,-5,-1:17.12
-11,-4,-1:17.12
-10,-4,-1:17.12
-9,-4,-1:17.12
0,-4,-1:17.12
1,-4,-1:17.12
-10,-3,-1:17.12
1,-3,-1:17.12
-9,-2,-1:17.12
1,-2,-1:17.12
2,-2,-1:17.12
-9,-1,-1:17.12
2,-1,-1:17.12
-9,0,-1:17.12
1,0,-1:17.12
2,0,-1:17.12
-9,1,-1:17.12
-1,1,-1:17.12
0,1,-1:17.12
-8,2,-1:17.12
-7,2,-1:17.12
-6,2,-1:17.12
-5,2,-1:17.12
-2,2,-1:17.12
-1,2,-1:17.12
-7,3,-1:17.12
-4,3,-1:17.12
-3,3,-1:17.12
-2,3,-1:17.12
-3,4,-1:17.12
-2,4,-1:17.12
-5,-8,0:17.12
-4,-7,0:17.12
-3,-7,0:17.12
-1,-7,0:17.12
0,-7,0:17.12
-2,-6,0:17.12
-1,-6,0:17.12
0,-6,0:17.12
-8,-5,0:17.12
-7,-5,0:17.12
0,-5,0:17.12
-10,-4,0:17.12
-9,-4,0:17.12
-8,-4,0:17.12
0,-4,0:17.12
-10,-3,0:17.12
-9,-3,0:17.12
0,-3,0:17.12
1,-3,0:17.12
-9,-2,0:17.12
1,-2,0:17.12
-9,-1,0:17.12
1,-1,0:17.12
2,-1,0:17.12
-9,0,0:17.12
-8,0,0:18.14
0,0,0:17.12
1,0,0:17.12
2,0,0:17.12
-8,1,0:17.12
-1,1,0:17.12
0,1,0:17.12
-8,2,0:17.12
-7,2,0:17.12
-6,2,0:17.12
-5,2,0:17.12
-4,2,0:17.12
-2,2,0:17.12
-4,3,0:17.12
-3,3,0:17.12
-2,3,0:17.12
-5,-8,1:17.12
-5,-7,1:17.12
-4,-7,1:17.12
-3,-7,1:17.12
-2,-7,1:17.12
-4,-6,1:17.12
-3,-6,1:17.12
-2,-6,1:17.12
-1,-6,1:17.12
0,-6,1:17.12
-8,-5,1:17.12
-7,-5,1:17.12
0,-5,1:17.12
-9,-4,1:17.12
-8,-4,1:17.12
0,-4,1:17.12
-9,-3,1:17.12
0,-3,1:17.12
-9,-2,1:17.12
0,-2,1:17.12
1,-2,1:17.12
-8,-1,1:17.12
1,-1,1:17.12
-8,0,1:17.12
0,0,1:17.12
1,0,1:17.12
-8,1,1:17.12
-2,1,1:17.12
-1,1,1:17.12
-8,2,1:17.12
-7,2,1:17.12
-6,2,1:17.12
-5,2,1:17.12
-4,2,1:17.12
-3,2,1:17.12
-2,2,1:17.12
-3,3,1:17.12
-5,-7,2:17.12
-4,-7,2:17.12
-3,-7,2:17.12
-2,-7,2:17.12
-6,-6,2:17.12
-4,-6,2:17.12
-3,-6,2:17.12
-2,-6,2:17.12
-1,-6,2:17.12
-7,-5,2:17.12
-3,-5,2:17.12
-2,-5,2:17.12
-1,-5,2:17.12
-8,-4,2:17.12
-1,-4,2:17.12
0,-4,2:17.12
-9,-3,2:17.12
-8,-3,2:17.12
0,-3,2:17.12
-8,-2,2:17.12
0,-2,2:17.12
-8,-1,2:17.12
0,-1,2:17.12
1,-1,2:17.12
-8,0,2:17.12
-1,0,2:17.12
0,0,2:17.12
1,0,2:17.12
-8,1,2:17.12
-2,1,2:17.12
-1,1,2:17.12
-8,2,2:17.12
-7,2,2:17.12
-6,2,2:17.12
-5,2,2:17.12
-4,2,2:17.12
-3,2,2:17.12
-2,2,2:17.12
-6,-7,3:17.12
-5,-7,3:17.12
-3,-7,3:17.12
-1,-7,3:17.12
-6,-6,3:17.12
-5,-6,3:17.12
-4,-6,3:17.12
-3,-6,3:17.12
-2,-6,3:17.12
-7,-5,3:17.12
-6,-5,3:17.12
-3,-5,3:17.12
-2,-5,3:17.12
-1,-5,3:17.12
-8,-4,3:17.12
-7,-4,3:17.12
-1,-4,3:17.12
-8,-3,3:17.12
-1,-3,3:17.12
0,-3,3:17.12
-8,-2,3:17.12
0,-2,3:17.12
-8,-1,3:17.12
0,-1,3:17.12
1,-1,3:17.12
-8,0,3:17.12
-1,0,3:17.12
0,0,3:17.12
-8,1,3:17.12
-2,1,3:17.12
-1,1,3:17.12
-8,2,3:17.12
-7,2,3:17.12
-6,2,3:17.12
-5,2,3:17.12
-4,2,3:17.12
-3,2,3:17.12
-2,2,3:17.12
-6,-6,4:17.12
-5,-6,4:17.12
-4,-6,4:17.12
-3,-6,4:17.12
-2,-6,4:17.12
-7,-5,4:17.12
-6,-5,4:17.12
-4,-5,4:17.12
-3,-5,4:17.12
-2,-5,4:17.12
-1,-5,4:17.12
-7,-4,4:17.12
-1,-4,4:17.12
-8,-3,4:17.12
-1,-3,4:17.12
-8,-2,4:17.12
-1,-2,4:17.12
0,-2,4:17.12
-8,-1,4:17.12
0,-1,4:17.12
-8,0,4:17.12
-7,0,4:17.12
-1,0,4:17.12
0,0,4:17.12
-7,1,4:17.12
-2,1,4:17.12
-1,1,4:17.12
-7,2,4:17.12
-6,2,4:17.12
-5,2,4:17.12
-4,2,4:17.12
-3,2,4:17.12
-2,2,4:17.12
-5,-6,5:17.12
-6,-5,5:17.12
-5,-5,5:17.12
-4,-5,5:17.12
-3,-5,5:17.12
-2,-5,5:17.12
-1,-5,5:17.12
-7,-4,5:17.12
-1,-4,5:17.12
-8,-3,5:17.12
-1,-3,5:17.12
-8,-2,5:17.12
-1,-2,5:17.12
-8,-1,5:17.12
0,-1,5:17.12
-8,0,5:17.12
-7,0,5:17.12
-1,0,5:17.12
-7,1,5:17.12
-2,1,5:17.12
-6,2,5:17.12
-5,2,5:17.12
-4,2,5:17.12
-3,2,5:17.12
-2,2,5:17.12
-6,-5,6:17.12
-5,-5,6:17.12
-4,-5,6:17.12
-3,-5,6:17.12
-2,-5,6:17.12
-1,-5,6:17.12
-7,-4,6:17.12
-6,-4,6:17.12
-1,-4,6:17.12
-8,-3,6:17.12
-7,-3,6:17.12
-1,-3,6:17.12
-8,-2,6:17.12
-1,-2,6:17.12
-8,-1,6:17.12
-1,-1,6:17.12
0,-1,6:17.12
-8,0,6:17.12
-7,0,6:17.12
-1,0,6:17.12
-7,1,6:17.12
-2,1,6:17.12
-1,1,6:17.12
-6,2,6:17.12
-5,2,6:17.12
-4,2,6:17.12
-3,2,6:17.12
-2,2,6:17.12
-6,-5,7:17.12
-5,-5,7:17.12
-4,-5,7:17.12
-3,-5,7:17.12
-2,-5,7:17.12
-7,-4,7:17.12
-6,-4,7:17.12
-2,-4,7:17.12
-1,-4,7:17.12
-8,-3,7:17.12
-7,-3,7:17.12
-1,-3,7:17.12
-8,-2,7:17.12
-1,-2,7:17.12
-8,-1,7:17.12
-1,-1,7:17.12
-8,0,7:17.12
-7,0,7:17.12
-1,0,7:17.12
-7,1,7:17.12
-2,1,7:17.12
-1,1,7:17.12
-7,2,7:17.12
-6,2,7:17.12
-5,2,7:17.12
-4,2,7:17.12
-3,2,7:17.12
-2,2,7:17.12
-6,-5,8:17.12
-5,-5,8:17.12
-4,-5,8:17.12
-3,-5,8:17.12
-7,-4,8:17.12
-6,-4,8:17.12
-2,-4,8:17.12
-1,-4,8:17.12
-8,-3,8:17.12
-7,-3,8:17.12
-1,-3,8:17.12
-8,-2,8:17.12
-1,-2,8:17.12
-8,-1,8:17.12
-1,-1,8:17.12
-8,0,8:17.12
-7,0,8:17.12
-1,0,8:17.12
-7,1,8:17.12
-2,1,8:17.12
-1,1,8:17.12
-7,2,8:17.12
-6,2,8:17.12
-5,2,8:17.12
-4,2,8:17.12
-3,2,8:17.12
-2,2,8:17.12
-6,-5,9:17.12
-5,-5,9:17.12
-4,-5,9:17.12
-7,-4,9:17.12
-6,-4,9:17.12
-4,-4,9:18.14
-3,-4,9:17.12
-2,-4,9:17.12
-1,-4,9:17.12
-8,-3,9:17.12
-7,-3,9:17.12
-1,-3,9:17.12
-8,-2,9:17.12
-1,-2,9:17.12
-8,-1,9:17.12
-1,-1,9:17.12
-8,0,9:17.12
-7,0,9:17.12
-1,0,9:17.12
-7,1,9:17.12
-2,1,9:17.12
-1,1,9:17.12
-7,2,9:17.12
-6,2,9:17.12
-5,2,9:17.12
-4,2,9:17.12
-3,2,9:17.12
-2,2,9:17.12
-3,3,9:17.12
-6,-4,10:17.12
-4,-4,10:17.12
-3,-4,10:17.12
-2,-4,10:17.12
-1,-4,10:17.12
-7,-3,10:17.12
-1,-3,10:17.12
-8,-2,10:17.12
-1,-2,10:17.12
-8,-1,10:17.12
-1,-1,10:17.12
-8,0,10:17.12
-7,0,10:17.12
-1,0,10:17.12
-7,1,10:17.12
-2,1,10:17.12
-1,1,10:17.12
-7,2,10:17.12
-6,2,10:17.12
-5,2,10:17.12
-4,2,10:17.12
-3,2,10:17.12
-2,2,10:17.12
-3,3,10:17.12
-5,-5,11:17.12
-6,-4,11:17.12
-5,-4,11:17.12
-4,-4,11:17.12
-3,-4,11:17.12
-2,-4,11:17.12
-1,-4,11:17.12
-7,-3,11:17.12
-1,-3,11:17.12
-8,-2,11:17.12
-1,-2,11:17.12
-8,-1,11:17.12
-1,-1,11:17.12
-7,0,11:17.12
-1,0,11:17.12
-7,1,11:17.12
-2,1,11:17.12
-1,1,11:17.12
-7,2,11:17.12
-6,2,11:17.12
-5,2,11:17.12
-4,2,11:17.12
-3,2,11:17.12
-2,2,11:17.12
-4,3,11:17.12
-3,3,11:17.12
-6,-4,12:17.12
-5,-4,12:17.12
-4,-4,12:17.12
-3,-4,12:17.12
-2,-4,12:17.12
-7,-3,12:17.12
-6,-3,12:17.12
-2,-3,12:17.12
-1,-3,12:17.12
-8,-2,12:17.12
-7,-2,12:17.12
-1,-2,12:17.12
-8,-1,12:17.12
-1,-1,12:17.12
-7,0,12:17.12
-1,0,12:17.12
-7,1,12:17.12
-2,1,12:17.12
-1,1,12:17.12
-7,2,12:17.12
-6,2,12:17.12
-5,2,12:17.12
-4,2,12:17.12
-3,2,12:17.12
-2,2,12:17.12
-4,3,12:17.12
-3,3,12:17.12
-6,-4,13:17.12
-5,-4,13:17.12
-4,-4,13:17.12
-3,-4,13:17.12
-2,-4,13:17.12
-7,-3,13:17.12
-6,-3,13:17.12
-2,-3,13:17.12
-1,-3,13:17.12
-8,-2,13:17.12
-7,-2,13:17.12
-1,-2,13:17.12
-8,-1,13:17.12
-1,-1,13:17.12
-7,0,13:17.12
-1,0,13:17.12
-7,1,13:17.12
-2,1,13:17.12
-1,1,13:17.12
-7,2,13:17.12
-6,2,13:17.12
-5,2,13:17.12
-3,2,13:17.12
-2,2,13:17.12
-4,3,13:17.12
-3,3,13:17.12
-6,-4,14:17.12
-5,-4,14:17.12
-4,-4,14:17.12
-3,-4,14:17.12
-7,-3,14:17.12
-6,-3,14:17.12
-2,-3,14:17.12
-8,-2,14:17.12
-7,-2,14:17.12
-1,-2,14:17.12
-8,-1,14:17.12
-1,-1,14:17.12
-7,0,14:17.12
-1,0,14:17.12
-7,1,14:17.12
-2,1,14:17.12
-1,1,14:17.12
-7,2,14:17.12
-6,2,14:17.12
-5,2,14:17.12
-3,2,14:17.12
-2,2,14:17.12
-4,3,14:17.12
-3,3,14:17.12
-6,-4,15:17.12
-5,-4,15:17.12
-4,-4,15:17.12
-3,-4,15:17.12
-7,-3,15:17.12
-6,-3,15:17.12
-3,-3,15:17.12
-2,-3,15:17.12
-8,-2,15:17.12
-7,-2,15:17.12
-2,-2,15:17.12
-1,-2,15:17.12
-8,-1,15:17.12
-1,-1,15:17.12
-7,0,15:17.12
-1,0,15:17.12
-7,1,15:17.12
-2,1,15:17.12
-1,1,15:17.12
-7,2,15:17.12
-6,2,15:17.12
-5,2,15:17.12
-3,2,15:17.12
-2,2,15:17.12
-5,3,15:17.12
-4,3,15:17.12
-3,3,15:17.12
-5,-4,16:17.12
-4,-4,16:17.12
-6,-3,16:17.12
-4,-3,16:17.12
-3,-3,16:17.12
-2,-3,16:17.12
-7,-2,16:17.12
-2,-2,16:17.12
-8,-1,16:17.12
-1,-1,16:17.12
-7,0,16:17.12
-1,0,16:17.12
-7,1,16:17.12
-2,1,16:17.12
-1,1,16:17.12
-7,2,16:17.12
-6,2,16:17.12
-5,2,16:17.12
-3,2,16:17.12
-2,2,16:17.12
-5,3,16:17.12
-4,3,16:17.12
-3,3,16:17.12
-19,6,16:18.5
-19,7,16:18.5
11,7,16:18.5
-19,8,16:18.5
11,8,16:18.5
-19,9,16:18.5
-4,12,16:18.5
-7,13,16:18.5
-12,15,16:18.5
-11,15,16:18.5
4,17,16:18.5
1,-9,17:18.14
12,-9,17:18.5
-20,-8,17:18.5
3,-7,17:18.14
-5,-4,17:17.12
-6,-3,17:17.12
-5,-3,17:17.12
-4,-3,17:17.12
-3,-3,17:17.12
-2,-3,17:17.12
-7,-2,17:17.12
-2,-2,17:17.12
-8,-1,17:17.12
-2,-1,17:17.12
-1,-1,17:17.12
-7,0,17:17.12
-1,0,17:17.12
-7,1,17:17.12
-2,1,17:17.12
-1,1,17:17.12
-7,2,17:17.12
-6,2,17:17.12
-3,2,17:17.12
-2,2,17:17.12
-5,3,17:17.12
-4,3,17:17.12
-3,3,17:17.12
-18,5,17:18.5
-19,6,17:18.5
-18,6,17:18.5
-19,7,17:18.5
11,7,17:18.5
-19,8,17:18.5
11,8,17:18.5
-10,9,17:18.5
-9,9,17:18.5
0,10,17:18.5
1,10,17:18.5
2,10,17:18.5
-5,11,17:18.5
-4,11,17:18.5
-5,12,17:18.5
-4,12,17:18.5
-7,13,17:18.5
-6,13,17:18.5
-2,13,17:18.5
-11,14,17:18.5
-10,14,17:18.5
-9,14,17:18.5
0,14,17:18.5
-12,15,17:18.5
-11,15,17:18.5
0,15,17:18.5
1,15,17:18.5
2,16,17:18.5
3,16,17:18.5
3,17,17:18.5
4,17,17:18.5
5,17,17:18.5
5,18,17:18.5
-14,-17,18:18.5
3,-15,18:18.5
-1,-14,18:18.5
-4,-13,18:18.5
-3,-13,18:18.5
-10,-10,18:18.13
-9,-10,18:18.13
0,-10,18:18.13
1,-10,18:18.13
12,-10,18:18.5
-20,-9,18:18.5
-1,-9,18:18.14
0,-9,18:18.14
1,-9,18:18.14
12,-9,18:18.5
-19,-8,18:18.5
-1,-8,18:18.14
0,-8,18:18.14
1,-8,18:18.14
2,-8,18:18.14
12,-8,18:18.5
-19,-7,18:18.5
3,-7,18:18.14
4,-7,18:18.14
11,-7,18:18.5
-19,-6,18:18.5
-6,-3,18:17.12
-5,-3,18:17.12
-4,-3,18:17.12
-3,-3,18:17.12
-2,-3,18:17.12
-7,-2,18:17.12
-6,-2,18:17.12
-2,-2,18:17.12
-8,-1,18:17.12
-7,-1,18:17.12
-2,-1,18:17.12
-1,-1,18:17.12
-7,0,18:17.12
-1,0,18:17.12
-7,1,18:17.12
-2,1,18:17.12
-1,1,18:17.12
-7,2,18:17.12
-6,2,18:17.12
-3,2,18:17.12
-2,2,18:17.12
-5,3,18:17.12
-4,3,18:17.12
-3,3,18:17.12
-18,4,18:18.5
-18,5,18:18.5
-13,5,18:18.5
10,5,18:18.5
-18,6,18:18.5
10,6,18:18.5
-19,7,18:18.5
-18,7,18:18.5
-12,7,18:18.5
10,7,18:18.5
-19,8,18:18.5
-12,8,18:18.5
-11,8,18:18.5
-10,8,18:18.5
3,8,18:18.5
11,8,18:18.5
-10,9,18:18.5
-9,9,18:18.5
2,9,18:18.5
3,9,18:18.5
1,10,18:18.5
2,10,18:18.5
-6,11,18:18.5
-5,11,18:18.5
-4,11,18:18.5
-3,11,18:18.5
-2,11,18:18.5
-6,12,18:18.5
-5,12,18:18.5
-4,12,18:18.5
-3,12,18:18.5
-8,13,18:18.5
-7,13,18:18.5
-6,13,18:18.5
-3,13,18:18.5
-2,13,18:18.5
-11,14,18:18.5
-10,14,18:18.5
-9,14,18:18.5
-1,14,18:18.5
0,14,18:18.5
-13,15,18:18.5
-12,15,18:18.5
1,15,18:18.5
2,15,18:18.5
2,16,18:18.5
3,16,18:18.5
4,17,18:18.5
5,17,18:18.5
5,18,18:18.5
-16,-17,19:18.5
-15,-17,19:18.5
-14,-17,19:18.5
-14,-16,19:18.5
-13,-16,19:18.5
-12,-16,19:18.5
-11,-15,19:18.5
-10,-15,19:18.5
-9,-15,19:18.5
2,-15,19:18.5
3,-15,19:18.5
4,-15,19:18.5
-9,-14,19:18.5
0,-14,19:18.5
1,-14,19:18.5
-7,-13,19:18.5
-6,-13,19:18.5
-4,-13,19:18.5
-3,-13,19:18.5
-2,-13,19:18.5
-5,-12,19:18.13
-4,-12,19:18.13
-6,-11,19:18.13
-5,-11,19:18.13
-3,-11,19:18.13
-9,-10,19:18.5
1,-10,19:18.14
12,-10,19:18.5
-11,-9,19:18.5
-10,-9,19:18.5
0,-9,19:18.14
1,-9,19:18.13
12,-9,19:18.5
-19,-8,19:18.5
-12,-8,19:18.5
-11,-8,19:18.5
-2,-8,19:18.14
-1,-8,19:18.14
0,-8,19:18.14
1,-8,19:18.14
2,-8,19:18.14
3,-8,19:18.14
11,-8,19:18.5
-19,-7,19:18.5
-13,-7,19:18.5
-2,-7,19:18.14
2,-7,19:18.13
11,-7,19:18.5
-19,-6,19:18.5
-13,-6,19:18.5
11,-6,19:18.5
-18,-5,19:18.5
-18,-3,19:18.5
-6,-3,19:17.12
-5,-3,19:17.12
-4,-3,19:17.12
-3,-3,19:17.12
-2,-3,19:17.12
-17,-2,19:18.5
-7,-2,19:17.12
-6,-2,19:17.12
-2,-2,19:17.12
-17,-1,19:18.5
-8,-1,19:17.12
-7,-1,19:17.12
-2,-1,19:17.12
-17,0,19:18.5
-16,0,19:18.5
-15,0,19:18.5
-14,0,19:18.5
-7,0,19:17.12
-1,0,19:17.12
-7,1,19:17.12
-2,1,19:17.12
-1,1,19:17.12
-7,2,19:17.12
-6,2,19:17.12
-3,2,19:17.12
-2,2,19:17.12
9,2,19:18.5
-17,3,19:18.5
-5,3,19:17.12
-4,3,19:17.12
-3,3,19:17.12
9,3,19:18.5
-18,4,19:18.5
-18,5,19:18.5
-13,5,19:18.5
10,5,19:18.5
-18,6,19:18.5
-13,6,19:18.5
-12,6,19:18.5
1,6,19:18.13
5,6,19:18.5
10,6,19:18.5
-18,7,19:18.5
-12,7,19:18.5
1,7,19:18.13
2,7,19:18.5
4,7,19:18.5
10,7,19:18.5
-19,8,19:18.5
-18,8,19:18.5
-11,8,19:18.5
-10,8,19:18.5
3,8,19:18.5
4,8,19:18.5
10,8,19:18.5
-9,9,19:18.5
-8,9,19:18.5
1,9,19:18.5
2,9,19:18.5
3,9,19:18.5
-6,10,19:18.5
-5,10,19:18.5
-3,10,19:18.5
0,10,19:18.5
-5,11,19:18.5
-4,11,19:18.5
-3,11,19:18.5
-6,12,19:18.5
-5,12,19:18.5
-4,12,19:18.5
-3,12,19:18.5
-9,13,19:18.5
-8,13,19:18.5
-7,13,19:18.5
-2,13,19:18.5
-1,13,19:18.5
-12,14,19:18.5
-11,14,19:18.5
-10,14,19:18.5
-9,14,19:18.5
-1,14,19:18.5
0,14,19:18.5
-12,15,19:18.5
1,15,19:18.5
2,15,19:18.5
2,16,19:18.5
3,16,19:18.5
4,16,19:18.5
4,17,19:18.5
5,17,19:18.5
-16,-17,20:18.5
-15,-17,20:18.5
-14,-16,20:18.5
-13,-16,20:18.5
-12,-16,20:18.5
-12,-15,20:18.5
-11,-15,20:18.5
-10,-15,20:18.5
2,-15,20:18.5
3,-15,20:18.5
4,-15,20:18.5
-10,-14,20:18.5
-9,-14,20:18.5
-8,-14,20:18.5
0,-14,20:18.5
1,-14,20:18.5
2,-14,20:18.5
-8,-13,20:18.5
-7,-13,20:18.5
-6,-13,20:18.5
-3,-13,20:18.5
-2,-13,20:18.5
-1,-13,20:18.5
-5,-12,20:18.13
-4,-12,20:18.13
-3,-12,20:18.13
-6,-11,20:18.13
-5,-11,20:18.13
-4,-11,20:18.13
-3,-11,20:18.13
-3,-10,20:18.13
-10,-9,20:18.5
-9,-9,20:18.5
-8,-9,20:18.5
-3,-9,20:18.14
-2,-9,20:18.14
-1,-9,20:18.13
0,-9,20:18.13
1,-9,20:18.13
11,-9,20:18.5
-19,-8,20:18.5
-12,-8,20:18.5
-11,-8,20:18.5
-10,-8,20:18.5
-2,-8,20:18.14
-1,-8,20:18.14
1,-8,20:18.13
2,-8,20:18.13
3,-8,20:18.13
11,-8,20:18.5
-19,-7,20:18.5
-12,-7,20:18.5
-2,-7,20:18.14
-1,-7,20:18.14
0,-7,20:18.14
2,-7,20:18.13
3,-7,20:18.13
11,-7,20:18.5
-19,-6,20:18.5
-18,-6,20:18.5
-13,-6,20:18.5
-3,-6,20:18.14
0,-6,20:18.14
1,-6,20:18.13
3,-6,20:18.13
4,-6,20:18.5
10,-6,20:18.5
-18,-5,20:18.5
-13,-5,20:18.5
4,-5,20:18.5
10,-5,20:18.5
-18,-4,20:18.5
10,-4,20:18.5
-17,-3,20:18.5
-6,-3,20:17.12
-5,-3,20:17.12
-4,-3,20:17.12
-3,-3,20:17.12
-2,-3,20:17.12
-17,-2,20:18.5
-7,-2,20:17.12
-6,-2,20:17.12
-2,-2,20:17.12
-17,-1,20:18.5
-16,-1,20:18.5
-8,-1,20:17.12
-7,-1,20:17.12
-2,-1,20:17.12
-17,0,20:18.5
-16,0,20:18.5
-15,0,20:18.5
-14,0,20:18.5
-13,0,20:18.5
-12,0,20:18.13
-7,0,20:17.12
-2,0,20:17.12
-1,0,20:17.12
8,0,20:18.5
-17,1,20:18.5
-16,1,20:18.5
-7,1,20:17.12
-2,1,20:17.12
-1,1,20:17.12
8,1,20:18.5
-17,2,20:18.5
-7,2,20:17.12
-6,2,20:17.12
-3,2,20:17.12
-2,2,20:17.12
9,2,20:18.5
-17,3,20:18.5
-6,3,20:17.12
-5,3,20:17.12
-4,3,20:17.12
-3,3,20:17.12
9,3,20:18.5
-18,4,20:18.5
-17,4,20:18.5
-13,4,20:18.5
9,4,20:18.5
-18,5,20:18.5
-13,5,20:18.5
5,5,20:18.5
9,5,20:18.5
-18,6,20:18.5
-12,6,20:18.5
0,6,20:18.13
1,6,20:18.13
4,6,20:18.5
5,6,20:18.5
10,6,20:18.5
-18,7,20:18.5
-12,7,20:18.5
-11,7,20:18.5
1,7,20:18.13
2,7,20:18.5
4,7,20:18.5
10,7,20:18.5
-18,8,20:18.5
-11,8,20:18.5
-10,8,20:18.5
-9,8,20:18.5
2,8,20:18.5
3,8,20:18.5
4,8,20:18.5
-9,9,20:18.5
-8,9,20:18.5
-7,9,20:18.5
0,9,20:18.5
1,9,20:18.5
2,9,20:18.5
-6,10,20:18.5
-5,10,20:18.5
-4,10,20:18.5
-3,10,20:18.5
-2,10,20:18.5
-1,10,20:18.5
-5,11,20:18.5
-4,11,20:18.5
-6,12,20:18.5
-5,12,20:18.5
-3,12,20:18.5
-9,13,20:18.5
-8,13,20:18.5
-7,13,20:18.5
-2,13,20:18.5
-1,13,20:18.5
-11,14,20:18.5
-10,14,20:18.5
0,14,20:18.5
1,14,20:18.5
1,15,20:18.5
2,15,20:18.5
3,16,20:18.5
4,16,20:18.5
4,17,20:18.5
5,17,20:18.5
-15,-17,21:18.5
-15,-16,21:18.5
-14,-16,21:18.5
-13,-16,21:18.5
-13,-15,21:18.5
-12,-15,21:18.5
-11,-15,21:18.5
3,-15,21:18.5
4,-15,21:18.5
-11,-14,21:18.5
-10,-14,21:18.5
-9,-14,21:18.5
0,-14,21:18.5
1,-14,21:18.5
2,-14,21:18.5
3,-14,21:18.5
-8,-13,21:18.5
-7,-13,21:18.5
-2,-13,21:18.5
-1,-13,21:18.5
0,-13,21:18.5
-6,-12,21:18.5
-5,-12,21:18.5
-4,-12,21:18.5
-3,-12,21:18.5
-5,-11,21:18.5
-4,-11,21:18.5
-7,-10,21:18.5
-6,-10,21:18.5
-5,-10,21:18.5
-4,-10,21:18.5
-3,-10,21:18.5
-9,-9,21:18.5
-8,-9,21:18.5
-7,-9,21:18.5
-3,-9,21:18.6
-2,-9,21:18.5
-1,-9,21:18.5
0,-9,21:18.6
11,-9,21:18.5
-11,-8,21:18.5
-10,-8,21:18.5
-9,-8,21:18.13
-2,-8,21:18.14
-1,-8,21:18.14
0,-8,21:18.5
1,-8,21:18.5
2,-8,21:18.5
11,-8,21:18.5
-19,-7,21:18.5
-18,-7,21:18.5
-12,-7,21:18.5
-11,-7,21:18.5
-2,-7,21:18.14
-1,-7,21:18.14
0,-7,21:18.14
2,-7,21:18.13
3,-7,21:18.5
10,-7,21:18.5
11,-7,21:18.5
-18,-6,21:18.5
-12,-6,21:18.5
-3,-6,21:18.14
1,-6,21:18.13
3,-6,21:18.5
10,-6,21:18.5
-18,-5,21:18.5
-13,-5,21:18.5
0,-5,21:18.13
1,-5,21:18.13
4,-5,21:18.5
10,-5,21:18.5
-18,-4,21:18.5
-13,-4,21:18.5
4,-4,21:18.5
9,-4,21:18.5
-17,-3,21:18.5
-6,-3,21:17.12
-5,-3,21:17.12
-4,-3,21:17.12
-3,-3,21:17.12
9,-3,21:18.5
-17,-2,21:18.5
-7,-2,21:17.12
-6,-2,21:17.12
-3,-2,21:17.12
-2,-2,21:17.12
9,-2,21:18.5
-17,-1,21:18.5
-15,-1,21:18.5
-8,-1,21:17.12
-7,-1,21:17.12
-2,-1,21:17.12
8,-1,21:18.5
-16,0,21:18.5
-15,0,21:18.5
-14,0,21:18.5
-13,0,21:18.5
-12,0,21:18.13
-11,0,21:18.13
-7,0,21:17.12
-2,0,21:17.12
-1,0,21:17.12
7,0,21:18.5
8,0,21:18.5
-17,1,21:18.5
-16,1,21:18.5
-15,1,21:18.5
-7,1,21:17.12
-2,1,21:17.12
-1,1,21:17.12
7,1,21:18.5
8,1,21:18.5
-17,2,21:18.5
-7,2,21:17.12
-6,2,21:17.12
-3,2,21:17.12
-2,2,21:17.12
8,2,21:18.5
9,2,21:18.5
-17,3,21:18.5
-6,3,21:17.12
-5,3,21:17.12
-4,3,21:17.12
-3,3,21:17.12
9,3,21:18.5
-17,4,21:18.5
-13,4,21:18.5
5,4,21:18.5
9,4,21:18.5
-18,5,21:18.5
-17,5,21:18.5
-13,5,21:18.5
-12,5,21:18.5
5,5,21:18.5
9,5,21:18.5
-18,6,21:18.5
-12,6,21:18.5
-11,6,21:18.13
0,6,21:18.13
1,6,21:18.13
4,6,21:18.5
9,6,21:18.5
-18,7,21:18.5
-11,7,21:18.5
-10,7,21:18.13
1,7,21:18.13
2,7,21:18.5
3,7,21:18.5
4,7,21:18.5
10,7,21:18.5
-18,8,21:18.5
-10,8,21:18.5
-9,8,21:18.5
-8,8,21:18.5
2,8,21:18.5
3,8,21:18.5
10,8,21:18.5
-8,9,21:18.5
-7,9,21:18.5
-6,9,21:18.5
-2,9,21:18.5
-1,9,21:18.5
0,9,21:18.5
1,9,21:18.5
-6,10,21:18.5
-5,10,21:18.5
-4,10,21:18.5
-3,10,21:18.5
-2,10,21:18.5
-5,11,21:18.5
-4,11,21:18.5
-3,11,21:18.5
-7,12,21:18.5
-6,12,21:18.5
-5,12,21:18.5
-3,12,21:18.5
-2,12,21:18.5
-10,13,21:18.5
-9,13,21:18.5
-8,13,21:18.5
-7,13,21:18.5
-2,13,21:18.5
-1,13,21:18.5
-12,14,21:18.5
-11,14,21:18.5
-10,14,21:18.5
0,14,21:18.5
1,14,21:18.5
1,15,21:18.5
2,15,21:18.5
3,15,21:18.5
3,16,21:18.5
4,16,21:18.5
-15,-16,22:18.5
-14,-16,22:18.5
-14,-15,22:18.5
-13,-15,22:18.5
-12,-15,22:18.5
-11,-14,22:18.5
-10,-14,22:18.5
1,-14,22:18.5
2,-14,22:18.5
3,-14,22:18.5
-9,-13,22:18.5
-8,-13,22:18.5
-7,-13,22:18.5
-1,-13,22:18.5
0,-13,22:18.5
1,-13,22:18.5
-7,-12,22:18.5
-6,-12,22:18.5
-3,-12,22:18.5
-2,-12,22:18.5
-5,-11,22:18.5
-4,-11,22:18.5
-6,-10,22:18.5
-5,-10,22:18.5
-4,-10,22:18.5
-3,-10,22:18.5
-8,-9,22:18.5
-7,-9,22:18.5
-6,-9,22:18.5
-3,-9,22:18.5
-2,-9,22:18.5
-1,-9,22:18.5
11,-9,22:18.5
-10,-8,22:18.5
-9,-8,22:18.5
-8,-8,22:18.5
-2,-8,22:18.6
-1,-8,22:18.5
0,-8,22:18.5
11,-8,22:18.5
-18,-7,22:18.5
-11,-7,22:18.5
-10,-7,22:18.13
-1,-7,22:18.14
0,-7,22:18.14
1,-7,22:18.13
2,-7,22:18.13
10,-7,22:18.5
-18,-6,22:18.5
-12,-6,22:18.5
1,-6,22:18.13
2,-6,22:18.13
3,-6,22:18.5
10,-6,22:18.5
-18,-5,22:18.5
-12,-5,22:18.13
0,-5,22:18.13
1,-5,22:18.13
3,-5,22:18.13
4,-5,22:18.5
9,-5,22:18.5
10,-5,22:18.5
-18,-4,22:18.5
-17,-4,22:18.5
-13,-4,22:18.5
0,-4,22:18.13
4,-4,22:18.5
9,-4,22:18.5
-17,-3,22:18.5
-13,-3,22:18.5
-5,-3,22:17.12
-4,-3,22:17.12
4,-3,22:18.5
9,-3,22:18.5
-17,-2,22:18.5
-6,-2,22:17.12
-3,-2,22:17.12
-2,-2,22:17.12
8,-2,22:18.5
9,-2,22:18.5
-17,-1,22:18.5
-16,-1,22:18.5
-15,-1,22:18.5
-14,-1,22:18.5
-7,-1,22:17.12
-2,-1,22:17.12
6,-1,22:18.5
8,-1,22:18.5
-16,0,22:18.5
-15,0,22:18.5
-14,0,22:18.5
-13,0,22:18.5
-12,0,22:18.13
-11,0,22:18.13
-7,0,22:17.12
-2,0,22:17.12
7,0,22:18.5
8,0,22:18.5
-16,1,22:18.5
-15,1,22:18.5
-14,1,22:18.5
-7,1,22:17.12
-2,1,22:17.12
-1,1,22:17.12
6,1,22:18.5
7,1,22:18.5
8,1,22:18.5
-17,2,22:18.5
-16,2,22:18.5
-14,2,22:18.5
-7,2,22:17.12
-3,2,22:17.12
-2,2,22:17.12
8,2,22:18.5
-17,3,22:18.5
-13,3,22:18.5
-6,3,22:17.12
-5,3,22:17.12
-4,3,22:17.12
-3,3,22:17.12
8,3,22:18.5
-17,4,22:18.5
-13,4,22:18.5
-12,4,22:18.5
5,4,22:18.5
9,4,22:18.5
-17,5,22:18.5
-12,5,22:18.5
-1,5,22:18.13
0,5,22:18.13
4,5,22:18.5
9,5,22:18.5
-17,6,22:18.5
-11,6,22:18.13
0,6,22:18.13
1,6,22:18.13
4,6,22:18.5
9,6,22:18.5
-18,7,22:18.5
-11,7,22:18.5
-10,7,22:18.13
1,7,22:18.13
2,7,22:18.5
3,7,22:18.5
9,7,22:18.5
-18,8,22:18.5
-9,8,22:18.5
-8,8,22:18.5
-7,8,22:18.5
0,8,22:18.5
1,8,22:18.5
2,8,22:18.5
3,8,22:18.5
10,8,22:18.5
-18,9,22:18.5
-7,9,22:18.5
-6,9,22:18.5
-5,9,22:18.5
-3,9,22:18.5
-2,9,22:18.5
-1,9,22:18.5
0,9,22:18.5
-5,10,22:18.5
-4,10,22:18.5
-3,10,22:18.5
-5,11,22:18.5
-4,11,22:18.5
-3,11,22:18.5
-7,12,22:18.5
-6,12,22:18.5
-3,12,22:18.5
-2,12,22:18.5
-10,13,22:18.5
-9,13,22:18.5
-8,13,22:18.5
-1,13,22:18.5
0,13,22:18.5
-12,14,22:18.5
-11,14,22:18.5
-10,14,22:18.5
0,14,22:18.5
1,14,22:18.5
2,15,22:18.5
3,15,22:18.5
3,16,22:18.5
4,16,22:18.5
-14,-15,23:18.5
-13,-15,23:18.5
-12,-14,23:18.5
-11,-14,23:18.5
-10,-14,23:18.5
2,-14,23:18.5
3,-14,23:18.5
-10,-13,23:18.5
-9,-13,23:18.5
-8,-13,23:18.5
-1,-13,23:18.5
0,-13,23:18.5
1,-13,23:18.5
2,-13,23:18.5
-8,-12,23:18.5
-7,-12,23:18.5
-6,-12,23:18.5
-3,-12,23:18.5
-2,-12,23:18.5
-1,-12,23:18.5
-6,-11,23:18.5
-5,-11,23:18.5
-4,-11,23:18.5
-3,-11,23:18.5
-5,-10,23:18.5
-4,-10,23:18.5
-7,-9,23:18.5
-6,-9,23:18.5
-5,-9,23:18.5
-4,-9,23:18.5
-3,-9,23:18.5
-2,-9,23:18.6
11,-9,23:18.5
-18,-8,23:18.5
-9,-8,23:18.5
-8,-8,23:18.5
-7,-8,23:18.5
-2,-8,23:18.5
-1,-8,23:18.5
10,-8,23:18.5
-18,-7,23:18.5
-11,-7,23:18.5
-10,-7,23:18.13
-9,-7,23:18.13
-1,-7,23:18.14
0,-7,23:18.13
1,-7,23:18.13
10,-7,23:18.5
-18,-6,23:18.5
-11,-6,23:18.13
1,-6,23:18.13
2,-6,23:18.13
10,-6,23:18.5
-18,-5,23:18.5
-17,-5,23:18.5
-12,-5,23:18.13
0,-5,23:18.13
1,-5,23:18.13
2,-5,23:18.13
3,-5,23:18.5
9,-5,23:18.5
-17,-4,23:18.5
-13,-4,23:18.5
-12,-4,23:18.13
-1,-4,23:18.13
0,-4,23:18.13
3,-4,23:18.13
4,-4,23:18.5
9,-4,23:18.5
-17,-3,23:18.5
-13,-3,23:18.5
-5,-3,23:17.12
-4,-3,23:17.12
4,-3,23:18.5
8,-3,23:18.5
9,-3,23:18.5
-17,-2,23:18.5
-13,-2,23:18.5
-6,-2,23:17.12
-4,-2,23:17.12
-3,-2,23:17.12
-2,-2,23:17.12
8,-2,23:18.5
-16,-1,23:18.5
-14,-1,23:18.5
-7,-1,23:17.12
-2,-1,23:17.12
6,-1,23:18.5
8,-1,23:18.5
-16,0,23:18.5
-15,0,23:18.5
-14,0,23:18.5
-13,0,23:18.5
-12,0,23:18.13
-11,0,23:18.13
-10,0,23:18.13
-7,0,23:17.12
-2,0,23:17.12
6,0,23:18.5
7,0,23:18.5
-16,1,23:18.5
-15,1,23:18.5
-14,1,23:18.5
-7,1,23:17.12
-2,1,23:17.12
-1,1,23:17.12
6,1,23:18.5
7,1,23:18.5
8,1,23:18.5
-16,2,23:18.5
-14,2,23:18.5
-13,2,23:18.5
-7,2,23:17.12
-3,2,23:17.12
-2,2,23:17.12
6,2,23:18.5
8,2,23:18.5
-17,3,23:18.5
-16,3,23:18.5
-13,3,23:18.5
-6,3,23:17.12
-5,3,23:17.12
-4,3,23:17.12
-3,3,23:17.12
5,3,23:18.5
8,3,23:18.5
-17,4,23:18.5
-12,4,23:18.5
4,4,23:18.5
5,4,23:18.5
8,4,23:18.5
-17,5,23:18.5
-12,5,23:18.5
-11,5,23:18.13
-1,5,23:18.13
0,5,23:18.13
4,5,23:18.5
9,5,23:18.5
-17,6,23:18.5
-11,6,23:18.13
0,6,23:18.13
1,6,23:18.13
3,6,23:18.5
9,6,23:18.5
-17,7,23:18.5
-10,7,23:18.13
-9,7,23:18.13
1,7,23:18.13
2,7,23:18.5
3,7,23:18.5
9,7,23:18.5
-18,8,23:18.5
-8,8,23:18.5
-7,8,23:18.5
-1,8,23:18.5
0,8,23:18.5
1,8,23:18.5
2,8,23:18.5
-6,9,23:18.5
-5,9,23:18.5
-4,9,23:18.5
-3,9,23:18.5
-2,9,23:18.5
-1,9,23:18.5
-5,10,23:18.5
-4,10,23:18.5
-6,11,23:18.5
-5,11,23:18.5
-3,11,23:18.5
-8,12,23:18.5
-7,12,23:18.5
-6,12,23:18.5
-3,12,23:18.5
-2,12,23:18.5
-10,13,23:18.5
-9,13,23:18.5
-8,13,23:18.5
-1,13,23:18.5
0,13,23:18.5
-12,14,23:18.5
-11,14,23:18.5
0,14,23:18.5
1,14,23:18.5
2,14,23:18.5
2,15,23:18.5
3,15,23:18.5
4,16,23:18.5
-14,-15,24:18.5
-13,-15,24:18.5
-13,-14,24:18.5
-12,-14,24:18.5
-11,-14,24:18.5
3,-14,24:18.5
-11,-13,24:18.5
-10,-13,24:18.5
-9,-13,24:18.5
0,-13,24:18.5
1,-13,24:18.5
2,-13,24:18.5
3,-13,24:18.5
-9,-12,24:18.5
-8,-12,24:18.5
-7,-12,24:18.5
-2,-12,24:18.5
-1,-12,24:18.5
0,-12,24:18.5
-6,-11,24:18.5
-3,-11,24:18.5
-5,-10,24:18.5
-4,-10,24:18.5
-6,-9,24:18.5
-5,-9,24:18.5
-4,-9,24:18.5
-3,-9,24:18.5
10,-9,24:18.5
-18,-8,24:18.5
-8,-8,24:18.5
-7,-8,24:18.5
-6,-8,24:18.5
-3,-8,24:18.5
-2,-8,24:18.5
-1,-8,24:18.5
10,-8,24:18.5
-18,-7,24:18.5
-10,-7,24:18.13
-9,-7,24:18.13
-8,-7,24:18.13
-1,-7,24:18.13
0,-7,24:18.13
10,-7,24:18.5
-18,-6,24:18.5
-11,-6,24:18.13
-10,-6,24:18.13
0,-6,24:18.13
1,-6,24:18.13
2,-6,24:18.13
9,-6,24:18.5
10,-6,24:18.5
-17,-5,24:18.5
-11,-5,24:18.13
0,-5,24:18.13
1,-5,24:18.13
2,-5,24:18.13
9,-5,24:18.5
-17,-4,24:18.5
-12,-4,24:18.13
-1,-4,24:18.13
0,-4,24:18.13
2,-4,24:18.13
3,-4,24:18.13
9,-4,24:18.5
-17,-3,24:18.5
-13,-3,24:18.5
-12,-3,24:18.13
-5,-3,24:17.12
-1,-3,24:18.13
3,-3,24:18.13
4,-3,24:18.5
8,-3,24:18.5
-17,-2,24:18.5
-16,-2,24:18.5
-13,-2,24:18.5
-6,-2,24:17.12
-5,-2,24:17.12
-4,-2,24:17.12
-3,-2,24:17.12
-2,-2,24:17.12
4,-2,24:18.5
8,-2,24:18.5
-16,-1,24:18.5
-14,-1,24:18.5
-13,-1,24:18.5
-7,-1,24:17.12
-2,-1,24:17.12
5,-1,24:18.5
7,-1,24:18.5
8,-1,24:18.5
-15,0,24:18.5
-14,0,24:18.5
-13,0,24:18.5
-12,0,24:18.13
-11,0,24:18.13
-10,0,24:18.13
-9,0,24:18.13
-7,0,24:17.12
-2,0,24:17.12
5,0,24:18.5
6,0,24:18.5
7,0,24:18.5
-15,1,24:18.5
-14,1,24:18.5
-7,1,24:17.12
-2,1,24:17.12
5,1,24:18.5
6,1,24:18.5
7,1,24:18.5
-16,2,24:18.5
-13,2,24:18.5
-7,2,24:17.12
-3,2,24:17.12
-2,2,24:17.12
5,2,24:18.5
8,2,24:18.5
-16,3,24:18.5
-13,3,24:18.5
-12,3,24:18.13
-6,3,24:17.12
-5,3,24:17.12
-4,3,24:17.12
-3,3,24:17.12
4,3,24:18.5
5,3,24:18.5
8,3,24:18.5
-17,4,24:18.5
-16,4,24:18.5
-12,4,24:18.5
-2,4,24:18.13
4,4,24:18.5
8,4,24:18.5
-17,5,24:18.5
-11,5,24:18.13
-1,5,24:18.13
0,5,24:18.13
3,5,24:18.13
8,5,24:18.5
-17,6,24:18.5
-11,6,24:18.13
-10,6,24:18.13
0,6,24:18.13
1,6,24:18.13
3,6,24:18.5
8,6,24:18.5
9,6,24:18.5
-17,7,24:18.5
-10,7,24:18.13
-9,7,24:18.13
-8,7,24:18.13
1,7,24:18.13
2,7,24:18.5
9,7,24:18.5
-17,8,24:18.5
-8,8,24:18.13
-7,8,24:18.13
-6,8,24:18.13
-2,8,24:18.13
-1,8,24:18.13
0,8,24:18.13
1,8,24:18.5
-6,9,24:18.5
-5,9,24:18.5
-4,9,24:18.5
-3,9,24:18.5
-2,9,24:18.5
-5,10,24:18.5
-4,10,24:18.5
-3,10,24:18.5
-6,11,24:18.5
-5,11,24:18.5
-3,11,24:18.5
-8,12,24:18.5
-7,12,24:18.5
-6,12,24:18.5
-2,12,24:18.5
-1,12,24:18.5
-11,13,24:18.5
-10,13,24:18.5
-9,13,24:18.5
-8,13,24:18.5
-1,13,24:18.5
0,13,24:18.5
-12,14,24:18.5
-11,14,24:18.5
1,14,24:18.5
2,14,24:18.5
2,15,24:18.5
3,15,24:18.5
4,16,24:18.5
-15,-15,25:18.5
-14,-15,25:18.5
-14,-14,25:18.5
-13,-14,25:18.5
-12,-14,25:18.5
-12,-13,25:18.5
-11,-13,25:18.5
-10,-13,25:18.5
1,-13,25:18.5
2,-13,25:18.5
3,-13,25:18.5
-9,-12,25:18.5
-8,-12,25:18.5
-7,-12,25:18.5
-1,-12,25:18.5
0,-12,25:18.5
1,-12,25:18.5
-7,-11,25:18.5
-6,-11,25:18.5
-3,-11,25:18.5
-2,-11,25:18.5
-6,-10,25:18.5
-5,-10,25:18.5
-4,-10,25:18.5
-3,-10,25:18.5
-5,-9,25:18.5
-4,-9,25:18.5
-6,-8,25:18.5
-5,-8,25:18.5
-4,-8,25:18.5
-3,-8,25:18.5
10,-8,25:18.5
-18,-7,25:18.5
-8,-7,25:18.13
-7,-7,25:18.13
-3,-7,25:18.13
-2,-7,25:18.13
-1,-7,25:18.13
9,-7,25:18.5
10,-7,25:18.5
-18,-6,25:18.5
-17,-6,25:18.5
-10,-6,25:18.13
-9,-6,25:18.13
-1,-6,25:18.13
0,-6,25:18.13
1,-6,25:18.13
9,-6,25:18.5
-17,-5,25:18.5
-11,-5,25:18.13
-10,-5,25:18.13
0,-5,25:18.13
1,-5,25:18.13
2,-5,25:18.13
9,-5,25:18.5
-17,-4,25:18.5
-11,-4,25:18.13
-1,-4,25:18.13
0,-4,25:18.13
2,-4,25:18.13
8,-4,25:18.5
9,-4,25:18.5
-17,-3,25:18.5
-12,-3,25:18.13
-1,-3,25:18.13
3,-3,25:18.13
8,-3,25:18.5
-16,-2,25:18.5
-13,-2,25:18.5
-12,-2,25:18.13
-6,-2,25:17.12
-5,-2,25:17.12
-4,-2,25:17.12
-3,-2,25:17.12
-2,-2,25:17.12
3,-2,25:18.13
4,-2,25:18.5
8,-2,25:18.5
-16,-1,25:18.5
-15,-1,25:18.5
-13,-1,25:18.5
-7,-1,25:17.12
-6,-1,25:17.12
-2,-1,25:17.12
4,-1,25:18.5
7,-1,25:18.5
-15,0,25:18.5
-14,0,25:18.5
-13,0,25:18.5
-12,0,25:18.13
-11,0,25:18.13
-10,0,25:18.13
-9,0,25:18.13
-8,0,25:18.13
-7,0,25:17.12
-2,0,25:17.12
5,0,25:18.5
6,0,25:18.5
-15,1,25:18.5
-14,1,25:18.5
-13,1,25:18.5
-7,1,25:17.12
-2,1,25:17.12
5,1,25:18.5
6,1,25:18.5
7,1,25:18.5
-16,2,25:18.5
-15,2,25:18.5
-13,2,25:18.5
-7,2,25:17.12
-3,2,25:17.12
-2,2,25:17.12
4,2,25:18.5
5,2,25:18.5
7,2,25:18.5
-16,3,25:18.5
-12,3,25:18.13
-6,3,25:17.12
-5,3,25:17.12
-4,3,25:17.12
-3,3,25:17.12
4,3,25:18.5
8,3,25:18.5
-16,4,25:18.5
-12,4,25:18.5
-11,4,25:18.13
-2,4,25:18.13
3,4,25:18.13
4,4,25:18.5
8,4,25:18.5
-17,5,25:18.5
-16,5,25:18.5
-11,5,25:18.13
-10,5,25:18.13
-1,5,25:18.13
0,5,25:18.13
3,5,25:18.13
8,5,25:18.5
-17,6,25:18.5
-10,6,25:18.13
-9,6,25:18.13
0,6,25:18.13
1,6,25:18.13
2,6,25:18.13
8,6,25:18.5
-17,7,25:18.5
-9,7,25:18.13
-8,7,25:18.13
-7,7,25:18.13
0,7,25:18.13
1,7,25:18.13
2,7,25:18.5
8,7,25:18.5
9,7,25:18.5
-17,8,25:18.5
-7,8,25:18.13
-6,8,25:18.13
-5,8,25:18.13
-3,8,25:18.13
-2,8,25:18.13
-1,8,25:18.13
0,8,25:18.13
-5,9,25:18.5
-4,9,25:18.5
-3,9,25:18.5
-5,10,25:18.5
-4,10,25:18.5
-3,10,25:18.5
-6,11,25:18.5
-3,11,25:18.5
-2,11,25:18.5
-8,12,25:18.5
-7,12,25:18.5
-6,12,25:18.5
-2,12,25:18.5
-1,12,25:18.5
-11,13,25:18.5
-10,13,25:18.5
-9,13,25:18.5
-1,13,25:18.5
0,13,25:18.5
1,13,25:18.5
-12,14,25:18.5
1,14,25:18.5
2,14,25:18.5
3,15,25:18.5
-14,-14,26:18.5
-13,-14,26:18.5
-12,-13,26:18.5
-11,-13,26:18.5
2,-13,26:18.5
3,-13,26:18.5
4,-13,26:18.5
-10,-12,26:18.5
-9,-12,26:18.5
-8,-12,26:18.5
-1,-12,26:18.5
0,-12,26:18.5
1,-12,26:18.5
2,-12,26:18.5
-8,-11,26:18.5
-7,-11,26:18.5
-6,-11,26:18.5
-3,-11,26:18.5
-2,-11,26:18.5
-1,-11,26:18.5
-6,-10,26:18.5
-3,-10,26:18.5
-6,-9,26:18.5
-5,-9,26:18.5
-4,-9,26:18.5
-3,-9,26:18.5
-5,-8,26:18.5
-4,-8,26:18.5
-7,-7,26:18.13
-6,-7,26:18.13
-5,-7,26:18.13
-4,-7,26:18.13
-3,-7,26:18.13
-2,-7,26:18.13
9,-7,26:18.5
-17,-6,26:18.5
-9,-6,26:18.13
-8,-6,26:18.13
-7,-6,26:18.13
-2,-6,26:18.13
-1,-6,26:18.13
0,-6,26:18.13
9,-6,26:18.5
-17,-5,26:18.5
-10,-5,26:18.13
-9,-5,26:18.13
0,-5,26:18.13
1,-5,26:18.13
8,-5,26:18.5
9,-5,26:18.5
-17,-4,26:18.5
-11,-4,26:18.13
0,-4,26:18.13
1,-4,26:18.13
2,-4,26:18.13
8,-4,26:18.5
-16,-3,26:18.5
-11,-3,26:18.13
-1,-3,26:18.13
2,-3,26:18.13
3,-3,26:18.13
8,-3,26:18.5
-16,-2,26:18.5
-12,-2,26:18.5
-6,-2,26:17.12
-5,-2,26:17.12
-4,-2,26:17.12
-3,-2,26:17.12
-2,-2,26:18.13
3,-2,26:18.13
7,-2,26:18.5
8,-2,26:18.5
-16,-1,26:18.5
-15,-1,26:18.5
-13,-1,26:18.5
-12,-1,26:18.5
-7,-1,26:17.12
-6,-1,26:17.12
-3,-1,26:18.13
-2,-1,26:17.12
4,-1,26:18.5
6,-1,26:18.5
7,-1,26:18.5
-15,0,26:18.5
-14,0,26:18.5
-13,0,26:18.5
-12,0,26:18.5
-11,0,26:18.13
-10,0,26:18.13
-9,0,26:18.13
-8,0,26:18.13
-7,0,26:17.12
-2,0,26:17.12
4,0,26:18.5
5,0,26:18.5
6,0,26:18.5
-14,1,26:18.5
-13,1,26:18.5
-12,1,26:18.5
-7,1,26:17.12
-2,1,26:17.12
4,1,26:18.5
5,1,26:18.5
6,1,26:18.5
-15,2,26:18.5
-13,2,26:18.5
-12,2,26:18.5
-7,2,26:17.12
-3,2,26:17.12
-2,2,26:17.12
4,2,26:18.5
6,2,26:18.5
7,2,26:18.5
-16,3,26:18.5
-12,3,26:18.5
-11,3,26:18.13
-6,3,26:17.12
-5,3,26:17.12
-4,3,26:17.12
-3,3,26:17.12
3,3,26:18.13
4,3,26:18.5
7,3,26:18.5
-16,4,26:18.5
-11,4,26:18.13
-3,4,26:18.13
-2,4,26:18.13
3,4,26:18.13
7,4,26:18.5
8,4,26:18.5
-16,5,26:18.5
-11,5,26:18.13
-10,5,26:18.13
-1,5,26:18.13
0,5,26:18.13
2,5,26:18.13
3,5,26:18.13
8,5,26:18.5
-17,6,26:18.5
-16,6,26:18.5
-10,6,26:18.13
-9,6,26:18.13
0,6,26:18.13
1,6,26:18.13
2,6,26:18.13
8,6,26:18.5
-17,7,26:18.5
-8,7,26:18.13
-7,7,26:18.13
-1,7,26:18.13
0,7,26:18.13
1,7,26:18.13
8,7,26:18.5
-6,8,26:18.13
-5,8,26:18.13
-4,8,26:18.13
-3,8,26:18.13
-2,8,26:18.13
-1,8,26:18.13
-5,9,26:18.5
-4,9,26:18.5
-6,10,26:18.5
-5,10,26:18.5
-3,10,26:18.5
-6,11,26:18.5
-3,11,26:18.5
-2,11,26:18.5
-9,12,26:18.5
-8,12,26:18.5
-7,12,26:18.5
-2,12,26:18.5
-1,12,26:18.5
-11,13,26:18.5
-10,13,26:18.5
-9,13,26:18.5
0,13,26:18.5
1,13,26:18.5
1,14,26:18.5
2,14,26:18.5
-13,-13,27:18.5
-12,-13,27:18.5
-11,-13,27:18.5
3,-13,27:18.5
-11,-12,27:18.5
-10,-12,27:18.5
-9,-12,27:18.5
0,-12,27:18.5
1,-12,27:18.5
2,-12,27:18.5
-9,-11,27:18.5
-8,-11,27:18.5
-7,-11,27:18.5
-2,-11,27:18.5
-1,-11,27:18.5
0,-11,27:18.5
-7,-10,27:18.5
-6,-10,27:18.5
-3,-10,27:18.5
-2,-10,27:18.5
-6,-9,27:18.5
-5,-9,27:18.5
-4,-9,27:18.5
-3,-9,27:18.5
-5,-8,27:18.5
-4,-8,27:18.5
-6,-7,27:18.13
-5,-7,27:18.13
-4,-7,27:18.13
-3,-7,27:18.13
9,-7,27:18.5
-17,-6,27:18.5
-8,-6,27:18.13
-7,-6,27:18.13
-6,-6,27:18.13
-3,-6,27:18.13
-2,-6,27:18.13
-1,-6,27:18.13
9,-6,27:18.5
-17,-5,27:18.5
-10,-5,27:18.13
-9,-5,27:18.13
-8,-5,27:18.13
-1,-5,27:18.13
0,-5,27:18.13
1,-5,27:18.13
8,-5,27:18.5
-17,-4,27:18.5
-16,-4,27:18.5
-10,-4,27:18.13
0,-4,27:18.13
1,-4,27:18.13
8,-4,27:18.5
-16,-3,27:18.5
-11,-3,27:18.13
-1,-3,27:18.13
1,-3,27:18.13
2,-3,27:18.13
8,-3,27:18.5
-16,-2,27:18.5
-11,-2,27:18.13
-6,-2,27:17.12
-5,-2,27:17.12
-4,-2,27:17.12
-3,-2,27:17.12
-2,-2,27:18.13
2,-2,27:18.13
3,-2,27:18.13
7,-2,27:18.5
-16,-1,27:18.5
-15,-1,27:18.5
-12,-1,27:18.5
-7,-1,27:17.12
-6,-1,27:17.12
-3,-1,27:18.13
-2,-1,27:17.12
3,-1,27:18.13
6,-1,27:18.5
7,-1,27:18.5
-14,0,27:18.5
-13,0,27:18.5
-12,0,27:18.5
-10,0,27:18.13
-9,0,27:18.13
-8,0,27:18.13
-7,0,27:17.12
-2,0,27:17.12
4,0,27:18.5
5,0,27:18.5
6,0,27:18.5
-14,1,27:18.5
-13,1,27:18.5
-12,1,27:18.5
-11,1,27:18.13
-10,1,27:18.13
-7,1,27:17.12
-2,1,27:17.12
4,1,27:18.5
5,1,27:18.5
-15,2,27:18.5
-14,2,27:18.5
-12,2,27:18.5
-7,2,27:17.12
-3,2,27:17.12
-2,2,27:17.12
3,2,27:18.13
4,2,27:18.5
6,2,27:18.5
7,2,27:18.5
-16,3,27:18.5
-15,3,27:18.5
-11,3,27:18.13
-7,3,27:17.12
-6,3,27:17.12
-5,3,27:17.12
-4,3,27:17.12
-3,3,27:17.12
3,3,27:18.13
7,3,27:18.5
-16,4,27:18.5
-11,4,27:18.13
-10,4,27:18.13
-3,4,27:18.13
-2,4,27:18.13
2,4,27:18.13
3,4,27:18.13
7,4,27:18.5
-16,5,27:18.5
-10,5,27:18.13
-1,5,27:18.13
0,5,27:18.13
2,5,27:18.13
7,5,27:18.5
8,5,27:18.5
-16,6,27:18.5
-9,6,27:18.13
-8,6,27:18.13
0,6,27:18.13
1,6,27:18.13
8,6,27:18.5
-16,7,27:18.5
-8,7,27:18.13
-7,7,27:18.13
-6,7,27:18.13
-2,7,27:18.13
-1,7,27:18.13
0,7,27:18.13
1,7,27:18.13
8,7,27:18.5
-6,8,27:18.13
-5,8,27:18.13
-4,8,27:18.13
-3,8,27:18.13
-2,8,27:18.13
-5,9,27:18.5
-4,9,27:18.5
-3,9,27:18.5
-6,10,27:18.5
-5,10,27:18.5
-3,10,27:18.5
-7,11,27:18.5
-6,11,27:18.5
-2,11,27:18.5
-9,12,27:18.5
-8,12,27:18.5
-7,12,27:18.5
-2,12,27:18.5
-1,12,27:18.5
0,12,27:18.5
-10,13,27:18.5
0,13,27:18.5
1,13,27:18.5
2,14,27:18.5
-12,-12,28:18.5
-11,-12,28:18.5
-10,-12,28:18.5
1,-12,28:18.5
2,-12,28:18.5
-10,-11,28:18.5
-9,-11,28:18.5
-8,-11,28:18.5
-1,-11,28:18.5
0,-11,28:18.5
1,-11,28:18.5
-7,-10,28:18.5
-2,-10,28:18.5
-6,-9,28:18.5
-3,-9,28:18.5
-6,-8,28:18.5
-5,-8,28:18.5
-4,-8,28:18.5
-3,-8,28:18.5
-5,-7,28:18.13
-4,-7,28:18.13
-17,-6,28:18.5
-7,-6,28:18.13
-6,-6,28:18.13
-5,-6,28:18.13
-4,-6,28:18.13
-3,-6,28:18.13
-2,-6,28:18.13
8,-6,28:18.5
-17,-5,28:18.5
-9,-5,28:18.13
-8,-5,28:18.13
-7,-5,28:18.13
-2,-5,28:18.13
-1,-5,28:18.13
0,-5,28:18.13
8,-5,28:18.5
-16,-4,28:18.5
-10,-4,28:18.13
-9,-4,28:18.13
0,-4,28:18.13
1,-4,28:18.13
8,-4,28:18.5
-16,-3,28:18.5
-10,-3,28:18.13
-1,-3,28:18.13
1,-3,28:18.13
7,-3,28:18.5
-16,-2,28:18.5
-11,-2,28:18.13
-6,-2,28:17.12
-5,-2,28:17.12
-4,-2,28:17.12
-3,-2,28:17.12
-2,-2,28:18.13
2,-2,28:18.13
7,-2,28:18.5
-15,-1,28:18.5
-14,-1,28:18.5
-12,-1,28:18.5
-11,-1,28:18.13
-7,-1,28:17.12
-6,-1,28:17.12
-3,-1,28:18.13
-2,-1,28:17.12
2,-1,28:18.13
3,-1,28:18.5
6,-1,28:18.5
7,-1,28:18.5
-14,0,28:18.5
-13,0,28:18.5
-12,0,28:18.5
-8,0,28:18.13
-7,0,28:17.12
-6,0,28:18.13
-2,0,28:17.12
3,0,28:18.5
4,0,28:18.5
5,0,28:18.5
-13,1,28:18.5
-12,1,28:18.5
-11,1,28:18.13
-10,1,28:18.13
-9,1,28:18.13
-7,1,28:17.12
-2,1,28:17.12
3,1,28:18.5
4,1,28:18.5
5,1,28:18.5
-14,2,28:18.5
-13,2,28:18.5
-12,2,28:18.5
-11,2,28:18.13
-7,2,28:17.12
-3,2,28:17.12
-2,2,28:17.12
3,2,28:18.5
5,2,28:18.5
6,2,28:18.5
-15,3,28:18.5
-11,3,28:18.13
-7,3,28:17.12
-6,3,28:17.12
-5,3,28:17.12
-4,3,28:18.13
-3,3,28:17.12
2,3,28:18.13
3,3,28:18.5
6,3,28:18.5
7,3,28:18.5
-16,4,28:18.5
-10,4,28:18.13
-4,4,28:17.12
-3,4,28:18.13
-2,4,28:18.13
2,4,28:18.13
7,4,28:18.5
-16,5,28:18.5
-10,5,28:18.13
-9,5,28:18.13
-1,5,28:18.13
0,5,28:18.13
1,5,28:18.13
2,5,28:18.13
7,5,28:18.5
-16,6,28:18.5
-9,6,28:18.13
-8,6,28:18.13
-7,6,28:18.13
0,6,28:18.13
1,6,28:18.13
7,6,28:18.5
8,6,28:18.5
-16,7,28:18.5
-7,7,28:18.13
-6,7,28:18.13
-5,7,28:18.13
-3,7,28:18.13
-2,7,28:18.13
-1,7,28:18.13
0,7,28:18.13
-5,8,28:18.13
-4,8,28:18.13
-3,8,28:18.13
-6,9,28:18.5
-5,9,28:18.5
-4,9,28:18.5
-3,9,28:18.5
-6,10,28:18.5
-3,10,28:18.5
-2,10,28:18.5
-7,11,28:18.5
-2,11,28:18.5
-9,12,28:18.5
-8,12,28:18.5
-7,12,28:18.5
-1,12,28:18.5
0,12,28:18.5
-10,13,28:18.5
0,13,28:18.5
1,13,28:18.5
-11,-12,29:18.5
-10,-11,29:18.5
-9,-11,29:18.5
-8,-11,29:18.5
-1,-11,29:18.5
0,-11,29:18.5
1,-11,29:18.5
-8,-10,29:18.5
-7,-10,29:18.5
-2,-10,29:18.5
-1,-10,29:18.5
-7,-9,29:18.5
-6,-9,29:18.5
-3,-9,29:18.5
-2,-9,29:18.5
-6,-8,29:18.5
-3,-8,29:18.5
-5,-7,29:18.5
-4,-7,29:18.5
-6,-6,29:18.13
-5,-6,29:18.13
-4,-6,29:18.13
-3,-6,29:18.13
8,-6,29:18.5
-8,-5,29:18.13
-7,-5,29:18.13
-6,-5,29:18.13
-3,-5,29:18.13
-2,-5,29:18.13
-1,-5,29:18.13
8,-5,29:18.5
-16,-4,29:18.5
-9,-4,29:18.13
-8,-4,29:18.13
-1,-4,29:18.13
0,-4,29:18.13
7,-4,29:18.5
8,-4,29:18.5
-16,-3,29:18.5
-10,-3,29:18.13
-9,-3,29:18.13
-1,-3,29:18.13
0,-3,29:18.13
1,-3,29:18.13
7,-3,29:18.5
-16,-2,29:18.5
-15,-2,29:18.5
-10,-2,29:18.13
-5,-2,29:17.12
-4,-2,29:17.12
-2,-2,29:18.13
1,-2,29:18.13
2,-2,29:18.13
7,-2,29:18.5
-15,-1,29:18.5
-14,-1,29:18.5
-11,-1,29:18.13
-6,-1,29:17.12
-3,-1,29:18.13
-2,-1,29:17.12
2,-1,29:18.13
5,-1,29:18.5
6,-1,29:18.5
-14,0,29:18.5
-13,0,29:18.5
-12,0,29:18.5
-11,0,29:18.13
-7,0,29:17.12
-6,0,29:18.13
-2,0,29:17.12
2,0,29:18.13
3,0,29:18.5
4,0,29:18.5
5,0,29:18.5
-12,1,29:18.5
-11,1,29:18.13
-10,1,29:18.13
-9,1,29:18.13
-7,1,29:17.12
-2,1,29:17.12
3,1,29:18.5
4,1,29:18.5
-14,2,29:18.5
-13,2,29:18.5
-11,2,29:18.13
-7,2,29:17.12
-2,2,29:17.12
2,2,29:18.13
3,2,29:18.5
4,2,29:18.5
5,2,29:18.5
-15,3,29:18.5
-14,3,29:18.5
-11,3,29:18.13
-10,3,29:18.13
-6,3,29:17.12
-5,3,29:17.12
-4,3,29:18.13
-3,3,29:17.12
2,3,29:18.13
6,3,29:18.5
7,3,29:18.5
-15,4,29:18.5
-10,4,29:18.13
-9,4,29:18.13
-4,4,29:17.12
-2,4,29:18.13
1,4,29:18.13
2,4,29:18.13
7,4,29:18.5
-16,5,29:18.5
-9,5,29:18.13
-1,5,29:18.13
1,5,29:18.13
7,5,29:18.5
-16,6,29:18.5
-8,6,29:18.13
-7,6,29:18.13
-1,6,29:18.13
0,6,29:18.13
1,6,29:18.13
7,6,29:18.5
-6,7,29:18.13
-5,7,29:18.13
-4,7,29:18.13
-3,7,29:18.13
-2,7,29:18.13
-1,7,29:18.13
-5,8,29:18.13
-4,8,29:18.13
-6,9,29:18.5
-5,9,29:18.5
-3,9,29:18.5
-7,10,29:18.5
-6,10,29:18.5
-3,10,29:18.5
-2,10,29:18.5
-7,11,29:18.5
-2,11,29:18.5
-1,11,29:18.5
-10,12,29:18.5
-9,12,29:18.5
-8,12,29:18.5
-1,12,29:18.5
0,12,29:18.5
1,13,29:18.5
-11,-11,30:18.5
-10,-11,30:18.5
-9,-11,30:18.5
0,-11,30:18.5
1,-11,30:18.5
-9,-10,30:18.5
-8,-10,30:18.5
-7,-10,30:18.5
-2,-10,30:18.5
-1,-10,30:18.5
0,-10,30:18.5
-7,-9,30:18.5
-2,-9,30:18.5
-6,-8,30:18.5
-3,-8,30:18.5
-6,-7,30:18.5
-5,-7,30:18.5
-4,-7,30:18.5
-3,-7,30:18.5
-5,-6,30:18.13
-4,-6,30:18.13
-16,-5,30:18.5
-7,-5,30:18.13
-6,-5,30:18.13
-5,-5,30:18.13
-4,-5,30:18.13
-3,-5,30:18.13
8,-5,30:18.5
-16,-4,30:18.5
-9,-4,30:18.13
-8,-4,30:18.13
-7,-4,30:18.13
-2,-4,30:18.13
-1,-4,30:18.13
7,-4,30:18.5
-16,-3,30:18.5
-9,-3,30:18.13
-1,-3,30:18.13
0,-3,30:18.13
7,-3,30:18.5
-15,-2,30:18.5
-10,-2,30:18.13
-9,-2,30:18.13
-5,-2,30:17.12
-2,-2,30:18.13
0,-2,30:18.13
1,-2,30:18.13
6,-2,30:18.5
7,-2,30:18.5
-15,-1,30:18.5
-14,-1,30:18.5
-10,-1,30:18.13
-6,-1,30:17.12
-4,-1,30:17.12
-3,-1,30:17.12
-2,-1,30:18.13
1,-1,30:18.13
2,-1,30:18.13
5,-1,30:18.5
6,-1,30:18.5
-13,0,30:18.5
-12,0,30:18.5
-11,0,30:18.13
-7,0,30:17.12
-3,0,30:18.13
-2,0,30:17.12
2,0,30:18.13
3,0,30:18.5
4,0,30:18.5
5,0,30:18.5
-12,1,30:18.5
-11,1,30:18.13
-10,1,30:18.13
-9,1,30:18.13
-7,1,30:17.12
-6,1,30:18.13
-2,1,30:17.12
2,1,30:18.13
3,1,30:18.5
-13,2,30:18.5
-12,2,30:18.5
-11,2,30:18.13
-10,2,30:18.13
-7,2,30:17.12
-2,2,30:17.12
2,2,30:18.13
4,2,30:18.5
5,2,30:18.5
-14,3,30:18.5
-13,3,30:18.5
-10,3,30:18.13
-6,3,30:17.12
-5,3,30:17.12
-4,3,30:18.13
-3,3,30:17.12
1,3,30:18.13
2,3,30:18.13
5,3,30:18.5
6,3,30:18.5
-15,4,30:18.5
-10,4,30:18.13
-9,4,30:18.13
-4,4,30:17.12
-2,4,30:18.13
1,4,30:18.13
6,4,30:18.5
7,4,30:18.5
-15,5,30:18.5
-9,5,30:18.13
-8,5,30:18.13
-1,5,30:18.13
0,5,30:18.13
1,5,30:18.13
7,5,30:18.5
-16,6,30:18.5
-8,6,30:18.13
-7,6,30:18.13
-6,6,30:18.13
-2,6,30:18.13
-1,6,30:18.13
0,6,30:18.13
7,6,30:18.5
-6,7,30:18.13
-5,7,30:18.13
-4,7,30:18.13
-3,7,30:18.13
-2,7,30:18.13
-5,8,30:18.13
-4,8,30:18.13
-3,8,30:18.13
-6,9,30:18.5
-3,9,30:18.5
-7,10,30:18.5
-6,10,30:18.5
-2,10,30:18.5
-8,11,30:18.5
-7,11,30:18.5
-2,11,30:18.5
-1,11,30:18.5
-1,12,30:18.5
0,12,30:18.5
-10,-11,31:18.5
-10,-10,31:18.5
-9,-10,31:18.5
-8,-10,31:18.5
0,-10,31:18.5
1,-10,31:18.5
-8,-9,31:18.5
-7,-9,31:18.5
-2,-9,31:18.5
-7,-8,31:18.5
-6,-8,31:18.5
-3,-8,31:18.5
-2,-8,31:18.5
-6,-7,31:18.5
-3,-7,31:18.5
-5,-6,31:18.13
-4,-6,31:18.13
-6,-5,31:18.13
-5,-5,31:18.13
-4,-5,31:18.13
-16,-4,31:18.5
-8,-4,31:18.13
-7,-4,31:18.13
-6,-4,31:18.13
-3,-4,31:18.13
-2,-4,31:18.13
7,-4,31:18.5
-16,-3,31:18.5
-9,-3,31:18.13
-8,-3,31:18.13
-2,-3,31:18.13
-1,-3,31:18.13
0,-3,31:18.13
7,-3,31:18.5
-15,-2,31:18.5
-9,-2,31:18.13
-5,-2,31:17.12
-2,-2,31:18.13
0,-2,31:18.13
6,-2,31:18.5
-14,-1,31:18.5
-13,-1,31:18.5
-10,-1,31:18.13
-6,-1,31:17.12
-5,-1,31:17.12
-4,-1,31:17.12
-3,-1,31:17.12
-2,-1,31:18.13
0,-1,31:18.13
1,-1,31:18.13
4,-1,31:18.5
5,-1,31:18.5
-13,0,31:18.5
-12,0,31:18.5
-10,0,31:18.13
-7,0,31:17.12
-6,0,31:17.12
-3,0,31:18.13
-2,0,31:17.12
1,0,31:18.13
2,0,31:18.13
3,0,31:18.5
4,0,31:18.5
-12,1,31:18.5
-11,1,31:18.13
-9,1,31:18.13
-7,1,31:17.12
-6,1,31:18.13
-2,1,31:17.12
2,1,31:18.13
3,1,31:18.5
-13,2,31:18.5
-12,2,31:18.5
-11,2,31:18.13
-10,2,31:18.13
-7,2,31:17.12
-4,2,31:18.13
-2,2,31:17.12
1,2,31:18.13
2,2,31:18.13
3,2,31:18.5
4,2,31:18.5
-14,3,31:18.5
-13,3,31:18.5
-10,3,31:18.13
-9,3,31:18.13
-6,3,31:17.12
-5,3,31:17.12
-4,3,31:18.13
-3,3,31:17.12
1,3,31:18.13
4,3,31:18.5
5,3,31:18.5
-15,4,31:18.5
-14,4,31:18.5
-9,4,31:18.13
-4,4,31:17.12
-2,4,31:18.13
0,4,31:18.13
1,4,31:18.13
6,4,31:18.5
-15,5,31:18.5
-8,5,31:18.13
-7,5,31:18.13
0,5,31:18.13
7,5,31:18.5
-15,6,31:18.5
-7,6,31:18.13
-6,6,31:18.13
-5,6,31:18.13
-3,6,31:18.13
-2,6,31:18.13
-1,6,31:18.13
7,6,31:18.5
-5,7,31:18.13
-4,7,31:18.13
-6,8,31:18.13
-5,8,31:18.13
-4,8,31:18.13
-3,8,31:18.13
-6,9,31:18.5
-3,9,31:18.5
-2,9,31:18.5
-7,10,31:18.5
-2,10,31:18.5
-8,11,31:18.5
-7,11,31:18.5
-1,11,31:18.5
0,12,31:18.5
-9,-10,32:18.5
-8,-9,32:18.5
-2,-9,32:18.5
-1,-9,32:18.5
-7,-8,32:18.5
-2,-8,32:18.5
-7,-7,32:18.5
-6,-7,32:18.5
-3,-7,32:18.5
-6,-6,32:18.13
-5,-6,32:18.13
-4,-6,32:18.13
-3,-6,32:18.13
-5,-5,32:18.13
-4,-5,32:18.13
-6,-4,32:18.13
-5,-4,32:18.13
-4,-4,32:18.13
-3,-4,32:18.13
7,-4,32:18.5
-8,-3,32:18.13
-7,-3,32:18.13
-3,-3,32:18.13
-2,-3,32:18.13
-1,-3,32:18.13
6,-3,32:18.5
7,-3,32:18.5
-15,-2,32:18.5
-14,-2,32:18.5
-9,-2,32:18.13
-8,-2,32:18.13
-1,-2,32:18.13
0,-2,32:18.13
5,-2,32:18.5
6,-2,32:18.5
-14,-1,32:18.5
-13,-1,32:18.5
-9,-1,32:18.13
-6,-1,32:17.12
-5,-1,32:17.12
-4,-1,32:17.12
-3,-1,32:17.12
-2,-1,32:18.13
0,-1,32:18.13
4,-1,32:18.5
5,-1,32:18.5
-13,0,32:18.5
-12,0,32:18.5
-10,0,32:18.13
-7,0,32:17.12
-6,0,32:17.12
-4,0,32:18.13
-3,0,32:18.13
-2,0,32:17.12
1,0,32:18.13
3,0,32:18.5
4,0,32:18.5
-11,1,32:18.13
-10,1,32:18.13
-9,1,32:18.13
-7,1,32:17.12
-6,1,32:18.13
-2,1,32:17.12
1,1,32:18.13
2,1,32:18.13
-12,2,32:18.5
-11,2,32:18.13
-10,2,32:18.13
-7,2,32:17.12
-4,2,32:18.13
-2,2,32:17.12
1,2,32:18.13
2,2,32:18.13
3,2,32:18.5
-13,3,32:18.5
-12,3,32:18.5
-9,3,32:18.13
-6,3,32:17.12
-5,3,32:17.12
-4,3,32:18.13
-3,3,32:17.12
0,3,32:18.13
1,3,32:18.13
4,3,32:18.5
5,3,32:18.5
-14,4,32:18.5
-13,4,32:18.5
-9,4,32:18.13
-8,4,32:18.13
-4,4,32:17.12
-2,4,32:18.13
0,4,32:18.13
5,4,32:18.5
6,4,32:18.5
-15,5,32:18.5
-8,5,32:18.13
-7,5,32:18.13
-1,5,32:18.13
0,5,32:18.13
-15,6,32:18.5
-6,6,32:18.13
-5,6,32:18.13
-4,6,32:18.13
-3,6,32:18.13
-2,6,32:18.13
-5,7,32:18.13
-4,7,32:18.13
-6,8,32:18.13
-5,8,32:18.13
-3,8,32:18.13
-7,9,32:18.5
-6,9,32:18.5
-3,9,32:18.5
-2,9,32:18.5
-7,10,32:18.5
-2,10,32:18.5
-1,10,32:18.5
-8,11,32:18.5
-1,11,32:18.5
0,12,32:18.5
1,12,32:18.5
-9,-10,33:18.5
-9,-9,33:18.5
-8,-9,33:18.5
-1,-9,33:18.5
-8,-8,33:18.5
-7,-8,33:18.5
-2,-8,33:18.5
-1,-8,33:18.5
-7,-7,33:18.5
-3,-7,33:18.5
-2,-7,33:18.5
-6,-6,33:18.13
-3,-6,33:18.13
-6,-5,33:18.13
-5,-5,33:18.13
-4,-5,33:18.13
-5,-4,33:18.13
-4,-4,33:18.13
-7,-3,33:18.13
-6,-3,33:18.13
-5,-3,33:18.13
-4,-3,33:18.13
-3,-3,33:18.13
-2,-3,33:18.13
6,-3,33:18.5
-15,-2,33:18.5
-14,-2,33:18.5
-8,-2,33:18.13
-7,-2,33:18.13
-2,-2,33:18.13
-1,-2,33:18.13
5,-2,33:18.5
6,-2,33:18.5
-14,-1,33:18.5
-13,-1,33:18.5
-9,-1,33:18.13
-8,-1,33:18.13
-6,-1,33:17.12
-5,-1,33:17.12
-4,-1,33:17.12
-3,-1,33:17.12
-2,-1,33:18.13
-1,-1,33:18.13
0,-1,33:18.13
4,-1,33:18.5
5,-1,33:18.5
-12,0,33:18.5
-11,0,33:18.13
-9,0,33:18.13
-7,0,33:17.12
-6,0,33:17.12
-4,0,33:18.13
-3,0,33:18.13
-2,0,33:17.12
0,0,33:18.13
1,0,33:18.13
2,0,33:18.13
3,0,33:18.5
-11,1,33:18.13
-10,1,33:18.13
-6,1,33:18.13
-2,1,33:17.12
1,1,33:18.13
2,1,33:18.13
-11,2,33:18.13
-10,2,33:18.13
-9,2,33:18.13
-7,2,33:17.12
-4,2,33:18.13
-2,2,33:17.12
1,2,33:18.13
2,2,33:18.13
3,2,33:18.5
-13,3,33:18.5
-12,3,33:18.5
-9,3,33:18.13
-8,3,33:18.13
-6,3,33:17.12
-5,3,33:17.12
-4,3,33:18.13
-3,3,33:17.12
0,3,33:18.13
3,3,33:18.5
4,3,33:18.5
-14,4,33:18.5
-13,4,33:18.5
-8,4,33:18.13
-5,4,33:17.12
-4,4,33:17.12
-2,4,33:18.13
-1,4,33:18.13
0,4,33:18.13
4,4,33:18.5
5,4,33:18.5
-15,5,33:18.5
-14,5,33:18.5
-8,5,33:18.13
-7,5,33:18.13
-6,5,33:18.13
-2,5,33:18.13
-1,5,33:18.13
6,5,33:18.5
-15,6,33:18.5
-6,6,33:18.13
-5,6,33:18.13
-4,6,33:18.13
-3,6,33:18.13
-5,7,33:18.13
-4,7,33:18.13
-3,7,33:18.13
-6,8,33:18.13
-3,8,33:18.13
-7,9,33:18.5
-6,9,33:18.5
-2,9,33:18.5
-8,10,33:18.5
-7,10,33:18.5
-2,10,33:18.5
-1,10,33:18.5
-8,11,33:18.5
-1,11,33:18.5
0,11,33:18.5
0,12,33:18.5
1,12,33:18.5
-10,-9,34:18.5
-9,-9,34:18.5
-8,-9,34:18.5
-1,-9,34:18.5
-8,-8,34:18.5
-2,-8,34:18.5
-1,-8,34:18.5
-7,-7,34:18.5
-2,-7,34:18.5
-7,-6,34:18.13
-6,-6,34:18.13
-3,-6,34:18.13
-2,-6,34:18.13
-6,-5,34:18.13
-4,-5,34:18.13
-3,-5,34:18.13
-5,-4,34:18.13
-4,-4,34:18.13
6,-4,34:18.5
-6,-3,34:18.13
-5,-3,34:18.13
-4,-3,34:18.13
-3,-3,34:18.13
6,-3,34:18.5
-15,-2,34:18.5
-14,-2,34:18.5
-8,-2,34:18.13
-7,-2,34:18.13
-6,-2,34:18.13
-3,-2,34:18.13
-2,-2,34:18.13
5,-2,34:18.5
6,-2,34:18.5
-13,-1,34:18.5
-12,-1,34:18.5
-8,-1,34:18.13
-6,-1,34:17.12
-5,-1,34:17.12
-4,-1,34:17.12
-3,-1,34:17.12
-1,-1,34:18.13
3,-1,34:18.5
4,-1,34:18.5
-12,0,34:18.5
-11,0,34:18.13
-9,0,34:18.13
-8,0,34:18.13
-7,0,34:17.12
-6,0,34:17.12
-4,0,34:18.13
-3,0,34:18.13
-1,0,34:18.13
0,0,34:18.13
2,0,34:18.13
3,0,34:18.5
-10,1,34:18.13
-9,1,34:18.13
-7,1,34:17.12
-6,1,34:18.13
-4,1,34:18.13
-2,1,34:17.12
0,1,34:18.13
1,1,34:18.13
2,1,34:18.13
-11,2,34:18.13
-10,2,34:18.13
-9,2,34:18.13
-7,2,34:17.12
-4,2,34:18.13
-2,2,34:17.12
0,2,34:18.13
1,2,34:18.13
2,2,34:18.13
-12,3,34:18.5
-11,3,34:18.13
-9,3,34:18.13
-8,3,34:18.13
-6,3,34:17.12
-5,3,34:17.12
-4,3,34:18.13
-3,3,34:17.12
-1,3,34:18.13
0,3,34:18.13
2,3,34:18.13
3,3,34:18.5
-13,4,34:18.5
-12,4,34:18.5
-8,4,34:18.13
-7,4,34:18.13
-5,4,34:17.12
-4,4,34:17.12
-1,4,34:18.13
4,4,34:18.5
5,4,34:18.5
-14,5,34:18.5
-7,5,34:18.13
-6,5,34:18.13
-5,5,34:18.13
-4,5,34:18.13
-3,5,34:18.13
-2,5,34:18.13
-1,5,34:18.13
5,5,34:18.5
6,5,34:18.5
-15,6,34:18.5
-5,6,34:18.13
-4,6,34:18.13
-15,7,34:18.5
-6,7,34:18.13
-5,7,34:18.13
-4,7,34:18.13
-3,7,34:18.13
-6,8,34:18.13
-3,8,34:18.13
-2,8,34:18.13
-7,9,34:18.5
-2,9,34:18.5
-8,10,34:18.5
-7,10,34:18.5
-1,10,34:18.5
-1,11,34:18.5
0,11,34:18.5
0,12,34:18.5
1,12,34:18.5
-10,-9,35:18.5
-9,-9,35:18.5
-9,-8,35:18.5
-8,-8,35:18.5
-1,-8,35:18.5
-8,-7,35:18.5
-7,-7,35:18.5
-2,-7,35:18.5
-1,-7,35:18.5
-7,-6,35:18.13
-3,-6,35:18.13
-2,-6,35:18.13
-6,-5,35:18.13
-3,-5,35:18.13
-6,-4,35:18.13
-5,-4,35:18.13
-4,-4,35:18.13
-3,-4,35:18.13
6,-4,35:18.5
-5,-3,35:18.13
-4,-3,35:18.13
6,-3,35:18.5
-14,-2,35:18.5
-13,-2,35:18.5
-7,-2,35:18.13
-6,-2,35:18.13
-5,-2,35:18.13
-4,-2,35:18.13
-3,-2,35:18.13
-2,-2,35:18.13
4,-2,35:18.5
5,-2,35:18.5
-13,-1,35:18.5
-12,-1,35:18.5
-8,-1,35:18.13
-7,-1,35:18.13
-6,-1,35:17.12
-5,-1,35:17.12
-4,-1,35:17.12
-3,-1,35:17.12
-2,-1,35:18.13
-1,-1,35:18.13
3,-1,35:18.5
4,-1,35:18.5
-11,0,35:18.13
-10,0,35:18.13
-8,0,35:18.13
-7,0,35:17.12
-6,0,35:17.12
-3,0,35:17.12
-1,0,35:18.13
2,0,35:18.13
3,0,35:18.5
-10,1,35:18.13
-9,1,35:18.13
-7,1,35:17.12
-6,1,35:18.13
-5,1,35:18.13
-4,1,35:18.13
-2,1,35:17.12
-1,1,35:18.13
0,1,35:18.13
1,1,35:18.13
-10,2,35:18.13
-9,2,35:18.13
-8,2,35:18.13
-7,2,35:17.12
-4,2,35:18.13
-2,2,35:17.12
0,2,35:18.13
1,2,35:18.13
-11,3,35:18.13
-10,3,35:18.13
-8,3,35:18.13
-6,3,35:17.12
-4,3,35:18.13
-3,3,35:17.12
-1,3,35:18.13
2,3,35:18.13
3,3,35:18.5
-13,4,35:18.5
-12,4,35:18.5
-7,4,35:18.13
-5,4,35:17.12
-4,4,35:17.12
-2,4,35:18.13
-1,4,35:18.13
3,4,35:18.5
4,4,35:18.5
-14,5,35:18.5
-13,5,35:18.5
-6,5,35:18.13
-5,5,35:18.13
-4,5,35:18.13
-3,5,35:18.13
-2,5,35:18.13
4,5,35:18.5
5,5,35:18.5
-15,6,35:18.5
-14,6,35:18.5
-5,6,35:18.13
-4,6,35:18.13
6,6,35:18.5
-15,7,35:18.5
-6,7,35:18.13
-5,7,35:18.13
-3,7,35:18.13
6,7,35:18.5
-15,8,35:18.5
-7,8,35:18.13
-6,8,35:18.13
-3,8,35:18.13
-2,8,35:18.13
-7,9,35:18.5
-2,9,35:18.5
-1,9,35:18.5
-8,10,35:18.5
-5,10,35:18.5
-1,10,35:18.5
0,11,35:18.5
-10,12,35:18.5
1,12,35:18.5
-10,-9,36:18.5
-9,-8,36:18.5
-8,-7,36:18.5
-4,-7,36:18.5
-1,-7,36:18.5
-8,-6,36:18.5
-7,-6,36:18.5
-2,-6,36:18.5
-7,-5,36:18.13
-6,-5,36:18.13
-3,-5,36:18.13
-2,-5,36:18.13
-15,-4,36:18.5
-6,-4,36:18.13
-4,-4,36:18.13
-3,-4,36:18.13
6,-4,36:18.5
-15,-3,36:18.5
-5,-3,36:18.13
-4,-3,36:18.13
5,-3,36:18.5
6,-3,36:18.5
-14,-2,36:18.5
-13,-2,36:18.5
-6,-2,36:18.13
-5,-2,36:18.13
-4,-2,36:18.13
-3,-2,36:18.13
4,-2,36:18.5
5,-2,36:18.5
-13,-1,36:18.5
-12,-1,36:18.5
-7,-1,36:18.13
-6,-1,36:18.13
-5,-1,36:17.12
-4,-1,36:17.12
-3,-1,36:18.13
-2,-1,36:18.13
2,-1,36:18.13
3,-1,36:18.5
4,-1,36:18.5
-11,0,36:18.13
-10,0,36:18.13
-8,0,36:18.13
-7,0,36:18.13
-6,0,36:17.12
-4,0,36:17.12
-3,0,36:17.12
-2,0,36:18.13
-1,0,36:18.13
1,0,36:18.13
2,0,36:18.13
-10,1,36:18.13
-9,1,36:18.13
-7,1,36:17.12
-6,1,36:18.13
-5,1,36:18.13
-4,1,36:18.13
-3,1,36:17.12
-2,1,36:17.12
-1,1,36:18.13
0,1,36:18.13
1,1,36:18.13
-10,2,36:18.13
-9,2,36:18.13
-8,2,36:18.13
-7,2,36:17.12
-6,2,36:18.13
-4,2,36:18.13
-2,2,36:17.12
-1,2,36:18.13
0,2,36:18.13
1,2,36:18.13
-11,3,36:18.13
-10,3,36:18.13
-8,3,36:18.13
-7,3,36:18.13
-6,3,36:17.12
-4,3,36:18.13
-3,3,36:17.12
-1,3,36:18.13
1,3,36:18.13
2,3,36:18.13
-12,4,36:18.5
-11,4,36:18.13
-7,4,36:18.13
-6,4,36:18.13
-5,4,36:17.12
-4,4,36:17.12
-3,4,36:18.13
-2,4,36:18.13
2,4,36:18.13
3,4,36:18.5
-14,5,36:18.5
-13,5,36:18.5
-12,5,36:18.5
-5,5,36:18.13
-4,5,36:18.13
-3,5,36:18.13
4,5,36:18.5
5,5,36:18.5
-14,6,36:18.5
-5,6,36:18.13
-4,6,36:18.13
5,6,36:18.5
6,6,36:18.5
-15,7,36:18.5
-14,7,36:18.5
-8,7,36:18.13
-7,7,36:18.13
-6,7,36:18.13
-3,7,36:18.13
6,7,36:18.5
-7,8,36:18.13
-6,8,36:18.13
-2,8,36:18.13
-8,9,36:18.5
-7,9,36:18.5
-5,9,36:18.5
-4,9,36:18.5
-2,9,36:18.5
-1,9,36:18.5
-6,10,36:18.5
-5,10,36:18.5
-4,10,36:18.5
-3,10,36:18.5
-1,10,36:18.5
-9,11,36:18.5
-8,11,36:18.5
-6,11,36:18.5
-2,11,36:18.5
-1,11,36:18.5
0,11,36:18.5
-10,12,36:18.5
-9,12,36:18.5
1,12,36:18.5
2,12,36:18.5
-11,-9,37:18.5
-10,-9,37:18.5
0,-9,37:18.5
1,-9,37:18.5
-10,-8,37:18.5
-9,-8,37:18.5
-8,-8,37:18.5
-7,-8,37:18.5
-1,-8,37:18.5
0,-8,37:18.5
-9,-7,37:18.5
-8,-7,37:18.5
-7,-7,37:18.5
-6,-7,37:18.5
-5,-7,37:18.5
-4,-7,37:18.5
-3,-7,37:18.5
-8,-6,37:18.5
-5,-6,37:18.5
-4,-6,37:18.5
-2,-6,37:18.5
-1,-6,37:18.5
-7,-5,37:18.13
-2,-5,37:18.13
-15,-4,37:18.5
-7,-4,37:18.13
-6,-4,37:18.13
-3,-4,37:18.13
-2,-4,37:18.13
5,-4,37:18.5
6,-4,37:18.5
-15,-3,37:18.5
-14,-3,37:18.5
-8,-3,37:18.13
-6,-3,37:18.13
-5,-3,37:18.13
-4,-3,37:18.13
-3,-3,37:18.13
5,-3,37:18.5
-14,-2,37:18.5
-13,-2,37:18.5
-9,-2,37:18.13
-5,-2,37:18.13
-4,-2,37:18.13
4,-2,37:18.5
5,-2,37:18.5
-12,-1,37:18.5
-11,-1,37:18.13
-10,-1,37:18.13
-7,-1,37:18.13
-6,-1,37:18.13
-5,-1,37:17.12
-4,-1,37:18.13
-3,-1,37:18.13
2,-1,37:18.13
3,-1,37:18.5
-14,0,37:18.5
-11,0,37:18.13
-10,0,37:18.13
-7,0,37:18.13
-6,0,37:17.12
-4,0,37:17.12
-3,0,37:17.12
-2,0,37:18.13
1,0,37:18.13
2,0,37:18.13
-9,1,37:18.13
-7,1,37:17.12
-4,1,37:18.13
-3,1,37:17.12
-2,1,37:18.13
-1,1,37:18.13
0,1,37:18.13
-9,2,37:18.13
-8,2,37:18.13
-7,2,37:17.12
-6,2,37:18.13
-5,2,37:18.13
-4,2,37:18.13
-2,2,37:17.12
-1,2,37:18.13
0,2,37:18.13
-10,3,37:18.13
-9,3,37:18.13
-7,3,37:18.13
-6,3,37:17.12
-3,3,37:17.12
-2,3,37:18.13
0,3,37:18.13
1,3,37:18.13
-14,4,37:18.5
-11,4,37:18.13
-10,4,37:18.13
-7,4,37:18.13
-6,4,37:18.13
-5,4,37:17.12
-4,4,37:17.12
-3,4,37:18.13
-2,4,37:18.13
1,4,37:18.13
2,4,37:18.13
3,4,37:18.5
5,4,37:18.5
-14,5,37:18.5
-13,5,37:18.5
-12,5,37:18.5
-10,5,37:18.13
-9,5,37:18.13
-5,5,37:18.13
-4,5,37:18.13
1,5,37:18.13
3,5,37:18.5
4,5,37:18.5
5,5,37:18.5
-14,6,37:18.5
-13,6,37:18.5
-9,6,37:18.13
-8,6,37:18.13
-6,6,37:18.13
-5,6,37:18.13
-4,6,37:18.13
-3,6,37:18.13
-1,6,37:18.13
5,6,37:18.5
-14,7,37:18.5
-8,7,37:18.13
-7,7,37:18.13
-6,7,37:18.13
-3,7,37:18.13
-2,7,37:18.13
5,7,37:18.5
-7,8,37:18.13
-2,8,37:18.13
-8,9,37:18.5
-5,9,37:18.5
-4,9,37:18.5
-1,9,37:18.5
-6,10,37:18.5
-5,10,37:18.5
-4,10,37:18.5
-3,10,37:18.5
-1,10,37:18.5
0,10,37:18.5
-9,11,37:18.5
-8,11,37:18.5
-7,11,37:18.5
-2,11,37:18.5
-1,11,37:18.5
0,11,37:18.5
-10,12,37:18.5
-9,12,37:18.5
1,12,37:18.5
1,-9,38:18.5
-10,-8,38:18.5
-9,-8,38:18.5
-8,-8,38:18.5
-2,-8,38:18.5
-1,-8,38:18.5
0,-8,38:18.5
-9,-7,38:18.5
-8,-7,38:18.5
-7,-7,38:18.5
-6,-7,38:18.5
-5,-7,38:18.5
-4,-7,38:18.5
-3,-7,38:18.5
-2,-7,38:18.5
-8,-6,38:18.5
-5,-6,38:18.5
-4,-6,38:18.5
-1,-6,38:18.5
-8,-5,38:18.13
-7,-5,38:18.13
-5,-5,38:18.13
-4,-5,38:18.13
-2,-5,38:18.13
-7,-4,38:18.13
-6,-4,38:18.13
-3,-4,38:18.13
-2,-4,38:18.13
5,-4,38:18.5
-14,-3,38:18.5
-8,-3,38:18.13
-7,-3,38:18.13
-6,-3,38:18.13
-3,-3,38:18.13
-2,-3,38:18.13
-1,-3,38:18.13
5,-3,38:18.5
-14,-2,38:18.5
-12,-2,38:18.5
-9,-2,38:18.13
-8,-2,38:18.13
-6,-2,38:18.13
-5,-2,38:18.13
-4,-2,38:18.13
-1,-2,38:18.13
0,-2,38:18.13
3,-2,38:18.5
4,-2,38:18.5
5,-2,38:18.5
-14,-1,38:18.5
-12,-1,38:18.5
-11,-1,38:18.13
-10,-1,38:18.13
-6,-1,38:18.13
-5,-1,38:18.13
-4,-1,38:18.13
1,-1,38:18.13
2,-1,38:18.13
3,-1,38:18.5
5,-1,38:18.5
-14,0,38:18.5
-13,0,38:18.5
-10,0,38:18.13
-9,0,38:18.13
-7,0,38:18.13
-6,0,38:17.12
-5,0,38:17.12
-4,0,38:17.12
-3,0,38:18.13
-2,0,38:18.13
0,0,38:18.13
1,0,38:18.13
-13,1,38:18.5
-12,1,38:18.5
-9,1,38:18.13
-6,1,38:17.12
-4,1,38:18.13
-3,1,38:17.12
-2,1,38:18.13
-1,1,38:18.13
0,1,38:18.13
-13,2,38:18.5
-12,2,38:18.5
-8,2,38:18.13
-7,2,38:18.13
-5,2,38:18.13
-4,2,38:18.13
-2,2,38:18.13
-1,2,38:18.13
4,2,38:18.5
-13,3,38:18.5
-10,3,38:18.13
-9,3,38:18.13
-7,3,38:18.13
-6,3,38:17.12
-3,3,38:17.12
-2,3,38:18.13
0,3,38:18.13
1,3,38:18.13
4,3,38:18.5
-14,4,38:18.5
-13,4,38:18.5
-11,4,38:18.13
-10,4,38:18.13
-6,4,38:18.13
-5,4,38:18.13
-4,4,38:17.12
-3,4,38:18.13
1,4,38:18.13
2,4,38:18.13
5,4,38:18.5
-14,5,38:18.5
-12,5,38:18.5
-11,5,38:18.13
-10,5,38:18.13
-9,5,38:18.13
-5,5,38:18.13
-4,5,38:18.13
0,5,38:18.13
1,5,38:18.13
2,5,38:18.13
3,5,38:18.5
5,5,38:18.5
-14,6,38:18.5
-13,6,38:18.5
-12,6,38:18.5
-8,6,38:18.13
-6,6,38:18.13
-3,6,38:18.13
-1,6,38:18.13
5,6,38:18.5
-14,7,38:18.5
-7,7,38:18.13
-6,7,38:18.13
-3,7,38:18.13
-2,7,38:18.13
5,7,38:18.5
-8,8,38:18.13
-7,8,38:18.13
-6,8,38:18.13
-5,8,38:18.13
-2,8,38:18.13
-1,8,38:18.13
-8,9,38:18.5
-5,9,38:18.5
-4,9,38:18.5
-1,9,38:18.5
-6,10,38:18.5
-5,10,38:18.5
-4,10,38:18.5
-3,10,38:18.5
-2,10,38:18.5
0,10,38:18.5
-9,11,38:18.5
-8,11,38:18.5
-7,11,38:18.5
-2,11,38:18.5
-1,11,38:18.5
0,11,38:18.5
1,11,38:18.5
1,12,38:18.5
-10,-8,39:18.5
-9,-8,39:18.5
-1,-8,39:18.5
0,-8,39:18.5
-9,-7,39:18.5
-8,-7,39:18.5
-7,-7,39:18.5
-6,-7,39:18.5
-3,-7,39:18.5
-2,-7,39:18.5
-1,-7,39:18.5
-9,-6,39:18.5
-8,-6,39:18.5
-6,-6,39:18.5
-5,-6,39:18.5
-4,-6,39:18.5
-8,-5,39:18.13
-5,-5,39:18.13
-4,-5,39:18.13
-2,-5,39:18.13
-1,-5,39:18.13
-7,-4,39:18.13
-6,-4,39:18.13
-3,-4,39:18.13
-2,-4,39:18.13
5,-4,39:18.5
-14,-3,39:18.5
-8,-3,39:18.13
-7,-3,39:18.13
-6,-3,39:18.13
-3,-3,39:18.13
-2,-3,39:18.13
-1,-3,39:18.13
5,-3,39:18.5
-14,-2,39:18.5
-12,-2,39:18.5
-9,-2,39:18.13
-8,-2,39:18.13
-6,-2,39:18.13
-5,-2,39:18.13
-4,-2,39:18.13
-3,-2,39:18.13
-1,-2,39:18.13
0,-2,39:18.13
3,-2,39:18.5
4,-2,39:18.5
5,-2,39:18.5
-14,-1,39:18.5
-11,-1,39:18.13
-10,-1,39:18.13
-9,-1,39:18.13
-5,-1,39:18.13
-4,-1,39:18.13
0,-1,39:18.13
1,-1,39:18.13
2,-1,39:18.13
4,-1,39:18.5
5,-1,39:18.5
-13,0,39:18.5
-10,0,39:18.13
-9,0,39:18.13
-6,0,39:18.13
-5,0,39:17.12
-4,0,39:18.13
-3,0,39:17.12
0,0,39:18.13
1,0,39:18.13
4,0,39:18.5
-13,1,39:18.5
-12,1,39:18.5
-11,1,39:18.13
-9,1,39:18.13
-6,1,39:18.13
-3,1,39:18.13
-2,1,39:18.13
-1,1,39:18.13
0,1,39:18.13
4,1,39:18.5
-13,2,39:18.5
-12,2,39:18.5
-8,2,39:18.13
-7,2,39:18.13
-3,2,39:17.12
-2,2,39:18.13
-1,2,39:18.13
3,2,39:18.5
4,2,39:18.5
-13,3,39:18.5
-9,3,39:18.13
-8,3,39:18.13
-6,3,39:18.13
-3,3,39:17.12
-2,3,39:18.13
-1,3,39:18.13
0,3,39:18.13
4,3,39:18.5
-13,4,39:18.5
-10,4,39:18.13
-9,4,39:18.13
-6,4,39:17.12
-5,4,39:18.13
-4,4,39:18.13
-3,4,39:18.13
0,4,39:18.13
1,4,39:18.13
4,4,39:18.5
-14,5,39:18.5
-13,5,39:18.5
-11,5,39:18.13
-10,5,39:18.13
-9,5,39:18.13
-8,5,39:18.13
-6,5,39:18.13
-5,5,39:18.13
-4,5,39:18.13
-1,5,39:18.13
0,5,39:18.13
2,5,39:18.13
4,5,39:18.5
5,5,39:18.5
-14,6,39:18.5
-13,6,39:18.5
-12,6,39:18.5
-8,6,39:18.13
-7,6,39:18.13
-6,6,39:18.13
-3,6,39:18.13
-2,6,39:18.13
-1,6,39:18.13
5,6,39:18.5
-14,7,39:18.5
-7,7,39:18.13
-6,7,39:18.13
-3,7,39:18.13
-2,7,39:18.13
5,7,39:18.5
-7,8,39:18.13
-6,8,39:18.13
-5,8,39:18.13
-4,8,39:18.13
-3,8,39:18.13
-2,8,39:18.13
-1,8,39:18.13
-8,9,39:18.5
-5,9,39:18.5
-4,9,39:18.5
-1,9,39:18.5
-7,10,39:18.5
-6,10,39:18.5
-5,10,39:18.5
-4,10,39:18.5
-3,10,39:18.5
-2,10,39:18.5
0,10,39:18.5
-10,11,39:18.5
-9,11,39:18.5
-8,11,39:18.5
-7,11,39:18.5
-1,11,39:18.5
0,11,39:18.5
1,11,39:18.5
-10,-8,40:18.5
0,-8,40:18.5
-9,-7,40:18.5
-8,-7,40:18.5
-7,-7,40:18.5
-3,-7,40:18.5
-2,-7,40:18.5
-1,-7,40:18.5
0,-7,40:18.5
-9,-6,40:18.5
-6,-6,40:18.5
-5,-6,40:18.5
-4,-6,40:18.5
-3,-6,40:18.5
-9,-5,40:18.13
-8,-5,40:18.13
-5,-5,40:18.13
-4,-5,40:18.13
-1,-5,40:18.13
-8,-4,40:18.13
-7,-4,40:18.13
-6,-4,40:18.13
-5,-4,40:18.13
-4,-4,40:18.13
-3,-4,40:18.13
-2,-4,40:18.13
5,-4,40:18.5
-14,-3,40:18.5
-7,-3,40:18.13
-6,-3,40:18.13
-3,-3,40:18.13
-2,-3,40:18.13
5,-3,40:18.5
-14,-2,40:18.5
-8,-2,40:18.13
-7,-2,40:18.13
-6,-2,40:18.13
-3,-2,40:18.13
-2,-2,40:18.13
-1,-2,40:18.13
2,-2,40:18.13
3,-2,40:18.5
4,-2,40:18.5
5,-2,40:18.5
-14,-1,40:18.5
-13,-1,40:18.5
-11,-1,40:18.13
-10,-1,40:18.13
-9,-1,40:18.13
-8,-1,40:18.13
-6,-1,40:18.13
-5,-1,40:18.13
-4,-1,40:18.13
-1,-1,40:18.13
0,-1,40:18.13
1,-1,40:18.13
2,-1,40:18.13
4,-1,40:18.5
-13,0,40:18.5
-10,0,40:18.13
-9,0,40:18.13
-6,0,40:17.12
-5,0,40:18.13
-4,0,40:18.13
-3,0,40:17.12
0,0,40:18.13
1,0,40:18.13
4,0,40:18.5
-13,1,40:18.5
-11,1,40:18.13
-6,1,40:18.13
-4,1,40:18.13
-3,1,40:18.13
-2,1,40:18.13
-1,1,40:18.13
2,1,40:18.13
3,1,40:18.5
4,1,40:18.5
-12,2,40:18.5
-11,2,40:18.13
-7,2,40:18.13
-6,2,40:18.13
-3,2,40:18.13
-2,2,40:18.13
3,2,40:18.5
4,2,40:18.5
-13,3,40:18.5
-11,3,40:18.13
-10,3,40:18.13
-8,3,40:18.13
-7,3,40:18.13
-6,3,40:18.13
-5,3,40:18.13
-4,3,40:18.13
-3,3,40:18.13
-2,3,40:18.13
-1,3,40:18.13
1,3,40:18.13
2,3,40:18.13
4,3,40:18.5
-13,4,40:18.5
-10,4,40:18.13
-9,4,40:18.13
-6,4,40:17.12
-5,4,40:18.13
-4,4,40:18.13
0,4,40:18.13
1,4,40:18.13
4,4,40:18.5
-13,5,40:18.5
-11,5,40:18.13
-10,5,40:18.13
-9,5,40:18.13
-8,5,40:18.13
-6,5,40:18.13
-5,5,40:18.13
-4,5,40:18.13
-3,5,40:18.13
-1,5,40:18.13
0,5,40:18.13
1,5,40:18.13
2,5,40:18.13
4,5,40:18.5
-14,6,40:18.5
-13,6,40:18.5
-12,6,40:18.5
-11,6,40:18.13
-8,6,40:18.13
-7,6,40:18.13
-6,6,40:18.13
-3,6,40:18.13
-2,6,40:18.13
-1,6,40:18.13
4,6,40:18.5
5,6,40:18.5
-14,7,40:18.5
-7,7,40:18.13
-6,7,40:18.13
-3,7,40:18.13
-2,7,40:18.13
5,7,40:18.5
-8,8,40:18.13
-5,8,40:18.13
-4,8,40:18.13
-1,8,40:18.13
5,8,40:18.5
-5,9,40:18.5
-4,9,40:18.5
-7,10,40:18.5
-6,10,40:18.5
-3,10,40:18.5
-2,10,40:18.5
-10,11,40:18.5
-9,11,40:18.5
-8,11,40:18.5
-1,11,40:18.5
0,11,40:18.5
1,11,40:18.5
1,-8,41:18.5
-10,-7,41:18.5
-9,-7,41:18.5
-8,-7,41:18.5
-2,-7,41:18.5
-1,-7,41:18.5
0,-7,41:18.5
-7,-6,41:18.5
-6,-6,41:18.5
-4,-6,41:18.5
-3,-6,41:18.5
-2,-6,41:18.5
-5,-5,41:18.13
-4,-5,41:18.13
-14,-4,41:18.5
-8,-4,41:18.13
-5,-4,41:18.13
-4,-4,41:18.13
-2,-4,41:18.13
-14,-3,41:18.5
-8,-3,41:18.13
-7,-3,41:18.13
-6,-3,41:18.13
-3,-3,41:18.13
-2,-3,41:18.13
4,-3,41:18.5
5,-3,41:18.5
-14,-2,41:18.5
-13,-2,41:18.5
-8,-2,41:18.13
-7,-2,41:18.13
-6,-2,41:18.13
-3,-2,41:18.13
-2,-2,41:18.13
2,-2,41:18.13
3,-2,41:18.5
4,-2,41:18.5
-13,-1,41:18.5
-10,-1,41:18.13
-9,-1,41:18.13
-8,-1,41:18.13
-6,-1,41:18.13
-4,-1,41:18.13
-3,-1,41:18.13
-1,-1,41:18.13
0,-1,41:18.13
1,-1,41:18.13
2,-1,41:18.13
4,-1,41:18.5
-13,0,41:18.5
-10,0,41:18.13
-9,0,41:18.13
-8,0,41:18.13
-6,0,41:17.12
-5,0,41:18.13
-4,0,41:18.13
-3,0,41:17.12
-1,0,41:18.13
0,0,41:18.13
1,0,41:18.13
4,0,41:18.5
-13,1,41:18.5
-12,1,41:18.5
-11,1,41:18.13
-10,1,41:18.13
-6,1,41:17.12
-5,1,41:18.13
-4,1,41:18.13
-3,1,41:17.12
-2,1,41:18.13
-1,1,41:18.13
1,1,41:18.13
2,1,41:18.13
3,1,41:18.5
4,1,41:18.5
-12,2,41:18.5
-11,2,41:18.13
-7,2,41:17.12
-6,2,41:18.13
-3,2,41:18.13
-2,2,41:18.13
2,2,41:18.13
3,2,41:18.5
-13,3,41:18.5
-12,3,41:18.5
-11,3,41:18.13
-10,3,41:18.13
-8,3,41:18.13
-7,3,41:18.13
-6,3,41:17.12
-5,3,41:18.13
-4,3,41:18.13
-3,3,41:17.12
-2,3,41:18.13
-1,3,41:18.13
1,3,41:18.13
2,3,41:18.13
3,3,41:18.5
4,3,41:18.5
-13,4,41:18.5
-10,4,41:18.13
-9,4,41:18.13
-8,4,41:18.13
-6,4,41:17.12
-5,4,41:18.13
-4,4,41:18.13
-1,4,41:18.13
0,4,41:18.13
1,4,41:18.13
4,4,41:18.5
-13,5,41:18.5
-10,5,41:18.13
-9,5,41:18.13
-8,5,41:18.13
-6,5,41:18.13
-4,5,41:18.13
-3,5,41:18.13
-1,5,41:18.13
0,5,41:18.13
1,5,41:18.13
4,5,41:18.5
-13,6,41:18.5
-11,6,41:18.13
-7,6,41:18.13
-6,6,41:18.13
-3,6,41:18.13
-2,6,41:18.13
4,6,41:18.5
-13,7,41:18.5
-8,7,41:18.13
-7,7,41:18.13
-6,7,41:18.13
-5,7,41:18.13
-4,7,41:18.13
-3,7,41:18.13
-2,7,41:18.13
-1,7,41:18.13
4,7,41:18.5
5,7,41:18.5
-5,8,41:18.13
-4,8,41:18.13
-1,8,41:18.13
-6,9,41:18.5
-5,9,41:18.5
-4,9,41:18.5
-7,10,41:18.5
-6,10,41:18.5
-3,10,41:18.5
-2,10,41:18.5
-1,10,41:18.5
-10,11,41:18.5
-9,11,41:18.5
-8,11,41:18.5
-1,11,41:18.5
0,11,41:18.5
1,11,41:18.5
-10,-7,42:18.5
-9,-7,42:18.5
-1,-7,42:18.5
0,-7,42:18.5
1,-7,42:18.5
-8,-6,42:18.5
-7,-6,42:18.5
-6,-6,42:18.5
-3,-6,42:18.5
-2,-6,42:18.5
-1,-6,42:18.5
-6,-5,42:18.5
-5,-5,42:18.5
-4,-5,42:18.5
-9,-4,42:18.13
-8,-4,42:18.13
-5,-4,42:18.13
-4,-4,42:18.13
-14,-3,42:18.5
-8,-3,42:18.13
-7,-3,42:18.13
-6,-3,42:18.13
-5,-3,42:18.13
-4,-3,42:18.13
-3,-3,42:18.13
-2,-3,42:18.13
4,-3,42:18.5
-13,-2,42:18.5
-7,-2,42:18.13
-6,-2,42:18.13
-3,-2,42:18.13
-2,-2,42:18.13
1,-2,42:18.13
2,-2,42:18.5
4,-2,42:18.5
-13,-1,42:18.5
-10,-1,42:18.13
-9,-1,42:18.13
-8,-1,42:18.13
-7,-1,42:18.13
-6,-1,42:18.13
-3,-1,42:18.13
-2,-1,42:18.13
-1,-1,42:18.13
0,-1,42:18.13
1,-1,42:18.13
4,-1,42:18.5
-13,0,42:18.5
-9,0,42:18.13
-8,0,42:18.13
-6,0,42:18.13
-5,0,42:17.12
-4,0,42:18.13
-3,0,42:17.12
-1,0,42:18.13
0,0,42:18.13
4,0,42:18.5
-13,1,42:18.5
-12,1,42:18.5
-10,1,42:18.13
-9,1,42:18.13
-6,1,42:17.12
-5,1,42:18.13
-4,1,42:18.13
-3,1,42:17.12
-2,1,42:18.13
0,1,42:18.13
1,1,42:18.13
3,1,42:18.5
-12,2,42:18.5
-11,2,42:18.13
-10,2,42:18.13
-7,2,42:17.12
-6,2,42:18.13
-5,2,42:18.13
-4,2,42:18.13
-3,2,42:18.13
2,2,42:18.5
3,2,42:18.5
-12,3,42:18.5
-11,3,42:18.13
-10,3,42:18.13
-7,3,42:18.13
-6,3,42:17.12
-5,3,42:18.13
-4,3,42:18.13
-3,3,42:17.12
-2,3,42:18.13
1,3,42:18.13
2,3,42:18.5
3,3,42:18.5
-13,4,42:18.5
-9,4,42:18.13
-8,4,42:18.13
-7,4,42:18.13
-6,4,42:17.12
-5,4,42:17.12
-4,4,42:18.13
-3,4,42:18.13
-2,4,42:18.13
-1,4,42:18.13
0,4,42:18.13
4,4,42:18.5
-13,5,42:18.5
-10,5,42:18.13
-9,5,42:18.13
-8,5,42:18.13
-7,5,42:18.13
-6,5,42:18.13
-3,5,42:18.13
-2,5,42:18.13
-1,5,42:18.13
0,5,42:18.13
1,5,42:18.13
4,5,42:18.5
-13,6,42:18.5
-7,6,42:18.13
-6,6,42:18.13
-3,6,42:18.13
-2,6,42:18.13
4,6,42:18.5
-6,7,42:18.13
-5,7,42:18.13
-4,7,42:18.13
-3,7,42:18.13
-2,7,42:18.13
-1,7,42:18.13
4,7,42:18.5
-5,8,42:18.13
-4,8,42:18.13
-6,9,42:18.5
-5,9,42:18.5
-4,9,42:18.5
-3,9,42:18.5
-8,10,42:18.5
-7,10,42:18.5
-6,10,42:18.5
-3,10,42:18.5
-2,10,42:18.5
-1,10,42:18.5
-9,11,42:18.5
-8,11,42:18.5
0,11,42:18.5
0,-7,43:18.5
-9,-6,43:18.5
-8,-6,43:18.5
-7,-6,43:18.5
-3,-6,43:18.5
-2,-6,43:18.5
-1,-6,43:18.5
-6,-5,43:18.5
-4,-5,43:18.5
-3,-5,43:18.5
-5,-4,43:18.13
-4,-4,43:18.13
-8,-3,43:18.13
-5,-3,43:18.13
-4,-3,43:18.13
-13,-2,43:18.5
-8,-2,43:18.13
-7,-2,43:18.13
-6,-2,43:18.13
-4,-2,43:18.13
-3,-2,43:18.13
-2,-2,43:18.13
4,-2,43:18.5
-13,-1,43:18.5
-8,-1,43:18.13
-7,-1,43:18.13
-6,-1,43:18.13
-3,-1,43:18.13
-2,-1,43:18.13
0,-1,43:18.13
4,-1,43:18.5
-13,0,43:18.5
-9,0,43:18.13
-8,0,43:18.13
-6,0,43:18.13
-5,0,43:17.12
-4,0,43:17.12
-3,0,43:18.13
-2,0,43:18.13
-1,0,43:18.13
0,0,43:18.13
3,0,43:18.5
4,0,43:18.5
-12,1,43:18.5
-10,1,43:18.13
-9,1,43:18.13
-6,1,43:17.12
-5,1,43:18.13
-4,1,43:18.13
-3,1,43:17.12
-2,1,43:18.13
0,1,43:18.13
1,1,43:18.13
3,1,43:18.5
-11,2,43:18.13
-10,2,43:18.13
-7,2,43:17.12
-6,2,43:18.13
-5,2,43:18.13
-4,2,43:18.13
-3,2,43:17.12
1,2,43:18.13
2,2,43:18.5
-12,3,43:18.5
-11,3,43:18.13
-10,3,43:18.13
-9,3,43:18.13
-7,3,43:18.13
-6,3,43:18.13
-5,3,43:18.13
-4,3,43:18.13
-3,3,43:18.13
0,3,43:18.13
1,3,43:18.13
2,3,43:18.5
3,3,43:18.5
-12,4,43:18.5
-9,4,43:18.13
-8,4,43:18.13
-7,4,43:18.13
-6,4,43:18.13
-5,4,43:17.12
-4,4,43:17.12
-3,4,43:18.13
-2,4,43:18.13
-1,4,43:18.13
0,4,43:18.13
3,4,43:18.5
-13,5,43:18.5
-9,5,43:18.13
-8,5,43:18.13
-7,5,43:18.13
-6,5,43:18.13
-3,5,43:18.13
-2,5,43:18.13
-1,5,43:18.13
3,5,43:18.5
4,5,43:18.5
-13,6,43:18.5
-10,6,43:18.13
-9,6,43:18.13
-7,6,43:18.13
-6,6,43:18.13
-3,6,43:18.13
-2,6,43:18.13
4,6,43:18.5
-6,7,43:18.13
-5,7,43:18.13
-4,7,43:18.13
-1,7,43:18.13
4,7,43:18.5
-5,8,43:18.13
-4,8,43:18.13
-6,9,43:18.5
-4,9,43:18.5
-3,9,43:18.5
-8,10,43:18.5
-7,10,43:18.5
-6,10,43:18.5
-3,10,43:18.5
-2,10,43:18.5
-1,10,43:18.5
-9,-6,44:18.5
-8,-6,44:18.5
-2,-6,44:18.5
-1,-6,44:18.5
0,-6,44:18.5
-7,-5,44:18.5
-6,-5,44:18.5
-3,-5,44:18.5
-2,-5,44:18.5
-6,-4,44:18.13
-5,-4,44:18.13
-4,-4,44:18.13
-5,-3,44:18.13
-4,-3,44:18.13
-8,-2,44:18.13
-6,-2,44:18.13
-5,-2,44:18.13
-4,-2,44:18.13
-3,-2,44:18.13
4,-2,44:18.5
-13,-1,44:18.5
-7,-1,44:18.13
-6,-1,44:18.13
-3,-1,44:18.13
-2,-1,44:18.13
-1,-1,44:18.13
0,-1,44:18.13
3,-1,44:18.5
4,-1,44:18.5
-13,0,44:18.5
-12,0,44:18.5
-8,0,44:18.13
-7,0,44:18.13
-6,0,44:18.13
-5,0,44:17.12
-3,0,44:18.13
-2,0,44:18.13
-1,0,44:18.13
3,0,44:18.5
-12,1,44:18.5
-11,1,44:18.13
-9,1,44:18.13
-6,1,44:17.12
-5,1,44:18.13
-4,1,44:18.13
-3,1,44:18.13
-1,1,44:18.13
0,1,44:18.13
2,1,44:18.5
3,1,44:18.5
-11,2,44:18.13
-10,2,44:18.13
-9,2,44:18.13
-7,2,44:17.12
-6,2,44:17.12
-5,2,44:18.13
-4,2,44:18.13
-3,2,44:17.12
0,2,44:18.13
1,2,44:18.13
2,2,44:18.5
-11,3,44:18.13
-10,3,44:18.13
-9,3,44:18.13
-6,3,44:17.12
-5,3,44:18.13
-4,3,44:18.13
-3,3,44:17.12
0,3,44:18.13
1,3,44:18.13
2,3,44:18.5
-12,4,44:18.5
-9,4,44:18.13
-8,4,44:18.13
-6,4,44:18.13
-5,4,44:17.12
-4,4,44:17.12
-3,4,44:18.13
-2,4,44:18.13
-1,4,44:18.13
0,4,44:18.13
3,4,44:18.5
-12,5,44:18.5
-8,5,44:18.13
-7,5,44:18.13
-6,5,44:18.13
-3,5,44:18.13
-2,5,44:18.13
-1,5,44:18.13
3,5,44:18.5
-13,6,44:18.5
-9,6,44:18.13
-7,6,44:18.13
-6,6,44:18.13
-4,6,44:18.13
-3,6,44:18.13
-2,6,44:18.13
3,6,44:18.5
4,6,44:18.5
-5,7,44:18.13
-4,7,44:18.13
-1,7,44:18.13
-6,8,44:18.13
-5,8,44:18.13
-4,8,44:18.13
-6,9,44:18.5
-3,9,44:18.5
-8,10,44:18.5
-7,10,44:18.5
-3,10,44:18.5
-2,10,44:18.5
-1,10,44:18.5
-9,-6,45:18.5
-8,-6,45:18.5
-1,-6,45:18.5
-8,-5,45:18.5
-7,-5,45:18.5
-3,-5,45:18.5
-2,-5,45:18.5
-6,-4,45:18.13
-4,-4,45:18.13
-3,-4,45:18.13
-6,-3,45:18.13
-5,-3,45:18.13
-4,-3,45:18.13
-8,-2,45:18.13
-5,-2,45:18.13
-4,-2,45:18.13
-13,-1,45:18.5
-7,-1,45:18.13
-6,-1,45:18.13
-4,-1,45:18.13
-3,-1,45:18.13
-1,-1,45:18.13
3,-1,45:18.5
-12,0,45:18.5
-8,0,45:18.13
-7,0,45:18.13
-3,0,45:18.13
-2,0,45:18.13
3,0,45:18.5
-12,1,45:18.5
-11,1,45:18.13
-9,1,45:18.13
-6,1,45:17.12
-5,1,45:17.12
-4,1,45:17.12
-3,1,45:17.12
-1,1,45:18.13
0,1,45:18.13
2,1,45:18.5
3,1,45:18.5
-11,2,45:18.13
-10,2,45:18.13
-9,2,45:18.13
-7,2,45:17.12
-6,2,45:17.12
-3,2,45:17.12
0,2,45:18.13
1,2,45:18.13
2,2,45:18.5
-11,3,45:18.13
-10,3,45:18.13
-9,3,45:18.13
-6,3,45:17.12
-3,3,45:17.12
0,3,45:18.13
1,3,45:18.13
2,3,45:18.5
-12,4,45:18.5
-11,4,45:18.13
-8,4,45:18.13
-6,4,45:17.12
-5,4,45:17.12
-4,4,45:17.12
-3,4,45:17.12
-2,4,45:18.13
-1,4,45:18.13
2,4,45:18.5
3,4,45:18.5
-12,5,45:18.5
-7,5,45:18.13
-6,5,45:18.13
-3,5,45:18.13
-2,5,45:18.13
3,5,45:18.5
-12,6,45:18.5
-6,6,45:18.13
-5,6,45:18.13
-4,6,45:18.13
-3,6,45:18.13
3,6,45:18.5
-5,7,45:18.13
-4,7,45:18.13
-6,8,45:18.13
-5,8,45:18.13
-4,8,45:18.13
-3,8,45:18.13
-7,9,45:18.5
-6,9,45:18.5
-3,9,45:18.5
-8,10,45:18.5
-2,10,45:18.5
-1,10,45:18.5
-8,-5,46:18.5
-7,-5,46:18.5
-2,-5,46:18.5
-1,-5,46:18.5
-7,-4,46:18.13
-6,-4,46:18.13
-3,-4,46:18.13
-6,-3,46:18.13
-5,-3,46:18.13
-4,-3,46:18.13
-5,-2,46:18.13
-4,-2,46:18.13
-12,-1,46:18.5
-6,-1,46:18.13
-5,-1,46:18.13
-4,-1,46:18.13
-3,-1,46:18.13
3,-1,46:18.5
-12,0,46:18.5
-7,0,46:18.13
-6,0,46:18.13
-3,0,46:18.13
-2,0,46:18.13
3,0,46:18.5
-12,1,46:18.5
-11,1,46:18.13
-6,1,46:17.12
-5,1,46:17.12
-4,1,46:17.12
-3,1,46:17.12
-2,1,46:18.13
-1,1,46:18.13
2,1,46:18.5
3,1,46:18.5
-10,2,46:18.13
-9,2,46:18.13
-8,2,46:18.13
-7,2,46:17.12
-6,2,46:17.12
-3,2,46:17.12
-1,2,46:18.13
0,2,46:18.13
1,2,46:18.13
-10,3,46:18.13
-9,3,46:18.13
-8,3,46:18.13
-6,3,46:17.12
-3,3,46:17.12
-1,3,46:18.13
0,3,46:18.13
1,3,46:18.13
-11,4,46:18.13
-8,4,46:18.13
-7,4,46:18.13
-6,4,46:17.12
-5,4,46:17.12
-4,4,46:17.12
-3,4,46:17.12
-2,4,46:18.13
-1,4,46:18.13
2,4,46:18.5
-12,5,46:18.5
-7,5,46:18.13
-6,5,46:18.13
-3,5,46:18.13
-2,5,46:18.13
3,5,46:18.5
-12,6,46:18.5
-6,6,46:18.13
-5,6,46:18.13
-4,6,46:18.13
-3,6,46:18.13
3,6,46:18.5
-5,7,46:18.13
-4,7,46:18.13
-6,8,46:18.13
-5,8,46:18.13
-4,8,46:18.13
-3,8,46:18.13
-7,9,46:18.5
-6,9,46:18.5
-3,9,46:18.5
-2,9,46:18.5
-7,10,46:18.5
-2,10,46:18.5
-8,-5,47:18.5
-7,-5,47:18.5
-7,-4,47:18.13
-3,-4,47:18.13
-2,-4,47:18.13
-6,-3,47:18.13
-4,-3,47:18.13
-3,-3,47:18.13
-6,-2,47:18.13
-5,-2,47:18.13
-4,-2,47:18.13
-5,-1,47:18.13
-4,-1,47:18.13
3,-1,47:18.5
-12,0,47:18.5
-6,0,47:18.13
-4,0,47:18.13
-3,0,47:18.13
3,0,47:18.5
-11,1,47:18.13
-10,1,47:18.13
-6,1,47:17.12
-5,1,47:17.12
-4,1,47:17.12
-3,1,47:17.12
-2,1,47:18.13
1,1,47:18.13
2,1,47:18.5
-10,2,47:18.13
-9,2,47:18.13
-8,2,47:18.13
-6,2,47:17.12
-3,2,47:17.12
-1,2,47:18.13
0,2,47:18.13
1,2,47:18.13
-10,3,47:18.13
-9,3,47:18.13
-8,3,47:18.13
-6,3,47:17.12
-3,3,47:17.12
-1,3,47:18.13
0,3,47:18.13
1,3,47:18.13
-11,4,47:18.13
-10,4,47:18.13
-8,4,47:18.13
-7,4,47:18.13
-6,4,47:17.12
-5,4,47:17.12
-4,4,47:17.12
-3,4,47:17.12
-2,4,47:18.13
1,4,47:18.13
2,4,47:18.5
-12,5,47:18.5
-11,5,47:18.13
-7,5,47:18.13
-6,5,47:18.13
-4,5,47:18.13
-3,5,47:18.13
2,5,47:18.5
-12,6,47:18.5
-5,6,47:18.13
-4,6,47:18.13
-5,7,47:18.13
-4,7,47:18.13
-6,8,47:18.13
-3,8,47:18.13
-7,9,47:18.5
-3,9,47:18.5
-2,9,47:18.5
-2,10,47:18.5
-1,10,47:18.5
-8,-5,48:18.5
-8,-4,48:18.13
-7,-4,48:18.13
-3,-4,48:18.13
-2,-4,48:18.13
-7,-3,48:18.13
-6,-3,48:18.13
-3,-3,48:18.13
-6,-2,48:18.13
-5,-2,48:18.13
-4,-2,48:18.13
-5,-1,48:18.13
-4,-1,48:18.13
-12,0,48:18.5
-11,0,48:18.13
-6,0,48:18.13
-5,0,48:18.13
-4,0,48:18.13
-3,0,48:18.13
2,0,48:18.5
3,0,48:18.5
-11,1,48:18.13
-10,1,48:18.13
-6,1,48:18.13
-5,1,48:17.12
-4,1,48:17.12
-3,1,48:18.13
-2,1,48:18.13
1,1,48:18.13
2,1,48:18.5
-10,2,48:18.13
-9,2,48:18.13
-8,2,48:18.13
-7,2,48:18.13
-6,2,48:17.12
-3,2,48:17.12
-2,2,48:18.13
-1,2,48:18.13
0,2,48:18.13
1,2,48:18.13
-9,3,48:18.13
-8,3,48:18.13
-6,3,48:17.12
-3,3,48:17.12
-2,3,48:18.13
-1,3,48:18.13
0,3,48:18.13
-10,4,48:18.13
-9,4,48:18.13
-7,4,48:18.13
-6,4,48:17.12
-5,4,48:17.12
-4,4,48:17.12
-3,4,48:18.13
-2,4,48:18.13
0,4,48:18.13
1,4,48:18.13
-11,5,48:18.13
-6,5,48:18.13
-5,5,48:18.13
-4,5,48:18.13
-3,5,48:18.13
2,5,48:18.5
-13,6,48:18.5
-12,6,48:18.5
-5,6,48:18.13
-4,6,48:18.13
-11,7,48:18.5
-10,7,48:18.13
-9,7,48:18.13
-6,7,48:18.13
-5,7,48:18.13
-4,7,48:18.13
-7,8,48:18.13
-6,8,48:18.13
-3,8,48:18.13
-8,9,48:18.5
-7,9,48:18.5
-2,9,48:18.5
-8,10,48:18.5
-1,10,48:18.5
-8,11,48:18.5
-7,11,48:18.5
-7,12,48:18.5
-8,-4,49:18.5
-7,-4,49:18.5
-2,-4,49:18.5
-7,-3,49:18.13
-3,-3,49:18.13
-2,-3,49:18.13
-6,-2,49:18.13
-4,-2,49:18.13
-3,-2,49:18.13
0,-2,49:18.13
-6,-1,49:18.13
-5,-1,49:18.13
-4,-1,49:18.13
1,-1,49:18.13
2,-1,49:18.5
-11,0,49:18.13
-5,0,49:18.13
-4,0,49:18.13
2,0,49:18.5
4,0,49:18.5
-11,1,49:18.13
-10,1,49:18.13
-6,1,49:18.13
-5,1,49:17.12
-4,1,49:17.12
-3,1,49:18.13
1,1,49:18.13
-9,2,49:18.13
-8,2,49:18.13
-7,2,49:18.13
-6,2,49:17.12
-3,2,49:17.12
-2,2,49:18.13
-1,2,49:18.13
0,2,49:18.13
-9,3,49:18.13
-8,3,49:18.13
-7,3,49:18.13
-6,3,49:17.12
-3,3,49:17.12
-2,3,49:18.13
-1,3,49:18.13
-10,4,49:18.13
-9,4,49:18.13
-7,4,49:18.13
-6,4,49:17.12
-5,4,49:17.12
-4,4,49:17.12
-3,4,49:18.13
-2,4,49:18.13
0,4,49:18.13
1,4,49:18.13
-11,5,49:18.13
-10,5,49:18.13
-6,5,49:18.13
-5,5,49:18.13
-4,5,49:18.13
-3,5,49:18.13
1,5,49:18.13
2,5,49:18.5
-13,6,49:18.5
-12,6,49:18.5
-11,6,49:18.13
-5,6,49:18.13
-4,6,49:18.13
-10,7,49:18.13
-9,7,49:18.13
-6,7,49:18.13
-5,7,49:18.13
-4,7,49:18.13
-3,7,49:18.13
-9,8,49:18.13
-7,8,49:18.13
-6,8,49:18.13
-3,8,49:18.13
-2,8,49:18.13
-8,9,49:18.5
-7,9,49:18.5
-2,9,49:18.5
-8,10,49:18.5
-7,11,49:18.5
-7,12,49:18.5
-2,-6,50:18.5
-2,-5,50:18.5
-1,-4,50:18.5
-8,-3,50:18.13
-7,-3,50:18.13
-2,-3,50:18.13
-1,-3,50:18.13
-7,-2,50:18.13
-6,-2,50:18.13
-3,-2,50:18.13
-1,-2,50:18.13
0,-2,50:18.13
-6,-1,50:18.13
-4,-1,50:18.13
0,-1,50:18.13
1,-1,50:18.13
2,-1,50:18.5
-11,0,50:18.13
-5,0,50:18.13
-4,0,50:18.13
1,0,50:18.13
2,0,50:18.5
3,0,50:18.5
4,0,50:18.5
-10,1,50:18.13
-6,1,50:18.13
-5,1,50:17.12
-4,1,50:18.13
-3,1,50:18.13
0,1,50:18.13
1,1,50:18.13
-9,2,50:18.13
-8,2,50:18.13
-7,2,50:18.13
-6,2,50:17.12
-4,2,50:17.12
-3,2,50:18.13
-2,2,50:18.13
-1,2,50:18.13
0,2,50:18.13
-8,3,50:18.13
-7,3,50:18.13
-6,3,50:17.12
-3,3,50:17.12
-2,3,50:18.13
-1,3,50:18.13
-9,4,50:18.13
-8,4,50:18.13
-7,4,50:18.13
-6,4,50:17.12
-5,4,50:17.12
-4,4,50:17.12
-3,4,50:18.13
-1,4,50:18.13
0,4,50:18.13
-10,5,50:18.13
-9,5,50:18.13
-6,5,50:18.13
-5,5,50:18.13
-4,5,50:18.13
0,5,50:18.13
1,5,50:18.13
-13,6,50:18.5
-12,6,50:18.5
-11,6,50:18.13
-9,6,50:18.13
-5,6,50:18.13
-4,6,50:18.13
-11,7,50:18.5
-10,7,50:18.13
-9,7,50:18.13
-8,7,50:18.13
-6,7,50:18.13
-4,7,50:18.13
-3,7,50:18.13
-9,8,50:18.13
-7,8,50:18.13
-6,8,50:18.13
-5,8,50:18.13
-3,8,50:18.13
-2,8,50:18.13
-8,9,50:18.5
-2,9,50:18.5
-8,10,50:18.5
-7,11,50:18.5
-7,12,50:18.5
-3,-6,51:18.5
-2,-6,51:18.5
-2,-5,51:18.5
-2,-4,51:18.5
-1,-4,51:18.5
-7,-3,51:18.13
-1,-3,51:18.13
-7,-2,51:18.13
-3,-2,51:18.13
-2,-2,51:18.13
-1,-2,51:18.13
0,-2,51:18.13
-6,-1,51:18.13
-4,-1,51:18.13
-3,-1,51:18.13
-1,-1,51:18.13
0,-1,51:18.13
1,-1,51:18.13
2,-1,51:18.5
-6,0,51:18.13
-5,0,51:18.13
-4,0,51:18.13
1,0,51:18.13
2,0,51:18.5
3,0,51:18.5
4,0,51:18.5
-10,1,51:18.13
-9,1,51:18.13
-5,1,51:18.13
-4,1,51:18.13
0,1,51:18.13
1,1,51:18.13
-9,2,51:18.13
-8,2,51:18.13
-6,2,51:18.13
-5,2,51:17.12
-4,2,51:17.12
-3,2,51:18.13
-1,2,51:18.13
0,2,51:18.13
-9,3,51:18.13
-8,3,51:18.13
-7,3,51:18.13
-6,3,51:17.12
-3,3,51:17.12
-2,3,51:18.13
0,3,51:18.13
-9,4,51:18.13
-8,4,51:18.13
-6,4,51:18.13
-5,4,51:17.12
-4,4,51:17.12
-3,4,51:18.13
-1,4,51:18.13
0,4,51:18.13
-10,5,51:18.13
-9,5,51:18.13
-5,5,51:18.13
-4,5,51:18.13
0,5,51:18.13
1,5,51:18.13
-13,6,51:18.5
-12,6,51:18.5
-11,6,51:18.5
-10,6,51:18.13
-9,6,51:18.13
-6,6,51:18.13
-5,6,51:18.13
-4,6,51:18.13
-11,7,51:18.5
-10,7,51:18.13
-9,7,51:18.13
-8,7,51:18.13
-7,7,51:18.13
-6,7,51:18.13
-3,7,51:18.13
-9,8,51:18.13
-7,8,51:18.13
-6,8,51:18.13
-5,8,51:18.13
-4,8,51:18.13
-3,8,51:18.13
-2,8,51:18.13
-8,9,51:18.5
-2,9,51:18.5
-8,10,51:18.5
-7,11,51:18.5
-7,12,51:18.5
-3,-6,52:18.5
-2,-5,52:18.5
-2,-4,52:18.5
-1,-3,52:18.13
-8,-2,52:18.13
-7,-2,52:18.13
-6,-2,52:18.13
-5,-2,52:18.13
-4,-2,52:18.13
-3,-2,52:18.13
-1,-2,52:18.13
-7,-1,52:18.13
-6,-1,52:18.13
-4,-1,52:18.13
-3,-1,52:18.13
-1,-1,52:18.13
0,-1,52:18.13
1,-1,52:18.13
-6,0,52:18.13
-4,0,52:18.13
-1,0,52:18.13
1,0,52:18.13
2,0,52:18.5
3,0,52:18.5
-10,1,52:18.13
-9,1,52:18.13
-5,1,52:18.13
-4,1,52:18.13
-1,1,52:18.13
0,1,52:18.13
-9,2,52:18.13
-8,2,52:18.13
-6,2,52:17.12
-5,2,52:17.12
-4,2,52:18.13
-3,2,52:17.12
-2,2,52:18.13
-1,2,52:18.13
0,2,52:18.13
-9,3,52:18.13
-7,3,52:18.13
-6,3,52:18.13
-3,3,52:18.13
-2,3,52:18.13
0,3,52:18.13
-9,4,52:18.13
-8,4,52:18.13
-7,4,52:18.13
-6,4,52:17.12
-5,4,52:18.13
-4,4,52:18.13
-3,4,52:17.12
-2,4,52:18.13
-1,4,52:18.13
0,4,52:18.13
-9,5,52:18.13
-8,5,52:18.13
-5,5,52:18.13
-4,5,52:18.13
-1,5,52:18.13
0,5,52:18.13
-13,6,52:18.5
-12,6,52:18.5
-11,6,52:18.5
-10,6,52:18.13
-9,6,52:18.13
-6,6,52:18.13
-5,6,52:18.13
-4,6,52:18.13
-3,6,52:18.13
-11,7,52:18.5
-10,7,52:18.13
-9,7,52:18.13
-8,7,52:18.13
-7,7,52:18.13
-6,7,52:18.13
-5,7,52:18.13
-3,7,52:18.13
-9,8,52:18.13
-8,8,52:18.13
-7,8,52:18.13
-5,8,52:18.13
-4,8,52:18.13
-3,8,52:18.13
-2,8,52:18.13
-8,9,52:18.5
-8,10,52:18.5
-7,10,52:18.5
-7,11,52:18.5
-3,-6,53:18.5
-3,-5,53:18.5
-2,-5,53:18.5
-2,-4,53:18.5
-2,-3,53:18.13
-1,-3,53:18.13
-7,-2,53:18.13
-6,-2,53:18.13
-1,-2,53:18.13
-7,-1,53:18.13
-6,-1,53:18.13
-5,-1,53:18.13
-4,-1,53:18.13
-3,-1,53:18.13
-2,-1,53:18.13
-1,-1,53:18.13
0,-1,53:18.13
1,-1,53:18.13
-6,0,53:18.13
-4,0,53:18.13
-3,0,53:18.13
-1,0,53:18.13
1,0,53:18.13
2,0,53:18.5
3,0,53:18.5
-9,1,53:18.13
-6,1,53:18.13
-5,1,53:18.13
-4,1,53:18.13
-1,1,53:18.13
0,1,53:18.13
3,1,53:18.5
-9,2,53:18.13
-8,2,53:18.13
-7,2,53:18.13
-6,2,53:17.12
-5,2,53:18.13
-4,2,53:17.12
-2,2,53:18.13
-1,2,53:18.13
-9,3,53:18.13
-7,3,53:18.13
-6,3,53:18.13
-4,3,53:18.13
-3,3,53:18.13
-2,3,53:18.13
-1,3,53:18.13
-9,4,53:18.13
-8,4,53:18.13
-7,4,53:18.13
-6,4,53:17.12
-5,4,53:18.13
-4,4,53:18.13
-3,4,53:18.13
-2,4,53:18.13
-1,4,53:18.13
0,4,53:18.13
-9,5,53:18.13
-8,5,53:18.13
-5,5,53:18.13
-4,5,53:18.13
-2,5,53:18.13
-1,5,53:18.13
0,5,53:18.13
-12,6,53:18.5
-11,6,53:18.5
-9,6,53:18.13
-8,6,53:18.13
-6,6,53:18.13
-4,6,53:18.13
-3,6,53:18.13
4,6,53:18.5
-10,7,53:18.13
-9,7,53:18.13
-8,7,53:18.13
-7,7,53:18.13
-6,7,53:18.13
-5,7,53:18.13
-4,7,53:18.13
-3,7,53:18.13
-2,7,53:18.13
3,7,53:18.5
-8,8,53:18.13
-4,8,53:18.13
-3,8,53:18.13
-2,8,53:18.13
-1,8,53:18.13
0,8,53:18.13
-8,9,53:18.5
0,9,53:18.5
-8,10,53:18.5
-7,10,53:18.5
-1,10,53:18.5
-7,11,53:18.5
-1,11,53:18.5
-7,12,53:18.5
-2,12,53:18.5
-3,-5,54:18.5
-2,-4,54:18.5
-2,-3,54:18.13
-1,-2,54:18.13
-7,-1,54:18.13
-6,-1,54:18.13
-5,-1,54:18.13
-4,-1,54:18.13
-3,-1,54:18.13
-2,-1,54:18.13
-1,-1,54:18.13
0,-1,54:18.13
-13,0,54:18.5
-12,0,54:18.5
-7,0,54:18.13
-6,0,54:18.13
-3,0,54:18.13
-2,0,54:18.13
-1,0,54:18.13
0,0,54:18.13
1,0,54:18.13
2,0,54:18.5
-14,1,54:18.5
-9,1,54:18.13
-6,1,54:18.13
-4,1,54:18.13
-3,1,54:18.13
-1,1,54:18.13
0,1,54:18.13
2,1,54:18.5
3,1,54:18.5
-9,2,54:18.13
-8,2,54:18.13
-7,2,54:18.13
-6,2,54:17.12
-5,2,54:18.13
-4,2,54:17.12
-3,2,54:18.13
-2,2,54:18.13
-1,2,54:18.13
-9,3,54:18.13
-7,3,54:18.13
-6,3,54:18.13
-5,3,54:18.13
-4,3,54:18.13
-3,3,54:18.13
-1,3,54:18.13
-9,4,54:18.13
-7,4,54:18.13
-6,4,54:17.12
-5,4,54:18.13
-4,4,54:18.13
-3,4,54:18.13
-2,4,54:18.13
-1,4,54:18.13
-13,5,54:18.5
-9,5,54:18.13
-8,5,54:18.13
-7,5,54:18.13
-6,5,54:18.13
-5,5,54:18.13
-4,5,54:18.13
-2,5,54:18.13
-1,5,54:18.13
-12,6,54:18.5
-11,6,54:18.5
-9,6,54:18.13
-8,6,54:18.13
-6,6,54:18.13
-3,6,54:18.13
-1,6,54:18.13
3,6,54:18.5
4,6,54:18.5
-10,7,54:18.13
-9,7,54:18.13
-8,7,54:18.13
-7,7,54:18.13
-6,7,54:18.13
-5,7,54:18.13
-4,7,54:18.13
-3,7,54:18.13
0,7,54:18.13
1,7,54:18.13
2,7,54:18.5
3,7,54:18.5
-8,8,54:18.13
-3,8,54:18.13
-2,8,54:18.13
-1,8,54:18.13
0,8,54:18.13
1,8,54:18.13
-8,9,54:18.5
-1,9,54:18.5
0,9,54:18.5
-7,10,54:18.5
-1,10,54:18.5
-7,11,54:18.5
-1,11,54:18.5
-2,12,54:18.5
-8,-6,55:18.5
-8,-5,55:18.5
-3,-5,55:18.5
-8,-4,55:18.5
-3,-4,55:18.5
-2,-4,55:18.5
-9,-3,55:18.5
-2,-3,55:18.5
-9,-2,55:18.13
-2,-2,55:18.13
-1,-2,55:18.13
-11,-1,55:18.5
-10,-1,55:18.13
-9,-1,55:18.13
-8,-1,55:18.13
-7,-1,55:18.13
-6,-1,55:18.13
-5,-1,55:18.13
-4,-1,55:18.13
-1,-1,55:18.13
-13,0,55:18.5
-12,0,55:18.5
-11,0,55:18.5
-7,0,55:18.13
-4,0,55:18.13
-3,0,55:18.13
-2,0,55:18.13
-1,0,55:18.13
0,0,55:18.13
1,0,55:18.13
-14,1,55:18.5
-13,1,55:18.5
-9,1,55:18.13
-6,1,55:18.13
-4,1,55:18.13
-3,1,55:18.13
-2,1,55:18.13
-1,1,55:18.13
2,1,55:18.5
3,1,55:18.5
-9,2,55:18.13
-8,2,55:18.13
-7,2,55:18.13
-6,2,55:18.13
-5,2,55:17.0
-4,2,55:18.13
-3,2,55:18.13
-2,2,55:18.13
-1,2,55:18.13
-9,3,55:18.13
-6,3,55:18.13
-5,3,55:18.13
-4,3,55:18.13
-3,3,55:18.13
-1,3,55:18.13
-8,4,55:18.13
-6,4,55:18.13
-5,4,55:18.13
-4,4,55:18.13
-3,4,55:18.13
-1,4,55:18.13
-8,5,55:18.13
-7,5,55:18.13
-6,5,55:18.13
-5,5,55:17.0
-4,5,55:18.13
-3,5,55:18.13
-2,5,55:18.13
-1,5,55:18.13
-12,6,55:18.5
-11,6,55:18.5
-8,6,55:18.13
-6,6,55:18.13
-3,6,55:18.13
-1,6,55:18.13
3,6,55:18.5
4,6,55:18.5
-10,7,55:18.13
-9,7,55:18.13
-8,7,55:18.13
-7,7,55:18.13
-6,7,55:18.13
-5,7,55:18.13
-4,7,55:18.13
-3,7,55:18.13
-2,7,55:18.13
-1,7,55:18.13
1,7,55:18.13
2,7,55:18.5
3,7,55:18.5
-8,8,55:18.13
-2,8,55:18.13
-1,8,55:18.13
0,8,55:18.13
1,8,55:18.13
-8,9,55:18.5
-1,9,55:18.5
-7,10,55:18.5
-1,10,55:18.5
-7,11,55:18.5
-2,11,55:18.5
-1,11,55:18.5
-2,12,55:18.5
-8,-5,56:18.5
-8,-4,56:18.5
-3,-4,56:18.5
-9,-3,56:18.5
-8,-3,56:18.5
-2,-3,56:18.5
-9,-2,56:18.13
-2,-2,56:18.13
-11,-1,56:18.5
-10,-1,56:18.13
-9,-1,56:18.13
-8,-1,56:18.13
-7,-1,56:18.13
-6,-1,56:18.13
-2,-1,56:18.13
-1,-1,56:18.13
-12,0,56:18.5
-11,0,56:18.5
-9,0,56:18.13
-7,0,56:18.13
-6,0,56:18.13
-5,0,56:18.13
-4,0,56:18.13
-3,0,56:18.13
-2,0,56:18.13
-1,0,56:18.13
0,0,56:18.13
1,0,56:18.13
-13,1,56:18.5
-9,1,56:18.13
-6,1,56:18.13
-3,1,56:18.13
-2,1,56:18.13
-1,1,56:18.13
1,1,56:18.13
2,1,56:18.5
3,1,56:18.5
-9,2,56:18.13
-7,2,56:18.13
-6,2,56:18.13
-5,2,56:17.0
-4,2,56:18.13
-3,2,56:18.13
-2,2,56:18.13
-1,2,56:18.13
-8,3,56:18.13
-6,3,56:17.0
-5,3,56:18.13
-4,3,56:18.13
-1,3,56:18.13
-8,4,56:18.13
-6,4,56:17.0
-5,4,56:18.13
-4,4,56:18.13
-3,4,56:17.0
-1,4,56:18.13
-8,5,56:18.13
-7,5,56:18.13
-6,5,56:18.13
-5,5,56:17.0
-4,5,56:17.0
-3,5,56:18.13
-1,5,56:18.13
-12,6,56:18.5
-11,6,56:18.5
-10,6,56:18.13
-8,6,56:18.13
-3,6,56:18.13
-1,6,56:18.13
3,6,56:18.5
4,6,56:18.5
-10,7,56:18.13
-9,7,56:18.13
-8,7,56:18.13
-7,7,56:18.13
-6,7,56:18.13
-5,7,56:18.13
-4,7,56:18.13
-3,7,56:18.13
-2,7,56:18.13
-1,7,56:18.13
1,7,56:18.13
2,7,56:18.5
-8,8,56:18.13
-1,8,56:18.13
0,8,56:18.13
-8,9,56:18.5
-7,9,56:18.5
-1,9,56:18.5
-7,10,56:18.5
-1,10,56:18.5
-2,11,56:18.5
-2,12,56:18.5
-8,-5,57:18.5
-8,-4,57:18.5
-3,-4,57:18.5
-8,-3,57:18.5
-3,-3,57:18.5
-2,-3,57:18.5
-9,-2,57:18.5
-2,-2,57:18.5
-10,-1,57:18.5
-9,-1,57:18.5
-8,-1,57:18.5
-2,-1,57:18.5
-12,0,57:18.5
-11,0,57:18.5
-10,0,57:18.5
-9,0,57:18.5
-8,0,57:18.5
-7,0,57:18.5
-6,0,57:18.5
-5,0,57:18.5
-4,0,57:18.5
-3,0,57:18.5
-2,0,57:18.5
-1,0,57:18.5
0,0,57:18.5
-13,1,57:18.5
-12,1,57:18.5
-9,1,57:18.5
-2,1,57:18.5
1,1,57:18.5
2,1,57:18.5
-8,2,57:18.5
-5,2,57:17.0
-4,2,57:17.0
-2,2,57:18.5
-8,3,57:18.5
-6,3,57:17.0
-4,3,57:17.0
-2,3,57:18.5
-8,4,57:18.5
-6,4,57:17.0
-4,4,57:17.0
-3,4,57:17.0
-2,4,57:18.5
-1,4,57:18.5
-8,5,57:18.5
-6,5,57:17.0
-5,5,57:17.0
-4,5,57:17.0
-1,5,57:18.5
-11,6,57:18.5
-10,6,57:18.5
-8,6,57:18.5
-1,6,57:18.5
3,6,57:18.5
-10,7,57:18.5
-9,7,57:18.5
-8,7,57:18.5
-7,7,57:18.5
-6,7,57:18.5
-5,7,57:18.5
-4,7,57:18.5
-3,7,57:18.5
-2,7,57:18.5
-1,7,57:18.5
0,7,57:18.5
1,7,57:18.5
2,7,57:18.5
-8,8,57:18.5
-1,8,57:18.5
0,8,57:18.5
-8,9,57:18.5
-7,9,57:18.5
-1,9,57:18.5
-7,10,57:18.5
-2,10,57:18.5
-1,10,57:18.5
-2,11,57:18.5
-2,12,57:18.5
-7,-5,58:18.5
-8,-4,58:18.5
-8,-3,58:18.5
-3,-3,58:18.5
-9,-2,58:18.5
-8,-2,58:18.5
-2,-2,58:18.5
-9,-1,58:18.5
-2,-1,58:18.5
-11,0,58:18.5
-10,0,58:18.5
-9,0,58:18.5
-8,0,58:18.5
-7,0,58:18.5
-6,0,58:18.5
-5,0,58:18.5
-4,0,58:18.5
-2,0,58:18.5
-13,1,58:18.5
-12,1,58:18.5
-11,1,58:18.5
-4,1,58:18.5
-3,1,58:18.5
-2,1,58:18.5
-1,1,58:18.5
0,1,58:18.5
1,1,58:18.5
-8,2,58:18.5
-5,2,58:17.0
-2,2,58:18.5
-8,3,58:18.5
-6,3,58:17.0
-5,3,58:17.0
-4,3,58:17.0
-2,3,58:18.5
-8,4,58:18.5
-6,4,58:17.0
-4,4,58:17.0
-2,4,58:18.5
-8,5,58:18.5
-6,5,58:17.0
-5,5,58:17.0
-4,5,58:17.0
-2,5,58:18.5
-11,6,58:18.5
-10,6,58:18.5
-8,6,58:18.5
-7,6,58:18.5
-2,6,58:18.5
-1,6,58:18.5
2,6,58:18.5
3,6,58:18.5
-9,7,58:18.5
-8,7,58:18.5
-7,7,58:18.5
-6,7,58:18.5
-5,7,58:18.5
-4,7,58:18.5
-3,7,58:18.5
-2,7,58:18.5
-1,7,58:18.5
0,7,58:18.5
1,7,58:18.5
2,7,58:18.5
-8,8,58:18.5
-7,8,58:18.5
-1,8,58:18.5
-7,9,58:18.5
-1,9,58:18.5
-7,10,58:18.5
-2,10,58:18.5
-2,11,58:18.5
-7,-5,59:18.5
-8,-4,59:18.5
-7,-4,59:18.5
-8,-3,59:18.5
-3,-3,59:18.5
-8,-2,59:18.5
-3,-2,59:18.5
-2,-2,59:18.5
-9,-1,59:18.5
-8,-1,59:18.5
-2,-1,59:18.5
-10,0,59:18.5
-9,0,59:18.5
-8,0,59:18.5
-7,0,59:18.5
-6,0,59:18.5
-2,0,59:18.5
-12,1,59:18.5
-11,1,59:18.5
-6,1,59:18.5
-5,1,59:18.5
-4,1,59:18.5
-3,1,59:18.5
-2,1,59:18.5
-1,1,59:18.5
0,1,59:18.5
1,1,59:18.5
-8,2,59:18.5
-2,2,59:18.5
-8,3,59:18.5
-6,3,59:17.0
-5,3,59:17.0
-4,3,59:17.0
-2,3,59:18.5
-8,4,59:18.5
-6,4,59:17.0
-4,4,59:17.0
-2,4,59:18.5
-7,5,59:18.5
-6,5,59:17.0
-5,5,59:17.0
-4,5,59:17.0
-2,5,59:18.5
-9,6,59:18.5
-8,6,59:18.5
-7,6,59:18.5
-6,6,59:18.5
-2,6,59:18.5
2,6,59:18.5
-9,7,59:18.5
-7,7,59:18.5
-6,7,59:18.5
-5,7,59:18.5
-4,7,59:18.5
-3,7,59:18.5
-2,7,59:18.5
-1,7,59:18.5
0,7,59:18.5
1,7,59:18.5
2,7,59:18.5
-7,8,59:18.5
-2,8,59:18.5
-1,8,59:18.5
-7,9,59:18.5
-2,9,59:18.5
-1,9,59:18.5
-2,10,59:18.5
-2,11,59:18.5
-7,-4,60:18.5
-8,-3,60:18.5
-7,-3,60:18.5
-8,-2,60:18.5
-3,-2,60:18.5
-8,-1,60:18.5
-2,-1,60:18.5
-10,0,60:18.5
-9,0,60:18.5
-8,0,60:18.5
-2,0,60:18.5
-12,1,60:18.5
-11,1,60:18.5
-10,1,60:18.5
-9,1,60:18.5
-6,1,60:18.5
-5,1,60:18.5
-4,1,60:18.5
-3,1,60:18.5
-2,1,60:18.5
-1,1,60:18.5
0,1,60:18.5
-8,2,60:18.5
-3,2,60:18.5
-2,2,60:18.5
-8,3,60:18.5
-6,3,60:17.0
-5,3,60:17.0
-4,3,60:17.0
-2,3,60:18.5
-7,4,60:18.5
-6,4,60:17.0
-4,4,60:17.0
-2,4,60:18.5
-7,5,60:18.5
-6,5,60:17.0
-5,5,60:17.0
-4,5,60:17.0
-2,5,60:18.5
-9,6,60:18.5
-8,6,60:18.5
-7,6,60:18.5
-6,6,60:18.5
-5,6,60:18.5
-2,6,60:18.5
2,6,60:18.5
-7,7,60:18.5
-5,7,60:18.5
-4,7,60:18.5
-3,7,60:18.5
-2,7,60:18.5
-1,7,60:18.5
0,7,60:18.5
1,7,60:18.5
-7,8,60:18.5
-2,8,60:18.5
-7,9,60:18.5
-2,9,60:18.5
-2,10,60:18.5
-7,-3,61:18.5
-8,-2,61:18.5
-8,-1,61:18.5
-3,-1,61:18.5
-2,-1,61:18.5
-8,0,61:18.5
-3,0,61:18.5
-2,0,61:18.5
-11,1,61:18.5
-10,1,61:18.5
-9,1,61:18.5
-6,1,61:18.5
-5,1,61:18.5
-4,1,61:18.5
-3,1,61:18.5
-1,1,61:18.5
0,1,61:18.5
-8,2,61:18.5
-5,2,61:18.5
-4,2,61:18.5
-3,2,61:18.5
-2,2,61:18.5
-1,2,61:18.5
-7,3,61:18.5
-6,3,61:17.0
-5,3,61:17.0
-4,3,61:17.0
-3,3,61:18.5
-7,4,61:18.5
-6,4,61:17.0
-4,4,61:17.0
-3,4,61:18.5
-2,4,61:18.5
-7,5,61:18.5
-6,5,61:17.0
-5,5,61:17.0
-4,5,61:17.0
-2,5,61:18.5
-9,6,61:18.5
-8,6,61:18.5
-7,6,61:18.5
-6,6,61:18.5
-5,6,61:18.5
-4,6,61:18.5
-2,6,61:18.5
-7,7,61:18.5
-4,7,61:18.5
-3,7,61:18.5
-2,7,61:18.5
-1,7,61:18.5
0,7,61:18.5
1,7,61:18.5
-7,8,61:18.5
-2,8,61:18.5
-7,9,61:18.5
-2,9,61:18.5
-2,10,61:18.5
-8,-2,62:18.5
-7,-2,62:18.5
-8,-1,62:18.5
-3,-1,62:18.5
-8,0,62:18.5
-3,0,62:18.5
-10,1,62:18.5
-9,1,62:18.5
-6,1,62:18.5
-3,1,62:18.5
-11,2,62:18.5
-7,2,62:18.5
-6,2,62:18.5
-5,2,62:18.5
-4,2,62:18.5
-3,2,62:18.5
-2,2,62:18.5
-1,2,62:18.5
0,2,62:18.5
-7,3,62:18.5
-5,3,62:17.0
-4,3,62:17.0
-3,3,62:18.5
-7,4,62:18.5
-6,4,62:17.0
-4,4,62:17.0
-3,4,62:18.5
-7,5,62:18.5
-6,5,62:17.0
-5,5,62:17.0
-4,5,62:17.0
-3,5,62:18.5
-9,6,62:18.5
-8,6,62:18.5
-7,6,62:18.5
-6,6,62:18.5
-5,6,62:18.5
-4,6,62:18.5
-3,6,62:18.5
-2,6,62:18.5
-7,7,62:18.5
-3,7,62:18.5
-2,7,62:18.5
-1,7,62:18.5
0,7,62:18.5
1,7,62:18.5
-7,8,62:18.5
-2,8,62:18.5
-7,9,62:18.5
-2,9,62:18.5
-8,-1,63:18.5
-3,-1,63:18.5
-8,0,63:18.5
-7,0,63:18.5
-3,0,63:18.5
-10,1,63:18.5
-9,1,63:18.5
-3,1,63:18.5
-10,2,63:18.5
-9,2,63:18.5
-8,2,63:18.5
-7,2,63:18.5
-6,2,63:18.5
-5,2,63:18.5
-4,2,63:18.5
-3,2,63:18.5
-2,2,63:18.5
-1,2,63:18.5
-7,3,63:18.5
-5,3,63:17.0
-4,3,63:17.0
-3,3,63:18.5
-7,4,63:18.5
-6,4,63:17.0
-4,4,63:17.0
-3,4,63:18.5
-7,5,63:18.5
-6,5,63:17.0
-5,5,63:17.0
-4,5,63:17.0
-3,5,63:18.5
-9,6,63:18.5
-8,6,63:18.5
-7,6,63:18.5
-6,6,63:18.5
-5,6,63:18.5
-4,6,63:18.5
-3,6,63:18.5
-2,6,63:18.5
-7,7,63:18.5
-6,7,63:18.5
-3,7,63:18.5
-2,7,63:18.5
-1,7,63:18.5
0,7,63:18.5
-7,8,63:18.5
-3,8,63:18.5
-2,8,63:18.5
-7,9,63:18.5
-2,9,63:18.5
-7,-1,64:18.5
-3,-1,64:18.5
-7,0,64:18.5
-3,0,64:18.5
-3,1,64:18.5
-10,2,64:18.5
-9,2,64:18.5
-8,2,64:18.5
-7,2,64:18.5
-6,2,64:18.5
-5,2,64:18.5
-4,2,64:18.5
-3,2,64:18.5
-2,2,64:18.5
-1,2,64:18.5
-7,3,64:18.5
-5,3,64:17.0
-4,3,64:18.5
-3,3,64:18.5
-2,3,64:18.5
-7,4,64:18.5
-6,4,64:17.0
-4,4,64:17.0
-3,4,64:18.5
-7,5,64:18.5
-6,5,64:18.5
-5,5,64:17.0
-4,5,64:17.0
-3,5,64:18.5
-9,6,64:18.5
-8,6,64:18.5
-7,6,64:18.5
-6,6,64:18.5
-5,6,64:18.5
-4,6,64:18.5
-3,6,64:18.5
-2,6,64:18.5
-1,6,64:18.5
-6,7,64:18.5
-3,7,64:18.5
-1,7,64:18.5
0,7,64:18.5
-6,8,64:18.5
-3,8,64:18.5
-3,9,64:18.5
-7,0,65:18.5
-3,0,65:18.5
-3,1,65:18.5
-10,2,65:18.5
-9,2,65:18.5
-8,2,65:18.5
-7,2,65:18.5
-4,2,65:18.5
-3,2,65:18.5
-7,3,65:18.5
-6,3,65:18.5
-5,3,65:18.5
-4,3,65:18.5
-3,3,65:18.5
-2,3,65:18.5
-1,3,65:18.5
-6,4,65:18.5
-5,4,65:17.0
-4,4,65:17.0
-3,4,65:18.5
-6,5,65:18.5
-5,5,65:17.0
-4,5,65:17.0
-3,5,65:18.5
-8,6,65:18.5
-7,6,65:18.5
-6,6,65:18.5
-5,6,65:18.5
-4,6,65:18.5
-3,6,65:18.5
-2,6,65:18.5
-1,6,65:18.5
0,6,65:18.5
-6,7,65:18.5
-3,7,65:18.5
-6,8,65:18.5
-3,8,65:18.5
-6,9,65:18.5
-3,9,65:18.5
-7,0,66:18.5
-4,1,66:18.5
-7,2,66:18.5
-6,2,66:18.5
-4,2,66:18.5
-9,3,66:18.5
-8,3,66:18.5
-7,3,66:18.5
-6,3,66:18.5
-5,3,66:18.5
-4,3,66:18.5
-3,3,66:18.5
-2,3,66:18.5
-1,3,66:18.5
-6,4,66:18.5
-5,4,66:17.0
-4,4,66:17.0
-6,5,66:18.5
-5,5,66:17.0
-4,5,66:17.0
-8,6,66:18.5
-7,6,66:18.5
-6,6,66:18.5
-5,6,66:18.5
-4,6,66:18.5
-3,6,66:18.5
-2,6,66:18.5
-1,6,66:18.5
-6,7,66:18.5
-3,7,66:18.5
-6,8,66:18.5
-3,8,66:18.5
-6,9,66:18.5
-4,0,67:18.5
-6,1,67:18.5
-4,1,67:18.5
-6,2,67:18.5
-4,2,67:18.5
-9,3,67:18.5
-8,3,67:18.5
-7,3,67:18.5
-6,3,67:18.5
-5,3,67:18.5
-4,3,67:18.5
-3,3,67:18.5
-2,3,67:18.5
-6,4,67:18.5
-5,4,67:17.0
-4,4,67:18.5
-3,4,67:18.5
-6,5,67:18.5
-5,5,67:17.0
-4,5,67:17.0
-8,6,67:18.5
-7,6,67:18.5
-6,6,67:18.5
-5,6,67:18.5
-4,6,67:18.5
-3,6,67:18.5
-2,6,67:18.5
-1,6,67:18.5
-6,7,67:18.5
-4,7,67:18.5
-6,8,67:18.5
-4,8,67:18.5
-3,8,67:18.5
-6,9,67:18.5
-6,1,68:18.5
-4,1,68:18.5
-6,2,68:18.5
-4,2,68:18.5
-2,2,68:18.5
-9,3,68:18.5
-8,3,68:18.5
-7,3,68:18.5
-6,3,68:18.5
-4,3,68:18.5
-2,3,68:18.5
-8,4,68:18.5
-7,4,68:18.5
-6,4,68:18.5
-5,4,68:17.0
-4,4,68:18.5
-3,4,68:18.5
-2,4,68:18.5
-7,5,68:18.5
-6,5,68:18.5
-5,5,68:18.5
-4,5,68:18.5
-9,6,68:18.5
-8,6,68:18.5
-7,6,68:18.5
-6,6,68:18.5
-5,6,68:18.5
-4,6,68:18.5
-3,6,68:18.5
-2,6,68:18.5
-1,6,68:18.5
-8,7,68:18.5
-7,7,68:18.5
-6,7,68:18.5
-4,7,68:18.5
-7,8,68:18.5
-6,8,68:18.5
-4,8,68:18.5
-6,9,68:18.5
-4,0,69:18.5
-4,1,69:18.5
-3,1,69:18.5
-6,2,69:18.5
-5,2,69:18.5
-4,2,69:18.5
-3,2,69:18.5
-6,3,69:18.5
-4,3,69:18.5
-3,3,69:18.5
-2,3,69:18.5
-1,3,69:18.5
-8,4,69:18.5
-7,4,69:18.5
-6,4,69:18.5
-5,4,69:17.0
-4,4,69:18.5
-3,4,69:18.5
-2,4,69:18.5
-7,5,69:18.5
-6,5,69:18.5
-5,5,69:18.5
-4,5,69:18.5
-3,5,69:18.5
-9,6,69:18.5
-8,6,69:18.5
-7,6,69:18.5
-5,6,69:18.5
-4,6,69:18.5
-3,6,69:18.5
-2,6,69:18.5
-8,7,69:18.5
-7,7,69:18.5
-6,7,69:18.5
-5,7,69:18.5
-4,7,69:18.5
-2,7,69:18.5
-7,8,69:18.5
-6,8,69:18.5
-4,8,69:18.5
-3,8,69:18.5
-6,9,69:18.5
-3,9,69:18.5
-7,0,70:18.5
-4,0,70:18.5
-4,1,70:18.5
-3,1,70:18.5
-7,2,70:18.5
-6,2,70:18.5
-5,2,70:18.5
-4,2,70:18.5
-3,2,70:18.5
-9,3,70:18.5
-8,3,70:18.5
-6,3,70:18.5
-5,3,70:18.5
-4,3,70:18.5
-3,3,70:18.5
-2,3,70:18.5
-1,3,70:18.5
-8,4,70:18.5
-7,4,70:18.5
-6,4,70:18.5
-5,4,70:18.5
-4,4,70:18.5
-3,4,70:18.5
-1,4,70:18.5
-7,5,70:18.5
-6,5,70:18.5
-5,5,70:18.5
-4,5,70:18.5
-3,5,70:18.5
-9,6,70:18.5
-8,6,70:18.5
-7,6,70:18.5
-5,6,70:18.5
-4,6,70:18.5
-3,6,70:18.5
-2,6,70:18.5
-1,6,70:18.5
0,6,70:18.5
-8,7,70:18.5
-7,7,70:18.5
-6,7,70:18.5
-5,7,70:18.5
-4,7,70:18.5
-3,7,70:18.5
-2,7,70:18.5
-1,7,70:18.5
-7,8,70:18.5
-6,8,70:18.5
-5,8,70:18.5
-3,8,70:18.5
-6,9,70:18.5
-3,9,70:18.5
-4,1,71:18.5
-7,2,71:18.5
-5,2,71:18.5
-4,2,71:18.5
-3,2,71:18.5
-9,3,71:18.5
-8,3,71:18.5
-7,3,71:18.5
-6,3,71:18.5
-5,3,71:18.5
-4,3,71:18.5
-3,3,71:18.5
-2,3,71:18.5
-9,4,71:18.5
-7,4,71:18.5
-5,4,71:18.5
-3,4,71:18.5
-2,4,71:18.5
-1,4,71:18.5
-7,5,71:18.5
-6,5,71:18.5
-5,5,71:18.5
-4,5,71:18.5
-3,5,71:18.5
-2,5,71:18.5
-8,6,71:18.5
-7,6,71:18.5
-5,6,71:18.5
-3,6,71:18.5
-1,6,71:18.5
-8,7,71:18.5
-7,7,71:18.5
-6,7,71:18.5
-5,7,71:18.5
-4,7,71:18.5
-3,7,71:18.5
-2,7,71:18.5
-1,7,71:18.5
-7,8,71:18.5
-6,8,71:18.5
-3,8,71:18.5
-6,9,71:18.5
-4,9,71:18.5
-3,9,71:18.5
-6,1,72:18.5
-4,1,72:18.5
-7,2,72:18.5
-4,2,72:18.5
-8,3,72:18.5
-7,3,72:18.5
-6,3,72:18.5
-5,3,72:18.5
-4,3,72:18.5
-3,3,72:18.5
-9,4,72:18.5
-8,4,72:18.5
-7,4,72:18.5
-5,4,72:17.0
-3,4,72:18.5
-2,4,72:18.5
-7,5,72:18.5
-6,5,72:17.0
-5,5,72:17.0
-4,5,72:17.0
-3,5,72:18.5
-8,6,72:18.5
-7,6,72:18.5
-5,6,72:17.0
-3,6,72:18.5
-1,6,72:18.5
-8,7,72:18.5
-7,7,72:18.5
-6,7,72:18.5
-5,7,72:18.5
-4,7,72:18.5
-3,7,72:18.5
-2,7,72:18.5
-6,8,72:18.5
-3,8,72:18.5
-6,9,72:18.5
-4,9,72:18.5
-7,2,73:18.5
-6,2,73:18.5
-4,2,73:18.5
-7,3,73:18.5
-6,3,73:18.5
-5,3,73:18.5
-4,3,73:18.5
-3,3,73:18.5
-9,4,73:18.5
-8,4,73:18.5
-7,4,73:18.5
-3,4,73:18.5
-2,4,73:18.5
-7,5,73:18.5
-6,5,73:17.0
-5,5,73:17.0
-4,5,73:17.0
-3,5,73:18.5
-8,6,73:18.5
-7,6,73:18.5
-5,6,73:17.0
-3,6,73:18.5
-7,7,73:18.5
-6,7,73:18.5
-5,7,73:18.5
-4,7,73:18.5
-3,7,73:18.5
-2,7,73:18.5
-6,8,73:18.5
-4,8,73:18.5
-3,8,73:18.5
-6,2,74:18.5
-4,2,74:18.5
-7,3,74:18.5
-6,3,74:18.5
-5,3,74:18.5
-4,3,74:18.5
-8,4,74:18.5
-7,4,74:18.5
-6,4,74:18.5
-5,4,74:18.5
-4,4,74:18.5
-3,4,74:18.5
-2,4,74:18.5
-7,5,74:18.5
-5,5,74:17.0
-3,5,74:18.5
-8,6,74:18.5
-7,6,74:18.5
-5,6,74:17.0
-3,6,74:18.5
-2,6,74:18.5
