[META]
version=2.0
spawnOnBlockType=2
spawnSunlight=True
spawnDarkness=True
spawnWater=False
spawnLava=False
underFill=False
randomRotation=True
dig=True
tree=False
branch=False
needsFoundation=True
rarity=100
collisionPercentage=20
spawnElevationMin=0
spawnElevationMax=200
spawnInBiome=Custom
[DATA]
-4,1,-8:17.12
-3,1,-8:17.12
-2,2,-8:17.12
-3,-1,-7:17.12
-5,0,-7:17.12
-3,0,-7:17.12
-2,0,-7:17.12
-4,1,-7:17.12
-3,1,-7:17.12
-2,1,-7:17.12
-1,1,-7:17.12
-3,2,-7:17.12
-6,-1,-6:17.12
-5,-1,-6:17.12
-4,-1,-6:17.12
-3,-1,-6:17.12
-2,-1,-6:17.12
-6,0,-6:17.12
-5,0,-6:17.12
-2,0,-6:17.12
-1,0,-6:17.12
-6,1,-6:17.12
-5,1,-6:17.12
-4,1,-6:17.12
-3,1,-6:17.12
-2,1,-6:17.12
-6,2,-6:17.12
-4,2,-6:17.12
-3,2,-6:17.12
-4,3,-6:17.12
-2,3,-6:17.12
-7,-2,-5:17.12
-7,-1,-5:17.12
-6,-1,-5:17.12
-4,-1,-5:17.12
-3,-1,-5:17.12
-2,-1,-5:17.12
-6,0,-5:17.12
-5,0,-5:17.12
-4,0,-5:17.12
-3,0,-5:17.12
-2,0,-5:17.12
-1,0,-5:17.12
0,0,-5:17.12
-6,1,-5:17.12
-5,1,-5:17.12
-4,1,-5:17.12
-3,1,-5:17.12
-2,1,-5:17.12
-1,1,-5:17.12
-6,2,-5:17.12
-5,2,-5:17.12
-4,2,-5:17.12
-3,2,-5:17.12
-2,2,-5:17.12
-4,3,-5:17.12
-3,3,-5:17.12
-1,3,-5:17.12
-5,-3,-4:17.12
-6,-2,-4:17.12
-5,-2,-4:17.12
-7,-1,-4:17.12
-6,-1,-4:17.12
-5,-1,-4:17.12
-4,-1,-4:17.12
-3,-1,-4:17.12
-2,-1,-4:17.12
-7,0,-4:17.12
-6,0,-4:17.12
-5,0,-4:17.12
-4,0,-4:17.12
-3,0,-4:17.12
-2,0,-4:17.12
-1,0,-4:17.12
-7,1,-4:17.12
-6,1,-4:17.12
-5,1,-4:17.12
-4,1,-4:17.12
-3,1,-4:17.12
-2,1,-4:17.12
-1,1,-4:17.12
-7,2,-4:17.12
-5,2,-4:17.12
-4,2,-4:17.12
-3,2,-4:17.12
-2,2,-4:17.12
-1,2,-4:17.12
0,2,-4:17.12
-6,3,-4:17.12
-5,3,-4:17.12
-4,3,-4:17.12
-3,3,-4:17.12
-1,3,-4:17.12
-4,4,-4:17.12
-3,4,-4:17.12
-2,4,-4:17.12
-6,-3,-3:17.12
-5,-3,-3:17.12
-5,-2,-3:17.12
-4,-2,-3:17.12
-6,-1,-3:17.12
-5,-1,-3:17.12
-3,-1,-3:17.12
-7,0,-3:17.12
-4,0,-3:17.12
-3,0,-3:17.12
1,0,-3:17.12
-6,1,-3:17.12
-4,1,-3:17.12
-3,1,-3:17.12
-2,1,-3:17.12
0,1,-3:17.12
-6,2,-3:17.12
-3,2,-3:17.12
-2,2,-3:17.12
-1,2,-3:17.12
-4,3,-3:17.12
-3,3,-3:17.12
-2,3,-3:17.12
-4,4,-3:17.12
-3,4,-3:17.12
-6,-2,-2:17.12
-5,-2,-2:17.12
-4,-2,-2:17.12
-3,-2,-2:17.12
-2,-2,-2:17.12
-6,-1,-2:17.12
-5,-1,-2:17.12
-4,-1,-2:17.12
-3,-1,-2:17.12
-2,-1,-2:17.12
-1,-1,-2:17.12
0,-1,-2:17.12
-6,0,-2:17.12
-5,0,-2:17.12
-4,0,-2:17.12
-3,0,-2:17.12
-2,0,-2:17.12
-1,0,-2:17.12
0,0,-2:17.12
1,0,-2:17.12
-6,1,-2:17.12
-5,1,-2:17.12
-4,1,-2:17.12
-3,1,-2:17.12
-2,1,-2:17.12
-1,1,-2:17.12
0,1,-2:17.12
-6,2,-2:17.12
-5,2,-2:17.12
-4,2,-2:17.12
-2,2,-2:17.12
-1,2,-2:17.12
0,2,-2:17.12
-5,3,-2:17.12
-4,3,-2:17.12
-3,3,-2:17.12
-2,3,-2:17.12
-1,3,-2:17.12
0,3,-2:17.12
-5,4,-2:17.12
-4,4,-2:17.12
-3,4,-2:17.12
-4,-3,-1:18.14
-3,-3,-1:18.14
-5,-2,-1:18.14
-4,-2,-1:17.12
-3,-2,-1:17.12
-2,-2,-1:17.12
-1,-2,-1:18.14
0,-2,-1:18.14
1,-2,-1:18.14
-5,-1,-1:17.12
-4,-1,-1:17.12
-3,-1,-1:17.12
-2,-1,-1:17.12
-1,-1,-1:17.12
0,-1,-1:18.14
1,-1,-1:18.14
-5,0,-1:17.12
-4,0,-1:17.12
-3,0,-1:18.14
-2,0,-1:17.12
-1,0,-1:17.12
0,0,-1:17.12
1,0,-1:18.14
-5,1,-1:17.12
-2,1,-1:18.14
-1,1,-1:17.12
0,1,-1:17.12
1,1,-1:18.14
2,1,-1:18.14
-5,2,-1:17.12
-4,2,-1:17.12
-2,2,-1:18.14
-1,2,-1:18.14
0,2,-1:18.14
1,2,-1:18.14
-4,3,-1:17.12
-3,3,-1:17.12
-2,3,-1:17.12
-1,3,-1:17.12
0,3,-1:18.14
-4,4,-1:17.12
-3,4,-1:18.14
-2,4,-1:18.14
-1,-7,0:18.14
-1,-6,0:18.14
-3,-3,0:18.14
-5,-2,0:18.14
-4,-2,0:18.14
-3,-2,0:18.14
-2,-2,0:18.14
-1,-2,0:18.14
0,-2,0:18.14
1,-2,0:18.14
-5,-1,0:17.12
-4,-1,0:17.12
-3,-1,0:18.14
-2,-1,0:18.14
-1,-1,0:18.14
0,-1,0:18.14
-4,0,0:17.12
-3,0,0:18.14
-2,0,0:17.12
-1,0,0:18.14
0,0,0:18.14
1,0,0:18.14
-5,1,0:17.12
-4,1,0:17.12
-2,1,0:18.14
-1,1,0:17.12
0,1,0:18.14
1,1,0:18.14
2,1,0:18.14
-4,2,0:17.12
-2,2,0:18.14
-1,2,0:18.14
0,2,0:18.14
1,2,0:18.14
-4,3,0:17.12
-3,3,0:18.14
-2,3,0:18.14
-1,3,0:18.14
-4,4,0:17.12
-3,4,0:18.14
-2,4,0:18.14
-1,-7,1:18.14
-1,-6,1:18.14
-3,-2,1:18.14
-2,-2,1:18.14
-1,-2,1:18.14
-4,-1,1:17.12
-3,-1,1:17.12
-2,-1,1:18.14
-1,-1,1:18.14
-6,0,1:18.14
-4,0,1:17.12
-3,0,1:18.14
-2,0,1:17.12
-1,0,1:17.12
0,0,1:17.12
-4,1,1:17.12
-1,1,1:17.12
-4,2,1:17.12
-3,2,1:17.12
-2,2,1:17.12
-1,2,1:17.12
-3,3,1:17.12
-2,3,1:18.14
-1,-7,2:18.14
-1,-6,2:18.14
-1,-4,2:18.14
-5,-1,2:18.14
-3,-1,2:17.12
-2,-1,2:17.12
-6,0,2:18.14
-4,0,2:17.12
-2,0,2:17.12
-1,0,2:18.14
-4,1,2:17.12
-2,1,2:17.12
-1,1,2:17.12
-4,2,2:17.12
-3,2,2:17.12
-2,2,2:17.12
-4,3,2:18.14
-17,5,2:18.14
-4,5,2:18.14
-5,7,2:18.14
-4,8,2:18.14
-6,11,2:18.14
-7,13,2:18.14
1,-13,3:18.14
0,-8,3:18.14
-1,-7,3:18.14
-1,-6,3:18.14
-1,-4,3:18.14
-5,-2,3:18.14
-4,-2,3:18.14
-5,-1,3:18.14
-4,-1,3:17.12
-3,-1,3:17.12
-2,-1,3:17.12
-6,0,3:18.14
-4,0,3:17.12
-2,0,3:17.12
-1,0,3:18.14
2,0,3:18.14
-6,1,3:18.14
-5,1,3:18.14
-4,1,3:17.12
-2,1,3:17.12
-1,1,3:18.14
-16,2,3:18.14
-4,2,3:17.12
-3,2,3:17.12
-2,2,3:17.12
-1,2,3:18.14
-16,3,3:18.14
-4,3,3:18.6
-3,3,3:18.6
-4,5,3:18.14
-6,7,3:18.14
-5,7,3:18.14
-15,8,3:18.14
-6,8,3:18.14
-5,8,3:18.14
-4,8,3:18.14
-3,8,3:18.14
-7,9,3:18.14
-6,9,3:18.14
-5,9,3:18.14
-4,9,3:18.14
-3,9,3:18.14
-6,10,3:18.14
-5,10,3:18.14
-4,10,3:18.14
-6,11,3:18.14
-4,11,3:18.14
-7,13,3:18.14
-2,-14,4:18.14
1,-14,4:18.6
-3,-13,4:18.14
1,-13,4:18.14
-3,-12,4:18.14
-2,-12,4:18.14
-1,-12,4:18.14
0,-12,4:18.14
1,-12,4:18.14
4,-12,4:18.6
0,-11,4:18.14
1,-11,4:18.14
0,-10,4:18.14
0,-9,4:18.14
-1,-8,4:18.14
0,-8,4:18.14
-1,-7,4:18.14
-1,-6,4:18.6
-1,-5,4:18.6
-1,-4,4:18.6
-5,-2,4:18.6
-4,-2,4:18.6
-3,-2,4:18.6
-2,-2,4:18.6
-5,-1,4:18.6
-4,-1,4:17.12
-3,-1,4:17.12
-2,-1,4:17.12
-1,-1,4:18.6
-18,0,4:18.6
-6,0,4:18.6
-4,0,4:17.12
-2,0,4:17.12
-1,0,4:18.6
1,0,4:18.6
2,0,4:18.6
-5,1,4:18.6
-4,1,4:17.12
-2,1,4:17.12
-1,1,4:18.6
-16,2,4:18.14
-15,2,4:18.14
-14,2,4:18.14
-13,2,4:18.14
-5,2,4:18.6
-4,2,4:18.6
-3,2,4:17.12
-2,2,4:17.12
-1,2,4:18.6
-16,3,4:18.14
-15,3,4:18.14
-13,3,4:18.14
-12,3,4:18.14
-4,3,4:18.6
-3,3,4:18.6
-2,3,4:18.6
-16,4,4:18.14
0,4,4:18.6
-16,5,4:18.14
-4,5,4:18.14
-18,6,4:18.14
-17,6,4:18.14
-16,6,4:18.14
-7,6,4:18.14
-6,6,4:18.14
-4,6,4:18.14
2,6,4:18.6
-16,7,4:18.14
-14,7,4:18.14
-6,7,4:18.14
-5,7,4:18.14
-6,8,4:18.14
-5,8,4:18.14
-4,8,4:18.14
-3,8,4:18.14
-2,8,4:18.14
9,8,4:18.6
-7,9,4:18.14
-6,9,4:18.14
-5,9,4:18.14
-4,9,4:18.14
-3,9,4:18.14
-7,10,4:18.14
-6,10,4:18.14
-5,10,4:18.14
-4,10,4:18.14
6,10,4:18.6
-6,11,4:18.14
-5,11,4:18.14
-4,11,4:18.14
-7,12,4:18.14
-7,13,4:18.14
-2,-14,5:18.6
1,-14,5:18.6
2,-14,5:18.6
1,-13,5:18.6
-2,-12,5:18.14
-1,-12,5:18.6
1,-12,5:18.6
4,-12,5:18.6
5,-12,5:18.6
0,-11,5:18.6
1,-11,5:18.6
0,-10,5:18.6
-12,-9,5:18.6
-1,-9,5:18.14
0,-9,5:18.6
-10,-8,5:18.6
-2,-8,5:18.14
0,-8,5:18.6
-1,-7,5:18.6
0,-7,5:18.6
-1,-6,5:18.6
-1,-5,5:18.6
-1,-4,5:18.6
-2,-3,5:18.6
-5,-2,5:18.6
-4,-2,5:18.6
-3,-2,5:18.6
-2,-2,5:18.6
-5,-1,5:18.6
-4,-1,5:17.12
-3,-1,5:17.12
-2,-1,5:17.12
-1,-1,5:18.6
4,-1,5:18.6
-18,0,5:18.6
-6,0,5:18.6
-5,0,5:17.12
-4,0,5:17.12
-2,0,5:17.12
-1,0,5:18.6
1,0,5:18.6
2,0,5:18.6
-12,1,5:18.14
-11,1,5:18.14
-5,1,5:18.6
-4,1,5:17.12
-2,1,5:17.12
-1,1,5:18.6
-16,2,5:18.14
-15,2,5:18.14
-14,2,5:18.14
-13,2,5:18.14
-5,2,5:18.6
-4,2,5:18.6
-3,2,5:17.12
-2,2,5:18.6
-1,2,5:18.6
-18,3,5:18.14
-17,3,5:18.14
-16,3,5:18.14
-15,3,5:18.14
-14,3,5:18.14
-13,3,5:18.14
-12,3,5:18.14
-4,3,5:18.6
-3,3,5:18.6
-2,3,5:18.6
-18,4,5:18.14
-16,4,5:18.14
-15,4,5:18.14
-13,4,5:18.14
-12,4,5:18.14
-4,4,5:18.6
0,4,5:18.6
-17,5,5:18.14
-16,5,5:18.14
-14,5,5:18.14
-13,5,5:18.14
-4,5,5:18.14
-17,6,5:18.14
-15,6,5:18.14
-14,6,5:18.14
-7,6,5:18.14
-6,6,5:18.14
-4,6,5:18.14
2,6,5:18.6
-17,7,5:18.14
-16,7,5:18.14
-15,7,5:18.14
-14,7,5:18.14
-5,7,5:18.14
-13,8,5:18.14
-7,8,5:18.14
-6,8,5:18.14
-5,8,5:18.14
-4,8,5:18.14
-3,8,5:18.14
9,8,5:18.6
-6,9,5:18.14
-5,9,5:18.14
-3,9,5:18.14
9,9,5:18.6
-8,10,5:18.14
-7,10,5:18.14
-6,10,5:18.14
-5,10,5:18.14
-4,10,5:18.14
6,10,5:18.6
-6,11,5:18.14
-4,11,5:18.14
7,11,5:18.14
-7,12,5:18.14
-4,12,5:18.14
3,12,5:18.6
7,12,5:18.14
-7,13,5:18.14
3,13,5:18.6
-7,14,5:18.6
3,14,5:18.6
4,14,5:18.14
0,-15,6:18.6
2,-15,6:18.6
-3,-14,6:18.6
-2,-14,6:18.6
-1,-14,6:18.6
1,-14,6:18.6
2,-14,6:18.6
3,-14,6:18.6
-9,-13,6:18.6
-8,-13,6:18.6
-2,-13,6:18.14
1,-13,6:18.6
4,-13,6:18.6
-12,-12,6:18.6
-2,-12,6:18.14
-1,-12,6:18.6
1,-12,6:18.6
4,-12,6:18.6
5,-12,6:18.6
-1,-11,6:18.14
0,-11,6:18.6
1,-11,6:18.6
-1,-10,6:18.14
0,-10,6:18.6
-15,-9,6:18.6
-12,-9,6:18.6
-1,-9,6:18.14
0,-9,6:18.6
-10,-8,6:18.6
0,-8,6:18.6
-16,-7,6:18.6
-10,-7,6:18.6
-1,-7,6:18.6
0,-7,6:18.6
9,-7,6:18.6
-9,-6,6:18.6
-8,-6,6:18.6
-1,-6,6:18.6
-16,-5,6:18.6
-1,-5,6:18.6
-1,-4,6:18.6
-17,-3,6:18.6
-2,-3,6:18.6
-1,-3,6:18.6
-5,-2,6:18.6
-4,-2,6:18.6
-3,-2,6:18.6
-2,-2,6:18.6
-5,-1,6:18.6
-4,-1,6:17.12
-3,-1,6:17.12
-2,-1,6:17.12
-1,-1,6:18.6
4,-1,6:18.6
12,-1,6:18.6
-18,0,6:18.6
-6,0,6:18.6
-5,0,6:17.12
-4,0,6:17.12
-2,0,6:17.12
-1,0,6:18.6
0,0,6:18.6
1,0,6:18.6
2,0,6:18.6
-18,1,6:18.14
-12,1,6:18.14
-11,1,6:18.14
-10,1,6:18.14
-9,1,6:18.6
-5,1,6:18.6
-4,1,6:17.12
-3,1,6:17.12
-2,1,6:17.12
-1,1,6:18.6
-18,2,6:18.14
-16,2,6:18.14
-15,2,6:18.14
-14,2,6:18.14
-13,2,6:18.14
-12,2,6:18.14
-5,2,6:18.6
-4,2,6:18.6
-3,2,6:17.12
-2,2,6:18.6
-1,2,6:18.6
11,2,6:18.6
-19,3,6:18.14
-18,3,6:18.14
-17,3,6:18.14
-16,3,6:18.14
-15,3,6:18.14
-14,3,6:18.14
-13,3,6:18.14
-4,3,6:18.6
-3,3,6:18.6
-2,3,6:18.6
-1,3,6:18.6
-19,4,6:18.14
-18,4,6:18.14
-17,4,6:18.14
-13,4,6:18.14
-4,4,6:18.6
0,4,6:18.6
-18,5,6:18.14
-17,5,6:18.14
-16,5,6:18.14
-13,5,6:18.14
-4,5,6:18.6
-18,6,6:18.14
-17,6,6:18.14
-16,6,6:18.14
-13,6,6:18.14
-7,6,6:18.6
-4,6,6:18.6
2,6,6:18.6
-17,7,6:18.14
-16,7,6:18.14
-15,7,6:18.14
-14,7,6:18.14
-7,7,6:18.6
-6,7,6:18.6
-5,7,6:18.6
-4,7,6:18.6
3,7,6:18.6
-14,8,6:18.14
-7,8,6:18.6
-5,8,6:18.6
-4,8,6:18.6
-3,8,6:18.6
4,8,6:18.6
9,8,6:18.6
-14,9,6:18.14
-5,9,6:18.6
-4,9,6:18.6
9,9,6:18.6
-8,10,6:18.6
-7,10,6:18.6
-6,10,6:18.6
-4,10,6:18.6
-3,10,6:18.6
6,10,6:18.6
8,10,6:18.6
-6,11,6:18.6
-5,11,6:18.6
-4,11,6:18.6
7,11,6:18.14
8,11,6:18.14
-12,12,6:18.6
-7,12,6:18.6
4,12,6:18.6
7,12,6:18.14
-7,13,6:18.6
3,13,6:18.6
5,13,6:18.6
6,13,6:18.14
-10,14,6:18.6
-7,14,6:18.6
1,14,6:18.6
4,14,6:18.14
5,14,6:18.14
-8,15,6:18.6
-6,15,6:18.6
-3,15,6:18.6
4,15,6:18.14
0,-15,7:18.6
1,-15,7:18.6
2,-15,7:18.6
-3,-14,7:18.6
-2,-14,7:18.6
-1,-14,7:18.6
1,-14,7:18.6
2,-14,7:18.6
3,-14,7:18.6
-9,-13,7:18.6
-8,-13,7:18.6
-6,-13,7:18.6
-5,-13,7:18.6
-2,-13,7:18.6
1,-13,7:18.6
4,-13,7:18.6
-12,-12,7:18.6
1,-12,7:18.6
4,-12,7:18.6
5,-12,7:18.6
1,-11,7:18.6
-13,-10,7:18.6
-12,-10,7:18.6
-1,-10,7:18.14
0,-10,7:18.6
6,-10,7:18.6
7,-10,7:18.6
-15,-9,7:18.6
-12,-9,7:18.6
-11,-9,7:18.6
-1,-9,7:18.14
0,-9,7:18.6
-10,-8,7:18.6
0,-8,7:18.6
8,-8,7:18.6
-16,-7,7:18.6
-10,-7,7:18.6
-9,-7,7:18.6
-1,-7,7:18.6
0,-7,7:18.6
9,-7,7:18.6
-16,-6,7:18.6
-9,-6,7:18.6
-8,-6,7:18.6
-1,-6,7:18.6
-16,-5,7:18.6
-8,-5,7:18.6
-7,-5,7:18.6
-1,-5,7:18.6
11,-5,7:18.6
-6,-4,7:18.6
-1,-4,7:18.6
-17,-3,7:18.6
-2,-3,7:18.6
-1,-3,7:18.6
-5,-2,7:18.6
-4,-2,7:18.6
-3,-2,7:18.6
-2,-2,7:18.6
9,-2,7:18.6
-18,-1,7:18.6
-5,-1,7:18.6
-4,-1,7:17.12
-3,-1,7:17.12
-2,-1,7:17.12
-1,-1,7:18.6
4,-1,7:18.6
5,-1,7:18.6
12,-1,7:18.6
-18,0,7:18.6
-8,0,7:18.6
-6,0,7:18.6
-5,0,7:17.12
-2,0,7:17.12
-1,0,7:18.6
0,0,7:18.6
1,0,7:18.6
2,0,7:18.6
-18,1,7:18.14
-17,1,7:18.14
-11,1,7:18.14
-10,1,7:18.6
-9,1,7:18.6
-8,1,7:18.6
-5,1,7:18.6
-4,1,7:17.12
-2,1,7:17.12
-1,1,7:18.6
-18,2,7:18.14
-17,2,7:18.14
-15,2,7:18.14
-14,2,7:18.14
-13,2,7:18.14
-12,2,7:18.14
-5,2,7:18.6
-4,2,7:17.12
-3,2,7:17.12
-2,2,7:18.6
-1,2,7:18.6
11,2,7:18.6
-19,3,7:18.14
-18,3,7:18.14
-17,3,7:18.14
-16,3,7:18.14
-15,3,7:18.14
-14,3,7:18.14
-13,3,7:18.14
-4,3,7:18.6
-3,3,7:18.6
-2,3,7:18.6
-1,3,7:18.6
-19,4,7:18.14
-18,4,7:18.14
-17,4,7:18.14
-16,4,7:18.14
-13,4,7:18.14
-4,4,7:18.6
0,4,7:18.6
-18,5,7:18.14
-17,5,7:18.14
-12,5,7:18.14
-4,5,7:18.6
1,5,7:18.6
10,5,7:18.6
-17,6,7:18.14
-16,6,7:18.14
-13,6,7:18.14
-4,6,7:18.6
2,6,7:18.6
10,6,7:18.6
-17,7,7:18.14
-16,7,7:18.14
-15,7,7:18.14
-14,7,7:18.14
-13,7,7:18.14
-5,7,7:18.6
-4,7,7:18.6
3,7,7:18.6
-13,8,7:18.14
-7,8,7:18.6
-6,8,7:18.6
-5,8,7:18.6
-4,8,7:18.6
-3,8,7:18.6
-2,8,7:18.6
4,8,7:18.6
9,8,7:18.6
-14,9,7:18.14
-7,9,7:18.6
-6,9,7:18.6
-5,9,7:18.6
-3,9,7:18.6
5,9,7:18.6
9,9,7:18.6
-8,10,7:18.6
-7,10,7:18.6
-6,10,7:18.6
-5,10,7:18.6
-4,10,7:18.6
5,10,7:18.6
6,10,7:18.6
8,10,7:18.6
-13,11,7:18.6
-6,11,7:18.6
6,11,7:18.6
7,11,7:18.14
8,11,7:18.14
-12,12,7:18.6
-7,12,7:18.6
-4,12,7:18.6
7,12,7:18.14
8,12,7:18.14
-7,13,7:18.6
3,13,7:18.6
5,13,7:18.6
6,13,7:18.14
7,13,7:18.14
-10,14,7:18.6
-8,14,7:18.6
-7,14,7:18.6
0,14,7:18.6
1,14,7:18.6
6,14,7:18.14
-8,15,7:18.6
-6,15,7:18.6
-3,15,7:18.6
0,-15,8:18.6
1,-15,8:18.6
2,-15,8:18.6
-3,-14,8:18.6
-2,-14,8:18.6
-1,-14,8:18.6
0,-14,8:18.6
1,-14,8:18.6
2,-14,8:18.6
3,-14,8:18.6
-9,-13,8:18.6
-8,-13,8:18.6
-7,-13,8:18.6
-6,-13,8:18.6
-5,-13,8:18.6
-2,-13,8:18.6
1,-13,8:18.6
3,-13,8:18.6
4,-13,8:18.6
-12,-12,8:18.6
-2,-12,8:18.6
1,-12,8:18.6
4,-12,8:18.6
5,-12,8:18.6
-14,-11,8:18.6
-13,-11,8:18.6
1,-11,8:18.6
5,-11,8:18.6
-13,-10,8:18.6
-12,-10,8:18.6
-2,-10,8:18.14
0,-10,8:18.6
6,-10,8:18.6
7,-10,8:18.6
-15,-9,8:18.6
-12,-9,8:18.6
-11,-9,8:18.6
0,-9,8:18.6
7,-9,8:18.6
-11,-8,8:18.6
-10,-8,8:18.6
0,-8,8:18.6
8,-8,8:18.6
-16,-7,8:18.6
-10,-7,8:18.6
-9,-7,8:18.6
-1,-7,8:18.6
0,-7,8:18.6
9,-7,8:18.6
-16,-6,8:18.6
-9,-6,8:18.6
-8,-6,8:18.6
-1,-6,8:18.6
-16,-5,8:18.6
-8,-5,8:18.6
-7,-5,8:18.6
-1,-5,8:18.6
11,-5,8:18.6
-7,-4,8:18.6
-6,-4,8:18.6
-1,-4,8:18.6
-17,-3,8:18.6
-5,-3,8:18.6
-2,-3,8:18.6
-1,-3,8:18.6
11,-3,8:18.6
-5,-2,8:18.6
-4,-2,8:18.6
-3,-2,8:18.6
-2,-2,8:18.6
7,-2,8:18.6
9,-2,8:18.6
10,-2,8:18.6
-18,-1,8:18.6
-17,-1,8:18.6
-5,-1,8:18.6
-4,-1,8:17.12
-3,-1,8:17.12
-2,-1,8:17.12
-1,-1,8:18.6
4,-1,8:18.6
5,-1,8:18.6
12,-1,8:18.6
-18,0,8:18.6
-8,0,8:18.6
-7,0,8:18.6
-6,0,8:18.6
-5,0,8:17.12
-2,0,8:17.12
-1,0,8:18.6
0,0,8:18.6
1,0,8:18.6
2,0,8:18.6
3,0,8:18.6
-18,1,8:18.14
-11,1,8:18.14
-10,1,8:18.6
-9,1,8:18.6
-8,1,8:18.6
-5,1,8:18.6
-4,1,8:17.12
-2,1,8:17.12
-1,1,8:18.6
-18,2,8:18.14
-17,2,8:18.14
-15,2,8:18.14
-14,2,8:18.14
-13,2,8:18.14
-12,2,8:18.14
-11,2,8:18.14
-5,2,8:18.6
-4,2,8:17.12
-3,2,8:17.12
-2,2,8:18.6
-1,2,8:18.6
11,2,8:18.6
-19,3,8:18.14
-18,3,8:18.14
-17,3,8:18.14
-16,3,8:18.14
-15,3,8:18.14
-14,3,8:18.14
-11,3,8:18.14
-10,3,8:18.6
-4,3,8:18.6
-3,3,8:18.6
-2,3,8:18.6
-1,3,8:18.6
-19,4,8:18.14
-18,4,8:18.14
-13,4,8:18.14
-4,4,8:18.6
0,4,8:18.6
-18,5,8:18.14
-17,5,8:18.14
-13,5,8:18.14
-4,5,8:18.6
1,5,8:18.6
10,5,8:18.6
-17,6,8:18.14
-14,6,8:18.14
-13,6,8:18.14
-6,6,8:18.6
-5,6,8:18.6
-4,6,8:18.6
2,6,8:18.6
10,6,8:18.6
-18,7,8:18.14
-17,7,8:18.14
-16,7,8:18.14
-15,7,8:18.14
-5,7,8:18.6
3,7,8:18.6
-13,8,8:18.14
-6,8,8:18.6
-5,8,8:18.6
-4,8,8:18.6
-3,8,8:18.6
3,8,8:18.6
4,8,8:18.6
9,8,8:18.6
-14,9,8:18.14
-7,9,8:18.6
-6,9,8:18.6
-5,9,8:18.6
-4,9,8:18.6
-3,9,8:18.6
4,9,8:18.6
5,9,8:18.6
9,9,8:18.6
-6,10,8:18.6
-5,10,8:18.6
5,10,8:18.6
6,10,8:18.6
8,10,8:18.6
-13,11,8:18.14
-6,11,8:18.6
-5,11,8:18.6
6,11,8:18.6
7,11,8:18.6
8,11,8:18.6
-12,12,8:18.14
-7,12,8:18.6
7,12,8:18.6
8,12,8:18.6
-7,13,8:18.6
3,13,8:18.6
5,13,8:18.6
6,13,8:18.6
7,13,8:18.6
-10,14,8:18.6
-8,14,8:18.6
-7,14,8:18.6
0,14,8:18.6
1,14,8:18.6
-8,15,8:18.6
-6,15,8:18.6
-3,15,8:18.6
0,-15,9:18.6
1,-15,9:18.6
2,-15,9:18.6
-3,-14,9:18.6
-2,-14,9:18.6
-1,-14,9:18.6
0,-14,9:18.6
1,-14,9:18.6
2,-14,9:18.6
3,-14,9:18.6
-9,-13,9:18.6
-8,-13,9:18.6
-7,-13,9:18.6
-6,-13,9:18.6
-5,-13,9:18.6
1,-13,9:18.6
3,-13,9:18.6
4,-13,9:18.6
-12,-12,9:18.6
-11,-12,9:18.6
-10,-12,9:18.6
1,-12,9:18.6
4,-12,9:18.6
5,-12,9:18.6
-14,-11,9:18.6
-13,-11,9:18.6
1,-11,9:18.6
5,-11,9:18.6
-13,-10,9:18.6
-12,-10,9:18.6
0,-10,9:18.6
6,-10,9:18.6
7,-10,9:18.6
-15,-9,9:18.6
-12,-9,9:18.6
-11,-9,9:18.6
0,-9,9:18.6
7,-9,9:18.6
-11,-8,9:18.6
-10,-8,9:18.6
0,-8,9:18.6
8,-8,9:18.6
-16,-7,9:18.6
-10,-7,9:18.6
-9,-7,9:18.6
-1,-7,9:18.6
0,-7,9:18.6
9,-7,9:18.6
-16,-6,9:18.6
-9,-6,9:18.6
-8,-6,9:18.6
-1,-6,9:18.6
-16,-5,9:18.6
-8,-5,9:18.6
-7,-5,9:18.6
-1,-5,9:18.6
11,-5,9:18.6
-17,-4,9:18.6
-16,-4,9:18.6
-7,-4,9:18.6
-6,-4,9:18.6
-1,-4,9:18.6
-17,-3,9:18.6
-6,-3,9:18.6
-5,-3,9:18.6
-2,-3,9:18.6
-1,-3,9:18.6
11,-3,9:18.6
12,-3,9:18.6
-17,-2,9:18.6
-5,-2,9:18.6
-4,-2,9:18.6
-3,-2,9:18.6
-2,-2,9:18.6
7,-2,9:18.6
9,-2,9:18.6
10,-2,9:18.6
-18,-1,9:18.6
-17,-1,9:18.6
-5,-1,9:18.6
-4,-1,9:17.12
-3,-1,9:17.12
-2,-1,9:17.12
-1,-1,9:18.6
4,-1,9:18.6
5,-1,9:18.6
6,-1,9:18.6
7,-1,9:18.6
12,-1,9:18.6
-18,0,9:18.6
-7,0,9:18.6
-6,0,9:18.6
-5,0,9:17.12
-2,0,9:17.12
-1,0,9:18.6
0,0,9:18.6
1,0,9:18.6
2,0,9:18.6
3,0,9:18.6
12,0,9:18.6
-18,1,9:18.14
-17,1,9:18.14
-16,1,9:18.14
-11,1,9:18.14
-10,1,9:18.6
-9,1,9:18.6
-8,1,9:18.6
-5,1,9:17.12
-2,1,9:17.12
-1,1,9:18.6
11,1,9:18.6
-18,2,9:18.14
-17,2,9:18.14
-16,2,9:18.14
-15,2,9:18.14
-14,2,9:18.14
-13,2,9:18.14
-12,2,9:18.14
-11,2,9:18.14
-5,2,9:18.6
-4,2,9:17.12
-3,2,9:17.12
-2,2,9:17.12
-1,2,9:18.6
11,2,9:18.6
-18,3,9:18.14
-17,3,9:18.14
-16,3,9:18.14
-15,3,9:18.14
-14,3,9:18.14
-13,3,9:18.14
-4,3,9:18.6
-3,3,9:18.6
-2,3,9:18.6
-1,3,9:18.6
-18,4,9:18.14
-17,4,9:18.14
-16,4,9:18.14
-15,4,9:18.14
-14,4,9:18.14
-13,4,9:18.14
-4,4,9:18.6
0,4,9:18.6
10,4,9:18.6
-18,5,9:18.14
-17,5,9:18.14
-16,5,9:18.14
-15,5,9:18.14
-13,5,9:18.14
-12,5,9:18.14
-4,5,9:18.6
1,5,9:18.6
10,5,9:18.6
-17,6,9:18.14
-16,6,9:18.14
-14,6,9:18.14
-5,6,9:18.6
-4,6,9:18.6
2,6,9:18.6
10,6,9:18.6
-16,7,9:18.14
-13,7,9:18.14
-5,7,9:18.6
2,7,9:18.6
3,7,9:18.6
9,7,9:18.6
-15,8,9:18.14
-14,8,9:18.14
-13,8,9:18.14
-6,8,9:18.6
-5,8,9:18.6
-4,8,9:18.6
-2,8,9:18.6
3,8,9:18.6
4,8,9:18.6
5,8,9:18.6
9,8,9:18.6
-14,9,9:18.14
-7,9,9:18.6
-6,9,9:18.6
-5,9,9:18.6
-3,9,9:18.6
4,9,9:18.6
5,9,9:18.6
6,9,9:18.6
7,9,9:18.6
8,9,9:18.6
9,9,9:18.6
-13,10,9:18.14
-6,10,9:18.6
-5,10,9:18.6
4,10,9:18.6
5,10,9:18.6
6,10,9:18.6
7,10,9:18.6
8,10,9:18.6
-12,11,9:18.14
-6,11,9:18.6
-5,11,9:18.6
4,11,9:18.6
5,11,9:18.6
6,11,9:18.6
7,11,9:18.6
8,11,9:18.6
-12,12,9:18.14
-11,12,9:18.6
-7,12,9:18.6
4,12,9:18.6
5,12,9:18.6
6,12,9:18.6
7,12,9:18.6
8,12,9:18.6
-7,13,9:18.6
3,13,9:18.6
5,13,9:18.6
6,13,9:18.6
7,13,9:18.6
-10,14,9:18.6
-8,14,9:18.6
-7,14,9:18.6
-1,14,9:18.6
0,14,9:18.6
1,14,9:18.6
2,14,9:18.6
-8,15,9:18.6
-6,15,9:18.6
-4,15,9:18.6
-3,15,9:18.6
0,-15,10:18.6
1,-15,10:18.6
2,-15,10:18.6
-5,-14,10:18.6
-4,-14,10:18.6
-3,-14,10:18.6
-2,-14,10:18.6
-1,-14,10:18.6
0,-14,10:18.6
1,-14,10:18.6
2,-14,10:18.6
3,-14,10:18.6
-9,-13,10:18.6
-8,-13,10:18.6
-7,-13,10:18.6
-6,-13,10:18.6
-5,-13,10:18.6
-2,-13,10:18.6
-1,-13,10:18.6
0,-13,10:18.6
1,-13,10:18.6
2,-13,10:18.6
3,-13,10:18.6
4,-13,10:18.6
-13,-12,10:18.6
-12,-12,10:18.6
-11,-12,10:18.6
-10,-12,10:18.6
-2,-12,10:18.6
-1,-12,10:18.6
0,-12,10:18.6
1,-12,10:18.6
2,-12,10:18.6
3,-12,10:18.6
4,-12,10:18.6
5,-12,10:18.6
-14,-11,10:18.6
-13,-11,10:18.6
-2,-11,10:18.6
-1,-11,10:18.6
0,-11,10:18.6
1,-11,10:18.6
2,-11,10:18.6
3,-11,10:18.6
4,-11,10:18.6
5,-11,10:18.6
6,-11,10:18.6
-15,-10,10:18.6
-13,-10,10:18.6
-12,-10,10:18.6
-2,-10,10:18.6
-1,-10,10:18.6
0,-10,10:18.6
1,-10,10:18.6
2,-10,10:18.6
3,-10,10:18.6
6,-10,10:18.6
-15,-9,10:18.6
-12,-9,10:18.6
-11,-9,10:18.6
-2,-9,10:18.6
-1,-9,10:18.6
0,-9,10:18.6
1,-9,10:18.6
2,-9,10:18.6
3,-9,10:18.6
7,-9,10:18.6
-11,-8,10:18.6
-10,-8,10:18.6
-2,-8,10:18.6
-1,-8,10:18.6
0,-8,10:18.6
1,-8,10:18.6
2,-8,10:18.6
8,-8,10:18.6
-16,-7,10:18.6
-10,-7,10:18.6
-9,-7,10:18.6
-2,-7,10:18.6
-1,-7,10:18.6
0,-7,10:18.6
1,-7,10:18.6
9,-7,10:18.6
-16,-6,10:18.6
-9,-6,10:18.6
-8,-6,10:18.6
-2,-6,10:18.6
-1,-6,10:18.6
0,-6,10:18.6
1,-6,10:18.6
10,-6,10:18.6
-16,-5,10:18.6
-8,-5,10:18.6
-7,-5,10:18.6
-2,-5,10:18.6
-1,-5,10:18.6
0,-5,10:18.6
11,-5,10:18.6
-17,-4,10:18.6
-7,-4,10:18.6
-6,-4,10:18.6
-2,-4,10:18.6
-1,-4,10:18.6
0,-4,10:18.6
12,-4,10:18.6
-17,-3,10:18.6
-16,-3,10:18.6
-15,-3,10:18.6
-6,-3,10:18.6
-5,-3,10:18.6
-2,-3,10:18.6
-1,-3,10:18.6
11,-3,10:18.6
12,-3,10:18.6
-17,-2,10:18.6
-16,-2,10:18.6
-15,-2,10:18.6
-14,-2,10:18.6
-13,-2,10:18.6
-12,-2,10:18.6
-11,-2,10:18.6
-5,-2,10:18.6
-4,-2,10:18.6
-3,-2,10:18.6
-2,-2,10:18.6
-1,-2,10:18.6
7,-2,10:18.6
8,-2,10:18.6
9,-2,10:18.6
10,-2,10:18.6
12,-2,10:18.6
-17,-1,10:18.6
-16,-1,10:18.6
-15,-1,10:18.6
-14,-1,10:18.6
-13,-1,10:18.6
-12,-1,10:18.6
-11,-1,10:18.6
-10,-1,10:18.6
-9,-1,10:18.6
-8,-1,10:18.6
-7,-1,10:18.6
-5,-1,10:18.6
-2,-1,10:17.12
-1,-1,10:18.6
3,-1,10:18.6
4,-1,10:18.6
5,-1,10:18.6
6,-1,10:18.6
7,-1,10:18.6
12,-1,10:18.6
-18,0,10:18.6
-17,0,10:18.6
-16,0,10:18.6
-15,0,10:18.6
-14,0,10:18.6
-13,0,10:18.6
-12,0,10:18.6
-11,0,10:18.6
-10,0,10:18.6
-9,0,10:18.6
-8,0,10:18.6
-7,0,10:18.6
-6,0,10:18.6
-5,0,10:17.12
-1,0,10:17.12
0,0,10:18.6
1,0,10:18.6
2,0,10:18.6
3,0,10:18.6
12,0,10:18.6
-18,1,10:18.6
-16,1,10:18.6
-15,1,10:18.6
-14,1,10:18.6
-13,1,10:18.6
-12,1,10:18.6
-11,1,10:18.6
-10,1,10:18.6
-9,1,10:18.6
-8,1,10:18.6
-7,1,10:18.6
-6,1,10:18.6
-5,1,10:18.6
-1,1,10:17.12
11,1,10:18.6
-18,2,10:18.14
-13,2,10:18.6
-12,2,10:18.6
-11,2,10:18.6
-10,2,10:18.6
-9,2,10:18.6
-8,2,10:18.6
-7,2,10:18.6
-6,2,10:18.6
-5,2,10:18.6
-4,2,10:17.12
-3,2,10:17.12
-2,2,10:17.12
-1,2,10:18.6
11,2,10:18.6
-18,3,10:18.14
-15,3,10:18.6
-14,3,10:18.6
-13,3,10:18.6
-12,3,10:18.6
-11,3,10:18.6
-10,3,10:18.6
-9,3,10:18.6
-8,3,10:18.6
-7,3,10:18.6
-6,3,10:18.6
-4,3,10:18.6
-3,3,10:18.6
-2,3,10:18.6
-1,3,10:18.6
0,3,10:18.6
1,3,10:18.6
2,3,10:18.6
-18,4,10:18.14
-16,4,10:18.6
-14,4,10:18.6
-13,4,10:18.6
-12,4,10:18.6
-11,4,10:18.6
-10,4,10:18.6
-8,4,10:18.6
-4,4,10:18.6
-1,4,10:18.6
0,4,10:18.6
1,4,10:18.6
2,4,10:18.6
3,4,10:18.6
4,4,10:18.6
5,4,10:18.6
6,4,10:18.6
10,4,10:18.6
-18,5,10:18.14
-17,5,10:18.6
-16,5,10:18.6
-15,5,10:18.6
-14,5,10:18.6
-13,5,10:18.6
-12,5,10:18.6
-11,5,10:18.6
-10,5,10:18.6
-9,5,10:18.6
-4,5,10:18.6
-1,5,10:18.6
0,5,10:18.6
1,5,10:18.6
2,5,10:18.6
3,5,10:18.6
4,5,10:18.6
5,5,10:18.6
6,5,10:18.6
7,5,10:18.6
8,5,10:18.6
9,5,10:18.6
10,5,10:18.6
-17,6,10:18.6
-16,6,10:18.6
-15,6,10:18.6
-14,6,10:18.6
-13,6,10:18.6
-12,6,10:18.6
-11,6,10:18.6
-10,6,10:18.6
-4,6,10:18.6
-1,6,10:18.6
0,6,10:18.6
1,6,10:18.6
2,6,10:18.6
3,6,10:18.6
4,6,10:18.6
5,6,10:18.6
6,6,10:18.6
7,6,10:18.6
8,6,10:18.6
9,6,10:18.6
10,6,10:18.6
-16,7,10:18.6
-15,7,10:18.6
-14,7,10:18.6
-13,7,10:18.6
-12,7,10:18.6
-11,7,10:18.6
-5,7,10:18.6
-1,7,10:18.6
0,7,10:18.6
1,7,10:18.6
2,7,10:18.6
3,7,10:18.6
4,7,10:18.6
5,7,10:18.6
6,7,10:18.6
7,7,10:18.6
8,7,10:18.6
9,7,10:18.6
-15,8,10:18.6
-14,8,10:18.6
-13,8,10:18.6
-12,8,10:18.6
-6,8,10:18.6
-5,8,10:18.6
-3,8,10:18.6
-1,8,10:18.6
0,8,10:18.6
1,8,10:18.6
2,8,10:18.6
3,8,10:18.6
5,8,10:18.6
6,8,10:18.6
7,8,10:18.6
8,8,10:18.6
9,8,10:18.6
-15,9,10:18.14
-14,9,10:18.14
-6,9,10:18.6
0,9,10:18.6
1,9,10:18.6
2,9,10:18.6
3,9,10:18.6
8,9,10:18.6
9,9,10:18.6
-13,10,10:18.14
-6,10,10:18.6
-5,10,10:18.6
0,10,10:18.6
1,10,10:18.6
2,10,10:18.6
3,10,10:18.6
8,10,10:18.6
-12,11,10:18.14
-6,11,10:18.6
0,11,10:18.6
1,11,10:18.6
2,11,10:18.6
3,11,10:18.6
4,11,10:18.6
8,11,10:18.6
-12,12,10:18.14
-11,12,10:18.6
-7,12,10:18.6
0,12,10:18.6
1,12,10:18.6
2,12,10:18.6
3,12,10:18.6
4,12,10:18.6
6,12,10:18.6
7,12,10:18.6
-11,13,10:18.6
-7,13,10:18.6
0,13,10:18.6
1,13,10:18.6
2,13,10:18.6
3,13,10:18.6
5,13,10:18.6
6,13,10:18.6
-10,14,10:18.6
-8,14,10:18.6
-7,14,10:18.6
-1,14,10:18.6
0,14,10:18.6
1,14,10:18.6
2,14,10:18.6
-9,15,10:18.6
-8,15,10:18.6
-6,15,10:18.6
-5,15,10:18.6
-4,15,10:18.6
-3,15,10:18.6
-8,16,10:18.6
-7,16,10:18.6
-4,-14,11:18.6
-3,-14,11:18.6
-2,-14,11:18.6
-1,-14,11:18.6
0,-14,11:18.6
1,-14,11:18.6
2,-14,11:18.6
-9,-13,11:18.6
-8,-13,11:18.6
-7,-13,11:18.6
-6,-13,11:18.6
-5,-13,11:18.6
-4,-13,11:18.6
-3,-13,11:18.6
3,-13,11:18.6
-13,-12,11:18.6
-12,-12,11:18.6
-11,-12,11:18.6
-10,-12,11:18.6
-8,-12,11:18.6
-7,-12,11:18.6
-6,-12,11:18.6
-5,-12,11:18.6
-4,-12,11:18.6
-3,-12,11:18.6
4,-12,11:18.6
5,-12,11:18.6
-14,-11,11:18.6
-13,-11,11:18.6
-8,-11,11:18.6
-7,-11,11:18.6
-6,-11,11:18.6
-5,-11,11:18.6
-4,-11,11:18.6
-3,-11,11:18.6
4,-11,11:18.6
5,-11,11:18.6
-15,-10,11:18.6
-13,-10,11:18.6
-12,-10,11:18.6
-8,-10,11:18.6
-7,-10,11:18.6
-6,-10,11:18.6
-5,-10,11:18.6
-4,-10,11:18.6
-3,-10,11:18.6
4,-10,11:18.6
5,-10,11:18.6
6,-10,11:18.6
-15,-9,11:18.6
-12,-9,11:18.6
-11,-9,11:18.6
-8,-9,11:18.6
-6,-9,11:18.6
-5,-9,11:18.6
-4,-9,11:18.6
-3,-9,11:18.6
3,-9,11:18.6
4,-9,11:18.6
5,-9,11:18.6
6,-9,11:18.6
7,-9,11:18.6
-11,-8,11:18.6
-10,-8,11:18.6
-8,-8,11:18.6
-7,-8,11:18.6
-6,-8,11:18.6
-5,-8,11:18.6
-4,-8,11:18.6
-3,-8,11:18.6
-2,-8,11:18.6
2,-8,11:18.6
3,-8,11:18.6
4,-8,11:18.6
5,-8,11:18.6
6,-8,11:18.6
7,-8,11:18.6
8,-8,11:18.6
-16,-7,11:18.6
-15,-7,11:18.6
-10,-7,11:18.6
-9,-7,11:18.6
-7,-7,11:18.6
-6,-7,11:18.6
-5,-7,11:18.6
-4,-7,11:18.6
-3,-7,11:18.6
-2,-7,11:18.6
2,-7,11:18.6
3,-7,11:18.6
4,-7,11:18.6
5,-7,11:18.6
6,-7,11:18.6
7,-7,11:18.6
8,-7,11:18.6
9,-7,11:18.6
-16,-6,11:18.6
-15,-6,11:18.6
-14,-6,11:18.6
-13,-6,11:18.6
-12,-6,11:18.6
-11,-6,11:18.6
-9,-6,11:18.6
-8,-6,11:18.6
-7,-6,11:18.6
-6,-6,11:18.6
-5,-6,11:18.6
-4,-6,11:18.6
-3,-6,11:18.6
-2,-6,11:18.6
1,-6,11:18.6
2,-6,11:18.6
3,-6,11:18.6
4,-6,11:18.6
5,-6,11:18.6
6,-6,11:18.6
7,-6,11:18.6
10,-6,11:18.6
-16,-5,11:18.6
-15,-5,11:18.6
-14,-5,11:18.6
-13,-5,11:18.6
-12,-5,11:18.6
-11,-5,11:18.6
-10,-5,11:18.6
-9,-5,11:18.6
-8,-5,11:18.6
-7,-5,11:18.6
-6,-5,11:18.6
-5,-5,11:18.6
-4,-5,11:18.6
-3,-5,11:18.6
0,-5,11:18.6
1,-5,11:18.6
2,-5,11:18.6
3,-5,11:18.6
4,-5,11:18.6
5,-5,11:18.6
6,-5,11:18.6
11,-5,11:18.6
-16,-4,11:18.6
-15,-4,11:18.6
-14,-4,11:18.6
-13,-4,11:18.6
-12,-4,11:18.6
-11,-4,11:18.6
-10,-4,11:18.6
-9,-4,11:18.6
-8,-4,11:18.6
-7,-4,11:18.6
-6,-4,11:18.6
-5,-4,11:18.6
-4,-4,11:18.6
-3,-4,11:18.6
0,-4,11:18.6
1,-4,11:18.6
2,-4,11:18.6
3,-4,11:18.6
4,-4,11:18.6
5,-4,11:18.6
6,-4,11:18.6
11,-4,11:18.6
12,-4,11:18.6
-17,-3,11:18.6
-16,-3,11:18.6
-15,-3,11:18.6
-14,-3,11:18.6
-13,-3,11:18.6
-12,-3,11:18.6
-11,-3,11:18.6
-10,-3,11:18.6
-9,-3,11:18.6
-8,-3,11:18.6
-7,-3,11:18.6
-6,-3,11:18.6
-5,-3,11:18.6
-4,-3,11:18.6
-3,-3,11:18.6
0,-3,11:18.6
1,-3,11:18.6
2,-3,11:18.6
3,-3,11:18.6
4,-3,11:18.6
5,-3,11:18.6
11,-3,11:18.6
12,-3,11:18.6
-17,-2,11:18.6
-12,-2,11:18.6
-11,-2,11:18.6
-10,-2,11:18.6
-9,-2,11:18.6
-8,-2,11:18.6
-7,-2,11:18.6
-6,-2,11:18.6
-5,-2,11:18.6
-4,-2,11:18.6
-3,-2,11:18.6
-1,-2,11:18.6
0,-2,11:18.6
1,-2,11:18.6
2,-2,11:18.6
3,-2,11:18.6
4,-2,11:18.6
7,-2,11:18.6
8,-2,11:18.6
9,-2,11:18.6
10,-2,11:18.6
12,-2,11:18.6
-17,-1,11:18.6
-8,-1,11:18.6
-7,-1,11:18.6
-6,-1,11:18.6
-5,-1,11:18.6
-4,-1,11:18.6
-1,-1,11:18.6
0,-1,11:18.6
1,-1,11:18.6
2,-1,11:18.6
3,-1,11:18.6
4,-1,11:18.6
5,-1,11:18.6
6,-1,11:18.6
7,-1,11:18.6
12,-1,11:18.6
-17,0,11:18.6
-3,0,11:18.6
-2,0,11:18.6
-1,0,11:18.6
0,0,11:18.6
1,0,11:18.6
2,0,11:18.6
3,0,11:18.6
4,0,11:18.6
5,0,11:18.6
6,0,11:18.6
7,0,11:18.6
11,0,11:18.6
12,0,11:18.6
-18,1,11:18.6
-3,1,11:18.6
-2,1,11:18.6
-1,1,11:18.6
0,1,11:18.6
1,1,11:18.6
2,1,11:18.6
3,1,11:18.6
4,1,11:18.6
5,1,11:18.6
6,1,11:18.6
7,1,11:18.6
8,1,11:18.6
9,1,11:18.6
10,1,11:18.6
11,1,11:18.6
-18,2,11:18.6
-16,2,11:18.6
-5,2,11:18.6
-4,2,11:18.6
-3,2,11:18.6
-1,2,11:18.6
0,2,11:18.6
1,2,11:18.6
2,2,11:18.6
3,2,11:18.6
4,2,11:18.6
5,2,11:18.6
6,2,11:18.6
7,2,11:18.6
8,2,11:18.6
9,2,11:18.6
10,2,11:18.6
11,2,11:18.6
-18,3,11:18.14
-15,3,11:18.6
-14,3,11:18.6
-6,3,11:18.6
-5,3,11:18.6
-4,3,11:18.6
-3,3,11:18.6
-2,3,11:18.6
1,3,11:18.6
2,3,11:18.6
3,3,11:18.6
4,3,11:18.6
5,3,11:18.6
6,3,11:18.6
7,3,11:18.6
8,3,11:18.6
9,3,11:18.6
10,3,11:18.6
-18,4,11:18.14
-16,4,11:18.6
-13,4,11:18.6
-12,4,11:18.6
-7,4,11:18.6
-6,4,11:18.6
-5,4,11:18.6
-4,4,11:18.6
-3,4,11:18.6
-2,4,11:18.6
5,4,11:18.6
6,4,11:18.6
7,4,11:18.6
8,4,11:18.6
9,4,11:18.6
10,4,11:18.6
-18,5,11:18.14
-17,5,11:18.6
-13,5,11:18.6
-8,5,11:18.6
-7,5,11:18.6
-6,5,11:18.6
-5,5,11:18.6
-4,5,11:18.6
-2,5,11:18.6
-1,5,11:18.6
9,5,11:18.6
10,5,11:18.6
-17,6,11:18.6
-16,6,11:18.6
-13,6,11:18.6
-10,6,11:18.6
-9,6,11:18.6
-8,6,11:18.6
-7,6,11:18.6
-6,6,11:18.6
-5,6,11:18.6
-4,6,11:18.6
-3,6,11:18.6
-2,6,11:18.6
-1,6,11:18.6
9,6,11:18.6
10,6,11:18.6
-16,7,11:18.6
-15,7,11:18.6
-11,7,11:18.6
-10,7,11:18.6
-9,7,11:18.6
-8,7,11:18.6
-7,7,11:18.6
-6,7,11:18.6
-5,7,11:18.6
-4,7,11:18.6
-3,7,11:18.6
-2,7,11:18.6
-1,7,11:18.6
9,7,11:18.6
-15,8,11:18.6
-14,8,11:18.6
-13,8,11:18.6
-12,8,11:18.6
-11,8,11:18.6
-10,8,11:18.6
-9,8,11:18.6
-8,8,11:18.6
-7,8,11:18.6
-6,8,11:18.6
-5,8,11:18.6
-4,8,11:18.6
-3,8,11:18.6
-2,8,11:18.6
-1,8,11:18.6
8,8,11:18.6
9,8,11:18.6
-14,9,11:18.14
-13,9,11:18.14
-12,9,11:18.6
-11,9,11:18.6
-10,9,11:18.6
-9,9,11:18.6
-8,9,11:18.6
-7,9,11:18.6
-6,9,11:18.6
-5,9,11:18.6
-4,9,11:18.6
-3,9,11:18.6
-2,9,11:18.6
-1,9,11:18.6
8,9,11:18.6
-13,10,11:18.14
-12,10,11:18.14
-11,10,11:18.6
-10,10,11:18.6
-9,10,11:18.6
-6,10,11:18.6
-5,10,11:18.6
-4,10,11:18.6
-3,10,11:18.6
-2,10,11:18.6
-1,10,11:18.6
8,10,11:18.6
-12,11,11:18.14
-11,11,11:18.6
-10,11,11:18.6
-7,11,11:18.6
-6,11,11:18.6
-4,11,11:18.6
-3,11,11:18.6
-2,11,11:18.6
-1,11,11:18.6
7,11,11:18.6
8,11,11:18.6
-12,12,11:18.14
-11,12,11:18.6
-7,12,11:18.6
-4,12,11:18.6
-3,12,11:18.6
-2,12,11:18.6
-1,12,11:18.6
0,12,11:18.6
5,12,11:18.6
6,12,11:18.6
7,12,11:18.6
-11,13,11:18.6
-10,13,11:18.6
-7,13,11:18.6
-4,13,11:18.6
-3,13,11:18.6
-2,13,11:18.6
-1,13,11:18.6
0,13,11:18.6
2,13,11:18.6
3,13,11:18.6
5,13,11:18.6
6,13,11:18.6
-10,14,11:18.6
-8,14,11:18.6
-7,14,11:18.6
-4,14,11:18.6
-3,14,11:18.6
-1,14,11:18.6
0,14,11:18.6
1,14,11:18.6
5,14,11:18.14
-9,15,11:18.6
-8,15,11:18.6
-7,15,11:18.6
-6,15,11:18.6
-5,15,11:18.6
-4,15,11:18.6
-3,15,11:18.6
-7,16,11:18.6
-3,-14,12:18.6
-2,-14,12:18.6
-1,-14,12:18.6
0,-14,12:18.6
1,-14,12:18.6
2,-14,12:18.6
-9,-13,12:18.6
-8,-13,12:18.6
-7,-13,12:18.6
-6,-13,12:18.6
-5,-13,12:18.6
-4,-13,12:18.6
-3,-13,12:18.6
-2,-13,12:18.6
2,-13,12:18.6
3,-13,12:18.6
-13,-12,12:18.6
-12,-12,12:18.6
-11,-12,12:18.6
-10,-12,12:18.6
-9,-12,12:18.6
-8,-12,12:18.6
3,-12,12:18.6
4,-12,12:18.6
-14,-11,12:18.6
-13,-11,12:18.6
-12,-11,12:18.6
-11,-11,12:18.6
-10,-11,12:18.6
-9,-11,12:18.6
-8,-11,12:18.6
4,-11,12:18.6
5,-11,12:18.6
-15,-10,12:18.6
-14,-10,12:18.6
-13,-10,12:18.6
-12,-10,12:18.6
-11,-10,12:18.6
-10,-10,12:18.6
-9,-10,12:18.6
-8,-10,12:18.6
5,-10,12:18.6
6,-10,12:18.6
-15,-9,12:18.6
-14,-9,12:18.6
-13,-9,12:18.6
-12,-9,12:18.6
-11,-9,12:18.6
-10,-9,12:18.6
-9,-9,12:18.6
-8,-9,12:18.6
6,-9,12:18.6
7,-9,12:18.6
-14,-8,12:18.6
-13,-8,12:18.6
-12,-8,12:18.6
-11,-8,12:18.6
-10,-8,12:18.6
-9,-8,12:18.6
-8,-8,12:18.6
7,-8,12:18.6
8,-8,12:18.6
-15,-7,12:18.6
-14,-7,12:18.6
-13,-7,12:18.6
-12,-7,12:18.6
-11,-7,12:18.6
-10,-7,12:18.6
-9,-7,12:18.6
-8,-7,12:18.6
8,-7,12:18.6
9,-7,12:18.6
-16,-6,12:18.6
-12,-6,12:18.6
-11,-6,12:18.6
-10,-6,12:18.6
-9,-6,12:18.6
-8,-6,12:18.6
7,-6,12:18.6
8,-6,12:18.6
9,-6,12:18.6
10,-6,12:18.6
-16,-5,12:18.6
-8,-5,12:18.6
7,-5,12:18.6
8,-5,12:18.6
9,-5,12:18.6
10,-5,12:18.6
11,-5,12:18.6
-16,-4,12:18.6
-7,-4,12:18.6
6,-4,12:18.6
7,-4,12:18.6
8,-4,12:18.6
9,-4,12:18.6
10,-4,12:18.6
11,-4,12:18.6
12,-4,12:18.6
-16,-3,12:18.6
-6,-3,12:18.6
5,-3,12:18.6
6,-3,12:18.6
7,-3,12:18.6
8,-3,12:18.6
9,-3,12:18.6
10,-3,12:18.6
11,-3,12:18.6
12,-3,12:18.6
-17,-2,12:18.6
-5,-2,12:18.6
5,-2,12:18.6
6,-2,12:18.6
7,-2,12:18.6
8,-2,12:18.6
9,-2,12:18.6
10,-2,12:18.6
11,-2,12:18.6
12,-2,12:18.6
-17,-1,12:18.6
-4,-1,12:18.6
2,-1,12:18.6
3,-1,12:18.6
4,-1,12:18.6
5,-1,12:18.6
6,-1,12:18.6
7,-1,12:18.6
8,-1,12:18.6
9,-1,12:18.6
10,-1,12:18.6
11,-1,12:18.6
12,-1,12:18.6
-17,0,12:18.6
-3,0,12:18.6
-2,0,12:18.6
-1,0,12:18.6
0,0,12:18.6
1,0,12:18.6
2,0,12:18.6
6,0,12:18.6
7,0,12:18.6
8,0,12:18.6
9,0,12:18.6
10,0,12:18.6
11,0,12:18.6
12,0,12:18.6
-17,1,12:18.6
-3,1,12:18.6
-2,1,12:18.6
10,1,12:18.6
11,1,12:18.6
-18,2,12:18.6
-17,2,12:18.6
-3,2,12:18.6
11,2,12:18.6
-18,3,12:18.6
-14,3,12:18.6
-13,3,12:18.6
-4,3,12:18.6
-3,3,12:18.6
10,3,12:18.6
-18,4,12:18.6
-17,4,12:18.6
-4,4,12:18.6
10,4,12:18.6
-17,5,12:18.6
-16,5,12:18.6
-14,5,12:18.6
-4,5,12:18.6
9,5,12:18.6
10,5,12:18.6
-16,6,12:18.6
-5,6,12:18.6
9,6,12:18.6
-16,7,12:18.6
-15,7,12:18.6
-14,7,12:18.6
-5,7,12:18.6
9,7,12:18.6
-15,8,12:18.6
-14,8,12:18.6
-13,8,12:18.6
-6,8,12:18.6
-5,8,12:18.6
8,8,12:18.6
-14,9,12:18.14
-13,9,12:18.14
-7,9,12:18.6
-6,9,12:18.6
-5,9,12:18.6
8,9,12:18.6
-13,10,12:18.14
-8,10,12:18.6
-7,10,12:18.6
-6,10,12:18.6
-5,10,12:18.6
7,10,12:18.6
8,10,12:18.6
-12,11,12:18.14
-10,11,12:18.6
-9,11,12:18.6
-8,11,12:18.6
-7,11,12:18.6
-6,11,12:18.6
-5,11,12:18.6
7,11,12:18.6
-12,12,12:18.14
-11,12,12:18.6
-10,12,12:18.6
-9,12,12:18.6
-8,12,12:18.6
-7,12,12:18.6
-6,12,12:18.6
-5,12,12:18.6
4,12,12:18.6
5,12,12:18.6
6,12,12:18.6
7,12,12:18.6
-11,13,12:18.6
-10,13,12:18.6
-9,13,12:18.6
-8,13,12:18.6
-7,13,12:18.6
-6,13,12:18.6
-5,13,12:18.6
-4,13,12:18.6
0,13,12:18.6
1,13,12:18.6
2,13,12:18.6
3,13,12:18.6
5,13,12:18.6
6,13,12:18.6
-10,14,12:18.6
-9,14,12:18.6
-8,14,12:18.6
-7,14,12:18.6
-6,14,12:18.6
-5,14,12:18.6
-4,14,12:18.6
-3,14,12:18.6
-1,14,12:18.6
0,14,12:18.6
5,14,12:18.14
-9,15,12:18.6
-8,15,12:18.6
-7,15,12:18.6
-6,15,12:18.6
-5,15,12:18.6
-4,15,12:18.6
-3,15,12:18.6
-8,16,12:18.14
-7,16,12:18.14
0,-14,13:18.6
1,-14,13:18.6
-7,-13,13:18.6
-6,-13,13:18.6
-5,-13,13:18.6
-4,-13,13:18.6
-3,-13,13:18.6
-2,-13,13:18.6
-1,-13,13:18.6
0,-13,13:18.6
2,-13,13:18.6
-13,-12,13:18.6
-12,-12,13:18.6
-11,-12,13:18.6
-10,-12,13:18.6
-9,-12,13:18.6
-8,-12,13:18.6
-7,-12,13:18.6
3,-12,13:18.6
-14,-11,13:18.6
-13,-11,13:18.6
4,-11,13:18.6
5,-11,13:18.6
-14,-10,13:18.6
5,-10,13:18.6
6,-10,13:18.6
-15,-9,13:18.6
-12,-9,13:18.6
6,-9,13:18.6
7,-9,13:18.6
-11,-8,13:18.6
7,-8,13:18.6
8,-8,13:18.6
-15,-7,13:18.6
-10,-7,13:18.6
8,-7,13:18.6
9,-7,13:18.6
-15,-6,13:18.6
-9,-6,13:18.6
9,-6,13:18.6
10,-6,13:18.6
-16,-5,13:18.6
-15,-5,13:18.6
-8,-5,13:18.6
10,-5,13:18.6
11,-5,13:18.6
-16,-4,13:18.6
-7,-4,13:18.6
11,-4,13:18.6
12,-4,13:18.6
-16,-3,13:18.6
-6,-3,13:18.6
12,-3,13:18.6
-16,-2,13:18.6
-5,-2,13:18.6
6,-2,13:18.6
7,-2,13:18.6
8,-2,13:18.6
9,-2,13:18.6
12,-2,13:18.6
-17,-1,13:18.6
-16,-1,13:18.6
-4,-1,13:18.6
2,-1,13:18.6
3,-1,13:18.6
4,-1,13:18.6
5,-1,13:18.6
6,-1,13:18.6
11,-1,13:18.6
12,-1,13:18.6
-17,0,13:18.6
-3,0,13:18.6
-2,0,13:18.6
-1,0,13:18.6
0,0,13:18.6
1,0,13:18.6
2,0,13:18.6
11,0,13:18.6
-17,1,13:18.6
-3,1,13:18.6
11,1,13:18.6
-17,2,13:18.6
-3,2,13:18.6
10,2,13:18.6
11,2,13:18.6
-18,3,13:18.6
-17,3,13:18.6
-4,3,13:18.6
-3,3,13:18.6
10,3,13:18.6
-17,4,13:18.6
-4,4,13:18.6
9,4,13:18.6
10,4,13:18.6
-17,5,13:18.6
-16,5,13:18.6
-14,5,13:18.6
-4,5,13:18.6
9,5,13:18.6
-18,6,13:18.6
-16,6,13:18.6
-15,6,13:18.6
-5,6,13:18.6
9,6,13:18.6
-15,7,13:18.6
-5,7,13:18.6
8,7,13:18.6
-14,8,13:18.6
-5,8,13:18.6
8,8,13:18.6
-14,9,13:18.6
-13,9,13:18.6
-6,9,13:18.6
7,9,13:18.6
8,9,13:18.6
-13,10,13:18.6
-12,10,13:18.6
-6,10,13:18.6
7,10,13:18.6
-12,11,13:18.6
-7,11,13:18.6
-6,11,13:18.6
6,11,13:18.6
7,11,13:18.6
-11,12,13:18.6
-7,12,13:18.6
3,12,13:18.6
4,12,13:18.6
5,12,13:18.6
6,12,13:18.6
-11,13,13:18.6
-10,13,13:18.6
-7,13,13:18.6
-1,13,13:18.6
0,13,13:18.6
1,13,13:18.6
2,13,13:18.6
5,13,13:18.14
-10,14,13:18.6
-9,14,13:18.14
-4,14,13:18.6
-3,14,13:18.6
-1,14,13:18.6
5,14,13:18.14
-9,15,13:18.14
-8,15,13:18.14
-7,15,13:18.14
-6,15,13:18.14
-5,15,13:18.14
-4,15,13:18.6
-5,-13,14:18.6
-4,-13,14:18.6
-3,-13,14:18.6
-2,-13,14:18.6
-1,-13,14:18.6
0,-13,14:18.6
1,-13,14:18.6
2,-13,14:18.6
-11,-12,14:18.6
-10,-12,14:18.6
-9,-12,14:18.6
-8,-12,14:18.6
-7,-12,14:18.6
-6,-12,14:18.6
-5,-12,14:18.6
-4,-12,14:18.6
2,-12,14:18.6
3,-12,14:18.6
-14,-11,14:18.6
-13,-11,14:18.6
-12,-11,14:18.6
-11,-11,14:18.6
3,-11,14:18.6
4,-11,14:18.6
-14,-10,14:18.6
4,-10,14:18.6
5,-10,14:18.6
-14,-9,14:18.6
5,-9,14:18.6
6,-9,14:18.6
-14,-8,14:18.6
-11,-8,14:18.6
6,-8,14:18.6
7,-8,14:18.6
-15,-7,14:18.6
-10,-7,14:18.6
7,-7,14:18.6
8,-7,14:18.6
-15,-6,14:18.6
-9,-6,14:18.6
9,-6,14:18.6
-15,-5,14:18.6
-8,-5,14:18.6
10,-5,14:18.6
-16,-4,14:18.6
-15,-4,14:18.6
-7,-4,14:18.6
11,-4,14:18.6
-16,-3,14:18.6
-6,-3,14:18.6
12,-3,14:18.6
-16,-2,14:18.6
-5,-2,14:18.6
6,-2,14:18.6
7,-2,14:18.6
8,-2,14:18.6
9,-2,14:18.6
11,-2,14:18.6
12,-2,14:18.6
-16,-1,14:18.6
-4,-1,14:18.6
2,-1,14:18.6
3,-1,14:18.6
4,-1,14:18.6
5,-1,14:18.6
6,-1,14:18.6
11,-1,14:18.6
-17,0,14:18.6
-16,0,14:18.6
-4,0,14:18.6
-3,0,14:18.6
-2,0,14:18.6
-1,0,14:18.6
0,0,14:18.6
1,0,14:18.6
2,0,14:18.6
11,0,14:18.6
-17,1,14:18.6
-3,1,14:18.6
10,1,14:18.6
-17,2,14:18.6
-3,2,14:18.6
10,2,14:18.6
-17,3,14:18.6
-4,3,14:18.6
-3,3,14:18.6
10,3,14:18.6
-17,4,14:18.6
-4,4,14:18.6
9,4,14:18.6
-16,5,14:18.6
-4,5,14:18.6
9,5,14:18.6
-17,6,14:18.6
-16,6,14:18.6
-15,6,14:18.6
-5,6,14:18.6
8,6,14:18.6
9,6,14:18.6
-15,7,14:18.6
-14,7,14:18.6
-5,7,14:18.6
8,7,14:18.6
-14,8,14:18.6
-13,8,14:18.6
-6,8,14:18.6
-5,8,14:18.6
7,8,14:18.6
8,8,14:18.6
-13,9,14:18.6
-6,9,14:18.6
7,9,14:18.6
-12,10,14:18.6
-6,10,14:18.6
7,10,14:18.6
-12,11,14:18.6
-11,11,14:18.6
-7,11,14:18.6
-6,11,14:18.6
5,11,14:18.6
6,11,14:18.6
7,11,14:18.6
-11,12,14:18.6
-7,12,14:18.6
2,12,14:18.6
3,12,14:18.6
4,12,14:18.6
5,12,14:18.6
6,12,14:18.6
-10,13,14:18.6
-2,13,14:18.6
-1,13,14:18.6
0,13,14:18.6
1,13,14:18.6
5,13,14:18.14
6,13,14:18.14
-9,14,14:18.14
-5,14,14:18.14
-4,14,14:18.6
-3,14,14:18.6
-9,15,14:18.14
-2,-13,15:18.6
-1,-13,15:18.6
0,-13,15:18.6
1,-13,15:18.6
2,-13,15:18.6
-9,-12,15:18.6
-8,-12,15:18.6
-7,-12,15:18.6
-6,-12,15:18.6
-5,-12,15:18.6
-4,-12,15:18.6
-3,-12,15:18.6
-2,-12,15:18.6
2,-12,15:18.6
3,-12,15:18.6
-14,-11,15:18.6
-13,-11,15:18.6
-12,-11,15:18.6
-11,-11,15:18.6
-10,-11,15:18.6
-9,-11,15:18.6
3,-11,15:18.6
4,-11,15:18.6
-14,-10,15:18.6
-13,-10,15:18.6
4,-10,15:18.6
5,-10,15:18.6
-14,-9,15:18.6
-12,-9,15:18.6
5,-9,15:18.6
6,-9,15:18.6
-14,-8,15:18.6
-11,-8,15:18.6
6,-8,15:18.6
7,-8,15:18.6
-15,-7,15:18.6
-14,-7,15:18.6
-10,-7,15:18.6
7,-7,15:18.6
8,-7,15:18.6
-15,-6,15:18.6
-9,-6,15:18.6
8,-6,15:18.6
9,-6,15:18.6
-15,-5,15:18.6
-8,-5,15:18.6
9,-5,15:18.6
10,-5,15:18.6
-15,-4,15:18.6
-7,-4,15:18.6
10,-4,15:18.6
11,-4,15:18.6
-16,-3,15:18.6
-15,-3,15:18.6
-6,-3,15:18.6
10,-3,15:18.6
11,-3,15:18.6
12,-3,15:18.6
-16,-2,15:18.6
-5,-2,15:18.6
6,-2,15:18.6
7,-2,15:18.6
8,-2,15:18.6
9,-2,15:18.6
10,-2,15:18.6
11,-2,15:18.6
-16,-1,15:18.6
-4,-1,15:18.6
2,-1,15:18.6
3,-1,15:18.6
4,-1,15:18.6
5,-1,15:18.6
6,-1,15:18.6
11,-1,15:18.6
-16,0,15:18.6
-4,0,15:18.6
-3,0,15:18.6
-2,0,15:18.6
-1,0,15:18.6
0,0,15:18.6
1,0,15:18.6
2,0,15:18.6
10,0,15:18.6
11,0,15:18.6
-16,1,15:18.6
-3,1,15:18.6
10,1,15:18.6
-17,2,15:18.6
-3,2,15:18.6
10,2,15:18.6
-17,3,15:18.6
-4,3,15:18.6
-3,3,15:18.6
9,3,15:18.6
-17,4,15:18.6
-16,4,15:18.6
-4,4,15:18.6
9,4,15:18.6
-16,5,15:18.6
-15,5,15:18.6
-4,5,15:18.6
8,5,15:18.6
9,5,15:18.6
-15,6,15:18.6
-5,6,15:18.6
8,6,15:18.6
-14,7,15:18.6
-5,7,15:18.6
8,7,15:18.6
-14,8,15:18.6
-13,8,15:18.6
-5,8,15:18.6
7,8,15:18.6
-13,9,15:18.6
-12,9,15:18.6
-6,9,15:18.6
7,9,15:18.6
-12,10,15:18.6
-6,10,15:18.6
6,10,15:18.6
7,10,15:18.6
-11,11,15:18.6
-7,11,15:18.6
4,11,15:18.6
5,11,15:18.6
6,11,15:18.6
-11,12,15:18.6
-10,12,15:18.6
-7,12,15:18.6
0,12,15:18.6
1,12,15:18.6
2,12,15:18.6
3,12,15:18.6
4,12,15:18.6
-10,13,15:18.6
-9,13,15:18.6
-7,13,15:18.6
-3,13,15:18.6
-2,13,15:18.6
-1,13,15:18.6
0,13,15:18.6
5,13,15:18.14
6,13,15:18.14
-9,14,15:18.14
-8,14,15:18.14
-7,14,15:18.14
-6,14,15:18.14
-5,14,15:18.14
-4,14,15:18.6
-3,14,15:18.6
0,-13,16:18.6
1,-13,16:18.6
-7,-12,16:18.6
-6,-12,16:18.6
-5,-12,16:18.6
-4,-12,16:18.6
-3,-12,16:18.6
-2,-12,16:18.6
-1,-12,16:18.6
0,-12,16:18.6
1,-12,16:18.6
2,-12,16:18.6
-14,-11,16:18.6
-13,-11,16:18.6
-12,-11,16:18.6
-11,-11,16:18.6
-10,-11,16:18.6
-9,-11,16:18.6
-8,-11,16:18.6
-7,-11,16:18.6
-6,-11,16:18.6
2,-11,16:18.6
3,-11,16:18.6
-13,-10,16:18.6
-12,-10,16:18.6
3,-10,16:18.6
4,-10,16:18.6
-14,-9,16:18.6
-13,-9,16:18.6
-12,-9,16:18.6
4,-9,16:18.6
5,-9,16:18.6
-14,-8,16:18.6
-11,-8,16:18.6
5,-8,16:18.6
6,-8,16:18.6
-14,-7,16:18.6
-10,-7,16:18.6
7,-7,16:18.6
-14,-6,16:18.6
-9,-6,16:18.6
8,-6,16:18.6
-15,-5,16:18.6
-8,-5,16:18.6
9,-5,16:18.6
-15,-4,16:18.6
-7,-4,16:18.6
10,-4,16:18.6
-15,-3,16:18.6
-6,-3,16:18.6
10,-3,16:18.6
11,-3,16:18.6
12,-3,16:18.6
-15,-2,16:18.6
-5,-2,16:18.6
6,-2,16:18.6
7,-2,16:18.6
8,-2,16:18.6
9,-2,16:18.6
10,-2,16:18.6
11,-2,16:18.6
-16,-1,16:18.6
-4,-1,16:18.6
2,-1,16:18.6
3,-1,16:18.6
4,-1,16:18.6
5,-1,16:18.6
6,-1,16:18.6
10,-1,16:18.6
11,-1,16:18.6
-16,0,16:18.6
-4,0,16:18.6
-3,0,16:18.6
-2,0,16:18.6
-1,0,16:18.6
0,0,16:18.6
1,0,16:18.6
2,0,16:18.6
10,0,16:18.6
-16,1,16:18.6
-3,1,16:18.6
10,1,16:18.6
-16,2,16:18.6
-3,2,16:18.6
9,2,16:18.6
10,2,16:18.6
-17,3,16:18.6
-4,3,16:18.6
9,3,16:18.6
-16,4,16:18.6
-4,4,16:18.6
8,4,16:18.6
9,4,16:18.6
-16,5,16:18.6
-15,5,16:18.6
-4,5,16:18.6
8,5,16:18.6
-15,6,16:18.6
-14,6,16:18.6
-5,6,16:18.6
8,6,16:18.6
-14,7,16:18.6
-5,7,16:18.6
7,7,16:18.6
8,7,16:18.6
-13,8,16:18.6
-6,8,16:18.6
-5,8,16:18.6
7,8,16:18.6
-12,9,16:18.6
-6,9,16:18.6
6,9,16:18.6
7,9,16:18.6
-12,10,16:18.6
-11,10,16:18.6
-6,10,16:18.6
6,10,16:18.6
-11,11,16:18.6
-10,11,16:18.6
-7,11,16:18.6
-6,11,16:18.6
3,11,16:18.6
4,11,16:18.6
5,11,16:18.6
-10,12,16:18.6
-7,12,16:18.6
-1,12,16:18.6
0,12,16:18.6
1,12,16:18.6
2,12,16:18.6
3,12,16:18.6
-9,13,16:18.6
-7,13,16:18.6
-4,13,16:18.6
-3,13,16:18.6
-2,13,16:18.6
-1,13,16:18.6
-8,14,16:18.14
-7,14,16:18.14
-6,14,16:18.14
-5,14,16:18.6
-4,14,16:18.6
-5,-12,17:18.6
-4,-12,17:18.6
-3,-12,17:18.6
-2,-12,17:18.6
-1,-12,17:18.6
0,-12,17:18.6
1,-12,17:18.6
2,-12,17:18.6
-13,-11,17:18.6
-11,-11,17:18.6
-10,-11,17:18.6
-9,-11,17:18.6
-8,-11,17:18.6
-7,-11,17:18.6
-6,-11,17:18.6
-5,-11,17:18.6
-4,-11,17:18.6
2,-11,17:18.6
3,-11,17:18.6
-13,-10,17:18.6
-12,-10,17:18.6
-11,-10,17:18.6
-10,-10,17:18.6
3,-10,17:18.6
4,-10,17:18.6
-13,-9,17:18.6
-12,-9,17:18.6
4,-9,17:18.6
5,-9,17:18.6
-14,-8,17:18.6
-13,-8,17:18.6
-11,-8,17:18.6
5,-8,17:18.6
6,-8,17:18.6
-14,-7,17:18.6
-10,-7,17:18.6
6,-7,17:18.6
7,-7,17:18.6
-14,-6,17:18.6
-9,-6,17:18.6
7,-6,17:18.6
8,-6,17:18.6
-14,-5,17:18.6
-8,-5,17:18.6
8,-5,17:18.6
9,-5,17:18.6
-15,-4,17:18.6
-14,-4,17:18.6
-7,-4,17:18.6
9,-4,17:18.6
10,-4,17:18.6
-15,-3,17:18.6
-6,-3,17:18.6
10,-3,17:18.6
11,-3,17:18.6
12,-3,17:18.6
-15,-2,17:18.6
-5,-2,17:18.6
6,-2,17:18.6
7,-2,17:18.6
8,-2,17:18.6
9,-2,17:18.6
10,-2,17:18.6
11,-2,17:18.6
-15,-1,17:18.6
-5,-1,17:18.6
-4,-1,17:18.6
2,-1,17:18.6
3,-1,17:18.6
4,-1,17:18.6
5,-1,17:18.6
6,-1,17:18.6
10,-1,17:18.6
-16,0,17:18.6
-15,0,17:18.6
-4,0,17:18.6
-3,0,17:18.6
-2,0,17:18.6
-1,0,17:18.6
0,0,17:18.6
1,0,17:18.6
10,0,17:18.6
-16,1,17:18.6
-3,1,17:18.6
9,1,17:18.6
10,1,17:18.6
-16,2,17:18.6
-3,2,17:18.6
9,2,17:18.6
-16,3,17:18.6
-4,3,17:18.6
9,3,17:18.6
-16,4,17:18.6
-4,4,17:18.6
8,4,17:18.6
-15,5,17:18.6
-4,5,17:18.6
8,5,17:18.6
-14,6,17:18.6
-5,6,17:18.6
7,6,17:18.6
8,6,17:18.6
-14,7,17:18.6
-13,7,17:18.6
-5,7,17:18.6
7,7,17:18.6
-13,8,17:18.6
-12,8,17:18.6
-6,8,17:18.6
-5,8,17:18.6
7,8,17:18.6
-12,9,17:18.6
-6,9,17:18.6
6,9,17:18.6
-11,10,17:18.6
-6,10,17:18.6
5,10,17:18.6
6,10,17:18.6
-10,11,17:18.6
-7,11,17:18.6
-6,11,17:18.6
2,11,17:18.6
3,11,17:18.6
4,11,17:18.6
5,11,17:18.6
-10,12,17:18.6
-9,12,17:18.6
-7,12,17:18.6
-2,12,17:18.6
-1,12,17:18.6
0,12,17:18.6
1,12,17:18.6
-9,13,17:18.6
-8,13,17:18.6
-7,13,17:18.6
-6,13,17:18.6
-5,13,17:18.6
-4,13,17:18.6
-3,13,17:18.6
-2,13,17:18.6
-8,14,17:18.14
-7,14,17:18.14
-6,14,17:18.6
-2,-12,18:18.6
-1,-12,18:18.6
0,-12,18:18.6
1,-12,18:18.6
-13,-11,18:18.6
-9,-11,18:18.6
-8,-11,18:18.6
-7,-11,18:18.6
-6,-11,18:18.6
-5,-11,18:18.6
-4,-11,18:18.6
-3,-11,18:18.6
-2,-11,18:18.6
1,-11,18:18.6
2,-11,18:18.6
-13,-10,18:18.6
-12,-10,18:18.6
-11,-10,18:18.6
-10,-10,18:18.6
-9,-10,18:18.6
-8,-10,18:18.6
2,-10,18:18.6
3,-10,18:18.6
-13,-9,18:18.6
-12,-9,18:18.6
4,-9,18:18.6
-13,-8,18:18.6
-11,-8,18:18.6
5,-8,18:18.6
-14,-7,18:18.6
-13,-7,18:18.6
-10,-7,18:18.6
6,-7,18:18.6
-14,-6,18:18.6
-9,-6,18:18.6
7,-6,18:18.6
-14,-5,18:18.6
-8,-5,18:18.6
8,-5,18:18.6
-14,-4,18:18.6
-7,-4,18:18.6
9,-4,18:18.6
-15,-3,18:18.6
-14,-3,18:18.6
-6,-3,18:18.6
9,-3,18:18.6
10,-3,18:18.6
11,-3,18:18.6
12,-3,18:18.6
-15,-2,18:18.6
-5,-2,18:18.6
6,-2,18:18.6
7,-2,18:18.6
8,-2,18:18.6
9,-2,18:18.6
10,-2,18:18.6
-15,-1,18:18.6
-5,-1,18:18.6
-4,-1,18:18.6
2,-1,18:18.6
3,-1,18:18.6
4,-1,18:18.6
5,-1,18:18.6
6,-1,18:18.6
10,-1,18:18.6
-15,0,18:18.6
-4,0,18:18.6
-3,0,18:18.6
-2,0,18:18.6
-1,0,18:18.6
0,0,18:18.6
1,0,18:18.6
9,0,18:18.6
-16,1,18:18.6
-15,1,18:18.6
-3,1,18:18.6
9,1,18:18.6
-16,2,18:18.6
-3,2,18:18.6
8,2,18:18.6
9,2,18:18.6
-16,3,18:18.6
-4,3,18:18.6
8,3,18:18.6
-15,4,18:18.6
-4,4,18:18.6
8,4,18:18.6
-15,5,18:18.6
-14,5,18:18.6
-5,5,18:18.6
-4,5,18:18.6
7,5,18:18.6
8,5,18:18.6
-14,6,18:18.6
-5,6,18:18.6
7,6,18:18.6
-13,7,18:18.6
-5,7,18:18.6
7,7,18:18.6
-12,8,18:18.6
-6,8,18:18.6
-5,8,18:18.6
6,8,18:18.6
-12,9,18:18.6
-11,9,18:18.6
-6,9,18:18.6
6,9,18:18.6
-11,10,18:18.6
-10,10,18:18.6
-6,10,18:18.6
4,10,18:18.6
5,10,18:18.6
6,10,18:18.6
-10,11,18:18.6
-9,11,18:18.6
-7,11,18:18.6
1,11,18:18.6
2,11,18:18.6
3,11,18:18.6
4,11,18:18.6
-9,12,18:18.6
-7,12,18:18.6
-3,12,18:18.6
-2,12,18:18.6
-1,12,18:18.6
0,12,18:18.6
-8,13,18:18.6
-7,13,18:18.6
-6,13,18:18.6
-5,13,18:18.6
-4,13,18:18.6
-3,13,18:18.6
-8,14,18:18.6
0,-12,19:18.6
1,-12,19:18.6
-13,-11,19:18.6
-7,-11,19:18.6
-6,-11,19:18.6
-5,-11,19:18.6
-4,-11,19:18.6
-3,-11,19:18.6
-2,-11,19:18.6
-1,-11,19:18.6
0,-11,19:18.6
1,-11,19:18.6
2,-11,19:18.6
-13,-10,19:18.6
-12,-10,19:18.6
-11,-10,19:18.6
-10,-10,19:18.6
-9,-10,19:18.6
-8,-10,19:18.6
-7,-10,19:18.6
-6,-10,19:18.6
2,-10,19:18.6
3,-10,19:18.6
-13,-9,19:18.6
-12,-9,19:18.6
3,-9,19:18.6
4,-9,19:18.6
-13,-8,19:18.6
-11,-8,19:18.6
4,-8,19:18.6
5,-8,19:18.6
-13,-7,19:18.6
-10,-7,19:18.6
5,-7,19:18.6
6,-7,19:18.6
-13,-6,19:18.6
-9,-6,19:18.6
6,-6,19:18.6
7,-6,19:18.6
-14,-5,19:18.6
-13,-5,19:18.6
-8,-5,19:18.6
7,-5,19:18.6
8,-5,19:18.6
-14,-4,19:18.6
-7,-4,19:18.6
8,-4,19:18.6
9,-4,19:18.6
-14,-3,19:18.6
-6,-3,19:18.6
9,-3,19:18.6
10,-3,19:18.6
11,-3,19:18.6
12,-3,19:18.6
-15,-2,19:18.6
-14,-2,19:18.6
-6,-2,19:18.6
-5,-2,19:18.6
6,-2,19:18.6
7,-2,19:18.6
8,-2,19:18.6
9,-2,19:18.6
10,-2,19:18.6
-15,-1,19:18.6
-5,-1,19:18.6
-4,-1,19:18.6
2,-1,19:18.6
3,-1,19:18.6
4,-1,19:18.6
5,-1,19:18.6
6,-1,19:18.6
9,-1,19:18.6
-15,0,19:18.6
-4,0,19:18.6
-3,0,19:18.6
-2,0,19:18.6
-1,0,19:18.6
0,0,19:18.6
1,0,19:18.6
9,0,19:18.6
-15,1,19:18.6
-3,1,19:18.6
8,1,19:18.6
9,1,19:18.6
-15,2,19:18.6
-3,2,19:18.6
8,2,19:18.6
-16,3,19:18.6
-15,3,19:18.6
-4,3,19:18.6
8,3,19:18.6
-15,4,19:18.6
-4,4,19:18.6
7,4,19:18.6
8,4,19:18.6
-14,5,19:18.6
-5,5,19:18.6
-4,5,19:18.6
7,5,19:18.6
-14,6,19:18.6
-13,6,19:18.6
-5,6,19:18.6
7,6,19:18.6
-13,7,19:18.6
-12,7,19:18.6
-5,7,19:18.6
6,7,19:18.6
7,7,19:18.6
-12,8,19:18.6
-11,8,19:18.6
-6,8,19:18.6
-5,8,19:18.6
6,8,19:18.6
-11,9,19:18.6
-6,9,19:18.6
5,9,19:18.6
6,9,19:18.6
-10,10,19:18.6
-6,10,19:18.6
3,10,19:18.6
4,10,19:18.6
5,10,19:18.6
-9,11,19:18.6
-7,11,19:18.6
-1,11,19:18.6
0,11,19:18.6
1,11,19:18.6
2,11,19:18.6
3,11,19:18.6
-9,12,19:18.6
-8,12,19:18.6
-7,12,19:18.6
-5,12,19:18.6
-4,12,19:18.6
-3,12,19:18.6
-2,12,19:18.6
-1,12,19:18.6
-8,13,19:18.6
-7,13,19:18.6
-6,13,19:18.6
-5,13,19:18.6
-8,14,19:18.6
-4,-11,20:18.6
-3,-11,20:18.6
-2,-11,20:18.6
-1,-11,20:18.6
0,-11,20:18.6
1,-11,20:18.6
-13,-10,20:18.6
-12,-10,20:18.6
-10,-10,20:18.6
-9,-10,20:18.6
-8,-10,20:18.6
-7,-10,20:18.6
-6,-10,20:18.6
-5,-10,20:18.6
-4,-10,20:18.6
2,-10,20:18.6
-12,-9,20:18.6
-11,-9,20:18.6
-10,-9,20:18.6
3,-9,20:18.6
-13,-8,20:18.6
-12,-8,20:18.6
-11,-8,20:18.6
4,-8,20:18.6
-13,-7,20:18.6
-10,-7,20:18.6
5,-7,20:18.6
-13,-6,20:18.6
-9,-6,20:18.6
6,-6,20:18.6
-13,-5,20:18.6
-8,-5,20:18.6
6,-5,20:18.6
7,-5,20:18.6
-14,-4,20:18.6
-13,-4,20:18.6
-7,-4,20:18.6
7,-4,20:18.6
8,-4,20:18.6
-14,-3,20:18.6
-6,-3,20:18.6
8,-3,20:18.6
9,-3,20:18.6
10,-3,20:18.6
11,-3,20:18.6
12,-3,20:18.6
-14,-2,20:18.6
-6,-2,20:18.6
-5,-2,20:18.6
6,-2,20:18.6
7,-2,20:18.6
8,-2,20:18.6
9,-2,20:18.6
10,-2,20:18.6
-14,-1,20:18.6
-5,-1,20:18.6
-4,-1,20:18.6
2,-1,20:18.6
3,-1,20:18.6
4,-1,20:18.6
5,-1,20:18.6
9,-1,20:18.6
-15,0,20:18.6
-4,0,20:18.6
-3,0,20:18.6
-2,0,20:18.6
-1,0,20:18.6
0,0,20:18.6
1,0,20:18.6
8,0,20:18.6
9,0,20:18.6
-15,1,20:18.6
-3,1,20:18.6
8,1,20:18.6
-15,2,20:18.6
-4,2,20:18.6
-3,2,20:18.6
8,2,20:18.6
-15,3,20:18.6
-4,3,20:18.6
7,3,20:18.6
8,3,20:18.6
-15,4,20:18.6
-14,4,20:18.6
-4,4,20:18.6
7,4,20:18.6
-14,5,20:18.6
-5,5,20:18.6
-4,5,20:18.6
7,5,20:18.6
-13,6,20:18.6
-5,6,20:18.6
6,6,20:18.6
7,6,20:18.6
-12,7,20:18.6
-5,7,20:18.6
6,7,20:18.6
-12,8,20:18.6
-11,8,20:18.6
-6,8,20:18.6
-5,8,20:18.6
6,8,20:18.6
-11,9,20:18.6
-10,9,20:18.6
-6,9,20:18.6
5,9,20:18.6
-10,10,20:18.6
-9,10,20:18.6
-6,10,20:18.6
2,10,20:18.6
3,10,20:18.6
4,10,20:18.6
5,10,20:18.6
-9,11,20:18.6
-8,11,20:18.6
-7,11,20:18.6
-2,11,20:18.6
-1,11,20:18.6
0,11,20:18.6
1,11,20:18.6
2,11,20:18.6
-8,12,20:18.6
-7,12,20:18.6
-6,12,20:18.6
-5,12,20:18.6
-4,12,20:18.6
-3,12,20:18.6
-2,12,20:18.6
-8,13,20:18.6
-7,13,20:18.6
-13,-11,21:18.6
-2,-11,21:18.6
-1,-11,21:18.6
0,-11,21:18.6
1,-11,21:18.6
-13,-10,21:18.6
-12,-10,21:18.6
-8,-10,21:18.6
-7,-10,21:18.6
-6,-10,21:18.6
-5,-10,21:18.6
-4,-10,21:18.6
-3,-10,21:18.6
-2,-10,21:18.6
1,-10,21:18.6
2,-10,21:18.6
-12,-9,21:18.6
-11,-9,21:18.6
-10,-9,21:18.6
-9,-9,21:18.6
-8,-9,21:18.6
2,-9,21:18.6
3,-9,21:18.6
-12,-8,21:18.6
-11,-8,21:18.6
3,-8,21:18.6
4,-8,21:18.6
-12,-7,21:18.6
-10,-7,21:18.6
4,-7,21:18.6
5,-7,21:18.6
-13,-6,21:18.6
-12,-6,21:18.6
-9,-6,21:18.6
5,-6,21:18.6
6,-6,21:18.6
-13,-5,21:18.6
-8,-5,21:18.6
6,-5,21:18.6
7,-5,21:18.6
-13,-4,21:18.6
-7,-4,21:18.6
7,-4,21:18.6
8,-4,21:18.6
-14,-3,21:18.6
-13,-3,21:18.6
-6,-3,21:18.6
8,-3,21:18.6
9,-3,21:18.6
10,-3,21:18.6
11,-3,21:18.6
12,-3,21:18.6
-14,-2,21:18.6
-6,-2,21:18.6
-5,-2,21:18.6
6,-2,21:18.6
7,-2,21:18.6
8,-2,21:18.6
9,-2,21:18.6
-14,-1,21:18.6
-5,-1,21:18.6
-4,-1,21:18.6
2,-1,21:18.6
3,-1,21:18.6
4,-1,21:18.6
5,-1,21:18.6
8,-1,21:18.6
9,-1,21:18.6
-14,0,21:18.6
-4,0,21:18.6
-3,0,21:18.6
-2,0,21:18.6
-1,0,21:18.6
0,0,21:18.6
1,0,21:18.6
8,0,21:18.6
-15,1,21:18.6
-14,1,21:18.6
-3,1,21:18.6
8,1,21:18.6
-15,2,21:18.6
-4,2,21:18.6
-3,2,21:18.6
7,2,21:18.6
8,2,21:18.6
-15,3,21:18.6
-4,3,21:18.6
7,3,21:18.6
-14,4,21:18.6
-4,4,21:18.6
7,4,21:18.6
-14,5,21:18.6
-13,5,21:18.6
-5,5,21:18.6
-4,5,21:18.6
6,5,21:18.6
7,5,21:18.6
-13,6,21:18.6
-12,6,21:18.6
-5,6,21:18.6
6,6,21:18.6
-12,7,21:18.6
-11,7,21:18.6
-5,7,21:18.6
6,7,21:18.6
-11,8,21:18.6
-10,8,21:18.6
-6,8,21:18.6
-5,8,21:18.6
5,8,21:18.6
-10,9,21:18.6
-6,9,21:18.6
4,9,21:18.6
5,9,21:18.6
-9,10,21:18.6
-6,10,21:18.6
0,10,21:18.6
1,10,21:18.6
2,10,21:18.6
3,10,21:18.6
4,10,21:18.6
-8,11,21:18.6
-7,11,21:18.6
-4,11,21:18.6
-3,11,21:18.6
-2,11,21:18.6
-1,11,21:18.6
0,11,21:18.6
-8,12,21:18.6
-7,12,21:18.6
-6,12,21:18.6
-5,12,21:18.6
-4,12,21:18.6
-8,13,21:18.6
0,-11,22:18.6
-12,-10,22:18.6
-6,-10,22:18.6
-5,-10,22:18.6
-4,-10,22:18.6
-3,-10,22:18.6
-2,-10,22:18.6
-1,-10,22:18.6
0,-10,22:18.6
1,-10,22:18.6
-12,-9,22:18.6
-11,-9,22:18.6
-10,-9,22:18.6
-9,-9,22:18.6
-8,-9,22:18.6
-6,-9,22:18.6
0,-9,22:18.6
1,-9,22:18.6
2,-9,22:18.6
-12,-8,22:18.6
-11,-8,22:18.6
2,-8,22:18.6
3,-8,22:18.6
-12,-7,22:18.6
-10,-7,22:18.6
3,-7,22:18.6
4,-7,22:18.6
-12,-6,22:18.6
-9,-6,22:18.6
4,-6,22:18.6
5,-6,22:18.6
-13,-5,22:18.6
-12,-5,22:18.6
-8,-5,22:18.6
5,-5,22:18.6
6,-5,22:18.6
-13,-4,22:18.6
-7,-4,22:18.6
6,-4,22:18.6
7,-4,22:18.6
-13,-3,22:18.6
-7,-3,22:18.6
-6,-3,22:18.6
7,-3,22:18.6
8,-3,22:18.6
10,-3,22:18.6
11,-3,22:18.6
12,-3,22:18.6
-13,-2,22:18.6
-6,-2,22:18.6
-5,-2,22:18.6
6,-2,22:18.6
7,-2,22:18.6
8,-2,22:18.6
9,-2,22:18.6
-14,-1,22:18.6
-13,-1,22:18.6
-5,-1,22:18.6
-4,-1,22:18.6
2,-1,22:18.6
3,-1,22:18.6
4,-1,22:18.6
5,-1,22:18.6
8,-1,22:18.6
-14,0,22:18.6
-4,0,22:18.6
-3,0,22:18.6
-2,0,22:18.6
-1,0,22:18.6
0,0,22:18.6
1,0,22:18.6
8,0,22:18.6
-14,1,22:18.6
-3,1,22:18.6
7,1,22:18.6
8,1,22:18.6
-15,2,22:18.6
-14,2,22:18.6
-4,2,22:18.6
-3,2,22:18.6
7,2,22:18.6
-15,3,22:18.6
-14,3,22:18.6
-4,3,22:18.6
6,3,22:18.6
7,3,22:18.6
-14,4,22:18.6
-13,4,22:18.6
-4,4,22:18.6
6,4,22:18.6
-13,5,22:18.6
-12,5,22:18.6
-5,5,22:18.6
-4,5,22:18.6
6,5,22:18.6
-12,6,22:18.6
-5,6,22:18.6
5,6,22:18.6
6,6,22:18.6
-11,7,22:18.6
-5,7,22:18.6
5,7,22:18.6
-11,8,22:18.6
-10,8,22:18.6
-6,8,22:18.6
4,8,22:18.6
5,8,22:18.6
-10,9,22:18.6
-9,9,22:18.6
-6,9,22:18.6
1,9,22:18.6
2,9,22:18.6
3,9,22:18.6
4,9,22:18.6
5,9,22:18.6
-9,10,22:18.6
-8,10,22:18.6
-6,10,22:18.6
-2,10,22:18.6
-1,10,22:18.6
0,10,22:18.6
1,10,22:18.6
2,10,22:18.6
3,10,22:18.6
-8,11,22:18.6
-7,11,22:18.6
-6,11,22:18.6
-5,11,22:18.6
-4,11,22:18.6
-3,11,22:18.6
-2,11,22:18.6
-7,12,22:18.6
-6,12,22:18.6
-8,13,22:18.6
-12,-10,23:18.6
-12,-9,23:18.6
-11,-9,23:18.6
-10,-9,23:18.6
-9,-9,23:18.6
-8,-9,23:18.6
-6,-9,23:18.6
-5,-9,23:18.6
-4,-9,23:18.6
-3,-9,23:18.6
-2,-9,23:18.6
-1,-9,23:18.6
0,-9,23:18.6
-11,-8,23:18.6
-10,-8,23:18.6
-9,-8,23:18.6
-8,-8,23:18.6
-7,-8,23:18.6
-6,-8,23:18.6
-5,-8,23:18.6
-4,-8,23:18.6
-3,-8,23:18.6
-2,-8,23:18.6
-1,-8,23:18.6
0,-8,23:18.6
1,-8,23:18.6
2,-8,23:18.6
-12,-7,23:18.6
-11,-7,23:18.6
-10,-7,23:18.6
1,-7,23:18.6
2,-7,23:18.6
3,-7,23:18.6
-12,-6,23:18.6
-11,-6,23:18.6
-9,-6,23:18.6
2,-6,23:18.6
3,-6,23:18.6
4,-6,23:18.6
-12,-5,23:18.6
-8,-5,23:18.6
3,-5,23:18.6
4,-5,23:18.6
5,-5,23:18.6
-12,-4,23:18.6
-7,-4,23:18.6
4,-4,23:18.6
5,-4,23:18.6
6,-4,23:18.6
-13,-3,23:18.6
-12,-3,23:18.6
-7,-3,23:18.6
-6,-3,23:18.6
5,-3,23:18.6
6,-3,23:18.6
7,-3,23:18.6
8,-3,23:18.6
10,-3,23:18.6
11,-3,23:18.6
-13,-2,23:18.6
-12,-2,23:18.6
-6,-2,23:18.6
-5,-2,23:18.6
6,-2,23:18.6
7,-2,23:18.6
8,-2,23:18.6
9,-2,23:18.6
10,-2,23:18.6
-13,-1,23:18.6
-12,-1,23:18.6
-5,-1,23:18.6
-4,-1,23:18.6
2,-1,23:18.6
3,-1,23:18.6
4,-1,23:18.6
5,-1,23:18.6
7,-1,23:18.6
8,-1,23:18.6
-13,0,23:18.6
-12,0,23:18.6
-4,0,23:18.6
-3,0,23:18.6
-2,0,23:18.6
-1,0,23:18.6
0,0,23:18.6
1,0,23:18.6
6,0,23:18.6
7,0,23:18.6
-13,1,23:18.6
-12,1,23:18.6
-3,1,23:18.6
6,1,23:18.6
7,1,23:18.6
-14,2,23:18.6
-13,2,23:18.6
-12,2,23:18.6
-4,2,23:18.6
-3,2,23:18.6
5,2,23:18.6
6,2,23:18.6
7,2,23:18.6
-14,3,23:18.6
-13,3,23:18.6
-12,3,23:18.6
-4,3,23:18.6
5,3,23:18.6
6,3,23:18.6
-13,4,23:18.6
-12,4,23:18.6
-11,4,23:18.6
-4,4,23:18.6
4,4,23:18.6
5,4,23:18.6
6,4,23:18.6
-12,5,23:18.6
-11,5,23:18.6
-10,5,23:18.6
-5,5,23:18.6
4,5,23:18.6
5,5,23:18.6
-11,6,23:18.6
-10,6,23:18.6
-5,6,23:18.6
3,6,23:18.6
4,6,23:18.6
5,6,23:18.6
-11,7,23:18.6
-10,7,23:18.6
-9,7,23:18.6
-5,7,23:18.6
2,7,23:18.6
3,7,23:18.6
4,7,23:18.6
-10,8,23:18.6
-9,8,23:18.6
-8,8,23:18.6
-6,8,23:18.6
0,8,23:18.6
1,8,23:18.6
2,8,23:18.6
3,8,23:18.6
4,8,23:18.6
-9,9,23:18.6
-8,9,23:18.6
-6,9,23:18.6
-3,9,23:18.6
-2,9,23:18.6
-1,9,23:18.6
0,9,23:18.6
1,9,23:18.6
2,9,23:18.6
-8,10,23:18.6
-7,10,23:18.6
-6,10,23:18.6
-5,10,23:18.6
-4,10,23:18.6
-3,10,23:18.6
-2,10,23:18.6
-1,10,23:18.6
-7,11,23:18.6
-6,11,23:18.6
-5,11,23:18.6
-4,11,23:18.6
-8,12,23:18.6
-7,12,23:18.6
-8,13,23:18.6
-12,-10,24:18.6
-12,-9,24:18.6
-11,-9,24:18.6
-11,-8,24:18.6
-10,-8,24:18.6
-9,-8,24:18.6
-8,-8,24:18.6
-7,-8,24:18.6
-6,-8,24:18.6
-5,-8,24:18.6
-4,-8,24:18.6
-3,-8,24:18.6
-2,-8,24:18.6
-1,-8,24:18.6
-11,-7,24:18.6
-10,-7,24:18.6
-9,-7,24:18.6
-8,-7,24:18.6
-7,-7,24:18.6
-6,-7,24:18.6
-5,-7,24:18.6
-4,-7,24:18.6
-3,-7,24:18.6
-2,-7,24:18.6
-1,-7,24:18.6
0,-7,24:18.6
-11,-6,24:18.6
-10,-6,24:18.6
-9,-6,24:18.6
-1,-6,24:18.6
0,-6,24:18.6
1,-6,24:18.6
2,-6,24:18.6
-11,-5,24:18.6
-10,-5,24:18.6
-8,-5,24:18.6
1,-5,24:18.6
2,-5,24:18.6
3,-5,24:18.6
-11,-4,24:18.6
-10,-4,24:18.6
-8,-4,24:18.6
-7,-4,24:18.6
2,-4,24:18.6
3,-4,24:18.6
4,-4,24:18.6
-11,-3,24:18.6
-10,-3,24:18.6
-7,-3,24:18.6
-6,-3,24:18.6
3,-3,24:18.6
4,-3,24:18.6
5,-3,24:18.6
-11,-2,24:18.6
-10,-2,24:18.6
-6,-2,24:18.6
-5,-2,24:18.6
4,-2,24:18.6
5,-2,24:18.6
6,-2,24:18.6
7,-2,24:18.6
8,-2,24:18.6
9,-2,24:18.6
10,-2,24:18.6
-12,-1,24:18.6
-11,-1,24:18.6
-10,-1,24:18.6
-5,-1,24:18.6
-4,-1,24:18.6
1,-1,24:18.6
2,-1,24:18.6
3,-1,24:18.6
4,-1,24:18.6
5,-1,24:18.6
6,-1,24:18.6
-12,0,24:18.6
-11,0,24:18.6
-4,0,24:18.6
-3,0,24:18.6
-2,0,24:18.6
-1,0,24:18.6
0,0,24:18.6
1,0,24:18.6
4,0,24:18.6
5,0,24:18.6
6,0,24:18.6
-12,1,24:18.6
-11,1,24:18.6
-3,1,24:18.6
4,1,24:18.6
5,1,24:18.6
-12,2,24:18.6
-11,2,24:18.6
-4,2,24:18.6
-3,2,24:18.6
4,2,24:18.6
5,2,24:18.6
-12,3,24:18.6
-11,3,24:18.6
-10,3,24:18.6
-4,3,24:18.6
3,3,24:18.6
4,3,24:18.6
-11,4,24:18.6
-10,4,24:18.6
-4,4,24:18.6
3,4,24:18.6
4,4,24:18.6
-10,5,24:18.6
-9,5,24:18.6
-5,5,24:18.6
2,5,24:18.6
3,5,24:18.6
-9,6,24:18.6
-8,6,24:18.6
-5,6,24:18.6
1,6,24:18.6
2,6,24:18.6
3,6,24:18.6
-9,7,24:18.6
-8,7,24:18.6
-7,7,24:18.6
-5,7,24:18.6
-2,7,24:18.6
-1,7,24:18.6
0,7,24:18.6
1,7,24:18.6
2,7,24:18.6
3,7,24:18.6
-8,8,24:18.6
-7,8,24:18.6
-6,8,24:18.6
-5,8,24:18.6
-4,8,24:18.6
-3,8,24:18.6
-2,8,24:18.6
-1,8,24:18.6
0,8,24:18.6
-7,9,24:18.6
-6,9,24:18.6
-5,9,24:18.6
-4,9,24:18.6
-3,9,24:18.6
-7,10,24:18.6
-6,10,24:18.6
-7,11,24:18.6
-8,12,24:18.6
-7,12,24:18.6
-8,13,24:18.6
-12,-10,25:18.6
-11,-9,25:18.6
-11,-8,25:18.6
-10,-8,25:18.6
-10,-7,25:18.6
-9,-6,25:18.6
-8,-6,25:18.6
-7,-6,25:18.6
-6,-6,25:18.6
-5,-6,25:18.6
-4,-6,25:18.6
-3,-6,25:18.6
-2,-6,25:18.6
-1,-6,25:18.6
-9,-5,25:18.6
-8,-5,25:18.6
-7,-5,25:18.6
-6,-5,25:18.6
-5,-5,25:18.6
-4,-5,25:18.6
-3,-5,25:18.6
-2,-5,25:18.6
-1,-5,25:18.6
0,-5,25:18.6
-10,-4,25:18.6
-9,-4,25:18.6
-8,-4,25:18.6
-7,-4,25:18.6
-1,-4,25:18.6
0,-4,25:18.6
1,-4,25:18.6
2,-4,25:18.6
-10,-3,25:18.6
-9,-3,25:18.6
-7,-3,25:18.6
-6,-3,25:18.6
1,-3,25:18.6
2,-3,25:18.6
3,-3,25:18.6
-10,-2,25:18.6
-9,-2,25:18.6
-6,-2,25:18.6
-5,-2,25:18.6
2,-2,25:18.6
3,-2,25:18.6
4,-2,25:18.6
8,-2,25:18.6
-10,-1,25:18.6
-9,-1,25:18.6
-5,-1,25:18.6
-4,-1,25:18.6
1,-1,25:18.6
2,-1,25:18.6
3,-1,25:18.6
4,-1,25:18.6
5,-1,25:18.6
6,-1,25:18.6
7,-1,25:18.6
-10,0,25:18.6
-9,0,25:18.6
-4,0,25:18.6
-3,0,25:18.6
-2,0,25:18.6
-1,0,25:18.6
0,0,25:18.6
1,0,25:18.6
3,0,25:18.6
4,0,25:18.6
-10,1,25:18.6
-9,1,25:18.6
-3,1,25:18.6
2,1,25:18.6
3,1,25:18.6
4,1,25:18.6
-10,2,25:18.6
-9,2,25:18.6
-4,2,25:18.6
2,2,25:18.6
3,2,25:18.6
-10,3,25:18.6
-9,3,25:18.6
-8,3,25:18.6
-4,3,25:18.6
1,3,25:18.6
2,3,25:18.6
3,3,25:18.6
-8,4,25:18.6
-7,4,25:18.6
-4,4,25:18.6
1,4,25:18.6
2,4,25:18.6
-8,5,25:18.6
-7,5,25:18.6
-5,5,25:18.6
-1,5,25:18.6
0,5,25:18.6
1,5,25:18.6
2,5,25:18.6
-7,6,25:18.6
-6,6,25:18.6
-5,6,25:18.6
-4,6,25:18.6
-3,6,25:18.6
-2,6,25:18.6
-1,6,25:18.6
0,6,25:18.6
1,6,25:18.6
-7,7,25:18.6
-6,7,25:18.6
-5,7,25:18.6
-4,7,25:18.6
-3,7,25:18.6
-2,7,25:18.6
-1,7,25:18.6
-6,8,25:18.6
-5,8,25:18.6
-4,8,25:18.6
-6,9,25:18.6
-7,10,25:18.6
-6,10,25:18.6
-7,11,25:18.6
-8,12,25:18.6
-11,-9,26:18.6
-11,-8,26:18.6
-10,-8,26:18.6
-10,-7,26:18.6
-9,-6,26:18.6
-8,-5,26:18.6
-7,-5,26:18.6
-6,-5,26:18.6
-5,-5,26:18.6
-4,-5,26:18.6
-3,-5,26:18.6
-8,-4,26:18.6
-7,-4,26:18.6
-6,-4,26:18.6
-5,-4,26:18.6
-4,-4,26:18.6
-3,-4,26:18.6
-2,-4,26:18.6
-1,-4,26:18.6
-8,-3,26:18.6
-7,-3,26:18.6
-6,-3,26:18.6
-5,-3,26:18.6
-4,-3,26:18.6
-3,-3,26:18.6
-2,-3,26:18.6
-1,-3,26:18.6
0,-3,26:18.6
1,-3,26:18.6
-8,-2,26:18.6
-7,-2,26:18.6
-6,-2,26:18.6
-5,-2,26:18.6
0,-2,26:18.6
1,-2,26:18.6
2,-2,26:18.6
-8,-1,26:18.6
-7,-1,26:18.6
-5,-1,26:18.6
-4,-1,26:18.6
1,-1,26:18.6
2,-1,26:18.6
3,-1,26:18.6
4,-1,26:18.6
5,-1,26:18.6
6,-1,26:18.6
7,-1,26:18.6
-8,0,26:18.6
-7,0,26:18.6
-4,0,26:18.6
-3,0,26:18.6
-2,0,26:18.6
-1,0,26:18.6
0,0,26:18.6
1,0,26:18.6
2,0,26:18.6
-9,1,26:18.6
-8,1,26:18.6
-7,1,26:18.6
-3,1,26:18.6
1,1,26:18.6
2,1,26:18.6
-8,2,26:18.6
-7,2,26:18.6
-4,2,26:18.6
0,2,26:18.6
1,2,26:18.6
2,2,26:18.6
-8,3,26:18.6
-7,3,26:18.6
-6,3,26:18.6
-4,3,26:18.6
0,3,26:18.6
1,3,26:18.6
-7,4,26:18.6
-6,4,26:18.6
-5,4,26:18.6
-4,4,26:18.6
-3,4,26:18.6
-2,4,26:18.6
-1,4,26:18.6
0,4,26:18.6
1,4,26:18.6
-6,5,26:18.6
-5,5,26:18.6
-4,5,26:18.6
-2,5,26:18.6
-1,5,26:18.6
0,5,26:18.6
-6,6,26:18.6
-5,6,26:18.6
-4,6,26:18.6
-3,6,26:18.6
-5,7,26:18.6
-6,8,26:18.6
-6,9,26:18.6
-7,10,26:18.6
-6,10,26:18.6
-7,11,26:18.6
-10,-8,27:18.6
-10,-7,27:18.6
-9,-7,27:18.6
-9,-6,27:18.6
-8,-5,27:18.6
-7,-4,27:18.6
-7,-3,27:18.6
-6,-3,27:18.6
-5,-3,27:18.6
-4,-3,27:18.6
-3,-3,27:18.6
-2,-3,27:18.6
-7,-2,27:18.6
-6,-2,27:18.6
-5,-2,27:18.6
-4,-2,27:18.6
-3,-2,27:18.6
-2,-2,27:18.6
-1,-2,27:18.6
-7,-1,27:18.6
-6,-1,27:18.6
-5,-1,27:18.6
-4,-1,27:18.6
-2,-1,27:18.6
-1,-1,27:18.6
0,-1,27:18.6
1,-1,27:18.6
2,-1,27:18.6
3,-1,27:18.6
4,-1,27:18.6
5,-1,27:18.6
6,-1,27:18.6
-7,0,27:18.6
-6,0,27:18.6
-4,0,27:18.6
-3,0,27:18.6
-2,0,27:18.6
-1,0,27:18.6
0,0,27:18.6
1,0,27:18.6
2,0,27:18.6
3,0,27:18.6
4,0,27:18.6
-7,1,27:18.6
-6,1,27:18.6
-3,1,27:18.6
-1,1,27:18.6
0,1,27:18.6
-7,2,27:18.6
-6,2,27:18.6
-5,2,27:18.6
-4,2,27:18.6
-2,2,27:18.6
-1,2,27:18.6
0,2,27:18.6
-6,3,27:18.6
-5,3,27:18.6
-4,3,27:18.6
-3,3,27:18.6
-2,3,27:18.6
-1,3,27:18.6
-5,4,27:18.6
-4,4,27:18.6
-3,4,27:18.6
-2,4,27:18.6
-5,5,27:18.6
-5,6,27:18.6
-5,7,27:18.6
-6,8,27:18.6
-6,9,27:18.6
-7,10,27:18.6
-9,-6,28:18.6
-8,-6,28:18.6
-8,-5,28:18.6
-7,-4,28:18.6
-6,-3,28:18.6
-6,-2,28:18.6
-5,-2,28:18.6
-4,-2,28:18.6
-3,-2,28:18.6
-5,-1,28:18.6
-4,-1,28:18.6
-3,-1,28:18.6
-2,-1,28:18.6
-5,0,28:18.6
-4,0,28:18.6
-3,0,28:18.6
-2,0,28:18.6
-1,0,28:18.6
0,0,28:18.6
1,0,28:18.6
2,0,28:18.6
3,0,28:18.6
4,0,28:18.6
5,0,28:18.6
-5,1,28:18.6
-4,1,28:18.6
-3,1,28:18.6
-2,1,28:18.6
-1,1,28:18.6
-5,2,28:18.6
-4,2,28:18.6
-3,2,28:18.6
-2,2,28:18.6
-4,3,28:18.6
-4,4,28:18.6
-5,5,28:18.6
-5,6,28:18.6
-5,7,28:18.6
-6,8,28:18.6
-5,-2,29:18.6
-4,-1,29:18.6
-4,0,29:18.6
-3,0,29:18.6
-2,0,29:18.6
-4,1,29:18.6
-3,1,29:18.6
-4,2,29:18.6
-4,3,29:18.6
-5,6,29:18.6
-5,7,29:18.6
