[META]
version=2.0
spawnOnBlockType=2
spawnSunlight=True
spawnDarkness=True
spawnWater=False
spawnLava=False
underFill=False
randomRotation=True
dig=True
tree=False
branch=False
needsFoundation=True
rarity=100
collisionPercentage=20
spawnElevationMin=0
spawnElevationMax=200
spawnInBiome=Custom
[DATA]
6,-2,-8:17.12
7,-2,-8:17.12
8,-1,-8:17.12
5,-2,-7:17.12
7,-2,-7:17.12
7,-1,-7:17.12
8,-1,-7:17.12
6,0,-7:17.12
6,-4,-6:17.12
7,-4,-6:17.12
5,-3,-6:17.12
6,-3,-6:17.12
7,-3,-6:17.12
9,-3,-6:17.12
5,-2,-6:17.12
6,-2,-6:17.12
7,-2,-6:17.12
8,-2,-6:17.12
9,-2,-6:17.12
5,-1,-6:17.12
6,-1,-6:17.12
7,-1,-6:17.12
9,-1,-6:17.12
6,0,-6:17.12
8,-4,-5:17.12
5,-3,-5:17.12
6,-3,-5:17.12
7,-3,-5:17.12
8,-3,-5:17.12
5,-2,-5:17.12
6,-2,-5:17.12
7,-2,-5:17.12
8,-2,-5:17.12
9,-2,-5:17.12
6,-1,-5:17.12
7,0,-5:17.12
5,-3,-4:17.12
6,-3,-4:17.12
6,-2,-4:17.12
7,-2,-4:17.12
8,-2,-4:17.12
5,-1,-4:17.12
7,-4,-3:17.12
5,-2,-3:17.12
6,-2,-3:17.12
7,-2,-3:17.12
8,-2,-3:17.12
4,-1,-3:17.12
5,-1,-3:17.12
6,-1,-3:17.12
7,0,-3:17.12
5,-4,-2:17.12
4,-3,-2:17.12
5,-3,-2:17.12
6,-3,-2:17.12
8,-3,-2:17.12
4,-2,-2:17.12
5,-2,-2:17.12
6,-2,-2:17.12
7,-2,-2:17.12
8,-2,-2:17.12
4,-1,-2:17.12
5,-1,-2:17.12
6,-1,-2:17.12
7,-1,-2:17.12
8,-1,-2:17.12
5,-4,-1:17.12
4,-3,-1:17.12
5,-3,-1:17.12
6,-3,-1:17.12
7,-3,-1:18.13
8,-3,-1:18.13
4,-2,-1:17.12
5,-2,-1:17.12
6,-2,-1:18.13
7,-2,-1:18.13
8,-2,-1:18.13
9,-2,-1:18.13
4,-1,-1:17.12
5,-1,-1:17.12
6,-1,-1:17.12
7,-1,-1:17.12
8,-1,-1:18.13
7,0,-1:18.13
8,0,-1:18.13
9,0,-1:18.13
5,-4,0:17.12
4,-3,0:17.12
5,-3,0:17.12
6,-3,0:17.12
7,-3,0:18.13
4,-2,0:17.12
6,-2,0:17.12
7,-2,0:18.13
8,-2,0:18.13
9,-2,0:18.13
4,-1,0:17.12
5,-1,0:17.12
6,-1,0:17.12
7,-1,0:18.13
8,-1,0:18.13
7,0,0:18.13
8,0,0:18.13
2,-5,1:18.14
3,-5,1:18.14
2,-4,1:18.14
4,-4,1:18.14
5,-4,1:18.14
6,-4,1:18.14
3,-3,1:18.14
4,-3,1:17.12
5,-3,1:17.12
6,-3,1:17.12
7,-3,1:18.13
4,-2,1:17.12
6,-2,1:17.12
7,-2,1:18.13
8,-2,1:18.13
9,-2,1:18.13
4,-1,1:17.12
5,-1,1:17.12
6,-1,1:17.12
7,-1,1:18.13
8,-1,1:18.13
7,0,1:18.13
8,0,1:18.13
2,-5,2:18.14
3,-5,2:18.14
4,-5,2:18.14
5,-5,2:18.14
2,-4,2:18.14
3,-4,2:18.14
4,-4,2:18.14
5,-4,2:18.14
6,-4,2:18.14
3,-3,2:18.14
4,-3,2:18.14
5,-3,2:17.12
3,-2,2:18.14
4,-2,2:17.12
5,-2,2:17.12
6,-2,2:17.12
7,-2,2:18.13
8,-2,2:18.13
4,-1,2:17.12
5,-1,2:17.12
6,-1,2:17.12
7,-1,2:18.13
8,-1,2:18.13
7,0,2:18.13
4,-5,3:18.14
5,-5,3:18.14
6,-5,3:18.14
2,-4,3:18.14
3,-4,3:18.14
4,-4,3:18.14
5,-4,3:18.14
6,-4,3:18.14
3,-3,3:18.14
4,-3,3:18.14
5,-3,3:18.14
6,-3,3:18.14
4,-2,3:17.12
5,-2,3:17.12
6,-2,3:17.12
7,-2,3:18.13
8,-2,3:18.13
5,-1,3:17.12
6,-1,3:17.12
7,-1,3:18.13
8,-1,3:18.13
3,-5,4:18.14
4,-5,4:18.14
5,-5,4:18.14
2,-4,4:18.14
3,-4,4:18.14
4,-4,4:18.14
5,-4,4:18.14
6,-4,4:18.14
7,-4,4:18.14
4,-3,4:18.14
5,-3,4:18.14
6,-3,4:18.14
4,-2,4:17.12
5,-2,4:17.12
6,-2,4:17.12
7,-2,4:18.13
8,-2,4:18.13
5,-1,4:17.12
6,-1,4:17.12
7,-1,4:18.13
8,-1,4:18.13
9,-6,5:18.13
3,-5,5:18.14
4,-5,5:18.14
5,-5,5:18.14
3,-4,5:18.14
4,-4,5:18.14
5,-4,5:18.14
6,-4,5:18.14
7,-4,5:18.14
4,-3,5:18.14
5,-3,5:18.14
6,-3,5:18.14
7,-3,5:18.14
4,-2,5:17.12
5,-2,5:17.12
6,-2,5:17.12
7,-2,5:18.13
8,-2,5:18.13
11,-2,5:18.13
5,-1,5:17.12
6,-1,5:17.12
7,-1,5:18.13
8,-1,5:18.13
0,-7,6:18.5
1,-7,6:18.13
2,-7,6:18.13
1,-6,6:18.13
2,-6,6:18.13
8,-6,6:18.13
9,-6,6:18.13
11,-6,6:18.13
12,-6,6:18.13
13,-6,6:18.5
4,-5,6:18.14
8,-5,6:18.13
9,-5,6:18.13
10,-5,6:18.13
11,-5,6:18.13
12,-5,6:18.13
-2,-4,6:18.5
-1,-4,6:18.5
3,-4,6:18.14
4,-4,6:18.14
5,-4,6:18.14
6,-4,6:18.14
11,-4,6:18.13
12,-4,6:18.13
-1,-3,6:18.5
5,-3,6:17.12
10,-3,6:18.13
11,-3,6:18.13
4,-2,6:17.12
5,-2,6:17.12
6,-2,6:17.12
8,-2,6:18.13
10,-2,6:18.13
5,-1,6:17.12
6,-1,6:17.12
8,-1,6:18.13
3,3,6:18.13
4,3,6:18.13
7,3,6:18.13
3,4,6:18.5
4,4,6:18.5
7,4,6:18.5
8,4,6:18.5
4,5,6:18.5
5,5,6:18.5
6,5,6:18.5
7,5,6:18.5
5,6,6:18.5
6,6,6:18.5
-2,-7,7:18.5
-1,-7,7:18.5
-2,-6,7:18.5
-1,-6,7:18.5
0,-6,7:18.13
1,-6,7:18.13
2,-6,7:18.13
-2,-5,7:18.5
-1,-5,7:18.5
0,-5,7:18.13
1,-5,7:18.13
2,-5,7:18.13
4,-5,7:18.14
8,-5,7:18.13
9,-5,7:18.13
10,-5,7:18.13
11,-5,7:18.13
-1,-4,7:18.5
0,-4,7:18.13
4,-4,7:18.14
5,-4,7:18.14
8,-4,7:18.13
9,-4,7:18.13
10,-4,7:18.13
11,-4,7:18.13
0,-3,7:18.13
1,-3,7:18.13
5,-3,7:17.12
9,-3,7:18.13
10,-3,7:18.13
4,-2,7:17.12
5,-2,7:17.12
6,-2,7:17.12
8,-2,7:17.12
9,-2,7:18.13
5,-1,7:17.12
6,-1,7:17.12
10,-1,7:18.13
10,0,7:18.13
11,0,7:18.13
11,1,7:18.13
4,2,7:18.13
6,2,7:18.13
1,3,7:18.13
4,3,7:18.13
5,3,7:18.13
6,3,7:18.13
7,3,7:18.13
8,3,7:18.13
5,4,7:18.5
6,4,7:18.5
5,5,7:18.5
6,5,7:18.5
5,6,7:18.5
5,-9,8:18.5
7,-9,8:18.5
4,-8,8:18.5
5,-8,8:18.5
7,-8,8:18.5
3,-7,8:18.13
4,-7,8:18.13
7,-7,8:18.13
8,-7,8:18.13
7,-6,8:18.13
8,-6,8:18.13
0,-5,8:18.13
2,-5,8:18.13
0,-4,8:18.13
1,-4,8:18.13
2,-4,8:18.13
3,-4,8:18.13
7,-4,8:18.13
8,-4,8:18.13
9,-4,8:18.13
1,-3,8:18.13
2,-3,8:18.13
4,-3,8:18.13
5,-3,8:18.13
6,-3,8:18.13
7,-3,8:18.13
8,-3,8:18.13
9,-3,8:18.13
-1,-2,8:18.5
4,-2,8:18.13
5,-2,8:17.12
6,-2,8:17.12
7,-2,8:18.13
8,-2,8:18.13
-1,-1,8:18.5
0,-1,8:18.13
1,-1,8:18.13
4,-1,8:18.13
5,-1,8:17.12
6,-1,8:18.13
9,-1,8:18.13
-1,0,8:18.5
0,0,8:18.13
1,0,8:18.13
5,0,8:18.13
9,0,8:18.13
10,0,8:18.13
-1,1,8:18.5
4,1,8:18.13
5,1,8:18.13
6,1,8:18.13
9,1,8:18.13
10,1,8:18.13
11,1,8:18.13
-1,2,8:18.5
0,2,8:18.13
1,2,8:18.13
2,2,8:18.13
4,2,8:18.13
5,2,8:18.13
6,2,8:18.13
7,2,8:18.13
8,2,8:18.13
9,2,8:18.13
10,2,8:18.13
11,2,8:18.13
0,3,8:18.5
1,3,8:18.13
8,3,8:18.13
9,3,8:18.13
10,3,8:18.13
11,3,8:18.5
4,4,8:18.5
8,4,8:18.5
11,4,8:18.5
5,5,8:18.5
7,5,8:18.5
6,-10,9:18.5
5,-9,9:18.5
6,-9,9:18.5
5,-8,9:18.5
6,-8,9:18.5
5,-7,9:18.13
6,-7,9:18.13
9,-7,9:18.13
10,-7,9:18.5
4,-6,9:18.13
5,-6,9:18.13
6,-6,9:18.13
7,-6,9:18.13
9,-6,9:18.13
11,-6,9:18.13
6,-5,9:18.13
7,-5,9:18.13
12,-5,9:18.13
-2,-4,9:18.5
-1,-4,9:18.5
0,-4,9:18.13
1,-4,9:18.13
2,-4,9:18.13
3,-4,9:18.13
11,-4,9:18.13
12,-4,9:18.13
-2,-3,9:18.5
-1,-3,9:18.5
2,-3,9:18.13
3,-3,9:18.13
4,-3,9:18.13
5,-3,9:18.13
6,-3,9:18.13
7,-3,9:18.13
8,-3,9:18.13
11,-3,9:18.13
-1,-2,9:18.5
3,-2,9:18.13
4,-2,9:18.13
5,-2,9:17.12
6,-2,9:17.12
7,-2,9:18.13
0,-1,9:18.13
1,-1,9:18.13
2,-1,9:18.13
4,-1,9:18.13
5,-1,9:18.13
6,-1,9:18.13
8,-1,9:18.13
1,0,9:18.13
2,0,9:18.13
5,0,9:18.13
6,0,9:18.13
8,0,9:18.13
9,0,9:18.13
0,1,9:18.13
1,1,9:18.13
2,1,9:18.13
3,1,9:18.13
5,1,9:18.13
6,1,9:18.13
7,1,9:18.13
8,1,9:18.13
9,1,9:18.13
-1,2,9:18.5
0,2,9:18.13
8,2,9:18.13
9,2,9:18.13
4,3,9:18.13
5,3,9:18.13
7,3,9:18.13
8,3,9:18.13
4,4,9:18.5
5,4,9:18.5
6,4,9:18.5
7,4,9:18.5
6,5,9:18.5
7,5,9:18.5
5,-6,10:18.13
9,-6,10:18.13
11,-6,10:18.13
5,-5,10:18.13
6,-5,10:18.13
9,-5,10:18.13
10,-5,10:18.13
11,-5,10:18.13
-2,-4,10:18.5
-1,-4,10:18.5
0,-4,10:18.13
1,-4,10:18.13
2,-4,10:18.13
3,-4,10:18.13
4,-4,10:18.13
5,-4,10:18.13
6,-4,10:18.13
10,-4,10:18.13
11,-4,10:18.13
-1,-3,10:18.5
0,-3,10:18.13
3,-3,10:18.13
4,-3,10:18.13
5,-3,10:18.13
6,-3,10:18.13
10,-3,10:18.13
1,-2,10:18.13
4,-2,10:18.13
5,-2,10:18.13
6,-2,10:18.13
7,-2,10:18.13
1,-1,10:18.13
2,-1,10:18.13
3,-1,10:18.13
5,-1,10:18.13
6,-1,10:18.13
7,-1,10:18.13
2,0,10:18.13
3,0,10:18.13
5,0,10:18.13
6,0,10:18.13
7,0,10:18.13
8,0,10:18.13
7,1,10:18.13
4,2,10:18.13
5,2,10:18.13
7,2,10:18.13
5,3,10:18.13
6,3,10:18.13
7,3,10:18.13
6,4,10:18.5
7,4,10:18.5
2,-6,11:18.13
3,-6,11:18.13
3,-5,11:18.13
4,-5,11:18.13
8,-5,11:18.13
9,-5,11:18.13
10,-5,11:18.13
11,-5,11:18.13
0,-4,11:18.13
5,-4,11:18.13
8,-4,11:18.13
9,-4,11:18.13
10,-4,11:18.13
0,-3,11:18.13
1,-3,11:18.13
2,-3,11:18.13
3,-3,11:18.13
4,-3,11:18.13
5,-3,11:18.13
6,-3,11:18.13
9,-3,11:18.13
1,-2,11:18.13
2,-2,11:18.13
4,-2,11:18.13
5,-2,11:18.13
6,-2,11:18.13
7,-2,11:18.13
3,-1,11:18.13
4,-1,11:18.13
5,-1,11:18.13
6,-1,11:18.13
7,-1,11:18.13
12,-1,11:18.13
4,0,11:18.13
5,1,11:18.13
6,1,11:18.13
7,1,11:18.13
2,2,11:18.13
5,2,11:18.13
6,2,11:18.13
7,2,11:18.13
2,3,11:18.13
6,3,11:18.13
3,4,11:18.5
5,4,11:18.5
6,4,11:18.5
3,5,11:18.5
4,5,11:18.5
5,5,11:18.5
-1,-7,12:18.5
0,-7,12:18.5
-1,-6,12:18.5
0,-6,12:18.5
1,-6,12:18.13
2,-6,12:18.13
0,-5,12:18.5
2,-5,12:18.13
3,-5,12:18.13
4,-5,12:18.13
11,-5,12:18.5
0,-4,12:18.5
1,-4,12:18.13
4,-4,12:18.13
7,-4,12:18.13
8,-4,12:18.13
9,-4,12:18.13
10,-4,12:18.13
11,-4,12:18.5
12,-4,12:18.5
1,-3,12:18.13
2,-3,12:18.13
3,-3,12:18.13
4,-3,12:18.13
5,-3,12:18.13
6,-3,12:18.13
7,-3,12:18.13
8,-3,12:18.13
12,-3,12:18.5
1,-2,12:18.13
2,-2,12:18.13
3,-2,12:18.13
4,-2,12:18.13
5,-2,12:18.13
6,-2,12:18.13
11,-2,12:18.5
12,-2,12:18.5
13,-2,12:18.5
4,-1,12:18.13
5,-1,12:18.13
6,-1,12:18.13
7,-1,12:18.13
11,-1,12:18.5
12,-1,12:18.5
5,0,12:18.13
6,0,12:18.13
5,1,12:18.13
6,1,12:18.13
2,2,12:18.13
3,2,12:18.13
3,3,12:18.13
5,3,12:18.13
6,3,12:18.13
3,4,12:18.5
4,4,12:18.5
5,4,12:18.5
4,5,12:18.5
0,-6,13:18.5
1,-6,13:18.13
0,-5,13:18.5
1,-5,13:18.13
2,-5,13:18.13
3,-5,13:18.13
1,-4,13:18.13
2,-4,13:18.13
3,-4,13:18.13
4,-4,13:18.13
10,-4,13:18.13
2,-3,13:18.13
4,-3,13:18.13
5,-3,13:18.13
6,-3,13:18.13
7,-3,13:18.13
10,-3,13:18.13
11,-3,13:18.5
12,-3,13:18.5
3,-2,13:18.13
4,-2,13:18.13
5,-2,13:18.13
6,-2,13:18.13
7,-2,13:18.13
10,-2,13:18.13
11,-2,13:18.5
4,-1,13:18.13
5,-1,13:18.13
6,-1,13:18.13
10,-1,13:18.13
5,0,13:18.13
6,0,13:18.13
3,1,13:18.13
3,2,13:18.13
4,2,13:18.13
5,2,13:18.13
6,2,13:18.13
4,3,13:18.13
5,3,13:18.13
4,4,13:18.5
6,-7,14:18.5
7,-7,14:18.5
8,-7,14:18.5
9,-7,14:18.5
5,-6,14:18.13
6,-6,14:18.13
8,-6,14:18.13
1,-5,14:18.13
2,-5,14:18.13
5,-5,14:18.13
8,-5,14:18.13
1,-4,14:18.13
2,-4,14:18.13
3,-4,14:18.13
4,-4,14:18.13
8,-4,14:18.13
0,-3,14:18.5
1,-3,14:18.13
2,-3,14:18.13
3,-3,14:18.13
4,-3,14:18.13
5,-3,14:18.13
6,-3,14:18.13
8,-3,14:18.13
9,-3,14:18.13
10,-3,14:18.13
3,-2,14:18.13
4,-2,14:18.13
5,-2,14:18.13
6,-2,14:18.13
7,-2,14:18.13
9,-2,14:18.13
10,-2,14:18.13
0,-1,14:18.5
1,-1,14:18.13
4,-1,14:18.13
5,-1,14:18.13
6,-1,14:18.13
9,-1,14:18.13
1,0,14:18.13
4,0,14:18.13
5,0,14:18.13
4,1,14:18.13
5,1,14:18.13
6,1,14:18.13
4,2,14:18.13
5,2,14:18.13
9,2,14:18.13
8,3,14:18.13
9,3,14:18.13
6,4,14:18.5
7,4,14:18.5
9,-8,15:18.5
7,-7,15:18.5
8,-7,15:18.5
6,-6,15:18.13
7,-6,15:18.13
8,-6,15:18.13
5,-5,15:18.13
6,-5,15:18.13
8,-5,15:18.13
3,-4,15:18.13
7,-4,15:18.13
8,-4,15:18.13
1,-3,15:18.13
2,-3,15:18.13
3,-3,15:18.13
4,-3,15:18.13
5,-3,15:18.13
7,-3,15:18.13
8,-3,15:18.13
1,-2,15:18.13
4,-2,15:18.13
5,-2,15:18.13
6,-2,15:18.13
7,-2,15:18.13
8,-2,15:18.13
9,-2,15:18.13
1,-1,15:18.13
2,-1,15:18.13
5,-1,15:18.13
6,-1,15:18.13
4,0,15:18.13
5,0,15:18.13
6,0,15:18.13
5,1,15:18.13
8,1,15:18.13
6,2,15:18.13
8,2,15:18.13
6,3,15:18.13
7,3,15:18.13
8,3,15:18.13
7,4,15:18.5
8,4,15:18.5
7,-6,16:18.13
8,-6,16:18.13
4,-5,16:18.13
6,-5,16:18.13
7,-5,16:18.13
2,-4,16:18.13
5,-4,16:18.13
6,-4,16:18.13
7,-4,16:18.13
2,-3,16:18.13
3,-3,16:18.13
4,-3,16:18.13
5,-3,16:18.13
7,-3,16:18.13
1,-2,16:18.13
2,-2,16:18.13
3,-2,16:18.13
5,-2,16:18.13
6,-2,16:18.13
7,-2,16:18.13
2,-1,16:18.13
3,-1,16:18.13
5,-1,16:18.13
6,-1,16:18.13
2,1,16:18.13
6,1,16:18.13
7,1,16:18.13
8,1,16:18.13
6,2,16:18.13
7,2,16:18.13
3,3,16:18.13
4,3,16:18.13
5,3,16:18.13
7,3,16:18.13
2,-6,17:18.13
3,-6,17:18.13
2,-5,17:18.13
3,-5,17:18.13
4,-5,17:18.13
7,-5,17:18.13
2,-4,17:18.13
4,-4,17:18.13
5,-4,17:18.13
6,-4,17:18.13
7,-4,17:18.13
2,-3,17:18.13
3,-3,17:18.13
5,-3,17:18.13
6,-3,17:18.13
7,-3,17:18.13
9,-3,17:18.13
10,-3,17:18.13
3,-2,17:18.13
4,-2,17:18.13
5,-2,17:17.12
6,-2,17:18.13
10,-2,17:18.13
11,-2,17:18.5
3,-1,17:18.13
4,-1,17:18.13
5,-1,17:17.12
6,-1,17:17.12
10,-1,17:18.13
11,-1,17:18.5
6,0,17:18.13
7,0,17:18.13
10,0,17:18.13
3,1,17:18.13
6,1,17:18.13
7,1,17:18.13
3,2,17:18.13
4,2,17:18.13
5,2,17:18.13
3,3,17:18.13
4,3,17:18.13
5,-6,18:18.13
2,-5,18:18.13
3,-5,18:18.13
3,-4,18:18.13
4,-4,18:18.13
5,-4,18:18.13
8,-4,18:18.13
3,-3,18:18.13
5,-3,18:18.13
6,-3,18:18.13
9,-3,18:18.13
4,-2,18:18.13
5,-2,18:17.12
6,-2,18:17.12
8,-2,18:18.13
9,-2,18:18.13
10,-2,18:18.13
5,-1,18:17.12
6,-1,18:18.13
8,-1,18:18.13
9,-1,18:18.13
10,-1,18:18.13
4,0,18:18.13
6,0,18:18.13
4,1,18:18.13
5,1,18:18.13
4,2,18:18.13
6,-7,19:18.5
7,-7,19:18.5
8,-7,19:18.5
5,-6,19:18.13
6,-6,19:18.13
7,-6,19:18.13
8,-6,19:18.13
5,-5,19:18.13
7,-5,19:18.13
3,-4,19:18.13
4,-4,19:18.13
7,-4,19:18.13
2,-3,19:18.13
4,-3,19:18.13
5,-3,19:18.13
7,-3,19:18.13
1,-2,19:18.13
2,-2,19:18.13
4,-2,19:18.13
5,-2,19:17.12
6,-2,19:17.12
7,-2,19:18.13
8,-2,19:18.13
0,-1,19:18.5
1,-1,19:18.13
5,-1,19:17.12
6,-1,19:17.12
7,-1,19:18.13
8,-1,19:18.13
1,0,19:18.13
2,0,19:18.13
4,0,19:18.13
5,0,19:18.13
9,1,19:18.13
8,2,19:18.13
9,2,19:18.13
7,3,19:18.13
8,3,19:18.13
9,3,19:18.13
7,-7,20:18.5
6,-6,20:18.13
7,-6,20:18.13
5,-5,20:18.13
6,-5,20:18.13
7,-5,20:18.13
5,-4,20:18.13
6,-4,20:18.13
7,-4,20:18.13
5,-3,20:18.13
6,-3,20:18.13
7,-3,20:18.13
2,-2,20:18.13
3,-2,20:18.13
4,-2,20:18.13
5,-2,20:18.13
6,-2,20:18.13
7,-2,20:18.13
1,-1,20:18.13
2,-1,20:18.13
3,-1,20:18.13
5,-1,20:18.13
6,-1,20:17.12
7,-1,20:18.13
3,0,20:18.13
7,1,20:18.13
8,1,20:18.13
7,2,20:18.13
8,2,20:18.13
6,-5,21:18.13
7,-5,21:18.13
6,-4,21:18.13
7,-4,21:18.13
5,-3,21:18.13
6,-3,21:18.13
3,-2,21:18.13
4,-2,21:18.13
5,-2,21:17.12
6,-2,21:17.12
10,-2,21:18.13
3,-1,21:18.13
4,-1,21:18.13
5,-1,21:18.13
6,-1,21:18.13
7,-1,21:18.13
10,-1,21:18.13
3,0,21:18.13
6,0,21:18.13
7,0,21:18.13
9,0,21:18.13
10,0,21:18.13
3,1,21:18.13
5,1,21:18.13
6,1,21:18.13
7,1,21:18.13
2,2,21:18.13
4,2,21:18.13
5,2,21:18.13
5,-7,22:18.5
4,-6,22:18.13
5,-6,22:18.13
6,-6,22:18.13
4,-5,22:18.13
5,-3,22:18.13
6,-3,22:18.13
4,-2,22:18.13
5,-2,22:18.13
6,-2,22:18.13
9,-2,22:18.13
4,-1,22:18.13
5,-1,22:18.13
6,-1,22:18.13
9,-1,22:18.13
10,-1,22:18.13
3,0,22:18.13
4,0,22:18.13
6,0,22:18.13
8,0,22:18.13
9,0,22:18.13
3,1,22:18.13
4,1,22:18.13
5,1,22:18.13
2,2,22:18.13
3,2,22:18.13
4,2,22:18.13
2,3,22:18.13
5,-6,23:18.13
4,-5,23:18.13
5,-5,23:18.13
6,-5,23:18.13
4,-3,23:18.13
5,-3,23:18.13
6,-3,23:18.13
4,-2,23:18.13
5,-2,23:18.13
6,-2,23:18.13
7,-2,23:18.13
8,-2,23:18.13
9,-2,23:18.13
4,-1,23:18.13
5,-1,23:18.13
6,-1,23:18.13
7,-1,23:18.13
8,-1,23:18.13
9,-1,23:18.13
4,0,23:18.13
5,0,23:18.13
8,0,23:18.13
3,1,23:18.13
4,1,23:18.13
5,1,23:18.13
3,2,23:18.13
5,-5,24:18.13
5,-4,24:18.13
6,-4,24:18.13
5,-3,24:18.13
6,-3,24:18.13
5,-2,24:18.13
6,-2,24:18.13
7,-2,24:18.13
8,-2,24:18.13
4,-1,24:18.13
5,-1,24:18.13
6,-1,24:18.13
7,-1,24:18.13
8,-1,24:18.13
4,0,24:18.13
5,0,24:18.13
4,1,24:18.13
7,-5,25:18.13
8,-5,25:18.13
9,-5,25:18.13
2,-4,25:18.13
9,-4,25:18.13
1,-3,25:18.13
5,-3,25:18.13
6,-3,25:18.13
9,-3,25:18.13
1,-2,25:18.13
5,-2,25:18.13
6,-2,25:18.13
7,-2,25:18.13
5,-1,25:18.13
6,-1,25:18.13
7,-1,25:18.13
5,0,25:18.13
8,0,25:18.13
5,1,25:18.13
6,1,25:18.13
8,1,25:18.13
6,2,25:18.13
8,2,25:18.13
7,3,25:18.13
8,3,25:18.13
7,-5,26:18.13
8,-5,26:18.13
1,-4,26:18.13
2,-4,26:18.13
3,-4,26:18.13
7,-4,26:18.13
8,-4,26:18.13
9,-4,26:18.13
1,-3,26:18.13
2,-3,26:18.13
8,-3,26:18.13
9,-3,26:18.13
2,-2,26:18.13
5,-2,26:18.13
6,-2,26:18.13
5,-1,26:18.13
6,-1,26:18.13
7,0,26:18.13
8,0,26:18.13
6,1,26:18.13
7,1,26:18.13
8,1,26:18.13
6,2,26:18.13
7,2,26:18.13
7,3,26:18.13
4,-5,27:18.13
6,-5,27:18.13
3,-4,27:18.13
6,-4,27:18.13
7,-4,27:18.13
8,-4,27:18.13
2,-3,27:18.13
3,-3,27:18.13
7,-3,27:18.13
8,-3,27:18.13
3,-2,27:18.13
5,-2,27:17.12
6,-2,27:18.13
2,-1,27:18.13
5,-1,27:17.12
6,-1,27:17.12
9,-1,27:18.13
2,0,27:18.13
6,0,27:18.13
7,0,27:18.13
9,0,27:18.13
2,1,27:18.13
3,1,27:18.13
4,1,27:18.13
6,1,27:18.13
7,1,27:18.13
8,1,27:18.13
9,1,27:18.13
7,2,27:18.13
4,-6,28:18.13
5,-6,28:18.13
4,-5,28:18.13
5,-5,28:18.13
6,-5,28:18.13
4,-4,28:18.13
6,-4,28:18.13
4,-3,28:18.13
6,-3,28:18.13
7,-3,28:18.13
4,-2,28:18.13
5,-2,28:17.12
6,-2,28:17.12
7,-2,28:18.13
3,-1,28:18.13
5,-1,28:17.12
6,-1,28:18.13
7,-1,28:18.13
9,-1,28:18.13
2,0,28:18.13
3,0,28:18.13
6,0,28:18.13
7,0,28:18.13
9,0,28:18.13
2,1,28:18.13
3,1,28:18.13
4,1,28:18.13
7,1,28:18.13
8,1,28:18.13
9,1,28:18.13
5,-5,29:18.13
4,-4,29:18.13
5,-4,29:18.13
6,-4,29:18.13
6,-3,29:18.13
4,-2,29:18.13
5,-2,29:18.13
6,-2,29:18.13
3,-1,29:18.13
4,-1,29:18.13
5,-1,29:17.12
6,-1,29:18.13
8,-1,29:18.13
3,0,29:18.13
4,0,29:18.13
6,0,29:18.13
7,0,29:18.13
8,0,29:18.13
5,-4,30:18.13
6,-4,30:18.13
5,-3,30:18.13
6,-3,30:18.13
7,-3,30:18.13
4,-2,30:18.13
5,-2,30:17.12
6,-2,30:17.12
4,-1,30:18.13
5,-1,30:17.12
6,-1,30:17.12
7,-1,30:18.13
8,-1,30:18.13
4,0,30:18.13
5,0,30:18.13
7,0,30:18.13
3,-4,31:18.13
7,-4,31:18.13
8,-4,31:18.13
5,-3,31:18.13
6,-3,31:18.13
8,-3,31:18.13
5,-2,31:17.12
6,-2,31:17.12
4,-1,31:18.13
5,-1,31:18.13
6,-1,31:18.13
7,-1,31:18.13
8,-1,31:18.13
4,0,31:18.13
6,0,31:18.13
7,0,31:18.13
5,1,31:18.13
6,1,31:18.13
8,1,31:18.13
6,-4,32:18.13
7,-4,32:18.13
8,-4,32:18.13
2,-3,32:18.13
3,-3,32:18.13
5,-3,32:18.13
6,-3,32:18.13
8,-3,32:18.13
2,-2,32:18.13
3,-2,32:18.13
5,-2,32:18.13
6,-2,32:17.12
8,-2,32:18.13
5,-1,32:18.13
6,-1,32:18.13
7,-1,32:18.13
7,0,32:18.13
5,1,32:18.13
6,1,32:18.13
7,1,32:18.13
6,2,32:18.13
7,2,32:18.13
5,-5,33:18.13
6,-5,33:18.13
3,-3,33:18.13
4,-3,33:18.13
6,-3,33:18.13
7,-3,33:18.13
3,-2,33:18.13
4,-2,33:18.13
5,-2,33:17.12
6,-2,33:17.12
7,-2,33:18.13
3,-1,33:18.13
5,-1,33:18.13
6,-1,33:18.13
7,-1,33:18.13
8,-1,33:18.13
9,-1,33:18.13
3,0,33:18.13
4,0,33:18.13
6,0,33:18.13
7,0,33:18.13
8,0,33:18.13
4,1,33:18.13
6,1,33:18.13
7,1,33:18.13
4,-5,34:18.13
5,-5,34:18.13
5,-4,34:18.13
6,-4,34:18.13
4,-2,34:18.13
5,-2,34:18.13
6,-2,34:18.13
8,-2,34:18.13
4,-1,34:18.13
5,-1,34:17.12
6,-1,34:18.13
7,-1,34:18.13
8,-1,34:18.13
4,0,34:18.13
6,0,34:18.13
7,0,34:18.13
4,1,34:18.13
5,-4,35:18.13
3,-3,35:18.13
4,-3,35:18.13
5,-3,35:18.13
6,-3,35:18.13
8,-3,35:18.13
5,-2,35:17.12
6,-2,35:17.12
8,-2,35:18.13
4,-1,35:18.13
5,-1,35:18.13
6,-1,35:17.12
7,-1,35:18.13
8,-1,35:18.13
4,0,35:18.13
5,0,35:18.13
5,1,35:18.13
6,1,35:18.13
4,-3,36:18.13
5,-3,36:18.13
6,-3,36:18.13
8,-3,36:18.13
4,-2,36:18.13
5,-2,36:17.12
6,-2,36:17.12
7,-2,36:18.13
8,-2,36:18.13
5,-1,36:18.13
6,-1,36:18.13
7,-1,36:18.13
8,-1,36:18.13
4,0,36:18.13
5,0,36:18.13
6,0,36:18.13
6,1,36:18.13
6,-4,37:18.13
4,-2,37:18.13
5,-2,37:18.13
6,-2,37:17.12
7,-2,37:18.13
5,-1,37:18.13
6,-1,37:17.12
7,-1,37:18.13
5,0,37:18.13
6,0,37:18.13
5,-4,38:18.13
6,-4,38:18.13
6,-3,38:18.13
7,-3,38:18.13
5,-2,38:18.13
6,-2,38:17.12
7,-2,38:18.13
4,-1,38:18.13
5,-1,38:18.13
6,-1,38:17.12
8,-1,38:18.13
4,0,38:18.13
7,0,38:18.13
5,-3,39:18.13
6,-3,39:18.13
5,-2,39:18.13
6,-2,39:18.13
7,-2,39:18.13
4,-1,39:18.13
5,-1,39:18.13
6,-1,39:18.13
7,-1,39:18.13
8,-1,39:18.13
4,0,39:18.13
7,0,39:18.13
5,-3,40:18.13
6,-3,40:18.13
5,-2,40:18.13
6,-2,40:18.13
7,-2,40:18.13
5,-1,40:18.13
6,-1,40:18.13
7,-1,40:18.13
6,-3,41:18.13
4,-2,41:18.13
5,-2,41:18.13
6,-2,41:18.13
7,-2,41:18.13
5,-1,41:18.13
6,-1,41:18.13
6,-3,42:18.13
4,-2,42:18.13
5,-2,42:18.13
6,-2,42:18.13
7,-2,42:18.13
6,-1,42:17.12
5,0,42:18.13
6,0,42:18.13
7,0,42:18.13
4,-2,43:18.13
5,-2,43:18.13
6,-2,43:18.13
6,-1,43:17.12
6,0,43:18.13
5,-2,44:18.13
6,-2,44:17.12
6,-1,44:18.13
6,-3,45:18.13
6,-2,45:17.12
4,-1,45:18.13
6,-1,45:17.12
7,-1,45:18.13
4,0,45:18.13
7,0,45:18.13
5,-3,46:18.13
6,-3,46:18.13
6,-2,46:17.12
5,-1,46:18.13
6,-1,46:18.13
7,-1,46:18.13
6,-2,47:18.13
5,-1,47:18.13
6,-1,47:18.13
6,-2,48:17.12
6,-1,48:17.12
6,-2,49:17.12
6,-1,49:17.12
6,-2,50:17.12
6,-1,50:17.12
6,-2,51:17.12
6,-1,51:17.12
6,-1,52:17.12
6,-1,53:17.12
6,-1,54:17.12
