[META]
version=2.0
spawnOnBlockType=2
spawnSunlight=True
spawnDarkness=True
spawnWater=False
spawnLava=False
underFill=False
randomRotation=True
dig=True
tree=False
branch=False
needsFoundation=True
rarity=100
collisionPercentage=20
spawnElevationMin=0
spawnElevationMax=200
spawnInBiome=Custom
[DATA]
0,0,-8:17.12
-1,1,-8:17.12
-1,2,-8:17.12
-1,-1,-7:17.12
0,-1,-7:17.12
-2,0,-7:17.12
-1,0,-7:17.12
0,1,-7:17.12
-1,2,-7:17.12
-1,3,-7:17.12
-1,-1,-6:17.12
-3,0,-6:17.12
-2,0,-6:17.12
-1,0,-6:17.12
0,0,-6:17.12
-3,1,-6:17.12
-2,1,-6:17.12
-1,1,-6:17.12
0,1,-6:17.12
-2,2,-6:17.12
-1,2,-6:17.12
-1,3,-6:17.12
-2,-2,-5:17.12
-2,-1,-5:17.12
-3,0,-5:17.12
-2,0,-5:17.12
-1,0,-5:17.12
0,0,-5:17.12
-2,1,-5:17.12
-1,1,-5:17.12
0,1,-5:17.12
0,2,-5:17.12
-1,3,-5:17.12
0,3,-5:17.12
-1,-2,-4:17.12
0,-2,-4:17.12
-3,-1,-4:17.12
-2,-1,-4:17.12
-1,-1,-4:17.12
0,-1,-4:17.12
1,-1,-4:17.12
-2,0,-4:17.12
-1,0,-4:17.12
0,0,-4:17.12
1,0,-4:17.12
-2,1,-4:17.12
-1,1,-4:17.12
0,1,-4:17.12
-2,2,-4:17.12
-1,2,-4:17.12
0,2,-4:17.12
0,-2,-3:17.12
-3,-1,-3:17.12
-1,-1,-3:17.12
1,-1,-3:17.12
-2,0,-3:17.12
-1,0,-3:17.12
1,0,-3:17.12
-1,1,-3:17.12
-1,2,-3:17.12
-2,-1,-2:17.12
-1,-1,-2:17.12
0,-1,-2:17.12
-2,0,-2:17.12
-1,0,-2:17.12
0,0,-2:17.12
-2,1,-2:17.12
-1,1,-2:17.12
0,1,-2:17.12
-2,2,-2:17.12
-1,2,-2:17.12
-2,-1,-1:17.12
-1,-1,-1:17.12
0,-1,-1:17.12
-2,0,-1:17.12
0,0,-1:17.12
-2,1,-1:17.12
0,1,-1:17.12
-2,2,-1:17.12
-1,2,-1:17.12
-2,-1,0:17.12
-1,-1,0:17.12
-2,0,0:17.12
0,0,0:17.12
-2,1,0:17.12
0,1,0:17.12
-1,2,0:17.12
-1,-1,1:17.12
-2,0,1:17.12
0,0,1:17.12
-2,1,1:17.12
-1,1,1:17.12
0,1,1:17.12
-2,0,2:17.12
-1,0,2:17.12
0,0,2:17.12
-2,1,2:17.12
-1,1,2:17.12
0,1,2:17.12
-2,0,3:17.12
-1,0,3:17.12
-2,1,3:17.12
-1,1,3:17.12
0,1,3:17.12
-2,0,4:17.12
-1,0,4:17.12
-2,1,4:17.12
-1,1,4:17.12
-2,0,5:17.12
-1,0,5:17.12
-2,1,5:17.12
-1,1,5:17.12
-9,-3,6:18.5
-8,-3,6:18.5
-7,-3,6:18.5
-6,-3,6:18.13
-5,-3,6:18.13
4,-2,6:18.13
-9,-1,6:18.5
-9,0,6:18.5
-8,0,6:18.5
-2,0,6:17.12
-1,0,6:17.12
-8,1,6:18.5
-7,1,6:18.5
-2,1,6:17.12
-1,1,6:17.12
2,6,6:18.5
-2,7,6:18.5
2,7,6:18.5
2,-6,7:18.5
3,-6,7:18.5
1,-5,7:18.5
2,-5,7:18.5
3,-5,7:18.5
4,-5,7:18.5
1,-4,7:18.13
4,-4,7:18.5
-5,-3,7:18.13
3,-3,7:18.13
4,-3,7:18.13
-10,-2,7:18.5
-9,-2,7:18.5
-8,-2,7:18.5
-7,-2,7:18.5
-6,-2,7:18.13
-5,-2,7:18.13
3,-2,7:18.13
4,-2,7:18.13
-9,-1,7:18.5
-8,-1,7:18.5
-7,-1,7:18.5
3,-1,7:18.13
-8,0,7:18.5
-7,0,7:18.5
-6,0,7:18.13
-2,0,7:17.12
-1,0,7:17.12
-6,1,7:18.13
-2,1,7:17.12
-1,1,7:17.12
2,5,7:18.13
-2,6,7:18.5
-1,6,7:18.5
1,6,7:18.5
2,6,7:18.5
-2,7,7:18.5
-1,7,7:18.5
0,7,7:18.5
1,7,7:18.5
2,7,7:18.5
-1,8,7:18.5
0,8,7:18.5
1,8,7:18.5
2,8,7:18.5
-1,9,7:18.5
0,9,7:18.5
1,9,7:18.5
-4,-6,8:18.5
-4,-5,8:18.5
0,-5,8:18.5
3,-5,8:18.5
4,-5,8:18.5
-4,-4,8:18.13
0,-4,8:18.13
1,-4,8:18.13
2,-4,8:18.13
3,-4,8:18.13
-4,-3,8:18.13
0,-3,8:18.13
1,-3,8:18.13
2,-3,8:18.13
3,-3,8:18.13
-5,-2,8:18.13
-4,-2,8:18.13
2,-2,8:18.13
3,-2,8:18.13
-7,-1,8:18.5
-6,-1,8:18.13
-5,-1,8:18.13
-4,-1,8:18.13
2,-1,8:18.13
-6,0,8:18.13
-5,0,8:18.13
-2,0,8:17.12
-1,0,8:17.12
4,0,8:18.5
5,0,8:18.5
-5,1,8:18.13
-2,1,8:17.12
-1,1,8:17.12
-7,2,8:18.5
-1,2,8:18.13
-7,3,8:18.5
1,4,8:18.13
3,4,8:18.13
4,4,8:18.5
-2,5,8:18.13
-1,5,8:18.13
0,5,8:18.13
1,5,8:18.13
-6,6,8:18.5
-5,6,8:18.5
-4,6,8:18.5
-1,6,8:18.5
0,6,8:18.5
1,6,8:18.5
0,7,8:18.5
1,7,8:18.5
0,8,8:18.5
1,8,8:18.5
1,9,8:18.5
-2,-8,9:18.5
-3,-7,9:18.5
-2,-7,9:18.5
-3,-6,9:18.5
-2,-6,9:18.5
-1,-6,9:18.5
-3,-5,9:18.5
-2,-5,9:18.5
-1,-5,9:18.5
0,-5,9:18.5
1,-5,9:18.5
-3,-4,9:18.13
-1,-4,9:18.13
0,-4,9:18.13
3,-4,9:18.13
-8,-3,9:18.5
-4,-3,9:18.13
-3,-3,9:18.13
0,-3,9:18.13
1,-3,9:18.13
1,-2,9:18.13
3,-2,9:18.13
-5,-1,9:18.13
-4,-1,9:18.13
-3,-1,9:18.13
1,-1,9:18.13
-5,0,9:18.13
-4,0,9:18.13
-3,0,9:18.13
-2,0,9:17.12
-1,0,9:18.13
0,0,9:18.13
3,0,9:18.13
4,0,9:18.5
-9,1,9:18.5
-8,1,9:18.5
-4,1,9:18.13
-3,1,9:18.13
-2,1,9:17.12
-1,1,9:17.12
0,1,9:18.13
3,1,9:18.13
4,1,9:18.5
5,1,9:18.5
-8,2,9:18.5
-6,2,9:18.13
-2,2,9:18.13
-1,2,9:18.13
4,2,9:18.5
5,2,9:18.5
6,2,9:18.5
-6,3,9:18.13
-2,3,9:18.13
-1,3,9:18.13
0,3,9:18.13
2,3,9:18.13
3,3,9:18.13
4,3,9:18.5
5,3,9:18.5
6,3,9:18.5
-7,4,9:18.5
-6,4,9:18.13
-2,4,9:18.13
-1,4,9:18.13
0,4,9:18.13
3,4,9:18.13
-8,5,9:18.5
-7,5,9:18.5
-6,5,9:18.13
-5,5,9:18.13
-4,5,9:18.13
-1,5,9:18.13
0,5,9:18.13
3,5,9:18.13
-8,6,9:18.5
-7,6,9:18.5
-6,6,9:18.5
0,6,9:18.5
3,6,9:18.5
1,7,9:18.5
3,7,9:18.5
-2,-5,10:18.5
0,-5,10:18.5
1,-5,10:18.5
2,-5,10:18.5
3,-5,10:18.5
-2,-4,10:18.13
-1,-4,10:18.13
0,-4,10:18.13
1,-4,10:18.13
2,-4,10:18.13
3,-4,10:18.13
-3,-3,10:18.13
-2,-3,10:18.13
-1,-3,10:18.13
2,-3,10:18.13
3,-3,10:18.13
-9,-2,10:18.5
-8,-2,10:18.5
-7,-2,10:18.5
-3,-2,10:18.13
-1,-2,10:18.13
2,-2,10:18.13
3,-2,10:18.13
-9,-1,10:18.5
-8,-1,10:18.5
-1,-1,10:18.13
0,-1,10:18.13
-9,0,10:18.5
-8,0,10:18.5
-4,0,10:18.13
-3,0,10:18.13
-2,0,10:18.13
-1,0,10:18.13
0,0,10:18.13
-8,1,10:18.5
-7,1,10:18.5
-3,1,10:18.13
-2,1,10:17.12
-1,1,10:17.12
2,1,10:18.13
3,1,10:18.13
-5,2,10:18.13
-4,2,10:18.13
-2,2,10:18.13
-1,2,10:18.13
0,2,10:18.13
1,2,10:18.13
2,2,10:18.13
3,2,10:18.13
4,2,10:18.5
-5,3,10:18.13
-4,3,10:18.13
-1,3,10:18.13
0,3,10:18.13
2,3,10:18.13
-5,4,10:18.13
-4,4,10:18.13
-3,4,10:18.13
-1,4,10:18.13
-1,5,10:18.13
0,5,10:18.13
2,5,10:18.13
0,6,10:18.5
1,6,10:18.5
2,6,10:18.5
1,7,10:18.5
2,7,10:18.5
3,7,10:18.5
2,8,10:18.5
0,-4,11:18.13
1,-4,11:18.13
2,-4,11:18.13
-2,-3,11:18.13
0,-3,11:18.13
1,-3,11:18.13
2,-3,11:18.13
-7,-2,11:18.5
-6,-2,11:18.13
-2,-2,11:18.13
-1,-2,11:18.13
1,-2,11:18.13
2,-2,11:18.13
-8,-1,11:18.5
-7,-1,11:18.5
-6,-1,11:18.13
-3,-1,11:18.13
-2,-1,11:18.13
-1,-1,11:18.13
-8,0,11:18.5
-7,0,11:18.5
-3,0,11:18.13
-2,0,11:18.13
-1,0,11:18.13
-7,1,11:18.5
-6,1,11:18.13
-3,1,11:18.13
-2,1,11:18.13
-1,1,11:18.13
1,1,11:18.13
2,1,11:18.13
-4,2,11:18.13
-3,2,11:18.13
-2,2,11:18.13
-1,2,11:18.13
0,2,11:18.13
1,2,11:18.13
2,2,11:18.13
-4,3,11:18.13
-3,3,11:18.13
-1,3,11:18.13
1,3,11:18.13
-3,4,11:18.13
-1,4,11:18.13
0,4,11:18.13
1,4,11:18.13
-3,5,11:18.13
0,5,11:18.13
1,5,11:18.13
2,5,11:18.13
1,6,11:18.5
2,6,11:18.5
2,7,11:18.5
-6,-5,12:18.5
2,-4,12:18.13
3,-4,12:18.13
0,-3,12:18.13
1,-3,12:18.13
-8,-2,12:18.5
-1,-2,12:18.13
1,-2,12:18.13
4,-2,12:18.5
-8,-1,12:18.5
-6,-1,12:18.13
-5,-1,12:18.13
-2,-1,12:18.13
-1,-1,12:18.13
1,-1,12:18.13
4,-1,12:18.5
-7,0,12:18.5
-6,0,12:18.13
-5,0,12:18.13
-3,0,12:18.13
-2,0,12:18.13
-1,0,12:18.13
4,0,12:18.5
-6,1,12:18.13
-5,1,12:18.13
-3,1,12:18.13
-2,1,12:18.13
-1,1,12:18.13
0,1,12:18.13
-3,2,12:18.13
-2,2,12:18.13
-1,2,12:18.13
0,2,12:18.13
-1,3,12:18.13
0,3,12:18.13
1,3,12:18.13
-3,4,12:18.13
-1,4,12:18.13
0,4,12:18.13
1,4,12:18.13
-3,5,12:18.13
-2,5,12:18.13
0,5,12:18.13
1,5,12:18.13
-2,6,12:18.5
0,6,12:18.5
1,6,12:18.5
-2,7,12:18.5
0,7,12:18.5
-1,8,12:18.5
0,8,12:18.5
-7,-4,13:18.5
-6,-4,13:18.13
-5,-4,13:18.13
-8,-3,13:18.5
-7,-3,13:18.5
1,-3,13:18.13
2,-3,13:18.13
3,-3,13:18.13
4,-3,13:18.5
-8,-2,13:18.5
-7,-2,13:18.5
3,-2,13:18.13
4,-2,13:18.5
-7,-1,13:18.5
-2,-1,13:18.13
-1,-1,13:18.13
0,-1,13:18.13
3,-1,13:18.13
4,-1,13:18.5
-5,0,13:18.13
-4,0,13:18.13
-2,0,13:18.13
-1,0,13:18.13
0,0,13:18.13
3,0,13:18.13
-5,1,13:18.13
-4,1,13:18.13
-3,1,13:18.13
-2,1,13:18.13
-1,1,13:18.13
0,1,13:18.13
-3,2,13:18.13
-2,2,13:18.13
-1,2,13:18.13
0,2,13:18.13
-1,3,13:18.13
0,3,13:18.13
-3,4,13:18.13
-2,4,13:18.13
0,4,13:18.13
1,4,13:18.13
-2,5,13:18.13
0,5,13:18.13
-2,6,13:18.5
0,6,13:18.5
-2,7,13:18.5
-1,7,13:18.5
0,7,13:18.5
-1,8,13:18.5
-1,9,13:18.5
-7,-3,14:18.5
-6,-3,14:18.13
-5,-3,14:18.13
-7,-2,14:18.5
-6,-2,14:18.13
-5,-2,14:18.13
1,-2,14:18.13
2,-2,14:18.13
3,-2,14:18.13
-6,-1,14:18.13
-1,-1,14:18.13
2,-1,14:18.13
3,-1,14:18.13
-5,0,14:18.13
-3,0,14:18.13
-2,0,14:18.13
-1,0,14:18.13
0,0,14:18.13
2,0,14:18.13
-3,1,14:18.13
-2,1,14:18.13
-1,1,14:18.13
0,1,14:18.13
-2,2,14:18.13
-1,2,14:18.13
-2,3,14:18.13
0,3,14:18.13
-6,4,14:18.13
-5,4,14:18.13
-4,4,14:18.13
-2,4,14:18.13
0,4,14:18.13
-2,5,14:18.13
-1,5,14:18.13
0,5,14:18.13
-2,6,14:18.13
-1,6,14:18.13
-1,7,14:18.5
-1,-5,15:18.5
2,-4,15:18.13
2,-3,15:18.13
-6,-2,15:18.13
-5,-2,15:18.13
-4,-2,15:18.13
1,-2,15:18.13
-5,-1,15:18.13
-4,-1,15:18.13
0,-1,15:18.13
1,-1,15:18.13
2,-1,15:18.13
-5,0,15:18.13
-4,0,15:18.13
-3,0,15:18.13
-2,0,15:18.13
-1,0,15:18.13
0,0,15:18.13
1,0,15:18.13
-6,1,15:18.13
-5,1,15:18.13
-3,1,15:18.13
-2,1,15:18.13
-1,1,15:18.13
0,1,15:18.13
-8,2,15:18.5
-7,2,15:18.5
-6,2,15:18.13
-2,2,15:18.13
-1,2,15:18.13
-8,3,15:18.5
-7,3,15:18.5
-6,3,15:18.13
-5,3,15:18.13
-4,3,15:18.13
-2,3,15:18.13
-1,3,15:18.13
0,3,15:18.13
2,3,15:18.13
-7,4,15:18.5
-6,4,15:18.13
-5,4,15:18.13
-4,4,15:18.13
-2,4,15:18.13
-1,4,15:18.13
3,4,15:18.13
-1,5,15:18.13
0,5,15:18.13
1,5,15:18.13
2,5,15:18.13
3,5,15:18.13
0,-5,16:18.5
1,-5,16:18.5
-1,-4,16:18.13
0,-4,16:18.13
1,-4,16:18.13
-1,-3,16:18.13
1,-3,16:18.13
-4,-1,16:18.13
-3,-1,16:18.13
0,-1,16:18.13
-4,0,16:18.13
-3,0,16:18.13
-2,0,16:18.13
-1,0,16:18.13
0,0,16:18.13
-5,1,16:18.13
-4,1,16:18.13
-3,1,16:18.13
-2,1,16:18.13
-1,1,16:18.13
-7,2,16:18.13
-6,2,16:18.13
-2,2,16:18.13
-1,2,16:18.13
-8,3,16:18.5
-7,3,16:18.13
-6,3,16:18.13
-5,3,16:18.13
-4,3,16:18.13
-2,3,16:18.13
-1,3,16:18.13
1,3,16:18.13
2,3,16:18.13
-1,4,16:18.13
0,4,16:18.13
1,4,16:18.13
1,5,16:18.13
2,5,16:18.13
-4,-4,17:18.13
0,-4,17:18.13
-1,-3,17:18.13
0,-3,17:18.13
-2,-2,17:18.13
-1,-2,17:18.13
1,-2,17:18.13
2,-2,17:18.13
-6,-1,17:18.13
-3,0,17:18.13
-2,0,17:18.13
-1,0,17:18.13
3,0,17:18.13
-5,1,17:18.13
-4,1,17:18.13
-3,1,17:18.13
-2,1,17:18.13
-1,1,17:18.13
2,1,17:18.13
-6,2,17:18.13
-5,2,17:18.13
-4,2,17:18.13
-3,2,17:18.13
-2,2,17:18.13
0,2,17:18.13
-4,3,17:18.13
-3,3,17:18.13
-1,3,17:18.13
0,3,17:18.13
1,3,17:18.13
-3,4,17:18.13
0,4,17:18.13
1,4,17:18.13
-3,5,17:18.13
-1,5,17:18.13
0,5,17:18.13
-3,6,17:18.13
-1,6,17:18.13
-2,7,17:18.5
-6,-3,18:18.13
-5,-3,18:18.13
-4,-3,18:18.13
-6,-2,18:18.13
-1,-2,18:18.13
1,-2,18:18.13
2,-2,18:18.13
-6,-1,18:18.13
-5,-1,18:18.13
-2,-1,18:18.13
-1,-1,18:18.13
0,-1,18:18.13
1,-1,18:18.13
2,-1,18:18.13
3,-1,18:18.13
-2,0,18:17.12
2,0,18:18.13
3,0,18:18.13
-4,1,18:18.13
-3,1,18:18.13
-2,1,18:18.13
-1,1,18:18.13
2,1,18:18.13
-5,2,18:18.13
-4,2,18:18.13
-3,2,18:18.13
-2,2,18:17.12
-1,2,18:18.13
0,2,18:18.13
-3,3,18:18.13
-1,3,18:18.13
0,3,18:18.13
-3,4,18:18.13
-1,4,18:18.13
-3,5,18:18.13
-2,5,18:18.13
-1,5,18:18.13
-2,6,18:18.13
-2,7,18:18.5
-5,-2,19:18.13
-4,-2,19:18.13
-5,-1,19:18.13
-4,-1,19:18.13
0,-1,19:18.13
1,-1,19:18.13
2,-1,19:18.13
-2,0,19:18.13
-1,0,19:18.13
1,0,19:18.13
2,0,19:18.13
-5,1,19:18.13
-3,1,19:18.13
-2,1,19:18.13
-1,1,19:17.12
1,1,19:18.13
-6,2,19:18.13
-2,2,19:17.12
-1,2,19:18.13
-7,3,19:18.13
-3,3,19:18.13
-2,3,19:18.13
-1,3,19:18.13
-6,4,19:18.13
-5,4,19:18.13
-4,4,19:18.13
-3,4,19:18.13
-2,4,19:18.13
-1,4,19:18.13
-2,5,19:18.13
0,5,19:18.13
1,5,19:18.13
-2,-4,20:18.13
-1,-4,20:18.13
0,-4,20:18.13
-2,-3,20:18.13
0,-3,20:18.13
1,-3,20:18.13
-4,-1,20:18.13
-3,-1,20:18.13
-4,0,20:18.13
-3,0,20:18.13
-1,0,20:18.13
0,0,20:18.13
-5,1,20:18.13
-4,1,20:18.13
-3,1,20:17.12
-2,1,20:17.12
-1,1,20:17.12
0,1,20:18.13
-6,2,20:18.13
-5,2,20:18.13
-2,2,20:17.12
-1,2,20:18.13
2,2,20:18.13
-7,3,20:18.13
-6,3,20:18.13
-5,3,20:18.13
-4,3,20:18.13
-2,3,20:18.13
2,3,20:18.13
-8,4,20:18.5
-7,4,20:18.13
-6,4,20:18.13
-5,4,20:18.13
-4,4,20:18.13
-2,4,20:18.13
0,4,20:18.13
1,4,20:18.13
3,4,20:18.13
-1,-4,21:18.13
0,-4,21:18.13
-2,-3,21:18.13
-1,-3,21:18.13
0,-3,21:18.13
-2,-2,21:18.13
-1,-2,21:18.13
-3,0,21:18.13
-2,0,21:18.13
-1,0,21:18.13
-4,1,21:18.13
-3,1,21:18.13
-2,1,21:17.12
-1,1,21:18.13
-5,2,21:18.13
-4,2,21:18.13
-3,2,21:18.13
-2,2,21:18.13
-1,2,21:18.13
0,2,21:18.13
1,2,21:18.13
-6,3,21:18.13
-5,3,21:18.13
-4,3,21:18.13
-3,3,21:18.13
0,3,21:18.13
1,3,21:18.13
0,4,21:18.13
1,4,21:18.13
-5,-3,22:18.13
-4,-3,22:18.13
-3,-3,22:18.13
-5,-2,22:18.13
-2,-2,22:18.13
-1,-2,22:18.13
-2,-1,22:18.13
-1,-1,22:18.13
1,-1,22:18.13
-2,0,22:18.13
-1,0,22:18.13
-3,1,22:18.13
-2,1,22:17.12
-1,1,22:18.13
2,1,22:18.13
3,1,22:18.13
-5,2,22:18.13
-4,2,22:18.13
-3,2,22:18.13
-2,2,22:18.13
-1,2,22:18.13
0,2,22:18.13
1,2,22:18.13
-5,3,22:18.13
-1,3,22:18.13
0,3,22:18.13
-6,4,22:18.13
-5,5,22:18.13
-4,5,22:18.13
-3,5,22:18.13
-5,-3,23:18.13
-4,-3,23:18.13
-3,-3,23:18.13
-5,-2,23:18.13
-4,-2,23:18.13
-3,-2,23:18.13
-5,-1,23:18.13
0,-1,23:18.13
1,-1,23:18.13
-2,0,23:18.13
-1,0,23:18.13
1,0,23:18.13
2,0,23:18.13
3,0,23:18.13
-3,1,23:18.13
-2,1,23:17.12
-1,1,23:18.13
1,1,23:18.13
2,1,23:18.13
3,1,23:18.13
-3,2,23:18.13
-2,2,23:18.13
-1,2,23:18.13
0,2,23:18.13
-5,4,23:18.13
-5,5,23:18.13
-4,5,23:18.13
-3,5,23:18.13
-4,-2,24:18.13
-3,-2,24:18.13
-4,-1,24:18.13
-3,-1,24:18.13
-4,0,24:18.13
-2,0,24:18.13
-1,0,24:18.13
0,0,24:18.13
1,0,24:18.13
2,0,24:18.13
-3,1,24:18.13
-2,1,24:17.12
-1,1,24:18.13
0,1,24:18.13
1,1,24:18.13
2,1,24:18.13
-3,2,24:18.13
-2,2,24:18.13
-1,2,24:18.13
0,2,24:18.13
-4,3,24:18.13
-2,3,24:18.13
-4,4,24:18.13
-3,4,24:18.13
-4,-1,25:18.13
-3,-1,25:18.13
-4,0,25:18.13
-3,0,25:18.13
-2,0,25:18.13
-1,0,25:18.13
0,0,25:18.13
-3,1,25:18.13
-2,1,25:18.13
-1,1,25:18.13
0,1,25:18.13
1,1,25:18.13
-3,2,25:18.13
-2,2,25:18.13
-1,2,25:18.13
-4,3,25:18.13
-3,3,25:18.13
-2,3,25:18.13
-2,-3,26:18.13
-1,-3,26:18.13
0,-3,26:18.13
-3,-2,26:18.13
-2,-2,26:18.13
0,-1,26:18.13
-6,0,26:18.13
-3,0,26:18.13
-2,0,26:18.13
0,0,26:18.13
-7,1,26:18.13
-6,1,26:18.13
-3,1,26:18.13
-2,1,26:18.13
-1,1,26:18.13
0,1,26:18.13
-7,2,26:18.13
-6,2,26:18.13
-3,2,26:18.13
-2,2,26:18.13
-1,2,26:18.13
-3,3,26:18.13
1,4,26:18.13
0,5,26:18.13
1,5,26:18.13
-2,6,26:18.13
-1,6,26:18.13
0,6,26:18.13
0,-4,27:18.5
-1,-3,27:18.13
0,-3,27:18.13
-2,-2,27:18.13
-1,-2,27:18.13
-2,-1,27:18.13
0,-1,27:18.13
-5,0,27:18.13
-1,0,27:18.13
0,0,27:18.13
-6,1,27:18.13
-5,1,27:18.13
-3,1,27:18.13
-2,1,27:18.13
-1,1,27:18.13
-6,2,27:18.13
-5,2,27:18.13
-3,2,27:17.12
-2,2,27:18.13
0,4,27:18.13
-2,5,27:18.13
-1,5,27:18.13
0,5,27:18.13
-1,6,27:18.13
-2,-3,28:18.13
-4,-2,28:18.13
-1,-2,28:18.13
-2,-1,28:18.13
-1,-1,28:18.13
-1,0,28:18.13
-5,1,28:18.13
-4,1,28:18.13
-3,1,28:18.13
-2,1,28:18.13
-1,1,28:18.13
2,1,28:18.13
-5,2,28:18.13
-4,2,28:18.13
-3,2,28:17.12
-2,2,28:17.12
2,2,28:18.13
-5,3,28:18.13
1,3,28:18.13
-5,4,28:18.13
-2,4,28:18.13
-1,4,28:18.13
0,4,28:18.13
-3,5,28:18.13
-1,5,28:18.13
-3,-3,29:18.13
-2,-3,29:18.13
-4,-2,29:18.13
-3,-2,29:18.13
-2,-2,29:18.13
-4,-1,29:18.13
-2,-1,29:18.13
-1,-1,29:18.13
-2,0,29:18.13
-1,0,29:18.13
-4,1,29:18.13
-3,1,29:17.12
-2,1,29:17.12
1,1,29:18.13
2,1,29:18.13
-4,2,29:18.13
-3,2,29:17.12
-2,2,29:17.12
1,2,29:18.13
2,2,29:18.13
-4,3,29:18.13
-2,3,29:18.13
-1,3,29:18.13
0,3,29:18.13
1,3,29:18.13
-4,4,29:18.13
-3,4,29:18.13
-2,4,29:18.13
-1,4,29:18.13
-5,5,29:18.13
-4,5,29:18.13
-3,5,29:18.13
-3,-2,30:18.13
-2,-2,30:18.13
-4,-1,30:18.13
-3,-1,30:18.13
-2,-1,30:18.13
-2,0,30:18.13
-3,1,30:18.13
-2,1,30:18.13
0,1,30:18.13
1,1,30:18.13
-4,2,30:18.13
-3,2,30:18.13
-2,2,30:17.12
0,2,30:18.13
1,2,30:18.13
-4,3,30:18.13
-2,3,30:18.13
0,3,30:18.13
-4,4,30:18.13
-3,4,30:18.13
-4,5,30:18.13
-3,-1,31:18.13
-2,-1,31:18.13
-3,0,31:18.13
-2,0,31:18.13
-3,1,31:17.12
-2,1,31:17.12
0,1,31:18.13
-4,2,31:18.13
-3,2,31:18.13
-2,2,31:17.12
-1,2,31:18.13
0,2,31:18.13
-4,3,31:18.13
-3,3,31:18.13
-2,3,31:18.13
-1,3,31:18.13
-3,4,31:18.13
-5,0,32:18.13
-3,0,32:18.13
-2,0,32:18.13
-6,1,32:18.13
-5,1,32:18.13
-3,1,32:17.12
-2,1,32:17.12
-1,1,32:18.13
-6,2,32:18.13
-4,2,32:18.13
-3,2,32:18.13
-2,2,32:17.12
-1,2,32:18.13
0,2,32:18.13
-5,3,32:18.13
-3,3,32:18.13
-2,5,32:18.13
-1,5,32:18.13
-2,-2,33:18.13
-1,-2,33:18.13
-2,-1,33:18.13
0,-1,33:18.13
-3,0,33:18.13
-2,0,33:18.13
-1,0,33:18.13
0,0,33:18.13
-5,1,33:18.13
-4,1,33:18.13
-3,1,33:17.12
-2,1,33:17.12
-6,2,33:18.13
-5,2,33:18.13
-3,2,33:18.13
-2,2,33:18.13
-1,2,33:18.13
-5,3,33:18.13
-3,3,33:18.13
-2,4,33:18.13
-1,4,33:18.13
0,4,33:18.13
-2,5,33:18.13
-1,5,33:18.13
0,5,33:18.13
-1,-2,34:18.13
-4,-1,34:18.13
-3,-1,34:18.13
-2,-1,34:18.13
-1,-1,34:18.13
-2,0,34:18.13
-1,0,34:18.13
-4,1,34:18.13
-3,1,34:18.13
-2,1,34:17.12
-5,2,34:18.13
-4,2,34:18.13
-3,2,34:18.13
-2,2,34:18.13
-1,2,34:18.13
0,2,34:18.13
1,2,34:18.13
-5,3,34:18.13
-2,3,34:18.13
-1,3,34:18.13
0,3,34:18.13
-4,4,34:18.13
-2,4,34:18.13
-1,4,34:18.13
-4,-1,35:18.13
-3,-1,35:18.13
-2,-1,35:18.13
-4,0,35:18.13
-3,0,35:18.13
-2,0,35:18.13
-1,0,35:18.13
-3,1,35:18.13
-2,1,35:18.13
-1,1,35:18.13
1,1,35:18.13
-4,2,35:18.13
-3,2,35:18.13
-2,2,35:17.12
-1,2,35:18.13
0,2,35:18.13
-5,3,35:18.13
-4,3,35:18.13
-2,3,35:18.13
-1,3,35:18.13
-4,4,35:18.13
-4,5,35:18.13
-3,5,35:18.13
-5,0,36:18.13
-4,0,36:18.13
-3,0,36:18.13
-2,0,36:18.13
0,0,36:18.13
-3,1,36:17.12
-2,1,36:17.12
0,1,36:18.13
-3,2,36:17.12
-2,2,36:17.12
-1,2,36:18.13
0,2,36:18.13
-4,3,36:18.13
-3,3,36:18.13
-3,4,36:18.13
-2,4,36:18.13
-1,4,36:18.13
-4,0,37:18.13
-3,0,37:18.13
-1,0,37:18.13
0,0,37:18.13
-5,1,37:18.13
-4,1,37:18.13
-3,1,37:18.13
-2,1,37:17.12
-1,1,37:18.13
0,1,37:18.13
-3,2,37:18.13
-2,2,37:17.12
-1,2,37:18.13
-3,3,37:18.13
-2,3,37:18.13
-2,4,37:18.13
-1,4,37:18.13
-3,0,38:18.13
-1,0,38:18.13
-4,1,38:18.13
-3,1,38:18.13
-2,1,38:17.12
-1,1,38:18.13
-3,2,38:17.12
-2,2,38:17.12
-3,3,38:18.13
-2,3,38:18.13
-3,0,39:18.13
-2,0,39:18.13
-4,1,39:18.13
-3,1,39:18.13
-2,1,39:18.13
-1,1,39:18.13
-4,2,39:18.13
-3,2,39:17.12
-2,2,39:17.12
-1,2,39:18.13
0,2,39:18.13
-4,3,39:18.13
-2,3,39:18.13
-1,3,39:18.13
-4,4,39:18.13
-3,4,39:18.13
-4,0,40:18.13
-3,0,40:18.13
-2,0,40:18.13
-3,1,40:18.13
-2,1,40:18.13
-4,2,40:18.13
-3,2,40:18.13
-2,2,40:18.13
-1,2,40:18.13
0,2,40:18.13
-4,3,40:18.13
-3,3,40:18.13
-2,3,40:18.13
-1,3,40:18.13
-3,4,40:18.13
-3,0,41:18.13
-3,1,41:18.13
-2,1,41:18.13
-3,2,41:18.13
-2,2,41:18.13
-1,2,41:18.13
-3,3,41:18.13
-2,3,41:18.13
-4,1,42:18.13
-3,1,42:18.13
-2,1,42:18.13
-4,2,42:18.13
-3,2,42:18.13
-2,2,42:18.13
-3,3,42:18.13
-2,0,43:18.13
-1,0,43:18.13
-3,1,43:18.13
-1,1,43:18.13
-4,2,43:18.13
-3,2,43:18.13
-2,2,43:18.13
-1,3,43:18.13
-2,4,43:18.13
-1,4,43:18.13
-2,0,44:18.13
-2,1,44:18.13
-1,1,44:18.13
-3,2,44:18.13
-2,2,44:17.12
-2,3,44:18.13
-1,3,44:18.13
-2,1,45:18.13
-3,2,45:17.12
-2,2,45:17.12
-2,3,45:18.13
-3,0,46:18.13
-2,1,46:18.13
-3,2,46:17.12
-2,2,46:18.13
0,2,46:18.13
-1,3,46:18.13
-3,0,47:18.13
-3,1,47:18.13
-2,1,47:18.13
-3,2,47:17.12
-2,2,47:17.12
-1,2,47:18.13
-4,3,47:18.13
-3,3,47:18.13
-1,3,47:18.13
-3,4,47:18.13
-3,1,48:18.13
-3,2,48:17.12
-2,2,48:18.13
-1,2,48:18.13
-3,3,48:18.13
-3,2,49:17.12
-2,2,49:18.13
-3,2,50:17.12
-3,2,51:17.12
-3,2,52:17.12
-3,2,53:17.12
-3,2,54:17.12
-3,2,55:17.12
-3,2,56:17.12
-3,2,57:17.12
