[META]
version=2.0
spawnOnBlockType=2
spawnSunlight=True
spawnDarkness=True
spawnWater=False
spawnLava=False
underFill=False
randomRotation=True
dig=True
tree=False
branch=False
needsFoundation=True
rarity=100
collisionPercentage=20
spawnElevationMin=0
spawnElevationMax=200
spawnInBiome=Custom
[DATA]
-3,2,-8:17.12
-2,3,-8:17.12
-3,4,-8:17.12
-3,2,-7:17.12
-4,3,-7:17.12
-3,3,-7:17.12
-2,3,-7:17.12
-4,4,-7:17.12
-3,4,-7:17.12
-4,3,-6:17.12
-3,3,-6:17.12
-3,4,-6:17.12
-4,3,-5:17.12
-3,3,-5:17.12
-2,3,-5:17.12
-3,4,-5:17.12
-4,2,-4:17.12
-3,2,-4:17.12
-2,2,-4:17.12
-4,3,-4:17.12
-3,3,-4:17.12
-3,4,-4:17.12
-2,4,-4:17.12
-3,2,-3:17.12
-4,3,-3:17.12
-3,3,-3:17.12
-2,3,-3:17.12
-4,4,-3:17.12
-3,4,-3:17.12
-4,3,-2:17.12
-3,3,-2:17.12
-4,4,-2:17.12
-3,4,-2:17.12
-4,3,-1:17.12
-3,3,-1:17.12
-4,4,-1:17.12
-3,4,-1:17.12
-1,-1,0:18.14
-2,0,0:18.14
-1,0,0:18.14
-4,3,0:17.12
-3,3,0:17.12
1,3,0:18.14
-4,4,0:17.12
-3,4,0:17.12
-7,0,1:18.14
-6,0,1:18.14
-5,0,1:18.14
-2,0,1:18.14
-1,0,1:18.14
0,0,1:18.14
1,0,1:18.14
-8,1,1:18.14
-7,1,1:18.14
-6,1,1:18.14
-5,1,1:18.14
-4,1,1:18.14
-3,1,1:18.14
-2,1,1:18.14
-1,1,1:18.14
0,1,1:18.14
1,1,1:18.14
0,2,1:18.14
1,2,1:18.14
-8,3,1:18.14
-4,3,1:17.12
-3,3,1:17.12
0,3,1:18.14
1,3,1:18.14
-8,4,1:18.14
-7,4,1:18.14
-3,4,1:17.12
-1,4,1:18.14
0,4,1:18.14
-8,5,1:18.14
-7,5,1:18.14
-6,5,1:18.14
-1,5,1:18.14
-1,7,1:18.14
0,7,1:18.14
-4,8,1:18.14
0,8,1:18.14
-6,1,2:18.14
-5,1,2:18.14
-4,1,2:18.14
-3,1,2:18.14
-2,1,2:18.14
-1,1,2:18.14
0,1,2:18.14
-8,2,2:18.14
-7,2,2:18.14
-6,2,2:18.14
-5,2,2:18.14
-4,2,2:18.14
-3,2,2:18.14
-2,2,2:18.14
-1,2,2:18.14
0,2,2:18.14
-8,3,2:18.14
-7,3,2:18.14
-6,3,2:18.14
-4,3,2:17.12
-3,3,2:17.12
-2,3,2:18.14
-1,3,2:18.14
-7,4,2:18.14
-6,4,2:18.14
-5,4,2:18.14
-3,4,2:17.12
-2,4,2:18.14
-1,4,2:18.14
-6,5,2:18.14
-5,5,2:18.14
-2,5,2:18.14
-1,5,2:18.14
-6,6,2:18.14
-5,6,2:18.14
-4,6,2:18.14
-2,6,2:18.14
-1,6,2:18.14
-5,7,2:18.14
-4,7,2:18.14
-2,7,2:18.14
-1,7,2:18.14
-4,8,2:18.14
-3,8,2:18.14
-2,8,2:18.14
-4,9,2:18.6
-3,9,2:18.6
-2,9,2:18.6
-3,0,3:18.14
-6,1,3:18.14
-6,2,3:18.14
-5,2,3:18.14
-4,2,3:18.14
-6,3,3:18.14
-5,3,3:18.14
-4,3,3:18.14
-3,3,3:17.12
-2,3,3:18.14
-5,4,3:18.14
-4,4,3:18.14
-3,4,3:17.12
-2,4,3:18.14
-1,4,3:18.14
-5,5,3:18.14
-4,5,3:18.14
-3,5,3:18.14
-2,5,3:18.14
-4,6,3:18.14
-3,6,3:18.14
-2,6,3:18.14
-4,7,3:18.14
-2,7,3:18.14
-3,8,3:18.14
-5,-1,4:18.14
-5,0,4:18.14
-4,0,4:18.14
-3,0,4:18.14
-5,1,4:18.14
-4,1,4:18.14
-3,1,4:18.14
-2,1,4:18.14
-5,2,4:18.14
-3,2,4:18.14
-2,2,4:18.14
-5,3,4:18.14
-4,3,4:17.12
-3,3,4:17.12
-4,4,4:18.14
-3,4,4:18.14
-3,5,4:18.14
-4,1,5:18.14
-1,1,5:18.14
0,1,5:18.14
-6,2,5:18.14
-4,2,5:18.14
-3,2,5:18.14
-1,2,5:18.14
0,2,5:18.14
-7,3,5:18.14
-6,3,5:18.14
-4,3,5:18.14
-3,3,5:17.12
1,3,5:18.14
-7,4,5:18.14
-3,4,5:17.12
-1,4,5:18.14
0,4,5:18.14
-8,5,5:18.14
-7,5,5:18.14
-6,5,5:18.14
-2,5,5:18.14
-1,5,5:18.14
0,5,5:18.14
-6,6,5:18.14
-5,6,5:18.14
-4,6,5:18.14
-5,2,6:18.14
-4,2,6:18.14
-3,2,6:18.14
-2,2,6:18.14
-1,2,6:18.14
-6,3,6:18.14
-5,3,6:18.14
-4,3,6:17.12
-3,3,6:17.12
-2,3,6:18.14
-1,3,6:18.14
0,3,6:18.14
-6,4,6:18.14
-5,4,6:18.14
-4,4,6:18.14
-3,4,6:18.14
-2,4,6:18.14
-1,4,6:18.14
-7,5,6:18.14
-6,5,6:18.14
-5,5,6:18.14
-4,5,6:18.14
-3,5,6:18.14
-2,5,6:18.14
-3,6,6:18.14
-4,0,7:18.14
-3,0,7:18.14
-2,0,7:18.14
-4,1,7:18.14
-2,1,7:18.14
-1,1,7:18.14
-2,2,7:18.14
-1,2,7:18.14
-5,3,7:18.14
-4,3,7:18.14
-3,3,7:18.14
-2,3,7:18.14
-5,4,7:18.14
-4,4,7:18.14
-3,4,7:18.14
-2,4,7:18.14
-5,5,7:18.14
-4,5,7:18.14
-3,5,7:18.14
-5,6,7:18.14
-4,6,7:18.14
-3,6,7:18.14
-5,7,7:18.14
-3,0,8:18.14
-5,1,8:18.14
-4,1,8:18.14
-3,1,8:18.14
-2,1,8:18.14
-6,2,8:18.14
-5,2,8:18.14
-4,2,8:18.14
-3,2,8:18.14
-2,2,8:18.14
-4,3,8:18.14
-3,3,8:17.12
-2,3,8:18.14
-6,4,8:18.14
-4,4,8:18.14
-3,4,8:18.14
-1,4,8:18.14
-4,5,8:18.14
-1,5,8:18.14
-3,6,8:18.14
-2,6,8:18.14
-1,6,8:18.14
-7,2,9:18.14
-6,2,9:18.14
-5,2,9:18.14
-4,2,9:18.14
-3,2,9:18.14
-6,3,9:18.14
-5,3,9:18.14
-4,3,9:18.14
-3,3,9:18.14
-2,3,9:18.14
-5,4,9:18.14
-4,4,9:18.14
-3,4,9:18.14
-2,4,9:18.14
-4,5,9:18.14
-3,5,9:18.14
-2,5,9:18.14
-1,5,9:18.14
-1,6,9:18.14
-3,1,10:18.14
-5,2,10:18.14
-4,2,10:18.14
-3,2,10:18.14
-2,2,10:18.14
-1,2,10:18.14
-5,3,10:18.14
-4,3,10:18.14
-3,3,10:18.14
-2,3,10:18.14
-1,3,10:18.14
-5,4,10:18.14
-4,4,10:18.14
-3,4,10:18.14
-2,4,10:18.14
-1,4,10:18.14
-5,3,11:18.14
-4,3,11:18.14
-3,3,11:18.14
-2,3,11:18.14
-5,4,11:18.14
-4,4,11:18.14
-3,4,11:18.14
-2,4,11:18.14
-5,2,12:18.14
-4,2,12:18.14
-3,2,12:18.14
-5,3,12:18.14
-4,3,12:18.14
-3,3,12:18.14
-4,4,12:18.14
-3,3,13:18.14
-2,3,13:18.14
-4,4,13:18.14
-3,4,13:18.14
-2,4,13:18.14
-3,5,13:18.14
-2,5,13:18.14
-4,3,14:18.14
-3,3,14:17.12
-4,4,14:18.14
-3,4,14:18.14
-3,3,15:18.14
-3,3,16:17.12
-3,3,17:17.12
