[META]
version=2.0
spawnOnBlockType=2
spawnSunlight=True
spawnDarkness=True
spawnWater=False
spawnLava=False
underFill=False
randomRotation=True
dig=True
tree=False
branch=False
needsFoundation=True
rarity=100
collisionPercentage=20
spawnElevationMin=0
spawnElevationMax=200
spawnInBiome=Custom
[DATA]
-1,-6,-8:17.12
0,-6,-8:17.12
1,-5,-8:17.12
1,-8,-7:17.12
1,-7,-7:17.12
2,-7,-7:17.12
-2,-6,-7:17.12
0,-6,-7:17.12
-1,-5,-7:17.12
1,-5,-7:17.12
2,-5,-7:17.12
0,-4,-7:17.12
0,-8,-6:17.12
1,-7,-6:17.12
-2,-6,-6:17.12
1,-6,-6:17.12
2,-6,-6:17.12
-1,-5,-6:17.12
0,-5,-6:17.12
2,-5,-6:17.12
0,-4,-6:17.12
0,-8,-5:17.12
-2,-7,-5:17.12
-2,-6,-5:17.12
0,-6,-5:17.12
1,-6,-5:17.12
2,-6,-5:17.12
1,-4,-5:17.12
-1,-7,-4:17.12
0,-7,-4:17.12
-2,-6,-4:17.12
0,-6,-4:17.12
1,-6,-4:17.12
-1,-5,-4:17.12
0,-5,-4:17.12
-1,-4,-4:17.12
-1,-8,-3:17.12
-2,-7,-3:17.12
1,-7,-3:17.12
2,-7,-3:17.12
0,-6,-3:17.12
1,-6,-3:17.12
-2,-5,-3:17.12
-1,-5,-3:17.12
0,-5,-3:17.12
0,-4,-3:17.12
1,-4,-3:17.12
-1,-8,-2:17.12
0,-8,-2:17.12
1,-8,-2:17.12
-2,-7,-2:17.12
-1,-7,-2:17.12
0,-7,-2:17.12
1,-7,-2:17.12
-2,-6,-2:17.12
-1,-6,-2:17.12
1,-6,-2:17.12
2,-6,-2:17.12
-2,-5,-2:17.12
-1,-5,-2:17.12
0,-5,-2:17.12
1,-5,-2:17.12
-1,-4,-2:17.12
0,-8,-1:17.12
1,-8,-1:17.12
-1,-7,-1:17.12
0,-7,-1:17.12
1,-7,-1:17.12
2,-7,-1:17.12
-1,-6,-1:17.12
0,-6,-1:17.12
1,-6,-1:17.12
1,-8,0:17.12
5,-8,0:18.14
0,-7,0:17.12
1,-7,0:17.12
2,-7,0:17.12
4,-7,0:18.14
5,-7,0:18.14
0,-6,0:17.12
1,-6,0:17.12
5,-6,0:18.14
5,-5,0:18.14
5,-10,1:18.14
3,-9,1:18.14
5,-9,1:18.14
3,-8,1:18.14
4,-8,1:18.14
5,-8,1:18.14
0,-7,1:17.12
1,-7,1:17.12
2,-7,1:17.12
4,-7,1:18.14
5,-7,1:18.14
1,-6,1:17.12
2,-6,1:17.12
3,-6,1:18.14
4,-6,1:18.14
5,-6,1:18.14
3,-5,1:18.14
5,-5,1:18.14
6,-5,1:18.14
6,-4,1:18.14
3,-11,2:18.14
1,-10,2:18.14
2,-10,2:18.14
5,-10,2:18.14
0,-9,2:18.14
1,-9,2:18.14
2,-9,2:18.14
3,-9,2:18.14
5,-9,2:18.14
-2,-8,2:18.14
0,-8,2:18.14
3,-8,2:18.14
4,-8,2:18.14
5,-8,2:18.14
1,-7,2:17.12
2,-7,2:17.12
4,-7,2:18.14
-2,-6,2:18.14
1,-6,2:17.12
2,-6,2:17.12
3,-6,2:18.14
4,-6,2:18.14
5,-6,2:18.14
3,-5,2:18.14
5,-5,2:18.14
6,-5,2:18.14
6,-4,2:18.14
7,-4,2:18.14
3,-11,3:18.14
4,-11,3:18.14
1,-10,3:18.14
2,-10,3:18.14
3,-10,3:18.14
-3,-9,3:18.14
-2,-9,3:18.14
0,-9,3:18.14
1,-9,3:18.14
2,-9,3:18.14
3,-9,3:18.14
5,-9,3:18.14
-2,-8,3:18.14
-1,-8,3:18.14
0,-8,3:18.14
1,-8,3:18.14
3,-8,3:18.14
4,-8,3:18.14
5,-8,3:18.14
6,-8,3:18.14
7,-8,3:18.14
-1,-7,3:18.14
0,-7,3:18.14
1,-7,3:17.12
2,-7,3:17.12
3,-7,3:17.12
4,-7,3:18.14
5,-7,3:18.14
6,-7,3:18.14
-1,-6,3:18.14
0,-6,3:18.14
2,-6,3:17.12
3,-6,3:18.14
4,-6,3:18.14
5,-6,3:18.14
-1,-5,3:18.14
0,-5,3:18.14
1,-5,3:18.14
3,-5,3:18.14
5,-5,3:18.14
6,-5,3:18.14
2,-4,3:18.14
3,-4,3:18.14
5,-4,3:18.14
6,-4,3:18.14
4,-11,4:18.14
1,-10,4:18.14
2,-10,4:18.14
3,-10,4:18.14
4,-10,4:18.14
-2,-9,4:18.14
-1,-9,4:18.14
2,-9,4:18.14
3,-9,4:18.14
4,-9,4:18.14
5,-9,4:18.14
7,-9,4:18.14
-1,-8,4:18.14
0,-8,4:18.14
1,-8,4:18.14
2,-8,4:18.14
3,-8,4:18.14
4,-8,4:18.14
5,-8,4:18.14
6,-8,4:18.14
7,-8,4:18.14
-1,-7,4:18.14
0,-7,4:18.14
1,-7,4:18.14
2,-7,4:17.12
3,-7,4:17.12
4,-7,4:18.14
5,-7,4:18.14
6,-7,4:18.14
-1,-6,4:18.14
0,-6,4:18.14
1,-6,4:18.14
2,-6,4:17.12
3,-6,4:17.12
4,-6,4:18.14
5,-6,4:18.14
6,-6,4:18.14
-1,-5,4:18.14
1,-5,4:18.14
2,-5,4:18.14
3,-5,4:18.14
5,-5,4:18.14
6,-5,4:18.14
2,-4,4:18.14
3,-4,4:18.14
4,-4,4:18.14
5,-4,4:18.14
1,-3,4:18.14
5,-11,5:18.14
0,-10,5:18.14
1,-10,5:18.14
3,-10,5:18.14
4,-10,5:18.14
5,-10,5:18.14
8,-10,5:18.14
-1,-9,5:18.14
1,-9,5:18.14
2,-9,5:18.14
3,-9,5:18.14
4,-9,5:18.14
5,-9,5:18.14
7,-9,5:18.14
8,-9,5:18.14
-1,-8,5:18.14
0,-8,5:18.14
1,-8,5:18.14
2,-8,5:18.14
3,-8,5:18.14
4,-8,5:18.14
5,-8,5:18.14
6,-8,5:18.14
7,-8,5:18.14
0,-7,5:18.14
1,-7,5:18.14
2,-7,5:17.12
3,-7,5:17.12
4,-7,5:18.14
5,-7,5:18.14
6,-7,5:18.14
-1,-6,5:18.14
0,-6,5:18.14
1,-6,5:18.14
2,-6,5:18.14
3,-6,5:18.14
4,-6,5:18.14
5,-6,5:18.14
6,-6,5:18.14
0,-5,5:18.14
2,-5,5:18.14
3,-5,5:18.14
4,-5,5:18.14
5,-5,5:18.14
6,-5,5:18.14
1,-4,5:18.14
2,-4,5:18.14
1,-3,5:18.14
0,-2,5:18.14
2,-11,6:18.14
3,-10,6:18.14
4,-10,6:18.14
5,-10,6:18.14
6,-10,6:18.14
-1,-9,6:18.14
0,-9,6:18.14
1,-9,6:18.14
2,-9,6:18.14
3,-9,6:18.14
4,-9,6:18.14
7,-9,6:18.14
0,-8,6:18.14
1,-8,6:18.14
2,-8,6:18.14
3,-8,6:18.14
4,-8,6:18.14
5,-8,6:18.14
6,-8,6:18.14
7,-8,6:18.14
0,-7,6:18.14
1,-7,6:18.14
2,-7,6:18.14
3,-7,6:17.12
4,-7,6:18.14
5,-7,6:18.14
6,-7,6:18.14
-1,-6,6:18.14
0,-6,6:18.14
1,-6,6:18.14
2,-6,6:18.14
3,-6,6:18.14
4,-6,6:18.14
5,-6,6:18.14
-2,-5,6:18.14
-1,-5,6:18.14
1,-5,6:18.14
2,-5,6:18.14
3,-5,6:18.14
4,-5,6:18.14
5,-5,6:18.14
6,-5,6:18.14
1,-4,6:18.14
2,-4,6:18.14
3,-4,6:18.14
1,-3,6:18.14
4,-3,6:18.14
1,-12,7:18.6
2,-11,7:18.14
3,-10,7:18.14
5,-10,7:18.14
6,-10,7:18.14
0,-9,7:18.14
1,-9,7:18.14
3,-9,7:18.14
4,-9,7:18.14
7,-9,7:18.14
1,-8,7:18.14
2,-8,7:18.14
3,-8,7:18.14
4,-8,7:18.14
0,-7,7:18.14
1,-7,7:18.14
2,-7,7:18.14
3,-7,7:18.14
4,-7,7:18.14
5,-7,7:18.14
0,-6,7:18.14
1,-6,7:18.14
2,-6,7:18.14
3,-6,7:18.14
4,-6,7:18.14
5,-6,7:18.14
-1,-5,7:18.14
2,-5,7:18.14
3,-5,7:18.14
4,-5,7:18.14
5,-5,7:18.14
1,-4,7:18.14
2,-4,7:18.14
3,-4,7:18.14
4,-4,7:18.14
4,-3,7:18.14
5,-3,7:18.14
5,-2,7:18.14
2,-11,8:18.14
2,-10,8:18.14
3,-10,8:18.14
1,-9,8:18.14
2,-9,8:18.14
3,-9,8:18.14
4,-9,8:18.14
5,-9,8:18.14
6,-9,8:18.14
7,-9,8:18.14
1,-8,8:18.14
2,-8,8:18.14
3,-8,8:18.14
4,-8,8:18.14
5,-8,8:18.14
6,-8,8:18.14
1,-7,8:18.14
2,-7,8:18.14
3,-7,8:17.12
4,-7,8:18.14
5,-7,8:18.14
0,-6,8:18.14
1,-6,8:18.14
2,-6,8:18.14
3,-6,8:18.14
4,-6,8:18.14
5,-6,8:18.14
6,-6,8:18.14
7,-6,8:18.14
-1,-5,8:18.14
0,-5,8:18.14
2,-5,8:18.14
3,-5,8:18.14
4,-5,8:18.14
5,-5,8:18.14
7,-5,8:18.14
1,-4,8:18.14
2,-4,8:18.14
4,-4,8:18.14
5,-4,8:18.14
8,-4,8:18.14
5,-3,8:18.14
2,-11,9:18.14
2,-10,9:18.14
3,-10,9:18.14
2,-9,9:18.14
3,-9,9:18.14
4,-9,9:18.14
6,-9,9:18.14
7,-9,9:18.14
0,-8,9:18.14
1,-8,9:18.14
2,-8,9:18.14
3,-8,9:18.14
4,-8,9:18.14
5,-8,9:18.14
6,-8,9:18.14
1,-7,9:18.14
2,-7,9:18.14
3,-7,9:17.12
4,-7,9:17.12
5,-7,9:18.14
6,-7,9:18.14
1,-6,9:18.14
2,-6,9:18.14
3,-6,9:18.14
4,-6,9:18.14
5,-6,9:18.14
6,-6,9:18.14
0,-5,9:18.14
1,-5,9:18.14
2,-5,9:18.14
3,-5,9:18.14
4,-5,9:18.14
5,-5,9:18.14
7,-5,9:18.14
4,-4,9:18.14
5,-4,9:18.14
7,-4,9:18.14
5,-11,10:18.14
-1,-10,10:18.14
2,-10,10:18.14
3,-10,10:18.14
4,-10,10:18.14
5,-10,10:18.14
0,-9,10:18.14
3,-9,10:18.14
4,-9,10:18.14
6,-9,10:18.14
0,-8,10:18.14
1,-8,10:18.14
2,-8,10:18.14
3,-8,10:18.14
4,-8,10:18.14
5,-8,10:18.14
6,-8,10:18.14
1,-7,10:18.14
2,-7,10:18.14
3,-7,10:18.14
4,-7,10:18.14
5,-7,10:18.14
6,-7,10:18.14
1,-6,10:18.14
2,-6,10:18.14
3,-6,10:18.14
4,-6,10:18.14
5,-6,10:18.14
6,-6,10:18.14
0,-5,10:18.14
1,-5,10:18.14
2,-5,10:18.14
3,-5,10:18.14
4,-5,10:18.14
5,-5,10:18.14
7,-5,10:18.14
4,-4,10:18.14
5,-4,10:18.14
6,-4,10:18.14
2,-3,10:18.14
6,-11,11:18.14
2,-10,11:18.14
5,-10,11:18.14
6,-10,11:18.14
0,-9,11:18.14
1,-9,11:18.14
2,-9,11:18.14
3,-9,11:18.14
4,-9,11:18.14
1,-8,11:18.14
3,-8,11:18.14
4,-8,11:18.14
5,-8,11:18.14
6,-8,11:18.14
7,-8,11:18.14
2,-7,11:18.14
3,-7,11:18.14
4,-7,11:18.14
5,-7,11:18.14
6,-7,11:18.14
7,-7,11:18.14
2,-6,11:18.14
3,-6,11:18.14
4,-6,11:18.14
5,-6,11:18.14
6,-6,11:18.14
2,-5,11:18.14
3,-5,11:18.14
4,-5,11:18.14
5,-5,11:18.14
6,-5,11:18.14
7,-5,11:18.14
3,-4,11:18.14
4,-4,11:18.14
5,-4,11:18.14
6,-4,11:18.14
2,-3,11:18.14
5,-10,12:18.14
6,-10,12:18.14
1,-9,12:18.14
2,-9,12:18.14
3,-9,12:18.14
4,-9,12:18.14
5,-9,12:18.14
8,-9,12:18.14
1,-8,12:18.14
2,-8,12:18.14
3,-8,12:18.14
4,-8,12:18.14
5,-8,12:18.14
6,-8,12:18.14
7,-8,12:18.14
2,-7,12:18.14
3,-7,12:18.14
4,-7,12:17.12
5,-7,12:18.14
6,-7,12:18.14
7,-7,12:18.14
1,-6,12:18.14
2,-6,12:18.14
3,-6,12:18.14
4,-6,12:18.14
5,-6,12:18.14
6,-6,12:18.14
0,-5,12:18.14
1,-5,12:18.14
2,-5,12:18.14
3,-5,12:18.14
4,-5,12:18.14
5,-5,12:18.14
6,-5,12:18.14
7,-5,12:18.14
2,-4,12:18.14
3,-4,12:18.14
2,-3,12:18.14
3,-10,13:18.14
4,-10,13:18.14
2,-9,13:18.14
4,-9,13:18.14
5,-9,13:18.14
6,-9,13:18.14
2,-8,13:18.14
3,-8,13:18.14
4,-8,13:18.14
5,-8,13:18.14
7,-8,13:18.14
2,-7,13:18.14
3,-7,13:18.14
4,-7,13:18.14
5,-7,13:18.14
6,-7,13:18.14
7,-7,13:18.14
1,-6,13:18.14
2,-6,13:18.14
3,-6,13:18.14
4,-6,13:18.14
5,-6,13:18.14
6,-6,13:18.14
1,-5,13:18.14
3,-5,13:18.14
4,-5,13:18.14
5,-5,13:18.14
6,-5,13:18.14
2,-4,13:18.14
3,-4,13:18.14
5,-4,13:18.14
5,-3,13:18.14
6,-3,13:18.14
3,-10,14:18.14
4,-9,14:18.14
5,-9,14:18.14
6,-9,14:18.14
2,-8,14:18.14
3,-8,14:18.14
4,-8,14:18.14
5,-8,14:18.14
6,-8,14:18.14
7,-8,14:18.14
3,-7,14:18.14
4,-7,14:18.14
5,-7,14:18.14
6,-7,14:18.14
2,-6,14:18.14
3,-6,14:18.14
4,-6,14:18.14
5,-6,14:18.14
6,-6,14:18.14
2,-5,14:18.14
3,-5,14:18.14
4,-5,14:18.14
5,-5,14:18.14
6,-5,14:18.14
5,-4,14:18.14
6,-4,14:18.14
6,-3,14:18.14
3,-10,15:18.14
3,-9,15:18.14
4,-9,15:18.14
3,-8,15:18.14
4,-8,15:18.14
5,-8,15:18.14
6,-8,15:18.14
7,-8,15:18.14
3,-7,15:18.14
4,-7,15:18.14
5,-7,15:18.14
6,-7,15:18.14
2,-6,15:18.14
3,-6,15:18.14
4,-6,15:18.14
5,-6,15:18.14
6,-6,15:18.14
7,-6,15:18.14
2,-5,15:18.14
3,-5,15:18.14
4,-5,15:18.14
5,-5,15:18.14
5,-4,15:18.14
6,-4,15:18.14
3,-9,16:18.14
4,-9,16:18.14
2,-8,16:18.14
4,-8,16:18.14
5,-8,16:18.14
7,-8,16:18.14
3,-7,16:18.14
4,-7,16:18.14
5,-7,16:18.14
6,-7,16:18.14
3,-6,16:18.14
4,-6,16:18.14
5,-6,16:18.14
6,-6,16:18.14
3,-5,16:18.14
4,-5,16:18.14
5,-5,16:18.14
7,-5,16:18.14
4,-4,16:18.14
6,-9,17:18.6
3,-8,17:18.6
4,-8,17:18.6
5,-8,17:18.6
6,-8,17:18.6
3,-7,17:18.6
4,-7,17:18.6
5,-7,17:18.6
6,-7,17:18.6
3,-6,17:18.6
4,-6,17:18.6
5,-6,17:18.6
6,-6,17:18.6
3,-5,17:18.6
4,-5,17:18.6
5,-5,17:18.6
6,-5,17:18.6
7,-5,17:18.6
3,-4,17:18.6
4,-4,17:18.6
4,-8,18:18.6
5,-8,18:18.6
6,-8,18:18.6
3,-7,18:18.6
4,-7,18:18.6
5,-7,18:18.6
6,-7,18:18.6
4,-6,18:18.6
5,-6,18:18.6
6,-6,18:18.6
4,-5,18:18.6
5,-5,18:18.6
6,-5,18:18.6
4,-4,18:18.6
4,-7,19:18.6
5,-7,19:18.6
4,-6,19:18.6
5,-6,19:18.6
6,-6,19:18.6
4,-5,19:18.6
5,-5,19:18.6
4,-7,20:18.6
5,-7,20:18.6
4,-6,20:18.6
5,-6,20:18.6
5,-5,20:18.6
5,-6,21:18.6
5,-6,22:17.0
5,-6,23:17.0
