[META]
version=2.0
spawnOnBlockType=2
spawnSunlight=True
spawnDarkness=True
spawnWater=False
spawnLava=False
underFill=False
randomRotation=True
dig=True
tree=False
branch=False
needsFoundation=True
rarity=100
collisionPercentage=20
spawnElevationMin=0
spawnElevationMax=200
spawnInBiome=Custom
[DATA]
8,-5,-8:17.13
6,-4,-8:17.13
6,-8,-7:17.13
4,-6,-7:17.13
5,-5,-7:17.13
8,-5,-7:17.13
7,-7,-6:17.13
5,-5,-6:17.13
8,-5,-6:17.13
5,-3,-6:17.13
7,-7,-5:17.13
8,-5,-5:17.13
5,-4,-5:17.13
6,-6,-4:17.13
8,-5,-4:17.13
6,-4,-4:17.13
6,-6,-3:17.13
8,-5,-3:17.13
6,-4,-3:17.13
6,-6,-2:17.13
7,-6,-2:17.13
6,-5,-2:17.13
7,-5,-2:17.13
8,-5,-2:17.13
6,-4,-2:17.13
7,-4,-2:17.13
7,-6,-1:17.13
6,-5,-1:17.13
7,-5,-1:17.13
8,-5,-1:17.13
6,-4,-1:17.13
7,-4,-1:17.13
7,-6,0:17.13
6,-5,0:17.13
7,-5,0:17.13
6,-4,0:17.13
7,-4,0:17.13
6,-5,1:17.13
7,-5,1:17.13
6,-4,1:17.13
7,-4,1:17.13
6,-5,2:17.13
7,-5,2:17.13
6,-4,2:17.13
7,-4,2:17.13
6,-5,3:17.13
7,-5,3:17.13
6,-4,3:17.13
7,-4,3:17.13
6,-5,4:17.13
7,-5,4:17.13
6,-4,4:17.13
7,-4,4:17.13
6,-5,5:17.13
7,-5,5:17.13
6,-4,5:17.13
7,-4,5:17.13
6,-5,6:17.13
7,-5,6:17.13
5,-4,6:17.13
6,-4,6:17.13
7,-4,6:17.13
6,-5,7:17.13
7,-5,7:17.13
5,-4,7:17.13
6,-4,7:17.13
7,-4,7:17.13
6,-5,8:17.13
7,-5,8:17.13
6,-4,8:17.13
7,-4,8:17.13
2,-5,9:17.13
3,-5,9:17.13
4,-5,9:17.13
5,-5,9:17.13
6,-5,9:17.13
7,-5,9:17.13
5,-4,9:17.13
6,-4,9:17.13
7,-4,9:17.13
-2,-8,10:17.13
-1,-7,10:17.13
0,-7,10:17.13
1,-6,10:17.13
2,-6,10:17.13
2,-5,10:17.13
3,-5,10:17.13
4,-5,10:17.13
5,-5,10:17.13
6,-5,10:17.13
7,-5,10:17.13
6,-4,10:17.13
7,-4,10:17.13
6,-5,11:17.13
7,-5,11:17.13
6,-4,11:17.13
7,-4,11:17.13
2,-7,12:17.13
3,-6,12:17.13
4,-6,12:17.13
4,-5,12:17.13
5,-5,12:17.13
6,-5,12:17.13
7,-5,12:17.13
6,-4,12:17.13
7,-4,12:17.13
8,-7,13:18.13
9,-7,13:18.13
10,-7,13:18.13
11,-7,13:18.13
12,-7,13:18.13
13,-7,13:17.13
9,-6,13:18.13
10,-6,13:18.13
11,-6,13:18.13
12,-6,13:18.13
5,-5,13:17.13
6,-5,13:17.13
7,-5,13:17.13
10,-5,13:18.13
11,-5,13:18.13
6,-4,13:17.13
7,-4,13:17.13
8,-7,14:18.13
13,-7,14:18.13
7,-6,14:18.13
8,-6,14:18.13
9,-6,14:18.13
10,-6,14:18.13
11,-6,14:17.13
6,-5,14:17.13
7,-5,14:17.13
8,-5,14:18.13
9,-5,14:18.13
10,-5,14:18.13
6,-4,14:17.13
7,-4,14:17.13
6,-5,15:17.13
7,-5,15:17.13
8,-5,15:17.13
9,-5,15:17.13
6,-4,15:17.13
7,-4,15:17.13
6,-5,16:17.13
7,-5,16:17.13
6,-4,16:17.13
7,-4,16:17.13
-2,-3,16:18.13
-1,-3,16:18.13
0,-3,16:18.13
-2,-2,16:18.13
-1,-2,16:18.13
0,-2,16:18.13
1,-2,16:18.13
-2,-1,16:18.13
-1,-1,16:18.13
0,-1,16:18.13
6,-5,17:17.13
7,-5,17:17.13
6,-4,17:17.13
7,-4,17:17.13
1,-3,17:18.13
2,-3,17:18.13
-1,-2,17:18.13
0,-2,17:18.13
1,-2,17:17.13
2,-2,17:17.13
6,-5,18:17.13
7,-5,18:17.13
4,-4,18:17.13
5,-4,18:17.13
6,-4,18:17.13
7,-4,18:17.13
3,-3,18:17.13
4,-3,18:17.13
6,-5,19:17.13
7,-5,19:17.13
10,-5,19:18.13
11,-5,19:18.13
6,-4,19:17.13
7,-4,19:17.13
11,-4,19:18.13
12,-4,19:18.13
11,-3,19:18.13
11,-2,19:17.13
6,-5,20:17.13
7,-5,20:17.13
8,-5,20:18.13
9,-5,20:18.13
10,-5,20:18.13
6,-4,20:17.13
7,-4,20:17.13
8,-4,20:17.13
9,-4,20:18.13
10,-4,20:18.13
10,-3,20:17.13
11,-3,20:17.13
12,-3,20:17.13
13,-2,20:17.13
6,-5,21:17.13
7,-5,21:17.13
6,-4,21:17.13
7,-4,21:17.13
8,-4,21:17.13
9,-4,21:17.13
-5,-8,22:17.13
-4,-8,22:17.13
-2,-7,22:17.13
-1,-7,22:18.13
0,-7,22:18.13
-2,-6,22:18.13
-1,-6,22:18.13
-2,-5,22:18.13
-1,-5,22:18.13
0,-5,22:18.13
1,-5,22:18.13
6,-5,22:17.13
7,-5,22:17.13
6,-4,22:17.13
-3,-8,23:17.13
-2,-7,23:17.13
-1,-7,23:17.13
0,-7,23:17.13
1,-7,23:18.13
-3,-6,23:18.13
0,-6,23:18.13
1,-6,23:18.13
2,-6,23:17.13
3,-6,23:17.13
4,-6,23:17.13
-3,-5,23:18.13
-2,-5,23:18.13
-1,-5,23:18.13
0,-5,23:18.13
1,-5,23:18.13
2,-5,23:18.13
4,-5,23:17.13
5,-5,23:17.13
6,-5,23:17.13
7,-5,23:17.13
-3,-4,23:18.13
6,-4,23:17.13
0,-6,24:17.13
1,-6,24:17.13
2,-6,24:17.13
6,-5,24:17.13
7,-5,24:17.13
6,-4,24:17.13
-2,-7,25:17.13
-1,-7,25:17.13
6,-5,25:17.13
7,-5,25:17.13
6,-4,25:17.13
6,-5,26:17.13
7,-5,26:17.13
1,-4,26:18.13
2,-4,26:18.13
6,-4,26:17.13
7,-4,26:17.13
1,-3,26:18.13
6,-5,27:17.13
7,-5,27:17.13
1,-4,27:18.13
2,-4,27:18.13
3,-4,27:18.13
4,-4,27:18.13
5,-4,27:17.13
6,-4,27:17.13
7,-4,27:17.13
0,-3,27:18.13
1,-3,27:18.13
2,-3,27:18.13
3,-3,27:18.13
4,-3,27:18.13
0,-2,27:18.13
1,-2,27:17.13
6,-5,28:17.13
7,-5,28:17.13
4,-4,28:17.13
5,-4,28:17.13
6,-4,28:17.13
7,-4,28:17.13
3,-3,28:17.13
4,-3,28:17.13
6,-5,29:17.13
7,-5,29:17.13
6,-5,30:17.13
7,-5,30:17.13
6,-5,31:17.13
4,-5,32:17.13
5,-5,32:17.13
6,-5,32:17.13
6,-5,33:17.13
6,-5,34:17.13
7,-5,34:17.13
6,-5,35:17.13
7,-5,35:17.13
7,-5,36:17.13
7,-4,36:17.13
7,-5,37:17.13
7,-5,38:17.13
6,-5,39:17.13
7,-5,39:17.13
6,-5,40:17.13
6,-5,41:17.13
6,-5,42:17.13
