[META]
version=2.0
spawnOnBlockType=2
spawnSunlight=True
spawnDarkness=True
spawnWater=False
spawnLava=False
underFill=False
randomRotation=True
dig=True
tree=False
branch=False
needsFoundation=True
rarity=100
collisionPercentage=20
spawnElevationMin=0
spawnElevationMax=200
spawnInBiome=Custom
[DATA]
4,-2,-8:17.13
-1,0,-8:17.13
5,0,-8:17.13
1,2,-8:17.13
3,2,-8:17.13
1,-5,-7:17.13
-2,-4,-7:17.13
4,-3,-7:17.13
4,-2,-7:17.13
5,0,-7:17.13
-1,1,-7:17.13
1,2,-7:17.13
4,2,-7:17.13
0,-4,-6:17.13
-2,-3,-6:17.13
3,-3,-6:17.13
4,-3,-6:17.13
5,-1,-6:17.13
-1,0,-6:17.13
-1,1,-6:17.13
0,1,-6:17.13
4,1,-6:17.13
-1,-3,-5:17.13
3,-3,-5:17.13
0,-1,-5:17.13
4,-1,-5:17.13
0,0,-5:17.13
0,1,-5:17.13
1,1,-5:17.13
4,1,-5:17.13
0,2,-5:17.13
-1,-3,-4:17.13
3,-3,-4:17.13
0,-1,-4:17.13
1,-1,-4:17.13
-1,0,-4:17.13
0,0,-4:17.13
3,0,-4:17.13
4,0,-4:17.13
-1,1,-4:17.13
0,1,-4:17.13
3,-3,-3:17.13
-1,-2,-3:17.13
1,-1,-3:17.13
1,0,-3:17.13
3,0,-3:17.13
0,1,-3:17.13
1,1,-3:17.13
0,-3,-2:17.13
1,-3,-2:17.13
2,-3,-2:17.13
3,-3,-2:17.13
-1,-2,-2:17.13
0,-2,-2:17.13
1,-2,-2:17.13
2,-2,-2:17.13
3,-2,-2:17.13
-1,-1,-2:17.13
0,-1,-2:17.13
1,-1,-2:17.13
2,-1,-2:17.13
3,-1,-2:17.13
-1,0,-2:17.13
0,0,-2:17.13
1,0,-2:17.13
2,0,-2:17.13
3,0,-2:17.13
0,1,-2:17.13
1,1,-2:17.13
2,1,-2:17.13
0,-3,-1:17.13
1,-3,-1:17.13
2,-3,-1:17.13
-1,-2,-1:17.13
0,-2,-1:17.13
2,-2,-1:17.13
3,-2,-1:17.13
-1,-1,-1:17.13
0,-1,-1:17.13
2,-1,-1:17.13
3,-1,-1:17.13
0,0,-1:17.13
1,0,-1:17.13
2,0,-1:17.13
1,1,-1:17.13
0,-3,0:17.13
1,-3,0:17.13
2,-3,0:17.13
-1,-2,0:17.13
0,-2,0:17.13
2,-2,0:17.13
-1,-1,0:17.13
2,-1,0:17.13
0,0,0:17.13
1,0,0:17.13
2,0,0:17.13
0,-3,1:17.13
1,-3,1:17.13
2,-3,1:17.13
-1,-2,1:17.13
0,-2,1:17.13
2,-2,1:17.13
-1,-1,1:17.13
0,-1,1:17.13
2,-1,1:17.13
0,0,1:17.13
1,0,1:17.13
2,0,1:17.13
0,-3,2:17.13
1,-3,2:17.13
2,-3,2:17.13
0,-2,2:17.13
2,-2,2:17.13
0,-1,2:17.13
2,-1,2:17.13
0,0,2:17.13
1,0,2:17.13
2,0,2:17.13
-2,-6,3:17.13
-2,-5,3:17.13
-1,-5,3:17.13
-1,-4,3:17.13
-1,-3,3:17.13
0,-3,3:17.13
1,-3,3:17.13
0,-2,3:17.13
1,-2,3:17.13
2,-2,3:17.13
0,-1,3:17.13
2,-1,3:17.13
5,-1,3:18.14
0,0,3:17.13
1,0,3:17.13
2,0,3:17.13
-1,-5,4:17.13
-1,-4,4:17.13
0,-3,4:17.13
1,-3,4:17.13
0,-2,4:17.13
1,-2,4:17.13
2,-2,4:17.13
0,-1,4:17.13
2,-1,4:17.13
3,-1,4:18.14
4,-1,4:17.13
5,-1,4:18.14
6,-1,4:17.13
0,0,4:17.13
1,0,4:17.13
0,-2,5:17.13
1,-2,5:17.13
2,-2,5:17.13
0,-1,5:17.13
2,-1,5:17.13
3,-1,5:18.14
4,-1,5:18.14
5,-1,5:18.14
0,0,5:17.13
1,0,5:17.13
3,0,5:18.14
4,0,5:18.14
5,0,5:18.14
0,-2,6:17.13
1,-2,6:17.13
2,-2,6:17.13
-1,-1,6:18.14
0,-1,6:17.13
1,-1,6:18.14
2,-1,6:17.13
4,-1,6:18.14
5,-1,6:18.14
-1,0,6:18.14
1,0,6:17.13
0,-2,7:17.13
1,-2,7:17.13
2,-2,7:17.13
-1,-1,7:18.14
0,-1,7:17.13
1,-1,7:18.14
2,-1,7:17.13
0,0,7:18.14
1,0,7:17.13
2,0,7:17.13
3,0,7:17.13
2,1,7:17.13
2,2,7:17.13
3,2,7:17.13
0,-2,8:17.13
1,-2,8:17.13
2,-2,8:17.13
0,-1,8:17.13
1,-1,8:18.14
2,-1,8:17.13
1,0,8:17.13
2,0,8:17.13
2,1,8:17.13
0,-2,9:17.13
1,-2,9:17.13
2,-2,9:17.13
0,-1,9:17.13
2,-1,9:17.13
1,0,9:17.13
0,-2,10:17.13
1,-2,10:17.13
2,-2,10:17.13
-1,-1,10:17.13
0,-1,10:17.13
2,-1,10:17.13
1,0,10:17.13
-1,2,10:17.13
-2,3,10:17.13
-1,3,10:17.13
4,-4,11:18.14
-1,-3,11:18.14
2,-3,11:17.13
0,-2,11:17.13
1,-2,11:17.13
2,-2,11:17.13
0,-1,11:17.13
1,-1,11:17.13
2,-1,11:17.13
0,0,11:17.13
1,0,11:17.13
-1,1,11:17.13
0,1,11:17.13
-1,2,11:17.13
2,-4,12:18.14
3,-4,12:18.14
4,-4,12:18.14
-1,-3,12:18.14
0,-3,12:18.14
2,-3,12:17.13
3,-3,12:18.14
0,-2,12:18.14
1,-2,12:17.13
2,-2,12:17.13
0,-1,12:17.13
1,-1,12:17.13
2,-1,12:17.13
1,0,12:17.13
3,-4,13:18.14
-5,-3,13:17.13
-4,-3,13:17.13
-3,-3,13:17.13
-1,-3,13:18.14
0,-3,13:18.14
2,-3,13:18.14
3,-3,13:18.14
-3,-2,13:17.13
-2,-2,13:17.13
-1,-2,13:18.14
0,-2,13:18.14
1,-2,13:17.13
2,-2,13:17.13
0,-1,13:17.13
1,-1,13:17.13
2,-1,13:17.13
1,0,13:17.13
2,1,13:18.14
-2,-2,14:17.13
-1,-2,14:17.13
0,-2,14:17.13
1,-2,14:17.13
-2,-1,14:18.14
-1,-1,14:18.14
0,-1,14:17.13
1,-1,14:17.13
2,-1,14:17.13
1,0,14:17.13
2,1,14:18.14
3,2,14:18.14
2,3,14:18.14
3,3,14:18.14
3,-4,15:17.13
0,-2,15:17.13
1,-2,15:17.13
-1,-1,15:18.14
0,-1,15:18.14
1,-1,15:17.13
2,-1,15:17.13
-1,0,15:18.14
-1,1,15:18.14
2,1,15:18.14
2,2,15:18.14
3,2,15:18.14
2,3,15:18.14
3,3,15:18.14
2,4,15:18.14
0,-2,16:17.13
1,-2,16:17.13
-1,-1,16:18.14
0,-1,16:17.13
1,-1,16:18.14
2,-1,16:17.13
0,0,16:18.14
1,0,16:18.14
2,0,16:18.14
2,1,16:18.14
1,2,16:18.14
2,2,16:18.14
3,2,16:18.14
3,3,16:18.14
2,-3,17:17.13
3,-3,17:18.14
0,-2,17:17.13
1,-2,17:17.13
2,-2,17:18.14
0,-1,17:17.13
1,-1,17:17.13
2,-1,17:17.13
2,0,17:17.13
2,1,17:18.14
3,2,17:18.14
4,-4,18:18.14
3,-3,18:18.14
4,-3,18:18.14
0,-2,18:17.13
1,-2,18:17.13
2,-2,18:18.14
5,-2,18:18.14
6,-2,18:17.13
-1,-1,18:17.13
0,-1,18:17.13
1,-1,18:17.13
2,-1,18:17.13
2,0,18:17.13
2,-3,19:18.14
3,-3,19:18.14
-1,-2,19:18.14
0,-2,19:18.14
1,-2,19:17.13
2,-2,19:18.14
3,-2,19:18.14
4,-2,19:18.14
5,-2,19:17.13
0,-1,19:17.13
1,-1,19:17.13
2,-1,19:17.13
3,-1,19:18.14
4,-1,19:17.13
-1,-4,20:17.13
0,-4,20:17.13
-2,-3,20:18.14
-1,-2,20:18.14
0,-2,20:18.14
1,-2,20:17.13
2,-2,20:17.13
3,-2,20:17.13
1,-1,20:17.13
2,-1,20:17.13
3,-1,20:17.13
-2,-4,21:18.14
-1,-4,21:18.14
-2,-3,21:18.14
-1,-3,21:18.14
0,-3,21:17.13
-2,-2,21:18.14
-1,-2,21:18.14
0,-2,21:18.14
1,-2,21:17.13
1,-1,21:17.13
2,-1,21:17.13
-1,-4,22:18.14
0,-3,22:18.14
-2,-2,22:18.14
-1,-2,22:18.14
0,-2,22:18.14
1,-2,22:17.13
1,-1,22:17.13
2,-1,22:17.13
0,1,22:17.13
-1,-2,23:18.14
0,-2,23:18.14
1,-2,23:17.13
2,-2,23:17.13
1,-1,23:17.13
2,-1,23:17.13
0,0,23:17.13
1,0,23:17.13
0,-2,24:17.13
1,-2,24:17.13
2,-2,24:17.13
1,-1,24:17.13
2,-1,24:17.13
3,0,24:17.13
1,-2,25:17.13
2,-2,25:17.13
1,-1,25:17.13
2,-1,25:17.13
2,0,25:17.13
2,-2,26:17.13
2,-1,26:17.13
1,-2,27:17.13
2,-2,27:17.13
2,-1,27:17.13
3,-1,27:17.13
