[META]
version=2.0
spawnOnBlockType=2
spawnSunlight=True
spawnDarkness=True
spawnWater=False
spawnLava=False
underFill=False
randomRotation=True
dig=True
tree=False
branch=False
needsFoundation=True
rarity=100
collisionPercentage=20
spawnElevationMin=0
spawnElevationMax=200
spawnInBiome=Custom
[DATA]
-3,-4,-8:17.13
1,-4,-8:17.13
5,-1,-8:17.13
-1,0,-8:17.13
5,0,-8:17.13
6,0,-8:17.13
-2,1,-8:17.13
-1,3,-8:17.13
1,-6,-7:17.13
1,-5,-7:17.13
2,-5,-7:17.13
-3,-4,-7:17.13
0,-4,-7:17.13
1,-4,-7:17.13
4,-1,-7:17.13
5,-1,-7:17.13
6,-1,-7:17.13
-3,0,-7:17.13
-2,0,-7:17.13
2,0,-7:17.13
3,0,-7:17.13
4,0,-7:17.13
5,0,-7:17.13
6,0,-7:17.13
-3,1,-7:17.13
-2,1,-7:17.13
-1,1,-7:17.13
4,1,-7:17.13
6,1,-7:17.13
-1,3,-7:17.13
1,3,-7:17.13
1,-6,-6:17.13
0,-5,-6:17.13
1,-5,-6:17.13
2,-5,-6:17.13
-2,-4,-6:17.13
1,-4,-6:17.13
2,-4,-6:17.13
1,-3,-6:17.13
-2,-1,-6:17.13
3,-1,-6:17.13
4,-1,-6:17.13
5,-1,-6:17.13
-2,0,-6:17.13
-1,0,-6:17.13
2,0,-6:17.13
3,0,-6:17.13
4,0,-6:17.13
5,0,-6:17.13
6,0,-6:17.13
-2,1,-6:17.13
3,1,-6:17.13
5,1,-6:17.13
0,3,-6:17.13
1,-6,-5:17.13
0,-5,-5:17.13
2,-5,-5:17.13
-2,-4,-5:17.13
1,-4,-5:17.13
2,-4,-5:17.13
-2,-3,-5:17.13
1,-3,-5:17.13
-2,-1,-5:17.13
3,-1,-5:17.13
-2,0,-5:17.13
-1,0,-5:17.13
2,0,-5:17.13
3,0,-5:17.13
4,0,-5:17.13
-2,1,-5:17.13
3,1,-5:17.13
4,1,-5:17.13
0,2,-5:17.13
1,-5,-4:17.13
1,-4,-4:17.13
-2,-3,-4:17.13
1,-3,-4:17.13
2,-3,-4:17.13
3,-2,-4:17.13
-1,-1,-4:17.13
2,-1,-4:17.13
4,-1,-4:17.13
5,-1,-4:17.13
-2,0,-4:17.13
3,0,-4:17.13
4,0,-4:17.13
-3,1,-4:17.13
3,1,-4:17.13
5,1,-4:17.13
0,2,-4:17.13
1,-4,-3:17.13
-3,-3,-3:17.13
-2,-3,-3:17.13
-1,-3,-3:17.13
1,-3,-3:17.13
2,-3,-3:17.13
2,-2,-3:17.13
3,-2,-3:17.13
4,-2,-3:17.13
-1,-1,-3:17.13
2,-1,-3:17.13
3,-1,-3:17.13
4,-1,-3:17.13
-2,0,-3:17.13
-1,0,-3:17.13
2,0,-3:17.13
3,0,-3:17.13
4,0,-3:17.13
-1,1,-3:17.13
0,1,-3:17.13
3,1,-3:17.13
4,1,-3:17.13
0,2,-3:17.13
-1,-5,-2:17.13
0,-5,-2:17.13
1,-5,-2:17.13
-1,-4,-2:17.13
0,-4,-2:17.13
1,-4,-2:17.13
2,-4,-2:17.13
3,-4,-2:17.13
4,-4,-2:17.13
-3,-3,-2:17.13
-2,-3,-2:17.13
-1,-3,-2:17.13
0,-3,-2:17.13
1,-3,-2:17.13
2,-3,-2:17.13
3,-3,-2:17.13
4,-3,-2:17.13
-3,-2,-2:17.13
-2,-2,-2:17.13
-1,-2,-2:17.13
0,-2,-2:17.13
1,-2,-2:17.13
2,-2,-2:17.13
3,-2,-2:17.13
4,-2,-2:17.13
-3,-1,-2:17.13
-2,-1,-2:17.13
-1,-1,-2:17.13
0,-1,-2:17.13
1,-1,-2:17.13
2,-1,-2:17.13
3,-1,-2:17.13
4,-1,-2:17.13
-3,0,-2:17.13
-2,0,-2:17.13
-1,0,-2:17.13
0,0,-2:17.13
1,0,-2:17.13
2,0,-2:17.13
3,0,-2:17.13
4,0,-2:17.13
-1,1,-2:17.13
0,1,-2:17.13
1,1,-2:17.13
2,1,-2:17.13
3,1,-2:17.13
0,2,-2:17.13
1,2,-2:17.13
2,2,-2:17.13
0,-5,-1:17.13
-1,-4,-1:17.13
0,-4,-1:17.13
1,-4,-1:17.13
2,-4,-1:17.13
3,-4,-1:17.13
4,-4,-1:17.13
-2,-3,-1:17.13
-1,-3,-1:17.13
0,-3,-1:17.13
1,-3,-1:17.13
2,-3,-1:17.13
3,-3,-1:17.13
4,-3,-1:17.13
5,-3,-1:17.13
-2,-2,-1:17.13
-1,-2,-1:17.13
0,-2,-1:17.13
1,-2,-1:17.13
2,-2,-1:17.13
3,-2,-1:17.13
4,-2,-1:17.13
5,-2,-1:17.13
-2,-1,-1:17.13
-1,-1,-1:17.13
0,-1,-1:17.13
1,-1,-1:17.13
2,-1,-1:17.13
3,-1,-1:17.13
4,-1,-1:17.13
5,-1,-1:17.13
-2,0,-1:17.13
-1,0,-1:17.13
1,0,-1:17.13
2,0,-1:17.13
3,0,-1:17.13
4,0,-1:17.13
0,1,-1:17.13
1,1,-1:17.13
2,1,-1:17.13
3,1,-1:17.13
4,1,-1:17.13
1,2,-1:17.13
2,2,-1:17.13
-1,-4,0:17.13
0,-4,0:17.13
1,-4,0:17.13
2,-4,0:17.13
3,-4,0:17.13
4,-4,0:17.13
-2,-3,0:17.13
-1,-3,0:17.13
0,-3,0:17.13
1,-3,0:17.13
2,-3,0:17.13
3,-3,0:17.13
4,-3,0:17.13
5,-3,0:17.13
-2,-2,0:17.13
-1,-2,0:18.14
0,-2,0:17.13
1,-2,0:17.13
2,-2,0:18.14
4,-2,0:17.13
5,-2,0:17.13
-2,-1,0:17.13
0,-1,0:17.13
1,-1,0:17.13
3,-1,0:17.13
4,-1,0:17.13
-2,0,0:17.13
-1,0,0:17.13
1,0,0:17.13
2,0,0:17.13
3,0,0:17.13
4,0,0:17.13
0,1,0:17.13
1,1,0:17.13
2,1,0:17.13
3,1,0:17.13
1,2,0:17.13
0,-4,1:17.13
1,-4,1:17.13
2,-4,1:17.13
3,-4,1:17.13
-2,-3,1:17.13
-1,-3,1:17.13
0,-3,1:18.14
1,-3,1:17.13
2,-3,1:17.13
3,-3,1:17.13
4,-3,1:17.13
-2,-2,1:17.13
-1,-2,1:18.14
0,-2,1:18.14
1,-2,1:17.13
2,-2,1:18.14
3,-2,1:18.14
4,-2,1:17.13
-2,-1,1:17.13
-1,-1,1:18.14
1,-1,1:17.13
2,-1,1:18.14
3,-1,1:17.13
4,-1,1:17.13
-2,0,1:17.13
-1,0,1:17.13
1,0,1:17.13
2,0,1:17.13
3,0,1:17.13
4,0,1:17.13
0,1,1:17.13
1,1,1:17.13
2,1,1:17.13
3,1,1:17.13
0,-4,2:17.13
1,-4,2:17.13
2,-4,2:17.13
3,-4,2:17.13
-1,-3,2:17.13
0,-3,2:17.13
1,-3,2:17.13
2,-3,2:17.13
3,-3,2:17.13
4,-3,2:17.13
-2,-2,2:17.13
0,-2,2:18.14
1,-2,2:17.13
2,-2,2:18.14
3,-2,2:17.13
4,-2,2:17.13
-2,-1,2:17.13
1,-1,2:17.13
2,-1,2:18.14
3,-1,2:17.13
4,-1,2:17.13
-2,0,2:17.13
-1,0,2:17.13
1,0,2:17.13
2,0,2:17.13
3,0,2:17.13
0,1,2:17.13
1,1,2:17.13
2,1,2:17.13
3,1,2:17.13
0,-4,3:17.13
1,-4,3:17.13
2,-4,3:17.13
3,-4,3:17.13
-1,-3,3:17.13
0,-3,3:17.13
1,-3,3:17.13
2,-3,3:17.13
3,-3,3:17.13
4,-3,3:17.13
-2,-2,3:17.13
1,-2,3:17.13
2,-2,3:18.14
3,-2,3:17.13
4,-2,3:17.13
-2,-1,3:17.13
1,-1,3:17.13
3,-1,3:17.13
4,-1,3:17.13
-2,0,3:17.13
-1,0,3:17.13
2,0,3:17.13
3,0,3:17.13
0,1,3:17.13
1,1,3:17.13
2,1,3:17.13
3,1,3:17.13
0,-4,4:17.13
1,-4,4:17.13
2,-4,4:17.13
3,-4,4:17.13
-1,-3,4:17.13
0,-3,4:17.13
1,-3,4:17.13
2,-3,4:17.13
3,-3,4:17.13
4,-3,4:17.13
-2,-2,4:17.13
1,-2,4:17.13
3,-2,4:17.13
4,-2,4:17.13
-2,-1,4:17.13
1,-1,4:17.13
3,-1,4:17.13
4,-1,4:17.13
-1,0,4:17.13
2,0,4:17.13
3,0,4:17.13
0,1,4:17.13
1,1,4:17.13
2,1,4:17.13
0,-4,5:17.13
1,-4,5:17.13
2,-4,5:17.13
3,-4,5:17.13
-1,-3,5:17.13
1,-3,5:17.13
2,-3,5:17.13
3,-3,5:17.13
4,-3,5:17.13
-1,-2,5:17.13
1,-2,5:17.13
3,-2,5:17.13
4,-2,5:17.13
-2,-1,5:18.14
-1,-1,5:17.13
1,-1,5:17.13
3,-1,5:17.13
4,-1,5:17.13
5,-1,5:17.13
-1,0,5:17.13
0,0,5:17.13
2,0,5:17.13
3,0,5:17.13
4,0,5:17.13
5,0,5:17.13
0,1,5:17.13
1,1,5:17.13
2,1,5:17.13
6,1,5:17.13
7,2,5:17.13
-3,-10,6:17.13
-3,-9,6:17.13
-2,-6,6:17.13
-1,-6,6:17.13
-2,-5,6:17.13
-1,-5,6:17.13
-1,-4,6:18.14
0,-4,6:17.13
1,-4,6:17.13
2,-4,6:17.13
-1,-3,6:17.13
0,-3,6:17.13
1,-3,6:17.13
2,-3,6:17.13
3,-3,6:17.13
4,-3,6:17.13
-1,-2,6:17.13
1,-2,6:17.13
3,-2,6:17.13
4,-2,6:17.13
-3,-1,6:18.14
-2,-1,6:18.14
-1,-1,6:17.13
0,-1,6:17.13
1,-1,6:17.13
3,-1,6:17.13
4,-1,6:17.13
5,-1,6:17.13
-3,0,6:17.13
-1,0,6:17.13
0,0,6:17.13
2,0,6:17.13
3,0,6:17.13
4,0,6:17.13
5,0,6:17.13
7,0,6:18.14
8,0,6:18.14
0,1,6:17.13
1,1,6:17.13
2,1,6:17.13
5,1,6:17.13
6,1,6:17.13
-4,-11,7:17.13
-4,-10,7:17.13
-3,-10,7:17.13
-3,-9,7:17.13
-3,-8,7:17.13
-2,-8,7:17.13
-2,-7,7:17.13
-2,-6,7:17.13
-1,-6,7:17.13
-2,-5,7:17.13
-1,-5,7:17.13
0,-5,7:17.13
-2,-4,7:17.13
-1,-4,7:17.13
0,-4,7:17.13
1,-4,7:17.13
2,-4,7:17.13
-1,-3,7:17.13
2,-3,7:17.13
3,-3,7:17.13
-3,-2,7:18.14
-2,-2,7:18.14
-1,-2,7:17.13
0,-2,7:18.14
1,-2,7:17.13
3,-2,7:17.13
4,-2,7:17.13
-3,-1,7:18.14
-2,-1,7:18.14
-1,-1,7:17.13
0,-1,7:17.13
1,-1,7:17.13
2,-1,7:17.13
3,-1,7:17.13
4,-1,7:17.13
-1,0,7:17.13
0,0,7:17.13
2,0,7:17.13
3,0,7:17.13
5,0,7:18.14
6,0,7:18.14
8,0,7:18.14
9,0,7:18.14
10,0,7:17.13
0,1,7:17.13
1,1,7:17.13
2,1,7:17.13
-3,-8,8:17.13
-1,-4,8:17.13
0,-4,8:17.13
1,-4,8:17.13
2,-4,8:17.13
4,-4,8:18.14
-1,-3,8:17.13
2,-3,8:17.13
3,-3,8:17.13
4,-3,8:18.14
5,-3,8:18.14
-1,-2,8:17.13
1,-2,8:17.13
3,-2,8:17.13
4,-2,8:17.13
-2,-1,8:18.14
-1,-1,8:17.13
0,-1,8:18.14
1,-1,8:17.13
2,-1,8:17.13
3,-1,8:17.13
4,-1,8:17.13
5,-1,8:18.14
6,-1,8:17.13
7,-1,8:17.13
8,-1,8:17.13
-1,0,8:17.13
0,0,8:17.13
2,0,8:17.13
3,0,8:17.13
5,0,8:18.14
6,0,8:18.14
7,0,8:17.13
8,0,8:17.13
9,0,8:17.13
10,0,8:17.13
1,1,8:17.13
0,-4,9:17.13
1,-4,9:17.13
3,-4,9:18.14
4,-4,9:18.14
-1,-3,9:17.13
0,-3,9:17.13
2,-3,9:17.13
3,-3,9:17.13
4,-3,9:18.14
-1,-2,9:17.13
1,-2,9:17.13
3,-2,9:17.13
4,-2,9:17.13
-1,-1,9:17.13
1,-1,9:17.13
2,-1,9:17.13
3,-1,9:17.13
4,-1,9:17.13
5,-1,9:17.13
6,-1,9:17.13
-1,0,9:17.13
0,0,9:17.13
2,0,9:17.13
3,0,9:17.13
4,0,9:17.13
5,0,9:17.13
6,0,9:18.14
7,0,9:18.14
8,0,9:18.14
9,0,9:18.14
10,0,9:18.14
1,1,9:17.13
8,1,9:18.14
9,1,9:18.14
-1,-5,10:17.13
0,-5,10:17.13
0,-4,10:17.13
1,-4,10:17.13
3,-4,10:18.14
-1,-3,10:17.13
0,-3,10:17.13
1,-3,10:17.13
2,-3,10:17.13
3,-3,10:17.13
4,-3,10:18.14
-1,-2,10:17.13
1,-2,10:17.13
3,-2,10:17.13
4,-2,10:17.13
-1,-1,10:17.13
1,-1,10:17.13
2,-1,10:17.13
3,-1,10:17.13
4,-1,10:18.14
5,-1,10:18.14
-1,0,10:17.13
0,0,10:17.13
1,0,10:17.13
2,0,10:17.13
3,0,10:17.13
4,0,10:18.14
7,0,10:18.14
8,0,10:18.14
9,0,10:18.14
1,1,10:17.13
4,1,10:18.14
5,1,10:18.14
6,1,10:18.14
7,1,10:18.14
6,2,10:18.14
7,2,10:18.14
8,2,10:18.14
9,2,10:18.14
0,-4,11:17.13
1,-4,11:17.13
-1,-3,11:17.13
0,-3,11:17.13
1,-3,11:17.13
2,-3,11:17.13
3,-3,11:17.13
-1,-2,11:17.13
1,-2,11:17.13
2,-2,11:18.14
3,-2,11:17.13
4,-2,11:17.13
-3,-1,11:18.14
-2,-1,11:18.14
-1,-1,11:17.13
0,-1,11:18.14
1,-1,11:17.13
2,-1,11:17.13
3,-1,11:17.13
-3,0,11:18.14
-1,0,11:17.13
0,0,11:17.13
1,0,11:17.13
2,0,11:17.13
3,0,11:17.13
6,0,11:18.14
7,0,11:18.14
8,0,11:18.14
9,0,11:18.14
1,1,11:17.13
0,-3,12:17.13
1,-3,12:17.13
2,-3,12:17.13
3,-3,12:17.13
-1,-2,12:17.13
1,-2,12:17.13
3,-2,12:17.13
4,-2,12:17.13
-3,-1,12:18.14
-2,-1,12:18.14
-1,-1,12:17.13
0,-1,12:18.14
1,-1,12:17.13
2,-1,12:17.13
3,-1,12:17.13
-2,0,12:18.14
-1,0,12:17.13
0,0,12:17.13
1,0,12:17.13
2,0,12:17.13
3,0,12:17.13
-3,1,12:18.14
6,2,12:17.13
4,-8,13:17.13
0,-3,13:17.13
1,-3,13:17.13
2,-3,13:17.13
3,-3,13:17.13
5,-3,13:17.13
-1,-2,13:17.13
1,-2,13:17.13
3,-2,13:17.13
4,-2,13:17.13
-3,-1,13:18.14
-2,-1,13:18.14
-1,-1,13:17.13
0,-1,13:18.14
2,-1,13:17.13
3,-1,13:17.13
-1,0,13:18.14
0,0,13:17.13
1,0,13:17.13
2,0,13:17.13
-2,1,13:18.14
5,2,13:17.13
6,2,13:17.13
3,-7,14:17.13
3,-6,14:17.13
3,-5,14:17.13
2,-4,14:17.13
3,-4,14:17.13
0,-3,14:17.13
1,-3,14:17.13
2,-3,14:17.13
3,-3,14:17.13
-1,-2,14:17.13
1,-2,14:17.13
3,-2,14:17.13
4,-2,14:17.13
-2,-1,14:18.14
-1,-1,14:17.13
0,-1,14:18.14
2,-1,14:17.13
3,-1,14:17.13
4,-1,14:18.14
-1,0,14:17.13
0,0,14:17.13
1,0,14:17.13
2,0,14:17.13
-1,1,14:18.14
1,1,14:17.13
2,1,14:17.13
3,1,14:17.13
4,1,14:17.13
2,2,14:17.13
4,2,14:17.13
3,3,14:17.13
3,4,14:17.13
3,5,14:17.13
4,5,14:17.13
3,-5,15:17.13
0,-3,15:17.13
1,-3,15:17.13
2,-3,15:17.13
3,-3,15:17.13
-1,-2,15:17.13
1,-2,15:17.13
3,-2,15:17.13
4,-2,15:17.13
-2,-1,15:18.14
-1,-1,15:17.13
0,-1,15:18.14
1,-1,15:18.14
2,-1,15:17.13
3,-1,15:17.13
4,-1,15:18.14
5,-1,15:18.14
-1,0,15:17.13
0,0,15:17.13
1,0,15:17.13
2,0,15:17.13
5,0,15:18.14
0,1,15:18.14
1,1,15:17.13
2,1,15:17.13
3,1,15:17.13
0,2,15:18.14
2,2,15:17.13
3,2,15:17.13
2,3,15:17.13
3,3,15:17.13
3,4,15:17.13
0,-4,16:18.14
0,-3,16:17.13
1,-3,16:17.13
2,-3,16:17.13
3,-3,16:17.13
-1,-2,16:17.13
1,-2,16:17.13
3,-2,16:17.13
4,-2,16:17.13
-1,-1,16:17.13
0,-1,16:18.14
1,-1,16:18.14
2,-1,16:17.13
3,-1,16:17.13
4,-1,16:18.14
5,-1,16:18.14
6,-1,16:18.14
-1,0,16:17.13
0,0,16:17.13
1,0,16:18.14
2,0,16:17.13
5,0,16:18.14
1,1,16:18.14
2,1,16:18.14
1,2,16:18.14
2,2,16:18.14
-2,-6,17:18.14
-1,-5,17:18.14
0,-4,17:18.14
-1,-3,17:17.13
0,-3,17:17.13
1,-3,17:17.13
2,-3,17:17.13
3,-3,17:17.13
-1,-2,17:17.13
1,-2,17:17.13
2,-2,17:17.13
3,-2,17:17.13
4,-2,17:18.14
5,-2,17:17.13
6,-2,17:17.13
7,-2,17:17.13
8,-2,17:17.13
9,-2,17:17.13
10,-2,17:17.13
-1,-1,17:17.13
2,-1,17:17.13
3,-1,17:17.13
4,-1,17:18.14
5,-1,17:18.14
-1,0,17:17.13
0,0,17:17.13
1,0,17:17.13
2,0,17:17.13
4,0,17:18.14
1,1,17:18.14
1,2,17:18.14
-2,-6,18:18.14
-1,-6,18:18.14
-1,-5,18:18.14
0,-4,18:18.14
5,-4,18:18.14
-1,-3,18:17.13
0,-3,18:17.13
1,-3,18:17.13
2,-3,18:17.13
3,-3,18:17.13
4,-3,18:18.14
-1,-2,18:17.13
1,-2,18:17.13
2,-2,18:17.13
3,-2,18:17.13
4,-2,18:17.13
5,-2,18:17.13
-1,-1,18:17.13
2,-1,18:17.13
3,-1,18:17.13
-1,0,18:17.13
0,0,18:17.13
1,0,18:17.13
2,0,18:17.13
-5,7,18:17.13
-1,-7,19:18.14
0,-7,19:18.14
-2,-6,19:18.14
-1,-6,19:18.14
0,-6,19:18.14
-1,-5,19:18.14
4,-5,19:18.14
0,-4,19:18.14
4,-4,19:18.14
5,-4,19:18.14
-1,-3,19:17.13
0,-3,19:17.13
1,-3,19:17.13
2,-3,19:17.13
3,-3,19:18.14
4,-3,19:18.14
5,-3,19:18.14
-3,-2,19:17.13
-2,-2,19:17.13
-1,-2,19:17.13
1,-2,19:17.13
2,-2,19:17.13
3,-2,19:17.13
-1,-1,19:17.13
2,-1,19:17.13
3,-1,19:17.13
-1,0,19:17.13
0,0,19:17.13
1,0,19:17.13
2,0,19:17.13
1,2,19:17.13
-5,6,19:17.13
-4,6,19:17.13
-5,7,19:17.13
-2,-6,20:18.14
0,-6,20:18.14
-1,-5,20:18.14
0,-5,20:18.14
0,-4,20:18.14
3,-4,20:18.14
0,-3,20:17.13
1,-3,20:17.13
2,-3,20:17.13
3,-3,20:18.14
4,-3,20:18.14
-1,-2,20:17.13
1,-2,20:17.13
2,-2,20:17.13
3,-2,20:17.13
-1,-1,20:17.13
2,-1,20:17.13
3,-1,20:17.13
-1,0,20:17.13
0,0,20:17.13
1,0,20:17.13
2,0,20:17.13
2,1,20:17.13
-3,4,20:17.13
-4,5,20:17.13
-3,5,20:17.13
-4,6,20:17.13
-2,-5,21:18.14
-1,-5,21:18.14
1,-5,21:18.14
4,-5,21:17.13
-1,-4,21:18.14
0,-4,21:17.13
1,-4,21:18.14
-1,-3,21:18.14
0,-3,21:17.13
1,-3,21:17.13
2,-3,21:17.13
3,-3,21:17.13
-1,-2,21:17.13
1,-2,21:18.14
2,-2,21:17.13
3,-2,21:17.13
-1,-1,21:17.13
2,-1,21:17.13
3,-1,21:17.13
-1,0,21:17.13
0,0,21:17.13
1,0,21:17.13
2,0,21:17.13
-1,1,21:17.13
0,1,21:17.13
2,1,21:17.13
-2,2,21:17.13
-1,2,21:17.13
-3,3,21:17.13
-2,3,21:17.13
-3,4,21:17.13
-2,4,21:17.13
-3,5,21:17.13
4,-8,22:18.14
5,-8,22:18.14
4,-7,22:18.14
7,-6,22:18.14
-3,-5,22:18.14
-2,-5,22:18.14
4,-5,22:17.13
6,-5,22:18.14
-2,-4,22:18.14
-1,-4,22:18.14
0,-4,22:17.13
-1,-3,22:18.14
0,-3,22:17.13
1,-3,22:17.13
2,-3,22:17.13
-1,-2,22:17.13
1,-2,22:17.13
2,-2,22:17.13
3,-2,22:17.13
-1,-1,22:17.13
2,-1,22:17.13
3,-1,22:17.13
0,0,22:17.13
1,0,22:18.14
2,0,22:17.13
0,1,22:18.14
1,1,22:18.14
0,2,22:18.14
5,-8,23:18.14
4,-7,23:18.14
5,-7,23:18.14
6,-7,23:18.14
7,-7,23:18.14
-2,-6,23:18.14
-1,-6,23:18.14
3,-6,23:18.14
4,-6,23:18.14
6,-6,23:18.14
-3,-5,23:18.14
-2,-5,23:18.14
5,-5,23:18.14
6,-5,23:18.14
-2,-4,23:18.14
3,-4,23:17.13
4,-4,23:17.13
5,-4,23:18.14
-1,-3,23:18.14
0,-3,23:17.13
1,-3,23:17.13
2,-3,23:17.13
-1,-2,23:17.13
0,-2,23:18.14
1,-2,23:17.13
2,-2,23:17.13
3,-2,23:17.13
4,-2,23:17.13
-1,-1,23:17.13
2,-1,23:17.13
3,-1,23:17.13
-3,0,23:17.13
-2,0,23:17.13
-1,0,23:18.14
0,0,23:17.13
1,0,23:18.14
2,0,23:17.13
-1,1,23:18.14
0,1,23:18.14
1,1,23:18.14
0,2,23:18.14
5,-7,24:18.14
6,-7,24:18.14
-1,-6,24:18.14
4,-6,24:18.14
5,-6,24:18.14
6,-6,24:18.14
-4,-5,24:18.14
-3,-5,24:18.14
-1,-5,24:18.14
3,-5,24:18.14
4,-5,24:18.14
5,-5,24:18.14
-3,-4,24:18.14
-2,-4,24:18.14
-1,-4,24:18.14
2,-4,24:18.14
3,-4,24:17.13
4,-4,24:18.14
-4,-3,24:17.13
-1,-3,24:18.14
0,-3,24:17.13
1,-3,24:17.13
2,-3,24:17.13
3,-3,24:18.14
-1,-2,24:17.13
0,-2,24:18.14
2,-2,24:17.13
3,-2,24:17.13
4,-2,24:18.14
-1,-1,24:17.13
0,-1,24:18.14
1,-1,24:18.14
2,-1,24:17.13
3,-1,24:17.13
-2,0,24:17.13
-1,0,24:18.14
0,0,24:17.13
1,0,24:17.13
2,0,24:17.13
1,1,24:18.14
-10,-6,25:17.13
6,-6,25:18.14
-9,-5,25:17.13
-8,-5,25:17.13
-7,-5,25:17.13
-1,-5,25:18.14
4,-5,25:18.14
5,-5,25:18.14
6,-5,25:18.14
-7,-4,25:17.13
-6,-4,25:17.13
-5,-4,25:17.13
-3,-4,25:18.14
-2,-4,25:18.14
-1,-4,25:18.14
2,-4,25:18.14
3,-4,25:17.13
4,-4,25:18.14
-5,-3,25:17.13
-4,-3,25:17.13
-3,-3,25:17.13
-1,-3,25:18.14
0,-3,25:17.13
1,-3,25:17.13
2,-3,25:17.13
3,-3,25:17.13
-1,-2,25:17.13
0,-2,25:18.14
1,-2,25:17.13
2,-2,25:17.13
3,-2,25:17.13
4,-2,25:18.14
5,-2,25:18.14
6,-2,25:18.14
-1,-1,25:17.13
0,-1,25:17.13
1,-1,25:17.13
2,-1,25:17.13
3,-1,25:17.13
0,0,25:17.13
1,0,25:17.13
2,0,25:17.13
5,1,25:17.13
3,3,25:18.14
3,4,25:18.14
-5,-4,26:17.13
-3,-4,26:18.14
4,-4,26:18.14
-5,-3,26:17.13
-4,-3,26:17.13
-3,-3,26:17.13
-2,-3,26:18.14
-1,-3,26:18.14
0,-3,26:17.13
1,-3,26:17.13
2,-3,26:17.13
-3,-2,26:17.13
-2,-2,26:17.13
-1,-2,26:17.13
0,-2,26:18.14
2,-2,26:17.13
3,-2,26:17.13
4,-2,26:18.14
5,-2,26:18.14
6,-2,26:18.14
-2,-1,26:18.14
-1,-1,26:17.13
0,-1,26:18.14
2,-1,26:17.13
3,-1,26:17.13
4,-1,26:17.13
5,-1,26:18.14
6,-1,26:18.14
0,0,26:17.13
1,0,26:17.13
2,0,26:17.13
4,0,26:17.13
5,0,26:17.13
6,0,26:18.14
3,3,26:18.14
3,4,26:18.14
4,4,26:18.14
4,5,26:18.14
4,6,26:18.14
4,7,26:18.14
-3,-3,27:17.13
0,-3,27:17.13
1,-3,27:17.13
2,-3,27:17.13
-2,-2,27:17.13
-1,-2,27:17.13
0,-2,27:17.13
2,-2,27:17.13
3,-2,27:18.14
4,-2,27:18.14
5,-2,27:18.14
6,-2,27:18.14
7,-2,27:18.14
-4,-1,27:18.14
-3,-1,27:18.14
-2,-1,27:18.14
-1,-1,27:17.13
0,-1,27:18.14
1,-1,27:18.14
2,-1,27:17.13
3,-1,27:17.13
4,-1,27:18.14
-4,0,27:18.14
0,0,27:17.13
1,0,27:17.13
2,0,27:17.13
4,0,27:18.14
5,0,27:18.14
6,0,27:18.14
3,3,27:18.14
3,4,27:18.14
4,4,27:18.14
4,5,27:18.14
4,6,27:18.14
3,7,27:18.14
4,7,27:18.14
5,7,27:18.14
3,8,27:18.14
5,-7,28:17.13
2,-4,28:17.13
0,-3,28:17.13
1,-3,28:17.13
2,-3,28:17.13
-1,-2,28:17.13
0,-2,28:17.13
2,-2,28:17.13
3,-2,28:18.14
4,-2,28:18.14
5,-2,28:18.14
-4,-1,28:18.14
-3,-1,28:18.14
-2,-1,28:18.14
-1,-1,28:17.13
0,-1,28:18.14
1,-1,28:18.14
2,-1,28:17.13
3,-1,28:18.14
-4,0,28:18.14
-3,0,28:18.14
0,0,28:17.13
1,0,28:17.13
2,0,28:17.13
-4,1,28:18.14
-3,1,28:18.14
-4,2,28:18.14
3,2,28:18.14
3,3,28:18.14
4,5,28:18.14
3,6,28:18.14
4,6,28:18.14
3,7,28:18.14
5,7,28:18.14
2,8,28:18.14
5,-6,29:17.13
0,-3,29:17.13
1,-3,29:17.13
2,-3,29:17.13
-1,-2,29:17.13
0,-2,29:17.13
1,-2,29:17.13
2,-2,29:17.13
4,-2,29:17.13
-4,-1,29:18.14
-3,-1,29:18.14
-2,-1,29:18.14
-1,-1,29:18.14
0,-1,29:17.13
1,-1,29:17.13
2,-1,29:17.13
3,-1,29:17.13
-2,0,29:18.14
-1,0,29:18.14
0,0,29:17.13
1,0,29:17.13
2,0,29:17.13
-3,1,29:18.14
-2,1,29:18.14
-3,2,29:18.14
3,2,29:18.14
3,5,29:18.14
4,5,29:18.14
2,6,29:18.14
3,6,29:18.14
4,6,29:18.14
2,7,29:18.14
5,7,29:18.14
5,8,29:18.14
4,-6,30:17.13
0,-3,30:17.13
1,-3,30:17.13
-1,-2,30:17.13
0,-2,30:17.13
1,-2,30:17.13
2,-2,30:17.13
3,-2,30:17.13
4,-2,30:17.13
-3,-1,30:18.14
-2,-1,30:18.14
-1,-1,30:18.14
0,-1,30:18.14
1,-1,30:18.14
2,-1,30:17.13
3,-1,30:17.13
0,0,30:17.13
1,0,30:17.13
2,0,30:17.13
-1,1,30:18.14
0,1,30:18.14
3,2,30:18.14
3,3,30:18.14
3,4,30:18.14
3,5,30:18.14
4,5,30:17.13
2,6,30:18.14
4,6,30:18.14
1,7,30:18.14
4,7,30:18.14
5,7,30:18.14
5,8,30:18.14
4,-5,31:17.13
0,-3,31:17.13
1,-3,31:17.13
-1,-2,31:17.13
0,-2,31:17.13
1,-2,31:17.13
2,-2,31:17.13
3,-2,31:17.13
-2,-1,31:18.14
-1,-1,31:18.14
0,-1,31:17.13
1,-1,31:18.14
2,-1,31:17.13
3,-1,31:17.13
0,0,31:17.13
1,0,31:17.13
0,1,31:18.14
1,1,31:18.14
3,2,31:18.14
3,3,31:18.14
2,4,31:18.14
4,4,31:17.13
1,5,31:18.14
2,5,31:18.14
4,5,31:18.14
1,6,31:18.14
4,6,31:18.14
5,7,31:18.14
3,-5,32:17.13
4,-5,32:17.13
0,-3,32:17.13
1,-3,32:17.13
-1,-2,32:17.13
0,-2,32:17.13
1,-2,32:17.13
2,-2,32:17.13
-1,-1,32:18.14
0,-1,32:17.13
1,-1,32:17.13
2,-1,32:17.13
3,-1,32:18.14
0,0,32:17.13
1,0,32:17.13
2,0,32:17.13
2,2,32:18.14
3,2,32:18.14
2,3,32:18.14
3,3,32:17.13
2,4,32:18.14
3,4,32:17.13
4,4,32:17.13
4,5,32:18.14
4,6,32:18.14
3,-4,33:17.13
5,-4,33:18.14
1,-3,33:17.13
2,-3,33:17.13
3,-3,33:18.14
4,-3,33:18.14
0,-2,33:17.13
1,-2,33:17.13
2,-2,33:17.13
0,-1,33:17.13
1,-1,33:17.13
2,-1,33:17.13
0,0,33:17.13
1,0,33:17.13
2,0,33:17.13
2,1,33:17.13
2,2,33:17.13
3,2,33:17.13
3,3,33:17.13
3,4,33:18.14
6,-5,34:18.14
7,-5,34:18.14
8,-5,34:18.14
5,-4,34:18.14
6,-4,34:18.14
1,-3,34:17.13
2,-3,34:17.13
3,-3,34:18.14
4,-3,34:18.14
-1,-2,34:17.13
0,-2,34:17.13
1,-2,34:17.13
2,-2,34:17.13
0,-1,34:17.13
1,-1,34:17.13
2,-1,34:17.13
11,-1,34:17.13
1,0,34:17.13
2,0,34:17.13
2,1,34:17.13
5,-5,35:18.14
6,-5,35:18.14
5,-4,35:18.14
6,-4,35:18.14
7,-4,35:18.14
8,-4,35:18.14
1,-3,35:17.13
3,-3,35:18.14
4,-3,35:18.14
6,-3,35:18.14
7,-3,35:18.14
8,-3,35:18.14
9,-3,35:18.14
-3,-2,35:17.13
-2,-2,35:17.13
-1,-2,35:17.13
0,-2,35:17.13
1,-2,35:17.13
2,-2,35:17.13
0,-1,35:17.13
1,-1,35:17.13
2,-1,35:17.13
9,-1,35:17.13
10,-1,35:17.13
1,0,35:17.13
2,0,35:17.13
4,-5,36:18.14
5,-5,36:18.14
4,-4,36:18.14
-2,-3,36:18.14
1,-3,36:17.13
3,-3,36:18.14
4,-3,36:18.14
5,-3,36:18.14
0,-2,36:17.13
1,-2,36:17.13
2,-2,36:17.13
4,-2,36:18.14
6,-2,36:18.14
7,-2,36:18.14
8,-2,36:18.14
0,-1,36:17.13
1,-1,36:17.13
2,-1,36:17.13
8,-1,36:17.13
9,-1,36:17.13
1,0,36:17.13
2,0,36:17.13
2,-4,37:18.14
3,-4,37:18.14
-2,-3,37:18.14
-1,-3,37:18.14
1,-3,37:17.13
2,-3,37:18.14
3,-3,37:18.14
0,-2,37:17.13
1,-2,37:17.13
2,-2,37:17.13
3,-2,37:18.14
4,-2,37:17.13
5,-2,37:18.14
0,-1,37:17.13
1,-1,37:17.13
2,-1,37:17.13
3,-1,37:18.14
4,-1,37:18.14
5,-1,37:18.14
6,-1,37:18.14
7,-1,37:17.13
8,-1,37:17.13
1,0,37:17.13
-4,-4,38:18.14
-3,-4,38:18.14
-2,-3,38:18.14
-1,-3,38:18.14
1,-3,38:18.14
2,-3,38:18.14
0,-2,38:17.13
1,-2,38:17.13
2,-2,38:17.13
3,-2,38:17.13
4,-2,38:17.13
5,-2,38:17.13
6,-2,38:17.13
0,-1,38:17.13
1,-1,38:17.13
2,-1,38:17.13
3,-1,38:17.13
4,-1,38:17.13
5,-1,38:17.13
6,-1,38:17.13
3,0,38:18.14
-1,-7,39:17.13
-1,-6,39:17.13
-5,-5,39:18.14
-4,-5,39:18.14
-5,-4,39:18.14
-4,-4,39:18.14
-3,-4,39:18.14
-1,-3,39:18.14
1,-3,39:17.13
0,-2,39:17.13
1,-2,39:17.13
2,-2,39:17.13
0,-1,39:17.13
1,-1,39:17.13
2,-1,39:17.13
3,-1,39:17.13
-4,-6,40:18.14
-3,-6,40:18.14
-1,-6,40:17.13
-4,-5,40:18.14
-3,-5,40:18.14
-1,-5,40:17.13
0,-5,40:17.13
-5,-4,40:18.14
-4,-4,40:18.14
-3,-4,40:18.14
-2,-4,40:18.14
0,-4,40:17.13
1,-4,40:17.13
-3,-3,40:18.14
-2,-3,40:18.14
0,-3,40:17.13
1,-3,40:17.13
0,-2,40:18.14
1,-2,40:17.13
2,-2,40:17.13
1,-1,40:17.13
2,-1,40:17.13
-3,-7,41:18.14
-3,-6,41:18.14
-2,-6,41:18.14
-2,-5,41:18.14
-5,-4,41:18.14
-4,-4,41:18.14
-2,-4,41:18.14
0,-4,41:17.13
1,-4,41:17.13
-2,-3,41:18.14
-1,-3,41:18.14
0,-3,41:17.13
1,-3,41:17.13
-1,-2,41:18.14
0,-2,41:18.14
1,-2,41:17.13
2,-2,41:17.13
1,-1,41:17.13
2,-1,41:17.13
-1,-6,42:18.14
-1,-5,42:18.14
0,-5,42:18.14
-5,-4,42:18.14
-4,-4,42:18.14
0,-4,42:18.14
-3,-3,42:18.14
-2,-3,42:18.14
0,-2,42:18.14
1,-2,42:17.13
2,-2,42:17.13
1,-1,42:17.13
2,-1,42:17.13
-1,2,42:17.13
-1,3,42:17.13
0,-4,43:18.14
1,-4,43:18.14
-3,-3,43:18.14
-2,-3,43:18.14
1,-3,43:18.14
-1,-2,43:18.14
0,-2,43:18.14
1,-2,43:17.13
2,-2,43:17.13
1,-1,43:17.13
2,-1,43:17.13
3,-1,43:17.13
0,1,43:17.13
-1,2,43:17.13
0,2,43:17.13
1,-2,44:17.13
2,-2,44:17.13
1,-1,44:17.13
2,-1,44:17.13
3,-1,44:17.13
4,-1,44:17.13
1,0,44:17.13
0,1,44:17.13
1,1,44:17.13
-2,-2,45:17.13
-1,-2,45:17.13
1,-2,45:17.13
2,-2,45:17.13
1,-1,45:17.13
2,-1,45:17.13
3,-1,45:17.13
1,0,45:17.13
-1,-2,46:17.13
1,-2,46:17.13
2,-2,46:17.13
1,-1,46:17.13
2,-1,46:17.13
3,-1,46:17.13
0,-2,47:17.13
2,-2,47:17.13
3,-2,47:17.13
2,-1,47:17.13
3,-1,47:17.13
4,1,47:17.13
0,-2,48:17.13
1,-2,48:17.13
2,-2,48:17.13
3,-2,48:17.13
1,-1,48:17.13
2,-1,48:17.13
3,-1,48:17.13
3,0,48:17.13
3,1,48:17.13
4,1,48:17.13
2,-2,49:17.13
3,-2,49:17.13
2,-1,49:17.13
3,-1,49:17.13
3,0,49:17.13
2,-2,50:17.13
3,-2,50:17.13
2,-1,50:17.13
3,-1,50:17.13
2,-2,51:17.13
3,-2,51:17.13
3,-1,51:17.13
3,-2,52:17.13
3,-1,52:17.13
5,0,52:17.13
3,-2,53:17.13
3,-1,53:17.13
4,-1,53:17.13
3,-2,54:17.13
