[META]
version=2.0
spawnOnBlockType=2
spawnSunlight=True
spawnDarkness=True
spawnWater=False
spawnLava=False
underFill=False
randomRotation=True
dig=True
tree=False
branch=False
needsFoundation=True
rarity=100
collisionPercentage=20
spawnElevationMin=0
spawnElevationMax=200
spawnInBiome=Custom
[DATA]
3,-6,-8:17.13
7,-5,-8:17.13
0,-1,-8:17.13
2,-1,-8:17.13
6,-1,-8:17.13
7,-1,-8:17.13
1,-7,-7:17.13
2,-7,-7:17.13
1,-6,-7:17.13
2,-6,-7:17.13
7,-6,-7:17.13
2,-5,-7:17.13
6,-2,-7:17.13
1,-1,-7:17.13
2,-1,-7:17.13
6,-1,-7:17.13
7,-1,-7:17.13
0,0,-7:17.13
2,0,-7:17.13
6,0,-7:17.13
7,0,-7:17.13
1,-7,-6:17.13
2,-7,-6:17.13
2,-6,-6:17.13
7,-6,-6:17.13
1,-5,-6:17.13
3,-5,-6:17.13
6,-2,-6:17.13
0,-1,-6:17.13
6,-1,-6:17.13
7,-1,-6:17.13
8,-1,-6:17.13
0,0,-6:17.13
1,0,-6:17.13
2,0,-6:17.13
6,0,-6:17.13
7,0,-6:17.13
8,0,-6:17.13
1,1,-6:17.13
2,1,-6:17.13
2,-7,-5:17.13
2,-6,-5:17.13
7,-6,-5:17.13
1,-5,-5:17.13
2,-5,-5:17.13
3,-5,-5:17.13
4,-5,-5:17.13
6,-5,-5:17.13
7,-5,-5:17.13
1,-4,-5:17.13
2,-4,-5:17.13
3,-4,-5:17.13
6,-3,-5:17.13
5,-2,-5:17.13
6,-2,-5:17.13
7,-2,-5:17.13
1,-1,-5:17.13
5,-1,-5:17.13
6,-1,-5:17.13
7,-1,-5:17.13
8,-1,-5:17.13
0,0,-5:17.13
1,0,-5:17.13
2,0,-5:17.13
5,0,-5:17.13
6,0,-5:17.13
7,0,-5:17.13
0,1,-5:17.13
1,1,-5:17.13
6,1,-5:17.13
7,1,-5:17.13
2,-6,-4:17.13
3,-6,-4:17.13
4,-6,-4:17.13
6,-6,-4:17.13
2,-5,-4:17.13
3,-5,-4:17.13
4,-5,-4:17.13
6,-5,-4:17.13
2,-4,-4:17.13
3,-4,-4:17.13
4,-4,-4:17.13
5,-3,-4:17.13
6,-3,-4:17.13
1,-2,-4:17.13
5,-2,-4:17.13
6,-2,-4:17.13
0,-1,-4:17.13
1,-1,-4:17.13
2,-1,-4:17.13
3,-1,-4:17.13
6,-1,-4:17.13
7,-1,-4:17.13
8,-1,-4:17.13
0,0,-4:17.13
1,0,-4:17.13
2,0,-4:17.13
2,-6,-3:17.13
3,-6,-3:17.13
4,-6,-3:17.13
2,-5,-3:17.13
3,-5,-3:17.13
4,-5,-3:17.13
5,-5,-3:17.13
6,-5,-3:17.13
3,-4,-3:17.13
4,-4,-3:17.13
5,-3,-3:17.13
6,-3,-3:17.13
7,-3,-3:17.13
1,-2,-3:17.13
2,-2,-3:17.13
4,-2,-3:17.13
5,-2,-3:17.13
6,-2,-3:17.13
7,-2,-3:17.13
8,-2,-3:17.13
0,-1,-3:17.13
1,-1,-3:17.13
2,-1,-3:17.13
3,-1,-3:17.13
4,-1,-3:17.13
5,-1,-3:17.13
6,-1,-3:17.13
7,-1,-3:17.13
0,0,-3:17.13
1,0,-3:17.13
6,0,-3:17.13
4,-6,-2:17.13
5,-6,-2:17.13
6,-6,-2:17.13
1,-5,-2:17.13
2,-5,-2:17.13
3,-5,-2:17.13
4,-5,-2:17.13
5,-5,-2:17.13
6,-5,-2:17.13
1,-4,-2:17.13
2,-4,-2:17.13
3,-4,-2:17.13
4,-4,-2:17.13
5,-4,-2:17.13
6,-4,-2:17.13
1,-3,-2:17.13
2,-3,-2:17.13
3,-3,-2:17.13
4,-3,-2:17.13
5,-3,-2:17.13
6,-3,-2:17.13
7,-3,-2:17.13
1,-2,-2:17.13
2,-2,-2:17.13
3,-2,-2:17.13
4,-2,-2:17.13
5,-2,-2:17.13
6,-2,-2:17.13
7,-2,-2:17.13
8,-2,-2:17.13
0,-1,-2:17.13
1,-1,-2:17.13
2,-1,-2:17.13
3,-1,-2:17.13
4,-1,-2:17.13
5,-1,-2:17.13
6,-1,-2:17.13
7,-1,-2:17.13
1,0,-2:17.13
2,0,-2:17.13
3,0,-2:17.13
4,0,-2:17.13
5,0,-2:17.13
6,0,-2:17.13
1,-5,-1:17.13
2,-5,-1:17.13
3,-5,-1:17.13
4,-5,-1:17.13
5,-5,-1:17.13
6,-5,-1:17.13
1,-4,-1:17.13
6,-4,-1:17.13
1,-3,-1:17.13
6,-3,-1:17.13
7,-3,-1:17.13
1,-2,-1:17.13
2,-2,-1:17.13
6,-2,-1:17.13
7,-2,-1:17.13
1,-1,-1:17.13
2,-1,-1:17.13
6,-1,-1:17.13
7,-1,-1:17.13
1,0,-1:17.13
2,0,-1:17.13
3,0,-1:17.13
4,0,-1:17.13
5,0,-1:17.13
2,-5,0:17.13
3,-5,0:17.13
4,-5,0:17.13
5,-5,0:17.13
6,-5,0:17.13
1,-4,0:17.13
6,-4,0:17.13
1,-3,0:17.13
6,-3,0:17.13
7,-3,0:17.13
1,-2,0:17.13
2,-2,0:17.13
7,-2,0:17.13
1,-1,0:17.13
6,-1,0:17.13
7,-1,0:17.13
2,0,0:17.13
3,0,0:17.13
4,0,0:17.13
5,0,0:17.13
2,-5,1:17.13
3,-5,1:17.13
4,-5,1:17.13
5,-5,1:17.13
1,-4,1:17.13
6,-4,1:17.13
1,-3,1:17.13
6,-3,1:17.13
7,-3,1:17.13
1,-2,1:17.13
2,-2,1:17.13
7,-2,1:17.13
2,-1,1:17.13
6,-1,1:17.13
2,0,1:17.13
3,0,1:17.13
4,0,1:17.13
5,0,1:17.13
2,-5,2:17.13
3,-5,2:17.13
4,-5,2:17.13
5,-5,2:17.13
1,-4,2:17.13
2,-4,2:17.13
5,-4,2:17.13
6,-4,2:17.13
1,-3,2:17.13
6,-3,2:17.13
7,-3,2:17.13
1,-2,2:17.13
2,-2,2:17.13
6,-2,2:17.13
7,-2,2:17.13
2,-1,2:17.13
6,-1,2:17.13
3,0,2:17.13
4,0,2:17.13
5,0,2:17.13
2,-5,3:17.13
3,-5,3:17.13
4,-5,3:17.13
5,-5,3:17.13
1,-4,3:17.13
2,-4,3:17.13
5,-4,3:17.13
6,-4,3:17.13
1,-3,3:17.13
6,-3,3:17.13
7,-3,3:17.13
1,-2,3:17.13
2,-2,3:17.13
6,-2,3:17.13
7,-2,3:17.13
2,-1,3:17.13
5,-1,3:17.13
6,-1,3:17.13
3,0,3:17.13
4,0,3:17.13
5,0,3:17.13
2,-5,4:17.13
3,-5,4:17.13
4,-5,4:17.13
5,-5,4:17.13
2,-4,4:17.13
5,-4,4:17.13
6,-4,4:17.13
1,-3,4:17.13
6,-3,4:17.13
7,-3,4:17.13
2,-2,4:17.13
6,-2,4:17.13
2,-1,4:17.13
3,-1,4:17.13
5,-1,4:17.13
6,-1,4:17.13
3,0,4:17.13
4,0,4:17.13
5,0,4:17.13
3,-5,5:17.13
4,-5,5:17.13
5,-5,5:17.13
2,-4,5:17.13
5,-4,5:17.13
6,-4,5:17.13
1,-3,5:17.13
6,-3,5:17.13
7,-3,5:17.13
2,-2,5:17.13
6,-2,5:17.13
2,-1,5:17.13
3,-1,5:17.13
5,-1,5:17.13
6,-1,5:17.13
3,0,5:17.13
4,0,5:17.13
7,-12,6:17.13
6,-11,6:17.13
6,-10,6:17.13
5,-8,6:17.13
4,-7,6:17.13
5,-7,6:17.13
4,-6,6:17.13
5,-6,6:17.13
3,-5,6:17.13
4,-5,6:17.13
5,-5,6:17.13
2,-4,6:17.13
5,-4,6:17.13
6,-4,6:17.13
1,-3,6:17.13
2,-3,6:17.13
6,-3,6:17.13
2,-2,6:17.13
6,-2,6:17.13
2,-1,6:17.13
3,-1,6:17.13
5,-1,6:17.13
6,-1,6:17.13
3,0,6:17.13
4,0,6:17.13
8,3,6:18.14
8,4,6:18.14
7,-13,7:17.13
7,-12,7:17.13
6,-11,7:17.13
6,-10,7:17.13
5,-9,7:17.13
6,-9,7:17.13
5,-8,7:17.13
6,-8,7:17.13
4,-7,7:17.13
5,-7,7:17.13
4,-6,7:17.13
5,-6,7:17.13
3,-5,7:17.13
4,-5,7:17.13
5,-5,7:17.13
2,-4,7:17.13
5,-4,7:17.13
6,-4,7:17.13
1,-3,7:17.13
2,-3,7:17.13
6,-3,7:17.13
2,-2,7:17.13
6,-2,7:17.13
2,-1,7:17.13
3,-1,7:17.13
5,-1,7:17.13
6,-1,7:17.13
4,0,7:17.13
5,0,7:17.13
7,2,7:18.14
8,3,7:18.14
8,4,7:18.14
9,4,7:17.13
9,5,7:17.13
3,-5,8:17.13
4,-5,8:17.13
5,-5,8:17.13
2,-4,8:17.13
5,-4,8:17.13
6,-4,8:17.13
1,-3,8:17.13
2,-3,8:17.13
6,-3,8:17.13
2,-2,8:17.13
6,-2,8:17.13
2,-1,8:17.13
3,-1,8:17.13
4,-1,8:17.13
5,-1,8:17.13
6,-1,8:17.13
4,0,8:17.13
5,0,8:17.13
6,1,8:18.14
7,1,8:17.13
7,2,8:17.13
8,2,8:17.13
8,3,8:17.13
8,4,8:18.14
9,4,8:17.13
9,5,8:18.14
3,-5,9:17.13
4,-5,9:17.13
5,-5,9:17.13
2,-4,9:17.13
5,-4,9:17.13
6,-4,9:17.13
2,-3,9:17.13
6,-3,9:17.13
2,-2,9:17.13
6,-2,9:17.13
2,-1,9:17.13
3,-1,9:17.13
4,-1,9:17.13
5,-1,9:17.13
6,-1,9:17.13
5,0,9:18.14
6,0,9:17.13
5,1,9:18.14
6,1,9:17.13
7,1,9:17.13
6,2,9:18.14
7,2,9:18.14
7,3,9:18.14
8,3,9:18.14
7,4,9:18.14
8,4,9:18.14
9,4,9:18.14
7,5,9:18.14
8,5,9:18.14
9,5,9:18.14
0,-5,10:18.14
3,-5,10:17.13
4,-5,10:17.13
5,-5,10:17.13
2,-4,10:17.13
5,-4,10:17.13
2,-3,10:17.13
6,-3,10:17.13
2,-2,10:17.13
6,-2,10:17.13
2,-1,10:17.13
3,-1,10:17.13
4,-1,10:17.13
5,-1,10:17.13
6,-1,10:17.13
6,0,10:18.14
5,1,10:18.14
6,1,10:18.14
5,2,10:18.14
7,2,10:18.14
5,3,10:18.14
6,3,10:18.14
8,3,10:18.14
6,4,10:18.14
8,4,10:18.14
9,4,10:18.14
6,5,10:18.14
7,5,10:18.14
0,-5,11:18.14
1,-5,11:18.14
3,-5,11:17.13
4,-5,11:17.13
-1,-4,11:18.14
0,-4,11:18.14
1,-4,11:18.14
2,-4,11:17.13
3,-4,11:17.13
4,-4,11:17.13
5,-4,11:17.13
2,-3,11:17.13
3,-3,11:18.14
6,-3,11:17.13
2,-2,11:17.13
6,-2,11:17.13
2,-1,11:17.13
3,-1,11:17.13
4,-1,11:17.13
5,-1,11:17.13
6,-1,11:17.13
7,2,11:18.14
8,3,11:18.14
9,4,11:18.14
1,-5,12:18.14
0,-4,12:18.14
1,-4,12:18.14
2,-4,12:18.14
3,-4,12:17.13
4,-4,12:17.13
5,-4,12:17.13
-1,-3,12:18.14
0,-3,12:18.14
2,-3,12:17.13
3,-3,12:18.14
6,-3,12:17.13
2,-2,12:17.13
6,-2,12:17.13
2,-1,12:17.13
3,-1,12:17.13
4,-1,12:17.13
5,-1,12:17.13
6,-1,12:17.13
5,3,12:17.13
1,-5,13:18.14
1,-4,13:18.14
2,-4,13:17.13
3,-4,13:17.13
4,-4,13:17.13
5,-4,13:17.13
0,-3,13:18.14
1,-3,13:18.14
2,-3,13:17.13
3,-3,13:18.14
6,-3,13:17.13
2,-2,13:17.13
6,-2,13:17.13
2,-1,13:17.13
3,-1,13:17.13
4,-1,13:17.13
5,-1,13:17.13
4,2,13:17.13
4,3,13:17.13
5,3,13:17.13
1,4,13:17.13
1,-4,14:18.14
2,-4,14:17.13
3,-4,14:17.13
4,-4,14:17.13
5,-4,14:17.13
2,-3,14:17.13
3,-3,14:18.14
6,-3,14:17.13
1,-2,14:18.14
2,-2,14:17.13
6,-2,14:17.13
2,-1,14:17.13
3,-1,14:17.13
4,-1,14:17.13
5,-1,14:17.13
2,0,14:17.13
3,0,14:17.13
4,0,14:17.13
2,1,14:17.13
3,1,14:17.13
4,1,14:17.13
2,2,14:17.13
4,2,14:17.13
1,3,14:17.13
2,3,14:17.13
1,4,14:17.13
2,-4,15:17.13
3,-4,15:17.13
4,-4,15:17.13
5,-4,15:17.13
2,-3,15:17.13
6,-3,15:17.13
2,-2,15:17.13
3,-2,15:18.14
6,-2,15:17.13
2,-1,15:17.13
3,-1,15:17.13
4,-1,15:17.13
5,-1,15:17.13
2,0,15:17.13
3,0,15:17.13
2,1,15:17.13
3,1,15:17.13
4,-5,16:17.13
5,-5,16:17.13
2,-4,16:17.13
3,-4,16:17.13
4,-4,16:17.13
5,-4,16:17.13
2,-3,16:17.13
6,-3,16:17.13
2,-2,16:17.13
5,-2,16:17.13
6,-2,16:17.13
3,-1,16:17.13
4,-1,16:17.13
5,-1,16:17.13
3,-5,17:17.13
4,-5,17:17.13
2,-4,17:17.13
3,-4,17:17.13
5,-4,17:17.13
2,-3,17:17.13
6,-3,17:17.13
2,-2,17:17.13
5,-2,17:17.13
3,-1,17:17.13
4,-1,17:17.13
5,-1,17:17.13
1,-6,18:17.13
4,-5,18:17.13
2,-4,18:17.13
3,-4,18:17.13
5,-4,18:17.13
2,-3,18:17.13
6,-3,18:17.13
2,-2,18:17.13
5,-2,18:17.13
-6,-1,18:17.13
3,-1,18:17.13
4,-1,18:17.13
5,-1,18:17.13
2,-5,19:17.13
4,-5,19:17.13
2,-4,19:17.13
3,-4,19:17.13
4,-4,19:17.13
5,-4,19:17.13
2,-3,19:17.13
5,-3,19:17.13
6,-3,19:17.13
2,-2,19:17.13
5,-2,19:17.13
-6,-1,19:17.13
-5,-1,19:17.13
3,-1,19:17.13
4,-1,19:17.13
5,-1,19:17.13
4,-5,20:18.14
2,-4,20:17.13
3,-4,20:17.13
4,-4,20:17.13
5,-4,20:17.13
2,-3,20:17.13
5,-3,20:17.13
6,-3,20:17.13
-3,-2,20:17.13
-1,-2,20:17.13
0,-2,20:17.13
1,-2,20:17.13
2,-2,20:17.13
5,-2,20:17.13
-5,-1,20:17.13
-4,-1,20:17.13
-3,-1,20:17.13
-2,-1,20:17.13
3,-1,20:17.13
4,-1,20:17.13
5,-1,20:17.13
4,-7,21:18.14
4,-6,21:18.14
4,-5,21:18.14
2,-4,21:17.13
3,-4,21:17.13
4,-4,21:17.13
5,-4,21:17.13
2,-3,21:17.13
5,-3,21:17.13
6,-3,21:17.13
8,-3,21:17.13
-2,-2,21:17.13
-1,-2,21:17.13
0,-2,21:17.13
1,-2,21:17.13
2,-2,21:17.13
5,-2,21:17.13
-3,-1,21:17.13
-2,-1,21:17.13
-1,-1,21:17.13
0,-1,21:17.13
3,-1,21:17.13
4,-1,21:17.13
5,-1,21:17.13
11,-1,21:18.14
4,-7,22:18.14
4,-6,22:18.14
4,-5,22:18.14
10,-5,22:18.14
2,-4,22:17.13
3,-4,22:17.13
4,-4,22:17.13
5,-4,22:17.13
10,-4,22:18.14
2,-3,22:17.13
5,-3,22:17.13
8,-3,22:17.13
2,-2,22:17.13
5,-2,22:17.13
9,-2,22:18.14
10,-2,22:18.14
11,-2,22:18.14
3,-1,22:17.13
4,-1,22:17.13
5,-1,22:17.13
3,-8,23:18.14
3,-7,23:18.14
4,-7,23:18.14
5,-7,23:18.14
3,-6,23:18.14
4,-6,23:18.14
2,-4,23:17.13
3,-4,23:17.13
4,-4,23:17.13
5,-4,23:17.13
8,-4,23:18.14
9,-4,23:18.14
10,-4,23:18.14
2,-3,23:17.13
5,-3,23:17.13
7,-3,23:17.13
8,-3,23:17.13
10,-3,23:18.14
11,-3,23:18.14
2,-2,23:17.13
3,-2,23:17.13
5,-2,23:17.13
8,-2,23:18.14
9,-2,23:18.14
10,-2,23:18.14
11,-2,23:18.14
3,-1,23:17.13
4,-1,23:17.13
5,-1,23:17.13
0,-11,24:17.13
0,-10,24:17.13
1,-9,24:17.13
3,-8,24:18.14
1,-7,24:17.13
3,-7,24:18.14
5,-7,24:18.14
4,-6,24:18.14
5,-6,24:18.14
3,-5,24:18.14
4,-5,24:18.14
2,-4,24:17.13
3,-4,24:17.13
4,-4,24:17.13
5,-4,24:17.13
7,-4,24:18.14
2,-3,24:17.13
5,-3,24:17.13
6,-3,24:17.13
7,-3,24:17.13
8,-3,24:18.14
9,-3,24:18.14
10,-3,24:18.14
2,-2,24:17.13
3,-2,24:17.13
5,-2,24:17.13
7,-2,24:18.14
10,-2,24:18.14
3,-1,24:17.13
4,-1,24:17.13
5,-1,24:17.13
2,2,24:18.14
2,3,24:18.14
-1,-14,25:17.13
-1,-13,25:17.13
0,-12,25:17.13
0,-11,25:17.13
0,-10,25:17.13
1,-9,25:17.13
1,-8,25:17.13
1,-7,25:17.13
2,-7,25:17.13
3,-7,25:18.14
2,-6,25:17.13
3,-6,25:18.14
5,-6,25:18.14
3,-5,25:18.14
4,-5,25:18.14
2,-4,25:17.13
3,-4,25:18.14
4,-4,25:17.13
5,-4,25:17.13
2,-3,25:17.13
5,-3,25:17.13
6,-3,25:17.13
7,-3,25:18.14
2,-2,25:17.13
3,-2,25:17.13
5,-2,25:17.13
8,-2,25:18.14
9,-2,25:18.14
10,-2,25:18.14
3,-1,25:17.13
4,-1,25:17.13
5,-1,25:17.13
2,3,25:18.14
1,5,25:18.14
1,-7,26:17.13
2,-7,26:17.13
2,-6,26:17.13
3,-6,26:18.14
2,-5,26:17.13
3,-5,26:17.13
1,-4,26:18.14
2,-4,26:17.13
3,-4,26:17.13
4,-4,26:17.13
5,-4,26:17.13
2,-3,26:17.13
3,-3,26:18.14
5,-3,26:17.13
2,-2,26:17.13
3,-2,26:17.13
5,-2,26:17.13
3,-1,26:17.13
4,-1,26:17.13
5,-1,26:17.13
2,2,26:18.14
2,3,26:18.14
1,4,26:18.14
2,4,26:18.14
0,5,26:18.14
1,5,26:18.14
-1,-5,27:18.14
0,-5,27:18.14
1,-5,27:18.14
1,-4,27:18.14
2,-4,27:18.14
3,-4,27:17.13
4,-4,27:17.13
2,-3,27:17.13
3,-3,27:18.14
5,-3,27:17.13
2,-2,27:17.13
3,-2,27:17.13
5,-2,27:17.13
3,-1,27:17.13
4,-1,27:17.13
5,-1,27:17.13
2,2,27:18.14
2,3,27:18.14
1,4,27:18.14
-1,5,27:18.14
0,5,27:18.14
1,5,27:18.14
0,-5,28:18.14
1,-5,28:18.14
-2,-4,28:18.14
-1,-4,28:18.14
0,-4,28:18.14
1,-4,28:18.14
2,-4,28:18.14
3,-4,28:17.13
4,-4,28:17.13
10,-4,28:17.13
-1,-3,28:18.14
0,-3,28:18.14
2,-3,28:17.13
3,-3,28:18.14
5,-3,28:17.13
2,-2,28:17.13
3,-2,28:17.13
5,-2,28:17.13
3,-1,28:17.13
4,-1,28:17.13
5,-1,28:17.13
3,1,28:18.14
2,2,28:18.14
-2,4,28:18.14
-1,4,28:18.14
0,4,28:18.14
1,4,28:18.14
-2,5,28:18.14
1,5,28:18.14
1,-5,29:18.14
2,-4,29:18.14
3,-4,29:17.13
4,-4,29:17.13
-1,-3,29:18.14
0,-3,29:18.14
1,-3,29:18.14
2,-3,29:18.14
3,-3,29:18.14
5,-3,29:17.13
0,-2,29:18.14
1,-2,29:18.14
2,-2,29:17.13
3,-2,29:17.13
5,-2,29:17.13
3,-1,29:17.13
4,-1,29:17.13
5,-1,29:17.13
3,1,29:18.14
2,2,29:18.14
-1,3,29:18.14
1,3,29:18.14
2,3,29:18.14
-2,4,29:18.14
-1,4,29:18.14
2,4,29:17.13
1,5,29:18.14
1,-5,30:18.14
1,-4,30:18.14
3,-4,30:17.13
4,-4,30:17.13
2,-3,30:18.14
3,-3,30:18.14
5,-3,30:17.13
9,-3,30:17.13
1,-2,30:18.14
3,-2,30:17.13
4,-2,30:18.14
5,-2,30:17.13
2,-1,30:18.14
3,-1,30:17.13
4,-1,30:17.13
5,-1,30:17.13
3,1,30:18.14
0,2,30:18.14
2,2,30:18.14
-1,3,30:18.14
0,3,30:18.14
2,3,30:17.13
2,4,30:17.13
1,5,30:18.14
2,-4,31:18.14
3,-4,31:17.13
4,-4,31:17.13
3,-3,31:18.14
5,-3,31:17.13
8,-3,31:17.13
3,-2,31:17.13
5,-2,31:17.13
3,-1,31:18.14
4,-1,31:18.14
5,-1,31:18.14
2,1,31:18.14
3,1,31:18.14
0,2,31:18.14
1,2,31:18.14
2,2,31:17.13
2,3,31:17.13
1,4,31:18.14
2,4,31:18.14
1,5,31:18.14
3,-4,32:17.13
4,-4,32:17.13
3,-3,32:18.14
5,-3,32:17.13
7,-3,32:17.13
8,-3,32:17.13
3,-2,32:17.13
5,-2,32:17.13
3,-1,32:17.13
4,-1,32:17.13
5,-1,32:17.13
3,0,32:17.13
1,1,32:18.14
2,1,32:18.14
3,1,32:18.14
2,2,32:17.13
3,2,32:17.13
2,3,32:18.14
1,4,32:18.14
3,-4,33:17.13
4,-4,33:17.13
3,-3,33:17.13
5,-3,33:17.13
6,-3,33:17.13
7,-3,33:17.13
3,-2,33:17.13
5,-2,33:17.13
7,-2,33:18.14
8,-2,33:18.14
3,-1,33:17.13
4,-1,33:17.13
5,-1,33:17.13
9,-1,33:18.14
11,-1,33:18.14
3,0,33:17.13
3,1,33:17.13
1,-5,34:17.13
2,-5,34:17.13
2,-4,34:17.13
3,-4,34:17.13
4,-4,34:17.13
3,-3,34:17.13
5,-3,34:17.13
3,-2,34:17.13
5,-2,34:17.13
6,-2,34:18.14
7,-2,34:18.14
8,-2,34:18.14
10,-2,34:18.14
3,-1,34:17.13
4,-1,34:17.13
5,-1,34:17.13
8,-1,34:18.14
9,-1,34:18.14
10,-1,34:18.14
10,0,34:18.14
11,0,34:18.14
10,1,34:18.14
10,4,34:17.13
11,4,34:17.13
3,-6,35:18.14
4,-4,35:17.13
3,-3,35:17.13
4,-3,35:17.13
5,-3,35:17.13
3,-2,35:17.13
5,-2,35:17.13
6,-2,35:18.14
7,-2,35:18.14
8,-2,35:18.14
9,-2,35:18.14
4,-1,35:17.13
5,-1,35:17.13
7,-1,35:18.14
8,-1,35:18.14
9,-1,35:18.14
8,0,35:18.14
9,0,35:18.14
8,1,35:18.14
9,1,35:18.14
10,1,35:18.14
9,2,35:18.14
10,2,35:18.14
9,3,35:17.13
10,3,35:17.13
3,-6,36:18.14
4,-4,36:17.13
3,-3,36:17.13
4,-3,36:17.13
5,-3,36:17.13
7,-3,36:18.14
8,-3,36:18.14
3,-2,36:17.13
5,-2,36:17.13
6,-2,36:18.14
7,-2,36:18.14
4,-1,36:17.13
5,-1,36:17.13
6,-1,36:18.14
7,-1,36:18.14
6,0,36:18.14
7,0,36:18.14
7,1,36:18.14
8,1,36:18.14
8,2,36:17.13
9,2,36:17.13
2,-8,37:18.14
3,-6,37:18.14
3,-5,37:18.14
4,-4,37:17.13
5,-4,37:18.14
6,-4,37:18.14
3,-3,37:17.13
4,-3,37:17.13
5,-3,37:17.13
6,-3,37:18.14
3,-2,37:17.13
4,-2,37:18.14
5,-2,37:17.13
4,-1,37:18.14
5,-1,37:17.13
6,-1,37:17.13
5,0,37:18.14
6,0,37:17.13
7,0,37:17.13
7,1,37:17.13
8,1,37:17.13
8,2,37:17.13
2,-9,38:18.14
2,-8,38:18.14
6,-8,38:17.13
2,-7,38:18.14
3,-6,38:18.14
3,-5,38:18.14
4,-4,38:18.14
5,-4,38:18.14
3,-3,38:17.13
4,-3,38:17.13
5,-3,38:17.13
3,-2,38:17.13
4,-2,38:17.13
5,-2,38:17.13
4,-1,38:17.13
5,-1,38:17.13
6,-1,38:17.13
3,-9,39:18.14
4,-9,39:18.14
2,-8,39:18.14
3,-8,39:18.14
2,-7,39:18.14
3,-7,39:18.14
5,-7,39:17.13
6,-7,39:17.13
3,-6,39:18.14
5,-6,39:17.13
6,-6,39:17.13
5,-5,39:17.13
4,-4,39:18.14
3,-3,39:17.13
4,-3,39:17.13
5,-3,39:17.13
3,-2,39:17.13
4,-2,39:17.13
5,-2,39:17.13
4,-1,39:17.13
5,-1,39:17.13
1,-9,40:18.14
4,-9,40:18.14
5,-9,40:18.14
2,-8,40:18.14
4,-8,40:18.14
2,-7,40:18.14
3,-7,40:18.14
4,-7,40:18.14
3,-6,40:18.14
5,-6,40:17.13
3,-5,40:18.14
4,-5,40:17.13
5,-5,40:17.13
3,-4,40:18.14
4,-4,40:17.13
5,-4,40:17.13
4,-3,40:17.13
5,-3,40:17.13
3,-2,40:17.13
4,-2,40:17.13
5,-2,40:17.13
4,-1,40:17.13
5,-1,40:17.13
1,-9,41:18.14
2,-8,41:18.14
5,-8,41:18.14
2,-7,41:18.14
5,-7,41:18.14
5,-6,41:18.14
4,-5,41:18.14
4,-4,41:18.14
4,-3,41:17.13
5,-3,41:17.13
3,-2,41:17.13
4,-2,41:17.13
5,-2,41:17.13
-1,-1,41:17.13
4,-1,41:17.13
5,-1,41:17.13
2,-8,42:18.14
2,-7,42:18.14
2,-6,42:18.14
3,-6,42:18.14
5,-6,42:18.14
3,-5,42:18.14
5,-5,42:18.14
3,-4,42:18.14
5,-4,42:18.14
4,-3,42:18.14
5,-3,42:17.13
4,-2,42:17.13
5,-2,42:17.13
0,-1,42:17.13
1,-1,42:17.13
4,-1,42:17.13
5,-1,42:17.13
3,-4,43:18.14
4,-3,43:17.13
5,-3,43:17.13
2,-2,43:17.13
4,-2,43:17.13
5,-2,43:17.13
1,-1,43:17.13
2,-1,43:17.13
4,-1,43:17.13
5,-1,43:17.13
2,-5,44:17.13
4,-3,44:17.13
5,-3,44:17.13
2,-2,44:17.13
3,-2,44:17.13
4,-2,44:17.13
5,-2,44:17.13
2,-1,44:17.13
3,-1,44:17.13
4,-1,44:17.13
5,-1,44:17.13
3,-4,45:17.13
4,-2,45:17.13
5,-2,45:17.13
4,-1,45:17.13
5,-1,45:17.13
3,-4,46:17.13
4,-2,46:17.13
5,-2,46:17.13
4,-1,46:17.13
5,-1,46:17.13
4,1,46:17.13
4,2,46:17.13
4,-3,47:17.13
4,-2,47:17.13
5,-2,47:17.13
4,-1,47:17.13
5,-1,47:17.13
4,0,47:17.13
4,1,47:17.13
4,-2,48:17.13
5,-2,48:17.13
4,-1,48:17.13
5,-1,48:17.13
4,0,48:17.13
5,0,48:17.13
5,-2,49:17.13
5,-1,49:17.13
5,-3,50:17.13
5,-2,50:17.13
5,-1,50:17.13
5,-2,51:17.13
5,-1,51:17.13
6,-1,51:17.13
6,1,51:17.13
5,-1,52:17.13
6,-1,52:17.13
6,0,52:17.13
6,-1,53:17.13
6,-1,54:17.13
