[META]
version=2.0
spawnOnBlockType=2
spawnSunlight=True
spawnDarkness=True
spawnWater=False
spawnLava=False
underFill=False
randomRotation=True
dig=True
tree=False
branch=False
needsFoundation=True
rarity=100
collisionPercentage=20
spawnElevationMin=0
spawnElevationMax=200
spawnInBiome=Custom
[DATA]
-7,6,-8:17.13
-8,7,-8:17.13
-7,7,-8:17.13
-6,7,-8:17.13
-7,9,-8:17.13
-6,9,-8:17.13
-7,10,-8:17.13
-6,10,-8:17.13
-7,11,-8:17.13
-6,11,-8:17.13
-2,11,-8:17.13
-1,11,-8:17.13
-6,12,-8:17.13
-3,12,-8:17.13
-2,12,-8:17.13
-1,12,-8:17.13
-2,13,-8:17.13
-1,13,-8:17.13
-7,7,-7:17.13
-6,7,-7:17.13
-8,8,-7:17.13
-7,8,-7:17.13
-7,9,-7:17.13
-6,9,-7:17.13
-5,9,-7:17.13
-7,10,-7:17.13
-6,10,-7:17.13
-7,11,-7:17.13
-6,11,-7:17.13
-3,11,-7:17.13
-2,11,-7:17.13
-4,12,-7:17.13
-3,12,-7:17.13
-2,12,-7:17.13
-3,13,-7:17.13
-2,13,-7:17.13
-7,7,-6:17.13
-8,8,-6:17.13
-7,8,-6:17.13
-8,9,-6:17.13
-7,9,-6:17.13
-6,9,-6:17.13
-5,9,-6:17.13
-8,10,-6:17.13
-7,10,-6:17.13
-6,10,-6:17.13
-5,10,-6:17.13
-6,11,-6:17.13
-4,11,-6:17.13
-3,11,-6:17.13
-4,12,-6:17.13
-3,12,-6:17.13
-2,12,-6:17.13
-2,13,-6:17.13
-6,8,-5:17.13
-7,9,-5:17.13
-6,9,-5:17.13
-8,10,-5:17.13
-7,10,-5:17.13
-6,10,-5:17.13
-5,10,-5:17.13
-7,11,-5:17.13
-5,11,-5:17.13
-3,11,-5:17.13
-2,11,-5:17.13
-4,12,-5:17.13
-3,12,-5:17.13
-2,12,-5:17.13
-2,13,-5:17.13
-7,8,-4:17.13
-8,9,-4:17.13
-6,9,-4:17.13
-7,10,-4:17.13
-6,10,-4:17.13
-5,10,-4:17.13
-7,11,-4:17.13
-6,11,-4:17.13
-3,11,-4:17.13
-5,12,-4:17.13
-4,12,-4:17.13
-3,12,-4:17.13
-2,12,-4:17.13
-6,7,-3:17.13
-7,8,-3:17.13
-6,8,-3:17.13
-5,8,-3:17.13
-8,9,-3:17.13
-7,9,-3:17.13
-6,9,-3:17.13
-5,9,-3:17.13
-4,9,-3:17.13
-8,10,-3:17.13
-7,10,-3:17.13
-6,10,-3:17.13
-5,10,-3:17.13
-4,10,-3:17.13
-8,11,-3:17.13
-7,11,-3:17.13
-6,11,-3:17.13
-5,11,-3:17.13
-4,11,-3:17.13
-6,12,-3:17.13
-5,12,-3:17.13
-4,12,-3:17.13
-3,12,-3:17.13
-4,13,-3:17.13
-7,8,-2:17.13
-6,8,-2:17.13
-5,8,-2:17.13
-7,9,-2:17.13
-5,9,-2:17.13
-4,9,-2:17.13
-7,10,-2:17.13
-5,10,-2:17.13
-4,10,-2:17.13
-6,11,-2:17.13
-5,11,-2:17.13
-4,11,-2:17.13
-4,12,-2:17.13
-3,12,-2:17.13
-4,13,-2:17.13
-7,8,-1:17.13
-6,8,-1:17.13
-5,8,-1:17.13
-7,9,-1:17.13
-5,9,-1:17.13
-4,9,-1:17.13
-7,10,-1:17.13
-5,10,-1:17.13
-4,10,-1:17.13
-6,11,-1:17.13
-5,11,-1:17.13
-4,12,-1:17.13
-3,12,-1:17.13
-4,13,-1:17.13
-7,8,0:17.13
-6,8,0:17.13
-5,8,0:17.13
-7,9,0:17.13
-5,9,0:17.13
-7,10,0:17.13
-6,10,0:17.13
-5,10,0:17.13
-6,11,0:17.13
-4,12,0:17.13
-3,12,0:17.13
-6,8,1:17.13
-5,8,1:17.13
-7,9,1:17.13
-5,9,1:17.13
-7,10,1:17.13
-6,10,1:17.13
-5,10,1:17.13
-6,11,1:17.13
-5,11,1:18.14
-4,12,1:17.13
-3,12,1:17.13
-10,8,2:18.14
-9,8,2:18.14
-6,8,2:17.13
-9,9,2:18.14
-8,9,2:18.14
-7,9,2:17.13
-5,9,2:17.13
-7,10,2:17.13
-6,10,2:17.13
-5,10,2:17.13
-6,11,2:17.13
-5,11,2:17.13
-5,12,2:17.13
-4,12,2:17.13
-3,12,2:17.13
-2,12,2:17.13
-5,13,2:17.13
-4,13,2:17.13
-4,14,2:17.13
-10,8,3:18.14
-9,8,3:18.14
-8,8,3:18.14
-6,8,3:17.13
-9,9,3:17.13
-8,9,3:17.13
-7,9,3:17.13
-6,9,3:17.13
-5,9,3:17.13
-7,10,3:17.13
-6,10,3:17.13
-5,10,3:17.13
-4,12,3:17.13
-3,12,3:17.13
-10,8,4:18.14
-6,8,4:17.13
-9,9,4:18.14
-8,9,4:18.14
-7,9,4:17.13
-6,9,4:17.13
-5,9,4:17.13
-4,9,4:18.14
-7,10,4:17.13
-6,10,4:17.13
-5,10,4:17.13
-4,12,4:17.13
-3,12,4:17.13
-3,13,4:17.13
-2,13,4:17.13
-2,14,4:17.13
-1,14,4:17.13
-1,15,4:17.13
-7,6,5:17.13
-8,8,5:17.13
-7,8,5:17.13
-6,8,5:17.13
-4,8,5:18.14
-7,9,5:17.13
-6,9,5:17.13
-5,9,5:18.14
-4,9,5:18.14
-7,10,5:17.13
-6,10,5:17.13
-5,10,5:17.13
-4,12,5:17.13
-3,12,5:17.13
-2,14,5:17.13
-2,15,5:17.13
-7,7,6:17.13
-6,7,6:17.13
-7,8,6:17.13
-6,8,6:17.13
-7,9,6:17.13
-6,9,6:18.14
-5,9,6:17.13
-7,10,6:17.13
-6,10,6:17.13
-5,10,6:17.13
-7,11,6:18.13
-6,11,6:18.13
-5,11,6:18.13
-7,12,6:18.13
-6,12,6:18.13
-5,12,6:18.13
-4,12,6:17.13
-3,12,6:17.13
-5,13,6:18.13
-3,13,6:17.13
-2,14,6:17.13
-6,8,7:17.13
-7,9,7:17.13
-6,9,7:17.13
-5,9,7:17.13
-7,10,7:17.13
-6,10,7:17.13
-5,10,7:17.13
-5,11,7:18.13
-6,12,7:17.13
-5,12,7:18.13
-4,12,7:17.13
-3,12,7:17.13
-4,13,7:18.13
-3,6,8:17.13
-7,9,8:17.13
-6,9,8:17.13
-5,9,8:17.13
-7,10,8:17.13
-6,10,8:17.13
-5,10,8:17.13
-4,10,8:17.13
-4,12,8:17.13
-3,12,8:17.13
0,13,8:18.13
1,13,8:18.13
2,13,8:18.13
1,14,8:18.13
2,14,8:18.13
-4,7,9:17.13
-5,8,9:17.13
-4,8,9:17.13
-7,9,9:17.13
-6,9,9:17.13
-5,9,9:17.13
-7,10,9:17.13
-6,10,9:17.13
-5,10,9:17.13
-9,11,9:18.14
-5,11,9:18.14
-4,11,9:18.14
-3,12,9:17.13
-2,12,9:17.13
-1,12,9:17.13
-1,13,9:17.13
-7,9,10:17.13
-6,9,10:17.13
-5,9,10:17.13
-7,10,10:18.14
-6,10,10:17.13
-5,10,10:17.13
-9,11,10:18.14
-8,11,10:18.14
-7,11,10:18.14
-6,11,10:18.13
-5,11,10:18.13
-4,11,10:18.14
-8,12,10:18.14
-5,12,10:18.14
-4,12,10:18.13
-3,12,10:17.13
-7,5,11:18.14
-7,6,11:18.14
-7,7,11:18.14
-7,9,11:17.13
-6,9,11:17.13
-5,9,11:17.13
-7,10,11:17.13
-6,10,11:17.13
-5,10,11:18.14
-4,10,11:17.13
-8,11,11:18.14
-7,11,11:18.14
-5,11,11:18.14
-4,11,11:18.14
-3,11,11:17.13
-2,11,11:17.13
-4,12,11:17.13
-3,12,11:17.13
-1,12,11:17.13
0,15,11:18.13
0,16,11:18.13
1,17,11:17.13
1,18,11:17.13
2,18,11:17.13
2,19,11:17.13
-7,5,12:18.14
-6,5,12:18.14
-7,6,12:18.14
-7,7,12:18.14
-7,9,12:17.13
-6,9,12:17.13
-5,9,12:17.13
-4,9,12:18.14
-3,9,12:18.14
-6,10,12:17.13
-5,10,12:17.13
-4,10,12:17.13
-3,12,12:17.13
-3,13,12:17.13
-2,13,12:17.13
-2,14,12:17.13
-1,14,12:18.13
0,14,12:18.13
-1,15,12:17.13
0,15,12:18.13
1,15,12:18.13
2,15,12:18.13
0,16,12:17.13
1,16,12:18.13
1,17,12:17.13
-7,5,13:18.14
-6,5,13:18.14
-7,6,13:18.14
-6,6,13:18.14
-7,7,13:18.14
-7,8,13:18.14
-5,8,13:18.14
-4,8,13:18.14
-7,9,13:17.13
-6,9,13:17.13
-5,9,13:18.14
-4,9,13:18.14
-6,10,13:17.13
-5,10,13:17.13
-3,12,13:17.13
-1,15,13:17.13
0,15,13:17.13
0,16,13:17.13
-7,5,14:18.14
-7,6,14:18.14
-6,6,14:18.14
-7,7,14:17.13
-6,7,14:18.14
-7,8,14:18.14
-6,8,14:18.14
-7,9,14:18.14
-6,9,14:17.13
-5,9,14:17.13
-6,10,14:17.13
-5,10,14:17.13
-7,11,14:17.13
-3,12,14:17.13
-1,12,14:18.13
-1,13,14:18.13
0,13,14:18.13
1,13,14:18.13
0,14,14:18.13
-7,7,15:17.13
-7,8,15:17.13
-6,8,15:17.13
-7,9,15:17.13
-6,9,15:17.13
-5,9,15:17.13
-8,10,15:18.14
-7,10,15:17.13
-6,10,15:17.13
-5,10,15:17.13
-9,11,15:18.14
-7,11,15:17.13
-3,12,15:17.13
-2,12,15:17.13
-2,13,15:17.13
-1,13,15:17.13
-10,9,16:17.13
-9,9,16:18.14
-7,9,16:17.13
-6,9,16:17.13
-5,9,16:17.13
-9,10,16:18.14
-8,10,16:18.14
-7,10,16:18.14
-6,10,16:17.13
-5,10,16:17.13
-8,11,16:18.14
-3,12,16:17.13
-3,13,16:17.13
-9,9,17:17.13
-8,9,17:17.13
-7,9,17:17.13
-6,9,17:17.13
-7,10,17:18.14
-6,10,17:17.13
-5,10,17:18.14
-4,11,17:18.14
-3,11,17:18.14
-3,12,17:17.13
-3,13,17:17.13
-2,13,17:17.13
-7,9,18:17.13
-6,9,18:17.13
-6,10,18:17.13
-5,10,18:18.14
-6,11,18:17.13
-5,11,18:17.13
-4,11,18:18.14
-3,11,18:18.14
-5,12,18:17.13
-4,12,18:18.14
-3,12,18:17.13
-3,13,18:17.13
-7,9,19:17.13
-6,9,19:17.13
-6,10,19:17.13
-5,10,19:18.14
-5,11,19:18.14
-4,11,19:18.14
-3,11,19:18.14
-5,12,19:18.14
-4,12,19:18.14
-3,12,19:17.13
-6,8,20:17.13
-5,8,20:17.13
-7,9,20:17.13
-6,9,20:17.13
-6,10,20:17.13
-5,10,20:18.14
-3,12,20:17.13
-7,9,21:17.13
-6,9,21:17.13
-6,10,21:17.13
-5,10,21:17.13
-3,12,21:17.13
-7,8,22:17.13
-7,9,22:17.13
-6,9,22:17.13
-6,10,22:17.13
-7,9,23:17.13
-7,10,23:17.13
-8,9,24:17.13
-7,9,24:17.13
-7,9,25:17.13
