[META]
version=2.0
spawnOnBlockType=2
spawnSunlight=True
spawnDarkness=True
spawnWater=False
spawnLava=False
underFill=False
randomRotation=True
dig=True
tree=False
branch=False
needsFoundation=True
rarity=100
collisionPercentage=20
spawnElevationMin=0
spawnElevationMax=200
spawnInBiome=Custom
[DATA]
-6,-3,-8:17.12
0,-2,-8:17.12
-9,5,-8:17.12
1,6,-8:17.12
-4,-4,-7:17.12
-2,-4,-7:17.12
-1,-4,-7:17.12
-5,-3,-7:17.12
-4,-3,-7:17.12
-1,-3,-7:17.12
-6,-2,-7:17.12
-5,-2,-7:17.12
-4,-2,-7:17.12
-1,-2,-7:17.12
0,-2,-7:17.12
1,-2,-7:17.12
-5,-1,-7:17.12
-1,-1,-7:17.12
0,-1,-7:17.12
1,-1,-7:17.12
-9,4,-7:17.12
-8,4,-7:17.12
-7,4,-7:17.12
-8,5,-7:17.12
-7,5,-7:17.12
-6,5,-7:17.12
-7,6,-7:17.12
0,6,-7:17.12
0,7,-7:17.12
1,7,-7:17.12
-6,-3,-6:17.12
-5,-3,-6:17.12
-4,-3,-6:17.12
-2,-3,-6:17.12
-1,-3,-6:17.12
-6,-2,-6:17.12
-5,-2,-6:17.12
-4,-2,-6:17.12
-1,-2,-6:17.12
0,-2,-6:17.12
-5,-1,-6:17.12
-4,-1,-6:17.12
-2,-1,-6:17.12
-1,0,-6:17.12
0,0,-6:17.12
-1,1,-6:17.12
0,1,-6:17.12
-7,4,-6:17.12
-6,4,-6:17.12
-8,5,-6:17.12
-7,5,-6:17.12
0,5,-6:17.12
1,5,-6:17.12
-7,6,-6:17.12
-6,6,-6:17.12
0,6,-6:17.12
1,6,-6:17.12
-6,-3,-5:17.12
-5,-3,-5:17.12
-4,-3,-5:17.12
-1,-3,-5:17.12
-5,-2,-5:17.12
-4,-2,-5:17.12
-2,-2,-5:17.12
-1,-2,-5:17.12
0,-2,-5:17.12
-4,-1,-5:17.12
-2,-1,-5:17.12
-1,-1,-5:17.12
0,-1,-5:17.12
1,-1,-5:17.12
-2,0,-5:17.12
-1,0,-5:17.12
0,0,-5:17.12
1,0,-5:17.12
-1,1,-5:17.12
0,1,-5:17.12
-7,4,-5:17.12
-6,4,-5:17.12
1,4,-5:17.12
-8,5,-5:17.12
-7,5,-5:17.12
-6,5,-5:17.12
0,5,-5:17.12
-8,6,-5:17.12
-7,6,-5:17.12
-1,6,-5:17.12
0,6,-5:17.12
-1,7,-5:17.12
0,7,-5:17.12
-5,-3,-4:17.12
-6,-2,-4:17.12
-5,-2,-4:17.12
-4,-2,-4:17.12
-6,-1,-4:17.12
-5,-1,-4:17.12
-1,-1,-4:17.12
0,-1,-4:17.12
-1,0,-4:17.12
0,0,-4:17.12
1,0,-4:17.12
-1,1,-4:17.12
0,1,-4:17.12
-7,4,-4:17.12
-6,4,-4:17.12
-5,4,-4:17.12
1,4,-4:17.12
2,4,-4:17.12
-7,5,-4:17.12
-6,5,-4:17.12
0,5,-4:17.12
1,5,-4:17.12
2,5,-4:17.12
-7,6,-4:17.12
0,6,-4:17.12
-5,-2,-3:17.12
-4,-2,-3:17.12
2,-2,-3:17.12
-7,-1,-3:17.12
-6,-1,-3:17.12
-5,-1,-3:17.12
-4,-1,-3:17.12
1,-1,-3:17.12
-7,0,-3:17.12
-5,0,-3:17.12
-4,0,-3:17.12
-1,0,-3:17.12
0,0,-3:17.12
0,1,-3:17.12
1,1,-3:17.12
-6,3,-3:17.12
-5,3,-3:17.12
-6,4,-3:17.12
-5,4,-3:17.12
-1,4,-3:17.12
0,4,-3:17.12
1,4,-3:17.12
-8,5,-3:17.12
-7,5,-3:17.12
-6,5,-3:17.12
-1,5,-3:17.12
0,5,-3:17.12
1,5,-3:17.12
2,5,-3:17.12
-10,6,-3:17.12
-9,6,-3:17.12
-8,6,-3:17.12
-1,6,-3:17.12
0,6,-3:17.12
1,6,-3:17.12
-5,-2,-2:17.12
-4,-2,-2:17.12
-5,-1,-2:17.12
-4,-1,-2:17.12
0,-1,-2:17.12
1,-1,-2:17.12
-7,0,-2:17.12
-6,0,-2:17.12
-4,0,-2:17.12
-3,0,-2:17.12
-2,0,-2:17.12
0,0,-2:17.12
1,0,-2:17.12
-6,1,-2:17.12
-4,1,-2:17.12
-3,1,-2:17.12
-2,1,-2:17.12
-1,1,-2:17.12
0,1,-2:17.12
1,1,-2:17.12
-6,2,-2:17.12
-5,2,-2:17.12
-3,2,-2:17.12
-2,2,-2:17.12
0,2,-2:17.12
-7,3,-2:17.12
-6,3,-2:17.12
-5,3,-2:17.12
-7,4,-2:17.12
-6,4,-2:17.12
-5,4,-2:17.12
-2,4,-2:17.12
-1,4,-2:17.12
0,4,-2:17.12
-8,5,-2:17.12
-7,5,-2:17.12
-6,5,-2:17.12
-5,5,-2:17.12
-2,5,-2:17.12
-1,5,-2:17.12
0,5,-2:17.12
-9,6,-2:17.12
-8,6,-2:17.12
-7,6,-2:17.12
-2,6,-2:17.12
-1,6,-2:17.12
0,6,-2:17.12
-2,7,-2:17.12
-1,7,-2:17.12
-2,8,-2:17.12
-1,8,-2:17.12
-4,-1,-1:17.12
-3,-1,-1:17.12
-4,0,-1:17.12
-3,0,-1:17.12
-2,0,-1:17.12
0,0,-1:17.12
-6,1,-1:17.12
-4,1,-1:17.12
-3,1,-1:17.12
-2,1,-1:17.12
-1,1,-1:17.12
0,1,-1:17.12
-6,2,-1:17.12
-5,2,-1:17.12
-4,2,-1:17.12
-3,2,-1:17.12
-2,2,-1:17.12
-1,2,-1:17.12
0,2,-1:17.12
-6,3,-1:17.12
-5,3,-1:17.12
-4,3,-1:17.12
-3,3,-1:17.12
-2,3,-1:17.12
-1,3,-1:17.12
0,3,-1:17.12
-7,4,-1:17.12
-6,4,-1:17.12
-5,4,-1:17.12
-4,4,-1:17.12
-3,4,-1:17.12
-2,4,-1:17.12
-1,4,-1:17.12
0,4,-1:17.12
-8,5,-1:17.12
-7,5,-1:17.12
-6,5,-1:17.12
-5,5,-1:17.12
-4,5,-1:17.12
-3,5,-1:17.12
-2,5,-1:17.12
-1,5,-1:17.12
0,5,-1:17.12
-7,6,-1:17.12
-3,6,-1:17.12
-2,6,-1:17.12
-1,6,-1:17.12
0,6,-1:17.12
1,6,-1:17.12
-3,7,-1:17.12
-2,7,-1:17.12
-1,7,-1:17.12
1,7,-1:17.12
-4,1,0:17.12
-3,1,0:17.12
-2,1,0:17.12
-4,2,0:17.12
-2,2,0:17.12
-1,2,0:17.12
0,2,0:17.12
-5,3,0:17.12
-4,3,0:17.12
-3,3,0:17.12
-2,3,0:17.12
0,3,0:17.12
-5,4,0:17.12
-4,4,0:17.12
-3,4,0:17.12
-2,4,0:17.12
-1,4,0:17.12
0,4,0:17.12
-5,5,0:17.12
-4,5,0:17.12
-3,5,0:17.12
-2,5,0:17.12
-1,5,0:17.12
-3,6,0:17.12
-2,6,0:17.12
-1,6,0:17.12
-4,2,1:17.12
-3,2,1:17.12
-2,2,1:17.12
-5,3,1:17.12
-4,3,1:17.12
-1,3,1:17.12
-5,4,1:17.12
-1,4,1:17.12
-4,5,1:17.12
-3,5,1:17.12
-2,5,1:17.12
-1,5,1:17.12
-3,6,1:17.12
-2,6,1:17.12
-4,2,2:17.12
-3,2,2:17.12
-2,2,2:17.12
-5,3,2:17.12
-4,3,2:17.12
-1,3,2:17.12
-5,4,2:17.12
-1,4,2:17.12
-4,5,2:17.12
-3,5,2:17.12
-2,5,2:17.12
-3,6,2:17.12
4,-1,3:18.14
-4,2,3:17.12
-3,2,3:17.12
-2,2,3:17.12
-5,3,3:17.12
-4,3,3:17.12
-2,3,3:17.12
-1,3,3:17.12
0,3,3:17.12
-5,4,3:17.12
-4,4,3:17.12
-2,4,3:17.12
-1,4,3:17.12
-4,5,3:17.12
-3,5,3:17.12
-2,5,3:17.12
5,-1,4:18.14
6,-1,4:18.14
3,0,4:18.14
4,0,4:18.14
3,1,4:18.14
-4,2,4:17.12
-3,2,4:17.12
-2,2,4:17.12
-1,2,4:17.12
0,2,4:17.12
-5,3,4:17.12
-4,3,4:17.12
-2,3,4:17.12
-1,3,4:17.12
0,3,4:17.12
-5,4,4:17.12
-4,4,4:18.14
-2,4,4:17.12
-1,4,4:17.12
-4,5,4:17.12
-3,5,4:17.12
-2,5,4:17.12
-4,7,4:18.14
4,-1,5:18.14
6,-1,5:18.14
7,-1,5:18.14
4,0,5:18.14
5,0,5:18.14
6,0,5:18.14
3,1,5:18.14
4,1,5:18.14
-4,2,5:17.12
-3,2,5:17.12
-2,2,5:17.12
-1,2,5:17.12
0,2,5:17.12
1,2,5:18.14
2,2,5:18.14
-5,3,5:17.12
-4,3,5:17.12
-2,3,5:17.12
-1,3,5:17.12
0,3,5:17.12
1,3,5:17.12
3,3,5:18.14
-5,4,5:17.12
-4,4,5:17.12
-2,4,5:17.12
3,4,5:18.14
-4,5,5:18.14
-3,5,5:17.12
-2,5,5:17.12
-4,6,5:18.14
-4,7,5:18.14
-4,9,5:18.14
-6,-1,6:18.14
4,-1,6:18.14
-6,0,6:18.14
-5,0,6:18.14
3,0,6:18.14
5,0,6:18.14
6,0,6:18.14
7,0,6:18.14
-5,1,6:18.14
2,1,6:18.14
4,1,6:18.14
5,1,6:18.14
-4,2,6:17.12
-3,2,6:17.12
-2,2,6:17.12
0,2,6:17.12
1,2,6:18.14
2,2,6:18.14
3,2,6:18.14
4,2,6:18.14
-5,3,6:17.12
-2,3,6:17.12
0,3,6:17.12
1,3,6:17.12
3,3,6:18.14
4,3,6:18.14
5,3,6:18.14
-5,4,6:17.12
-4,4,6:17.12
-2,4,6:17.12
1,4,6:18.14
2,4,6:18.14
3,4,6:18.14
4,4,6:18.14
-5,5,6:18.14
-4,5,6:17.12
-3,5,6:17.12
3,5,6:18.14
-5,6,6:18.14
-4,6,6:18.14
-3,6,6:18.14
-4,7,6:18.14
-4,9,6:18.14
7,-3,7:18.14
-7,-2,7:18.14
4,-2,7:18.14
5,-2,7:18.14
6,-2,7:18.14
7,-2,7:18.14
-6,-1,7:18.14
3,-1,7:18.14
4,-1,7:18.14
6,-1,7:18.14
-5,0,7:18.14
2,0,7:18.14
3,0,7:18.14
6,0,7:18.14
7,0,7:18.14
-5,1,7:18.14
-4,1,7:18.14
1,1,7:18.14
2,1,7:18.14
3,1,7:18.14
4,1,7:18.14
5,1,7:18.14
6,1,7:18.14
-5,2,7:17.12
-4,2,7:17.12
-3,2,7:17.12
-2,2,7:17.12
2,2,7:18.14
3,2,7:18.14
4,2,7:18.14
5,2,7:18.14
-5,3,7:17.12
-2,3,7:17.12
1,3,7:17.12
2,3,7:17.12
5,3,7:18.14
-5,4,7:17.12
-4,4,7:17.12
-3,4,7:17.12
-2,4,7:17.12
1,4,7:17.12
2,4,7:18.14
-9,5,7:18.14
-8,5,7:18.14
-4,5,7:17.12
-3,5,7:17.12
2,5,7:18.14
3,5,7:18.14
-6,6,7:18.14
-5,6,7:18.14
-3,6,7:18.14
-2,6,7:18.14
1,6,7:18.14
2,6,7:18.14
-5,7,7:18.14
-4,7,7:18.14
-3,7,7:18.14
1,7,7:18.14
1,8,7:18.14
-4,9,7:18.14
0,9,7:18.14
8,-3,8:18.14
9,-3,8:18.14
4,-2,8:18.14
7,-2,8:18.14
8,-2,8:18.14
-6,-1,8:18.14
3,-1,8:18.14
4,-1,8:18.14
6,-1,8:18.14
7,-1,8:18.14
-5,0,8:18.14
-4,0,8:18.14
-3,0,8:18.14
0,0,8:18.14
1,0,8:18.14
2,0,8:18.14
5,0,8:18.14
6,0,8:18.14
-6,1,8:18.14
-4,1,8:17.12
2,1,8:18.14
3,1,8:18.14
4,1,8:18.14
5,1,8:17.12
6,1,8:17.12
-6,2,8:18.14
-5,2,8:17.12
-4,2,8:17.12
-3,2,8:17.12
-2,2,8:17.12
2,2,8:18.14
3,2,8:17.12
4,2,8:17.12
-5,3,8:17.12
-2,3,8:17.12
1,3,8:17.12
2,3,8:17.12
-5,4,8:17.12
-4,4,8:17.12
-3,4,8:17.12
-2,4,8:17.12
1,4,8:17.12
2,4,8:18.14
-9,5,8:18.14
-8,5,8:18.14
-7,5,8:18.14
-6,5,8:18.14
-5,5,8:18.14
-4,5,8:17.12
-3,5,8:17.12
2,5,8:18.14
3,5,8:18.14
-10,6,8:18.14
-9,6,8:18.14
-8,6,8:18.14
-6,6,8:18.14
-2,6,8:18.14
3,6,8:18.14
-6,7,8:18.14
-5,7,8:18.14
-3,7,8:18.14
-2,7,8:18.14
2,7,8:18.14
3,7,8:18.14
-5,8,8:18.14
-3,8,8:18.14
1,8,8:18.14
2,8,8:18.14
-5,9,8:18.14
1,9,8:18.14
2,9,8:18.14
1,10,8:18.14
9,-3,9:18.14
4,-2,9:18.14
8,-2,9:18.14
9,-2,9:18.14
-5,-1,9:18.14
-4,-1,9:18.14
-3,-1,9:18.14
-1,-1,9:18.14
0,-1,9:18.14
1,-1,9:18.14
2,-1,9:18.14
3,-1,9:18.14
7,-1,9:18.14
8,-1,9:18.14
-6,0,9:18.14
1,0,9:18.14
2,0,9:18.14
3,0,9:18.14
6,0,9:18.14
7,0,9:17.12
-6,1,9:18.14
-5,1,9:17.12
-4,1,9:17.12
2,1,9:18.14
3,1,9:18.14
4,1,9:18.14
5,1,9:18.14
6,1,9:18.14
-6,2,9:18.14
-5,2,9:17.12
-4,2,9:17.12
-3,2,9:17.12
-2,2,9:17.12
3,2,9:18.14
7,2,9:18.14
-6,3,9:17.12
-5,3,9:17.12
-2,3,9:17.12
-1,3,9:18.14
0,3,9:18.14
1,3,9:17.12
2,3,9:17.12
-6,4,9:17.12
-5,4,9:17.12
-4,4,9:17.12
-3,4,9:17.12
-2,4,9:17.12
-1,4,9:18.14
2,4,9:18.14
-6,5,9:18.14
-5,5,9:18.14
-4,5,9:17.12
-3,5,9:17.12
3,5,9:18.14
-10,6,9:18.14
-9,6,9:18.14
-8,6,9:18.14
-7,6,9:18.14
-6,6,9:18.14
-5,6,9:18.14
3,6,9:18.14
4,6,9:18.14
-10,7,9:18.14
-9,7,9:18.14
-8,7,9:18.14
-6,7,9:18.14
-6,8,9:18.14
3,8,9:18.14
-6,9,9:18.14
-5,9,9:18.14
2,9,9:18.14
3,9,9:18.14
-6,10,9:18.14
2,10,9:18.14
-6,11,9:18.14
0,-2,10:18.14
1,-2,10:18.14
2,-2,10:18.14
8,-2,10:18.14
9,-2,10:18.14
1,-1,10:18.14
8,-1,10:18.14
-5,0,10:17.12
3,0,10:18.14
6,0,10:18.14
7,0,10:18.14
8,0,10:18.14
-5,1,10:17.12
-4,1,10:17.12
2,1,10:18.14
3,1,10:18.14
4,1,10:18.14
5,1,10:18.14
6,1,10:18.14
7,1,10:18.14
9,1,10:18.14
10,1,10:18.14
-5,2,10:17.12
-4,2,10:17.12
-3,2,10:17.12
-2,2,10:17.12
3,2,10:18.14
4,2,10:18.14
8,2,10:18.14
9,2,10:18.14
-6,3,10:17.12
-5,3,10:17.12
-4,3,10:17.12
-3,3,10:17.12
-2,3,10:17.12
1,3,10:18.14
2,3,10:17.12
3,3,10:18.14
-6,4,10:17.12
-5,4,10:17.12
-4,4,10:17.12
-3,4,10:17.12
-2,4,10:17.12
-1,4,10:18.14
1,4,10:18.14
2,4,10:17.12
3,4,10:18.14
-6,5,10:18.14
-5,5,10:18.14
-4,5,10:17.12
-3,5,10:17.12
-1,5,10:18.14
3,5,10:18.14
-7,6,10:18.14
-6,6,10:18.14
-1,6,10:18.14
4,6,10:18.14
-10,7,10:18.14
-9,7,10:18.14
-8,7,10:18.14
-7,7,10:18.14
-6,7,10:18.14
-1,7,10:18.14
-9,8,10:18.14
-7,8,10:18.14
-6,8,10:18.14
-1,8,10:18.14
-7,9,10:18.14
-6,9,10:18.14
-7,10,10:18.14
-6,10,10:18.14
-7,11,10:18.6
-7,12,10:18.6
8,-1,11:18.14
-6,0,11:17.12
-5,0,11:17.12
4,0,11:18.14
5,0,11:18.14
6,0,11:18.14
7,0,11:18.14
9,0,11:18.14
10,0,11:18.14
-6,1,11:17.12
-5,1,11:17.12
-4,1,11:17.12
-2,1,11:17.12
4,1,11:18.14
9,1,11:18.14
-5,2,11:17.12
-4,2,11:17.12
-3,2,11:17.12
-2,2,11:17.12
-1,2,11:17.12
4,2,11:18.14
-6,3,11:17.12
-5,3,11:17.12
-4,3,11:17.12
-3,3,11:17.12
-2,3,11:17.12
2,3,11:18.14
3,3,11:18.14
-7,4,11:17.12
-6,4,11:17.12
-5,4,11:17.12
-4,4,11:17.12
-3,4,11:17.12
-2,4,11:17.12
-1,4,11:18.14
0,4,11:18.14
1,4,11:18.14
2,4,11:18.14
3,4,11:18.14
-6,5,11:18.14
-4,5,11:17.12
-3,5,11:17.12
-2,5,11:17.12
3,5,11:18.14
4,5,11:18.14
-9,6,11:18.14
-8,6,11:18.14
-7,6,11:18.14
-6,6,11:18.14
-3,6,11:18.14
-1,6,11:18.14
0,6,11:18.14
4,6,11:18.14
-8,7,11:18.14
-7,7,11:18.14
-6,7,11:18.14
-5,7,11:18.14
-2,7,11:18.14
-1,7,11:18.14
0,7,11:18.14
-7,8,11:18.14
-6,8,11:18.14
-2,8,11:18.14
-1,8,11:18.14
-8,9,11:18.14
-6,9,11:18.14
-1,9,11:18.14
-7,10,11:18.14
-7,11,11:18.6
-5,11,11:18.14
-6,-1,12:17.12
7,-1,12:18.14
8,-1,12:18.14
-7,0,12:17.12
-6,0,12:17.12
-5,0,12:17.12
5,0,12:18.14
6,0,12:18.14
-6,1,12:17.12
-5,1,12:17.12
-2,1,12:17.12
-1,1,12:17.12
-5,2,12:17.12
-3,2,12:17.12
-2,2,12:17.12
-1,2,12:17.12
2,2,12:18.14
5,2,12:18.14
6,2,12:18.14
-7,3,12:17.12
-6,3,12:17.12
-5,3,12:17.12
-2,3,12:18.14
2,3,12:18.14
3,3,12:18.14
4,3,12:18.14
-7,4,12:17.12
-6,4,12:17.12
-5,4,12:17.12
-3,4,12:17.12
-1,4,12:18.14
1,4,12:18.14
2,4,12:18.14
3,4,12:18.14
-6,5,12:18.14
-3,5,12:17.12
-2,5,12:17.12
0,5,12:18.14
1,5,12:18.14
4,5,12:18.14
-7,6,12:18.14
-6,6,12:18.14
-3,6,12:17.12
-2,6,12:17.12
0,6,12:18.14
4,6,12:18.14
5,6,12:18.14
-9,7,12:18.14
-8,7,12:18.14
-7,7,12:18.14
-5,7,12:18.14
-4,7,12:18.14
-3,7,12:18.14
0,7,12:18.14
-9,8,12:18.14
-8,8,12:18.14
-7,8,12:18.14
-6,8,12:18.14
-5,8,12:18.14
-2,8,12:18.14
0,8,12:18.14
-8,9,12:18.14
-7,9,12:18.14
-6,9,12:18.14
-5,9,12:18.14
-2,9,12:18.14
-1,9,12:18.14
-4,10,12:18.14
-1,10,12:18.14
-7,11,12:18.6
-5,11,12:18.14
-4,11,12:18.14
-1,11,12:18.14
0,11,12:18.14
-5,12,12:18.6
-7,-1,13:17.12
-6,-1,13:17.12
5,-1,13:18.14
6,-1,13:18.14
7,-1,13:18.14
8,-1,13:18.14
-7,0,13:17.12
-6,0,13:17.12
5,0,13:18.14
-6,1,13:18.14
-5,1,13:18.14
-4,1,13:18.14
-3,1,13:18.14
-2,1,13:17.12
-1,1,13:18.14
2,1,13:18.14
-3,2,13:17.12
-2,2,13:17.12
2,2,13:18.14
5,2,13:18.14
6,2,13:18.14
-7,3,13:17.12
-6,3,13:17.12
-2,3,13:18.14
2,3,13:18.14
3,3,13:18.14
4,3,13:18.14
-8,4,13:17.12
-7,4,13:17.12
-6,4,13:17.12
-1,4,13:18.14
0,4,13:18.14
1,4,13:18.14
2,4,13:18.14
3,4,13:18.14
5,4,13:18.14
-8,5,13:17.12
-7,5,13:17.12
-6,5,13:18.14
-3,5,13:17.12
-2,5,13:17.12
-1,5,13:18.14
0,5,13:18.14
3,5,13:18.14
4,5,13:18.14
5,5,13:18.14
-7,6,13:18.14
-3,6,13:17.12
-2,6,13:17.12
-1,6,13:17.12
4,6,13:18.14
5,6,13:18.14
-4,7,13:18.14
-3,7,13:18.14
-2,7,13:17.12
-1,7,13:17.12
0,7,13:18.14
1,7,13:18.14
5,7,13:18.14
-10,8,13:18.14
-9,8,13:18.14
-5,8,13:18.14
-3,8,13:18.14
-2,8,13:18.14
3,8,13:18.14
-9,9,13:18.14
-8,9,13:18.14
-6,9,13:18.14
-5,9,13:18.14
-4,9,13:18.14
-3,9,13:18.14
-2,9,13:18.14
-5,10,13:18.14
-4,10,13:18.14
-3,10,13:18.14
-2,10,13:18.14
-1,10,13:18.14
-4,11,13:18.14
-3,11,13:18.14
-2,11,13:18.14
-1,11,13:18.14
-4,12,13:18.6
-3,12,13:18.14
-2,12,13:18.14
-1,12,13:18.14
-4,13,13:18.6
-2,13,13:18.6
-1,13,13:18.6
-7,-2,14:17.12
2,-2,14:18.14
-8,-1,14:18.14
-7,-1,14:17.12
-6,-1,14:17.12
6,-1,14:18.14
7,-1,14:18.14
-7,0,14:17.12
-6,0,14:18.14
0,0,14:18.14
2,0,14:18.14
-5,1,14:18.14
-4,1,14:18.14
-3,1,14:18.14
-2,1,14:17.12
-1,1,14:18.14
0,1,14:18.14
1,1,14:18.14
2,1,14:18.14
-3,2,14:18.14
-2,2,14:17.12
2,2,14:18.14
3,2,14:18.14
5,2,14:18.14
6,2,14:18.14
-2,3,14:18.14
2,3,14:18.14
3,3,14:17.12
4,3,14:18.14
-9,4,14:17.12
-8,4,14:17.12
-7,4,14:17.12
-6,4,14:17.12
-1,4,14:18.14
0,4,14:18.14
1,4,14:18.14
2,4,14:18.14
3,4,14:18.14
4,4,14:18.14
6,4,14:18.14
-8,5,14:17.12
-7,5,14:17.12
-1,5,14:18.14
0,5,14:18.14
3,5,14:18.14
4,5,14:18.14
6,5,14:18.14
-2,6,14:18.14
-1,6,14:17.12
5,6,14:18.14
6,6,14:18.14
-2,7,14:18.14
-1,7,14:17.12
0,7,14:17.12
5,7,14:18.14
-2,8,14:18.14
-1,8,14:18.14
0,8,14:18.14
3,8,14:18.14
4,8,14:18.14
5,8,14:18.14
-5,9,14:18.14
-4,9,14:18.14
-3,9,14:18.14
-2,9,14:18.14
1,9,14:18.14
2,9,14:18.14
3,9,14:18.14
4,9,14:18.14
-6,10,14:18.14
-5,10,14:18.14
-3,10,14:18.14
2,10,14:18.14
3,10,14:18.14
-3,11,14:18.14
-7,-2,15:17.12
2,-2,15:18.14
-11,-1,15:18.14
-10,-1,15:18.14
-9,-1,15:18.14
-8,-1,15:18.14
-7,-1,15:17.12
-3,-1,15:18.14
-2,-1,15:18.14
1,-1,15:18.14
2,-1,15:18.14
-7,0,15:18.14
-6,0,15:18.14
-5,0,15:18.14
-4,0,15:18.14
-3,0,15:18.14
-2,0,15:17.12
1,0,15:18.14
2,0,15:18.14
-4,1,15:18.14
-3,1,15:17.12
-2,1,15:17.12
0,1,15:18.14
2,1,15:18.14
-3,2,15:18.14
0,2,15:18.14
2,2,15:18.14
3,2,15:18.14
5,2,15:18.14
2,3,15:18.14
-9,4,15:17.12
-8,4,15:17.12
-7,4,15:17.12
1,4,15:18.14
2,4,15:18.14
3,4,15:18.14
4,4,15:18.14
6,4,15:18.14
7,4,15:18.14
-9,5,15:17.12
-8,5,15:17.12
-1,5,15:18.14
0,5,15:18.14
3,5,15:18.14
4,5,15:18.14
6,5,15:18.14
7,5,15:18.14
-2,6,15:18.14
-1,6,15:18.14
4,6,15:18.14
5,6,15:18.14
7,6,15:18.14
-2,7,15:18.14
-1,7,15:17.12
0,7,15:17.12
1,7,15:17.12
5,7,15:18.14
-2,8,15:18.14
-1,8,15:18.14
0,8,15:18.14
1,8,15:17.12
4,8,15:18.14
5,8,15:18.14
6,8,15:18.14
-2,9,15:18.14
0,9,15:18.14
1,9,15:18.14
3,9,15:18.14
4,9,15:18.14
5,9,15:18.14
-3,10,15:18.14
-2,10,15:18.14
2,10,15:18.14
3,10,15:18.14
-4,11,15:18.14
-3,11,15:18.14
3,11,15:18.14
4,11,15:18.14
-4,12,15:18.14
4,12,15:18.14
-11,-3,16:18.14
-10,-3,16:18.14
-9,-2,16:18.14
-8,-2,16:18.14
-7,-2,16:17.12
-3,-2,16:18.14
3,-2,16:18.14
-11,-1,16:18.14
-10,-1,16:18.14
-9,-1,16:18.14
-8,-1,16:18.14
-7,-1,16:17.12
-4,-1,16:18.14
-3,-1,16:18.14
2,-1,16:18.14
-7,0,16:18.14
-5,0,16:18.14
-4,0,16:18.14
-2,0,16:17.12
1,0,16:18.14
-4,1,16:18.14
-3,1,16:17.12
-2,1,16:17.12
-1,1,16:18.14
0,1,16:18.14
2,1,16:18.14
-4,2,16:18.14
1,2,16:18.14
2,2,16:18.14
3,2,16:18.14
1,3,16:18.14
-9,4,16:17.12
-8,4,16:17.12
-2,4,16:18.14
1,4,16:18.14
2,4,16:18.14
3,4,16:18.14
4,4,16:18.14
-9,5,16:17.12
-8,5,16:17.12
-1,5,16:18.14
0,5,16:18.14
3,5,16:18.14
4,5,16:18.14
7,5,16:18.14
-1,6,16:18.14
0,6,16:17.12
4,6,16:18.14
-1,7,16:18.14
0,7,16:18.14
2,7,16:17.12
5,7,16:18.14
4,8,16:18.14
5,8,16:18.14
6,8,16:18.14
-1,9,16:18.14
0,9,16:18.14
3,9,16:18.14
4,9,16:18.14
6,9,16:18.14
-4,10,16:18.14
-1,10,16:18.14
0,10,16:18.14
1,10,16:18.14
2,10,16:18.14
3,10,16:18.14
-4,11,16:18.14
-2,11,16:18.14
-1,11,16:18.14
2,11,16:18.14
3,11,16:18.14
-3,12,16:18.14
-2,12,16:18.14
3,12,16:18.14
4,12,16:18.14
-3,13,16:18.14
-7,-5,17:18.14
-6,-5,17:18.14
-11,-4,17:18.14
-10,-4,17:18.14
-7,-4,17:18.14
-10,-3,17:18.14
-9,-3,17:18.14
-7,-3,17:18.14
-8,-2,17:17.12
-7,-2,17:17.12
3,-2,17:18.14
-10,-1,17:18.14
-9,-1,17:18.14
-8,-1,17:18.14
-7,-1,17:17.12
-4,-1,17:18.14
2,-1,17:18.14
3,-1,17:18.14
-11,0,17:18.14
-8,0,17:18.14
-3,0,17:18.14
-2,0,17:17.12
-1,0,17:18.14
0,0,17:18.14
-7,1,17:18.14
-5,1,17:18.14
-4,1,17:18.14
-2,1,17:17.12
0,1,17:18.14
-7,2,17:18.14
-4,2,17:18.14
1,2,17:18.14
2,2,17:18.14
-13,3,17:18.14
-2,3,17:18.14
2,3,17:18.14
-12,4,17:18.14
-11,4,17:18.14
-10,4,17:18.14
-9,4,17:17.12
-8,4,17:17.12
-2,4,17:18.14
2,4,17:18.14
-9,5,17:18.14
-8,5,17:17.12
4,5,17:18.14
-1,6,17:18.14
0,6,17:17.12
4,6,17:18.14
-2,7,17:18.14
-1,7,17:17.12
0,7,17:17.12
1,7,17:18.14
2,7,17:18.14
3,7,17:17.12
5,7,17:18.14
-2,8,17:18.14
0,8,17:18.14
0,9,17:18.14
4,9,17:18.14
6,9,17:18.14
7,9,17:18.14
0,10,17:18.14
3,10,17:18.14
4,10,17:18.14
-1,11,17:18.14
0,11,17:18.14
1,11,17:18.14
2,11,17:18.14
-2,12,17:18.14
-1,12,17:18.14
2,12,17:18.14
3,12,17:18.14
-2,13,17:18.14
-1,13,17:18.14
-2,14,17:18.14
-7,-6,18:18.14
-8,-5,18:18.14
-7,-5,18:18.14
-11,-4,18:18.14
-10,-4,18:18.14
-9,-4,18:18.14
-8,-4,18:18.14
-7,-3,18:18.14
-8,-2,18:18.14
-7,-2,18:17.12
-9,-1,18:18.14
-8,-1,18:17.12
3,-1,18:18.14
-10,0,18:18.14
-8,0,18:18.14
-3,0,18:18.14
-2,0,18:17.12
-1,0,18:18.14
0,0,18:18.14
1,0,18:18.14
-8,1,18:18.14
-2,1,18:17.12
-7,2,18:18.14
2,2,18:18.14
-2,3,18:18.14
2,3,18:18.14
-13,4,18:18.14
-12,4,18:18.14
-9,4,18:17.12
-1,4,18:18.14
3,4,18:18.14
-10,5,18:18.14
-9,5,18:17.12
-8,5,18:17.12
-1,5,18:18.14
4,5,18:18.14
-10,6,18:18.14
-1,6,18:18.14
0,6,18:17.12
1,6,18:18.14
4,6,18:18.14
-2,7,18:18.14
-1,7,18:17.12
0,7,18:17.12
2,7,18:18.14
3,7,18:18.14
5,7,18:18.14
-2,8,18:18.14
-1,8,18:17.12
0,8,18:18.14
5,8,18:18.14
0,9,18:18.14
0,10,18:18.14
1,10,18:18.14
1,11,18:18.14
0,12,18:18.14
2,12,18:18.14
-1,13,18:18.14
0,13,18:18.14
-1,14,18:18.14
-8,-6,19:18.14
-8,-2,19:17.12
-7,-2,19:17.12
-8,-1,19:17.12
1,-1,19:18.14
2,-1,19:18.14
-3,0,19:17.12
-2,0,19:17.12
-1,0,19:18.14
0,0,19:18.14
-8,1,19:18.14
-2,1,19:17.12
-8,2,19:18.14
3,2,19:18.14
-2,3,19:18.14
-14,4,19:18.14
-13,4,19:18.14
-9,4,19:17.12
-1,4,19:18.14
-12,5,19:18.14
-11,5,19:18.14
-10,5,19:18.14
-9,5,19:17.12
-1,5,19:18.14
1,6,19:18.14
2,6,19:18.14
-11,7,19:18.14
-10,7,19:18.14
-2,7,19:18.14
-1,7,19:18.14
0,7,19:17.12
3,7,19:18.14
-11,8,19:18.14
-10,8,19:18.14
-2,8,19:18.14
-1,8,19:17.12
0,8,19:18.14
-11,9,19:18.14
-3,9,19:18.14
-2,9,19:17.12
-1,9,19:17.12
0,9,19:18.14
1,9,19:18.14
1,10,19:18.14
1,11,19:18.14
-9,-4,20:18.14
-9,-3,20:17.12
-9,-2,20:18.14
-8,-2,20:17.12
2,-2,20:18.14
-9,-1,20:18.14
-8,-1,20:18.14
-2,-1,20:17.12
-1,-1,20:18.14
0,-1,20:18.14
1,-1,20:18.14
-3,0,20:17.12
-2,0,20:17.12
-1,0,20:17.12
-3,1,20:18.14
-2,1,20:18.14
-1,3,20:18.14
-15,4,20:18.14
-14,4,20:18.14
-9,4,20:18.14
-1,4,20:18.14
-13,5,20:18.14
-12,5,20:18.14
-11,5,20:18.14
-10,5,20:18.14
-9,5,20:17.12
-1,5,20:18.14
-11,6,20:18.14
2,6,20:18.14
-12,7,20:18.14
-11,7,20:18.14
-2,7,20:18.14
0,7,20:18.14
-11,8,20:18.14
-2,8,20:18.14
0,8,20:18.14
1,8,20:18.14
-12,9,20:18.14
-11,9,20:18.14
-3,9,20:18.14
1,9,20:18.14
-2,10,20:17.12
1,10,20:18.14
1,11,20:18.14
-12,-4,21:18.14
-9,-4,21:18.14
-10,-3,21:18.14
-9,-3,21:18.14
-1,-3,21:18.14
-9,-2,21:17.12
-8,-2,21:18.14
-1,-2,21:18.14
0,-2,21:18.14
1,-2,21:18.14
2,-2,21:18.14
-9,-1,21:18.14
-8,-1,21:18.14
-1,-1,21:17.12
0,-1,21:18.14
-10,0,21:18.14
-3,0,21:17.12
-11,1,21:18.14
-5,1,21:18.14
-4,1,21:18.14
-3,1,21:18.14
-6,2,21:18.14
-2,2,21:18.14
-10,4,21:18.14
-9,4,21:18.14
-13,5,21:18.14
-11,5,21:17.12
-10,5,21:17.12
-9,5,21:17.12
-12,6,21:18.14
-11,6,21:18.14
-9,6,21:18.14
-12,7,21:18.14
-2,7,21:18.14
-1,7,21:18.14
0,7,21:17.12
-12,8,21:18.14
-2,8,21:18.14
-12,9,21:18.14
1,9,21:18.14
-13,-5,22:18.14
-12,-4,22:18.14
-11,-4,22:17.12
-10,-4,22:18.14
-9,-4,22:18.14
-1,-4,22:18.14
0,-4,22:18.14
-10,-3,22:18.14
-9,-3,22:18.14
-1,-3,22:18.14
0,-3,22:18.14
-9,-2,22:17.12
-1,-2,22:18.14
0,-2,22:18.14
1,-2,22:18.14
-9,-1,22:18.14
-7,-1,22:18.14
-1,-1,22:17.12
0,-1,22:18.14
-10,0,22:18.14
-4,0,22:17.12
-3,0,22:18.14
0,0,22:18.14
-11,1,22:18.14
-5,1,22:18.14
-4,1,22:18.14
-3,1,22:18.14
-6,2,22:18.14
-5,2,22:18.14
-3,2,22:18.14
-10,3,22:18.14
-2,3,22:18.14
-10,4,22:18.14
-9,4,22:18.14
-8,4,22:18.14
-12,5,22:17.12
-11,5,22:17.12
-10,5,22:18.14
-9,5,22:17.12
-11,6,22:18.14
-10,6,22:18.14
-9,6,22:18.14
-13,7,22:18.14
-12,7,22:18.14
-8,7,22:18.14
-13,8,22:18.14
-13,-5,23:18.14
-10,-5,23:18.14
-9,-5,23:18.14
0,-5,23:18.14
-12,-4,23:18.14
-11,-4,23:18.14
-10,-4,23:18.14
0,-4,23:18.14
-11,-3,23:18.14
-9,-3,23:18.14
0,-3,23:18.14
-10,-2,23:18.14
-9,-2,23:18.14
-1,-2,23:18.14
0,-2,23:17.12
-10,-1,23:18.14
-9,-1,23:18.14
-8,-1,23:18.14
-7,-1,23:18.14
-6,-1,23:18.14
-3,-1,23:18.14
0,-1,23:18.14
1,-1,23:18.14
-10,0,23:18.14
-4,0,23:18.14
-3,0,23:18.14
0,0,23:18.14
-11,1,23:18.14
-4,1,23:18.14
-7,2,23:18.14
-6,2,23:18.14
-5,2,23:18.14
-4,2,23:18.14
-3,2,23:18.14
-10,3,23:18.14
-3,3,23:18.14
-2,3,23:18.14
-10,4,23:18.14
-9,4,23:17.12
-8,4,23:17.12
-12,5,23:17.12
-11,5,23:18.14
-10,5,23:18.14
-9,5,23:17.12
-11,6,23:18.14
-10,6,23:18.14
-9,6,23:18.14
-9,7,23:18.14
-8,7,23:18.14
-10,-6,24:18.14
-9,-6,24:18.14
-13,-5,24:18.14
-11,-5,24:18.14
-10,-5,24:18.14
0,-5,24:18.14
1,-5,24:18.14
-11,-4,24:18.14
-10,-4,24:18.14
0,-4,24:18.14
-11,-3,24:18.14
-10,-3,24:18.14
0,-3,24:18.14
1,-3,24:17.12
-11,-2,24:18.14
-1,-2,24:18.14
0,-2,24:18.14
1,-2,24:18.14
-10,-1,24:18.14
-8,-1,24:18.14
-7,-1,24:18.14
1,-1,24:18.14
-4,0,24:18.14
-3,0,24:18.14
-5,1,24:18.14
-4,1,24:18.14
-7,2,24:18.14
-6,2,24:18.14
-3,2,24:18.14
-13,3,24:18.14
-8,3,24:18.14
-13,4,24:18.14
-10,4,24:18.14
-9,4,24:17.12
-8,4,24:17.12
-14,5,24:17.12
-13,5,24:18.14
-12,5,24:18.14
-9,5,24:17.12
-15,6,24:18.14
-14,6,24:18.14
-9,7,24:18.14
1,-5,25:18.14
0,-4,25:18.14
1,-4,25:17.12
-2,-3,25:18.14
-1,-3,25:18.14
0,-3,25:18.14
-11,-2,25:18.14
-2,-2,25:18.14
1,-2,25:18.14
2,-2,25:18.14
-8,-1,25:18.14
-7,-1,25:18.14
-5,-1,25:18.14
2,-1,25:18.14
-5,0,25:18.14
-4,0,25:17.12
-5,1,25:18.14
-14,2,25:18.14
-7,2,25:18.14
-6,2,25:18.14
-4,2,25:18.14
-3,2,25:18.14
-14,3,25:18.14
-13,3,25:18.14
-8,3,25:18.14
-3,3,25:18.14
-2,3,25:18.14
-13,4,25:18.14
-9,4,25:17.12
-8,4,25:18.14
-7,4,25:18.14
-14,5,25:18.14
-13,5,25:18.14
-12,5,25:18.14
-9,5,25:17.12
-8,5,25:17.12
-15,6,25:18.14
-2,-3,26:18.14
-1,-3,26:18.14
2,-2,26:18.14
-5,-1,26:18.14
-5,0,26:18.14
-9,1,26:18.14
-14,2,26:18.14
-9,2,26:18.14
-6,2,26:18.14
-4,2,26:18.14
-14,3,26:18.14
-9,3,26:18.14
-4,3,26:18.14
-3,3,26:18.14
-14,4,26:18.14
-13,4,26:18.14
-9,4,26:17.12
-8,4,26:18.14
-7,4,26:18.14
-6,4,26:18.14
-15,5,26:18.14
-14,5,26:18.14
-12,5,26:18.14
-9,5,26:18.14
-8,5,26:17.12
-15,6,26:18.14
-1,-3,27:18.14
-5,-1,27:18.14
-5,0,27:18.14
-9,1,27:18.14
-9,2,27:18.14
-9,3,27:18.14
-8,3,27:18.14
-7,3,27:18.14
-6,3,27:18.14
-4,3,27:18.14
-3,3,27:18.14
-13,4,27:18.14
-9,4,27:18.14
-13,5,27:18.14
-12,5,27:18.14
-11,5,27:18.14
-10,5,27:18.14
-9,5,27:18.14
-8,5,27:17.12
-8,6,27:17.12
-9,1,28:18.14
-9,2,28:18.14
-7,3,28:18.14
-6,3,28:18.14
-13,4,28:18.14
-9,4,28:18.14
-12,5,28:18.14
-10,5,28:18.14
-9,5,28:18.14
-8,6,28:18.14
-8,7,28:17.12
-7,7,28:18.14
-9,4,29:18.14
-8,7,29:18.14
-7,7,29:17.12
-6,7,29:18.14
-8,8,29:18.14
-7,8,29:18.14
-6,8,29:18.14
-5,8,29:18.14
-9,9,29:18.14
-9,10,29:18.14
-8,6,30:18.14
-8,7,30:18.14
-8,8,30:18.14
-7,8,30:18.14
-6,8,30:18.14
-5,8,30:18.14
-9,9,30:18.14
-8,9,30:18.14
-9,10,30:18.14
-8,6,31:18.14
-8,7,31:18.14
-8,8,31:18.14
-7,9,31:18.14
-6,9,31:18.14
-8,10,31:18.14
-8,7,32:18.14
-8,8,32:18.14
