[META]
version=2.0
spawnOnBlockType=2
spawnSunlight=True
spawnDarkness=True
spawnWater=False
spawnLava=False
underFill=False
randomRotation=True
dig=True
tree=False
branch=False
needsFoundation=True
rarity=100
collisionPercentage=20
spawnElevationMin=0
spawnElevationMax=200
spawnInBiome=Custom
[DATA]
-1,2,-8:17.12
0,2,-8:17.12
1,2,-8:17.12
0,3,-8:17.12
-1,4,-8:17.12
0,4,-8:17.12
-1,1,-7:17.12
0,1,-7:17.12
-1,2,-7:17.12
-2,3,-7:17.12
2,3,-7:17.12
-2,2,-6:17.12
-1,2,-6:17.12
0,2,-6:17.12
1,2,-6:17.12
-2,3,-6:17.12
-1,3,-6:17.12
0,3,-6:17.12
1,3,-6:17.12
2,3,-6:17.12
-2,4,-6:17.12
-1,4,-6:17.12
0,4,-6:17.12
1,4,-6:17.12
0,1,-5:17.12
-1,2,-5:17.12
0,2,-5:17.12
1,2,-5:17.12
2,2,-5:17.12
-2,3,-5:17.12
-1,3,-5:17.12
0,3,-5:17.12
1,3,-5:17.12
2,3,-5:17.12
-1,4,-5:17.12
0,4,-5:17.12
2,4,-5:17.12
-1,5,-5:17.12
0,5,-5:17.12
1,5,-5:17.12
0,1,-4:17.12
-2,2,-4:17.12
-1,2,-4:17.12
0,2,-4:17.12
1,2,-4:17.12
2,2,-4:17.12
-1,3,-4:17.12
0,3,-4:17.12
-2,4,-4:17.12
-1,4,-4:17.12
0,4,-4:17.12
1,4,-4:17.12
-1,5,-4:17.12
0,5,-4:17.12
-1,2,-3:17.12
0,2,-3:17.12
1,2,-3:17.12
0,3,-3:17.12
2,3,-3:17.12
-1,4,-3:17.12
1,4,-3:17.12
-1,1,-2:17.12
1,1,-2:17.12
-1,2,-2:17.12
-2,3,-2:17.12
-1,3,-2:17.12
0,3,-2:17.12
1,3,-2:17.12
-1,4,-2:17.12
0,4,-2:17.12
1,4,-2:17.12
-1,1,-1:17.12
0,1,-1:17.12
-1,2,-1:17.12
1,2,-1:17.12
2,2,-1:17.12
-2,3,-1:17.12
-1,3,-1:17.12
2,3,-1:18.14
-1,4,-1:17.12
0,4,-1:17.12
1,4,-1:18.14
-2,-1,0:18.14
-1,1,0:18.14
0,1,0:18.14
1,1,0:18.14
2,1,0:18.14
-2,2,0:18.14
0,2,0:17.12
1,2,0:18.14
2,2,0:18.14
-2,3,0:18.14
-1,3,0:18.14
0,3,0:18.14
1,3,0:18.14
2,3,0:18.14
-1,4,0:18.14
0,4,0:18.14
1,4,0:18.14
2,4,0:18.14
0,5,0:18.14
2,6,0:18.14
3,7,0:18.14
-3,-4,1:18.6
-3,-3,1:18.14
-3,-2,1:18.14
-2,-1,1:18.14
-1,0,1:18.14
-1,1,1:18.14
0,1,1:18.14
1,1,1:18.14
0,2,1:17.12
1,2,1:17.12
2,2,1:18.14
-1,3,1:18.14
0,3,1:17.12
1,3,1:17.12
0,4,1:18.14
1,4,1:18.14
1,5,1:18.14
2,6,1:18.14
3,7,1:18.14
4,8,1:18.14
4,9,1:18.6
-4,-4,2:18.6
4,-4,2:18.6
-3,-3,2:18.14
4,-3,2:18.14
6,-3,2:18.6
-3,-2,2:18.14
-2,-1,2:18.14
3,-1,2:18.14
-2,0,2:18.14
-1,0,2:18.14
-1,1,2:18.14
0,1,2:18.14
1,1,2:18.14
0,2,2:17.12
1,2,2:17.12
2,2,2:18.14
-7,3,2:18.6
-4,3,2:18.14
-2,3,2:18.14
-1,3,2:18.14
0,3,2:17.12
1,3,2:17.12
2,3,2:18.14
-8,4,2:18.6
-1,4,2:18.14
0,4,2:18.14
1,4,2:18.14
1,5,2:18.14
2,5,2:18.14
2,6,2:18.14
3,7,2:18.14
3,8,2:18.14
4,8,2:18.14
6,8,2:18.6
4,9,2:18.6
-4,-5,3:18.6
-3,-5,3:18.6
-1,-5,3:18.6
2,-5,3:18.6
3,-5,3:18.6
4,-5,3:18.6
5,-5,3:18.6
-4,-4,3:18.6
-3,-4,3:18.6
4,-4,3:18.6
5,-4,3:18.6
6,-4,3:18.6
-6,-3,3:18.6
-3,-3,3:18.14
4,-3,3:18.14
6,-3,3:18.6
-3,-2,3:18.14
3,-2,3:18.14
-7,-1,3:18.6
-2,-1,3:18.14
3,-1,3:18.14
-7,0,3:18.6
-2,0,3:18.14
-1,0,3:18.14
2,0,3:18.14
-8,1,3:18.6
-1,1,3:18.14
0,1,3:18.14
1,1,3:18.14
-8,2,3:18.6
-2,2,3:18.14
0,2,3:17.12
1,2,3:17.12
2,2,3:18.14
-7,3,3:18.6
-6,3,3:18.14
-5,3,3:18.14
-4,3,3:18.14
-2,3,3:18.14
-1,3,3:18.14
0,3,3:17.12
1,3,3:17.12
2,3,3:18.14
5,3,3:18.14
6,3,3:18.14
7,3,3:18.6
-8,4,3:18.6
-1,4,3:18.14
0,4,3:18.14
1,4,3:18.14
-7,5,3:18.6
-1,5,3:18.14
1,5,3:18.14
2,5,3:18.14
8,5,3:18.6
-7,6,3:18.6
-2,6,3:18.14
2,6,3:18.14
3,7,3:18.14
-6,8,3:18.6
3,8,3:18.14
4,8,3:18.14
6,8,3:18.6
4,9,3:18.6
5,9,3:18.6
-1,10,3:18.6
2,10,3:18.6
3,10,3:18.6
4,10,3:18.6
5,10,3:18.6
-6,-5,4:18.4
-4,-5,4:18.6
-3,-5,4:18.4
-1,-5,4:18.6
0,-5,4:18.6
1,-5,4:18.6
2,-5,4:18.6
3,-5,4:18.6
4,-5,4:18.6
5,-5,4:18.6
-5,-4,4:18.6
-4,-4,4:18.6
-3,-4,4:18.6
4,-4,4:18.6
5,-4,4:18.6
6,-4,4:18.6
-6,-3,4:18.6
-3,-3,4:18.6
3,-3,4:18.6
4,-3,4:18.6
6,-3,4:18.6
-6,-2,4:18.6
-3,-2,4:18.14
-2,-2,4:18.14
3,-2,4:18.14
7,-2,4:18.6
-7,-1,4:18.6
-2,-1,4:18.14
2,-1,4:18.14
3,-1,4:18.14
7,-1,4:18.6
-7,0,4:18.6
-2,0,4:18.14
-1,0,4:18.14
2,0,4:18.14
8,0,4:18.6
-8,1,4:18.6
-1,1,4:18.14
0,1,4:18.14
1,1,4:18.14
2,1,4:18.14
-9,2,4:18.6
-8,2,4:18.6
-7,2,4:18.6
-6,2,4:18.6
-5,2,4:18.6
-4,2,4:18.14
-3,2,4:18.14
-2,2,4:18.14
0,2,4:17.12
1,2,4:17.12
8,2,4:18.6
-7,3,4:18.6
-6,3,4:18.6
-5,3,4:18.6
-4,3,4:18.14
-1,3,4:18.14
0,3,4:17.12
1,3,4:17.12
2,3,4:18.14
3,3,4:18.14
4,3,4:18.14
5,3,4:18.14
6,3,4:18.6
7,3,4:18.6
8,3,4:18.6
-8,4,4:18.6
-1,4,4:18.14
0,4,4:18.14
1,4,4:18.14
-7,5,4:18.6
-2,5,4:18.14
-1,5,4:18.14
1,5,4:18.14
2,5,4:18.14
7,5,4:18.6
8,5,4:18.6
-7,6,4:18.6
-2,6,4:18.14
2,6,4:18.14
7,6,4:18.6
-6,7,4:18.6
-3,7,4:18.14
3,7,4:18.14
7,7,4:18.6
-6,8,4:18.6
-3,8,4:18.6
3,8,4:18.6
4,8,4:18.6
6,8,4:18.6
-5,9,4:18.6
-4,9,4:18.6
-3,9,4:18.6
4,9,4:18.6
5,9,4:18.6
-3,10,4:18.6
-1,10,4:18.6
0,10,4:18.6
1,10,4:18.6
2,10,4:18.6
3,10,4:18.6
4,10,4:18.6
5,10,4:18.6
-6,-5,5:18.4
-5,-5,5:18.4
-4,-5,5:18.6
-3,-5,5:18.4
-2,-5,5:18.6
-1,-5,5:18.6
0,-5,5:18.6
1,-5,5:18.6
2,-5,5:18.6
3,-5,5:18.6
4,-5,5:18.6
5,-5,5:18.6
-5,-4,5:18.6
-4,-4,5:18.6
-3,-4,5:18.6
0,-4,5:18.6
1,-4,5:18.6
2,-4,5:18.6
3,-4,5:18.6
4,-4,5:18.6
5,-4,5:18.6
6,-4,5:18.6
-6,-3,5:18.6
-5,-3,5:18.6
-3,-3,5:18.6
0,-3,5:18.6
1,-3,5:18.6
2,-3,5:18.6
3,-3,5:18.6
4,-3,5:18.6
5,-3,5:18.6
6,-3,5:18.6
-6,-2,5:18.6
-3,-2,5:18.14
-2,-2,5:18.14
0,-2,5:18.14
1,-2,5:18.14
2,-2,5:18.14
3,-2,5:18.14
5,-2,5:18.14
6,-2,5:18.6
7,-2,5:18.6
-7,-1,5:18.6
-6,-1,5:18.6
-5,-1,5:18.6
-2,-1,5:18.14
0,-1,5:18.14
1,-1,5:18.14
2,-1,5:18.14
3,-1,5:18.14
4,-1,5:18.14
5,-1,5:18.14
7,-1,5:18.6
-7,0,5:18.6
-6,0,5:18.6
-5,0,5:18.6
-4,0,5:18.14
-2,0,5:18.14
-1,0,5:18.14
0,0,5:18.14
1,0,5:18.14
2,0,5:18.14
3,0,5:18.14
8,0,5:18.6
-8,1,5:18.6
-7,1,5:18.6
-6,1,5:18.6
-5,1,5:18.6
-4,1,5:18.14
-3,1,5:18.14
-1,1,5:18.14
0,1,5:18.14
1,1,5:18.14
2,1,5:18.14
8,1,5:18.6
-8,2,5:18.6
-7,2,5:18.6
-6,2,5:18.6
-5,2,5:18.6
-4,2,5:18.14
-3,2,5:18.14
-2,2,5:18.14
0,2,5:17.12
1,2,5:17.12
8,2,5:18.6
9,2,5:18.6
-7,3,5:18.6
-6,3,5:18.6
-5,3,5:18.6
-4,3,5:18.14
-3,3,5:18.14
-2,3,5:18.14
-1,3,5:18.14
0,3,5:17.12
1,3,5:17.12
2,3,5:18.14
3,3,5:18.14
4,3,5:18.14
5,3,5:18.14
6,3,5:18.6
7,3,5:18.6
9,3,5:18.6
-8,4,5:18.6
-7,4,5:18.6
-6,4,5:18.6
-5,4,5:18.6
-4,4,5:18.14
-3,4,5:18.14
-1,4,5:18.14
0,4,5:18.14
1,4,5:18.14
8,4,5:18.6
-7,5,5:18.6
-6,5,5:18.6
-5,5,5:18.6
-4,5,5:18.14
-2,5,5:18.14
-1,5,5:18.14
1,5,5:18.14
2,5,5:18.14
7,5,5:18.6
8,5,5:18.6
-7,6,5:18.6
-6,6,5:18.6
-2,6,5:18.14
2,6,5:18.14
7,6,5:18.6
-6,7,5:18.6
-3,7,5:18.14
2,7,5:18.14
3,7,5:18.14
6,7,5:18.6
7,7,5:18.6
-6,8,5:18.6
-5,8,5:18.6
-3,8,5:18.6
3,8,5:18.6
4,8,5:18.6
6,8,5:18.6
-5,9,5:18.6
-4,9,5:18.6
-3,9,5:18.6
3,9,5:18.6
4,9,5:18.6
5,9,5:18.6
-4,10,5:18.6
-3,10,5:18.6
-2,10,5:18.6
-1,10,5:18.6
0,10,5:18.6
1,10,5:18.6
2,10,5:18.6
3,10,5:18.6
4,10,5:18.6
5,10,5:18.6
-6,-5,6:18.4
-5,-5,6:18.4
-4,-5,6:18.6
-3,-5,6:18.6
-2,-5,6:18.6
-1,-5,6:18.6
0,-5,6:18.6
1,-5,6:18.6
2,-5,6:18.6
3,-5,6:18.6
4,-5,6:18.6
5,-5,6:18.6
-5,-4,6:18.6
-4,-4,6:18.6
-3,-4,6:18.6
-2,-4,6:18.6
-1,-4,6:18.6
0,-4,6:18.6
5,-4,6:18.6
-6,-3,6:18.6
-5,-3,6:18.6
-4,-3,6:18.6
-3,-3,6:18.6
-2,-3,6:18.6
-1,-3,6:18.6
0,-3,6:18.6
5,-3,6:18.6
6,-3,6:18.6
-6,-2,6:18.6
-5,-2,6:18.6
-4,-2,6:18.14
-3,-2,6:18.14
-2,-2,6:18.14
-1,-2,6:18.14
0,-2,6:18.14
6,-2,6:18.6
7,-2,6:18.6
-7,-1,6:18.6
-6,-1,6:18.6
-5,-1,6:18.6
-4,-1,6:18.14
-3,-1,6:18.14
-2,-1,6:18.14
-1,-1,6:18.14
0,-1,6:18.14
5,-1,6:18.14
6,-1,6:18.6
7,-1,6:18.6
-7,0,6:18.6
-4,0,6:18.14
-3,0,6:18.14
-2,0,6:18.14
-1,0,6:18.14
0,0,6:18.14
4,0,6:18.14
5,0,6:18.14
6,0,6:18.6
7,0,6:18.6
8,0,6:18.6
-8,1,6:18.6
-7,1,6:18.6
-3,1,6:18.14
-2,1,6:18.14
-1,1,6:18.14
0,1,6:18.14
2,1,6:18.14
3,1,6:18.14
4,1,6:18.14
5,1,6:18.14
6,1,6:18.6
7,1,6:18.6
8,1,6:18.6
-8,2,6:18.6
0,2,6:18.14
2,2,6:18.14
3,2,6:18.14
4,2,6:18.14
5,2,6:18.14
6,2,6:18.6
7,2,6:18.6
8,2,6:18.6
9,2,6:18.6
-1,3,6:18.14
0,3,6:18.14
1,3,6:18.14
2,3,6:18.14
3,3,6:18.14
4,3,6:18.14
5,3,6:18.14
6,3,6:18.6
7,3,6:18.6
8,3,6:18.6
9,3,6:18.6
-8,4,6:18.6
-7,4,6:18.6
-3,4,6:18.14
-2,4,6:18.14
-1,4,6:18.14
0,4,6:18.14
1,4,6:18.14
2,4,6:18.14
3,4,6:18.14
4,4,6:18.14
5,4,6:18.14
6,4,6:18.6
7,4,6:18.6
8,4,6:18.6
-7,5,6:18.6
-4,5,6:18.14
-3,5,6:18.14
-2,5,6:18.14
-1,5,6:18.14
0,5,6:18.14
1,5,6:18.14
2,5,6:18.14
3,5,6:18.14
4,5,6:18.14
5,5,6:18.14
6,5,6:18.6
7,5,6:18.6
8,5,6:18.6
-7,6,6:18.6
-6,6,6:18.6
-5,6,6:18.6
-4,6,6:18.14
-3,6,6:18.14
-2,6,6:18.14
-1,6,6:18.14
0,6,6:18.14
1,6,6:18.14
4,6,6:18.14
5,6,6:18.14
6,6,6:18.6
7,6,6:18.6
-6,7,6:18.6
-5,7,6:18.6
-4,7,6:18.14
-3,7,6:18.14
-2,7,6:18.14
-1,7,6:18.14
0,7,6:18.14
1,7,6:18.14
2,7,6:18.14
4,7,6:18.14
5,7,6:18.14
6,7,6:18.6
-6,8,6:18.6
-5,8,6:18.6
-4,8,6:18.6
-3,8,6:18.6
-2,8,6:18.6
-1,8,6:18.6
0,8,6:18.6
1,8,6:18.6
2,8,6:18.6
5,8,6:18.6
6,8,6:18.6
-5,9,6:18.6
-4,9,6:18.6
-3,9,6:18.6
-2,9,6:18.6
-1,9,6:18.6
0,9,6:18.6
1,9,6:18.6
2,9,6:18.6
5,9,6:18.6
-4,10,6:18.6
-3,10,6:18.6
-2,10,6:18.6
-1,10,6:18.6
0,10,6:18.6
1,10,6:18.6
2,10,6:18.6
3,10,6:18.6
4,10,6:18.6
5,10,6:18.6
-6,-5,7:18.4
-5,-5,7:18.4
-4,-5,7:18.4
-3,-5,7:18.6
-2,-5,7:18.6
-1,-5,7:18.6
0,-5,7:18.6
1,-5,7:18.6
2,-5,7:18.6
3,-5,7:18.6
4,-5,7:18.6
-5,-4,7:18.6
4,-4,7:18.6
5,-4,7:18.6
-5,-3,7:18.6
-3,-3,7:18.6
5,-3,7:18.6
6,-3,7:18.6
-6,-2,7:18.6
-3,-2,7:18.14
-2,-2,7:18.14
6,-2,7:18.6
-6,-1,7:18.6
-2,-1,7:18.14
6,-1,7:18.6
7,-1,7:18.6
-7,0,7:18.6
-2,0,7:18.14
-1,0,7:18.14
7,0,7:18.6
8,0,7:18.6
-7,1,7:18.6
-1,1,7:18.14
8,1,7:18.6
-8,2,7:18.6
-7,2,7:18.6
0,2,7:18.14
3,2,7:18.14
4,2,7:18.14
5,2,7:18.14
6,2,7:18.6
7,2,7:18.6
8,2,7:18.6
9,2,7:18.6
-7,3,7:18.6
-1,3,7:18.14
0,3,7:18.14
1,3,7:18.14
2,3,7:18.14
3,3,7:18.14
7,3,7:18.6
8,3,7:18.6
9,3,7:18.6
-7,4,7:18.6
-1,4,7:18.14
8,4,7:18.6
-7,5,7:18.6
-6,5,7:18.6
-2,5,7:18.14
-1,5,7:18.14
7,5,7:18.6
-6,6,7:18.6
-2,6,7:18.14
6,6,7:18.6
7,6,7:18.6
-6,7,7:18.6
-5,7,7:18.6
-3,7,7:18.14
-2,7,7:18.14
6,7,7:18.6
-5,8,7:18.6
-3,8,7:18.6
5,8,7:18.6
-5,9,7:18.6
-4,9,7:18.6
4,9,7:18.6
5,9,7:18.6
-4,10,7:18.6
-3,10,7:18.6
-2,10,7:18.6
-1,10,7:18.6
0,10,7:18.6
1,10,7:18.6
2,10,7:18.6
3,10,7:18.6
4,10,7:18.6
-5,-5,8:18.4
-4,-5,8:18.6
-3,-5,8:18.6
-2,-5,8:18.6
-1,-5,8:18.6
0,-5,8:18.6
1,-5,8:18.6
-5,-4,8:18.6
-4,-4,8:18.6
-3,-4,8:18.6
0,-4,8:18.6
1,-4,8:18.6
2,-4,8:18.6
3,-4,8:18.6
4,-4,8:18.6
-5,-3,8:18.6
-3,-3,8:18.6
5,-3,8:18.6
-6,-2,8:18.6
-5,-2,8:18.6
-3,-2,8:18.14
-2,-2,8:18.14
5,-2,8:18.14
6,-2,8:18.6
-6,-1,8:18.6
-2,-1,8:18.14
6,-1,8:18.6
7,-1,8:18.6
-7,0,8:18.6
-6,0,8:18.6
-2,0,8:18.14
-1,0,8:18.14
7,0,8:18.6
-7,1,8:18.6
-1,1,8:18.14
7,1,8:18.6
8,1,8:18.6
-7,2,8:18.6
0,2,8:18.14
3,2,8:18.14
4,2,8:18.14
5,2,8:18.14
6,2,8:18.6
7,2,8:18.6
8,2,8:18.6
9,2,8:18.6
-7,3,8:18.6
-1,3,8:18.14
0,3,8:18.14
1,3,8:18.14
2,3,8:18.14
8,3,8:18.6
-7,4,8:18.6
-1,4,8:18.14
7,4,8:18.6
8,4,8:18.6
-6,5,8:18.6
-2,5,8:18.14
-1,5,8:18.14
7,5,8:18.6
-6,6,8:18.6
-2,6,8:18.14
6,6,8:18.6
-5,7,8:18.6
-3,7,8:18.14
-2,7,8:18.14
5,7,8:18.14
6,7,8:18.6
-5,8,8:18.6
-3,8,8:18.6
5,8,8:18.6
-4,9,8:18.6
-3,9,8:18.6
-2,9,8:18.6
-1,9,8:18.6
0,9,8:18.6
1,9,8:18.6
2,9,8:18.6
3,9,8:18.6
4,9,8:18.6
-4,10,8:18.6
-3,10,8:18.6
-2,10,8:18.6
-1,10,8:18.6
0,10,8:18.6
-4,-5,9:18.6
-4,-4,9:18.6
-3,-4,9:18.6
-2,-4,9:18.6
-1,-4,9:18.6
0,-4,9:18.6
1,-4,9:18.6
2,-4,9:18.6
3,-4,9:18.6
4,-4,9:18.6
-5,-3,9:18.6
-4,-3,9:18.6
-3,-3,9:18.6
4,-3,9:18.6
5,-3,9:18.6
-5,-2,9:18.6
-3,-2,9:18.14
-2,-2,9:18.14
5,-2,9:18.14
-6,-1,9:18.6
-5,-1,9:18.6
-2,-1,9:18.14
6,-1,9:18.6
-6,0,9:18.6
-2,0,9:18.14
-1,0,9:18.14
6,0,9:18.6
7,0,9:18.6
-7,1,9:18.6
-6,1,9:18.6
-1,1,9:18.14
7,1,9:18.6
-7,2,9:18.6
0,2,9:18.14
1,2,9:18.14
2,2,9:18.14
3,2,9:18.14
4,2,9:18.14
5,2,9:18.14
6,2,9:18.6
7,2,9:18.6
8,2,9:18.6
-7,3,9:18.6
-1,3,9:18.14
0,3,9:18.14
1,3,9:18.14
7,3,9:18.6
8,3,9:18.6
-7,4,9:18.6
-6,4,9:18.6
-1,4,9:18.14
7,4,9:18.6
-6,5,9:18.6
-2,5,9:18.14
-1,5,9:18.14
6,5,9:18.6
7,5,9:18.6
-6,6,9:18.6
-5,6,9:18.6
-2,6,9:18.14
5,6,9:18.14
6,6,9:18.6
-5,7,9:18.6
-3,7,9:18.14
-2,7,9:18.14
5,7,9:18.14
-5,8,9:18.6
-4,8,9:18.6
-3,8,9:18.6
4,8,9:18.6
5,8,9:18.6
-4,9,9:18.6
-3,9,9:18.6
-2,9,9:18.6
-1,9,9:18.6
0,9,9:18.6
1,9,9:18.6
2,9,9:18.6
3,9,9:18.6
4,9,9:18.6
-4,10,9:18.6
-4,-4,10:18.6
-3,-4,10:18.6
-2,-4,10:18.6
-1,-4,10:18.6
0,-4,10:18.6
1,-4,10:18.6
2,-4,10:18.6
3,-4,10:18.6
4,-4,10:18.6
-4,-3,10:18.6
-3,-3,10:18.6
4,-3,10:18.6
-5,-2,10:18.6
-4,-2,10:18.6
-3,-2,10:18.6
-2,-2,10:18.6
5,-2,10:18.6
-5,-1,10:18.6
-2,-1,10:18.6
5,-1,10:18.6
6,-1,10:18.6
-6,0,10:18.6
-2,0,10:18.6
-1,0,10:18.6
6,0,10:18.6
-6,1,10:18.6
-1,1,10:18.6
7,1,10:18.6
-7,2,10:18.6
0,2,10:18.6
1,2,10:18.6
2,2,10:18.6
3,2,10:18.6
4,2,10:18.6
5,2,10:18.6
6,2,10:18.6
7,2,10:18.6
8,2,10:18.6
-7,3,10:18.6
-6,3,10:18.6
-1,3,10:18.6
0,3,10:18.6
7,3,10:18.6
-6,4,10:18.6
-1,4,10:18.6
6,4,10:18.6
7,4,10:18.6
-6,5,10:18.6
-5,5,10:18.6
-2,5,10:18.6
-1,5,10:18.6
6,5,10:18.6
-5,6,10:18.6
-2,6,10:18.6
5,6,10:18.6
-5,7,10:18.6
-4,7,10:18.6
-3,7,10:18.6
-2,7,10:18.6
4,7,10:18.6
5,7,10:18.6
-4,8,10:18.6
-3,8,10:18.6
3,8,10:18.6
4,8,10:18.6
-4,9,10:18.6
-3,9,10:18.6
-2,9,10:18.6
-1,9,10:18.6
0,9,10:18.6
1,9,10:18.6
2,9,10:18.6
3,9,10:18.6
-4,10,10:18.6
-4,-4,11:18.6
-3,-4,11:18.6
-2,-4,11:18.6
-1,-4,11:18.6
0,-4,11:18.6
1,-4,11:18.6
2,-4,11:18.6
3,-4,11:18.6
-4,-3,11:18.6
-3,-3,11:18.6
0,-3,11:18.6
1,-3,11:18.6
2,-3,11:18.6
3,-3,11:18.6
4,-3,11:18.6
-4,-2,11:18.6
-3,-2,11:18.6
-2,-2,11:18.6
5,-2,11:18.6
-5,-1,11:18.6
-2,-1,11:18.6
5,-1,11:18.6
-6,0,11:18.6
-5,0,11:18.6
-2,0,11:18.6
-1,0,11:18.6
5,0,11:18.6
6,0,11:18.6
-6,1,11:18.6
-1,1,11:18.6
6,1,11:18.6
7,1,11:18.6
-7,2,11:18.6
-6,2,11:18.6
0,2,11:18.6
1,2,11:18.6
2,2,11:18.6
3,2,11:18.6
4,2,11:18.6
5,2,11:18.6
6,2,11:18.6
7,2,11:18.6
8,2,11:18.6
-6,3,11:18.6
-1,3,11:18.6
0,3,11:18.6
7,3,11:18.6
-6,4,11:18.6
-1,4,11:18.6
6,4,11:18.6
-5,5,11:18.6
-2,5,11:18.6
-1,5,11:18.6
5,5,11:18.6
6,5,11:18.6
-5,6,11:18.6
-2,6,11:18.6
5,6,11:18.6
-4,7,11:18.6
-3,7,11:18.6
-2,7,11:18.6
4,7,11:18.6
-4,8,11:18.6
-3,8,11:18.6
-2,8,11:18.6
-1,8,11:18.6
0,8,11:18.6
1,8,11:18.6
2,8,11:18.6
3,8,11:18.6
4,8,11:18.6
-4,9,11:18.6
-3,9,11:18.6
-2,9,11:18.6
-4,10,11:18.6
-3,-4,12:18.6
-4,-3,12:18.6
-3,-3,12:18.6
-2,-3,12:18.6
-1,-3,12:18.6
0,-3,12:18.6
1,-3,12:18.6
2,-3,12:18.6
3,-3,12:18.6
-4,-2,12:18.6
-3,-2,12:18.6
-2,-2,12:18.6
3,-2,12:18.6
-5,-1,12:18.6
-4,-1,12:18.6
-2,-1,12:18.6
4,-1,12:18.6
5,-1,12:18.6
-5,0,12:18.6
-4,0,12:18.6
-2,0,12:18.6
-1,0,12:18.6
5,0,12:18.6
-6,1,12:18.6
-5,1,12:18.6
-1,1,12:18.6
6,1,12:18.6
-6,2,12:18.6
-5,2,12:18.6
0,2,12:18.6
1,2,12:18.6
2,2,12:18.6
3,2,12:18.6
4,2,12:18.6
5,2,12:18.6
6,2,12:18.6
7,2,12:18.6
-6,3,12:18.6
-5,3,12:18.6
-1,3,12:18.6
0,3,12:18.6
6,3,12:18.6
7,3,12:18.6
8,3,12:18.6
-5,4,12:18.6
-1,4,12:18.6
5,4,12:18.6
6,4,12:18.6
-5,5,12:18.6
-4,5,12:18.6
-2,5,12:18.6
-1,5,12:18.6
5,5,12:18.6
-4,6,12:18.6
-2,6,12:18.6
4,6,12:18.6
5,6,12:18.6
-4,7,12:18.6
-3,7,12:18.6
-2,7,12:18.6
-1,7,12:18.6
0,7,12:18.6
1,7,12:18.6
2,7,12:18.6
3,7,12:18.6
4,7,12:18.6
-3,8,12:18.6
-2,8,12:18.6
-1,8,12:18.6
0,8,12:18.6
1,8,12:18.6
2,8,12:18.6
3,8,12:18.6
-4,9,12:18.6
-4,10,12:18.6
-3,-4,13:18.6
-3,-3,13:18.6
-3,-2,13:18.6
-2,-2,13:18.6
-1,-2,13:18.6
0,-2,13:18.6
1,-2,13:18.6
2,-2,13:18.6
3,-2,13:18.6
-3,-1,13:18.6
-2,-1,13:18.6
-1,-1,13:18.6
0,-1,13:18.6
1,-1,13:18.6
2,-1,13:18.6
3,-1,13:18.6
4,-1,13:18.6
-4,0,13:18.6
-3,0,13:18.6
-2,0,13:18.6
-1,0,13:18.6
3,0,13:18.6
4,0,13:18.6
5,0,13:18.6
-4,1,13:18.6
-3,1,13:18.6
-1,1,13:18.6
4,1,13:18.6
5,1,13:18.6
6,1,13:18.6
-5,2,13:18.6
-4,2,13:18.6
-3,2,13:18.6
0,2,13:18.6
1,2,13:18.6
2,2,13:18.6
3,2,13:18.6
4,2,13:18.6
5,2,13:18.6
6,2,13:18.6
7,2,13:18.6
-5,3,13:18.6
-4,3,13:18.6
-3,3,13:18.6
-1,3,13:18.6
0,3,13:18.6
4,3,13:18.6
5,3,13:18.6
6,3,13:18.6
7,3,13:18.6
8,3,13:18.6
-4,4,13:18.6
-3,4,13:18.6
-1,4,13:18.6
3,4,13:18.6
4,4,13:18.6
5,4,13:18.6
-4,5,13:18.6
-3,5,13:18.6
-2,5,13:18.6
-1,5,13:18.6
2,5,13:18.6
3,5,13:18.6
4,5,13:18.6
-3,6,13:18.6
-2,6,13:18.6
-1,6,13:18.6
0,6,13:18.6
1,6,13:18.6
2,6,13:18.6
-3,7,13:18.6
-2,7,13:18.6
-1,7,13:18.6
0,7,13:18.6
1,7,13:18.6
2,7,13:18.6
-4,8,13:18.6
-3,8,13:18.6
-3,-3,14:18.6
-3,-2,14:18.6
-2,-2,14:18.6
-2,-1,14:18.6
-1,-1,14:18.6
0,-1,14:18.6
1,-1,14:18.6
-2,0,14:18.6
-1,0,14:18.6
0,0,14:18.6
1,0,14:18.6
2,0,14:18.6
-3,1,14:18.6
-2,1,14:18.6
-1,1,14:18.6
1,1,14:18.6
2,1,14:18.6
3,1,14:18.6
-3,2,14:18.6
-2,2,14:18.6
0,2,14:18.6
1,2,14:18.6
2,2,14:18.6
3,2,14:18.6
4,2,14:18.6
5,2,14:18.6
6,2,14:18.6
-3,3,14:18.6
-2,3,14:18.6
-1,3,14:18.6
0,3,14:18.6
2,3,14:18.6
3,3,14:18.6
4,3,14:18.6
6,3,14:18.6
7,3,14:18.6
-3,4,14:18.6
-2,4,14:18.6
-1,4,14:18.6
0,4,14:18.6
1,4,14:18.6
2,4,14:18.6
3,4,14:18.6
-2,5,14:18.6
-1,5,14:18.6
0,5,14:18.6
1,5,14:18.6
2,5,14:18.6
-3,6,14:18.6
-2,6,14:18.6
-3,7,14:18.6
-2,-2,15:18.6
-2,-1,15:18.6
-2,0,15:18.6
-1,0,15:18.6
-1,1,15:18.6
0,1,15:18.6
1,1,15:18.6
-2,2,15:18.6
0,2,15:18.6
1,2,15:18.6
2,2,15:18.6
3,2,15:18.6
4,2,15:18.6
5,2,15:18.6
-1,3,15:18.6
0,3,15:18.6
1,3,15:18.6
2,3,15:18.6
-1,4,15:18.6
0,4,15:18.6
1,4,15:18.6
-2,5,15:18.6
-3,6,15:18.6
0,2,16:18.6
