[META]
version=2.0
spawnOnBlockType=2
spawnSunlight=True
spawnDarkness=True
spawnWater=False
spawnLava=False
underFill=False
randomRotation=True
dig=True
tree=False
branch=False
needsFoundation=True
rarity=100
collisionPercentage=20
spawnElevationMin=0
spawnElevationMax=200
spawnInBiome=Custom
[DATA]
1,1,-8:17.12
3,1,-8:17.12
-5,4,-8:17.12
9,4,-8:17.12
9,6,-8:17.12
-7,11,-8:17.12
-5,11,-8:17.12
-6,12,-8:17.12
8,15,-8:17.12
9,16,-8:17.12
-5,17,-8:17.12
-5,19,-8:17.12
0,20,-8:17.12
6,20,-8:17.12
0,21,-8:17.12
6,21,-8:17.12
6,22,-8:17.12
2,0,-7:17.12
1,1,-7:17.12
2,1,-7:17.12
1,2,-7:17.12
-5,3,-7:17.12
-4,3,-7:17.12
1,3,-7:17.12
-6,4,-7:17.12
-5,4,-7:17.12
-4,4,-7:17.12
2,4,-7:17.12
9,4,-7:17.12
10,4,-7:17.12
-6,5,-7:17.12
-5,5,-7:17.12
-4,5,-7:17.12
8,5,-7:17.12
9,5,-7:17.12
10,5,-7:17.12
-5,6,-7:17.12
9,6,-7:17.12
-6,10,-7:17.12
-7,11,-7:17.12
-6,11,-7:17.12
-5,11,-7:17.12
-6,12,-7:17.12
-5,12,-7:17.12
8,15,-7:17.12
9,15,-7:17.12
10,15,-7:17.12
8,16,-7:17.12
9,16,-7:17.12
10,16,-7:17.12
-4,17,-7:17.12
-5,18,-7:17.12
-4,18,-7:17.12
-3,18,-7:17.12
-6,19,-7:17.12
-5,19,-7:17.12
-4,19,-7:17.12
0,19,-7:17.12
0,20,-7:17.12
5,20,-7:17.12
6,20,-7:17.12
0,21,-7:17.12
1,21,-7:17.12
6,21,-7:17.12
7,21,-7:17.12
1,1,-6:17.12
2,1,-6:17.12
2,2,-6:17.12
3,2,-6:17.12
-5,3,-6:17.12
2,3,-6:17.12
-5,4,-6:17.12
2,4,-6:17.12
-5,5,-6:17.12
-4,5,-6:17.12
9,5,-6:17.12
-5,6,-6:17.12
8,6,-6:17.12
9,6,-6:17.12
8,7,-6:17.12
9,7,-6:17.12
10,7,-6:17.12
-6,10,-6:17.12
-5,10,-6:17.12
-6,11,-6:17.12
-5,11,-6:17.12
-4,11,-6:17.12
-6,12,-6:17.12
-5,12,-6:17.12
7,14,-6:17.12
7,15,-6:17.12
8,15,-6:17.12
9,15,-6:17.12
-4,17,-6:17.12
-3,17,-6:17.12
-6,18,-6:17.12
-5,18,-6:17.12
-4,18,-6:17.12
-3,18,-6:17.12
0,18,-6:17.12
-5,19,-6:17.12
-4,19,-6:17.12
-3,19,-6:17.12
-1,19,-6:17.12
0,19,-6:17.12
1,19,-6:17.12
-1,20,-6:17.12
6,20,-6:17.12
7,20,-6:17.12
0,21,-6:17.12
5,21,-6:17.12
6,21,-6:17.12
7,21,-6:17.12
3,2,-5:17.12
1,3,-5:17.12
2,3,-5:17.12
3,3,-5:17.12
-5,4,-5:17.12
1,4,-5:17.12
2,4,-5:17.12
-5,5,-5:17.12
-4,5,-5:17.12
2,5,-5:17.12
8,5,-5:17.12
9,5,-5:17.12
10,5,-5:17.12
-6,6,-5:17.12
-5,6,-5:17.12
-4,6,-5:17.12
8,6,-5:17.12
9,6,-5:17.12
-5,7,-5:17.12
8,7,-5:17.12
9,7,-5:17.12
10,7,-5:17.12
9,8,-5:17.12
-6,9,-5:17.12
-5,9,-5:17.12
-4,9,-5:17.12
-5,10,-5:17.12
-4,10,-5:17.12
-5,11,-5:17.12
-4,11,-5:17.12
-3,11,-5:17.12
-5,12,-5:17.12
7,13,-5:17.12
7,14,-5:17.12
8,14,-5:17.12
7,15,-5:17.12
9,15,-5:17.12
8,16,-5:17.12
-4,17,-5:17.12
-3,17,-5:17.12
-5,18,-5:17.12
-4,18,-5:17.12
-3,18,-5:17.12
-1,18,-5:17.12
0,18,-5:17.12
-4,19,-5:17.12
-1,19,-5:17.12
0,19,-5:17.12
1,19,-5:17.12
6,19,-5:17.12
6,20,-5:17.12
7,20,-5:17.12
6,21,-5:17.12
7,21,-5:17.12
1,3,-4:17.12
2,3,-4:17.12
3,3,-4:17.12
1,4,-4:17.12
2,4,-4:17.12
3,4,-4:17.12
-6,5,-4:17.12
2,5,-4:17.12
-6,6,-4:17.12
-5,6,-4:17.12
-4,6,-4:17.12
8,6,-4:17.12
9,6,-4:17.12
10,6,-4:17.12
-5,7,-4:17.12
8,7,-4:17.12
9,7,-4:17.12
-6,8,-4:17.12
9,8,-4:17.12
-6,9,-4:17.12
-5,9,-4:17.12
-5,10,-4:17.12
-4,10,-4:17.12
-5,11,-4:17.12
-4,11,-4:17.12
-4,12,-4:17.12
7,13,-4:17.12
6,14,-4:17.12
7,14,-4:17.12
8,14,-4:17.12
9,14,-4:17.12
7,15,-4:17.12
8,15,-4:17.12
-4,17,-4:17.12
-3,17,-4:17.12
-4,18,-4:17.12
-3,18,-4:17.12
-1,18,-4:17.12
0,18,-4:17.12
-4,19,-4:17.12
-3,19,-4:17.12
-1,19,-4:17.12
0,19,-4:17.12
1,19,-4:17.12
6,19,-4:17.12
0,20,-4:17.12
5,20,-4:17.12
6,20,-4:17.12
7,20,-4:17.12
6,21,-4:17.12
7,21,-4:17.12
2,3,-3:17.12
2,4,-3:17.12
3,4,-3:17.12
1,5,-3:17.12
2,5,-3:17.12
3,5,-3:17.12
-6,6,-3:17.12
-5,6,-3:17.12
-4,6,-3:17.12
7,6,-3:17.12
9,6,-3:17.12
-6,7,-3:17.12
-5,7,-3:17.12
-4,7,-3:17.12
7,7,-3:17.12
8,7,-3:17.12
9,7,-3:17.12
10,7,-3:17.12
-6,8,-3:17.12
-5,8,-3:17.12
-4,8,-3:17.12
7,8,-3:17.12
8,8,-3:17.12
-6,9,-3:17.12
-5,9,-3:17.12
-4,9,-3:17.12
8,9,-3:17.12
-6,10,-3:17.12
-5,10,-3:17.12
-4,10,-3:17.12
-5,11,-3:17.12
6,13,-3:17.12
7,13,-3:17.12
6,14,-3:17.12
7,14,-3:17.12
7,15,-3:17.12
-5,17,-3:17.12
-4,17,-3:17.12
-3,17,-3:17.12
-1,17,-3:17.12
0,17,-3:17.12
1,17,-3:17.12
-5,18,-3:17.12
-4,18,-3:17.12
-3,18,-3:17.12
-1,18,-3:17.12
0,18,-3:17.12
1,18,-3:17.12
-4,19,-3:17.12
0,19,-3:17.12
1,19,-3:17.12
5,19,-3:17.12
6,19,-3:17.12
7,19,-3:17.12
4,20,-3:17.12
5,20,-3:17.12
6,20,-3:17.12
7,20,-3:17.12
6,21,-3:17.12
7,21,-3:17.12
1,2,-2:17.12
1,3,-2:17.12
1,4,-2:17.12
2,4,-2:17.12
3,4,-2:17.12
-2,5,-2:17.12
1,5,-2:17.12
2,5,-2:17.12
3,5,-2:17.12
-5,6,-2:17.12
-3,6,-2:17.12
-2,6,-2:17.12
-1,6,-2:17.12
2,6,-2:17.12
11,6,-2:17.12
-7,7,-2:17.12
-6,7,-2:17.12
-5,7,-2:17.12
-4,7,-2:17.12
-3,7,-2:17.12
-2,7,-2:17.12
-1,7,-2:17.12
7,7,-2:17.12
8,7,-2:17.12
-5,8,-2:17.12
-4,8,-2:17.12
-1,8,-2:17.12
8,8,-2:17.12
-6,9,-2:17.12
-5,9,-2:17.12
-4,9,-2:17.12
-3,9,-2:17.12
7,9,-2:17.12
8,9,-2:17.12
9,9,-2:17.12
-5,10,-2:17.12
5,12,-2:17.12
6,12,-2:17.12
7,12,-2:17.12
5,13,-2:17.12
6,13,-2:17.12
7,13,-2:17.12
6,14,-2:17.12
7,14,-2:17.12
8,14,-2:17.12
-3,16,-2:17.12
0,16,-2:17.12
-5,17,-2:17.12
-4,17,-2:17.12
-3,17,-2:17.12
-1,17,-2:17.12
0,17,-2:17.12
-5,18,-2:17.12
-4,18,-2:17.12
-3,18,-2:17.12
-1,18,-2:17.12
0,18,-2:17.12
1,18,-2:17.12
5,18,-2:17.12
-5,19,-2:17.12
-4,19,-2:17.12
-3,19,-2:17.12
0,19,-2:17.12
6,19,-2:17.12
-6,20,-2:17.12
-5,20,-2:17.12
4,20,-2:17.12
5,20,-2:17.12
6,20,-2:17.12
5,21,-2:17.12
6,21,-2:17.12
1,3,-1:17.12
2,3,-1:17.12
1,4,-1:17.12
2,4,-1:17.12
3,4,-1:17.12
5,4,-1:17.12
6,4,-1:17.12
-2,5,-1:17.12
1,5,-1:17.12
2,5,-1:17.12
3,5,-1:17.12
4,5,-1:17.12
5,5,-1:17.12
-2,6,-1:17.12
-1,6,-1:17.12
2,6,-1:17.12
3,6,-1:17.12
6,6,-1:17.12
7,6,-1:17.12
9,6,-1:17.12
10,6,-1:17.12
11,6,-1:17.12
-6,7,-1:17.12
-5,7,-1:17.12
-3,7,-1:17.12
-2,7,-1:17.12
-1,7,-1:17.12
0,7,-1:17.12
1,7,-1:17.12
8,7,-1:17.12
9,7,-1:17.12
10,7,-1:17.12
11,7,-1:17.12
-6,8,-1:17.12
-5,8,-1:17.12
-4,8,-1:17.12
-3,8,-1:17.12
-2,8,-1:17.12
-1,8,-1:17.12
0,8,-1:17.12
1,8,-1:17.12
4,8,-1:17.12
5,8,-1:17.12
8,8,-1:17.12
9,8,-1:17.12
10,8,-1:17.12
-5,9,-1:17.12
-4,9,-1:17.12
-3,9,-1:17.12
-2,9,-1:17.12
-1,9,-1:17.12
0,9,-1:17.12
4,9,-1:17.12
-4,10,-1:17.12
-3,10,-1:17.12
-1,10,-1:17.12
4,10,-1:17.12
5,10,-1:17.12
6,11,-1:17.12
5,12,-1:17.12
6,12,-1:17.12
7,12,-1:17.12
-3,13,-1:17.12
5,13,-1:17.12
6,13,-1:17.12
7,13,-1:17.12
-4,14,-1:17.12
-3,14,-1:17.12
5,14,-1:17.12
6,14,-1:17.12
7,14,-1:17.12
-5,15,-1:17.12
-4,15,-1:17.12
-3,15,-1:17.12
-1,15,-1:17.12
5,15,-1:17.12
-5,16,-1:17.12
-4,16,-1:17.12
-3,16,-1:17.12
-1,16,-1:17.12
0,16,-1:17.12
1,16,-1:17.12
-5,17,-1:17.12
-4,17,-1:17.12
-3,17,-1:17.12
-1,17,-1:17.12
0,17,-1:17.12
1,17,-1:17.12
-5,18,-1:17.12
-4,18,-1:17.12
-3,18,-1:17.12
-2,18,-1:17.12
0,18,-1:17.12
1,18,-1:17.12
4,18,-1:17.12
5,18,-1:17.12
6,18,-1:17.12
-5,19,-1:17.12
-4,19,-1:17.12
0,19,-1:17.12
4,19,-1:17.12
5,19,-1:17.12
6,19,-1:17.12
4,20,-1:17.12
5,20,-1:17.12
6,20,-1:17.12
5,21,-1:17.12
6,21,-1:17.12
1,4,0:17.12
2,4,0:17.12
1,5,0:17.12
2,5,0:17.12
3,5,0:17.12
4,5,0:17.12
5,5,0:17.12
-2,6,0:17.12
-1,6,0:17.12
1,6,0:17.12
2,6,0:17.12
3,6,0:17.12
4,6,0:17.12
5,6,0:17.12
6,6,0:17.12
-3,7,0:17.12
-2,7,0:17.12
-1,7,0:17.12
0,7,0:17.12
1,7,0:17.12
2,7,0:17.12
3,7,0:17.12
4,7,0:17.12
5,7,0:17.12
6,7,0:17.12
7,7,0:17.12
8,7,0:17.12
9,7,0:17.12
-5,8,0:17.12
-4,8,0:17.12
-3,8,0:17.12
0,8,0:17.12
1,8,0:17.12
2,8,0:17.12
3,8,0:17.12
4,8,0:17.12
5,8,0:17.12
6,8,0:17.12
7,8,0:17.12
8,8,0:17.12
9,8,0:17.12
-5,9,0:17.12
-4,9,0:17.12
-3,9,0:17.12
-2,9,0:17.12
0,9,0:17.12
1,9,0:17.12
2,9,0:17.12
3,9,0:17.12
4,9,0:17.12
5,9,0:17.12
6,9,0:17.12
7,9,0:17.12
8,9,0:17.12
9,9,0:17.12
-4,10,0:17.12
-3,10,0:17.12
-2,10,0:17.12
-1,10,0:17.12
0,10,0:17.12
1,10,0:17.12
2,10,0:17.12
3,10,0:17.12
4,10,0:17.12
5,10,0:17.12
6,10,0:17.12
-2,11,0:17.12
-1,11,0:17.12
0,11,0:17.12
1,11,0:17.12
5,11,0:17.12
6,11,0:17.12
-4,12,0:17.12
-3,12,0:17.12
-2,12,0:17.12
-1,12,0:17.12
0,12,0:17.12
1,12,0:17.12
2,12,0:17.12
3,12,0:17.12
4,12,0:17.12
6,12,0:17.12
-5,13,0:17.12
-4,13,0:17.12
-3,13,0:17.12
-2,13,0:17.12
-1,13,0:17.12
0,13,0:17.12
1,13,0:17.12
4,13,0:17.12
5,13,0:17.12
-5,14,0:17.12
-4,14,0:17.12
-3,14,0:17.12
-2,14,0:17.12
-1,14,0:17.12
0,14,0:17.12
1,14,0:17.12
4,14,0:17.12
5,14,0:17.12
6,14,0:17.12
-5,15,0:17.12
-4,15,0:17.12
-3,15,0:17.12
-2,15,0:17.12
-1,15,0:17.12
0,15,0:17.12
1,15,0:17.12
2,15,0:17.12
5,15,0:17.12
6,15,0:17.12
-4,16,0:17.12
-3,16,0:17.12
-2,16,0:17.12
-1,16,0:17.12
0,16,0:17.12
1,16,0:17.12
2,16,0:17.12
6,16,0:17.12
7,16,0:17.12
-4,17,0:17.12
-3,17,0:17.12
-1,17,0:17.12
0,17,0:17.12
1,17,0:17.12
2,17,0:17.12
7,17,0:17.12
8,17,0:17.12
0,18,0:17.12
2,18,0:17.12
3,18,0:17.12
4,18,0:17.12
5,18,0:17.12
3,19,0:17.12
4,19,0:17.12
5,19,0:17.12
6,19,0:17.12
4,20,0:17.12
1,5,1:17.12
2,5,1:17.12
1,6,1:17.12
2,6,1:17.12
3,6,1:17.12
-2,7,1:17.12
-1,7,1:17.12
0,7,1:17.12
2,7,1:17.12
3,7,1:17.12
4,7,1:17.12
5,7,1:17.12
6,7,1:17.12
7,7,1:17.12
8,7,1:17.12
-3,8,1:17.12
-2,8,1:17.12
0,8,1:17.12
1,8,1:17.12
2,8,1:17.12
3,8,1:17.12
4,8,1:17.12
5,8,1:17.12
6,8,1:17.12
7,8,1:17.12
8,8,1:17.12
-3,9,1:17.12
-2,9,1:17.12
0,9,1:17.12
1,9,1:17.12
2,9,1:17.12
3,9,1:17.12
6,9,1:17.12
7,9,1:17.12
8,9,1:17.12
-4,10,1:17.12
-3,10,1:17.12
-2,10,1:17.12
-1,10,1:17.12
0,10,1:17.12
1,10,1:17.12
4,10,1:17.12
5,10,1:17.12
6,10,1:17.12
7,10,1:17.12
-4,11,1:17.12
-3,11,1:17.12
-2,11,1:17.12
-1,11,1:17.12
0,11,1:17.12
1,11,1:17.12
2,11,1:17.12
3,11,1:17.12
4,11,1:17.12
5,11,1:17.12
6,11,1:17.12
-4,12,1:17.12
-2,12,1:17.12
-1,12,1:17.12
0,12,1:17.12
1,12,1:17.12
2,12,1:17.12
3,12,1:17.12
4,12,1:17.12
5,12,1:17.12
-5,13,1:17.12
-4,13,1:17.12
-2,13,1:17.12
-1,13,1:17.12
0,13,1:17.12
1,13,1:17.12
2,13,1:17.12
3,13,1:17.12
4,13,1:17.12
5,13,1:17.12
6,13,1:17.12
-4,14,1:17.12
-3,14,1:17.12
-2,14,1:17.12
-1,14,1:17.12
0,14,1:17.12
2,14,1:17.12
4,14,1:17.12
5,14,1:17.12
6,14,1:17.12
-4,15,1:17.12
-3,15,1:17.12
-2,15,1:17.12
-1,15,1:17.12
0,15,1:17.12
2,15,1:17.12
3,15,1:17.12
5,15,1:17.12
6,15,1:17.12
7,15,1:17.12
-1,16,1:17.12
0,16,1:17.12
3,16,1:17.12
6,16,1:17.12
7,16,1:17.12
0,17,1:17.12
1,17,1:17.12
3,17,1:17.12
4,17,1:17.12
7,17,1:17.12
1,18,1:17.12
2,18,1:17.12
3,18,1:17.12
4,18,1:17.12
2,19,1:17.12
3,19,1:17.12
4,19,1:17.12
1,3,2:18.14
1,6,2:17.12
2,6,2:17.12
3,6,2:17.12
-2,7,2:17.12
-1,7,2:17.12
0,7,2:17.12
3,7,2:17.12
-3,8,2:17.12
-2,8,2:17.12
0,8,2:17.12
1,8,2:17.12
2,8,2:17.12
3,8,2:17.12
5,8,2:17.12
6,8,2:17.12
7,8,2:17.12
-3,9,2:17.12
-2,9,2:17.12
0,9,2:17.12
1,9,2:17.12
2,9,2:17.12
3,9,2:17.12
4,9,2:17.12
5,9,2:17.12
6,9,2:17.12
7,9,2:17.12
-4,10,2:17.12
-3,10,2:17.12
-2,10,2:17.12
4,10,2:17.12
5,10,2:17.12
-4,11,2:17.12
-2,11,2:17.12
0,11,2:17.12
1,11,2:17.12
2,11,2:17.12
3,11,2:17.12
4,11,2:17.12
-4,12,2:17.12
-2,12,2:17.12
-1,12,2:17.12
0,12,2:17.12
1,12,2:17.12
2,12,2:17.12
3,12,2:17.12
4,12,2:17.12
-4,13,2:17.12
-3,13,2:17.12
-2,13,2:17.12
-1,13,2:17.12
2,13,2:17.12
3,13,2:17.12
4,13,2:17.12
5,13,2:17.12
-4,14,2:17.12
-3,14,2:17.12
-2,14,2:17.12
-1,14,2:17.12
2,14,2:17.12
-1,15,2:17.12
0,15,2:17.12
1,15,2:17.12
2,15,2:17.12
0,16,2:17.12
1,16,2:17.12
2,16,2:17.12
3,16,2:17.12
1,17,2:17.12
2,17,2:17.12
3,17,2:17.12
2,18,2:17.12
3,18,2:17.12
4,1,3:18.14
1,2,3:18.14
4,2,3:18.14
1,3,3:18.14
1,4,3:18.14
5,4,3:18.14
5,5,3:18.14
7,5,3:18.14
1,6,3:17.12
2,6,3:17.12
-2,7,3:17.12
-1,7,3:17.12
0,7,3:17.12
2,7,3:17.12
3,7,3:17.12
-2,8,3:17.12
-1,8,3:17.12
0,8,3:17.12
1,8,3:17.12
2,8,3:17.12
-3,9,3:17.12
2,9,3:17.12
3,9,3:17.12
-3,10,3:17.12
3,10,3:17.12
-3,11,3:17.12
0,11,3:17.12
2,11,3:17.12
3,11,3:17.12
-4,12,3:17.12
-3,12,3:17.12
1,12,3:17.12
2,12,3:17.12
-3,13,3:17.12
-2,13,3:17.12
-1,13,3:17.12
1,13,3:17.12
2,13,3:17.12
-1,14,3:17.12
0,14,3:17.12
1,14,3:17.12
2,14,3:17.12
0,15,3:17.12
1,15,3:17.12
2,0,4:18.14
3,0,4:18.14
4,0,4:18.14
2,1,4:18.14
3,1,4:18.14
4,1,4:18.14
0,2,4:18.14
2,2,4:18.14
4,2,4:18.14
1,3,4:18.14
2,3,4:18.14
4,3,4:18.14
5,3,4:18.14
1,4,4:18.14
2,4,4:17.12
4,4,4:18.14
5,4,4:18.14
1,5,4:17.12
2,5,4:17.12
3,5,4:17.12
4,5,4:18.14
6,5,4:18.14
7,5,4:18.14
8,5,4:18.14
1,6,4:17.12
2,6,4:17.12
3,6,4:17.12
0,7,4:17.12
1,7,4:17.12
2,7,4:17.12
3,7,4:17.12
-2,8,4:17.12
-1,8,4:17.12
0,8,4:17.12
1,8,4:17.12
2,8,4:17.12
-3,9,4:17.12
1,9,4:17.12
2,9,4:17.12
3,9,4:17.12
-3,10,4:17.12
2,10,4:17.12
3,10,4:17.12
-3,11,4:17.12
2,11,4:17.12
-4,12,4:17.12
-3,12,4:17.12
2,12,4:17.12
-3,13,4:17.12
-2,13,4:17.12
-1,13,4:17.12
1,13,4:17.12
0,14,4:17.12
1,14,4:17.12
6,-2,5:18.14
5,-1,5:18.14
1,0,5:18.14
4,0,5:18.14
5,0,5:18.14
1,1,5:18.14
2,1,5:18.14
3,1,5:18.14
4,1,5:18.14
2,2,5:18.14
3,2,5:18.14
0,3,5:18.14
2,3,5:18.14
3,3,5:17.12
0,4,5:18.14
2,4,5:17.12
3,4,5:17.12
5,4,5:18.14
6,4,5:18.14
9,4,5:18.14
1,5,5:17.12
2,5,5:17.12
3,5,5:17.12
4,5,5:17.12
5,5,5:18.14
6,5,5:18.14
7,5,5:18.14
8,5,5:18.14
1,6,5:17.12
2,6,5:17.12
3,6,5:17.12
4,6,5:17.12
7,6,5:18.14
8,6,5:18.14
1,7,5:17.12
2,7,5:17.12
7,7,5:18.14
8,7,5:18.14
-2,8,5:17.12
-1,8,5:17.12
0,8,5:17.12
1,8,5:17.12
-3,9,5:17.12
1,9,5:17.12
2,9,5:17.12
-3,10,5:17.12
2,10,5:17.12
-4,11,5:17.12
-3,11,5:17.12
2,11,5:17.12
-4,12,5:17.12
-3,12,5:17.12
1,12,5:17.12
2,12,5:17.12
-2,13,5:17.12
-1,13,5:17.12
0,13,5:17.12
1,13,5:17.12
0,14,5:17.12
4,-3,6:18.14
5,-3,6:18.14
3,-2,6:18.14
4,-2,6:18.14
5,-2,6:18.14
6,-2,6:18.14
4,-1,6:18.14
5,-1,6:18.14
4,0,6:18.14
1,1,6:18.14
2,1,6:18.14
3,1,6:17.12
4,1,6:18.14
8,1,6:18.14
9,1,6:18.14
0,2,6:18.14
1,2,6:18.14
2,2,6:18.14
3,2,6:17.12
1,3,6:18.14
2,3,6:17.12
3,3,6:17.12
4,3,6:18.14
8,3,6:18.14
9,3,6:18.14
10,3,6:18.14
4,4,6:18.14
5,4,6:17.12
7,4,6:18.14
8,4,6:18.14
0,5,6:18.14
1,5,6:17.12
4,5,6:18.14
5,5,6:18.14
6,5,6:18.14
-2,6,6:18.14
-1,6,6:18.14
0,6,6:18.14
1,6,6:17.12
2,6,6:17.12
3,6,6:17.12
6,6,6:18.14
2,7,6:17.12
3,7,6:18.14
5,7,6:18.14
-2,8,6:17.12
-1,8,6:17.12
0,8,6:17.12
-3,9,6:17.12
-2,9,6:17.12
1,9,6:17.12
2,9,6:17.12
-3,10,6:17.12
2,10,6:17.12
-4,11,6:17.12
-3,11,6:17.12
2,11,6:17.12
-5,12,6:17.12
-4,12,6:17.12
-3,12,6:17.12
-2,12,6:17.12
1,12,6:17.12
-2,13,6:17.12
-1,13,6:17.12
0,13,6:17.12
1,13,6:17.12
-11,17,6:18.14
-10,17,6:18.14
5,-2,7:18.14
6,-2,7:18.14
5,-1,7:18.14
4,0,7:18.14
5,0,7:18.14
3,1,7:18.14
4,1,7:18.14
3,2,7:18.14
4,2,7:18.14
7,2,7:18.14
8,2,7:18.14
2,3,7:18.14
3,3,7:18.14
5,3,7:18.14
6,3,7:17.12
7,3,7:18.14
8,3,7:18.14
9,3,7:18.14
-1,4,7:18.14
0,4,7:18.14
1,4,7:18.14
5,4,7:18.14
6,4,7:18.14
-3,5,7:18.14
-2,5,7:18.14
-1,5,7:18.14
0,5,7:17.12
1,5,7:18.14
4,5,7:18.14
5,5,7:18.14
-2,6,7:18.14
-1,6,7:18.14
0,6,7:18.14
2,6,7:17.12
3,6,7:17.12
3,7,7:18.14
4,7,7:18.14
5,7,7:18.14
-2,8,7:17.12
-1,8,7:17.12
0,8,7:17.12
3,8,7:18.14
4,8,7:18.14
5,8,7:18.14
-15,9,7:18.6
-14,9,7:18.14
-3,9,7:17.12
1,9,7:17.12
2,9,7:17.12
3,9,7:18.14
4,9,7:18.14
-14,10,7:18.14
-4,10,7:17.12
-3,10,7:17.12
2,10,7:17.12
-5,11,7:17.12
-4,11,7:17.12
1,11,7:17.12
-6,12,7:17.12
-5,12,7:17.12
-4,12,7:17.12
-3,12,7:17.12
-2,12,7:17.12
1,12,7:17.12
-6,13,7:18.14
-4,13,7:17.12
-3,13,7:17.12
-2,13,7:17.12
-1,13,7:17.12
0,13,7:17.12
-11,16,7:18.14
-10,16,7:18.14
-12,17,7:18.6
-11,17,7:18.14
-14,18,7:18.6
-13,18,7:18.6
-12,18,7:18.6
6,-2,8:18.14
5,-1,8:18.14
5,0,8:18.14
3,1,8:18.14
4,1,8:18.14
5,1,8:18.14
2,2,8:18.14
3,2,8:17.12
4,2,8:18.14
5,2,8:18.14
6,2,8:18.14
7,2,8:18.14
-1,3,8:18.14
0,3,8:18.14
1,3,8:18.14
2,3,8:18.14
3,3,8:18.14
4,3,8:18.14
6,3,8:18.14
7,3,8:18.14
8,3,8:18.14
9,3,8:18.14
-2,4,8:18.14
-1,4,8:18.14
0,4,8:18.14
1,4,8:18.14
3,4,8:18.14
-3,5,8:18.14
-2,5,8:18.14
-1,5,8:17.12
0,5,8:18.14
1,5,8:18.14
3,5,8:18.14
4,5,8:18.14
5,5,8:18.14
-1,6,8:18.14
0,6,8:18.14
3,6,8:17.12
4,6,8:18.14
-17,7,8:18.6
3,7,8:18.14
4,7,8:18.14
-16,8,8:18.6
-15,8,8:18.14
-2,8,8:17.12
-1,8,8:17.12
0,8,8:17.12
4,8,8:18.14
-15,9,8:18.14
-14,9,8:18.14
-13,9,8:18.14
-3,9,8:17.12
0,9,8:17.12
1,9,8:17.12
4,9,8:18.14
-13,10,8:18.14
-12,10,8:18.14
-5,10,8:17.12
-4,10,8:17.12
-3,10,8:17.12
1,10,8:17.12
2,10,8:17.12
-12,11,8:18.14
-11,11,8:18.14
-10,11,8:18.14
-6,11,8:17.12
-5,11,8:17.12
1,11,8:17.12
-7,12,8:18.14
-6,12,8:17.12
-5,12,8:17.12
-4,12,8:17.12
-3,12,8:17.12
-2,12,8:17.12
0,12,8:17.12
1,12,8:17.12
-8,13,8:18.14
-7,13,8:18.14
-6,13,8:17.12
-5,13,8:17.12
-4,13,8:17.12
-3,13,8:17.12
-2,13,8:17.12
-1,13,8:17.12
0,13,8:17.12
-9,14,8:18.14
-8,14,8:18.14
-11,15,8:18.14
-10,15,8:18.14
-9,15,8:18.14
-13,16,8:18.14
-12,16,8:18.14
-11,16,8:18.14
-14,17,8:18.14
-13,17,8:18.14
-12,17,8:18.14
-15,18,8:18.14
-14,18,8:18.14
3,0,9:18.14
1,1,9:18.14
2,1,9:18.14
3,1,9:18.14
4,1,9:18.14
5,1,9:18.14
6,1,9:18.14
0,2,9:18.14
2,2,9:18.14
3,2,9:17.12
4,2,9:18.14
-3,3,9:18.14
-2,3,9:18.14
0,3,9:18.14
2,3,9:18.14
3,3,9:18.14
6,3,9:18.14
-3,4,9:18.14
-1,4,9:18.14
0,4,9:18.14
3,4,9:18.14
4,4,9:18.14
-3,5,9:18.14
-2,5,9:18.14
-1,5,9:17.12
0,5,9:18.14
1,5,9:18.14
3,5,9:18.14
4,5,9:18.14
-2,6,9:18.14
0,6,9:18.14
3,6,9:17.12
4,6,9:18.14
5,6,9:18.14
-17,7,9:18.6
-16,7,9:18.6
0,7,9:18.14
3,7,9:18.14
4,7,9:18.14
-15,8,9:18.14
-14,8,9:18.14
-2,8,9:17.12
-1,8,9:17.12
0,8,9:18.14
4,8,9:18.14
-15,9,9:18.14
-14,9,9:18.14
-13,9,9:18.14
-12,9,9:18.14
-3,9,9:17.12
0,9,9:18.14
1,9,9:17.12
-16,10,9:18.14
-15,10,9:18.14
-14,10,9:18.14
-13,10,9:18.14
-12,10,9:18.14
-11,10,9:18.14
-3,10,9:17.12
1,10,9:17.12
2,10,9:17.12
-15,11,9:18.14
-14,11,9:18.14
-13,11,9:18.14
-12,11,9:18.14
-11,11,9:18.14
-7,11,9:17.12
-6,11,9:17.12
-5,11,9:17.12
-4,11,9:17.12
1,11,9:17.12
-13,12,9:18.14
-12,12,9:18.14
-11,12,9:18.14
-10,12,9:18.14
-8,12,9:17.12
-7,12,9:17.12
-5,12,9:17.12
-4,12,9:17.12
-3,12,9:17.12
-2,12,9:17.12
0,12,9:17.12
1,12,9:17.12
-10,13,9:18.14
-9,13,9:18.14
-8,13,9:18.14
-7,13,9:17.12
-6,13,9:17.12
-5,13,9:17.12
-1,13,9:17.12
0,13,9:17.12
-11,14,9:18.14
-10,14,9:18.14
-13,15,9:18.14
-12,15,9:18.14
-11,15,9:18.14
-14,16,9:18.14
-13,16,9:18.14
-12,16,9:18.14
-15,17,9:18.14
-14,17,9:18.14
-11,17,9:18.14
-12,18,9:18.14
-11,18,9:18.14
3,0,10:18.14
6,0,10:18.14
-1,1,10:18.14
1,1,10:18.14
2,1,10:18.14
3,1,10:18.14
4,1,10:18.14
5,1,10:18.14
-2,2,10:18.14
-1,2,10:17.12
0,2,10:18.14
2,2,10:18.14
4,2,10:18.14
-2,3,10:18.14
-1,3,10:18.14
0,3,10:18.14
2,3,10:18.14
3,3,10:18.14
6,3,10:18.14
-1,4,10:18.14
0,4,10:18.14
3,4,10:18.14
4,4,10:18.14
5,4,10:18.14
-2,5,10:18.14
-1,5,10:17.12
0,5,10:18.14
3,5,10:18.14
4,5,10:17.12
-17,6,10:18.6
-16,6,10:18.6
-3,6,10:18.14
-2,6,10:18.14
0,6,10:18.14
-16,7,10:18.6
-15,7,10:18.6
-14,7,10:18.14
0,7,10:18.14
4,7,10:18.14
5,7,10:18.14
6,7,10:18.14
-14,8,10:18.14
-13,8,10:18.14
-12,8,10:18.14
-3,8,10:17.12
-2,8,10:17.12
-1,8,10:17.12
0,8,10:17.12
4,8,10:18.14
-11,9,10:18.14
-3,9,10:17.12
0,9,10:17.12
1,9,10:17.12
3,9,10:18.14
-10,10,10:18.14
-9,10,10:18.14
-8,10,10:18.14
-4,10,10:17.12
-3,10,10:17.12
1,10,10:17.12
-16,11,10:18.14
-15,11,10:18.14
-8,11,10:18.14
-7,11,10:17.12
-6,11,10:17.12
-5,11,10:17.12
-4,11,10:17.12
1,11,10:17.12
-17,12,10:18.14
-16,12,10:18.14
-15,12,10:18.14
-14,12,10:18.14
-13,12,10:18.14
-9,12,10:17.12
-8,12,10:17.12
-7,12,10:17.12
-6,12,10:17.12
-5,12,10:17.12
-3,12,10:17.12
-2,12,10:17.12
0,12,10:17.12
-15,13,10:18.14
-14,13,10:18.14
-13,13,10:18.14
-12,13,10:18.14
-10,13,10:18.14
-9,13,10:18.14
-8,13,10:18.14
-7,13,10:17.12
-6,13,10:17.12
-1,13,10:17.12
0,13,10:17.12
-13,14,10:18.14
-12,14,10:18.14
-9,14,10:18.14
-14,15,10:18.14
-13,15,10:18.14
-9,15,10:18.14
-15,16,10:18.14
-14,16,10:18.14
-10,16,10:18.14
-16,17,10:18.14
-11,17,10:18.14
-12,18,10:18.14
-11,18,10:18.14
3,0,11:18.14
4,0,11:18.14
6,0,11:18.14
4,1,11:18.14
5,1,11:18.14
-1,2,11:18.14
0,2,11:18.14
2,2,11:18.14
5,2,11:18.14
-9,3,11:18.6
-8,3,11:18.6
-1,3,11:18.14
0,3,11:18.14
3,3,11:18.14
5,3,11:18.14
-9,4,11:18.6
-8,4,11:18.6
-2,4,11:18.14
-1,4,11:18.14
0,4,11:18.14
3,4,11:18.14
4,4,11:18.14
-17,5,11:18.6
-16,5,11:18.6
-10,5,11:18.6
-9,5,11:18.6
-2,5,11:18.14
-1,5,11:18.14
0,5,11:18.14
3,5,11:18.14
4,5,11:17.12
-16,6,11:18.6
-15,6,11:18.6
-14,6,11:18.14
-10,6,11:18.14
-9,6,11:18.14
-3,6,11:18.14
-2,6,11:18.14
-1,6,11:18.14
0,6,11:18.14
3,6,11:18.14
4,6,11:18.14
-14,7,11:18.14
-13,7,11:18.14
-10,7,11:18.14
-9,7,11:18.14
-3,7,11:18.14
-2,7,11:18.14
-1,7,11:18.14
0,7,11:18.14
1,7,11:18.14
4,7,11:18.14
5,7,11:18.14
6,7,11:18.14
-12,8,11:18.14
-11,8,11:18.14
-10,8,11:18.14
-3,8,11:17.12
-2,8,11:17.12
-1,8,11:17.12
0,8,11:17.12
4,8,11:18.14
5,8,11:18.14
-10,9,11:18.14
-3,9,11:17.12
0,9,11:17.12
1,9,11:17.12
4,9,11:18.14
-9,10,11:18.14
-4,10,11:17.12
-3,10,11:17.12
1,10,11:17.12
-9,11,11:17.12
-8,11,11:17.12
-7,11,11:17.12
-4,11,11:17.12
-3,11,11:17.12
1,11,11:17.12
-10,12,11:17.12
-9,12,11:17.12
-8,12,11:17.12
-7,12,11:17.12
-3,12,11:17.12
-2,12,11:17.12
0,12,11:17.12
-17,13,11:18.14
-16,13,11:18.14
-9,13,11:18.14
-8,13,11:18.14
-1,13,11:17.12
0,13,11:17.12
-12,14,11:18.14
-11,14,11:18.14
-10,14,11:18.14
-9,14,11:18.14
-8,14,11:18.14
-9,15,11:18.14
-10,16,11:18.14
-11,17,11:18.14
-12,18,11:18.14
-11,18,11:18.14
-15,19,11:18.14
-12,19,11:18.14
-16,20,11:18.14
4,0,12:18.14
-12,2,12:18.14
-11,2,12:18.6
-10,2,12:18.6
-1,2,12:18.14
0,2,12:18.14
5,2,12:18.14
-12,3,12:18.14
-11,3,12:18.14
-1,3,12:18.14
0,3,12:18.14
-12,4,12:18.14
-11,4,12:18.14
-10,4,12:18.6
-2,4,12:18.14
-1,4,12:18.14
0,4,12:18.14
1,4,12:18.14
3,4,12:18.14
-16,5,12:18.14
-15,5,12:18.14
-12,5,12:18.14
-11,5,12:18.14
-10,5,12:18.6
-3,5,12:18.14
-2,5,12:18.14
-1,5,12:18.14
0,5,12:18.14
1,5,12:18.14
3,5,12:18.14
-15,6,12:18.14
-14,6,12:18.14
-13,6,12:18.14
-12,6,12:18.14
-11,6,12:18.14
-4,6,12:18.14
-3,6,12:18.14
-2,6,12:18.14
-1,6,12:18.14
0,6,12:18.14
1,6,12:18.14
4,6,12:18.14
-13,7,12:18.14
-12,7,12:18.14
-4,7,12:18.14
4,7,12:18.14
-3,8,12:17.12
-2,8,12:17.12
-1,8,12:17.12
0,8,12:17.12
-11,9,12:18.14
-10,9,12:18.14
-3,9,12:17.12
0,9,12:17.12
1,9,12:17.12
-8,10,12:17.12
-4,10,12:17.12
-3,10,12:17.12
1,10,12:17.12
-10,11,12:17.12
-9,11,12:17.12
-8,11,12:17.12
-4,11,12:17.12
-3,11,12:17.12
0,11,12:17.12
1,11,12:17.12
-11,12,12:17.12
-10,12,12:17.12
-9,12,12:17.12
-3,12,12:17.12
-2,12,12:17.12
0,12,12:17.12
-12,13,12:17.12
-11,13,12:17.12
-10,13,12:17.12
-1,13,12:17.12
0,13,12:18.14
-14,14,12:17.12
-13,14,12:18.14
-12,14,12:18.14
-11,14,12:18.14
-10,14,12:18.14
-9,14,12:18.14
-15,15,12:17.12
-14,15,12:17.12
-9,15,12:18.14
2,15,12:18.14
3,15,12:18.14
-10,16,12:18.14
3,16,12:18.14
-15,17,12:18.14
-11,17,12:18.14
-16,18,12:18.14
-15,18,12:18.14
-12,18,12:18.14
-11,18,12:18.14
-17,19,12:18.14
-16,19,12:18.14
-13,19,12:18.14
-12,19,12:18.14
-18,20,12:18.14
-17,20,12:18.14
-16,20,12:18.14
-18,21,12:18.14
-17,21,12:18.14
-13,2,13:18.14
-12,2,13:18.14
0,2,13:18.14
-14,3,13:18.14
-13,3,13:18.14
-12,3,13:18.14
-2,3,13:18.14
-13,4,13:18.14
-4,4,13:18.14
-3,4,13:18.14
-2,4,13:18.14
-1,4,13:18.14
0,4,13:18.14
1,4,13:18.14
-4,5,13:18.14
-3,5,13:18.14
0,5,13:18.14
1,5,13:18.14
-18,6,13:18.14
-4,6,13:18.14
1,6,13:18.14
2,6,13:18.14
-13,7,13:18.14
-12,7,13:18.14
-2,7,13:17.12
-12,8,13:18.14
-3,8,13:17.12
-2,8,13:17.12
-1,8,13:17.12
0,8,13:17.12
-11,9,13:18.14
-3,9,13:17.12
0,9,13:17.12
1,9,13:17.12
-10,10,13:18.14
-9,10,13:17.12
-4,10,13:17.12
1,10,13:17.12
-10,11,13:17.12
-9,11,13:17.12
-4,11,13:17.12
0,11,13:17.12
1,11,13:17.12
-21,12,13:18.14
-20,12,13:18.14
-11,12,13:17.12
-10,12,13:17.12
-3,12,13:17.12
-2,12,13:17.12
0,12,13:17.12
-20,13,13:18.14
-19,13,13:18.14
-18,13,13:18.14
-17,13,13:18.14
-13,13,13:17.12
-12,13,13:17.12
-11,13,13:17.12
-10,13,13:18.14
-1,13,13:17.12
0,13,13:18.14
1,13,13:18.14
-17,14,13:18.14
-14,14,13:18.14
-13,14,13:18.14
-12,14,13:18.14
-11,14,13:18.14
-10,14,13:18.14
-9,14,13:18.14
1,14,13:18.14
2,14,13:18.14
-16,15,13:17.12
-15,15,13:18.14
-14,15,13:18.14
-13,15,13:18.14
-9,15,13:18.14
-8,15,13:18.14
2,15,13:18.14
3,15,13:18.14
-17,16,13:17.12
-16,16,13:17.12
-15,16,13:18.14
-10,16,13:18.14
3,16,13:18.14
-16,17,13:18.14
-15,17,13:18.14
-11,17,13:18.14
4,17,13:18.14
-17,18,13:18.14
-16,18,13:18.14
-12,18,13:18.14
-11,18,13:18.14
-18,19,13:18.14
-17,19,13:18.14
-12,19,13:18.14
-19,20,13:18.14
-18,20,13:18.14
-19,21,13:18.14
0,1,14:18.14
0,2,14:18.14
-3,3,14:18.14
0,3,14:18.14
0,4,14:18.14
1,4,14:18.14
-20,5,14:18.14
1,5,14:18.14
2,5,14:18.14
-19,6,14:18.14
-18,6,14:18.14
-17,7,14:18.14
-13,7,14:18.14
-2,7,14:17.12
5,7,14:18.14
6,7,14:18.14
-13,8,14:18.14
-12,8,14:18.14
-3,8,14:17.12
-2,8,14:17.12
-1,8,14:17.12
0,8,14:18.14
-12,9,14:18.14
-11,9,14:18.14
-4,9,14:17.12
-3,9,14:17.12
0,9,14:17.12
1,9,14:17.12
-11,10,14:18.14
-10,10,14:17.12
-9,10,14:17.12
-4,10,14:17.12
1,10,14:17.12
-10,11,14:17.12
-9,11,14:17.12
-4,11,14:17.12
0,11,14:17.12
1,11,14:17.12
-12,12,14:18.14
-11,12,14:18.14
-3,12,14:17.12
-2,12,14:17.12
0,12,14:17.12
1,12,14:18.14
-22,13,14:18.14
-21,13,14:18.14
-20,13,14:18.14
-11,13,14:18.14
-1,13,14:17.12
1,13,14:18.14
-23,14,14:18.6
-22,14,14:18.14
-21,14,14:18.14
-20,14,14:18.14
-19,14,14:18.14
-18,14,14:18.14
-17,14,14:18.14
-11,14,14:18.14
-10,14,14:18.14
-9,14,14:18.14
-1,14,14:18.14
0,14,14:18.14
1,14,14:18.14
-19,15,14:18.14
-18,15,14:18.14
-17,15,14:18.14
-16,15,14:18.14
-15,15,14:18.14
-14,15,14:18.14
-13,15,14:18.14
-12,15,14:18.14
-11,15,14:18.14
-10,15,14:18.14
2,15,14:18.14
-17,16,14:18.14
-16,16,14:18.14
-10,16,14:18.14
-9,16,14:18.14
-8,16,14:18.14
-7,16,14:18.14
-6,16,14:18.14
3,16,14:18.14
-18,17,14:17.12
-17,17,14:18.14
-11,17,14:18.14
4,17,14:18.14
-18,18,14:18.14
-17,18,14:18.14
-12,18,14:18.14
-11,18,14:18.14
-19,19,14:18.14
-18,19,14:18.14
-12,19,14:18.14
-20,20,14:18.14
-19,20,14:18.14
-20,21,14:18.14
1,-2,15:18.6
1,-1,15:18.6
0,0,15:18.6
1,0,15:18.6
0,1,15:18.14
1,1,15:18.14
0,2,15:18.14
1,2,15:18.14
0,3,15:18.14
1,3,15:18.14
-21,4,15:18.6
0,4,15:18.14
1,4,15:18.14
-20,5,15:18.14
-19,5,15:18.14
-15,5,15:18.14
1,5,15:18.14
-19,6,15:18.14
-18,6,15:18.14
-17,6,15:18.14
-15,6,15:18.14
-14,6,15:18.14
1,6,15:18.14
3,6,15:18.14
4,6,15:18.14
5,6,15:18.14
6,6,15:18.14
7,6,15:18.14
-17,7,15:18.14
-14,7,15:18.14
-13,7,15:18.14
-3,7,15:17.12
-2,7,15:17.12
1,7,15:18.14
2,7,15:18.14
3,7,15:18.14
4,7,15:18.14
5,7,15:18.14
6,7,15:18.14
-13,8,15:18.14
-3,8,15:17.12
-2,8,15:17.12
-1,8,15:17.12
0,8,15:17.12
-12,9,15:18.14
-4,9,15:17.12
-3,9,15:17.12
0,9,15:17.12
1,9,15:17.12
-11,10,15:18.14
-10,10,15:17.12
-5,10,15:18.14
-4,10,15:17.12
1,10,15:17.12
-12,11,15:18.14
-11,11,15:17.12
-10,11,15:17.12
-4,11,15:17.12
0,11,15:17.12
1,11,15:17.12
-12,12,15:18.14
-3,12,15:17.12
-2,12,15:17.12
0,12,15:17.12
2,12,15:18.14
-12,13,15:18.14
-1,13,15:17.12
1,13,15:18.14
2,13,15:18.14
-12,14,15:18.14
-11,14,15:18.14
-10,14,15:18.14
-9,14,15:18.14
0,14,15:18.14
1,14,15:18.14
-23,15,15:18.6
-22,15,15:18.14
-21,15,15:18.14
-20,15,15:18.14
-19,15,15:18.14
-18,15,15:18.14
-16,15,15:18.14
-15,15,15:18.14
-13,15,15:18.14
-12,15,15:18.14
-11,15,15:18.14
-2,15,15:18.14
-1,15,15:18.14
0,15,15:18.14
1,15,15:18.14
2,15,15:18.14
-22,16,15:18.14
-21,16,15:18.14
-20,16,15:18.14
-19,16,15:18.14
-18,16,15:18.14
-9,16,15:18.14
-8,16,15:18.14
-7,16,15:18.14
-6,16,15:18.14
-5,16,15:18.14
3,16,15:18.14
-19,17,15:18.14
-18,17,15:18.14
-11,17,15:18.14
-9,17,15:18.14
-8,17,15:18.14
-7,17,15:18.14
-6,17,15:18.14
3,17,15:18.14
4,17,15:18.14
-20,18,15:18.14
-19,18,15:18.14
-12,18,15:18.14
-20,19,15:18.14
-19,19,15:18.14
-21,20,15:18.14
-20,20,15:18.14
1,-3,16:18.6
1,-2,16:18.6
1,-1,16:18.6
1,0,16:18.6
1,1,16:18.6
1,2,16:18.14
-7,3,16:18.14
1,3,16:18.14
2,3,16:18.14
-21,4,16:18.6
-7,4,16:18.14
1,4,16:18.14
2,4,16:18.14
7,4,16:18.6
-20,5,16:18.14
-19,5,16:18.14
-7,5,16:18.14
1,5,16:18.14
2,5,16:18.14
3,5,16:18.14
4,5,16:18.14
5,5,16:18.14
6,5,16:18.14
7,5,16:18.6
-18,6,16:18.14
-16,6,16:17.12
-15,6,16:18.14
-7,6,16:18.14
-6,6,16:18.14
1,6,16:18.14
2,6,16:18.14
4,6,16:18.14
-16,7,16:18.14
-15,7,16:17.12
-14,7,16:18.14
-6,7,16:18.14
-3,7,16:17.12
-2,7,16:17.12
-15,8,16:18.14
-14,8,16:18.14
-13,8,16:18.14
-6,8,16:18.14
-3,8,16:17.12
-2,8,16:17.12
-1,8,16:17.12
0,8,16:17.12
-13,9,16:18.14
-12,9,16:18.14
-6,9,16:18.14
-4,9,16:17.12
0,9,16:17.12
1,9,16:17.12
-12,10,16:18.14
-11,10,16:17.12
-10,10,16:18.14
-9,10,16:18.14
-8,10,16:18.14
-7,10,16:18.14
-6,10,16:18.14
-4,10,16:17.12
1,10,16:17.12
-11,11,16:17.12
-10,11,16:17.12
-5,11,16:17.12
-4,11,16:17.12
0,11,16:17.12
1,11,16:17.12
2,11,16:18.14
-13,12,16:18.14
-3,12,16:17.12
-2,12,16:17.12
0,12,16:17.12
2,12,16:18.14
-13,13,16:18.14
-12,13,16:18.14
-1,13,16:17.12
2,13,16:18.14
-13,14,16:18.14
-12,14,16:18.14
2,14,16:18.14
-15,15,16:18.14
-14,15,16:18.14
-12,15,16:18.14
-11,15,16:18.14
-2,15,16:18.14
-1,15,16:18.14
0,15,16:18.14
1,15,16:18.14
2,15,16:18.14
-23,16,16:18.6
-22,16,16:18.14
-21,16,16:18.14
-18,16,16:18.14
-17,16,16:18.14
-16,16,16:18.14
-12,16,16:18.14
-2,16,16:18.14
-1,16,16:18.14
2,16,16:18.14
3,16,16:18.14
-22,17,16:18.14
-18,17,16:18.14
-9,17,16:18.14
-8,17,16:18.14
-7,17,16:18.14
-6,17,16:18.14
3,17,16:18.14
1,-3,17:18.6
1,-2,17:18.6
1,-1,17:18.6
1,0,17:18.6
2,0,17:18.6
-7,1,17:18.14
1,1,17:18.6
2,1,17:18.6
-7,2,17:18.14
1,2,17:18.14
2,2,17:18.6
-8,3,17:18.14
-7,3,17:18.14
-6,3,17:18.14
1,3,17:18.14
2,3,17:18.14
6,3,17:18.14
-21,4,17:18.6
-20,4,17:18.14
-8,4,17:18.14
-7,4,17:18.14
-6,4,17:18.14
1,4,17:18.14
2,4,17:18.14
3,4,17:18.14
4,4,17:18.14
5,4,17:18.14
6,4,17:18.14
7,4,17:18.6
-20,5,17:18.14
-19,5,17:18.14
-8,5,17:18.14
-7,5,17:18.14
1,5,17:18.14
2,5,17:18.14
-18,6,17:18.14
-17,6,17:18.14
-16,6,17:17.12
-7,6,17:18.14
1,6,17:18.14
-15,7,17:18.14
-14,7,17:17.12
-7,7,17:18.14
-4,7,17:17.12
-3,7,17:17.12
-2,7,17:17.12
0,7,17:18.14
-15,8,17:18.14
-14,8,17:18.14
-13,8,17:17.12
-7,8,17:18.14
-4,8,17:17.12
-2,8,17:17.12
-1,8,17:17.12
0,8,17:17.12
-13,9,17:18.14
-12,9,17:17.12
-10,9,17:18.14
-9,9,17:18.14
-8,9,17:18.14
-7,9,17:18.14
-6,9,17:18.14
-4,9,17:17.12
-3,9,17:17.12
-1,9,17:17.12
1,9,17:17.12
-12,10,17:18.14
-11,10,17:18.14
-10,10,17:18.14
-9,10,17:18.14
-5,10,17:17.12
-4,10,17:17.12
1,10,17:17.12
-12,11,17:17.12
-11,11,17:17.12
-5,11,17:17.12
0,11,17:17.12
1,11,17:17.12
3,11,17:18.14
-5,12,17:17.12
-4,12,17:17.12
-3,12,17:17.12
-2,12,17:17.12
0,12,17:17.12
2,12,17:18.14
3,12,17:18.14
-2,13,17:17.12
-1,13,17:17.12
0,13,17:17.12
2,13,17:18.14
3,13,17:18.14
-13,14,17:18.14
2,14,17:18.14
-15,15,17:18.14
-13,15,17:18.14
-17,16,17:18.14
-16,16,17:18.14
-13,16,17:18.14
-12,16,17:18.14
-2,16,17:18.14
-1,16,17:18.14
0,16,17:18.14
1,16,17:18.14
-18,17,17:18.14
-10,18,17:18.6
-9,18,17:18.6
-8,18,17:18.6
-7,18,17:18.6
1,-3,18:18.6
1,-2,18:18.6
1,-1,18:18.6
1,0,18:18.6
2,0,18:18.6
3,0,18:18.6
-7,1,18:18.14
1,1,18:18.6
3,1,18:18.6
-7,2,18:18.14
-6,2,18:18.14
-9,3,18:18.14
-8,3,18:18.14
-6,3,18:18.14
0,3,18:18.14
1,3,18:18.14
3,3,18:18.14
4,3,18:18.14
5,3,18:18.14
6,3,18:18.14
-21,4,18:18.6
-20,4,18:18.14
-9,4,18:18.14
-8,4,18:18.14
-6,4,18:18.14
-5,4,18:18.14
-1,4,18:18.14
1,4,18:18.14
2,4,18:18.14
3,4,18:18.14
-20,5,18:18.14
-19,5,18:18.14
-18,5,18:18.14
-8,5,18:18.14
1,5,18:18.14
2,5,18:18.14
-18,6,18:18.14
-17,6,18:18.14
-15,6,18:18.14
-14,6,18:18.14
-8,6,18:18.14
-4,6,18:17.12
1,6,18:18.14
-16,7,18:18.14
-15,7,18:18.14
-8,7,18:18.14
-5,7,18:17.12
-4,7,18:17.12
-3,7,18:17.12
-2,7,18:17.12
0,7,18:18.14
-15,8,18:18.14
-14,8,18:18.14
-9,8,18:18.14
-8,8,18:18.14
-5,8,18:17.12
-4,8,18:17.12
-2,8,18:17.12
-1,8,18:17.12
0,8,18:17.12
1,8,18:17.12
-13,9,18:18.14
-12,9,18:18.14
-11,9,18:18.14
-10,9,18:18.14
-9,9,18:18.14
-6,9,18:18.14
-4,9,18:17.12
-3,9,18:17.12
-2,9,18:17.12
-1,9,18:17.12
1,9,18:17.12
2,9,18:17.12
-12,10,18:17.12
-11,10,18:18.14
-5,10,18:18.14
-4,10,18:17.12
-3,10,18:17.12
-2,10,18:17.12
-1,10,18:17.12
0,10,18:17.12
1,10,18:17.12
-13,11,18:18.14
-12,11,18:17.12
-5,11,18:17.12
-3,11,18:17.12
-2,11,18:17.12
-1,11,18:17.12
0,11,18:17.12
1,11,18:17.12
-15,12,18:18.14
-5,12,18:17.12
-4,12,18:17.12
-3,12,18:17.12
-2,12,18:17.12
0,12,18:17.12
1,12,18:17.12
3,12,18:18.14
-17,13,18:18.14
-16,13,18:18.14
-2,13,18:17.12
-1,13,18:17.12
0,13,18:17.12
3,13,18:18.14
0,14,18:17.12
2,14,18:18.14
3,14,18:18.14
-17,16,18:18.14
-16,16,18:18.14
-15,16,18:18.14
0,16,18:18.14
1,16,18:18.14
-19,17,18:18.14
-18,17,18:18.14
-17,17,18:18.14
-20,18,18:18.14
-8,-4,19:18.6
-2,-4,19:18.6
-9,-3,19:18.6
-8,-3,19:18.6
-3,-3,19:18.6
-2,-3,19:18.6
1,-3,19:18.6
-8,-2,19:18.6
-3,-2,19:18.6
-2,-2,19:18.6
1,-2,19:18.6
-8,-1,19:18.14
-7,-1,19:18.14
-3,-1,19:18.6
1,-1,19:18.6
-7,0,19:18.14
1,0,19:18.6
-7,1,19:18.14
-6,1,19:18.14
1,1,19:18.6
-6,2,19:18.14
0,2,19:18.14
1,2,19:18.14
2,2,19:18.14
-21,3,19:18.6
-6,3,19:18.14
-5,3,19:18.14
-1,3,19:18.14
0,3,19:18.14
2,3,19:18.14
3,3,19:18.14
-21,4,19:18.6
-20,4,19:18.14
-19,4,19:18.14
-16,4,19:18.14
-15,4,19:18.14
-14,4,19:18.14
-9,4,19:18.14
-1,4,19:18.14
2,4,19:18.14
3,4,19:18.14
4,4,19:18.14
-19,5,19:18.14
-18,5,19:18.14
-17,5,19:18.14
-16,5,19:18.14
-15,5,19:18.14
-14,5,19:18.14
-9,5,19:18.14
-4,5,19:18.14
1,5,19:18.14
2,5,19:18.14
-18,6,19:18.14
-17,6,19:18.14
-16,6,19:18.14
-15,6,19:18.14
-9,6,19:18.14
-5,6,19:17.12
-4,6,19:17.12
-3,6,19:17.12
1,6,19:18.14
-17,7,19:18.14
-16,7,19:18.14
-15,7,19:18.14
-5,7,19:17.12
-3,7,19:17.12
0,7,19:17.12
-17,8,19:18.14
-16,8,19:18.14
-15,8,19:18.14
-14,8,19:18.14
-11,8,19:18.14
-10,8,19:18.14
-9,8,19:18.14
-8,8,19:18.14
-7,8,19:18.14
-5,8,19:17.12
-4,8,19:17.12
-3,8,19:17.12
-2,8,19:17.12
-1,8,19:17.12
0,8,19:17.12
1,8,19:17.12
2,8,19:17.12
-16,9,19:18.14
-13,9,19:18.14
-12,9,19:18.14
-11,9,19:18.14
-10,9,19:18.14
-9,9,19:18.14
-7,9,19:18.14
-6,9,19:18.14
-3,9,19:17.12
-2,9,19:17.12
-1,9,19:17.12
1,9,19:17.12
2,9,19:17.12
-13,10,19:17.12
-12,10,19:17.12
-11,10,19:18.14
-5,10,19:17.12
-4,10,19:17.12
-3,10,19:17.12
-2,10,19:17.12
-1,10,19:17.12
0,10,19:17.12
1,10,19:17.12
-13,11,19:18.14
-12,11,19:17.12
-11,11,19:18.14
-5,11,19:17.12
-3,11,19:17.12
-2,11,19:17.12
-1,11,19:17.12
0,11,19:17.12
-16,12,19:18.14
-15,12,19:18.14
-11,12,19:18.14
-6,12,19:17.12
-5,12,19:17.12
-4,12,19:17.12
-3,12,19:17.12
-2,12,19:17.12
1,12,19:17.12
-17,13,19:18.14
-16,13,19:18.14
-5,13,19:17.12
-4,13,19:17.12
-2,13,19:17.12
-1,13,19:17.12
0,13,19:17.12
1,13,19:17.12
0,14,19:17.12
-16,16,19:18.6
-15,16,19:18.6
-19,17,19:18.6
-18,17,19:18.6
-17,17,19:18.6
-20,18,19:18.6
-19,18,19:18.6
-7,-5,20:18.6
-4,-5,20:18.6
-3,-5,20:18.6
-7,-4,20:18.6
-6,-4,20:18.6
-4,-4,20:18.6
-3,-4,20:18.6
-7,-3,20:18.6
-6,-3,20:18.6
-4,-3,20:18.6
-3,-3,20:18.6
1,-3,20:18.6
-7,-2,20:18.6
-6,-2,20:18.6
-4,-2,20:18.6
-3,-2,20:18.6
-7,-1,20:18.14
-6,-1,20:18.14
-4,-1,20:18.14
-3,-1,20:18.6
-15,0,20:18.14
-14,0,20:18.14
-7,0,20:18.14
-6,0,20:18.14
-5,0,20:18.14
-4,0,20:18.14
1,0,20:18.6
2,0,20:18.6
-13,1,20:18.14
-6,1,20:18.14
-5,1,20:18.14
-2,1,20:18.14
-1,1,20:18.14
0,1,20:18.14
1,1,20:18.6
2,1,20:18.6
-22,2,20:18.6
-16,2,20:18.14
-15,2,20:18.14
-14,2,20:18.14
-6,2,20:18.14
-5,2,20:18.14
-4,2,20:18.14
-3,2,20:18.14
-2,2,20:18.14
-1,2,20:18.14
0,2,20:18.14
2,2,20:18.14
3,2,20:18.14
-21,3,20:18.6
-20,3,20:18.14
-19,3,20:18.14
-18,3,20:18.14
-17,3,20:18.14
-16,3,20:18.14
-15,3,20:18.14
-14,3,20:18.14
-5,3,20:18.14
-4,3,20:18.14
-3,3,20:18.14
-2,3,20:18.14
2,3,20:18.14
3,3,20:18.14
4,3,20:18.14
-20,4,20:18.14
-19,4,20:18.14
-18,4,20:18.14
-17,4,20:18.14
-16,4,20:18.14
-15,4,20:18.14
-10,4,20:18.14
-5,4,20:18.14
-4,4,20:18.14
-3,4,20:18.14
2,4,20:18.14
4,4,20:18.14
5,4,20:18.14
-18,5,20:18.14
-16,5,20:18.14
-10,5,20:18.14
-7,5,20:17.12
-6,5,20:17.12
-5,5,20:17.12
-4,5,20:17.12
1,5,20:18.14
-19,6,20:18.14
-18,6,20:18.14
-16,6,20:18.14
-6,6,20:17.12
-4,6,20:17.12
0,6,20:18.14
1,6,20:18.14
-19,7,20:18.14
-18,7,20:18.14
-16,7,20:18.14
-11,7,20:18.14
-10,7,20:18.14
-6,7,20:17.12
-5,7,20:17.12
-4,7,20:17.12
-3,7,20:17.12
0,7,20:17.12
1,7,20:17.12
-18,8,20:18.14
-17,8,20:18.14
-15,8,20:18.14
-14,8,20:18.14
-11,8,20:18.14
-10,8,20:18.14
-9,8,20:18.14
-8,8,20:18.14
-7,8,20:18.14
-4,8,20:17.12
-3,8,20:17.12
-1,8,20:17.12
0,8,20:17.12
2,8,20:17.12
-17,9,20:18.14
-14,9,20:18.14
-13,9,20:18.14
-12,9,20:18.14
-10,9,20:18.14
-7,9,20:18.14
-6,9,20:18.14
-1,9,20:17.12
2,9,20:17.12
-13,10,20:18.14
-12,10,20:18.14
-11,10,20:18.14
-5,10,20:18.14
-1,10,20:17.12
0,10,20:17.12
1,10,20:17.12
-14,11,20:18.14
-13,11,20:18.14
-12,11,20:18.14
-11,11,20:18.14
-6,11,20:17.12
-5,11,20:17.12
-4,11,20:17.12
-3,11,20:17.12
-1,11,20:17.12
0,11,20:17.12
-16,12,20:18.14
-15,12,20:18.14
-11,12,20:18.14
-6,12,20:17.12
-4,12,20:17.12
-1,12,20:17.12
0,12,20:17.12
1,12,20:17.12
-18,13,20:18.6
-17,13,20:18.14
-11,13,20:18.14
-6,13,20:17.12
-5,13,20:17.12
-4,13,20:17.12
-1,13,20:17.12
1,13,20:17.12
-1,14,20:17.12
0,14,20:17.12
1,14,20:17.12
-16,16,20:18.6
-15,16,20:18.6
-18,17,20:18.6
-17,17,20:18.6
-19,18,20:18.6
-6,-4,21:18.6
-6,-3,21:18.6
-5,-3,21:18.6
-16,-2,21:18.6
-15,-2,21:18.6
-5,-2,21:18.6
-15,-1,21:18.14
-14,-1,21:18.14
-5,-1,21:18.14
-4,-1,21:18.14
-14,0,21:18.14
-13,0,21:18.14
-5,0,21:18.14
-4,0,21:18.14
-3,0,21:18.14
-2,0,21:18.14
-1,0,21:18.6
0,0,21:18.6
2,0,21:18.6
3,0,21:18.6
-14,1,21:18.14
-13,1,21:18.14
-12,1,21:18.14
-5,1,21:18.14
-4,1,21:18.14
-3,1,21:18.14
-2,1,21:18.14
-1,1,21:18.14
3,1,21:18.14
4,1,21:18.14
-22,2,21:18.6
-21,2,21:18.6
-19,2,21:18.14
-18,2,21:18.14
-17,2,21:18.14
-16,2,21:18.14
-15,2,21:18.14
-14,2,21:18.14
-6,2,21:18.14
-5,2,21:18.14
-3,2,21:18.14
-2,2,21:18.14
3,2,21:18.14
4,2,21:18.14
5,2,21:18.14
-21,3,21:18.6
-20,3,21:18.14
-19,3,21:18.14
-18,3,21:18.14
-16,3,21:18.14
-15,3,21:18.14
-9,3,21:17.12
-6,3,21:18.14
-5,3,21:18.14
-3,3,21:18.14
2,3,21:18.14
3,3,21:18.14
5,3,21:18.14
-19,4,21:18.14
-18,4,21:18.14
-17,4,21:18.14
-16,4,21:18.14
-9,4,21:17.12
-8,4,21:17.12
-7,4,21:17.12
-6,4,21:17.12
-5,4,21:18.14
2,4,21:18.14
5,4,21:18.14
6,4,21:18.14
-16,5,21:18.14
-8,5,21:17.12
-7,5,21:17.12
-6,5,21:17.12
-5,5,21:17.12
1,5,21:18.14
-20,6,21:18.14
-16,6,21:18.14
-14,6,21:18.14
-7,6,21:17.12
-6,6,21:17.12
-5,6,21:17.12
-4,6,21:17.12
0,6,21:18.14
1,6,21:18.14
-20,7,21:18.14
-19,7,21:18.14
-16,7,21:18.14
-15,7,21:18.14
-14,7,21:18.14
-8,7,21:18.14
-7,7,21:18.14
-5,7,21:17.12
-4,7,21:17.12
0,7,21:17.12
1,7,21:17.12
2,7,21:17.12
-19,8,21:18.14
-18,8,21:18.14
-15,8,21:18.14
-14,8,21:18.14
-10,8,21:18.14
-9,8,21:18.14
-8,8,21:18.14
-7,8,21:18.14
-1,8,21:17.12
0,8,21:17.12
2,8,21:17.12
-19,9,21:18.14
-18,9,21:18.14
-14,9,21:18.14
-13,9,21:18.14
-12,9,21:18.14
-11,9,21:18.14
-10,9,21:18.14
-7,9,21:18.14
-6,9,21:18.14
-1,9,21:17.12
0,9,21:17.12
1,9,21:17.12
2,9,21:17.12
-18,10,21:18.14
-17,10,21:18.14
-14,10,21:18.14
-12,10,21:18.14
-5,10,21:18.14
-15,11,21:18.14
-14,11,21:18.14
-13,11,21:18.14
-12,11,21:18.14
-11,11,21:18.14
-6,11,21:17.12
-5,11,21:17.12
-4,11,21:17.12
-1,11,21:17.12
-17,12,21:18.14
-16,12,21:18.14
-15,12,21:18.14
-12,12,21:18.14
-11,12,21:18.14
-6,12,21:17.12
-5,12,21:18.14
-4,12,21:17.12
-1,12,21:17.12
0,12,21:17.12
1,12,21:17.12
-18,13,21:18.6
-17,13,21:18.14
-11,13,21:18.14
-6,13,21:17.12
-5,13,21:17.12
-4,13,21:17.12
-1,13,21:17.12
1,13,21:17.12
-11,14,21:18.14
-1,14,21:17.12
0,14,21:17.12
1,14,21:17.12
1,15,21:17.12
-17,17,21:18.6
-16,-3,22:18.6
-5,-3,22:18.6
-16,-2,22:18.6
-15,-2,22:18.6
-5,-2,22:18.6
-14,-1,22:18.14
-13,-1,22:18.14
-5,-1,22:18.14
-1,-1,22:18.6
0,-1,22:18.6
3,-1,22:18.6
-14,0,22:18.14
-13,0,22:18.14
-12,0,22:18.14
-5,0,22:18.14
-2,0,22:18.14
-1,0,22:18.6
3,0,22:18.6
4,0,22:18.6
-15,1,22:18.14
-14,1,22:18.14
-12,1,22:18.14
-11,1,22:18.14
-7,1,22:18.14
-6,1,22:18.14
-3,1,22:18.14
-2,1,22:18.14
4,1,22:18.14
5,1,22:18.14
-21,2,22:18.6
-20,2,22:18.6
-16,2,22:18.14
-15,2,22:18.14
-10,2,22:18.14
-9,2,22:18.14
-6,2,22:18.14
-3,2,22:18.14
5,2,22:18.14
6,2,22:18.14
-19,3,22:18.14
-18,3,22:18.14
-17,3,22:18.14
-16,3,22:18.14
-11,3,22:17.12
-10,3,22:17.12
-9,3,22:17.12
-8,3,22:18.14
-7,3,22:18.14
-6,3,22:18.14
-17,4,22:18.14
-10,4,22:17.12
-9,4,22:17.12
-8,4,22:17.12
-7,4,22:17.12
-6,4,22:18.14
-16,5,22:18.14
-8,5,22:17.12
-7,5,22:17.12
-6,5,22:17.12
1,5,22:18.14
-16,6,22:18.14
-15,6,22:18.14
-7,6,22:17.12
-6,6,22:17.12
1,6,22:17.12
-20,7,22:18.6
-16,7,22:18.14
-15,7,22:18.14
-9,7,22:18.14
-8,7,22:18.14
0,7,22:17.12
1,7,22:17.12
2,7,22:17.12
3,7,22:17.12
-20,8,22:18.6
-15,8,22:18.14
-14,8,22:18.14
-10,8,22:18.14
-9,8,22:18.14
-8,8,22:18.14
-7,8,22:18.14
0,8,22:17.12
2,8,22:17.12
3,8,22:17.12
-19,9,22:18.6
-15,9,22:18.14
-14,9,22:18.14
-13,9,22:18.14
-12,9,22:18.14
-11,9,22:18.14
-7,9,22:18.14
-6,9,22:18.14
-1,9,22:17.12
0,9,22:17.12
1,9,22:17.12
2,9,22:17.12
-15,10,22:18.14
-14,10,22:18.14
-12,10,22:18.14
-5,10,22:18.14
-15,11,22:18.14
-14,11,22:18.14
-13,11,22:18.14
-12,11,22:18.14
-6,11,22:17.12
-5,11,22:17.12
-17,12,22:18.14
-16,12,22:18.14
-13,12,22:18.14
-12,12,22:18.14
-11,12,22:18.14
-6,12,22:17.12
-5,12,22:18.14
-4,12,22:17.12
0,12,22:17.12
1,12,22:17.12
-18,13,22:18.6
-12,13,22:18.14
-7,13,22:18.14
-6,13,22:17.12
-5,13,22:17.12
-4,13,22:17.12
0,13,22:17.12
1,13,22:17.12
2,13,22:17.12
-12,14,22:18.14
-11,14,22:18.14
0,14,22:17.12
1,14,22:17.12
2,14,22:17.12
1,15,22:17.12
2,15,22:17.12
-5,-5,23:18.6
-5,-4,23:18.6
-16,-3,23:18.6
-15,-3,23:18.6
-5,-3,23:18.6
-15,-2,23:18.6
-14,-2,23:18.6
-5,-2,23:18.6
-14,-1,23:18.14
-13,-1,23:18.14
-12,-1,23:18.14
-5,-1,23:18.14
-15,0,23:18.14
-14,0,23:18.14
-12,0,23:18.14
-11,0,23:18.14
-21,1,23:18.6
-20,1,23:18.6
-16,1,23:18.14
-15,1,23:18.14
-9,1,23:18.14
-7,1,23:18.14
-20,2,23:18.6
-19,2,23:18.14
-18,2,23:18.14
-16,2,23:18.14
-9,2,23:18.14
-8,2,23:18.14
-7,2,23:18.14
-18,3,23:18.14
-17,3,23:18.14
-12,3,23:17.12
-11,3,23:17.12
-8,3,23:18.14
-7,3,23:18.14
-17,4,23:18.14
-11,4,23:17.12
-9,4,23:17.12
-8,4,23:17.12
-7,4,23:18.14
-6,4,23:18.14
-17,5,23:18.14
-9,5,23:17.12
-8,5,23:17.12
-7,5,23:18.14
-6,5,23:18.14
-16,6,23:18.14
-8,6,23:18.14
1,6,23:17.12
2,6,23:17.12
3,6,23:17.12
-16,7,23:18.14
-15,7,23:18.14
-9,7,23:18.14
-8,7,23:18.14
0,7,23:17.12
1,7,23:17.12
3,7,23:17.12
-15,8,23:18.14
-14,8,23:18.14
-11,8,23:18.14
-10,8,23:18.14
-8,8,23:18.14
0,8,23:17.12
1,8,23:17.12
2,8,23:17.12
3,8,23:17.12
-15,9,23:18.14
-13,9,23:18.14
-7,9,23:18.14
-6,9,23:18.14
1,9,23:17.12
2,9,23:17.12
-15,10,23:18.14
-16,11,23:18.14
-15,11,23:18.14
-14,11,23:18.14
-12,11,23:18.14
-5,11,23:17.12
-18,12,23:18.6
-17,12,23:18.14
-16,12,23:18.14
-13,12,23:18.14
-12,12,23:18.14
-6,12,23:17.12
-5,12,23:17.12
-4,12,23:18.14
-3,12,23:18.14
-2,12,23:18.14
-1,12,23:18.14
-12,13,23:18.14
-11,13,23:18.14
-10,13,23:18.14
-7,13,23:18.14
-6,13,23:17.12
-5,13,23:17.12
-4,13,23:17.12
0,13,23:17.12
1,13,23:17.12
2,13,23:17.12
-12,14,23:18.14
0,14,23:17.12
1,14,23:17.12
2,14,23:17.12
-9,15,23:18.14
0,15,23:17.12
1,15,23:17.12
2,15,23:17.12
-10,16,23:18.14
2,16,23:17.12
-11,17,23:18.14
-11,18,23:18.6
-7,-5,24:18.6
-6,-5,24:18.6
-15,-4,24:18.6
-7,-4,24:18.6
-6,-4,24:18.6
-5,-4,24:18.6
-15,-3,24:18.6
-14,-3,24:18.6
-8,-3,24:18.6
-7,-3,24:18.6
-5,-3,24:18.6
-14,-2,24:18.14
-13,-2,24:18.14
-12,-2,24:18.14
-9,-2,24:18.14
-8,-2,24:18.14
-7,-2,24:18.14
-5,-2,24:18.14
-12,-1,24:18.14
-11,-1,24:18.14
-9,-1,24:18.14
-8,-1,24:18.14
-5,-1,24:18.14
-16,0,24:18.14
-11,0,24:18.14
-10,0,24:18.14
-9,0,24:18.14
-8,0,24:18.14
-20,1,24:18.6
-17,1,24:18.14
-16,1,24:18.14
-10,1,24:18.14
-9,1,24:18.14
-19,2,24:18.14
-13,3,24:17.12
-12,3,24:17.12
-8,3,24:17.12
-7,3,24:18.14
-17,4,24:18.14
-11,4,24:18.14
-9,4,24:17.12
-8,4,24:17.12
-17,5,24:18.14
-8,5,24:18.14
-17,6,24:18.14
-16,6,24:18.14
2,6,24:17.12
3,6,24:17.12
4,6,24:17.12
-16,7,24:18.14
-10,7,24:18.14
-9,7,24:18.14
1,7,24:17.12
2,7,24:18.14
3,7,24:17.12
4,7,24:17.12
-16,8,24:18.6
-15,8,24:18.14
-14,8,24:18.14
-11,8,24:18.14
-10,8,24:18.14
0,8,24:17.12
1,8,24:17.12
2,8,24:17.12
3,8,24:17.12
-16,9,24:18.6
-10,10,24:18.14
-12,11,24:18.6
-10,11,24:18.14
-9,11,24:18.14
-14,12,24:18.6
-13,12,24:18.6
-12,12,24:18.6
-9,12,24:18.14
-6,12,24:17.12
-5,12,24:17.12
-4,12,24:17.12
-2,12,24:18.14
-12,13,24:18.6
-11,13,24:18.14
-9,13,24:18.14
-8,13,24:18.14
-7,13,24:18.14
-6,13,24:17.12
-5,13,24:17.12
-4,13,24:18.14
-1,13,24:18.14
0,13,24:18.14
1,13,24:18.14
-9,14,24:18.14
-5,14,24:18.14
1,14,24:17.12
2,14,24:17.12
3,14,24:17.12
-10,15,24:18.14
-9,15,24:18.14
1,15,24:17.12
2,15,24:17.12
3,15,24:17.12
-11,16,24:18.14
-10,16,24:18.14
2,16,24:17.12
3,16,24:17.12
-11,17,24:18.14
-12,18,24:18.6
-8,-6,25:18.6
-7,-6,25:18.6
-9,-5,25:18.6
-8,-5,25:18.6
-7,-5,25:18.6
-15,-4,25:18.6
-14,-4,25:18.6
-10,-4,25:18.14
-8,-4,25:18.14
-14,-3,25:18.14
-13,-3,25:18.14
-10,-3,25:18.14
-9,-3,25:18.14
-8,-3,25:18.14
-5,-3,25:18.14
-13,-2,25:18.14
-12,-2,25:18.14
-11,-2,25:18.14
-10,-2,25:18.14
-9,-2,25:18.14
-5,-2,25:18.14
-11,-1,25:18.14
-10,-1,25:18.14
-17,0,25:18.14
-10,1,25:18.14
-10,2,25:18.14
-9,2,25:18.14
-15,3,25:17.12
-14,3,25:17.12
-9,3,25:17.12
-17,4,25:18.14
-15,4,25:18.14
-14,4,25:18.14
-12,4,25:18.14
-11,4,25:18.14
-10,4,25:17.12
-9,4,25:17.12
-8,4,25:18.14
-17,5,25:18.14
-8,5,25:18.14
3,5,25:17.12
-17,6,25:18.14
-8,6,25:18.14
2,6,25:17.12
3,6,25:17.12
4,6,25:17.12
-16,7,25:18.14
-10,7,25:18.14
1,7,25:17.12
2,7,25:17.12
3,7,25:18.14
4,7,25:17.12
-16,8,25:18.6
-12,8,25:18.14
-11,8,25:18.14
2,8,25:17.12
3,8,25:17.12
-12,9,25:18.14
-11,9,25:18.14
-11,10,25:18.14
-10,10,25:18.14
-12,11,25:18.6
-10,11,25:18.14
-4,11,25:18.14
-14,12,25:18.6
-13,12,25:18.6
-12,12,25:18.6
-10,12,25:18.14
-9,12,25:18.14
-6,12,25:17.12
-5,12,25:17.12
-4,12,25:18.14
-12,13,25:18.6
-9,13,25:18.14
-6,13,25:17.12
-5,13,25:17.12
-4,13,25:18.14
-3,13,25:18.14
-2,13,25:18.14
-1,13,25:18.14
0,13,25:18.14
1,13,25:18.14
-10,14,25:18.14
-5,14,25:18.14
-4,14,25:18.14
2,14,25:17.12
3,14,25:17.12
-11,15,25:18.14
-10,15,25:18.14
-5,15,25:18.14
1,15,25:17.12
2,15,25:18.14
3,15,25:17.12
-11,16,25:18.14
2,16,25:17.12
-12,17,25:18.6
-13,18,25:18.6
-12,18,25:18.6
-10,-6,26:18.14
-9,-6,26:18.14
-11,-5,26:18.14
-10,-5,26:18.14
-9,-5,26:18.14
-11,-4,26:18.14
-10,-4,26:18.14
-12,-2,26:18.14
-11,-1,26:18.14
-11,0,26:18.14
-10,1,26:18.14
-10,2,26:18.14
-8,2,26:18.14
-7,2,26:18.14
-18,3,26:18.14
-9,3,26:18.14
-8,3,26:18.14
-18,4,26:18.14
-17,4,26:18.14
-15,4,26:18.14
-14,4,26:18.14
-13,4,26:18.14
-12,4,26:18.14
-11,4,26:18.14
-10,4,26:17.12
-9,4,26:18.14
-17,5,26:18.14
3,5,26:17.12
-17,6,26:18.14
-8,6,26:18.14
2,6,26:17.12
3,6,26:18.14
4,6,26:17.12
-17,7,26:18.14
-8,7,26:18.14
-7,7,26:18.14
2,7,26:17.12
3,7,26:17.12
4,7,26:17.12
-13,8,26:18.14
-7,8,26:18.14
-13,9,26:18.14
-12,9,26:18.14
-12,10,26:18.6
-11,10,26:18.14
-4,10,26:18.14
-11,11,26:18.14
-4,11,26:18.14
-11,12,26:18.14
-10,12,26:18.14
-6,12,26:17.12
-5,12,26:17.12
-3,12,26:18.14
-9,13,26:18.14
-8,13,26:18.14
-7,13,26:17.12
-6,13,26:17.12
-5,13,26:17.12
-3,13,26:18.14
-2,13,26:18.14
-1,13,26:18.14
0,13,26:18.14
1,13,26:18.14
-11,14,26:18.14
-10,14,26:18.14
-6,14,26:17.12
-4,14,26:18.14
-3,14,26:18.14
2,14,26:17.12
3,14,26:17.12
-11,15,26:18.14
-5,15,26:18.14
-4,15,26:18.14
1,15,26:17.12
2,15,26:18.14
3,15,26:17.12
-12,16,26:18.6
-5,16,26:18.14
2,16,26:17.12
-13,17,26:18.6
-12,17,26:18.6
-13,18,26:18.6
-11,-6,27:18.14
-11,-5,27:18.14
-12,-1,27:18.14
-11,-1,27:18.14
-11,0,27:18.14
-11,1,27:18.14
-7,1,27:18.14
-10,2,27:18.14
-8,2,27:18.14
-10,3,27:17.12
-9,3,27:17.12
-8,3,27:18.14
4,3,27:18.14
-15,4,27:18.14
-14,4,27:18.14
-13,4,27:18.14
-12,4,27:18.14
-11,4,27:18.14
-10,4,27:17.12
-9,4,27:17.12
4,4,27:18.14
-9,5,27:18.14
2,5,27:17.12
3,5,27:17.12
-9,6,27:18.14
-8,6,27:18.14
2,6,27:17.12
3,6,27:18.14
4,6,27:18.14
-8,7,27:18.14
2,7,27:17.12
3,7,27:17.12
5,7,27:18.14
6,7,27:18.14
7,7,27:18.14
8,7,27:18.14
-14,8,27:18.14
-7,8,27:18.14
8,8,27:18.14
9,8,27:18.6
10,8,27:18.6
-14,9,27:18.6
-13,9,27:18.14
-7,9,27:18.14
-4,9,27:18.14
-13,10,27:18.6
-12,10,27:18.6
-6,10,27:18.14
-4,10,27:18.14
-12,11,27:18.6
-4,11,27:18.14
-3,11,27:18.14
-12,12,27:18.6
-11,12,27:18.14
-7,12,27:17.12
-6,12,27:17.12
-3,12,27:18.14
-11,13,27:18.14
-10,13,27:18.14
-9,13,27:18.14
-8,13,27:18.14
-7,13,27:17.12
-6,13,27:17.12
-2,13,27:18.14
-1,13,27:18.14
0,13,27:18.14
1,13,27:18.14
-11,14,27:18.14
-6,14,27:17.12
-3,14,27:18.14
2,14,27:17.12
3,14,27:18.14
4,14,27:18.14
5,14,27:18.14
-12,15,27:18.6
-11,15,27:18.14
-4,15,27:18.14
1,15,27:17.12
2,15,27:18.14
3,15,27:17.12
-13,16,27:18.6
-12,16,27:18.6
-5,16,27:18.14
-4,16,27:18.14
2,16,27:17.12
-13,17,27:18.6
-13,-3,28:18.14
-13,-2,28:18.14
-12,-2,28:18.14
-12,-1,28:18.14
4,-1,28:18.6
-12,0,28:18.14
-7,0,28:18.14
4,0,28:18.14
-11,1,28:18.14
-7,1,28:18.14
4,1,28:18.14
-11,2,28:18.14
-10,2,28:17.12
-9,2,28:17.12
-8,2,28:18.14
4,2,28:18.14
-11,3,28:17.12
-10,3,28:17.12
-9,3,28:18.14
-8,3,28:18.14
4,3,28:18.14
-16,4,28:18.14
-15,4,28:18.14
-14,4,28:18.14
-13,4,28:18.14
-12,4,28:18.14
-11,4,28:18.14
-10,4,28:17.12
-9,4,28:18.14
4,4,28:18.14
-9,5,28:18.14
2,5,28:17.12
3,5,28:17.12
4,5,28:18.14
-9,6,28:18.14
2,6,28:17.12
3,6,28:17.12
4,6,28:18.14
-8,7,28:18.14
3,7,28:17.12
7,7,28:18.14
8,7,28:18.14
9,7,28:18.6
-8,8,28:18.14
-7,8,28:18.14
9,8,28:18.6
10,8,28:18.6
-14,9,28:18.6
-7,9,28:18.14
-4,9,28:18.14
-14,10,28:18.6
-13,10,28:18.6
-6,10,28:18.14
-4,10,28:18.14
-13,11,28:18.6
-3,11,28:18.14
-13,12,28:18.6
-12,12,28:18.14
-7,12,28:17.12
-6,12,28:17.12
-3,12,28:18.14
1,12,28:18.14
-11,13,28:18.14
-10,13,28:18.14
-9,13,28:18.14
-8,13,28:18.14
-7,13,28:17.12
-6,13,28:17.12
-1,13,28:18.14
0,13,28:18.14
2,13,28:18.14
6,13,28:18.14
7,13,28:18.14
8,13,28:18.6
-11,14,28:18.14
-7,14,28:17.12
-6,14,28:17.12
-3,14,28:18.14
2,14,28:17.12
3,14,28:18.14
4,14,28:18.14
5,14,28:18.14
-13,15,28:18.6
-12,15,28:18.14
-4,15,28:18.14
-3,15,28:18.14
1,15,28:17.12
2,15,28:18.14
3,15,28:17.12
-14,16,28:18.6
-13,16,28:18.6
-4,16,28:18.14
2,16,28:17.12
-13,-3,29:18.14
-13,-2,29:18.14
-13,-1,29:18.14
-12,-1,29:18.14
-6,-1,29:18.14
5,-1,29:18.6
-12,0,29:18.14
-9,0,29:17.12
-7,0,29:18.14
-6,0,29:18.14
5,0,29:18.14
-12,1,29:18.14
-10,1,29:17.12
-9,1,29:17.12
-8,1,29:18.14
-7,1,29:18.14
5,1,29:18.14
-11,2,29:18.14
-10,2,29:17.12
-9,2,29:17.12
-8,2,29:18.14
4,2,29:18.14
5,2,29:18.14
-12,3,29:17.12
-11,3,29:17.12
-9,3,29:18.14
4,3,29:18.14
5,3,29:18.14
-15,4,29:18.14
-14,4,29:18.14
-13,4,29:18.14
-12,4,29:18.14
-11,4,29:18.14
-10,4,29:18.14
4,4,29:18.14
-10,5,29:18.14
-9,5,29:18.14
2,5,29:17.12
3,5,29:17.12
4,5,29:18.14
5,5,29:18.14
-9,6,29:18.14
2,6,29:17.12
3,6,29:17.12
5,6,29:18.14
6,6,29:18.14
7,6,29:18.14
8,6,29:18.14
-9,7,29:18.14
-8,7,29:18.14
2,7,29:18.14
8,7,29:18.14
9,7,29:18.6
10,7,29:18.6
-8,8,29:18.14
-8,9,29:18.14
-7,9,29:18.14
-3,10,29:18.14
0,10,29:18.14
-14,11,29:18.6
-3,11,29:18.14
1,11,29:18.14
-14,12,29:18.6
-13,12,29:18.14
-7,12,29:17.12
-3,12,29:18.14
-2,12,29:18.14
1,12,29:18.14
2,12,29:18.14
-9,13,29:18.14
-8,13,29:18.14
-7,13,29:17.12
-6,13,29:17.12
-4,13,29:18.14
2,13,29:18.14
4,13,29:18.14
5,13,29:18.14
6,13,29:18.14
7,13,29:18.14
-11,14,29:18.14
-10,14,29:18.14
-7,14,29:17.12
-6,14,29:17.12
2,14,29:17.12
3,14,29:18.14
4,14,29:18.14
-13,15,29:18.14
-3,15,29:18.14
2,15,29:17.12
3,15,29:17.12
-14,16,29:18.6
2,16,29:18.14
3,16,29:18.14
4,16,29:18.14
6,16,29:18.14
7,16,29:18.14
-13,-2,30:18.14
-9,-2,30:17.12
5,-2,30:18.6
-13,-1,30:18.14
-9,-1,30:17.12
5,-1,30:18.6
-13,0,30:18.14
-12,0,30:18.14
-9,0,30:17.12
-7,0,30:18.14
5,0,30:18.14
-12,1,30:18.14
-9,1,30:17.12
-8,1,30:18.14
5,1,30:18.14
-12,2,30:18.14
-11,2,30:18.14
-9,2,30:18.14
-8,2,30:18.14
5,2,30:18.14
-12,3,30:17.12
-11,3,30:18.14
-9,3,30:18.14
5,3,30:18.14
-14,4,30:18.14
-13,4,30:18.14
-12,4,30:18.14
3,4,30:17.12
5,4,30:18.14
-10,5,30:18.14
2,5,30:17.12
3,5,30:17.12
4,5,30:17.12
5,5,30:18.14
6,5,30:18.14
7,5,30:18.14
-10,6,30:18.14
-9,6,30:18.14
2,6,30:17.12
3,6,30:18.14
7,6,30:18.14
8,6,30:18.14
9,6,30:18.6
-9,7,30:18.14
2,7,30:18.14
9,7,30:18.6
10,7,30:18.6
11,7,30:18.6
-8,8,30:18.14
-8,9,30:18.14
0,9,30:18.14
-7,10,30:18.14
0,10,30:18.14
1,10,30:18.14
1,11,30:18.14
-7,12,30:17.12
2,12,30:18.14
-8,13,30:18.14
-7,13,30:17.12
-6,13,30:17.12
2,13,30:18.14
3,13,30:18.14
4,13,30:18.14
5,13,30:18.14
6,13,30:18.14
7,13,30:18.14
8,13,30:18.6
-11,14,30:18.14
-10,14,30:18.14
-9,14,30:18.14
-8,14,30:18.14
-7,14,30:17.12
-6,14,30:17.12
3,14,30:18.14
2,15,30:17.12
3,15,30:17.12
2,16,30:17.12
3,16,30:17.12
5,16,30:18.14
6,16,30:18.14
1,17,30:18.14
3,17,30:18.14
6,17,30:18.14
7,17,30:18.14
8,17,30:18.6
2,18,30:18.14
2,19,30:18.14
1,20,30:18.14
1,21,30:18.6
-9,-3,31:17.12
-9,-2,31:17.12
-7,-1,31:18.14
-8,0,31:18.14
-7,0,31:18.14
5,0,31:18.14
6,0,31:18.14
-12,1,31:18.14
-8,1,31:18.14
5,1,31:18.14
6,1,31:18.14
-12,2,31:17.12
-9,2,31:18.14
5,2,31:18.14
6,2,31:18.14
-12,3,31:17.12
-9,3,31:18.14
5,3,31:18.14
-14,4,31:18.14
-13,4,31:18.14
3,4,31:17.12
5,4,31:18.14
2,5,31:17.12
3,5,31:17.12
4,5,31:17.12
5,5,31:18.14
6,5,31:18.14
7,5,31:18.14
8,5,31:18.14
-10,6,31:18.14
3,6,31:18.14
4,6,31:18.14
8,6,31:18.14
9,6,31:18.6
10,6,31:18.6
11,6,31:18.6
-9,7,31:18.14
2,7,31:18.14
11,7,31:18.6
-9,8,31:18.14
-8,9,31:18.14
0,9,31:18.14
1,9,31:18.14
1,10,31:18.14
2,11,31:18.14
-7,12,31:17.12
2,12,31:18.14
8,12,31:18.14
-7,13,31:17.12
-6,13,31:17.12
3,13,31:18.14
4,13,31:18.14
5,13,31:18.14
6,13,31:18.14
7,13,31:18.14
-10,14,31:18.14
-9,14,31:18.14
-8,14,31:18.14
-7,14,31:17.12
-6,14,31:17.12
3,14,31:18.14
-11,15,31:18.14
2,15,31:17.12
3,15,31:17.12
-13,16,31:18.14
-12,16,31:18.14
2,16,31:18.14
3,16,31:18.14
1,17,31:18.14
3,17,31:18.14
4,17,31:18.14
5,17,31:18.14
6,17,31:18.14
7,17,31:18.14
8,17,31:18.14
1,18,31:18.14
3,18,31:18.14
8,18,31:18.14
2,19,31:18.14
2,20,31:18.14
1,21,31:18.6
1,22,31:18.6
-8,-3,32:17.12
-8,0,32:18.14
6,0,32:18.14
-9,1,32:18.14
-8,1,32:18.14
6,1,32:18.14
-12,2,32:17.12
-9,2,32:18.14
6,2,32:18.14
-12,3,32:17.12
-13,4,32:18.14
3,4,32:17.12
4,4,32:17.12
6,4,32:18.14
7,4,32:18.14
2,5,32:17.12
3,5,32:17.12
4,5,32:18.14
5,5,32:18.14
7,5,32:18.14
8,5,32:18.14
9,5,32:18.14
10,5,32:18.6
-10,6,32:18.14
3,6,32:18.14
4,6,32:18.14
10,6,32:18.6
11,6,32:18.6
-10,7,32:18.14
-9,7,32:18.14
1,7,32:18.14
2,7,32:18.14
-9,8,32:18.14
1,8,32:18.14
1,9,32:18.14
1,10,32:18.14
2,10,32:18.14
2,11,32:18.14
-7,12,32:18.14
-6,12,32:17.12
6,12,32:18.14
-8,13,32:17.12
-7,13,32:17.12
-6,13,32:17.12
4,13,32:18.14
5,13,32:18.14
6,13,32:18.14
-9,14,32:18.14
-8,14,32:18.14
-7,14,32:17.12
3,14,32:18.14
-11,15,32:18.14
-10,15,32:18.14
2,15,32:17.12
3,15,32:17.12
-13,16,32:18.14
-12,16,32:18.14
2,16,32:18.14
3,16,32:18.14
-14,17,32:18.14
1,17,32:18.14
3,17,32:18.14
3,18,32:18.14
4,18,32:18.14
5,18,32:18.14
6,18,32:18.14
7,18,32:18.14
8,18,32:18.14
9,18,32:18.6
3,19,32:18.14
2,20,32:18.14
3,20,32:18.14
2,21,32:18.14
1,22,32:18.6
2,22,32:18.6
6,0,33:18.14
6,1,33:18.14
-10,2,33:18.14
-9,2,33:18.14
6,2,33:18.14
3,4,33:17.12
4,4,33:17.12
8,4,33:18.14
2,5,33:17.12
3,5,33:17.12
4,5,33:18.14
8,5,33:18.14
9,5,33:18.14
10,5,33:18.6
2,6,33:18.14
3,6,33:18.14
1,7,33:18.14
2,7,33:18.14
0,8,33:18.14
1,8,33:18.14
-9,9,33:18.14
-8,10,33:18.14
2,10,33:18.14
-8,11,33:18.14
-7,11,33:18.14
-4,11,33:18.14
2,11,33:18.14
3,11,33:18.14
-7,12,33:18.14
-6,12,33:17.12
-5,12,33:18.14
-4,12,33:18.14
6,12,33:18.14
-8,13,33:17.12
-7,13,33:17.12
-6,13,33:17.12
-9,14,33:17.12
-8,14,33:17.12
-7,14,33:17.12
2,14,33:17.12
3,14,33:18.14
-10,15,33:18.14
-9,15,33:18.14
-8,15,33:17.12
2,15,33:17.12
3,15,33:18.14
-13,16,33:18.14
-12,16,33:18.14
-11,16,33:18.14
2,16,33:18.14
3,16,33:18.14
-14,17,33:18.14
-13,17,33:18.14
1,17,33:18.14
2,17,33:18.14
3,17,33:18.14
4,18,33:18.14
5,18,33:18.14
6,18,33:18.14
7,18,33:18.14
8,18,33:18.14
3,19,33:18.14
6,19,33:18.14
7,19,33:18.14
8,19,33:18.14
3,20,33:18.14
2,21,33:18.14
3,21,33:18.14
2,22,33:18.6
7,1,34:18.14
6,2,34:18.14
5,3,34:18.14
3,4,34:17.12
4,4,34:18.14
2,5,34:17.12
3,5,34:17.12
4,5,34:18.14
5,5,34:18.14
2,6,34:18.14
3,6,34:18.14
1,7,34:18.14
2,7,34:18.14
-9,9,34:18.14
-8,9,34:18.14
-8,10,34:18.14
-7,10,34:18.14
-2,10,34:18.14
-7,11,34:18.14
-6,11,34:18.14
-5,11,34:18.14
-4,11,34:18.14
-3,11,34:18.14
-2,11,34:18.14
-6,12,34:17.12
-5,12,34:18.14
-6,13,34:17.12
-10,14,34:18.14
-9,14,34:17.12
-8,14,34:17.12
2,14,34:18.14
3,14,34:18.14
-10,15,34:18.14
-9,15,34:17.12
-8,15,34:17.12
2,15,34:17.12
3,15,34:17.12
-13,16,34:18.14
-12,16,34:18.14
-11,16,34:18.14
-9,16,34:18.14
-8,16,34:18.14
2,16,34:17.12
3,16,34:17.12
-14,17,34:18.14
-13,17,34:18.14
-9,17,34:18.14
3,17,34:18.14
5,19,34:18.14
6,19,34:18.14
7,19,34:18.14
3,20,34:18.14
3,21,34:18.14
7,1,35:18.14
1,2,35:18.14
6,2,35:18.14
7,2,35:18.14
2,3,35:18.14
3,3,35:18.14
5,3,35:18.14
3,4,35:17.12
4,4,35:17.12
5,4,35:18.14
2,5,35:17.12
3,5,35:17.12
4,5,35:18.14
5,5,35:18.14
2,6,35:18.14
3,6,35:18.14
1,7,35:18.14
2,7,35:18.14
-9,8,35:18.14
-8,9,35:18.14
-7,10,35:18.14
-3,10,35:18.14
-2,10,35:18.14
-6,11,35:18.14
-5,11,35:18.14
-4,11,35:18.14
-3,11,35:18.14
-6,12,35:17.12
-5,12,35:17.12
-10,13,35:18.14
-6,13,35:18.14
-10,14,35:18.14
-9,14,35:17.12
-7,14,35:18.14
2,14,35:18.14
3,14,35:18.14
-11,15,35:18.14
-9,15,35:17.12
-8,15,35:17.12
2,15,35:17.12
3,15,35:17.12
-12,16,35:18.14
-11,16,35:18.14
-10,16,35:18.14
2,16,35:18.14
3,16,35:17.12
4,16,35:17.12
-14,17,35:18.14
-13,17,35:18.14
-11,17,35:18.14
-10,17,35:18.14
-9,17,35:18.14
3,17,35:18.14
-9,18,35:18.14
-8,18,35:18.14
3,18,35:18.14
4,18,35:18.14
-8,19,35:18.14
0,1,36:18.14
6,1,36:18.14
7,1,36:18.14
1,2,36:18.14
2,2,36:18.14
5,2,36:18.14
6,2,36:18.14
2,3,36:18.14
3,3,36:18.14
4,3,36:18.14
5,3,36:18.14
2,4,36:17.12
3,4,36:17.12
4,4,36:17.12
5,4,36:17.12
2,5,36:17.12
3,5,36:17.12
4,5,36:18.14
4,6,36:18.14
-8,8,36:18.14
-8,9,36:18.14
-7,9,36:18.14
-7,10,36:18.14
-6,10,36:18.14
-4,10,36:18.14
-3,10,36:18.14
-2,10,36:18.14
-6,11,36:18.14
-5,11,36:18.14
5,11,36:18.14
-6,12,36:17.12
-5,12,36:17.12
4,12,36:18.14
-11,13,36:18.14
-10,13,36:18.14
-7,13,36:18.14
-6,13,36:18.14
3,13,36:18.14
4,13,36:18.14
-11,14,36:18.14
-7,14,36:18.14
2,14,36:18.14
3,14,36:18.14
-12,15,36:18.14
-11,15,36:18.14
-10,15,36:17.12
-9,15,36:17.12
2,15,36:17.12
3,15,36:17.12
-10,16,36:17.12
-9,16,36:18.14
2,16,36:18.14
3,16,36:18.14
4,16,36:17.12
-11,17,36:18.14
3,17,36:18.14
4,17,36:17.12
-11,18,36:18.14
-10,18,36:18.14
-9,18,36:18.14
3,18,36:18.14
4,18,36:18.14
-10,19,36:18.14
-9,19,36:18.14
7,0,37:18.14
0,1,37:18.14
1,1,37:18.14
6,1,37:18.14
7,1,37:18.14
1,2,37:18.14
2,2,37:18.14
5,2,37:18.14
6,2,37:18.14
3,3,37:18.14
4,3,37:18.14
5,3,37:17.12
2,4,37:17.12
3,4,37:17.12
4,4,37:17.12
5,4,37:17.12
2,5,37:17.12
3,5,37:17.12
4,5,37:18.14
4,6,37:18.14
4,7,37:18.14
-7,9,37:18.14
-2,9,37:18.14
-6,10,37:18.14
-4,10,37:18.14
-3,10,37:18.14
5,10,37:18.14
-6,11,37:17.12
-5,11,37:18.14
-4,11,37:18.14
5,11,37:18.14
-11,12,37:18.14
-6,12,37:17.12
-5,12,37:17.12
4,12,37:18.14
-12,13,37:18.14
-11,13,37:18.14
-6,13,37:18.14
3,13,37:18.14
-12,14,37:18.14
-7,14,37:18.14
0,14,37:18.14
1,14,37:18.14
2,14,37:18.14
-13,15,37:18.14
-12,15,37:18.14
-10,15,37:17.12
-9,15,37:17.12
2,15,37:17.12
3,15,37:17.12
-13,16,37:18.14
-11,16,37:17.12
-10,16,37:17.12
3,16,37:18.14
4,16,37:18.14
-10,17,37:18.14
4,17,37:17.12
5,17,37:17.12
-12,18,37:18.14
-10,18,37:18.14
-11,19,37:18.14
-10,19,37:18.14
-11,20,37:18.14
-10,20,37:18.14
-11,21,37:18.14
7,0,38:18.14
0,1,38:18.14
1,1,38:18.14
6,1,38:18.14
7,1,38:18.14
2,2,38:18.14
3,2,38:18.14
4,2,38:18.14
5,2,38:18.14
4,3,38:18.14
5,3,38:17.12
6,3,38:17.12
2,4,38:17.12
4,4,38:18.14
5,4,38:17.12
6,4,38:17.12
1,5,38:17.12
2,5,38:17.12
4,5,38:18.14
4,6,38:18.14
4,7,38:18.14
-1,8,38:18.14
0,8,38:18.14
-2,9,38:18.14
-1,9,38:18.14
-7,10,38:18.14
-4,10,38:18.14
-3,10,38:18.14
5,10,38:18.6
-6,11,38:18.14
-5,11,38:18.14
5,11,38:18.14
-6,12,38:18.14
4,12,38:18.14
-12,13,38:18.14
-7,13,38:18.14
-6,13,38:18.14
-2,13,38:18.14
-1,13,38:18.14
3,13,38:18.14
-12,14,38:18.14
-7,14,38:18.14
0,14,38:18.14
1,14,38:18.14
2,14,38:18.14
3,14,38:18.14
-13,15,38:18.14
-12,15,38:18.14
3,15,38:17.12
-12,16,38:18.14
-11,16,38:18.14
-10,16,38:18.14
3,16,38:18.14
4,16,38:18.14
5,16,38:18.14
-12,17,38:17.12
-11,17,38:18.14
3,17,38:18.14
5,17,38:17.12
7,17,38:18.14
-11,19,38:18.14
-11,20,38:18.14
-11,21,38:18.14
1,1,39:18.14
2,1,39:18.14
5,1,39:18.14
6,1,39:18.14
2,2,39:18.14
5,2,39:18.14
6,3,39:17.12
1,4,39:17.12
2,4,39:17.12
4,4,39:18.14
5,4,39:17.12
6,4,39:17.12
1,5,39:17.12
2,5,39:17.12
4,5,39:18.14
4,6,39:18.14
4,7,39:18.14
-1,8,39:18.14
-7,9,39:18.14
-3,9,39:18.14
-2,9,39:18.14
-6,10,39:18.14
-5,10,39:18.14
-4,10,39:18.14
5,10,39:18.6
-6,11,39:18.14
-5,11,39:18.14
4,11,39:18.14
5,11,39:18.14
-6,12,39:17.12
-5,12,39:18.14
4,12,39:18.14
-2,13,39:18.14
-1,13,39:18.14
0,13,39:18.14
3,13,39:18.14
1,14,39:18.14
2,14,39:18.14
3,14,39:18.14
-14,15,39:18.14
-13,15,39:18.14
3,15,39:18.14
4,15,39:18.14
5,15,39:18.14
-13,16,39:18.14
-12,16,39:18.14
-10,16,39:18.14
-9,16,39:18.14
3,16,39:18.14
5,16,39:18.14
-12,17,39:17.12
-11,17,39:18.14
3,17,39:18.14
4,17,39:18.14
5,17,39:18.14
6,17,39:18.14
7,17,39:18.14
-12,18,39:17.12
-11,18,39:18.14
4,18,39:18.14
8,18,39:18.14
9,18,39:18.6
-11,19,39:18.14
-12,20,39:18.14
-11,20,39:18.14
-12,21,39:18.14
-11,21,39:18.14
2,1,40:18.14
6,3,40:17.12
7,3,40:17.12
1,4,40:17.12
2,4,40:17.12
4,4,40:18.14
6,4,40:17.12
7,4,40:17.12
1,5,40:17.12
2,5,40:17.12
4,5,40:18.14
4,6,40:18.14
-9,7,40:18.14
-9,8,40:18.14
-8,8,40:18.14
-1,8,40:18.14
0,8,40:18.14
-7,9,40:18.14
-6,9,40:18.14
-3,9,40:18.14
-2,9,40:18.14
-6,10,40:18.14
-5,10,40:18.14
-4,10,40:18.14
5,10,40:18.6
4,11,40:18.14
5,11,40:18.14
-6,12,40:17.12
-5,12,40:18.14
3,12,40:18.14
4,12,40:18.14
-2,13,40:18.14
-1,13,40:18.14
0,13,40:18.14
1,13,40:18.14
3,13,40:18.14
2,14,40:18.14
3,14,40:18.14
4,14,40:18.14
5,14,40:18.14
-15,15,40:18.14
-14,15,40:18.14
3,15,40:18.14
5,15,40:18.14
-14,16,40:18.14
-13,16,40:18.14
-10,16,40:18.14
-9,16,40:18.14
3,16,40:18.14
5,16,40:18.14
-13,17,40:18.14
-12,17,40:18.14
-11,17,40:18.14
-10,17,40:18.14
4,17,40:18.14
5,17,40:18.14
6,17,40:17.12
7,17,40:18.14
-13,18,40:17.12
-12,18,40:18.14
-11,18,40:18.14
4,18,40:18.14
5,18,40:18.14
7,18,40:17.12
8,18,40:18.14
9,18,40:18.6
10,18,40:18.6
-12,19,40:18.14
4,19,40:18.14
-12,20,40:18.14
-12,21,40:18.14
9,1,41:18.6
8,2,41:18.6
7,3,41:18.6
8,3,41:17.12
0,4,41:17.12
1,4,41:17.12
7,4,41:17.12
0,5,41:18.6
1,5,41:17.12
7,5,41:18.6
-9,7,41:18.14
-8,7,41:18.14
0,7,41:18.6
-8,8,41:18.14
-7,8,41:18.14
-2,8,41:18.14
-1,8,41:18.14
-7,9,41:18.14
-6,9,41:18.14
-4,9,41:18.14
-3,9,41:18.14
-2,9,41:18.14
-5,10,41:18.14
-4,10,41:18.14
-5,11,41:18.14
4,11,41:18.14
-6,12,41:17.12
-5,12,41:18.14
3,12,41:18.14
4,12,41:18.14
-2,13,41:18.14
-1,13,41:18.14
0,13,41:18.14
1,13,41:18.14
3,13,41:18.14
4,13,41:18.14
-5,14,41:18.14
5,14,41:18.14
-5,15,41:18.14
3,15,41:18.14
5,15,41:18.14
-14,16,41:18.14
-9,16,41:18.14
-8,16,41:18.14
3,16,41:18.14
4,16,41:18.14
5,16,41:18.14
6,16,41:18.14
-14,17,41:18.14
-13,17,41:18.14
-11,17,41:18.14
-10,17,41:18.14
4,17,41:18.14
6,17,41:18.14
7,17,41:18.14
-12,18,41:18.14
4,18,41:18.14
5,18,41:18.14
7,18,41:18.14
8,18,41:18.6
9,18,41:18.6
10,18,41:18.6
-12,19,41:18.14
4,19,41:18.14
-12,20,41:18.14
3,20,41:18.6
10,0,42:18.6
9,1,42:18.6
10,1,42:18.6
8,2,42:18.6
9,2,42:18.6
0,3,42:17.12
5,3,42:18.6
6,3,42:18.6
7,3,42:18.6
8,3,42:17.12
9,3,42:17.12
0,4,42:17.12
1,4,42:17.12
7,4,42:18.6
-2,5,42:18.6
-1,5,42:18.6
0,5,42:17.12
1,5,42:17.12
7,5,42:18.6
8,5,42:18.6
-4,6,42:18.6
-3,6,42:18.6
8,6,42:18.6
-8,7,42:18.6
8,7,42:18.6
-7,8,42:18.14
-6,8,42:18.14
-2,8,42:18.14
-1,8,42:18.6
-6,9,42:18.14
-4,9,42:18.14
-3,9,42:18.14
-4,10,42:18.14
-5,11,42:18.14
-5,12,42:18.14
0,13,42:18.6
1,13,42:18.6
5,13,42:18.6
-5,14,42:18.14
5,14,42:18.6
-5,15,42:18.14
3,15,42:18.6
5,15,42:18.6
6,15,42:18.6
-9,16,42:18.14
-8,16,42:18.14
3,16,42:18.6
4,16,42:18.6
6,16,42:18.6
-14,17,42:18.14
-11,17,42:18.14
-10,17,42:18.14
4,17,42:18.6
6,17,42:18.6
5,18,42:18.6
8,18,42:18.6
9,18,42:18.6
4,19,42:18.6
5,19,42:18.6
3,20,42:18.6
4,20,42:18.6
9,1,43:18.6
10,1,43:18.6
9,2,43:18.6
-1,3,43:17.12
0,3,43:17.12
5,3,43:18.6
6,3,43:18.6
8,3,43:18.6
1,4,43:18.6
8,4,43:18.6
0,5,43:17.12
1,5,43:17.12
8,5,43:18.6
-4,6,43:18.6
-3,6,43:18.6
-2,6,43:18.6
-1,6,43:18.6
1,6,43:18.6
8,6,43:18.6
-8,7,43:18.6
-7,7,43:18.6
1,7,43:18.6
8,7,43:18.6
9,7,43:18.6
-7,8,43:18.14
-6,8,43:18.14
-3,8,43:18.14
-2,8,43:18.14
-3,9,43:18.14
-4,11,43:18.14
-5,12,43:18.14
5,13,43:18.6
-5,14,43:18.14
5,14,43:18.6
3,15,43:18.6
6,15,43:18.6
-9,16,43:18.14
-8,16,43:18.14
6,16,43:18.6
-11,17,43:18.14
-10,17,43:18.14
-9,17,43:18.14
-11,18,43:18.14
6,18,43:18.6
8,18,43:18.6
5,19,43:18.6
4,20,43:18.6
10,1,44:18.6
-1,2,44:17.12
9,2,44:18.6
10,2,44:18.6
-1,3,44:17.12
1,3,44:18.6
4,3,44:18.6
5,3,44:18.6
6,3,44:18.6
7,3,44:18.6
8,3,44:18.6
9,3,44:18.6
1,4,44:18.6
8,4,44:18.6
0,5,44:17.12
1,5,44:17.12
8,5,44:18.6
-5,6,44:18.6
-4,6,44:18.6
-3,6,44:18.6
-2,6,44:18.6
-1,6,44:18.6
0,6,44:18.6
8,6,44:18.6
9,6,44:18.6
1,7,44:18.6
9,7,44:18.6
-6,8,44:18.14
1,8,44:18.6
2,9,44:18.6
-4,11,44:18.14
-4,12,44:18.14
-4,13,44:18.14
-5,14,44:18.14
6,15,44:18.6
6,16,44:18.6
5,19,44:18.6
6,19,44:18.6
-2,0,45:17.12
-2,1,45:17.12
-1,1,45:17.12
10,1,45:18.6
-2,2,45:17.12
-1,2,45:17.12
2,2,45:18.6
9,2,45:18.6
10,2,45:18.6
1,3,45:18.6
4,3,45:18.6
5,3,45:18.6
6,3,45:18.6
7,3,45:18.6
8,3,45:18.6
9,3,45:18.6
1,4,45:18.6
0,5,45:18.6
1,5,45:17.12
9,5,45:18.6
-4,6,45:18.6
-3,6,45:18.6
-2,6,45:18.6
-1,6,45:18.6
0,6,45:18.6
9,6,45:18.6
0,7,45:18.6
1,7,45:18.6
9,7,45:18.6
1,8,45:18.6
1,9,45:18.6
2,9,45:18.6
2,10,45:18.6
-4,11,45:18.14
-4,12,45:18.14
0,-4,46:18.6
-1,-3,46:18.6
0,-3,46:18.6
-1,-2,46:18.6
-7,-1,46:18.6
-6,-1,46:18.6
-5,-1,46:18.6
-2,-1,46:18.6
-1,-1,46:18.6
-6,0,46:18.6
-5,0,46:18.6
-4,0,46:18.6
-3,0,46:18.6
-2,0,46:18.6
-2,1,46:18.6
1,2,46:18.6
10,2,46:18.6
1,3,46:18.6
4,3,46:18.6
5,3,46:18.6
6,3,46:18.6
7,3,46:18.6
0,4,46:18.6
1,4,46:18.6
0,5,46:18.6
1,5,46:17.12
9,5,46:18.6
-3,6,46:18.6
-2,6,46:18.6
-1,6,46:18.6
9,6,46:18.6
0,7,46:18.6
0,8,46:18.6
1,8,46:18.6
1,9,46:18.6
-1,-5,47:18.6
0,-5,47:18.6
-1,-4,47:18.6
-2,-3,47:18.6
-1,-3,47:18.6
-7,-2,47:18.6
-6,-2,47:18.6
-5,-2,47:18.6
-2,-2,47:18.6
-6,-1,47:18.6
-5,-1,47:18.6
-4,-1,47:18.6
-3,-1,47:18.6
-2,-1,47:18.6
-3,0,47:17.12
-2,0,47:18.6
1,3,47:18.6
6,3,47:18.6
7,3,47:18.6
0,4,47:18.6
0,5,47:18.6
1,5,47:17.12
0,8,47:18.6
-1,-5,48:18.6
-2,-4,48:18.6
-1,-4,48:18.6
-7,-3,48:18.6
-6,-3,48:18.6
-2,-3,48:18.6
-7,-2,48:18.6
-6,-2,48:18.6
-5,-2,48:18.6
-4,-2,48:18.6
-3,-2,48:18.6
-2,-2,48:18.6
-3,-1,48:18.6
-2,0,48:18.6
-2,1,48:18.6
0,4,48:18.6
0,5,48:18.6
-2,-5,49:18.6
-3,-4,49:18.6
-2,-4,49:18.6
-6,-3,49:18.6
-5,-3,49:18.6
-4,-3,49:18.6
-3,-2,49:18.6
-3,-1,49:18.6
-2,-1,49:18.6
-2,0,49:18.6
-2,1,49:18.6
-3,-2,50:18.6
-3,-1,50:18.6
-2,-1,50:18.6
-2,0,50:18.6
-2,1,50:18.6
-3,-2,51:18.6
-3,-1,51:18.6
-2,-1,51:18.6
-2,0,51:18.6
-2,1,51:18.6
-3,-2,52:18.6
-3,-1,52:18.6
-2,0,52:18.6
