[META]
version=2.0
spawnOnBlockType=2
spawnSunlight=True
spawnDarkness=True
spawnWater=False
spawnLava=False
underFill=False
randomRotation=True
dig=True
tree=False
branch=False
needsFoundation=True
rarity=100
collisionPercentage=20
spawnElevationMin=0
spawnElevationMax=200
spawnInBiome=Custom
[DATA]
-2,-7,-8:17.12
-7,-6,-8:17.12
-1,-6,-8:17.12
-7,-5,-8:17.12
-2,-5,-8:17.12
-7,-1,-8:17.12
-2,-1,-8:17.12
-8,0,-8:17.12
-3,1,-8:17.12
-3,-7,-7:17.12
-1,-7,-7:17.12
-2,-6,-7:17.12
-1,-6,-7:17.12
-8,-5,-7:17.12
-7,-5,-7:17.12
-3,-5,-7:17.12
-2,-5,-7:17.12
-1,-5,-7:17.12
-7,-4,-7:17.12
-8,-2,-7:17.12
-7,-2,-7:17.12
-8,-1,-7:17.12
-7,-1,-7:17.12
-3,-1,-7:17.12
-7,0,-7:17.12
-3,0,-7:17.12
-2,0,-7:17.12
-1,0,-7:17.12
-8,-6,-6:17.12
-7,-6,-6:17.12
-2,-6,-6:17.12
-1,-6,-6:17.12
-7,-5,-6:17.12
-6,-5,-6:17.12
-2,-5,-6:17.12
-7,-4,-6:17.12
-6,-4,-6:17.12
-8,-2,-6:17.12
-7,-2,-6:17.12
-8,-1,-6:17.12
-7,-1,-6:17.12
-6,-1,-6:17.12
-2,-1,-6:17.12
-1,-1,-6:17.12
-8,0,-6:17.12
-3,0,-6:17.12
-2,0,-6:17.12
-1,0,-6:17.12
-2,1,-6:17.12
-2,-7,-5:17.12
-1,-7,-5:17.12
-7,-6,-5:17.12
-2,-6,-5:17.12
-7,-5,-5:17.12
-3,-5,-5:17.12
-1,-5,-5:17.12
-6,-4,-5:17.12
-7,-2,-5:17.12
-6,-2,-5:17.12
-8,-1,-5:17.12
-7,-1,-5:17.12
-6,-1,-5:17.12
-3,-1,-5:17.12
-2,-1,-5:17.12
-1,-1,-5:17.12
-8,0,-5:17.12
-7,0,-5:17.12
-3,0,-5:17.12
-2,0,-5:17.12
-1,0,-5:17.12
-3,1,-5:17.12
-2,1,-5:17.12
-6,-6,-4:17.12
-5,-6,-4:17.12
-2,-6,-4:17.12
-1,-6,-4:17.12
-8,-5,-4:17.12
-7,-5,-4:17.12
-6,-5,-4:17.12
-5,-5,-4:17.12
-3,-5,-4:17.12
-2,-5,-4:17.12
-7,-4,-4:17.12
-6,-4,-4:17.12
-5,-4,-4:17.12
-2,-4,-4:17.12
-6,-3,-4:17.12
-2,-3,-4:17.12
-1,-3,-4:17.12
-8,-2,-4:17.12
-3,-2,-4:17.12
-2,-2,-4:17.12
-8,-1,-4:17.12
-7,-1,-4:17.12
-6,-1,-4:17.12
-3,-1,-4:17.12
-2,-1,-4:17.12
-7,0,-4:17.12
-6,0,-4:17.12
-3,0,-4:17.12
-2,0,-4:17.12
-8,-6,-3:17.12
-3,-6,-3:17.12
-2,-6,-3:17.12
-6,-5,-3:17.12
-5,-5,-3:17.12
-3,-5,-3:17.12
-2,-5,-3:17.12
-7,-4,-3:17.12
-6,-4,-3:17.12
-3,-4,-3:17.12
-2,-4,-3:17.12
-1,-4,-3:17.12
-7,-3,-3:17.12
-6,-3,-3:17.12
-4,-3,-3:17.12
-3,-3,-3:17.12
-2,-3,-3:17.12
-1,-3,-3:17.12
-8,-2,-3:17.12
-7,-2,-3:17.12
-4,-2,-3:17.12
-3,-2,-3:17.12
-2,-2,-3:17.12
-8,-1,-3:17.12
-7,-1,-3:17.12
-6,-1,-3:17.12
-4,-1,-3:17.12
-3,-1,-3:17.12
-2,-1,-3:17.12
-1,-1,-3:17.12
-8,0,-3:17.12
-7,0,-3:17.12
-6,0,-3:17.12
-3,0,-3:17.12
-2,0,-3:17.12
-1,0,-3:17.12
0,0,-3:17.12
-7,-5,-2:17.12
-6,-5,-2:17.12
-3,-5,-2:17.12
-7,-4,-2:17.12
-6,-4,-2:17.12
-5,-4,-2:17.12
-4,-4,-2:17.12
-3,-4,-2:17.12
-2,-4,-2:17.12
-1,-4,-2:17.12
-7,-3,-2:17.12
-6,-3,-2:17.12
-5,-3,-2:17.12
-4,-3,-2:17.12
-3,-3,-2:17.12
-2,-3,-2:17.12
-1,-3,-2:17.12
-7,-2,-2:17.12
-6,-2,-2:17.12
-5,-2,-2:17.12
-4,-2,-2:17.12
-3,-2,-2:17.12
-2,-2,-2:17.12
-8,-1,-2:17.12
-7,-1,-2:17.12
-6,-1,-2:17.12
-5,-1,-2:17.12
-4,-1,-2:17.12
-3,-1,-2:17.12
-2,-1,-2:17.12
-8,0,-2:17.12
-7,0,-2:17.12
-6,0,-2:17.12
-5,0,-2:17.12
-3,0,-2:17.12
-2,0,-2:17.12
-1,0,-2:17.12
-5,1,-2:17.12
-6,-5,-1:17.12
-6,-4,-1:17.12
-5,-4,-1:17.12
-4,-4,-1:17.12
-7,-3,-1:17.12
-6,-3,-1:17.12
-5,-3,-1:17.12
-4,-3,-1:17.12
-3,-3,-1:17.12
-2,-3,-1:17.12
-7,-2,-1:17.12
-6,-2,-1:17.12
-5,-2,-1:17.12
-4,-2,-1:17.12
-3,-2,-1:17.12
-2,-2,-1:17.12
-7,-1,-1:17.12
-6,-1,-1:17.12
-5,-1,-1:17.12
-4,-1,-1:17.12
-3,-1,-1:17.12
-2,-1,-1:17.12
-7,0,-1:17.12
-6,0,-1:17.12
-5,0,-1:17.12
-4,0,-1:17.12
-3,0,-1:17.12
-2,0,-1:17.12
-5,1,-1:17.12
-9,-4,0:18.14
-10,-3,0:18.14
-9,-3,0:18.14
-6,-3,0:17.12
-5,-3,0:17.12
-4,-3,0:17.12
-3,-3,0:17.12
-11,-2,0:18.14
-10,-2,0:18.14
-9,-2,0:18.14
-8,-2,0:18.14
-7,-2,0:17.12
-6,-2,0:17.12
-5,-2,0:17.12
-3,-2,0:17.12
-7,-1,0:17.12
-6,-1,0:17.12
-5,-1,0:17.12
-4,-1,0:17.12
-3,-1,0:17.12
-4,0,0:17.12
1,2,0:18.14
-9,-5,1:18.14
-8,-5,1:18.14
-11,-4,1:18.14
-9,-4,1:18.14
-8,-4,1:18.14
-11,-3,1:18.14
-10,-3,1:18.14
-9,-3,1:18.14
-8,-3,1:18.14
-7,-3,1:18.14
-6,-3,1:18.14
-5,-3,1:17.12
-4,-3,1:17.12
-3,-3,1:17.12
-11,-2,1:18.14
-10,-2,1:18.14
-9,-2,1:18.14
-8,-2,1:18.14
-7,-2,1:17.12
-6,-2,1:17.12
-5,-2,1:17.12
-3,-2,1:17.12
-7,-1,1:17.12
-5,-1,1:17.12
-4,-1,1:17.12
-3,-1,1:17.12
-2,-1,1:17.12
0,2,1:18.14
1,2,1:18.14
-10,-5,2:18.14
-9,-5,2:18.14
-9,-4,2:18.14
-7,-4,2:18.14
-11,-3,2:18.14
-10,-3,2:18.14
-9,-3,2:18.14
-8,-3,2:18.14
-7,-3,2:17.12
-6,-3,2:18.14
-4,-3,2:17.12
-3,-3,2:17.12
-2,-3,2:17.12
-10,-2,2:18.14
-9,-2,2:18.14
-8,-2,2:17.12
-7,-2,2:17.12
-6,-2,2:18.14
-5,-2,2:17.12
-4,-2,2:17.12
-3,-2,2:17.12
-2,-2,2:17.12
-9,-1,2:18.14
-8,-1,2:18.14
-7,-1,2:18.14
-4,-1,2:17.12
-3,-1,2:17.12
-2,-1,2:17.12
-7,0,2:18.14
-3,0,2:17.12
-2,0,2:17.12
-1,1,2:18.14
0,1,2:18.14
0,2,2:18.14
1,2,2:18.14
1,3,2:18.14
2,3,2:18.14
-10,-6,3:18.14
-10,-5,3:18.14
-9,-5,3:18.14
-8,-5,3:18.14
-7,-5,3:18.14
-1,-5,3:18.14
-10,-4,3:18.14
-9,-4,3:18.14
-8,-4,3:18.14
-7,-4,3:18.14
-6,-4,3:18.14
-5,-4,3:18.14
-2,-4,3:18.14
-10,-3,3:18.14
-9,-3,3:18.14
-8,-3,3:18.14
-7,-3,3:17.12
-6,-3,3:18.14
-5,-3,3:18.14
-4,-3,3:17.12
-3,-3,3:17.12
-2,-3,3:17.12
-10,-2,3:18.14
-8,-2,3:17.12
-7,-2,3:17.12
-6,-2,3:18.14
-5,-2,3:18.14
-4,-2,3:17.12
-2,-2,3:17.12
-7,-1,3:17.12
-4,-1,3:17.12
-3,-1,3:17.12
-2,-1,3:17.12
-3,0,3:17.12
-2,0,3:17.12
-1,0,3:18.14
-2,1,3:17.12
-1,1,3:18.14
0,1,3:18.14
1,1,3:18.14
-2,2,3:18.14
-1,2,3:18.14
0,2,3:18.14
2,2,3:18.14
-3,3,3:18.14
-2,3,3:18.14
-1,3,3:18.14
0,3,3:18.14
1,3,3:18.14
3,3,3:18.14
-3,4,3:18.14
-2,4,3:18.14
1,4,3:18.14
2,4,3:18.14
-8,-6,4:18.14
-10,-5,4:18.14
-9,-5,4:18.14
-8,-5,4:18.14
-7,-5,4:18.14
-6,-5,4:18.14
-1,-5,4:18.14
-10,-4,4:18.14
-9,-4,4:18.14
-8,-4,4:18.14
-7,-4,4:18.14
-6,-4,4:18.14
-5,-4,4:18.14
-4,-4,4:17.12
-3,-4,4:17.12
-2,-4,4:18.14
-1,-4,4:18.14
-10,-3,4:18.14
-9,-3,4:18.14
-8,-3,4:18.14
-6,-3,4:18.14
-5,-3,4:18.14
-4,-3,4:17.12
-3,-3,4:17.12
-2,-3,4:17.12
-1,-3,4:18.14
-10,-2,4:18.14
-9,-2,4:18.14
-8,-2,4:18.14
-7,-2,4:18.14
-6,-2,4:17.12
-5,-2,4:18.14
-4,-2,4:17.12
-3,-2,4:17.12
-2,-2,4:17.12
-8,-1,4:18.14
-7,-1,4:17.12
-5,-1,4:18.14
-3,-1,4:17.12
0,-1,4:18.14
-7,0,4:17.12
-2,0,4:17.12
0,0,4:18.14
-4,1,4:18.14
-3,1,4:18.14
-2,1,4:17.12
-1,1,4:17.12
0,1,4:18.14
1,1,4:18.14
2,1,4:18.14
-3,2,4:18.14
-1,2,4:17.12
0,2,4:18.14
3,2,4:18.14
-3,3,4:18.14
-1,3,4:18.14
0,3,4:18.14
1,3,4:18.14
2,3,4:18.14
3,3,4:18.14
-3,4,4:18.14
-2,4,4:18.14
-1,4,4:18.14
0,4,4:18.14
3,4,4:18.14
4,4,4:18.6
-3,5,4:18.14
-2,5,4:18.14
-1,5,4:18.14
-8,-6,5:18.14
-7,-6,5:18.14
-6,-6,5:18.14
-5,-6,5:18.14
-9,-5,5:18.14
-8,-5,5:18.14
-5,-5,5:18.14
-2,-5,5:18.14
-1,-5,5:18.14
-9,-4,5:18.14
-8,-4,5:18.14
-7,-4,5:18.14
-6,-4,5:18.14
-5,-4,5:18.14
-4,-4,5:18.14
-3,-4,5:17.12
-2,-4,5:17.12
-1,-4,5:18.14
0,-4,5:18.14
-10,-3,5:18.14
-9,-3,5:18.14
-8,-3,5:18.14
-6,-3,5:18.14
-5,-3,5:18.14
-4,-3,5:17.12
-2,-3,5:17.12
0,-3,5:18.14
-10,-2,5:18.14
-9,-2,5:18.14
-8,-2,5:18.14
-7,-2,5:18.14
-6,-2,5:18.14
-5,-2,5:18.14
-4,-2,5:17.12
-3,-2,5:17.12
-2,-2,5:17.12
1,-2,5:18.14
-8,-1,5:18.14
-7,-1,5:18.14
-5,-1,5:18.14
-2,-1,5:18.14
1,-1,5:18.14
2,-1,5:18.14
-8,0,5:18.14
-7,0,5:18.14
-6,0,5:18.14
0,0,5:18.14
1,0,5:18.14
2,0,5:18.14
-8,1,5:18.14
-6,1,5:18.14
-5,1,5:18.14
-2,1,5:17.12
-1,1,5:18.14
0,1,5:18.14
1,1,5:18.14
2,1,5:18.14
-6,2,5:18.14
-5,2,5:18.14
-4,2,5:18.14
-3,2,5:18.14
-2,2,5:18.14
-1,2,5:17.12
0,2,5:18.14
1,2,5:18.14
-4,3,5:18.14
-3,3,5:18.14
0,3,5:18.14
1,3,5:18.14
2,3,5:18.14
-3,4,5:18.14
1,4,5:18.14
2,4,5:18.14
3,4,5:18.14
4,4,5:18.6
-3,5,5:18.14
4,5,5:18.6
-6,-6,6:18.14
-6,-5,6:18.14
-2,-5,6:18.14
-1,-5,6:17.12
-9,-4,6:18.14
-8,-4,6:18.14
-6,-4,6:18.14
-5,-4,6:18.14
-4,-4,6:17.12
-3,-4,6:17.12
-2,-4,6:17.12
-1,-4,6:17.12
-9,-3,6:18.14
-8,-3,6:18.14
-7,-3,6:18.14
-6,-3,6:18.14
-5,-3,6:18.14
-4,-3,6:17.12
-3,-3,6:17.12
-2,-3,6:17.12
-1,-3,6:17.12
-11,-2,6:18.14
-10,-2,6:18.14
-9,-2,6:18.14
-8,-2,6:18.14
-7,-2,6:18.14
-6,-2,6:18.14
-5,-2,6:18.14
-4,-2,6:17.12
-3,-2,6:17.12
-2,-2,6:17.12
-1,-2,6:17.12
-11,-1,6:18.14
-10,-1,6:18.14
-7,-1,6:18.14
-6,-1,6:18.14
-5,-1,6:18.14
-3,-1,6:18.14
-2,-1,6:18.14
2,-1,6:18.14
-8,0,6:18.14
-7,0,6:18.14
-2,0,6:18.14
2,0,6:18.14
-8,1,6:18.14
-7,1,6:18.14
-2,1,6:17.12
-1,1,6:18.14
0,1,6:18.14
1,1,6:18.14
-6,2,6:18.14
-3,2,6:18.14
-2,2,6:18.14
-1,2,6:18.14
0,2,6:18.14
1,2,6:18.14
-6,3,6:18.14
-5,3,6:18.14
-4,3,6:18.14
-3,3,6:18.14
1,3,6:18.14
2,3,6:18.14
-4,4,6:18.14
2,4,6:18.14
3,4,6:18.14
1,5,6:18.14
2,5,6:18.14
3,5,6:18.14
4,5,6:18.6
0,6,6:18.14
1,6,6:18.14
2,6,6:18.14
1,7,6:18.14
-7,-6,7:18.14
0,-6,7:17.12
-6,-5,7:18.14
-4,-5,7:17.12
-3,-5,7:17.12
-2,-5,7:17.12
-1,-5,7:17.12
0,-5,7:17.12
-8,-4,7:18.14
-7,-4,7:18.14
-6,-4,7:18.14
-5,-4,7:18.14
-4,-4,7:17.12
-3,-4,7:17.12
-2,-4,7:17.12
-1,-4,7:17.12
-9,-3,7:18.14
-8,-3,7:18.14
-7,-3,7:18.14
-6,-3,7:18.14
-5,-3,7:18.14
-4,-3,7:17.12
-3,-3,7:17.12
-2,-3,7:17.12
-1,-3,7:17.12
-11,-2,7:18.14
-10,-2,7:18.14
-9,-2,7:18.14
-8,-2,7:18.14
-7,-2,7:18.14
-6,-2,7:18.14
-5,-2,7:18.14
-4,-2,7:17.12
-3,-2,7:17.12
-2,-2,7:17.12
-1,-2,7:17.12
0,-2,7:17.12
-11,-1,7:18.14
-10,-1,7:18.14
-8,-1,7:18.14
-7,-1,7:18.14
-3,-1,7:17.12
-2,-1,7:18.14
-8,0,7:18.14
-7,0,7:18.14
-5,0,7:18.14
-4,0,7:18.14
-3,0,7:18.14
-2,0,7:18.14
-8,1,7:18.14
-7,1,7:18.14
-2,1,7:18.14
-1,1,7:18.14
-2,2,7:18.14
-1,2,7:18.14
0,2,7:18.14
1,2,7:18.14
2,2,7:18.14
-3,3,7:18.14
-2,3,7:18.14
2,3,7:18.14
3,3,7:18.14
-3,4,7:18.14
-2,4,7:18.14
3,4,7:18.14
-3,5,7:18.14
-3,6,7:18.14
3,6,7:18.14
-6,-6,8:18.14
-1,-6,8:17.12
0,-6,8:17.12
-6,-5,8:18.14
-4,-5,8:17.12
-3,-5,8:17.12
-1,-5,8:17.12
0,-5,8:17.12
-7,-4,8:18.14
-6,-4,8:18.14
-5,-4,8:18.14
-4,-4,8:18.14
-3,-4,8:17.12
-1,-4,8:18.14
-9,-3,8:18.14
-8,-3,8:18.14
-7,-3,8:18.14
-6,-3,8:18.14
-5,-3,8:18.14
-1,-3,8:17.12
0,-3,8:17.12
-9,-2,8:18.14
-8,-2,8:18.14
-7,-2,8:18.14
-6,-2,8:18.14
-5,-2,8:18.14
-4,-2,8:17.12
-3,-2,8:17.12
-2,-2,8:18.14
-1,-2,8:17.12
0,-2,8:17.12
-9,-1,8:18.14
-8,-1,8:18.14
-7,-1,8:18.14
-5,-1,8:18.14
-4,-1,8:17.12
-3,-1,8:17.12
-2,-1,8:18.14
-8,0,8:18.14
-7,0,8:18.14
-6,0,8:18.14
-5,0,8:18.14
-4,0,8:18.14
-2,0,8:18.14
1,0,8:18.14
-8,1,8:18.14
-7,1,8:18.14
-6,1,8:18.14
-5,1,8:18.14
-4,1,8:18.14
-2,1,8:18.14
-1,1,8:18.14
0,1,8:18.14
-2,2,8:18.14
-1,2,8:18.14
0,2,8:18.14
2,2,8:18.14
-3,3,8:18.14
-2,3,8:18.14
0,3,8:18.14
1,3,8:18.14
3,3,8:18.14
-3,4,8:17.12
-2,4,8:18.14
3,4,8:18.14
-3,5,8:18.14
-3,6,8:18.14
-1,-8,9:18.14
0,-7,9:18.14
-7,-6,9:18.14
-6,-6,9:18.14
-4,-6,9:17.12
-3,-6,9:17.12
0,-6,9:17.12
1,-6,9:17.12
-7,-5,9:18.14
-6,-5,9:18.14
-4,-5,9:17.12
-3,-5,9:17.12
-1,-5,9:18.14
0,-5,9:18.14
-8,-4,9:18.14
-7,-4,9:18.14
-5,-4,9:18.14
-3,-4,9:17.12
0,-4,9:18.14
-8,-3,9:18.14
-7,-3,9:18.14
-6,-3,9:18.14
-1,-3,9:18.14
0,-3,9:17.12
1,-3,9:18.14
-9,-2,9:18.6
-8,-2,9:18.14
-7,-2,9:18.14
-6,-2,9:18.14
-5,-2,9:18.14
-1,-2,9:17.12
0,-2,9:17.12
-8,-1,9:18.14
-7,-1,9:18.14
-6,-1,9:18.14
-5,-1,9:18.14
-4,-1,9:17.12
-3,-1,9:17.12
-2,-1,9:18.14
0,-1,9:18.14
1,-1,9:18.14
-7,0,9:18.14
-6,0,9:18.14
-4,0,9:17.12
-3,0,9:18.14
-2,0,9:18.14
0,0,9:18.14
1,0,9:18.14
2,0,9:18.14
3,0,9:18.14
-8,1,9:18.14
-7,1,9:18.14
-4,1,9:18.14
-1,1,9:18.14
0,1,9:18.14
-2,2,9:18.14
-1,2,9:18.14
0,2,9:18.14
-4,3,9:18.14
-3,3,9:18.14
-2,3,9:18.14
1,3,9:18.14
-3,4,9:18.14
-2,4,9:18.14
-1,4,9:18.14
0,4,9:18.14
-3,5,9:18.14
-2,5,9:18.14
-3,6,9:18.14
1,-10,10:18.14
-1,-9,10:18.14
1,-9,10:18.14
-1,-8,10:18.14
1,-8,10:18.14
0,-7,10:18.14
1,-7,10:18.14
2,-7,10:18.14
3,-7,10:18.14
-4,-6,10:17.12
-3,-6,10:17.12
0,-6,10:18.14
1,-6,10:17.12
-4,-5,10:17.12
-3,-5,10:17.12
0,-5,10:18.14
-8,-4,10:18.14
-7,-4,10:18.14
0,-4,10:18.14
1,-4,10:18.14
2,-4,10:18.14
-7,-3,10:18.14
-1,-3,10:18.14
0,-3,10:17.12
1,-3,10:17.12
-6,-2,10:18.14
0,-2,10:17.12
1,-2,10:17.12
-9,-1,10:18.14
-8,-1,10:18.14
-7,-1,10:18.14
-6,-1,10:18.14
-5,-1,10:18.14
-4,-1,10:18.14
-3,-1,10:18.14
1,-1,10:18.14
-8,0,10:18.14
-5,0,10:18.14
-4,0,10:18.14
-3,0,10:17.12
-2,0,10:18.14
-1,0,10:18.14
0,0,10:18.14
1,0,10:18.14
2,0,10:18.14
3,0,10:18.14
-8,1,10:18.14
-5,1,10:18.14
-4,1,10:17.12
-1,1,10:18.14
0,1,10:18.14
1,1,10:18.14
-5,2,10:18.14
-1,2,10:18.14
-5,3,10:18.14
-4,3,10:18.14
-3,3,10:18.14
-2,3,10:18.14
-1,3,10:18.14
-5,4,10:18.14
-4,4,10:18.14
-3,4,10:18.14
0,4,10:18.14
-3,5,10:18.14
-2,5,10:18.14
-1,5,10:18.14
0,5,10:18.14
-3,6,10:18.14
2,-10,11:18.14
-1,-9,11:18.14
2,-9,11:18.14
-1,-8,11:18.14
0,-8,11:18.14
2,-8,11:18.14
3,-8,11:18.14
4,-8,11:18.14
-4,-7,11:18.14
0,-7,11:18.14
1,-7,11:17.12
2,-7,11:18.14
3,-7,11:18.14
4,-7,11:18.14
-4,-6,11:17.12
-3,-6,11:17.12
-1,-6,11:18.14
-4,-5,11:17.12
-1,-4,11:18.14
0,-4,11:18.14
-1,-3,11:18.14
0,-3,11:17.12
1,-3,11:17.12
-2,-2,11:18.14
-1,-2,11:18.14
0,-2,11:17.12
1,-2,11:18.14
-8,-1,11:18.14
-7,-1,11:18.14
-6,-1,11:18.14
-4,-1,11:18.14
-2,-1,11:18.14
1,-1,11:18.14
-7,0,11:18.14
-6,0,11:18.14
-5,0,11:18.14
-4,0,11:18.14
-3,0,11:18.14
-2,0,11:18.14
0,0,11:18.14
1,0,11:18.14
3,0,11:18.14
-5,1,11:18.14
-3,1,11:18.14
-1,1,11:18.14
0,1,11:18.14
-5,2,11:18.14
-3,2,11:17.12
-6,3,11:18.14
-5,3,11:18.14
-4,3,11:18.14
-2,3,11:18.14
-1,3,11:18.14
-6,4,11:18.14
-3,4,11:18.14
-3,5,11:18.14
-3,6,11:18.14
-4,-10,12:18.14
-4,-9,12:18.14
-4,-8,12:18.14
1,-8,12:17.12
2,-8,12:18.14
-4,-7,12:18.14
-1,-7,12:18.14
1,-7,12:17.12
2,-7,12:18.14
-4,-6,12:17.12
-3,-6,12:17.12
-1,-6,12:18.14
1,-3,12:17.12
-1,-2,12:18.14
1,-2,12:18.14
2,-2,12:18.14
-4,-1,12:18.14
-2,-1,12:18.14
2,-1,12:18.14
3,-1,12:18.14
-8,0,12:18.14
-7,0,12:18.14
-4,0,12:18.14
-3,0,12:17.12
3,0,12:18.14
-7,1,12:18.14
-6,1,12:18.14
-5,1,12:18.14
-4,1,12:18.14
-3,1,12:18.14
0,1,12:18.14
1,1,12:18.14
-6,2,12:18.14
-3,2,12:18.14
-6,3,12:18.14
-5,3,12:18.14
-2,3,12:18.14
-1,3,12:18.14
-6,4,12:18.14
-4,4,12:18.14
-3,4,12:18.14
-3,5,12:18.14
-4,-10,13:18.14
-4,-9,13:18.14
2,-9,13:18.14
-4,-8,13:18.14
0,-8,13:18.14
1,-8,13:17.12
2,-8,13:18.14
-6,-7,13:18.14
-5,-7,13:18.14
-4,-7,13:18.14
-3,-7,13:17.12
-1,-7,13:18.14
1,-7,13:18.14
-4,-6,13:17.12
-3,-6,13:17.12
1,-3,13:17.12
2,-3,13:17.12
4,-3,13:18.14
-1,-2,13:18.14
2,-2,13:18.14
3,-2,13:18.14
-5,-1,13:18.14
-4,-1,13:18.14
-2,-1,13:18.14
-1,-1,13:18.14
3,-1,13:18.14
-4,0,13:17.12
-3,0,13:18.14
-2,0,13:18.14
4,0,13:18.14
-8,1,13:18.14
-7,1,13:18.14
-5,1,13:18.14
-4,1,13:18.14
-3,1,13:17.12
-2,1,13:18.14
-7,2,13:18.14
-6,2,13:18.14
-2,2,13:18.14
-6,3,13:18.14
-2,3,13:18.14
-3,4,13:18.14
2,-12,14:18.14
2,-11,14:18.14
-4,-10,14:18.14
2,-10,14:18.14
-5,-9,14:18.14
-4,-9,14:18.14
2,-9,14:18.14
3,-9,14:18.14
-6,-8,14:18.14
-5,-8,14:18.14
-4,-8,14:18.14
-1,-8,14:18.14
0,-8,14:18.14
1,-8,14:18.14
2,-8,14:18.14
-7,-7,14:18.14
-6,-7,14:18.14
-4,-7,14:18.14
-3,-7,14:18.14
1,-7,14:18.14
-4,-6,14:18.14
-3,-6,14:18.14
0,-5,14:18.14
0,-4,14:18.14
1,-4,14:17.12
0,-3,14:18.14
1,-3,14:18.14
2,-3,14:18.14
3,-3,14:17.12
0,-2,14:18.14
2,-2,14:18.14
3,-2,14:17.12
4,-2,14:18.14
5,-2,14:18.14
-5,-1,14:18.14
-4,-1,14:18.14
-3,-1,14:18.14
3,-1,14:18.14
4,-1,14:18.14
-5,0,14:17.12
-4,1,14:18.14
-3,1,14:18.14
-2,1,14:18.14
-5,2,14:18.14
2,-10,15:18.14
3,-10,15:18.14
4,-10,15:18.14
-1,-9,15:18.14
1,-9,15:18.14
2,-9,15:18.14
3,-9,15:18.14
4,-9,15:18.14
-7,-8,15:18.14
-6,-8,15:18.14
-5,-8,15:18.14
-4,-8,15:17.12
-2,-8,15:18.14
0,-8,15:18.14
1,-8,15:18.14
2,-8,15:18.14
-7,-7,15:18.14
-4,-7,15:18.14
-3,-7,15:18.14
1,-7,15:18.14
-4,-6,15:18.14
-3,-6,15:17.12
-2,-6,15:18.14
-1,-6,15:18.14
1,-6,15:18.14
-1,-5,15:18.14
0,-5,15:18.14
0,-4,15:18.14
1,-4,15:18.14
2,-4,15:18.14
0,-3,15:18.14
-1,-2,15:18.14
0,-2,15:18.14
3,-2,15:17.12
4,-2,15:18.14
5,-2,15:18.14
6,-2,15:18.14
-4,-1,15:18.14
-3,-1,15:18.14
2,-1,15:18.14
3,-1,15:18.14
1,-10,16:18.14
2,-10,16:18.14
-4,-9,16:17.12
1,-9,16:18.14
2,-9,16:18.14
-5,-8,16:18.14
-4,-8,16:18.14
-3,-8,16:18.14
-4,-7,16:18.14
-3,-7,16:18.14
1,-7,16:18.14
-4,-6,16:18.14
-3,-6,16:17.12
-1,-6,16:18.14
1,-6,16:18.14
0,-5,16:18.14
2,-5,16:18.14
0,-4,16:18.14
1,-4,16:18.14
2,-4,16:18.14
0,-3,16:18.14
4,-3,16:18.14
4,-2,16:18.14
5,-2,16:18.14
4,-1,16:18.14
-2,-11,17:18.14
-5,-10,17:18.14
-4,-10,17:18.14
-3,-10,17:18.14
-2,-10,17:18.14
-4,-9,17:18.14
-3,-7,17:17.12
-2,-7,17:18.14
-1,-7,17:18.14
-3,-6,17:17.12
-2,-6,17:18.14
-1,-6,17:18.14
-2,-5,17:18.14
0,-5,17:18.14
1,-5,17:18.14
2,-5,17:18.14
0,-4,17:18.14
0,-3,17:18.14
4,-3,17:18.14
5,-3,17:18.14
5,-1,17:18.14
-5,-11,18:18.14
-4,-11,18:18.14
-3,-11,18:18.14
-2,-11,18:18.14
-4,-10,18:18.14
-3,-10,18:18.14
-3,-9,18:18.14
-3,-8,18:18.14
0,-8,18:18.14
-2,-7,18:17.12
-1,-7,18:18.14
0,-7,18:18.14
-3,-6,18:17.12
-2,-6,18:18.14
-1,-6,18:18.14
-1,-5,18:18.14
2,-5,18:18.14
0,-4,18:18.14
0,-3,18:18.14
-3,-10,19:18.14
-3,-9,19:18.14
-3,-7,19:18.14
-2,-7,19:18.14
0,-7,19:18.14
-3,-6,19:17.12
-1,-6,19:18.14
-3,-5,19:18.14
-1,-5,19:18.14
-2,-7,20:18.14
-5,-6,20:18.14
-3,-6,20:18.14
-4,-5,20:18.14
-3,-5,20:18.14
-3,-4,20:18.14
-6,-6,21:18.14
-5,-6,21:18.14
-3,-6,21:18.14
-5,-5,21:18.14
-4,-5,21:18.14
-4,-4,21:18.14
-4,-3,21:18.14
-3,-6,22:18.14
-5,-5,22:18.14
-4,-5,22:18.14
-4,-4,22:18.14
