[META]
version=2.0
spawnOnBlockType=2
spawnSunlight=True
spawnDarkness=True
spawnWater=False
spawnLava=False
underFill=False
randomRotation=True
dig=True
tree=False
branch=False
needsFoundation=True
rarity=100
collisionPercentage=20
spawnElevationMin=0
spawnElevationMax=200
spawnInBiome=Custom
[DATA]
-12,-3,-8:17.12
-11,-2,-8:17.12
1,-1,-8:17.12
-14,4,-8:17.12
1,4,-8:17.12
-13,5,-8:17.12
1,5,-8:17.12
2,5,-8:17.12
3,5,-8:17.12
1,6,-8:17.12
-9,7,-8:17.12
-8,7,-8:17.12
-2,11,-8:17.12
-12,12,-8:17.12
-2,13,-8:17.12
-3,17,-8:17.12
-3,19,-8:17.12
-10,-4,-7:17.12
-11,-3,-7:17.12
-10,-3,-7:17.12
-12,-2,-7:17.12
-10,-2,-7:17.12
0,-2,-7:17.12
2,-2,-7:17.12
0,-1,-7:17.12
1,-1,-7:17.12
2,-1,-7:17.12
1,0,-7:17.12
0,1,-7:17.12
1,1,-7:17.12
1,4,-7:17.12
2,4,-7:17.12
-14,5,-7:17.12
-8,5,-7:17.12
1,5,-7:17.12
2,5,-7:17.12
3,5,-7:17.12
-14,6,-7:17.12
-13,6,-7:17.12
-9,6,-7:17.12
-8,6,-7:17.12
-7,6,-7:17.12
1,6,-7:17.12
2,6,-7:17.12
3,6,-7:17.12
-10,7,-7:17.12
-9,7,-7:17.12
-8,7,-7:17.12
-9,8,-7:17.12
-12,11,-7:17.12
-2,11,-7:17.12
-13,12,-7:17.12
-12,12,-7:17.12
-11,12,-7:17.12
-3,12,-7:17.12
-2,12,-7:17.12
-1,12,-7:17.12
-12,13,-7:17.12
-11,13,-7:17.12
-2,13,-7:17.12
-12,14,-7:17.12
-11,14,-7:17.12
-4,17,-7:17.12
-3,17,-7:17.12
-2,17,-7:17.12
-3,18,-7:17.12
-2,18,-7:17.12
-2,19,-7:17.12
-11,-4,-6:17.12
-10,-4,-6:17.12
-11,-3,-6:17.12
-10,-3,-6:17.12
-11,-2,-6:17.12
2,-1,-6:17.12
1,0,-6:17.12
0,1,-6:17.12
1,1,-6:17.12
0,2,-6:17.12
2,4,-6:17.12
-14,5,-6:17.12
-13,5,-6:17.12
1,5,-6:17.12
2,5,-6:17.12
3,5,-6:17.12
-14,6,-6:17.12
-13,6,-6:17.12
-10,6,-6:17.12
-9,6,-6:17.12
-8,6,-6:17.12
2,6,-6:17.12
-14,7,-6:17.12
-13,7,-6:17.12
-10,7,-6:17.12
-9,7,-6:17.12
-8,7,-6:17.12
-7,7,-6:17.12
1,7,-6:17.12
2,7,-6:17.12
-2,10,-6:17.12
-12,11,-6:17.12
-11,11,-6:17.12
-4,11,-6:17.12
-3,11,-6:17.12
-2,11,-6:17.12
-1,11,-6:17.12
-13,12,-6:17.12
-12,12,-6:17.12
-11,12,-6:17.12
-2,12,-6:17.12
-13,13,-6:17.12
-12,13,-6:17.12
-3,16,-6:17.12
-3,17,-6:17.12
-2,17,-6:17.12
-3,18,-6:17.12
-2,18,-6:17.12
-11,-3,-5:17.12
-10,-2,-5:17.12
-9,-2,-5:17.12
-11,-1,-5:17.12
-9,-1,-5:17.12
0,0,-5:17.12
1,0,-5:17.12
2,0,-5:17.12
0,1,-5:17.12
1,1,-5:17.12
-14,4,-5:17.12
-12,4,-5:17.12
-7,4,-5:17.12
1,4,-5:17.12
2,4,-5:17.12
3,4,-5:17.12
-14,5,-5:17.12
-13,5,-5:17.12
-12,5,-5:17.12
-9,5,-5:17.12
-8,5,-5:17.12
-7,5,-5:17.12
1,5,-5:17.12
2,5,-5:17.12
3,5,-5:17.12
-15,6,-5:17.12
-14,6,-5:17.12
-13,6,-5:17.12
-10,6,-5:17.12
-9,6,-5:17.12
-8,6,-5:17.12
-7,6,-5:17.12
-6,6,-5:17.12
1,6,-5:17.12
-13,7,-5:17.12
-7,7,-5:17.12
-13,10,-5:17.12
-12,10,-5:17.12
-11,10,-5:17.12
-3,10,-5:17.12
-2,10,-5:17.12
-13,11,-5:17.12
-12,11,-5:17.12
-11,11,-5:17.12
-4,11,-5:17.12
-3,11,-5:17.12
-2,11,-5:17.12
-13,12,-5:17.12
-12,12,-5:17.12
-11,12,-5:17.12
-4,12,-5:17.12
-3,12,-5:17.12
-2,12,-5:17.12
-12,13,-5:17.12
-4,16,-5:17.12
-2,16,-5:17.12
-4,17,-5:17.12
-3,17,-5:17.12
-4,18,-5:17.12
-3,18,-5:17.12
-2,18,-5:17.12
-9,-3,-4:17.12
-8,-3,-4:17.12
-11,-2,-4:17.12
-10,-2,-4:17.12
-9,-2,-4:17.12
-10,-1,-4:17.12
-9,-1,-4:17.12
-9,0,-4:17.12
0,0,-4:17.12
-1,1,-4:17.12
0,1,-4:17.12
1,1,-4:17.12
-1,2,-4:17.12
0,2,-4:17.12
-13,4,-4:17.12
-7,4,-4:17.12
2,4,-4:17.12
3,4,-4:17.12
-13,5,-4:17.12
-8,5,-4:17.12
-7,5,-4:17.12
-6,5,-4:17.12
1,5,-4:17.12
2,5,-4:17.12
3,5,-4:17.12
-13,6,-4:17.12
-8,6,-4:17.12
-7,6,-4:17.12
-6,6,-4:17.12
-14,7,-4:17.12
-12,9,-4:17.12
-11,9,-4:17.12
-13,10,-4:17.12
-12,10,-4:17.12
-11,10,-4:17.12
-10,10,-4:17.12
-3,10,-4:17.12
-12,11,-4:17.12
-11,11,-4:17.12
-4,11,-4:17.12
-3,11,-4:17.12
-2,11,-4:17.12
-12,12,-4:17.12
-11,12,-4:17.12
-3,12,-4:17.12
-2,12,-4:17.12
-4,16,-4:17.12
-3,16,-4:17.12
-4,17,-4:17.12
-3,17,-4:17.12
-2,17,-4:17.12
-10,-2,-3:17.12
-9,-2,-3:17.12
-8,-2,-3:17.12
-10,-1,-3:17.12
-9,-1,-3:17.12
-10,0,-3:17.12
-9,0,-3:17.12
-8,0,-3:17.12
0,0,-3:17.12
-2,1,-3:17.12
-1,1,-3:17.12
0,1,-3:17.12
1,1,-3:17.12
-1,2,-3:17.12
0,2,-3:17.12
1,2,-3:17.12
-2,3,-3:17.12
-1,3,-3:17.12
0,3,-3:17.12
-13,4,-3:17.12
-12,4,-3:17.12
-6,4,-3:17.12
0,4,-3:17.12
1,4,-3:17.12
-13,5,-3:17.12
-12,5,-3:17.12
-7,5,-3:17.12
-6,5,-3:17.12
0,5,-3:17.12
1,5,-3:17.12
-8,6,-3:17.12
-7,6,-3:17.12
1,6,-3:17.12
-7,7,-3:17.12
-12,9,-3:17.12
-11,9,-3:17.12
-13,10,-3:17.12
-12,10,-3:17.12
-11,10,-3:17.12
-10,10,-3:17.12
-4,10,-3:17.12
-3,10,-3:17.12
-2,10,-3:17.12
-12,11,-3:17.12
-11,11,-3:17.12
-4,11,-3:17.12
-3,11,-3:17.12
-2,11,-3:17.12
-4,12,-3:17.12
-3,12,-3:17.12
-2,12,-3:17.12
-3,15,-3:17.12
-2,15,-3:17.12
-4,16,-3:17.12
-3,16,-3:17.12
-2,16,-3:17.12
-3,17,-3:17.12
-2,17,-3:17.12
-3,18,-3:17.12
-11,-3,-2:17.12
-10,-3,-2:17.12
-11,-2,-2:17.12
-10,-2,-2:17.12
-9,-2,-2:17.12
-11,-1,-2:17.12
-10,-1,-2:17.12
-9,-1,-2:17.12
-8,-1,-2:17.12
-7,-1,-2:17.12
-10,0,-2:17.12
-9,0,-2:17.12
-8,0,-2:17.12
-7,0,-2:17.12
-6,0,-2:17.12
-8,1,-2:17.12
-7,1,-2:17.12
-6,1,-2:17.12
-5,1,-2:17.12
-1,1,-2:17.12
0,1,-2:17.12
1,1,-2:17.12
-5,2,-2:17.12
-2,2,-2:17.12
-1,2,-2:17.12
0,2,-2:17.12
1,2,-2:17.12
-12,3,-2:17.12
-11,3,-2:17.12
-2,3,-2:17.12
-1,3,-2:17.12
0,3,-2:17.12
-12,4,-2:17.12
-11,4,-2:17.12
-10,4,-2:17.12
-6,4,-2:17.12
-5,4,-2:17.12
-2,4,-2:17.12
-1,4,-2:17.12
0,4,-2:17.12
1,4,-2:17.12
-13,5,-2:17.12
-7,5,-2:17.12
-6,5,-2:17.12
-5,5,-2:17.12
-2,5,-2:17.12
-1,5,-2:17.12
0,5,-2:17.12
1,5,-2:17.12
2,5,-2:17.12
-6,6,-2:17.12
-2,6,-2:17.12
-1,6,-2:17.12
0,6,-2:17.12
1,6,-2:17.12
2,6,-2:17.12
-1,7,-2:17.12
0,7,-2:17.12
1,7,-2:17.12
-11,9,-2:17.12
-3,9,-2:17.12
-11,10,-2:17.12
-10,10,-2:17.12
-4,10,-2:17.12
-3,10,-2:17.12
-4,11,-2:17.12
-3,11,-2:17.12
-2,11,-2:17.12
-3,12,-2:17.12
-3,15,-2:17.12
-4,16,-2:17.12
-3,16,-2:17.12
-2,16,-2:17.12
-4,17,-2:17.12
-3,17,-2:17.12
-2,17,-2:17.12
-4,18,-2:17.12
-3,18,-2:17.12
-3,19,-2:17.12
-9,-2,-1:17.12
-10,-1,-1:17.12
-9,-1,-1:17.12
-8,-1,-1:17.12
-7,-1,-1:17.12
-6,-1,-1:17.12
-10,0,-1:17.12
-9,0,-1:17.12
-8,0,-1:17.12
-6,0,-1:17.12
-5,0,-1:17.12
-4,0,-1:17.12
-9,1,-1:17.12
-8,1,-1:17.12
-7,1,-1:17.12
-6,1,-1:17.12
-5,1,-1:17.12
-4,1,-1:17.12
-3,1,-1:17.12
-9,2,-1:17.12
-8,2,-1:17.12
-7,2,-1:17.12
-6,2,-1:17.12
-5,2,-1:17.12
-4,2,-1:17.12
-3,2,-1:17.12
-2,2,-1:17.12
-1,2,-1:17.12
0,2,-1:17.12
-11,3,-1:17.12
-10,3,-1:17.12
-9,3,-1:17.12
-8,3,-1:17.12
-7,3,-1:17.12
-6,3,-1:17.12
-5,3,-1:17.12
-4,3,-1:17.12
-3,3,-1:17.12
-2,3,-1:17.12
-1,3,-1:17.12
0,3,-1:17.12
-12,4,-1:17.12
-11,4,-1:17.12
-10,4,-1:17.12
-9,4,-1:17.12
-8,4,-1:17.12
-7,4,-1:17.12
-6,4,-1:17.12
-5,4,-1:17.12
-4,4,-1:17.12
-3,4,-1:17.12
-2,4,-1:17.12
-1,4,-1:17.12
0,4,-1:17.12
1,4,-1:17.12
-9,5,-1:17.12
-8,5,-1:17.12
-7,5,-1:17.12
-6,5,-1:17.12
-5,5,-1:17.12
-4,5,-1:17.12
-3,5,-1:17.12
-2,5,-1:17.12
0,5,-1:17.12
1,5,-1:17.12
2,5,-1:17.12
-7,6,-1:17.12
-4,6,-1:17.12
-3,6,-1:17.12
-2,6,-1:17.12
1,6,-1:17.12
-5,7,-1:17.12
-4,7,-1:17.12
-3,7,-1:17.12
-1,7,-1:17.12
0,7,-1:17.12
-4,8,-1:17.12
-3,8,-1:17.12
-10,9,-1:17.12
-4,9,-1:17.12
-3,9,-1:17.12
-11,10,-1:17.12
-10,10,-1:17.12
-9,10,-1:17.12
-4,10,-1:17.12
-3,10,-1:17.12
-2,10,-1:17.12
-11,11,-1:17.12
-10,11,-1:17.12
-9,11,-1:17.12
-6,11,-1:17.12
-5,11,-1:17.12
-4,11,-1:17.12
-3,11,-1:17.12
-2,11,-1:17.12
-6,12,-1:17.12
-5,12,-1:17.12
-4,12,-1:17.12
-3,12,-1:17.12
-2,12,-1:17.12
-4,13,-1:17.12
-3,13,-1:17.12
-4,14,-1:17.12
-3,14,-1:17.12
-2,14,-1:17.12
-4,15,-1:17.12
-3,15,-1:17.12
-2,15,-1:17.12
-4,16,-1:17.12
-3,16,-1:17.12
-2,16,-1:17.12
-3,17,-1:17.12
-7,0,0:17.12
-6,0,0:17.12
-5,0,0:17.12
-4,0,0:17.12
-7,1,0:17.12
-6,1,0:17.12
-3,1,0:17.12
-2,1,0:17.12
-8,2,0:17.12
-7,2,0:17.12
-6,2,0:17.12
-3,2,0:17.12
-2,2,0:17.12
-1,2,0:17.12
-10,3,0:17.12
-9,3,0:17.12
-8,3,0:17.12
-7,3,0:17.12
-6,3,0:17.12
-5,3,0:17.12
-4,3,0:17.12
-3,3,0:17.12
-2,3,0:17.12
-1,3,0:17.12
0,3,0:17.12
-10,4,0:17.12
-9,4,0:17.12
-8,4,0:17.12
-7,4,0:17.12
-6,4,0:17.12
-5,4,0:17.12
-4,4,0:17.12
-3,4,0:17.12
-2,4,0:17.12
-1,4,0:17.12
0,4,0:17.12
1,4,0:17.12
-12,5,0:17.12
-11,5,0:17.12
-10,5,0:17.12
-5,5,0:17.12
-4,5,0:17.12
-3,5,0:17.12
-2,5,0:17.12
1,5,0:17.12
-12,6,0:17.12
-11,6,0:17.12
-10,6,0:17.12
-9,6,0:17.12
-8,6,0:17.12
-7,6,0:17.12
-6,6,0:17.12
-5,6,0:17.12
-4,6,0:17.12
-3,6,0:17.12
-2,6,0:17.12
0,6,0:17.12
1,6,0:17.12
-7,7,0:17.12
-6,7,0:17.12
-5,7,0:17.12
-4,7,0:17.12
-3,7,0:17.12
-2,7,0:17.12
-1,7,0:17.12
0,7,0:17.12
-8,8,0:17.12
-7,8,0:17.12
-6,8,0:17.12
-5,8,0:17.12
-4,8,0:17.12
-2,8,0:17.12
-11,9,0:17.12
-10,9,0:17.12
-9,9,0:17.12
-8,9,0:17.12
-7,9,0:17.12
-6,9,0:17.12
-5,9,0:17.12
-4,9,0:17.12
-2,9,0:17.12
-12,10,0:17.12
-11,10,0:17.12
-10,10,0:17.12
-9,10,0:17.12
-8,10,0:17.12
-7,10,0:17.12
-6,10,0:17.12
-5,10,0:17.12
-3,10,0:17.12
-2,10,0:17.12
-11,11,0:17.12
-10,11,0:17.12
-6,11,0:17.12
-5,11,0:17.12
-2,11,0:17.12
-5,12,0:17.12
-3,12,0:17.12
-2,12,0:17.12
-5,13,0:17.12
-4,13,0:17.12
-3,13,0:17.12
-2,13,0:17.12
-5,14,0:17.12
-4,14,0:17.12
-3,14,0:17.12
-2,14,0:17.12
-4,15,0:17.12
-3,15,0:17.12
-5,0,1:17.12
-5,1,1:17.12
-4,1,1:17.12
-3,1,1:17.12
-6,2,1:17.12
-5,2,1:17.12
-2,2,1:17.12
-1,2,1:17.12
-9,3,1:17.12
-8,3,1:17.12
-7,3,1:17.12
-6,3,1:17.12
-5,3,1:17.12
-4,3,1:17.12
-2,3,1:17.12
-1,3,1:17.12
0,3,1:17.12
-12,4,1:17.12
-11,4,1:17.12
-10,4,1:17.12
-9,4,1:17.12
-8,4,1:17.12
-6,4,1:17.12
-5,4,1:17.12
-4,4,1:17.12
-1,4,1:17.12
0,4,1:17.12
-12,5,1:17.12
-11,5,1:17.12
-5,5,1:17.12
-4,5,1:17.12
1,5,1:17.12
-11,6,1:17.12
-10,6,1:17.12
-9,6,1:17.12
-8,6,1:17.12
-6,6,1:17.12
-5,6,1:17.12
-4,6,1:17.12
-3,6,1:17.12
0,6,1:17.12
1,6,1:17.12
-10,7,1:17.12
-9,7,1:17.12
-8,7,1:17.12
-7,7,1:17.12
-6,7,1:17.12
-5,7,1:17.12
-4,7,1:17.12
-2,7,1:17.12
-1,7,1:17.12
0,7,1:17.12
-8,8,1:17.12
-7,8,1:17.12
-5,8,1:17.12
-1,8,1:17.12
-9,9,1:17.12
-8,9,1:17.12
-7,9,1:17.12
-6,9,1:17.12
-5,9,1:17.12
-2,9,1:17.12
-1,9,1:17.12
-11,10,1:17.12
-10,10,1:17.12
-9,10,1:17.12
-8,10,1:17.12
-7,10,1:17.12
-6,10,1:17.12
-5,10,1:17.12
-4,10,1:17.12
-3,10,1:17.12
-2,10,1:17.12
-10,11,1:17.12
-6,11,1:17.12
-4,11,1:17.12
-3,11,1:17.12
-4,12,1:17.12
-3,12,1:17.12
-4,13,1:17.12
-3,13,1:17.12
-4,14,1:17.12
-3,14,1:17.12
-4,1,2:17.12
-3,1,2:17.12
-5,2,2:17.12
-4,2,2:17.12
-3,2,2:17.12
-2,2,2:17.12
-1,2,2:17.12
-7,3,2:17.12
-6,3,2:17.12
-5,3,2:17.12
-1,3,2:17.12
0,3,2:17.12
-9,4,2:17.12
-8,4,2:17.12
-7,4,2:17.12
-6,4,2:17.12
0,4,2:17.12
-11,5,2:17.12
-10,5,2:17.12
-9,5,2:17.12
-8,5,2:17.12
-4,5,2:17.12
1,5,2:17.12
-10,6,2:17.12
-9,6,2:17.12
-8,6,2:17.12
-7,6,2:17.12
-5,6,2:17.12
-4,6,2:17.12
0,6,2:17.12
-7,7,2:17.12
-6,7,2:17.12
-5,7,2:17.12
-4,7,2:17.12
-1,7,2:17.12
0,7,2:17.12
-7,8,2:17.12
-6,8,2:17.12
-5,8,2:17.12
-4,8,2:17.12
-2,8,2:17.12
-1,8,2:17.12
-6,9,2:17.12
-5,9,2:17.12
-4,9,2:17.12
-3,9,2:17.12
-2,9,2:17.12
-4,10,2:17.12
-3,10,2:17.12
-3,1,3:17.12
-4,2,3:17.12
-3,2,3:17.12
-2,2,3:17.12
-1,2,3:17.12
-5,3,3:17.12
-1,3,3:17.12
0,3,3:17.12
-7,4,3:17.12
-6,4,3:17.12
0,4,3:17.12
-7,5,3:17.12
-6,5,3:17.12
1,5,3:17.12
-7,6,3:17.12
-6,6,3:17.12
0,6,3:17.12
-5,7,3:17.12
-1,7,3:17.12
0,7,3:17.12
-4,8,3:17.12
-2,8,3:17.12
-1,8,3:17.12
-3,9,3:17.12
-2,9,3:17.12
-3,1,4:17.12
-4,2,4:17.12
-3,2,4:17.12
-2,2,4:17.12
-1,2,4:17.12
-5,3,4:17.12
-4,3,4:17.12
-1,3,4:17.12
0,3,4:17.12
-6,4,4:17.12
-5,4,4:17.12
0,4,4:17.12
-6,5,4:17.12
1,5,4:17.12
-6,6,4:17.12
-5,6,4:17.12
0,6,4:17.12
-5,7,4:17.12
-4,7,4:17.12
-1,7,4:17.12
0,7,4:17.12
-4,8,4:17.12
-3,8,4:17.12
-2,8,4:17.12
-1,8,4:17.12
-3,9,4:17.12
-2,0,5:17.12
-3,1,5:17.12
-2,1,5:17.12
-4,2,5:17.12
-3,2,5:17.12
-2,2,5:17.12
-1,2,5:17.12
-5,3,5:17.12
-4,3,5:17.12
-1,3,5:17.12
0,3,5:17.12
-6,4,5:17.12
-5,4,5:17.12
0,4,5:17.12
1,4,5:17.12
-6,5,5:17.12
1,5,5:17.12
-5,6,5:17.12
0,6,5:17.12
-5,7,5:17.12
-4,7,5:17.12
-1,7,5:17.12
0,7,5:17.12
-3,8,5:17.12
-2,8,5:17.12
-6,-10,6:18.6
5,-10,6:18.6
-6,-9,6:18.6
5,-9,6:18.6
-6,-8,6:18.6
3,-8,6:18.14
-5,-7,6:18.14
-2,-1,6:17.12
-3,0,6:17.12
-2,0,6:17.12
-3,1,6:17.12
-2,1,6:17.12
-1,1,6:17.12
-4,2,6:17.12
-3,2,6:17.12
-1,2,6:17.12
-4,3,6:17.12
-1,3,6:17.12
0,3,6:17.12
-5,4,6:17.12
0,4,6:17.12
1,4,6:17.12
-6,5,6:17.12
-5,5,6:17.12
1,5,6:17.12
-5,6,6:17.12
-4,6,6:17.12
0,6,6:17.12
-4,7,6:17.12
-3,7,6:17.12
-1,7,6:17.12
-3,8,6:17.12
-2,8,6:17.12
-6,-12,7:18.6
-6,-11,7:18.6
-5,-11,7:18.6
8,-11,7:18.6
6,-10,7:18.6
7,-10,7:18.6
-5,-9,7:18.6
5,-9,7:18.14
-5,-8,7:18.14
-4,-8,7:18.14
3,-8,7:18.14
4,-8,7:18.14
5,-8,7:18.14
-5,-7,7:18.14
-4,-7,7:18.14
3,-7,7:18.14
-4,-6,7:18.14
-3,-5,7:18.14
-3,-4,7:18.14
-3,-3,7:18.14
-2,-2,7:18.14
-2,-1,7:17.12
-1,-1,7:17.12
-3,0,7:17.12
-2,0,7:17.12
-1,0,7:17.12
-3,1,7:17.12
-1,1,7:17.12
0,1,7:17.12
-4,2,7:17.12
-3,2,7:17.12
-1,2,7:17.12
0,2,7:17.12
-4,3,7:17.12
0,3,7:17.12
-5,4,7:17.12
-4,4,7:17.12
0,4,7:17.12
1,4,7:17.12
-5,5,7:17.12
1,5,7:17.12
-4,6,7:17.12
0,6,7:17.12
-4,7,7:17.12
-3,7,7:17.12
-2,7,7:17.12
-1,7,7:17.12
-2,8,7:17.12
4,8,7:18.14
5,8,7:18.14
6,8,7:18.14
-5,-13,8:18.14
-4,-13,8:18.14
-5,-12,8:18.14
-4,-12,8:18.14
-5,-11,8:18.14
-4,-11,8:18.14
4,-11,8:18.14
5,-11,8:18.6
-4,-10,8:18.14
3,-10,8:18.14
4,-10,8:18.14
7,-10,8:18.6
8,-10,8:18.6
-4,-9,8:18.14
-3,-9,8:18.14
2,-9,8:18.14
3,-9,8:18.14
6,-9,8:18.6
7,-9,8:18.6
2,-8,8:18.14
3,-8,8:18.14
5,-8,8:18.14
1,-7,8:18.14
2,-7,8:18.14
3,-7,8:18.14
4,-7,8:18.14
0,-6,8:18.14
1,-6,8:18.14
3,-6,8:18.14
-2,-5,8:18.14
-1,-5,8:18.14
0,-5,8:18.14
2,-5,8:18.14
-3,-4,8:18.14
-2,-4,8:18.14
-1,-4,8:18.14
-2,-3,8:18.14
-2,-2,8:17.12
-1,-2,8:17.12
-3,-1,8:17.12
-2,-1,8:18.14
-1,-1,8:17.12
-3,0,8:17.12
-1,0,8:17.12
0,0,8:17.12
-3,1,8:17.12
-2,1,8:17.12
-1,1,8:17.12
-3,2,8:17.12
-2,2,8:17.12
-1,2,8:17.12
-4,3,8:17.12
-3,3,8:17.12
0,3,8:17.12
-5,4,8:17.12
-4,4,8:17.12
1,4,8:17.12
-5,5,8:17.12
-4,5,8:17.12
1,5,8:17.12
-4,6,8:17.12
-1,6,8:18.14
0,6,8:17.12
-3,7,8:17.12
-2,7,8:17.12
-1,7,8:17.12
2,7,8:18.14
3,7,8:18.14
-2,8,8:17.12
4,8,8:18.14
5,8,8:18.14
6,8,8:18.14
7,8,8:18.6
-3,-12,9:18.14
3,-12,9:18.14
4,-12,9:18.14
-3,-11,9:18.14
2,-11,9:18.14
3,-11,9:18.14
4,-11,9:18.14
-3,-10,9:18.14
-2,-10,9:18.14
1,-10,9:18.14
2,-10,9:18.14
3,-10,9:18.14
-3,-9,9:18.14
-2,-9,9:18.14
0,-9,9:18.14
1,-9,9:18.14
2,-9,9:18.14
7,-9,9:18.6
8,-9,9:18.6
-3,-8,9:18.14
-2,-8,9:18.14
1,-8,9:18.14
6,-8,9:18.14
7,-8,9:18.6
-2,-7,9:18.14
-1,-7,9:18.14
5,-7,9:18.14
6,-7,9:18.14
-2,-6,9:18.14
-1,-6,9:18.14
-2,-5,9:18.14
2,-5,9:18.14
-2,-4,9:18.14
1,-4,9:18.14
2,-4,9:18.14
-2,-3,9:17.12
-1,-3,9:17.12
0,-3,9:18.14
1,-3,9:18.14
-3,-2,9:17.12
-2,-2,9:17.12
-1,-2,9:18.14
0,-2,9:18.14
-3,-1,9:17.12
-2,-1,9:17.12
-1,-1,9:17.12
-2,0,9:17.12
-1,0,9:17.12
-2,1,9:17.12
-1,1,9:17.12
-3,2,9:17.12
-2,2,9:17.12
-1,2,9:17.12
0,2,9:17.12
-4,3,9:17.12
-3,3,9:17.12
0,3,9:17.12
1,3,9:17.12
-5,4,9:17.12
-4,4,9:17.12
1,4,9:17.12
-5,5,9:17.12
-4,5,9:17.12
1,5,9:17.12
-4,6,9:17.12
-3,6,9:17.12
-1,6,9:18.14
0,6,9:17.12
1,6,9:18.14
-3,7,9:17.12
-2,7,9:17.12
-1,7,9:17.12
0,7,9:18.14
1,7,9:18.14
2,7,9:18.14
-2,8,9:17.12
5,8,9:18.14
6,8,9:18.14
7,8,9:18.6
8,8,9:18.6
2,-13,10:18.14
3,-13,10:18.14
-2,-12,10:18.14
2,-12,10:18.14
3,-12,10:18.14
-2,-11,10:18.14
-6,-10,10:18.6
-2,-10,10:18.14
-1,-10,10:18.14
1,-10,10:18.14
-6,-9,10:18.6
-5,-9,10:18.14
-2,-9,10:18.14
8,-9,10:18.6
9,-9,10:18.6
-5,-8,10:18.14
7,-8,10:18.6
8,-8,10:18.6
-4,-7,10:18.14
7,-7,10:18.6
5,-6,10:18.14
6,-6,10:18.14
-3,-5,10:18.14
-2,-5,10:18.14
0,-5,10:17.12
4,-5,10:18.14
-2,-4,10:18.14
-1,-4,10:17.12
0,-4,10:17.12
1,-4,10:17.12
2,-4,10:18.14
3,-4,10:18.14
4,-4,10:18.14
-2,-3,10:18.14
-1,-3,10:17.12
0,-3,10:17.12
1,-3,10:18.14
2,-3,10:18.14
3,-3,10:18.14
4,-3,10:18.14
5,-3,10:18.14
6,-3,10:18.14
7,-3,10:18.6
8,-3,10:18.6
-2,-2,10:17.12
-1,-2,10:17.12
0,-2,10:17.12
6,-2,10:18.14
7,-2,10:18.6
8,-2,10:18.6
9,-2,10:18.6
10,-2,10:18.6
-1,-1,10:17.12
8,-1,10:18.6
9,-1,10:18.6
9,0,10:18.6
-1,1,10:17.12
-3,2,10:17.12
-2,2,10:17.12
-1,2,10:17.12
0,2,10:17.12
-4,3,10:17.12
-3,3,10:17.12
0,3,10:17.12
1,3,10:17.12
-5,4,10:17.12
-4,4,10:17.12
1,4,10:17.12
2,4,10:17.12
-4,5,10:17.12
1,5,10:17.12
-3,6,10:17.12
0,6,10:17.12
1,6,10:18.14
2,6,10:18.14
-3,7,10:17.12
-2,7,10:17.12
-1,7,10:17.12
1,7,10:18.14
2,7,10:18.14
3,7,10:18.14
4,7,10:18.14
5,7,10:18.14
6,8,10:18.14
7,8,10:18.14
-7,-15,11:18.6
-6,-15,11:18.6
-5,-9,11:18.14
-5,-8,11:18.14
-4,-7,11:18.14
7,-7,11:18.14
8,-7,11:18.14
-2,-6,11:18.14
0,-6,11:17.12
6,-6,11:18.14
-2,-5,11:18.14
0,-5,11:17.12
1,-5,11:17.12
4,-5,11:18.14
5,-5,11:18.14
7,-5,11:18.14
8,-5,11:18.14
9,-5,11:18.14
10,-5,11:18.14
11,-5,11:18.14
-2,-4,11:18.14
0,-4,11:17.12
1,-4,11:17.12
2,-4,11:18.14
3,-4,11:18.14
7,-4,11:18.14
8,-4,11:18.6
9,-4,11:18.6
10,-4,11:18.6
11,-4,11:18.6
12,-4,11:18.6
0,-3,11:17.12
1,-3,11:17.12
9,-3,11:18.6
10,-3,11:18.6
11,-3,11:18.6
12,-3,11:18.6
0,-2,11:17.12
11,-2,11:18.6
-1,1,11:17.12
-2,2,11:17.12
-1,2,11:17.12
0,2,11:17.12
-4,3,11:17.12
-3,3,11:17.12
0,3,11:17.12
1,3,11:17.12
-4,4,11:17.12
1,4,11:17.12
2,4,11:17.12
3,4,11:18.14
4,4,11:18.14
-4,5,11:17.12
-3,5,11:17.12
1,5,11:17.12
2,5,11:17.12
3,5,11:18.14
4,5,11:18.14
-3,6,11:17.12
-2,6,11:17.12
0,6,11:17.12
1,6,11:17.12
-2,7,11:17.12
-1,7,11:17.12
2,7,11:18.14
3,7,11:18.14
4,7,11:18.14
5,7,11:18.14
6,7,11:18.14
2,8,11:18.14
7,8,11:18.14
-6,-16,12:18.6
4,-16,12:18.6
-6,-15,12:18.6
-5,-15,12:18.14
-5,-14,12:18.14
-4,-14,12:18.14
-4,-13,12:18.14
-1,-13,12:17.12
-1,-12,12:17.12
10,-12,12:18.14
-1,-11,12:17.12
-6,-10,12:18.6
-1,-10,12:17.12
0,-10,12:17.12
-5,-9,12:18.14
-1,-9,12:18.14
0,-9,12:17.12
-5,-8,12:18.14
-1,-8,12:18.14
0,-8,12:17.12
-2,-7,12:18.14
0,-7,12:17.12
-2,-6,12:18.14
0,-6,12:17.12
1,-6,12:17.12
12,-6,12:18.14
-3,-5,12:18.14
-2,-5,12:18.14
-1,-5,12:18.14
0,-5,12:17.12
1,-5,12:17.12
3,-5,12:18.14
12,-5,12:18.14
-3,-4,12:18.14
0,-4,12:17.12
1,-4,12:17.12
2,-4,12:17.12
1,-3,12:17.12
-1,1,12:17.12
-2,2,12:17.12
0,2,12:17.12
-3,3,12:17.12
1,3,12:17.12
4,3,12:18.14
-4,4,12:17.12
2,4,12:17.12
4,4,12:18.14
5,4,12:18.14
-4,5,12:18.14
-3,5,12:17.12
1,5,12:17.12
2,5,12:17.12
4,5,12:18.14
5,5,12:18.14
-3,6,12:17.12
-2,6,12:17.12
0,6,12:17.12
1,6,12:17.12
5,6,12:18.14
-2,7,12:17.12
-1,7,12:17.12
0,7,12:17.12
2,8,12:18.14
3,8,12:18.14
4,8,12:18.14
-6,-19,13:18.6
4,-19,13:18.6
-6,-18,13:18.6
-6,-17,13:18.6
-5,-17,13:18.14
3,-17,13:18.14
4,-17,13:18.6
2,-16,13:18.14
3,-16,13:18.14
4,-16,13:18.6
-4,-15,13:18.14
-1,-15,13:17.12
2,-15,13:18.14
3,-15,13:18.14
-4,-14,13:18.14
-1,-14,13:17.12
1,-14,13:18.14
2,-14,13:18.14
12,-14,13:18.14
-3,-13,13:18.14
-3,-12,13:18.14
-2,-12,13:18.14
0,-12,13:18.14
10,-12,13:18.14
-7,-11,13:18.6
-6,-11,13:18.6
-2,-11,13:18.14
-1,-11,13:18.14
0,-11,13:18.14
9,-11,13:18.14
-6,-10,13:18.6
-1,-10,13:18.14
0,-10,13:18.14
-5,-9,13:18.14
-1,-9,13:18.14
0,-9,13:18.14
-5,-8,13:18.14
-4,-8,13:18.14
-1,-8,13:18.14
0,-8,13:17.12
-4,-7,13:18.14
-2,-7,13:18.14
0,-7,13:17.12
6,-7,13:18.14
7,-7,13:18.14
-3,-6,13:18.14
-2,-6,13:18.14
-1,-6,13:18.14
4,-6,13:18.14
5,-6,13:18.14
6,-6,13:18.14
-3,-5,13:18.14
-2,-5,13:18.14
1,-5,13:17.12
2,-5,13:17.12
3,-5,13:18.14
-3,-4,13:18.14
1,-4,13:17.12
2,-4,13:17.12
-1,1,13:17.12
0,1,13:17.12
-2,2,13:17.12
0,2,13:17.12
1,2,13:17.12
-3,3,13:17.12
1,3,13:17.12
2,3,13:17.12
6,3,13:18.14
-4,4,13:17.12
2,4,13:17.12
6,4,13:18.14
7,4,13:18.14
-5,5,13:18.14
-4,5,13:18.14
-3,5,13:17.12
1,5,13:17.12
2,5,13:17.12
6,5,13:18.14
7,5,13:18.14
-6,6,13:18.14
-3,6,13:17.12
-2,6,13:17.12
0,6,13:17.12
1,6,13:17.12
-8,7,13:18.14
-2,7,13:17.12
-1,7,13:17.12
0,7,13:17.12
4,8,13:18.14
5,8,13:18.14
2,9,13:18.14
3,9,13:18.14
4,9,13:18.14
3,-20,14:18.6
-5,-19,14:18.14
3,-19,14:18.14
-5,-18,14:18.14
-4,-18,14:18.14
2,-18,14:18.14
3,-18,14:18.14
-5,-17,14:18.14
-4,-17,14:18.14
-3,-17,14:18.14
1,-17,14:18.14
2,-17,14:18.14
3,-17,14:18.14
-3,-16,14:18.14
1,-16,14:18.14
2,-16,14:18.14
-3,-15,14:18.14
-2,-15,14:18.14
1,-15,14:18.14
-2,-14,14:18.14
-1,-14,14:18.14
1,-14,14:18.14
12,-14,14:18.14
13,-14,14:18.14
-1,-13,14:18.14
0,-13,14:18.14
1,-13,14:18.14
11,-13,14:18.14
12,-13,14:18.14
-1,-12,14:18.14
0,-12,14:18.14
10,-12,14:18.14
-6,-11,14:18.6
-1,-11,14:18.14
0,-11,14:18.14
9,-11,14:18.14
-6,-10,14:18.6
-1,-10,14:18.14
0,-10,14:18.14
-5,-9,14:18.14
-1,-9,14:18.14
-4,-8,14:18.14
-2,-8,14:18.14
8,-8,14:18.14
-4,-7,14:18.14
-2,-7,14:18.14
-1,-7,14:18.14
0,-7,14:18.14
5,-7,14:18.14
6,-7,14:18.14
7,-7,14:18.14
-2,-6,14:18.14
3,-6,14:18.14
4,-6,14:18.14
5,-6,14:18.14
1,-5,14:17.12
2,-5,14:17.12
-4,-4,14:18.14
2,-4,14:17.12
-1,1,14:17.12
0,1,14:17.12
-2,2,14:17.12
0,2,14:17.12
1,2,14:17.12
-3,3,14:17.12
1,3,14:17.12
2,3,14:17.12
-5,4,14:18.14
-4,4,14:17.12
2,4,14:17.12
3,4,14:17.12
-5,5,14:18.14
-4,5,14:18.14
-3,5,14:17.12
1,5,14:17.12
2,5,14:17.12
-8,6,14:18.14
-7,6,14:18.14
-6,6,14:18.14
-2,6,14:17.12
0,6,14:18.14
1,6,14:18.14
-9,7,14:18.14
-8,7,14:18.14
-1,7,14:17.12
0,7,14:17.12
1,7,14:18.14
6,8,14:18.14
3,9,14:18.14
4,9,14:18.14
5,9,14:18.14
6,9,14:18.14
7,9,14:18.14
8,9,14:18.6
9,9,14:18.6
4,10,14:18.14
2,-20,15:18.6
-4,-19,15:18.14
1,-19,15:18.14
2,-19,15:18.14
-4,-18,15:18.14
-3,-18,15:18.14
1,-18,15:18.14
2,-18,15:18.14
-3,-17,15:18.14
-2,-17,15:18.14
0,-17,15:18.14
1,-17,15:18.14
-2,-16,15:18.14
0,-16,15:18.14
-2,-15,15:18.14
-1,-15,15:18.14
-1,-14,15:18.14
13,-14,15:18.14
-1,-13,15:18.14
11,-13,15:18.14
12,-13,15:18.14
-1,-12,15:18.14
10,-12,15:18.14
-1,-11,15:18.14
9,-11,15:18.14
-6,-10,15:18.6
-5,-10,15:18.14
-1,-10,15:18.14
8,-10,15:18.14
-5,-9,15:18.14
-1,-9,15:18.14
8,-9,15:17.12
9,-9,15:18.14
-4,-8,15:18.14
-2,-8,15:18.14
-1,-8,15:18.14
0,-8,15:18.14
1,-8,15:18.14
2,-8,15:18.14
7,-8,15:18.14
8,-8,15:18.14
-2,-7,15:18.14
-1,-7,15:18.14
0,-7,15:18.14
5,-7,15:18.14
6,-7,15:18.14
-4,-6,15:18.14
-2,-6,15:18.14
2,-6,15:17.12
3,-6,15:17.12
4,-6,15:18.14
-4,-5,15:18.14
1,-5,15:18.14
2,-5,15:17.12
3,-5,15:17.12
-5,-4,15:18.14
-4,-4,15:18.14
1,-4,15:18.14
-5,-3,15:18.14
1,-1,15:18.14
0,0,15:18.14
1,0,15:18.14
-1,1,15:17.12
0,1,15:17.12
1,1,15:18.14
-2,2,15:17.12
1,2,15:17.12
-3,3,15:17.12
2,3,15:17.12
-5,4,15:18.14
-4,4,15:17.12
-3,4,15:17.12
2,4,15:17.12
3,4,15:17.12
-5,5,15:18.14
-3,5,15:17.12
1,5,15:17.12
2,5,15:17.12
-8,6,15:18.14
-7,6,15:18.14
-4,6,15:18.14
-2,6,15:17.12
0,6,15:17.12
1,6,15:17.12
-10,7,15:18.6
-9,7,15:18.6
-1,7,15:17.12
0,7,15:17.12
1,7,15:18.14
2,7,15:18.14
1,8,15:18.14
2,8,15:18.14
3,8,15:18.14
4,8,15:18.14
5,8,15:18.14
1,9,15:18.14
6,9,15:18.14
7,9,15:18.14
1,10,15:18.14
8,10,15:18.6
9,10,15:18.6
10,10,15:18.6
1,11,15:18.14
10,11,15:18.6
11,11,15:18.6
1,12,15:18.14
0,13,15:18.6
1,13,15:18.6
0,14,15:18.6
1,-21,16:18.6
-3,-19,16:18.14
-2,-17,16:18.14
13,-14,16:18.14
12,-13,16:18.14
-1,-12,16:18.14
10,-12,16:18.14
11,-12,16:18.14
10,-11,16:18.14
-1,-10,16:18.14
9,-10,16:17.12
10,-10,16:17.12
-2,-9,16:18.14
-1,-9,16:18.14
0,-9,16:18.14
1,-9,16:18.14
7,-9,16:18.14
8,-9,16:17.12
-2,-8,16:18.14
-1,-8,16:18.14
0,-8,16:18.14
6,-8,16:18.14
7,-8,16:17.12
8,-8,16:18.14
-2,-7,16:18.14
3,-7,16:18.14
4,-7,16:18.14
5,-7,16:17.12
6,-7,16:17.12
-5,-6,16:18.14
-4,-6,16:18.14
-2,-6,16:18.14
2,-6,16:17.12
3,-6,16:17.12
4,-6,16:17.12
-5,-5,16:18.14
2,-5,16:18.14
3,-5,16:17.12
-5,-4,16:18.14
2,-4,16:18.14
-6,-3,16:18.14
-5,-3,16:18.14
2,-3,16:18.14
1,0,16:18.14
2,0,16:18.14
3,0,16:18.14
4,0,16:18.14
6,0,16:18.14
7,0,16:18.14
-1,1,16:17.12
0,1,16:17.12
1,1,16:17.12
7,1,16:18.14
9,1,16:18.14
10,1,16:18.14
-5,2,16:18.14
-2,2,16:17.12
-1,2,16:17.12
1,2,16:17.12
2,2,16:17.12
-6,3,16:18.14
-5,3,16:18.14
-3,3,16:17.12
2,3,16:17.12
3,3,16:17.12
-4,4,16:17.12
-3,4,16:17.12
3,4,16:17.12
-6,5,16:18.14
-3,5,16:17.12
-2,5,16:17.12
2,5,16:17.12
-8,6,16:18.14
-7,6,16:18.14
-4,6,16:18.14
-2,6,16:17.12
-1,6,16:17.12
0,6,16:17.12
1,6,16:17.12
-10,7,16:18.6
-9,7,16:18.6
-4,7,16:18.14
-1,7,16:17.12
0,7,16:17.12
2,7,16:18.14
3,7,16:18.14
2,8,16:18.14
3,8,16:18.14
4,8,16:18.14
3,9,16:18.14
4,9,16:18.14
6,9,16:18.14
3,10,16:18.14
6,10,16:18.14
7,10,16:18.6
8,10,16:18.6
9,10,16:18.6
2,11,16:18.14
8,11,16:18.6
9,11,16:18.6
10,11,16:18.6
11,11,16:18.6
2,12,16:18.14
12,12,16:18.6
1,13,16:18.6
2,13,16:18.6
1,14,16:18.6
-1,-16,17:18.14
-1,-15,17:18.14
-1,-14,17:18.14
13,-14,17:18.14
-1,-13,17:18.14
12,-13,17:18.14
13,-13,17:18.14
-1,-12,17:18.14
11,-12,17:18.14
9,-11,17:18.14
10,-11,17:18.14
8,-10,17:18.14
9,-10,17:18.14
-2,-9,17:18.14
-1,-9,17:18.14
0,-9,17:18.14
1,-9,17:18.14
7,-9,17:18.14
8,-9,17:18.14
5,-8,17:18.14
6,-8,17:18.14
7,-8,17:18.14
8,-8,17:18.14
3,-7,17:17.12
4,-7,17:18.14
5,-7,17:18.14
6,-7,17:18.14
-5,-6,17:18.14
2,-6,17:17.12
3,-6,17:18.14
4,-6,17:18.14
-6,-5,17:18.14
-5,-5,17:18.14
3,-5,17:18.14
-6,-4,17:18.14
3,-4,17:18.14
-6,-3,17:18.14
3,-3,17:18.14
3,-2,17:18.14
2,-1,17:18.14
3,-1,17:18.14
5,-1,17:18.14
6,-1,17:18.14
7,-1,17:18.14
-1,0,17:17.12
0,0,17:17.12
2,0,17:18.14
6,0,17:18.14
7,0,17:18.14
8,0,17:18.14
9,0,17:18.14
-6,1,17:18.14
-1,1,17:17.12
0,1,17:17.12
1,1,17:17.12
11,1,17:18.14
12,1,17:18.14
-6,2,17:18.14
-2,2,17:17.12
-1,2,17:17.12
1,2,17:17.12
2,2,17:17.12
3,2,17:17.12
8,2,17:18.14
9,2,17:18.14
-6,3,17:18.14
-3,3,17:17.12
3,3,17:17.12
4,3,17:17.12
-6,4,17:18.14
-4,4,17:17.12
-3,4,17:17.12
3,4,17:17.12
-3,5,17:17.12
-2,5,17:17.12
1,5,17:17.12
2,5,17:17.12
-8,6,17:18.14
-7,6,17:18.14
-5,6,17:18.14
-2,6,17:17.12
-1,6,17:17.12
1,6,17:17.12
2,6,17:17.12
-10,7,17:18.6
-9,7,17:18.14
-4,7,17:18.14
-3,7,17:18.14
-1,7,17:17.12
0,7,17:17.12
1,7,17:17.12
-3,8,17:18.14
3,8,17:18.14
4,8,17:18.14
5,8,17:18.14
3,9,17:18.14
4,9,17:18.14
5,9,17:18.14
6,9,17:18.14
7,9,17:18.14
3,10,17:18.14
4,10,17:18.14
6,10,17:18.14
7,10,17:18.6
9,10,17:18.6
3,11,17:18.14
4,11,17:18.14
7,11,17:18.6
8,11,17:18.6
9,11,17:18.6
10,11,17:18.6
11,11,17:18.6
3,12,17:18.14
4,12,17:18.14
9,12,17:18.6
12,12,17:18.6
13,12,17:18.6
3,13,17:18.14
2,14,17:18.6
3,14,17:18.6
2,15,17:18.6
3,15,17:18.6
3,16,17:18.6
-1,-16,18:18.6
-1,-15,18:18.6
-1,-14,18:18.6
14,-14,18:18.14
-1,-13,18:18.6
12,-13,18:18.14
13,-13,18:18.14
-1,-12,18:18.14
11,-12,18:18.14
12,-12,18:18.14
10,-11,18:18.14
11,-11,18:18.14
-2,-10,18:18.14
-1,-10,18:18.14
0,-10,18:18.14
7,-10,18:18.14
8,-10,18:18.14
9,-10,18:18.14
10,-10,18:18.14
3,-9,18:18.14
7,-9,18:18.14
8,-9,18:18.14
9,-9,18:18.14
3,-8,18:18.14
6,-8,18:18.14
9,-8,18:18.14
10,-8,18:18.14
-6,-7,18:18.6
3,-7,18:17.12
4,-7,18:18.14
5,-7,18:18.14
-6,-6,18:18.6
3,-6,18:18.14
4,-6,18:18.14
-6,-5,18:18.14
3,-5,18:18.14
4,-5,18:18.14
-6,-4,18:18.14
4,-4,18:18.14
4,-3,18:18.14
3,-2,18:18.14
4,-2,18:18.14
5,-1,18:18.14
6,-1,18:18.14
7,-1,18:18.14
8,-1,18:18.14
9,-1,18:18.14
-1,0,18:17.12
0,0,18:17.12
2,0,18:18.14
-2,1,18:17.12
-1,1,18:17.12
1,1,18:17.12
14,1,18:18.14
15,1,18:18.14
-6,2,18:18.14
-2,2,18:17.12
-1,2,18:17.12
1,2,18:17.12
2,2,18:17.12
3,2,18:17.12
4,2,18:17.12
5,2,18:17.12
7,2,18:18.14
8,2,18:18.14
9,2,18:18.14
10,2,18:18.14
11,2,18:18.14
12,2,18:18.14
16,2,18:18.6
17,2,18:18.6
-7,3,18:18.14
-6,3,18:18.14
-3,3,18:17.12
-2,3,18:17.12
-1,3,18:17.12
1,3,18:17.12
4,3,18:17.12
5,3,18:17.12
-4,4,18:17.12
1,4,18:17.12
2,4,18:17.12
3,4,18:17.12
4,4,18:17.12
-3,5,18:17.12
-2,5,18:17.12
-1,5,18:17.12
1,5,18:17.12
2,5,18:17.12
3,5,18:17.12
-5,6,18:18.14
-2,6,18:17.12
-1,6,18:17.12
1,6,18:17.12
2,6,18:17.12
-5,7,18:18.14
-4,7,18:18.14
-1,7,18:17.12
0,7,18:17.12
1,7,18:17.12
-3,8,18:18.14
0,8,18:17.12
3,8,18:18.14
5,8,18:18.14
6,8,18:18.14
13,8,18:18.6
4,9,18:18.14
5,9,18:18.14
6,9,18:18.14
7,9,18:18.14
15,9,18:18.6
4,10,18:18.14
9,10,18:18.6
5,11,18:18.14
10,11,18:18.6
11,11,18:18.6
12,11,18:18.6
4,12,18:18.14
5,12,18:18.14
9,12,18:18.6
12,12,18:18.6
13,12,18:18.6
4,13,18:18.14
5,13,18:18.14
4,14,18:18.6
5,14,18:18.6
4,15,18:18.6
-1,-18,19:18.6
-1,-17,19:18.6
-1,-16,19:18.6
-1,-15,19:18.6
-1,-14,19:18.6
2,-14,19:18.6
14,-14,19:18.14
-1,-13,19:18.6
3,-13,19:18.6
13,-13,19:18.14
14,-13,19:18.14
3,-12,19:18.14
10,-12,19:18.14
12,-12,19:18.14
13,-12,19:18.14
3,-11,19:18.14
7,-11,19:18.14
8,-11,19:18.14
11,-11,19:18.14
3,-10,19:18.14
8,-10,19:18.14
10,-10,19:18.14
11,-10,19:18.14
12,-10,19:18.14
13,-10,19:18.14
7,-9,19:18.14
8,-9,19:18.14
9,-9,19:18.14
10,-9,19:18.14
11,-9,19:18.14
12,-9,19:18.14
13,-9,19:18.14
-6,-8,19:18.6
3,-8,19:17.12
4,-8,19:18.14
6,-8,19:18.14
11,-8,19:18.14
12,-8,19:18.14
13,-8,19:18.14
-6,-7,19:18.6
3,-7,19:18.14
11,-7,19:18.14
12,-7,19:18.14
2,-6,19:18.14
3,-6,19:18.14
4,-6,19:18.14
15,-6,19:18.14
16,-6,19:18.14
4,-5,19:18.14
5,-5,19:18.14
14,-5,19:18.14
15,-5,19:18.14
5,-4,19:18.14
4,-3,19:18.14
5,-3,19:18.14
7,-2,19:18.14
8,-2,19:18.14
-1,-1,19:17.12
0,-1,19:17.12
3,-1,19:18.14
-2,0,19:17.12
-1,0,19:17.12
0,0,19:17.12
1,0,19:17.12
2,0,19:18.14
-2,1,19:17.12
-1,1,19:17.12
1,1,19:17.12
4,1,19:17.12
5,1,19:17.12
6,1,19:17.12
-7,2,19:18.14
-1,2,19:17.12
1,2,19:17.12
2,2,19:17.12
3,2,19:17.12
4,2,19:17.12
5,2,19:17.12
6,2,19:17.12
9,2,19:18.14
10,2,19:18.14
11,2,19:18.14
12,2,19:18.14
13,2,19:18.14
14,2,19:18.14
-7,3,19:18.14
-3,3,19:17.12
-2,3,19:17.12
-1,3,19:17.12
0,3,19:17.12
1,3,19:17.12
2,3,19:17.12
4,3,19:18.14
5,3,19:17.12
6,3,19:18.14
7,3,19:18.14
9,3,19:18.14
12,3,19:18.14
14,3,19:18.14
15,3,19:18.6
16,3,19:18.6
17,3,19:18.6
-4,4,19:17.12
-1,4,19:17.12
0,4,19:17.12
1,4,19:17.12
2,4,19:17.12
3,4,19:17.12
4,4,19:17.12
5,4,19:17.12
16,4,19:18.6
17,4,19:18.6
-4,5,19:17.12
-3,5,19:17.12
-2,5,19:17.12
-1,5,19:17.12
0,5,19:17.12
1,5,19:17.12
-3,6,19:17.12
-2,6,19:17.12
-1,6,19:17.12
2,6,19:17.12
12,6,19:18.6
13,6,19:18.6
-5,7,19:18.14
-1,7,19:17.12
0,7,19:17.12
1,7,19:17.12
2,7,19:17.12
3,7,19:18.14
7,7,19:18.14
13,7,19:18.6
14,7,19:18.6
15,7,19:18.6
16,7,19:18.6
-4,8,19:18.14
0,8,19:17.12
1,8,19:17.12
3,8,19:18.14
4,8,19:18.14
7,8,19:18.14
14,8,19:18.6
15,8,19:18.6
16,8,19:18.6
17,8,19:18.6
4,9,19:18.14
7,9,19:18.14
4,10,19:18.14
5,10,19:18.14
7,10,19:18.14
5,11,19:18.14
12,11,19:18.6
13,12,19:18.6
-1,-19,20:18.6
-1,-18,20:18.6
-1,-17,20:18.6
-1,-16,20:18.6
-1,-15,20:18.6
16,-14,20:18.6
-1,-13,20:18.6
3,-13,20:18.6
8,-13,20:18.14
9,-13,20:18.14
10,-13,20:18.14
14,-13,20:18.14
15,-13,20:18.6
3,-12,20:18.14
7,-12,20:18.14
8,-12,20:18.14
9,-12,20:18.14
10,-12,20:18.14
13,-12,20:18.14
14,-12,20:18.14
14,-11,20:18.14
15,-11,20:18.6
9,-10,20:18.14
10,-10,20:18.14
11,-10,20:18.14
14,-10,20:18.14
15,-10,20:18.14
7,-9,20:18.14
10,-9,20:18.14
11,-9,20:18.14
13,-9,20:18.14
14,-9,20:18.14
15,-9,20:18.14
3,-8,20:18.14
4,-8,20:18.14
5,-8,20:18.14
6,-8,20:18.14
11,-8,20:18.14
12,-8,20:18.14
13,-8,20:18.14
14,-8,20:18.14
2,-7,20:18.14
5,-7,20:18.14
13,-7,20:18.14
18,-7,20:18.6
3,-6,20:18.14
4,-6,20:18.14
13,-6,20:18.14
14,-6,20:18.14
16,-6,20:18.14
18,-6,20:18.6
4,-5,20:18.14
14,-5,20:18.14
15,-5,20:18.14
16,-5,20:18.14
4,-4,20:18.14
5,-4,20:18.14
14,-4,20:18.14
8,-3,20:18.14
-1,-2,20:17.12
4,-2,20:18.14
-1,-1,20:17.12
0,-1,20:17.12
3,-1,20:18.14
-2,0,20:17.12
1,0,20:17.12
2,0,20:18.14
6,0,20:17.12
7,0,20:17.12
8,0,20:17.12
-2,1,20:17.12
-1,1,20:17.12
0,1,20:17.12
1,1,20:17.12
4,1,20:17.12
5,1,20:17.12
6,1,20:17.12
7,1,20:17.12
8,1,20:17.12
-1,2,20:17.12
0,2,20:17.12
3,2,20:17.12
4,2,20:17.12
6,2,20:17.12
7,2,20:17.12
-4,3,20:17.12
-3,3,20:17.12
-2,3,20:17.12
-1,3,20:17.12
0,3,20:17.12
2,3,20:17.12
3,3,20:17.12
4,3,20:17.12
5,3,20:17.12
6,3,20:17.12
7,3,20:18.14
8,3,20:18.14
9,3,20:18.14
10,3,20:18.14
11,3,20:18.14
-4,4,20:17.12
-1,4,20:17.12
0,4,20:17.12
1,4,20:17.12
6,4,20:18.14
7,4,20:18.14
10,4,20:18.14
12,4,20:18.14
13,4,20:18.14
14,4,20:18.6
15,4,20:18.6
16,4,20:18.6
-4,5,20:17.12
-3,5,20:17.12
-2,5,20:17.12
-1,5,20:17.12
0,5,20:17.12
1,5,20:17.12
2,5,20:17.12
8,5,20:18.14
9,5,20:18.14
10,5,20:18.14
12,5,20:18.14
15,5,20:18.6
16,5,20:18.6
-3,6,20:17.12
-2,6,20:17.12
-1,6,20:17.12
0,6,20:17.12
2,6,20:17.12
7,6,20:18.14
8,6,20:18.14
9,6,20:18.14
10,6,20:18.14
14,6,20:18.6
15,6,20:18.6
-6,7,20:18.14
-5,7,20:18.14
-1,7,20:17.12
0,7,20:17.12
2,7,20:17.12
3,7,20:18.14
8,7,20:18.14
9,7,20:18.14
10,7,20:18.14
-4,8,20:18.14
0,8,20:17.12
1,8,20:17.12
2,8,20:17.12
4,8,20:18.14
8,8,20:18.14
9,8,20:18.14
4,9,20:18.14
9,9,20:18.6
5,10,20:18.14
8,10,20:18.14
5,11,20:18.14
7,11,20:18.14
8,11,20:18.14
9,11,20:18.6
4,12,20:18.14
5,12,20:18.14
-1,-16,21:18.6
-1,-15,21:18.6
11,-15,21:18.6
12,-15,21:18.6
3,-14,21:18.6
9,-14,21:18.6
10,-14,21:18.6
11,-14,21:18.6
16,-14,21:18.6
17,-14,21:18.6
-1,-13,21:18.6
3,-13,21:18.6
7,-13,21:18.6
8,-13,21:18.6
9,-13,21:18.6
15,-13,21:18.6
16,-13,21:18.6
14,-12,21:18.14
15,-12,21:18.14
4,-11,21:18.14
13,-11,21:18.14
4,-10,21:18.14
8,-10,21:18.14
9,-10,21:18.14
10,-10,21:18.14
11,-10,21:18.14
12,-10,21:18.14
13,-10,21:18.14
6,-9,21:18.14
7,-9,21:18.14
8,-9,21:18.14
3,-8,21:18.14
4,-8,21:17.12
6,-8,21:18.14
7,-8,21:18.14
8,-8,21:18.14
9,-8,21:18.14
13,-8,21:18.14
1,-7,21:18.14
2,-7,21:18.14
5,-7,21:18.14
13,-7,21:18.14
14,-7,21:18.14
19,-7,21:18.6
4,-6,21:18.14
14,-6,21:18.14
15,-6,21:18.14
18,-6,21:18.6
19,-6,21:18.6
15,-5,21:18.14
16,-5,21:18.14
5,-4,21:18.14
14,-4,21:18.14
15,-4,21:18.14
5,-3,21:18.14
13,-3,21:18.14
14,-3,21:18.14
-1,-2,21:17.12
0,-2,21:17.12
4,-2,21:18.14
5,-2,21:18.14
9,-2,21:17.12
10,-2,21:17.12
12,-2,21:18.14
-2,-1,21:17.12
-1,-1,21:17.12
0,-1,21:17.12
1,-1,21:17.12
3,-1,21:18.14
4,-1,21:18.14
8,-1,21:17.12
9,-1,21:17.12
10,-1,21:17.12
-2,0,21:17.12
-1,0,21:17.12
0,0,21:17.12
1,0,21:18.14
2,0,21:18.14
6,0,21:17.12
7,0,21:17.12
8,0,21:17.12
9,0,21:17.12
-1,1,21:17.12
0,1,21:17.12
5,1,21:17.12
6,1,21:17.12
7,1,21:17.12
8,1,21:17.12
9,1,21:17.12
0,2,21:17.12
4,2,21:17.12
5,2,21:17.12
6,2,21:17.12
7,2,21:17.12
8,2,21:18.14
10,2,21:18.14
-4,3,21:17.12
-3,3,21:17.12
-2,3,21:17.12
4,3,21:17.12
9,3,21:18.14
-5,4,21:17.12
-4,4,21:17.12
-2,4,21:17.12
-1,4,21:17.12
10,4,21:18.14
12,4,21:18.14
13,4,21:18.14
-5,5,21:17.12
-4,5,21:17.12
-2,5,21:17.12
0,5,21:17.12
1,5,21:17.12
2,5,21:17.12
8,5,21:18.14
9,5,21:18.14
11,5,21:18.14
12,5,21:18.14
13,5,21:18.14
-3,6,21:17.12
0,6,21:17.12
2,6,21:17.12
9,6,21:18.14
10,6,21:18.14
11,6,21:18.14
12,6,21:18.6
-1,7,21:17.12
0,7,21:17.12
2,7,21:17.12
3,7,21:18.14
9,7,21:18.14
10,7,21:18.14
11,7,21:18.6
12,7,21:18.6
0,8,21:17.12
1,8,21:17.12
2,8,21:17.12
4,8,21:18.14
9,8,21:18.14
10,8,21:18.6
1,9,21:17.12
5,9,21:18.14
5,10,21:18.14
6,10,21:18.14
6,11,21:18.14
8,11,21:18.14
9,11,21:18.6
5,12,21:18.14
6,12,21:18.14
7,12,21:18.14
8,12,21:18.14
9,12,21:18.6
4,13,21:18.14
5,13,21:18.14
-1,-15,22:18.6
3,-15,22:18.6
8,-15,22:18.6
9,-15,22:18.6
10,-15,22:18.6
3,-14,22:18.6
7,-14,22:18.6
9,-14,22:18.6
4,-13,22:18.6
16,-13,22:18.6
4,-12,22:18.14
15,-12,22:18.14
16,-12,22:18.14
4,-11,22:18.14
14,-11,22:18.14
15,-11,22:18.14
4,-10,22:18.14
8,-10,22:18.14
9,-10,22:18.14
10,-10,22:18.14
13,-10,22:18.14
14,-10,22:18.14
6,-9,22:18.14
7,-9,22:18.14
8,-9,22:18.14
0,-8,22:18.14
3,-8,22:18.14
4,-8,22:17.12
6,-8,22:18.14
7,-8,22:18.14
14,-8,22:18.14
15,-8,22:18.14
1,-7,22:18.14
2,-7,22:18.14
3,-7,22:18.14
5,-7,22:18.14
6,-7,22:18.14
15,-7,22:18.14
15,-6,22:18.14
16,-6,22:18.14
19,-6,22:18.6
20,-6,22:18.6
5,-5,22:18.14
16,-5,22:18.14
17,-5,22:18.14
18,-5,22:18.6
5,-4,22:18.14
11,-4,22:17.12
16,-4,22:18.14
17,-4,22:18.14
5,-3,22:18.14
6,-3,22:18.14
10,-3,22:17.12
11,-3,22:17.12
-1,-2,22:17.12
0,-2,22:17.12
4,-2,22:18.14
5,-2,22:18.14
6,-2,22:18.14
10,-2,22:17.12
11,-2,22:17.12
12,-2,22:18.14
-2,-1,22:17.12
-1,-1,22:18.14
0,-1,22:17.12
1,-1,22:17.12
3,-1,22:18.14
4,-1,22:18.14
6,-1,22:18.14
8,-1,22:17.12
9,-1,22:17.12
10,-1,22:18.14
11,-1,22:18.14
-2,0,22:17.12
-1,0,22:17.12
0,0,22:17.12
2,0,22:18.14
7,0,22:17.12
8,0,22:17.12
9,0,22:18.14
10,0,22:18.14
-1,1,22:17.12
0,1,22:17.12
5,1,22:17.12
6,1,22:17.12
7,1,22:17.12
8,1,22:17.12
9,1,22:18.14
8,2,22:18.14
9,2,22:18.14
10,2,22:18.14
11,2,22:18.14
-4,3,22:17.12
-3,3,22:17.12
-5,4,22:17.12
-4,4,22:17.12
-3,4,22:17.12
-2,4,22:17.12
13,4,22:18.14
-5,5,22:17.12
-4,5,22:17.12
-3,5,22:17.12
-2,5,22:17.12
1,5,22:17.12
10,5,22:18.14
14,5,22:18.6
15,5,22:18.6
-4,6,22:17.12
-3,6,22:17.12
0,6,22:17.12
1,6,22:17.12
2,6,22:17.12
10,6,22:18.14
11,6,22:18.14
0,7,22:17.12
3,7,22:17.12
4,7,22:18.14
10,7,22:18.14
11,7,22:18.6
0,8,22:17.12
1,8,22:17.12
2,8,22:17.12
3,8,22:17.12
11,8,22:18.6
12,8,22:18.6
1,9,22:17.12
2,9,22:17.12
5,9,22:18.14
6,10,22:18.14
6,11,22:18.14
7,11,22:18.14
9,12,22:18.6
10,12,22:18.6
6,13,22:18.14
7,13,22:18.14
8,13,22:18.14
9,13,22:18.6
4,-14,23:18.6
4,-13,23:18.6
4,-12,23:18.14
16,-12,23:18.14
4,-11,23:18.14
15,-11,23:18.14
6,-10,23:18.14
7,-10,23:18.14
8,-10,23:18.14
9,-10,23:18.14
10,-10,23:18.14
11,-10,23:18.14
12,-10,23:18.14
14,-10,23:18.14
3,-9,23:18.14
7,-9,23:18.14
8,-9,23:18.14
9,-9,23:18.14
10,-9,23:18.14
-1,-8,23:18.14
0,-8,23:18.14
1,-8,23:18.14
2,-8,23:18.14
3,-8,23:18.14
4,-8,23:17.12
6,-8,23:18.14
7,-8,23:18.14
15,-8,23:18.14
16,-8,23:18.14
2,-7,23:18.14
3,-7,23:18.14
4,-7,23:18.14
5,-7,23:18.14
6,-7,23:18.14
16,-7,23:18.14
16,-6,23:18.14
17,-6,23:18.14
5,-5,23:18.14
11,-5,23:17.12
12,-5,23:17.12
18,-5,23:18.6
19,-5,23:18.6
6,-4,23:18.14
11,-4,23:17.12
17,-4,23:18.14
18,-4,23:18.6
6,-3,23:18.14
15,-3,23:18.14
16,-3,23:18.14
-1,-2,23:17.12
0,-2,23:18.14
4,-2,23:18.14
6,-2,23:18.14
9,-2,23:17.12
15,-2,23:18.14
-2,-1,23:17.12
-1,-1,23:18.14
0,-1,23:17.12
3,-1,23:18.14
8,-1,23:17.12
9,-1,23:17.12
10,-1,23:17.12
11,-1,23:18.14
12,-1,23:18.14
13,-1,23:18.14
-2,0,23:17.12
-1,0,23:17.12
0,0,23:17.12
8,0,23:18.14
9,0,23:17.12
10,0,23:18.14
11,0,23:18.14
12,0,23:18.14
13,0,23:18.14
-1,1,23:18.14
8,1,23:18.14
9,1,23:18.14
10,1,23:18.14
11,1,23:18.14
12,1,23:18.14
-5,4,23:17.12
-4,4,23:17.12
-3,4,23:17.12
-2,4,23:17.12
13,4,23:18.14
-6,5,23:17.12
-5,5,23:17.12
-3,5,23:17.12
-2,5,23:17.12
14,5,23:18.6
15,5,23:18.6
16,5,23:18.6
-5,6,23:17.12
-4,6,23:17.12
-3,6,23:17.12
1,6,23:17.12
2,6,23:17.12
11,6,23:18.14
17,6,23:18.6
0,7,23:17.12
1,7,23:17.12
2,7,23:17.12
3,7,23:17.12
0,8,23:17.12
3,8,23:17.12
5,8,23:18.14
12,8,23:18.6
1,9,23:17.12
2,9,23:17.12
3,9,23:17.12
2,10,23:17.12
6,14,23:18.14
7,14,23:18.14
8,14,23:18.14
4,-12,24:18.14
7,-10,24:18.14
8,-10,24:18.14
9,-10,24:18.14
10,-10,24:18.14
11,-10,24:18.14
12,-10,24:18.14
13,-10,24:18.14
3,-9,24:18.14
1,-8,24:18.14
2,-8,24:18.14
7,-8,24:18.14
17,-8,24:18.14
1,-7,24:18.14
2,-7,24:18.14
3,-7,24:18.14
17,-7,24:18.14
12,-6,24:17.12
12,-5,24:17.12
19,-5,24:18.6
-1,-4,24:18.14
6,-4,24:18.14
18,-4,24:18.6
19,-4,24:18.6
0,-3,24:18.14
1,-3,24:18.14
6,-3,24:18.14
16,-3,24:18.14
17,-3,24:18.14
18,-3,24:18.6
-1,-2,24:17.12
0,-2,24:18.14
7,-2,24:18.14
9,-2,24:17.12
10,-2,24:17.12
15,-2,24:18.14
16,-2,24:18.14
-2,-1,24:17.12
-1,-1,24:17.12
0,-1,24:17.12
1,-1,24:17.12
7,-1,24:18.14
8,-1,24:18.14
9,-1,24:18.14
10,-1,24:17.12
11,-1,24:18.14
12,-1,24:18.14
13,-1,24:18.14
14,-1,24:18.14
-1,0,24:17.12
0,0,24:17.12
10,0,24:18.14
14,0,24:18.14
-1,1,24:18.14
8,1,24:18.14
10,1,24:18.14
11,1,24:18.14
14,1,24:18.14
15,1,24:18.14
16,1,24:18.14
17,1,24:18.6
-1,2,24:18.14
15,2,24:18.14
16,2,24:18.14
17,2,24:18.6
18,2,24:18.6
16,3,24:18.14
17,3,24:18.6
18,3,24:18.6
-5,4,24:17.12
-4,4,24:17.12
17,4,24:18.6
18,4,24:18.6
-6,5,24:17.12
-5,5,24:17.12
-4,5,24:17.12
-3,5,24:17.12
14,5,24:18.6
15,5,24:18.6
16,5,24:18.6
18,5,24:18.6
-6,6,24:17.12
-5,6,24:17.12
-4,6,24:17.12
2,6,24:17.12
1,7,24:17.12
2,7,24:17.12
3,7,24:17.12
0,8,24:17.12
1,8,24:17.12
3,8,24:17.12
1,9,24:17.12
3,9,24:17.12
4,9,24:17.12
2,10,24:17.12
3,10,24:17.12
7,-11,25:18.14
8,-11,25:18.14
-4,-10,25:18.6
9,-10,25:18.14
10,-10,25:18.14
11,-10,25:18.14
12,-10,25:18.14
13,-10,25:18.14
-4,-9,25:18.6
-3,-9,25:18.6
0,-9,25:18.14
3,-9,25:18.14
-3,-8,25:18.6
1,-8,25:18.14
2,-8,25:18.14
3,-8,25:18.14
13,-8,25:17.12
-2,-7,25:18.14
12,-7,25:17.12
13,-7,25:17.12
-1,-6,25:18.14
12,-6,25:17.12
-1,-5,25:18.14
2,-5,25:18.14
3,-5,25:18.14
4,-5,25:18.14
6,-5,25:18.14
0,-4,25:18.14
1,-4,25:18.14
2,-4,25:18.14
6,-4,25:18.14
7,-4,25:18.14
0,-3,25:18.14
7,-3,25:18.14
10,-3,25:18.14
17,-3,25:18.14
18,-3,25:18.14
-1,-2,25:17.12
0,-2,25:17.12
7,-2,25:18.14
9,-2,25:17.12
10,-2,25:17.12
13,-2,25:18.14
-2,-1,25:17.12
-1,-1,25:17.12
0,-1,25:17.12
7,-1,25:18.14
8,-1,25:18.14
9,-1,25:18.14
10,-1,25:17.12
12,-1,25:18.14
17,-1,25:18.14
-1,0,25:17.12
0,0,25:17.12
10,0,25:18.14
17,0,25:18.14
18,0,25:18.14
19,0,25:18.6
-1,1,25:18.14
0,1,25:18.14
18,1,25:18.14
19,1,25:18.6
20,1,25:18.6
18,2,25:18.14
19,2,25:18.6
20,2,25:18.6
-2,3,25:18.14
19,3,25:18.6
20,3,25:18.6
21,3,25:18.6
-5,4,25:17.12
-2,4,25:18.14
20,4,25:18.6
-6,5,25:17.12
-5,5,25:17.12
-4,5,25:17.12
-3,5,25:18.14
14,5,25:18.6
-7,6,25:17.12
-6,6,25:17.12
-5,6,25:17.12
-4,6,25:17.12
-5,7,25:17.12
2,7,25:17.12
3,7,25:17.12
1,8,25:17.12
2,8,25:17.12
3,8,25:17.12
1,9,25:17.12
2,9,25:18.14
3,9,25:18.14
4,9,25:17.12
1,10,25:17.12
2,10,25:17.12
3,10,25:17.12
4,10,25:17.12
2,11,25:17.12
3,11,25:17.12
9,-11,26:18.14
11,-11,26:18.14
12,-11,26:18.14
13,-11,26:18.14
-4,-10,26:18.6
3,-10,26:18.14
12,-10,26:18.14
13,-10,26:18.14
-3,-9,26:18.6
-2,-9,26:18.6
3,-9,26:18.14
-2,-8,26:18.6
1,-8,26:18.14
2,-8,26:18.14
3,-8,26:18.14
12,-8,26:18.14
-2,-7,26:18.14
-1,-7,26:18.14
6,-7,26:18.14
7,-7,26:18.14
12,-7,26:18.14
4,-6,26:18.14
5,-6,26:18.14
6,-6,26:18.14
11,-6,26:18.14
0,-5,26:18.14
1,-5,26:18.14
2,-5,26:18.14
3,-5,26:18.14
7,-5,26:18.14
11,-5,26:18.14
0,-4,26:18.14
7,-4,26:18.14
10,-4,26:18.14
11,-4,26:18.14
10,-3,26:17.12
-1,-2,26:17.12
0,-2,26:17.12
9,-2,26:18.14
10,-2,26:17.12
11,-2,26:17.12
13,-2,26:18.14
16,-2,26:18.14
-2,-1,26:17.12
-1,-1,26:17.12
0,-1,26:17.12
7,-1,26:18.14
9,-1,26:18.14
10,-1,26:18.14
-2,0,26:18.14
-1,0,26:17.12
0,0,26:17.12
10,0,26:18.14
20,0,26:18.14
21,0,26:18.6
22,0,26:18.6
-1,1,26:18.14
0,1,26:18.14
21,1,26:18.6
-2,4,26:18.14
-6,5,26:17.12
-5,5,26:17.12
-3,5,26:18.14
-7,6,26:17.12
-6,6,26:17.12
-5,6,26:17.12
-6,7,26:17.12
-5,7,26:17.12
2,8,26:17.12
3,8,26:17.12
1,9,26:17.12
2,9,26:17.12
3,9,26:17.12
4,9,26:17.12
1,10,26:17.12
2,10,26:17.12
3,10,26:18.14
4,10,26:17.12
2,11,26:17.12
3,11,26:17.12
-3,-11,27:18.6
11,-11,27:18.14
12,-11,27:18.14
13,-11,27:18.14
14,-11,27:18.14
-3,-10,27:18.6
-2,-10,27:18.6
3,-10,27:18.14
-2,-9,27:18.6
-1,-8,27:18.6
12,-8,27:18.14
4,-7,27:18.14
5,-7,27:18.14
12,-7,27:18.14
3,-6,27:18.14
4,-6,27:18.14
11,-6,27:18.14
0,-5,27:18.14
11,-5,27:18.14
0,-3,27:17.12
10,-3,27:17.12
11,-3,27:17.12
14,-3,27:18.14
15,-3,27:18.14
16,-3,27:18.14
17,-3,27:18.14
-1,-2,27:17.12
0,-2,27:17.12
1,-2,27:17.12
10,-2,27:17.12
11,-2,27:17.12
12,-2,27:18.14
13,-2,27:18.14
14,-2,27:18.14
-3,-1,27:18.14
-1,-1,27:17.12
0,-1,27:17.12
5,-1,27:18.14
6,-1,27:18.14
7,-1,27:18.14
11,-1,27:18.14
-2,0,27:18.14
-1,0,27:17.12
0,0,27:17.12
11,0,27:18.14
-1,1,27:18.14
1,1,27:18.14
-2,2,27:18.14
-2,3,27:18.14
-6,5,27:17.12
-5,5,27:17.12
-3,5,27:18.14
-7,6,27:17.12
-6,6,27:17.12
-5,6,27:17.12
-6,7,27:17.12
-5,7,27:17.12
2,9,27:17.12
3,9,27:17.12
4,9,27:17.12
2,10,27:17.12
3,10,27:18.14
4,10,27:17.12
2,11,27:18.14
3,11,27:17.12
4,11,27:17.12
-3,-12,28:18.6
-3,-11,28:18.6
-2,-11,28:18.6
-2,-10,28:18.6
-1,-10,28:18.6
-1,-9,28:18.6
-1,-8,28:18.6
0,-8,28:18.6
4,-8,28:18.6
5,-8,28:18.6
6,-8,28:18.6
7,-8,28:18.14
12,-8,28:18.14
2,-7,28:18.14
3,-7,28:18.14
4,-7,28:18.14
12,-7,28:18.14
11,-6,28:18.14
0,-5,28:18.14
11,-5,28:18.14
0,-4,28:18.14
11,-4,28:17.12
-1,-3,28:17.12
0,-3,28:17.12
10,-3,28:17.12
11,-3,28:17.12
12,-3,28:18.14
13,-3,28:18.14
14,-3,28:18.14
15,-3,28:18.14
16,-3,28:18.14
17,-3,28:18.14
-4,-2,28:18.14
-1,-2,28:17.12
0,-2,28:17.12
1,-2,28:17.12
9,-2,28:18.14
10,-2,28:18.14
11,-2,28:17.12
12,-2,28:17.12
-3,-1,28:18.14
-1,-1,28:17.12
0,-1,28:17.12
4,-1,28:18.14
5,-1,28:18.14
6,-1,28:18.14
11,-1,28:17.12
12,-1,28:17.12
-3,0,28:18.14
-2,0,28:18.14
12,0,28:18.14
-2,1,28:18.14
0,1,28:18.14
1,1,28:18.14
2,1,28:18.14
3,1,28:18.14
12,1,28:18.14
-2,2,28:18.14
-2,3,28:18.14
-3,4,28:18.14
-6,5,28:17.12
-5,5,28:17.12
-3,5,28:18.14
-6,6,28:17.12
-5,6,28:17.12
-4,6,28:17.12
-3,6,28:18.14
-6,7,28:18.14
-5,7,28:17.12
3,9,28:17.12
4,9,28:17.12
2,10,28:17.12
3,10,28:17.12
4,10,28:17.12
5,10,28:17.12
3,11,28:18.14
4,11,28:18.14
5,11,28:18.14
2,12,28:18.14
-2,-12,29:18.6
-2,-11,29:18.6
-1,-11,29:18.6
-1,-10,29:18.6
5,-9,29:18.6
6,-9,29:18.6
7,-9,29:18.6
13,-9,29:18.14
3,-8,29:18.14
4,-8,29:18.14
5,-8,29:18.6
12,-8,29:18.14
12,-7,29:18.14
1,-6,29:18.14
11,-6,29:18.14
0,-5,29:18.14
11,-5,29:18.14
0,-4,29:18.14
11,-4,29:18.14
12,-4,29:17.12
16,-4,29:18.14
17,-4,29:18.14
18,-4,29:18.14
19,-4,29:18.14
20,-4,29:18.14
-1,-3,29:17.12
0,-3,29:17.12
9,-3,29:18.14
11,-3,29:17.12
12,-3,29:17.12
13,-3,29:18.14
14,-3,29:18.14
15,-3,29:18.14
16,-3,29:18.14
-1,-2,29:17.12
0,-2,29:17.12
1,-2,29:17.12
5,-2,29:18.14
6,-2,29:18.14
7,-2,29:18.14
8,-2,29:18.14
9,-2,29:18.14
12,-2,29:17.12
-4,-1,29:18.14
-3,-1,29:18.14
-1,-1,29:18.14
0,-1,29:17.12
3,-1,29:18.14
4,-1,29:18.14
12,-1,29:17.12
13,-1,29:17.12
14,-1,29:17.12
-3,0,29:18.14
12,0,29:18.14
14,0,29:17.12
1,1,29:18.14
2,1,29:18.14
3,1,29:18.14
12,1,29:18.14
13,1,29:18.14
-2,2,29:18.14
0,2,29:18.14
13,2,29:18.14
-2,3,29:18.14
-3,4,29:18.14
-6,5,29:17.12
-5,5,29:17.12
-3,5,29:18.14
-6,6,29:17.12
-5,6,29:18.14
-4,6,29:17.12
-6,7,29:18.14
-5,7,29:18.14
-6,8,29:18.14
3,9,29:17.12
4,9,29:17.12
5,9,29:17.12
3,10,29:17.12
5,10,29:17.12
3,11,29:18.14
4,11,29:18.14
5,12,29:18.14
6,12,29:18.14
2,13,29:18.14
7,13,29:18.14
8,13,29:18.14
1,14,29:18.14
9,14,29:18.14
10,14,29:18.14
0,15,29:18.14
-1,-12,30:18.6
-1,-11,30:18.6
5,-10,30:18.6
5,-9,30:18.6
13,-9,30:18.14
12,-8,30:18.14
1,-7,30:18.14
12,-7,30:18.14
1,-6,30:18.14
12,-6,30:18.14
0,-5,30:18.14
11,-5,30:18.14
0,-4,30:18.14
12,-4,30:17.12
13,-4,30:18.14
15,-4,30:18.14
16,-4,30:18.14
17,-4,30:18.14
18,-4,30:18.14
19,-4,30:18.14
-1,-3,30:17.12
0,-3,30:17.12
1,-3,30:17.12
9,-3,30:18.14
10,-3,30:18.14
-1,-2,30:17.12
0,-2,30:17.12
1,-2,30:17.12
4,-2,30:18.14
6,-2,30:18.14
7,-2,30:18.14
11,-2,30:18.14
-4,-1,30:18.14
-1,-1,30:18.14
12,-1,30:18.14
14,-1,30:17.12
-4,0,30:18.14
-3,0,30:18.14
-1,0,30:18.14
12,0,30:18.14
13,0,30:18.14
14,0,30:17.12
15,0,30:17.12
16,0,30:17.12
13,1,30:18.14
16,1,30:17.12
0,2,30:18.14
1,2,30:18.14
2,2,30:18.14
14,2,30:18.14
14,3,30:18.14
-6,5,30:17.12
-5,5,30:17.12
-6,6,30:17.12
-5,6,30:18.14
-4,6,30:18.14
-5,7,30:18.14
-5,9,30:18.14
4,9,30:17.12
5,9,30:17.12
-6,10,30:18.14
3,10,30:17.12
4,10,30:17.12
5,10,30:17.12
-6,11,30:18.14
4,11,30:18.14
5,11,30:17.12
-6,12,30:18.6
4,12,30:18.14
7,13,30:18.14
8,13,30:18.14
2,14,30:18.14
8,14,30:18.14
9,14,30:18.14
10,14,30:18.14
1,15,30:18.14
11,15,30:18.6
0,16,30:18.6
-1,17,30:18.6
4,-10,31:18.6
5,-10,31:18.6
12,-8,31:18.14
12,-7,31:18.14
1,-6,31:18.14
12,-6,31:18.14
0,-5,31:18.14
13,-5,31:17.12
0,-4,31:18.14
13,-4,31:17.12
15,-4,31:18.14
16,-4,31:18.14
17,-4,31:18.14
-1,-3,31:17.12
0,-3,31:17.12
1,-3,31:17.12
6,-3,31:18.14
7,-3,31:18.14
8,-3,31:18.14
9,-3,31:18.14
10,-3,31:18.14
-1,-2,31:17.12
0,-2,31:17.12
1,-2,31:17.12
5,-2,31:18.14
12,-2,31:18.14
-1,-1,31:18.14
12,-1,31:18.14
-4,0,31:18.14
-1,0,31:18.14
13,0,31:18.14
13,1,31:18.14
14,1,31:18.14
17,1,31:17.12
0,2,31:18.14
1,2,31:18.14
2,2,31:18.14
-6,5,31:17.12
-5,5,31:17.12
-6,6,31:18.14
-5,6,31:17.12
-3,6,31:18.14
-2,6,31:18.14
-1,6,31:18.14
0,6,31:18.14
1,6,31:18.14
-6,7,31:18.14
-5,7,31:18.14
-4,7,31:18.14
4,9,31:17.12
5,9,31:17.12
-5,10,31:18.14
4,10,31:17.12
5,10,31:17.12
6,10,31:17.12
-5,11,31:18.14
4,11,31:17.12
5,11,31:17.12
-6,12,31:18.6
4,12,31:18.14
-6,13,31:18.6
3,13,31:18.14
4,13,31:18.14
7,13,31:18.14
3,14,31:18.14
7,14,31:18.14
8,14,31:18.14
9,14,31:18.14
1,15,31:18.14
2,15,31:18.14
10,15,31:18.14
0,16,31:18.6
1,16,31:18.6
0,17,31:18.6
1,-7,32:18.14
12,-7,32:18.14
1,-6,32:18.14
0,-5,32:18.14
13,-5,32:17.12
0,-4,32:18.14
13,-4,32:17.12
-1,-3,32:17.12
0,-3,32:17.12
1,-3,32:17.12
5,-3,32:18.14
6,-3,32:18.14
7,-3,32:18.14
8,-3,32:18.14
0,-2,32:17.12
1,-2,32:17.12
4,-2,32:18.14
-1,-1,32:18.14
13,-1,32:18.14
13,0,32:18.14
14,1,32:18.14
0,2,32:18.14
-7,5,32:18.14
-6,5,32:17.12
-5,5,32:17.12
-7,6,32:18.14
-6,6,32:18.14
-5,6,32:17.12
-1,6,32:18.14
0,6,32:18.14
1,6,32:18.14
-7,7,32:18.14
-6,7,32:17.12
-5,7,32:18.14
-4,7,32:18.14
-2,7,32:18.14
-1,7,32:18.14
-7,8,32:18.14
-5,8,32:18.14
-4,8,32:18.14
-8,9,32:18.14
-5,9,32:18.14
4,9,32:18.14
5,9,32:17.12
-8,10,32:18.14
-5,10,32:18.14
4,10,32:17.12
5,10,32:17.12
6,10,32:17.12
-5,11,32:18.14
4,11,32:17.12
5,11,32:17.12
6,11,32:17.12
4,13,32:18.14
3,14,32:18.14
4,14,32:18.14
7,14,32:18.14
8,14,32:18.14
3,15,32:18.14
9,15,32:18.14
10,15,32:18.14
11,16,32:18.6
1,17,32:18.6
0,18,32:18.6
-1,-10,33:18.14
0,-10,33:18.14
0,-9,33:18.14
12,-7,33:18.14
1,-6,33:18.14
0,-5,33:18.14
13,-5,33:17.12
0,-4,33:17.12
9,-4,33:18.14
-1,-3,33:17.12
0,-3,33:18.14
1,-3,33:17.12
4,-3,33:18.14
5,-3,33:18.14
6,-3,33:18.14
7,-3,33:18.14
0,-2,33:17.12
1,-2,33:17.12
12,-2,33:18.14
13,-1,33:18.14
14,0,33:18.14
14,1,33:18.14
-8,5,33:18.14
-7,5,33:18.14
-6,5,33:17.12
-5,5,33:17.12
-7,6,33:18.14
-6,6,33:17.12
-5,6,33:17.12
-3,7,33:18.14
-2,7,33:18.14
-1,7,33:18.14
0,7,33:18.14
-8,8,33:18.14
-4,8,33:18.14
-8,9,33:18.14
-4,9,33:18.14
4,9,33:18.14
-9,10,33:18.14
-8,10,33:18.14
-5,10,33:18.14
4,10,33:18.14
5,10,33:17.12
6,10,33:17.12
-9,11,33:18.14
-5,11,33:18.14
4,11,33:18.14
5,11,33:17.12
6,11,33:17.12
-5,12,33:18.6
5,12,33:18.14
-5,13,33:18.6
4,14,33:18.14
7,14,33:18.14
3,15,33:18.14
4,15,33:18.14
8,15,33:18.14
9,15,33:18.14
10,15,33:18.14
2,16,33:18.14
10,16,33:18.14
11,16,33:18.6
1,17,33:18.6
2,17,33:18.6
0,18,33:18.6
1,18,33:18.6
-1,-12,34:18.6
-1,-11,34:18.6
-1,-10,34:18.14
0,-9,34:18.14
0,-8,34:18.14
0,-7,34:18.14
0,-6,34:18.14
0,-5,34:18.14
-1,-4,34:17.12
0,-4,34:17.12
1,-4,34:17.12
0,-3,34:17.12
1,-3,34:17.12
2,-3,34:18.14
0,-2,34:17.12
1,-2,34:17.12
13,-2,34:18.14
13,-1,34:18.14
-11,2,34:18.6
-11,3,34:18.14
-10,3,34:18.14
-10,4,34:18.14
-7,4,34:18.14
-7,5,34:18.14
-6,5,34:18.14
-5,5,34:17.12
-8,6,34:18.14
-7,6,34:18.14
-6,6,34:17.12
-5,6,34:17.12
-8,7,34:18.14
-5,7,34:18.14
-2,7,34:18.14
-1,7,34:18.14
0,7,34:18.14
1,7,34:18.14
-4,8,34:18.14
4,8,34:18.14
-9,9,34:18.14
-4,9,34:18.14
4,9,34:18.14
-9,10,34:18.14
-4,10,34:18.14
4,10,34:18.14
5,10,34:17.12
6,10,34:17.12
-9,11,34:18.14
-4,11,34:18.14
4,11,34:18.14
5,11,34:18.14
6,11,34:17.12
-5,12,34:18.6
5,12,34:18.14
-5,13,34:18.6
5,14,34:18.14
4,15,34:18.14
5,15,34:18.14
8,15,34:18.14
9,15,34:18.14
3,16,34:18.14
4,16,34:18.14
9,16,34:18.14
10,16,34:18.14
2,17,34:18.6
1,18,34:18.6
2,18,34:18.6
1,19,34:18.6
-1,-12,35:18.14
-1,-11,35:18.14
-1,-10,35:18.14
-1,-9,35:18.14
0,-6,35:18.14
-1,-5,35:17.12
0,-5,35:17.12
-1,-4,35:17.12
0,-4,35:17.12
5,-4,35:18.14
6,-4,35:18.14
0,-3,35:17.12
1,-3,35:17.12
3,-3,35:18.14
4,-3,35:18.14
5,-3,35:18.14
0,-2,35:17.12
1,-2,35:17.12
1,-1,35:18.14
-11,3,35:18.14
-10,4,35:18.14
-8,4,35:18.14
-7,4,35:18.14
-9,5,35:18.14
-6,5,35:18.14
-5,5,35:17.12
-4,5,35:17.12
-8,6,35:18.14
-6,6,35:18.14
-5,6,35:17.12
-4,6,35:17.12
-8,7,35:18.14
-5,7,35:18.14
0,7,35:18.14
1,7,35:18.14
4,7,35:18.14
-9,8,35:18.14
-1,8,35:18.14
4,8,35:18.14
-9,9,35:18.14
4,9,35:18.14
-10,10,35:18.14
-4,10,35:18.14
4,10,35:18.14
5,10,35:17.12
6,10,35:17.12
-10,11,35:18.14
-4,11,35:18.14
5,11,35:18.14
6,11,35:17.12
-4,12,35:18.6
5,12,35:18.14
6,12,35:18.14
4,16,35:18.14
9,16,35:18.14
3,17,35:18.14
2,18,35:18.6
-1,-12,36:18.14
-1,-11,36:18.14
-1,-10,36:18.14
-1,-9,36:18.14
0,-8,36:18.14
-1,-7,36:18.14
0,-7,36:18.14
-1,-6,36:18.14
0,-6,36:18.14
1,-6,36:18.14
-1,-5,36:17.12
0,-5,36:17.12
0,-4,36:17.12
4,-3,36:18.14
5,-3,36:18.14
6,-3,36:18.14
1,-2,36:17.12
2,-2,36:18.14
1,-1,36:17.12
2,-1,36:18.14
1,0,36:18.14
1,1,36:18.14
2,1,36:18.14
-12,2,36:18.6
2,2,36:18.14
-12,3,36:18.6
-11,3,36:18.14
-11,4,36:18.14
-10,4,36:18.14
-10,5,36:18.14
-9,5,36:18.14
-7,5,36:18.14
-6,5,36:18.14
-5,5,36:17.12
-4,5,36:17.12
-6,6,36:18.14
-5,6,36:17.12
-4,6,36:17.12
-9,7,36:18.14
4,7,36:18.14
-9,8,36:18.14
0,8,36:18.14
-10,9,36:18.14
4,9,36:18.14
-10,10,36:18.14
4,10,36:18.14
5,10,36:18.14
6,10,36:17.12
-11,11,36:18.14
-10,11,36:18.14
5,11,36:18.14
6,11,36:17.12
7,11,36:18.14
6,12,36:18.14
7,13,36:18.14
9,16,36:18.14
-1,-11,37:18.14
-1,-10,37:18.14
-1,-9,37:18.14
-2,-7,37:18.14
1,-7,37:18.14
-3,-6,37:18.14
-2,-6,37:18.14
-1,-6,37:17.12
0,-6,37:17.12
1,-6,37:18.14
-1,-5,37:17.12
0,-5,37:17.12
6,-3,37:18.14
7,-3,37:18.6
1,-2,37:17.12
2,-2,37:18.14
3,-2,37:18.14
4,-2,37:18.14
5,-2,37:18.14
1,-1,37:17.12
2,-1,37:17.12
2,0,37:18.14
2,1,37:18.14
2,2,37:18.14
-12,3,37:18.6
2,3,37:18.14
-11,4,37:18.14
-6,5,37:18.14
-5,5,37:17.12
-4,5,37:18.14
-7,6,37:18.14
-6,6,37:17.12
-5,6,37:17.12
-4,6,37:17.12
-9,7,37:18.14
-5,7,37:18.14
-10,8,37:18.14
-10,9,37:18.14
4,9,37:18.14
9,9,37:18.14
-11,10,37:18.14
-10,10,37:18.14
5,10,37:18.14
6,10,37:17.12
7,10,37:17.12
8,10,37:18.14
9,10,37:18.14
-11,11,37:18.14
5,11,37:18.14
6,11,37:17.12
7,11,37:18.14
5,12,37:18.14
6,12,37:17.12
7,13,37:18.14
7,14,37:18.14
8,15,37:18.14
8,16,37:18.14
-1,-10,38:18.14
-2,-9,38:18.14
-3,-8,38:18.14
-2,-8,38:18.14
0,-8,38:18.14
1,-8,38:18.14
-4,-7,38:18.14
-3,-7,38:18.14
1,-7,38:18.14
2,-7,38:18.14
-4,-6,38:18.14
-1,-6,38:17.12
0,-6,38:17.12
0,-3,38:18.14
6,-3,38:18.14
7,-3,38:18.14
2,-2,38:17.12
4,-2,38:18.14
5,-2,38:18.14
6,-2,38:18.14
1,-1,38:17.12
2,-1,38:18.14
3,-1,38:18.14
4,-1,38:18.14
2,0,38:18.14
3,0,38:18.14
3,1,38:18.14
2,2,38:18.14
3,2,38:18.14
2,3,38:18.14
3,3,38:18.14
-12,4,38:18.6
-5,5,38:17.12
-4,5,38:18.14
-3,5,38:18.14
-7,6,38:18.14
-6,6,38:17.12
-5,6,38:17.12
-4,6,38:18.14
-7,7,38:17.12
-6,7,38:17.12
-5,7,38:18.14
-4,7,38:18.14
-3,7,38:18.14
-10,8,38:18.14
4,8,38:18.14
11,8,38:18.14
6,9,38:17.12
10,9,38:18.14
5,10,38:18.14
6,10,38:17.12
7,10,38:17.12
9,10,38:18.14
5,11,38:18.14
6,11,38:17.12
7,11,38:17.12
5,12,38:18.14
6,12,38:17.12
7,12,38:18.14
6,13,38:18.14
8,13,38:18.14
8,14,38:18.14
8,15,38:18.14
8,16,38:18.14
-4,-9,39:18.14
-3,-9,39:18.14
1,-9,39:18.14
2,-9,39:18.14
-4,-8,39:18.14
-3,-8,39:18.14
-1,-8,39:17.12
0,-8,39:17.12
2,-8,39:18.14
-5,-7,39:18.14
-2,-7,39:18.14
-1,-7,39:18.14
0,-7,39:17.12
3,-7,39:18.14
-1,-6,39:18.14
0,-6,39:17.12
0,-3,39:18.14
1,-3,39:18.14
2,-2,39:18.14
5,-2,39:18.14
6,-2,39:18.14
2,-1,39:17.12
3,-1,39:18.14
4,-1,39:18.14
5,-1,39:18.14
2,0,39:18.14
3,1,39:18.14
3,2,39:18.14
3,3,39:18.14
-4,5,39:18.14
-3,5,39:18.14
-7,6,39:18.14
-6,6,39:18.14
-5,6,39:17.12
-4,6,39:18.14
-7,7,39:17.12
-6,7,39:17.12
-3,7,39:18.14
-3,8,39:18.14
-2,9,39:18.14
6,9,39:17.12
7,9,39:17.12
10,9,39:18.14
11,9,39:18.14
-1,10,39:18.14
6,10,39:17.12
7,10,39:17.12
9,10,39:18.14
10,10,39:18.14
5,11,39:18.14
6,11,39:17.12
6,12,39:17.12
7,12,39:17.12
8,12,39:18.14
6,13,39:17.12
7,13,39:17.12
8,13,39:18.14
8,14,39:18.14
9,15,39:18.14
9,16,39:18.14
1,-11,40:18.14
-5,-10,40:18.14
-3,-10,40:18.14
-1,-10,40:17.12
1,-10,40:18.14
2,-10,40:18.14
-5,-9,40:18.14
-4,-9,40:18.14
-3,-9,40:18.14
-1,-9,40:17.12
0,-9,40:17.12
2,-9,40:18.14
3,-9,40:18.14
-3,-8,40:18.14
-2,-8,40:18.14
-1,-8,40:17.12
0,-8,40:18.14
3,-8,40:18.14
-1,-7,40:18.14
-1,-4,40:18.14
0,-3,40:18.14
1,-3,40:18.14
2,-2,40:18.14
2,-1,40:17.12
3,-1,40:18.14
3,0,40:18.14
3,1,40:18.14
3,2,40:18.14
4,2,40:18.14
3,3,40:18.14
3,4,40:18.14
-3,5,40:18.14
-8,6,40:18.14
-7,6,40:18.14
-6,6,40:18.14
-5,6,40:17.12
-4,6,40:18.14
-3,6,40:18.14
-7,7,40:17.12
-6,7,40:18.14
7,8,40:17.12
-2,9,40:18.14
6,9,40:17.12
7,9,40:17.12
11,9,40:18.14
-1,10,40:18.14
4,10,40:18.14
6,10,40:17.12
7,10,40:17.12
10,10,40:18.14
0,11,40:18.6
5,11,40:18.14
6,11,40:18.14
7,11,40:18.14
9,11,40:18.14
6,12,40:17.12
8,12,40:18.14
6,13,40:17.12
7,13,40:17.12
8,13,40:18.14
6,14,40:17.12
9,14,40:18.14
9,15,40:18.14
9,16,40:18.14
2,-11,41:18.14
-6,-10,41:18.14
-5,-10,41:18.14
-4,-10,41:18.14
-1,-10,41:17.12
1,-10,41:18.14
-4,-9,41:18.14
-3,-9,41:18.14
-1,-9,41:17.12
0,-9,41:18.14
-1,-8,41:18.14
-1,-7,41:18.14
0,-3,41:18.14
1,-3,41:18.14
2,-2,41:18.14
2,-1,41:18.14
3,-1,41:18.14
4,-1,41:18.14
3,0,41:18.14
3,2,41:18.14
-2,3,41:18.14
-1,3,41:18.14
4,3,41:18.14
-2,4,41:18.14
4,4,41:18.14
4,5,41:18.14
-5,6,41:18.14
-4,6,41:17.12
-3,6,41:18.14
4,6,41:18.14
-7,7,41:18.14
-6,7,41:18.14
-3,7,41:18.14
-7,8,41:17.12
7,8,41:17.12
-2,9,41:18.14
-1,9,41:18.14
6,9,41:17.12
7,9,41:17.12
-1,10,41:18.14
3,10,41:18.14
4,10,41:18.14
10,10,41:18.14
11,10,41:18.14
5,11,41:18.14
6,11,41:18.14
7,11,41:18.14
8,12,41:18.14
6,13,41:17.12
7,13,41:17.12
9,13,41:18.14
6,14,41:17.12
7,14,41:17.12
9,14,41:18.14
9,15,41:18.14
2,-12,42:18.14
-6,-11,42:18.14
-5,-11,42:18.14
-2,-11,42:17.12
-1,-11,42:17.12
1,-11,42:18.14
2,-11,42:18.14
-4,-10,42:18.14
-3,-10,42:18.14
-1,-10,42:17.12
0,-10,42:18.14
1,-10,42:18.14
-3,-9,42:18.14
-2,-9,42:18.14
-1,-9,42:18.14
-1,-7,42:18.14
1,-3,42:18.14
8,-3,42:18.6
2,-2,42:18.14
3,-2,42:17.12
6,-2,42:18.14
7,-2,42:18.14
2,-1,42:18.14
3,-1,42:18.14
5,-1,42:18.14
3,0,42:18.14
4,1,42:18.14
-1,2,42:18.14
0,2,42:18.14
4,2,42:18.14
-1,3,42:18.14
4,3,42:18.14
-2,4,42:18.14
-1,4,42:18.14
4,4,42:18.14
4,5,42:18.14
-6,6,42:18.14
-5,6,42:18.14
-4,6,42:17.12
-7,7,42:18.14
-3,7,42:18.14
-2,7,42:18.14
-7,8,42:18.14
-6,8,42:18.14
-5,8,42:18.14
7,8,42:17.12
8,8,42:17.12
-1,9,42:18.14
7,9,42:17.12
8,9,42:17.12
-1,10,42:18.14
0,10,42:18.14
11,10,42:18.14
0,11,42:18.6
5,11,42:18.14
6,11,42:18.14
7,11,42:18.14
6,14,42:17.12
7,14,42:17.12
6,15,42:17.12
7,15,42:18.14
1,-12,43:18.14
2,-12,43:18.14
-5,-11,43:18.14
-4,-11,43:18.14
-2,-11,43:17.12
0,-11,43:18.14
1,-11,43:18.14
-3,-10,43:18.14
-2,-10,43:18.14
0,-10,43:18.14
-1,-7,43:18.14
-1,-6,43:18.14
8,-3,43:18.6
2,-2,43:17.12
3,-2,43:17.12
6,-2,43:18.14
7,-2,43:18.14
1,-1,43:18.14
5,-1,43:18.14
6,-1,43:18.14
4,1,43:18.14
4,2,43:18.14
-1,3,43:18.14
0,3,43:18.14
4,3,43:18.14
-1,4,43:18.14
4,4,43:18.14
-2,5,43:18.14
5,5,43:18.14
-8,6,43:18.14
-7,6,43:18.14
-6,6,43:18.14
-5,6,43:18.14
-4,6,43:18.14
5,6,43:18.14
-8,7,43:18.14
-7,7,43:18.14
-2,7,43:18.14
7,7,43:18.14
8,7,43:17.12
-7,8,43:18.14
-5,8,43:18.14
-4,8,43:18.14
-1,8,43:18.14
7,8,43:17.12
8,8,43:17.12
9,8,43:17.12
-8,9,43:18.14
-1,9,43:18.14
7,9,43:17.12
8,9,43:17.12
-9,10,43:18.14
-8,10,43:18.14
0,10,43:18.14
4,10,43:18.14
-9,11,43:18.14
0,11,43:18.6
5,11,43:18.14
6,11,43:18.14
7,11,43:18.14
-10,12,43:18.14
6,14,43:17.12
7,14,43:18.14
6,15,43:17.12
7,15,43:18.14
7,16,43:18.14
-5,-12,44:18.14
0,-12,44:18.14
1,-12,44:18.14
-4,-11,44:18.14
-3,-11,44:18.14
-2,-10,44:18.14
-1,-8,44:18.14
-1,-7,44:18.14
-1,-6,44:18.14
3,-2,44:17.12
7,-2,44:18.14
8,-2,44:18.6
0,-1,44:18.14
1,-1,44:18.14
2,-1,44:18.14
5,-1,44:18.14
6,-1,44:18.14
3,0,44:18.14
4,1,44:18.14
0,2,44:18.14
4,2,44:18.14
0,3,44:18.14
4,3,44:18.14
5,3,44:18.14
8,3,44:18.14
-1,4,44:18.14
5,4,44:18.14
5,5,44:18.14
8,5,44:18.14
-8,6,44:18.14
-7,6,44:18.14
-6,6,44:18.14
-5,6,44:18.14
-4,6,44:18.14
5,6,44:18.14
7,6,44:18.14
-2,7,44:18.14
7,7,44:17.12
8,7,44:17.12
9,7,44:17.12
-7,8,44:18.14
-6,8,44:18.14
-4,8,44:18.14
-3,8,44:18.14
-1,8,44:18.14
7,8,44:18.14
8,8,44:17.12
9,8,44:17.12
10,8,44:17.12
-8,9,44:17.12
-1,9,44:18.14
-9,10,44:18.14
-8,10,44:18.14
0,10,44:18.14
-9,11,44:18.14
7,14,44:18.14
6,15,44:18.14
7,15,44:18.14
6,16,44:17.12
7,16,44:17.12
6,17,44:17.12
7,17,44:17.12
8,17,44:18.14
8,18,44:18.14
8,19,44:18.14
0,-12,45:18.14
-1,-8,45:18.14
-1,-7,45:18.14
-1,-6,45:18.14
-1,-5,45:18.14
-1,-2,45:18.14
8,-2,45:18.6
9,-2,45:18.6
0,-1,45:18.14
1,-1,45:18.14
7,-1,45:18.14
2,0,45:18.14
3,0,45:18.14
4,1,45:18.14
5,2,45:18.14
8,2,45:18.6
0,3,45:18.14
5,3,45:18.14
8,3,45:18.14
-1,4,45:18.14
0,4,45:18.14
5,4,45:18.14
-9,5,45:18.14
-1,5,45:18.14
5,5,45:18.14
8,5,45:18.14
-9,6,45:18.14
-8,6,45:18.14
-7,6,45:18.14
-6,6,45:18.14
-5,6,45:18.14
-8,7,45:18.14
7,7,45:17.12
8,7,45:17.12
9,7,45:17.12
10,7,45:17.12
-1,8,45:18.14
6,8,45:18.14
7,8,45:17.12
8,8,45:18.14
9,8,45:17.12
10,8,45:17.12
-7,9,45:18.14
-6,9,45:18.14
-5,9,45:18.14
-4,9,45:18.14
-3,9,45:18.14
-2,9,45:18.14
-9,10,45:18.14
-8,10,45:18.14
-9,11,45:18.14
-10,12,45:18.14
-10,13,45:18.14
7,14,45:18.14
4,15,45:18.14
5,15,45:18.14
6,15,45:18.14
7,15,45:18.14
7,16,45:18.14
7,17,45:17.12
7,18,45:17.12
8,18,45:18.14
8,19,45:18.14
9,19,45:18.14
-1,-9,46:18.14
-1,-8,46:18.14
-1,-7,46:18.14
-1,-2,46:18.14
0,-1,46:18.14
1,-1,46:18.14
7,-1,46:18.14
8,-1,46:18.6
2,0,46:18.14
3,0,46:18.14
8,2,46:18.6
5,3,46:18.14
0,4,46:18.14
-9,5,46:18.14
7,5,46:18.14
-9,6,46:18.14
7,6,46:18.14
-8,7,46:18.14
-7,7,46:18.14
-6,7,46:18.14
-5,7,46:18.14
-4,7,46:18.14
5,7,46:18.14
7,7,46:18.14
8,7,46:17.12
10,7,46:17.12
11,7,46:17.12
-8,8,46:18.14
7,8,46:17.12
8,8,46:18.14
-7,9,46:18.14
-6,9,46:18.14
-5,9,46:18.14
-4,9,46:18.14
-9,11,46:18.14
-10,12,46:18.14
-9,12,46:18.14
8,13,46:18.14
2,15,46:18.14
3,15,46:18.14
4,15,46:18.14
5,15,46:18.14
7,16,46:18.14
7,17,46:18.14
8,18,46:17.12
8,19,46:18.14
-1,-9,47:18.14
-1,-8,47:18.14
-1,-7,47:18.14
0,-1,47:18.14
1,-1,47:18.14
2,0,47:18.14
3,0,47:18.14
7,0,47:18.14
8,2,47:18.6
8,3,47:18.14
-9,5,47:18.14
7,5,47:18.14
-9,6,47:18.14
7,6,47:18.14
12,6,47:18.14
13,6,47:18.14
-9,7,47:18.14
-5,7,47:18.14
-4,7,47:18.14
3,7,47:18.14
4,7,47:18.14
5,7,47:18.14
7,7,47:17.12
11,7,47:17.12
12,7,47:17.12
13,7,47:17.12
7,8,47:17.12
8,8,47:18.14
9,8,47:18.14
-6,9,47:18.14
-5,9,47:18.14
-4,9,47:18.14
-3,9,47:18.6
9,9,47:18.14
-9,11,47:18.14
9,12,47:18.14
8,13,47:18.14
7,14,47:18.14
8,14,47:18.14
3,15,47:18.14
4,15,47:18.14
5,15,47:18.14
5,16,47:18.14
6,16,47:18.14
7,16,47:18.14
7,17,47:18.14
7,18,47:18.14
8,18,47:18.14
8,19,47:18.6
8,20,47:18.6
1,-1,48:18.14
2,0,48:18.14
3,0,48:18.14
8,2,48:18.6
16,2,48:18.6
17,2,48:18.6
8,3,48:18.14
15,3,48:18.6
16,3,48:18.6
7,4,48:18.14
15,4,48:18.6
7,5,48:18.14
14,5,48:18.6
15,5,48:18.6
-9,6,48:18.14
6,6,48:18.14
7,6,48:18.14
13,6,48:18.14
14,6,48:17.12
-9,7,48:18.14
3,7,48:18.14
4,7,48:18.14
5,7,48:18.14
8,7,48:18.14
13,7,48:18.14
14,7,48:18.6
7,8,48:17.12
8,8,48:17.12
9,8,48:18.14
10,9,48:18.14
16,9,48:18.6
17,9,48:18.6
10,10,48:18.14
17,10,48:18.6
18,10,48:18.6
-9,11,48:18.14
9,12,48:18.14
8,13,48:18.6
7,14,48:18.6
8,14,48:18.6
7,15,48:18.6
2,16,48:18.6
3,16,48:18.6
4,16,48:18.6
5,16,48:18.6
6,16,48:18.6
7,17,48:18.6
7,18,48:18.6
8,19,48:18.6
3,0,49:18.6
18,2,49:18.6
17,3,49:18.6
18,3,49:18.6
7,4,49:18.14
16,4,49:18.6
15,5,49:17.12
16,5,49:18.6
4,6,49:18.14
5,6,49:18.14
14,6,49:18.6
15,6,49:18.6
-9,7,49:18.6
3,7,49:18.14
4,7,49:18.14
8,7,49:18.14
13,7,49:18.6
14,7,49:18.6
15,7,49:18.6
-9,8,49:18.6
8,8,49:17.12
9,8,49:18.14
16,8,49:18.6
17,8,49:18.6
10,9,49:18.14
17,9,49:18.6
18,9,49:18.6
19,10,49:18.6
8,13,49:18.6
9,13,49:18.6
8,14,49:18.6
2,16,49:18.6
3,16,49:18.6
4,16,49:18.6
7,18,49:18.6
19,2,50:18.6
18,3,50:18.6
19,3,50:18.6
17,4,50:18.6
18,4,50:18.6
16,5,50:18.6
17,5,50:18.6
3,6,50:18.6
4,6,50:18.6
5,6,50:18.6
14,6,50:18.6
16,6,50:18.6
17,6,50:18.6
8,7,50:18.6
9,7,50:18.6
17,7,50:18.6
8,8,50:17.12
9,8,50:18.6
10,8,50:18.6
17,8,50:18.6
18,8,50:18.6
10,9,50:18.6
18,9,50:18.6
19,9,50:18.6
8,13,50:18.6
8,14,50:18.6
4,16,50:18.6
18,4,51:18.6
19,4,51:18.6
18,5,51:18.6
14,6,51:18.6
17,6,51:18.6
9,7,51:18.6
19,8,51:18.6
20,8,51:18.6
19,9,51:18.6
7,15,51:18.6
13,6,52:18.6
14,6,52:18.6
15,6,52:18.6
16,6,52:18.6
20,8,52:18.6
13,6,53:18.6
14,6,53:18.6
15,6,53:18.6
16,6,53:18.6
17,6,53:18.6
13,6,54:18.6
15,6,54:18.6
16,6,54:18.6
17,6,54:18.6
15,6,55:18.6
16,6,55:18.6
