[META]
version=2.0
spawnOnBlockType=2
spawnSunlight=True
spawnDarkness=True
spawnWater=False
spawnLava=False
underFill=False
randomRotation=True
dig=True
tree=False
branch=False
needsFoundation=True
rarity=100
collisionPercentage=20
spawnElevationMin=0
spawnElevationMax=200
spawnInBiome=Custom
[DATA]
-3,-7,-8:17.12
-2,-7,-8:17.12
-1,-7,-8:17.12
-2,-3,-8:17.12
-3,-2,-8:17.12
-2,-2,-8:17.12
0,0,-8:17.12
-4,2,-8:17.12
-2,2,-8:17.12
0,2,-8:17.12
-4,3,-8:17.12
-3,3,-8:17.12
-2,3,-8:17.12
-2,4,-8:17.12
-3,5,-8:17.12
-3,6,-8:17.12
-3,7,-8:17.12
-2,7,-8:17.12
0,8,-8:17.12
-1,-8,-7:17.12
-2,-7,-7:17.12
-1,-7,-7:17.12
-3,-6,-7:17.12
-1,-3,-7:17.12
-2,-2,-7:17.12
-1,-2,-7:17.12
0,-2,-7:17.12
-3,-1,-7:17.12
-1,-1,-7:17.12
0,-1,-7:17.12
-1,0,-7:17.12
-2,1,-7:17.12
-1,1,-7:17.12
0,1,-7:17.12
0,2,-7:17.12
-4,3,-7:17.12
-3,3,-7:17.12
-4,4,-7:17.12
-3,4,-7:17.12
-2,4,-7:17.12
-3,5,-7:17.12
-2,5,-7:17.12
-4,6,-7:17.12
-3,6,-7:17.12
0,6,-7:17.12
-4,7,-7:17.12
-3,7,-7:17.12
-1,7,-7:17.12
0,7,-7:17.12
-4,8,-7:17.12
-2,8,-7:17.12
0,8,-7:17.12
-3,-7,-6:17.12
-2,-7,-6:17.12
-2,-6,-6:17.12
-1,-6,-6:17.12
-3,-5,-6:17.12
-2,-3,-6:17.12
-1,-3,-6:17.12
-1,-2,-6:17.12
-2,0,-6:17.12
-1,0,-6:17.12
-2,1,-6:17.12
-1,1,-6:17.12
0,1,-6:17.12
1,1,-6:17.12
-2,2,-6:17.12
-1,2,-6:17.12
-3,3,-6:17.12
-4,4,-6:17.12
-3,4,-6:17.12
-2,4,-6:17.12
-3,5,-6:17.12
-2,5,-6:17.12
-1,5,-6:17.12
-4,6,-6:17.12
-3,6,-6:17.12
-1,6,-6:17.12
0,6,-6:17.12
-4,7,-6:17.12
-3,7,-6:17.12
-2,7,-6:17.12
-1,7,-6:17.12
0,7,-6:17.12
1,7,-6:17.12
-3,8,-6:17.12
-1,8,-6:17.12
0,8,-6:17.12
-1,-7,-5:17.12
-3,-6,-5:17.12
-2,-6,-5:17.12
-3,-5,-5:17.12
-2,-5,-5:17.12
-1,-5,-5:17.12
-2,-4,-5:17.12
-1,-4,-5:17.12
0,-4,-5:17.12
-2,-3,-5:17.12
-1,-3,-5:17.12
0,-3,-5:17.12
-2,-2,-5:17.12
-1,-2,-5:17.12
0,0,-5:17.12
-2,1,-5:17.12
-1,1,-5:17.12
0,1,-5:17.12
1,1,-5:17.12
-1,2,-5:17.12
-3,4,-5:17.12
-3,5,-5:17.12
-2,5,-5:17.12
-1,5,-5:17.12
-3,6,-5:17.12
-2,6,-5:17.12
-1,6,-5:17.12
-3,7,-5:17.12
-2,7,-5:17.12
-1,7,-5:17.12
0,7,-5:17.12
1,7,-5:17.12
-1,8,-5:17.12
0,8,-5:17.12
-1,9,-5:17.12
0,9,-5:17.12
-1,-7,-4:17.12
0,-7,-4:17.12
-1,-6,-4:17.12
0,-6,-4:17.12
-2,-5,-4:17.12
-1,-5,-4:17.12
0,-5,-4:17.12
-2,-4,-4:17.12
-1,-4,-4:17.12
0,-4,-4:17.12
-2,-3,-4:17.12
-1,-3,-4:17.12
-1,-2,-4:17.12
1,1,-4:17.12
0,2,-4:17.12
1,2,-4:17.12
0,3,-4:17.12
-2,5,-4:17.12
-1,5,-4:17.12
-3,6,-4:17.12
-2,6,-4:17.12
2,6,-4:17.12
-3,7,-4:17.12
-2,7,-4:17.12
-1,7,-4:17.12
0,8,-4:17.12
1,8,-4:17.12
2,8,-4:17.12
-2,9,-4:17.12
0,9,-4:17.12
-2,10,-4:17.12
-1,-7,-3:17.12
-2,-6,-3:17.12
-1,-6,-3:17.12
-2,-5,-3:17.12
-1,-5,-3:17.12
-2,-4,-3:17.12
-1,-4,-3:17.12
-1,-3,-3:17.12
-1,-2,-3:17.12
0,1,-3:17.12
0,3,-3:17.12
1,3,-3:17.12
-4,4,-3:17.12
-3,4,-3:17.12
-1,4,-3:17.12
0,4,-3:17.12
-4,5,-3:17.12
-3,5,-3:17.12
-2,5,-3:17.12
-1,5,-3:17.12
0,5,-3:17.12
-5,6,-3:17.12
-4,6,-3:17.12
-3,6,-3:17.12
-2,6,-3:17.12
-1,6,-3:17.12
0,6,-3:17.12
1,6,-3:17.12
2,6,-3:17.12
-3,7,-3:17.12
-2,7,-3:17.12
-1,7,-3:17.12
0,7,-3:17.12
1,7,-3:17.12
-3,8,-3:17.12
-2,8,-3:17.12
-1,8,-3:17.12
0,8,-3:17.12
1,8,-3:17.12
-2,9,-3:17.12
-1,-7,-2:17.12
-2,-6,-2:17.12
-1,-6,-2:17.12
0,-6,-2:17.12
-2,-5,-2:17.12
-1,-5,-2:17.12
0,-5,-2:17.12
1,-5,-2:17.12
2,-5,-2:17.12
-4,-4,-2:17.12
-3,-4,-2:17.12
-2,-4,-2:17.12
-1,-4,-2:17.12
0,-4,-2:17.12
1,-4,-2:17.12
-2,-3,-2:17.12
-1,-3,-2:17.12
0,-3,-2:17.12
-1,-2,-2:17.12
0,-2,-2:17.12
-3,4,-2:18.12
-1,4,-2:17.12
0,4,-2:17.12
-4,5,-2:18.12
-3,5,-2:18.12
-2,5,-2:17.12
-1,5,-2:17.12
0,5,-2:17.12
-3,6,-2:17.12
-2,6,-2:17.12
-1,6,-2:17.12
0,6,-2:17.12
-3,7,-2:17.12
-2,7,-2:17.12
-1,7,-2:17.12
0,7,-2:17.12
-3,8,-2:17.12
-2,8,-2:17.12
-1,-6,-1:17.12
-2,-5,-1:17.12
-1,-5,-1:17.12
0,-5,-1:17.12
-3,-4,-1:17.12
-2,-4,-1:17.12
-1,-4,-1:17.12
0,-4,-1:17.12
-2,-3,-1:17.12
-1,-3,-1:17.12
0,-3,-1:17.12
-3,5,-1:18.12
-2,5,-1:17.12
-1,5,-1:17.12
-3,6,-1:17.12
-1,6,-1:17.12
-3,7,-1:17.12
-2,7,-1:17.12
-1,7,-1:17.12
-2,-4,0:17.12
-1,-4,0:17.12
0,-4,0:17.12
-2,-3,0:17.12
-1,-3,0:17.12
0,-3,0:17.12
-3,5,0:17.12
-2,5,0:17.12
-1,5,0:17.12
-3,6,0:17.12
-1,6,0:17.12
-3,7,0:17.12
-2,7,0:17.12
-1,7,0:17.12
-3,8,0:17.12
-4,10,0:18.14
-4,11,0:18.14
-2,-4,1:17.12
-1,-4,1:17.12
0,-4,1:17.12
1,-4,1:17.12
2,-4,1:18.14
3,-4,1:18.14
-2,-3,1:18.14
-1,-3,1:17.12
0,-3,1:17.12
1,-3,1:18.14
2,-3,1:18.14
3,-3,1:18.14
-2,-2,1:18.14
2,-2,1:18.14
2,-1,1:18.14
3,-1,1:18.14
-3,3,1:18.14
-3,4,1:18.14
-3,5,1:17.12
-2,5,1:18.14
-1,5,1:17.12
-3,6,1:17.12
-1,6,1:17.12
-3,7,1:17.12
-2,7,1:17.12
-1,7,1:17.12
-7,8,1:18.14
-6,8,1:18.14
-5,8,1:18.14
-4,8,1:17.12
-3,8,1:17.12
-7,9,1:18.14
-6,9,1:18.14
-5,9,1:18.14
-4,9,1:18.14
-4,10,1:18.14
-5,11,1:18.14
-4,11,1:18.14
-5,12,1:18.14
-1,-6,2:18.14
-1,-5,2:18.14
-2,-4,2:17.12
-1,-4,2:17.12
0,-4,2:17.12
1,-4,2:18.14
2,-4,2:18.14
3,-4,2:18.14
5,-4,2:18.14
-2,-3,2:18.14
-1,-3,2:17.12
0,-3,2:17.12
1,-3,2:17.12
2,-3,2:18.14
3,-3,2:18.14
-2,-2,2:18.14
-1,-2,2:18.14
1,-2,2:18.14
3,-2,2:18.14
0,-1,2:18.14
1,-1,2:18.14
2,-1,2:18.14
0,0,2:18.14
-3,3,2:18.14
-3,4,2:18.14
-2,4,2:18.14
-1,4,2:18.14
-3,5,2:18.14
-2,5,2:17.12
-1,5,2:17.12
-5,6,2:18.14
-2,6,2:17.12
-1,6,2:17.12
-5,7,2:18.14
-2,7,2:17.12
-1,7,2:17.12
0,7,2:18.14
1,7,2:18.14
2,7,2:18.14
-8,8,2:18.14
-7,8,2:18.14
-6,8,2:18.14
-5,8,2:18.14
-4,8,2:17.12
-3,8,2:17.12
-7,9,2:18.14
-6,9,2:18.14
-5,9,2:18.14
-4,9,2:18.14
-3,9,2:18.14
-7,10,2:18.14
-6,10,2:18.14
-5,10,2:18.14
-4,10,2:18.14
-3,10,2:18.14
-5,11,2:18.14
-4,11,2:18.14
-3,11,2:18.14
-5,12,2:18.14
-4,12,2:18.14
-5,13,2:18.14
-1,-6,3:18.14
-2,-5,3:18.14
-1,-5,3:18.14
0,-5,3:18.14
1,-5,3:18.14
2,-5,3:18.14
-2,-4,3:17.12
-1,-4,3:17.12
0,-4,3:17.12
2,-4,3:18.14
3,-4,3:18.14
5,-4,3:18.14
-4,-3,3:18.14
-3,-3,3:18.14
-2,-3,3:18.14
-1,-3,3:17.12
0,-3,3:18.14
1,-3,3:18.14
2,-3,3:18.14
3,-3,3:18.14
5,-3,3:18.14
-3,-2,3:18.14
-2,-2,3:18.14
0,-2,3:18.14
1,-2,3:17.12
2,-2,3:18.14
4,-2,3:18.14
5,-2,3:18.14
-3,-1,3:18.14
2,-1,3:18.14
1,0,3:18.14
3,0,3:18.14
-3,3,3:18.14
-2,3,3:18.14
-1,3,3:18.14
0,3,3:18.14
1,3,3:18.14
-4,4,3:18.14
-3,4,3:18.14
-2,4,3:18.14
-1,4,3:18.14
-7,5,3:18.14
-6,5,3:18.14
-4,5,3:18.14
-3,5,3:18.14
-2,5,3:17.12
-1,5,3:17.12
-7,6,3:18.14
-6,6,3:18.14
-2,6,3:17.12
-1,6,3:17.12
0,6,3:18.14
-8,7,3:18.14
-7,7,3:18.14
-6,7,3:18.14
-2,7,3:17.12
-1,7,3:17.12
0,7,3:18.14
1,7,3:18.14
2,7,3:18.14
-8,8,3:18.14
-5,8,3:18.14
-4,8,3:17.12
0,8,3:18.14
-5,9,3:17.12
-4,9,3:18.14
-3,9,3:18.14
-2,9,3:18.14
-5,10,3:18.14
-4,10,3:18.14
-3,10,3:18.14
-6,11,3:17.12
-5,11,3:18.14
-3,11,3:18.14
-5,12,3:18.14
-3,12,3:18.14
-5,13,3:18.14
-6,14,3:18.14
-5,14,3:18.14
-2,-5,4:18.14
-1,-5,4:17.12
-2,-4,4:17.12
-1,-4,4:17.12
0,-4,4:17.12
-4,-3,4:18.14
-3,-3,4:18.14
-2,-3,4:17.12
-1,-3,4:17.12
0,-3,4:18.14
2,-3,4:18.14
3,-3,4:18.14
-3,-2,4:18.14
-2,-2,4:18.14
-1,-2,4:18.14
0,-2,4:18.14
1,-2,4:18.14
2,-2,4:18.14
3,-2,4:18.14
-4,-1,4:18.14
-3,-1,4:18.14
-1,-1,4:18.14
0,-1,4:18.14
2,-1,4:18.14
-3,0,4:18.14
-1,0,4:18.14
3,0,4:18.14
-3,1,4:18.14
-3,2,4:18.14
-2,2,4:18.14
0,2,4:18.14
1,2,4:18.14
-2,3,4:18.14
-1,3,4:18.14
0,3,4:18.14
-2,4,4:18.14
-1,4,4:18.14
-2,5,4:17.12
-1,5,4:17.12
0,5,4:17.12
-8,6,4:18.14
-4,6,4:18.14
-3,6,4:18.14
-2,6,4:17.12
-1,6,4:17.12
0,6,4:17.12
1,6,4:18.14
-7,7,4:18.14
-3,7,4:18.14
-2,7,4:17.12
-1,7,4:17.12
0,7,4:17.12
1,7,4:18.14
-9,8,4:18.14
-8,8,4:18.14
-6,8,4:18.14
-5,8,4:18.14
-4,8,4:18.14
0,8,4:18.14
-5,9,4:18.14
-4,9,4:18.14
-3,9,4:18.14
-5,10,4:18.14
-4,10,4:18.14
-3,10,4:18.14
-2,10,4:18.14
-1,10,4:18.14
-8,11,4:18.14
-7,11,4:18.14
-6,11,4:18.14
-5,11,4:18.14
-3,11,4:18.14
-8,12,4:18.14
-7,12,4:18.14
-6,12,4:18.14
-6,13,4:18.14
-6,14,4:18.14
-1,-6,5:17.12
-2,-5,5:17.12
-1,-5,5:17.12
-3,-4,5:17.12
-2,-4,5:17.12
0,-4,5:17.12
1,-4,5:18.14
-3,-3,5:17.12
-2,-3,5:17.12
0,-3,5:18.14
2,-3,5:18.14
-4,-2,5:18.14
-3,-2,5:18.14
-2,-2,5:18.14
-1,-2,5:17.12
0,-2,5:18.14
1,-2,5:18.14
2,-2,5:18.14
3,-2,5:18.14
4,-2,5:18.14
-3,-1,5:18.14
-2,-1,5:18.14
-1,-1,5:18.14
0,-1,5:17.12
2,-1,5:18.14
3,-1,5:18.14
-3,0,5:18.14
-2,0,5:18.14
-1,0,5:18.14
0,0,5:18.14
1,0,5:18.14
2,0,5:18.14
3,0,5:18.14
-3,1,5:18.14
-2,1,5:18.14
1,1,5:18.14
3,1,5:18.14
-3,2,5:18.14
-2,2,5:18.14
-1,2,5:18.14
0,2,5:18.14
-2,3,5:18.14
-1,3,5:18.14
0,3,5:18.14
-6,4,5:18.14
-5,4,5:18.14
-1,4,5:18.14
-5,5,5:18.14
-4,5,5:18.14
-3,5,5:17.12
-2,5,5:17.12
-1,5,5:17.12
0,5,5:17.12
-5,6,5:18.14
-4,6,5:18.14
-3,6,5:17.12
-2,6,5:17.12
-1,6,5:17.12
0,6,5:17.12
-7,7,5:18.14
-4,7,5:18.14
-3,7,5:18.14
-2,7,5:17.12
-1,7,5:17.12
0,7,5:17.12
1,7,5:17.12
-10,8,5:18.14
-9,8,5:18.14
-8,8,5:18.14
-7,8,5:18.14
-6,8,5:18.14
-5,8,5:18.14
-4,8,5:18.14
-2,8,5:17.12
-5,9,5:18.14
-5,10,5:18.14
-5,11,5:18.14
-4,11,5:18.14
-6,12,5:18.14
-5,12,5:18.14
-8,13,5:18.14
-7,13,5:18.14
-3,-6,6:18.14
-2,-6,6:18.14
-1,-6,6:17.12
-2,-5,6:18.14
-1,-5,6:18.14
0,-5,6:18.14
-3,-4,6:17.12
0,-4,6:17.12
1,-4,6:18.14
2,-4,6:18.14
3,-4,6:18.14
-3,-3,6:17.12
1,-3,6:18.14
2,-3,6:18.14
0,-2,6:18.14
1,-2,6:18.14
2,-2,6:18.14
-1,-1,6:18.14
0,-1,6:18.14
1,-1,6:18.14
2,-1,6:18.14
-2,0,6:18.14
-1,0,6:18.14
0,0,6:18.14
1,0,6:17.12
2,0,6:18.14
-5,1,6:18.14
-4,1,6:18.14
-3,1,6:18.14
-2,1,6:18.14
-1,1,6:18.14
0,1,6:18.14
1,1,6:18.14
3,1,6:18.14
-6,2,6:18.14
-5,2,6:18.14
-4,2,6:18.14
-3,2,6:18.14
-2,2,6:18.14
-1,2,6:18.14
0,2,6:18.14
-6,3,6:18.14
-5,3,6:18.14
-4,3,6:18.14
-3,3,6:18.14
-1,3,6:18.14
-6,4,6:18.14
-5,4,6:18.14
-4,4,6:18.14
-3,4,6:18.14
-1,4,6:18.14
0,4,6:17.12
-5,5,6:18.14
-4,5,6:17.12
-3,5,6:17.12
-1,5,6:17.12
0,5,6:17.12
-7,6,6:18.14
-5,6,6:18.14
-4,6,6:17.12
-3,6,6:17.12
-2,6,6:17.12
-1,6,6:17.12
0,6,6:17.12
-8,7,6:18.14
-7,7,6:18.14
-4,7,6:18.14
-3,7,6:18.14
-2,7,6:17.12
-1,7,6:17.12
0,7,6:17.12
1,7,6:17.12
2,7,6:17.12
-10,8,6:18.14
-9,8,6:18.14
-8,8,6:18.14
-7,8,6:18.14
-6,8,6:18.14
-5,8,6:18.14
-4,8,6:18.14
-2,8,6:18.14
-1,8,6:17.12
-7,9,6:18.14
-5,9,6:18.14
-4,9,6:18.14
-6,10,6:18.14
-6,11,6:18.14
-5,11,6:18.14
-5,12,6:18.14
-6,13,6:18.14
-3,-7,7:18.14
-2,-7,7:18.14
-1,-7,7:18.14
-3,-6,7:18.14
-2,-6,7:18.14
-1,-6,7:17.12
-5,-5,7:18.14
-2,-5,7:18.14
0,-5,7:18.14
-4,-4,7:18.14
-3,-4,7:18.14
-1,-4,7:18.14
0,-4,7:18.14
1,-4,7:18.14
2,-4,7:18.14
3,-4,7:18.14
-4,-3,7:18.14
-3,-3,7:17.12
0,-3,7:18.14
2,-3,7:18.14
-4,-2,7:18.14
0,-2,7:18.14
2,-2,7:18.14
-1,-1,7:18.14
0,-1,7:17.12
1,-1,7:18.14
2,-1,7:18.14
0,0,7:18.14
2,0,7:18.14
-1,1,7:18.14
0,1,7:18.14
-5,2,7:18.14
-3,2,7:18.14
-5,3,7:18.14
-4,3,7:18.14
-3,3,7:18.14
0,3,7:17.12
-5,4,7:18.14
-4,4,7:18.14
-1,4,7:17.12
0,4,7:17.12
-9,5,7:18.14
-8,5,7:18.14
-7,5,7:18.14
-6,5,7:18.14
-5,5,7:18.14
-4,5,7:18.14
-1,5,7:17.12
0,5,7:17.12
-8,6,7:18.14
-7,6,7:18.14
-6,6,7:17.12
-5,6,7:17.12
-4,6,7:18.14
-9,7,7:18.14
-8,7,7:18.14
-7,7,7:18.14
-4,7,7:18.14
-3,7,7:18.14
-2,7,7:17.12
-1,7,7:18.14
0,7,7:18.14
1,7,7:17.12
2,7,7:17.12
-10,8,7:18.14
-9,8,7:18.14
-8,8,7:18.14
-7,8,7:18.14
-6,8,7:18.14
-5,8,7:18.14
-4,8,7:18.14
-3,8,7:18.14
-2,8,7:18.14
-1,8,7:17.12
-8,9,7:18.14
-7,9,7:18.14
-6,9,7:18.14
-5,9,7:18.14
-4,9,7:18.14
-3,9,7:18.14
-2,9,7:18.14
-7,10,7:18.14
-6,10,7:18.14
-4,10,7:18.14
-3,10,7:18.14
-6,11,7:18.14
-3,11,7:18.14
-1,-8,8:18.14
-2,-7,8:18.14
-1,-7,8:18.14
-2,-6,8:18.14
-1,-6,8:18.14
-2,-5,8:18.14
-5,-4,8:18.14
-4,-4,8:18.14
-3,-4,8:18.14
-2,-4,8:18.14
0,-4,8:18.14
1,-4,8:17.12
2,-4,8:18.14
3,-4,8:18.14
-5,-3,8:18.14
-4,-3,8:18.14
-3,-3,8:17.12
0,-3,8:18.14
-5,-2,8:18.14
0,-2,8:18.14
-1,-1,8:18.14
0,-1,8:18.14
1,-1,8:18.14
-1,0,8:17.12
0,0,8:18.14
-6,2,8:18.14
-5,2,8:18.14
-6,3,8:18.14
-5,3,8:18.14
-4,3,8:18.14
0,3,8:17.12
-9,4,8:18.14
-8,4,8:18.14
-7,4,8:18.14
-6,4,8:18.14
-5,4,8:18.14
0,4,8:17.12
-9,5,8:18.14
-8,5,8:18.14
-7,5,8:18.14
-6,5,8:18.14
-5,5,8:18.14
-4,5,8:18.14
-8,6,8:18.14
-6,6,8:17.12
-5,6,8:17.12
-4,6,8:18.14
3,6,8:18.14
-10,7,8:18.14
-9,7,8:18.14
-8,7,8:18.14
-4,7,8:18.14
-3,7,8:18.14
-1,7,8:18.14
0,7,8:18.14
1,7,8:18.14
2,7,8:17.12
-7,8,8:18.14
-6,8,8:18.14
-5,8,8:18.14
-4,8,8:18.14
-2,8,8:17.12
-1,8,8:17.12
0,8,8:18.14
-6,9,8:18.14
-4,9,8:18.14
-3,9,8:18.14
-2,9,8:18.14
-1,9,8:18.14
0,9,8:18.14
-3,10,8:18.14
-3,11,8:18.14
-2,-7,9:18.14
-2,-6,9:18.14
-3,-5,9:18.14
1,-5,9:18.14
2,-5,9:18.14
-4,-4,9:17.12
-3,-4,9:18.14
-1,-4,9:18.14
0,-4,9:18.14
1,-4,9:18.14
2,-4,9:18.14
3,-4,9:18.14
-5,-3,9:18.14
-4,-3,9:18.14
-3,-3,9:17.12
0,-3,9:18.14
-7,2,9:18.14
-6,2,9:18.14
-7,3,9:18.14
0,3,9:17.12
1,3,9:18.14
2,3,9:18.14
-9,4,9:18.14
-8,4,9:18.14
-7,4,9:18.14
-6,4,9:18.14
0,4,9:17.12
-6,5,9:18.14
-5,5,9:18.14
-4,5,9:18.14
3,5,9:18.14
4,5,9:18.14
-8,6,9:18.14
-6,6,9:18.14
-5,6,9:17.12
-4,6,9:18.14
1,6,9:18.14
2,6,9:18.14
3,6,9:18.14
-8,7,9:18.14
-7,7,9:18.14
-6,7,9:18.14
-3,7,9:18.14
-2,7,9:18.14
-1,7,9:18.14
2,7,9:17.12
3,7,9:18.14
4,7,9:18.14
5,7,9:18.14
-7,8,9:18.14
-5,8,9:18.14
-2,8,9:17.12
-1,8,9:18.14
0,8,9:18.14
2,8,9:18.14
3,8,9:18.14
-5,9,9:18.14
-4,9,9:18.14
-3,9,9:18.14
-2,9,9:18.14
3,9,9:18.14
-3,11,9:18.14
-3,-8,10:18.14
-3,-7,10:18.14
-2,-7,10:18.14
-2,-6,10:18.14
3,-6,10:18.14
-3,-5,10:18.14
-1,-5,10:18.14
2,-5,10:18.14
3,-5,10:18.14
-5,-4,10:18.14
-4,-4,10:18.14
-3,-4,10:18.14
-2,-4,10:18.14
-1,-4,10:18.14
0,-4,10:18.14
2,-4,10:18.14
3,-4,10:18.14
-4,-3,10:18.14
-3,-3,10:17.12
0,-3,10:18.14
-3,-2,10:18.14
0,1,10:18.14
0,2,10:18.14
2,2,10:18.14
3,2,10:18.14
0,3,10:17.12
1,3,10:18.14
-7,4,10:18.14
-5,4,10:17.12
-4,4,10:18.14
0,4,10:17.12
-7,5,10:18.14
-6,5,10:18.14
-5,5,10:18.14
1,5,10:18.14
-6,6,10:17.12
-5,6,10:18.14
-4,6,10:18.14
1,6,10:18.14
2,6,10:18.14
3,6,10:18.14
-7,7,10:18.14
-6,7,10:18.14
-4,7,10:18.14
-3,7,10:18.14
2,7,10:17.12
3,7,10:18.14
4,7,10:18.14
5,7,10:18.14
-2,8,10:17.12
-1,8,10:17.12
3,8,10:18.14
4,8,10:18.14
-5,9,10:18.14
-3,9,10:18.14
-2,9,10:18.14
-1,9,10:17.12
3,9,10:18.14
4,9,10:18.14
-3,10,10:18.14
-3,11,10:18.14
-2,-8,11:18.14
-3,-7,11:18.14
-3,-6,11:18.14
-5,-5,11:18.14
0,-5,11:18.14
1,-5,11:18.14
2,-5,11:18.14
-6,-4,11:18.14
-5,-4,11:18.14
-3,-4,11:18.14
-2,-4,11:18.14
-1,-4,11:18.14
0,-4,11:18.14
3,-4,11:18.14
-4,-3,11:18.14
-3,-3,11:17.12
-2,-3,11:18.14
-1,-3,11:18.14
0,-3,11:18.14
0,0,11:18.14
0,1,11:18.14
1,1,11:18.14
1,2,11:18.14
2,2,11:18.14
3,2,11:18.14
-5,3,11:17.12
0,3,11:17.12
1,3,11:18.14
-7,4,11:18.14
-5,4,11:18.14
-4,4,11:18.14
0,4,11:18.14
-7,5,11:18.14
-6,5,11:18.14
-5,5,11:18.14
-6,6,11:18.14
2,6,11:18.14
-6,7,11:18.14
-4,7,11:18.14
-3,7,11:18.14
2,7,11:18.14
3,7,11:17.12
-2,8,11:18.14
-1,8,11:17.12
3,8,11:18.14
-2,9,11:18.14
-1,9,11:17.12
-2,10,11:18.14
-1,10,11:18.14
-3,11,11:18.14
-5,-5,12:18.14
-5,-4,12:18.14
-2,-4,12:18.14
-4,-3,12:18.14
-3,-3,12:18.14
-2,-3,12:18.14
-1,-3,12:18.14
-3,-2,12:18.14
-3,-1,12:18.14
-2,-1,12:18.14
0,0,12:18.14
1,1,12:18.14
1,2,12:18.14
-1,3,12:18.14
0,3,12:18.14
1,3,12:17.12
0,4,12:18.14
1,4,12:18.14
3,5,12:18.14
0,6,12:18.14
2,6,12:18.14
-3,7,12:18.14
-2,7,12:18.14
-1,7,12:18.14
2,7,12:18.14
3,7,12:18.14
4,7,12:18.14
5,7,12:18.14
-1,8,12:18.14
-2,9,12:18.14
-2,10,12:18.14
-1,10,12:18.14
-2,11,12:18.14
-1,11,12:18.14
-3,-2,13:18.14
-4,-1,13:18.14
-3,-1,13:18.14
-2,-1,13:18.14
-2,0,13:18.14
1,1,13:18.14
-1,2,13:18.14
0,2,13:18.14
1,2,13:18.14
2,2,13:17.12
-1,3,13:18.14
0,3,13:17.12
1,3,13:18.14
0,4,13:17.12
1,4,13:18.14
0,5,13:18.14
3,5,13:18.14
-1,6,13:18.14
0,6,13:18.14
3,6,13:18.14
-3,7,13:18.14
-2,7,13:18.14
-1,7,13:18.14
1,7,13:18.14
2,7,13:18.14
3,7,13:18.14
4,7,13:18.14
5,7,13:18.14
6,7,13:18.14
-1,8,13:18.14
4,8,13:18.14
-3,9,13:18.14
-3,10,13:18.14
-2,10,13:17.12
-1,10,13:18.14
-3,11,13:18.14
-2,11,13:17.12
-1,11,13:18.14
-1,12,13:18.14
-3,-2,14:18.14
-3,-1,14:18.14
2,1,14:18.14
3,1,14:17.12
2,2,14:18.14
0,3,14:17.12
1,3,14:18.14
3,3,14:18.14
0,4,14:18.14
0,5,14:18.14
0,6,14:18.14
3,6,14:18.14
4,6,14:18.14
-2,7,14:18.14
-1,7,14:18.14
0,7,14:18.14
1,7,14:18.14
2,7,14:18.14
3,7,14:18.14
4,7,14:18.14
5,7,14:18.14
-1,8,14:17.12
0,8,14:18.14
5,8,14:18.14
-1,10,14:18.14
-3,11,14:18.14
-2,11,14:18.14
-1,11,14:18.14
-1,12,14:18.14
3,1,15:18.14
1,2,15:18.14
2,2,15:18.14
3,2,15:18.14
-1,3,15:17.12
4,3,15:18.14
-1,4,15:17.12
0,4,15:17.12
-1,5,15:18.14
0,5,15:18.14
1,5,15:18.14
2,5,15:18.14
-2,6,15:18.14
0,6,15:18.14
-2,7,15:18.14
-1,7,15:18.14
0,7,15:18.14
0,8,15:18.14
-1,10,15:18.14
-1,11,15:18.14
1,2,16:18.14
2,2,16:18.14
-2,3,16:18.14
-1,3,16:18.14
0,3,16:18.14
0,4,16:18.14
-1,5,16:18.14
0,5,16:18.14
1,5,16:18.14
-1,6,16:18.14
-2,1,17:18.14
-2,2,17:18.14
-3,3,17:18.14
-2,3,17:18.14
-1,3,17:18.14
0,4,17:18.14
-2,1,18:18.14
-2,2,18:18.14
-3,3,18:18.14
-2,3,18:18.14
-1,3,18:18.14
-2,2,19:18.14
-1,3,19:18.14
