[META]
version=2.0
spawnOnBlockType=2
spawnSunlight=True
spawnDarkness=True
spawnWater=False
spawnLava=False
underFill=False
randomRotation=True
dig=True
tree=False
branch=False
needsFoundation=True
rarity=100
collisionPercentage=20
spawnElevationMin=0
spawnElevationMax=200
spawnInBiome=Custom
[DATA]
-22,-4,-8:17.12
-22,-3,-8:17.12
-20,0,-8:17.12
-19,0,-8:17.12
-18,2,-8:17.12
-19,3,-8:17.12
-17,3,-8:17.12
-9,6,-8:17.12
-8,6,-8:17.12
-16,10,-8:17.12
-11,11,-8:17.12
-23,-4,-7:17.12
-22,-4,-7:17.12
-21,-4,-7:17.12
-22,-3,-7:17.12
-20,-3,-7:17.12
-22,-2,-7:17.12
-21,-2,-7:17.12
-19,-1,-7:17.12
-7,-1,-7:17.12
-19,0,-7:17.12
-18,0,-7:17.12
-20,1,-7:17.12
-19,1,-7:17.12
-17,2,-7:17.12
-19,3,-7:17.12
-18,3,-7:17.12
-17,3,-7:17.12
-16,3,-7:17.12
-17,4,-7:17.12
-16,4,-7:17.12
-15,4,-7:17.12
-10,5,-7:17.12
-9,5,-7:17.12
-9,6,-7:17.12
-8,6,-7:17.12
-7,6,-7:17.12
-9,7,-7:17.12
-8,7,-7:17.12
-17,8,-7:17.12
-17,9,-7:17.12
-16,9,-7:17.12
-15,9,-7:17.12
-16,10,-7:17.12
-12,10,-7:17.12
-11,10,-7:17.12
-10,10,-7:17.12
-11,11,-7:17.12
-10,11,-7:17.12
-21,-4,-6:17.12
-20,-4,-6:17.12
-22,-3,-6:17.12
-21,-3,-6:17.12
-20,-3,-6:17.12
-22,-2,-6:17.12
-21,-2,-6:17.12
-20,-2,-6:17.12
-9,-2,-6:17.12
-20,-1,-6:17.12
-19,-1,-6:17.12
-18,-1,-6:17.12
-9,-1,-6:17.12
-8,-1,-6:17.12
-20,0,-6:17.12
-19,0,-6:17.12
-18,0,-6:17.12
-17,0,-6:17.12
-9,0,-6:17.12
-8,0,-6:17.12
-7,0,-6:17.12
-19,1,-6:17.12
-18,1,-6:17.12
-17,1,-6:17.12
-18,2,-6:17.12
-17,2,-6:17.12
-18,3,-6:17.12
-17,3,-6:17.12
-18,4,-6:17.12
-17,4,-6:17.12
-16,4,-6:17.12
-15,4,-6:17.12
-20,5,-6:17.12
-17,5,-6:17.12
-16,5,-6:17.12
-15,5,-6:17.12
-7,5,-6:17.12
-9,6,-6:17.12
-8,6,-6:17.12
-7,6,-6:17.12
-16,7,-6:17.12
-9,7,-6:17.12
-7,7,-6:17.12
-6,7,-6:17.12
-5,7,-6:17.12
-17,8,-6:17.12
-16,8,-6:17.12
-15,8,-6:17.12
-14,8,-6:17.12
-6,8,-6:17.12
-17,9,-6:17.12
-16,9,-6:17.12
-15,9,-6:17.12
-12,9,-6:17.12
-11,9,-6:17.12
-16,10,-6:17.12
-11,10,-6:17.12
-10,10,-6:17.12
-11,11,-6:17.12
-21,-4,-5:17.12
-22,-3,-5:17.12
-21,-3,-5:17.12
-20,-3,-5:17.12
-20,-2,-5:17.12
-21,-1,-5:17.12
-20,-1,-5:17.12
-18,-1,-5:17.12
-9,-1,-5:17.12
-8,-1,-5:17.12
-7,-1,-5:17.12
-19,0,-5:17.12
-18,0,-5:17.12
-17,0,-5:17.12
-9,0,-5:17.12
-8,0,-5:17.12
-7,0,-5:17.12
-19,1,-5:17.12
-18,1,-5:17.12
-8,1,-5:17.12
-7,1,-5:17.12
-20,2,-5:17.12
-19,2,-5:17.12
-17,2,-5:17.12
-21,3,-5:17.12
-19,3,-5:17.12
-17,3,-5:17.12
-21,4,-5:17.12
-20,4,-5:17.12
-19,4,-5:17.12
-17,4,-5:17.12
-15,4,-5:17.12
-14,4,-5:17.12
-21,5,-5:17.12
-16,5,-5:17.12
-15,5,-5:17.12
-14,5,-5:17.12
-8,5,-5:17.12
-15,6,-5:17.12
-7,6,-5:17.12
-6,6,-5:17.12
-5,6,-5:17.12
-16,7,-5:17.12
-15,7,-5:17.12
-8,7,-5:17.12
-7,7,-5:17.12
-6,7,-5:17.12
-5,7,-5:17.12
-4,7,-5:17.12
-15,8,-5:17.12
-14,8,-5:17.12
-13,8,-5:17.12
-11,8,-5:17.12
-7,8,-5:17.12
-6,8,-5:17.12
-16,9,-5:17.12
-15,9,-5:17.12
-14,9,-5:17.12
-11,9,-5:17.12
-10,9,-5:17.12
-11,10,-5:17.12
-11,11,-5:17.12
-22,-3,-4:17.12
-21,-3,-4:17.12
-20,-3,-4:17.12
-19,-3,-4:17.12
-21,-2,-4:17.12
-20,-2,-4:17.12
-19,-2,-4:17.12
-20,-1,-4:17.12
-19,-1,-4:17.12
-18,-1,-4:17.12
-8,-1,-4:17.12
-19,0,-4:17.12
-17,0,-4:17.12
-8,0,-4:17.12
-7,0,-4:17.12
-20,1,-4:17.12
-19,1,-4:17.12
-9,1,-4:17.12
-8,1,-4:17.12
-20,2,-4:17.12
-19,2,-4:17.12
-9,2,-4:17.12
-8,2,-4:17.12
-7,2,-4:17.12
-21,3,-4:17.12
-20,3,-4:17.12
-19,3,-4:17.12
-21,4,-4:17.12
-20,4,-4:17.12
-16,4,-4:17.12
-15,4,-4:17.12
-14,4,-4:17.12
-11,4,-4:17.12
-16,5,-4:17.12
-15,5,-4:17.12
-14,5,-4:17.12
-11,5,-4:17.12
-15,6,-4:17.12
-11,6,-4:17.12
-7,6,-4:17.12
-6,6,-4:17.12
-5,6,-4:17.12
-14,7,-4:17.12
-12,7,-4:17.12
-7,7,-4:17.12
-6,7,-4:17.12
-5,7,-4:17.12
-4,7,-4:17.12
-16,8,-4:17.12
-15,8,-4:17.12
-14,8,-4:17.12
-13,8,-4:17.12
-12,8,-4:17.12
-11,8,-4:17.12
-6,8,-4:17.12
-5,8,-4:17.12
-15,9,-4:17.12
-14,9,-4:17.12
-12,9,-4:17.12
-11,9,-4:17.12
-10,9,-4:17.12
-11,10,-4:17.12
-21,-2,-3:17.12
-20,-2,-3:17.12
-19,-2,-3:17.12
-18,-2,-3:17.12
-21,-1,-3:17.12
-20,-1,-3:17.12
-19,-1,-3:17.12
-18,-1,-3:17.12
-20,0,-3:17.12
-19,0,-3:17.12
-18,0,-3:17.12
-8,0,-3:17.12
-20,1,-3:17.12
-19,1,-3:17.12
-8,1,-3:17.12
-21,2,-3:17.12
-20,2,-3:17.12
-19,2,-3:17.12
-9,2,-3:17.12
-8,2,-3:17.12
-21,3,-3:17.12
-20,3,-3:17.12
-19,3,-3:17.12
-8,3,-3:17.12
-7,3,-3:17.12
-15,4,-3:17.12
-14,4,-3:17.12
-10,4,-3:17.12
-7,4,-3:17.12
-5,4,-3:17.12
-16,5,-3:17.12
-15,5,-3:17.12
-14,5,-3:17.12
-11,5,-3:17.12
-10,5,-3:17.12
-16,6,-3:17.12
-15,6,-3:17.12
-14,6,-3:17.12
-13,6,-3:17.12
-12,6,-3:17.12
-5,6,-3:17.12
-3,6,-3:17.12
-15,7,-3:17.12
-14,7,-3:17.12
-13,7,-3:17.12
-12,7,-3:17.12
-6,7,-3:17.12
-5,7,-3:17.12
-4,7,-3:17.12
-3,7,-3:17.12
-2,7,-3:17.12
-15,8,-3:17.12
-14,8,-3:17.12
-13,8,-3:17.12
-12,8,-3:17.12
-11,8,-3:17.12
-10,8,-3:17.12
-6,8,-3:17.12
-4,8,-3:17.12
-14,9,-3:17.12
-13,9,-3:17.12
-12,9,-3:17.12
-11,9,-3:17.12
-10,9,-3:17.12
-12,10,-3:17.12
-10,10,-3:17.12
-20,-3,-2:17.12
-19,-3,-2:17.12
-18,-3,-2:17.12
-17,-3,-2:17.12
-21,-2,-2:17.12
-20,-2,-2:17.12
-19,-2,-2:17.12
-18,-2,-2:17.12
-17,-2,-2:17.12
-16,-2,-2:17.12
-22,-1,-2:17.12
-21,-1,-2:17.12
-20,-1,-2:17.12
-19,-1,-2:17.12
-18,-1,-2:17.12
-17,-1,-2:17.12
-16,-1,-2:17.12
-22,0,-2:17.12
-21,0,-2:17.12
-20,0,-2:17.12
-19,0,-2:17.12
-18,0,-2:17.12
-17,0,-2:17.12
-16,0,-2:17.12
-22,1,-2:17.12
-21,1,-2:17.12
-20,1,-2:17.12
-19,1,-2:17.12
-18,1,-2:17.12
-17,1,-2:17.12
-16,1,-2:17.12
-8,1,-2:17.12
-21,2,-2:17.12
-20,2,-2:17.12
-19,2,-2:17.12
-18,2,-2:17.12
-17,2,-2:17.12
-10,2,-2:17.12
-9,2,-2:17.12
-8,2,-2:17.12
-20,3,-2:17.12
-13,3,-2:17.12
-12,3,-2:17.12
-11,3,-2:17.12
-10,3,-2:17.12
-9,3,-2:17.12
-8,3,-2:17.12
-7,3,-2:17.12
-6,3,-2:17.12
-5,3,-2:17.12
-15,4,-2:17.12
-14,4,-2:17.12
-13,4,-2:17.12
-12,4,-2:17.12
-11,4,-2:17.12
-10,4,-2:17.12
-9,4,-2:17.12
-8,4,-2:17.12
-7,4,-2:17.12
-6,4,-2:17.12
-5,4,-2:17.12
-4,4,-2:17.12
-18,5,-2:17.12
-17,5,-2:17.12
-16,5,-2:17.12
-15,5,-2:17.12
-14,5,-2:17.12
-13,5,-2:17.12
-12,5,-2:17.12
-11,5,-2:17.12
-10,5,-2:17.12
-9,5,-2:17.12
-8,5,-2:17.12
-7,5,-2:17.12
-6,5,-2:17.12
-5,5,-2:17.12
-4,5,-2:17.12
-3,5,-2:17.12
-17,6,-2:17.12
-16,6,-2:17.12
-15,6,-2:17.12
-14,6,-2:17.12
-13,6,-2:17.12
-12,6,-2:17.12
-11,6,-2:17.12
-10,6,-2:17.12
-9,6,-2:17.12
-8,6,-2:17.12
-7,6,-2:17.12
-6,6,-2:17.12
-5,6,-2:17.12
-4,6,-2:17.12
-3,6,-2:17.12
-2,6,-2:17.12
-16,7,-2:17.12
-15,7,-2:17.12
-14,7,-2:17.12
-13,7,-2:17.12
-12,7,-2:17.12
-11,7,-2:17.12
-10,7,-2:17.12
-9,7,-2:17.12
-8,7,-2:17.12
-7,7,-2:17.12
-6,7,-2:17.12
-5,7,-2:17.12
-4,7,-2:17.12
-3,7,-2:17.12
-2,7,-2:17.12
-15,8,-2:17.12
-14,8,-2:17.12
-13,8,-2:17.12
-12,8,-2:17.12
-11,8,-2:17.12
-10,8,-2:17.12
-9,8,-2:17.12
-8,8,-2:17.12
-7,8,-2:17.12
-6,8,-2:17.12
-5,8,-2:17.12
-4,8,-2:17.12
-3,8,-2:17.12
-2,8,-2:17.12
-1,8,-2:17.12
-14,9,-2:17.12
-13,9,-2:17.12
-12,9,-2:17.12
-11,9,-2:17.12
-10,9,-2:17.12
-9,9,-2:17.12
-8,9,-2:17.12
-7,9,-2:17.12
-6,9,-2:17.12
-5,9,-2:17.12
-4,9,-2:17.12
-3,9,-2:17.12
-13,10,-2:17.12
-12,10,-2:17.12
-11,10,-2:17.12
-10,10,-2:17.12
-9,10,-2:17.12
-8,10,-2:17.12
-7,10,-2:17.12
-6,10,-2:17.12
-5,10,-2:17.12
-4,10,-2:17.12
-11,11,-2:17.12
-10,11,-2:17.12
-9,11,-2:17.12
-8,11,-2:17.12
-7,11,-2:17.12
-6,11,-2:17.12
-20,-3,-1:17.12
-19,-3,-1:17.12
-18,-3,-1:17.12
-21,-2,-1:17.12
-20,-2,-1:17.12
-17,-2,-1:17.12
-16,-2,-1:17.12
-22,-1,-1:17.12
-21,-1,-1:17.12
-20,-1,-1:17.12
-19,-1,-1:17.12
-16,-1,-1:17.12
-22,0,-1:17.12
-21,0,-1:17.12
-19,0,-1:17.12
-17,0,-1:17.12
-16,0,-1:17.12
-21,1,-1:17.12
-20,1,-1:17.12
-18,1,-1:17.12
-17,1,-1:17.12
-20,2,-1:17.12
-19,2,-1:17.12
-18,2,-1:17.12
-11,3,-1:17.12
-10,3,-1:17.12
-9,3,-1:17.12
-8,3,-1:17.12
-7,3,-1:17.12
-6,3,-1:17.12
-13,4,-1:17.12
-12,4,-1:17.12
-11,4,-1:17.12
-10,4,-1:17.12
-8,4,-1:17.12
-5,4,-1:17.12
-4,4,-1:17.12
-15,5,-1:17.12
-14,5,-1:17.12
-13,5,-1:17.12
-12,5,-1:17.12
-11,5,-1:17.12
-10,5,-1:17.12
-5,5,-1:17.12
-3,5,-1:17.12
-16,6,-1:17.12
-15,6,-1:17.12
-14,6,-1:17.12
-13,6,-1:17.12
-11,6,-1:17.12
-5,6,-1:17.12
-3,6,-1:17.12
-2,6,-1:17.12
-15,7,-1:17.12
-14,7,-1:17.12
-13,7,-1:17.12
-12,7,-1:17.12
-10,7,-1:17.12
-4,7,-1:17.12
-3,7,-1:17.12
-2,7,-1:17.12
-1,7,-1:17.12
-14,8,-1:17.12
-13,8,-1:17.12
-12,8,-1:17.12
-11,8,-1:17.12
-10,8,-1:17.12
-2,8,-1:17.12
-1,8,-1:17.12
-13,9,-1:17.12
-12,9,-1:17.12
-11,9,-1:17.12
-10,9,-1:17.12
-3,9,-1:17.12
-2,9,-1:17.12
-12,10,-1:17.12
-11,10,-1:17.12
-10,10,-1:17.12
-5,10,-1:17.12
-4,10,-1:17.12
-3,10,-1:17.12
-9,11,-1:17.12
-8,11,-1:17.12
-7,11,-1:17.12
-6,11,-1:17.12
-5,11,-1:17.12
-20,-3,0:17.12
-19,-3,0:17.12
-18,-3,0:17.12
-21,-2,0:17.12
-20,-2,0:17.12
-18,-2,0:17.12
-17,-2,0:17.12
-21,-1,0:17.12
-17,-1,0:17.12
-21,0,0:17.12
-17,0,0:17.12
-21,1,0:17.12
-20,1,0:17.12
-18,1,0:17.12
-17,1,0:17.12
-20,2,0:17.12
-19,2,0:17.12
-18,2,0:17.12
-9,3,0:17.12
-8,3,0:17.12
-7,3,0:17.12
-6,3,0:17.12
-5,3,0:17.12
-11,4,0:17.12
-10,4,0:17.12
-9,4,0:17.12
-8,4,0:17.12
-5,4,0:17.12
-4,4,0:17.12
-13,5,0:17.12
-12,5,0:17.12
-11,5,0:17.12
-3,5,0:17.12
-2,5,0:17.12
-14,6,0:17.12
-13,6,0:17.12
-12,6,0:17.12
-2,6,0:17.12
-1,6,0:17.12
-13,7,0:17.12
-12,7,0:17.12
-1,7,0:17.12
-12,8,0:17.12
-11,8,0:17.12
-1,8,0:17.12
0,8,0:17.12
-11,9,0:17.12
-10,9,0:17.12
-2,9,0:17.12
-1,9,0:17.12
-10,10,0:17.12
-9,10,0:17.12
-8,10,0:17.12
-4,10,0:17.12
-3,10,0:17.12
-8,11,0:17.12
-7,11,0:17.12
-6,11,0:17.12
-5,11,0:17.12
-19,-3,1:17.12
-18,-3,1:17.12
-21,-2,1:17.12
-20,-2,1:17.12
-19,-2,1:17.12
-18,-2,1:17.12
-17,-2,1:17.12
-21,-1,1:17.12
-17,-1,1:17.12
-21,0,1:17.12
-17,0,1:17.12
-21,1,1:17.12
-20,1,1:17.12
-19,1,1:17.12
-18,1,1:17.12
-17,1,1:17.12
-20,2,1:17.12
-19,2,1:17.12
-9,4,1:17.12
-8,4,1:17.12
-7,4,1:17.12
-6,4,1:17.12
-5,4,1:17.12
-4,4,1:17.12
-3,4,1:17.12
-11,5,1:17.12
-10,5,1:17.12
-9,5,1:17.12
-3,5,1:17.12
-2,5,1:17.12
-12,6,1:17.12
-11,6,1:17.12
-10,6,1:17.12
-2,6,1:17.12
-1,6,1:17.12
-12,7,1:17.12
-11,7,1:17.12
-1,7,1:17.12
0,7,1:17.12
-11,8,1:17.12
-10,8,1:17.12
-1,8,1:17.12
0,8,1:17.12
-10,9,1:17.12
-9,9,1:17.12
-2,9,1:17.12
-1,9,1:17.12
-9,10,1:17.12
-8,10,1:17.12
-7,10,1:17.12
-4,10,1:17.12
-3,10,1:17.12
-2,10,1:17.12
-7,11,1:17.12
-6,11,1:17.12
-5,11,1:17.12
-4,11,1:17.12
3,13,1:18.12
-21,-5,2:18.15
-21,-4,2:18.15
-20,-2,2:17.12
-19,-2,2:17.12
-18,-2,2:17.12
-17,-2,2:17.12
-21,-1,2:17.12
-17,-1,2:17.12
-21,0,2:17.12
-17,0,2:17.12
-21,1,2:17.12
-20,1,2:17.12
-19,1,2:17.12
-18,1,2:17.12
-17,1,2:17.12
-24,2,2:18.15
-23,2,2:18.15
-7,4,2:17.12
-6,4,2:17.12
-5,4,2:17.12
-4,4,2:17.12
-3,4,2:17.12
-9,5,2:17.12
-8,5,2:17.12
-7,5,2:17.12
-3,5,2:17.12
-2,5,2:17.12
-11,6,2:17.12
-10,6,2:17.12
-9,6,2:17.12
-1,6,2:17.12
-11,7,2:17.12
-10,7,2:17.12
-9,7,2:17.12
-1,7,2:17.12
0,7,2:17.12
-10,8,2:17.12
-9,8,2:17.12
0,8,2:17.12
-9,9,2:17.12
-8,9,2:17.12
-1,9,2:17.12
-8,10,2:17.12
-7,10,2:17.12
-6,10,2:17.12
-4,10,2:17.12
-3,10,2:17.12
-2,10,2:17.12
-6,11,2:17.12
-5,11,2:17.12
-4,11,2:17.12
3,12,2:18.12
2,13,2:18.12
3,13,2:18.12
2,14,2:18.12
-21,-7,3:18.15
-22,-6,3:18.15
-21,-6,3:18.15
-21,-5,3:18.15
-20,-4,3:18.15
-20,-3,3:18.15
-20,-2,3:17.12
-19,-2,3:17.12
-18,-2,3:17.12
-17,-2,3:17.12
-21,-1,3:17.12
-17,-1,3:17.12
-21,0,3:17.12
-17,0,3:17.12
-21,1,3:17.12
-20,1,3:17.12
-19,1,3:17.12
-18,1,3:17.12
-24,2,3:18.15
-23,2,3:18.15
-25,3,3:18.15
-6,4,3:17.12
-5,4,3:17.12
-4,4,3:17.12
-3,4,3:17.12
-7,5,3:17.12
-6,5,3:17.12
-2,5,3:17.12
-1,5,3:17.12
-9,6,3:17.12
-8,6,3:17.12
-1,6,3:17.12
-9,7,3:17.12
-8,7,3:17.12
0,7,3:17.12
-8,8,3:17.12
0,8,3:17.12
4,8,3:18.12
7,8,3:18.4
-8,9,3:17.12
-7,9,3:17.12
-1,9,3:17.12
0,9,3:17.12
8,9,3:18.4
-7,10,3:17.12
-6,10,3:17.12
-3,10,3:17.12
-2,10,3:17.12
-1,10,3:17.12
7,10,3:18.4
-5,11,3:17.12
-4,11,3:17.12
3,12,3:18.12
4,12,3:18.12
3,13,3:18.12
1,14,3:18.12
2,14,3:18.12
3,14,3:18.12
-3,17,3:18.12
-2,17,3:18.12
-22,-7,4:18.15
-21,-7,4:18.15
-21,-6,4:18.15
-21,-5,4:18.15
-21,-4,4:18.15
-20,-3,4:18.15
-20,-2,4:17.12
-19,-2,4:17.12
-18,-2,4:17.12
-17,-2,4:17.12
-21,-1,4:17.12
-17,-1,4:17.12
-21,0,4:17.12
-17,0,4:17.12
-22,1,4:18.15
-21,1,4:17.12
-20,1,4:17.12
-19,1,4:17.12
-18,1,4:17.12
-25,3,4:18.15
-17,3,4:18.15
-16,4,4:18.15
-5,4,4:17.12
-4,4,4:17.12
-3,4,4:17.12
3,4,4:18.12
-7,5,4:17.12
-6,5,4:17.12
-2,5,4:17.12
-1,5,4:17.12
3,5,4:18.12
4,5,4:18.12
-8,6,4:17.12
-7,6,4:17.12
-1,6,4:17.12
0,6,4:17.12
4,6,4:18.12
-8,7,4:17.12
0,7,4:17.12
3,7,4:18.12
-8,8,4:17.12
-7,8,4:17.12
0,8,4:17.12
1,8,4:17.12
3,8,4:18.12
4,8,4:18.12
7,8,4:18.4
-7,9,4:17.12
-1,9,4:17.12
0,9,4:17.12
3,9,4:18.12
7,9,4:18.4
8,9,4:18.4
-6,10,4:17.12
-5,10,4:17.12
-3,10,4:17.12
-2,10,4:17.12
-1,10,4:17.12
7,10,4:18.4
-5,11,4:17.12
-4,11,4:17.12
-3,11,4:17.12
4,11,4:18.12
3,12,4:18.12
1,13,4:18.12
2,13,4:18.12
3,13,4:18.12
-4,15,4:18.12
-3,16,4:18.12
-1,16,4:18.4
-3,17,4:18.12
-2,17,4:18.12
-22,-7,5:18.15
-21,-7,5:18.15
-21,-6,5:18.15
-21,-5,5:18.15
-21,-4,5:18.15
-20,-3,5:18.15
-20,-2,5:17.12
-19,-2,5:17.12
-18,-2,5:17.12
-17,-2,5:17.12
-21,-1,5:17.12
-17,-1,5:17.12
-21,0,5:17.12
-17,0,5:17.12
-22,1,5:18.15
-21,1,5:17.12
-20,1,5:17.12
-19,1,5:17.12
-18,1,5:17.12
2,1,5:18.12
-23,2,5:18.15
1,2,5:18.12
2,2,5:18.12
-25,3,5:18.15
-17,3,5:18.15
-16,4,5:18.15
-4,4,5:17.12
-3,4,5:17.12
2,4,5:18.12
3,4,5:18.12
-6,5,5:17.12
-5,5,5:17.12
-2,5,5:17.12
-1,5,5:17.12
2,5,5:18.12
3,5,5:18.12
4,5,5:18.12
-7,6,5:17.12
-6,6,5:17.12
-1,6,5:17.12
0,6,5:17.12
4,6,5:18.12
5,6,5:18.12
-8,7,5:17.12
-7,7,5:17.12
0,7,5:17.12
1,7,5:17.12
3,7,5:18.12
4,7,5:18.12
6,7,5:18.12
-7,8,5:17.12
1,8,5:17.12
3,8,5:18.12
6,8,5:18.12
7,8,5:18.4
-7,9,5:17.12
-6,9,5:17.12
0,9,5:17.12
3,9,5:18.12
7,9,5:18.4
-6,10,5:17.12
-5,10,5:17.12
-2,10,5:17.12
-1,10,5:17.12
3,10,5:18.12
4,10,5:18.12
6,10,5:18.12
7,10,5:18.4
-4,11,5:17.12
-3,11,5:17.12
2,11,5:18.12
3,11,5:18.12
4,11,5:18.12
6,11,5:18.12
3,12,5:18.12
0,13,5:18.12
1,13,5:18.12
2,13,5:18.12
3,13,5:18.12
-4,14,5:18.12
-4,15,5:18.12
-3,15,5:18.12
-3,16,5:18.4
-2,16,5:18.4
-1,16,5:18.4
0,16,5:18.4
-22,-7,6:18.15
-21,-7,6:18.15
-22,-6,6:18.15
-21,-5,6:18.15
-20,-3,6:18.15
-20,-2,6:17.12
-19,-2,6:17.12
-18,-2,6:17.12
-17,-2,6:17.12
-21,-1,6:17.12
-17,-1,6:17.12
-21,0,6:17.12
-17,0,6:17.12
-20,1,6:17.12
-19,1,6:17.12
-18,1,6:17.12
-23,2,6:18.15
1,2,6:18.12
2,2,6:18.12
3,2,6:18.12
-25,3,6:18.15
-17,3,6:18.15
3,3,6:18.12
-16,4,6:18.15
-3,4,6:17.12
-2,4,6:17.12
-6,5,6:17.12
-5,5,6:17.12
-4,5,6:17.12
-2,5,6:17.12
-1,5,6:17.12
1,5,6:18.12
2,5,6:18.12
3,5,6:18.12
4,5,6:18.12
-7,6,6:17.12
-6,6,6:17.12
0,6,6:17.12
1,6,6:18.12
3,6,6:18.12
4,6,6:18.12
-7,7,6:17.12
0,7,6:17.12
1,7,6:17.12
2,7,6:18.12
3,7,6:18.12
4,7,6:18.12
5,7,6:18.12
-7,8,6:17.12
-6,8,6:17.12
1,8,6:17.12
2,8,6:18.12
3,8,6:18.12
4,8,6:18.12
5,8,6:18.12
6,8,6:18.12
-6,9,6:17.12
0,9,6:17.12
1,9,6:17.12
2,9,6:18.12
3,9,6:18.12
4,9,6:18.12
6,9,6:18.12
7,9,6:18.12
-6,10,6:17.12
-5,10,6:17.12
-4,10,6:17.12
-2,10,6:17.12
-1,10,6:17.12
0,10,6:17.12
1,10,6:18.12
2,10,6:18.12
3,10,6:18.12
4,10,6:18.12
5,10,6:18.12
6,10,6:18.12
-4,11,6:17.12
-3,11,6:17.12
-2,11,6:17.12
2,11,6:18.12
3,11,6:18.12
5,11,6:18.12
6,11,6:18.12
-1,12,6:18.12
0,12,6:18.12
1,12,6:18.12
2,12,6:18.12
3,12,6:18.12
4,12,6:18.12
0,13,6:18.12
1,13,6:18.12
2,13,6:18.12
-4,14,6:18.12
-3,14,6:18.12
1,14,6:18.12
2,14,6:18.12
-3,15,6:18.12
-2,15,6:18.12
-1,15,6:18.12
0,15,6:18.12
1,15,6:18.12
4,15,6:18.12
-2,16,6:18.4
-1,16,6:18.4
-22,-7,7:18.15
-21,-7,7:18.15
-22,-6,7:18.15
-21,-6,7:18.15
-21,-5,7:18.15
-20,-2,7:17.12
-19,-2,7:17.12
-18,-2,7:17.12
-17,-2,7:17.12
-21,-1,7:17.12
-17,-1,7:17.12
-21,0,7:17.12
-17,0,7:17.12
-22,1,7:18.15
-21,1,7:17.12
-20,1,7:17.12
-19,1,7:17.12
-18,1,7:17.12
-17,1,7:17.12
-24,2,7:18.15
-23,2,7:18.15
1,2,7:18.12
2,2,7:18.12
-25,3,7:18.15
-24,3,7:18.15
-17,3,7:18.15
0,3,7:18.12
1,3,7:18.12
2,3,7:18.12
3,3,7:18.12
-16,4,7:18.15
-2,4,7:17.12
3,4,7:18.12
4,4,7:18.12
-5,5,7:17.12
-4,5,7:17.12
-3,5,7:17.12
-2,5,7:17.12
-1,5,7:17.12
2,5,7:18.12
3,5,7:18.12
4,5,7:18.12
6,5,7:18.12
-6,6,7:17.12
-5,6,7:17.12
0,6,7:17.12
1,6,7:18.12
2,6,7:18.12
3,6,7:18.12
4,6,7:18.12
-7,7,7:17.12
-6,7,7:17.12
1,7,7:17.12
2,7,7:18.12
3,7,7:18.12
4,7,7:18.12
5,7,7:18.12
-6,8,7:17.12
1,8,7:18.12
2,8,7:18.12
3,8,7:18.12
4,8,7:18.12
5,8,7:18.12
6,8,7:18.12
-6,9,7:17.12
-5,9,7:17.12
0,9,7:17.12
1,9,7:17.12
2,9,7:18.12
3,9,7:18.12
4,9,7:18.12
5,9,7:18.12
6,9,7:18.12
-5,10,7:17.12
-4,10,7:17.12
-2,10,7:17.12
-1,10,7:17.12
0,10,7:17.12
1,10,7:18.12
2,10,7:18.12
3,10,7:18.12
4,10,7:18.12
5,10,7:18.12
6,10,7:18.12
-3,11,7:17.12
-2,11,7:17.12
0,11,7:18.12
1,11,7:18.12
2,11,7:18.12
3,11,7:18.12
4,11,7:18.12
5,11,7:18.12
-3,12,7:18.12
0,12,7:18.12
1,12,7:18.12
2,12,7:18.12
3,12,7:18.12
4,12,7:18.12
-3,13,7:18.12
-2,13,7:18.12
1,13,7:18.12
2,13,7:18.12
4,13,7:18.12
-3,14,7:18.12
-2,14,7:18.12
-1,14,7:18.12
0,14,7:18.12
1,14,7:18.12
4,14,7:18.12
-2,15,7:18.12
-1,15,7:18.12
0,15,7:18.12
2,15,7:18.12
3,15,7:18.12
4,15,7:18.12
-22,-7,8:18.15
-21,-7,8:18.15
-21,-6,8:18.15
-21,-5,8:18.15
-20,-4,8:18.15
-14,-4,8:18.12
-13,-4,8:18.12
-20,-3,8:18.15
-19,-3,8:17.12
-21,-2,8:17.12
-20,-2,8:17.12
-19,-2,8:17.12
-18,-2,8:17.12
-17,-2,8:17.12
-21,-1,8:17.12
-17,-1,8:17.12
-21,0,8:17.12
-17,0,8:17.12
-22,1,8:18.15
-21,1,8:17.12
-20,1,8:17.12
-19,1,8:17.12
-18,1,8:17.12
-17,1,8:17.12
-24,2,8:18.15
-25,3,8:18.15
-17,3,8:18.15
1,3,8:18.12
2,3,8:18.12
-16,4,8:18.15
0,4,8:18.12
1,4,8:18.12
2,4,8:18.12
3,4,8:18.12
-16,5,8:18.15
-4,5,8:17.12
-3,5,8:17.12
-2,5,8:17.12
-1,5,8:17.12
0,5,8:18.12
1,5,8:18.12
3,5,8:18.12
4,5,8:18.12
5,5,8:18.12
6,5,8:18.12
-14,6,8:18.12
-6,6,8:17.12
-5,6,8:17.12
0,6,8:17.12
1,6,8:17.12
2,6,8:18.12
3,6,8:18.12
4,6,8:18.12
5,6,8:18.12
6,6,8:18.12
-7,7,8:18.15
-6,7,8:17.12
1,7,8:17.12
2,7,8:18.12
3,7,8:18.12
4,7,8:18.12
5,7,8:18.12
-6,8,8:17.12
1,8,8:18.12
2,8,8:18.12
3,8,8:18.12
4,8,8:18.12
5,8,8:18.12
-5,9,8:17.12
1,9,8:17.12
2,9,8:18.12
3,9,8:18.12
4,9,8:18.12
5,9,8:18.12
-5,10,8:17.12
-4,10,8:17.12
-3,10,8:17.12
-1,10,8:17.12
0,10,8:18.12
1,10,8:18.12
2,10,8:18.12
3,10,8:18.12
4,10,8:18.12
5,10,8:18.12
-3,11,8:17.12
-2,11,8:18.12
0,11,8:18.12
1,11,8:18.12
2,11,8:18.12
3,11,8:18.12
4,11,8:18.12
-2,12,8:18.12
-1,12,8:18.12
0,12,8:18.12
1,12,8:18.12
3,12,8:18.12
4,12,8:18.12
-2,13,8:18.12
-1,13,8:18.12
0,13,8:18.12
1,13,8:18.12
3,13,8:18.12
4,13,8:18.12
-1,14,8:18.12
1,14,8:18.12
2,14,8:18.12
3,14,8:18.12
4,14,8:18.12
-16,-9,9:18.12
-17,-8,9:18.12
-16,-8,9:18.12
-26,-7,9:18.12
-25,-7,9:18.12
-22,-7,9:18.15
-21,-7,9:18.15
-17,-7,9:18.12
-25,-6,9:18.12
-24,-6,9:18.12
-21,-6,9:18.15
-24,-5,9:18.12
-21,-5,9:18.15
-17,-5,9:18.12
-13,-5,9:18.12
-12,-5,9:18.12
-11,-5,9:18.12
-21,-4,9:18.15
-20,-4,9:18.15
-17,-4,9:18.12
-15,-4,9:18.12
-14,-4,9:18.12
-13,-4,9:18.12
-12,-4,9:18.12
-21,-3,9:18.12
-20,-3,9:17.12
-19,-3,9:17.12
-18,-3,9:17.12
-17,-3,9:18.12
-16,-3,9:18.12
-15,-3,9:18.12
-14,-3,9:18.12
-21,-2,9:17.12
-20,-2,9:17.12
-19,-2,9:18.12
-18,-2,9:18.12
-17,-2,9:17.12
-16,-2,9:18.12
-21,-1,9:17.12
-19,-1,9:18.12
-18,-1,9:18.12
-17,-1,9:18.12
-16,-1,9:17.12
-21,0,9:17.12
-20,0,9:18.12
-19,0,9:18.12
-18,0,9:18.12
-17,0,9:18.12
-16,0,9:18.12
-15,0,9:18.12
-14,0,9:18.12
8,0,9:18.7
9,0,9:18.7
-28,1,9:18.12
-27,1,9:18.12
-26,1,9:18.12
-25,1,9:18.12
-23,1,9:18.12
-22,1,9:18.15
-21,1,9:17.12
-20,1,9:17.12
-17,1,9:17.12
-24,2,9:18.15
-20,2,9:17.12
-19,2,9:17.12
-18,2,9:17.12
-17,2,9:18.15
-16,2,9:18.12
-25,3,9:18.15
-17,3,9:18.15
-16,4,9:18.15
-16,5,9:18.15
-15,5,9:18.12
-4,5,9:17.12
-3,5,9:17.12
-2,5,9:17.12
-1,5,9:17.12
0,5,9:17.12
1,5,9:18.12
2,5,9:18.12
3,5,9:18.12
4,5,9:18.12
5,5,9:18.12
-14,6,9:18.12
-5,6,9:17.12
-4,6,9:17.12
0,6,9:17.12
1,6,9:17.12
2,6,9:18.12
3,6,9:18.12
4,6,9:18.12
5,6,9:18.12
-14,7,9:18.12
-13,7,9:18.12
-7,7,9:18.15
-6,7,9:17.12
-5,7,9:17.12
1,7,9:17.12
2,7,9:18.12
3,7,9:18.12
4,7,9:18.12
-6,8,9:17.12
-5,8,9:17.12
2,8,9:17.12
3,8,9:18.12
4,8,9:18.12
-5,9,9:17.12
1,9,9:17.12
2,9,9:17.12
-4,10,9:17.12
-3,10,9:17.12
-1,10,9:17.12
0,10,9:17.12
1,10,9:17.12
-3,11,9:17.12
-2,11,9:17.12
-1,11,9:17.12
1,11,9:18.12
2,11,9:18.12
1,12,9:18.12
2,12,9:18.12
3,12,9:18.12
2,13,9:18.12
3,13,9:18.12
-24,-11,10:17.12
-18,-11,10:18.12
-17,-11,10:18.12
-18,-10,10:18.12
-15,-10,10:18.12
-14,-10,10:18.12
-23,-9,10:18.12
-22,-9,10:18.12
-21,-9,10:18.12
-19,-9,10:18.12
-18,-9,10:18.12
-16,-9,10:18.12
-15,-9,10:18.12
-14,-9,10:18.12
-26,-8,10:18.12
-25,-8,10:18.12
-22,-8,10:18.12
-21,-8,10:18.12
-18,-8,10:18.12
-16,-8,10:18.12
-15,-8,10:18.12
-11,-8,10:18.12
-25,-7,10:18.12
-24,-7,10:18.12
-22,-7,10:18.15
-21,-7,10:18.12
-18,-7,10:18.12
-17,-7,10:18.12
-16,-7,10:18.12
-15,-7,10:18.12
-13,-7,10:18.12
-12,-7,10:18.12
-11,-7,10:18.12
-10,-7,10:18.12
-24,-6,10:18.12
-23,-6,10:18.12
-22,-6,10:18.12
-21,-6,10:18.12
-18,-6,10:18.12
-17,-6,10:18.12
-16,-6,10:18.12
-15,-6,10:18.12
-14,-6,10:18.12
-13,-6,10:18.12
-12,-6,10:18.12
-11,-6,10:18.12
-23,-5,10:18.12
-22,-5,10:18.12
-21,-5,10:18.12
-20,-5,10:18.12
-18,-5,10:18.12
-17,-5,10:18.12
-16,-5,10:18.12
-15,-5,10:18.12
-14,-5,10:18.12
-13,-5,10:18.12
-11,-5,10:18.12
-10,-5,10:18.12
-22,-4,10:18.12
-21,-4,10:18.12
-20,-4,10:18.12
-19,-4,10:18.12
-18,-4,10:17.12
-17,-4,10:18.12
-16,-4,10:18.12
-15,-4,10:18.12
-14,-4,10:18.12
-13,-4,10:18.12
-12,-4,10:18.12
-11,-4,10:18.12
-7,-4,10:18.12
-6,-4,10:18.12
-21,-3,10:18.12
-20,-3,10:17.12
-19,-3,10:17.12
-18,-3,10:17.12
-17,-3,10:18.12
-16,-3,10:18.12
-15,-3,10:18.12
-14,-3,10:18.12
-13,-3,10:18.12
-21,-2,10:17.12
-20,-2,10:18.12
-19,-2,10:17.12
-18,-2,10:18.12
-17,-2,10:18.12
-16,-2,10:18.12
-15,-2,10:18.12
-14,-2,10:18.12
-21,-1,10:17.12
-20,-1,10:18.12
-19,-1,10:18.12
-18,-1,10:18.12
-17,-1,10:18.12
-16,-1,10:18.12
-15,-1,10:18.12
-14,-1,10:18.12
-13,-1,10:18.12
5,-1,10:18.7
-22,0,10:18.12
-21,0,10:18.12
-20,0,10:18.12
-19,0,10:18.12
-18,0,10:18.12
-17,0,10:18.12
-16,0,10:18.12
9,0,10:18.7
-29,1,10:18.12
-28,1,10:18.12
-27,1,10:18.12
-26,1,10:18.12
-25,1,10:18.12
-24,1,10:18.12
-23,1,10:18.12
-22,1,10:18.12
-21,1,10:18.12
-20,1,10:18.12
-19,1,10:18.12
-18,1,10:18.12
-17,1,10:18.12
-16,1,10:18.12
8,1,10:18.7
-28,2,10:18.12
-27,2,10:18.12
-26,2,10:18.12
-25,2,10:18.12
-24,2,10:18.12
-23,2,10:18.15
-22,2,10:18.12
-21,2,10:18.12
-20,2,10:17.12
-19,2,10:17.12
-18,2,10:17.12
-17,2,10:18.12
-16,2,10:18.12
-15,2,10:18.12
-28,3,10:18.12
-27,3,10:18.12
-26,3,10:18.12
-25,3,10:18.12
-23,3,10:18.12
-22,3,10:18.12
-17,3,10:18.12
-16,3,10:18.12
-15,3,10:18.12
-30,4,10:18.12
-29,4,10:18.12
-27,4,10:18.12
-26,4,10:18.12
-25,4,10:18.12
-24,4,10:18.12
-23,4,10:18.12
-22,4,10:18.12
-17,4,10:18.12
-16,4,10:18.12
-30,5,10:18.12
-26,5,10:18.12
-25,5,10:18.12
-24,5,10:18.12
-23,5,10:18.12
-16,5,10:18.15
-15,5,10:18.12
-3,5,10:17.12
-2,5,10:17.12
-1,5,10:17.12
0,5,10:17.12
-27,6,10:18.12
-26,6,10:18.12
-25,6,10:18.12
-14,6,10:18.12
-9,6,10:18.15
-5,6,10:17.12
-4,6,10:17.12
1,6,10:17.12
-28,7,10:18.12
-27,7,10:18.12
-14,7,10:18.12
-13,7,10:18.12
-8,7,10:18.15
-5,7,10:17.12
2,7,10:17.12
-5,8,10:17.12
2,8,10:17.12
3,8,10:17.12
-12,9,10:18.12
-5,9,10:17.12
-4,9,10:17.12
1,9,10:17.12
2,9,10:17.12
-4,10,10:17.12
-3,10,10:17.12
0,10,10:17.12
1,10,10:17.12
-2,11,10:17.12
-1,11,10:17.12
0,11,10:17.12
-25,-13,11:18.12
-24,-13,11:18.12
-18,-13,11:18.12
-17,-13,11:18.12
-25,-12,11:18.12
-24,-12,11:18.12
-21,-12,11:18.12
-18,-12,11:18.12
-16,-12,11:18.12
-24,-11,11:18.12
-23,-11,11:18.12
-22,-11,11:18.12
-18,-11,11:18.12
-17,-11,11:18.12
-16,-11,11:18.12
-15,-11,11:18.12
-24,-10,11:17.12
-23,-10,11:18.12
-22,-10,11:18.12
-18,-10,11:18.12
-17,-10,11:18.12
-16,-10,11:18.12
-15,-10,11:18.12
-14,-10,11:18.12
-25,-9,11:18.12
-24,-9,11:18.12
-23,-9,11:17.12
-22,-9,11:18.12
-18,-9,11:18.12
-17,-9,11:18.12
-16,-9,11:18.12
-14,-9,11:18.12
-13,-9,11:18.12
-12,-9,11:18.12
-10,-9,11:18.12
-25,-8,11:18.12
-24,-8,11:18.12
-23,-8,11:18.12
-22,-8,11:18.12
-21,-8,11:18.12
-20,-8,11:18.12
-18,-8,11:18.12
-17,-8,11:18.12
-16,-8,11:18.12
-14,-8,11:18.12
-13,-8,11:18.12
-12,-8,11:18.12
-11,-8,11:18.12
-10,-8,11:18.12
-9,-8,11:18.12
-24,-7,11:18.12
-23,-7,11:18.12
-22,-7,11:17.12
-21,-7,11:18.12
-20,-7,11:18.12
-19,-7,11:18.12
-18,-7,11:18.12
-17,-7,11:17.12
-16,-7,11:17.12
-14,-7,11:18.12
-13,-7,11:18.12
-11,-7,11:18.12
-10,-7,11:18.12
-23,-6,11:18.12
-22,-6,11:18.12
-21,-6,11:17.12
-20,-6,11:18.12
-19,-6,11:18.12
-18,-6,11:17.12
-17,-6,11:17.12
-16,-6,11:17.12
-15,-6,11:18.12
-11,-6,11:18.12
-23,-5,11:18.12
-22,-5,11:18.12
-21,-5,11:17.12
-20,-5,11:17.12
-19,-5,11:18.12
-18,-5,11:17.12
-17,-5,11:17.12
-16,-5,11:18.12
-15,-5,11:18.12
-13,-5,11:18.12
-12,-5,11:18.12
-11,-5,11:18.12
-10,-5,11:18.12
-7,-5,11:18.12
-6,-5,11:18.12
-5,-5,11:18.12
-4,-5,11:18.12
-23,-4,11:18.12
-22,-4,11:18.12
-21,-4,11:18.12
-20,-4,11:17.12
-19,-4,11:17.12
-18,-4,11:17.12
-17,-4,11:17.12
-16,-4,11:18.12
-15,-4,11:18.12
-14,-4,11:18.12
-13,-4,11:18.12
-12,-4,11:17.12
-11,-4,11:18.12
-10,-4,11:18.12
-9,-4,11:18.12
-8,-4,11:18.12
-7,-4,11:18.12
-22,-3,11:18.12
-21,-3,11:17.12
-20,-3,11:17.12
-19,-3,11:17.12
-18,-3,11:17.12
-17,-3,11:17.12
-16,-3,11:17.12
-15,-3,11:17.12
-14,-3,11:17.12
-13,-3,11:18.12
-11,-3,11:18.12
-10,-3,11:18.12
-9,-3,11:18.12
-8,-3,11:18.12
-22,-2,11:18.12
-21,-2,11:18.12
-20,-2,11:18.12
-18,-2,11:18.12
-17,-2,11:17.12
-16,-2,11:17.12
-15,-2,11:17.12
-14,-2,11:18.12
-13,-2,11:18.12
-12,-2,11:18.12
-11,-2,11:18.12
-10,-2,11:18.12
-23,-1,11:18.12
-22,-1,11:18.12
-21,-1,11:18.12
-20,-1,11:18.12
-19,-1,11:18.12
-18,-1,11:18.12
-17,-1,11:18.12
-16,-1,11:17.12
-15,-1,11:18.12
-14,-1,11:18.12
-13,-1,11:18.12
-12,-1,11:18.12
-11,-1,11:18.12
5,-1,11:18.7
9,-1,11:18.7
-25,0,11:18.12
-24,0,11:18.12
-23,0,11:18.12
-22,0,11:18.12
-21,0,11:17.12
-19,0,11:18.12
-18,0,11:18.12
-17,0,11:17.12
-16,0,11:18.12
-15,0,11:18.12
8,0,11:18.7
9,0,11:18.7
-28,1,11:18.12
-27,1,11:18.12
-26,1,11:18.12
-25,1,11:18.12
-24,1,11:18.12
-23,1,11:18.12
-22,1,11:17.12
-21,1,11:17.12
-20,1,11:17.12
-19,1,11:18.12
-17,1,11:17.12
-16,1,11:17.12
-15,1,11:18.12
8,1,11:18.7
-30,2,11:18.12
-29,2,11:18.12
-28,2,11:18.12
-26,2,11:18.12
-25,2,11:18.12
-24,2,11:18.12
-23,2,11:18.12
-22,2,11:18.12
-21,2,11:18.12
-20,2,11:18.12
-19,2,11:18.12
-18,2,11:17.12
-17,2,11:17.12
-16,2,11:18.12
-15,2,11:18.12
-14,2,11:18.12
7,2,11:18.15
-35,3,11:18.12
-34,3,11:18.12
-33,3,11:18.12
-27,3,11:18.12
-26,3,11:18.12
-25,3,11:18.12
-24,3,11:18.12
-23,3,11:18.12
-22,3,11:18.12
-21,3,11:18.12
-20,3,11:18.12
-19,3,11:18.12
-18,3,11:18.12
-17,3,11:18.12
-16,3,11:18.12
-15,3,11:18.12
-28,4,11:18.12
-27,4,11:18.12
-26,4,11:18.12
-25,4,11:18.12
-22,4,11:18.12
-21,4,11:18.12
-19,4,11:18.12
-18,4,11:18.12
-17,4,11:18.12
-16,4,11:18.12
-15,4,11:18.12
-29,5,11:18.12
-28,5,11:18.12
-27,5,11:18.12
-26,5,11:18.12
-18,5,11:18.12
-17,5,11:18.12
-16,5,11:18.12
-15,5,11:18.12
-3,5,11:17.12
-2,5,11:17.12
-1,5,11:17.12
0,5,11:17.12
1,5,11:17.12
-30,6,11:18.12
-29,6,11:18.12
-28,6,11:18.12
-27,6,11:18.12
-15,6,11:18.12
-14,6,11:18.12
-9,6,11:18.15
-4,6,11:17.12
-3,6,11:17.12
1,6,11:17.12
2,6,11:17.12
-14,7,11:18.12
-13,7,11:18.12
-8,7,11:18.15
-5,7,11:17.12
-4,7,11:17.12
2,7,11:17.12
-5,8,11:17.12
-4,8,11:17.12
3,8,11:17.12
-22,9,11:18.4
-12,9,11:18.12
-4,9,11:17.12
2,9,11:17.12
3,9,11:17.12
-4,10,11:17.12
-3,10,11:17.12
0,10,11:17.12
1,10,11:17.12
2,10,11:17.12
-2,11,11:17.12
-1,11,11:17.12
0,11,11:17.12
5,16,11:18.7
6,16,11:18.7
6,17,11:18.7
-24,-15,12:18.12
-24,-14,12:18.12
-23,-14,12:18.12
-22,-14,12:18.12
-21,-14,12:18.12
-19,-14,12:18.12
-18,-14,12:18.12
-24,-13,12:18.12
-23,-13,12:18.12
-22,-13,12:18.12
-21,-13,12:18.12
-19,-13,12:18.12
-18,-13,12:18.12
-24,-12,12:18.12
-23,-12,12:18.12
-22,-12,12:18.12
-21,-12,12:18.12
-19,-12,12:18.12
-18,-12,12:18.12
-23,-11,12:18.12
-22,-11,12:18.12
-21,-11,12:18.12
-20,-11,12:18.12
-19,-11,12:18.12
-18,-11,12:18.12
-15,-11,12:18.12
-26,-10,12:18.12
-23,-10,12:18.12
-22,-10,12:18.12
-21,-10,12:18.12
-20,-10,12:18.12
-19,-10,12:18.12
-18,-10,12:18.12
-16,-10,12:18.12
-10,-10,12:18.12
-9,-10,12:18.12
-25,-9,12:18.12
-23,-9,12:17.12
-22,-9,12:17.12
-21,-9,12:18.12
-20,-9,12:18.12
-19,-9,12:18.12
-18,-9,12:18.12
-16,-9,12:18.12
-13,-9,12:18.12
-10,-9,12:18.12
-9,-9,12:18.12
-24,-8,12:18.12
-23,-8,12:17.12
-22,-8,12:17.12
-21,-8,12:18.12
-20,-8,12:18.12
-19,-8,12:18.12
-17,-8,12:17.12
-16,-8,12:17.12
-14,-8,12:18.12
-13,-8,12:18.12
-11,-8,12:18.12
-10,-8,12:18.12
-9,-8,12:18.12
-24,-7,12:18.12
-23,-7,12:18.12
-22,-7,12:17.12
-21,-7,12:18.12
-20,-7,12:18.12
-19,-7,12:18.12
-18,-7,12:18.12
-17,-7,12:17.12
-16,-7,12:17.12
-14,-7,12:18.12
-11,-7,12:18.12
-10,-7,12:18.12
-25,-6,12:18.12
-24,-6,12:18.12
-23,-6,12:18.12
-22,-6,12:18.12
-21,-6,12:17.12
-20,-6,12:17.12
-19,-6,12:18.12
-18,-6,12:18.12
-17,-6,12:17.12
-16,-6,12:17.12
-15,-6,12:18.12
-13,-6,12:18.12
-12,-6,12:18.12
-11,-6,12:18.12
-9,-6,12:18.12
-26,-5,12:18.12
-25,-5,12:18.12
-24,-5,12:18.12
-23,-5,12:18.12
-22,-5,12:18.12
-21,-5,12:18.12
-20,-5,12:17.12
-19,-5,12:18.12
-18,-5,12:18.12
-17,-5,12:18.12
-16,-5,12:18.12
-15,-5,12:18.12
-14,-5,12:18.12
-13,-5,12:18.12
-12,-5,12:18.12
-11,-5,12:17.12
-10,-5,12:18.12
-9,-5,12:18.12
-8,-5,12:18.12
-7,-5,12:18.12
-6,-5,12:18.12
-5,-5,12:18.12
-4,-5,12:18.12
-24,-4,12:18.12
-23,-4,12:18.12
-22,-4,12:18.12
-21,-4,12:17.12
-20,-4,12:17.12
-19,-4,12:18.12
-18,-4,12:18.12
-17,-4,12:18.12
-16,-4,12:18.12
-15,-4,12:18.12
-14,-4,12:18.12
-13,-4,12:18.12
-12,-4,12:18.12
-11,-4,12:17.12
-10,-4,12:18.12
-9,-4,12:18.12
-8,-4,12:18.12
-24,-3,12:18.12
-23,-3,12:18.12
-22,-3,12:18.12
-21,-3,12:17.12
-20,-3,12:17.12
-19,-3,12:17.12
-18,-3,12:18.12
-17,-3,12:18.12
-16,-3,12:18.12
-15,-3,12:18.12
-14,-3,12:17.12
-13,-3,12:18.12
-12,-3,12:17.12
-11,-3,12:18.12
-10,-3,12:18.12
-9,-3,12:18.12
-8,-3,12:18.12
-7,-3,12:18.12
-24,-2,12:18.12
-23,-2,12:18.12
-22,-2,12:18.12
-21,-2,12:17.12
-20,-2,12:18.12
-19,-2,12:17.12
-18,-2,12:17.12
-17,-2,12:17.12
-16,-2,12:18.12
-15,-2,12:18.12
-14,-2,12:18.12
-13,-2,12:18.12
-12,-2,12:18.12
-11,-2,12:18.12
-10,-2,12:18.12
-25,-1,12:18.12
-24,-1,12:18.12
-23,-1,12:18.12
-22,-1,12:17.12
-21,-1,12:17.12
-20,-1,12:18.12
-19,-1,12:18.12
-18,-1,12:18.12
-17,-1,12:18.12
-16,-1,12:18.12
-15,-1,12:18.12
-13,-1,12:18.12
-12,-1,12:18.12
-11,-1,12:18.12
-10,-1,12:18.12
5,-1,12:18.7
9,-1,12:18.7
-27,0,12:18.12
-26,0,12:18.12
-25,0,12:18.12
-24,0,12:18.12
-23,0,12:18.12
-22,0,12:17.12
-21,0,12:17.12
-20,0,12:17.12
-19,0,12:18.12
-18,0,12:18.12
-17,0,12:17.12
-16,0,12:17.12
-15,0,12:18.12
-14,0,12:18.12
-13,0,12:18.12
-12,0,12:18.12
9,0,12:18.7
-28,1,12:18.12
-27,1,12:18.12
-26,1,12:18.12
-25,1,12:18.12
-24,1,12:18.12
-23,1,12:17.12
-22,1,12:17.12
-21,1,12:17.12
-20,1,12:17.12
-19,1,12:18.12
-18,1,12:17.12
-17,1,12:17.12
-16,1,12:17.12
-15,1,12:17.12
-14,1,12:18.12
-13,1,12:18.12
-12,1,12:18.12
-29,2,12:18.12
-28,2,12:18.12
-27,2,12:18.12
-26,2,12:18.12
-25,2,12:18.12
-24,2,12:17.12
-23,2,12:18.12
-22,2,12:17.12
-20,2,12:18.12
-19,2,12:18.12
-18,2,12:17.12
-17,2,12:17.12
-16,2,12:17.12
-15,2,12:18.12
-14,2,12:18.12
-13,2,12:18.12
-12,2,12:18.12
-11,2,12:18.12
7,2,12:18.15
-36,3,12:18.12
-35,3,12:18.12
-34,3,12:18.12
-33,3,12:18.12
-32,3,12:18.12
-28,3,12:18.12
-27,3,12:18.12
-26,3,12:17.12
-25,3,12:18.12
-24,3,12:18.12
-23,3,12:18.12
-22,3,12:18.12
-20,3,12:18.12
-19,3,12:18.12
-18,3,12:17.12
-17,3,12:17.12
-16,3,12:17.12
-15,3,12:18.12
-14,3,12:18.12
-13,3,12:18.12
-37,4,12:18.12
-36,4,12:18.12
-35,4,12:18.12
-34,4,12:18.12
-33,4,12:18.12
-32,4,12:18.12
-31,4,12:18.12
-28,4,12:17.12
-27,4,12:17.12
-26,4,12:18.12
-25,4,12:18.12
-24,4,12:18.12
-23,4,12:18.12
-22,4,12:18.12
-21,4,12:18.12
-20,4,12:18.12
-19,4,12:18.12
-18,4,12:18.12
-17,4,12:17.12
-16,4,12:17.12
-15,4,12:18.12
-14,4,12:18.12
-13,4,12:18.12
1,4,12:18.12
-29,5,12:18.12
-28,5,12:18.12
-27,5,12:18.12
-26,5,12:18.12
-25,5,12:18.12
-24,5,12:18.12
-23,5,12:18.12
-22,5,12:18.12
-21,5,12:18.12
-20,5,12:18.12
-19,5,12:18.12
-18,5,12:18.12
-17,5,12:18.12
-16,5,12:17.12
-15,5,12:18.12
-14,5,12:18.12
-13,5,12:18.12
-3,5,12:17.12
-2,5,12:17.12
-1,5,12:17.12
0,5,12:17.12
1,5,12:17.12
-29,6,12:18.12
-28,6,12:18.12
-27,6,12:18.12
-26,6,12:18.12
-25,6,12:18.12
-24,6,12:18.12
-23,6,12:18.12
-22,6,12:18.12
-20,6,12:18.12
-19,6,12:18.12
-18,6,12:18.12
-17,6,12:18.12
-16,6,12:18.12
-15,6,12:18.12
-14,6,12:18.12
-13,6,12:18.12
-9,6,12:18.15
-4,6,12:17.12
-3,6,12:17.12
1,6,12:17.12
2,6,12:17.12
-29,7,12:18.12
-28,7,12:18.12
-27,7,12:18.12
-25,7,12:18.12
-24,7,12:18.12
-18,7,12:18.12
-17,7,12:18.12
-16,7,12:18.12
-15,7,12:18.12
-14,7,12:18.12
-13,7,12:18.12
-6,7,12:18.15
-5,7,12:17.12
-4,7,12:17.12
2,7,12:17.12
3,7,12:17.12
-30,8,12:18.12
-29,8,12:18.12
-28,8,12:18.12
-24,8,12:18.12
-23,8,12:18.12
-15,8,12:18.12
-14,8,12:18.12
-4,8,12:17.12
3,8,12:17.12
-30,9,12:18.12
-29,9,12:18.12
-24,9,12:18.12
-23,9,12:18.12
-13,9,12:18.12
-12,9,12:18.12
-4,9,12:17.12
-3,9,12:17.12
2,9,12:17.12
3,9,12:17.12
-24,10,12:18.4
-23,10,12:18.4
-3,10,12:17.12
-2,10,12:17.12
1,10,12:17.12
2,10,12:17.12
-24,11,12:18.4
-23,11,12:18.4
-2,11,12:17.12
-1,11,12:17.12
0,11,12:17.12
1,11,12:17.12
5,16,12:18.15
6,17,12:18.7
-25,-15,13:18.12
-23,-15,13:18.12
-21,-15,13:18.12
-16,-15,13:18.12
-15,-15,13:18.12
-25,-14,13:18.12
-24,-14,13:18.12
-23,-14,13:18.12
-22,-14,13:18.12
-21,-14,13:18.12
-16,-14,13:18.12
-15,-14,13:18.12
-14,-14,13:18.12
-28,-13,13:18.12
-25,-13,13:18.12
-24,-13,13:18.12
-23,-13,13:18.12
-22,-13,13:18.12
-21,-13,13:18.12
-20,-13,13:18.12
-16,-13,13:18.12
-15,-13,13:18.12
-14,-13,13:18.12
-28,-12,13:18.12
-27,-12,13:18.12
-26,-12,13:18.12
-25,-12,13:18.12
-24,-12,13:18.12
-23,-12,13:18.12
-22,-12,13:18.12
-21,-12,13:18.12
-20,-12,13:18.12
-19,-12,13:18.12
-16,-12,13:18.12
-15,-12,13:18.12
-28,-11,13:18.12
-27,-11,13:18.12
-26,-11,13:18.12
-25,-11,13:18.12
-24,-11,13:18.12
-23,-11,13:18.12
-21,-11,13:18.12
-20,-11,13:18.12
-19,-11,13:18.12
-16,-11,13:18.12
-15,-11,13:18.12
-12,-11,13:18.12
-11,-11,13:18.12
-9,-11,13:18.12
-26,-10,13:18.12
-25,-10,13:18.12
-24,-10,13:18.12
-23,-10,13:18.12
-21,-10,13:18.12
-19,-10,13:18.12
-18,-10,13:18.12
-17,-10,13:18.12
-16,-10,13:18.12
-15,-10,13:18.12
-14,-10,13:18.12
-10,-10,13:18.12
-9,-10,13:18.12
-25,-9,13:18.12
-24,-9,13:18.12
-23,-9,13:17.12
-22,-9,13:17.12
-21,-9,13:18.12
-19,-9,13:18.12
-18,-9,13:18.12
-17,-9,13:18.12
-16,-9,13:18.12
-15,-9,13:18.12
-13,-9,13:18.12
-10,-9,13:18.12
-25,-8,13:18.12
-24,-8,13:18.12
-23,-8,13:17.12
-22,-8,13:17.12
-21,-8,13:18.12
-19,-8,13:18.12
-18,-8,13:18.12
-17,-8,13:17.12
-16,-8,13:17.12
-15,-8,13:18.12
-14,-8,13:18.12
-13,-8,13:18.12
-12,-8,13:18.12
-11,-8,13:18.12
-10,-8,13:18.12
-9,-8,13:18.12
-8,-8,13:18.12
-7,-8,13:18.12
-25,-7,13:18.12
-24,-7,13:18.12
-23,-7,13:18.12
-21,-7,13:18.12
-18,-7,13:18.12
-17,-7,13:18.12
-16,-7,13:18.12
-14,-7,13:18.12
-12,-7,13:18.12
-11,-7,13:18.12
-10,-7,13:18.12
-8,-7,13:18.12
-7,-7,13:18.12
-6,-7,13:18.12
-28,-6,13:18.12
-27,-6,13:18.12
-26,-6,13:18.12
-25,-6,13:18.12
-24,-6,13:18.12
-23,-6,13:18.12
-22,-6,13:18.12
-21,-6,13:18.12
-17,-6,13:18.12
-16,-6,13:18.12
-15,-6,13:18.12
-14,-6,13:18.12
-13,-6,13:18.12
-12,-6,13:18.12
-11,-6,13:18.12
-10,-6,13:18.12
-9,-6,13:17.12
-8,-6,13:17.12
-7,-6,13:18.12
-6,-6,13:18.12
-5,-6,13:18.12
-28,-5,13:18.12
-27,-5,13:18.12
-26,-5,13:18.12
-25,-5,13:18.12
-23,-5,13:18.12
-21,-5,13:18.12
-19,-5,13:18.12
-17,-5,13:18.12
-16,-5,13:18.12
-15,-5,13:18.12
-14,-5,13:18.12
-13,-5,13:18.12
-12,-5,13:18.12
-11,-5,13:18.12
-10,-5,13:17.12
-9,-5,13:17.12
-8,-5,13:17.12
-7,-5,13:18.12
-6,-5,13:18.12
-5,-5,13:18.12
-4,-5,13:18.12
-28,-4,13:18.12
-27,-4,13:18.12
-26,-4,13:18.12
-25,-4,13:18.12
-17,-4,13:18.12
-16,-4,13:18.12
-11,-4,13:18.12
-10,-4,13:18.12
-9,-4,13:18.12
-8,-4,13:18.12
-7,-4,13:18.12
-6,-4,13:18.12
-5,-4,13:18.12
-27,-3,13:18.12
-26,-3,13:18.12
-25,-3,13:18.12
-24,-3,13:18.12
-23,-3,13:17.12
-20,-3,13:18.12
-19,-3,13:18.12
-17,-3,13:18.12
-11,-3,13:18.12
-10,-3,13:18.12
-9,-3,13:18.12
-8,-3,13:18.12
-7,-3,13:18.12
-27,-2,13:18.12
-26,-2,13:18.12
-25,-2,13:18.12
-24,-2,13:18.12
-23,-2,13:18.12
-22,-2,13:18.12
-21,-2,13:17.12
-20,-2,13:17.12
-19,-2,13:18.12
-18,-2,13:18.12
-15,-2,13:18.12
-14,-2,13:18.12
-13,-2,13:18.12
-12,-2,13:18.12
-11,-2,13:18.12
-10,-2,13:18.12
-9,-2,13:18.12
-8,-2,13:18.12
-7,-2,13:18.12
-30,-1,13:18.12
-29,-1,13:18.12
-28,-1,13:18.12
-27,-1,13:18.12
-26,-1,13:18.12
-25,-1,13:18.12
-24,-1,13:17.12
-23,-1,13:17.12
-22,-1,13:17.12
-21,-1,13:17.12
-20,-1,13:17.12
-19,-1,13:17.12
-18,-1,13:17.12
-17,-1,13:18.12
-16,-1,13:18.12
-15,-1,13:18.12
-12,-1,13:18.12
-11,-1,13:18.12
-10,-1,13:18.12
5,-1,13:18.7
9,-1,13:18.7
-30,0,13:18.12
-29,0,13:18.12
-28,0,13:18.12
-27,0,13:18.12
-26,0,13:18.12
-25,0,13:18.12
-23,0,13:18.12
-22,0,13:18.12
-20,0,13:17.12
-19,0,13:17.12
-18,0,13:17.12
-17,0,13:18.12
-16,0,13:17.12
-15,0,13:17.12
-14,0,13:17.12
-13,0,13:18.12
-12,0,13:18.12
-11,0,13:18.12
-10,0,13:18.12
-6,0,13:18.12
8,0,13:18.7
9,0,13:18.7
-30,1,13:18.12
-29,1,13:18.12
-28,1,13:18.12
-27,1,13:18.12
-25,1,13:18.12
-24,1,13:18.12
-23,1,13:18.12
-19,1,13:18.12
-18,1,13:18.12
-17,1,13:18.12
-16,1,13:17.12
-15,1,13:17.12
-14,1,13:17.12
-13,1,13:18.15
-12,1,13:18.12
-11,1,13:18.12
-10,1,13:18.12
-29,2,13:18.12
-28,2,13:18.12
-27,2,13:18.12
-26,2,13:18.12
-25,2,13:18.12
-24,2,13:18.12
-23,2,13:18.12
-20,2,13:18.12
-18,2,13:18.12
-13,2,13:18.12
-12,2,13:18.12
-11,2,13:18.12
-10,2,13:18.12
7,2,13:18.15
-28,3,13:18.12
-27,3,13:18.12
-26,3,13:18.12
-25,3,13:18.12
-24,3,13:18.12
-20,3,13:18.12
-19,3,13:18.12
-18,3,13:18.12
-16,3,13:18.12
-14,3,13:18.12
-13,3,13:18.12
-12,3,13:18.12
-11,3,13:18.12
-2,3,13:18.12
-1,3,13:18.12
1,3,13:18.12
-30,4,13:18.12
-29,4,13:18.12
-28,4,13:18.12
-27,4,13:18.12
-26,4,13:18.12
-25,4,13:18.12
-24,4,13:18.12
-20,4,13:18.12
-15,4,13:18.12
-14,4,13:18.12
-13,4,13:18.12
-12,4,13:18.12
-11,4,13:18.12
-2,4,13:18.12
0,4,13:18.12
1,4,13:18.12
2,4,13:18.12
4,4,13:18.12
-37,5,13:18.12
-36,5,13:18.12
-35,5,13:18.12
-34,5,13:18.12
-33,5,13:18.12
-32,5,13:18.12
-31,5,13:18.12
-30,5,13:18.12
-29,5,13:17.12
-28,5,13:18.12
-27,5,13:18.12
-26,5,13:18.12
-25,5,13:18.12
-24,5,13:18.12
-23,5,13:18.12
-22,5,13:18.12
-21,5,13:18.12
-20,5,13:18.12
-19,5,13:18.12
-16,5,13:17.12
-15,5,13:17.12
-14,5,13:18.12
-13,5,13:18.12
-12,5,13:18.12
-11,5,13:18.12
-2,5,13:17.12
-1,5,13:17.12
0,5,13:17.12
1,5,13:17.12
4,5,13:18.12
-36,6,13:18.12
-35,6,13:18.12
-34,6,13:18.12
-33,6,13:18.12
-32,6,13:18.12
-31,6,13:17.12
-30,6,13:17.12
-29,6,13:18.12
-28,6,13:18.12
-27,6,13:18.12
-26,6,13:18.12
-25,6,13:18.12
-24,6,13:18.12
-23,6,13:18.12
-22,6,13:18.12
-21,6,13:18.12
-20,6,13:18.12
-19,6,13:18.12
-16,6,13:17.12
-15,6,13:17.12
-14,6,13:18.12
-13,6,13:18.12
-12,6,13:18.12
-11,6,13:18.12
-9,6,13:18.15
-3,6,13:17.12
2,6,13:17.12
-35,7,13:18.12
-34,7,13:18.12
-33,7,13:18.12
-32,7,13:18.12
-31,7,13:18.12
-30,7,13:18.12
-27,7,13:18.12
-26,7,13:18.12
-25,7,13:18.12
-24,7,13:18.12
-23,7,13:18.12
-22,7,13:18.12
-21,7,13:18.12
-20,7,13:18.12
-19,7,13:18.12
-18,7,13:18.12
-17,7,13:18.12
-16,7,13:18.12
-15,7,13:17.12
-14,7,13:17.12
-13,7,13:18.12
-12,7,13:18.12
-11,7,13:18.12
-6,7,13:18.15
-4,7,13:17.12
-3,7,13:17.12
2,7,13:17.12
3,7,13:17.12
-36,8,13:18.12
-35,8,13:18.12
-34,8,13:18.12
-33,8,13:18.12
-32,8,13:18.12
-28,8,13:18.12
-27,8,13:18.12
-26,8,13:18.12
-25,8,13:18.12
-22,8,13:18.12
-20,8,13:18.12
-19,8,13:18.12
-18,8,13:18.12
-17,8,13:18.12
-16,8,13:18.12
-15,8,13:18.12
-14,8,13:17.12
-12,8,13:18.12
-11,8,13:18.12
-4,8,13:17.12
3,8,13:17.12
4,8,13:17.12
-36,9,13:18.12
-35,9,13:18.12
-34,9,13:18.12
-33,9,13:18.12
-29,9,13:18.12
-28,9,13:18.12
-27,9,13:18.12
-26,9,13:18.12
-25,9,13:18.12
-20,9,13:18.12
-19,9,13:18.12
-17,9,13:18.12
-16,9,13:18.12
-15,9,13:18.12
-14,9,13:18.12
-13,9,13:18.12
-12,9,13:18.12
-11,9,13:18.12
-3,9,13:17.12
3,9,13:17.12
4,9,13:17.12
-30,10,13:18.12
-29,10,13:18.12
-28,10,13:18.12
-26,10,13:18.12
-25,10,13:18.12
-24,10,13:18.12
-15,10,13:18.12
-14,10,13:18.12
-13,10,13:18.12
-12,10,13:18.12
-3,10,13:17.12
-2,10,13:17.12
1,10,13:17.12
2,10,13:17.12
-30,11,13:18.12
-29,11,13:18.12
-26,11,13:18.4
-25,11,13:18.12
-24,11,13:18.12
-2,11,13:17.12
-1,11,13:17.12
0,11,13:17.12
1,11,13:17.12
-26,12,13:18.4
-25,12,13:18.4
-24,12,13:18.4
-25,13,13:18.4
5,14,13:18.15
5,15,13:18.15
6,17,13:18.7
6,18,13:18.7
-21,-16,14:18.12
-14,-16,14:18.12
-26,-15,14:18.12
-25,-15,14:18.12
-23,-15,14:18.12
-21,-15,14:18.12
-15,-15,14:18.12
-14,-15,14:18.12
-28,-14,14:18.12
-27,-14,14:18.12
-26,-14,14:18.12
-25,-14,14:18.12
-23,-14,14:18.12
-22,-14,14:18.12
-21,-14,14:18.12
-20,-14,14:18.12
-16,-14,14:18.12
-15,-14,14:18.12
-14,-14,14:18.12
-28,-13,14:18.12
-27,-13,14:18.12
-26,-13,14:18.12
-25,-13,14:18.12
-23,-13,14:18.12
-22,-13,14:18.12
-21,-13,14:18.12
-20,-13,14:18.12
-19,-13,14:18.12
-17,-13,14:18.12
-16,-13,14:18.12
-15,-13,14:18.12
-14,-13,14:18.12
-12,-13,14:18.12
-11,-13,14:18.12
-10,-13,14:18.4
-26,-12,14:18.12
-25,-12,14:18.12
-23,-12,14:18.12
-22,-12,14:18.12
-21,-12,14:18.12
-20,-12,14:18.12
-19,-12,14:18.12
-18,-12,14:18.12
-16,-12,14:18.12
-15,-12,14:18.12
-14,-12,14:18.12
-13,-12,14:18.12
-12,-12,14:18.12
-11,-12,14:18.12
-25,-11,14:18.12
-24,-11,14:18.12
-23,-11,14:18.12
-21,-11,14:18.12
-19,-11,14:18.12
-18,-11,14:18.12
-17,-11,14:18.12
-16,-11,14:17.12
-15,-11,14:18.12
-14,-11,14:18.12
-13,-11,14:18.12
-12,-11,14:18.12
-9,-11,14:18.12
-26,-10,14:18.12
-24,-10,14:18.12
-23,-10,14:17.12
-21,-10,14:18.12
-19,-10,14:18.12
-17,-10,14:18.12
-16,-10,14:17.12
-15,-10,14:18.12
-14,-10,14:18.12
-11,-10,14:18.12
-10,-10,14:18.12
-9,-10,14:18.12
-6,-10,14:18.12
-5,-10,14:18.12
-27,-9,14:18.12
-26,-9,14:18.12
-24,-9,14:17.12
-23,-9,14:17.12
-21,-9,14:18.12
-19,-9,14:18.12
-18,-9,14:18.12
-17,-9,14:17.12
-16,-9,14:17.12
-15,-9,14:18.12
-14,-9,14:18.12
-13,-9,14:18.12
-12,-9,14:18.12
-11,-9,14:18.12
-10,-9,14:18.12
-9,-9,14:18.12
-6,-9,14:18.12
-29,-8,14:18.12
-27,-8,14:18.12
-26,-8,14:18.12
-21,-8,14:18.12
-18,-8,14:18.12
-17,-8,14:17.12
-16,-8,14:17.12
-15,-8,14:18.12
-14,-8,14:18.12
-13,-8,14:18.12
-12,-8,14:18.12
-11,-8,14:18.12
-10,-8,14:18.12
-9,-8,14:18.12
-8,-8,14:18.12
-7,-8,14:18.12
-6,-8,14:18.12
-5,-8,14:18.12
-29,-7,14:18.12
-28,-7,14:18.12
-27,-7,14:18.12
-26,-7,14:18.12
-25,-7,14:18.12
-24,-7,14:18.12
-15,-7,14:18.12
-14,-7,14:18.12
-13,-7,14:18.12
-12,-7,14:18.12
-11,-7,14:18.12
-10,-7,14:18.12
-9,-7,14:18.12
-8,-7,14:18.12
-7,-7,14:18.12
-6,-7,14:18.12
-5,-7,14:18.12
-4,-7,14:18.12
-29,-6,14:18.12
-28,-6,14:18.12
-27,-6,14:18.12
-24,-6,14:18.12
-23,-6,14:18.12
-16,-6,14:18.12
-15,-6,14:18.12
-14,-6,14:18.12
-13,-6,14:18.12
-11,-6,14:18.12
-10,-6,14:18.12
-9,-6,14:18.12
-8,-6,14:18.12
-7,-6,14:17.12
-6,-6,14:17.12
-29,-5,14:18.12
-27,-5,14:18.12
-26,-5,14:18.12
-16,-5,14:18.12
-11,-5,14:18.12
-10,-5,14:18.12
-9,-5,14:18.12
-8,-5,14:18.12
-4,-5,14:18.12
-3,-5,14:18.12
-29,-4,14:18.12
-28,-4,14:18.12
-26,-4,14:18.12
-25,-4,14:18.12
-17,-4,14:18.12
-10,-4,14:18.12
-9,-4,14:18.12
-5,-4,14:18.12
-4,-4,14:18.12
-29,-3,14:18.12
-28,-3,14:18.12
-27,-3,14:18.12
-25,-3,14:17.12
-24,-3,14:17.12
-23,-3,14:18.12
-19,-3,14:18.12
-18,-3,14:18.12
-17,-3,14:18.12
-11,-3,14:18.12
-10,-3,14:18.12
-7,-3,14:18.12
-6,-3,14:18.12
-5,-3,14:18.12
-31,-2,14:18.12
-30,-2,14:18.12
-29,-2,14:18.12
-28,-2,14:18.12
-27,-2,14:18.12
-26,-2,14:18.12
-25,-2,14:17.12
-24,-2,14:17.12
-23,-2,14:17.12
-22,-2,14:18.12
-21,-2,14:18.12
-18,-2,14:18.12
-17,-2,14:18.12
-16,-2,14:18.12
-14,-2,14:18.12
-10,-2,14:18.12
-9,-2,14:18.12
-8,-2,14:18.12
-7,-2,14:18.12
-30,-1,14:18.12
-29,-1,14:18.12
-28,-1,14:18.12
-27,-1,14:18.12
-26,-1,14:18.12
-25,-1,14:17.12
-24,-1,14:17.12
-20,-1,14:17.12
-19,-1,14:17.12
-18,-1,14:17.12
-16,-1,14:18.12
-15,-1,14:18.12
-10,-1,14:18.12
-9,-1,14:18.12
-8,-1,14:18.12
5,-1,14:18.7
9,-1,14:18.7
10,-1,14:18.7
-32,0,14:18.12
-31,0,14:18.12
-30,0,14:18.12
-29,0,14:18.12
-28,0,14:18.12
-27,0,14:18.12
-21,0,14:18.12
-20,0,14:18.12
-19,0,14:17.12
-18,0,14:17.12
-17,0,14:18.12
-16,0,14:18.12
-15,0,14:17.12
-14,0,14:17.12
-13,0,14:17.12
-12,0,14:18.12
-11,0,14:18.12
-10,0,14:18.12
-9,0,14:18.12
-8,0,14:18.12
-7,0,14:18.12
-6,0,14:18.12
-5,0,14:18.12
-4,0,14:18.4
8,0,14:18.7
9,0,14:18.7
-31,1,14:18.12
-30,1,14:18.12
-29,1,14:18.12
-22,1,14:18.12
-21,1,14:18.12
-20,1,14:17.12
-19,1,14:17.12
-17,1,14:18.12
-16,1,14:18.12
-14,1,14:17.12
-13,1,14:17.12
-31,2,14:18.12
-30,2,14:18.12
-24,2,14:18.12
-23,2,14:18.12
-22,2,14:18.12
-21,2,14:18.12
-20,2,14:18.12
-19,2,14:18.12
-17,2,14:18.12
-11,2,14:18.12
-10,2,14:18.12
-9,2,14:18.12
1,2,14:18.12
2,2,14:18.12
7,2,14:18.15
-31,3,14:18.12
-30,3,14:18.12
-28,3,14:18.12
-26,3,14:17.12
-25,3,14:18.12
-24,3,14:18.12
-23,3,14:18.12
-22,3,14:18.12
-21,3,14:18.12
-20,3,14:18.12
-19,3,14:18.12
-18,3,14:18.12
-16,3,14:18.12
-12,3,14:18.12
-11,3,14:18.12
-10,3,14:18.12
-2,3,14:18.12
-1,3,14:18.12
0,3,14:18.12
1,3,14:18.12
2,3,14:18.12
3,3,14:18.12
-32,4,14:18.12
-31,4,14:18.12
-30,4,14:18.12
-29,4,14:18.12
-28,4,14:18.12
-27,4,14:18.12
-26,4,14:18.12
-25,4,14:18.12
-24,4,14:18.12
-23,4,14:18.12
-22,4,14:18.12
-21,4,14:18.12
-20,4,14:18.12
-19,4,14:18.12
-18,4,14:18.12
-15,4,14:18.12
-14,4,14:18.12
-13,4,14:18.12
-12,4,14:18.12
-11,4,14:18.12
-10,4,14:18.12
-2,4,14:18.12
0,4,14:18.12
1,4,14:18.12
2,4,14:18.12
4,4,14:18.12
-33,5,14:18.12
-32,5,14:18.12
-31,5,14:18.12
-30,5,14:18.12
-28,5,14:18.12
-27,5,14:18.12
-26,5,14:18.12
-25,5,14:18.12
-24,5,14:18.12
-23,5,14:18.12
-22,5,14:18.12
-21,5,14:18.12
-20,5,14:18.12
-19,5,14:18.12
-18,5,14:18.12
-15,5,14:17.12
-13,5,14:18.12
-12,5,14:18.12
-11,5,14:18.12
-10,5,14:18.12
-2,5,14:17.12
-1,5,14:17.12
0,5,14:17.12
1,5,14:17.12
2,5,14:17.12
4,5,14:18.12
-38,6,14:18.12
-37,6,14:18.12
-36,6,14:18.12
-35,6,14:18.12
-34,6,14:18.12
-33,6,14:18.12
-32,6,14:18.12
-31,6,14:18.12
-30,6,14:18.12
-28,6,14:18.12
-27,6,14:18.12
-26,6,14:18.12
-25,6,14:18.12
-24,6,14:18.12
-23,6,14:18.12
-22,6,14:18.12
-20,6,14:18.12
-19,6,14:18.12
-18,6,14:18.12
-16,6,14:17.12
-15,6,14:17.12
-14,6,14:18.12
-13,6,14:18.12
-12,6,14:18.12
-11,6,14:18.12
-10,6,14:18.12
-9,6,14:18.15
-3,6,14:17.12
-2,6,14:17.12
2,6,14:17.12
3,6,14:17.12
-36,7,14:18.12
-33,7,14:17.12
-32,7,14:17.12
-31,7,14:18.12
-30,7,14:18.12
-29,7,14:18.12
-28,7,14:18.12
-26,7,14:18.12
-21,7,14:18.12
-20,7,14:18.12
-19,7,14:18.12
-15,7,14:18.12
-14,7,14:18.12
-13,7,14:18.12
-12,7,14:18.12
-10,7,14:18.12
-6,7,14:18.15
-4,7,14:18.15
-3,7,14:17.12
3,7,14:17.12
4,7,14:17.12
-32,8,14:18.12
-31,8,14:18.12
-30,8,14:18.12
-29,8,14:18.12
-28,8,14:18.12
-27,8,14:18.12
-26,8,14:18.12
-21,8,14:18.12
-16,8,14:18.12
-15,8,14:18.12
-14,8,14:17.12
-12,8,14:18.12
-4,8,14:17.12
-3,8,14:17.12
4,8,14:17.12
-32,9,14:18.12
-28,9,14:18.12
-27,9,14:18.12
-26,9,14:18.12
-22,9,14:18.12
-21,9,14:18.12
-20,9,14:18.12
-18,9,14:18.12
-17,9,14:18.12
-16,9,14:18.12
-15,9,14:18.12
-14,9,14:18.12
-13,9,14:18.12
-12,9,14:18.12
-3,9,14:17.12
3,9,14:17.12
4,9,14:17.12
-28,10,14:18.12
-27,10,14:18.12
-26,10,14:18.12
-19,10,14:18.12
-18,10,14:18.12
-17,10,14:18.12
-16,10,14:18.12
-15,10,14:18.12
-14,10,14:18.12
-13,10,14:18.12
-12,10,14:18.12
-3,10,14:17.12
-2,10,14:17.12
2,10,14:17.12
3,10,14:17.12
-29,11,14:18.12
-28,11,14:18.12
-27,11,14:18.4
-26,11,14:18.4
-20,11,14:18.12
-18,11,14:18.12
-14,11,14:18.12
-13,11,14:18.12
-12,11,14:18.12
-2,11,14:17.12
-1,11,14:17.12
0,11,14:17.12
1,11,14:17.12
2,11,14:17.12
-29,12,14:18.4
-28,12,14:18.4
-27,12,14:18.4
-20,12,14:18.4
-15,12,14:18.12
-14,12,14:18.12
-13,12,14:18.12
-12,12,14:18.12
-29,13,14:18.4
-15,13,14:18.12
-12,13,14:18.12
5,14,14:18.15
5,15,14:18.15
6,17,14:18.7
6,18,14:18.7
7,21,14:18.7
-23,-16,15:18.12
-22,-16,15:18.12
-21,-16,15:18.12
-16,-16,15:18.12
-13,-16,15:18.12
-27,-15,15:18.12
-24,-15,15:18.12
-23,-15,15:18.12
-22,-15,15:18.12
-20,-15,15:18.12
-19,-15,15:18.12
-17,-15,15:18.12
-16,-15,15:18.12
-13,-15,15:18.12
-12,-15,15:18.12
-26,-14,15:18.12
-25,-14,15:18.12
-24,-14,15:18.12
-23,-14,15:18.12
-22,-14,15:18.12
-20,-14,15:18.12
-19,-14,15:18.12
-18,-14,15:18.12
-17,-14,15:18.12
-16,-14,15:18.12
-14,-14,15:18.12
-13,-14,15:18.12
-12,-14,15:18.12
-11,-14,15:18.12
-10,-14,15:18.4
-26,-13,15:18.12
-25,-13,15:18.12
-24,-13,15:18.12
-23,-13,15:18.12
-22,-13,15:18.12
-21,-13,15:18.12
-20,-13,15:18.12
-19,-13,15:18.12
-18,-13,15:18.12
-17,-13,15:18.12
-14,-13,15:18.12
-13,-13,15:18.12
-12,-13,15:18.12
-25,-12,15:18.12
-24,-12,15:18.12
-23,-12,15:18.12
-22,-12,15:18.12
-20,-12,15:18.12
-19,-12,15:18.12
-18,-12,15:18.12
-16,-12,15:17.12
-15,-12,15:17.12
-14,-12,15:18.12
-13,-12,15:18.12
-24,-11,15:18.12
-23,-11,15:18.12
-22,-11,15:18.12
-21,-11,15:18.12
-19,-11,15:18.12
-18,-11,15:18.12
-17,-11,15:18.12
-16,-11,15:17.12
-15,-11,15:18.12
-14,-11,15:18.12
-13,-11,15:18.12
-12,-11,15:18.12
-11,-11,15:18.12
-10,-11,15:18.4
-9,-11,15:18.12
-5,-11,15:18.12
-24,-10,15:17.12
-23,-10,15:17.12
-21,-10,15:18.12
-19,-10,15:18.12
-18,-10,15:18.12
-17,-10,15:18.12
-15,-10,15:18.12
-14,-10,15:18.12
-13,-10,15:18.12
-12,-10,15:18.12
-11,-10,15:18.12
-10,-10,15:18.12
-9,-10,15:18.12
-5,-10,15:18.12
-30,-9,15:18.4
-29,-9,15:18.12
-21,-9,15:18.12
-18,-9,15:18.12
-17,-9,15:18.12
-15,-9,15:18.12
-14,-9,15:18.12
-13,-9,15:18.12
-12,-9,15:18.12
-11,-9,15:18.12
-10,-9,15:18.12
-9,-9,15:18.12
-6,-9,15:18.12
-5,-9,15:18.12
-29,-8,15:18.12
-28,-8,15:18.12
-27,-8,15:18.12
-21,-8,15:18.12
-18,-8,15:18.12
-17,-8,15:18.12
-16,-8,15:18.12
-15,-8,15:18.12
-14,-8,15:18.12
-13,-8,15:18.12
-12,-8,15:18.12
-10,-8,15:18.12
-9,-8,15:18.12
-8,-8,15:18.12
-7,-8,15:18.12
-6,-8,15:18.12
-5,-8,15:18.12
-4,-8,15:18.12
-29,-7,15:18.12
-28,-7,15:18.12
-27,-7,15:18.12
-26,-7,15:18.12
-25,-7,15:18.12
-24,-7,15:18.12
-17,-7,15:18.12
-15,-7,15:18.12
-14,-7,15:18.12
-9,-7,15:18.12
-8,-7,15:18.12
-7,-7,15:18.12
-6,-7,15:18.12
-5,-7,15:18.12
-4,-7,15:18.12
-27,-6,15:18.12
-26,-6,15:18.12
-25,-6,15:18.12
-24,-6,15:18.12
-23,-6,15:18.12
-17,-6,15:18.12
-12,-6,15:18.12
-9,-6,15:18.12
-8,-6,15:18.12
-7,-6,15:18.12
-6,-6,15:18.12
-5,-6,15:18.12
-27,-5,15:18.12
-26,-5,15:18.12
-25,-5,15:18.12
-23,-5,15:18.12
-18,-5,15:18.12
-16,-5,15:18.12
-11,-5,15:18.12
-10,-5,15:18.12
-9,-5,15:18.12
-8,-5,15:18.12
-7,-5,15:18.12
-26,-4,15:18.12
-25,-4,15:18.12
-23,-4,15:18.12
-10,-4,15:18.12
-9,-4,15:18.12
-30,-3,15:18.12
-29,-3,15:18.12
-26,-3,15:17.12
-25,-3,15:17.12
-23,-3,15:18.12
-22,-3,15:18.12
-21,-3,15:18.12
-18,-3,15:18.12
-17,-3,15:18.12
-10,-3,15:18.12
-9,-3,15:18.12
-8,-3,15:18.12
-29,-2,15:18.12
-28,-2,15:18.12
-27,-2,15:18.12
-26,-2,15:18.12
-25,-2,15:17.12
-24,-2,15:17.12
-23,-2,15:18.12
-18,-2,15:18.12
-16,-2,15:18.12
-15,-2,15:18.12
-10,-2,15:18.12
-8,-2,15:18.12
-7,-2,15:18.12
-30,-1,15:18.12
-29,-1,15:18.12
-28,-1,15:18.12
-27,-1,15:18.12
-24,-1,15:18.12
-20,-1,15:17.12
-19,-1,15:17.12
-18,-1,15:17.12
-10,-1,15:18.12
5,-1,15:18.7
9,-1,15:18.7
-33,0,15:18.12
-32,0,15:18.12
-31,0,15:18.12
-20,0,15:17.12
-19,0,15:17.12
-18,0,15:17.12
-13,0,15:18.12
-12,0,15:18.12
-11,0,15:18.12
-10,0,15:18.12
-9,0,15:18.12
-8,0,15:18.12
-7,0,15:18.12
-6,0,15:18.12
-5,0,15:18.12
-4,0,15:18.12
-3,0,15:18.4
-2,0,15:18.4
8,0,15:18.7
9,0,15:18.7
-32,1,15:18.12
-31,1,15:18.12
-22,1,15:18.12
-21,1,15:18.12
-20,1,15:17.12
-19,1,15:17.12
-16,1,15:18.12
-14,1,15:17.12
-13,1,15:17.12
-12,1,15:18.12
-11,1,15:18.12
-32,2,15:18.12
-31,2,15:18.12
-24,2,15:18.12
-23,2,15:18.12
-21,2,15:17.12
-20,2,15:17.12
-19,2,15:17.12
-12,2,15:18.12
1,2,15:18.12
2,2,15:18.12
7,2,15:18.15
-32,3,15:18.12
-31,3,15:18.12
-30,3,15:18.12
-28,3,15:18.12
-26,3,15:17.12
-25,3,15:18.12
-24,3,15:18.12
-21,3,15:17.12
-20,3,15:18.12
-19,3,15:17.12
-16,3,15:18.12
-11,3,15:18.12
-10,3,15:18.12
-9,3,15:18.12
-8,3,15:18.12
-1,3,15:18.12
0,3,15:18.12
1,3,15:18.12
2,3,15:18.12
-33,4,15:18.12
-32,4,15:18.12
-27,4,15:18.12
-26,4,15:18.12
-25,4,15:18.12
-21,4,15:18.12
-20,4,15:18.12
-15,4,15:18.12
-14,4,15:18.12
-13,4,15:18.12
-12,4,15:18.12
-11,4,15:18.12
-10,4,15:18.12
-9,4,15:18.12
-2,4,15:18.12
-1,4,15:18.12
0,4,15:18.12
1,4,15:18.12
2,4,15:18.12
3,4,15:18.12
4,4,15:18.12
-34,5,15:18.12
-33,5,15:18.12
-31,5,15:18.12
-30,5,15:18.12
-28,5,15:18.12
-27,5,15:18.12
-25,5,15:18.12
-23,5,15:18.12
-22,5,15:18.12
-21,5,15:18.12
-20,5,15:18.12
-16,5,15:17.12
-15,5,15:17.12
-12,5,15:18.12
-11,5,15:18.12
-10,5,15:18.12
-9,5,15:18.12
-8,5,15:18.12
-2,5,15:18.12
-1,5,15:17.12
0,5,15:17.12
1,5,15:17.12
2,5,15:17.12
3,5,15:18.12
4,5,15:18.12
-37,6,15:18.12
-36,6,15:18.12
-35,6,15:18.12
-34,6,15:18.12
-33,6,15:18.12
-32,6,15:18.12
-31,6,15:18.12
-30,6,15:18.12
-28,6,15:18.12
-26,6,15:18.12
-25,6,15:18.12
-24,6,15:18.12
-23,6,15:18.12
-22,6,15:18.12
-21,6,15:18.12
-20,6,15:18.12
-19,6,15:18.12
-16,6,15:17.12
-15,6,15:17.12
-14,6,15:18.12
-12,6,15:18.12
-11,6,15:18.12
-10,6,15:18.12
-9,6,15:18.12
-8,6,15:18.12
-2,6,15:17.12
2,6,15:17.12
3,6,15:17.12
-34,7,15:17.12
-33,7,15:17.12
-30,7,15:18.12
-29,7,15:18.12
-28,7,15:18.12
-26,7,15:18.12
-25,7,15:18.12
-22,7,15:18.12
-21,7,15:18.12
-20,7,15:18.12
-19,7,15:18.12
-13,7,15:18.12
-12,7,15:18.12
-11,7,15:18.12
-10,7,15:18.12
-7,7,15:18.15
-6,7,15:18.15
-4,7,15:18.15
-3,7,15:17.12
4,7,15:17.12
-35,8,15:17.12
-34,8,15:17.12
-30,8,15:18.12
-29,8,15:18.12
-26,8,15:18.12
-21,8,15:18.12
-20,8,15:18.12
-19,8,15:18.12
-15,8,15:18.12
-12,8,15:18.12
-11,8,15:18.12
-3,8,15:17.12
4,8,15:17.12
5,8,15:17.12
-32,9,15:18.12
-31,9,15:18.12
-30,9,15:18.12
-29,9,15:18.12
-28,9,15:18.12
-27,9,15:18.12
-16,9,15:18.12
-14,9,15:18.12
-13,9,15:18.12
-12,9,15:18.12
-11,9,15:18.12
-3,9,15:17.12
-2,9,15:17.12
4,9,15:17.12
5,9,15:17.12
-32,10,15:18.12
-31,10,15:18.12
-29,10,15:18.12
-28,10,15:18.12
-27,10,15:18.12
-17,10,15:18.12
-16,10,15:18.12
-15,10,15:18.12
-14,10,15:18.12
-13,10,15:17.12
-12,10,15:18.12
-11,10,15:18.12
-2,10,15:17.12
3,10,15:17.12
4,10,15:17.12
-28,11,15:18.12
-27,11,15:18.4
-18,11,15:18.12
-17,11,15:18.12
-16,11,15:18.12
-15,11,15:18.12
-14,11,15:18.12
-13,11,15:17.12
-12,11,15:17.12
-11,11,15:18.12
-10,11,15:18.12
-1,11,15:17.12
0,11,15:17.12
1,11,15:17.12
2,11,15:17.12
3,11,15:17.12
-28,12,15:18.4
-19,12,15:18.12
-18,12,15:18.12
-17,12,15:18.12
-15,12,15:18.12
-14,12,15:18.12
-13,12,15:18.12
-11,12,15:18.12
-10,12,15:18.12
-20,13,15:18.4
-19,13,15:18.4
-14,13,15:18.12
-13,13,15:18.12
-12,13,15:18.12
-15,14,15:18.12
-14,14,15:18.12
-13,14,15:18.12
-12,14,15:18.12
5,14,15:18.15
6,17,15:18.7
6,18,15:18.7
-17,-19,16:18.4
-17,-18,16:18.4
-18,-17,16:18.12
-17,-17,16:18.12
-16,-17,16:18.12
-24,-16,16:18.12
-23,-16,16:18.12
-22,-16,16:18.12
-21,-16,16:18.12
-18,-16,16:18.12
-17,-16,16:18.12
-16,-16,16:18.12
-24,-15,16:18.12
-23,-15,16:18.12
-22,-15,16:18.12
-21,-15,16:18.12
-20,-15,16:18.12
-19,-15,16:18.12
-18,-15,16:18.12
-17,-15,16:18.12
-16,-15,16:18.12
-12,-15,16:18.12
-11,-15,16:18.12
-26,-14,16:18.12
-23,-14,16:18.12
-22,-14,16:18.12
-21,-14,16:18.12
-20,-14,16:18.12
-19,-14,16:18.12
-18,-14,16:18.12
-17,-14,16:18.12
-16,-14,16:18.12
-14,-14,16:18.12
-13,-14,16:18.12
-12,-14,16:18.12
-26,-13,16:18.12
-25,-13,16:18.12
-21,-13,16:18.12
-20,-13,16:18.12
-19,-13,16:18.12
-18,-13,16:18.12
-17,-13,16:18.12
-16,-13,16:18.12
-15,-13,16:18.12
-14,-13,16:18.12
-13,-13,16:18.12
-12,-13,16:18.12
-26,-12,16:18.12
-25,-12,16:18.12
-24,-12,16:17.12
-22,-12,16:18.12
-21,-12,16:18.12
-19,-12,16:18.12
-18,-12,16:18.12
-16,-12,16:17.12
-15,-12,16:18.12
-14,-12,16:18.12
-13,-12,16:18.12
-12,-12,16:18.12
-11,-12,16:18.12
-10,-12,16:18.4
-26,-11,16:18.12
-25,-11,16:18.12
-24,-11,16:18.12
-17,-11,16:18.12
-16,-11,16:17.12
-15,-11,16:18.12
-14,-11,16:18.12
-13,-11,16:18.12
-12,-11,16:18.12
-11,-11,16:18.12
-10,-11,16:18.4
-9,-11,16:18.12
-8,-11,16:18.12
-4,-11,16:18.12
-28,-10,16:18.12
-26,-10,16:18.12
-24,-10,16:17.12
-23,-10,16:17.12
-17,-10,16:18.12
-16,-10,16:18.12
-14,-10,16:18.12
-13,-10,16:18.12
-12,-10,16:18.12
-11,-10,16:18.12
-10,-10,16:18.12
-9,-10,16:18.12
-8,-10,16:18.12
-6,-10,16:18.12
-5,-10,16:18.12
-4,-10,16:18.12
-29,-9,16:18.12
-28,-9,16:18.12
-27,-9,16:18.12
-26,-9,16:18.12
-25,-9,16:18.12
-24,-9,16:18.12
-17,-9,16:18.12
-16,-9,16:18.12
-15,-9,16:18.12
-14,-9,16:18.12
-13,-9,16:18.12
-12,-9,16:18.12
-11,-9,16:18.12
-10,-9,16:18.12
-9,-9,16:18.12
-8,-9,16:18.12
-7,-9,16:18.12
-6,-9,16:18.12
-5,-9,16:18.12
-4,-9,16:18.12
-3,-9,16:18.12
-29,-8,16:18.12
-28,-8,16:18.12
-27,-8,16:18.12
-26,-8,16:18.12
-25,-8,16:18.12
-24,-8,16:18.12
-17,-8,16:18.12
-13,-8,16:18.12
-8,-8,16:18.12
-7,-8,16:18.12
-4,-8,16:18.12
-3,-8,16:18.12
-29,-7,16:18.12
-28,-7,16:18.12
-27,-7,16:18.12
-26,-7,16:18.12
-25,-7,16:18.12
-24,-7,16:18.12
-17,-7,16:18.12
-13,-7,16:18.12
-8,-7,16:18.12
-7,-7,16:18.12
-6,-7,16:18.12
-5,-7,16:17.12
-4,-7,16:17.12
-28,-6,16:18.12
-27,-6,16:18.12
-25,-6,16:18.12
-24,-6,16:18.12
-17,-6,16:18.12
-12,-6,16:18.12
-11,-6,16:18.12
-8,-6,16:18.12
-7,-6,16:18.12
-6,-6,16:18.12
-5,-6,16:18.12
-28,-5,16:18.12
-27,-5,16:18.12
-24,-5,16:18.12
-23,-5,16:18.12
-18,-5,16:18.12
-17,-5,16:18.12
-11,-5,16:18.12
-10,-5,16:18.12
-9,-5,16:18.12
-8,-5,16:18.12
-7,-5,16:18.12
-5,-5,16:18.12
-4,-5,16:18.12
-27,-4,16:18.12
-23,-4,16:18.12
-22,-4,16:18.12
-18,-4,16:18.12
-9,-4,16:18.12
-4,-4,16:18.12
-3,-4,16:18.12
-30,-3,16:18.12
-29,-3,16:18.12
-28,-3,16:18.12
-26,-3,16:17.12
-25,-3,16:17.12
-23,-3,16:18.12
-22,-3,16:18.12
-21,-3,16:18.12
-20,-3,16:18.12
-18,-3,16:18.12
-10,-3,16:18.12
-9,-3,16:18.12
-31,-2,16:18.12
-30,-2,16:18.12
-29,-2,16:18.12
-28,-2,16:18.12
-27,-2,16:18.12
-26,-2,16:17.12
-25,-2,16:17.12
-24,-2,16:18.12
-23,-2,16:18.12
-19,-2,16:18.12
-18,-2,16:18.12
-10,-2,16:18.12
-9,-2,16:18.12
-32,-1,16:18.12
-30,-1,16:18.12
-29,-1,16:18.12
-28,-1,16:18.12
-27,-1,16:18.12
-25,-1,16:18.12
-24,-1,16:18.12
-19,-1,16:17.12
-18,-1,16:17.12
-11,-1,16:18.12
-10,-1,16:18.12
-9,-1,16:18.12
5,-1,16:18.7
10,-1,16:18.7
-34,0,16:18.12
-33,0,16:18.12
-30,0,16:18.12
-29,0,16:18.12
-28,0,16:18.12
-19,0,16:17.12
-18,0,16:17.12
-13,0,16:17.12
-12,0,16:17.12
-11,0,16:18.12
-10,0,16:18.12
-9,0,16:18.12
-8,0,16:18.12
-7,0,16:18.12
-6,0,16:18.12
-5,0,16:18.12
-4,0,16:18.12
-3,0,16:18.12
-2,0,16:18.12
8,0,16:18.15
9,0,16:18.7
-34,1,16:18.12
-33,1,16:18.12
-23,1,16:18.12
-19,1,16:17.12
-13,1,16:17.12
-12,1,16:18.12
-11,1,16:18.12
-10,1,16:18.12
-9,1,16:18.12
-8,1,16:18.12
-33,2,16:18.12
-32,2,16:18.12
-24,2,16:18.12
-23,2,16:18.12
-13,2,16:18.12
-12,2,16:18.12
-11,2,16:18.12
-10,2,16:18.12
-9,2,16:18.12
7,2,16:18.15
-34,3,16:18.12
-33,3,16:18.12
-32,3,16:18.12
-31,3,16:18.12
-30,3,16:18.12
-28,3,16:18.12
-26,3,16:18.12
-25,3,16:18.12
-24,3,16:18.12
-21,3,16:17.12
-20,3,16:18.12
-19,3,16:18.12
-18,3,16:18.12
-17,3,16:18.12
-16,3,16:18.12
-11,3,16:18.12
-10,3,16:18.12
-8,3,16:18.12
1,3,16:18.12
-34,4,16:18.12
-31,4,16:18.12
-28,4,16:17.12
-27,4,16:18.12
-26,4,16:18.12
-21,4,16:17.12
-20,4,16:17.12
-19,4,16:18.12
-16,4,16:18.12
-15,4,16:18.12
-14,4,16:18.12
-13,4,16:18.12
-10,4,16:18.12
-9,4,16:18.12
-8,4,16:18.12
0,4,16:18.12
1,4,16:18.12
2,4,16:18.12
-34,5,16:18.12
-31,5,16:18.12
-28,5,16:18.12
-27,5,16:18.12
-25,5,16:18.12
-21,5,16:18.12
-20,5,16:17.12
-16,5,16:17.12
-15,5,16:17.12
-13,5,16:18.12
-12,5,16:18.12
-11,5,16:18.12
-10,5,16:18.12
-9,5,16:18.12
-1,5,16:17.12
0,5,16:17.12
1,5,16:18.12
2,5,16:17.12
3,5,16:17.12
-37,6,16:18.12
-36,6,16:18.12
-35,6,16:18.12
-34,6,16:18.12
-32,6,16:18.12
-31,6,16:18.12
-28,6,16:18.12
-26,6,16:18.12
-23,6,16:18.12
-22,6,16:18.12
-21,6,16:18.12
-20,6,16:18.12
-15,6,16:17.12
-11,6,16:18.12
-10,6,16:18.12
-9,6,16:18.15
-8,6,16:18.12
-7,6,16:18.12
-2,6,16:17.12
-1,6,16:17.12
3,6,16:17.12
4,6,16:17.12
-35,7,16:18.12
-34,7,16:18.12
-33,7,16:18.12
-31,7,16:18.12
-30,7,16:18.12
-29,7,16:18.12
-28,7,16:18.12
-26,7,16:18.12
-25,7,16:18.12
-24,7,16:18.12
-23,7,16:18.12
-22,7,16:18.12
-21,7,16:18.12
-20,7,16:18.12
-13,7,16:18.12
-12,7,16:18.12
-11,7,16:18.12
-10,7,16:18.12
-9,7,16:18.12
-8,7,16:18.12
-7,7,16:18.15
-5,7,16:18.15
-4,7,16:18.15
-3,7,16:17.12
-2,7,16:17.12
4,7,16:17.12
5,7,16:17.12
-36,8,16:18.12
-30,8,16:18.12
-29,8,16:18.12
-26,8,16:18.12
-25,8,16:18.12
-24,8,16:18.12
-21,8,16:18.12
-20,8,16:18.12
-19,8,16:18.12
-15,8,16:18.12
-12,8,16:18.12
-11,8,16:18.12
-10,8,16:18.12
-9,8,16:18.12
-3,8,16:17.12
5,8,16:17.12
-30,9,16:18.12
-29,9,16:18.12
-27,9,16:18.12
-26,9,16:18.12
-20,9,16:18.12
-19,9,16:18.12
-16,9,16:18.12
-15,9,16:18.12
-14,9,16:18.12
-13,9,16:18.12
-12,9,16:18.12
-11,9,16:18.12
-10,9,16:18.12
-2,9,16:17.12
5,9,16:17.12
6,9,16:17.12
-30,10,16:18.12
-29,10,16:18.12
-27,10,16:18.12
-20,10,16:18.12
-19,10,16:18.12
-16,10,16:18.12
-14,10,16:18.12
-13,10,16:18.12
-12,10,16:18.12
-11,10,16:18.12
-10,10,16:18.12
-2,10,16:17.12
-1,10,16:17.12
3,10,16:17.12
4,10,16:17.12
5,10,16:17.12
-29,11,16:18.12
-27,11,16:18.4
-16,11,16:18.12
-14,11,16:18.12
-13,11,16:18.12
-12,11,16:17.12
-10,11,16:18.12
-9,11,16:18.12
-1,11,16:17.12
0,11,16:17.12
1,11,16:17.12
2,11,16:17.12
3,11,16:17.12
-28,12,16:18.4
-17,12,16:18.12
-16,12,16:18.12
-15,12,16:18.12
-14,12,16:18.12
-13,12,16:18.12
-12,12,16:17.12
-11,12,16:17.12
-9,12,16:18.12
0,12,16:17.12
1,12,16:17.12
-19,13,16:18.4
-18,13,16:18.4
-17,13,16:18.12
-16,13,16:18.12
-15,13,16:18.12
-14,13,16:18.12
-20,14,16:18.4
-19,14,16:18.4
-18,14,16:18.4
-15,14,16:18.12
-14,14,16:18.12
-13,14,16:18.12
5,14,16:18.15
-19,15,16:18.4
-14,15,16:18.12
-13,15,16:18.12
6,16,16:18.15
6,17,16:18.15
6,18,16:18.7
-16,-20,17:18.4
-19,-19,17:18.4
-18,-19,17:18.4
-17,-19,17:18.4
-16,-19,17:18.4
-19,-18,17:18.4
-18,-18,17:18.4
-17,-18,17:18.4
-16,-18,17:18.4
-15,-18,17:18.4
-11,-18,17:18.4
-23,-17,17:18.12
-22,-17,17:18.12
-21,-17,17:18.12
-20,-17,17:18.4
-19,-17,17:18.12
-18,-17,17:18.12
-16,-17,17:18.12
-15,-17,17:18.12
-13,-17,17:18.12
-12,-17,17:18.12
-11,-17,17:18.12
-27,-16,17:17.12
-25,-16,17:18.12
-23,-16,17:18.12
-22,-16,17:18.12
-21,-16,17:18.12
-20,-16,17:18.12
-19,-16,17:18.12
-18,-16,17:18.12
-16,-16,17:18.12
-14,-16,17:18.12
-13,-16,17:18.12
-12,-16,17:18.12
-11,-16,17:18.12
-26,-15,17:17.12
-25,-15,17:18.12
-24,-15,17:18.12
-23,-15,17:18.12
-21,-15,17:18.12
-20,-15,17:18.12
-19,-15,17:18.12
-18,-15,17:18.12
-15,-15,17:18.12
-14,-15,17:18.12
-13,-15,17:18.12
-12,-15,17:18.12
-11,-15,17:18.12
-29,-14,17:18.12
-28,-14,17:18.12
-26,-14,17:17.12
-25,-14,17:18.12
-24,-14,17:18.12
-19,-14,17:18.12
-18,-14,17:18.12
-17,-14,17:18.12
-15,-14,17:18.12
-14,-14,17:18.12
-13,-14,17:18.12
-12,-14,17:18.12
-11,-14,17:18.12
-29,-13,17:18.12
-28,-13,17:18.12
-27,-13,17:18.12
-25,-13,17:17.12
-24,-13,17:18.12
-18,-13,17:18.12
-17,-13,17:18.12
-15,-13,17:18.12
-14,-13,17:18.12
-13,-13,17:18.12
-12,-13,17:18.12
-11,-13,17:18.12
-10,-13,17:18.4
-28,-12,17:18.12
-27,-12,17:18.12
-26,-12,17:18.12
-25,-12,17:18.12
-24,-12,17:18.12
-18,-12,17:18.12
-16,-12,17:17.12
-15,-12,17:17.12
-14,-12,17:18.12
-12,-12,17:18.12
-11,-12,17:18.12
-10,-12,17:18.4
-9,-12,17:18.4
-8,-12,17:18.4
-7,-12,17:18.4
-28,-11,17:18.12
-27,-11,17:18.12
-26,-11,17:18.12
-25,-11,17:18.12
-17,-11,17:18.12
-16,-11,17:18.12
-15,-11,17:18.12
-14,-11,17:18.12
-13,-11,17:18.12
-12,-11,17:18.12
-11,-11,17:18.12
-10,-11,17:18.4
-9,-11,17:18.12
-8,-11,17:18.12
-7,-11,17:18.12
-6,-11,17:18.12
-5,-11,17:18.12
-4,-11,17:18.12
-30,-10,17:18.12
-29,-10,17:18.12
-28,-10,17:18.12
-23,-10,17:17.12
-17,-10,17:18.12
-16,-10,17:18.12
-15,-10,17:18.12
-14,-10,17:18.12
-13,-10,17:18.12
-12,-10,17:18.12
-11,-10,17:18.12
-10,-10,17:18.12
-9,-10,17:18.12
-8,-10,17:18.12
-7,-10,17:18.12
-6,-10,17:18.12
-3,-10,17:18.12
-31,-9,17:18.4
-30,-9,17:18.4
-29,-9,17:18.12
-16,-9,17:18.12
-15,-9,17:18.12
-13,-9,17:18.12
-12,-9,17:18.12
-8,-9,17:18.12
-7,-9,17:18.12
-3,-9,17:18.12
-2,-9,17:18.12
-17,-8,17:18.12
-4,-8,17:18.12
-3,-8,17:18.12
-30,-7,17:18.12
-29,-7,17:18.12
-24,-7,17:18.12
-17,-7,17:18.12
-13,-7,17:18.12
-12,-7,17:18.12
-6,-7,17:18.12
-5,-7,17:18.12
-4,-7,17:18.12
-29,-6,17:18.12
-24,-6,17:18.12
-17,-6,17:18.12
-11,-6,17:18.12
-10,-6,17:18.12
-7,-6,17:18.12
-6,-6,17:18.12
-5,-6,17:18.12
-4,-6,17:18.12
-29,-5,17:18.12
-28,-5,17:18.12
-24,-5,17:18.12
-23,-5,17:18.12
-17,-5,17:18.12
-10,-5,17:18.12
-9,-5,17:18.12
-8,-5,17:18.12
-7,-5,17:18.12
-4,-5,17:18.12
-3,-5,17:18.12
-31,-4,17:18.12
-30,-4,17:18.12
-29,-4,17:18.12
-28,-4,17:18.12
-24,-4,17:18.12
-23,-4,17:18.12
-22,-4,17:18.12
-21,-4,17:18.12
-20,-4,17:18.12
-19,-4,17:18.12
-18,-4,17:18.12
-17,-4,17:18.12
-9,-4,17:18.12
-3,-4,17:18.12
-2,-4,17:18.12
-33,-3,17:18.12
-32,-3,17:18.12
-31,-3,17:18.12
-30,-3,17:18.12
-27,-3,17:17.12
-26,-3,17:17.12
-25,-3,17:17.12
-24,-3,17:18.12
-20,-3,17:18.12
-19,-3,17:18.12
-18,-3,17:18.12
-17,-3,17:18.12
-10,-3,17:18.12
-9,-3,17:18.12
-33,-2,17:18.12
-32,-2,17:18.12
-31,-2,17:18.12
-30,-2,17:18.12
-29,-2,17:18.12
-28,-2,17:18.12
-27,-2,17:18.12
-26,-2,17:17.12
-25,-2,17:18.12
-24,-2,17:18.12
-17,-2,17:18.12
-16,-2,17:18.12
-10,-2,17:18.12
-9,-2,17:18.12
-8,-2,17:18.12
-33,-1,17:18.12
-32,-1,17:18.12
-30,-1,17:18.12
-29,-1,17:18.12
-28,-1,17:18.12
-27,-1,17:18.12
-25,-1,17:18.12
-19,-1,17:17.12
-18,-1,17:17.12
-9,-1,17:18.12
-8,-1,17:18.12
-7,-1,17:18.12
-6,-1,17:18.12
5,-1,17:18.7
10,-1,17:18.7
-34,0,17:18.12
-33,0,17:18.12
-32,0,17:18.12
-31,0,17:18.12
-30,0,17:18.12
-29,0,17:18.12
-28,0,17:18.12
-19,0,17:17.12
-18,0,17:17.12
-17,0,17:18.12
-12,0,17:18.12
-10,0,17:18.12
-8,0,17:18.12
-7,0,17:18.12
-6,0,17:18.12
-5,0,17:18.12
-4,0,17:18.12
-3,0,17:18.12
8,0,17:18.15
9,0,17:18.7
-34,1,17:18.12
-32,1,17:18.12
-31,1,17:18.12
-30,1,17:18.12
-29,1,17:18.12
-28,1,17:18.12
-19,1,17:17.12
-13,1,17:17.12
-12,1,17:17.12
-11,1,17:17.12
-10,1,17:17.12
-9,1,17:17.12
-8,1,17:18.12
-7,1,17:18.12
-6,1,17:18.12
-5,1,17:18.12
8,1,17:18.15
-34,2,17:18.12
-33,2,17:18.12
-32,2,17:18.12
-31,2,17:18.12
-26,2,17:18.12
-24,2,17:18.12
-11,2,17:18.12
-10,2,17:18.12
-9,2,17:18.12
-8,2,17:18.12
-7,2,17:18.12
-6,2,17:18.12
7,2,17:18.15
-32,3,17:18.12
-31,3,17:18.12
-30,3,17:18.12
-26,3,17:18.12
-25,3,17:18.12
-20,3,17:18.12
-19,3,17:18.12
-18,3,17:18.12
-17,3,17:18.12
-16,3,17:18.12
-15,3,17:18.12
-13,3,17:18.12
-12,3,17:18.12
-11,3,17:18.12
-10,3,17:18.12
-9,3,17:18.12
-8,3,17:18.12
-7,3,17:18.12
-32,4,17:18.12
-31,4,17:18.12
-28,4,17:18.12
-27,4,17:18.12
-26,4,17:18.12
-25,4,17:18.12
-21,4,17:17.12
-20,4,17:17.12
-19,4,17:18.12
-18,4,17:18.12
-17,4,17:18.12
-15,4,17:18.12
-14,4,17:18.12
-13,4,17:18.12
-12,4,17:18.12
-11,4,17:18.12
-10,4,17:18.12
-9,4,17:18.12
-8,4,17:18.12
-32,5,17:18.12
-31,5,17:18.12
-29,5,17:17.12
-28,5,17:17.12
-21,5,17:17.12
-20,5,17:18.12
-19,5,17:18.12
-18,5,17:18.12
-16,5,17:18.12
-15,5,17:18.12
-13,5,17:18.12
-12,5,17:18.12
-11,5,17:18.12
-10,5,17:18.12
-9,5,17:18.12
-1,5,17:17.12
0,5,17:17.12
1,5,17:17.12
2,5,17:17.12
3,5,17:17.12
-32,6,17:18.12
-28,6,17:18.12
-22,6,17:18.12
-21,6,17:17.12
-20,6,17:18.12
-19,6,17:18.12
-15,6,17:17.12
-10,6,17:18.12
-9,6,17:18.12
-8,6,17:18.12
-1,6,17:17.12
3,6,17:17.12
4,6,17:17.12
-35,7,17:18.12
-34,7,17:18.12
-33,7,17:18.12
-32,7,17:18.12
-31,7,17:18.12
-29,7,17:18.12
-26,7,17:18.12
-23,7,17:18.12
-22,7,17:18.12
-21,7,17:17.12
-19,7,17:18.12
-14,7,17:18.12
-13,7,17:18.12
-12,7,17:18.12
-10,7,17:18.12
-9,7,17:18.12
-8,7,17:18.12
-7,7,17:18.12
-5,7,17:18.15
-4,7,17:18.15
-2,7,17:17.12
5,7,17:17.12
-36,8,17:18.12
-35,8,17:18.12
-31,8,17:18.12
-30,8,17:18.12
-29,8,17:18.12
-27,8,17:18.12
-26,8,17:18.12
-24,8,17:18.12
-23,8,17:18.12
-22,8,17:18.12
-21,8,17:18.12
-15,8,17:18.12
-12,8,17:18.12
-11,8,17:18.12
-10,8,17:18.12
-9,8,17:18.12
-8,8,17:18.12
-7,8,17:18.12
-3,8,17:17.12
-2,8,17:17.12
5,8,17:17.12
6,8,17:17.12
-30,9,17:18.12
-29,9,17:18.12
-28,9,17:18.12
-27,9,17:18.12
-26,9,17:18.12
-25,9,17:18.12
-24,9,17:18.12
-23,9,17:18.12
-22,9,17:18.12
-21,9,17:18.12
-15,9,17:18.12
-12,9,17:18.12
-10,9,17:18.12
-9,9,17:18.12
-8,9,17:18.12
-2,9,17:17.12
5,9,17:17.12
6,9,17:17.12
-30,10,17:18.12
-27,10,17:18.12
-26,10,17:18.12
-25,10,17:18.12
-22,10,17:18.12
-21,10,17:18.12
-20,10,17:18.12
-16,10,17:18.12
-15,10,17:18.12
-14,10,17:18.12
-13,10,17:18.12
-12,10,17:18.12
-11,10,17:18.12
-10,10,17:18.12
-9,10,17:18.12
-8,10,17:18.12
-1,10,17:17.12
4,10,17:17.12
5,10,17:17.12
-27,11,17:18.4
-26,11,17:18.12
-22,11,17:18.12
-21,11,17:18.12
-20,11,17:18.12
-16,11,17:18.12
-14,11,17:18.12
-13,11,17:18.12
-12,11,17:18.12
-11,11,17:18.12
-9,11,17:18.12
-1,11,17:17.12
0,11,17:17.12
2,11,17:17.12
3,11,17:17.12
4,11,17:17.12
-21,12,17:18.12
-16,12,17:18.12
-13,12,17:18.12
-12,12,17:18.12
-11,12,17:17.12
1,12,17:17.12
2,12,17:17.12
-16,13,17:18.12
-14,13,17:18.12
-13,13,17:18.12
-12,13,17:18.12
-18,14,17:18.12
-17,14,17:18.12
-16,14,17:18.12
-15,14,17:18.12
-14,14,17:18.12
-12,14,17:18.12
5,14,17:18.15
-19,15,17:18.4
-18,15,17:18.4
-17,15,17:18.12
-15,15,17:18.12
-14,15,17:18.12
-19,16,17:18.4
-14,16,17:18.12
6,16,17:18.15
6,17,17:18.15
6,18,17:18.7
-16,-21,18:18.4
-15,-21,18:18.4
-15,-20,18:18.4
-14,-20,18:18.4
-11,-20,18:18.4
-20,-19,18:18.4
-19,-19,18:18.4
-15,-19,18:18.4
-14,-19,18:18.4
-13,-19,18:18.4
-12,-19,18:18.4
-11,-19,18:18.4
-23,-18,18:18.12
-22,-18,18:18.12
-21,-18,18:18.4
-20,-18,18:18.4
-19,-18,18:18.4
-15,-18,18:18.4
-14,-18,18:18.4
-13,-18,18:18.4
-12,-18,18:18.4
-11,-18,18:18.4
-27,-17,18:17.12
-25,-17,18:18.12
-24,-17,18:18.12
-23,-17,18:18.12
-21,-17,18:18.12
-20,-17,18:18.4
-14,-17,18:18.12
-13,-17,18:18.12
-25,-16,18:18.12
-24,-16,18:18.12
-23,-16,18:18.12
-19,-16,18:18.12
-14,-16,18:18.12
-10,-16,18:18.4
-9,-16,18:18.4
-24,-15,18:18.12
-19,-15,18:18.12
-15,-15,18:18.12
-12,-15,18:18.12
-10,-15,18:18.4
-9,-15,18:18.4
-31,-14,18:18.12
-30,-14,18:18.12
-24,-14,18:18.12
-19,-14,18:18.12
-18,-14,18:18.12
-17,-14,18:18.12
-15,-14,18:18.12
-13,-14,18:18.12
-10,-14,18:18.4
-9,-14,18:18.4
-8,-14,18:18.4
-7,-14,18:18.4
-6,-14,18:18.4
-31,-13,18:18.12
-30,-13,18:18.12
-29,-13,18:18.12
-25,-13,18:17.12
-24,-13,18:18.12
-18,-13,18:18.12
-17,-13,18:18.12
-15,-13,18:17.12
-14,-13,18:18.12
-13,-13,18:18.12
-11,-13,18:18.12
-10,-13,18:18.4
-9,-13,18:18.4
-8,-13,18:18.4
-7,-13,18:18.4
-6,-13,18:18.4
-30,-12,18:18.12
-29,-12,18:18.12
-28,-12,18:18.12
-14,-12,18:18.12
-13,-12,18:18.12
-12,-12,18:18.12
-11,-12,18:18.12
-10,-12,18:18.4
-9,-12,18:18.4
-8,-12,18:18.4
-30,-11,18:18.12
-29,-11,18:18.12
-28,-11,18:18.12
-27,-11,18:18.12
-26,-11,18:18.12
-25,-11,18:18.12
-17,-11,18:18.12
-16,-11,18:18.12
-15,-11,18:18.12
-14,-11,18:18.12
-13,-11,18:18.12
-11,-11,18:18.12
-6,-11,18:18.12
-32,-10,18:18.4
-31,-10,18:18.4
-30,-10,18:18.12
-16,-10,18:18.12
-15,-10,18:18.12
-14,-10,18:18.12
-13,-10,18:18.12
-12,-10,18:18.12
-31,-9,18:18.4
-16,-9,18:18.12
-13,-9,18:18.12
-12,-9,18:18.12
-2,-9,18:18.12
-32,-8,18:18.12
-31,-8,18:18.12
-17,-8,18:18.12
-16,-8,18:18.12
-3,-8,18:18.12
-2,-8,18:18.12
-32,-7,18:18.12
-31,-7,18:18.12
-30,-7,18:18.12
-24,-7,18:18.12
-17,-7,18:18.12
-12,-7,18:18.12
-11,-7,18:18.12
-6,-7,18:18.12
-5,-7,18:18.12
-4,-7,18:18.12
-31,-6,18:18.12
-30,-6,18:18.12
-24,-6,18:18.12
-21,-6,18:18.12
-17,-6,18:18.12
-11,-6,18:18.12
-10,-6,18:18.12
-9,-6,18:18.12
-6,-6,18:18.12
-5,-6,18:18.12
-3,-6,18:18.12
-31,-5,18:18.12
-30,-5,18:18.12
-24,-5,18:18.12
-23,-5,18:18.12
-22,-5,18:18.12
-21,-5,18:18.12
-19,-5,18:18.12
-18,-5,18:18.12
-17,-5,18:18.12
-9,-5,18:18.12
-8,-5,18:18.12
-7,-5,18:18.12
-3,-5,18:18.12
-2,-5,18:18.12
-30,-4,18:17.12
-29,-4,18:17.12
-28,-4,18:17.12
-24,-4,18:18.12
-22,-4,18:18.12
-21,-4,18:18.12
-20,-4,18:18.12
-19,-4,18:18.12
-18,-4,18:18.12
-17,-4,18:18.12
-16,-4,18:18.12
-9,-4,18:18.12
-8,-4,18:18.12
-2,-4,18:18.12
-32,-3,18:18.12
-31,-3,18:18.12
-30,-3,18:18.12
-29,-3,18:18.12
-28,-3,18:17.12
-27,-3,18:17.12
-26,-3,18:18.12
-25,-3,18:18.12
-24,-3,18:18.12
-21,-3,18:18.12
-20,-3,18:18.12
-16,-3,18:18.12
-15,-3,18:18.12
-9,-3,18:18.12
-8,-3,18:18.12
-7,-3,18:18.12
-6,-3,18:18.12
-34,-2,18:18.12
-33,-2,18:18.12
-32,-2,18:18.12
-31,-2,18:18.12
-30,-2,18:18.12
-29,-2,18:18.12
-28,-2,18:18.12
-27,-2,18:17.12
-26,-2,18:17.12
-25,-2,18:18.12
-19,-2,18:17.12
-9,-2,18:18.12
-8,-2,18:18.12
-7,-2,18:18.12
-6,-2,18:18.12
-5,-2,18:18.12
-33,-1,18:18.12
-32,-1,18:18.12
-30,-1,18:18.12
-29,-1,18:18.12
-26,-1,18:18.12
-19,-1,18:17.12
-18,-1,18:17.12
-14,-1,18:18.12
-13,-1,18:18.12
-12,-1,18:18.12
-9,-1,18:18.12
-6,-1,18:18.12
-5,-1,18:18.12
-4,-1,18:18.12
-3,-1,18:18.12
5,-1,18:18.15
9,-1,18:18.7
10,-1,18:18.7
-32,0,18:18.12
-31,0,18:18.12
-30,0,18:18.12
-26,0,18:18.12
-19,0,18:17.12
-18,0,18:17.12
-17,0,18:18.12
-16,0,18:18.12
-15,0,18:18.12
-12,0,18:18.12
-11,0,18:18.12
-9,0,18:18.12
-8,0,18:18.12
-5,0,18:18.12
-4,0,18:18.12
-3,0,18:18.12
-2,0,18:18.12
-33,1,18:18.12
-32,1,18:18.12
-31,1,18:18.12
-30,1,18:18.12
-26,1,18:18.12
-17,1,18:18.12
-16,1,18:18.12
-12,1,18:18.12
-11,1,18:18.12
-10,1,18:18.12
-9,1,18:18.12
-8,1,18:18.12
-7,1,18:18.12
-6,1,18:18.12
-4,1,18:18.12
-3,1,18:18.12
-2,1,18:18.12
8,1,18:18.15
-34,2,18:18.12
-33,2,18:18.12
-32,2,18:18.12
-31,2,18:18.12
-26,2,18:18.12
-16,2,18:18.12
-12,2,18:18.12
-10,2,18:18.12
-9,2,18:18.12
-8,2,18:18.12
-6,2,18:18.12
-5,2,18:18.12
-4,2,18:18.12
-3,2,18:18.12
-2,2,18:18.12
7,2,18:18.15
-32,3,18:18.12
-31,3,18:18.12
-30,3,18:18.12
-27,3,18:18.12
-26,3,18:18.12
-20,3,18:18.12
-19,3,18:18.12
-15,3,18:18.12
-10,3,18:18.12
-9,3,18:18.12
-7,3,18:18.12
-6,3,18:18.12
-5,3,18:18.12
-4,3,18:18.12
6,3,18:18.15
-32,4,18:18.12
-28,4,18:18.12
-27,4,18:18.12
-26,4,18:18.12
-25,4,18:18.12
-19,4,18:18.12
-18,4,18:18.12
-17,4,18:18.12
-16,4,18:18.12
-15,4,18:18.12
-14,4,18:18.12
-13,4,18:18.12
-12,4,18:18.12
-11,4,18:18.12
-10,4,18:18.12
-9,4,18:18.12
-8,4,18:18.12
-7,4,18:18.12
-6,4,18:18.12
-5,4,18:18.12
-32,5,18:18.12
-30,5,18:17.12
-29,5,18:17.12
-24,5,18:18.12
-21,5,18:17.12
-20,5,18:17.12
-18,5,18:18.12
-17,5,18:18.12
-16,5,18:18.12
-15,5,18:18.12
-14,5,18:18.12
-13,5,18:18.12
-12,5,18:18.12
-11,5,18:18.12
-10,5,18:18.12
-9,5,18:18.12
0,5,18:17.12
1,5,18:17.12
2,5,18:17.12
3,5,18:17.12
4,5,18:17.12
-33,6,18:18.12
-32,6,18:18.12
-31,6,18:17.12
-30,6,18:17.12
-23,6,18:18.12
-22,6,18:18.12
-21,6,18:18.12
-20,6,18:18.12
-18,6,18:18.12
-15,6,18:18.12
-10,6,18:18.12
-9,6,18:18.12
-8,6,18:18.12
-1,6,18:17.12
0,6,18:17.12
4,6,18:17.12
5,6,18:17.12
-34,7,18:18.12
-33,7,18:18.12
-32,7,18:18.12
-23,7,18:18.12
-22,7,18:18.12
-21,7,18:17.12
-20,7,18:18.12
-19,7,18:18.12
-18,7,18:18.12
-15,7,18:17.12
-13,7,18:18.12
-12,7,18:18.12
-10,7,18:18.12
-9,7,18:18.12
-8,7,18:18.15
-7,7,18:18.12
-5,7,18:18.15
-4,7,18:18.15
-2,7,18:17.12
-1,7,18:17.12
5,7,18:17.12
6,7,18:17.12
-36,8,18:18.12
-35,8,18:18.12
-32,8,18:18.12
-31,8,18:18.12
-30,8,18:18.12
-29,8,18:18.12
-23,8,18:18.12
-22,8,18:18.12
-21,8,18:18.12
-20,8,18:18.12
-19,8,18:18.12
-12,8,18:18.12
-11,8,18:18.12
-10,8,18:18.12
-2,8,18:17.12
6,8,18:17.12
-30,9,18:18.12
-29,9,18:18.12
-25,9,18:18.12
-24,9,18:18.12
-23,9,18:18.12
-22,9,18:18.12
-19,9,18:18.12
-18,9,18:18.12
-15,9,18:18.12
-12,9,18:18.12
-11,9,18:18.12
-10,9,18:18.12
-8,9,18:18.12
-7,9,18:18.12
-2,9,18:17.12
-1,9,18:17.12
6,9,18:17.12
7,9,18:17.12
-29,10,18:18.12
-25,10,18:18.12
-24,10,18:18.12
-23,10,18:18.12
-18,10,18:18.12
-17,10,18:18.12
-16,10,18:18.12
-15,10,18:18.12
-14,10,18:18.12
-12,10,18:18.12
-10,10,18:18.12
-8,10,18:18.12
-1,10,18:17.12
5,10,18:17.12
6,10,18:17.12
-26,11,18:18.12
-25,11,18:18.12
-24,11,18:18.12
-23,11,18:18.12
-22,11,18:18.12
-17,11,18:18.12
-16,11,18:18.12
-15,11,18:18.12
-14,11,18:18.12
-13,11,18:18.12
-12,11,18:18.12
-11,11,18:18.12
-10,11,18:18.12
0,11,18:17.12
1,11,18:17.12
3,11,18:17.12
4,11,18:17.12
5,11,18:17.12
-26,12,18:18.12
-23,12,18:18.12
-22,12,18:18.12
-16,12,18:18.12
-13,12,18:18.12
-12,12,18:18.12
-11,12,18:18.12
1,12,18:17.12
2,12,18:17.12
3,12,18:17.12
-22,13,18:18.12
-16,13,18:18.12
-13,13,18:18.12
-12,13,18:18.12
-10,13,18:17.12
-16,14,18:18.12
-13,14,18:18.12
-12,14,18:18.12
-10,14,18:17.12
5,14,18:18.15
-17,15,18:18.12
-16,15,18:18.12
-14,15,18:18.12
-13,15,18:18.12
-11,15,18:18.12
5,15,18:18.15
-18,16,18:18.4
-17,16,18:18.4
-16,16,18:18.12
5,16,18:18.15
6,16,18:18.15
6,17,18:18.15
-14,-21,19:18.4
-14,-20,19:18.4
-13,-20,19:18.4
-12,-20,19:18.4
-28,-19,19:17.12
-14,-19,19:18.4
-13,-19,19:18.4
-27,-18,19:17.12
-14,-18,19:18.4
-27,-17,19:17.12
-23,-17,19:18.12
-20,-17,19:18.4
-14,-17,19:18.12
-23,-16,19:18.12
-20,-16,19:18.12
-19,-16,19:18.12
-14,-16,19:18.12
-9,-16,19:18.4
-23,-15,19:18.12
-19,-15,19:18.12
-15,-15,19:18.12
-9,-15,19:18.4
-8,-15,19:18.4
-7,-15,19:18.4
-26,-14,19:18.12
-25,-14,19:18.12
-24,-14,19:18.12
-23,-14,19:18.12
-19,-14,19:18.12
-18,-14,19:18.12
-15,-14,19:18.12
-13,-14,19:18.12
-12,-14,19:18.12
-9,-14,19:18.4
-8,-14,19:18.4
-31,-13,19:18.12
-26,-13,19:18.12
-25,-13,19:18.12
-18,-13,19:18.12
-13,-13,19:18.12
-10,-13,19:18.4
-31,-12,19:18.12
-14,-12,19:18.12
-13,-12,19:18.12
-11,-12,19:18.12
-10,-12,19:18.4
-32,-11,19:18.4
-31,-11,19:18.4
-30,-11,19:18.12
-29,-11,19:18.12
-28,-11,19:18.12
-27,-11,19:18.12
-26,-11,19:18.12
-25,-11,19:18.12
-17,-11,19:18.12
-16,-11,19:18.12
-15,-11,19:18.12
-14,-11,19:18.12
-13,-11,19:18.12
-12,-11,19:18.12
-11,-11,19:18.12
-16,-10,19:18.12
-13,-10,19:18.12
-12,-10,19:18.12
-16,-9,19:18.12
-12,-9,19:18.12
-34,-8,19:18.12
-33,-8,19:18.12
-16,-8,19:18.12
-2,-8,19:18.12
-34,-7,19:18.12
-33,-7,19:18.12
-32,-7,19:18.12
-17,-7,19:18.12
-14,-7,19:18.12
-11,-7,19:18.4
-10,-7,19:18.4
-6,-7,19:18.12
-5,-7,19:18.12
-4,-7,19:18.12
-2,-7,19:18.12
-33,-6,19:18.12
-32,-6,19:18.12
-31,-6,19:18.12
-23,-6,19:18.12
-21,-6,19:18.12
-19,-6,19:18.12
-18,-6,19:18.12
-17,-6,19:18.12
-16,-6,19:18.12
-15,-6,19:18.12
-10,-6,19:18.4
-9,-6,19:18.12
-6,-6,19:18.12
-2,-6,19:18.12
-32,-5,19:18.12
-31,-5,19:18.12
-30,-5,19:18.12
-29,-5,19:18.12
-25,-5,19:18.12
-24,-5,19:18.12
-23,-5,19:18.12
-22,-5,19:18.12
-21,-5,19:18.12
-20,-5,19:18.12
-19,-5,19:18.12
-18,-5,19:18.12
-16,-5,19:18.12
-15,-5,19:18.12
-8,-5,19:18.12
-7,-5,19:18.12
-2,-5,19:18.12
-1,-5,19:18.12
-34,-4,19:18.12
-33,-4,19:18.12
-32,-4,19:18.12
-31,-4,19:18.12
-30,-4,19:17.12
-29,-4,19:18.12
-28,-4,19:18.12
-27,-4,19:18.12
-26,-4,19:18.12
-25,-4,19:18.12
-24,-4,19:18.12
-22,-4,19:18.12
-21,-4,19:18.12
-20,-4,19:18.12
-16,-4,19:18.12
-15,-4,19:18.12
-14,-4,19:18.12
-8,-4,19:18.12
-7,-4,19:18.12
-6,-4,19:18.12
-35,-3,19:18.12
-34,-3,19:18.12
-33,-3,19:18.12
-32,-3,19:18.12
-31,-3,19:18.12
-29,-3,19:18.12
-28,-3,19:18.12
-27,-3,19:18.12
-26,-3,19:18.12
-25,-3,19:18.12
-20,-3,19:17.12
-15,-3,19:18.12
-14,-3,19:18.12
-8,-3,19:18.12
-6,-3,19:18.12
-5,-3,19:18.12
-4,-3,19:18.12
-35,-2,19:18.12
-34,-2,19:18.12
-33,-2,19:18.12
-32,-2,19:18.12
-31,-2,19:18.12
-30,-2,19:18.12
-29,-2,19:18.12
-27,-2,19:18.12
-26,-2,19:18.12
-20,-2,19:17.12
-19,-2,19:17.12
-14,-2,19:18.12
-12,-2,19:18.12
-11,-2,19:18.12
-10,-2,19:18.12
-8,-2,19:18.12
-5,-2,19:18.12
-4,-2,19:18.12
-3,-2,19:18.12
10,-2,19:18.15
-33,-1,19:18.12
-32,-1,19:18.12
-30,-1,19:18.12
-26,-1,19:18.12
-20,-1,19:17.12
-19,-1,19:17.12
-18,-1,19:17.12
-13,-1,19:18.12
-12,-1,19:18.12
-11,-1,19:18.12
-3,-1,19:18.12
-2,-1,19:18.12
5,-1,19:18.15
9,-1,19:18.15
-32,0,19:18.12
-26,0,19:18.12
-17,0,19:18.12
-16,0,19:18.12
-14,0,19:18.12
-13,0,19:18.12
-12,0,19:18.12
-11,0,19:18.12
-10,0,19:18.12
-9,0,19:18.12
-26,1,19:18.12
-16,1,19:18.12
-15,1,19:18.12
-14,1,19:18.12
-11,1,19:18.12
-10,1,19:18.12
-9,1,19:18.12
-8,1,19:18.12
-7,1,19:18.12
-6,1,19:18.12
-5,1,19:18.12
8,1,19:18.15
-26,2,19:18.12
-15,2,19:18.12
-14,2,19:18.12
-12,2,19:18.12
-11,2,19:18.12
-8,2,19:17.12
-7,2,19:18.12
7,2,19:18.15
-32,3,19:18.12
-27,3,19:18.12
-26,3,19:18.12
-20,3,19:18.12
-19,3,19:18.12
-16,3,19:18.12
-15,3,19:18.12
-14,3,19:18.12
-13,3,19:18.12
-12,3,19:18.12
-9,3,19:18.12
-8,3,19:18.12
-7,3,19:18.12
-3,3,19:18.12
6,3,19:18.15
-33,4,19:18.12
-32,4,19:18.12
-29,4,19:18.12
-28,4,19:18.12
-26,4,19:18.12
-25,4,19:18.12
-19,4,19:18.12
-18,4,19:18.12
-16,4,19:18.12
-15,4,19:18.12
-14,4,19:18.12
-8,4,19:18.12
-7,4,19:18.12
-4,4,19:18.12
3,4,19:17.12
-33,5,19:18.12
-30,5,19:18.12
-24,5,19:18.12
-23,5,19:18.12
-20,5,19:18.12
-19,5,19:18.12
-18,5,19:18.12
-17,5,19:18.12
-16,5,19:18.12
-15,5,19:18.12
-14,5,19:18.12
-13,5,19:18.12
-12,5,19:18.12
-11,5,19:18.12
-8,5,19:18.12
-7,5,19:18.12
0,5,19:17.12
1,5,19:17.12
2,5,19:17.12
3,5,19:17.12
4,5,19:17.12
-33,6,19:18.12
-27,6,19:18.12
-24,6,19:18.12
-23,6,19:18.12
-22,6,19:18.12
-21,6,19:18.12
-20,6,19:18.12
-17,6,19:18.12
-16,6,19:18.12
-15,6,19:18.12
-14,6,19:18.12
-13,6,19:18.12
-12,6,19:18.12
-11,6,19:18.12
-10,6,19:18.12
-9,6,19:18.12
-8,6,19:18.12
-7,6,19:18.12
-1,6,19:17.12
0,6,19:17.12
5,6,19:17.12
-34,7,19:18.12
-33,7,19:18.12
-28,7,19:18.12
-27,7,19:18.12
-26,7,19:18.12
-25,7,19:18.12
-23,7,19:18.12
-22,7,19:18.12
-21,7,19:18.12
-20,7,19:18.12
-18,7,19:18.12
-17,7,19:18.12
-15,7,19:18.12
-14,7,19:17.12
-13,7,19:18.12
-10,7,19:18.12
-9,7,19:18.12
-8,7,19:18.12
-7,7,19:18.15
-5,7,19:18.15
-4,7,19:18.15
-1,7,19:17.12
4,7,19:18.12
5,7,19:18.12
6,7,19:17.12
-36,8,19:18.12
-35,8,19:18.12
-33,8,19:18.12
-32,8,19:18.12
-23,8,19:18.12
-22,8,19:17.12
-21,8,19:18.12
-20,8,19:18.12
-19,8,19:18.12
-18,8,19:18.12
-15,8,19:18.12
-14,8,19:17.12
-11,8,19:18.12
-10,8,19:18.12
-9,8,19:18.12
-2,8,19:17.12
6,8,19:17.12
7,8,19:17.12
13,8,19:18.12
-32,9,19:18.12
-31,9,19:18.12
-30,9,19:18.12
-24,9,19:18.12
-23,9,19:18.12
-22,9,19:18.12
-21,9,19:18.12
-20,9,19:18.12
-19,9,19:18.12
-15,9,19:18.12
-14,9,19:18.12
-11,9,19:18.12
-10,9,19:18.12
-1,9,19:17.12
7,9,19:17.12
14,9,19:18.12
15,9,19:18.12
16,9,19:18.12
17,9,19:18.12
-30,10,19:18.12
-29,10,19:18.12
-24,10,19:18.12
-23,10,19:18.12
-22,10,19:18.12
-21,10,19:18.12
-20,10,19:18.12
-19,10,19:18.12
-18,10,19:18.12
-17,10,19:18.12
-16,10,19:18.12
-12,10,19:18.12
-11,10,19:18.12
-1,10,19:17.12
0,10,19:17.12
6,10,19:17.12
-25,11,19:18.12
-24,11,19:18.12
-23,11,19:18.12
-18,11,19:18.12
-17,11,19:18.12
-16,11,19:18.12
-15,11,19:18.12
-14,11,19:18.12
-13,11,19:18.12
-12,11,19:18.12
0,11,19:17.12
1,11,19:17.12
4,11,19:17.12
5,11,19:17.12
-25,12,19:18.12
-24,12,19:18.12
-18,12,19:18.12
-17,12,19:18.12
-16,12,19:18.12
-14,12,19:18.12
-13,12,19:18.12
-12,12,19:18.12
-11,12,19:18.12
-10,12,19:18.12
1,12,19:17.12
2,12,19:17.12
3,12,19:17.12
4,12,19:17.12
-24,13,19:18.12
-17,13,19:18.12
-16,13,19:18.12
-13,13,19:18.12
-12,13,19:18.12
-11,13,19:18.12
-16,14,19:18.12
-13,14,19:18.12
-12,14,19:18.12
-11,14,19:18.12
5,14,19:18.15
-16,15,19:18.12
-13,15,19:18.12
-11,15,19:18.12
5,15,19:18.15
-16,16,19:18.12
5,16,19:18.15
6,17,19:18.15
6,18,19:18.15
3,22,19:18.4
3,23,19:18.4
3,24,19:18.4
3,25,19:18.4
-28,-19,20:17.12
-14,-19,20:18.4
-14,-18,20:18.4
-27,-17,20:18.12
-14,-17,20:18.12
-27,-16,20:18.12
-26,-15,20:18.12
-19,-15,20:18.12
-15,-15,20:18.12
-26,-14,20:18.12
-25,-14,20:18.12
-24,-14,20:18.12
-23,-14,20:18.12
-19,-14,20:18.12
-15,-14,20:18.12
-10,-14,20:18.4
-9,-14,20:18.4
-27,-13,20:18.12
-26,-13,20:18.12
-13,-13,20:18.12
-10,-13,20:18.4
-27,-12,20:18.12
-15,-12,20:18.12
-14,-12,20:18.12
-13,-12,20:18.12
-11,-12,20:18.12
-31,-11,20:18.4
-30,-11,20:18.12
-29,-11,20:18.12
-28,-11,20:18.12
-27,-11,20:18.12
-26,-11,20:18.12
-16,-11,20:18.12
-13,-11,20:18.12
-12,-11,20:18.12
-11,-11,20:18.12
-16,-10,20:18.12
-12,-10,20:18.12
-16,-9,20:18.12
-35,-8,20:18.12
-20,-8,20:18.12
-17,-8,20:18.12
-16,-8,20:18.12
-13,-8,20:18.12
-12,-8,20:18.12
-35,-7,20:18.12
-34,-7,20:18.12
-22,-7,20:18.12
-20,-7,20:18.12
-19,-7,20:18.12
-18,-7,20:18.12
-17,-7,20:18.12
-16,-7,20:18.12
-15,-7,20:18.12
-14,-7,20:18.12
-13,-7,20:18.12
-5,-7,20:18.12
-4,-7,20:18.12
-2,-7,20:18.12
-1,-7,20:18.12
0,-7,20:18.12
-35,-6,20:18.12
-34,-6,20:18.12
-33,-6,20:18.12
-31,-6,20:18.12
-25,-6,20:18.12
-24,-6,20:18.12
-21,-6,20:18.12
-20,-6,20:18.12
-19,-6,20:18.12
-16,-6,20:18.12
-15,-6,20:18.12
-14,-6,20:18.4
-9,-6,20:18.12
-8,-6,20:18.12
-1,-6,20:18.12
0,-6,20:18.12
-36,-5,20:18.12
-35,-5,20:18.12
-34,-5,20:18.12
-33,-5,20:18.12
-32,-5,20:18.12
-30,-5,20:18.12
-29,-5,20:18.12
-26,-5,20:18.12
-25,-5,20:18.12
-22,-5,20:18.12
-21,-5,20:18.12
-20,-5,20:18.12
-19,-5,20:18.12
-18,-5,20:18.12
-16,-5,20:18.12
-15,-5,20:18.12
-14,-5,20:18.12
-8,-5,20:18.12
0,-5,20:18.12
-36,-4,20:18.12
-35,-4,20:18.12
-34,-4,20:18.12
-32,-4,20:18.12
-31,-4,20:17.12
-30,-4,20:18.12
-28,-4,20:18.12
-27,-4,20:18.12
-26,-4,20:18.12
-21,-4,20:17.12
-20,-4,20:17.12
-16,-4,20:18.12
-14,-4,20:18.12
-13,-4,20:18.12
-8,-4,20:18.12
-7,-4,20:18.12
0,-4,20:18.12
-36,-3,20:18.12
-27,-3,20:18.12
-20,-3,20:18.12
-19,-3,20:17.12
-17,-3,20:18.12
-13,-3,20:18.12
-11,-3,20:18.12
-27,-2,20:18.12
-20,-2,20:17.12
-19,-2,20:18.12
-18,-2,20:18.12
-17,-2,20:18.12
-11,-2,20:18.12
-10,-2,20:18.12
10,-2,20:18.15
-27,-1,20:18.12
-19,-1,20:17.12
-18,-1,20:17.12
-17,-1,20:18.12
-16,-1,20:18.12
-11,-1,20:18.12
-10,-1,20:18.12
-9,-1,20:18.12
5,-1,20:18.15
9,-1,20:18.15
13,-1,20:18.12
14,-1,20:18.12
-26,0,20:18.12
-19,0,20:17.12
-18,0,20:17.12
-17,0,20:18.12
-12,0,20:18.12
-11,0,20:18.12
-10,0,20:18.12
-9,0,20:18.12
-8,0,20:18.12
-7,0,20:18.12
12,0,20:18.12
13,0,20:18.12
-26,1,20:18.12
-19,1,20:18.12
-16,1,20:18.12
-15,1,20:18.12
-14,1,20:18.12
-13,1,20:18.12
-12,1,20:18.12
-10,1,20:18.12
-7,1,20:18.12
-6,1,20:18.12
-5,1,20:18.12
8,1,20:18.15
12,1,20:18.12
-27,2,20:18.12
-26,2,20:18.12
-19,2,20:18.12
-14,2,20:18.12
-13,2,20:18.12
-12,2,20:18.12
-11,2,20:18.12
-10,2,20:18.12
-8,2,20:17.12
-7,2,20:17.12
-6,2,20:17.12
7,2,20:18.15
-27,3,20:18.12
-26,3,20:18.12
-19,3,20:18.12
-17,3,20:18.12
-14,3,20:18.12
-13,3,20:18.12
-12,3,20:18.12
-11,3,20:18.12
-10,3,20:18.12
-9,3,20:18.12
-7,3,20:18.12
6,3,20:18.15
-33,4,20:18.12
-30,4,20:18.12
-29,4,20:18.12
-28,4,20:18.12
-26,4,20:18.12
-25,4,20:18.12
-20,4,20:18.12
-19,4,20:18.12
-18,4,20:18.12
-16,4,20:18.12
-15,4,20:18.12
-14,4,20:18.12
-13,4,20:18.12
-12,4,20:18.12
-8,4,20:18.12
-7,4,20:18.12
-6,4,20:18.12
2,4,20:17.12
3,4,20:17.12
4,4,20:17.12
10,4,20:18.12
-33,5,20:18.12
-30,5,20:18.12
-24,5,20:18.12
-23,5,20:18.12
-22,5,20:18.12
-19,5,20:18.12
-18,5,20:18.12
-17,5,20:18.12
-16,5,20:18.12
-15,5,20:18.12
-13,5,20:18.12
-12,5,20:18.12
-7,5,20:18.12
-6,5,20:18.12
0,5,20:17.12
1,5,20:17.12
4,5,20:17.12
5,5,20:17.12
8,5,20:18.12
-34,6,20:18.12
-33,6,20:18.12
-23,6,20:18.12
-22,6,20:18.12
-19,6,20:18.12
-18,6,20:18.12
-17,6,20:18.12
-16,6,20:18.12
-15,6,20:18.12
-13,6,20:18.12
-12,6,20:18.12
-10,6,20:18.15
-9,6,20:18.15
-7,6,20:18.12
-6,6,20:18.12
-4,6,20:18.12
-1,6,20:17.12
0,6,20:17.12
5,6,20:17.12
6,6,20:17.12
-34,7,20:18.12
-29,7,20:18.12
-28,7,20:18.12
-27,7,20:18.12
-26,7,20:18.12
-25,7,20:18.12
-24,7,20:18.12
-23,7,20:18.12
-15,7,20:18.12
-13,7,20:18.12
-12,7,20:18.12
-11,7,20:18.12
-10,7,20:18.12
-9,7,20:18.12
-8,7,20:18.12
-7,7,20:18.15
-5,7,20:18.15
-1,7,20:17.12
4,7,20:18.12
6,7,20:17.12
7,7,20:18.12
-34,8,20:18.12
-33,8,20:18.12
-23,8,20:18.12
-22,8,20:18.12
-21,8,20:18.12
-20,8,20:18.12
-19,8,20:18.12
-18,8,20:18.12
-17,8,20:18.12
-15,8,20:18.12
-11,8,20:18.12
-10,8,20:18.12
-9,8,20:18.12
-8,8,20:18.12
-2,8,20:17.12
0,8,20:18.12
5,8,20:18.12
6,8,20:18.12
7,8,20:17.12
8,8,20:18.12
9,8,20:18.12
12,8,20:18.12
-33,9,20:18.12
-32,9,20:18.12
-31,9,20:18.12
-24,9,20:18.12
-23,9,20:18.12
-22,9,20:18.12
-21,9,20:18.12
-20,9,20:18.12
-19,9,20:18.12
-18,9,20:18.12
-17,9,20:18.12
-14,9,20:18.12
-10,9,20:18.12
-9,9,20:18.12
-1,9,20:17.12
4,9,20:18.12
5,9,20:18.12
7,9,20:17.12
8,9,20:17.12
12,9,20:18.12
13,9,20:18.12
14,9,20:18.12
15,9,20:18.12
16,9,20:18.12
17,9,20:18.12
-31,10,20:18.12
-24,10,20:18.12
-22,10,20:18.12
-21,10,20:18.12
-20,10,20:18.12
-11,10,20:18.12
-10,10,20:18.12
-1,10,20:17.12
3,10,20:18.12
4,10,20:18.12
5,10,20:18.12
6,10,20:17.12
7,10,20:17.12
16,10,20:18.12
17,10,20:18.12
18,10,20:18.12
19,10,20:18.12
-24,11,20:18.12
-23,11,20:18.12
-22,11,20:18.12
-21,11,20:18.12
-20,11,20:18.12
-16,11,20:18.12
-15,11,20:18.12
-14,11,20:18.12
-12,11,20:18.12
-11,11,20:18.12
0,11,20:17.12
4,11,20:18.12
5,11,20:17.12
6,11,20:17.12
-24,12,20:18.12
-23,12,20:18.12
-22,12,20:18.12
-20,12,20:18.12
-19,12,20:18.12
-18,12,20:18.12
-16,12,20:18.12
-14,12,20:18.12
-13,12,20:18.12
-12,12,20:18.12
1,12,20:17.12
2,12,20:17.12
3,12,20:17.12
4,12,20:17.12
5,12,20:17.12
7,12,20:18.12
-25,13,20:18.12
-24,13,20:18.12
-23,13,20:18.12
-19,13,20:18.12
-18,13,20:18.12
-17,13,20:18.4
-16,13,20:18.12
-13,13,20:18.12
-12,13,20:18.12
2,13,20:17.12
3,13,20:17.12
7,13,20:18.12
8,13,20:18.12
-18,14,20:18.12
-16,14,20:18.12
-12,14,20:18.12
-11,14,20:18.12
5,14,20:18.15
-11,15,20:18.12
5,16,20:18.15
6,17,20:18.15
6,18,20:18.15
3,21,20:18.12
3,22,20:18.4
3,23,20:18.4
3,24,20:18.4
3,25,20:18.4
3,26,20:18.4
-14,-18,21:18.4
-27,-17,21:18.12
-27,-16,21:18.12
-27,-15,21:18.12
-26,-15,21:18.12
-25,-15,21:18.12
-24,-15,21:18.12
-27,-14,21:18.12
-26,-14,21:18.12
-25,-14,21:18.12
-24,-14,21:18.12
-23,-14,21:18.12
-27,-13,21:18.12
-10,-13,21:18.4
-28,-12,21:18.12
-27,-12,21:18.12
-19,-12,21:18.12
-14,-12,21:18.12
-20,-11,21:18.12
-19,-11,21:18.12
-24,-10,21:18.12
-20,-10,21:18.12
-19,-10,21:18.12
-16,-10,21:18.12
0,-10,21:18.12
-23,-9,21:18.12
-22,-9,21:18.12
-21,-9,21:18.12
-20,-9,21:18.12
-19,-9,21:18.12
-17,-9,21:18.12
-16,-9,21:18.12
0,-9,21:18.12
-23,-8,21:17.12
-22,-8,21:17.12
-21,-8,21:18.12
-20,-8,21:18.12
-19,-8,21:18.12
-18,-8,21:18.12
-17,-8,21:18.12
-16,-8,21:18.12
-12,-8,21:18.12
-11,-8,21:18.12
0,-8,21:18.12
-36,-7,21:18.12
-22,-7,21:17.12
-21,-7,21:18.12
-20,-7,21:18.12
-19,-7,21:18.12
-15,-7,21:18.12
-14,-7,21:18.4
-13,-7,21:18.4
-12,-7,21:18.4
0,-7,21:18.12
1,-7,21:18.12
-36,-6,21:18.12
-35,-6,21:18.12
-31,-6,21:18.12
-30,-6,21:18.12
-26,-6,21:18.12
-25,-6,21:18.12
-22,-6,21:17.12
-21,-6,21:18.12
-20,-6,21:18.12
-19,-6,21:18.12
-18,-6,21:18.12
-17,-6,21:18.12
-16,-6,21:18.12
-15,-6,21:18.12
-14,-6,21:18.4
-13,-6,21:18.4
0,-6,21:18.12
1,-6,21:18.12
-36,-5,21:18.12
-35,-5,21:18.12
-34,-5,21:18.12
-33,-5,21:18.12
-32,-5,21:18.12
-30,-5,21:18.12
-29,-5,21:18.12
-28,-5,21:18.12
-27,-5,21:18.12
-26,-5,21:18.12
-21,-5,21:17.12
-20,-5,21:18.12
-19,-5,21:18.12
-18,-5,21:18.12
-16,-5,21:18.12
-15,-5,21:18.12
-14,-5,21:18.12
-13,-5,21:18.4
0,-5,21:18.12
1,-5,21:18.12
-32,-4,21:17.12
-31,-4,21:18.12
-30,-4,21:18.12
-28,-4,21:18.12
-27,-4,21:18.12
-20,-4,21:18.12
-15,-4,21:18.12
-14,-4,21:18.12
1,-4,21:18.12
-28,-3,21:18.12
-27,-3,21:18.12
-20,-3,21:18.12
-17,-3,21:18.12
-16,-3,21:18.12
-15,-3,21:18.12
-11,-3,21:18.12
-10,-3,21:18.12
1,-3,21:18.12
-28,-2,21:18.12
-27,-2,21:18.12
-19,-2,21:18.12
-18,-2,21:18.12
-16,-2,21:18.12
-15,-2,21:18.12
-14,-2,21:18.12
-10,-2,21:18.12
-9,-2,21:18.12
1,-2,21:18.12
2,-2,21:18.12
10,-2,21:18.15
-27,-1,21:18.12
-20,-1,21:18.12
-19,-1,21:18.12
-18,-1,21:18.12
-16,-1,21:18.12
-15,-1,21:18.12
-14,-1,21:18.12
-13,-1,21:18.12
-9,-1,21:18.12
5,-1,21:18.15
9,-1,21:18.15
14,-1,21:18.12
15,-1,21:18.12
16,-1,21:18.12
-27,0,21:18.12
-26,0,21:18.12
-20,0,21:18.12
-19,0,21:18.12
-18,0,21:17.12
-16,0,21:18.12
-13,0,21:18.12
-10,0,21:18.12
-9,0,21:18.12
-8,0,21:18.12
-7,0,21:18.12
-6,0,21:18.12
-5,0,21:18.12
14,0,21:18.12
15,0,21:18.12
16,0,21:18.12
18,0,21:18.12
19,0,21:18.4
-27,1,21:18.12
-22,1,21:18.12
-21,1,21:18.12
-20,1,21:18.12
-19,1,21:18.12
-18,1,21:17.12
-16,1,21:18.12
-15,1,21:18.12
-14,1,21:18.12
-13,1,21:18.12
-12,1,21:18.12
-11,1,21:18.12
-10,1,21:18.12
-9,1,21:18.12
-5,1,21:18.12
3,1,21:18.12
8,1,21:18.15
13,1,21:18.12
14,1,21:18.12
15,1,21:18.12
16,1,21:18.12
17,1,21:18.12
18,1,21:18.12
-27,2,21:18.12
-24,2,21:18.12
-23,2,21:18.12
-22,2,21:18.12
-21,2,21:18.12
-19,2,21:18.12
-17,2,21:18.12
-14,2,21:18.12
-13,2,21:18.12
-12,2,21:18.12
-11,2,21:18.12
-10,2,21:18.12
3,2,21:18.12
7,2,21:18.15
12,2,21:18.12
13,2,21:18.12
14,2,21:18.12
16,2,21:18.12
17,2,21:18.12
-28,3,21:18.12
-27,3,21:18.12
-26,3,21:18.12
-25,3,21:18.12
-19,3,21:18.12
-17,3,21:18.12
-14,3,21:18.12
-13,3,21:18.12
-12,3,21:18.12
-11,3,21:18.12
-10,3,21:18.12
-9,3,21:18.12
2,3,21:18.12
3,3,21:18.12
6,3,21:18.15
11,3,21:18.12
12,3,21:18.12
13,3,21:18.12
-30,4,21:18.12
-29,4,21:18.12
-28,4,21:18.12
-26,4,21:18.12
-25,4,21:18.12
-22,4,21:18.12
-20,4,21:18.12
-17,4,21:18.12
-16,4,21:18.12
-15,4,21:18.12
-12,4,21:18.12
-11,4,21:18.12
-9,4,21:18.12
-8,4,21:18.12
-7,4,21:18.12
1,4,21:17.12
2,4,21:17.12
3,4,21:18.12
4,4,21:17.12
10,4,21:18.12
11,4,21:18.12
12,4,21:18.12
-24,5,21:18.12
-23,5,21:18.12
-22,5,21:18.12
-20,5,21:18.12
-16,5,21:18.12
-15,5,21:18.12
-12,5,21:18.12
-11,5,21:18.12
-10,5,21:18.12
-9,5,21:18.12
-8,5,21:18.12
-7,5,21:18.12
-6,5,21:18.12
0,5,21:17.12
1,5,21:17.12
3,5,21:18.12
4,5,21:18.12
5,5,21:17.12
6,5,21:17.12
7,5,21:17.12
8,5,21:18.12
9,5,21:18.12
10,5,21:18.12
11,5,21:18.12
12,5,21:18.12
-34,6,21:18.12
-24,6,21:18.12
-23,6,21:18.12
-19,6,21:18.12
-18,6,21:18.12
-17,6,21:18.12
-16,6,21:18.12
-12,6,21:18.12
-11,6,21:18.12
-10,6,21:18.15
-4,6,21:18.12
-1,6,21:17.12
0,6,21:17.12
3,6,21:18.12
4,6,21:18.12
5,6,21:17.12
6,6,21:17.12
7,6,21:18.12
8,6,21:18.12
9,6,21:18.12
10,6,21:18.12
11,6,21:18.12
12,6,21:18.12
-34,7,21:18.12
-28,7,21:18.12
-27,7,21:18.12
-26,7,21:18.12
-25,7,21:18.12
-24,7,21:18.12
-16,7,21:18.12
-15,7,21:18.12
-12,7,21:18.12
-11,7,21:18.12
-7,7,21:18.15
-5,7,21:18.15
-3,7,21:18.12
-2,7,21:18.12
-1,7,21:17.12
3,7,21:18.12
4,7,21:18.12
5,7,21:18.12
6,7,21:17.12
7,7,21:18.12
8,7,21:18.12
9,7,21:18.12
10,7,21:18.12
11,7,21:18.12
12,7,21:18.12
13,7,21:18.12
14,7,21:18.12
15,7,21:18.12
16,7,21:18.12
17,7,21:18.12
18,7,21:18.12
-29,8,21:18.12
-28,8,21:18.12
-27,8,21:18.12
-26,8,21:18.12
-25,8,21:18.12
-24,8,21:18.12
-23,8,21:18.12
-22,8,21:17.12
-21,8,21:18.12
-20,8,21:18.12
-15,8,21:18.12
-3,8,21:18.12
-2,8,21:17.12
-1,8,21:18.12
0,8,21:18.12
1,8,21:18.12
2,8,21:18.12
3,8,21:18.12
4,8,21:18.12
5,8,21:18.12
6,8,21:18.12
7,8,21:17.12
8,8,21:17.12
11,8,21:18.12
12,8,21:18.12
13,8,21:18.12
14,8,21:18.12
15,8,21:18.12
16,8,21:18.12
17,8,21:18.12
18,8,21:18.12
19,8,21:18.12
20,8,21:18.12
-33,9,21:18.12
-24,9,21:18.12
-23,9,21:18.12
-22,9,21:17.12
-20,9,21:18.12
-19,9,21:18.12
-18,9,21:18.12
-17,9,21:18.12
-15,9,21:18.12
-9,9,21:18.12
-4,9,21:18.12
-3,9,21:18.12
-2,9,21:17.12
-1,9,21:17.12
0,9,21:18.12
1,9,21:18.12
2,9,21:18.12
3,9,21:18.12
4,9,21:18.12
5,9,21:18.12
6,9,21:18.12
7,9,21:18.12
8,9,21:18.12
9,9,21:18.12
10,9,21:18.12
12,9,21:18.12
13,9,21:18.12
14,9,21:18.12
15,9,21:18.12
16,9,21:18.12
17,9,21:18.12
-24,10,21:18.12
-23,10,21:18.12
-22,10,21:17.12
-20,10,21:18.12
-19,10,21:18.12
-18,10,21:18.12
-17,10,21:18.12
-10,10,21:18.12
-9,10,21:18.12
-1,10,21:17.12
3,10,21:18.12
5,10,21:18.12
6,10,21:18.12
7,10,21:17.12
8,10,21:18.12
9,10,21:18.12
10,10,21:18.12
16,10,21:18.12
17,10,21:18.12
18,10,21:18.12
19,10,21:18.12
-25,11,21:18.12
-23,11,21:18.12
-22,11,21:18.12
-21,11,21:18.12
-20,11,21:18.12
-11,11,21:18.12
-10,11,21:18.12
0,11,21:17.12
5,11,21:18.12
6,11,21:17.12
7,11,21:18.12
8,11,21:18.12
9,11,21:18.12
-22,12,21:18.12
-21,12,21:18.12
-20,12,21:18.12
-19,12,21:18.12
-16,12,21:18.12
-15,12,21:18.12
-14,12,21:18.12
-13,12,21:18.12
-12,12,21:18.12
-11,12,21:18.12
-9,12,21:18.12
-8,12,21:18.12
-7,12,21:18.12
0,12,21:17.12
1,12,21:17.12
4,12,21:17.12
5,12,21:17.12
7,12,21:18.12
8,12,21:18.12
9,12,21:18.12
-23,13,21:18.12
-22,13,21:18.12
-21,13,21:18.12
-20,13,21:18.12
-19,13,21:18.12
-14,13,21:18.12
-13,13,21:18.12
-12,13,21:18.12
2,13,21:17.12
3,13,21:17.12
4,13,21:17.12
5,13,21:18.12
8,13,21:18.12
9,13,21:18.12
10,13,21:18.12
-24,14,21:18.12
-23,14,21:18.12
-22,14,21:18.12
-19,14,21:18.12
-18,14,21:18.12
4,14,21:18.12
5,14,21:18.12
4,15,21:18.12
5,15,21:18.12
3,16,21:18.12
5,16,21:18.15
3,17,21:18.12
6,17,21:18.15
3,18,21:18.12
6,18,21:18.15
3,19,21:18.12
3,20,21:18.12
3,21,21:18.12
3,22,21:18.12
3,23,21:18.12
3,24,21:18.12
3,25,21:18.4
3,26,21:18.4
3,27,21:18.4
3,28,21:18.4
3,29,21:18.4
-27,-16,22:18.12
-27,-15,22:18.12
-26,-15,22:18.12
-25,-15,22:18.12
-24,-15,22:18.12
-23,-15,22:18.12
-28,-14,22:18.12
-27,-14,22:18.12
-28,-13,22:18.12
-23,-13,22:18.12
-22,-13,22:18.12
-19,-13,22:18.12
-24,-12,22:18.12
-23,-12,22:18.12
-22,-12,22:18.12
-21,-12,22:18.12
-20,-12,22:18.12
-19,-12,22:18.12
6,-12,22:17.12
-24,-11,22:18.12
-23,-11,22:18.12
-22,-11,22:18.12
-21,-11,22:18.12
-20,-11,22:18.12
-23,-10,22:18.12
-22,-10,22:18.12
-21,-10,22:18.12
-19,-10,22:18.12
-18,-10,22:18.12
0,-10,22:18.12
1,-10,22:18.12
-23,-9,22:17.12
-22,-9,22:18.12
-21,-9,22:18.12
-19,-9,22:18.12
-18,-9,22:18.12
-17,-9,22:18.12
-10,-9,22:18.4
1,-9,22:18.12
-24,-8,22:18.12
-23,-8,22:18.12
-22,-8,22:18.12
-21,-8,22:18.12
-19,-8,22:18.12
-18,-8,22:18.12
-11,-8,22:18.4
-10,-8,22:18.4
1,-8,22:18.12
7,-8,22:18.12
-26,-7,22:18.12
-25,-7,22:18.12
-19,-7,22:18.12
-18,-7,22:18.12
-17,-7,22:18.12
-16,-7,22:18.12
-15,-7,22:18.12
-12,-7,22:18.4
-11,-7,22:18.4
1,-7,22:18.12
2,-7,22:18.12
7,-7,22:18.12
-31,-6,22:18.12
-30,-6,22:18.12
-27,-6,22:18.12
-26,-6,22:18.12
-21,-6,22:18.12
-19,-6,22:18.12
-18,-6,22:18.12
-17,-6,22:18.12
-16,-6,22:18.12
-15,-6,22:18.12
-13,-6,22:18.4
-12,-6,22:18.4
1,-6,22:18.12
2,-6,22:18.12
6,-6,22:18.12
7,-6,22:18.12
8,-6,22:18.12
-34,-5,22:18.12
-33,-5,22:18.12
-29,-5,22:18.12
-28,-5,22:18.12
-27,-5,22:18.12
-23,-5,22:18.12
-21,-5,22:18.12
-20,-5,22:18.12
-19,-5,22:18.12
-13,-5,22:18.4
-12,-5,22:18.4
1,-5,22:18.12
2,-5,22:18.12
6,-5,22:18.12
7,-5,22:18.12
8,-5,22:18.12
12,-5,22:18.12
13,-5,22:18.12
14,-5,22:18.12
-32,-4,22:18.12
-31,-4,22:18.12
-30,-4,22:18.12
-28,-4,22:18.12
-23,-4,22:18.12
-21,-4,22:18.12
-20,-4,22:18.12
-19,-4,22:18.12
-18,-4,22:18.12
-16,-4,22:18.12
-15,-4,22:18.12
-14,-4,22:18.12
-13,-4,22:18.4
1,-4,22:18.12
2,-4,22:18.12
3,-4,22:18.12
6,-4,22:18.12
7,-4,22:18.12
8,-4,22:18.12
11,-4,22:18.12
12,-4,22:18.12
13,-4,22:18.12
-28,-3,22:18.12
-22,-3,22:18.12
-20,-3,22:18.12
-19,-3,22:18.12
-18,-3,22:18.12
-17,-3,22:18.12
-16,-3,22:18.12
-15,-3,22:18.12
-14,-3,22:18.12
-13,-3,22:18.4
-10,-3,22:18.4
-9,-3,22:18.4
2,-3,22:18.12
3,-3,22:18.12
6,-3,22:18.12
7,-3,22:18.12
11,-3,22:18.12
12,-3,22:18.12
13,-3,22:18.12
-28,-2,22:18.12
-22,-2,22:18.12
-21,-2,22:18.12
-20,-2,22:18.12
-19,-2,22:18.12
-18,-2,22:18.12
-16,-2,22:18.12
-15,-2,22:18.12
-14,-2,22:18.12
-13,-2,22:18.4
-12,-2,22:18.12
-9,-2,22:18.12
-8,-2,22:18.12
2,-2,22:18.12
3,-2,22:18.12
10,-2,22:18.15
11,-2,22:18.12
12,-2,22:18.12
18,-2,22:18.12
19,-2,22:18.4
-28,-1,22:18.12
-21,-1,22:18.12
-20,-1,22:18.12
-19,-1,22:18.12
-18,-1,22:18.12
-17,-1,22:18.12
-16,-1,22:18.12
-13,-1,22:18.4
-12,-1,22:18.12
-11,-1,22:18.12
-9,-1,22:18.12
-8,-1,22:18.12
2,-1,22:18.12
3,-1,22:18.12
4,-1,22:18.12
5,-1,22:18.12
6,-1,22:18.12
9,-1,22:18.15
11,-1,22:18.12
12,-1,22:18.12
17,-1,22:18.12
18,-1,22:18.12
19,-1,22:18.4
-27,0,22:18.12
-21,0,22:18.12
-20,0,22:18.12
-19,0,22:18.12
-18,0,22:18.12
-17,0,22:18.12
-16,0,22:18.12
-12,0,22:18.12
-11,0,22:18.12
-8,0,22:18.12
-7,0,22:18.12
3,0,22:18.12
4,0,22:18.12
5,0,22:18.12
15,0,22:18.12
16,0,22:18.12
17,0,22:18.12
18,0,22:18.12
-27,1,22:18.12
-22,1,22:18.12
-21,1,22:18.12
-20,1,22:18.12
-19,1,22:18.12
-18,1,22:18.12
-17,1,22:18.12
-16,1,22:18.12
-15,1,22:18.12
-14,1,22:18.12
-13,1,22:18.4
-10,1,22:18.12
-9,1,22:18.12
-8,1,22:18.12
3,1,22:18.12
4,1,22:18.12
5,1,22:18.12
8,1,22:18.15
10,1,22:18.12
13,1,22:18.12
14,1,22:18.12
15,1,22:18.12
16,1,22:18.12
17,1,22:18.12
-27,2,22:18.12
-23,2,22:18.12
-22,2,22:18.12
-21,2,22:18.12
-20,2,22:18.12
-19,2,22:18.12
-18,2,22:18.12
-17,2,22:18.12
-15,2,22:18.12
-14,2,22:18.12
-13,2,22:18.12
-12,2,22:18.12
-11,2,22:18.12
-10,2,22:18.12
-9,2,22:18.12
3,2,22:18.12
4,2,22:18.12
5,2,22:18.12
7,2,22:18.15
9,2,22:18.12
10,2,22:18.12
11,2,22:18.12
12,2,22:18.12
13,2,22:18.12
14,2,22:18.12
15,2,22:18.12
16,2,22:18.12
-27,3,22:18.12
-26,3,22:18.12
-25,3,22:18.12
-24,3,22:18.12
-23,3,22:18.12
-22,3,22:18.12
-21,3,22:18.12
-20,3,22:18.12
-19,3,22:18.12
-18,3,22:18.12
-17,3,22:18.12
-14,3,22:18.12
-11,3,22:18.12
-10,3,22:18.12
2,3,22:18.12
3,3,22:18.12
4,3,22:17.12
5,3,22:18.12
6,3,22:18.15
8,3,22:18.12
9,3,22:18.12
10,3,22:18.12
13,3,22:18.12
14,3,22:18.12
15,3,22:18.12
-26,4,22:18.12
-25,4,22:18.12
-24,4,22:18.12
-23,4,22:18.12
-22,4,22:18.12
-20,4,22:18.12
-19,4,22:18.12
-18,4,22:18.12
-17,4,22:18.12
-16,4,22:18.12
-15,4,22:18.12
-14,4,22:18.12
-13,4,22:18.12
-12,4,22:18.12
-11,4,22:18.12
-10,4,22:18.12
-9,4,22:18.12
-8,4,22:18.12
1,4,22:17.12
2,4,22:17.12
3,4,22:17.12
4,4,22:17.12
5,4,22:18.12
6,4,22:18.12
7,4,22:17.12
8,4,22:17.12
9,4,22:17.12
12,4,22:18.12
13,4,22:18.12
14,4,22:18.12
-24,5,22:18.12
-23,5,22:18.12
-20,5,22:18.12
-19,5,22:18.12
-18,5,22:18.12
-17,5,22:18.12
-16,5,22:18.12
-15,5,22:18.12
-14,5,22:18.12
-13,5,22:18.12
-11,5,22:18.12
-10,5,22:18.12
-9,5,22:18.12
-8,5,22:18.12
-7,5,22:18.12
-6,5,22:18.12
-5,5,22:18.12
0,5,22:17.12
1,5,22:17.12
2,5,22:18.12
4,5,22:17.12
5,5,22:17.12
6,5,22:17.12
7,5,22:18.12
8,5,22:17.12
9,5,22:17.12
11,5,22:18.12
12,5,22:18.12
13,5,22:18.12
14,5,22:18.12
15,5,22:18.12
16,5,22:18.12
17,5,22:18.12
18,5,22:18.12
-24,6,22:18.12
-20,6,22:18.12
-19,6,22:18.12
-18,6,22:18.12
-17,6,22:18.12
-16,6,22:18.12
-12,6,22:18.12
-11,6,22:18.12
-10,6,22:18.12
-9,6,22:18.12
-8,6,22:18.12
-7,6,22:18.12
-6,6,22:18.12
-5,6,22:18.12
-4,6,22:18.12
-3,6,22:18.12
-2,6,22:18.12
-1,6,22:17.12
0,6,22:17.12
2,6,22:18.12
4,6,22:17.12
5,6,22:17.12
6,6,22:18.12
7,6,22:17.12
8,6,22:17.12
10,6,22:18.12
11,6,22:18.12
12,6,22:18.12
13,6,22:18.12
14,6,22:18.12
15,6,22:18.12
16,6,22:18.12
17,6,22:18.12
18,6,22:18.12
19,6,22:18.12
20,6,22:18.12
21,6,22:18.12
-25,7,22:18.12
-16,7,22:18.12
-13,7,22:18.12
-12,7,22:18.12
-11,7,22:18.12
-10,7,22:18.12
-9,7,22:18.12
-8,7,22:18.12
-7,7,22:18.15
-6,7,22:18.12
-5,7,22:18.12
-4,7,22:18.12
-3,7,22:18.12
-2,7,22:18.12
-1,7,22:18.12
0,7,22:18.12
1,7,22:18.12
2,7,22:18.12
5,7,22:17.12
6,7,22:18.12
7,7,22:17.12
9,7,22:18.12
10,7,22:18.12
11,7,22:18.12
12,7,22:18.12
13,7,22:18.12
14,7,22:18.12
15,7,22:18.12
16,7,22:18.12
17,7,22:18.12
18,7,22:18.12
19,7,22:18.12
20,7,22:18.12
21,7,22:18.12
22,7,22:18.12
-29,8,22:18.12
-28,8,22:18.12
