[META]
version=2.0
spawnOnBlockType=2
spawnSunlight=True
spawnDarkness=True
spawnWater=False
spawnLava=False
underFill=False
randomRotation=True
dig=True
tree=False
branch=False
needsFoundation=True
rarity=100
collisionPercentage=20
spawnElevationMin=0
spawnElevationMax=200
spawnInBiome=Custom
[DATA]
-10,10,-8:17.12
-16,14,-8:17.12
-7,15,-8:17.12
-6,15,-8:17.12
-5,15,-8:17.12
-12,21,-8:17.12
-10,10,-7:17.12
-9,10,-7:17.12
-10,11,-7:17.12
-9,11,-7:17.12
-8,11,-7:17.12
-16,13,-7:17.12
-15,13,-7:17.12
-14,13,-7:17.12
-16,14,-7:17.12
-15,14,-7:17.12
-6,14,-7:17.12
-9,15,-7:17.12
-7,15,-7:17.12
-6,15,-7:17.12
-5,15,-7:17.12
-6,16,-7:17.12
-13,20,-7:17.12
-13,21,-7:17.12
-12,21,-7:17.12
-13,22,-7:17.12
-11,22,-7:17.12
-11,9,-6:17.12
-11,10,-6:17.12
-10,10,-6:17.12
-9,10,-6:17.12
-8,10,-6:17.12
-10,11,-6:17.12
-9,11,-6:17.12
-16,13,-6:17.12
-15,13,-6:17.12
-8,13,-6:17.12
-16,14,-6:17.12
-9,14,-6:17.12
-8,14,-6:17.12
-16,15,-6:17.12
-8,15,-6:17.12
-7,15,-6:17.12
-6,15,-6:17.12
-7,16,-6:17.12
-6,16,-6:17.12
-13,19,-6:17.12
-12,19,-6:17.12
-11,19,-6:17.12
-13,20,-6:17.12
-12,20,-6:17.12
-11,21,-6:17.12
-10,9,-5:17.12
-10,10,-5:17.12
-9,10,-5:17.12
-10,11,-5:17.12
-9,11,-5:17.12
-16,12,-5:17.12
-17,13,-5:17.12
-16,13,-5:17.12
-15,13,-5:17.12
-8,13,-5:17.12
-16,14,-5:17.12
-15,14,-5:17.12
-9,14,-5:17.12
-8,14,-5:17.12
-7,14,-5:17.12
-9,15,-5:17.12
-8,15,-5:17.12
-7,15,-5:17.12
-6,15,-5:17.12
-8,16,-5:17.12
-12,18,-5:17.12
-13,19,-5:17.12
-12,19,-5:17.12
-11,19,-5:17.12
-13,20,-5:17.12
-12,20,-5:17.12
-11,11,-4:17.12
-10,11,-4:17.12
-9,11,-4:17.12
-14,12,-4:17.12
-10,12,-4:17.12
-15,13,-4:17.12
-14,13,-4:17.12
-13,13,-4:17.12
-16,14,-4:17.12
-14,14,-4:17.12
-8,14,-4:17.12
-7,14,-4:17.12
-6,14,-4:17.12
-13,15,-4:17.12
-12,15,-4:17.12
-9,15,-4:17.12
-8,15,-4:17.12
-7,15,-4:17.12
-6,15,-4:17.12
-12,16,-4:17.12
-8,16,-4:17.12
-7,16,-4:17.12
-12,17,-4:17.12
-11,17,-4:17.12
-12,18,-4:17.12
-11,18,-4:17.12
-13,19,-4:17.12
-11,19,-4:17.12
-10,10,-3:17.12
-14,11,-3:17.12
-13,11,-3:17.12
-11,11,-3:17.12
-10,11,-3:17.12
-15,12,-3:17.12
-14,12,-3:17.12
-13,12,-3:17.12
-11,12,-3:17.12
-15,13,-3:17.12
-14,13,-3:17.12
-13,13,-3:17.12
-14,14,-3:17.12
-13,14,-3:17.12
-12,14,-3:17.12
-11,14,-3:17.12
-8,14,-3:17.12
-7,14,-3:17.12
-13,15,-3:17.12
-12,15,-3:17.12
-11,15,-3:17.12
-10,15,-3:17.12
-9,15,-3:17.12
-8,15,-3:17.12
-7,15,-3:17.12
-6,15,-3:17.12
-16,16,-3:17.12
-15,16,-3:17.12
-13,16,-3:17.12
-12,16,-3:17.12
-9,16,-3:17.12
-8,16,-3:17.12
-7,16,-3:17.12
-13,18,-3:17.12
-12,18,-3:17.12
-11,18,-3:17.12
-12,19,-3:17.12
-11,19,-3:17.12
-11,10,-2:17.12
-10,10,-2:17.12
-9,10,-2:17.12
-14,11,-2:17.12
-13,11,-2:17.12
-12,11,-2:17.12
-11,11,-2:17.12
-10,11,-2:17.12
-9,11,-2:17.12
-15,12,-2:17.12
-14,12,-2:17.12
-13,12,-2:17.12
-12,12,-2:17.12
-11,12,-2:17.12
-10,12,-2:17.12
-9,12,-2:17.12
-8,12,-2:17.12
-15,13,-2:17.12
-14,13,-2:17.12
-13,13,-2:17.12
-12,13,-2:17.12
-11,13,-2:17.12
-10,13,-2:17.12
-9,13,-2:17.12
-8,13,-2:17.12
-7,13,-2:17.12
-15,14,-2:17.12
-14,14,-2:17.12
-13,14,-2:17.12
-12,14,-2:17.12
-11,14,-2:17.12
-10,14,-2:17.12
-9,14,-2:17.12
-8,14,-2:17.12
-7,14,-2:17.12
-15,15,-2:17.12
-14,15,-2:17.12
-13,15,-2:17.12
-12,15,-2:17.12
-11,15,-2:17.12
-10,15,-2:17.12
-9,15,-2:17.12
-8,15,-2:17.12
-7,15,-2:17.12
-16,16,-2:17.12
-15,16,-2:17.12
-14,16,-2:17.12
-13,16,-2:17.12
-12,16,-2:17.12
-11,16,-2:17.12
-10,16,-2:17.12
-9,16,-2:17.12
-8,16,-2:17.12
-7,16,-2:17.12
-15,17,-2:17.12
-14,17,-2:17.12
-13,17,-2:17.12
-12,17,-2:17.12
-11,17,-2:17.12
-10,17,-2:17.12
-9,17,-2:17.12
-8,17,-2:17.12
-13,18,-2:17.12
-12,18,-2:17.12
-11,18,-2:17.12
-10,18,-2:17.12
-9,18,-2:17.12
-13,11,-1:17.12
-12,11,-1:17.12
-11,11,-1:17.12
-10,11,-1:17.12
-9,11,-1:17.12
-14,12,-1:17.12
-9,12,-1:17.12
-8,12,-1:17.12
-15,13,-1:17.12
-14,13,-1:17.12
-8,13,-1:17.12
-15,14,-1:17.12
-8,14,-1:17.12
-7,14,-1:17.12
-15,15,-1:17.12
-7,15,-1:17.12
-15,16,-1:17.12
-14,16,-1:17.12
-8,16,-1:17.12
-7,16,-1:17.12
-14,17,-1:17.12
-13,17,-1:17.12
-9,17,-1:17.12
-8,17,-1:17.12
-12,18,-1:17.12
-11,18,-1:17.12
-10,18,-1:17.12
-9,18,-1:17.12
-13,11,0:17.12
-12,11,0:17.12
-11,11,0:17.12
-10,11,0:17.12
-14,12,0:17.12
-13,12,0:17.12
-10,12,0:17.12
-9,12,0:17.12
-8,12,0:17.12
-15,13,0:17.12
-14,13,0:17.12
-8,13,0:17.12
-15,14,0:17.12
-8,14,0:17.12
-15,15,0:17.12
-14,15,0:17.12
-8,15,0:17.12
-7,15,0:17.12
-14,16,0:17.12
-8,16,0:17.12
-14,17,0:17.12
-13,17,0:17.12
-12,17,0:17.12
-11,17,0:17.12
-10,17,0:17.12
-9,17,0:17.12
-12,18,0:17.12
-11,18,0:17.12
-12,11,1:17.12
-11,11,1:17.12
-10,11,1:17.12
-14,12,1:17.12
-13,12,1:17.12
-12,12,1:17.12
-10,12,1:17.12
-9,12,1:17.12
-14,13,1:17.12
-8,13,1:17.12
-15,14,1:17.12
-8,14,1:17.12
-14,15,1:17.12
-8,15,1:17.12
-14,16,1:17.12
-9,16,1:17.12
-8,16,1:17.12
-13,17,1:17.12
-12,17,1:17.12
-11,17,1:17.12
-10,17,1:17.12
-9,17,1:17.12
-11,11,2:17.12
-13,12,2:17.12
-12,12,2:17.12
-11,12,2:17.12
-10,12,2:17.12
-9,12,2:17.12
-14,13,2:17.12
-9,13,2:17.12
-14,14,2:17.12
-8,14,2:17.12
-14,15,2:17.12
-8,15,2:17.12
-14,16,2:17.12
-13,16,2:17.12
-9,16,2:17.12
-13,17,2:17.12
-12,17,2:17.12
-11,17,2:17.12
-10,17,2:17.12
-9,17,2:17.12
-13,12,3:17.12
-12,12,3:17.12
-11,12,3:17.12
-10,12,3:17.12
-14,13,3:17.12
-13,13,3:17.12
-9,13,3:17.12
-14,14,3:17.12
-9,14,3:17.12
-14,15,3:17.12
-9,15,3:17.12
-8,15,3:17.12
-14,16,3:17.12
-13,16,3:17.12
-9,16,3:17.12
-13,17,3:17.12
-12,17,3:17.12
-11,17,3:17.12
-10,17,3:17.12
2,17,3:18.7
-16,9,4:18.15
-13,12,4:17.12
-12,12,4:17.12
-11,12,4:17.12
-10,12,4:17.12
-14,13,4:17.12
-13,13,4:17.12
-10,13,4:17.12
-9,13,4:17.12
-14,14,4:17.12
-9,14,4:17.12
-14,15,4:17.12
-9,15,4:17.12
-14,16,4:17.12
-13,16,4:17.12
-10,16,4:17.12
-9,16,4:17.12
-12,17,4:17.12
-11,17,4:17.12
-10,17,4:17.12
2,17,4:18.7
-13,19,4:18.15
-13,20,4:18.15
-16,9,5:18.15
-13,12,5:17.12
-12,12,5:17.12
-11,12,5:17.12
-10,12,5:17.12
-14,13,5:17.12
-13,13,5:17.12
-10,13,5:17.12
-9,13,5:17.12
-14,14,5:17.12
-9,14,5:17.12
-14,15,5:17.12
-9,15,5:17.12
-5,15,5:18.15
-14,16,5:17.12
-13,16,5:17.12
-10,16,5:17.12
-9,16,5:17.12
-12,17,5:17.12
-11,17,5:17.12
-10,17,5:17.12
2,17,5:18.7
-13,19,5:18.15
-13,21,5:18.15
-16,9,6:18.15
-13,12,6:17.12
-12,12,6:17.12
-11,12,6:17.12
-14,13,6:17.12
-13,13,6:17.12
-10,13,6:17.12
-9,13,6:17.12
-14,14,6:17.12
-9,14,6:17.12
-14,15,6:17.12
-9,15,6:17.12
-6,15,6:18.15
-14,16,6:17.12
-13,16,6:17.12
-10,16,6:17.12
-9,16,6:17.12
-4,16,6:18.15
-3,16,6:18.7
-12,17,6:17.12
-11,17,6:17.12
-10,17,6:17.12
-13,19,6:18.15
-13,21,6:18.15
-13,22,6:18.7
-11,8,7:18.15
-16,9,7:18.15
-11,9,7:18.15
-13,12,7:17.12
-12,12,7:17.12
-11,12,7:17.12
-14,13,7:17.12
-13,13,7:17.12
-10,13,7:17.12
-9,13,7:17.12
-14,14,7:17.12
-9,14,7:17.12
-14,15,7:17.12
-9,15,7:17.12
-7,15,7:18.15
-6,15,7:18.15
-14,16,7:17.12
-13,16,7:17.12
-10,16,7:17.12
-9,16,7:17.12
-4,16,7:18.15
-3,16,7:18.7
-12,17,7:17.12
-11,17,7:17.12
2,17,7:18.7
-13,19,7:18.15
-13,20,7:18.15
-13,21,7:18.15
-14,23,7:18.7
-13,23,7:18.7
-11,7,8:18.7
-16,9,8:18.15
-11,9,8:18.15
-11,10,8:18.15
-13,12,8:17.12
-12,12,8:17.12
-11,12,8:17.12
-14,13,8:17.12
-13,13,8:17.12
-10,13,8:17.12
-9,13,8:17.12
-14,14,8:17.12
-9,14,8:17.12
-14,15,8:17.12
-9,15,8:17.12
-7,15,8:18.15
-6,15,8:18.15
-14,16,8:17.12
-13,16,8:17.12
-10,16,8:17.12
-3,16,8:18.7
-12,17,8:17.12
-11,17,8:17.12
2,17,8:18.7
-13,19,8:18.15
-13,20,8:18.15
-13,21,8:18.15
-14,23,8:18.7
-11,7,9:18.7
-11,8,9:18.15
-16,9,9:18.15
-11,10,9:18.15
-13,12,9:17.12
-12,12,9:17.12
-11,12,9:17.12
-14,13,9:17.12
-10,13,9:17.12
-9,13,9:17.12
-14,14,9:17.12
-9,14,9:17.12
-14,15,9:17.12
-9,15,9:17.12
-7,15,9:18.15
-6,15,9:18.15
-14,16,9:17.12
-13,16,9:17.12
-10,16,9:17.12
-3,16,9:18.7
-12,17,9:17.12
-11,17,9:17.12
2,17,9:18.7
-13,18,9:18.15
-13,19,9:18.15
-13,20,9:18.15
-13,21,9:18.15
-13,22,9:18.7
-14,23,9:18.7
-11,7,10:18.15
-11,8,10:18.15
-16,9,10:18.15
-11,10,10:18.15
-13,12,10:17.12
-12,12,10:17.12
-11,12,10:17.12
-14,13,10:17.12
-10,13,10:17.12
-14,14,10:17.12
-9,14,10:17.12
-14,15,10:17.12
-9,15,10:17.12
-7,15,10:18.15
-6,15,10:18.15
-14,16,10:17.12
-13,16,10:17.12
-10,16,10:17.12
-5,16,10:18.15
-4,16,10:18.7
-3,16,10:18.7
-12,17,10:17.12
-11,17,10:17.12
-13,20,10:18.15
-14,21,10:18.15
-13,21,10:18.15
-14,22,10:18.15
-13,22,10:18.15
-14,23,10:18.7
-11,7,11:18.15
-11,8,11:18.15
-16,9,11:18.15
-11,10,11:18.15
-13,12,11:17.12
-12,12,11:17.12
-11,12,11:17.12
-14,13,11:17.12
-10,13,11:17.12
-9,13,11:17.12
-15,14,11:17.12
-14,14,11:17.12
-9,14,11:17.12
-14,15,11:17.12
-9,15,11:17.12
-6,15,11:18.15
-14,16,11:17.12
-13,16,11:17.12
-10,16,11:17.12
-5,16,11:18.15
-4,16,11:18.7
-3,16,11:18.7
-13,17,11:17.12
-12,17,11:17.12
-11,17,11:17.12
-10,17,11:17.12
2,17,11:18.7
-13,18,11:18.15
-13,19,11:18.15
-13,20,11:18.15
-14,21,11:18.15
-13,21,11:18.15
-14,22,11:18.15
-13,22,11:18.15
-14,23,11:18.7
-14,24,11:18.15
-11,7,12:18.15
-11,8,12:18.15
-11,9,12:18.15
-11,10,12:18.15
-14,12,12:17.12
-13,12,12:17.12
-12,12,12:17.12
-11,12,12:17.12
-22,13,12:18.12
-21,13,12:18.12
-20,13,12:18.12
-14,13,12:17.12
-10,13,12:17.12
-9,13,12:17.12
-21,14,12:18.12
-20,14,12:18.12
-19,14,12:18.12
-15,14,12:17.12
-9,14,12:17.12
-15,15,12:17.12
-14,15,12:17.12
-9,15,12:17.12
-7,15,12:18.15
-14,16,12:17.12
-13,16,12:17.12
-10,16,12:17.12
-5,16,12:18.15
-4,16,12:18.15
-3,16,12:18.7
-13,17,12:17.12
-12,17,12:17.12
-11,17,12:17.12
-10,17,12:17.12
2,17,12:18.7
-13,18,12:18.15
-13,19,12:18.15
-13,20,12:18.15
-14,21,12:18.15
-13,21,12:18.15
-14,22,12:18.15
-13,22,12:18.15
-14,23,12:18.15
-14,24,12:18.15
-11,2,13:18.4
-11,3,13:18.12
-11,4,13:18.12
-11,5,13:18.12
-11,7,13:18.15
-11,9,13:18.15
-11,10,13:18.15
-15,11,13:18.12
-23,12,13:18.12
-14,12,13:17.12
-13,12,13:17.12
-12,12,13:17.12
-11,12,13:17.12
-10,12,13:17.12
-23,13,13:18.12
-22,13,13:18.12
-21,13,13:18.12
-20,13,13:18.12
-19,13,13:18.12
-15,13,13:17.12
-14,13,13:17.12
-13,13,13:18.12
-10,13,13:17.12
-9,13,13:17.12
-21,14,13:18.12
-20,14,13:18.12
-19,14,13:18.12
-18,14,13:18.12
-17,14,13:18.12
-15,14,13:17.12
-14,14,13:18.12
-13,14,13:18.12
-9,14,13:17.12
-15,15,13:17.12
-14,15,13:18.12
-13,15,13:18.12
-9,15,13:17.12
-8,15,13:18.15
-7,15,13:18.15
-15,16,13:17.12
-14,16,13:17.12
-10,16,13:17.12
-9,16,13:17.12
-5,16,13:18.15
-3,16,13:18.15
-18,17,13:18.12
-17,17,13:18.12
-14,17,13:17.12
-13,17,13:17.12
-12,17,13:17.12
-11,17,13:17.12
-10,17,13:17.12
2,17,13:18.15
-13,18,13:18.15
-4,18,13:18.12
-19,19,13:18.12
-13,19,13:18.15
-4,19,13:18.12
-3,19,13:18.12
-20,20,13:18.12
-19,20,13:18.12
-13,20,13:18.15
-21,21,13:18.12
-14,22,13:18.15
-14,23,13:18.15
-14,24,13:18.15
-10,24,13:18.12
-11,0,14:18.12
-11,1,14:18.12
-11,2,14:18.12
-11,3,14:18.12
-11,4,14:18.12
-11,5,14:18.12
-12,6,14:18.12
-11,7,14:18.15
-28,8,14:18.12
-12,8,14:18.12
-26,9,14:18.12
-13,9,14:18.12
-12,9,14:18.12
-11,9,14:18.15
-18,10,14:18.12
-17,10,14:18.12
-13,10,14:18.12
-12,10,14:18.12
-11,10,14:18.15
-18,11,14:18.12
-17,11,14:18.12
-16,11,14:18.12
-13,11,14:18.12
-12,11,14:17.12
-11,11,14:17.12
-23,12,14:18.12
-22,12,14:18.12
-18,12,14:18.12
-17,12,14:18.12
-16,12,14:18.12
-15,12,14:18.12
-14,12,14:17.12
-13,12,14:17.12
-11,12,14:17.12
-10,12,14:17.12
-22,13,14:18.12
-21,13,14:18.12
-20,13,14:18.12
-19,13,14:18.12
-18,13,14:18.12
-17,13,14:18.12
-16,13,14:18.12
-15,13,14:18.12
-14,13,14:18.12
-13,13,14:18.12
-12,13,14:18.12
-10,13,14:17.12
-9,13,14:17.12
-23,14,14:18.12
-22,14,14:18.12
-21,14,14:18.12
-20,14,14:18.12
-19,14,14:18.12
-18,14,14:18.12
-17,14,14:18.12
-16,14,14:18.12
-15,14,14:18.12
-14,14,14:18.12
-13,14,14:18.12
-12,14,14:18.12
-11,14,14:18.12
-10,14,14:18.12
-9,14,14:17.12
-23,15,14:18.12
-22,15,14:18.12
-21,15,14:18.12
-20,15,14:18.12
-19,15,14:18.12
-18,15,14:18.12
-17,15,14:18.12
-16,15,14:18.12
-15,15,14:18.12
-14,15,14:18.12
-13,15,14:18.12
-12,15,14:18.12
-11,15,14:18.12
-10,15,14:18.12
-9,15,14:17.12
-8,15,14:18.15
-7,15,14:18.15
-22,16,14:18.12
-21,16,14:18.12
-20,16,14:18.12
-18,16,14:18.12
-17,16,14:18.12
-16,16,14:18.12
-15,16,14:18.12
-14,16,14:17.12
-13,16,14:18.12
-12,16,14:18.12
-10,16,14:17.12
-9,16,14:17.12
-8,16,14:18.12
-7,16,14:18.12
-5,16,14:18.15
-3,16,14:18.15
-20,17,14:18.12
-19,17,14:18.12
-16,17,14:18.12
-15,17,14:17.12
-14,17,14:17.12
-13,17,14:18.12
-12,17,14:18.12
-11,17,14:17.12
-10,17,14:17.12
-7,17,14:18.12
-21,18,14:18.12
-19,18,14:18.12
-18,18,14:18.12
-17,18,14:18.12
-13,18,14:18.12
-12,18,14:17.12
-11,18,14:17.12
-5,18,14:18.12
-4,18,14:18.12
-23,19,14:18.12
-22,19,14:18.12
-21,19,14:18.12
-20,19,14:18.12
-13,19,14:18.12
-12,19,14:18.12
-4,19,14:18.12
-3,19,14:18.12
-2,19,14:18.12
-24,20,14:18.12
-23,20,14:18.12
-22,20,14:18.12
-21,20,14:18.12
-13,20,14:18.15
-12,20,14:18.12
-2,20,14:18.12
-24,21,14:18.12
-23,21,14:18.12
-22,21,14:18.12
-14,22,14:18.15
-12,22,14:18.12
-11,22,14:18.12
-19,23,14:18.12
-18,23,14:18.12
-16,23,14:18.12
-14,23,14:18.15
-11,23,14:18.12
-16,24,14:18.12
-14,24,14:18.15
-11,24,14:18.12
-11,25,14:18.12
-10,25,14:18.12
-11,26,14:18.12
-10,26,14:18.12
-11,27,14:18.12
-11,-1,15:18.12
-11,0,15:18.12
-11,1,15:18.12
-11,2,15:18.12
-11,3,15:18.12
-11,4,15:18.12
-12,5,15:18.12
-11,5,15:18.12
-12,6,15:18.12
-30,7,15:18.12
-12,7,15:18.12
-11,7,15:18.15
-29,8,15:18.12
-28,8,15:18.12
-14,8,15:18.12
-13,8,15:18.12
-12,8,15:18.12
-11,8,15:18.12
-28,9,15:18.12
-26,9,15:18.12
-25,9,15:18.12
-13,9,15:18.12
-12,9,15:18.12
-11,9,15:18.12
-26,10,15:18.12
-25,10,15:18.12
-24,10,15:18.12
-23,10,15:18.12
-14,10,15:18.12
-13,10,15:18.12
-12,10,15:18.12
-11,10,15:18.12
-23,11,15:18.12
-18,11,15:18.12
-17,11,15:18.12
-15,11,15:18.12
-14,11,15:18.12
-13,11,15:17.12
-12,11,15:18.12
-11,11,15:17.12
-24,12,15:18.12
-23,12,15:18.12
-22,12,15:18.12
-21,12,15:18.12
-20,12,15:18.12
-19,12,15:17.12
-18,12,15:18.12
-17,12,15:18.12
-16,12,15:18.12
-15,12,15:18.12
-14,12,15:17.12
-13,12,15:18.12
-12,12,15:18.12
-11,12,15:18.12
-10,12,15:17.12
-5,12,15:18.12
-4,12,15:18.12
-23,13,15:18.12
-22,13,15:18.12
-21,13,15:18.12
-20,13,15:18.12
-19,13,15:17.12
-18,13,15:17.12
-17,13,15:17.12
-16,13,15:18.12
-15,13,15:18.12
-14,13,15:18.12
-13,13,15:18.12
-12,13,15:18.12
-11,13,15:18.12
-10,13,15:18.12
-9,13,15:17.12
-8,13,15:18.12
-6,13,15:18.12
-5,13,15:18.12
-4,13,15:18.12
-3,13,15:18.12
-2,13,15:18.12
-1,13,15:18.12
0,13,15:18.12
1,13,15:18.12
-27,14,15:18.12
-26,14,15:18.12
-25,14,15:18.12
-23,14,15:18.12
-19,14,15:17.12
-18,14,15:17.12
-17,14,15:17.12
-16,14,15:17.12
-15,14,15:18.12
-14,14,15:18.12
-13,14,15:18.12
-12,14,15:18.12
-11,14,15:18.12
-10,14,15:18.12
-9,14,15:18.12
-8,14,15:18.12
-7,14,15:18.12
-6,14,15:18.12
-5,14,15:18.12
-4,14,15:18.12
-3,14,15:18.12
-2,14,15:18.12
-27,15,15:18.12
-20,15,15:18.12
-18,15,15:18.12
-17,15,15:18.12
-16,15,15:17.12
-15,15,15:17.12
-14,15,15:17.12
-13,15,15:18.12
-12,15,15:18.12
-11,15,15:18.12
-10,15,15:18.12
-9,15,15:18.12
-8,15,15:18.12
-7,15,15:18.15
-24,16,15:18.12
-23,16,15:18.12
-22,16,15:18.12
-21,16,15:18.12
-20,16,15:18.12
-19,16,15:18.12
-18,16,15:18.12
-17,16,15:18.12
-16,16,15:17.12
-15,16,15:17.12
-13,16,15:17.12
-12,16,15:18.12
-11,16,15:18.12
-10,16,15:18.12
-9,16,15:18.12
-8,16,15:18.12
-7,16,15:18.12
-6,16,15:18.12
-5,16,15:18.12
-4,16,15:18.12
-3,16,15:18.15
-2,16,15:18.12
-23,17,15:18.12
-22,17,15:18.12
-21,17,15:18.12
-20,17,15:18.12
-17,17,15:17.12
-16,17,15:17.12
-15,17,15:18.12
-14,17,15:17.12
-13,17,15:17.12
-12,17,15:18.12
-11,17,15:18.12
-10,17,15:17.12
-7,17,15:18.12
-6,17,15:18.12
-4,17,15:18.12
-3,17,15:18.12
-2,17,15:18.12
-1,17,15:18.12
2,17,15:18.15
-24,18,15:18.12
-23,18,15:18.12
-22,18,15:18.12
-21,18,15:18.12
-19,18,15:18.12
-18,18,15:17.12
-17,18,15:17.12
-16,18,15:17.12
-15,18,15:18.12
-14,18,15:18.12
-13,18,15:17.12
-12,18,15:18.12
-11,18,15:17.12
-5,18,15:18.12
-4,18,15:18.12
-3,18,15:18.12
-1,18,15:18.12
0,18,15:18.12
-24,19,15:18.12
-23,19,15:18.12
-22,19,15:18.12
-20,19,15:18.12
-19,19,15:18.12
-18,19,15:18.12
-17,19,15:18.12
-16,19,15:18.12
-15,19,15:18.12
-14,19,15:18.12
-13,19,15:18.12
-12,19,15:18.12
-3,19,15:18.12
-2,19,15:18.12
-1,19,15:18.12
0,19,15:18.12
1,19,15:18.12
-24,20,15:18.12
-23,20,15:18.12
-22,20,15:18.12
-21,20,15:18.12
-20,20,15:18.12
-19,20,15:18.12
-18,20,15:18.12
-17,20,15:18.12
-15,20,15:18.12
-14,20,15:18.12
-13,20,15:18.12
-12,20,15:18.12
-2,20,15:18.12
-1,20,15:18.12
-24,21,15:18.12
-23,21,15:18.12
-22,21,15:18.12
-21,21,15:18.12
-20,21,15:18.12
-19,21,15:18.12
-18,21,15:18.12
-15,21,15:18.12
-14,21,15:18.12
-13,21,15:18.12
-12,21,15:18.12
-24,22,15:18.12
-23,22,15:18.12
-22,22,15:18.12
-21,22,15:18.12
-20,22,15:18.12
-19,22,15:18.12
-15,22,15:18.12
-14,22,15:18.15
-13,22,15:18.12
-12,22,15:18.12
-24,23,15:18.12
-23,23,15:18.12
-22,23,15:18.12
-21,23,15:18.12
-20,23,15:18.12
-19,23,15:18.12
-16,23,15:18.12
-15,23,15:18.12
-14,23,15:18.12
-13,23,15:18.12
-12,23,15:18.12
-23,24,15:18.12
-22,24,15:18.12
-21,24,15:18.12
-20,24,15:18.12
-16,24,15:18.12
-15,24,15:18.12
-14,24,15:18.12
-13,24,15:18.12
-12,24,15:18.12
-23,25,15:18.12
-16,25,15:18.12
-15,25,15:18.12
-14,25,15:18.12
-12,25,15:18.12
-16,26,15:18.12
-15,26,15:18.12
-14,26,15:18.12
-12,26,15:18.12
-11,26,15:18.12
-15,27,15:18.12
-11,27,15:18.12
-15,28,15:17.12
-12,28,15:18.12
-11,28,15:18.12
-15,29,15:17.12
-11,-1,16:18.12
-11,0,16:18.12
-11,1,16:18.12
-11,2,16:18.12
-11,3,16:18.12
-11,4,16:18.12
-12,5,16:18.12
-12,6,16:18.12
-31,7,16:18.12
-30,7,16:18.12
-12,7,16:18.12
-11,7,16:18.15
-30,8,16:18.12
-29,8,16:18.12
-25,8,16:18.12
-15,8,16:18.12
-14,8,16:18.12
-13,8,16:18.12
-12,8,16:18.12
-11,8,16:18.12
-10,8,16:18.12
-9,8,16:18.12
-28,9,16:18.12
-25,9,16:18.12
-24,9,16:18.12
-23,9,16:18.12
-22,9,16:18.12
-21,9,16:18.12
-20,9,16:18.12
-15,9,16:18.12
-13,9,16:18.12
-12,9,16:18.12
-11,9,16:17.12
-10,9,16:18.12
-9,9,16:18.12
-27,10,16:18.12
-26,10,16:18.12
-25,10,16:18.12
-24,10,16:18.12
-23,10,16:18.12
-22,10,16:18.12
-21,10,16:18.12
-20,10,16:18.12
-19,10,16:18.12
-18,10,16:18.12
-15,10,16:18.12
-13,10,16:18.12
-12,10,16:17.12
-11,10,16:18.12
-10,10,16:18.12
-9,10,16:18.12
-25,11,16:18.12
-24,11,16:18.12
-23,11,16:18.12
-22,11,16:18.12
-21,11,16:18.12
-20,11,16:18.12
-19,11,16:18.12
-17,11,16:18.12
-16,11,16:18.12
-15,11,16:18.12
-14,11,16:17.12
-13,11,16:17.12
-12,11,16:17.12
-11,11,16:17.12
-10,11,16:18.12
-9,11,16:18.12
-24,12,16:18.12
-23,12,16:17.12
-22,12,16:17.12
-21,12,16:17.12
-20,12,16:17.12
-19,12,16:17.12
-18,12,16:18.12
-17,12,16:18.12
-16,12,16:18.12
-15,12,16:18.12
-14,12,16:17.12
-13,12,16:17.12
-11,12,16:18.12
-10,12,16:17.12
-9,12,16:18.12
-8,12,16:18.12
-7,12,16:18.12
-6,12,16:18.12
-5,12,16:18.12
-24,13,16:18.12
-23,13,16:18.12
-22,13,16:17.12
-21,13,16:17.12
-20,13,16:18.12
-19,13,16:17.12
-18,13,16:17.12
-17,13,16:17.12
-16,13,16:17.12
-15,13,16:17.12
-14,13,16:18.12
-11,13,16:18.12
-10,13,16:18.12
-9,13,16:17.12
-8,13,16:18.12
-7,13,16:18.12
-6,13,16:18.12
-5,13,16:18.12
-27,14,16:18.12
-26,14,16:18.12
-25,14,16:18.12
-24,14,16:18.12
-23,14,16:18.12
-22,14,16:18.12
-21,14,16:18.12
-20,14,16:17.12
-19,14,16:17.12
-18,14,16:17.12
-17,14,16:17.12
-16,14,16:17.12
-15,14,16:18.12
-14,14,16:18.12
-13,14,16:18.12
-12,14,16:18.12
-11,14,16:18.12
-9,14,16:17.12
-8,14,16:17.12
-7,14,16:18.12
-6,14,16:18.12
-5,14,16:18.12
-4,14,16:18.12
-3,14,16:18.12
-2,14,16:18.12
-1,14,16:18.12
0,14,16:18.12
1,14,16:18.12
2,14,16:18.12
3,14,16:18.12
-29,15,16:18.12
-28,15,16:18.12
-26,15,16:18.12
-24,15,16:18.12
-22,15,16:18.12
-21,15,16:18.12
-19,15,16:18.12
-17,15,16:18.12
-16,15,16:17.12
-15,15,16:17.12
-14,15,16:18.12
-13,15,16:18.12
-12,15,16:18.12
-9,15,16:18.12
-8,15,16:18.12
-7,15,16:18.12
-6,15,16:18.12
-5,15,16:18.12
-4,15,16:18.12
-3,15,16:18.12
-2,15,16:18.12
-1,15,16:18.12
0,15,16:18.12
1,15,16:18.12
2,15,16:18.12
3,15,16:18.12
-28,16,16:18.12
-27,16,16:18.12
-20,16,16:18.12
-19,16,16:18.12
-18,16,16:18.12
-17,16,16:17.12
-16,16,16:17.12
-15,16,16:17.12
-12,16,16:18.12
-11,16,16:18.12
-9,16,16:17.12
-8,16,16:17.12
-7,16,16:18.12
-6,16,16:18.12
-5,16,16:18.12
-4,16,16:18.12
-3,16,16:18.12
-2,16,16:18.12
-1,16,16:18.12
0,16,16:18.12
1,16,16:18.12
2,16,16:18.12
3,16,16:18.12
-29,17,16:18.4
-23,17,16:18.12
-22,17,16:18.12
-21,17,16:18.12
-20,17,16:18.12
-18,17,16:17.12
-17,17,16:17.12
-16,17,16:17.12
-15,17,16:17.12
-14,17,16:17.12
-12,17,16:18.12
-11,17,16:18.12
-10,17,16:17.12
-9,17,16:18.12
-8,17,16:18.12
-7,17,16:18.12
-6,17,16:18.12
-3,17,16:18.12
-2,17,16:18.12
-1,17,16:18.12
0,17,16:18.12
1,17,16:18.12
2,17,16:18.12
3,17,16:18.12
4,17,16:18.12
-26,18,16:18.12
-25,18,16:18.12
-24,18,16:18.12
-23,18,16:18.12
-20,18,16:17.12
-19,18,16:17.12
-18,18,16:17.12
-17,18,16:17.12
-16,18,16:17.12
-15,18,16:18.12
-14,18,16:17.12
-13,18,16:17.12
-12,18,16:17.12
-11,18,16:18.12
-10,18,16:18.12
-9,18,16:18.12
-8,18,16:18.12
-7,18,16:18.12
-6,18,16:18.12
-5,18,16:18.12
-4,18,16:18.12
-3,18,16:18.12
-2,18,16:18.12
-1,18,16:18.12
0,18,16:18.12
2,18,16:18.12
3,18,16:18.12
-20,19,16:17.12
-19,19,16:17.12
-18,19,16:17.12
-17,19,16:17.12
-16,19,16:18.12
-15,19,16:18.12
-14,19,16:17.12
-13,19,16:18.15
-12,19,16:17.12
-11,19,16:18.12
-3,19,16:18.12
-2,19,16:18.12
-21,20,16:18.12
-20,20,16:17.12
-19,20,16:17.12
-18,20,16:18.12
-17,20,16:18.12
-16,20,16:18.12
-15,20,16:18.12
-14,20,16:17.12
-13,20,16:17.12
-12,20,16:18.12
-11,20,16:18.12
-1,20,16:18.12
0,20,16:18.12
-23,21,16:18.12
-22,21,16:18.12
-19,21,16:18.12
-18,21,16:18.12
-17,21,16:18.12
-16,21,16:18.12
-15,21,16:18.12
-14,21,16:17.12
-13,21,16:17.12
-12,21,16:18.12
-11,21,16:18.12
0,21,16:18.12
-24,22,16:18.12
-23,22,16:18.12
-20,22,16:18.12
-19,22,16:18.12
-18,22,16:18.12
-17,22,16:18.12
-16,22,16:18.12
-15,22,16:18.12
-14,22,16:17.12
-13,22,16:18.12
-12,22,16:18.12
-21,23,16:18.12
-20,23,16:18.12
-19,23,16:18.12
-17,23,16:18.12
-16,23,16:18.12
-15,23,16:18.12
-14,23,16:17.12
-13,23,16:18.12
-12,23,16:18.12
-22,24,16:18.12
-21,24,16:18.12
-20,24,16:18.12
-17,24,16:18.12
-16,24,16:18.12
-15,24,16:18.12
-14,24,16:17.12
-13,24,16:18.12
-12,24,16:18.12
-23,25,16:18.12
-22,25,16:18.12
-21,25,16:18.12
-16,25,16:18.12
-15,25,16:18.12
-14,25,16:17.12
-13,25,16:18.12
-12,25,16:18.12
-23,26,16:18.12
-22,26,16:18.12
-16,26,16:18.12
-15,26,16:17.12
-14,26,16:17.12
-13,26,16:18.12
-24,27,16:18.12
-23,27,16:18.12
-22,27,16:18.12
-19,27,16:18.12
-17,27,16:18.12
-16,27,16:18.12
-15,27,16:17.12
-14,27,16:17.12
-13,27,16:18.12
-24,28,16:18.4
-23,28,16:18.4
-20,28,16:18.12
-19,28,16:18.12
-18,28,16:18.12
-17,28,16:18.12
-16,28,16:18.12
-15,28,16:17.12
-12,28,16:18.12
-21,29,16:18.4
-20,29,16:18.12
-19,29,16:18.12
-18,29,16:18.12
-17,29,16:18.12
-16,29,16:18.12
-17,30,16:18.12
-16,30,16:18.12
-17,31,16:18.12
-16,31,16:18.12
-18,32,16:18.12
-17,32,16:18.12
-16,32,16:18.12
-18,33,16:18.12
-17,33,16:18.12
-11,0,17:18.12
-11,1,17:18.12
-11,2,17:18.12
-12,3,17:18.12
-11,3,17:18.12
-13,4,17:18.12
-12,4,17:18.12
-11,4,17:18.12
-10,4,17:18.12
-13,5,17:18.12
-12,5,17:18.12
-11,5,17:18.12
-10,5,17:18.12
-18,6,17:18.12
-17,6,17:18.12
-14,6,17:18.12
-13,6,17:18.12
-12,6,17:18.12
-11,6,17:18.12
-10,6,17:18.12
-9,6,17:18.12
-26,7,17:18.12
-18,7,17:18.12
-17,7,17:18.12
-16,7,17:18.12
-15,7,17:18.12
-14,7,17:18.12
-13,7,17:18.12
-12,7,17:18.12
-11,7,17:17.12
-10,7,17:18.12
-9,7,17:18.12
-1,7,17:18.4
0,7,17:18.4
-30,8,17:18.12
-29,8,17:18.12
-26,8,17:18.12
-25,8,17:18.12
-24,8,17:18.12
-22,8,17:18.12
-18,8,17:18.12
-17,8,17:18.12
-16,8,17:18.12
-15,8,17:18.12
-14,8,17:18.12
-13,8,17:18.12
-12,8,17:17.12
-11,8,17:17.12
-10,8,17:18.12
-9,8,17:18.12
-8,8,17:18.12
-2,8,17:18.4
-1,8,17:18.4
-29,9,17:18.12
-28,9,17:18.12
-26,9,17:18.12
-25,9,17:18.12
-24,9,17:18.12
-23,9,17:18.12
-22,9,17:18.12
-21,9,17:18.12
-20,9,17:18.12
-19,9,17:18.12
-18,9,17:18.12
-17,9,17:18.12
-16,9,17:18.12
-15,9,17:18.12
-13,9,17:17.12
-12,9,17:17.12
-11,9,17:17.12
-10,9,17:18.12
-9,9,17:18.12
-8,9,17:18.12
-7,9,17:18.12
-2,9,17:18.4
-1,9,17:18.4
-28,10,17:18.12
-27,10,17:18.12
-26,10,17:18.12
-25,10,17:18.12
-24,10,17:18.12
-23,10,17:18.12
-22,10,17:18.12
-21,10,17:18.12
-20,10,17:18.12
-19,10,17:18.12
-18,10,17:18.12
-17,10,17:18.12
-16,10,17:18.12
-15,10,17:17.12
-14,10,17:17.12
-13,10,17:17.12
-12,10,17:17.12
-11,10,17:17.12
-10,10,17:17.12
-9,10,17:18.12
-8,10,17:18.12
-7,10,17:18.12
-28,11,17:18.12
-27,11,17:18.12
-25,11,17:18.12
-24,11,17:17.12
-23,11,17:17.12
-22,11,17:18.12
-21,11,17:18.12
-20,11,17:18.12
-19,11,17:18.12
-16,11,17:18.12
-15,11,17:17.12
-14,11,17:17.12
-13,11,17:17.12
-12,11,17:17.12
-11,11,17:17.12
-9,11,17:18.12
-8,11,17:18.12
-7,11,17:18.12
-27,12,17:18.12
-26,12,17:18.12
-25,12,17:18.12
-24,12,17:17.12
-23,12,17:17.12
-22,12,17:18.12
-20,12,17:18.12
-19,12,17:18.12
-18,12,17:18.12
-17,12,17:18.12
-16,12,17:17.12
-15,12,17:17.12
-14,12,17:17.12
-13,12,17:17.12
-12,12,17:17.12
-11,12,17:17.12
-10,12,17:18.12
-9,12,17:18.12
-8,12,17:18.12
-7,12,17:18.12
-6,12,17:18.12
-5,12,17:18.12
-3,12,17:18.12
-2,12,17:18.12
-24,13,17:18.12
-23,13,17:18.12
-22,13,17:18.12
-21,13,17:18.12
-20,13,17:18.12
-17,13,17:18.12
-16,13,17:18.12
-15,13,17:18.12
-14,13,17:17.12
-13,13,17:17.12
-12,13,17:18.12
-11,13,17:18.12
-10,13,17:17.12
-9,13,17:17.12
-6,13,17:18.12
-5,13,17:18.12
-3,13,17:18.12
-28,14,17:18.12
-27,14,17:18.12
-26,14,17:18.12
-25,14,17:18.12
-24,14,17:18.12
-23,14,17:18.12
-22,14,17:18.12
-21,14,17:18.12
-19,14,17:18.12
-15,14,17:17.12
-14,14,17:18.12
-13,14,17:18.12
-12,14,17:18.12
-11,14,17:18.12
-10,14,17:17.12
-9,14,17:17.12
-8,14,17:17.12
-7,14,17:17.12
-6,14,17:18.12
-5,14,17:18.12
-4,14,17:18.12
-3,14,17:18.12
-29,15,17:18.12
-28,15,17:18.12
-26,15,17:18.12
-25,15,17:18.12
-23,15,17:18.12
-22,15,17:18.12
-21,15,17:18.12
-20,15,17:18.12
-19,15,17:18.12
-18,15,17:18.12
-17,15,17:18.12
-16,15,17:18.12
-15,15,17:17.12
-14,15,17:17.12
-13,15,17:18.12
-12,15,17:18.12
-10,15,17:17.12
-9,15,17:17.12
-8,15,17:17.12
-7,15,17:17.12
-6,15,17:18.12
-5,15,17:17.12
-4,15,17:18.12
-3,15,17:18.12
-2,15,17:18.12
-1,15,17:18.12
0,15,17:18.12
1,15,17:18.12
2,15,17:18.12
3,15,17:18.12
4,15,17:18.12
-29,16,17:18.12
-28,16,17:18.12
-27,16,17:18.12
-19,16,17:18.12
-18,16,17:18.12
-17,16,17:18.12
-16,16,17:18.12
-15,16,17:18.12
-14,16,17:17.12
-13,16,17:18.12
-12,16,17:18.12
-11,16,17:18.12
-10,16,17:17.12
-9,16,17:17.12
-8,16,17:17.12
-7,16,17:17.12
-6,16,17:17.12
-5,16,17:17.12
-4,16,17:17.12
-3,16,17:17.12
-2,16,17:17.12
-1,16,17:18.12
0,16,17:18.12
1,16,17:18.12
2,16,17:18.12
3,16,17:18.12
4,16,17:18.12
-30,17,17:18.4
-29,17,17:18.4
-23,17,17:18.12
-22,17,17:18.12
-21,17,17:18.12
-20,17,17:18.12
-17,17,17:18.12
-16,17,17:18.12
-15,17,17:18.12
-14,17,17:17.12
-13,17,17:17.12
-12,17,17:17.12
-11,17,17:17.12
-10,17,17:17.12
-9,17,17:17.12
-8,17,17:18.12
-7,17,17:18.12
-6,17,17:18.12
-4,17,17:18.12
-2,17,17:17.12
-1,17,17:17.12
0,17,17:17.12
2,17,17:18.15
-25,18,17:18.12
-24,18,17:18.12
-23,18,17:18.12
-20,18,17:17.12
-18,18,17:18.12
-17,18,17:18.12
-16,18,17:18.12
-15,18,17:18.12
-14,18,17:17.12
-13,18,17:17.12
-12,18,17:17.12
-11,18,17:17.12
-10,18,17:18.12
-9,18,17:18.12
-8,18,17:18.12
-7,18,17:18.12
-6,18,17:18.12
-5,18,17:18.12
-4,18,17:18.12
-3,18,17:18.12
-20,19,17:17.12
-19,19,17:17.12
-18,19,17:18.12
-17,19,17:18.12
-16,19,17:18.12
-15,19,17:18.12
-14,19,17:17.12
-13,19,17:17.12
-12,19,17:17.12
-11,19,17:17.12
-10,19,17:18.12
-9,19,17:18.12
-8,19,17:18.12
-7,19,17:18.12
-6,19,17:18.12
-5,19,17:18.12
-4,19,17:18.12
-3,19,17:18.12
-2,19,17:18.12
-1,19,17:18.12
-22,20,17:18.12
-21,20,17:18.12
-20,20,17:17.12
-19,20,17:17.12
-18,20,17:18.12
-17,20,17:18.12
-16,20,17:18.12
-15,20,17:17.12
-14,20,17:17.12
-13,20,17:18.12
-12,20,17:18.12
-11,20,17:18.12
-10,20,17:18.12
-6,20,17:18.12
-1,20,17:18.12
0,20,17:18.12
-23,21,17:18.12
-22,21,17:18.12
-18,21,17:18.12
-15,21,17:17.12
-14,21,17:17.12
-13,21,17:17.12
-12,21,17:18.12
-11,21,17:18.12
-10,21,17:18.12
1,21,17:18.12
4,21,17:18.12
-25,22,17:18.12
-24,22,17:18.12
-23,22,17:18.12
-18,22,17:18.12
-17,22,17:18.12
-16,22,17:18.12
-15,22,17:18.12
-14,22,17:17.12
-13,22,17:17.12
-12,22,17:18.12
-11,22,17:18.12
-10,22,17:18.12
5,22,17:18.12
-27,23,17:18.12
-26,23,17:18.12
-19,23,17:18.12
-18,23,17:18.12
-17,23,17:18.12
-16,23,17:18.12
-15,23,17:17.12
-14,23,17:17.12
-13,23,17:18.12
-12,23,17:18.12
-11,23,17:18.12
5,23,17:18.4
6,23,17:18.4
-21,24,17:18.12
-20,24,17:18.12
-19,24,17:18.12
-18,24,17:18.12
-17,24,17:18.12
-16,24,17:18.12
-15,24,17:17.12
-14,24,17:17.12
-13,24,17:18.12
-12,24,17:18.12
-11,24,17:18.12
-10,24,17:18.12
-9,24,17:18.12
7,24,17:18.4
-21,25,17:18.12
-20,25,17:18.12
-19,25,17:18.12
-18,25,17:18.12
-17,25,17:18.12
-16,25,17:18.12
-15,25,17:17.12
-14,25,17:17.12
-13,25,17:18.12
-12,25,17:18.12
-25,26,17:18.12
-22,26,17:18.12
-21,26,17:18.12
-20,26,17:18.12
-19,26,17:18.12
-18,26,17:18.12
-17,26,17:18.12
-16,26,17:18.12
-15,26,17:17.12
-14,26,17:17.12
-13,26,17:18.12
-12,26,17:18.12
-23,27,17:18.12
-22,27,17:18.12
-21,27,17:18.12
-19,27,17:18.12
-18,27,17:18.12
-17,27,17:18.12
-16,27,17:18.12
-23,28,17:18.4
-19,28,17:18.12
-18,28,17:18.12
-17,28,17:18.12
-16,28,17:18.12
-21,29,17:18.4
-20,29,17:18.12
-19,29,17:18.12
-18,29,17:18.12
-17,29,17:18.12
-12,29,17:18.12
-21,30,17:18.4
-20,30,17:18.12
-19,30,17:18.12
-18,30,17:18.12
-17,30,17:18.12
-21,31,17:18.4
-20,31,17:18.12
-19,31,17:18.12
-18,31,17:18.12
-17,31,17:18.12
-19,32,17:18.12
-18,32,17:18.12
-17,32,17:18.12
-19,33,17:18.12
-18,33,17:18.12
-11,-1,18:18.12
-12,0,18:18.12
-11,0,18:18.12
-10,0,18:18.12
-13,1,18:18.12
-12,1,18:18.12
-11,1,18:18.12
-10,1,18:18.12
-14,2,18:18.12
-13,2,18:18.12
-12,2,18:18.12
-11,2,18:18.12
-10,2,18:18.12
-9,2,18:18.12
-15,3,18:18.12
-14,3,18:18.12
-13,3,18:18.12
-12,3,18:18.12
-11,3,18:18.12
-10,3,18:18.12
-9,3,18:18.12
-24,4,18:18.4
-15,4,18:18.12
-14,4,18:18.12
-13,4,18:18.12
-12,4,18:18.12
-11,4,18:17.12
-10,4,18:18.12
-8,4,18:18.12
-19,5,18:18.12
-16,5,18:18.12
-15,5,18:18.12
-14,5,18:18.12
-12,5,18:18.12
-11,5,18:17.12
-10,5,18:17.12
-9,5,18:18.12
-8,5,18:18.12
-20,6,18:18.12
-19,6,18:18.12
-18,6,18:18.12
-17,6,18:18.12
-16,6,18:18.12
-15,6,18:18.12
-14,6,18:18.12
-13,6,18:18.12
-12,6,18:17.12
-11,6,18:17.12
-10,6,18:17.12
-9,6,18:18.12
-8,6,18:18.12
-7,6,18:18.12
-6,6,18:18.12
1,6,18:18.4
-31,7,18:18.12
-30,7,18:18.12
-29,7,18:18.12
-28,7,18:18.12
-26,7,18:18.12
-25,7,18:18.12
-22,7,18:18.12
-21,7,18:18.12
-20,7,18:18.12
-19,7,18:18.12
-18,7,18:18.12
-17,7,18:18.12
-16,7,18:18.12
-15,7,18:18.12
-14,7,18:18.12
-13,7,18:18.12
-12,7,18:17.12
-11,7,18:17.12
-10,7,18:17.12
-9,7,18:18.12
-8,7,18:18.12
-7,7,18:18.12
-6,7,18:18.12
0,7,18:18.4
1,7,18:18.4
2,7,18:18.4
-31,8,18:18.12
-30,8,18:18.12
-29,8,18:18.12
-28,8,18:18.12
-27,8,18:18.12
-26,8,18:18.12
-25,8,18:18.12
-24,8,18:18.12
-23,8,18:18.12
-21,8,18:18.12
-20,8,18:18.12
-19,8,18:18.12
-18,8,18:18.12
-16,8,18:18.12
-12,8,18:18.12
-11,8,18:17.12
-10,8,18:17.12
-8,8,18:18.12
-7,8,18:18.12
0,8,18:18.4
1,8,18:18.4
-31,9,18:18.12
-30,9,18:18.12
-29,9,18:18.12
-26,9,18:18.12
-25,9,18:18.12
-24,9,18:18.12
-23,9,18:18.12
-22,9,18:18.12
-21,9,18:18.12
-20,9,18:18.12
-19,9,18:18.12
-18,9,18:18.12
-17,9,18:18.12
-16,9,18:18.12
-15,9,18:17.12
-8,9,18:18.12
-7,9,18:18.12
-6,9,18:18.12
-1,9,18:18.4
0,9,18:18.4
1,9,18:18.4
-31,10,18:18.12
-30,10,18:18.12
-29,10,18:18.12
-28,10,18:17.12
-27,10,18:17.12
-24,10,18:18.12
-23,10,18:18.12
-22,10,18:18.12
-21,10,18:18.12
-20,10,18:18.12
-18,10,18:18.12
-17,10,18:18.12
-16,10,18:17.12
-15,10,18:17.12
-14,10,18:17.12
-8,10,18:18.12
-7,10,18:18.12
-6,10,18:18.12
-5,10,18:18.12
-4,10,18:18.12
-3,10,18:18.12
-1,10,18:18.4
0,10,18:18.4
-31,11,18:18.12
-30,11,18:18.12
-29,11,18:18.12
-28,11,18:17.12
-27,11,18:17.12
-26,11,18:17.12
-25,11,18:17.12
-24,11,18:18.12
-23,11,18:18.12
-21,11,18:18.12
-19,11,18:18.12
-17,11,18:17.12
-16,11,18:17.12
-15,11,18:18.12
-14,11,18:17.12
-11,11,18:18.12
-10,11,18:18.12
-9,11,18:18.12
-8,11,18:18.12
-7,11,18:18.12
-6,11,18:18.12
-5,11,18:18.12
-4,11,18:18.12
-3,11,18:18.12
-2,11,18:18.12
-1,11,18:18.12
0,11,18:18.4
-30,12,18:18.12
-29,12,18:18.12
-28,12,18:18.12
-27,12,18:17.12
-26,12,18:17.12
-25,12,18:17.12
-24,12,18:17.12
-23,12,18:18.12
-21,12,18:18.12
-18,12,18:18.12
-17,12,18:18.12
-16,12,18:18.12
-15,12,18:17.12
-14,12,18:17.12
-13,12,18:17.12
-12,12,18:18.12
-11,12,18:18.12
-9,12,18:18.12
-8,12,18:18.12
-5,12,18:18.12
-4,12,18:18.12
-2,12,18:18.12
-1,12,18:18.12
-33,13,18:18.12
-32,13,18:18.12
-29,13,18:18.12
-28,13,18:18.12
-26,13,18:18.12
-25,13,18:18.12
-24,13,18:18.12
-23,13,18:18.12
-22,13,18:18.12
-17,13,18:18.12
-16,13,18:18.12
-15,13,18:18.12
-14,13,18:18.12
-13,13,18:18.12
-12,13,18:17.12
-11,13,18:17.12
-10,13,18:18.12
-5,13,18:18.12
-4,13,18:18.12
-3,13,18:18.12
-2,13,18:18.12
-1,13,18:18.12
0,13,18:18.12
1,13,18:18.12
2,13,18:18.12
-33,14,18:18.12
-28,14,18:18.12
-27,14,18:18.12
-26,14,18:18.12
-25,14,18:18.12
-24,14,18:18.12
-23,14,18:18.12
-22,14,18:18.12
-15,14,18:18.12
-14,14,18:18.12
-13,14,18:17.12
-12,14,18:17.12
-11,14,18:17.12
-10,14,18:17.12
-4,14,18:18.12
-3,14,18:18.12
-2,14,18:18.12
-1,14,18:18.12
0,14,18:18.12
1,14,18:18.12
2,14,18:18.12
3,14,18:18.12
4,14,18:18.12
5,14,18:18.12
6,14,18:18.12
7,14,18:18.12
-26,15,18:18.12
-25,15,18:18.12
-24,15,18:18.12
-23,15,18:18.12
-22,15,18:18.12
-21,15,18:18.12
-14,15,18:18.12
-13,15,18:17.12
-12,15,18:17.12
-11,15,18:17.12
-10,15,18:17.12
-7,15,18:18.12
-6,15,18:18.12
-5,15,18:18.12
-4,15,18:18.12
-3,15,18:18.12
-2,15,18:18.12
-1,15,18:18.12
0,15,18:18.12
1,15,18:18.12
2,15,18:18.12
3,15,18:18.12
4,15,18:18.12
5,15,18:18.12
6,15,18:18.12
-29,16,18:18.12
-28,16,18:18.12
-27,16,18:18.12
-26,16,18:18.12
-22,16,18:18.12
-21,16,18:18.12
-20,16,18:18.12
-19,16,18:18.12
-18,16,18:18.12
-17,16,18:18.12
-16,16,18:18.12
-15,16,18:18.12
-13,16,18:17.12
-12,16,18:17.12
-11,16,18:17.12
-4,16,18:17.12
-3,16,18:17.12
-2,16,18:17.12
-1,16,18:18.12
0,16,18:17.12
1,16,18:18.12
2,16,18:18.12
3,16,18:18.12
-31,17,18:18.4
-30,17,18:18.4
-29,17,18:18.4
-25,17,18:18.12
-22,17,18:18.12
-21,17,18:18.12
-20,17,18:18.12
-19,17,18:18.12
-18,17,18:18.12
-14,17,18:18.12
-13,17,18:18.12
-12,17,18:17.12
-11,17,18:17.12
-10,17,18:17.12
-9,17,18:17.12
-8,17,18:18.12
-7,17,18:18.12
-6,17,18:18.12
-4,17,18:18.12
-3,17,18:18.12
-2,17,18:17.12
-1,17,18:18.12
0,17,18:17.12
1,17,18:17.12
2,17,18:18.15
-24,18,18:18.12
-23,18,18:18.12
-19,18,18:18.12
-18,18,18:18.12
-15,18,18:18.12
-13,18,18:18.12
-11,18,18:17.12
-10,18,18:18.12
-9,18,18:17.12
-8,18,18:17.12
-7,18,18:18.12
-6,18,18:18.12
-5,18,18:18.12
-4,18,18:18.12
-3,18,18:18.12
-2,18,18:18.12
-1,18,18:18.12
0,18,18:18.12
-29,19,18:18.12
-28,19,18:18.12
-27,19,18:18.12
-22,19,18:18.12
-21,19,18:17.12
-20,19,18:18.12
-19,19,18:18.12
-18,19,18:18.12
-16,19,18:18.12
-11,19,18:17.12
-10,19,18:17.12
-9,19,18:18.12
-8,19,18:18.12
-7,19,18:18.12
-6,19,18:18.12
-5,19,18:18.12
-4,19,18:18.12
-3,19,18:18.12
-2,19,18:18.12
-1,19,18:18.12
4,19,18:18.12
-27,20,18:18.12
-26,20,18:18.12
-25,20,18:18.12
-24,20,18:18.12
-23,20,18:18.12
-22,20,18:18.12
-21,20,18:17.12
-20,20,18:17.12
-19,20,18:18.12
-16,20,18:18.12
-10,20,18:17.12
-9,20,18:18.12
-8,20,18:18.12
-7,20,18:18.12
-6,20,18:18.12
-5,20,18:18.12
-4,20,18:18.12
-3,20,18:18.12
-2,20,18:18.12
-1,20,18:18.12
4,20,18:18.12
5,20,18:18.12
-23,21,18:18.12
-22,21,18:18.12
-21,21,18:18.12
-20,21,18:18.12
-19,21,18:17.12
-18,21,18:18.12
-14,21,18:18.12
-13,21,18:18.12
-10,21,18:18.12
-9,21,18:18.12
-8,21,18:18.12
-7,21,18:18.12
-4,21,18:18.12
-2,21,18:18.12
-1,21,18:18.12
4,21,18:18.12
5,21,18:18.12
6,21,18:18.12
-24,22,18:18.12
-23,22,18:18.12
-22,22,18:18.12
-21,22,18:18.12
-20,22,18:18.12
-19,22,18:18.12
-18,22,18:18.12
-15,22,18:18.12
-14,22,18:18.12
-13,22,18:18.12
-12,22,18:18.12
-10,22,18:18.12
-9,22,18:18.12
-8,22,18:18.12
5,22,18:18.12
6,22,18:18.12
7,22,18:18.12
-26,23,18:18.12
-25,23,18:18.12
-24,23,18:18.12
-23,23,18:18.12
-20,23,18:18.12
-19,23,18:18.12
-16,23,18:18.12
-15,23,18:18.12
-14,23,18:18.12
-13,23,18:18.12
-12,23,18:18.12
-11,23,18:18.12
-10,23,18:18.12
-9,23,18:18.12
-8,23,18:18.12
6,23,18:18.12
7,23,18:18.12
8,23,18:18.12
-27,24,18:18.12
-26,24,18:18.12
-25,24,18:18.12
-24,24,18:18.12
-20,24,18:18.12
-19,24,18:18.12
-17,24,18:18.12
-16,24,18:18.12
-13,24,18:18.12
-12,24,18:18.12
-11,24,18:18.12
-10,24,18:18.12
-9,24,18:18.12
-8,24,18:18.12
7,24,18:18.4
8,24,18:18.4
9,24,18:18.4
-28,25,18:18.12
-27,25,18:18.12
-26,25,18:18.12
-25,25,18:18.12
-20,25,18:18.12
-18,25,18:18.12
-17,25,18:18.12
-15,25,18:17.12
-14,25,18:17.12
-13,25,18:18.12
-12,25,18:18.12
-11,25,18:18.12
-10,25,18:18.12
-9,25,18:18.12
-8,25,18:18.12
-28,26,18:18.12
-27,26,18:18.12
-26,26,18:18.12
-25,26,18:18.12
-20,26,18:18.12
-19,26,18:18.12
-18,26,18:18.12
-17,26,18:18.12
-15,26,18:17.12
-14,26,18:18.12
-13,26,18:18.12
-12,26,18:18.12
-8,26,18:18.12
-7,26,18:18.12
-21,27,18:18.12
-20,27,18:18.12
-19,27,18:18.12
-18,27,18:18.12
-15,27,18:18.12
-14,27,18:18.12
-13,27,18:18.12
-21,28,18:18.4
-20,28,18:18.12
-19,28,18:18.12
-18,28,18:18.12
-17,28,18:18.12
-16,28,18:18.12
-15,28,18:18.12
-14,28,18:18.12
-13,28,18:18.12
-21,29,18:18.4
-20,29,18:18.12
-19,29,18:18.12
-18,29,18:18.12
-17,29,18:18.12
-16,29,18:18.12
-15,29,18:18.12
-14,29,18:18.12
-13,29,18:18.12
-22,30,18:18.4
-21,30,18:18.4
-20,30,18:18.12
-19,30,18:18.12
-18,30,18:18.12
-17,30,18:18.12
-16,30,18:18.12
-14,30,18:18.12
-13,30,18:18.12
-12,30,18:18.12
-22,31,18:18.4
-21,31,18:18.4
-20,31,18:18.12
-19,31,18:18.12
-18,31,18:18.12
-17,31,18:18.12
-16,31,18:18.12
-13,31,18:18.12
-12,31,18:18.12
-20,32,18:18.12
-19,32,18:18.12
-18,32,18:18.12
-17,32,18:18.12
-13,32,18:18.12
-12,32,18:18.12
-18,33,18:18.12
-17,33,18:18.12
-12,33,18:18.12
-18,34,18:18.12
-13,-1,19:18.12
-12,-1,19:18.12
-10,-1,19:18.12
-15,0,19:18.12
-14,0,19:18.12
-13,0,19:18.12
-10,0,19:18.12
-9,0,19:18.12
-8,0,19:18.12
-15,1,19:18.12
-14,1,19:18.12
-13,1,19:18.12
-12,1,19:18.12
-11,1,19:18.12
-10,1,19:18.12
-9,1,19:18.12
-8,1,19:18.12
-27,2,19:18.4
-26,2,19:18.4
-16,2,19:18.12
-15,2,19:18.12
-14,2,19:18.12
-12,2,19:18.12
-11,2,19:18.12
-10,2,19:17.12
-9,2,19:18.12
-8,2,19:18.12
-7,2,19:18.12
-26,3,19:18.4
-25,3,19:18.12
-17,3,19:18.12
-16,3,19:18.12
-15,3,19:18.12
-13,3,19:18.12
-12,3,19:18.12
-11,3,19:17.12
-10,3,19:17.12
-9,3,19:18.12
-8,3,19:18.12
-7,3,19:18.12
-25,4,19:18.12
-24,4,19:18.12
-17,4,19:18.12
-16,4,19:18.12
-13,4,19:18.12
-12,4,19:18.12
-11,4,19:17.12
-10,4,19:18.12
-8,4,19:18.12
-7,4,19:18.12
-6,4,19:18.12
-23,5,19:18.12
-20,5,19:18.12
-19,5,19:18.12
-18,5,19:18.12
-17,5,19:18.12
-16,5,19:18.12
-15,5,19:18.12
-14,5,19:18.12
-13,5,19:18.12
-12,5,19:18.12
-11,5,19:17.12
-10,5,19:18.12
-7,5,19:18.12
-6,5,19:18.12
-5,5,19:18.4
-4,5,19:18.4
-31,6,19:18.12
-30,6,19:18.12
-29,6,19:18.12
-28,6,19:18.12
-21,6,19:18.12
-18,6,19:18.12
-17,6,19:18.12
-16,6,19:18.12
-15,6,19:18.12
-14,6,19:18.12
-13,6,19:18.12
-12,6,19:17.12
-11,6,19:17.12
-10,6,19:17.12
-7,6,19:18.12
-6,6,19:18.12
-5,6,19:18.12
-4,6,19:18.12
3,6,19:18.4
4,6,19:18.4
-31,7,19:18.12
-30,7,19:18.12
-29,7,19:18.12
-28,7,19:18.12
-27,7,19:18.12
-26,7,19:18.12
-25,7,19:18.12
-24,7,19:18.12
-23,7,19:18.12
-22,7,19:18.12
-21,7,19:18.12
-20,7,19:18.12
-13,7,19:18.12
-6,7,19:18.12
-5,7,19:18.12
-4,7,19:18.12
2,7,19:18.4
3,7,19:18.4
4,7,19:18.4
-24,8,19:18.12
-23,8,19:18.12
-22,8,19:18.12
-21,8,19:18.12
-20,8,19:18.12
-19,8,19:18.12
-17,8,19:17.12
-16,8,19:17.12
-12,8,19:18.12
-6,8,19:18.12
-5,8,19:18.12
-4,8,19:18.12
-3,8,19:18.12
2,8,19:18.4
3,8,19:18.4
-23,9,19:18.12
-19,9,19:18.12
-18,9,19:18.12
-17,9,19:17.12
-16,9,19:17.12
-7,9,19:18.12
-6,9,19:18.12
-5,9,19:18.12
-4,9,19:18.12
-3,9,19:18.12
-2,9,19:18.4
1,9,19:18.4
2,9,19:18.4
3,9,19:18.4
-32,10,19:18.12
-31,10,19:18.12
-30,10,19:18.12
-29,10,19:17.12
-28,10,19:17.12
-27,10,19:18.12
-26,10,19:18.12
-25,10,19:18.12
-23,10,19:18.12
-22,10,19:18.12
-18,10,19:18.12
-17,10,19:17.12
-16,10,19:17.12
-15,10,19:17.12
-11,10,19:18.12
-10,10,19:18.12
-8,10,19:18.12
-7,10,19:18.12
-6,10,19:18.12
-5,10,19:18.12
-4,10,19:18.12
-3,10,19:18.12
1,10,19:18.4
2,10,19:18.4
-31,11,19:18.12
-30,11,19:18.12
-29,11,19:18.12
-28,11,19:17.12
-27,11,19:18.12
-25,11,19:18.12
-24,11,19:18.12
-23,11,19:18.12
-22,11,19:18.12
-16,11,19:17.12
-15,11,19:17.12
-14,11,19:17.12
-13,11,19:18.12
-12,11,19:18.12
-11,11,19:18.12
-10,11,19:18.12
-8,11,19:18.12
-7,11,19:18.12
-6,11,19:18.12
-5,11,19:18.12
-4,11,19:18.12
-3,11,19:18.12
-2,11,19:18.12
0,11,19:18.4
1,11,19:18.4
2,11,19:18.4
-31,12,19:18.12
-30,12,19:18.12
-29,12,19:18.12
-28,12,19:18.12
-27,12,19:18.12
-26,12,19:18.12
-25,12,19:18.12
-24,12,19:18.12
-23,12,19:18.12
-21,12,19:18.12
-18,12,19:18.12
-17,12,19:18.12
-15,12,19:18.12
-14,12,19:18.12
-13,12,19:18.12
-12,12,19:18.12
-9,12,19:18.12
-8,12,19:18.12
-3,12,19:18.12
-2,12,19:18.12
0,12,19:18.12
1,12,19:18.12
2,12,19:18.12
3,12,19:18.12
4,12,19:18.12
5,12,19:18.4
6,12,19:18.4
7,12,19:18.4
8,12,19:18.4
-34,13,19:18.12
-33,13,19:18.12
-32,13,19:18.12
-29,13,19:18.12
-28,13,19:18.12
-27,13,19:18.12
-26,13,19:18.12
-25,13,19:18.12
-24,13,19:18.12
-16,13,19:18.12
-15,13,19:18.12
-14,13,19:18.12
-12,13,19:17.12
-10,13,19:18.12
-3,13,19:18.12
-2,13,19:18.12
-1,13,19:18.12
0,13,19:18.12
1,13,19:18.12
2,13,19:18.12
3,13,19:18.12
4,13,19:18.12
5,13,19:18.12
6,13,19:18.12
7,13,19:18.12
-34,14,19:18.12
-33,14,19:18.12
-29,14,19:18.12
-28,14,19:18.12
-27,14,19:18.12
-26,14,19:18.12
-25,14,19:18.12
-15,14,19:18.12
-14,14,19:17.12
-13,14,19:17.12
-12,14,19:17.12
-11,14,19:17.12
-3,14,19:18.12
-2,14,19:18.12
-1,14,19:18.12
1,14,19:18.12
-29,15,19:18.12
-28,15,19:18.12
-27,15,19:18.12
-26,15,19:18.12
-25,15,19:18.12
-24,15,19:18.12
-23,15,19:18.12
-15,15,19:18.12
-14,15,19:17.12
-13,15,19:17.12
-12,15,19:17.12
-11,15,19:17.12
-5,15,19:18.12
-4,15,19:18.12
-3,15,19:18.12
-2,15,19:18.12
-1,15,19:18.12
0,15,19:18.12
1,15,19:18.12
2,15,19:18.12
-29,16,19:18.12
-28,16,19:18.12
-27,16,19:18.12
-26,16,19:18.12
-25,16,19:18.12
-24,16,19:18.12
-23,16,19:18.12
-22,16,19:18.12
-21,16,19:18.12
-18,16,19:18.12
-17,16,19:18.12
-16,16,19:18.12
-15,16,19:18.12
-12,16,19:17.12
-9,16,19:18.12
-8,16,19:18.12
-7,16,19:18.12
-6,16,19:18.12
-5,16,19:18.12
-4,16,19:18.12
-3,16,19:18.12
-2,16,19:17.12
-1,16,19:18.12
0,16,19:18.12
1,16,19:18.12
2,16,19:18.12
3,16,19:18.12
4,16,19:18.12
8,16,19:18.12
9,16,19:18.12
-31,17,19:18.4
-30,17,19:18.4
-29,17,19:18.4
-28,17,19:18.4
-27,17,19:18.4
-26,17,19:18.12
-25,17,19:18.12
-23,17,19:18.12
-22,17,19:18.12
-21,17,19:18.12
-20,17,19:18.12
-19,17,19:18.12
-18,17,19:18.12
-14,17,19:18.12
-11,17,19:18.12
-8,17,19:18.12
-7,17,19:18.12
-6,17,19:18.12
-4,17,19:18.12
-3,17,19:18.12
-2,17,19:18.12
-1,17,19:18.12
0,17,19:18.12
1,17,19:17.12
2,17,19:17.12
3,17,19:17.12
4,17,19:17.12
5,17,19:17.12
6,17,19:18.12
7,17,19:18.12
8,17,19:18.12
9,17,19:18.12
10,17,19:18.12
-26,18,19:18.12
-25,18,19:18.12
-24,18,19:18.12
-23,18,19:18.12
-21,18,19:18.12
-14,18,19:18.12
-11,18,19:18.12
-10,18,19:17.12
-9,18,19:17.12
-2,18,19:18.12
-1,18,19:18.12
0,18,19:18.12
2,18,19:18.12
3,18,19:18.12
4,18,19:18.12
5,18,19:17.12
6,18,19:18.12
7,18,19:18.12
8,18,19:18.12
10,18,19:18.12
-25,19,19:18.12
-24,19,19:18.12
-23,19,19:18.12
-22,19,19:18.12
-21,19,19:18.12
-10,19,19:17.12
-9,19,19:17.12
-8,19,19:17.12
-7,19,19:17.12
-3,19,19:18.12
-2,19,19:18.12
-1,19,19:18.12
0,19,19:18.12
1,19,19:18.12
4,19,19:18.12
5,19,19:18.12
6,19,19:18.12
-30,20,19:18.4
-29,20,19:18.12
-28,20,19:18.12
-27,20,19:18.12
-26,20,19:18.12
-24,20,19:18.12
-23,20,19:18.12
-22,20,19:18.12
-21,20,19:17.12
-20,20,19:17.12
-10,20,19:17.12
-9,20,19:17.12
-8,20,19:17.12
-7,20,19:18.12
-6,20,19:18.12
-5,20,19:18.12
-4,20,19:18.12
-3,20,19:18.12
-2,20,19:18.12
-1,20,19:18.12
0,20,19:18.12
5,20,19:18.12
6,20,19:18.12
7,20,19:18.12
-31,21,19:18.4
-30,21,19:18.4
-29,21,19:18.12
-28,21,19:18.12
-27,21,19:18.12
-26,21,19:18.12
-25,21,19:18.12
-24,21,19:18.12
-23,21,19:18.12
-22,21,19:17.12
-21,21,19:17.12
-20,21,19:17.12
-19,21,19:18.12
-18,21,19:18.12
-9,21,19:17.12
-8,21,19:18.12
-7,21,19:18.12
-6,21,19:18.12
-5,21,19:18.12
-4,21,19:18.12
-1,21,19:18.12
0,21,19:18.12
6,21,19:18.12
7,21,19:18.12
8,21,19:18.12
-27,22,19:18.12
-26,22,19:18.12
-25,22,19:18.12
-24,22,19:18.12
-23,22,19:17.12
-22,22,19:17.12
-21,22,19:18.12
-19,22,19:18.12
-7,22,19:18.12
-6,22,19:18.12
-5,22,19:18.12
-4,22,19:18.12
-3,22,19:18.12
-2,22,19:18.4
-1,22,19:18.4
0,22,19:18.4
7,22,19:18.12
8,22,19:18.12
9,22,19:18.12
-27,23,19:18.12
-26,23,19:18.12
-25,23,19:18.12
-24,23,19:17.12
-23,23,19:18.12
-22,23,19:18.12
-21,23,19:18.12
-19,23,19:18.12
-16,23,19:18.12
-13,23,19:18.12
-12,23,19:18.12
-7,23,19:18.12
-6,23,19:18.12
-3,23,19:18.12
-2,23,19:18.4
-1,23,19:18.4
0,23,19:18.4
8,23,19:18.12
9,23,19:18.12
10,23,19:18.12
-28,24,19:18.12
-27,24,19:18.12
-26,24,19:18.12
-25,24,19:18.12
-24,24,19:18.12
-23,24,19:18.12
-22,24,19:18.12
-21,24,19:18.12
-20,24,19:18.12
-16,24,19:18.12
-12,24,19:18.12
-7,24,19:18.12
-6,24,19:18.12
9,24,19:18.4
10,24,19:18.4
-29,25,19:18.12
-28,25,19:18.12
-27,25,19:18.12
-26,25,19:18.12
-25,25,19:18.12
-24,25,19:18.12
-22,25,19:18.12
-21,25,19:18.12
-20,25,19:18.12
-17,25,19:18.12
-12,25,19:18.12
-11,25,19:18.12
-10,25,19:18.12
-8,25,19:18.12
-7,25,19:18.12
-6,25,19:18.12
-30,26,19:18.4
-29,26,19:18.12
-28,26,19:18.12
-27,26,19:18.12
-21,26,19:18.12
-20,26,19:18.12
-18,26,19:18.12
-17,26,19:18.12
-16,26,19:17.12
-15,26,19:17.12
-14,26,19:17.12
-12,26,19:18.12
-11,26,19:18.12
-10,26,19:18.12
-9,26,19:18.12
-8,26,19:18.12
-7,26,19:18.12
-6,26,19:18.12
-21,27,19:18.12
-20,27,19:18.12
-19,27,19:18.12
-18,27,19:18.12
-15,27,19:17.12
-11,27,19:18.12
-9,27,19:18.4
-8,27,19:18.4
-7,27,19:18.4
-21,28,19:18.12
-20,28,19:18.12
-19,28,19:18.12
-18,28,19:18.12
-17,28,19:18.12
-15,28,19:18.12
-13,28,19:18.12
-12,28,19:18.12
-7,28,19:18.4
-22,29,19:18.4
-21,29,19:18.12
-20,29,19:18.12
-19,29,19:18.12
-18,29,19:18.12
-17,29,19:18.12
-15,29,19:18.12
-13,29,19:18.12
-12,29,19:18.12
-7,29,19:18.4
-21,30,19:18.12
-20,30,19:18.12
-19,30,19:18.12
-18,30,19:18.12
-15,30,19:18.12
-14,30,19:18.12
-13,30,19:18.12
-12,30,19:18.12
-22,31,19:18.4
-21,31,19:18.12
-20,31,19:18.12
-19,31,19:18.12
-16,31,19:18.12
-15,31,19:18.12
-14,31,19:18.12
-20,32,19:18.12
-17,32,19:18.12
-16,32,19:18.12
-15,32,19:18.12
-14,32,19:18.12
-13,32,19:18.12
-18,33,19:18.12
-17,33,19:18.12
-16,33,19:18.12
-14,33,19:18.12
-13,33,19:18.12
-18,34,19:18.12
-17,34,19:18.12
-14,34,19:18.12
-13,34,19:18.12
-17,35,19:18.12
-9,-4,20:18.12
-10,-3,20:18.12
-9,-3,20:18.12
-11,-2,20:18.12
-10,-2,20:18.12
-9,-2,20:18.12
-8,-2,20:18.12
-6,-2,20:18.12
-11,-1,20:18.12
-10,-1,20:18.12
-8,-1,20:18.12
-7,-1,20:18.12
-13,0,20:18.12
-12,0,20:18.12
-11,0,20:18.12
-10,0,20:17.12
-9,0,20:18.12
-8,0,20:18.12
-28,1,20:18.4
-18,1,20:18.12
-16,1,20:18.12
-13,1,20:18.12
-12,1,20:18.12
-11,1,20:18.12
-10,1,20:17.12
-9,1,20:18.12
-8,1,20:18.12
-27,2,20:18.4
-26,2,20:18.4
-18,2,20:18.12
-17,2,20:18.12
-16,2,20:18.12
-15,2,20:18.12
-14,2,20:18.12
-13,2,20:18.12
-12,2,20:18.12
-11,2,20:17.12
-10,2,20:17.12
-9,2,20:18.12
-8,2,20:18.12
-26,3,20:18.4
-25,3,20:18.12
-16,3,20:18.12
-15,3,20:18.12
-14,3,20:18.12
-13,3,20:18.12
-12,3,20:18.12
-11,3,20:18.12
-10,3,20:17.12
-9,3,20:18.12
-8,3,20:18.12
-7,3,20:18.12
-6,3,20:18.12
-5,3,20:18.12
-4,3,20:18.4
-3,3,20:18.4
-24,4,20:18.12
-20,4,20:18.12
-19,4,20:18.12
-18,4,20:18.12
-17,4,20:18.12
-16,4,20:18.12
-15,4,20:18.12
-14,4,20:18.12
-13,4,20:18.12
-12,4,20:18.12
-10,4,20:18.12
-7,4,20:18.12
-6,4,20:18.12
-5,4,20:18.4
-4,4,20:18.4
-23,5,20:18.12
-22,5,20:18.12
-18,5,20:18.12
-17,5,20:18.12
-16,5,20:18.12
-15,5,20:18.12
-14,5,20:18.12
-11,5,20:17.12
-23,6,20:18.12
-22,6,20:18.12
-21,6,20:18.12
-14,6,20:18.12
-13,6,20:18.12
-11,6,20:17.12
-4,6,20:18.12
-3,6,20:18.12
-25,7,20:18.12
-24,7,20:18.12
-21,7,20:18.12
-20,7,20:18.12
-13,7,20:18.12
-8,7,20:18.12
-7,7,20:18.12
-4,7,20:18.12
-3,7,20:18.12
-2,7,20:18.12
4,7,20:18.4
5,7,20:18.4
-24,8,20:18.12
-20,8,20:18.12
-19,8,20:18.12
-17,8,20:17.12
-12,8,20:18.12
-9,8,20:18.12
-8,8,20:18.12
-7,8,20:18.12
-5,8,20:18.12
-4,8,20:18.12
-3,8,20:18.12
-2,8,20:18.12
4,8,20:18.4
-24,9,20:18.12
-23,9,20:18.12
-22,9,20:18.12
-19,9,20:18.12
-18,9,20:17.12
-17,9,20:17.12
-16,9,20:17.12
-12,9,20:18.12
-9,9,20:18.12
-8,9,20:18.12
-6,9,20:18.12
-5,9,20:18.12
3,9,20:18.4
4,9,20:18.4
5,9,20:18.4
-32,10,20:18.12
-31,10,20:18.12
-30,10,20:17.12
-29,10,20:17.12
-27,10,20:18.12
-26,10,20:18.12
-23,10,20:18.12
-18,10,20:18.12
-17,10,20:17.12
-16,10,20:17.12
-12,10,20:18.12
-11,10,20:18.12
-9,10,20:18.12
-7,10,20:18.12
3,10,20:18.4
4,10,20:18.4
5,10,20:18.4
6,10,20:18.4
7,10,20:18.4
-32,11,20:18.12
-31,11,20:18.12
-30,11,20:17.12
-29,11,20:17.12
-28,11,20:18.12
-27,11,20:18.12
-25,11,20:18.12
-24,11,20:18.12
-23,11,20:18.12
-22,11,20:18.12
-14,11,20:18.12
-13,11,20:18.12
-12,11,20:18.12
-9,11,20:18.12
-5,11,20:18.12
-4,11,20:18.12
-3,11,20:18.12
-1,11,20:18.12
2,11,20:18.4
3,11,20:18.4
4,11,20:18.4
5,11,20:18.4
6,11,20:18.4
7,11,20:18.4
8,11,20:18.4
-33,12,20:18.12
-32,12,20:18.12
-31,12,20:18.12
-30,12,20:18.12
-29,12,20:18.12
-28,12,20:18.12
-27,12,20:18.12
-26,12,20:18.12
-24,12,20:18.12
-18,12,20:18.12
-17,12,20:18.12
-16,12,20:18.12
-15,12,20:18.12
-14,12,20:18.12
-9,12,20:18.12
-8,12,20:18.12
-7,12,20:18.12
-6,12,20:18.12
-5,12,20:18.12
-4,12,20:18.12
-3,12,20:18.12
-2,12,20:18.12
-1,12,20:18.12
0,12,20:18.12
1,12,20:18.12
2,12,20:18.12
3,12,20:18.12
7,12,20:18.4
8,12,20:18.4
-34,13,20:18.12
-33,13,20:18.12
-32,13,20:18.12
-29,13,20:18.12
-27,13,20:18.12
-26,13,20:18.12
-24,13,20:18.12
-23,13,20:18.12
-16,13,20:18.12
-12,13,20:17.12
-11,13,20:17.12
-10,13,20:17.12
-9,13,20:18.12
-8,13,20:18.12
-7,13,20:18.12
-6,13,20:18.12
-5,13,20:18.12
-4,13,20:18.12
-3,13,20:18.12
-2,13,20:18.12
-1,13,20:18.12
0,13,20:18.12
2,13,20:18.12
3,13,20:18.12
-36,14,20:18.4
-35,14,20:18.12
-34,14,20:18.12
-28,14,20:18.12
-27,14,20:18.12
-23,14,20:18.12
-16,14,20:18.12
-14,14,20:17.12
-13,14,20:17.12
-12,14,20:17.12
-11,14,20:17.12
-10,14,20:18.12
-9,14,20:18.12
-8,14,20:18.12
-7,14,20:18.12
-6,14,20:18.12
-5,14,20:18.12
-4,14,20:18.12
-3,14,20:18.12
-2,14,20:18.12
-1,14,20:18.12
0,14,20:18.12
2,14,20:18.12
3,14,20:18.12
-29,15,20:18.12
-28,15,20:18.12
-27,15,20:18.12
-16,15,20:18.12
-15,15,20:18.12
-14,15,20:17.12
-13,15,20:17.12
-12,15,20:17.12
-11,15,20:18.12
-10,15,20:18.12
-9,15,20:18.12
-8,15,20:18.12
-7,15,20:18.12
-6,15,20:18.12
-5,15,20:18.12
-4,15,20:18.12
-3,15,20:18.12
-2,15,20:18.12
-1,15,20:18.12
0,15,20:18.12
1,15,20:18.12
2,15,20:18.12
3,15,20:18.12
4,15,20:18.12
5,15,20:18.12
-29,16,20:18.12
-28,16,20:18.12
-27,16,20:18.12
-26,16,20:18.12
-25,16,20:18.12
-18,16,20:18.12
-17,16,20:18.12
-16,16,20:18.12
-15,16,20:18.12
-12,16,20:17.12
-5,16,20:18.12
-4,16,20:18.12
-3,16,20:18.12
-2,16,20:17.12
-1,16,20:18.12
0,16,20:18.12
1,16,20:18.12
4,16,20:18.12
5,16,20:18.12
6,16,20:18.12
7,16,20:18.12
8,16,20:18.12
-30,17,20:18.4
-29,17,20:18.4
-28,17,20:18.4
-27,17,20:18.4
-26,17,20:18.12
-25,17,20:18.12
-23,17,20:18.12
-22,17,20:18.12
-21,17,20:18.12
-20,17,20:18.12
-19,17,20:18.12
-18,17,20:18.12
-15,17,20:18.12
-2,17,20:17.12
0,17,20:18.12
1,17,20:18.12
3,17,20:18.12
6,17,20:17.12
7,17,20:18.12
8,17,20:18.12
-28,18,20:18.12
-27,18,20:18.12
-26,18,20:18.12
-24,18,20:18.12
-23,18,20:18.12
-22,18,20:18.12
-21,18,20:18.12
-11,18,20:18.12
-10,18,20:18.12
0,18,20:18.12
3,18,20:18.12
4,18,20:18.12
6,18,20:17.12
7,18,20:17.12
10,18,20:18.12
11,18,20:18.12
12,18,20:18.12
-27,19,20:18.12
-26,19,20:18.12
-25,19,20:18.12
-11,19,20:18.12
-10,19,20:18.12
-9,19,20:17.12
-8,19,20:17.12
1,19,20:18.12
2,19,20:18.12
3,19,20:18.12
4,19,20:18.12
5,19,20:18.12
6,19,20:18.12
7,19,20:18.12
8,19,20:18.12
9,19,20:18.12
10,19,20:18.12
11,19,20:18.12
12,19,20:18.12
-26,20,20:18.12
-25,20,20:18.12
-24,20,20:18.12
-23,20,20:18.12
-22,20,20:18.12
-10,20,20:18.12
-9,20,20:17.12
-8,20,20:17.12
-7,20,20:17.12
0,20,20:18.12
1,20,20:18.12
2,20,20:18.12
7,20,20:18.12
8,20,20:18.12
9,20,20:18.12
10,20,20:18.12
11,20,20:18.12
12,20,20:18.12
-31,21,20:18.4
-30,21,20:18.12
-26,21,20:18.12
-25,21,20:18.12
-24,21,20:18.12
-23,21,20:18.12
-21,21,20:18.12
-19,21,20:18.12
-11,21,20:18.12
-9,21,20:17.12
-8,21,20:17.12
-7,21,20:17.12
-6,21,20:18.12
-5,21,20:18.12
-4,21,20:18.12
-2,21,20:18.12
-1,21,20:18.12
0,21,20:18.12
1,21,20:18.12
8,21,20:18.12
9,21,20:18.12
10,21,20:18.12
-31,22,20:18.4
-30,22,20:18.12
-29,22,20:18.12
-28,22,20:18.12
-27,22,20:18.12
-26,22,20:18.12
-25,22,20:18.12
-24,22,20:17.12
-23,22,20:17.12
-21,22,20:18.12
-19,22,20:18.12
-9,22,20:18.12
-8,22,20:17.12
-7,22,20:17.12
-6,22,20:18.12
-5,22,20:18.12
-4,22,20:18.12
-3,22,20:18.12
-2,22,20:18.12
0,22,20:18.4
1,22,20:18.12
9,22,20:18.12
10,22,20:18.12
11,22,20:18.12
-30,23,20:18.12
-29,23,20:18.12
-28,23,20:18.12
-27,23,20:18.12
-26,23,20:18.12
-24,23,20:17.12
-23,23,20:17.12
-22,23,20:18.12
-20,23,20:18.12
-19,23,20:18.12
-13,23,20:18.12
-9,23,20:18.12
-8,23,20:18.12
-5,23,20:18.12
-4,23,20:18.12
-3,23,20:18.12
-2,23,20:18.12
-1,23,20:18.4
0,23,20:18.4
1,23,20:18.4
10,23,20:18.12
11,23,20:18.12
12,23,20:18.12
-30,24,20:18.12
-29,24,20:18.12
-28,24,20:18.12
-23,24,20:18.12
-22,24,20:18.12
-20,24,20:18.12
-16,24,20:18.12
-12,24,20:18.12
-8,24,20:18.12
-5,24,20:18.12
-4,24,20:18.12
-3,24,20:18.12
-2,24,20:18.12
-1,24,20:18.4
0,24,20:18.4
1,24,20:18.4
-30,25,20:18.12
-29,25,20:18.12
-25,25,20:18.12
-24,25,20:18.12
-23,25,20:18.12
-22,25,20:18.12
-20,25,20:18.12
-17,25,20:18.12
-16,25,20:18.12
-12,25,20:18.12
-11,25,20:18.12
-8,25,20:18.12
-5,25,20:18.12
-4,25,20:18.12
-3,25,20:18.12
-2,25,20:18.12
-27,26,20:18.12
-26,26,20:18.12
-25,26,20:18.12
-24,26,20:18.12
-23,26,20:18.12
-22,26,20:18.12
-21,26,20:18.12
-18,26,20:18.12
-17,26,20:18.12
-15,26,20:17.12
-11,26,20:18.12
-8,26,20:18.12
-5,26,20:18.12
-28,27,20:18.12
-27,27,20:18.12
-26,27,20:18.12
-23,27,20:18.12
-22,27,20:18.12
-21,27,20:18.12
-18,27,20:18.12
-16,27,20:18.12
-15,27,20:17.12
-14,27,20:17.12
-11,27,20:18.12
-10,27,20:18.12
-9,27,20:18.12
-8,27,20:18.12
-5,27,20:18.12
-28,28,20:18.12
-23,28,20:18.12
-21,28,20:18.12
-20,28,20:18.12
-18,28,20:18.12
-17,28,20:18.12
-16,28,20:18.12
-15,28,20:17.12
-11,28,20:18.12
-9,28,20:18.12
-8,28,20:18.12
-7,28,20:18.12
-22,29,20:18.4
-21,29,20:18.12
-20,29,20:18.12
-19,29,20:18.12
-18,29,20:18.12
-17,29,20:18.12
-15,29,20:18.12
-11,29,20:18.12
-10,29,20:18.12
-8,29,20:18.4
-21,30,20:18.12
-20,30,20:18.12
-19,30,20:18.12
-18,30,20:18.12
-15,30,20:18.12
-12,30,20:18.12
-11,30,20:18.12
-8,30,20:18.4
-21,31,20:18.12
-20,31,20:18.12
-19,31,20:18.12
-15,31,20:18.12
-8,31,20:18.4
-22,32,20:18.4
-20,32,20:18.12
-15,32,20:18.12
-16,33,20:18.12
-15,33,20:18.12
-16,34,20:18.12
-15,34,20:18.12
-14,34,20:18.12
-15,35,20:18.12
-8,-5,21:18.12
-7,-5,21:18.12
-11,-4,21:18.12
-8,-4,21:18.12
-7,-4,21:18.12
-12,-3,21:18.12
-11,-3,21:18.12
-8,-3,21:18.12
-7,-3,21:18.12
-6,-3,21:18.12
-5,-3,21:18.12
-12,-2,21:18.12
-11,-2,21:18.12
-10,-2,21:17.12
-9,-2,21:17.12
-8,-2,21:18.12
-7,-2,21:18.12
-6,-2,21:18.12
-14,-1,21:18.12
-13,-1,21:18.12
-12,-1,21:18.12
-11,-1,21:18.12
-10,-1,21:17.12
-9,-1,21:17.12
-8,-1,21:18.12
-7,-1,21:18.12
-29,0,21:18.4
-18,0,21:18.12
-17,0,21:18.12
-16,0,21:18.4
-14,0,21:18.12
-13,0,21:18.12
-12,0,21:18.12
-11,0,21:18.12
-10,0,21:17.12
-9,0,21:18.12
-8,0,21:18.12
-7,0,21:18.12
-28,1,21:18.4
-27,1,21:18.4
-18,1,21:18.12
-17,1,21:18.12
-16,1,21:18.12
-15,1,21:18.12
-14,1,21:18.12
-13,1,21:18.12
-12,1,21:18.12
-11,1,21:18.12
-10,1,21:18.12
-8,1,21:18.12
-7,1,21:18.12
-27,2,21:18.4
-26,2,21:18.4
-20,2,21:18.12
-18,2,21:18.12
-15,2,21:18.12
-14,2,21:18.12
-13,2,21:18.12
-12,2,21:18.12
-10,2,21:17.12
-8,2,21:18.12
-7,2,21:18.12
-6,2,21:18.12
-5,2,21:18.12
-4,2,21:18.4
-3,2,21:18.4
-2,2,21:18.4
-26,3,21:18.4
-25,3,21:18.12
-21,3,21:18.12
-20,3,21:18.12
-19,3,21:18.12
-18,3,21:18.12
-17,3,21:18.12
-16,3,21:18.12
-15,3,21:18.12
-14,3,21:18.12
-12,3,21:18.12
-9,3,21:18.12
-5,3,21:18.12
-4,3,21:18.4
-3,3,21:18.4
-2,3,21:18.4
-24,4,21:18.12
-17,4,21:18.12
-16,4,21:18.12
-15,4,21:18.12
-12,4,21:18.12
-23,5,21:18.12
-22,5,21:18.12
-17,5,21:18.12
-14,5,21:18.12
-11,5,21:17.12
-22,6,21:18.12
-21,6,21:18.12
-17,6,21:18.12
-14,6,21:18.12
-13,6,21:18.12
-12,6,21:17.12
-11,6,21:17.12
-30,7,21:18.12
-21,7,21:18.12
-20,7,21:18.12
-19,7,21:18.12
-17,7,21:18.12
-13,7,21:18.12
-6,7,21:18.12
-5,7,21:18.12
-30,8,21:18.12
-25,8,21:18.12
-22,8,21:18.12
-20,8,21:18.12
-19,8,21:18.12
-18,8,21:18.12
-17,8,21:17.12
-12,8,21:18.12
-7,8,21:18.12
-6,8,21:18.12
-5,8,21:18.12
-4,8,21:18.12
-34,9,21:18.12
-33,9,21:18.12
-31,9,21:18.12
-30,9,21:18.12
-24,9,21:18.12
-23,9,21:18.12
-22,9,21:18.12
-19,9,21:18.12
-18,9,21:18.12
-17,9,21:17.12
-12,9,21:18.12
-8,9,21:18.12
-7,9,21:18.12
-6,9,21:18.12
-5,9,21:18.12
-4,9,21:18.12
5,9,21:18.4
6,9,21:18.4
7,9,21:18.4
8,9,21:18.4
-34,10,21:18.12
-33,10,21:18.12
-32,10,21:18.12
-31,10,21:17.12
-30,10,21:18.12
-29,10,21:18.12
-28,10,21:18.12
-27,10,21:18.12
-24,10,21:18.12
-23,10,21:18.12
-13,10,21:18.12
-8,10,21:18.12
-7,10,21:18.12
-6,10,21:18.12
-5,10,21:18.12
-4,10,21:18.12
-3,10,21:18.12
4,10,21:18.4
5,10,21:18.4
6,10,21:18.4
7,10,21:18.4
8,10,21:18.4
-34,11,21:18.12
-33,11,21:18.12
-32,11,21:18.12
-31,11,21:17.12
-30,11,21:18.12
-28,11,21:18.12
-27,11,21:18.12
-25,11,21:18.12
-24,11,21:18.12
-14,11,21:18.12
-8,11,21:18.12
-7,11,21:18.12
-6,11,21:18.12
-5,11,21:18.12
-4,11,21:18.12
2,11,21:18.4
3,11,21:18.4
4,11,21:18.4
5,11,21:18.4
-34,12,21:18.12
-33,12,21:18.12
-32,12,21:18.12
-29,12,21:18.12
-28,12,21:18.12
-27,12,21:18.12
-24,12,21:18.12
-11,12,21:17.12
-10,12,21:17.12
-9,12,21:18.12
-8,12,21:17.12
-7,12,21:18.12
-3,12,21:18.12
-2,12,21:18.12
1,12,21:18.12
2,12,21:18.12
4,12,21:18.12
5,12,21:18.4
-35,13,21:18.12
-34,13,21:18.12
-33,13,21:18.12
-32,13,21:18.12
-31,13,21:18.12
-30,13,21:18.12
-29,13,21:18.12
-28,13,21:18.12
-24,13,21:18.12
-17,13,21:18.12
-12,13,21:17.12
-11,13,21:17.12
-10,13,21:17.12
-9,13,21:17.12
-8,13,21:17.12
-2,13,21:18.12
-1,13,21:18.12
0,13,21:18.12
3,13,21:18.12
4,13,21:18.12
-36,14,21:18.4
-35,14,21:18.12
-30,14,21:18.12
-29,14,21:18.12
-28,14,21:18.12
-24,14,21:18.12
-17,14,21:18.12
-16,14,21:18.12
-14,14,21:17.12
-13,14,21:17.12
-12,14,21:17.12
-11,14,21:17.12
-10,14,21:17.12
-9,14,21:17.12
-2,14,21:18.12
-1,14,21:18.12
3,14,21:18.12
4,14,21:18.12
5,14,21:18.12
-30,15,21:18.12
-29,15,21:18.12
-23,15,21:18.12
-16,15,21:18.12
-14,15,21:18.12
-13,15,21:18.12
-12,15,21:17.12
-11,15,21:17.12
-10,15,21:17.12
-9,15,21:18.12
-8,15,21:18.12
-7,15,21:18.12
-6,15,21:18.12
-5,15,21:18.12
-4,15,21:18.12
-3,15,21:18.12
-2,15,21:18.12
-1,15,21:18.12
0,15,21:18.12
1,15,21:18.12
2,15,21:18.12
3,15,21:18.12
4,15,21:18.12
5,15,21:18.12
6,15,21:18.12
7,15,21:18.12
8,15,21:18.12
-31,16,21:18.12
-30,16,21:18.12
-29,16,21:18.12
-16,16,21:18.12
-12,16,21:17.12
-3,16,21:17.12
-2,16,21:17.12
0,16,21:18.12
1,16,21:18.12
4,16,21:18.12
7,16,21:18.12
8,16,21:18.12
-31,17,21:18.4
-30,17,21:18.4
-29,17,21:18.4
-28,17,21:18.4
-27,17,21:18.4
4,17,21:18.12
-30,18,21:18.4
-29,18,21:18.4
-28,18,21:18.12
-27,18,21:18.12
-26,18,21:18.12
-25,18,21:18.12
-24,18,21:18.12
-23,18,21:18.12
-18,18,21:18.12
-17,18,21:18.12
-12,18,21:18.12
0,18,21:18.12
3,18,21:18.12
4,18,21:18.12
5,18,21:18.12
6,18,21:18.12
7,18,21:17.12
8,18,21:17.12
-29,19,21:18.12
-28,19,21:18.12
-27,19,21:18.12
-26,19,21:18.12
-25,19,21:18.12
-24,19,21:18.12
-23,19,21:18.12
-22,19,21:18.12
-19,19,21:18.12
-18,19,21:18.12
-11,19,21:18.12
-10,19,21:18.12
-9,19,21:18.12
1,19,21:18.12
5,19,21:18.12
6,19,21:18.12
-28,20,21:18.12
-27,20,21:18.12
-26,20,21:18.12
-25,20,21:18.12
-24,20,21:18.12
-23,20,21:18.12
-22,20,21:18.12
-21,20,21:18.12
-20,20,21:18.12
-11,20,21:18.12
-10,20,21:18.12
-8,20,21:17.12
-7,20,21:18.12
1,20,21:18.12
2,20,21:18.12
3,20,21:18.12
4,20,21:18.12
5,20,21:18.12
6,20,21:18.12
7,20,21:18.12
8,20,21:18.12
-28,21,21:18.12
-27,21,21:18.12
-26,21,21:18.12
-21,21,21:18.12
-11,21,21:18.12
-8,21,21:17.12
-7,21,21:17.12
-6,21,21:18.12
1,21,21:18.12
2,21,21:18.12
3,21,21:18.12
9,21,21:18.12
10,21,21:18.12
11,21,21:18.12
-29,22,21:18.12
-28,22,21:18.12
-27,22,21:18.12
-26,22,21:18.12
-25,22,21:18.12
-24,22,21:18.12
-22,22,21:18.12
-19,22,21:18.12
-11,22,21:18.12
-8,22,21:17.12
-7,22,21:17.12
-6,22,21:18.12
-5,22,21:18.12
-4,22,21:18.12
-3,22,21:18.12
-2,22,21:18.12
1,22,21:18.12
2,22,21:18.12
11,22,21:18.12
-31,23,21:18.4
-30,23,21:18.12
-29,23,21:18.12
-28,23,21:18.12
-25,23,21:17.12
-24,23,21:17.12
-23,23,21:17.12
-22,23,21:18.12
-20,23,21:18.12
-13,23,21:18.12
-12,23,21:18.12
-11,23,21:18.12
-10,23,21:18.12
-9,23,21:18.12
-8,23,21:18.12
-5,23,21:18.12
-3,23,21:18.12
-2,23,21:18.12
-1,23,21:18.12
1,23,21:18.4
-31,24,21:18.4
-23,24,21:18.12
-22,24,21:18.12
-20,24,21:18.12
-16,24,21:18.12
-12,24,21:18.12
-11,24,21:18.12
-10,24,21:18.12
-9,24,21:18.12
-8,24,21:18.12
-4,24,21:18.12
-1,24,21:18.12
0,24,21:18.12
1,24,21:18.4
-24,25,21:18.12
-23,25,21:18.12
-22,25,21:18.12
-21,25,21:18.12
-20,25,21:18.12
-17,25,21:18.12
-16,25,21:18.12
-13,25,21:18.12
-12,25,21:18.12
-11,25,21:18.12
-10,25,21:18.12
-9,25,21:18.12
-8,25,21:18.12
-3,25,21:18.12
-2,25,21:18.12
1,25,21:18.4
2,25,21:18.4
-26,26,21:18.12
-25,26,21:18.12
-24,26,21:18.12
-23,26,21:18.12
-22,26,21:18.12
-21,26,21:18.12
-17,26,21:18.12
-11,26,21:18.12
-10,26,21:18.12
-9,26,21:18.12
-8,26,21:18.12
-27,27,21:18.12
-26,27,21:18.12
-25,27,21:18.12
-24,27,21:18.12
-23,27,21:18.12
-22,27,21:18.12
-21,27,21:18.12
-20,27,21:18.12
-18,27,21:18.12
-17,27,21:18.12
-16,27,21:17.12
-15,27,21:18.12
-10,27,21:18.12
-9,27,21:18.12
-8,27,21:18.12
-28,28,21:18.12
-27,28,21:18.12
-26,28,21:18.12
-25,28,21:18.12
-24,28,21:18.12
-21,28,21:18.12
-20,28,21:18.12
-19,28,21:18.12
-18,28,21:18.12
-17,28,21:18.12
-16,28,21:17.12
-15,28,21:17.12
-9,28,21:18.12
-8,28,21:18.12
-28,29,21:18.4
-27,29,21:18.4
-26,29,21:18.4
-24,29,21:18.4
-23,29,21:18.4
-22,29,21:18.4
-21,29,21:18.12
-20,29,21:18.12
-19,29,21:18.12
-18,29,21:18.12
-17,29,21:18.12
-16,29,21:18.12
-15,29,21:18.12
-9,29,21:18.12
-8,29,21:18.12
-28,30,21:18.4
-27,30,21:18.4
-23,30,21:18.4
-22,30,21:18.4
-21,30,21:18.12
-20,30,21:18.12
-19,30,21:18.12
-18,30,21:18.12
-17,30,21:18.12
-16,30,21:18.12
-15,30,21:18.12
-8,30,21:18.12
-20,31,21:18.12
-19,31,21:18.12
-18,31,21:18.12
-17,31,21:18.12
-16,31,21:18.12
-15,31,21:18.12
-8,31,21:18.4
-22,32,21:18.4
-21,32,21:18.12
-20,32,21:18.12
-19,32,21:18.12
-18,32,21:18.12
-17,32,21:18.12
-16,32,21:18.12
-15,32,21:18.12
-20,33,21:18.12
-19,33,21:18.12
-17,33,21:18.12
-16,33,21:18.12
-20,34,21:18.12
-19,34,21:18.12
-16,34,21:18.12
-16,35,21:18.12
-12,-5,22:18.12
-7,-5,22:18.12
-6,-5,22:18.12
-13,-4,22:18.12
-12,-4,22:18.12
-7,-4,22:18.12
-6,-4,22:18.12
-5,-4,22:18.12
-13,-3,22:18.12
-12,-3,22:18.12
-10,-3,22:17.12
-9,-3,22:17.12
-7,-3,22:18.12
-6,-3,22:18.12
-5,-3,22:18.12
-18,-2,22:18.4
-14,-2,22:18.12
-13,-2,22:18.12
-12,-2,22:18.12
-10,-2,22:17.12
-9,-2,22:18.12
-8,-2,22:18.12
-7,-2,22:18.12
-6,-2,22:18.12
-19,-1,22:18.4
-18,-1,22:18.4
-17,-1,22:18.4
-16,-1,22:18.4
-15,-1,22:18.12
-14,-1,22:18.12
-13,-1,22:18.12
-11,-1,22:18.12
-10,-1,22:18.12
-9,-1,22:18.12
-8,-1,22:18.12
-7,-1,22:18.12
-6,-1,22:18.12
-29,0,22:18.4
-18,0,22:18.12
-17,0,22:18.12
-16,0,22:18.4
-15,0,22:18.12
-14,0,22:18.12
-13,0,22:18.12
-11,0,22:18.12
-10,0,22:18.12
-9,0,22:18.12
-7,0,22:18.12
-6,0,22:18.12
-5,0,22:18.12
-28,1,22:18.4
-27,1,22:18.4
-20,1,22:18.12
-18,1,22:18.12
-16,1,22:18.12
-15,1,22:18.12
-14,1,22:18.12
-13,1,22:18.12
-11,1,22:18.12
-10,1,22:18.12
-9,1,22:18.12
-7,1,22:18.12
-6,1,22:18.12
-5,1,22:18.12
-4,1,22:18.4
-3,1,22:18.4
-2,1,22:18.4
-1,1,22:18.4
0,1,22:18.4
-27,2,22:18.4
-26,2,22:18.12
-21,2,22:18.12
-20,2,22:18.12
-19,2,22:18.12
-18,2,22:18.12
-17,2,22:18.12
-16,2,22:18.12
-15,2,22:18.12
-13,2,22:18.12
-8,2,22:18.12
-3,2,22:18.4
-2,2,22:18.4
-1,2,22:18.4
-26,3,22:18.12
-25,3,22:18.12
-18,3,22:18.12
-17,3,22:18.12
-16,3,22:18.12
-15,3,22:18.12
-12,3,22:18.12
-9,3,22:18.12
-24,4,22:18.12
-23,4,22:18.12
-18,4,22:18.12
-15,4,22:18.12
-12,4,22:18.12
-31,5,22:18.4
-23,5,22:18.12
-22,5,22:18.12
-21,5,22:18.12
-20,5,22:18.12
-19,5,22:18.12
-18,5,22:18.12
-17,5,22:18.12
-14,5,22:18.12
-5,5,22:18.12
-31,6,22:18.12
-23,6,22:18.12
-22,6,22:18.12
-21,6,22:18.12
-20,6,22:18.12
-19,6,22:18.12
-17,6,22:18.12
-14,6,22:18.12
-13,6,22:18.12
-12,6,22:17.12
-11,6,22:17.12
-5,6,22:18.12
-31,7,22:18.12
-22,7,22:18.12
-21,7,22:18.12
-19,7,22:18.12
-18,7,22:18.12
-17,7,22:18.12
-16,7,22:18.12
-13,7,22:18.12
-12,7,22:17.12
-11,7,22:17.12
-6,7,22:18.12
-5,7,22:18.12
-31,8,22:18.12
-23,8,22:18.12
-22,8,22:18.12
-21,8,22:18.12
-20,8,22:18.12
-19,8,22:17.12
-18,8,22:17.12
-17,8,22:17.12
-12,8,22:18.12
-6,8,22:18.12
-5,8,22:18.12
-4,8,22:18.12
-35,9,22:18.12
-34,9,22:18.12
-31,9,22:18.12
-30,9,22:18.12
-24,9,22:18.12
-23,9,22:18.12
-21,9,22:18.12
-18,9,22:17.12
-17,9,22:17.12
-6,9,22:18.12
-5,9,22:18.12
-4,9,22:18.12
6,9,22:18.4
7,9,22:18.4
-35,10,22:18.12
-34,10,22:18.12
-33,10,22:18.12
-32,10,22:18.12
-31,10,22:18.12
-30,10,22:18.12
-29,10,22:18.12
-28,10,22:18.12
-27,10,22:18.12
-25,10,22:18.12
-24,10,22:18.12
-7,10,22:18.12
-6,10,22:18.12
-5,10,22:18.12
4,10,22:18.4
5,10,22:18.4
6,10,22:18.4
-36,11,22:18.4
-35,11,22:18.12
-34,11,22:18.12
-30,11,22:18.12
-25,11,22:18.12
-10,11,22:18.12
-9,11,22:17.12
-8,11,22:17.12
-7,11,22:18.12
-6,11,22:18.12
-5,11,22:18.12
-4,11,22:18.12
-3,11,22:18.12
-2,11,22:18.12
-1,11,22:18.12
2,11,22:18.4
3,11,22:18.4
4,11,22:18.4
5,11,22:18.4
6,11,22:18.4
-36,12,22:18.4
-35,12,22:18.12
-34,12,22:18.12
-25,12,22:18.12
-10,12,22:17.12
-9,12,22:18.12
-8,12,22:17.12
-7,12,22:17.12
-5,12,22:18.12
-4,12,22:18.12
-3,12,22:18.12
-2,12,22:18.12
-1,12,22:18.12
0,12,22:18.12
1,12,22:18.12
2,12,22:18.12
5,12,22:18.4
6,12,22:18.4
-36,13,22:18.4
-35,13,22:18.12
-34,13,22:18.12
-33,13,22:18.12
-32,13,22:18.12
-31,13,22:18.12
-30,13,22:18.12
-25,13,22:18.12
-24,13,22:18.12
-14,13,22:17.12
-13,13,22:17.12
-12,13,22:17.12
-9,13,22:17.12
-8,13,22:17.12
-7,13,22:17.12
-1,13,22:18.12
0,13,22:18.12
5,13,22:18.12
6,13,22:18.12
-36,14,22:18.4
-35,14,22:18.12
-34,14,22:18.12
-33,14,22:18.12
-32,14,22:18.12
-31,14,22:18.12
-30,14,22:18.12
-24,14,22:18.12
-14,14,22:17.12
-13,14,22:17.12
-12,14,22:17.12
-11,14,22:17.12
-2,14,22:18.12
-1,14,22:18.12
3,14,22:18.12
4,14,22:18.12
5,14,22:18.12
6,14,22:18.12
7,14,22:18.12
8,14,22:18.12
-33,15,22:18.12
-31,15,22:18.12
-30,15,22:18.12
-24,15,22:18.12
-15,15,22:18.12
-14,15,22:18.12
-13,15,22:17.12
-12,15,22:17.12
-8,15,22:18.12
-7,15,22:18.12
-6,15,22:18.12
-5,15,22:18.12
-4,15,22:18.12
1,15,22:18.12
2,15,22:18.12
3,15,22:18.12
4,15,22:18.12
7,15,22:18.12
8,15,22:18.12
9,15,22:18.12
-33,16,22:18.4
-32,16,22:18.4
-31,16,22:18.12
-30,16,22:18.12
-29,16,22:18.12
-28,16,22:18.12
-24,16,22:18.12
-23,16,22:18.12
-15,16,22:18.12
-13,16,22:18.12
-7,16,22:18.12
-6,16,22:18.12
-5,16,22:18.12
-4,16,22:18.12
-3,16,22:18.12
-2,16,22:17.12
-1,16,22:18.12
0,16,22:18.12
1,16,22:18.12
4,16,22:18.12
-29,17,22:18.4
-28,17,22:18.4
-27,17,22:18.4
-26,17,22:18.12
-25,17,22:18.12
-23,17,22:18.12
-16,17,22:18.12
4,17,22:18.12
5,17,22:18.12
-30,18,22:18.4
-29,18,22:18.4
-28,18,22:18.12
-26,18,22:18.12
-25,18,22:18.12
-24,18,22:18.12
-18,18,22:18.12
-17,18,22:18.12
-13,18,22:18.12
-12,18,22:18.12
0,18,22:18.12
4,18,22:18.12
5,18,22:18.12
6,18,22:18.12
7,18,22:18.12
8,18,22:17.12
9,18,22:17.12
-30,19,22:18.4
-29,19,22:18.12
-28,19,22:18.12
-27,19,22:18.12
-26,19,22:18.12
-25,19,22:18.12
-19,19,22:18.12
-18,19,22:18.12
-12,19,22:18.12
-9,19,22:18.12
-8,19,22:18.12
-7,19,22:18.12
1,19,22:18.12
3,19,22:18.12
8,19,22:18.12
9,19,22:17.12
10,19,22:17.12
-30,20,22:18.12
-29,20,22:18.12
-28,20,22:18.12
-27,20,22:18.12
-26,20,22:18.12
-25,20,22:18.12
-24,20,22:18.12
-23,20,22:18.12
-22,20,22:18.12
-21,20,22:18.12
-20,20,22:18.12
-12,20,22:18.12
-11,20,22:18.12
-10,20,22:18.12
-9,20,22:18.12
-7,20,22:18.12
1,20,22:18.12
2,20,22:18.12
7,20,22:18.12
8,20,22:18.12
-29,21,22:18.12
-28,21,22:18.12
-27,21,22:18.12
-25,21,22:18.12
-22,21,22:18.12
-21,21,22:18.12
-11,21,22:18.12
-8,21,22:17.12
-7,21,22:17.12
-6,21,22:18.12
-5,21,22:18.12
-4,21,22:18.12
2,21,22:18.12
3,21,22:18.12
4,21,22:18.12
5,21,22:18.12
6,21,22:18.12
7,21,22:18.12
8,21,22:18.12
9,21,22:18.12
10,21,22:18.12
-30,22,22:18.12
-29,22,22:18.12
-28,22,22:18.12
-27,22,22:18.12
-26,22,22:18.12
-25,22,22:18.12
-24,22,22:18.12
-22,22,22:18.12
-11,22,22:18.12
-8,22,22:17.12
-7,22,22:17.12
-6,22,22:18.12
-5,22,22:18.12
-4,22,22:18.12
-3,22,22:18.12
2,22,22:18.12
3,22,22:18.12
4,22,22:18.12
10,22,22:18.12
11,22,22:18.12
-32,23,22:18.4
-31,23,22:18.4
-30,23,22:18.12
-29,23,22:18.12
-28,23,22:18.12
-27,23,22:18.12
-26,23,22:18.12
-25,23,22:17.12
-24,23,22:17.12
-22,23,22:18.12
-12,23,22:18.12
-11,23,22:18.12
-6,23,22:18.12
-5,23,22:18.12
-4,23,22:18.12
-3,23,22:18.12
-2,23,22:18.12
3,23,22:18.4
-33,24,22:18.4
-32,24,22:18.4
-31,24,22:18.4
-30,24,22:18.12
-29,24,22:18.12
-28,24,22:18.12
-27,24,22:18.12
-26,24,22:18.12
-25,24,22:18.12
-23,24,22:18.12
-22,24,22:18.12
-12,24,22:18.12
-7,24,22:18.12
-5,24,22:18.12
-4,24,22:18.12
-2,24,22:18.12
-1,24,22:18.12
0,24,22:18.12
2,24,22:18.4
-27,25,22:18.12
-26,25,22:18.12
-24,25,22:18.12
-23,25,22:18.12
-13,25,22:18.12
-12,25,22:18.12
-11,25,22:18.12
-8,25,22:18.12
-7,25,22:18.12
-3,25,22:18.12
0,25,22:18.12
1,25,22:18.4
2,25,22:18.4
-27,26,22:18.12
-26,26,22:18.12
-24,26,22:18.12
-23,26,22:18.12
-13,26,22:18.12
-12,26,22:18.12
-11,26,22:18.12
-10,26,22:18.12
-8,26,22:18.12
-7,26,22:18.12
-28,27,22:18.12
-27,27,22:18.12
-26,27,22:18.12
-25,27,22:18.12
-24,27,22:18.12
-23,27,22:18.12
-22,27,22:18.12
-21,27,22:18.12
-20,27,22:18.12
-19,27,22:18.12
-18,27,22:18.12
-15,27,22:17.12
-13,27,22:18.12
-11,27,22:18.12
-10,27,22:18.12
-9,27,22:18.12
-8,27,22:18.12
-28,28,22:18.12
-27,28,22:18.12
-26,28,22:18.12
-25,28,22:18.12
-24,28,22:18.12
-23,28,22:18.12
-21,28,22:18.12
-20,28,22:18.12
-19,28,22:18.12
-18,28,22:18.12
-16,28,22:17.12
-15,28,22:17.12
-13,28,22:18.12
-12,28,22:18.12
-11,28,22:18.12
-9,28,22:18.12
-8,28,22:18.12
-29,29,22:18.4
-28,29,22:18.4
-27,29,22:18.4
-26,29,22:18.4
-25,29,22:18.4
-23,29,22:18.4
-22,29,22:18.4
-21,29,22:18.12
-20,29,22:18.12
-19,29,22:18.12
-16,29,22:17.12
-15,29,22:18.12
-12,29,22:18.12
-11,29,22:18.12
-10,29,22:18.12
-9,29,22:18.12
-8,29,22:18.12
-29,30,22:18.4
-28,30,22:18.4
-27,30,22:18.4
-26,30,22:18.4
-22,30,22:18.4
-21,30,22:18.12
-20,30,22:18.12
-16,30,22:17.12
-15,30,22:18.12
-14,30,22:18.12
-13,30,22:18.12
-12,30,22:18.12
-11,30,22:18.12
-10,30,22:18.12
-9,30,22:18.12
-29,31,22:18.4
-28,31,22:18.4
-27,31,22:18.4
-23,31,22:18.4
-22,31,22:18.4
-21,31,22:18.12
-20,31,22:18.12
-19,31,22:18.12
-16,31,22:17.12
-15,31,22:18.12
-9,31,22:18.4
-8,31,22:18.4
-29,32,22:18.4
-28,32,22:18.4
-21,32,22:18.12
-20,32,22:18.12
-19,32,22:18.12
-18,32,22:18.12
-16,32,22:18.12
-9,32,22:18.4
-21,33,22:18.12
-20,33,22:18.12
-16,33,22:18.12
-16,34,22:18.12
-6,-6,23:18.12
-5,-6,23:18.12
-14,-5,23:18.12
-13,-5,23:18.12
-6,-5,23:18.12
-5,-5,23:18.12
-14,-4,23:18.12
-13,-4,23:18.12
-10,-4,23:17.12
-6,-4,23:18.12
-5,-4,23:18.12
-18,-3,23:18.4
-17,-3,23:18.4
-14,-3,23:18.12
-13,-3,23:18.12
-10,-3,23:17.12
-9,-3,23:18.12
-7,-3,23:18.12
-6,-3,23:18.12
-5,-3,23:18.12
-18,-2,23:18.4
-17,-2,23:18.4
-16,-2,23:18.4
-15,-2,23:18.12
-14,-2,23:18.12
-13,-2,23:18.12
-12,-2,23:18.12
-11,-2,23:18.12
-10,-2,23:18.12
-9,-2,23:18.12
-8,-2,23:18.12
-7,-2,23:18.12
-6,-2,23:18.12
-5,-2,23:18.12
-18,-1,23:18.12
-16,-1,23:18.4
-15,-1,23:18.12
-14,-1,23:18.12
-11,-1,23:18.12
-10,-1,23:18.12
-9,-1,23:18.12
-6,-1,23:18.12
-5,-1,23:18.12
-4,-1,23:18.4
-3,-1,23:18.4
-18,0,23:18.12
-17,0,23:18.12
-16,0,23:18.4
-14,0,23:18.12
-13,0,23:18.12
-12,0,23:18.12
-11,0,23:18.12
-10,0,23:18.12
-9,0,23:18.12
-6,0,23:18.12
-5,0,23:18.12
-4,0,23:18.4
-3,0,23:18.4
-2,0,23:18.4
-1,0,23:18.4
0,0,23:18.4
-28,1,23:18.12
-27,1,23:18.12
-18,1,23:18.12
-17,1,23:18.12
-16,1,23:18.12
-13,1,23:18.12
-9,1,23:18.12
-7,1,23:18.12
-1,1,23:18.4
0,1,23:18.4
-27,2,23:18.12
-26,2,23:18.12
-25,2,23:18.12
-24,2,23:18.12
-23,2,23:18.12
-18,2,23:18.12
-17,2,23:18.12
-16,2,23:18.12
-13,2,23:18.12
-12,2,23:18.12
-8,2,23:18.12
-26,3,23:18.12
-25,3,23:18.12
-24,3,23:18.12
-23,3,23:18.12
-22,3,23:18.12
-21,3,23:18.12
-20,3,23:18.12
-19,3,23:18.12
-18,3,23:18.12
-16,3,23:18.12
-15,3,23:18.12
-12,3,23:18.12
-9,3,23:18.12
-25,4,23:18.12
-24,4,23:18.12
-23,4,23:18.12
-22,4,23:18.12
-21,4,23:18.12
-20,4,23:18.12
-19,4,23:18.12
-18,4,23:18.12
-15,4,23:18.12
-4,4,23:18.12
-3,4,23:18.12
-32,5,23:18.4
-31,5,23:18.4
-25,5,23:18.12
-24,5,23:18.12
-21,5,23:17.12
-20,5,23:17.12
-19,5,23:18.12
-18,5,23:18.12
-17,5,23:18.12
-14,5,23:18.12
-11,5,23:17.12
-4,5,23:18.12
-3,5,23:18.12
-32,6,23:18.12
-31,6,23:18.12
-25,6,23:18.12
-24,6,23:18.12
-23,6,23:18.12
-20,6,23:17.12
-19,6,23:17.12
-18,6,23:18.12
-17,6,23:18.12
-16,6,23:18.12
-14,6,23:18.12
-13,6,23:18.12
-12,6,23:17.12
-11,6,23:17.12
-4,6,23:18.12
-3,6,23:18.12
-32,7,23:18.12
-24,7,23:18.12
-23,7,23:18.12
-22,7,23:18.12
-20,7,23:18.12
-19,7,23:17.12
-18,7,23:17.12
-16,7,23:18.12
-15,7,23:18.12
-13,7,23:18.12
-5,7,23:18.12
-4,7,23:18.12
-3,7,23:18.12
-32,8,23:18.12
-24,8,23:18.12
-23,8,23:18.12
-22,8,23:18.12
-19,8,23:17.12
-18,8,23:17.12
-17,8,23:17.12
-13,8,23:18.12
-12,8,23:18.12
-7,8,23:18.12
-5,8,23:18.12
-4,8,23:18.12
-3,8,23:18.12
-34,9,23:18.12
-33,9,23:18.12
-32,9,23:18.12
-31,9,23:18.12
-30,9,23:18.12
-24,9,23:18.12
-23,9,23:18.12
-22,9,23:18.12
-18,9,23:18.12
-17,9,23:17.12
-13,9,23:18.12
-12,9,23:18.12
-8,9,23:18.12
-5,9,23:18.12
-4,9,23:18.12
6,9,23:18.4
-35,10,23:18.12
-34,10,23:18.12
-33,10,23:18.12
-31,10,23:18.12
-30,10,23:18.12
-29,10,23:18.12
-28,10,23:18.12
-27,10,23:18.12
-26,10,23:18.12
-25,10,23:18.12
-23,10,23:18.12
-12,10,23:18.12
-11,10,23:18.12
-10,10,23:18.12
-9,10,23:18.12
-8,10,23:18.12
-7,10,23:17.12
-6,10,23:18.12
-5,10,23:18.12
-4,10,23:18.12
-3,10,23:18.12
-2,10,23:18.12
-1,10,23:18.12
0,10,23:18.12
4,10,23:18.4
5,10,23:18.4
7,10,23:18.4
-9,11,23:18.12
-8,11,23:17.12
-7,11,23:18.12
-6,11,23:18.12
-5,11,23:18.12
-4,11,23:18.12
-3,11,23:18.12
-2,11,23:18.12
-1,11,23:18.12
0,11,23:18.12
1,11,23:18.12
2,11,23:18.4
3,11,23:18.4
4,11,23:18.4
7,11,23:18.4
-25,12,23:18.12
-9,12,23:18.12
-8,12,23:18.12
-7,12,23:17.12
1,12,23:18.12
2,12,23:18.12
6,12,23:18.4
7,12,23:18.4
-25,13,23:18.12
-14,13,23:17.12
-13,13,23:17.12
-12,13,23:17.12
-1,13,23:18.12
0,13,23:18.12
1,13,23:18.12
4,13,23:18.12
6,13,23:18.12
7,13,23:18.12
-36,14,23:18.4
-35,14,23:18.12
-34,14,23:18.12
-33,14,23:18.12
-32,14,23:18.12
-25,14,23:18.12
-24,14,23:18.12
-16,14,23:18.12
-15,14,23:18.12
-13,14,23:17.12
-12,14,23:17.12
-11,14,23:17.12
-1,14,23:18.12
4,14,23:18.12
5,14,23:18.12
9,14,23:18.12
-35,15,23:18.12
-34,15,23:18.12
-33,15,23:18.12
-32,15,23:18.12
-31,15,23:18.12
-24,15,23:18.12
-16,15,23:18.12
-15,15,23:18.12
-13,15,23:17.12
-12,15,23:17.12
1,15,23:18.12
2,15,23:18.12
3,15,23:18.12
4,15,23:18.12
5,15,23:18.12
-34,16,23:18.4
-33,16,23:18.4
-32,16,23:18.4
-24,16,23:18.12
-16,16,23:18.12
-15,16,23:18.12
-7,16,23:18.12
-6,16,23:18.12
-5,16,23:18.12
-4,16,23:18.12
-3,16,23:18.12
-2,16,23:18.12
-1,16,23:18.12
0,16,23:18.12
1,16,23:18.12
5,16,23:18.12
-34,17,23:18.4
-32,17,23:18.4
-31,17,23:18.4
-30,17,23:18.4
-29,17,23:18.4
-17,17,23:18.12
-16,17,23:18.12
-15,17,23:18.12
-14,17,23:18.12
-3,17,23:18.12
-1,17,23:17.12
0,17,23:17.12
5,17,23:18.12
-33,18,23:18.4
-32,18,23:18.4
-31,18,23:18.4
-30,18,23:18.4
-29,18,23:18.4
-28,18,23:18.12
-27,18,23:18.12
-26,18,23:18.12
-25,18,23:18.12
-18,18,23:18.12
-17,18,23:18.12
-14,18,23:18.12
0,18,23:18.12
4,18,23:18.12
5,18,23:18.12
6,18,23:18.12
7,18,23:18.12
-30,19,23:18.4
-29,19,23:18.12
-28,19,23:18.12
-27,19,23:18.12
-25,19,23:18.12
-19,19,23:18.12
-18,19,23:18.12
-13,19,23:18.12
-12,19,23:18.12
-7,19,23:18.12
-6,19,23:18.12
1,19,23:18.12
3,19,23:18.12
4,19,23:18.12
8,19,23:18.12
9,19,23:18.12
10,19,23:18.12
11,19,23:17.12
12,19,23:17.12
-30,20,23:18.12
-29,20,23:18.12
-28,20,23:18.12
-26,20,23:18.12
-25,20,23:18.12
-24,20,23:18.12
-23,20,23:18.12
-22,20,23:18.12
-21,20,23:18.12
-20,20,23:18.12
-12,20,23:18.12
-11,20,23:18.12
-10,20,23:18.12
-9,20,23:18.12
-8,20,23:18.12
-7,20,23:18.12
1,20,23:18.12
2,20,23:18.12
3,20,23:18.12
7,20,23:18.12
10,20,23:18.12
11,20,23:18.12
-31,21,23:18.4
-30,21,23:18.12
-29,21,23:18.12
-28,21,23:18.12
-27,21,23:18.12
-26,21,23:18.12
-25,21,23:18.12
-22,21,23:18.12
-21,21,23:18.12
-11,21,23:18.12
-10,21,23:18.12
-9,21,23:18.12
-8,21,23:17.12
-7,21,23:17.12
-2,21,23:18.12
2,21,23:18.12
3,21,23:18.12
8,21,23:18.12
9,21,23:18.12
-32,22,23:18.4
-31,22,23:18.4
-30,22,23:18.12
-27,22,23:18.12
-26,22,23:18.12
-25,22,23:18.12
-23,22,23:18.12
-22,22,23:18.12
-11,22,23:18.12
-8,22,23:17.12
-7,22,23:17.12
-6,22,23:18.12
-5,22,23:18.12
-3,22,23:18.12
-2,22,23:18.12
3,22,23:18.12
4,22,23:18.12
5,22,23:18.12
6,22,23:18.12
7,22,23:18.12
10,22,23:18.12
11,22,23:18.12
-33,23,23:18.4
-32,23,23:18.4
-31,23,23:18.4
-30,23,23:18.12
-29,23,23:18.12
-28,23,23:18.12
-27,23,23:18.12
-25,23,23:17.12
-24,23,23:18.12
-23,23,23:18.12
-22,23,23:18.12
-12,23,23:18.12
-11,23,23:18.12
-5,23,23:18.12
-2,23,23:18.12
-1,23,23:18.12
3,23,23:18.4
4,23,23:18.4
-34,24,23:18.4
-33,24,23:18.4
-32,24,23:18.4
-31,24,23:18.4
-26,24,23:18.12
-25,24,23:17.12
-23,24,23:18.12
-12,24,23:18.12
-4,24,23:18.12
-3,24,23:18.12
-2,24,23:18.12
-1,24,23:18.12
0,24,23:18.12
3,24,23:18.4
-34,25,23:18.4
-33,25,23:18.4
-32,25,23:18.4
-31,25,23:18.4
-30,25,23:18.12
-29,25,23:18.12
-28,25,23:18.12
-27,25,23:18.12
-24,25,23:18.12
-23,25,23:18.12
-12,25,23:18.12
-11,25,23:18.12
-7,25,23:18.12
-6,25,23:18.12
-4,25,23:18.12
-3,25,23:18.12
-2,25,23:18.12
-1,25,23:18.12
0,25,23:18.12
1,25,23:18.12
2,25,23:18.4
3,25,23:18.4
-35,26,23:18.4
-34,26,23:18.4
-33,26,23:18.4
-32,26,23:18.4
-31,26,23:18.4
-30,26,23:18.12
-29,26,23:18.12
-28,26,23:18.12
-24,26,23:18.12
-23,26,23:18.12
-10,26,23:18.12
-7,26,23:18.12
-6,26,23:18.12
-5,26,23:18.12
-4,26,23:18.12
-3,26,23:18.12
-2,26,23:18.12
-1,26,23:18.12
2,26,23:18.4
3,26,23:18.4
-30,27,23:18.12
-29,27,23:18.12
-28,27,23:18.12
-25,27,23:18.12
-23,27,23:18.12
-15,27,23:17.12
-10,27,23:18.12
-7,27,23:18.12
-30,28,23:18.12
-29,28,23:18.12
-28,28,23:18.12
-24,28,23:18.12
-23,28,23:18.12
-20,28,23:18.12
-8,28,23:18.12
-7,28,23:18.12
-30,29,23:18.4
-29,29,23:18.4
-24,29,23:18.4
-23,29,23:18.4
-21,29,23:18.12
-16,29,23:18.12
-13,29,23:18.12
-12,29,23:18.12
-8,29,23:18.12
-7,29,23:18.12
-31,30,23:18.4
-30,30,23:18.4
-29,30,23:18.4
-26,30,23:18.4
-25,30,23:18.4
-24,30,23:18.4
-23,30,23:18.4
-16,30,23:18.12
-15,30,23:18.12
-14,30,23:18.12
-13,30,23:18.12
-12,30,23:18.12
-11,30,23:18.12
-10,30,23:18.12
-9,30,23:18.12
-8,30,23:18.12
-31,31,23:18.4
-30,31,23:18.4
-27,31,23:18.4
-26,31,23:18.4
-25,31,23:18.4
-24,31,23:18.4
-23,31,23:18.4
-22,31,23:18.4
-17,31,23:18.12
-16,31,23:17.12
-14,31,23:18.12
-13,31,23:18.12
-12,31,23:18.12
-11,31,23:18.12
-10,31,23:18.12
-9,31,23:18.4
-8,31,23:18.12
-32,32,23:18.4
-31,32,23:18.4
-30,32,23:18.4
-27,32,23:18.4
-26,32,23:18.4
-24,32,23:18.4
-23,32,23:18.4
-22,32,23:18.4
-20,32,23:18.12
-19,32,23:18.12
-18,32,23:18.12
-17,32,23:17.12
-16,32,23:17.12
-14,32,23:18.12
-13,32,23:18.12
-28,33,23:18.4
-27,33,23:18.4
-23,33,23:18.4
-22,33,23:18.12
-21,33,23:18.12
-20,33,23:18.12
-19,33,23:18.12
-18,33,23:18.12
-17,33,23:17.12
-16,33,23:17.12
-14,33,23:18.12
-13,33,23:18.12
-23,34,23:18.4
-22,34,23:18.12
-21,34,23:18.12
-18,34,23:18.12
-17,34,23:17.12
-14,34,23:18.12
-13,34,23:18.12
-17,35,23:18.12
-14,35,23:18.12
-13,35,23:18.12
-17,36,23:17.12
-14,36,23:18.12
-8,-6,24:18.12
-5,-6,24:18.12
-4,-6,24:18.4
-15,-5,24:18.12
-14,-5,24:18.12
-11,-5,24:17.12
-10,-5,24:17.12
-8,-5,24:18.12
-5,-5,24:18.12
-4,-5,24:18.4
-17,-4,24:18.4
-16,-4,24:18.4
-15,-4,24:18.12
-14,-4,24:18.12
-10,-4,24:17.12
-9,-4,24:18.12
-7,-4,24:18.12
-6,-4,24:18.12
-5,-4,24:18.12
-4,-4,24:18.4
-18,-3,24:18.4
-17,-3,24:18.4
-15,-3,24:18.12
-13,-3,24:18.12
-12,-3,24:18.12
-11,-3,24:18.12
-9,-3,24:18.12
-8,-3,24:18.12
-7,-3,24:18.12
-5,-3,24:18.12
-4,-3,24:18.4
-18,-2,24:18.4
-15,-2,24:18.12
-12,-2,24:18.12
-11,-2,24:18.12
-10,-2,24:18.12
-9,-2,24:18.12
-8,-2,24:18.12
-5,-2,24:18.12
-4,-2,24:18.4
-3,-2,24:18.4
-2,-2,24:18.4
-1,-2,24:18.4
-18,-1,24:18.12
-17,-1,24:18.4
-14,-1,24:18.12
-13,-1,24:18.12
-12,-1,24:18.12
-11,-1,24:18.12
-10,-1,24:18.12
-9,-1,24:18.12
-5,-1,24:18.12
-4,-1,24:18.4
-3,-1,24:18.4
-2,-1,24:18.4
-1,-1,24:18.4
0,-1,24:18.4
1,-1,24:18.4
-29,0,24:18.4
-28,0,24:18.12
-27,0,24:18.12
-26,0,24:18.12
-25,0,24:18.12
-24,0,24:18.12
-23,0,24:18.12
-22,0,24:18.12
-21,0,24:18.12
-18,0,24:18.12
-17,0,24:18.12
-15,0,24:18.12
-14,0,24:18.12
-13,0,24:18.12
-12,0,24:18.12
-9,0,24:18.12
-6,0,24:18.12
-29,1,24:18.4
-28,1,24:18.12
-27,1,24:18.12
-26,1,24:18.12
-25,1,24:18.12
-24,1,24:18.12
-23,1,24:18.12
-22,1,24:18.12
-21,1,24:18.12
-20,1,24:18.12
-19,1,24:18.12
-18,1,24:18.12
-17,1,24:18.12
-13,1,24:18.12
-9,1,24:18.12
-8,1,24:18.12
-7,1,24:18.12
-28,2,24:18.12
-27,2,24:18.12
-26,2,24:18.12
-25,2,24:18.12
-24,2,24:18.12
-23,2,24:18.12
-22,2,24:18.12
-21,2,24:18.12
-20,2,24:18.12
-19,2,24:18.12
-18,2,24:18.12
-16,2,24:18.12
-13,2,24:18.12
-12,2,24:18.12
-8,2,24:18.12
-7,2,24:18.12
-28,3,24:18.12
-27,3,24:18.12
-26,3,24:18.12
-19,3,24:18.12
-18,3,24:18.12
-17,3,24:18.12
-16,3,24:18.12
-15,3,24:18.12
-12,3,24:18.12
-9,3,24:18.12
-27,4,24:18.12
-26,4,24:18.12
-21,4,24:17.12
-20,4,24:18.12
-19,4,24:18.12
-18,4,24:18.12
-17,4,24:18.12
-16,4,24:18.12
-15,4,24:18.12
-12,4,24:18.12
-11,4,24:17.12
-2,4,24:18.12
-1,4,24:18.12
-33,5,24:18.4
-32,5,24:18.4
-27,5,24:18.12
-26,5,24:18.12
-25,5,24:18.12
-21,5,24:17.12
-20,5,24:18.12
-19,5,24:18.12
-16,5,24:18.12
-15,5,24:18.12
-14,5,24:18.12
-11,5,24:17.12
-2,5,24:18.12
-1,5,24:18.12
-33,6,24:18.12
-32,6,24:18.12
-26,6,24:18.12
-25,6,24:18.12
-21,6,24:18.12
-20,6,24:18.12
-15,6,24:18.12
-14,6,24:18.12
-13,6,24:18.12
-12,6,24:18.12
-11,6,24:18.12
-7,6,24:18.12
-3,6,24:18.12
-2,6,24:18.12
-1,6,24:18.12
-33,7,24:18.12
-32,7,24:18.12
-26,7,24:18.12
-25,7,24:18.12
-23,7,24:18.12
-22,7,24:18.12
-20,7,24:18.12
-19,7,24:18.12
-14,7,24:18.12
-13,7,24:18.12
-7,7,24:18.12
-6,7,24:18.12
-3,7,24:18.12
-2,7,24:18.12
-33,8,24:18.12
-32,8,24:18.12
-26,8,24:18.12
-25,8,24:18.12
-24,8,24:18.12
-23,8,24:18.12
-19,8,24:18.12
-18,8,24:18.12
-14,8,24:18.12
-13,8,24:18.12
-12,8,24:18.12
-8,8,24:18.12
-7,8,24:18.12
-3,8,24:18.12
-2,8,24:18.12
-35,9,24:18.12
-34,9,24:18.12
-33,9,24:18.12
-32,9,24:18.12
-31,9,24:18.12
-30,9,24:18.12
-25,9,24:18.12
-24,9,24:18.12
-19,9,24:18.12
-12,9,24:18.12
-11,9,24:18.12
-10,9,24:18.12
-9,9,24:18.12
-8,9,24:18.12
-7,9,24:18.12
-6,9,24:18.12
-5,9,24:17.12
-4,9,24:17.12
-3,9,24:18.12
-2,9,24:18.12
-1,9,24:18.12
0,9,24:18.12
1,9,24:18.12
2,9,24:18.4
-32,10,24:18.12
-31,10,24:18.12
-30,10,24:18.12
-29,10,24:18.12
-28,10,24:18.12
-27,10,24:18.12
-26,10,24:18.12
-25,10,24:18.12
-24,10,24:18.12
-10,10,24:18.12
-9,10,24:18.12
-7,10,24:17.12
-6,10,24:17.12
-5,10,24:17.12
-4,10,24:18.12
-3,10,24:18.12
-2,10,24:18.12
-1,10,24:18.12
0,10,24:18.12
1,10,24:18.12
2,10,24:18.4
3,10,24:18.4
4,10,24:18.4
5,10,24:18.4
-31,11,24:18.12
-9,11,24:18.12
-7,11,24:17.12
-6,11,24:17.12
-5,11,24:18.12
3,11,24:18.4
4,11,24:18.4
-26,12,24:18.12
-15,12,24:18.12
-14,12,24:18.12
-13,12,24:18.12
-9,12,24:18.12
-6,12,24:17.12
1,12,24:18.12
2,12,24:18.12
4,12,24:18.4
5,12,24:18.4
-26,13,24:18.12
-25,13,24:18.12
-14,13,24:18.12
-13,13,24:17.12
-12,13,24:17.12
0,13,24:18.12
1,13,24:18.12
4,13,24:18.12
5,13,24:18.12
6,13,24:18.12
7,13,24:18.12
-25,14,24:18.12
-17,14,24:18.12
-16,14,24:18.12
-13,14,24:17.12
-12,14,24:17.12
4,14,24:18.12
5,14,24:18.12
-34,15,24:18.12
-33,15,24:18.12
-25,15,24:18.12
-17,15,24:18.12
-16,15,24:18.12
-13,15,24:17.12
-12,15,24:17.12
-3,15,24:18.12
2,15,24:18.12
3,15,24:18.12
5,15,24:18.12
-25,16,24:18.4
-24,16,24:18.4
-17,16,24:18.12
-16,16,24:18.12
-2,16,24:18.12
0,16,24:18.12
1,16,24:18.12
5,16,24:18.12
6,16,24:18.12
-17,17,24:18.12
-16,17,24:18.12
-15,17,24:18.12
-14,17,24:18.12
-3,17,24:18.12
-2,17,24:18.12
-1,17,24:18.12
0,17,24:18.12
1,17,24:17.12
6,17,24:18.12
-35,18,24:18.4
-34,18,24:18.4
-33,18,24:18.4
-32,18,24:18.4
-26,18,24:18.12
-25,18,24:18.12
-18,18,24:18.12
-17,18,24:18.12
-16,18,24:18.12
-15,18,24:18.12
-14,18,24:18.12
-13,18,24:18.12
-4,18,24:18.12
-3,18,24:18.12
0,18,24:18.12
5,18,24:18.12
6,18,24:18.12
7,18,24:18.12
-35,19,24:18.4
-34,19,24:18.4
-33,19,24:18.4
-32,19,24:18.4
-31,19,24:18.4
-30,19,24:18.4
-29,19,24:18.12
-28,19,24:18.12
-27,19,24:18.12
-26,19,24:18.12
-25,19,24:18.12
-20,19,24:18.12
-19,19,24:18.12
-14,19,24:18.12
-13,19,24:18.12
1,19,24:18.12
4,19,24:18.12
5,19,24:18.12
8,19,24:18.12
9,19,24:18.12
10,19,24:18.12
-34,20,24:18.4
-33,20,24:18.4
-32,20,24:18.4
-31,20,24:18.4
-30,20,24:18.12
-26,20,24:18.12
-25,20,24:18.12
-24,20,24:18.12
-21,20,24:18.12
-20,20,24:18.12
-13,20,24:18.12
-12,20,24:18.12
-8,20,24:18.12
-7,20,24:18.12
-6,20,24:18.12
-2,20,24:18.12
-1,20,24:18.12
1,20,24:18.12
2,20,24:18.12
3,20,24:18.12
4,20,24:18.12
11,20,24:18.12
12,20,24:18.12
-33,21,24:18.4
-32,21,24:18.4
-31,21,24:18.4
-29,21,24:18.12
-28,21,24:18.12
-27,21,24:18.12
-26,21,24:18.12
-25,21,24:18.12
-22,21,24:18.12
-21,21,24:18.12
-12,21,24:18.12
-11,21,24:18.12
-10,21,24:18.12
-9,21,24:18.12
-8,21,24:18.12
-7,21,24:17.12
-4,21,24:18.12
-2,21,24:18.12
-1,21,24:18.12
2,21,24:18.12
3,21,24:18.12
-34,22,24:18.4
-33,22,24:18.4
-32,22,24:18.4
-27,22,24:18.12
-26,22,24:18.12
-25,22,24:18.12
-24,22,24:18.12
-23,22,24:18.12
-11,22,24:18.12
-10,22,24:18.12
-8,22,24:17.12
-7,22,24:17.12
-6,22,24:17.12
-5,22,24:18.12
-4,22,24:18.12
-3,22,24:18.12
-2,22,24:18.12
-1,22,24:18.12
0,22,24:18.12
3,22,24:18.12
-34,23,24:18.4
-33,23,24:18.4
-30,23,24:18.12
-29,23,24:18.12
-28,23,24:18.12
-27,23,24:18.12
-24,23,24:18.12
-23,23,24:18.12
-12,23,24:18.12
-11,23,24:18.12
-7,23,24:17.12
-6,23,24:17.12
-5,23,24:18.12
-4,23,24:18.12
-3,23,24:18.12
-1,23,24:18.12
0,23,24:18.12
1,23,24:18.12
4,23,24:18.4
5,23,24:18.12
-31,24,24:18.4
-26,24,24:17.12
-25,24,24:17.12
-23,24,24:18.12
-12,24,24:18.12
-7,24,24:17.12
-6,24,24:17.12
-3,24,24:18.12
-2,24,24:18.12
0,24,24:18.12
1,24,24:18.12
4,24,24:18.4
-28,25,24:18.12
-27,25,24:18.12
-24,25,24:18.12
-12,25,24:18.12
-6,25,24:18.12
-3,25,24:18.12
-2,25,24:18.12
-1,25,24:18.12
0,25,24:18.12
1,25,24:18.12
2,25,24:18.4
4,25,24:18.4
-29,26,24:18.12
-28,26,24:18.12
-25,26,24:18.12
-24,26,24:18.12
-23,26,24:18.12
-12,26,24:18.12
-6,26,24:18.12
-3,26,24:18.12
-2,26,24:18.12
-1,26,24:18.12
0,26,24:18.12
1,26,24:18.12
2,26,24:18.4
-36,27,24:18.4
-35,27,24:18.4
-34,27,24:18.4
-33,27,24:18.4
-32,27,24:18.4
-31,27,24:18.4
-30,27,24:18.12
-25,27,24:18.12
-23,27,24:18.12
-15,27,24:17.12
-6,27,24:18.12
-4,27,24:18.12
-3,27,24:18.12
-2,27,24:18.12
-1,27,24:18.12
0,27,24:18.12
-34,28,24:18.4
-33,28,24:18.4
-31,28,24:18.4
-30,28,24:18.12
-24,28,24:18.12
-23,28,24:18.12
-7,28,24:18.12
-6,28,24:18.12
-3,28,24:18.12
-2,28,24:18.12
-1,28,24:18.12
0,28,24:18.12
-32,29,24:18.4
-31,29,24:18.4
-24,29,24:18.4
-7,29,24:18.12
-6,29,24:18.12
-33,30,24:18.4
-32,30,24:18.4
-31,30,24:18.4
-24,30,24:18.4
-14,30,24:18.12
-7,30,24:18.12
-33,31,24:18.4
-32,31,24:18.4
-24,31,24:18.4
-17,31,24:18.12
-14,31,24:18.12
-13,31,24:18.12
-6,31,24:18.12
-32,32,24:18.4
-25,32,24:18.4
-24,32,24:18.4
-18,32,24:18.12
-16,32,24:17.12
-13,32,24:18.12
-12,32,24:18.12
-11,32,24:18.12
-10,32,24:18.4
-9,32,24:18.4
-8,32,24:18.4
-7,32,24:18.12
-26,33,24:18.4
-25,33,24:18.4
-24,33,24:18.4
-23,33,24:18.4
-20,33,24:18.12
-19,33,24:18.12
-18,33,24:18.12
-13,33,24:18.12
-12,33,24:18.12
-11,33,24:18.4
-10,33,24:18.4
-9,33,24:18.4
-8,33,24:18.4
-26,34,24:18.4
-25,34,24:18.4
-24,34,24:18.4
-23,34,24:18.4
-22,34,24:18.12
-21,34,24:18.12
-20,34,24:18.12
-19,34,24:18.12
-18,34,24:18.12
-17,34,24:17.12
-16,34,24:17.12
-13,34,24:18.12
-12,34,24:18.12
-24,35,24:18.4
-22,35,24:18.12
-21,35,24:18.12
-20,35,24:18.12
-19,35,24:18.12
-18,35,24:18.12
-17,35,24:17.12
-13,35,24:18.12
-12,35,24:18.12
-20,36,24:18.12
-19,36,24:18.12
-18,36,24:18.12
-17,36,24:17.12
-12,36,24:18.12
-17,37,24:17.12
-13,37,24:18.12
-12,37,24:18.12
-8,-7,25:18.12
-10,-6,25:17.12
-8,-6,25:18.12
-9,-5,25:18.12
-8,-5,25:18.12
-6,-5,25:18.12
-5,-5,25:18.12
-13,-4,25:18.12
-12,-4,25:18.12
-11,-4,25:18.12
-9,-4,25:18.12
-7,-4,25:18.12
-6,-4,25:18.12
-3,-4,25:18.4
-12,-3,25:18.12
-11,-3,25:18.12
-10,-3,25:18.12
-9,-3,25:18.12
-8,-3,25:18.12
-3,-3,25:18.4
-2,-3,25:18.4
-1,-3,25:18.4
-25,-2,25:18.12
-18,-2,25:18.4
-11,-2,25:18.12
-10,-2,25:18.12
-9,-2,25:18.12
-8,-2,25:18.12
-4,-2,25:18.4
-3,-2,25:18.4
-2,-2,25:18.4
-1,-2,25:18.4
0,-2,25:18.4
-28,-1,25:18.12
-27,-1,25:18.12
-25,-1,25:18.12
-24,-1,25:18.12
-23,-1,25:18.12
-22,-1,25:18.12
-18,-1,25:18.12
-16,-1,25:18.4
-15,-1,25:18.12
-14,-1,25:18.12
-13,-1,25:18.12
-12,-1,25:18.12
-11,-1,25:18.12
-10,-1,25:18.12
-9,-1,25:18.12
-8,-1,25:18.12
-5,-1,25:18.12
-28,0,25:18.12
-27,0,25:18.12
-26,0,25:18.12
-25,0,25:18.12
-24,0,25:18.12
-23,0,25:18.12
-22,0,25:18.12
-21,0,25:18.12
-18,0,25:18.12
-17,0,25:18.12
-16,0,25:18.4
-14,0,25:18.12
-13,0,25:18.12
-9,0,25:18.12
-8,0,25:18.12
-6,0,25:18.12
-30,1,25:18.4
-29,1,25:18.4
-19,1,25:18.12
-18,1,25:18.12
-17,1,25:18.12
-13,1,25:18.12
-8,1,25:18.12
-7,1,25:18.12
-6,1,25:18.12
-29,2,25:18.4
-20,2,25:18.12
-19,2,25:18.12
-18,2,25:18.12
-17,2,25:18.12
-16,2,25:18.12
-13,2,25:18.12
-12,2,25:18.12
-8,2,25:18.12
-7,2,25:18.12
-6,2,25:18.12
-30,3,25:18.4
-29,3,25:18.4
-28,3,25:18.12
-25,3,25:18.12
-24,3,25:18.12
-21,3,25:18.12
-20,3,25:18.12
-19,3,25:18.12
-17,3,25:18.12
-16,3,25:18.12
-15,3,25:18.12
-12,3,25:18.12
-9,3,25:18.12
-6,3,25:18.12
-29,4,25:18.4
-28,4,25:18.12
-24,4,25:18.12
-23,4,25:18.12
-22,4,25:18.12
-21,4,25:17.12
-20,4,25:18.12
-16,4,25:18.12
-15,4,25:18.12
-14,4,25:18.12
-11,4,25:17.12
-6,4,25:18.12
0,4,25:18.12
1,4,25:18.12
-34,5,25:18.4
-33,5,25:18.4
-29,5,25:18.4
-28,5,25:18.12
-27,5,25:18.12
-23,5,25:18.12
-22,5,25:18.12
-21,5,25:18.12
-15,5,25:18.12
-14,5,25:18.12
-13,5,25:18.12
-11,5,25:18.12
-6,5,25:18.12
-5,5,25:18.12
-1,5,25:18.12
0,5,25:18.12
1,5,25:18.12
-34,6,25:18.12
-33,6,25:18.12
-28,6,25:18.12
-22,6,25:18.12
-21,6,25:18.12
-14,6,25:18.12
-13,6,25:18.12
-12,6,25:18.12
-11,6,25:18.12
-7,6,25:18.12
-6,6,25:18.12
-5,6,25:18.12
-1,6,25:18.12
0,6,25:18.12
-34,7,25:18.12
-33,7,25:18.12
-28,7,25:18.12
-27,7,25:18.12
-24,7,25:18.12
-23,7,25:18.12
-20,7,25:18.12
-19,7,25:18.12
-18,7,25:18.12
-17,7,25:18.12
-14,7,25:18.12
-13,7,25:18.12
-12,7,25:18.12
-10,7,25:18.12
-8,7,25:18.12
-7,7,25:18.12
-6,7,25:18.12
-5,7,25:18.12
-1,7,25:18.12
0,7,25:18.12
-36,8,25:18.4
-35,8,25:18.12
-34,8,25:18.12
-33,8,25:18.12
-28,8,25:18.12
-27,8,25:18.12
-26,8,25:18.12
-25,8,25:18.12
-24,8,25:18.12
-20,8,25:18.12
-19,8,25:18.12
-13,8,25:18.12
-12,8,25:18.12
-11,8,25:18.12
-10,8,25:18.12
-9,8,25:18.12
-8,8,25:18.12
-6,8,25:18.12
-5,8,25:18.12
-4,8,25:17.12
-3,8,25:18.12
-1,8,25:18.12
0,8,25:18.12
1,8,25:18.12
2,8,25:18.12
3,8,25:18.4
-36,9,25:18.4
-35,9,25:18.12
-33,9,25:18.12
-32,9,25:18.12
-30,9,25:18.12
-26,9,25:18.4
-25,9,25:18.12
-20,9,25:18.12
-13,9,25:18.12
-10,9,25:18.12
-9,9,25:18.12
-6,9,25:18.12
-5,9,25:17.12
-4,9,25:17.12
-3,9,25:18.12
-2,9,25:18.12
-1,9,25:18.12
0,9,25:18.12
1,9,25:18.12
2,9,25:18.12
3,9,25:18.4
4,9,25:18.4
-32,10,25:18.12
-31,10,25:18.12
-30,10,25:18.12
-29,10,25:18.12
-28,10,25:18.12
-27,10,25:18.12
-26,10,25:18.4
-25,10,25:18.4
-21,10,25:18.12
-20,10,25:18.12
-19,10,25:18.12
-18,10,25:18.12
-17,10,25:18.12
-14,10,25:18.12
-9,10,25:18.12
-7,10,25:17.12
-6,10,25:18.12
-5,10,25:17.12
-4,10,25:18.12
-3,10,25:18.12
-1,10,25:18.12
0,10,25:18.12
-31,11,25:18.12
-27,11,25:18.12
-19,11,25:18.12
-18,11,25:18.12
-17,11,25:18.12
-16,11,25:18.12
-15,11,25:18.12
-14,11,25:18.12
-9,11,25:18.12
-6,11,25:17.12
-5,11,25:18.12
-26,12,25:18.4
-14,12,25:18.12
-9,12,25:18.12
5,12,25:18.4
-26,13,25:18.4
-19,13,25:18.12
-18,13,25:18.12
-3,13,25:18.12
5,13,25:18.12
6,13,25:18.12
7,13,25:18.12
-26,14,25:18.4
-25,14,25:18.4
-19,14,25:18.4
-18,14,25:18.12
-14,14,25:17.12
-13,14,25:17.12
-12,14,25:17.12
-3,14,25:18.12
4,14,25:18.12
5,14,25:18.12
6,14,25:18.12
-25,15,25:18.4
-19,15,25:18.4
-18,15,25:18.12
-13,15,25:17.12
-12,15,25:17.12
-3,15,25:18.12
2,15,25:18.12
3,15,25:18.12
6,15,25:18.12
-25,16,25:18.4
-19,16,25:18.4
-18,16,25:18.12
-13,16,25:17.12
-2,16,25:18.12
6,16,25:18.12
-26,17,25:18.4
-19,17,25:18.12
-18,17,25:18.12
-3,17,25:18.12
-2,17,25:18.12
-1,17,25:18.12
0,17,25:18.12
1,17,25:17.12
2,17,25:17.12
3,17,25:17.12
6,17,25:18.12
7,17,25:18.12
-26,18,25:18.4
-19,18,25:18.12
-18,18,25:18.12
-17,18,25:18.12
-16,18,25:18.12
-15,18,25:18.12
-14,18,25:18.12
-4,18,25:18.12
-3,18,25:18.12
6,18,25:18.12
7,18,25:18.12
8,18,25:18.12
-30,19,25:18.4
-29,19,25:18.12
-28,19,25:18.12
-27,19,25:18.12
-26,19,25:18.12
-20,19,25:18.12
-19,19,25:18.12
-18,19,25:18.12
-17,19,25:18.12
-16,19,25:18.12
-15,19,25:18.12
-14,19,25:18.12
-13,19,25:18.12
-12,19,25:18.12
-5,19,25:18.12
-4,19,25:18.12
5,19,25:18.12
6,19,25:18.12
8,19,25:18.12
9,19,25:18.12
10,19,25:18.12
11,19,25:18.12
-36,20,25:18.4
-35,20,25:18.4
-34,20,25:18.4
-33,20,25:18.4
-32,20,25:18.4
-31,20,25:18.4
-30,20,25:18.12
-26,20,25:18.12
-21,20,25:18.12
-20,20,25:18.12
-14,20,25:18.12
-13,20,25:18.12
-6,20,25:18.12
-5,20,25:18.12
1,20,25:18.12
2,20,25:18.12
3,20,25:18.12
4,20,25:18.12
5,20,25:18.12
11,20,25:18.12
12,20,25:18.12
-35,21,25:18.4
-34,21,25:18.4
-26,21,25:18.12
-22,21,25:18.12
-14,21,25:18.12
-13,21,25:18.12
-12,21,25:18.12
-9,21,25:18.12
-8,21,25:18.12
-7,21,25:18.12
-6,21,25:18.12
-1,21,25:18.12
0,21,25:18.12
2,21,25:18.12
3,21,25:18.12
-35,22,25:18.4
-28,22,25:18.12
-27,22,25:18.12
-26,22,25:18.12
-25,22,25:18.12
-24,22,25:18.12
-23,22,25:18.12
-14,22,25:18.12
-12,22,25:18.12
-11,22,25:18.12
-10,22,25:18.12
-9,22,25:18.12
-8,22,25:18.12
-7,22,25:17.12
-1,22,25:18.12
0,22,25:18.12
1,22,25:18.4
2,22,25:18.4
3,22,25:18.12
-30,23,25:18.12
-29,23,25:18.12
-28,23,25:18.12
-25,23,25:18.12
-24,23,25:18.12
-23,23,25:18.12
-12,23,25:18.12
-11,23,25:18.12
-8,23,25:18.12
-7,23,25:18.12
-6,23,25:17.12
-5,23,25:18.12
-4,23,25:18.12
-3,23,25:18.12
-2,23,25:18.12
-1,23,25:18.12
0,23,25:18.12
1,23,25:18.12
4,23,25:18.4
-23,24,25:18.12
-12,24,25:18.12
-7,24,25:18.12
-6,24,25:17.12
-5,24,25:17.12
-4,24,25:18.12
-3,24,25:18.12
-2,24,25:18.12
-1,24,25:18.12
0,24,25:18.12
2,24,25:18.4
3,24,25:18.4
-27,25,25:18.12
-12,25,25:18.12
-6,25,25:17.12
-5,25,25:17.12
-4,25,25:18.12
-3,25,25:18.12
-2,25,25:18.12
-1,25,25:18.12
0,25,25:18.12
1,25,25:18.12
2,25,25:18.12
3,25,25:18.4
-29,26,25:18.12
-28,26,25:18.12
-23,26,25:18.12
-12,26,25:18.12
-5,26,25:17.12
-4,26,25:17.12
-3,26,25:18.12
-2,26,25:18.12
-1,26,25:18.12
0,26,25:18.12
1,26,25:18.12
-30,27,25:18.12
-29,27,25:18.12
-23,27,25:18.12
-5,27,25:18.12
-31,28,25:18.4
-24,28,25:18.12
-23,28,25:18.12
-6,28,25:18.12
-5,28,25:18.12
0,28,25:18.12
-36,29,25:18.4
-35,29,25:18.4
-34,29,25:18.4
-33,29,25:18.4
-32,29,25:18.4
-24,29,25:18.4
-6,29,25:18.12
-5,29,25:18.12
-35,30,25:18.4
-34,30,25:18.4
-33,30,25:18.4
-24,30,25:18.4
-15,30,25:18.12
-14,30,25:18.12
-6,30,25:18.12
-5,30,25:18.12
-34,31,25:18.4
-33,31,25:18.4
-24,31,25:18.4
-18,31,25:18.12
-17,31,25:18.12
-14,31,25:18.12
-13,31,25:18.12
-6,31,25:18.12
-5,31,25:18.12
-34,32,25:18.4
-19,32,25:18.12
-18,32,25:18.12
-17,32,25:17.12
-16,32,25:18.12
-12,32,25:18.12
-6,32,25:18.12
-5,32,25:18.12
-20,33,25:18.12
-19,33,25:18.12
-11,33,25:18.4
-10,33,25:18.4
-9,33,25:18.4
-8,33,25:18.4
-7,33,25:18.4
-5,33,25:18.12
-21,34,25:18.12
-20,34,25:18.12
-11,34,25:18.4
-10,34,25:18.4
-9,34,25:18.4
-8,34,25:18.4
-7,34,25:18.4
-21,35,25:18.12
-11,35,25:18.4
-10,35,25:18.4
-11,36,25:18.4
-10,36,25:18.4
-18,37,25:17.12
-17,37,25:17.12
-11,37,25:18.4
-10,37,25:18.4
-18,38,25:17.12
-10,-8,26:17.12
-8,-7,26:18.12
-8,-6,26:18.12
-11,-5,26:18.12
-9,-5,26:18.12
-7,-5,26:18.12
-6,-5,26:18.12
-12,-4,26:18.12
-11,-4,26:18.12
-10,-4,26:18.12
-9,-4,26:18.12
-8,-4,26:18.12
-7,-4,26:18.12
-2,-4,26:18.4
-1,-4,26:18.4
-10,-3,26:18.12
-9,-3,26:18.12
-8,-3,26:18.12
-3,-3,26:18.4
-2,-3,26:18.4
-1,-3,26:18.4
-18,-2,26:18.4
-14,-2,26:18.12
-13,-2,26:18.12
-12,-2,26:18.12
-11,-2,26:18.12
-10,-2,26:18.12
-9,-2,26:18.12
-8,-2,26:18.12
-4,-2,26:18.4
-19,-1,26:18.12
-18,-1,26:18.12
-17,-1,26:18.4
-16,-1,26:18.4
-15,-1,26:18.12
-14,-1,26:18.12
-13,-1,26:18.12
-9,-1,26:18.12
-8,-1,26:18.12
-5,-1,26:18.12
-20,0,26:18.12
-19,0,26:18.12
-18,0,26:18.12
-17,0,26:18.12
-16,0,26:18.4
-14,0,26:18.12
-8,0,26:18.12
-7,0,26:18.12
-6,0,26:18.12
-5,0,26:18.12
-21,1,26:18.12
-20,1,26:18.12
-19,1,26:18.12
-17,1,26:18.12
-16,1,26:18.12
-15,1,26:18.12
-8,1,26:18.12
-7,1,26:18.12
-5,1,26:18.12
-22,2,26:18.12
-21,2,26:18.12
-20,2,26:18.12
-16,2,26:18.12
-15,2,26:18.12
-14,2,26:18.12
-8,2,26:18.12
-7,2,26:18.12
-6,2,26:18.12
-5,2,26:18.12
-25,3,26:18.12
-24,3,26:18.12
-23,3,26:18.12
-22,3,26:18.12
-21,3,26:18.12
-16,3,26:18.12
-15,3,26:18.12
-14,3,26:18.12
-13,3,26:18.12
-12,3,26:18.12
-11,3,26:17.12
-6,3,26:18.12
-5,3,26:18.12
-4,3,26:18.12
-30,4,26:18.4
-24,4,26:18.12
-23,4,26:18.12
-22,4,26:17.12
-21,4,26:17.12
-15,4,26:18.12
-14,4,26:18.12
-13,4,26:18.12
-12,4,26:18.12
-11,4,26:17.12
-10,4,26:18.12
-5,4,26:18.12
-4,4,26:18.12
1,4,26:18.12
-30,5,26:18.4
-29,5,26:18.4
-23,5,26:18.12
-22,5,26:18.12
-13,5,26:18.12
-12,5,26:18.12
-11,5,26:18.12
-5,5,26:18.12
-4,5,26:18.12
1,5,26:18.12
2,5,26:18.12
-35,6,26:18.4
-34,6,26:18.4
-29,6,26:18.4
-22,6,26:18.12
-21,6,26:18.12
-19,6,26:18.12
-18,6,26:18.12
-17,6,26:18.12
-16,6,26:18.12
-14,6,26:18.12
-13,6,26:18.12
-12,6,26:18.12
-11,6,26:18.12
-8,6,26:18.12
-7,6,26:18.12
-5,6,26:18.12
-4,6,26:18.12
1,6,26:18.12
2,6,26:18.12
-35,7,26:18.4
-34,7,26:18.4
-29,7,26:18.4
-28,7,26:18.4
-24,7,26:18.12
-21,7,26:18.12
-20,7,26:18.12
-19,7,26:18.12
-18,7,26:18.12
-15,7,26:18.12
-14,7,26:18.12
-13,7,26:18.12
-12,7,26:18.12
-11,7,26:18.12
-10,7,26:18.12
-9,7,26:18.12
-8,7,26:18.12
-5,7,26:18.12
-4,7,26:18.12
-3,7,26:18.12
-2,7,26:18.12
-1,7,26:18.12
0,7,26:18.12
1,7,26:18.12
2,7,26:18.12
3,7,26:18.12
4,7,26:18.4
-34,8,26:18.4
-28,8,26:18.4
-25,8,26:18.12
-22,8,26:18.12
-21,8,26:18.12
-20,8,26:18.12
-15,8,26:18.12
-14,8,26:18.12
-12,8,26:18.12
-10,8,26:18.12
-9,8,26:18.12
-8,8,26:18.12
-5,8,26:18.12
-4,8,26:18.12
-3,8,26:18.12
-2,8,26:18.12
-1,8,26:18.12
0,8,26:18.12
1,8,26:18.12
2,8,26:18.12
3,8,26:18.12
4,8,26:18.4
-33,9,26:18.4
-26,9,26:18.4
-22,9,26:18.12
-21,9,26:18.12
-20,9,26:18.12
-19,9,26:18.12
-18,9,26:18.12
-17,9,26:18.12
-15,9,26:18.12
-12,9,26:18.12
-9,9,26:18.12
-8,9,26:18.12
-7,9,26:18.12
-6,9,26:18.12
-5,9,26:18.12
-4,9,26:17.12
-3,9,26:17.12
-2,9,26:18.12
-1,9,26:18.12
1,9,26:18.12
2,9,26:18.12
-32,10,26:18.4
-27,10,26:18.4
-21,10,26:18.12
-19,10,26:18.12
-18,10,26:18.12
-17,10,26:18.12
-16,10,26:18.12
-15,10,26:18.12
-9,10,26:18.12
-6,10,26:18.12
-5,10,26:18.12
-4,10,26:18.12
-3,10,26:18.12
-27,11,26:18.4
-21,11,26:18.12
-15,11,26:18.12
-9,11,26:18.12
-4,11,26:18.12
-3,11,26:18.12
-27,12,26:18.4
-20,12,26:18.12
-19,12,26:18.12
-14,12,26:18.12
-9,12,26:18.12
-4,12,26:18.12
-3,12,26:18.12
-2,12,26:18.12
6,12,26:18.4
-26,13,26:18.4
-20,13,26:18.12
-19,13,26:18.12
-3,13,26:18.12
6,13,26:18.12
-26,14,26:18.4
-20,14,26:18.4
-19,14,26:18.4
-3,14,26:18.12
1,14,26:18.12
6,14,26:18.12
-26,15,26:18.4
-20,15,26:18.4
-19,15,26:18.4
-14,15,26:17.12
-13,15,26:17.12
-12,15,26:17.12
-3,15,26:18.12
6,15,26:18.12
7,15,26:18.12
-20,16,26:18.4
-19,16,26:18.4
-14,16,26:17.12
-13,16,26:17.12
-12,16,26:17.12
-2,16,26:18.12
6,16,26:18.12
7,16,26:18.12
-23,17,26:18.4
-22,17,26:18.4
-21,17,26:18.4
-20,17,26:18.4
-19,17,26:18.12
-14,17,26:17.12
-13,17,26:17.12
-3,17,26:18.12
-2,17,26:18.12
-1,17,26:18.12
0,17,26:18.12
1,17,26:18.12
7,17,26:18.12
-26,18,26:18.4
-19,18,26:18.12
-14,18,26:18.12
-4,18,26:18.12
-3,18,26:18.12
2,18,26:18.12
3,18,26:18.12
7,18,26:18.12
8,18,26:18.12
-29,19,26:18.12
-28,19,26:18.12
-27,19,26:18.12
-26,19,26:18.12
-20,19,26:18.12
-19,19,26:18.12
-18,19,26:18.12
-17,19,26:18.12
-16,19,26:18.12
-15,19,26:18.12
-14,19,26:18.12
-5,19,26:18.12
-4,19,26:18.12
6,19,26:18.12
7,19,26:18.12
9,19,26:18.12
10,19,26:18.12
11,19,26:18.12
-33,20,26:18.4
-32,20,26:18.4
-31,20,26:18.4
-30,20,26:18.12
-27,20,26:18.12
-26,20,26:18.12
-21,20,26:18.12
-20,20,26:18.12
-18,20,26:18.12
-17,20,26:18.12
-16,20,26:18.12
-15,20,26:18.12
-14,20,26:18.12
-13,20,26:18.12
-12,20,26:18.12
-5,20,26:18.12
4,20,26:18.12
5,20,26:18.12
11,20,26:18.12
12,20,26:18.12
-27,21,26:18.12
-23,21,26:18.12
-22,21,26:18.12
-14,21,26:18.12
-13,21,26:18.12
-7,21,26:18.12
3,21,26:18.12
4,21,26:18.12
-29,22,26:18.12
-28,22,26:18.12
-27,22,26:18.12
-26,22,26:18.12
-25,22,26:18.12
-24,22,26:18.12
-23,22,26:18.12
-14,22,26:18.12
-13,22,26:18.12
-12,22,26:18.12
-10,22,26:18.12
-9,22,26:18.12
-8,22,26:18.12
-7,22,26:18.12
3,22,26:18.4
-29,23,26:18.12
-25,23,26:18.12
-24,23,26:18.12
-15,23,26:18.12
-12,23,26:18.12
-11,23,26:18.12
-10,23,26:18.12
-9,23,26:18.12
-8,23,26:18.12
-7,23,26:18.12
-23,24,26:18.12
-7,24,26:18.12
-5,24,26:18.12
-4,24,26:18.12
-3,24,26:18.12
-2,24,26:18.12
-1,24,26:18.12
-27,25,26:18.12
-6,25,26:18.12
-5,25,26:18.12
-3,25,26:18.12
-2,25,26:18.12
-1,25,26:18.12
0,25,26:18.12
1,25,26:18.12
-29,26,26:18.12
-28,26,26:18.12
-5,26,26:17.12
-4,26,26:17.12
