[META]
version=2.0
spawnOnBlockType=2
spawnSunlight=True
spawnDarkness=True
spawnWater=False
spawnLava=False
underFill=False
randomRotation=True
dig=True
tree=False
branch=False
needsFoundation=True
rarity=100
collisionPercentage=20
spawnElevationMin=0
spawnElevationMax=200
spawnInBiome=Custom
[DATA]
2,-8,-8:17.12
-5,-7,-8:17.12
-4,-7,-8:17.12
2,-2,-8:17.12
3,-2,-8:17.12
-3,-1,-8:17.12
-2,-1,-8:17.12
-2,0,-8:17.12
-4,-8,-7:17.12
-3,-8,-7:17.12
-5,-7,-7:17.12
-4,-7,-7:17.12
-3,-7,-7:17.12
2,-7,-7:17.12
3,-7,-7:17.12
-5,-6,-7:17.12
-4,-6,-7:17.12
-3,-6,-7:17.12
2,-6,-7:17.12
-2,-2,-7:17.12
2,-2,-7:17.12
3,-2,-7:17.12
4,-2,-7:17.12
-2,-1,-7:17.12
-1,-1,-7:17.12
-2,0,-7:17.12
-1,0,-7:17.12
2,-9,-6:17.12
-4,-8,-6:17.12
-2,-8,-6:17.12
1,-8,-6:17.12
2,-8,-6:17.12
-4,-7,-6:17.12
-3,-7,-6:17.12
-2,-7,-6:17.12
1,-7,-6:17.12
2,-7,-6:17.12
3,-7,-6:17.12
-4,-6,-6:17.12
-2,-6,-6:17.12
1,-6,-6:17.12
2,-6,-6:17.12
3,-6,-6:17.12
-3,-5,-6:17.12
2,-3,-6:17.12
3,-3,-6:17.12
-3,-2,-6:17.12
-1,-2,-6:17.12
1,-2,-6:17.12
2,-2,-6:17.12
3,-2,-6:17.12
4,-2,-6:17.12
-2,-1,-6:17.12
-1,-1,-6:17.12
2,-1,-6:17.12
3,-1,-6:17.12
-2,0,-6:17.12
-1,0,-6:17.12
1,-9,-5:17.12
2,-9,-5:17.12
3,-9,-5:17.12
1,-8,-5:17.12
2,-8,-5:17.12
-2,-7,-5:17.12
2,-7,-5:17.12
-3,-6,-5:17.12
2,-6,-5:17.12
-3,-5,-5:17.12
-2,-5,-5:17.12
2,-3,-5:17.12
3,-3,-5:17.12
-2,-2,-5:17.12
-1,-2,-5:17.12
0,-2,-5:17.12
2,-2,-5:17.12
3,-2,-5:17.12
4,-2,-5:17.12
-2,-1,-5:17.12
-1,-1,-5:17.12
0,-1,-5:17.12
2,-1,-5:17.12
3,-1,-5:17.12
-2,0,-5:17.12
-1,0,-5:17.12
-1,-9,-4:17.12
1,-9,-4:17.12
-1,-8,-4:17.12
0,-8,-4:17.12
1,-8,-4:17.12
-2,-7,-4:17.12
1,-7,-4:17.12
2,-7,-4:17.12
3,-7,-4:17.12
-4,-6,-4:17.12
-2,-6,-4:17.12
-1,-6,-4:17.12
3,-6,-4:17.12
-3,-5,-4:17.12
-2,-5,-4:17.12
-1,-5,-4:17.12
4,-5,-4:17.12
4,-4,-4:17.12
-3,-3,-4:17.12
-1,-3,-4:17.12
0,-3,-4:17.12
2,-3,-4:17.12
3,-3,-4:17.12
4,-3,-4:17.12
-3,-2,-4:17.12
-2,-2,-4:17.12
-1,-2,-4:17.12
0,-2,-4:17.12
2,-2,-4:17.12
3,-2,-4:17.12
-3,-1,-4:17.12
-2,-1,-4:17.12
-1,-1,-4:17.12
0,-1,-4:17.12
1,-1,-4:17.12
2,-1,-4:17.12
3,-1,-4:17.12
-2,0,-4:17.12
-1,0,-4:17.12
0,0,-4:17.12
0,-9,-3:17.12
1,-9,-3:17.12
-1,-8,-3:17.12
0,-8,-3:17.12
1,-8,-3:17.12
2,-8,-3:17.12
3,-8,-3:17.12
-3,-7,-3:17.12
-1,-7,-3:17.12
1,-7,-3:17.12
2,-7,-3:17.12
3,-7,-3:17.12
-3,-6,-3:17.12
-2,-6,-3:17.12
2,-6,-3:17.12
3,-6,-3:17.12
4,-6,-3:17.12
-2,-5,-3:17.12
3,-4,-3:17.12
4,-4,-3:17.12
-2,-3,-3:17.12
3,-3,-3:17.12
4,-3,-3:17.12
-2,-2,-3:17.12
-1,-2,-3:17.12
0,-2,-3:17.12
1,-2,-3:17.12
2,-2,-3:17.12
3,-2,-3:17.12
4,-2,-3:17.12
-2,-1,-3:17.12
-1,-1,-3:17.12
0,-1,-3:17.12
1,-1,-3:17.12
3,-1,-3:17.12
-1,0,-3:17.12
0,-9,-2:17.12
1,-9,-2:17.12
2,-9,-2:17.12
-2,-8,-2:17.12
-1,-8,-2:17.12
0,-8,-2:17.12
1,-8,-2:17.12
2,-8,-2:17.12
3,-8,-2:17.12
-3,-7,-2:17.12
-2,-7,-2:17.12
-1,-7,-2:17.12
0,-7,-2:17.12
1,-7,-2:17.12
2,-7,-2:17.12
3,-7,-2:17.12
4,-7,-2:17.12
-3,-6,-2:17.12
-2,-6,-2:17.12
-1,-6,-2:17.12
0,-6,-2:17.12
1,-6,-2:17.12
2,-6,-2:17.12
3,-6,-2:17.12
4,-6,-2:17.12
-4,-5,-2:17.12
-3,-5,-2:17.12
-2,-5,-2:17.12
-1,-5,-2:17.12
0,-5,-2:17.12
1,-5,-2:17.12
2,-5,-2:17.12
3,-5,-2:17.12
4,-5,-2:17.12
-4,-4,-2:17.12
-3,-4,-2:17.12
-2,-4,-2:17.12
-1,-4,-2:17.12
0,-4,-2:17.12
1,-4,-2:17.12
2,-4,-2:17.12
3,-4,-2:17.12
4,-4,-2:17.12
5,-4,-2:17.12
-4,-3,-2:17.12
-3,-3,-2:17.12
-2,-3,-2:17.12
-1,-3,-2:17.12
0,-3,-2:17.12
1,-3,-2:17.12
2,-3,-2:17.12
3,-3,-2:17.12
4,-3,-2:17.12
-3,-2,-2:17.12
-2,-2,-2:17.12
-1,-2,-2:17.12
0,-2,-2:17.12
1,-2,-2:17.12
2,-2,-2:17.12
3,-2,-2:17.12
4,-2,-2:17.12
-3,-1,-2:17.12
-2,-1,-2:17.12
-1,-1,-2:17.12
0,-1,-2:17.12
1,-1,-2:17.12
2,-1,-2:17.12
3,-1,-2:17.12
4,-1,-2:17.12
-2,0,-2:17.12
-1,0,-2:17.12
0,0,-2:17.12
1,0,-2:17.12
2,0,-2:17.12
-1,-8,-1:17.12
0,-8,-1:17.12
1,-8,-1:17.12
2,-8,-1:17.12
3,-8,-1:17.12
-2,-7,-1:17.12
3,-7,-1:17.12
-3,-6,-1:17.12
-2,-6,-1:17.12
-1,-6,-1:17.12
3,-6,-1:17.12
4,-6,-1:17.12
-3,-5,-1:17.12
3,-5,-1:17.12
4,-5,-1:17.12
-3,-4,-1:17.12
2,-4,-1:17.12
4,-4,-1:17.12
-3,-3,-1:17.12
3,-3,-1:17.12
4,-3,-1:17.12
-3,-2,-1:17.12
-2,-2,-1:17.12
2,-2,-1:17.12
3,-2,-1:17.12
-2,-1,-1:17.12
-1,-1,-1:17.12
0,-1,-1:17.12
1,-1,-1:17.12
2,-1,-1:17.12
-1,0,-1:17.12
0,0,-1:17.12
-1,-8,0:17.12
0,-8,0:17.12
1,-8,0:17.12
2,-8,0:17.12
-2,-7,0:17.12
-1,-7,0:17.12
2,-7,0:17.12
3,-7,0:17.12
-3,-6,0:17.12
-2,-6,0:17.12
3,-6,0:17.12
4,-6,0:17.12
-3,-5,0:17.12
4,-5,0:17.12
-3,-4,0:17.12
3,-4,0:17.12
4,-4,0:17.12
-3,-3,0:17.12
3,-3,0:17.12
4,-3,0:17.12
-2,-2,0:17.12
2,-2,0:17.12
3,-2,0:17.12
-2,-1,0:17.12
-1,-1,0:17.12
0,-1,0:17.12
1,-1,0:17.12
2,-1,0:17.12
0,-8,1:17.12
1,-8,1:17.12
2,-8,1:17.12
-2,-7,1:17.12
-1,-7,1:17.12
0,-7,1:17.12
2,-7,1:17.12
3,-7,1:17.12
-3,-6,1:17.12
-2,-6,1:17.12
-1,-6,1:18.12
3,-6,1:17.12
-3,-5,1:17.12
3,-5,1:17.12
-3,-4,1:17.12
3,-4,1:17.12
-3,-3,1:17.12
-2,-3,1:17.12
3,-3,1:17.12
-2,-2,1:17.12
2,-2,1:17.12
3,-2,1:17.12
-1,-1,1:17.12
0,-1,1:17.12
1,-1,1:17.12
2,-1,1:17.12
-1,-7,2:17.12
0,-7,2:17.12
1,-7,2:17.12
2,-7,2:17.12
-2,-6,2:17.12
3,-6,2:17.12
-3,-5,2:17.12
-2,-5,2:17.12
3,-5,2:17.12
-3,-4,2:17.12
-2,-4,2:17.12
3,-4,2:17.12
-3,-3,2:17.12
-2,-3,2:17.12
3,-3,2:17.12
-2,-2,2:17.12
-1,-2,2:17.12
2,-2,2:17.12
-1,-1,2:17.12
0,-1,2:17.12
1,-1,2:17.12
6,-17,3:18.7
-1,-7,3:17.12
0,-7,3:17.12
1,-7,3:17.12
2,-7,3:17.12
-2,-6,3:17.12
-1,-6,3:17.12
2,-6,3:17.12
3,-6,3:17.12
-2,-5,3:17.12
3,-5,3:17.12
-2,-4,3:17.12
3,-4,3:17.12
-2,-3,3:17.12
2,-3,3:17.12
3,-3,3:17.12
-2,-2,3:17.12
-1,-2,3:17.12
0,-2,3:17.12
1,-2,3:17.12
2,-2,3:17.12
6,-17,4:18.7
-1,-7,4:17.12
0,-7,4:17.12
1,-7,4:17.12
2,-7,4:17.12
-2,-6,4:17.12
-1,-6,4:17.12
2,-6,4:17.12
3,-6,4:17.12
-2,-5,4:17.12
3,-5,4:17.12
-2,-4,4:17.12
3,-4,4:17.12
-2,-3,4:17.12
2,-3,4:17.12
3,-3,4:17.12
-1,-2,4:17.12
0,-2,4:17.12
1,-2,4:17.12
2,-2,4:17.12
5,-2,4:18.15
6,-17,5:18.7
3,-10,5:18.15
-1,-7,5:17.12
0,-7,5:17.12
1,-7,5:17.12
2,-7,5:17.12
-2,-6,5:17.12
-1,-6,5:17.12
2,-6,5:17.12
3,-6,5:17.12
-2,-5,5:17.12
3,-5,5:17.12
-2,-4,5:17.12
3,-4,5:17.12
-2,-3,5:17.12
2,-3,5:17.12
3,-3,5:17.12
-1,-2,5:17.12
0,-2,5:17.12
1,-2,5:17.12
2,-2,5:17.12
5,-2,5:18.15
6,-17,6:18.7
3,-11,6:18.15
2,-9,6:18.15
-1,-7,6:17.12
0,-7,6:17.12
1,-7,6:17.12
2,-7,6:17.12
-2,-6,6:17.12
-1,-6,6:17.12
2,-6,6:17.12
-2,-5,6:17.12
3,-5,6:17.12
-2,-4,6:17.12
3,-4,6:17.12
-2,-3,6:17.12
2,-3,6:17.12
-1,-2,6:17.12
0,-2,6:17.12
1,-2,6:17.12
4,-2,6:18.15
6,-1,6:18.15
7,-1,6:18.15
6,-17,7:18.7
4,-12,7:18.7
3,-11,7:18.15
2,-9,7:18.15
-6,-7,7:18.15
0,-7,7:17.12
1,-7,7:17.12
2,-7,7:17.12
-5,-6,7:18.15
-1,-6,7:17.12
2,-6,7:17.12
-2,-5,7:17.12
3,-5,7:17.12
-2,-4,7:17.12
2,-4,7:17.12
-2,-3,7:17.12
2,-3,7:17.12
-1,-2,7:17.12
0,-2,7:17.12
1,-2,7:17.12
5,-2,7:18.15
6,-1,7:18.15
7,-1,7:18.15
8,-1,7:18.7
7,0,7:18.15
8,0,7:18.7
6,-17,8:18.7
3,-12,8:18.7
4,-12,8:18.7
3,-10,8:18.15
2,-9,8:18.15
-6,-7,8:18.15
0,-7,8:17.12
1,-7,8:17.12
-5,-6,8:18.15
-4,-6,8:18.15
-1,-6,8:17.12
2,-6,8:17.12
-2,-5,8:17.12
2,-5,8:17.12
3,-5,8:17.12
-2,-4,8:17.12
2,-4,8:17.12
-2,-3,8:17.12
2,-3,8:17.12
4,-3,8:18.15
-1,-2,8:17.12
0,-2,8:17.12
1,-2,8:17.12
5,-2,8:18.15
6,-1,8:18.15
8,-1,8:18.7
7,0,8:18.15
8,0,8:18.7
6,-17,9:18.7
3,-12,9:18.7
3,-10,9:18.15
-7,-7,9:18.7
-6,-7,9:18.15
0,-7,9:17.12
1,-7,9:17.12
-4,-6,9:18.15
-1,-6,9:17.12
2,-6,9:17.12
-2,-5,9:17.12
2,-5,9:17.12
3,-5,9:17.12
-2,-4,9:17.12
2,-4,9:17.12
-2,-3,9:17.12
2,-3,9:17.12
-1,-2,9:17.12
0,-2,9:17.12
1,-2,9:17.12
5,-2,9:18.15
6,-2,9:18.15
6,-1,9:18.15
7,-1,9:18.15
8,-1,9:18.7
8,0,9:18.7
6,-17,10:18.7
3,-12,10:18.7
4,-12,10:18.7
3,-10,10:18.15
-6,-7,10:18.15
0,-7,10:17.12
1,-7,10:17.12
-4,-6,10:18.15
-1,-6,10:17.12
2,-6,10:17.12
-2,-5,10:17.12
3,-5,10:17.12
-2,-4,10:17.12
2,-4,10:17.12
-2,-3,10:17.12
2,-3,10:17.12
-1,-2,10:17.12
0,-2,10:17.12
1,-2,10:17.12
5,-2,10:18.15
6,-2,10:18.15
6,-1,10:18.15
7,-1,10:18.15
8,-1,10:18.7
7,0,10:18.15
8,0,10:18.7
6,-17,11:18.7
3,-12,11:18.7
4,-12,11:18.7
3,-11,11:18.15
3,-10,11:18.15
2,-9,11:18.15
2,-8,11:18.15
-7,-7,11:18.15
-6,-7,11:18.15
-1,-7,11:17.12
0,-7,11:17.12
1,-7,11:17.12
-5,-6,11:18.15
-4,-6,11:18.15
-2,-6,11:17.12
-1,-6,11:17.12
2,-6,11:17.12
-2,-5,11:17.12
3,-5,11:17.12
-2,-4,11:17.12
3,-4,11:17.12
-2,-3,11:17.12
2,-3,11:17.12
4,-3,11:18.15
-1,-2,11:17.12
0,-2,11:17.12
1,-2,11:17.12
5,-2,11:18.15
6,-2,11:18.15
6,-1,11:18.15
7,-1,11:18.15
8,-1,11:18.15
7,0,11:18.15
6,-17,12:18.7
3,-12,12:18.15
4,-12,12:18.15
3,-11,12:18.15
2,-9,12:18.15
2,-8,12:18.15
-1,-7,12:17.12
0,-7,12:17.12
1,-7,12:17.12
2,-7,12:17.12
-5,-6,12:18.15
-4,-6,12:18.15
-2,-6,12:17.12
-1,-6,12:17.12
2,-6,12:17.12
-2,-5,12:17.12
3,-5,12:17.12
-2,-4,12:17.12
3,-4,12:17.12
-2,-3,12:17.12
2,-3,12:17.12
3,-3,12:17.12
4,-3,12:18.15
-1,-2,12:17.12
0,-2,12:17.12
1,-2,12:17.12
2,-2,12:17.12
4,-2,12:18.15
5,-2,12:18.15
6,-2,12:18.15
6,-1,12:18.15
7,-1,12:18.15
9,0,12:18.15
6,-17,13:18.15
4,-12,13:18.15
7,-12,13:18.12
2,-9,13:18.15
-11,-8,13:18.4
2,-8,13:18.15
-10,-7,13:18.12
-9,-7,13:18.12
-7,-7,13:18.15
-6,-7,13:18.15
-1,-7,13:17.12
0,-7,13:17.12
1,-7,13:17.12
2,-7,13:17.12
-5,-6,13:18.15
-4,-6,13:18.15
-2,-6,13:17.12
-1,-6,13:17.12
2,-6,13:17.12
3,-6,13:17.12
-2,-5,13:17.12
3,-5,13:17.12
-2,-4,13:17.12
3,-4,13:17.12
-2,-3,13:17.12
0,-3,13:18.12
2,-3,13:17.12
3,-3,13:17.12
4,-3,13:18.15
-2,-2,13:17.12
-1,-2,13:17.12
0,-2,13:17.12
1,-2,13:17.12
2,-2,13:17.12
4,-2,13:18.15
5,-2,13:18.15
7,-1,13:18.15
8,0,13:18.15
9,0,13:18.15
-2,3,13:18.12
-3,4,13:18.12
-3,5,13:18.12
6,-17,14:18.15
4,-13,14:18.15
8,-13,14:18.12
4,-12,14:18.15
7,-12,14:18.12
3,-11,14:18.15
3,-10,14:18.15
5,-10,14:18.12
2,-9,14:18.15
4,-9,14:18.12
-13,-8,14:18.12
-12,-8,14:18.12
-11,-8,14:18.12
2,-8,14:18.15
3,-8,14:18.12
-10,-7,14:18.12
-9,-7,14:18.12
-8,-7,14:18.12
-7,-7,14:18.15
-6,-7,14:18.15
-1,-7,14:17.12
0,-7,14:17.12
1,-7,14:17.12
2,-7,14:17.12
-6,-6,14:18.12
-5,-6,14:18.15
-4,-6,14:18.15
-3,-6,14:17.12
-2,-6,14:17.12
1,-6,14:18.12
2,-6,14:17.12
3,-6,14:17.12
-5,-5,14:18.12
-4,-5,14:18.12
-3,-5,14:17.12
0,-5,14:18.12
3,-5,14:17.12
-4,-4,14:18.12
-3,-4,14:17.12
-2,-4,14:18.12
-1,-4,14:18.12
0,-4,14:18.12
1,-4,14:18.12
3,-4,14:17.12
4,-4,14:18.12
10,-4,14:18.12
-3,-3,14:17.12
-2,-3,14:17.12
-1,-3,14:18.12
0,-3,14:18.12
2,-3,14:18.12
3,-3,14:17.12
4,-3,14:18.12
8,-3,14:18.12
9,-3,14:18.12
10,-3,14:18.12
11,-3,14:18.12
12,-3,14:18.12
-4,-2,14:18.12
-3,-2,14:18.12
-2,-2,14:17.12
-1,-2,14:18.12
0,-2,14:18.12
1,-2,14:17.12
2,-2,14:17.12
3,-2,14:17.12
4,-2,14:18.15
5,-2,14:18.15
-5,-1,14:18.12
-4,-1,14:18.12
-1,-1,14:18.12
0,-1,14:18.12
1,-1,14:18.12
7,-1,14:18.15
-2,0,14:18.12
-1,0,14:18.12
0,0,14:18.12
1,0,14:18.12
7,0,14:18.15
8,0,14:18.15
9,0,14:18.15
-2,1,14:18.12
-1,1,14:18.12
1,1,14:18.12
2,1,14:18.12
-2,2,14:18.12
-1,2,14:18.12
1,2,14:18.12
2,2,14:18.12
-3,3,14:18.12
-2,3,14:18.12
-1,3,14:18.12
2,3,14:18.12
3,3,14:18.12
-3,4,14:18.12
-2,4,14:18.12
3,4,14:18.12
4,4,14:18.12
-4,5,14:18.12
-3,5,14:18.12
-2,5,14:18.12
3,5,14:18.12
4,5,14:18.12
-4,6,14:18.12
-3,6,14:18.12
2,6,14:18.12
4,6,14:18.12
2,7,14:18.12
2,8,14:18.12
3,-18,15:18.12
7,-18,15:18.12
2,-17,15:18.12
3,-17,15:18.12
6,-17,15:18.15
7,-17,15:18.12
2,-16,15:18.12
3,-16,15:18.12
7,-16,15:18.12
2,-15,15:18.12
7,-15,15:18.12
1,-14,15:18.12
2,-14,15:18.12
4,-14,15:18.12
5,-14,15:18.12
6,-14,15:18.12
7,-14,15:18.12
8,-14,15:18.12
9,-14,15:18.12
0,-13,15:18.12
1,-13,15:18.12
2,-13,15:18.12
4,-13,15:18.12
5,-13,15:18.12
6,-13,15:18.12
7,-13,15:18.12
8,-13,15:18.12
0,-12,15:18.12
1,-12,15:18.12
2,-12,15:18.12
4,-12,15:18.12
5,-12,15:18.12
6,-12,15:18.12
7,-12,15:18.12
0,-11,15:18.12
1,-11,15:18.12
3,-11,15:18.15
4,-11,15:18.12
5,-11,15:18.12
1,-10,15:18.12
3,-10,15:18.15
4,-10,15:18.12
5,-10,15:18.12
-14,-9,15:18.12
1,-9,15:18.12
2,-9,15:18.15
3,-9,15:18.12
4,-9,15:18.12
-13,-8,15:18.12
-12,-8,15:18.12
-11,-8,15:18.12
-10,-8,15:18.12
0,-8,15:18.12
1,-8,15:18.12
2,-8,15:18.12
3,-8,15:18.12
-10,-7,15:18.12
-9,-7,15:18.12
-8,-7,15:18.12
-7,-7,15:18.15
-6,-7,15:18.15
-2,-7,15:17.12
-1,-7,15:17.12
0,-7,15:17.12
1,-7,15:18.12
2,-7,15:18.12
-7,-6,15:18.12
-6,-6,15:18.12
-5,-6,15:18.12
-4,-6,15:18.12
-3,-6,15:17.12
-2,-6,15:17.12
0,-6,15:18.12
1,-6,15:18.12
2,-6,15:18.12
3,-6,15:17.12
-6,-5,15:18.12
-5,-5,15:18.12
-4,-5,15:18.12
-3,-5,15:18.12
-2,-5,15:18.12
-1,-5,15:18.12
0,-5,15:18.12
1,-5,15:18.12
2,-5,15:18.12
3,-5,15:17.12
-6,-4,15:18.12
-5,-4,15:18.12
-4,-4,15:18.12
-3,-4,15:17.12
-2,-4,15:18.12
-1,-4,15:18.12
0,-4,15:18.12
1,-4,15:18.12
2,-4,15:18.12
3,-4,15:18.12
4,-4,15:17.12
-4,-3,15:18.12
-2,-3,15:18.12
-1,-3,15:18.12
0,-3,15:18.12
2,-3,15:17.12
3,-3,15:18.12
4,-3,15:18.12
5,-3,15:18.12
6,-3,15:18.12
7,-3,15:18.12
8,-3,15:18.12
9,-3,15:18.12
10,-3,15:18.12
11,-3,15:18.12
-2,-2,15:18.12
-1,-2,15:18.12
0,-2,15:18.12
1,-2,15:18.12
2,-2,15:17.12
3,-2,15:17.12
4,-2,15:18.12
5,-2,15:18.12
6,-2,15:18.12
7,-2,15:18.12
8,-2,15:18.12
9,-2,15:18.12
10,-2,15:18.12
11,-2,15:18.12
12,-2,15:18.12
13,-2,15:18.12
-4,-1,15:18.12
-3,-1,15:18.12
-2,-1,15:18.12
-1,-1,15:17.12
0,-1,15:17.12
1,-1,15:17.12
2,-1,15:17.12
3,-1,15:18.12
4,-1,15:18.12
5,-1,15:18.12
6,-1,15:18.12
7,-1,15:18.15
-5,0,15:18.12
-4,0,15:18.12
-3,0,15:18.12
-2,0,15:18.12
-1,0,15:18.12
0,0,15:18.12
1,0,15:18.12
2,0,15:17.12
6,0,15:18.12
7,0,15:18.12
8,0,15:18.15
9,0,15:18.15
-5,1,15:18.12
-4,1,15:18.12
-3,1,15:18.12
-2,1,15:18.12
-1,1,15:18.12
0,1,15:18.12
1,1,15:18.12
2,1,15:18.12
3,1,15:18.12
7,1,15:18.12
8,1,15:18.12
9,1,15:18.12
-3,2,15:18.12
-2,2,15:18.12
-1,2,15:18.12
0,2,15:18.12
1,2,15:18.12
2,2,15:18.12
3,2,15:18.12
8,2,15:18.12
9,2,15:18.12
10,2,15:18.12
11,2,15:18.12
13,2,15:17.12
-3,3,15:18.12
-1,3,15:18.12
0,3,15:18.12
1,3,15:18.12
2,3,15:18.12
5,3,15:18.12
6,3,15:18.12
-4,4,15:18.12
-3,4,15:18.12
-2,4,15:18.12
-1,4,15:18.12
0,4,15:18.12
1,4,15:18.12
2,4,15:18.12
3,4,15:18.12
5,4,15:18.12
6,4,15:18.12
7,4,15:18.12
-4,5,15:18.12
-2,5,15:18.12
-1,5,15:18.12
0,5,15:18.12
1,5,15:18.12
2,5,15:18.12
3,5,15:18.12
6,5,15:18.12
7,5,15:18.12
-5,6,15:18.12
-4,6,15:18.12
-3,6,15:18.12
-2,6,15:18.12
-1,6,15:18.12
2,6,15:18.12
3,6,15:18.12
7,6,15:18.12
-5,7,15:18.12
-3,7,15:18.12
-2,7,15:18.12
-1,7,15:18.12
2,7,15:18.12
3,7,15:18.12
4,7,15:18.12
-8,8,15:18.12
-3,8,15:18.12
-2,8,15:18.12
3,8,15:18.12
4,8,15:18.12
-9,9,15:18.12
-3,9,15:18.12
3,9,15:18.12
4,9,15:18.12
-10,10,15:18.12
6,-19,16:18.12
4,-18,16:18.12
5,-18,16:18.12
6,-18,16:18.12
12,-18,16:18.12
3,-17,16:18.12
4,-17,16:18.12
5,-17,16:18.12
6,-17,16:18.12
3,-16,16:18.12
4,-16,16:18.12
5,-16,16:18.12
6,-16,16:18.12
3,-15,16:18.12
4,-15,16:18.12
5,-15,16:18.12
6,-15,16:18.12
9,-15,16:18.12
3,-14,16:18.12
4,-14,16:18.12
5,-14,16:18.12
6,-14,16:18.12
8,-14,16:18.12
9,-14,16:18.12
2,-13,16:18.12
3,-13,16:18.12
4,-13,16:18.12
5,-13,16:18.12
6,-13,16:18.12
7,-13,16:18.12
8,-13,16:18.12
2,-12,16:18.12
3,-12,16:18.12
4,-12,16:18.12
5,-12,16:18.12
6,-12,16:18.12
7,-12,16:18.12
0,-11,16:18.12
2,-11,16:18.12
3,-11,16:18.12
5,-11,16:18.12
-1,-10,16:18.12
0,-10,16:18.12
1,-10,16:18.12
2,-10,16:18.12
3,-10,16:17.12
4,-10,16:18.12
5,-10,16:18.12
-14,-9,16:18.12
-13,-9,16:18.12
-5,-9,16:18.12
-1,-9,16:18.12
0,-9,16:18.12
1,-9,16:18.12
2,-9,16:17.12
3,-9,16:18.12
4,-9,16:18.12
5,-9,16:18.12
-13,-8,16:18.12
-12,-8,16:18.12
-11,-8,16:18.12
-10,-8,16:18.12
-6,-8,16:18.12
-5,-8,16:18.12
-4,-8,16:18.12
-3,-8,16:18.12
-1,-8,16:18.12
0,-8,16:18.12
1,-8,16:17.12
2,-8,16:18.12
3,-8,16:18.12
4,-8,16:18.12
-10,-7,16:18.12
-9,-7,16:18.12
-8,-7,16:18.12
-7,-7,16:18.15
-6,-7,16:18.12
-5,-7,16:18.12
-4,-7,16:18.12
-3,-7,16:18.12
-2,-7,16:18.12
-1,-7,16:18.12
0,-7,16:17.12
1,-7,16:18.12
2,-7,16:18.12
3,-7,16:18.12
4,-7,16:18.12
-7,-6,16:18.12
-6,-6,16:18.12
-5,-6,16:18.12
-4,-6,16:18.12
-3,-6,16:17.12
-2,-6,16:18.12
-1,-6,16:18.12
0,-6,16:18.12
2,-6,16:18.12
3,-6,16:18.12
4,-6,16:18.12
-5,-5,16:18.12
-4,-5,16:17.12
-3,-5,16:18.12
-1,-5,16:18.12
0,-5,16:18.12
1,-5,16:18.12
2,-5,16:18.12
3,-5,16:18.12
4,-5,16:18.12
-7,-4,16:18.12
-6,-4,16:18.12
-5,-4,16:18.12
-4,-4,16:18.12
-3,-4,16:17.12
-1,-4,16:18.12
0,-4,16:18.12
1,-4,16:18.12
2,-4,16:18.12
3,-4,16:18.12
4,-4,16:18.12
5,-4,16:18.12
6,-4,16:18.12
-6,-3,16:18.12
-5,-3,16:18.12
-4,-3,16:18.12
-3,-3,16:17.12
-2,-3,16:18.12
-1,-3,16:18.12
0,-3,16:18.12
2,-3,16:17.12
4,-3,16:17.12
5,-3,16:18.12
6,-3,16:18.12
7,-3,16:18.12
-4,-2,16:18.12
-3,-2,16:18.12
-2,-2,16:18.12
-1,-2,16:18.12
0,-2,16:18.12
1,-2,16:18.12
2,-2,16:17.12
3,-2,16:17.12
4,-2,16:17.12
5,-2,16:17.12
6,-2,16:18.12
7,-2,16:18.12
8,-2,16:18.12
9,-2,16:18.12
10,-2,16:18.12
11,-2,16:18.12
-4,-1,16:18.12
-3,-1,16:18.12
-2,-1,16:17.12
-1,-1,16:18.12
0,-1,16:17.12
1,-1,16:17.12
2,-1,16:17.12
3,-1,16:18.12
4,-1,16:18.12
5,-1,16:17.12
6,-1,16:17.12
7,-1,16:17.12
8,-1,16:18.12
9,-1,16:18.12
10,-1,16:18.12
11,-1,16:18.12
12,-1,16:18.12
13,-1,16:18.12
-4,0,16:18.12
-3,0,16:18.12
-2,0,16:18.12
-1,0,16:17.12
1,0,16:17.12
2,0,16:17.12
3,0,16:17.12
4,0,16:18.12
5,0,16:18.12
6,0,16:18.12
7,0,16:18.15
8,0,16:18.12
9,0,16:18.12
10,0,16:18.12
11,0,16:18.12
12,0,16:18.12
-5,1,16:18.12
-4,1,16:18.12
-3,1,16:18.12
-2,1,16:17.12
-1,1,16:17.12
0,1,16:18.12
1,1,16:17.12
2,1,16:17.12
3,1,16:17.12
5,1,16:18.12
8,1,16:18.12
9,1,16:18.12
10,1,16:18.12
11,1,16:18.12
12,1,16:17.12
-6,2,16:18.12
-5,2,16:18.12
-4,2,16:18.12
-3,2,16:18.12
-2,2,16:18.12
-1,2,16:18.12
0,2,16:18.12
2,2,16:17.12
3,2,16:17.12
4,2,16:18.12
10,2,16:18.12
11,2,16:18.12
12,2,16:17.12
13,2,16:17.12
-6,3,16:18.12
-5,3,16:18.12
-4,3,16:18.12
-3,3,16:18.12
-2,3,16:18.12
-1,3,16:18.12
0,3,16:18.12
2,3,16:17.12
3,3,16:17.12
4,3,16:18.12
-6,4,16:18.12
-5,4,16:18.12
-4,4,16:17.12
-3,4,16:18.12
-2,4,16:18.12
0,4,16:18.12
3,4,16:18.12
4,4,16:18.12
5,4,16:18.12
-7,5,16:18.12
-6,5,16:18.12
-5,5,16:18.12
-4,5,16:18.12
-3,5,16:18.12
0,5,16:18.12
1,5,16:18.12
3,5,16:18.12
4,5,16:18.12
5,5,16:18.12
6,5,16:18.12
-7,6,16:18.12
-6,6,16:18.12
-5,6,16:18.12
-4,6,16:18.12
-3,6,16:18.12
0,6,16:18.12
1,6,16:18.12
4,6,16:18.12
5,6,16:18.12
6,6,16:18.12
7,6,16:18.12
-8,7,16:18.12
-7,7,16:18.12
-6,7,16:18.12
-5,7,16:18.12
-3,7,16:18.12
-1,7,16:18.12
0,7,16:18.12
1,7,16:18.12
2,7,16:18.12
4,7,16:18.12
5,7,16:18.12
6,7,16:18.12
7,7,16:18.12
-8,8,16:18.12
-7,8,16:18.12
-3,8,16:18.12
-1,8,16:18.12
0,8,16:18.12
1,8,16:18.12
2,8,16:18.12
3,8,16:18.12
4,8,16:18.12
5,8,16:18.12
6,8,16:18.12
7,8,16:18.12
8,8,16:18.12
-9,9,16:18.12
-8,9,16:18.12
-3,9,16:18.12
-2,9,16:18.12
-1,9,16:18.12
0,9,16:18.12
3,9,16:18.12
5,9,16:18.12
6,9,16:18.12
7,9,16:18.12
8,9,16:18.12
-10,10,16:18.12
-9,10,16:18.12
-3,10,16:18.12
-11,11,16:18.12
4,-21,17:18.12
5,-21,17:18.12
13,-21,17:18.12
14,-21,17:18.4
4,-20,17:18.12
5,-20,17:18.12
12,-20,17:18.12
13,-20,17:18.12
14,-20,17:18.4
4,-19,17:18.12
5,-19,17:18.12
6,-19,17:18.12
10,-19,17:18.12
11,-19,17:18.12
12,-19,17:18.12
-4,-18,17:18.4
4,-18,17:18.12
5,-18,17:18.12
10,-18,17:18.12
11,-18,17:18.12
-4,-17,17:18.4
-3,-17,17:18.4
-2,-17,17:18.4
4,-17,17:18.12
5,-17,17:18.12
6,-17,17:18.15
-4,-16,17:18.4
-3,-16,17:18.4
-2,-16,17:18.4
-1,-16,17:18.4
3,-16,17:18.12
4,-16,17:18.12
5,-16,17:18.12
-1,-15,17:18.12
3,-15,17:18.12
4,-15,17:18.12
5,-15,17:17.12
9,-15,17:18.12
0,-14,17:18.12
1,-14,17:18.12
3,-14,17:18.12
4,-14,17:17.12
5,-14,17:17.12
8,-14,17:18.12
1,-13,17:18.12
2,-13,17:18.12
3,-13,17:18.12
4,-13,17:17.12
5,-13,17:17.12
7,-13,17:18.12
2,-12,17:18.12
3,-12,17:18.12
4,-12,17:17.12
6,-12,17:18.12
7,-12,17:18.12
-1,-11,17:18.12
0,-11,17:18.12
1,-11,17:18.12
2,-11,17:17.12
3,-11,17:18.12
4,-11,17:18.12
5,-11,17:18.12
-5,-10,17:18.12
-4,-10,17:18.12
-3,-10,17:18.12
-2,-10,17:18.12
-1,-10,17:18.12
0,-10,17:18.12
1,-10,17:18.12
2,-10,17:17.12
3,-10,17:17.12
4,-10,17:18.12
5,-10,17:18.12
6,-10,17:18.12
-7,-9,17:18.12
-6,-9,17:18.12
-5,-9,17:18.12
-4,-9,17:18.12
-3,-9,17:18.12
-2,-9,17:18.12
-1,-9,17:18.12
1,-9,17:17.12
2,-9,17:18.12
3,-9,17:17.12
4,-9,17:18.12
5,-9,17:18.12
6,-9,17:18.12
-13,-8,17:18.12
-12,-8,17:18.12
-11,-8,17:18.12
-10,-8,17:18.12
-9,-8,17:18.12
-8,-8,17:18.12
-7,-8,17:18.12
-6,-8,17:18.12
-5,-8,17:18.12
-4,-8,17:18.12
-3,-8,17:18.12
-2,-8,17:18.12
-1,-8,17:18.12
1,-8,17:17.12
2,-8,17:17.12
3,-8,17:17.12
4,-8,17:18.12
5,-8,17:18.12
6,-8,17:18.12
-10,-7,17:18.12
-9,-7,17:18.12
-8,-7,17:18.12
-7,-7,17:18.12
-6,-7,17:17.12
-5,-7,17:17.12
-4,-7,17:17.12
-3,-7,17:17.12
-2,-7,17:17.12
-1,-7,17:17.12
0,-7,17:17.12
1,-7,17:17.12
2,-7,17:17.12
3,-7,17:17.12
4,-7,17:18.12
5,-7,17:18.12
6,-7,17:18.12
-9,-6,17:18.12
-8,-6,17:18.12
-7,-6,17:18.12
-6,-6,17:17.12
-5,-6,17:17.12
-4,-6,17:17.12
-3,-6,17:17.12
-2,-6,17:17.12
-1,-6,17:18.12
2,-6,17:17.12
3,-6,17:17.12
4,-6,17:18.12
5,-6,17:18.12
-8,-5,17:18.12
-7,-5,17:18.12
-6,-5,17:18.12
-5,-5,17:17.12
-4,-5,17:17.12
-3,-5,17:17.12
-2,-5,17:17.12
-1,-5,17:18.12
0,-5,17:18.12
2,-5,17:18.12
3,-5,17:17.12
4,-5,17:17.12
5,-5,17:18.12
6,-5,17:18.12
-7,-4,17:18.12
-6,-4,17:18.12
-5,-4,17:18.12
-4,-4,17:17.12
-3,-4,17:17.12
-2,-4,17:17.12
-1,-4,17:18.12
0,-4,17:18.12
1,-4,17:18.12
2,-4,17:18.12
3,-4,17:18.12
4,-4,17:17.12
5,-4,17:18.12
6,-4,17:18.12
7,-4,17:18.12
8,-4,17:18.12
-7,-3,17:18.12
-6,-3,17:18.12
-5,-3,17:18.12
-4,-3,17:17.12
-3,-3,17:17.12
-2,-3,17:17.12
-1,-3,17:18.12
0,-3,17:18.12
2,-3,17:18.12
3,-3,17:17.12
4,-3,17:17.12
5,-3,17:17.12
6,-3,17:18.12
7,-3,17:18.12
8,-3,17:18.12
-8,-2,17:18.12
-7,-2,17:18.12
-6,-2,17:18.12
-5,-2,17:18.12
-4,-2,17:18.12
-3,-2,17:17.12
-2,-2,17:17.12
-1,-2,17:18.12
0,-2,17:18.12
1,-2,17:18.12
2,-2,17:17.12
3,-2,17:17.12
4,-2,17:17.12
5,-2,17:17.12
6,-2,17:17.12
7,-2,17:18.12
8,-2,17:18.12
9,-2,17:18.12
10,-2,17:18.12
-6,-1,17:18.15
-5,-1,17:18.12
-4,-1,17:18.12
-3,-1,17:18.12
-2,-1,17:18.12
-1,-1,17:17.12
0,-1,17:17.12
1,-1,17:18.12
2,-1,17:18.12
3,-1,17:17.12
4,-1,17:17.12
5,-1,17:17.12
6,-1,17:17.12
7,-1,17:17.12
8,-1,17:17.12
9,-1,17:17.12
10,-1,17:18.12
11,-1,17:18.12
12,-1,17:18.12
-5,0,17:18.12
-4,0,17:18.12
-3,0,17:18.12
-2,0,17:18.12
-1,0,17:17.12
0,0,17:18.12
2,0,17:18.12
3,0,17:18.12
4,0,17:18.12
5,0,17:17.12
6,0,17:18.12
7,0,17:18.12
8,0,17:17.12
9,0,17:17.12
10,0,17:17.12
11,0,17:17.12
-6,1,17:18.12
-5,1,17:18.12
-4,1,17:18.12
-3,1,17:18.12
-2,1,17:17.12
-1,1,17:18.12
0,1,17:18.12
2,1,17:17.12
3,1,17:18.12
5,1,17:18.12
6,1,17:18.12
7,1,17:18.12
8,1,17:18.12
9,1,17:17.12
10,1,17:17.12
11,1,17:17.12
12,1,17:17.12
-7,2,17:18.12
-6,2,17:18.12
-5,2,17:18.12
-4,2,17:17.12
-3,2,17:18.12
-2,2,17:17.12
-1,2,17:18.12
0,2,17:18.12
1,2,17:17.12
2,2,17:17.12
3,2,17:17.12
4,2,17:18.12
5,2,17:18.12
6,2,17:18.12
7,2,17:18.12
8,2,17:18.12
9,2,17:18.12
10,2,17:18.12
11,2,17:18.12
12,2,17:18.12
13,2,17:18.12
-7,3,17:18.12
-6,3,17:18.12
-5,3,17:18.12
-4,3,17:17.12
-3,3,17:18.12
-2,3,17:17.12
0,3,17:18.12
2,3,17:17.12
3,3,17:17.12
4,3,17:17.12
5,3,17:18.12
6,3,17:18.12
7,3,17:18.12
8,3,17:18.12
9,3,17:18.12
10,3,17:18.12
11,3,17:18.12
12,3,17:18.12
13,3,17:18.12
14,3,17:18.12
-7,4,17:18.12
-6,4,17:18.12
-5,4,17:17.12
-4,4,17:17.12
-3,4,17:18.12
-2,4,17:18.12
-1,4,17:18.12
0,4,17:18.12
2,4,17:17.12
3,4,17:17.12
4,4,17:17.12
5,4,17:18.12
6,4,17:18.12
7,4,17:18.12
8,4,17:18.12
12,4,17:18.12
13,4,17:18.12
14,4,17:18.12
15,4,17:18.12
16,4,17:18.12
-7,5,17:18.12
-6,5,17:18.12
-5,5,17:17.12
-4,5,17:17.12
-3,5,17:18.12
-2,5,17:18.12
-1,5,17:18.12
1,5,17:18.12
3,5,17:17.12
4,5,17:18.12
6,5,17:18.12
7,5,17:18.12
12,5,17:18.12
13,5,17:18.12
15,5,17:18.12
16,5,17:18.12
-8,6,17:18.12
-7,6,17:18.12
-6,6,17:18.12
-5,6,17:17.12
-4,6,17:17.12
-3,6,17:18.12
-2,6,17:18.12
1,6,17:18.12
4,6,17:18.12
7,6,17:18.12
8,6,17:18.12
11,6,17:18.12
12,6,17:18.12
13,6,17:18.12
-9,7,17:18.12
-8,7,17:18.12
-7,7,17:18.12
-6,7,17:18.12
-5,7,17:18.12
-4,7,17:18.12
-3,7,17:18.12
-2,7,17:18.12
1,7,17:18.12
4,7,17:18.12
7,7,17:18.12
9,7,17:18.12
12,7,17:18.4
13,7,17:18.4
-8,8,17:18.12
-7,8,17:18.12
-3,8,17:18.12
1,8,17:18.12
5,8,17:18.12
8,8,17:18.12
9,8,17:18.12
-9,9,17:18.12
-8,9,17:18.12
-3,9,17:18.12
-2,9,17:18.12
0,9,17:18.12
1,9,17:18.12
5,9,17:18.12
9,9,17:18.12
10,9,17:18.12
-10,10,17:18.12
-9,10,17:18.12
-3,10,17:18.12
0,10,17:18.12
10,10,17:18.12
-11,11,17:18.12
-10,11,17:18.12
-3,11,17:18.12
-2,11,17:18.12
-11,12,17:18.12
-3,12,17:18.12
-2,12,17:18.12
7,-25,18:18.12
8,-25,18:18.12
7,-24,18:18.12
8,-24,18:18.12
3,-23,18:18.12
4,-23,18:18.12
7,-23,18:18.12
14,-23,18:18.12
15,-23,18:18.4
3,-22,18:18.12
4,-22,18:18.12
12,-22,18:18.12
13,-22,18:18.12
14,-22,18:18.12
-4,-21,18:18.4
3,-21,18:18.12
4,-21,18:18.12
7,-21,18:18.12
11,-21,18:18.12
12,-21,18:18.12
13,-21,18:18.12
-4,-20,18:18.4
-3,-20,18:18.4
2,-20,18:18.12
3,-20,18:18.12
4,-20,18:18.12
7,-20,18:18.12
9,-20,18:18.12
10,-20,18:18.12
11,-20,18:18.12
12,-20,18:18.12
-4,-19,18:18.4
-3,-19,18:18.4
-2,-19,18:18.4
2,-19,18:18.12
3,-19,18:18.12
7,-19,18:17.12
8,-19,18:18.12
9,-19,18:18.12
10,-19,18:18.12
-4,-18,18:18.4
-3,-18,18:18.4
-2,-18,18:18.4
-1,-18,18:18.4
2,-18,18:18.12
3,-18,18:18.12
5,-18,18:18.12
6,-18,18:18.12
7,-18,18:18.12
8,-18,18:18.12
-2,-17,18:18.4
-1,-17,18:18.4
0,-17,18:18.12
1,-17,18:18.12
2,-17,18:18.12
3,-17,18:18.12
5,-17,18:18.12
6,-17,18:17.12
7,-17,18:18.12
-1,-16,18:18.4
0,-16,18:18.12
1,-16,18:18.12
2,-16,18:18.12
3,-16,18:18.12
4,-16,18:18.12
5,-16,18:17.12
6,-16,18:17.12
-2,-15,18:18.12
0,-15,18:18.12
1,-15,18:18.12
2,-15,18:18.12
4,-15,18:18.12
5,-15,18:17.12
6,-15,18:18.12
7,-15,18:18.12
-2,-14,18:18.12
-1,-14,18:18.12
1,-14,18:18.12
2,-14,18:18.12
3,-14,18:18.12
4,-14,18:18.12
5,-14,18:17.12
6,-14,18:18.12
7,-14,18:18.12
8,-14,18:18.12
9,-14,18:18.12
-2,-13,18:18.12
-1,-13,18:18.12
0,-13,18:18.12
1,-13,18:18.12
2,-13,18:18.12
3,-13,18:18.12
4,-13,18:17.12
5,-13,18:18.12
6,-13,18:18.12
7,-13,18:18.12
9,-13,18:18.12
10,-13,18:18.12
-7,-12,18:18.12
-6,-12,18:18.12
-5,-12,18:18.12
-2,-12,18:18.12
-1,-12,18:18.12
0,-12,18:18.12
1,-12,18:18.12
2,-12,18:18.12
3,-12,18:18.12
4,-12,18:18.12
5,-12,18:18.12
6,-12,18:18.12
7,-12,18:18.12
8,-12,18:18.12
9,-12,18:18.12
-8,-11,18:18.12
-7,-11,18:18.12
-6,-11,18:18.12
-5,-11,18:18.12
-4,-11,18:18.12
-3,-11,18:18.12
-2,-11,18:18.12
-1,-11,18:18.12
3,-11,18:18.12
4,-11,18:17.12
5,-11,18:18.12
7,-11,18:18.12
8,-11,18:18.12
-12,-10,18:18.12
-11,-10,18:18.12
-10,-10,18:18.12
-9,-10,18:18.12
-8,-10,18:18.12
-7,-10,18:18.12
-6,-10,18:18.12
-5,-10,18:18.12
-4,-10,18:18.12
-3,-10,18:18.12
-2,-10,18:18.12
2,-10,18:18.12
4,-10,18:18.12
5,-10,18:18.12
6,-10,18:18.12
7,-10,18:18.12
8,-10,18:18.12
-14,-9,18:18.12
-13,-9,18:18.12
-12,-9,18:18.12
-11,-9,18:18.12
-10,-9,18:18.12
-9,-9,18:18.12
-8,-9,18:18.12
-7,-9,18:18.12
-6,-9,18:18.12
-4,-9,18:18.12
-3,-9,18:18.12
-2,-9,18:18.12
2,-9,18:18.12
4,-9,18:18.12
5,-9,18:18.12
6,-9,18:18.12
7,-9,18:18.12
-14,-8,18:18.12
-13,-8,18:18.12
-12,-8,18:18.12
-11,-8,18:18.12
-10,-8,18:18.12
-9,-8,18:17.12
-8,-8,18:17.12
-7,-8,18:17.12
-6,-8,18:17.12
-2,-8,18:18.12
-1,-8,18:18.12
4,-8,18:18.12
5,-8,18:18.12
6,-8,18:18.12
7,-8,18:18.12
-13,-7,18:18.12
-12,-7,18:18.12
-11,-7,18:18.12
-10,-7,18:18.12
-9,-7,18:18.12
-8,-7,18:17.12
-7,-7,18:17.12
-6,-7,18:17.12
-5,-7,18:17.12
-3,-7,18:18.12
-2,-7,18:18.12
-1,-7,18:18.12
4,-7,18:17.12
5,-7,18:18.12
6,-7,18:18.12
7,-7,18:18.12
-12,-6,18:18.12
-11,-6,18:18.12
-10,-6,18:18.12
-9,-6,18:18.12
-8,-6,18:18.12
-7,-6,18:18.12
-6,-6,18:17.12
-5,-6,18:18.12
-2,-6,18:18.12
-1,-6,18:17.12
0,-6,18:17.12
1,-6,18:17.12
2,-6,18:17.12
3,-6,18:17.12
4,-6,18:17.12
5,-6,18:18.12
6,-6,18:18.12
7,-6,18:18.12
8,-6,18:18.12
10,-6,18:18.12
11,-6,18:18.12
12,-6,18:18.12
-11,-5,18:18.12
-10,-5,18:18.12
-9,-5,18:18.12
-8,-5,18:18.12
-7,-5,18:18.12
-6,-5,18:18.12
-2,-5,18:18.12
-1,-5,18:17.12
0,-5,18:17.12
1,-5,18:17.12
2,-5,18:17.12
3,-5,18:18.12
4,-5,18:18.12
5,-5,18:17.12
6,-5,18:18.12
7,-5,18:18.12
8,-5,18:18.12
9,-5,18:18.12
10,-5,18:18.12
11,-5,18:18.12
-10,-4,18:18.12
-8,-4,18:18.12
-7,-4,18:18.12
-3,-4,18:17.12
-2,-4,18:17.12
-1,-4,18:17.12
0,-4,18:17.12
1,-4,18:18.12
2,-4,18:17.12
3,-4,18:17.12
4,-4,18:17.12
7,-4,18:18.12
8,-4,18:18.12
9,-4,18:18.12
10,-4,18:18.12
11,-4,18:18.12
-9,-3,18:18.12
-7,-3,18:18.12
-5,-3,18:17.12
-4,-3,18:17.12
-3,-3,18:17.12
-2,-3,18:17.12
-1,-3,18:18.12
0,-3,18:18.12
2,-3,18:18.12
3,-3,18:18.12
4,-3,18:18.12
8,-3,18:18.12
9,-3,18:18.12
10,-3,18:18.12
-8,-2,18:18.12
-7,-2,18:18.12
-6,-2,18:18.12
-5,-2,18:18.12
-4,-2,18:18.12
-3,-2,18:17.12
-2,-2,18:18.12
-1,-2,18:18.12
0,-2,18:17.12
1,-2,18:17.12
5,-2,18:18.12
6,-2,18:18.12
7,-2,18:18.12
8,-2,18:18.12
9,-2,18:18.12
10,-2,18:18.12
11,-2,18:18.12
-10,-1,18:18.12
-9,-1,18:18.12
-8,-1,18:18.12
-7,-1,18:18.12
-6,-1,18:18.12
-5,-1,18:18.12
-4,-1,18:17.12
-3,-1,18:18.12
-2,-1,18:18.12
1,-1,18:18.12
2,-1,18:18.12
3,-1,18:18.12
6,-1,18:18.12
7,-1,18:18.12
8,-1,18:18.12
9,-1,18:18.12
10,-1,18:18.12
11,-1,18:18.12
12,-1,18:18.12
14,-1,18:18.12
15,-1,18:18.12
16,-1,18:18.12
17,-1,18:18.12
-10,0,18:18.12
-9,0,18:18.12
-8,0,18:18.12
-7,0,18:18.12
-6,0,18:18.12
-3,0,18:18.12
-2,0,18:18.12
1,0,18:18.12
3,0,18:18.12
4,0,18:18.12
7,0,18:18.12
8,0,18:17.12
9,0,18:17.12
10,0,18:17.12
11,0,18:18.12
12,0,18:18.12
13,0,18:18.12
14,0,18:18.12
15,0,18:18.12
16,0,18:18.12
-8,1,18:18.12
-7,1,18:18.12
-6,1,18:18.12
-4,1,18:18.12
-3,1,18:18.12
0,1,18:18.12
1,1,18:18.12
2,1,18:18.12
3,1,18:18.12
5,1,18:18.12
7,1,18:18.12
8,1,18:18.12
9,1,18:17.12
10,1,18:17.12
11,1,18:18.12
12,1,18:18.12
-8,2,18:18.12
-7,2,18:18.12
-6,2,18:18.12
-5,2,18:18.12
-4,2,18:18.12
-1,2,18:18.12
0,2,18:18.12
1,2,18:18.12
2,2,18:18.12
3,2,18:18.12
4,2,18:18.12
8,2,18:18.12
9,2,18:18.12
12,2,18:18.12
13,2,18:18.12
-8,3,18:18.12
-7,3,18:18.12
-6,3,18:18.12
-5,3,18:18.12
-4,3,18:18.12
-1,3,18:18.12
0,3,18:18.12
3,3,18:18.12
4,3,18:18.12
5,3,18:18.12
6,3,18:18.12
8,3,18:18.12
9,3,18:18.12
10,3,18:18.12
11,3,18:18.12
12,3,18:18.12
13,3,18:18.12
14,3,18:18.12
-8,4,18:18.12
-7,4,18:18.12
-6,4,18:18.12
-4,4,18:18.12
-3,4,18:18.12
-2,4,18:18.12
-1,4,18:18.12
0,4,18:18.12
1,4,18:18.12
2,4,18:17.12
3,4,18:17.12
4,4,18:17.12
6,4,18:18.12
7,4,18:18.12
8,4,18:18.12
9,4,18:18.12
10,4,18:18.12
11,4,18:18.12
12,4,18:18.12
13,4,18:18.12
14,4,18:18.12
15,4,18:18.12
-8,5,18:18.12
-7,5,18:18.12
-6,5,18:17.12
-5,5,18:18.12
-4,5,18:18.12
-3,5,18:18.12
-2,5,18:18.12
-1,5,18:18.12
1,5,18:18.12
3,5,18:17.12
4,5,18:17.12
5,5,18:18.12
8,5,18:18.12
9,5,18:18.12
10,5,18:18.12
11,5,18:18.12
12,5,18:18.12
13,5,18:18.12
14,5,18:18.12
15,5,18:18.12
16,5,18:18.12
-9,6,18:18.12
-8,6,18:18.12
-7,6,18:18.12
-6,6,18:17.12
-5,6,18:17.12
-4,6,18:17.12
-3,6,18:18.12
-2,6,18:18.12
1,6,18:18.12
4,6,18:18.12
5,6,18:18.12
8,6,18:18.12
9,6,18:18.12
10,6,18:18.12
11,6,18:18.12
12,6,18:18.12
13,6,18:18.12
14,6,18:18.12
15,6,18:18.12
16,6,18:18.12
-10,7,18:18.12
-9,7,18:18.12
-8,7,18:18.12
-7,7,18:18.12
-6,7,18:17.12
-5,7,18:17.12
-4,7,18:18.12
-3,7,18:18.12
1,7,18:18.12
4,7,18:18.12
9,7,18:18.12
10,7,18:18.12
13,7,18:18.12
14,7,18:18.12
-8,8,18:18.12
-7,8,18:18.12
-6,8,18:18.12
-5,8,18:18.12
-3,8,18:18.12
-2,8,18:18.12
1,8,18:18.12
4,8,18:18.12
5,8,18:18.12
10,8,18:18.12
13,8,18:18.4
-9,9,18:18.12
-8,9,18:18.12
-7,9,18:18.12
-6,9,18:18.12
-3,9,18:18.12
-2,9,18:18.12
1,9,18:18.12
5,9,18:18.12
10,9,18:18.12
11,9,18:18.4
-9,10,18:18.12
-8,10,18:18.12
-7,10,18:18.12
-6,10,18:18.12
-3,10,18:18.12
5,10,18:18.12
8,10,18:18.12
-10,11,18:18.12
-3,11,18:18.12
-2,11,18:18.12
5,11,18:18.12
8,11,18:18.12
-3,12,18:18.12
-2,12,18:18.12
-2,13,18:18.12
-1,13,18:18.4
9,-26,19:18.12
10,-26,19:18.12
11,-26,19:18.12
8,-25,19:18.12
9,-25,19:18.12
10,-25,19:18.12
11,-25,19:18.12
14,-25,19:18.12
1,-24,19:18.4
2,-24,19:18.4
8,-24,19:18.12
9,-24,19:18.12
10,-24,19:18.12
11,-24,19:18.12
13,-24,19:18.12
14,-24,19:18.12
1,-23,19:18.4
2,-23,19:18.12
7,-23,19:18.12
8,-23,19:18.12
9,-23,19:18.12
10,-23,19:18.12
11,-23,19:18.12
12,-23,19:18.12
13,-23,19:18.12
14,-23,19:18.12
-4,-22,19:18.4
-3,-22,19:18.4
1,-22,19:18.4
2,-22,19:18.12
7,-22,19:18.12
8,-22,19:18.12
9,-22,19:18.12
10,-22,19:18.12
11,-22,19:18.12
12,-22,19:18.12
-4,-21,19:18.4
-3,-21,19:18.4
-2,-21,19:18.4
-1,-21,19:18.4
1,-21,19:18.4
2,-21,19:18.12
6,-21,19:18.12
7,-21,19:18.12
8,-21,19:17.12
9,-21,19:18.12
10,-21,19:18.12
11,-21,19:18.12
-3,-20,19:18.4
-2,-20,19:18.4
-1,-20,19:18.4
0,-20,19:18.4
2,-20,19:18.12
5,-20,19:18.12
6,-20,19:18.12
7,-20,19:17.12
8,-20,19:18.12
9,-20,19:18.12
-2,-19,19:18.4
-1,-19,19:18.4
0,-19,19:18.4
1,-19,19:18.12
2,-19,19:18.12
5,-19,19:18.12
6,-19,19:17.12
7,-19,19:17.12
8,-19,19:18.12
0,-18,19:18.12
1,-18,19:18.12
2,-18,19:18.12
3,-18,19:18.12
4,-18,19:18.12
5,-18,19:18.12
6,-18,19:17.12
7,-18,19:18.12
8,-18,19:18.12
1,-17,19:18.12
2,-17,19:18.12
3,-17,19:18.12
4,-17,19:18.12
5,-17,19:18.12
6,-17,19:17.12
7,-17,19:18.12
8,-17,19:18.12
-3,-16,19:18.4
0,-16,19:18.12
1,-16,19:18.12
2,-16,19:18.12
4,-16,19:18.12
5,-16,19:18.12
6,-16,19:18.12
7,-16,19:18.12
8,-16,19:18.12
-4,-15,19:18.12
-3,-15,19:18.12
-2,-15,19:18.12
0,-15,19:18.12
1,-15,19:18.12
2,-15,19:18.12
3,-15,19:18.12
4,-15,19:18.12
5,-15,19:18.12
6,-15,19:18.12
7,-15,19:18.12
8,-15,19:18.12
9,-15,19:18.12
-7,-14,19:18.12
-6,-14,19:18.12
-5,-14,19:18.12
-4,-14,19:18.12
-3,-14,19:18.12
-2,-14,19:18.12
-1,-14,19:18.12
0,-14,19:18.12
1,-14,19:18.12
2,-14,19:18.12
3,-14,19:18.12
4,-14,19:18.12
5,-14,19:18.12
6,-14,19:18.12
7,-14,19:18.12
8,-14,19:18.12
9,-14,19:18.12
10,-14,19:18.12
11,-14,19:18.4
12,-14,19:18.4
-8,-13,19:18.12
-7,-13,19:18.12
-6,-13,19:18.12
-5,-13,19:18.12
-4,-13,19:18.12
-3,-13,19:18.12
-2,-13,19:18.12
-1,-13,19:18.12
0,-13,19:18.12
3,-13,19:18.12
4,-13,19:17.12
5,-13,19:18.12
7,-13,19:18.12
8,-13,19:18.12
10,-13,19:18.12
11,-13,19:18.4
12,-13,19:18.4
-12,-12,19:18.12
-11,-12,19:18.12
-10,-12,19:18.12
-9,-12,19:18.12
-8,-12,19:18.12
-7,-12,19:18.12
-6,-12,19:18.12
-5,-12,19:18.12
-4,-12,19:18.12
-3,-12,19:18.12
-2,-12,19:18.12
-1,-12,19:18.12
3,-12,19:18.12
4,-12,19:18.12
5,-12,19:18.12
7,-12,19:18.12
8,-12,19:18.12
9,-12,19:18.12
10,-12,19:18.12
11,-12,19:18.12
-13,-11,19:18.12
-12,-11,19:18.12
-11,-11,19:18.12
-10,-11,19:18.12
-9,-11,19:18.12
-8,-11,19:18.12
-7,-11,19:18.12
-4,-11,19:18.12
-3,-11,19:18.12
-2,-11,19:18.12
-1,-11,19:18.12
3,-11,19:18.12
4,-11,19:18.12
7,-11,19:18.12
8,-11,19:18.12
9,-11,19:18.12
10,-11,19:18.12
-14,-10,19:18.12
-13,-10,19:18.12
-12,-10,19:18.12
-11,-10,19:18.12
-10,-10,19:18.12
-9,-10,19:18.12
-3,-10,19:18.12
-2,-10,19:18.12
3,-10,19:18.12
4,-10,19:18.12
7,-10,19:18.12
8,-10,19:18.12
9,-10,19:18.12
10,-10,19:18.12
-12,-9,19:18.12
-11,-9,19:17.12
-10,-9,19:17.12
-9,-9,19:18.12
-2,-9,19:18.12
-1,-9,19:18.12
3,-9,19:18.12
4,-9,19:18.12
7,-9,19:18.12
8,-9,19:18.12
9,-9,19:18.12
-15,-8,19:18.12
-14,-8,19:18.12
-13,-8,19:18.12
-12,-8,19:18.12
-11,-8,19:18.12
-10,-8,19:17.12
-9,-8,19:17.12
-8,-8,19:17.12
-7,-8,19:17.12
-1,-8,19:18.12
3,-8,19:18.12
6,-8,19:17.12
7,-8,19:18.12
8,-8,19:18.12
9,-8,19:18.12
10,-8,19:18.12
11,-8,19:18.12
12,-8,19:18.12
13,-8,19:18.12
-15,-7,19:18.12
-14,-7,19:18.12
-13,-7,19:18.12
-12,-7,19:18.12
-11,-7,19:18.12
-10,-7,19:18.12
-9,-7,19:18.12
-8,-7,19:17.12
-3,-7,19:18.12
-1,-7,19:18.12
2,-7,19:18.12
5,-7,19:17.12
6,-7,19:17.12
7,-7,19:18.12
8,-7,19:18.12
9,-7,19:18.12
10,-7,19:18.12
11,-7,19:18.12
12,-7,19:18.12
13,-7,19:18.12
-14,-6,19:18.12
-13,-6,19:18.12
-12,-6,19:18.12
-10,-6,19:18.12
-9,-6,19:18.12
-8,-6,19:18.12
-6,-6,19:18.12
-3,-6,19:18.12
-1,-6,19:18.12
0,-6,19:18.12
4,-6,19:17.12
5,-6,19:17.12
6,-6,19:18.12
7,-6,19:17.12
11,-6,19:18.12
12,-6,19:18.12
13,-6,19:18.12
14,-6,19:18.4
-13,-5,19:18.12
-12,-5,19:18.12
-11,-5,19:18.12
-9,-5,19:18.12
-8,-5,19:18.12
-7,-5,19:18.12
-3,-5,19:18.12
-2,-5,19:18.12
-1,-5,19:17.12
0,-5,19:17.12
1,-5,19:17.12
2,-5,19:18.12
3,-5,19:17.12
4,-5,19:17.12
5,-5,19:17.12
6,-5,19:17.12
12,-5,19:18.12
13,-5,19:18.12
-12,-4,19:18.12
-11,-4,19:18.12
-10,-4,19:18.12
-8,-4,19:18.12
-2,-4,19:18.12
-1,-4,19:17.12
1,-4,19:17.12
2,-4,19:17.12
11,-4,19:18.12
12,-4,19:18.12
-11,-3,19:18.12
-10,-3,19:18.12
-9,-3,19:18.12
-5,-3,19:17.12
-4,-3,19:17.12
-3,-3,19:17.12
-2,-3,19:18.12
-1,-3,19:18.12
0,-3,19:17.12
1,-3,19:17.12
8,-3,19:18.12
9,-3,19:18.12
10,-3,19:18.12
11,-3,19:18.12
-10,-2,19:18.12
-9,-2,19:18.12
-8,-2,19:18.12
-6,-2,19:17.12
-5,-2,19:17.12
-4,-2,19:17.12
-3,-2,19:17.12
-2,-2,19:18.12
-1,-2,19:18.12
0,-2,19:18.12
1,-2,19:18.12
2,-2,19:18.12
3,-2,19:18.12
8,-2,19:18.12
9,-2,19:18.12
10,-2,19:18.12
11,-2,19:18.12
12,-2,19:18.12
-10,-1,19:18.12
-9,-1,19:18.12
-8,-1,19:18.12
-6,-1,19:17.12
-5,-1,19:17.12
-4,-1,19:17.12
-3,-1,19:18.12
-2,-1,19:18.12
7,-1,19:18.12
8,-1,19:18.12
9,-1,19:18.12
11,-1,19:18.12
12,-1,19:18.12
13,-1,19:18.12
14,-1,19:18.12
-10,0,19:18.12
-9,0,19:18.12
-6,0,19:18.12
-5,0,19:18.12
-3,0,19:18.12
1,0,19:18.12
7,0,19:18.12
10,0,19:17.12
11,0,19:17.12
12,0,19:18.12
13,0,19:18.12
14,0,19:18.12
15,0,19:18.12
16,0,19:18.12
17,0,19:18.12
18,0,19:18.12
-10,1,19:18.12
-9,1,19:18.12
-8,1,19:18.12
-7,1,19:18.12
-4,1,19:18.12
1,1,19:18.12
8,1,19:18.12
10,1,19:17.12
11,1,19:17.12
12,1,19:18.12
13,1,19:18.12
14,1,19:18.12
15,1,19:18.12
16,1,19:18.12
17,1,19:18.12
18,1,19:18.12
19,1,19:18.12
-10,2,19:18.12
-9,2,19:18.12
-8,2,19:18.12
-7,2,19:18.12
1,2,19:18.12
8,2,19:18.12
9,2,19:18.12
13,2,19:18.12
14,2,19:18.12
15,2,19:18.12
-9,3,19:18.12
-8,3,19:18.12
-7,3,19:18.12
0,3,19:18.12
1,3,19:18.12
2,3,19:18.12
3,3,19:18.12
5,3,19:18.12
9,3,19:18.12
10,3,19:18.12
12,3,19:18.12
13,3,19:18.12
14,3,19:18.12
-8,4,19:18.12
-7,4,19:18.12
-6,4,19:18.12
-5,4,19:18.12
0,4,19:18.12
1,4,19:18.12
2,4,19:18.12
3,4,19:18.12
4,4,19:17.12
6,4,19:18.12
7,4,19:18.12
10,4,19:18.12
11,4,19:18.12
13,4,19:18.12
15,4,19:18.12
16,4,19:18.12
-13,5,19:18.12
-9,5,19:18.12
-8,5,19:18.12
-6,5,19:18.12
-5,5,19:18.12
-4,5,19:18.12
-2,5,19:18.12
-1,5,19:18.12
0,5,19:18.12
1,5,19:18.12
2,5,19:18.12
3,5,19:17.12
4,5,19:17.12
5,5,19:18.12
6,5,19:18.12
7,5,19:18.12
8,5,19:18.12
10,5,19:18.12
11,5,19:18.12
12,5,19:18.12
13,5,19:18.12
14,5,19:18.12
16,5,19:18.12
17,5,19:18.12
-10,6,19:18.12
-9,6,19:18.12
-8,6,19:18.12
-7,6,19:18.12
-6,6,19:18.12
-5,6,19:18.12
-4,6,19:18.12
-3,6,19:18.12
-2,6,19:18.12
-1,6,19:18.12
1,6,19:18.12
2,6,19:18.12
3,6,19:18.12
4,6,19:17.12
5,6,19:18.12
6,6,19:18.12
7,6,19:18.12
8,6,19:18.12
9,6,19:18.12
10,6,19:18.12
11,6,19:18.12
12,6,19:18.12
13,6,19:18.12
14,6,19:18.12
-10,7,19:18.12
-9,7,19:18.12
-8,7,19:18.12
-6,7,19:17.12
-5,7,19:17.12
-4,7,19:18.12
-3,7,19:18.12
-2,7,19:18.12
1,7,19:18.12
2,7,19:18.12
4,7,19:18.12
5,7,19:18.12
6,7,19:18.12
10,7,19:18.12
11,7,19:18.12
12,7,19:18.12
13,7,19:18.12
15,7,19:18.12
-10,8,19:18.12
-9,8,19:18.12
-7,8,19:17.12
-6,8,19:17.12
-5,8,19:17.12
-4,8,19:18.12
-3,8,19:18.12
-2,8,19:18.12
0,8,19:18.12
1,8,19:18.12
3,8,19:18.12
4,8,19:18.12
5,8,19:18.12
6,8,19:18.12
12,8,19:18.12
13,8,19:18.12
-10,9,19:18.12
-9,9,19:18.12
-7,9,19:17.12
-6,9,19:17.12
-5,9,19:18.12
-4,9,19:18.12
-3,9,19:18.12
-2,9,19:18.12
-1,9,19:18.12
3,9,19:18.12
5,9,19:18.12
6,9,19:18.12
-11,10,19:18.12
-10,10,19:18.12
-9,10,19:18.12
-8,10,19:18.12
-7,10,19:17.12
-6,10,19:17.12
-5,10,19:18.12
-4,10,19:18.12
2,10,19:18.12
5,10,19:18.12
6,10,19:18.12
7,10,19:18.12
-11,11,19:18.12
-10,11,19:18.12
-9,11,19:18.12
-8,11,19:18.12
-7,11,19:18.12
-6,11,19:18.12
-5,11,19:18.12
-4,11,19:18.12
-2,11,19:18.12
1,11,19:18.12
2,11,19:18.12
5,11,19:18.12
6,11,19:18.12
7,11,19:18.12
8,11,19:18.12
-11,12,19:18.12
-10,12,19:18.12
-9,12,19:18.12
-8,12,19:18.12
-7,12,19:18.12
-6,12,19:18.12
-2,12,19:18.12
1,12,19:18.12
6,12,19:18.12
7,12,19:18.12
8,12,19:18.12
-2,13,19:18.12
-1,13,19:18.4
1,13,19:18.12
6,13,19:18.12
8,13,19:18.12
-1,14,19:18.4
0,-25,20:18.4
12,-25,20:18.12
13,-25,20:18.12
14,-25,20:18.12
0,-24,20:18.4
1,-24,20:18.4
11,-24,20:18.12
12,-24,20:18.12
13,-24,20:18.12
-1,-23,20:18.4
0,-23,20:18.4
1,-23,20:18.4
6,-23,20:18.12
7,-23,20:18.12
11,-23,20:18.12
-1,-22,20:18.4
0,-22,20:18.4
5,-22,20:18.12
6,-22,20:18.12
8,-22,20:17.12
10,-22,20:18.12
11,-22,20:18.12
-1,-21,20:18.4
0,-21,20:18.4
1,-21,20:18.4
5,-21,20:18.12
6,-21,20:18.12
8,-21,20:17.12
9,-21,20:18.12
10,-21,20:18.12
0,-20,20:18.4
2,-20,20:18.12
3,-20,20:18.12
4,-20,20:18.12
5,-20,20:18.12
7,-20,20:18.12
8,-20,20:18.12
9,-20,20:18.12
1,-19,20:18.12
2,-19,20:18.12
3,-19,20:18.12
4,-19,20:18.12
6,-19,20:18.12
7,-19,20:18.12
8,-19,20:18.12
9,-19,20:18.12
1,-18,20:18.12
4,-18,20:18.12
7,-18,20:18.12
8,-18,20:18.12
9,-18,20:18.12
-8,-17,20:18.4
1,-17,20:18.12
4,-17,20:18.12
5,-17,20:18.12
8,-17,20:18.12
9,-17,20:18.12
-9,-16,20:18.4
-8,-16,20:18.4
-4,-16,20:18.12
1,-16,20:18.12
2,-16,20:18.12
3,-16,20:18.12
4,-16,20:18.12
5,-16,20:18.12
6,-16,20:18.12
7,-16,20:18.12
8,-16,20:18.12
9,-16,20:18.12
-14,-15,20:18.12
-9,-15,20:18.4
-8,-15,20:18.4
-6,-15,20:18.12
-5,-15,20:18.12
-4,-15,20:18.12
1,-15,20:18.12
2,-15,20:18.12
3,-15,20:18.12
4,-15,20:18.12
6,-15,20:18.12
7,-15,20:18.12
9,-15,20:18.12
10,-15,20:18.12
11,-15,20:18.12
12,-15,20:18.4
13,-15,20:18.4
-14,-14,20:18.12
-9,-14,20:18.12
-8,-14,20:18.12
-5,-14,20:18.12
-4,-14,20:18.12
-2,-14,20:18.12
-1,-14,20:18.12
1,-14,20:18.12
2,-14,20:18.12
3,-14,20:18.12
4,-14,20:17.12
5,-14,20:17.12
9,-14,20:18.12
10,-14,20:18.12
11,-14,20:18.4
12,-14,20:18.4
13,-14,20:18.4
-14,-13,20:18.12
-10,-13,20:18.12
-9,-13,20:18.12
-4,-13,20:18.12
-1,-13,20:18.12
0,-13,20:18.12
1,-13,20:18.12
2,-13,20:18.12
3,-13,20:18.12
4,-13,20:17.12
9,-13,20:18.12
11,-13,20:18.12
12,-13,20:18.12
-17,-12,20:18.12
-16,-12,20:18.12
-15,-12,20:18.12
-14,-12,20:18.12
-13,-12,20:18.12
-12,-12,20:18.12
-10,-12,20:18.12
-9,-12,20:18.12
-4,-12,20:18.12
-3,-12,20:18.12
-1,-12,20:18.12
0,-12,20:18.12
1,-12,20:18.12
2,-12,20:18.12
3,-12,20:18.12
9,-12,20:18.12
10,-12,20:18.12
11,-12,20:18.12
12,-12,20:18.12
13,-12,20:18.12
-16,-11,20:18.12
-15,-11,20:18.12
-13,-11,20:18.12
-12,-11,20:18.12
-11,-11,20:18.12
-10,-11,20:18.12
-9,-11,20:18.12
-6,-11,20:18.12
-5,-11,20:18.12
-3,-11,20:18.12
-1,-11,20:18.12
0,-11,20:18.12
1,-11,20:18.12
2,-11,20:18.12
3,-11,20:18.12
8,-11,20:18.12
9,-11,20:18.12
10,-11,20:18.12
11,-11,20:18.12
12,-11,20:18.12
-15,-10,20:18.12
-14,-10,20:18.12
-13,-10,20:17.12
-12,-10,20:18.12
-11,-10,20:17.12
-10,-10,20:18.12
-5,-10,20:18.12
-4,-10,20:18.12
-3,-10,20:18.12
-1,-10,20:18.12
0,-10,20:18.12
1,-10,20:18.12
2,-10,20:18.12
3,-10,20:18.12
8,-10,20:18.12
9,-10,20:18.12
10,-10,20:18.12
11,-10,20:18.12
12,-10,20:18.12
-14,-9,20:18.12
-13,-9,20:18.12
-12,-9,20:18.12
-11,-9,20:17.12
-10,-9,20:17.12
-9,-9,20:18.12
-5,-9,20:18.12
-4,-9,20:18.12
-3,-9,20:18.12
-1,-9,20:18.12
0,-9,20:18.12
1,-9,20:18.12
2,-9,20:18.12
8,-9,20:18.12
9,-9,20:18.12
10,-9,20:18.12
11,-9,20:18.12
12,-9,20:18.12
13,-9,20:18.12
-14,-8,20:18.12
-13,-8,20:18.12
-12,-8,20:18.12
-11,-8,20:18.12
-10,-8,20:18.12
-9,-8,20:17.12
-8,-8,20:17.12
-4,-8,20:18.12
-3,-8,20:18.12
-1,-8,20:18.12
0,-8,20:18.12
1,-8,20:18.12
2,-8,20:18.12
6,-8,20:17.12
7,-8,20:17.12
8,-8,20:18.12
12,-8,20:18.12
13,-8,20:18.12
14,-8,20:18.12
-13,-7,20:18.12
-12,-7,20:18.12
-11,-7,20:18.12
-10,-7,20:18.12
-9,-7,20:18.12
-8,-7,20:17.12
-1,-7,20:17.12
0,-7,20:17.12
1,-7,20:18.12
2,-7,20:18.12
5,-7,20:17.12
6,-7,20:17.12
7,-7,20:17.12
8,-7,20:17.12
-12,-6,20:18.12
-11,-6,20:18.12
-10,-6,20:18.12
-6,-6,20:18.12
-5,-6,20:18.12
-4,-6,20:18.12
-3,-6,20:18.12
-1,-6,20:17.12
0,-6,20:17.12
1,-6,20:18.12
5,-6,20:17.12
6,-6,20:17.12
7,-6,20:17.12
8,-6,20:18.12
9,-6,20:18.12
10,-6,20:18.12
11,-6,20:18.12
12,-6,20:18.12
13,-6,20:18.12
14,-6,20:18.12
15,-6,20:18.12
-14,-5,20:18.12
-12,-5,20:18.12
-11,-5,20:18.12
-10,-5,20:18.12
-9,-5,20:18.12
-8,-5,20:18.12
-7,-5,20:18.12
-4,-5,20:18.12
-3,-5,20:18.12
0,-5,20:17.12
1,-5,20:17.12
4,-5,20:18.12
5,-5,20:18.12
6,-5,20:18.12
13,-5,20:18.12
14,-5,20:18.12
15,-5,20:18.12
16,-5,20:18.4
-14,-4,20:18.12
-13,-4,20:18.12
-12,-4,20:18.12
-11,-4,20:18.12
-10,-4,20:18.12
-3,-4,20:18.12
-1,-4,20:17.12
0,-4,20:17.12
1,-4,20:17.12
2,-4,20:17.12
12,-4,20:18.12
13,-4,20:18.12
-13,-3,20:18.12
-12,-3,20:18.12
-10,-3,20:18.12
-9,-3,20:18.12
-2,-3,20:18.12
-1,-3,20:17.12
0,-3,20:17.12
1,-3,20:17.12
11,-3,20:18.12
12,-3,20:18.12
13,-3,20:18.12
14,-3,20:18.12
-13,-2,20:18.12
-12,-2,20:18.12
-11,-2,20:18.12
-10,-2,20:18.12
-7,-2,20:17.12
-6,-2,20:17.12
-5,-2,20:17.12
-4,-2,20:17.12
-3,-2,20:18.12
-2,-2,20:18.12
-1,-2,20:18.12
0,-2,20:18.12
1,-2,20:18.12
2,-2,20:18.12
8,-2,20:18.12
9,-2,20:18.12
10,-2,20:18.12
12,-2,20:18.12
13,-2,20:18.12
14,-2,20:18.12
15,-2,20:18.12
-11,-1,20:18.12
-10,-1,20:18.12
-7,-1,20:17.12
-6,-1,20:17.12
-5,-1,20:17.12
-3,-1,20:18.12
-2,-1,20:18.12
-1,-1,20:18.12
0,-1,20:18.12
1,-1,20:18.12
2,-1,20:18.12
14,-1,20:18.12
15,-1,20:18.12
-11,0,20:18.12
-10,0,20:18.12
-6,0,20:18.12
-5,0,20:18.12
-3,0,20:18.12
1,0,20:18.12
11,0,20:17.12
-12,1,20:18.12
-11,1,20:18.12
-9,1,20:18.12
-8,1,20:18.12
-7,1,20:18.12
-6,1,20:18.12
-4,1,20:18.12
1,1,20:18.12
8,1,20:18.12
11,1,20:17.12
12,1,20:17.12
13,1,20:18.12
19,1,20:18.12
-10,2,20:18.12
-9,2,20:18.12
-8,2,20:18.12
1,2,20:18.12
9,2,20:18.12
11,2,20:17.12
12,2,20:17.12
13,2,20:18.12
14,2,20:18.12
15,2,20:18.12
16,2,20:18.12
17,2,20:18.12
18,2,20:18.12
19,2,20:18.12
-10,3,20:18.12
-9,3,20:18.12
1,3,20:18.12
5,3,20:18.12
9,3,20:18.12
10,3,20:18.12
16,3,20:18.12
17,3,20:18.12
18,3,20:18.12
19,3,20:18.12
-12,4,20:18.12
-10,4,20:18.12
-9,4,20:18.12
-7,4,20:18.12
-6,4,20:18.12
-5,4,20:18.12
1,4,20:18.12
5,4,20:18.12
6,4,20:18.12
10,4,20:18.12
11,4,20:18.12
12,4,20:18.12
13,4,20:18.12
17,4,20:18.12
18,4,20:18.12
-13,5,20:18.12
-10,5,20:18.12
-9,5,20:18.12
-8,5,20:18.12
-7,5,20:18.12
-6,5,20:18.12
0,5,20:18.12
1,5,20:18.12
2,5,20:18.12
3,5,20:17.12
4,5,20:17.12
5,5,20:17.12
7,5,20:18.12
8,5,20:18.12
12,5,20:18.12
13,5,20:18.12
14,5,20:18.12
18,5,20:18.12
-15,6,20:18.12
-10,6,20:18.12
-6,6,20:18.12
-5,6,20:18.12
-4,6,20:18.12
-1,6,20:18.12
0,6,20:18.12
1,6,20:18.12
3,6,20:18.12
4,6,20:17.12
5,6,20:17.12
6,6,20:18.12
7,6,20:18.12
8,6,20:18.12
9,6,20:18.12
10,6,20:18.12
11,6,20:18.12
13,6,20:18.12
14,6,20:18.12
-15,7,20:18.4
-11,7,20:18.12
-10,7,20:18.12
-7,7,20:18.12
-6,7,20:18.12
-5,7,20:18.12
-4,7,20:18.12
-2,7,20:18.12
-1,7,20:18.12
0,7,20:18.12
2,7,20:18.12
3,7,20:18.12
4,7,20:17.12
5,7,20:17.12
6,7,20:18.12
7,7,20:18.12
9,7,20:18.12
10,7,20:18.12
11,7,20:18.12
12,7,20:18.12
13,7,20:18.12
15,7,20:18.12
-11,8,20:18.12
-10,8,20:18.12
-7,8,20:18.12
-6,8,20:18.12
-5,8,20:18.12
-4,8,20:18.12
-3,8,20:18.12
-2,8,20:18.12
-1,8,20:18.12
1,8,20:18.12
2,8,20:18.12
3,8,20:18.12
4,8,20:18.12
5,8,20:17.12
6,8,20:18.12
7,8,20:18.12
8,8,20:18.12
11,8,20:18.4
12,8,20:18.12
14,8,20:18.12
-11,9,20:18.12
-7,9,20:18.12
-6,9,20:18.12
-5,9,20:18.12
-4,9,20:18.12
-3,9,20:18.12
-2,9,20:18.12
-1,9,20:18.12
0,9,20:18.12
1,9,20:18.12
3,9,20:18.12
4,9,20:18.12
5,9,20:17.12
6,9,20:18.12
7,9,20:18.12
14,9,20:18.4
-12,10,20:18.12
-11,10,20:18.12
-8,10,20:17.12
-7,10,20:17.12
-6,10,20:18.12
-5,10,20:18.12
-4,10,20:18.12
-3,10,20:18.12
-1,10,20:18.12
0,10,20:18.12
3,10,20:18.12
4,10,20:18.12
5,10,20:18.12
6,10,20:18.12
7,10,20:18.12
-12,11,20:18.12
-11,11,20:18.12
-8,11,20:17.12
-7,11,20:18.12
-5,11,20:18.12
-4,11,20:18.12
-3,11,20:18.12
-2,11,20:18.12
-1,11,20:18.12
2,11,20:18.12
3,11,20:18.12
4,11,20:18.12
5,11,20:18.12
6,11,20:18.12
7,11,20:18.12
-12,12,20:18.12
-8,12,20:18.12
-7,12,20:18.12
-6,12,20:18.12
-2,12,20:18.12
3,12,20:18.12
5,12,20:18.12
6,12,20:18.12
7,12,20:18.12
8,12,20:18.12
-9,13,20:18.12
-8,13,20:18.12
-7,13,20:18.12
-6,13,20:18.12
-2,13,20:18.12
1,13,20:18.12
2,13,20:18.12
3,13,20:18.12
6,13,20:18.12
7,13,20:18.12
8,13,20:18.12
-6,14,20:18.12
-1,14,20:18.4
1,14,20:18.12
2,14,20:18.12
6,14,20:18.12
7,14,20:18.12
8,14,20:18.12
-6,15,20:18.12
-5,15,20:18.12
-1,15,20:18.4
2,15,20:18.4
7,15,20:18.4
-5,16,20:18.12
6,-25,21:18.12
5,-24,21:18.12
6,-24,21:18.12
9,-24,21:17.12
12,-24,21:18.12
-1,-23,21:18.4
0,-23,21:18.4
4,-23,21:18.12
5,-23,21:18.12
6,-23,21:18.12
8,-23,21:17.12
9,-23,21:17.12
11,-23,21:18.12
12,-23,21:18.12
0,-22,21:18.4
1,-22,21:18.4
2,-22,21:18.12
4,-22,21:18.12
5,-22,21:18.12
9,-22,21:18.12
10,-22,21:18.12
11,-22,21:18.12
0,-21,21:18.4
1,-21,21:18.4
2,-21,21:18.12
3,-21,21:18.12
4,-21,21:18.12
8,-21,21:18.12
10,-21,21:18.12
11,-21,21:18.12
0,-20,21:18.4
3,-20,21:18.12
4,-20,21:18.12
7,-20,21:18.12
8,-20,21:18.12
10,-20,21:18.12
11,-20,21:18.12
1,-19,21:18.12
4,-19,21:18.12
6,-19,21:18.12
7,-19,21:18.12
10,-19,21:18.12
-9,-18,21:18.4
1,-18,21:18.12
4,-18,21:18.12
7,-18,21:18.12
8,-18,21:18.12
9,-18,21:18.12
10,-18,21:18.12
-10,-17,21:18.4
-9,-17,21:18.4
1,-17,21:18.12
2,-17,21:18.12
4,-17,21:18.12
9,-17,21:18.12
10,-17,21:18.12
-10,-16,21:18.4
-9,-16,21:18.4
1,-16,21:18.12
2,-16,21:18.12
4,-16,21:18.12
7,-16,21:18.12
8,-16,21:18.12
9,-16,21:18.12
11,-16,21:18.12
12,-16,21:18.4
14,-16,21:18.4
-15,-15,21:18.12
-10,-15,21:18.12
-9,-15,21:18.4
1,-15,21:18.12
2,-15,21:18.12
4,-15,21:18.12
5,-15,21:18.12
6,-15,21:18.12
7,-15,21:18.12
11,-15,21:18.12
12,-15,21:18.4
13,-15,21:18.4
14,-15,21:18.4
-17,-14,21:18.12
-15,-14,21:18.12
-14,-14,21:18.12
-11,-14,21:18.12
-10,-14,21:18.12
-4,-14,21:18.12
-2,-14,21:18.12
0,-14,21:18.12
1,-14,21:18.12
2,-14,21:18.12
3,-14,21:18.12
4,-14,21:17.12
12,-14,21:18.4
13,-14,21:18.4
-17,-13,21:18.12
-16,-13,21:18.12
-15,-13,21:18.12
-14,-13,21:18.12
-13,-13,21:18.12
-12,-13,21:18.12
-11,-13,21:18.12
-10,-13,21:18.12
-5,-13,21:18.12
-4,-13,21:18.12
-3,-13,21:18.12
-2,-13,21:18.12
0,-13,21:18.12
3,-13,21:18.12
4,-13,21:17.12
11,-13,21:18.12
12,-13,21:18.12
-15,-12,21:18.12
-14,-12,21:18.12
-13,-12,21:18.12
-12,-12,21:18.12
-11,-12,21:18.12
-10,-12,21:18.12
-5,-12,21:18.12
-4,-12,21:18.12
-3,-12,21:18.12
-2,-12,21:18.12
3,-12,21:18.12
10,-12,21:18.12
11,-12,21:18.12
-15,-11,21:17.12
-14,-11,21:17.12
-13,-11,21:18.12
-11,-11,21:18.12
-10,-11,21:18.12
-5,-11,21:18.12
-4,-11,21:18.12
-3,-11,21:18.12
-2,-11,21:18.12
-1,-11,21:18.12
3,-11,21:18.12
10,-11,21:18.12
13,-11,21:18.12
-17,-10,21:18.12
-16,-10,21:18.12
-15,-10,21:17.12
-14,-10,21:17.12
-13,-10,21:17.12
-12,-10,21:18.12
-10,-10,21:18.12
-4,-10,21:18.12
-3,-10,21:18.12
-2,-10,21:18.12
-1,-10,21:18.12
2,-10,21:18.12
9,-10,21:18.12
10,-10,21:18.12
11,-10,21:18.12
12,-10,21:18.12
-16,-9,21:18.12
-15,-9,21:18.12
-14,-9,21:18.12
-13,-9,21:18.12
-12,-9,21:18.12
-3,-9,21:18.12
-2,-9,21:18.12
-1,-9,21:17.12
2,-9,21:18.12
8,-9,21:18.12
9,-9,21:18.12
10,-9,21:18.12
-15,-8,21:18.12
-14,-8,21:18.12
-13,-8,21:18.12
-8,-8,21:17.12
-7,-8,21:17.12
-2,-8,21:18.12
-1,-8,21:17.12
0,-8,21:17.12
2,-8,21:18.12
7,-8,21:18.12
8,-8,21:17.12
9,-8,21:17.12
-15,-7,21:18.12
-14,-7,21:18.12
-13,-7,21:18.12
-12,-7,21:18.12
-11,-7,21:18.12
-10,-7,21:18.12
-9,-7,21:18.12
-8,-7,21:17.12
-2,-7,21:17.12
-1,-7,21:17.12
0,-7,21:17.12
1,-7,21:18.12
6,-7,21:18.12
7,-7,21:17.12
8,-7,21:17.12
9,-7,21:17.12
-14,-6,21:18.12
-13,-6,21:18.12
-12,-6,21:18.12
-6,-6,21:18.12
-5,-6,21:18.12
-1,-6,21:17.12
0,-6,21:17.12
1,-6,21:17.12
5,-6,21:18.12
6,-6,21:17.12
9,-6,21:18.12
10,-6,21:18.12
11,-6,21:18.12
-13,-5,21:18.12
-12,-5,21:18.12
-11,-5,21:18.12
-10,-5,21:18.12
-9,-5,21:18.12
-8,-5,21:18.12
-7,-5,21:18.12
-4,-5,21:18.12
-1,-5,21:17.12
0,-5,21:17.12
1,-5,21:17.12
5,-5,21:18.12
6,-5,21:18.12
9,-5,21:18.12
10,-5,21:18.12
11,-5,21:18.12
12,-5,21:18.12
13,-5,21:18.12
14,-5,21:18.12
15,-5,21:18.12
16,-5,21:18.12
17,-5,21:18.12
-14,-4,21:18.12
-13,-4,21:18.12
-12,-4,21:18.12
-11,-4,21:18.12
-10,-4,21:18.12
-4,-4,21:18.12
-1,-4,21:17.12
0,-4,21:17.12
1,-4,21:17.12
2,-4,21:17.12
4,-4,21:18.12
6,-4,21:18.12
7,-4,21:18.12
9,-4,21:18.12
10,-4,21:18.12
11,-4,21:18.12
13,-4,21:18.12
14,-4,21:18.12
15,-4,21:18.12
17,-4,21:18.4
-14,-3,21:18.12
-13,-3,21:18.12
-11,-3,21:18.12
-10,-3,21:18.12
-1,-3,21:17.12
0,-3,21:17.12
9,-3,21:18.12
10,-3,21:18.12
11,-3,21:18.12
12,-3,21:18.12
13,-3,21:18.12
14,-3,21:18.12
15,-3,21:18.12
-15,-2,21:18.12
-14,-2,21:18.12
-13,-2,21:18.12
-12,-2,21:18.12
-11,-2,21:18.12
8,-2,21:18.12
9,-2,21:18.12
10,-2,21:18.12
15,-2,21:18.12
16,-2,21:18.12
-12,-1,21:18.12
-11,-1,21:18.12
-7,-1,21:17.12
-6,-1,21:17.12
-2,-1,21:18.12
-1,-1,21:18.12
0,-1,21:18.12
1,-1,21:18.12
-12,0,21:18.12
-7,0,21:18.12
-6,0,21:18.12
-3,0,21:18.12
-2,0,21:18.12
-1,0,21:18.12
0,0,21:18.12
-12,1,21:18.12
-8,1,21:18.12
-7,1,21:18.12
-4,1,21:18.12
1,1,21:18.12
8,1,21:18.12
9,1,21:18.12
12,1,21:17.12
-10,2,21:18.12
-9,2,21:18.12
1,2,21:18.12
3,2,21:18.12
9,2,21:18.12
11,2,21:18.12
12,2,21:17.12
13,2,21:18.12
14,2,21:18.12
15,2,21:18.12
-11,3,21:18.12
-10,3,21:18.12
-8,3,21:18.12
1,3,21:18.12
3,3,21:18.12
10,3,21:18.12
12,3,21:18.12
13,3,21:18.12
14,3,21:18.12
16,3,21:18.12
17,3,21:18.12
18,3,21:18.12
19,3,21:18.12
-12,4,21:18.12
-11,4,21:18.12
-7,4,21:18.12
5,4,21:18.12
6,4,21:18.12
11,4,21:18.12
12,4,21:18.12
13,4,21:18.12
14,4,21:18.12
15,4,21:18.12
18,4,21:18.12
19,4,21:18.12
-14,5,21:18.12
-13,5,21:18.12
-8,5,21:18.12
-7,5,21:18.12
-6,5,21:18.12
2,5,21:18.12
4,5,21:18.12
7,5,21:18.12
8,5,21:18.12
13,5,21:18.12
14,5,21:18.12
15,5,21:18.12
-15,6,21:18.12
-10,6,21:18.12
-9,6,21:18.12
-8,6,21:18.12
-6,6,21:18.12
-5,6,21:18.12
-4,6,21:18.12
-3,6,21:18.12
-2,6,21:18.12
1,6,21:18.12
2,6,21:18.12
3,6,21:18.12
5,6,21:18.12
8,6,21:18.12
9,6,21:18.12
13,6,21:18.12
14,6,21:18.12
15,6,21:18.12
-16,7,21:18.4
-15,7,21:18.4
-7,7,21:18.12
-6,7,21:18.12
0,7,21:18.12
1,7,21:18.12
3,7,21:18.12
6,7,21:18.12
7,7,21:18.12
10,7,21:18.12
11,7,21:18.12
12,7,21:18.12
14,7,21:18.12
-7,8,21:18.12
-6,8,21:18.12
-5,8,21:18.12
-1,8,21:18.12
0,8,21:18.12
1,8,21:18.12
3,8,21:18.12
4,8,21:18.12
5,8,21:17.12
6,8,21:17.12
7,8,21:18.12
8,8,21:18.12
9,8,21:18.12
10,8,21:18.12
11,8,21:18.4
12,8,21:18.12
14,8,21:18.12
-7,9,21:18.12
-6,9,21:18.12
-5,9,21:18.12
-4,9,21:18.12
-1,9,21:18.12
0,9,21:18.12
2,9,21:18.12
3,9,21:18.12
4,9,21:18.12
5,9,21:17.12
6,9,21:17.12
8,9,21:18.12
9,9,21:18.12
10,9,21:18.12
11,9,21:18.4
12,9,21:18.4
14,9,21:18.4
15,9,21:18.12
-8,10,21:18.12
-7,10,21:18.12
-6,10,21:18.12
-5,10,21:18.12
-4,10,21:18.12
-3,10,21:18.12
-1,10,21:18.12
0,10,21:18.12
1,10,21:18.12
2,10,21:18.12
3,10,21:18.12
4,10,21:18.12
8,10,21:18.12
9,10,21:18.12
15,10,21:18.4
-8,11,21:17.12
-7,11,21:17.12
-6,11,21:18.12
-4,11,21:18.12
-3,11,21:18.12
-2,11,21:18.12
-1,11,21:18.12
0,11,21:18.12
1,11,21:18.12
4,11,21:18.12
5,11,21:18.12
8,11,21:18.12
9,11,21:18.12
-9,12,21:18.12
-8,12,21:18.12
-7,12,21:18.12
-6,12,21:18.12
-5,12,21:18.12
-3,12,21:18.12
-2,12,21:18.12
-1,12,21:18.12
0,12,21:18.4
4,12,21:18.12
5,12,21:18.12
8,12,21:18.12
9,12,21:18.12
-8,13,21:18.12
-7,13,21:18.12
-6,13,21:18.12
-2,13,21:18.12
3,13,21:18.12
4,13,21:18.12
5,13,21:18.12
6,13,21:18.12
8,13,21:18.12
9,13,21:18.12
-7,14,21:18.12
-6,14,21:18.12
3,14,21:18.12
4,14,21:18.12
5,14,21:18.12
6,14,21:18.12
8,14,21:18.12
9,14,21:18.12
-6,15,21:18.12
2,15,21:18.12
3,15,21:18.12
6,15,21:18.12
7,15,21:18.12
-6,16,21:18.12
-6,17,21:18.12
-5,17,21:18.12
10,-26,22:17.12
5,-25,22:18.12
10,-25,22:18.12
11,-25,22:18.12
13,-25,22:18.12
-1,-24,22:18.4
1,-24,22:18.4
5,-24,22:18.12
10,-24,22:18.12
12,-24,22:18.12
13,-24,22:18.12
-1,-23,22:18.4
0,-23,22:18.4
1,-23,22:18.4
2,-23,22:18.12
3,-23,22:18.12
4,-23,22:18.12
9,-23,22:18.12
11,-23,22:18.12
12,-23,22:18.12
0,-22,22:18.4
2,-22,22:18.12
3,-22,22:18.12
4,-22,22:18.12
8,-22,22:18.12
9,-22,22:18.12
10,-22,22:18.12
11,-22,22:18.12
0,-21,22:18.4
3,-21,22:18.12
4,-21,22:18.12
8,-21,22:18.12
10,-21,22:18.12
11,-21,22:18.12
12,-21,22:18.12
0,-20,22:18.4
3,-20,22:18.12
4,-20,22:18.12
5,-20,22:18.12
6,-20,22:18.12
7,-20,22:18.12
8,-20,22:18.12
11,-20,22:18.12
12,-20,22:18.12
-10,-19,22:18.4
1,-19,22:18.12
4,-19,22:18.12
8,-19,22:18.12
11,-19,22:18.12
-11,-18,22:18.4
-10,-18,22:18.4
0,-18,22:18.12
1,-18,22:18.12
4,-18,22:18.12
8,-18,22:18.12
11,-18,22:18.12
-11,-17,22:18.4
-10,-17,22:18.4
0,-17,22:18.12
1,-17,22:18.12
2,-17,22:18.12
4,-17,22:18.12
9,-17,22:18.12
10,-17,22:18.12
11,-17,22:18.12
12,-17,22:18.12
13,-17,22:18.4
-16,-16,22:18.4
-11,-16,22:18.4
-10,-16,22:18.4
0,-16,22:18.12
2,-16,22:18.12
4,-16,22:18.12
5,-16,22:18.12
7,-16,22:18.12
8,-16,22:18.12
9,-16,22:18.12
12,-16,22:18.4
14,-16,22:18.4
-17,-15,22:18.12
-16,-15,22:18.12
-15,-15,22:18.12
-12,-15,22:18.12
-11,-15,22:18.12
-1,-15,22:18.12
0,-15,22:18.12
2,-15,22:18.12
4,-15,22:18.12
5,-15,22:17.12
6,-15,22:18.12
7,-15,22:18.12
13,-15,22:18.4
14,-15,22:18.4
-17,-14,22:18.12
-16,-14,22:18.12
-15,-14,22:18.12
-14,-14,22:18.12
-13,-14,22:18.12
-12,-14,22:18.12
-11,-14,22:18.12
-7,-14,22:18.12
-6,-14,22:18.12
-3,-14,22:18.12
-1,-14,22:18.12
0,-14,22:18.12
2,-14,22:18.12
4,-14,22:18.12
5,-14,22:17.12
13,-14,22:18.12
-15,-13,22:18.12
-14,-13,22:18.12
-13,-13,22:18.12
-12,-13,22:18.12
-11,-13,22:18.12
-6,-13,22:18.12
-5,-13,22:18.12
-4,-13,22:18.12
-3,-13,22:18.12
-1,-13,22:18.12
3,-13,22:18.12
4,-13,22:18.12
12,-13,22:18.12
-14,-12,22:18.12
-11,-12,22:18.12
-5,-12,22:18.12
-4,-12,22:18.12
-3,-12,22:18.12
-2,-12,22:18.12
-1,-12,22:18.12
3,-12,22:18.12
10,-12,22:18.12
11,-12,22:18.12
12,-12,22:18.12
-16,-11,22:17.12
-15,-11,22:17.12
-14,-11,22:18.12
-13,-11,22:18.12
-10,-11,22:18.12
-3,-11,22:18.12
-2,-11,22:18.12
-1,-11,22:18.12
3,-11,22:18.12
9,-11,22:18.12
10,-11,22:18.12
11,-11,22:18.12
13,-11,22:18.12
-14,-10,22:18.12
-13,-10,22:18.12
-12,-10,22:18.12
-10,-10,22:18.12
-2,-10,22:18.12
-1,-10,22:17.12
0,-10,22:17.12
3,-10,22:18.12
9,-10,22:18.12
10,-10,22:18.12
11,-10,22:18.12
12,-10,22:18.12
-17,-9,22:18.12
-16,-9,22:18.12
-14,-9,22:18.12
-13,-9,22:18.12
-2,-9,22:17.12
-1,-9,22:17.12
0,-9,22:17.12
2,-9,22:18.12
3,-9,22:18.12
9,-9,22:18.12
10,-9,22:18.12
11,-9,22:18.12
-17,-8,22:18.12
-16,-8,22:18.12
-15,-8,22:18.12
-14,-8,22:18.12
-7,-8,22:17.12
-2,-8,22:18.12
-1,-8,22:17.12
0,-8,22:17.12
2,-8,22:18.12
6,-8,22:18.12
7,-8,22:18.12
8,-8,22:17.12
9,-8,22:17.12
-16,-7,22:18.12
-15,-7,22:18.12
-14,-7,22:18.12
-13,-7,22:18.12
-12,-7,22:18.12
-11,-7,22:18.12
-10,-7,22:18.12
-8,-7,22:17.12
-7,-7,22:17.12
-2,-7,22:17.12
-1,-7,22:17.12
0,-7,22:17.12
6,-7,22:18.12
7,-7,22:17.12
8,-7,22:17.12
9,-7,22:17.12
10,-7,22:18.12
11,-7,22:18.12
-15,-6,22:18.12
-14,-6,22:18.12
-13,-6,22:18.12
-7,-6,22:18.12
-6,-6,22:18.12
6,-6,22:18.12
11,-6,22:18.12
12,-6,22:18.12
13,-6,22:18.12
-15,-5,22:18.12
-14,-5,22:18.12
-13,-5,22:18.12
-12,-5,22:18.12
-9,-5,22:18.12
-8,-5,22:18.12
-7,-5,22:18.12
-1,-5,22:17.12
0,-5,22:17.12
1,-5,22:17.12
6,-5,22:18.12
12,-5,22:18.12
13,-5,22:18.12
14,-5,22:18.12
15,-5,22:18.12
-15,-4,22:18.4
-14,-4,22:18.12
-13,-4,22:18.12
-12,-4,22:18.12
-11,-4,22:18.12
-10,-4,22:18.12
-1,-4,22:17.12
1,-4,22:17.12
4,-4,22:18.12
5,-4,22:18.12
6,-4,22:18.12
7,-4,22:18.12
8,-4,22:18.12
12,-4,22:18.12
13,-4,22:18.12
14,-4,22:18.12
15,-4,22:18.12
16,-4,22:18.12
17,-4,22:18.4
-16,-3,22:18.4
-15,-3,22:18.12
-14,-3,22:18.12
-12,-3,22:18.12
-1,-3,22:17.12
0,-3,22:17.12
3,-3,22:18.12
4,-3,22:18.12
8,-3,22:18.12
9,-3,22:18.12
10,-3,22:18.12
11,-3,22:18.12
12,-3,22:18.12
13,-3,22:18.12
14,-3,22:18.12
-16,-2,22:18.12
-15,-2,22:18.12
-14,-2,22:18.12
-13,-2,22:18.12
-12,-2,22:18.12
-11,-2,22:18.12
-10,-2,22:18.12
-7,-2,22:18.12
1,-2,22:18.12
8,-2,22:18.12
9,-2,22:18.12
10,-2,22:18.12
11,-2,22:18.12
12,-2,22:18.12
13,-2,22:18.12
14,-2,22:18.12
-13,-1,22:18.12
-12,-1,22:18.12
-9,-1,22:18.12
-8,-1,22:18.12
-7,-1,22:17.12
-6,-1,22:17.12
1,-1,22:18.12
10,-1,22:18.12
11,-1,22:18.12
12,-1,22:18.12
13,-1,22:18.12
-14,0,22:18.12
-13,0,22:18.12
-10,0,22:18.12
-9,0,22:18.12
-8,0,22:18.12
-7,0,22:17.12
-6,0,22:17.12
2,0,22:18.12
11,0,22:18.12
12,0,22:18.12
-13,1,22:18.12
-9,1,22:18.12
-8,1,22:18.12
-7,1,22:18.12
2,1,22:18.12
12,1,22:17.12
13,1,22:17.12
-10,2,22:18.12
-9,2,22:18.12
-8,2,22:18.12
-7,2,22:18.12
3,2,22:18.12
9,2,22:18.12
12,2,22:17.12
13,2,22:17.12
14,2,22:18.12
15,2,22:18.12
-11,3,22:18.12
-10,3,22:18.12
-9,3,22:18.12
-8,3,22:18.12
3,3,22:18.12
10,3,22:18.12
13,3,22:17.12
14,3,22:17.12
16,3,22:18.12
17,3,22:18.12
18,3,22:18.12
-12,4,22:18.12
-8,4,22:18.12
-7,4,22:18.12
4,4,22:18.12
11,4,22:18.12
12,4,22:18.12
15,4,22:18.12
16,4,22:18.12
18,4,22:18.12
19,4,22:18.12
-14,5,22:18.12
-13,5,22:18.12
-7,5,22:18.12
4,5,22:18.12
7,5,22:18.12
11,5,22:18.12
12,5,22:18.12
15,5,22:18.12
16,5,22:18.12
17,5,22:18.12
-15,6,22:18.12
-7,6,22:18.12
-6,6,22:18.12
-3,6,22:18.12
-2,6,22:18.12
-1,6,22:18.12
2,6,22:18.12
3,6,22:18.12
4,6,22:18.12
8,6,22:18.12
10,6,22:18.12
11,6,22:18.12
12,6,22:18.12
13,6,22:18.12
14,6,22:18.12
15,6,22:18.12
16,6,22:18.12
17,6,22:18.12
-16,7,22:18.4
-15,7,22:18.4
-6,7,22:18.12
-5,7,22:18.12
-4,7,22:18.12
-3,7,22:18.12
-2,7,22:18.12
1,7,22:18.12
2,7,22:18.12
3,7,22:18.12
6,7,22:18.12
7,7,22:18.12
9,7,22:18.12
10,7,22:18.12
11,7,22:18.12
12,7,22:18.12
13,7,22:18.12
14,7,22:18.12
15,7,22:18.12
16,7,22:18.12
17,7,22:18.12
-17,8,22:18.4
-7,8,22:18.12
1,8,22:18.12
2,8,22:18.12
3,8,22:18.12
6,8,22:17.12
7,8,22:18.12
8,8,22:18.12
9,8,22:18.12
10,8,22:18.12
11,8,22:18.4
13,8,22:18.12
14,8,22:18.12
15,8,22:18.12
16,8,22:18.12
-7,9,22:18.12
0,9,22:18.12
1,9,22:18.12
2,9,22:18.12
3,9,22:18.12
4,9,22:18.12
5,9,22:17.12
6,9,22:17.12
8,9,22:18.12
9,9,22:18.12
10,9,22:18.12
11,9,22:18.4
12,9,22:18.4
13,9,22:18.4
14,9,22:18.4
15,9,22:18.12
-8,10,22:18.12
-7,10,22:18.12
-6,10,22:18.12
-5,10,22:18.12
0,10,22:18.12
1,10,22:18.12
2,10,22:18.12
3,10,22:18.12
4,10,22:18.12
5,10,22:18.12
6,10,22:17.12
8,10,22:18.12
9,10,22:18.12
10,10,22:18.12
11,10,22:18.4
12,10,22:18.4
15,10,22:18.4
-12,11,22:18.12
-11,11,22:18.12
-10,11,22:18.12
-9,11,22:18.12
-8,11,22:18.12
-7,11,22:18.12
-6,11,22:18.12
-5,11,22:18.12
-4,11,22:18.12
-1,11,22:18.12
0,11,22:18.12
1,11,22:18.12
2,11,22:18.12
3,11,22:18.12
4,11,22:18.12
8,11,22:18.12
9,11,22:18.12
10,11,22:18.12
-9,12,22:18.12
-8,12,22:17.12
-7,12,22:17.12
-6,12,22:18.12
-5,12,22:18.12
-3,12,22:18.12
-2,12,22:18.12
-1,12,22:18.12
0,12,22:18.4
1,12,22:18.12
3,12,22:18.12
4,12,22:18.12
9,12,22:18.12
10,12,22:18.12
-8,13,22:18.12
-6,13,22:18.12
-5,13,22:18.12
-3,13,22:18.12
-2,13,22:18.12
-1,13,22:18.4
0,13,22:18.4
4,13,22:18.12
5,13,22:18.12
9,13,22:18.12
10,13,22:18.12
11,13,22:18.4
12,13,22:18.4
-10,14,22:18.12
-9,14,22:18.12
-8,14,22:18.12
-7,14,22:18.12
-6,14,22:18.12
-2,14,22:18.12
-1,14,22:18.4
4,14,22:18.12
5,14,22:18.12
10,14,22:18.12
11,14,22:18.4
-10,15,22:18.12
-9,15,22:18.12
-8,15,22:18.12
-7,15,22:18.12
-6,15,22:18.12
4,15,22:18.12
5,15,22:18.12
-6,16,22:18.12
5,16,22:18.4
-6,17,22:18.12
-6,18,22:18.12
11,-26,23:18.12
10,-25,23:18.12
11,-25,23:18.12
3,-24,23:18.12
10,-24,23:18.12
3,-23,23:18.12
9,-23,23:18.12
11,-23,23:18.12
12,-23,23:18.12
0,-22,23:18.4
3,-22,23:18.12
8,-22,23:18.12
9,-22,23:18.12
11,-22,23:18.12
0,-21,23:18.4
2,-21,23:18.12
3,-21,23:18.12
4,-21,23:18.12
5,-21,23:18.12
6,-21,23:18.12
7,-21,23:18.12
8,-21,23:18.12
-11,-20,23:18.4
0,-20,23:18.4
3,-20,23:18.12
4,-20,23:18.12
5,-20,23:18.12
6,-20,23:18.12
8,-20,23:18.12
12,-20,23:18.12
-12,-19,23:18.4
-11,-19,23:18.4
-1,-19,23:18.12
0,-19,23:18.12
1,-19,23:18.12
4,-19,23:18.12
8,-19,23:18.12
9,-19,23:18.12
12,-19,23:18.12
-12,-18,23:18.4
-11,-18,23:18.4
-1,-18,23:18.12
0,-18,23:18.12
1,-18,23:18.12
4,-18,23:18.12
9,-18,23:18.12
12,-18,23:18.12
13,-18,23:18.4
-12,-17,23:18.4
-11,-17,23:18.4
-7,-17,23:18.12
-1,-17,23:18.12
0,-17,23:18.12
2,-17,23:18.12
4,-17,23:18.12
9,-17,23:18.12
10,-17,23:18.12
11,-17,23:18.12
12,-17,23:18.12
13,-17,23:18.4
14,-17,23:18.4
-18,-16,23:18.4
-17,-16,23:18.4
-16,-16,23:18.4
-15,-16,23:18.4
-14,-16,23:18.4
-13,-16,23:18.4
-12,-16,23:18.4
-8,-16,23:18.12
-7,-16,23:18.12
-6,-16,23:18.12
-5,-16,23:18.12
-2,-16,23:18.12
-1,-16,23:18.12
2,-16,23:18.12
5,-16,23:17.12
7,-16,23:18.12
8,-16,23:18.12
9,-16,23:18.12
14,-16,23:18.4
15,-16,23:18.4
-17,-15,23:18.12
-16,-15,23:18.12
-15,-15,23:18.12
-14,-15,23:18.12
-13,-15,23:18.12
-12,-15,23:18.12
-7,-15,23:18.12
-6,-15,23:18.12
-5,-15,23:18.12
-4,-15,23:18.12
-3,-15,23:18.12
-2,-15,23:18.12
-1,-15,23:18.12
2,-15,23:18.12
5,-15,23:18.12
7,-15,23:18.12
14,-15,23:18.4
-16,-14,23:18.12
-15,-14,23:18.12
-12,-14,23:18.12
-6,-14,23:18.12
-5,-14,23:18.12
-4,-14,23:18.12
-3,-14,23:18.12
-2,-14,23:18.12
-1,-14,23:18.12
4,-14,23:18.12
5,-14,23:18.12
11,-14,23:18.12
12,-14,23:18.12
13,-14,23:18.12
14,-14,23:18.12
-18,-13,23:18.12
-15,-13,23:18.12
-12,-13,23:18.12
-11,-13,23:18.12
-4,-13,23:18.12
-3,-13,23:18.12
-2,-13,23:18.12
4,-13,23:18.12
5,-13,23:18.12
9,-13,23:18.12
10,-13,23:18.12
11,-13,23:18.12
12,-13,23:18.12
13,-13,23:18.12
14,-13,23:18.12
-15,-12,23:18.12
-14,-12,23:18.12
-11,-12,23:18.12
-3,-12,23:18.12
-2,-12,23:18.12
4,-12,23:18.12
8,-12,23:18.12
9,-12,23:18.12
10,-12,23:18.12
11,-12,23:18.12
12,-12,23:18.12
13,-12,23:18.12
14,-12,23:18.12
-17,-11,23:17.12
-16,-11,23:17.12
-15,-11,23:18.12
-14,-11,23:18.12
-13,-11,23:18.12
-12,-11,23:18.12
-11,-11,23:18.12
-10,-11,23:18.12
-5,-11,23:18.12
-2,-11,23:18.12
-1,-11,23:17.12
3,-11,23:18.12
9,-11,23:18.12
12,-11,23:18.12
13,-11,23:18.12
14,-11,23:18.12
-15,-10,23:18.12
-14,-10,23:18.12
-13,-10,23:18.12
-10,-10,23:18.12
-4,-10,23:18.12
-3,-10,23:18.12
-2,-10,23:17.12
-1,-10,23:17.12
3,-10,23:18.12
9,-10,23:18.12
11,-10,23:18.12
12,-10,23:18.12
13,-10,23:18.12
14,-10,23:18.12
-19,-9,23:18.12
-15,-9,23:18.12
-14,-9,23:18.12
-13,-9,23:18.12
-3,-9,23:18.12
-2,-9,23:17.12
-1,-9,23:18.12
3,-9,23:18.12
6,-9,23:18.12
9,-9,23:18.12
10,-9,23:18.12
13,-9,23:18.12
14,-9,23:18.12
-19,-8,23:18.12
-18,-8,23:18.12
-17,-8,23:18.12
-16,-8,23:18.12
-15,-8,23:18.12
-13,-8,23:18.12
-8,-8,23:17.12
-3,-8,23:18.12
-2,-8,23:18.12
6,-8,23:18.12
7,-8,23:18.12
8,-8,23:17.12
9,-8,23:17.12
12,-8,23:18.12
-18,-7,23:18.12
-17,-7,23:18.12
-16,-7,23:18.12
-15,-7,23:18.12
-14,-7,23:18.12
-13,-7,23:18.12
-12,-7,23:18.12
-11,-7,23:18.12
-8,-7,23:17.12
-7,-7,23:18.12
-4,-7,23:18.12
-3,-7,23:18.12
6,-7,23:18.12
7,-7,23:18.12
8,-7,23:17.12
9,-7,23:17.12
12,-7,23:18.12
13,-7,23:18.12
-16,-6,23:18.12
-15,-6,23:18.12
-14,-6,23:18.12
-7,-6,23:18.12
-6,-6,23:18.12
-5,-6,23:18.12
-4,-6,23:18.12
6,-6,23:18.12
7,-6,23:18.12
13,-6,23:18.12
14,-6,23:18.12
15,-6,23:18.12
-16,-5,23:18.4
-15,-5,23:18.12
-14,-5,23:18.12
-10,-5,23:18.12
-9,-5,23:18.12
-8,-5,23:18.12
-7,-5,23:18.12
-5,-5,23:18.12
-1,-5,23:17.12
0,-5,23:17.12
6,-5,23:18.12
7,-5,23:18.12
14,-5,23:18.12
15,-5,23:18.12
16,-5,23:18.12
-17,-4,23:18.4
-16,-4,23:18.4
-15,-4,23:18.4
-14,-4,23:18.12
-13,-4,23:18.12
-12,-4,23:18.12
-11,-4,23:18.12
-10,-4,23:18.12
-1,-4,23:17.12
0,-4,23:17.12
1,-4,23:17.12
5,-4,23:18.12
6,-4,23:18.12
7,-4,23:18.12
8,-4,23:18.12
12,-4,23:18.12
13,-4,23:18.12
15,-4,23:18.12
16,-4,23:18.12
17,-4,23:18.4
-17,-3,23:18.4
-16,-3,23:18.4
-14,-3,23:18.12
-13,-3,23:18.12
-1,-3,23:17.12
2,-3,23:18.12
4,-3,23:18.12
5,-3,23:18.12
8,-3,23:18.12
9,-3,23:18.12
10,-3,23:18.12
11,-3,23:18.12
15,-3,23:18.12
16,-3,23:18.12
17,-3,23:18.12
-17,-2,23:18.12
-16,-2,23:18.12
-15,-2,23:18.12
-14,-2,23:18.12
-13,-2,23:18.12
-12,-2,23:18.12
-11,-2,23:18.12
-10,-2,23:18.12
-9,-2,23:18.12
-8,-2,23:18.12
-1,-2,23:18.12
0,-2,23:18.12
1,-2,23:18.12
2,-2,23:18.12
3,-2,23:18.12
4,-2,23:18.12
10,-2,23:18.12
11,-2,23:18.12
14,-2,23:18.12
15,-2,23:18.12
16,-2,23:18.12
17,-2,23:18.12
-14,-1,23:18.12
-12,-1,23:18.12
-11,-1,23:18.12
-10,-1,23:18.12
-9,-1,23:18.12
-8,-1,23:17.12
-7,-1,23:17.12
-6,-1,23:17.12
1,-1,23:18.12
2,-1,23:18.12
13,-1,23:18.12
14,-1,23:18.12
15,-1,23:18.12
16,-1,23:18.12
-14,0,23:18.12
-12,0,23:18.12
-11,0,23:18.12
-10,0,23:18.12
-9,0,23:17.12
-8,0,23:17.12
-7,0,23:17.12
2,0,23:18.12
13,0,23:18.12
14,0,23:18.12
15,0,23:18.12
16,0,23:18.12
-12,1,23:18.12
-11,1,23:18.12
-10,1,23:18.12
-9,1,23:17.12
-8,1,23:17.12
2,1,23:18.12
12,1,23:17.12
14,1,23:18.12
15,1,23:18.12
16,1,23:18.12
17,1,23:18.12
-12,2,23:18.12
-11,2,23:18.12
3,2,23:18.12
12,2,23:17.12
13,2,23:18.12
14,2,23:18.12
15,2,23:18.12
16,2,23:18.12
17,2,23:18.12
19,2,23:18.12
-12,3,23:18.12
-11,3,23:18.12
-10,3,23:18.12
-9,3,23:18.12
-8,3,23:18.12
-7,3,23:18.12
3,3,23:18.12
14,3,23:17.12
15,3,23:17.12
16,3,23:17.12
17,3,23:18.12
-13,4,23:18.12
-12,4,23:18.12
-11,4,23:18.12
-10,4,23:18.12
-9,4,23:18.12
-8,4,23:18.12
-7,4,23:18.12
3,4,23:18.12
4,4,23:18.12
15,4,23:18.12
16,4,23:17.12
17,4,23:18.12
-14,5,23:18.12
-13,5,23:18.12
-8,5,23:18.12
-7,5,23:18.12
4,5,23:18.12
15,5,23:18.12
-15,6,23:18.12
-7,6,23:18.12
3,6,23:18.12
4,6,23:18.12
5,6,23:18.12
11,6,23:18.12
12,6,23:18.12
15,6,23:18.12
-16,7,23:18.12
-15,7,23:18.12
-7,7,23:18.12
-6,7,23:18.12
-5,7,23:18.12
-4,7,23:18.12
-3,7,23:18.12
-2,7,23:18.12
-1,7,23:18.12
0,7,23:18.12
3,7,23:18.12
5,7,23:18.12
6,7,23:18.12
12,7,23:18.12
13,7,23:18.12
14,7,23:18.12
15,7,23:18.12
16,7,23:18.12
-17,8,23:18.4
-7,8,23:18.12
0,8,23:18.12
1,8,23:18.12
3,8,23:18.12
6,8,23:18.12
7,8,23:18.12
8,8,23:18.12
9,8,23:18.12
10,8,23:18.12
11,8,23:18.4
12,8,23:18.12
13,8,23:18.12
14,8,23:18.12
15,8,23:18.12
16,8,23:18.12
-7,9,23:18.12
0,9,23:18.12
1,9,23:18.12
2,9,23:18.12
3,9,23:18.12
4,9,23:18.12
5,9,23:18.12
6,9,23:17.12
7,9,23:18.12
8,9,23:18.12
9,9,23:18.12
10,9,23:18.12
11,9,23:18.4
12,9,23:18.4
13,9,23:18.4
14,9,23:18.4
15,9,23:18.12
16,9,23:18.12
-8,10,23:18.12
-1,10,23:18.12
0,10,23:18.12
1,10,23:18.12
2,10,23:18.12
3,10,23:18.12
4,10,23:18.12
5,10,23:18.12
6,10,23:18.12
9,10,23:18.12
10,10,23:18.12
11,10,23:18.4
-13,11,23:18.12
-12,11,23:18.12
-9,11,23:18.12
-8,11,23:18.12
-2,11,23:18.12
-1,11,23:18.12
0,11,23:18.12
1,11,23:18.12
2,11,23:18.12
3,11,23:18.12
4,11,23:18.12
5,11,23:18.12
6,11,23:18.12
7,11,23:18.12
8,11,23:18.12
10,11,23:18.12
11,11,23:18.4
-12,12,23:18.12
-11,12,23:18.12
-10,12,23:18.12
-9,12,23:18.12
-8,12,23:18.12
-7,12,23:18.12
-6,12,23:18.12
-5,12,23:18.12
-3,12,23:18.12
-2,12,23:18.12
-1,12,23:18.12
0,12,23:18.4
1,12,23:18.12
3,12,23:18.12
4,12,23:18.12
6,12,23:18.12
7,12,23:18.12
8,12,23:18.12
9,12,23:18.12
10,12,23:18.12
11,12,23:18.4
12,12,23:18.4
-9,13,23:18.12
-8,13,23:17.12
-5,13,23:18.12
-4,13,23:18.12
-3,13,23:18.12
-2,13,23:18.12
0,13,23:18.4
1,13,23:18.12
2,13,23:18.12
3,13,23:18.12
4,13,23:18.12
5,13,23:18.12
6,13,23:18.12
8,13,23:18.12
9,13,23:18.12
10,13,23:18.12
11,13,23:18.4
12,13,23:18.4
-9,14,23:17.12
-5,14,23:18.12
-3,14,23:18.12
-2,14,23:18.12
-1,14,23:18.4
0,14,23:18.4
1,14,23:18.12
3,14,23:18.12
4,14,23:18.12
5,14,23:18.12
6,14,23:18.12
10,14,23:18.12
11,14,23:18.4
12,14,23:18.4
13,14,23:18.4
-10,15,23:18.12
-9,15,23:18.12
-6,15,23:18.12
-5,15,23:18.12
4,15,23:18.12
5,15,23:18.12
11,15,23:18.4
12,15,23:18.4
13,15,23:18.4
-10,16,23:18.12
-9,16,23:18.12
-8,16,23:18.12
-7,16,23:18.12
-6,16,23:18.12
4,16,23:18.4
5,16,23:18.4
13,16,23:18.4
-9,17,23:18.12
-8,17,23:18.12
-7,17,23:18.12
-6,17,23:18.12
4,17,23:18.4
11,-26,24:18.12
10,-25,24:18.12
3,-24,24:18.12
9,-24,24:18.12
10,-24,24:18.12
3,-23,24:18.12
9,-23,24:18.12
3,-22,24:18.12
4,-22,24:18.12
5,-22,24:18.12
6,-22,24:18.12
7,-22,24:18.12
8,-22,24:18.12
-1,-21,24:18.4
0,-21,24:18.4
2,-21,24:18.12
3,-21,24:18.12
4,-21,24:18.12
5,-21,24:18.12
6,-21,24:18.12
7,-21,24:18.12
8,-21,24:18.12
-13,-20,24:18.4
-12,-20,24:18.4
-2,-20,24:18.4
-1,-20,24:18.4
4,-20,24:18.12
8,-20,24:18.12
9,-20,24:18.12
-12,-19,24:18.4
-7,-19,24:18.12
-2,-19,24:18.12
-1,-19,24:18.12
1,-19,24:18.12
4,-19,24:18.12
9,-19,24:18.12
-14,-18,24:18.4
-13,-18,24:18.4
-7,-18,24:18.12
-6,-18,24:18.12
-5,-18,24:18.12
-2,-18,24:18.12
-1,-18,24:18.12
1,-18,24:18.12
4,-18,24:18.12
9,-18,24:18.12
10,-18,24:18.12
11,-18,24:18.12
12,-18,24:18.12
13,-18,24:18.4
14,-18,24:18.4
-17,-17,24:18.4
-16,-17,24:18.4
-15,-17,24:18.4
-14,-17,24:18.4
-13,-17,24:18.4
-7,-17,24:18.12
-6,-17,24:18.12
-5,-17,24:18.12
-4,-17,24:18.12
-3,-17,24:18.12
-2,-17,24:18.12
-1,-17,24:18.12
5,-17,24:18.12
6,-17,24:17.12
9,-17,24:18.12
10,-17,24:18.12
11,-17,24:18.12
-17,-16,24:18.4
-16,-16,24:18.4
-15,-16,24:18.4
-14,-16,24:18.4
-13,-16,24:18.4
-6,-16,24:18.12
-5,-16,24:18.12
-4,-16,24:18.12
-3,-16,24:18.12
-2,-16,24:18.12
5,-16,24:18.12
6,-16,24:18.12
8,-16,24:18.12
9,-16,24:18.12
12,-16,24:18.4
14,-16,24:18.4
-17,-15,24:18.12
-16,-15,24:18.12
-13,-15,24:18.12
-4,-15,24:18.12
-3,-15,24:18.12
-2,-15,24:18.12
5,-15,24:18.12
10,-15,24:18.12
11,-15,24:18.12
12,-15,24:18.12
13,-15,24:18.12
14,-15,24:18.12
-19,-14,24:18.12
-16,-14,24:18.12
-12,-14,24:18.12
-3,-14,24:17.12
-2,-14,24:18.12
3,-14,24:18.12
4,-14,24:18.12
5,-14,24:18.12
9,-14,24:18.12
10,-14,24:18.12
11,-14,24:18.12
12,-14,24:18.12
13,-14,24:18.12
14,-14,24:18.12
-18,-13,24:18.12
-17,-13,24:18.12
-16,-13,24:18.12
-15,-13,24:18.12
-12,-13,24:18.12
-11,-13,24:18.12
-3,-13,24:17.12
-2,-13,24:18.12
2,-13,24:18.12
5,-13,24:18.12
8,-13,24:18.12
9,-13,24:18.12
10,-13,24:18.12
11,-13,24:18.12
12,-13,24:18.12
13,-13,24:18.12
14,-13,24:18.12
15,-13,24:18.12
16,-13,24:18.12
-17,-12,24:18.12
-16,-12,24:18.12
-15,-12,24:18.12
-14,-12,24:18.12
-12,-12,24:18.12
-11,-12,24:18.12
-10,-12,24:18.12
-7,-12,24:18.12
-6,-12,24:18.12
-5,-12,24:18.12
-4,-12,24:18.12
-3,-12,24:18.12
-2,-12,24:17.12
5,-12,24:18.12
6,-12,24:18.12
9,-12,24:18.12
10,-12,24:18.12
11,-12,24:18.12
12,-12,24:18.12
13,-12,24:18.12
14,-12,24:18.12
15,-12,24:18.12
16,-12,24:18.12
-18,-11,24:17.12
-17,-11,24:17.12
-15,-11,24:18.12
-14,-11,24:18.12
-13,-11,24:18.12
-12,-11,24:18.12
-11,-11,24:18.12
-10,-11,24:18.12
-6,-11,24:18.12
-5,-11,24:18.12
-4,-11,24:18.12
-3,-11,24:18.12
-2,-11,24:17.12
-1,-11,24:17.12
9,-11,24:18.12
10,-11,24:18.12
11,-11,24:18.12
12,-11,24:18.12
14,-11,24:18.12
15,-11,24:18.12
-16,-10,24:18.12
-15,-10,24:18.12
-14,-10,24:18.12
-10,-10,24:18.12
-5,-10,24:18.12
-4,-10,24:18.12
-3,-10,24:17.12
-2,-10,24:17.12
7,-10,24:18.12
9,-10,24:18.12
10,-10,24:18.12
12,-10,24:18.12
14,-10,24:18.12
15,-10,24:18.12
-16,-9,24:18.12
-14,-9,24:18.12
-4,-9,24:18.12
7,-9,24:18.12
9,-9,24:17.12
10,-9,24:18.12
11,-9,24:17.12
14,-9,24:18.12
-17,-8,24:18.12
-16,-8,24:18.12
-14,-8,24:18.12
-9,-8,24:17.12
-8,-8,24:18.12
-7,-8,24:18.12
-4,-8,24:18.12
-3,-8,24:18.12
-2,-8,24:18.12
-1,-8,24:18.12
7,-8,24:18.12
8,-8,24:17.12
9,-8,24:17.12
10,-8,24:17.12
11,-8,24:17.12
12,-8,24:18.12
13,-8,24:18.12
14,-8,24:18.12
-19,-7,24:18.12
-18,-7,24:18.12
-14,-7,24:18.12
-13,-7,24:18.12
-12,-7,24:18.12
-11,-7,24:18.12
-10,-7,24:18.12
-8,-7,24:18.12
-7,-7,24:18.12
-5,-7,24:18.12
-4,-7,24:18.12
7,-7,24:18.12
8,-7,24:17.12
9,-7,24:17.12
10,-7,24:17.12
13,-7,24:18.12
14,-7,24:18.12
15,-7,24:18.12
16,-7,24:18.12
-18,-6,24:18.12
-17,-6,24:18.12
-16,-6,24:18.12
-15,-6,24:18.12
-14,-6,24:18.12
-7,-6,24:18.12
-6,-6,24:18.12
-5,-6,24:18.12
7,-6,24:18.12
15,-6,24:18.12
16,-6,24:18.12
-18,-5,24:18.4
-17,-5,24:18.4
-14,-5,24:18.12
-10,-5,24:18.12
-9,-5,24:18.12
-8,-5,24:18.12
-7,-5,24:18.12
-6,-5,24:18.12
-1,-5,24:17.12
0,-5,24:17.12
7,-5,24:18.12
16,-5,24:18.12
18,-5,24:18.12
-18,-4,24:18.4
-17,-4,24:18.4
-16,-4,24:18.4
-15,-4,24:18.4
-13,-4,24:18.12
-12,-4,24:18.12
-11,-4,24:18.12
-10,-4,24:18.12
-8,-4,24:18.12
-3,-4,24:18.12
-2,-4,24:18.12
-1,-4,24:17.12
0,-4,24:17.12
1,-4,24:17.12
7,-4,24:18.12
8,-4,24:18.12
17,-4,24:18.4
18,-4,24:18.4
-18,-3,24:18.4
-17,-3,24:18.4
-16,-3,24:18.4
-15,-3,24:18.12
-14,-3,24:18.12
-13,-3,24:18.12
-11,-3,24:18.12
-10,-3,24:18.12
-9,-3,24:18.12
-2,-3,24:18.12
3,-3,24:18.12
5,-3,24:18.12
6,-3,24:18.12
7,-3,24:18.12
8,-3,24:18.12
9,-3,24:18.12
10,-3,24:18.12
17,-3,24:18.12
18,-3,24:18.4
-15,-2,24:18.12
-14,-2,24:18.12
-13,-2,24:18.12
-12,-2,24:18.12
-11,-2,24:18.12
-10,-2,24:18.12
2,-2,24:18.12
3,-2,24:18.12
4,-2,24:18.12
5,-2,24:18.12
10,-2,24:18.12
11,-2,24:18.12
17,-2,24:18.12
18,-2,24:18.4
-14,-1,24:18.12
-13,-1,24:18.12
-12,-1,24:18.12
-11,-1,24:18.12
-10,-1,24:18.12
-7,-1,24:18.12
-1,-1,24:18.12
0,-1,24:18.12
1,-1,24:18.12
2,-1,24:18.12
3,-1,24:18.12
16,-1,24:18.12
17,-1,24:18.12
-14,0,24:18.12
-13,0,24:18.12
-12,0,24:18.12
-11,0,24:18.12
-10,0,24:18.12
-9,0,24:17.12
-8,0,24:18.12
-7,0,24:18.12
0,0,24:18.12
1,0,24:18.12
2,0,24:18.12
16,0,24:18.12
17,0,24:18.12
18,0,24:18.12
19,0,24:18.12
20,0,24:18.12
-14,1,24:18.12
-13,1,24:18.12
-11,1,24:17.12
-10,1,24:17.12
-9,1,24:18.12
-8,1,24:18.12
2,1,24:18.12
12,1,24:17.12
15,1,24:18.12
16,1,24:18.12
17,1,24:18.12
18,1,24:18.12
19,1,24:18.12
20,1,24:18.12
21,1,24:18.12
-14,2,24:18.12
-13,2,24:18.12
-11,2,24:17.12
-10,2,24:18.12
-9,2,24:18.12
2,2,24:18.12
3,2,24:18.12
20,2,24:18.12
21,2,24:18.12
-15,3,24:18.12
-14,3,24:18.12
-13,3,24:18.12
-9,3,24:18.12
3,3,24:18.12
15,3,24:17.12
16,3,24:17.12
-15,4,24:18.12
-14,4,24:18.12
-13,4,24:18.12
-9,4,24:18.12
-8,4,24:18.12
-7,4,24:18.12
3,4,24:18.12
4,4,24:18.12
15,4,24:18.12
16,4,24:17.12
17,4,24:17.12
18,4,24:17.12
-15,5,24:18.12
-14,5,24:18.12
-13,5,24:18.12
-12,5,24:18.12
-11,5,24:18.12
-10,5,24:18.12
-9,5,24:18.12
-8,5,24:18.12
-7,5,24:18.12
4,5,24:18.12
16,5,24:18.12
17,5,24:18.12
18,5,24:18.12
19,5,24:17.12
20,5,24:17.12
-15,6,24:18.12
-13,6,24:18.12
-12,6,24:18.12
-11,6,24:18.12
-10,6,24:18.12
-9,6,24:18.12
-8,6,24:18.12
-7,6,24:18.12
4,6,24:18.12
16,6,24:18.12
17,6,24:18.12
18,6,24:18.12
19,6,24:18.12
20,6,24:17.12
-16,7,24:18.12
-7,7,24:18.12
-5,7,24:18.12
-4,7,24:18.12
-3,7,24:18.12
-2,7,24:18.4
-1,7,24:18.12
3,7,24:18.12
5,7,24:18.12
6,7,24:18.12
16,7,24:18.12
17,7,24:18.12
-7,8,24:18.12
-6,8,24:18.12
-5,8,24:18.12
-4,8,24:18.12
3,8,24:18.12
5,8,24:18.12
6,8,24:18.12
7,8,24:18.12
8,8,24:18.12
9,8,24:18.12
16,8,24:18.12
-7,9,24:18.12
0,9,24:18.12
1,9,24:18.12
2,9,24:18.12
3,9,24:18.12
4,9,24:18.12
5,9,24:18.12
7,9,24:18.12
8,9,24:18.12
9,9,24:18.12
10,9,24:18.12
14,9,24:18.4
15,9,24:18.12
16,9,24:18.12
17,9,24:18.12
-8,10,24:18.12
1,10,24:18.12
3,10,24:18.12
4,10,24:18.12
5,10,24:17.12
6,10,24:17.12
8,10,24:18.12
9,10,24:18.12
11,10,24:18.4
12,10,24:18.4
13,10,24:18.4
14,10,24:18.4
15,10,24:18.4
16,10,24:18.12
17,10,24:18.12
-9,11,24:18.12
-8,11,24:18.12
0,11,24:18.12
1,11,24:18.12
3,11,24:18.12
4,11,24:18.12
5,11,24:18.12
6,11,24:18.12
9,11,24:18.12
12,11,24:18.4
13,11,24:18.4
14,11,24:18.4
15,11,24:18.4
-14,12,24:18.4
-13,12,24:18.12
-12,12,24:18.12
-11,12,24:18.12
-9,12,24:18.12
-8,12,24:18.12
-1,12,24:18.4
0,12,24:18.4
1,12,24:18.12
3,12,24:18.12
4,12,24:18.12
5,12,24:18.12
7,12,24:18.12
12,12,24:18.4
13,12,24:18.4
14,12,24:18.4
-12,13,24:18.12
-11,13,24:18.12
-10,13,24:18.12
-9,13,24:18.12
-4,13,24:18.12
-2,13,24:18.4
-1,13,24:18.4
0,13,24:18.4
1,13,24:18.12
2,13,24:18.12
4,13,24:18.12
5,13,24:18.12
7,13,24:18.12
8,13,24:18.12
13,13,24:18.4
14,13,24:18.4
-10,14,24:18.12
-9,14,24:18.12
-4,14,24:18.12
-3,14,24:18.12
-2,14,24:18.4
-1,14,24:18.4
0,14,24:18.4
1,14,24:18.12
2,14,24:18.12
3,14,24:18.12
5,14,24:18.12
6,14,24:18.12
7,14,24:18.12
8,14,24:18.12
9,14,24:18.12
10,14,24:18.12
13,14,24:18.4
14,14,24:18.4
15,14,24:18.4
-10,15,24:18.12
-9,15,24:18.12
-5,15,24:18.12
-4,15,24:18.12
-3,15,24:18.12
-2,15,24:18.4
-1,15,24:18.4
2,15,24:18.12
3,15,24:18.12
4,15,24:18.12
5,15,24:18.12
6,15,24:18.12
7,15,24:18.12
8,15,24:18.12
9,15,24:18.12
10,15,24:18.12
11,15,24:18.4
14,15,24:18.4
-10,16,24:18.12
-9,16,24:18.12
-5,16,24:18.12
-3,16,24:18.12
-2,16,24:18.4
3,16,24:18.4
4,16,24:18.4
5,16,24:18.4
6,16,24:18.4
7,16,24:18.4
10,16,24:18.4
11,16,24:18.4
12,16,24:18.4
-9,17,24:18.12
-6,17,24:18.12
-5,17,24:18.12
-3,17,24:18.4
4,17,24:18.4
5,17,24:18.4
6,17,24:18.4
7,17,24:18.4
11,17,24:18.4
12,17,24:18.4
13,17,24:18.4
-6,18,24:18.12
5,18,24:18.4
6,18,24:18.4
5,19,24:18.4
6,19,24:18.4
11,-26,25:18.12
10,-25,25:18.12
9,-24,25:18.12
10,-24,25:18.12
9,-23,25:18.12
2,-22,25:18.12
3,-22,25:18.12
4,-22,25:18.12
5,-22,25:18.12
6,-22,25:18.12
7,-22,25:18.12
8,-22,25:18.12
-3,-21,25:18.12
-2,-21,25:18.12
4,-21,25:18.12
8,-21,25:18.12
9,-21,25:18.12
-14,-20,25:18.4
-7,-20,25:18.12
-6,-20,25:18.12
-5,-20,25:18.12
-3,-20,25:18.12
-2,-20,25:18.12
4,-20,25:18.12
7,-20,25:17.12
9,-20,25:18.12
-15,-19,25:18.4
-14,-19,25:18.4
-7,-19,25:18.12
-6,-19,25:18.12
-5,-19,25:18.12
-4,-19,25:18.12
-3,-19,25:18.12
-2,-19,25:18.12
-1,-19,25:18.12
7,-19,25:17.12
9,-19,25:18.12
10,-19,25:18.12
-14,-18,25:18.4
-5,-18,25:18.12
-4,-18,25:18.12
-3,-18,25:18.12
-2,-18,25:18.12
6,-18,25:17.12
10,-18,25:18.12
11,-18,25:18.12
12,-18,25:18.4
13,-18,25:18.4
-14,-17,25:18.4
-3,-17,25:18.12
-2,-17,25:18.12
6,-17,25:17.12
10,-17,25:18.12
11,-17,25:18.12
-17,-16,25:18.4
-14,-16,25:18.4
-13,-16,25:18.4
-3,-16,25:18.12
-2,-16,25:18.12
6,-16,25:18.12
9,-16,25:18.12
11,-16,25:18.12
12,-16,25:18.4
-17,-15,25:18.12
-13,-15,25:18.12
-4,-15,25:18.12
-3,-15,25:18.12
-2,-15,25:18.12
5,-15,25:18.12
6,-15,25:18.12
10,-15,25:18.12
11,-15,25:18.12
14,-15,25:18.12
-19,-14,25:18.12
-16,-14,25:18.12
-12,-14,25:18.12
-11,-14,25:18.12
-10,-14,25:18.12
-9,-14,25:18.12
-8,-14,25:18.12
-7,-14,25:18.12
-4,-14,25:18.12
-3,-14,25:17.12
-2,-14,25:18.12
3,-14,25:18.12
4,-14,25:18.12
5,-14,25:18.12
10,-14,25:18.12
11,-14,25:18.12
12,-14,25:18.12
13,-14,25:18.12
14,-14,25:18.12
15,-14,25:18.12
16,-14,25:18.12
-19,-13,25:18.12
-18,-13,25:18.12
-16,-13,25:18.12
-12,-13,25:18.12
-11,-13,25:18.12
-10,-13,25:18.12
-9,-13,25:18.12
-8,-13,25:18.12
-7,-13,25:18.12
-6,-13,25:18.12
-5,-13,25:18.12
-4,-13,25:18.12
-3,-13,25:17.12
-2,-13,25:18.12
-1,-13,25:18.12
1,-13,25:18.12
2,-13,25:18.12
5,-13,25:18.12
11,-13,25:18.12
12,-13,25:18.12
13,-13,25:18.12
14,-13,25:18.12
15,-13,25:18.12
-17,-12,25:18.12
-16,-12,25:18.12
-15,-12,25:18.12
-14,-12,25:18.12
-13,-12,25:18.12
-12,-12,25:18.12
-11,-12,25:18.12
-6,-12,25:18.12
-5,-12,25:18.12
-4,-12,25:18.12
-3,-12,25:18.12
-2,-12,25:18.12
6,-12,25:18.12
11,-12,25:18.12
12,-12,25:18.12
13,-12,25:18.12
14,-12,25:18.12
15,-12,25:18.12
-20,-11,25:17.12
-19,-11,25:17.12
-16,-11,25:18.12
-15,-11,25:18.12
-14,-11,25:18.12
-13,-11,25:18.12
-11,-11,25:18.12
-10,-11,25:18.12
-6,-11,25:18.12
-3,-11,25:18.12
-2,-11,25:17.12
7,-11,25:18.12
11,-11,25:18.12
12,-11,25:18.12
13,-11,25:18.12
14,-11,25:18.12
-17,-10,25:18.12
-16,-10,25:18.12
-15,-10,25:18.12
-14,-10,25:18.12
-6,-10,25:18.12
-5,-10,25:18.12
7,-10,25:18.12
11,-10,25:18.12
12,-10,25:18.12
13,-10,25:18.12
-17,-9,25:18.12
-15,-9,25:18.12
-14,-9,25:18.12
-6,-9,25:18.12
-5,-9,25:18.12
7,-9,25:18.12
8,-9,25:18.12
10,-9,25:18.12
11,-9,25:17.12
12,-9,25:17.12
13,-9,25:17.12
14,-9,25:17.12
15,-9,25:18.12
-17,-8,25:18.12
-15,-8,25:18.12
-14,-8,25:18.12
-10,-8,25:17.12
-9,-8,25:18.12
-8,-8,25:18.12
-7,-8,25:18.12
-6,-8,25:18.12
-5,-8,25:18.12
-4,-8,25:18.12
-3,-8,25:18.12
-2,-8,25:18.12
-1,-8,25:18.12
7,-8,25:18.12
8,-8,25:18.12
9,-8,25:17.12
10,-8,25:17.12
11,-8,25:17.12
12,-8,25:17.12
13,-8,25:18.12
14,-8,25:18.12
15,-8,25:18.12
16,-8,25:18.12
17,-8,25:18.12
18,-8,25:18.12
-15,-7,25:18.12
-14,-7,25:18.12
-13,-7,25:18.12
-12,-7,25:18.12
-11,-7,25:18.12
-8,-7,25:18.12
-7,-7,25:18.12
-6,-7,25:18.12
-5,-7,25:18.12
8,-7,25:18.12
9,-7,25:18.12
10,-7,25:18.12
15,-7,25:18.12
16,-7,25:18.12
17,-7,25:18.12
18,-7,25:18.12
19,-7,25:18.12
20,-7,25:18.12
-16,-6,25:18.12
-15,-6,25:18.12
-14,-6,25:18.12
-9,-6,25:18.12
-8,-6,25:18.12
-7,-6,25:18.12
-6,-6,25:18.12
8,-6,25:18.12
18,-6,25:18.12
-18,-5,25:18.4
-15,-5,25:18.12
-10,-5,25:18.12
-9,-5,25:18.12
-8,-5,25:18.12
-7,-5,25:18.12
-6,-5,25:18.12
-5,-5,25:18.12
0,-5,25:17.12
8,-5,25:18.12
19,-5,25:18.4
20,-5,25:18.4
-15,-4,25:18.4
-13,-4,25:18.12
-12,-4,25:18.12
-11,-4,25:18.12
-10,-4,25:18.12
-5,-4,25:18.12
-4,-4,25:18.12
-3,-4,25:18.12
-2,-4,25:18.12
-1,-4,25:17.12
0,-4,25:17.12
1,-4,25:17.12
8,-4,25:18.12
19,-4,25:18.4
20,-4,25:18.4
-18,-3,25:18.4
-17,-3,25:18.4
-16,-3,25:18.4
-14,-3,25:18.12
-13,-3,25:18.12
-12,-3,25:18.12
-11,-3,25:18.12
-4,-3,25:18.12
-2,-3,25:18.12
-1,-3,25:17.12
0,-3,25:17.12
1,-3,25:17.12
4,-3,25:18.12
5,-3,25:18.12
6,-3,25:18.12
7,-3,25:18.12
8,-3,25:18.12
9,-3,25:18.12
18,-3,25:18.4
19,-3,25:18.4
-16,-2,25:18.12
-15,-2,25:18.12
-14,-2,25:18.12
-13,-2,25:18.12
-12,-2,25:18.12
-4,-2,25:18.12
-3,-2,25:18.12
3,-2,25:18.12
4,-2,25:18.12
5,-2,25:18.12
6,-2,25:18.12
10,-2,25:18.12
11,-2,25:18.12
18,-2,25:18.4
19,-2,25:18.4
-14,-1,25:18.12
-13,-1,25:18.12
-12,-1,25:18.12
-8,-1,25:18.12
-4,-1,25:18.12
3,-1,25:18.12
4,-1,25:18.12
5,-1,25:18.12
6,-1,25:18.12
17,-1,25:18.12
18,-1,25:18.12
19,-1,25:18.12
20,-1,25:18.12
21,-1,25:18.4
22,-1,25:18.4
-16,0,25:18.12
-15,0,25:18.12
-13,0,25:18.12
-12,0,25:18.12
-11,0,25:18.12
-8,0,25:18.12
-5,0,25:18.12
-1,0,25:18.12
0,0,25:18.12
2,0,25:18.12
3,0,25:18.12
16,0,25:18.12
17,0,25:18.12
19,0,25:18.12
20,0,25:18.12
21,0,25:18.12
22,0,25:18.12
-16,1,25:18.12
-15,1,25:18.12
-12,1,25:18.12
-11,1,25:18.12
-9,1,25:18.12
-8,1,25:18.12
-7,1,25:18.12
-5,1,25:18.12
-1,1,25:18.12
0,1,25:18.12
1,1,25:18.12
2,1,25:18.12
3,1,25:18.12
14,1,25:18.12
15,1,25:18.12
-17,2,25:18.12
-16,2,25:18.12
-15,2,25:18.12
-12,2,25:17.12
-11,2,25:18.12
-10,2,25:18.12
-6,2,25:18.12
2,2,25:18.12
3,2,25:18.12
-17,3,25:18.12
-16,3,25:18.12
-15,3,25:18.12
-12,3,25:18.12
-11,3,25:18.12
-10,3,25:18.12
3,3,25:18.12
16,3,25:17.12
-17,4,25:18.12
-16,4,25:18.12
-15,4,25:18.12
-13,4,25:18.12
-9,4,25:18.12
3,4,25:18.12
16,4,25:17.12
-17,5,25:18.12
-16,5,25:18.12
-9,5,25:18.12
-8,5,25:18.12
4,5,25:18.12
15,5,25:18.12
16,5,25:18.12
-17,6,25:18.12
-16,6,25:18.12
-12,6,25:18.12
-11,6,25:18.12
-10,6,25:18.12
-9,6,25:18.12
-8,6,25:18.12
-7,6,25:18.12
4,6,25:18.12
16,6,25:18.12
20,6,25:17.12
21,6,25:17.12
-18,7,25:18.12
-17,7,25:18.12
-16,7,25:18.12
-15,7,25:18.12
-14,7,25:18.12
-13,7,25:18.12
-12,7,25:18.12
-11,7,25:18.12
-10,7,25:18.12
-9,7,25:18.12
-8,7,25:18.12
-7,7,25:18.12
-1,7,25:18.4
4,7,25:18.12
5,7,25:18.12
16,7,25:18.12
17,7,25:18.12
18,7,25:18.12
19,7,25:18.12
-17,8,25:18.4
-16,8,25:18.4
-15,8,25:18.4
-14,8,25:18.4
-13,8,25:18.4
-12,8,25:18.12
-7,8,25:18.12
-6,8,25:18.12
-5,8,25:18.12
-4,8,25:18.12
-3,8,25:18.12
-2,8,25:18.4
-1,8,25:18.4
3,8,25:18.12
5,8,25:18.12
6,8,25:18.12
7,8,25:18.12
17,8,25:18.12
18,8,25:18.12
19,8,25:18.12
-8,9,25:18.12
-7,9,25:18.12
0,9,25:18.4
1,9,25:18.12
2,9,25:18.12
3,9,25:18.12
5,9,25:18.12
9,9,25:18.12
10,9,25:18.12
17,9,25:18.12
-8,10,25:18.12
1,10,25:18.12
2,10,25:18.12
3,10,25:18.12
4,10,25:18.12
6,10,25:17.12
8,10,25:18.12
9,10,25:18.12
11,10,25:18.4
12,10,25:18.4
17,10,25:18.12
-9,11,25:18.12
-8,11,25:18.12
1,11,25:18.12
3,11,25:18.12
4,11,25:18.12
6,11,25:17.12
13,11,25:18.4
14,11,25:18.4
15,11,25:18.4
16,11,25:18.4
17,11,25:18.4
-9,12,25:18.12
-8,12,25:18.12
1,12,25:18.12
3,12,25:18.12
4,12,25:18.12
7,12,25:18.12
14,12,25:18.4
15,12,25:18.4
16,12,25:18.4
-14,13,25:18.4
-13,13,25:18.12
-12,13,25:18.12
-11,13,25:18.12
-10,13,25:18.12
-9,13,25:18.12
-8,13,25:18.12
1,13,25:18.12
2,13,25:18.12
4,13,25:18.12
5,13,25:18.12
7,13,25:18.12
15,13,25:18.4
16,13,25:18.4
-11,14,25:18.12
-10,14,25:18.12
0,14,25:18.4
1,14,25:18.12
2,14,25:18.12
5,14,25:18.12
7,14,25:18.12
8,14,25:18.12
16,14,25:18.4
-10,15,25:18.12
-1,15,25:18.4
0,15,25:18.4
1,15,25:18.4
2,15,25:18.12
5,15,25:18.12
8,15,25:18.12
-10,16,25:18.12
-4,16,25:18.12
-2,16,25:18.4
-1,16,25:18.4
0,16,25:18.4
1,16,25:18.4
2,16,25:18.4
3,16,25:18.4
8,16,25:18.4
9,16,25:18.4
10,16,25:18.4
-2,17,25:18.4
-1,17,25:18.4
0,17,25:18.4
2,17,25:18.4
3,17,25:18.4
7,17,25:18.4
8,17,25:18.4
9,17,25:18.4
10,17,25:18.4
11,17,25:18.4
-2,18,25:18.4
-1,18,25:18.4
3,18,25:18.4
4,18,25:18.4
7,18,25:18.4
8,18,25:18.4
10,18,25:18.4
11,18,25:18.4
12,18,25:18.4
6,19,25:18.4
7,19,25:18.4
8,19,25:18.4
7,20,25:18.4
8,20,25:18.4
7,21,25:18.4
11,-27,26:18.12
10,-26,26:18.12
11,-26,26:18.12
10,-25,26:18.12
9,-24,26:18.12
3,-23,26:18.12
4,-23,26:18.12
5,-23,26:18.12
6,-23,26:18.12
7,-23,26:18.12
8,-23,26:18.12
9,-23,26:18.12
-3,-22,26:18.4
3,-22,26:18.12
4,-22,26:18.12
5,-22,26:18.12
9,-22,26:18.12
-5,-21,26:18.12
-4,-21,26:18.12
-3,-21,26:18.12
9,-21,26:18.12
-5,-20,26:18.12
-4,-20,26:18.12
-3,-20,26:18.12
-2,-20,26:18.12
9,-20,26:18.12
10,-20,26:18.12
-4,-19,26:18.12
-3,-19,26:18.12
10,-19,26:18.12
-14,-18,26:18.4
-4,-18,26:18.12
-3,-18,26:18.12
3,-18,26:18.12
4,-18,26:18.12
7,-18,26:18.12
10,-18,26:18.12
11,-18,26:18.12
-14,-17,26:18.4
-5,-17,26:18.12
-4,-17,26:18.12
-3,-17,26:18.12
-2,-17,26:18.12
2,-17,26:18.12
3,-17,26:18.12
6,-17,26:18.12
7,-17,26:18.12
11,-17,26:18.12
-14,-16,26:18.4
-13,-16,26:18.4
-5,-16,26:18.12
-4,-16,26:18.12
-2,-16,26:18.12
1,-16,26:18.12
6,-16,26:18.12
-17,-15,26:18.12
-13,-15,26:18.12
-12,-15,26:18.12
-11,-15,26:18.12
-10,-15,26:18.4
-9,-15,26:18.12
-8,-15,26:18.12
-7,-15,26:18.12
-6,-15,26:18.12
-5,-15,26:18.12
-4,-15,26:18.12
-3,-15,26:17.12
-2,-15,26:18.12
0,-15,26:18.12
5,-15,26:18.12
6,-15,26:18.12
14,-15,26:18.12
15,-15,26:18.12
17,-15,26:18.12
18,-15,26:18.12
-19,-14,26:18.12
-17,-14,26:18.12
-12,-14,26:18.12
-10,-14,26:18.4
-9,-14,26:18.12
-8,-14,26:18.12
-7,-14,26:18.12
-6,-14,26:18.12
-5,-14,26:18.12
-4,-14,26:18.12
-3,-14,26:17.12
-2,-14,26:18.12
-1,-14,26:18.12
0,-14,26:18.12
3,-14,26:18.12
4,-14,26:18.12
5,-14,26:18.12
13,-14,26:18.12
14,-14,26:18.12
15,-14,26:18.12
16,-14,26:18.12
17,-14,26:18.12
18,-14,26:18.12
-19,-13,26:18.12
-18,-13,26:18.12
-17,-13,26:18.12
-16,-13,26:18.12
-15,-13,26:18.12
-12,-13,26:18.12
-11,-13,26:18.12
-10,-13,26:18.12
-5,-13,26:18.12
-4,-13,26:18.12
-3,-13,26:18.12
-2,-13,26:18.12
-1,-13,26:18.12
0,-13,26:18.12
1,-13,26:18.12
2,-13,26:18.12
3,-13,26:18.12
5,-13,26:18.12
6,-13,26:18.12
12,-13,26:18.12
13,-13,26:18.12
14,-13,26:18.12
15,-13,26:18.12
16,-13,26:18.12
17,-13,26:18.12
-17,-12,26:18.12
-16,-12,26:18.12
-15,-12,26:18.12
-14,-12,26:18.12
-13,-12,26:18.12
-12,-12,26:18.12
-11,-12,26:18.12
-6,-12,26:18.12
-4,-12,26:18.12
-2,-12,26:18.12
6,-12,26:18.12
11,-12,26:18.12
12,-12,26:18.12
13,-12,26:18.12
14,-12,26:18.12
15,-12,26:18.12
16,-12,26:18.12
17,-12,26:18.12
-17,-11,26:18.12
-16,-11,26:18.12
-15,-11,26:18.12
-14,-11,26:18.12
-7,-11,26:18.12
7,-11,26:18.12
11,-11,26:18.12
12,-11,26:18.12
14,-11,26:18.12
15,-11,26:18.12
16,-11,26:18.12
-18,-10,26:18.12
-17,-10,26:18.12
-15,-10,26:18.12
-7,-10,26:18.12
-6,-10,26:18.12
-5,-10,26:18.12
-4,-10,26:18.12
7,-10,26:18.12
11,-10,26:18.12
12,-10,26:18.12
13,-10,26:17.12
14,-10,26:17.12
15,-10,26:18.12
16,-10,26:18.12
17,-10,26:18.12
-15,-9,26:18.12
-11,-9,26:17.12
-10,-9,26:17.12
-9,-9,26:18.12
-6,-9,26:18.12
-5,-9,26:18.12
-4,-9,26:18.12
8,-9,26:18.12
11,-9,26:18.12
12,-9,26:18.12
13,-9,26:18.12
14,-9,26:17.12
15,-9,26:18.12
16,-9,26:18.12
17,-9,26:18.12
18,-9,26:18.12
19,-9,26:18.12
20,-9,26:18.12
-15,-8,26:18.12
-10,-8,26:17.12
-9,-8,26:18.12
-8,-8,26:18.12
-7,-8,26:18.12
-6,-8,26:18.12
-4,-8,26:18.12
-3,-8,26:18.12
-2,-8,26:18.12
-1,-8,26:18.12
8,-8,26:18.12
9,-8,26:18.12
10,-8,26:18.12
11,-8,26:18.12
12,-8,26:18.12
17,-8,26:18.12
18,-8,26:18.12
19,-8,26:18.12
20,-8,26:18.12
21,-8,26:18.4
-15,-7,26:18.12
-14,-7,26:18.12
-13,-7,26:18.12
-10,-7,26:18.12
-9,-7,26:18.12
-8,-7,26:18.12
-7,-7,26:18.12
-6,-7,26:18.12
8,-7,26:18.12
9,-7,26:18.12
10,-7,26:18.12
20,-7,26:18.12
-16,-6,26:18.4
-15,-6,26:18.12
-11,-6,26:18.12
-10,-6,26:18.12
-9,-6,26:18.12
-8,-6,26:18.12
-7,-6,26:18.12
-6,-6,26:18.12
-5,-6,26:18.12
8,-6,26:18.12
9,-6,26:18.12
10,-6,26:18.12
-15,-5,26:18.12
-13,-5,26:18.12
-12,-5,26:18.12
-11,-5,26:18.12
-10,-5,26:18.12
-8,-5,26:18.12
-7,-5,26:18.12
-6,-5,26:18.12
1,-5,26:17.12
8,-5,26:18.12
9,-5,26:18.12
-15,-4,26:18.4
-14,-4,26:18.12
-13,-4,26:18.12
-12,-4,26:18.12
-11,-4,26:18.12
-7,-4,26:18.12
-6,-4,26:18.12
0,-4,26:17.12
1,-4,26:17.12
2,-4,26:17.12
8,-4,26:18.12
9,-4,26:18.12
20,-4,26:18.4
21,-4,26:18.4
-16,-3,26:18.4
-15,-3,26:18.12
-14,-3,26:18.12
-13,-3,26:18.12
-5,-3,26:18.12
-4,-3,26:18.12
-2,-3,26:18.12
0,-3,26:17.12
1,-3,26:17.12
2,-3,26:17.12
3,-3,26:17.12
5,-3,26:18.12
6,-3,26:18.12
7,-3,26:18.12
8,-3,26:18.12
9,-3,26:18.12
20,-3,26:18.4
21,-3,26:18.4
-16,-2,26:18.12
-15,-2,26:18.12
-14,-2,26:18.12
-9,-2,26:18.12
-8,-2,26:18.12
-5,-2,26:18.12
3,-2,26:18.12
4,-2,26:18.12
5,-2,26:18.12
6,-2,26:18.12
7,-2,26:18.12
19,-2,26:18.4
20,-2,26:18.4
21,-2,26:18.4
-15,-1,26:18.12
-14,-1,26:18.12
-9,-1,26:18.12
-8,-1,26:18.12
-6,-1,26:18.12
-5,-1,26:18.12
4,-1,26:18.12
5,-1,26:18.12
6,-1,26:18.12
7,-1,26:18.12
17,-1,26:18.12
18,-1,26:18.12
21,-1,26:18.4
22,-1,26:18.4
-14,0,26:18.12
-13,0,26:18.12
-9,0,26:18.12
-8,0,26:18.12
-6,0,26:18.12
-5,0,26:18.12
4,0,26:18.12
15,0,26:18.12
16,0,26:18.12
17,0,26:18.12
-14,1,26:18.12
-13,1,26:18.12
-12,1,26:18.12
-9,1,26:18.12
-8,1,26:18.12
-6,1,26:18.12
-3,1,26:18.12
-2,1,26:18.12
-1,1,26:18.12
3,1,26:18.12
14,1,26:18.12
15,1,26:18.12
-17,2,26:18.12
-13,2,26:18.12
-12,2,26:18.12
-11,2,26:18.12
-10,2,26:18.12
-9,2,26:18.12
-8,2,26:18.12
-7,2,26:18.12
-6,2,26:18.12
-3,2,26:18.12
-2,2,26:18.12
-1,2,26:18.12
0,2,26:18.12
1,2,26:18.12
2,2,26:18.12
3,2,26:18.12
-18,3,26:18.12
-17,3,26:18.12
-12,3,26:18.12
-11,3,26:18.12
-7,3,26:18.12
-6,3,26:18.12
-5,3,26:18.12
1,3,26:18.4
2,3,26:18.12
3,3,26:18.12
16,3,26:18.12
-18,4,26:18.12
-13,4,26:18.12
-12,4,26:18.12
3,4,26:18.12
16,4,26:18.12
17,4,26:18.12
18,4,26:18.12
-18,5,26:18.12
-14,5,26:18.12
-9,5,26:18.12
4,5,26:18.12
15,5,26:18.12
-18,6,26:18.12
-9,6,26:18.12
-8,6,26:18.12
4,6,26:18.12
15,6,26:18.12
16,6,26:18.12
21,6,26:17.12
22,6,26:17.12
-18,7,26:18.12
-8,7,26:18.4
4,7,26:18.12
5,7,26:18.12
16,7,26:18.12
-15,8,26:18.4
-14,8,26:18.4
-13,8,26:18.4
-12,8,26:18.12
-11,8,26:18.12
-10,8,26:18.12
-9,8,26:18.12
-8,8,26:18.12
-7,8,26:18.12
-6,8,26:18.12
-5,8,26:18.12
-4,8,26:18.12
-3,8,26:18.12
-2,8,26:18.4
5,8,26:18.12
6,8,26:18.12
7,8,26:18.12
9,8,26:18.12
16,8,26:18.12
17,8,26:18.12
-17,9,26:18.4
-16,9,26:18.4
-15,9,26:18.4
-14,9,26:18.4
-13,9,26:18.4
-12,9,26:18.12
-11,9,26:18.12
-10,9,26:18.12
-7,9,26:18.12
-6,9,26:18.12
0,9,26:18.4
1,9,26:18.12
5,9,26:18.12
6,9,26:18.12
9,9,26:18.12
10,9,26:18.12
11,9,26:18.4
17,9,26:18.12
1,10,26:18.12
2,10,26:18.12
3,10,26:18.12
4,10,26:18.12
5,10,26:18.12
11,10,26:18.4
12,10,26:18.4
-9,11,26:18.12
-8,11,26:18.12
1,11,26:18.12
4,11,26:18.12
13,11,26:18.4
14,11,26:18.4
-9,12,26:18.12
1,12,26:18.12
4,12,26:18.12
7,12,26:18.12
-14,13,26:18.4
-13,13,26:18.12
-9,13,26:18.12
-8,13,26:18.12
1,13,26:18.12
4,13,26:18.12
5,13,26:18.12
7,13,26:18.12
-14,14,26:18.4
-13,14,26:18.12
-12,14,26:18.12
-11,14,26:18.12
-10,14,26:18.12
1,14,26:18.12
4,14,26:18.12
5,14,26:18.12
8,14,26:18.12
-11,15,26:18.12
1,15,26:18.4
8,15,26:18.12
-11,16,26:18.12
1,16,26:18.4
8,16,26:18.4
9,16,26:18.4
-11,17,26:18.12
0,17,26:18.4
1,17,26:18.4
9,17,26:18.4
-1,18,26:18.4
0,18,26:18.4
1,18,26:18.4
2,18,26:18.4
9,18,26:18.4
10,18,26:18.4
0,19,26:18.4
2,19,26:18.4
8,19,26:18.4
9,19,26:18.4
10,19,26:18.4
11,19,26:18.4
8,20,26:18.4
9,20,26:18.4
11,20,26:18.4
9,21,26:18.4
4,-24,27:18.12
5,-24,27:18.12
6,-24,27:18.12
7,-24,27:18.12
8,-24,27:18.12
9,-24,27:18.12
4,-23,27:18.12
5,-23,27:18.12
6,-23,27:18.12
7,-23,27:18.12
8,-23,27:18.12
9,-23,27:18.12
-4,-22,27:18.4
-3,-22,27:18.4
9,-22,27:18.12
10,-22,27:18.12
-4,-21,27:18.12
10,-21,27:18.12
-5,-20,27:18.12
-4,-20,27:18.12
10,-20,27:18.12
-5,-19,27:18.12
-4,-19,27:18.12
-3,-19,27:18.12
4,-19,27:18.12
11,-19,27:18.12
-6,-18,27:18.12
-5,-18,27:18.12
-3,-18,27:18.12
2,-18,27:18.12
3,-18,27:18.12
7,-18,27:18.12
-14,-17,27:18.4
-12,-17,27:18.4
-11,-17,27:18.4
-10,-17,27:18.4
-7,-17,27:18.12
-6,-17,27:18.12
-5,-17,27:18.12
-2,-17,27:18.12
1,-17,27:18.12
2,-17,27:18.12
7,-17,27:18.12
-14,-16,27:18.4
-13,-16,27:18.4
-12,-16,27:18.4
-11,-16,27:18.4
-10,-16,27:18.4
-9,-16,27:18.12
-8,-16,27:18.12
-7,-16,27:18.12
-6,-16,27:18.12
-5,-16,27:18.12
-4,-16,27:18.12
-2,-16,27:18.12
0,-16,27:18.12
1,-16,27:18.12
6,-16,27:18.12
-13,-15,27:18.12
-8,-15,27:18.12
-7,-15,27:18.12
-6,-15,27:18.12
-5,-15,27:18.12
-4,-15,27:18.12
-3,-15,27:18.12
-2,-15,27:18.12
-1,-15,27:18.12
0,-15,27:18.12
6,-15,27:18.12
13,-15,27:18.12
14,-15,27:18.12
19,-15,27:18.12
20,-15,27:18.12
-20,-14,27:18.12
-19,-14,27:18.12
-17,-14,27:18.12
-12,-14,27:18.12
-11,-14,27:18.4
-6,-14,27:18.12
-5,-14,27:18.12
-4,-14,27:17.12
-3,-14,27:17.12
-2,-14,27:18.12
-1,-14,27:18.12
3,-14,27:18.12
4,-14,27:18.12
5,-14,27:18.12
12,-14,27:18.12
13,-14,27:18.12
18,-14,27:18.12
19,-14,27:18.12
20,-14,27:18.12
-19,-13,27:18.12
-18,-13,27:18.12
-17,-13,27:18.12
-16,-13,27:18.12
-15,-13,27:18.12
-14,-13,27:18.12
-13,-13,27:18.12
-12,-13,27:18.12
-11,-13,27:18.12
-7,-13,27:18.12
-6,-13,27:18.12
-5,-13,27:18.12
-4,-13,27:18.12
-1,-13,27:18.12
0,-13,27:18.12
1,-13,27:18.12
2,-13,27:18.12
3,-13,27:18.12
5,-13,27:18.12
6,-13,27:18.12
12,-13,27:18.12
13,-13,27:18.12
17,-13,27:18.12
18,-13,27:18.12
19,-13,27:18.12
-18,-12,27:18.12
-17,-12,27:18.12
-16,-12,27:18.12
-15,-12,27:18.12
-14,-12,27:18.12
-13,-12,27:18.12
-8,-12,27:18.12
-7,-12,27:18.12
-6,-12,27:18.12
-4,-12,27:18.12
-1,-12,27:18.12
6,-12,27:18.12
13,-12,27:18.12
17,-12,27:18.12
18,-12,27:18.12
19,-12,27:18.12
-18,-11,27:18.12
-16,-11,27:18.12
-15,-11,27:18.12
-8,-11,27:18.12
-7,-11,27:18.12
-4,-11,27:18.12
7,-11,27:18.12
12,-11,27:18.12
16,-11,27:18.12
17,-11,27:18.12
18,-11,27:18.12
-18,-10,27:18.12
-16,-10,27:18.12
-12,-10,27:18.12
-11,-10,27:18.12
-5,-10,27:18.12
-4,-10,27:18.12
7,-10,27:18.12
8,-10,27:18.12
14,-10,27:17.12
15,-10,27:17.12
16,-10,27:18.12
17,-10,27:18.12
18,-10,27:18.12
19,-10,27:18.12
20,-10,27:18.12
21,-10,27:18.4
-16,-9,27:18.12
-11,-9,27:17.12
-10,-9,27:18.12
-9,-9,27:18.12
-7,-9,27:18.12
-6,-9,27:18.12
-5,-9,27:18.12
-4,-9,27:18.12
-3,-9,27:18.12
-2,-9,27:18.12
9,-9,27:18.12
12,-9,27:18.12
13,-9,27:18.12
19,-9,27:18.12
20,-9,27:18.12
21,-9,27:18.4
22,-9,27:18.4
-16,-8,27:18.12
-9,-8,27:18.12
-8,-8,27:18.12
-7,-8,27:18.12
-2,-8,27:18.12
10,-8,27:18.12
12,-8,27:18.12
13,-8,27:18.12
14,-8,27:18.12
15,-8,27:18.12
16,-8,27:18.12
-16,-7,27:18.12
-12,-7,27:18.12
-11,-7,27:18.12
-10,-7,27:18.12
-7,-7,27:18.12
-6,-7,27:18.12
-1,-7,27:18.12
9,-7,27:18.12
10,-7,27:18.12
11,-7,27:18.12
-16,-6,27:18.4
-14,-6,27:18.12
-13,-6,27:18.12
-12,-6,27:18.12
-11,-6,27:18.12
-10,-6,27:18.12
-9,-6,27:18.12
-7,-6,27:18.12
-5,-6,27:18.12
-4,-6,27:18.12
-1,-6,27:18.12
9,-6,27:18.12
10,-6,27:18.12
-16,-5,27:18.4
-15,-5,27:18.12
-14,-5,27:18.12
-13,-5,27:18.12
-10,-5,27:18.12
-9,-5,27:18.12
-8,-5,27:18.12
-7,-5,27:18.12
1,-5,27:17.12
9,-5,27:18.12
10,-5,27:18.12
-17,-4,27:18.4
-16,-4,27:18.4
-15,-4,27:18.4
-14,-4,27:18.12
-8,-4,27:18.12
-7,-4,27:18.12
0,-4,27:17.12
1,-4,27:17.12
2,-4,27:17.12
9,-4,27:18.12
10,-4,27:18.12
-17,-3,27:18.4
-16,-3,27:18.4
-9,-3,27:18.12
-7,-3,27:18.12
-6,-3,27:18.12
-5,-3,27:18.12
-4,-3,27:18.12
-2,-3,27:18.12
0,-3,27:17.12
1,-3,27:17.12
2,-3,27:17.12
3,-3,27:17.12
4,-3,27:17.12
6,-3,27:18.12
9,-3,27:18.12
20,-3,27:18.4
21,-3,27:18.4
-17,-2,27:18.12
-16,-2,27:18.12
-9,-2,27:18.12
-7,-2,27:18.12
-6,-2,27:18.12
-5,-2,27:18.12
0,-2,27:18.12
1,-2,27:18.12
2,-2,27:17.12
3,-2,27:17.12
4,-2,27:17.12
5,-2,27:17.12
6,-2,27:18.12
7,-2,27:18.12
8,-2,27:18.12
18,-2,27:18.4
19,-2,27:18.4
-17,-1,27:18.12
-16,-1,27:18.12
-15,-1,27:18.12
-9,-1,27:18.12
-7,-1,27:18.12
-6,-1,27:18.12
0,-1,27:18.12
5,-1,27:18.12
6,-1,27:18.12
7,-1,27:18.12
17,-1,27:18.12
18,-1,27:18.12
-16,0,27:18.12
-15,0,27:18.12
-9,0,27:18.12
-7,0,27:18.12
-6,0,27:18.12
0,0,27:18.12
5,0,27:18.12
8,0,27:18.12
15,0,27:18.12
16,0,27:18.12
-15,1,27:18.12
-14,1,27:18.12
-9,1,27:18.12
-8,1,27:18.12
-7,1,27:18.12
0,1,27:18.12
5,1,27:18.12
15,1,27:18.12
17,1,27:18.12
-15,2,27:18.12
-14,2,27:18.12
-13,2,27:17.12
-12,2,27:17.12
-10,2,27:18.12
-9,2,27:18.12
-8,2,27:18.12
-7,2,27:18.12
-4,2,27:18.12
-3,2,27:18.12
-2,2,27:18.12
0,2,27:18.12
1,2,27:18.12
4,2,27:18.12
17,2,27:18.12
-14,3,27:17.12
-13,3,27:18.12
-12,3,27:18.12
-11,3,27:18.12
-8,3,27:18.12
-7,3,27:18.12
-6,3,27:18.12
-3,3,27:18.12
-2,3,27:18.12
-1,3,27:18.4
0,3,27:18.4
1,3,27:18.4
2,3,27:18.12
3,3,27:18.12
4,3,27:18.12
17,3,27:18.12
-13,4,27:18.12
-12,4,27:18.12
-9,4,27:18.12
-8,4,27:18.12
-6,4,27:18.12
-5,4,27:18.12
0,4,27:18.4
1,4,27:18.4
2,4,27:18.4
3,4,27:18.4
4,4,27:18.12
16,4,27:18.12
17,4,27:18.12
18,4,27:18.12
19,4,27:18.12
-14,5,27:18.12
-13,5,27:18.12
0,5,27:18.4
3,5,27:18.12
4,5,27:18.12
15,5,27:18.12
16,5,27:18.12
19,5,27:18.12
20,5,27:18.12
-9,6,27:18.12
0,6,27:18.4
1,6,27:18.12
4,6,27:18.12
-9,7,27:18.4
-8,7,27:18.4
0,7,27:18.4
4,7,27:18.12
23,7,27:17.12
24,7,27:17.12
-8,8,27:18.4
-3,8,27:18.4
5,8,27:18.12
6,8,27:18.12
-8,9,27:18.12
-7,9,27:18.12
-6,9,27:18.12
-5,9,27:18.12
-4,9,27:18.12
-3,9,27:18.4
5,9,27:18.12
6,9,27:18.12
10,9,27:18.12
11,9,27:18.4
-14,10,27:18.4
-13,10,27:18.12
-12,10,27:18.12
0,10,27:18.4
1,10,27:18.12
2,10,27:18.12
4,10,27:18.12
5,10,27:18.12
11,10,27:18.4
12,10,27:18.4
1,11,27:18.12
2,11,27:18.12
3,11,27:18.12
4,11,27:18.12
13,11,27:18.4
14,11,27:18.4
1,12,27:18.12
4,12,27:18.12
7,12,27:18.12
-9,13,27:18.12
-8,13,27:18.12
1,13,27:18.12
4,13,27:18.12
7,13,27:18.12
8,13,27:18.12
-13,14,27:18.12
-12,14,27:18.12
-10,14,27:18.12
-9,14,27:18.12
1,14,27:18.12
4,14,27:18.12
8,14,27:18.12
-13,15,27:18.12
-12,15,27:18.12
-11,15,27:18.12
1,15,27:18.4
8,15,27:18.12
-11,16,27:18.12
1,16,27:18.4
8,16,27:18.4
9,16,27:18.4
9,17,27:18.4
9,18,27:18.4
4,-24,28:18.12
5,-24,28:18.12
6,-24,28:18.12
7,-24,28:18.12
8,-24,28:18.12
9,-24,28:18.12
-5,-23,28:18.4
9,-23,28:18.12
10,-23,28:18.12
-6,-22,28:18.4
-5,-22,28:18.4
10,-22,28:18.12
-6,-21,28:18.12
-5,-21,28:18.12
10,-21,28:18.12
-7,-20,28:18.12
-6,-20,28:18.12
-5,-20,28:18.12
-3,-20,28:18.12
4,-20,28:18.12
11,-20,28:18.12
-7,-19,28:18.12
-6,-19,28:18.12
-3,-19,28:18.12
3,-19,28:18.12
4,-19,28:18.12
-12,-18,28:18.4
-11,-18,28:18.4
-10,-18,28:18.4
-9,-18,28:18.12
-8,-18,28:18.12
-7,-18,28:18.12
-6,-18,28:18.12
-5,-18,28:18.12
-2,-18,28:18.12
2,-18,28:18.12
3,-18,28:18.12
7,-18,28:18.12
-12,-17,28:18.4
-11,-17,28:18.4
-10,-17,28:18.4
-9,-17,28:18.12
-8,-17,28:18.12
-7,-17,28:18.12
-6,-17,28:18.12
-5,-17,28:18.12
-4,-17,28:18.12
-3,-17,28:18.12
-2,-17,28:18.12
0,-17,28:18.12
1,-17,28:18.12
7,-17,28:18.12
-14,-16,28:18.4
-8,-16,28:18.12
-7,-16,28:18.12
-6,-16,28:18.12
-4,-16,28:18.12
-3,-16,28:18.12
-2,-16,28:18.12
-1,-16,28:18.12
0,-16,28:18.12
6,-16,28:18.12
7,-16,28:18.12
-13,-15,28:18.12
-8,-15,28:18.12
-7,-15,28:18.12
