[META]
version=2.0
spawnOnBlockType=2
spawnSunlight=True
spawnDarkness=True
spawnWater=False
spawnLava=False
underFill=False
randomRotation=True
dig=True
tree=False
branch=False
needsFoundation=True
rarity=100
collisionPercentage=20
spawnElevationMin=0
spawnElevationMax=200
spawnInBiome=Custom
[DATA]
-5,1,-8:17.12
-4,2,-8:17.12
-3,1,-7:17.12
-5,2,-7:17.12
-3,2,-7:17.12
-3,3,-7:17.12
-4,4,-7:17.12
-5,0,-6:17.12
-7,1,-6:17.12
-6,1,-6:17.12
-5,1,-6:17.12
-4,1,-6:17.12
-3,1,-6:17.12
-7,2,-6:17.12
-6,2,-6:17.12
-5,2,-6:17.12
-4,2,-6:17.12
-3,2,-6:17.12
-6,3,-6:17.12
-5,3,-6:17.12
-3,3,-6:17.12
-6,4,-6:17.12
-5,4,-6:17.12
-4,4,-6:17.12
-3,4,-6:17.12
-5,0,-5:17.12
-4,0,-5:17.12
-3,0,-5:17.12
-7,1,-5:17.12
-6,1,-5:17.12
-5,1,-5:17.12
-4,1,-5:17.12
-3,1,-5:17.12
-2,1,-5:17.12
-7,2,-5:17.12
-5,2,-5:17.12
-3,2,-5:17.12
-5,3,-5:17.12
-4,3,-5:17.12
-6,4,-5:17.12
-5,4,-5:17.12
-5,6,-5:17.12
-4,6,-5:17.12
-6,0,-4:17.12
-2,0,-4:17.12
-7,1,-4:17.12
-6,1,-4:17.12
-4,1,-4:17.12
-3,1,-4:17.12
-2,1,-4:17.12
-5,2,-4:17.12
-4,2,-4:17.12
-3,2,-4:17.12
-1,2,-4:17.12
-7,3,-4:17.12
-6,3,-4:17.12
-5,3,-4:17.12
-4,3,-4:17.12
-3,3,-4:17.12
-2,3,-4:17.12
-6,4,-4:17.12
-5,4,-4:17.12
-4,4,-4:17.12
-3,4,-4:17.12
-2,4,-4:17.12
-6,5,-4:17.12
-3,5,-4:17.12
-2,5,-4:17.12
-6,6,-4:17.12
-3,0,-3:17.12
-7,1,-3:17.12
-5,1,-3:17.12
-4,1,-3:17.12
-3,1,-3:17.12
-1,1,-3:17.12
-7,2,-3:17.12
-5,2,-3:17.12
-3,2,-3:17.12
-2,2,-3:17.12
-6,3,-3:17.12
-5,3,-3:17.12
-3,3,-3:17.12
-6,4,-3:17.12
-4,4,-3:17.12
-3,4,-3:17.12
-4,5,-3:17.12
-6,6,-3:17.12
-5,0,-2:17.12
-4,0,-2:17.12
-3,0,-2:17.12
-7,1,-2:17.12
-6,1,-2:17.12
-5,1,-2:17.12
-4,1,-2:17.12
-7,2,-2:17.12
-5,2,-2:17.12
-4,2,-2:17.12
-3,2,-2:17.12
-2,2,-2:17.12
-7,3,-2:17.12
-6,3,-2:17.12
-5,3,-2:17.12
-4,3,-2:17.12
-2,3,-2:17.12
-6,4,-2:17.12
-5,4,-2:17.12
-4,4,-2:17.12
-2,4,-2:17.12
-6,5,-2:17.12
-5,5,-2:17.12
-3,5,-2:17.12
-6,6,-2:17.12
-5,6,-2:17.12
-4,6,-2:17.12
-6,-2,-1:18.15
-8,-1,-1:18.14
-7,-1,-1:18.14
-6,-1,-1:18.15
-5,-1,-1:18.14
-4,-1,-1:18.14
-6,0,-1:18.14
-5,0,-1:17.12
-4,0,-1:17.12
-3,0,-1:17.12
-7,1,-1:18.15
-6,1,-1:17.12
-5,1,-1:17.12
-3,1,-1:17.12
-7,2,-1:17.12
-3,2,-1:17.12
-2,2,-1:17.12
-7,3,-1:17.12
-6,3,-1:17.12
-2,3,-1:17.12
-6,4,-1:17.12
-2,4,-1:17.12
-6,5,-1:17.12
-4,5,-1:17.12
-3,5,-1:17.12
-6,6,-1:17.12
-5,6,-1:17.12
-4,6,-1:17.12
-7,-1,0:18.14
-6,-1,0:18.14
-5,-1,0:18.14
-7,0,0:18.14
-6,0,0:18.14
-4,0,0:17.12
-3,0,0:17.12
-6,1,0:17.12
-5,1,0:17.12
-3,1,0:17.12
-7,2,0:17.12
-6,2,0:17.12
-3,2,0:17.12
-2,2,0:17.12
-6,3,0:17.12
-2,3,0:17.12
-6,4,0:17.12
-3,4,0:17.12
-2,4,0:17.12
-6,5,0:17.12
-5,5,0:17.12
-4,5,0:17.12
-3,5,0:17.12
-4,0,1:17.12
-6,1,1:17.12
-5,1,1:17.12
-4,1,1:17.12
-3,1,1:17.12
-6,2,1:17.12
-3,2,1:17.12
-6,3,1:17.12
-3,3,1:17.12
-6,4,1:17.12
-4,4,1:17.12
-3,4,1:17.12
-6,5,1:17.12
-5,5,1:17.12
-4,5,1:17.12
-8,0,2:18.14
-7,1,2:18.14
-5,1,2:17.12
-4,1,2:17.12
-6,2,2:17.12
-4,2,2:17.12
-3,2,2:17.12
-6,3,2:17.12
-3,3,2:17.12
-6,4,2:17.12
-5,4,2:17.12
-4,4,2:17.12
-3,4,2:17.12
-5,5,2:17.12
-8,-1,3:18.14
-8,0,3:18.14
-7,1,3:18.14
-5,1,3:17.12
-4,1,3:17.12
-6,2,3:17.12
-5,2,3:17.12
-4,2,3:17.12
-6,3,3:17.12
-4,3,3:17.12
-6,4,3:17.12
-4,4,3:17.12
-3,4,3:18.14
-2,4,3:18.14
-6,5,3:17.12
-5,5,3:17.12
-2,-4,4:18.6
-8,-1,4:18.14
-8,0,4:18.14
-7,0,4:18.14
-7,1,4:18.14
-6,1,4:18.14
-5,1,4:17.12
-6,2,4:17.12
-5,2,4:17.12
-4,2,4:17.12
-6,3,4:17.12
-4,3,4:17.12
-6,4,4:17.12
-5,4,4:17.12
-4,4,4:17.12
-3,4,4:18.14
-2,4,4:18.14
-6,5,4:18.14
-2,-5,5:18.6
-2,-4,5:18.6
-2,-2,5:18.14
-8,-1,5:18.14
-2,-1,5:18.14
-7,0,5:18.14
1,0,5:18.14
2,0,5:18.14
-7,1,5:17.12
-6,1,5:17.12
-5,1,5:17.12
0,1,5:18.14
1,1,5:18.14
-7,2,5:17.12
-6,2,5:17.12
-5,2,5:17.12
-4,2,5:17.12
0,2,5:18.14
-6,3,5:17.12
-4,3,5:17.12
-1,3,5:17.12
-6,4,5:17.12
-5,4,5:17.12
-4,4,5:17.12
-3,4,5:17.12
-2,4,5:18.14
-6,5,5:18.14
-6,6,5:18.14
1,6,5:18.14
2,6,5:18.14
-4,7,5:18.14
-2,-5,6:18.6
-2,-4,6:18.6
-9,-2,6:17.12
-8,-2,6:17.12
-2,-2,6:18.14
-9,-1,6:17.12
-8,-1,6:17.12
-7,-1,6:17.12
-2,-1,6:18.14
1,-1,6:18.14
2,-1,6:18.14
-8,0,6:17.12
-7,0,6:17.12
-6,0,6:17.12
0,0,6:18.14
1,0,6:18.14
2,0,6:18.14
-8,1,6:17.12
-7,1,6:17.12
-6,1,6:17.12
-5,1,6:17.12
0,1,6:18.14
1,1,6:18.14
2,1,6:18.14
-7,2,6:17.12
-6,2,6:17.12
-4,2,6:17.12
-1,2,6:18.14
0,2,6:17.12
1,2,6:18.14
-6,3,6:17.12
-4,3,6:17.12
-2,3,6:17.12
-1,3,6:17.12
-6,4,6:17.12
-5,4,6:17.12
-4,4,6:17.12
-3,4,6:17.12
-2,4,6:17.12
1,4,6:18.14
2,4,6:18.14
-6,5,6:18.14
0,5,6:18.14
1,5,6:18.14
2,5,6:18.14
3,5,6:18.14
-6,6,6:18.14
-5,7,6:18.14
-4,7,6:18.14
0,8,6:18.6
1,-7,7:18.6
1,-6,7:18.6
-2,-5,7:18.6
-2,-4,7:18.6
-9,-2,7:17.12
-8,-2,7:17.12
-2,-2,7:18.14
-10,-1,7:17.12
-9,-1,7:17.12
-8,-1,7:17.12
-2,-1,7:18.14
0,-1,7:18.14
1,-1,7:18.14
2,-1,7:18.14
-10,0,7:17.12
-8,0,7:17.12
-7,0,7:17.12
0,0,7:18.14
1,0,7:18.14
2,0,7:18.14
-7,1,7:17.12
-6,1,7:17.12
-5,1,7:17.12
-4,1,7:17.12
-2,1,7:18.14
0,1,7:18.14
1,1,7:18.14
2,1,7:18.14
3,1,7:18.14
-6,2,7:17.12
-5,2,7:17.12
-4,2,7:17.12
-3,2,7:17.12
-1,2,7:18.14
-6,3,7:17.12
-5,3,7:17.12
-4,3,7:17.12
-6,4,7:17.12
-5,4,7:17.12
-2,4,7:17.12
-1,4,7:17.12
2,4,7:18.14
3,4,7:18.14
-6,5,7:17.12
-5,5,7:17.12
-1,5,7:17.12
0,5,7:18.14
1,5,7:18.14
2,5,7:18.14
3,5,7:18.14
-6,6,7:18.14
-5,6,7:18.14
-1,6,7:18.14
0,6,7:18.14
-5,7,7:18.14
-4,7,7:18.14
0,7,7:18.6
1,7,7:18.6
2,7,7:18.6
0,8,7:18.6
1,9,7:18.6
-5,-8,8:18.6
-4,-8,8:18.6
-3,-8,8:18.6
-1,-8,8:18.6
-1,-7,8:18.6
0,-7,8:18.6
1,-7,8:18.6
-7,-6,8:18.6
-2,-6,8:18.6
0,-6,8:18.6
-2,-5,8:18.6
0,-5,8:18.6
-2,-4,8:18.6
-8,-3,8:17.12
-2,-3,8:18.6
-8,-2,8:17.12
-2,-2,8:18.14
-2,-1,8:18.14
1,-1,8:18.14
-11,0,8:17.12
-10,0,8:17.12
-2,0,8:18.14
0,0,8:18.14
2,0,8:18.14
3,0,8:18.14
-12,1,8:18.6
-11,1,8:18.14
-5,1,8:17.12
-4,1,8:17.12
-3,1,8:17.12
-2,1,8:18.14
1,1,8:18.14
2,1,8:18.14
-13,2,8:18.6
-11,2,8:18.14
-5,2,8:17.12
-4,2,8:17.12
-3,2,8:17.12
-1,2,8:18.14
-6,3,8:17.12
-5,3,8:17.12
-4,3,8:17.12
2,3,8:18.14
3,3,8:18.14
4,3,8:18.14
-6,4,8:17.12
-5,4,8:17.12
1,4,8:18.14
2,4,8:18.14
3,4,8:18.14
-6,5,8:17.12
-5,5,8:17.12
0,5,8:17.12
1,5,8:18.14
2,5,8:18.14
3,5,8:18.14
4,5,8:18.14
-6,6,8:17.12
-5,6,8:17.12
0,6,8:18.14
2,6,8:18.14
3,6,8:18.14
-5,7,8:17.12
-4,7,8:17.12
0,7,8:18.6
1,7,8:18.6
-3,8,8:18.14
1,8,8:18.6
2,8,8:18.6
-4,9,8:18.14
1,9,8:18.6
-4,11,8:18.14
-6,-10,9:18.6
-9,-9,9:18.6
-6,-9,9:18.6
-5,-9,9:18.6
0,-9,9:18.6
-6,-8,9:18.6
-5,-8,9:18.6
-4,-8,9:18.6
-3,-8,9:18.6
0,-8,9:18.6
-6,-7,9:18.6
-5,-7,9:18.6
-4,-7,9:18.6
-3,-7,9:18.6
-1,-7,9:18.6
0,-7,9:18.6
-14,-6,9:18.6
-13,-6,9:18.6
-12,-6,9:18.6
-7,-6,9:18.6
-4,-6,9:18.6
-3,-6,9:18.6
-2,-6,9:18.6
-1,-6,9:18.6
0,-6,9:18.6
-13,-5,9:18.6
-12,-5,9:18.6
-9,-5,9:18.14
-8,-5,9:18.14
-7,-5,9:18.14
-3,-5,9:18.14
-2,-5,9:18.6
-1,-5,9:18.6
0,-5,9:18.6
-8,-4,9:18.14
-1,-4,9:18.6
0,-4,9:18.6
-9,-3,9:17.12
-8,-3,9:17.12
-2,-3,9:18.6
-8,-2,9:17.12
-2,-2,9:18.14
-2,-1,9:18.14
2,-1,9:18.14
3,-1,9:18.14
-11,0,9:17.12
-4,0,9:17.12
-3,0,9:17.12
-2,0,9:17.12
3,0,9:18.14
4,0,9:18.14
-14,1,9:18.6
-12,1,9:18.6
-11,1,9:18.14
-4,1,9:17.12
-3,1,9:17.12
-2,1,9:18.14
3,1,9:18.14
-13,2,9:18.6
-12,2,9:18.6
-4,2,9:17.12
-3,2,9:17.12
-1,2,9:18.14
3,2,9:18.14
3,3,9:18.14
4,3,9:18.14
5,3,9:18.6
1,4,9:18.14
2,4,9:18.14
3,4,9:18.14
1,5,9:18.14
2,5,9:18.14
3,5,9:18.14
4,5,9:18.14
-7,6,9:17.12
-6,6,9:17.12
0,6,9:18.14
2,6,9:18.14
3,6,9:18.14
-6,7,9:17.12
-4,7,9:17.12
0,7,9:18.6
1,7,9:18.6
-3,8,9:18.14
-2,8,9:18.6
-1,8,9:18.6
1,8,9:18.6
-11,9,9:18.14
-3,9,9:18.14
-2,9,9:18.6
2,9,9:18.6
-13,10,9:18.6
-12,10,9:18.6
-3,10,9:18.14
-2,10,9:18.6
-3,11,9:18.14
-3,12,9:18.14
-9,-10,10:18.6
-10,-9,10:18.6
-9,-9,10:18.6
-6,-9,10:18.6
-5,-9,10:18.6
-10,-8,10:18.6
-9,-8,10:18.6
-6,-8,10:18.6
-5,-8,10:18.6
-4,-8,10:18.6
0,-8,10:18.6
-9,-7,10:18.6
-6,-7,10:18.6
-5,-7,10:18.6
-4,-7,10:18.6
-3,-7,10:18.6
0,-7,10:18.6
-15,-6,10:18.6
-14,-6,10:18.6
-13,-6,10:18.6
-12,-6,10:18.6
-9,-6,10:18.6
-8,-6,10:18.6
-6,-6,10:18.6
-5,-6,10:18.6
-4,-6,10:18.6
-3,-6,10:18.6
-1,-6,10:18.6
0,-6,10:18.6
-14,-5,10:18.6
-13,-5,10:18.6
-12,-5,10:18.6
-11,-5,10:18.14
-9,-5,10:18.14
-8,-5,10:18.14
-5,-5,10:18.14
-3,-5,10:18.14
-2,-5,10:18.6
-1,-5,10:18.6
4,-5,10:18.6
-15,-4,10:18.6
-14,-4,10:18.6
-13,-4,10:18.6
-12,-4,10:18.6
-11,-4,10:17.12
-10,-4,10:17.12
-9,-4,10:17.12
-8,-4,10:18.14
-2,-4,10:18.6
-1,-4,10:18.6
0,-4,10:18.6
-9,-3,10:17.12
-8,-3,10:18.14
-2,-3,10:17.12
-1,-3,10:17.12
-2,-2,10:17.12
-1,-2,10:17.12
3,-2,10:18.14
4,-2,10:18.14
-3,-1,10:17.12
-2,-1,10:17.12
-1,-1,10:18.14
1,-1,10:18.14
2,-1,10:18.14
-14,0,10:18.6
-13,0,10:18.6
-12,0,10:18.6
-11,0,10:17.12
-3,0,10:17.12
-2,0,10:18.14
-1,0,10:18.14
0,0,10:18.14
-14,1,10:18.6
-13,1,10:18.6
-12,1,10:18.6
-11,1,10:18.14
-3,1,10:17.12
-2,1,10:17.12
-1,1,10:17.12
1,1,10:18.14
2,1,10:18.14
3,1,10:18.14
4,1,10:18.14
5,1,10:18.6
-15,2,10:18.6
-14,2,10:18.6
-13,2,10:18.6
-12,2,10:18.6
-1,2,10:17.12
0,2,10:18.14
1,2,10:18.14
2,2,10:18.14
3,2,10:18.14
4,2,10:18.14
5,2,10:18.6
6,2,10:18.6
-14,3,10:18.6
-13,3,10:18.6
3,4,10:18.14
4,4,10:18.14
1,5,10:18.14
2,5,10:18.14
3,5,10:18.14
4,5,10:18.14
-7,6,10:17.12
-6,6,10:17.12
3,6,10:18.14
4,6,10:18.14
-7,7,10:17.12
-3,8,10:18.14
-2,8,10:18.6
-3,9,10:18.14
-2,9,10:18.6
-1,9,10:18.6
0,9,10:18.6
-12,10,10:18.6
-11,10,10:18.14
-3,10,10:18.14
-2,10,10:18.6
-1,10,10:18.6
-14,11,10:18.6
-13,11,10:18.6
-3,11,10:18.14
-15,12,10:18.6
-14,12,10:18.6
-13,12,10:18.6
-12,12,10:18.6
-11,12,10:18.14
-3,12,10:18.14
-12,13,10:18.6
-10,-11,11:18.6
-10,-10,11:18.6
-9,-10,11:18.6
-10,-9,11:18.6
-9,-9,11:18.6
-10,-8,11:18.6
-9,-8,11:18.6
-5,-8,11:18.6
0,-8,11:18.6
-9,-7,11:18.6
-8,-7,11:18.6
-7,-7,11:18.6
-6,-7,11:18.6
-5,-7,11:18.6
-4,-7,11:18.6
0,-7,11:18.6
3,-7,11:18.6
4,-7,11:18.6
-15,-6,11:18.6
-9,-6,11:18.6
-8,-6,11:18.6
-6,-6,11:18.6
-5,-6,11:18.6
-4,-6,11:18.6
-3,-6,11:18.6
-2,-6,11:18.6
-1,-6,11:18.6
2,-6,11:18.6
3,-6,11:18.6
4,-6,11:18.6
5,-6,11:18.6
-15,-5,11:18.6
-14,-5,11:18.6
-13,-5,11:18.6
-12,-5,11:18.6
-9,-5,11:17.12
-8,-5,11:18.6
-2,-5,11:17.12
-1,-5,11:18.6
0,-5,11:17.12
1,-5,11:17.12
2,-5,11:18.6
3,-5,11:18.6
4,-5,11:18.6
-13,-4,11:18.6
-8,-4,11:18.14
-5,-4,11:18.14
-2,-4,11:17.12
-1,-4,11:17.12
0,-4,11:17.12
1,-4,11:18.6
-1,-3,11:17.12
0,-3,11:18.6
1,-3,11:18.6
-2,-2,11:17.12
-1,-2,11:18.14
0,-2,11:18.14
2,-2,11:18.14
3,-2,11:18.14
4,-2,11:18.14
-1,-1,11:18.14
0,-1,11:18.14
1,-1,11:18.14
2,-1,11:18.14
4,-1,11:18.14
-14,0,11:18.6
-13,0,11:18.6
-12,0,11:18.6
-4,0,11:17.12
-3,0,11:17.12
-2,0,11:18.14
-1,0,11:18.14
2,0,11:18.14
3,0,11:18.14
-14,1,11:18.6
-13,1,11:18.6
-12,1,11:18.6
-2,1,11:17.12
0,1,11:17.12
1,1,11:17.12
2,1,11:18.14
3,1,11:18.14
4,1,11:18.14
5,1,11:18.6
-15,2,11:18.6
-14,2,11:18.6
-1,2,11:17.12
0,2,11:17.12
1,2,11:18.14
2,2,11:18.14
3,2,11:18.14
4,2,11:18.14
5,2,11:18.6
6,2,11:18.6
7,2,11:18.6
-15,3,11:18.6
-14,3,11:18.6
-12,4,11:18.6
4,4,11:18.14
5,4,11:18.6
3,5,11:18.14
-12,6,11:18.6
-11,6,11:18.14
-8,6,11:17.12
-7,6,11:17.12
-8,7,11:17.12
-7,7,11:17.12
-2,8,11:18.6
-3,9,11:18.14
-2,9,11:18.6
-1,9,11:18.6
-12,10,11:18.6
-11,10,11:18.14
-3,10,11:18.14
-2,10,11:18.6
-1,10,11:18.6
-13,11,11:18.6
-12,11,11:18.6
-11,11,11:18.14
-3,11,11:18.14
-15,12,11:18.6
-14,12,11:18.6
-13,12,11:18.6
-12,12,11:18.6
-11,12,11:18.14
-3,12,11:18.14
-2,12,11:18.6
-8,13,11:18.14
-5,13,11:18.14
-2,13,11:18.6
-5,14,11:18.6
-2,14,11:18.6
-10,-10,12:18.6
-10,-9,12:18.6
-9,-9,12:18.6
-10,-8,12:18.6
-9,-8,12:18.6
-2,-8,12:18.6
-11,-7,12:18.6
-10,-7,12:18.6
-9,-7,12:18.6
-8,-7,12:18.6
-6,-7,12:18.6
-2,-7,12:18.6
4,-7,12:18.6
5,-7,12:18.6
-16,-6,12:18.6
-15,-6,12:18.6
-9,-6,12:18.6
-8,-6,12:18.6
-6,-6,12:18.6
-5,-6,12:18.6
-4,-6,12:18.6
-2,-6,12:18.6
2,-6,12:18.6
3,-6,12:18.6
4,-6,12:18.6
5,-6,12:18.6
6,-6,12:18.6
-14,-5,12:18.6
-13,-5,12:18.6
-8,-5,12:18.6
-6,-5,12:18.6
-5,-5,12:18.6
-4,-5,12:18.6
-3,-5,12:18.6
-2,-5,12:18.6
1,-5,12:17.12
2,-5,12:18.6
-7,-4,12:18.6
-6,-4,12:18.6
-5,-4,12:18.6
-3,-4,12:18.6
1,-4,12:18.6
2,-4,12:18.6
-5,-3,12:18.6
-3,-3,12:18.6
1,-3,12:18.6
3,-3,12:18.6
4,-3,12:18.6
-5,-2,12:18.14
-4,-2,12:18.14
-3,-2,12:18.14
0,-2,12:18.14
1,-2,12:18.14
2,-2,12:18.14
3,-2,12:18.14
-6,-1,12:18.14
-5,-1,12:18.14
-4,-1,12:18.14
-1,-1,12:18.14
0,-1,12:18.14
1,-1,12:18.14
3,-1,12:18.14
4,-1,12:18.14
-14,0,12:18.6
-13,0,12:18.6
-4,0,12:17.12
-2,0,12:18.14
-1,0,12:18.14
2,0,12:18.14
3,0,12:18.14
4,0,12:18.14
-14,1,12:18.6
-13,1,12:18.6
1,1,12:18.14
2,1,12:18.14
3,1,12:18.14
4,1,12:18.14
5,1,12:18.6
-15,2,12:18.6
-14,2,12:18.6
2,2,12:18.14
3,2,12:18.14
4,2,12:18.14
5,2,12:18.6
-16,3,12:18.6
-13,3,12:18.6
-14,4,12:18.6
-13,4,12:18.6
-12,4,12:18.6
-14,5,12:18.6
-13,5,12:18.6
-12,5,12:18.6
-11,6,12:18.14
-9,6,12:17.12
-8,6,12:17.12
-7,6,12:17.12
-13,7,12:18.6
-12,7,12:18.6
-11,7,12:18.14
-8,7,12:17.12
-7,7,12:17.12
-12,8,12:18.6
-11,8,12:18.14
-7,8,12:17.12
-6,8,12:17.12
-7,9,12:18.14
-6,9,12:18.14
-2,9,12:18.6
-1,9,12:18.6
-11,10,12:18.14
-10,10,12:18.14
-9,10,12:18.14
-7,10,12:18.14
-6,10,12:18.14
-5,10,12:18.14
-2,10,12:18.6
-1,10,12:18.6
0,10,12:18.6
-13,11,12:18.6
-12,11,12:18.6
-11,11,12:18.14
-10,11,12:18.14
-7,11,12:18.14
-5,11,12:18.14
-4,11,12:18.14
-1,11,12:18.6
0,11,12:18.6
-15,12,12:18.6
-14,12,12:18.6
-12,12,12:18.6
-11,12,12:18.14
-7,12,12:18.14
-5,12,12:18.14
-4,12,12:18.14
-3,12,12:18.14
-12,13,12:18.6
-7,13,12:18.14
-5,13,12:18.14
-4,13,12:18.14
-3,13,12:18.14
-2,13,12:18.6
-13,14,12:18.6
-10,14,12:18.6
-7,14,12:18.6
-4,14,12:18.6
-1,14,12:18.6
-11,15,12:18.6
-7,15,12:18.6
-11,-8,13:18.6
-10,-8,13:18.6
-5,-8,13:18.6
-2,-8,13:18.6
-11,-7,13:18.6
-10,-7,13:18.6
-8,-7,13:18.6
-5,-7,13:18.6
-3,-7,13:18.6
-2,-7,13:18.6
4,-7,13:18.6
6,-7,13:18.6
-9,-6,13:18.6
-8,-6,13:18.6
-7,-6,13:18.6
-5,-6,13:18.6
-3,-6,13:18.6
2,-6,13:18.6
3,-6,13:18.6
4,-6,13:18.6
5,-6,13:18.6
6,-6,13:18.6
-7,-5,13:18.6
-6,-5,13:18.6
-5,-5,13:18.6
-3,-5,13:18.6
1,-5,13:17.12
2,-5,13:18.6
3,-5,13:18.6
-8,-4,13:18.6
-6,-4,13:18.6
-5,-4,13:18.6
-4,-4,13:18.6
-3,-4,13:18.6
2,-4,13:18.6
3,-4,13:18.6
-8,-3,13:18.6
-7,-3,13:18.6
-6,-3,13:18.6
-5,-3,13:18.6
-4,-3,13:18.6
2,-3,13:18.6
3,-3,13:18.6
4,-3,13:18.6
-7,-2,13:18.14
-6,-2,13:18.14
-5,-2,13:18.14
-4,-2,13:18.14
1,-2,13:18.14
2,-2,13:18.14
-5,-1,13:18.14
-4,-1,13:17.12
-1,-1,13:18.14
0,-1,13:18.14
4,-1,13:18.14
-4,0,13:17.12
-1,0,13:18.14
3,0,13:18.14
4,0,13:18.14
5,0,13:18.6
2,1,13:18.14
3,1,13:18.14
4,1,13:18.14
5,1,13:18.6
3,2,13:18.14
-15,3,13:18.6
-14,4,13:18.6
-13,4,13:18.6
-13,5,13:18.6
-12,5,13:18.6
-11,5,13:18.14
-12,6,13:18.6
-11,6,13:18.14
-10,6,13:18.14
-9,6,13:17.12
-13,7,13:18.6
-12,7,13:18.6
-11,7,13:18.14
-10,7,13:18.14
-9,7,13:17.12
-7,8,13:17.12
-6,8,13:17.12
-9,9,13:18.14
-8,9,13:17.12
-7,9,13:17.12
-6,9,13:17.12
-11,10,13:18.14
-10,10,13:18.14
-9,10,13:18.14
-7,10,13:18.14
-6,10,13:18.14
-5,10,13:17.12
-4,10,13:18.14
-13,11,13:18.6
-12,11,13:18.6
-10,11,13:18.14
-9,11,13:18.14
-7,11,13:18.14
-5,11,13:18.14
-4,11,13:18.14
-3,11,13:18.14
-1,11,13:18.6
-14,12,13:18.6
-11,12,13:18.14
-10,12,13:18.14
-9,12,13:18.14
-7,12,13:18.14
-5,12,13:18.14
-4,12,13:18.14
-3,12,13:18.14
-2,12,13:18.6
-1,12,13:18.6
0,12,13:18.6
-12,13,13:18.6
-11,13,13:18.14
-10,13,13:18.14
-7,13,13:18.14
-5,13,13:18.14
-4,13,13:18.14
-2,13,13:18.6
-1,13,13:18.6
1,13,13:18.6
-13,14,13:18.6
-11,14,13:18.6
-10,14,13:18.6
-7,14,13:18.6
-4,14,13:18.6
-3,14,13:18.6
-1,14,13:18.6
0,14,13:18.6
-13,15,13:18.6
-12,15,13:18.6
-11,15,13:18.6
-3,15,13:18.6
-11,-9,14:18.6
-11,-8,14:18.6
-10,-8,14:18.6
-5,-8,14:18.6
-3,-8,14:18.6
2,-8,14:18.6
3,-8,14:18.6
5,-8,14:18.6
-10,-7,14:18.6
-6,-7,14:18.6
-5,-7,14:18.6
-4,-7,14:18.6
-3,-7,14:18.6
2,-7,14:18.6
3,-7,14:18.6
4,-7,14:18.6
5,-7,14:18.6
-7,-6,14:18.6
-6,-6,14:18.6
-5,-6,14:18.6
-4,-6,14:18.6
-3,-6,14:18.6
2,-6,14:18.6
3,-6,14:18.6
4,-6,14:18.6
5,-6,14:18.6
6,-6,14:18.6
-7,-5,14:18.6
-6,-5,14:18.6
-5,-5,14:18.6
-4,-5,14:18.6
-3,-5,14:18.6
2,-5,14:18.6
3,-5,14:18.6
-8,-4,14:18.6
-7,-4,14:18.6
-6,-4,14:18.6
-5,-4,14:18.6
-4,-4,14:18.6
3,-4,14:18.6
4,-4,14:18.6
-6,-3,14:18.6
-5,-3,14:18.6
-4,-3,14:18.6
2,-3,14:18.6
3,-3,14:18.6
-6,-2,14:18.6
-5,-2,14:18.14
-4,-2,14:18.14
1,-2,14:18.14
2,-2,14:18.14
-5,-1,14:18.14
-1,-1,14:18.14
0,-1,14:18.14
5,0,14:18.6
6,0,14:18.6
3,1,14:18.14
4,1,14:18.14
5,1,14:18.6
-14,4,14:18.6
-13,4,14:18.6
-13,5,14:18.6
-12,5,14:18.6
-11,5,14:18.14
-12,6,14:18.6
-11,6,14:18.14
-10,6,14:18.14
-9,6,14:18.14
-9,9,14:17.12
-7,9,14:18.14
-9,10,14:17.12
-6,10,14:18.14
-10,11,14:18.14
-3,11,14:18.14
-11,12,14:18.14
-10,12,14:18.14
-6,12,14:18.14
-5,12,14:18.14
-4,12,14:18.14
-3,12,14:18.14
-2,12,14:18.6
-1,12,14:18.6
-11,13,14:18.14
-6,13,14:18.14
-5,13,14:18.14
-4,13,14:18.14
-1,13,14:18.6
0,13,14:18.6
-7,14,14:18.6
-6,14,14:18.6
-5,14,14:18.6
-4,14,14:18.6
0,14,14:18.6
1,14,14:18.6
-13,15,14:18.6
-12,15,14:18.6
-3,15,14:18.6
1,15,14:18.6
-13,16,14:18.6
-4,-9,15:18.6
-3,-9,15:18.6
3,-9,15:18.6
-4,-8,15:18.6
-3,-8,15:18.6
3,-8,15:18.6
4,-8,15:18.6
-4,-7,15:18.6
-3,-7,15:18.6
3,-7,15:18.6
4,-7,15:18.6
5,-7,15:18.6
6,-7,15:18.6
-8,-6,15:18.6
-6,-6,15:18.6
-4,-6,15:18.6
2,-6,15:18.6
3,-6,15:18.6
4,-6,15:18.6
5,-6,15:18.6
-8,-5,15:18.6
-7,-5,15:18.6
-6,-5,15:18.6
-4,-5,15:18.6
2,-5,15:18.6
3,-5,15:18.6
-7,-4,15:18.6
-5,-4,15:18.6
-4,-4,15:18.6
4,-4,15:18.6
-6,-3,15:18.6
-4,-3,15:18.6
3,-3,15:18.6
-6,-2,15:18.6
-4,-2,15:18.14
0,-2,15:18.14
1,-2,15:18.14
-11,5,15:18.14
-12,6,15:18.6
-11,6,15:18.14
-10,6,15:18.14
-6,9,15:18.14
-11,10,15:18.14
-10,10,15:18.14
-9,10,15:17.12
-6,10,15:18.14
-13,11,15:18.6
-12,11,15:18.6
-11,11,15:18.14
-10,11,15:18.14
-3,11,15:18.14
-11,12,15:18.14
-10,12,15:18.14
-6,12,15:18.14
-2,12,15:18.6
-12,13,15:18.6
-11,13,15:18.14
-6,13,15:18.14
-1,13,15:18.6
0,13,15:18.6
-6,14,15:18.6
-5,14,15:18.6
0,14,15:18.6
1,14,15:18.6
-13,15,15:18.6
-6,15,15:18.6
2,15,15:18.6
-13,16,15:18.6
-3,-10,16:18.6
-4,-9,16:18.6
-3,-9,16:18.6
-3,-8,16:18.6
4,-8,16:18.6
-4,-7,16:18.6
3,-7,16:18.6
6,-7,16:18.6
-4,-6,16:18.6
2,-6,16:18.6
4,-6,16:18.6
5,-6,16:18.6
-4,-5,16:18.6
-7,-4,16:18.6
-4,-4,16:18.6
-6,-3,16:18.6
-4,-3,16:18.6
-12,5,16:18.6
-11,5,16:18.14
-6,10,16:18.14
-13,11,16:18.6
-12,11,16:18.6
-11,11,16:18.14
-10,11,16:18.14
-12,12,16:18.6
-11,12,16:18.14
-6,12,16:18.14
-12,13,16:18.6
-11,13,16:18.14
-6,13,16:18.14
-1,13,16:18.6
0,13,16:18.6
-6,14,16:18.6
-6,15,16:18.6
-5,15,16:18.6
-3,-9,17:18.6
-4,-7,17:18.6
-4,-6,17:18.6
-4,-5,17:18.6
-4,-4,17:18.6
-12,11,17:18.6
-11,11,17:18.14
-10,11,17:18.14
-13,12,17:18.6
-12,12,17:18.6
-6,12,17:18.14
-6,13,17:18.14
-6,14,17:18.6
-6,15,17:18.6
-11,11,18:18.6
-13,12,18:18.6
-12,12,18:18.6
