[META]
version=2.0
spawnOnBlockType=2
spawnSunlight=True
spawnDarkness=True
spawnWater=False
spawnLava=False
underFill=False
randomRotation=True
dig=True
tree=False
branch=False
needsFoundation=True
rarity=100
collisionPercentage=20
spawnElevationMin=0
spawnElevationMax=200
spawnInBiome=Custom
[DATA]
1,3,-8:17.12
2,3,-8:17.12
2,2,-7:17.12
4,2,-7:17.12
0,3,-7:17.12
1,3,-7:17.12
2,4,-7:17.12
3,4,-7:17.12
4,4,-7:17.12
2,5,-7:17.12
2,1,-6:17.12
0,2,-6:17.12
2,2,-6:17.12
3,2,-6:17.12
4,2,-6:17.12
0,3,-6:17.12
1,3,-6:17.12
2,3,-6:17.12
3,3,-6:17.12
4,3,-6:17.12
1,4,-6:17.12
2,4,-6:17.12
3,4,-6:17.12
4,4,-6:17.12
2,5,-6:17.12
1,0,-5:17.12
2,0,-5:17.12
1,1,-5:17.12
2,1,-5:17.12
0,2,-5:17.12
1,2,-5:17.12
2,2,-5:17.12
4,2,-5:17.12
0,3,-5:17.12
1,3,-5:17.12
2,3,-5:17.12
3,3,-5:17.12
4,3,-5:17.12
0,4,-5:17.12
2,4,-5:17.12
3,4,-5:17.12
2,5,-5:17.12
1,0,-4:17.12
2,0,-4:17.12
-1,1,-4:17.12
3,1,-4:17.12
0,2,-4:17.12
1,2,-4:17.12
2,2,-4:17.12
3,2,-4:17.12
0,3,-4:17.12
1,3,-4:17.12
2,3,-4:17.12
3,3,-4:17.12
1,4,-4:17.12
3,4,-4:17.12
2,5,-4:17.12
1,0,-3:17.12
-1,1,-3:17.12
1,1,-3:17.12
2,1,-3:17.12
3,1,-3:17.12
0,2,-3:17.12
1,2,-3:17.12
2,2,-3:17.12
3,2,-3:17.12
0,3,-3:17.12
1,3,-3:17.12
2,3,-3:17.12
1,4,-3:17.12
2,4,-3:17.12
4,4,-3:17.12
1,1,-2:17.12
2,1,-2:17.12
0,2,-2:17.12
1,2,-2:17.12
2,2,-2:17.12
3,2,-2:17.12
0,3,-2:17.12
1,3,-2:17.12
2,3,-2:17.12
3,3,-2:17.12
1,4,-2:17.12
1,1,-1:17.12
2,1,-1:17.12
0,2,-1:17.12
1,2,-1:17.12
2,2,-1:17.12
3,2,-1:17.12
0,3,-1:17.12
3,3,-1:17.12
0,4,-1:17.12
1,4,-1:17.12
2,4,-1:17.12
3,4,-1:17.12
1,5,-1:17.12
1,1,0:17.12
2,1,0:17.12
1,2,0:17.12
2,2,0:17.12
3,2,0:17.12
0,3,0:17.12
2,3,0:17.12
3,3,0:17.12
0,4,0:17.12
1,4,0:17.12
2,4,0:17.12
1,-1,1:18.14
1,0,1:18.14
1,1,1:18.14
0,2,1:17.12
1,2,1:17.12
2,2,1:17.12
0,3,1:17.12
1,3,1:17.12
2,3,1:17.12
2,4,1:18.14
1,-1,2:18.14
6,-1,2:18.14
1,0,2:18.14
1,1,2:17.12
2,1,2:17.12
0,2,2:17.12
2,2,2:17.12
0,3,2:18.14
1,3,2:17.12
2,3,2:17.12
5,3,2:18.14
2,4,2:18.14
5,4,2:18.14
0,-2,3:17.12
1,-2,3:17.12
2,-2,3:17.12
1,-1,3:17.12
6,-1,3:18.14
1,0,3:17.12
5,0,3:18.14
1,1,3:17.12
2,1,3:17.12
4,1,3:18.14
5,1,3:18.14
0,2,3:17.12
2,2,3:17.12
0,3,3:18.14
1,3,3:17.12
2,3,3:17.12
4,3,3:18.14
5,3,3:18.14
6,3,3:18.14
2,4,3:18.14
4,4,3:17.12
0,-7,4:18.14
0,-6,4:18.14
1,-6,4:18.14
4,-6,4:18.14
1,-5,4:18.14
5,-5,4:18.14
6,-5,4:18.14
3,-4,4:18.14
4,-4,4:18.14
5,-4,4:18.14
6,-4,4:18.14
2,-3,4:18.14
3,-3,4:18.14
5,-3,4:18.14
6,-3,4:18.14
9,-3,4:18.14
-2,-2,4:18.14
-1,-2,4:17.12
0,-2,4:17.12
1,-2,4:17.12
2,-2,4:17.12
6,-2,4:18.14
7,-2,4:18.14
8,-2,4:18.14
6,-1,4:18.14
7,-1,4:18.14
8,-1,4:18.14
5,0,4:18.14
1,1,4:17.12
2,1,4:17.12
3,1,4:17.12
4,1,4:18.14
0,2,4:17.12
1,2,4:17.12
2,2,4:17.12
3,2,4:17.12
5,2,4:18.14
6,2,4:18.14
0,3,4:17.12
1,3,4:17.12
2,3,4:17.12
3,3,4:17.12
4,3,4:18.14
5,3,4:18.14
6,3,4:18.14
0,4,4:18.14
2,4,4:17.12
3,4,4:17.12
6,4,4:18.14
0,5,4:18.14
3,5,4:18.14
4,5,4:18.14
2,6,4:18.14
4,6,4:18.14
5,6,4:18.14
4,-8,5:18.14
-1,-7,5:18.14
3,-7,5:18.14
4,-7,5:18.14
-1,-6,5:18.14
0,-6,5:18.14
1,-6,5:18.14
3,-6,5:18.14
4,-6,5:18.14
0,-5,5:18.14
1,-5,5:18.14
3,-5,5:18.14
5,-5,5:18.14
1,-4,5:17.12
2,-4,5:17.12
3,-4,5:18.14
4,-4,5:18.14
5,-4,5:18.14
6,-4,5:18.14
-4,-3,5:18.14
-3,-3,5:18.14
-2,-3,5:18.14
1,-3,5:17.12
2,-3,5:18.14
4,-3,5:18.14
5,-3,5:18.14
6,-3,5:18.14
-3,-2,5:18.14
-2,-2,5:18.14
-1,-2,5:18.14
5,-2,5:18.14
6,-2,5:18.14
7,-2,5:18.14
8,-2,5:18.14
-2,-1,5:18.14
6,-1,5:18.14
7,-1,5:18.14
4,0,5:17.12
5,0,5:18.14
2,1,5:17.12
3,1,5:17.12
4,1,5:17.12
0,2,5:17.12
1,2,5:17.12
2,2,5:17.12
3,2,5:17.12
4,2,5:18.14
-1,3,5:17.12
0,3,5:17.12
4,3,5:18.14
5,3,5:18.14
6,3,5:18.14
7,3,5:18.14
0,4,5:17.12
0,5,5:18.14
3,5,5:18.14
4,5,5:18.14
5,5,5:18.14
6,5,5:18.14
2,6,5:18.14
3,6,5:18.14
4,6,5:18.14
5,6,5:18.14
2,7,5:18.14
3,7,5:18.14
-1,-7,6:18.14
2,-7,6:18.14
3,-7,6:18.14
4,-7,6:18.14
0,-6,6:18.14
2,-6,6:18.14
3,-6,6:18.14
2,-5,6:18.14
3,-5,6:18.14
4,-5,6:18.14
3,-4,6:18.14
4,-4,6:18.14
5,-4,6:18.14
6,-4,6:18.14
-4,-3,6:18.14
-3,-3,6:18.14
-2,-3,6:18.14
2,-3,6:18.14
4,-3,6:18.14
5,-3,6:18.14
6,-3,6:18.14
-4,-2,6:18.14
-3,-2,6:18.14
-2,-2,6:18.14
4,-2,6:18.14
6,-2,6:18.14
7,-2,6:18.14
6,-1,6:17.12
7,-1,6:17.12
8,-1,6:18.14
9,-1,6:18.14
4,0,6:17.12
5,0,6:17.12
7,0,6:18.14
8,0,6:18.14
9,0,6:18.14
10,0,6:18.14
3,1,6:17.12
4,1,6:18.14
5,1,6:18.14
9,1,6:18.14
10,1,6:18.14
-1,2,6:17.12
3,2,6:17.12
4,2,6:17.12
5,2,6:18.14
6,2,6:18.14
7,2,6:18.14
8,2,6:18.14
-8,3,6:18.6
-7,3,6:18.14
-6,3,6:18.14
-5,3,6:18.14
-1,3,6:17.12
4,3,6:18.14
5,3,6:18.14
6,3,6:18.14
7,3,6:18.14
-6,4,6:18.14
5,4,6:18.14
6,4,6:18.14
7,4,6:18.14
0,5,6:18.14
1,5,6:18.14
4,5,6:18.14
5,5,6:18.14
6,5,6:18.14
7,5,6:18.14
-1,6,6:18.14
0,6,6:18.14
1,6,6:18.14
3,6,6:18.14
4,6,6:18.14
5,6,6:18.14
6,6,6:18.14
-1,7,6:18.14
0,7,6:18.14
2,7,6:18.14
3,7,6:18.14
2,-7,7:18.14
3,-7,7:18.14
2,-6,7:18.14
3,-6,7:18.14
3,-5,7:18.14
3,-4,7:18.14
4,-4,7:18.14
5,-4,7:18.14
-4,-3,7:18.14
-3,-3,7:18.14
2,-3,7:18.14
3,-3,7:18.14
4,-3,7:18.14
5,-3,7:18.14
6,-3,7:18.14
7,-3,7:18.14
-4,-2,7:18.14
2,-2,7:18.14
3,-2,7:18.14
4,-2,7:18.14
5,-2,7:18.14
6,-2,7:18.14
-4,-1,7:18.14
-3,-1,7:18.14
3,-1,7:18.14
4,-1,7:18.14
8,-1,7:17.12
-5,0,7:18.14
-4,0,7:18.14
-3,0,7:18.14
3,0,7:17.12
7,0,7:18.14
8,0,7:18.14
9,0,7:18.14
10,0,7:18.14
11,0,7:18.14
-4,1,7:18.14
-3,1,7:18.14
4,1,7:18.14
5,1,7:18.14
6,1,7:18.14
7,1,7:18.14
10,1,7:18.14
-2,2,7:17.12
-1,2,7:17.12
6,2,7:18.14
7,2,7:18.14
8,2,7:18.14
-8,3,7:18.6
-7,3,7:18.14
-6,3,7:18.14
-5,3,7:18.14
-4,3,7:18.14
-2,3,7:17.12
-1,3,7:17.12
5,3,7:18.14
6,3,7:18.14
7,3,7:18.14
8,3,7:18.14
-7,4,7:18.14
-6,4,7:18.14
-5,4,7:18.14
-2,4,7:18.14
6,4,7:18.14
7,4,7:18.14
0,5,7:18.14
1,5,7:18.14
4,5,7:18.14
5,5,7:18.14
7,5,7:18.14
8,5,7:18.14
-4,6,7:18.14
0,6,7:18.14
1,6,7:18.14
5,6,7:18.14
6,6,7:18.14
-1,7,7:18.14
0,7,7:18.14
1,7,7:18.14
6,-5,8:18.14
7,-5,8:18.14
3,-4,8:18.14
4,-4,8:18.14
5,-4,8:18.14
6,-4,8:18.14
7,-4,8:18.14
3,-3,8:18.14
4,-3,8:18.14
5,-3,8:18.14
6,-3,8:18.14
-4,-2,8:18.14
3,-2,8:18.14
4,-2,8:18.14
5,-2,8:18.14
9,-2,8:18.14
10,-2,8:18.14
-4,-1,8:18.14
-3,-1,8:18.14
3,-1,8:18.14
4,-1,8:18.14
8,-1,8:18.14
9,-1,8:18.14
10,-1,8:18.14
-4,0,8:18.14
-3,0,8:18.14
8,0,8:18.14
9,0,8:18.14
10,0,8:18.14
-4,1,8:18.14
-3,1,8:18.14
-2,1,8:17.12
5,1,8:18.14
6,1,8:18.14
7,1,8:18.14
8,1,8:18.14
9,1,8:18.14
-2,2,8:17.12
-7,3,8:18.14
-6,3,8:18.14
-5,3,8:18.14
-4,3,8:18.14
-3,3,8:17.12
-2,3,8:17.12
-1,3,8:17.12
6,3,8:18.14
7,3,8:18.14
8,3,8:18.14
-7,4,8:18.14
-6,4,8:18.14
-5,4,8:18.14
-4,4,8:18.14
-2,4,8:18.14
-1,4,8:17.12
6,4,8:18.14
7,4,8:18.14
8,4,8:18.14
-6,5,8:18.14
-5,5,8:18.14
-3,5,8:18.14
-2,5,8:18.14
-1,5,8:17.12
-4,6,8:18.14
-2,6,8:18.14
-1,6,8:18.14
0,6,8:18.14
1,6,8:18.14
-3,7,8:18.14
-2,7,8:18.14
-1,7,8:18.14
0,7,8:18.14
1,7,8:18.14
-1,8,8:18.14
-1,9,8:18.14
7,-5,9:18.14
6,-4,9:18.14
3,-3,9:18.14
4,-3,9:18.14
5,-3,9:18.14
3,-2,9:18.14
4,-2,9:18.14
10,-2,9:18.14
9,-1,9:18.14
10,-1,9:18.14
-3,0,9:18.14
9,0,9:18.14
10,0,9:18.14
11,0,9:18.14
-3,1,9:18.14
-2,1,9:18.14
6,1,9:18.14
7,1,9:18.14
8,1,9:18.14
9,1,9:18.14
-5,3,9:18.14
-4,3,9:18.14
-3,3,9:17.12
7,3,9:18.14
-7,4,9:18.14
-6,4,9:18.14
-5,4,9:18.14
-4,4,9:18.14
-2,4,9:18.14
8,4,9:18.14
-8,5,9:18.6
-7,5,9:18.14
-6,5,9:18.14
-3,5,9:18.14
-2,5,9:18.14
-4,6,9:18.14
-3,6,9:18.14
-2,6,9:18.14
-1,6,9:18.14
-4,7,9:18.14
-2,7,9:18.14
-1,7,9:18.14
0,7,9:18.14
-2,8,9:18.14
-1,8,9:18.14
0,8,9:18.14
1,8,9:18.14
0,9,9:18.14
5,-3,10:18.14
-6,2,10:18.14
-6,3,10:18.14
-5,3,10:18.14
-4,3,10:18.14
-7,4,10:18.14
-6,4,10:18.14
-5,4,10:18.14
-2,4,10:18.14
-8,5,10:18.6
-3,5,10:18.14
-2,5,10:18.14
-3,6,10:18.14
-1,6,10:18.14
-4,7,10:18.14
-3,7,10:18.14
-2,7,10:18.14
-1,7,10:18.14
0,8,10:18.14
0,9,10:18.14
0,10,10:18.6
-6,2,11:18.14
-6,3,11:18.14
-5,3,11:18.14
-3,5,11:18.14
-3,6,11:18.14
-4,7,11:18.14
-3,7,11:18.14
0,8,11:18.14
