[META]
version=2.0
spawnOnBlockType=2
spawnSunlight=True
spawnDarkness=True
spawnWater=False
spawnLava=False
underFill=False
randomRotation=True
dig=True
tree=False
branch=False
needsFoundation=True
rarity=100
collisionPercentage=20
spawnElevationMin=0
spawnElevationMax=200
spawnInBiome=Custom
[DATA]
-3,2,-8:17.12
-1,2,-8:17.12
-3,3,-8:17.12
-2,3,-8:17.12
-1,3,-8:17.12
-4,3,-7:17.12
-2,4,-7:17.12
-1,4,-7:17.12
0,4,-7:17.12
-3,5,-7:17.12
-2,5,-7:17.12
-3,1,-6:17.12
-1,1,-6:17.12
-3,2,-6:17.12
-2,2,-6:17.12
-4,3,-6:17.12
-3,3,-6:17.12
-2,3,-6:17.12
-1,3,-6:17.12
0,3,-6:17.12
-3,4,-6:17.12
-1,4,-6:17.12
0,4,-6:17.12
-2,5,-6:17.12
-1,5,-6:17.12
-1,2,-5:17.12
-4,3,-5:17.12
-2,3,-5:17.12
-1,3,-5:17.12
0,3,-5:17.12
1,3,-5:17.12
-2,4,-5:17.12
-1,4,-5:17.12
0,4,-5:17.12
-1,5,-5:17.12
-1,1,-4:17.12
0,1,-4:17.12
-3,2,-4:17.12
-1,2,-4:17.12
-3,3,-4:17.12
-2,3,-4:17.12
-1,3,-4:17.12
0,3,-4:17.12
-2,4,-4:17.12
0,4,-4:17.12
-3,1,-3:17.12
-2,1,-3:17.12
1,1,-3:17.12
-2,2,-3:17.12
-1,2,-3:17.12
2,2,-3:17.12
-4,3,-3:17.12
-3,3,-3:17.12
-2,3,-3:17.12
-1,3,-3:17.12
0,3,-3:17.12
-3,4,-3:17.12
1,4,-3:17.12
-3,5,-3:17.12
-3,1,-2:17.12
-2,1,-2:17.12
-1,1,-2:17.12
1,1,-2:17.12
-4,2,-2:17.12
-3,2,-2:17.12
0,2,-2:17.12
-4,3,-2:17.12
-3,3,-2:17.12
-2,3,-2:17.12
-1,3,-2:17.12
-4,4,-2:17.12
-1,4,-2:17.12
0,4,-2:17.12
-4,5,-2:17.12
-3,5,-2:17.12
-2,5,-2:17.12
0,5,-2:17.12
1,5,-2:17.12
-2,6,-2:17.12
-1,6,-2:17.12
0,6,-2:17.12
-5,-1,-1:18.15
-4,-1,-1:18.15
-4,0,-1:18.15
1,0,-1:18.15
2,0,-1:18.14
-4,1,-1:17.12
-3,1,-1:17.12
-2,1,-1:17.12
-1,1,-1:17.12
0,1,-1:17.12
1,1,-1:18.15
2,1,-1:18.14
3,1,-1:18.14
-4,2,-1:17.12
-2,2,-1:17.12
-1,2,-1:17.12
0,2,-1:17.12
2,2,-1:18.14
3,2,-1:18.15
-4,3,-1:17.12
-2,3,-1:17.12
0,3,-1:17.12
1,3,-1:17.12
2,3,-1:18.14
3,3,-1:18.15
-4,4,-1:17.12
-2,4,-1:17.12
1,4,-1:17.12
-7,5,-1:18.15
-4,5,-1:17.12
-3,5,-1:17.12
-2,5,-1:17.12
-3,1,0:17.12
-2,1,0:17.12
-1,1,0:18.14
2,1,0:18.14
3,1,0:18.14
-4,2,0:17.12
-3,2,0:17.12
-2,2,0:17.12
-1,2,0:17.12
0,2,0:17.12
2,2,0:18.14
3,2,0:18.14
-7,3,0:18.14
-6,3,0:18.14
-4,3,0:17.12
0,3,0:17.12
2,3,0:18.14
-7,4,0:18.15
-6,4,0:18.15
0,4,0:17.12
-7,5,0:18.15
-6,5,0:18.15
-5,5,0:18.14
-1,5,0:17.12
0,5,0:17.12
-5,6,0:18.14
-4,6,0:18.14
-5,7,0:18.14
-4,7,0:18.14
-3,7,0:18.14
0,0,1:18.14
-1,1,1:18.14
-5,2,1:18.14
-3,2,1:17.12
-2,2,1:17.12
-1,2,1:17.12
0,2,1:17.12
-3,3,1:17.12
0,3,1:17.12
-6,4,1:18.15
0,4,1:17.12
-7,5,1:18.15
-6,5,1:18.15
-2,5,1:17.12
-1,5,1:17.12
0,5,1:17.12
0,0,2:18.14
0,1,2:18.14
-6,2,2:18.14
-5,2,2:18.14
-3,2,2:17.12
-2,2,2:17.12
-3,3,2:17.12
0,3,2:17.12
-3,4,2:17.12
0,4,2:17.12
-2,5,2:17.12
-1,5,2:17.12
0,5,2:17.12
0,-1,3:18.14
0,0,3:18.14
2,0,3:18.14
0,1,3:18.14
-6,2,3:18.14
-3,2,3:17.12
-2,2,3:17.12
-1,2,3:17.12
-6,3,3:18.14
-5,3,3:18.14
-4,3,3:17.12
-3,3,3:17.12
-4,4,3:17.12
-3,4,3:17.12
-1,5,3:18.14
0,5,3:18.14
0,6,3:18.14
0,-1,4:18.14
1,0,4:18.14
2,0,4:18.14
-3,1,4:17.12
0,1,4:18.14
-4,2,4:17.12
-3,2,4:17.12
-2,2,4:17.12
-1,2,4:17.12
-6,3,4:18.14
-5,3,4:18.14
-4,3,4:17.12
-1,3,4:17.12
-2,4,4:17.12
-1,4,4:17.12
-2,5,4:18.14
-1,5,4:18.14
0,5,4:18.14
0,6,4:18.14
0,7,4:18.14
2,-6,5:18.14
2,-5,5:18.14
-4,-1,5:18.14
0,-1,5:18.14
0,0,5:17.12
1,0,5:18.14
2,0,5:18.14
-1,1,5:17.12
0,1,5:17.12
1,1,5:17.12
-3,2,5:17.12
-2,2,5:17.12
-1,2,5:17.12
0,2,5:17.12
-6,3,5:18.14
-5,3,5:17.12
-1,3,5:17.12
-4,4,5:17.12
-3,4,5:17.12
-2,4,5:17.12
-1,4,5:17.12
-1,5,5:18.14
0,5,5:18.14
0,6,5:18.14
0,7,5:18.14
1,7,5:18.14
1,8,5:18.14
2,8,5:18.14
-5,10,5:18.14
-9,11,5:18.14
-9,12,5:18.14
-5,12,5:18.14
-9,13,5:18.6
-1,-8,6:18.6
-1,-7,6:18.14
0,-7,6:18.14
2,-7,6:18.14
-1,-6,6:18.14
0,-6,6:18.14
2,-6,6:18.14
-2,-5,6:18.14
1,-5,6:18.14
1,-4,6:18.14
-4,-2,6:18.14
0,-2,6:17.12
7,-2,6:18.14
8,-2,6:18.6
-4,-1,6:18.14
-3,-1,6:18.14
0,-1,6:17.12
1,-1,6:17.12
-3,0,6:18.14
1,0,6:17.12
2,0,6:18.14
-3,1,6:18.14
0,1,6:17.12
1,1,6:17.12
-6,2,6:17.12
-5,2,6:17.12
-3,2,6:17.12
-2,2,6:17.12
-1,2,6:17.12
-7,3,6:17.12
-6,3,6:17.12
-5,3,6:17.12
-1,3,6:17.12
6,3,6:18.14
-7,4,6:17.12
-6,4,6:17.12
-5,4,6:17.12
-4,4,6:17.12
-3,4,6:17.12
-2,4,6:17.12
-1,4,6:17.12
5,4,6:18.14
-2,5,6:17.12
-1,5,6:17.12
0,5,6:18.14
4,5,6:18.14
5,5,6:18.14
0,6,6:18.14
4,6,6:18.14
5,6,6:18.14
0,7,6:18.14
1,7,6:18.14
1,8,6:18.14
2,8,6:18.14
-8,9,6:18.14
2,9,6:18.14
3,9,6:18.14
-8,10,6:18.14
-6,10,6:18.14
-10,11,6:18.14
-9,11,6:18.14
-8,11,6:18.14
-6,11,6:18.14
-8,12,6:18.14
-6,12,6:18.14
-8,13,6:18.6
-6,13,6:18.6
-1,-9,7:18.6
-1,-8,7:18.6
1,-8,7:18.6
2,-8,7:18.6
-1,-7,7:18.14
0,-7,7:18.14
1,-7,7:18.14
2,-7,7:18.14
-4,-6,7:18.14
-3,-6,7:18.14
-1,-6,7:18.14
0,-6,7:18.14
1,-6,7:18.14
-4,-5,7:18.14
-3,-5,7:18.14
-2,-5,7:18.14
0,-5,7:18.14
1,-5,7:18.14
-3,-4,7:18.14
-2,-4,7:18.14
-1,-4,7:18.14
0,-4,7:18.14
1,-4,7:18.14
-2,-3,7:18.14
-1,-3,7:18.14
0,-3,7:18.14
8,-3,7:18.6
9,-3,7:18.6
-4,-2,7:18.14
0,-2,7:17.12
6,-2,7:18.14
7,-2,7:18.14
8,-2,7:18.6
-4,-1,7:18.14
-3,-1,7:18.14
5,-1,7:18.14
2,0,7:17.12
3,0,7:17.12
-4,1,7:18.14
-3,1,7:18.14
2,1,7:17.12
3,1,7:18.14
4,1,7:18.14
5,1,7:18.14
-3,2,7:17.12
-2,2,7:17.12
5,2,7:18.14
6,2,7:18.14
7,2,7:18.14
-8,3,7:17.12
-7,3,7:17.12
-6,3,7:17.12
-5,3,7:17.12
-4,3,7:17.12
-1,3,7:17.12
3,3,7:18.14
4,3,7:18.14
5,3,7:18.14
6,3,7:18.14
7,3,7:18.14
-8,4,7:17.12
-7,4,7:17.12
-6,4,7:17.12
-5,4,7:17.12
-3,4,7:17.12
-2,4,7:17.12
-1,4,7:17.12
0,4,7:17.12
3,4,7:18.14
4,4,7:18.14
5,4,7:18.14
-8,5,7:17.12
-7,5,7:17.12
-2,5,7:17.12
-1,5,7:17.12
0,5,7:17.12
1,5,7:17.12
2,5,7:17.12
3,5,7:18.14
4,5,7:18.14
-9,6,7:18.14
-8,6,7:18.14
-1,6,7:17.12
0,6,7:17.12
1,6,7:17.12
4,6,7:18.14
5,6,7:18.14
-9,7,7:18.14
-8,7,7:18.14
-7,7,7:18.14
1,7,7:18.14
7,7,7:18.14
8,7,7:18.14
9,7,7:18.14
-9,8,7:18.14
-8,8,7:18.14
-7,8,7:18.14
1,8,7:18.14
-10,9,7:18.14
-9,9,7:18.14
-8,9,7:18.14
-7,9,7:18.14
2,9,7:18.14
3,9,7:18.14
-10,10,7:18.14
-8,10,7:18.14
-7,10,7:18.14
-11,11,7:18.14
-10,11,7:18.14
-8,11,7:18.14
-7,11,7:18.14
-11,12,7:18.14
-7,12,7:18.14
7,12,7:18.14
9,12,7:18.14
-7,13,7:18.6
-7,14,7:18.6
-7,15,7:18.6
-2,-9,8:18.6
2,-9,8:18.6
-4,-8,8:18.6
-2,-8,8:18.6
1,-8,8:18.6
2,-8,8:18.6
-4,-7,8:18.14
-3,-7,8:18.14
-1,-7,8:18.14
1,-7,8:18.14
-4,-6,8:18.14
-3,-6,8:18.14
-2,-6,8:18.14
-1,-6,8:18.14
1,-6,8:18.14
-3,-5,8:18.14
-2,-5,8:18.14
-1,-5,8:18.14
1,-5,8:18.14
4,-5,8:18.14
7,-5,8:18.6
-2,-4,8:18.14
-1,-4,8:18.14
0,-4,8:18.14
6,-4,8:18.14
7,-4,8:18.14
-1,-3,8:18.14
0,-3,8:17.12
5,-3,8:18.14
6,-3,8:18.14
8,-3,8:18.6
9,-3,8:18.6
-4,-2,8:18.14
5,-2,8:18.14
6,-2,8:18.14
7,-2,8:18.14
-4,-1,8:18.14
-3,-1,8:18.14
4,-1,8:18.14
5,-1,8:18.14
3,0,8:17.12
4,0,8:18.14
-3,1,8:17.12
-2,1,8:17.12
3,1,8:18.14
4,1,8:18.14
5,1,8:18.14
7,1,8:18.14
-3,2,8:17.12
-2,2,8:17.12
3,2,8:18.14
4,2,8:18.14
6,2,8:18.14
7,2,8:18.14
-8,3,8:17.12
-7,3,8:17.12
-3,3,8:17.12
-2,3,8:17.12
3,3,8:18.14
4,3,8:18.14
5,3,8:18.14
6,3,8:18.14
-8,4,8:17.12
-7,4,8:17.12
-3,4,8:17.12
-2,4,8:17.12
-1,4,8:17.12
3,4,8:18.14
4,4,8:18.14
5,4,8:18.14
-8,5,8:17.12
-1,5,8:17.12
0,5,8:17.12
1,5,8:17.12
4,5,8:17.12
5,5,8:17.12
6,5,8:18.14
7,5,8:18.14
8,5,8:18.14
9,5,8:18.14
10,5,8:18.14
-8,6,8:17.12
0,6,8:17.12
1,6,8:17.12
4,6,8:18.14
5,6,8:18.14
6,6,8:18.14
7,6,8:18.14
8,6,8:18.14
9,6,8:18.14
10,6,8:18.14
-9,7,8:18.14
-8,7,8:17.12
0,7,8:17.12
1,7,8:17.12
6,7,8:18.14
7,7,8:18.14
8,7,8:18.14
9,7,8:18.14
10,7,8:18.14
-12,8,8:18.14
-11,8,8:18.14
-10,8,8:18.14
-9,8,8:18.14
-8,8,8:18.14
-6,8,8:18.14
-5,8,8:18.14
-4,8,8:18.14
1,8,8:18.14
8,8,8:18.14
9,8,8:18.14
-14,9,8:18.14
-13,9,8:18.14
-12,9,8:18.14
-11,9,8:18.14
-10,9,8:18.14
-7,9,8:18.14
1,9,8:18.14
2,9,8:18.14
3,9,8:18.14
-15,10,8:18.14
-14,10,8:18.14
-13,10,8:18.14
-11,10,8:18.14
-10,10,8:18.14
-7,10,8:18.14
-6,10,8:18.14
-11,11,8:18.14
-10,11,8:18.14
-7,11,8:18.14
7,11,8:18.14
8,11,8:18.14
9,11,8:18.14
-12,12,8:18.14
-10,12,8:18.14
-7,12,8:18.14
9,12,8:18.14
-7,13,8:18.6
-7,14,8:18.6
3,14,8:18.14
4,14,8:18.14
1,15,8:18.14
5,15,8:18.14
1,16,8:18.14
-2,-9,9:18.6
-4,-8,9:18.14
-3,-8,9:18.14
-2,-8,9:18.14
-3,-7,9:18.14
-2,-7,9:18.14
1,-7,9:18.14
-2,-6,9:18.14
-1,-6,9:18.14
1,-6,9:18.14
5,-6,9:18.6
-3,-5,9:18.14
-1,-5,9:18.14
1,-5,9:18.14
4,-5,9:18.14
5,-5,9:18.14
8,-5,9:18.6
-2,-4,9:18.14
-1,-4,9:18.14
3,-4,9:18.14
5,-4,9:18.14
7,-4,9:18.14
8,-4,9:18.6
9,-4,9:18.6
10,-4,9:18.6
3,-3,9:18.14
4,-3,9:18.14
7,-3,9:18.14
8,-3,9:18.6
9,-3,9:18.6
-4,-2,9:18.14
3,-2,9:18.14
4,-2,9:18.14
6,-2,9:18.14
7,-2,9:18.14
-4,-1,9:18.14
-3,-1,9:18.14
3,-1,9:18.14
4,-1,9:18.14
5,-1,9:18.14
6,-1,9:18.14
-3,1,9:17.12
-2,1,9:17.12
3,1,9:18.14
4,1,9:18.14
5,1,9:18.14
-3,2,9:17.12
-2,2,9:17.12
4,2,9:18.14
6,2,9:18.14
7,2,9:18.14
-9,3,9:17.12
-8,3,9:17.12
-3,3,9:17.12
-2,3,9:17.12
3,3,9:18.14
6,3,9:18.14
-9,4,9:17.12
-8,4,9:17.12
5,5,9:17.12
6,5,9:18.14
7,5,9:18.14
8,5,9:18.14
0,6,9:17.12
5,6,9:18.14
6,6,9:18.14
7,6,9:18.14
8,6,9:18.14
9,6,9:18.14
10,6,9:18.14
11,6,9:18.6
-9,7,9:18.14
-8,7,9:17.12
0,7,9:17.12
1,7,9:17.12
7,7,9:18.14
8,7,9:18.14
9,7,9:18.14
10,7,9:18.14
11,7,9:18.6
-13,8,9:18.14
-11,8,9:18.14
-10,8,9:18.14
-9,8,9:18.14
-8,8,9:17.12
-7,8,9:18.14
-4,8,9:18.14
-3,8,9:18.14
-2,8,9:18.14
-1,8,9:18.14
0,8,9:17.12
1,8,9:17.12
7,8,9:18.14
8,8,9:18.14
9,8,9:18.14
-13,9,9:18.14
-12,9,9:18.14
-11,9,9:18.14
-10,9,9:18.14
-8,9,9:18.14
-7,9,9:18.14
-5,9,9:18.14
-4,9,9:18.14
-3,9,9:18.14
-1,9,9:18.14
0,9,9:18.14
1,9,9:18.14
2,9,9:18.14
3,9,9:18.14
7,9,9:18.14
8,9,9:18.14
9,9,9:18.14
10,9,9:18.14
-14,10,9:18.14
-13,10,9:18.14
-12,10,9:18.14
-11,10,9:18.14
-9,10,9:18.14
-8,10,9:18.14
-7,10,9:18.14
-6,10,9:18.14
-2,10,9:18.14
-1,10,9:18.14
5,10,9:18.14
6,10,9:18.14
7,10,9:18.14
9,10,9:18.14
10,10,9:18.14
11,10,9:18.6
-15,11,9:18.6
-14,11,9:18.6
-13,11,9:18.6
-12,11,9:18.14
-9,11,9:18.14
-8,11,9:18.14
-7,11,9:18.14
-6,11,9:18.14
-5,11,9:18.14
-4,11,9:18.14
-3,11,9:18.14
7,11,9:18.14
8,11,9:18.14
9,11,9:18.14
10,11,9:18.14
11,11,9:18.6
-13,12,9:18.6
-12,12,9:18.14
-10,12,9:18.14
-9,12,9:18.14
-8,12,9:18.14
-7,12,9:18.14
-6,12,9:18.14
-5,12,9:18.14
5,12,9:18.14
-9,13,9:18.6
-7,13,9:18.6
-4,13,9:18.14
2,13,9:18.14
3,13,9:18.14
5,13,9:18.14
-9,14,9:18.6
-4,14,9:18.14
-2,14,9:18.14
1,14,9:18.14
2,14,9:18.14
3,14,9:18.14
4,14,9:18.14
5,14,9:18.14
-2,15,9:18.14
1,15,9:18.14
2,15,9:18.14
5,15,9:18.14
6,15,9:18.14
1,16,9:18.14
4,16,9:18.14
4,17,9:18.14
4,18,9:18.6
-1,-11,10:18.6
-3,-10,10:18.14
-2,-10,10:18.14
-3,-9,10:18.14
-3,-8,10:18.14
-2,-8,10:18.14
-2,-7,10:18.14
1,-7,10:18.14
-2,-6,10:18.14
5,-6,10:18.6
-1,-5,10:18.14
2,-5,10:18.14
3,-5,10:18.14
4,-5,10:18.14
5,-5,10:18.14
-1,-4,10:18.14
3,-4,10:18.14
4,-4,10:18.14
5,-4,10:18.14
9,-4,10:18.6
10,-4,10:18.6
2,-3,10:18.14
3,-3,10:18.14
4,-3,10:18.14
8,-3,10:18.6
9,-3,10:18.6
-4,-2,10:18.14
1,-2,10:18.14
2,-2,10:18.14
4,-2,10:18.14
6,-2,10:18.14
7,-2,10:18.14
8,-2,10:18.6
-4,-1,10:18.14
-3,-1,10:18.14
5,-1,10:18.14
6,-1,10:18.14
-3,0,10:17.12
-2,0,10:17.12
-1,0,10:17.12
-3,1,10:17.12
-2,1,10:17.12
4,1,10:18.14
5,1,10:18.14
-9,2,10:18.14
-3,2,10:17.12
-2,2,10:17.12
-10,3,10:18.14
-9,3,10:17.12
-8,3,10:17.12
-9,4,10:17.12
-8,4,10:17.12
8,4,10:18.14
6,5,10:18.14
7,5,10:18.14
8,5,10:18.14
-12,6,10:18.14
6,6,10:18.14
7,6,10:18.14
8,6,10:18.14
9,6,10:18.14
10,6,10:18.14
11,6,10:18.6
-16,7,10:18.14
-15,7,10:18.14
-13,7,10:18.14
-12,7,10:18.14
6,7,10:18.14
7,7,10:18.14
8,7,10:18.14
9,7,10:18.14
10,7,10:18.14
11,7,10:18.6
-17,8,10:18.6
-16,8,10:18.14
-15,8,10:18.14
-14,8,10:18.14
-13,8,10:18.14
-12,8,10:18.14
-9,8,10:18.14
-8,8,10:17.12
0,8,10:17.12
1,8,10:17.12
2,8,10:17.12
6,8,10:18.14
7,8,10:18.14
8,8,10:18.14
9,8,10:18.14
-17,9,10:18.6
-16,9,10:18.14
-14,9,10:18.14
-12,9,10:18.14
-11,9,10:18.14
-10,9,10:18.14
-8,9,10:18.14
-7,9,10:18.14
-5,9,10:18.14
-4,9,10:18.14
-3,9,10:18.14
-2,9,10:18.14
-1,9,10:18.14
0,9,10:17.12
1,9,10:17.12
2,9,10:17.12
3,9,10:17.12
4,9,10:18.14
5,9,10:18.14
6,9,10:18.14
7,9,10:18.14
8,9,10:18.14
9,9,10:18.14
10,9,10:18.14
11,9,10:18.6
-17,10,10:18.6
-16,10,10:18.14
-12,10,10:18.14
-11,10,10:18.14
-8,10,10:18.14
-7,10,10:18.14
-6,10,10:18.14
-5,10,10:18.14
-4,10,10:18.14
-3,10,10:18.14
-2,10,10:18.14
-1,10,10:17.12
0,10,10:17.12
3,10,10:17.12
5,10,10:18.14
6,10,10:18.14
7,10,10:18.14
8,10,10:18.14
9,10,10:18.14
10,10,10:18.14
-13,11,10:18.6
-12,11,10:18.14
-8,11,10:18.14
-7,11,10:18.14
-6,11,10:18.14
-5,11,10:18.14
-4,11,10:18.14
-2,11,10:18.14
-1,11,10:18.14
2,11,10:18.14
3,11,10:18.14
10,11,10:18.14
11,11,10:18.6
12,11,10:18.6
-14,12,10:18.6
-13,12,10:18.6
-9,12,10:18.14
-7,12,10:18.14
-6,12,10:18.14
-3,12,10:18.14
-2,12,10:18.14
-1,12,10:18.14
2,12,10:18.14
3,12,10:18.14
-14,13,10:18.6
-9,13,10:18.6
-3,13,10:18.14
-2,13,10:18.14
2,13,10:18.14
3,13,10:18.14
4,13,10:18.14
-3,14,10:18.14
-2,14,10:18.14
2,14,10:18.14
3,14,10:18.14
4,14,10:18.14
5,14,10:18.14
-4,15,10:18.14
-3,15,10:18.14
2,15,10:18.14
3,15,10:18.14
4,15,10:18.14
6,15,10:18.14
-4,16,10:18.6
-3,16,10:18.6
2,16,10:18.14
3,16,10:18.14
4,16,10:18.14
2,17,10:18.14
4,17,10:18.14
5,17,10:18.14
4,18,10:18.6
5,18,10:18.6
5,19,10:18.6
-1,-13,11:18.6
-1,-12,11:18.6
-3,-10,11:18.14
-2,-10,11:18.14
-3,-9,11:18.14
1,-9,11:18.6
1,-8,11:18.6
-2,-7,11:18.14
1,-7,11:18.14
-2,-6,11:18.14
1,-6,11:18.14
2,-6,11:18.14
3,-6,11:18.14
5,-6,11:18.6
-1,-5,11:18.14
1,-5,11:18.14
2,-5,11:18.14
3,-5,11:18.14
4,-5,11:18.14
5,-5,11:18.14
1,-4,11:18.14
3,-4,11:18.14
4,-4,11:18.14
10,-4,11:18.6
1,-3,11:18.14
2,-3,11:18.14
4,-3,11:18.14
9,-3,11:18.6
-4,-2,11:18.14
-3,-2,11:17.12
1,-2,11:18.14
2,-2,11:18.14
4,-2,11:18.14
7,-2,11:18.14
8,-2,11:18.6
-14,-1,11:18.14
-4,-1,11:17.12
-3,-1,11:17.12
-2,-1,11:17.12
0,-1,11:17.12
1,-1,11:18.14
6,-1,11:18.14
-16,0,11:18.6
-15,0,11:18.14
-3,0,11:17.12
-2,0,11:17.12
-1,0,11:17.12
0,0,11:17.12
-16,1,11:18.6
-10,1,11:18.14
-3,1,11:17.12
-2,1,11:17.12
-12,2,11:18.14
-11,2,11:18.14
-10,2,11:18.14
-16,3,11:18.14
-15,3,11:18.14
-13,3,11:18.14
-12,3,11:18.14
-10,3,11:18.14
-9,3,11:18.14
-17,4,11:18.6
-15,4,11:18.14
-14,4,11:18.14
-13,4,11:18.14
-12,4,11:18.14
-11,4,11:17.12
-10,4,11:17.12
-9,4,11:17.12
10,4,11:18.14
-13,5,11:18.14
-12,5,11:18.14
-11,5,11:17.12
-10,5,11:17.12
6,5,11:18.14
7,5,11:18.14
8,5,11:18.14
9,5,11:18.14
10,5,11:18.14
-17,6,11:18.6
-16,6,11:18.14
-15,6,11:18.14
-14,6,11:18.14
-13,6,11:18.14
-12,6,11:18.14
6,6,11:18.14
7,6,11:18.14
8,6,11:18.14
9,6,11:18.14
10,6,11:18.14
11,6,11:18.6
-17,7,11:18.6
-16,7,11:18.14
-15,7,11:18.14
-14,7,11:18.14
-13,7,11:18.14
-12,7,11:18.14
7,7,11:18.14
8,7,11:18.14
9,7,11:18.14
-17,8,11:18.6
-16,8,11:18.14
-15,8,11:18.14
-14,8,11:18.14
-12,8,11:18.14
6,8,11:17.12
7,8,11:18.14
8,8,11:18.14
9,8,11:18.14
10,8,11:18.14
11,8,11:18.6
12,8,11:18.6
-16,9,11:18.14
-12,9,11:18.14
-10,9,11:18.14
-2,9,11:18.14
2,9,11:17.12
3,9,11:17.12
4,9,11:17.12
5,9,11:18.14
6,9,11:17.12
7,9,11:18.14
8,9,11:18.14
9,9,11:18.14
10,9,11:18.14
11,9,11:18.6
-17,10,11:18.6
-12,10,11:18.14
-11,10,11:18.14
-8,10,11:18.14
-7,10,11:18.14
-6,10,11:18.14
-5,10,11:18.14
-4,10,11:18.14
-3,10,11:18.14
-2,10,11:18.14
3,10,11:17.12
6,10,11:18.14
7,10,11:18.14
8,10,11:18.14
9,10,11:18.14
-12,11,11:18.14
-8,11,11:18.14
-7,11,11:18.14
-6,11,11:18.14
-5,11,11:18.14
-4,11,11:18.14
-3,11,11:18.14
-2,11,11:18.14
-1,11,11:17.12
2,11,11:18.14
3,11,11:17.12
10,11,11:18.14
11,11,11:18.6
-13,12,11:18.6
-9,12,11:18.14
-8,12,11:18.14
-7,12,11:18.14
-6,12,11:18.14
-5,12,11:18.14
-3,12,11:18.14
-2,12,11:18.14
2,12,11:18.14
3,12,11:17.12
-14,13,11:18.6
-9,13,11:18.6
-4,13,11:18.14
-3,13,11:18.14
-2,13,11:18.14
2,13,11:18.14
3,13,11:18.14
4,13,11:18.14
-5,14,11:18.14
-4,14,11:18.14
-3,14,11:18.14
-2,14,11:18.14
2,14,11:18.14
3,14,11:18.14
4,14,11:18.14
5,14,11:18.14
-5,15,11:18.14
-3,15,11:18.14
2,15,11:18.14
3,15,11:18.14
4,15,11:18.14
5,15,11:18.14
6,15,11:18.14
-3,16,11:18.6
2,16,11:18.14
3,16,11:18.14
4,16,11:18.14
5,16,11:18.14
6,16,11:18.14
2,17,11:18.14
3,17,11:18.14
5,17,11:18.14
6,17,11:18.14
7,17,11:18.14
2,18,11:18.6
3,18,11:18.6
5,18,11:18.6
6,18,11:18.6
7,18,11:18.6
6,19,11:18.6
7,19,11:18.6
7,20,11:18.6
-8,-12,12:18.6
-1,-12,12:18.6
-7,-11,12:18.6
-2,-11,12:18.6
-1,-11,12:18.6
-2,-10,12:18.14
-3,-9,12:18.14
-2,-9,12:18.14
1,-9,12:18.6
-3,-8,12:18.14
-2,-8,12:18.14
1,-8,12:18.6
3,-8,12:18.6
-4,-7,12:18.14
-3,-7,12:18.14
-2,-7,12:18.14
1,-7,12:18.14
3,-7,12:18.14
4,-7,12:18.14
5,-7,12:18.6
6,-7,12:18.6
-2,-6,12:18.14
-1,-6,12:18.14
0,-6,12:18.14
1,-6,12:18.14
2,-6,12:18.14
3,-6,12:18.14
4,-6,12:18.14
5,-6,12:18.6
-1,-5,12:18.14
0,-5,12:18.14
1,-5,12:18.14
2,-5,12:18.14
3,-5,12:18.14
4,-5,12:18.14
5,-5,12:18.14
0,-4,12:18.14
2,-4,12:18.14
3,-4,12:18.14
4,-4,12:18.14
-5,-3,12:17.12
-4,-3,12:17.12
0,-3,12:18.14
1,-3,12:18.14
2,-3,12:18.14
3,-3,12:18.14
4,-3,12:18.14
-16,-2,12:18.6
-15,-2,12:18.6
-5,-2,12:17.12
-4,-2,12:17.12
-3,-2,12:17.12
0,-2,12:18.14
1,-2,12:18.14
2,-2,12:18.14
4,-2,12:18.14
8,-2,12:18.6
-15,-1,12:18.14
-14,-1,12:18.14
-12,-1,12:18.14
-11,-1,12:18.14
-4,-1,12:17.12
-3,-1,12:17.12
1,-1,12:17.12
6,-1,12:18.14
-17,0,12:18.6
-16,0,12:18.6
-14,0,12:18.14
-13,0,12:18.14
-12,0,12:18.14
-11,0,12:18.14
-18,1,12:18.6
-17,1,12:18.6
-16,1,12:18.6
-15,1,12:18.14
-14,1,12:18.14
-13,1,12:18.14
-12,1,12:18.14
-11,1,12:18.14
-3,1,12:17.12
-2,1,12:17.12
-17,2,12:18.6
-16,2,12:18.14
-15,2,12:18.14
-14,2,12:18.14
-13,2,12:18.14
-12,2,12:18.14
-11,2,12:18.14
-10,2,12:18.14
-3,2,12:17.12
-15,3,12:18.14
-14,3,12:18.14
-13,3,12:18.14
-11,3,12:17.12
-10,3,12:18.14
-9,3,12:18.14
-18,4,12:18.6
-17,4,12:18.6
-16,4,12:18.14
-11,4,12:17.12
-10,4,12:17.12
11,4,12:18.6
-18,5,12:18.6
-17,5,12:18.6
-16,5,12:18.14
-15,5,12:18.14
-14,5,12:18.14
-13,5,12:18.14
-12,5,12:18.14
10,5,12:18.14
11,5,12:18.6
-15,6,12:18.14
-14,6,12:18.14
-13,6,12:18.14
-12,6,12:17.12
9,6,12:18.14
10,6,12:18.14
-18,7,12:18.6
-17,7,12:18.6
-16,7,12:18.14
-15,7,12:18.14
-14,7,12:18.14
-13,7,12:18.14
8,7,12:18.14
9,7,12:18.14
-15,8,12:18.14
-14,8,12:18.14
-16,9,12:18.14
-12,9,12:18.14
-10,9,12:18.14
8,9,12:18.14
9,9,12:18.14
10,9,12:18.14
11,9,12:18.6
-11,10,12:18.14
-7,10,12:18.14
-6,10,12:18.14
-5,10,12:18.14
-4,10,12:18.14
-3,10,12:18.14
-2,10,12:18.14
7,10,12:18.14
8,10,12:18.14
9,10,12:18.14
-12,11,12:18.14
-8,11,12:18.14
-7,11,12:18.14
-3,11,12:18.14
-2,11,12:18.14
10,11,12:18.14
11,11,12:18.6
-7,12,12:18.14
-6,12,12:18.14
-5,12,12:18.14
-4,12,12:18.14
-3,12,12:18.14
-2,12,12:18.14
2,12,12:18.14
-7,13,12:18.6
-6,13,12:18.6
-5,13,12:18.14
-4,13,12:18.14
-3,13,12:18.14
-2,13,12:18.14
3,13,12:17.12
-5,14,12:18.14
-3,14,12:18.14
-2,14,12:18.14
3,14,12:18.14
4,14,12:18.14
-6,15,12:18.6
-3,15,12:18.14
3,15,12:18.14
4,15,12:18.14
-3,16,12:18.6
3,16,12:18.14
5,16,12:18.14
3,17,12:18.14
5,17,12:18.14
6,17,12:18.14
3,18,12:18.6
6,18,12:18.6
3,19,12:18.6
7,19,12:18.6
7,20,12:18.6
-1,-13,13:18.6
-5,-12,13:18.6
-1,-12,13:18.6
-7,-11,13:18.6
-5,-11,13:18.6
-2,-11,13:18.6
-7,-10,13:18.14
-5,-10,13:18.14
-2,-10,13:18.14
-7,-9,13:18.14
-5,-9,13:18.14
-3,-9,13:18.14
-2,-9,13:18.14
0,-9,13:18.14
-6,-8,13:18.14
-5,-8,13:18.14
-3,-8,13:18.14
-1,-8,13:18.14
0,-8,13:18.14
4,-8,13:18.6
6,-8,13:18.6
-6,-7,13:18.14
-5,-7,13:18.14
-4,-7,13:18.14
-1,-7,13:18.14
0,-7,13:18.14
3,-7,13:18.6
4,-7,13:18.6
5,-7,13:18.6
6,-7,13:18.6
-11,-6,13:18.14
-10,-6,13:18.14
-6,-6,13:18.14
-5,-6,13:18.14
-4,-6,13:18.14
-1,-6,13:18.14
0,-6,13:18.14
3,-6,13:18.6
4,-6,13:18.6
5,-6,13:18.6
-10,-5,13:18.14
-9,-5,13:18.14
-5,-5,13:18.14
0,-5,13:18.14
1,-5,13:18.14
2,-5,13:18.14
4,-5,13:18.14
5,-5,13:18.14
-12,-4,13:18.14
-11,-4,13:18.14
-10,-4,13:18.14
-8,-4,13:18.14
-5,-4,13:17.12
-4,-4,13:17.12
0,-4,13:18.14
1,-4,13:18.14
2,-4,13:18.14
3,-4,13:18.14
4,-4,13:18.14
-11,-3,13:18.14
-10,-3,13:18.14
-9,-3,13:18.14
-8,-3,13:17.12
-7,-3,13:18.14
-6,-3,13:17.12
-5,-3,13:17.12
-4,-3,13:17.12
0,-3,13:18.14
1,-3,13:18.14
3,-3,13:18.14
4,-3,13:18.14
-17,-2,13:18.6
-16,-2,13:18.6
-12,-2,13:18.14
-9,-2,13:17.12
-8,-2,13:18.14
2,-2,13:18.14
4,-2,13:18.14
-17,-1,13:18.6
-16,-1,13:18.6
-15,-1,13:18.14
-13,-1,13:18.14
-12,-1,13:18.14
-10,-1,13:18.14
-9,-1,13:18.14
-16,0,13:18.6
-15,0,13:18.14
-14,0,13:18.14
-13,0,13:18.14
-12,0,13:18.14
-11,0,13:18.14
-10,0,13:18.14
-15,1,13:18.14
-14,1,13:18.14
-13,1,13:18.14
-12,1,13:18.14
-11,1,13:18.14
-17,2,13:18.6
-16,2,13:18.14
-15,2,13:18.14
-14,2,13:18.14
-13,2,13:18.14
-12,2,13:18.14
-11,2,13:18.14
-10,2,13:18.14
-4,2,13:17.12
-3,2,13:17.12
-13,3,13:18.14
-12,3,13:18.14
-11,3,13:17.12
-10,3,13:18.14
-9,3,13:18.14
-19,5,13:18.6
-18,5,13:18.6
-12,5,13:18.14
11,5,13:18.6
-18,6,13:18.6
-17,6,13:18.6
-16,6,13:18.14
-15,6,13:18.14
-14,6,13:18.14
-13,6,13:18.14
9,6,13:18.14
10,6,13:18.14
-18,7,13:18.6
-17,7,13:18.6
-16,7,13:18.14
-15,7,13:18.14
-14,7,13:18.14
9,7,13:18.14
-16,9,13:18.14
9,9,13:18.14
10,9,13:18.14
-5,10,13:18.14
-4,10,13:18.14
-3,10,13:18.14
9,10,13:18.14
-6,11,13:18.14
10,11,13:18.14
-4,12,13:18.14
-3,12,13:18.14
-2,12,13:18.14
-6,13,13:18.6
-5,13,13:18.14
-4,13,13:18.14
-3,13,13:18.14
-7,14,13:18.6
-6,14,13:18.6
-5,14,13:18.14
-4,14,13:18.14
-3,14,13:18.14
3,14,13:18.14
-6,15,13:18.6
-4,15,13:18.14
3,15,13:18.14
4,15,13:18.14
3,16,13:18.14
5,16,13:18.14
3,17,13:18.14
5,17,13:18.14
6,17,13:18.14
3,18,13:18.6
6,18,13:18.6
3,19,13:18.6
-4,-14,14:18.6
-8,-13,14:18.6
-4,-13,14:18.6
-3,-13,14:18.6
-1,-13,14:18.6
-8,-12,14:18.6
-4,-12,14:18.6
-3,-12,14:18.6
-2,-12,14:18.6
-1,-12,14:18.6
-8,-11,14:18.6
-4,-11,14:18.6
-3,-11,14:18.6
-2,-11,14:18.6
-7,-10,14:18.14
-4,-10,14:18.14
-3,-10,14:18.14
-2,-10,14:18.14
-1,-10,14:18.14
0,-10,14:18.14
-7,-9,14:18.14
-4,-9,14:18.14
-3,-9,14:18.14
-1,-9,14:18.14
0,-9,14:18.14
-10,-8,14:18.6
-7,-8,14:18.14
-4,-8,14:18.14
-3,-8,14:18.14
0,-8,14:18.14
4,-8,14:18.6
-8,-7,14:18.14
-6,-7,14:18.14
-4,-7,14:18.14
0,-7,14:18.14
1,-7,14:18.6
3,-7,14:18.6
5,-7,14:18.6
6,-7,14:18.6
-11,-6,14:18.14
-7,-6,14:18.14
-6,-6,14:18.14
-5,-6,14:17.12
-4,-6,14:18.14
0,-6,14:18.14
1,-6,14:18.14
3,-6,14:18.6
5,-6,14:18.6
-11,-5,14:18.14
-10,-5,14:18.14
-6,-5,14:18.14
-5,-5,14:18.14
0,-5,14:18.14
1,-5,14:18.14
2,-5,14:18.14
4,-5,14:18.14
5,-5,14:18.14
-12,-4,14:18.14
-11,-4,14:18.14
-10,-4,14:18.14
-9,-4,14:18.14
-8,-4,14:18.14
-5,-4,14:17.12
0,-4,14:18.14
1,-4,14:18.14
2,-4,14:18.14
4,-4,14:18.14
-13,-3,14:18.14
-11,-3,14:18.14
-10,-3,14:18.14
-8,-3,14:17.12
-7,-3,14:18.14
1,-3,14:18.14
3,-3,14:18.14
4,-3,14:18.14
-18,-2,14:18.6
-17,-2,14:18.6
-13,-2,14:18.14
-12,-2,14:18.14
-11,-2,14:18.14
-10,-2,14:18.14
-8,-2,14:18.14
-7,-2,14:18.14
4,-2,14:18.14
-16,-1,14:18.6
-13,-1,14:18.14
-12,-1,14:18.14
-11,-1,14:18.14
-10,-1,14:18.14
-6,-1,14:18.14
-15,0,14:18.14
-14,0,14:18.14
-13,0,14:18.14
-12,0,14:18.14
-11,0,14:18.14
-8,0,14:18.14
-6,0,14:18.14
-5,0,14:18.14
-14,1,14:18.14
-13,1,14:18.14
-12,1,14:18.14
-11,1,14:18.14
-7,1,14:18.14
-6,1,14:18.14
-5,1,14:18.14
-4,1,14:18.14
-17,2,14:18.6
-16,2,14:18.14
-15,2,14:18.14
-14,2,14:18.14
-13,2,14:18.14
-12,2,14:18.14
-11,2,14:18.14
-6,2,14:18.14
-5,2,14:18.14
-4,2,14:17.12
-3,2,14:17.12
-10,3,14:18.14
11,5,14:18.6
-19,6,14:18.6
-17,6,14:18.6
-16,6,14:18.14
-15,6,14:18.14
-14,6,14:18.14
-13,6,14:18.14
10,6,14:18.14
-20,7,14:18.6
-19,7,14:18.6
-18,7,14:18.6
-3,12,14:18.14
-5,13,14:18.14
-4,13,14:18.14
-3,13,14:18.14
-7,14,14:18.6
-6,14,14:18.6
-5,14,14:18.14
-3,14,14:18.14
-7,15,14:18.6
-4,15,14:18.14
3,15,14:18.14
3,16,14:18.14
5,16,14:18.14
3,17,14:18.14
5,17,14:18.14
6,18,14:18.6
-2,-14,15:18.6
-1,-14,15:18.6
0,-14,15:18.6
-3,-13,15:18.6
-2,-13,15:18.6
-1,-13,15:18.6
-8,-12,15:18.6
-3,-12,15:18.6
-2,-12,15:18.6
-1,-12,15:18.6
-8,-11,15:18.6
-3,-11,15:18.6
-2,-11,15:18.6
-8,-10,15:18.14
-7,-10,15:18.14
-3,-10,15:18.14
-2,-10,15:18.14
0,-10,15:18.14
-10,-9,15:18.6
-7,-9,15:18.14
-3,-9,15:18.14
0,-9,15:18.14
-10,-8,15:18.6
-9,-8,15:18.14
-8,-8,15:18.14
-7,-8,15:18.14
-4,-8,15:18.14
-3,-8,15:18.14
0,-8,15:18.14
1,-8,15:18.6
-8,-7,15:18.14
-7,-7,15:18.14
-6,-7,15:18.14
-5,-7,15:18.14
-4,-7,15:18.14
-3,-7,15:18.14
0,-7,15:18.14
1,-7,15:18.6
3,-7,15:18.6
-12,-6,15:18.14
-6,-6,15:18.14
-5,-6,15:18.14
-4,-6,15:17.12
0,-6,15:18.14
1,-6,15:18.14
2,-6,15:18.6
3,-6,15:18.6
-13,-5,15:18.14
-12,-5,15:18.14
-11,-5,15:18.14
-5,-5,15:18.14
0,-5,15:18.14
2,-5,15:18.14
5,-5,15:18.14
-10,-4,15:18.14
-9,-4,15:18.14
-8,-4,15:18.14
2,-4,15:18.14
-8,-3,15:18.14
1,-3,15:18.14
-17,-2,15:18.6
-12,-2,15:18.14
-11,-2,15:18.14
-10,-2,15:18.14
-8,-2,15:18.14
-7,-2,15:18.14
-16,-1,15:18.6
-12,-1,15:18.14
-11,-1,15:18.14
-10,-1,15:18.14
-9,-1,15:18.14
-8,-1,15:18.14
-7,-1,15:18.14
-15,0,15:18.14
-14,0,15:18.14
-13,0,15:18.14
-12,0,15:18.14
-9,0,15:18.14
-8,0,15:18.14
-7,0,15:18.14
-6,0,15:18.14
-14,1,15:18.14
-13,1,15:18.14
-12,1,15:18.14
-11,1,15:18.14
-10,1,15:18.14
-9,1,15:18.14
-8,1,15:18.14
-7,1,15:18.14
-6,1,15:18.14
-5,1,15:18.14
-11,2,15:18.14
-8,2,15:18.14
-7,2,15:18.14
-6,2,15:18.14
-5,2,15:18.14
-10,3,15:18.14
-9,3,15:18.14
-16,6,15:18.14
-15,6,15:18.14
-14,6,15:18.14
-19,7,15:18.6
-18,7,15:18.6
-17,7,15:18.6
-16,7,15:18.14
-4,13,15:18.14
-3,13,15:18.14
-5,14,15:18.14
-7,15,15:18.6
3,16,15:18.14
3,17,15:18.14
3,18,15:18.6
-1,-15,16:18.6
0,-15,16:18.6
-1,-14,16:18.6
-1,-13,16:18.6
-9,-12,16:18.6
-8,-12,16:18.6
-3,-12,16:18.6
-1,-12,16:18.6
-8,-11,16:18.6
-3,-11,16:18.6
-2,-11,16:18.6
-11,-10,16:18.6
-10,-10,16:18.6
-9,-10,16:18.14
-8,-10,16:18.14
-3,-10,16:18.14
-2,-10,16:18.14
-10,-9,16:18.6
-9,-9,16:18.14
-8,-9,16:18.14
-7,-9,16:18.14
-4,-9,16:18.14
-3,-9,16:18.14
-2,-9,16:18.14
-8,-8,16:18.14
-7,-8,16:18.14
-5,-8,16:18.14
-4,-8,16:18.14
-3,-8,16:18.14
0,-8,16:18.14
2,-8,16:18.6
-6,-7,16:18.14
-5,-7,16:18.14
-4,-7,16:18.14
-3,-7,16:18.14
0,-7,16:18.14
2,-7,16:18.6
3,-7,16:18.6
-6,-6,16:18.14
-5,-6,16:18.14
-4,-6,16:17.12
0,-6,16:18.14
2,-6,16:18.6
-12,-5,16:18.14
-11,-5,16:18.14
2,-5,16:18.14
-11,-4,16:18.14
-10,-4,16:18.14
-9,-4,16:18.14
2,-4,16:18.14
-10,-2,16:18.14
-8,-2,16:18.14
-16,-1,16:18.6
-12,-1,16:18.14
-11,-1,16:18.14
-10,-1,16:18.14
-9,-1,16:18.14
-8,-1,16:18.14
-7,-1,16:18.14
-15,0,16:18.14
-10,0,16:18.14
-9,0,16:18.14
-8,0,16:18.14
-7,0,16:18.14
-6,0,16:18.14
-13,1,16:18.14
-8,1,16:18.14
-7,1,16:18.14
-6,1,16:18.14
-5,1,16:18.14
-9,2,16:18.14
-8,2,16:18.14
-7,2,16:18.14
-6,2,16:18.14
-5,2,16:18.14
-10,3,16:18.14
-17,7,16:18.6
-16,7,16:18.14
-15,7,16:18.14
-5,14,16:18.6
3,17,16:18.14
-2,-14,17:18.6
0,-14,17:18.6
-2,-13,17:18.6
-1,-13,17:18.6
-9,-12,17:18.6
-7,-12,17:18.6
-3,-12,17:18.6
-11,-11,17:18.6
-10,-11,17:18.6
-9,-11,17:18.6
-8,-11,17:18.6
-7,-11,17:18.6
-6,-11,17:18.6
-3,-11,17:18.6
-2,-11,17:18.6
-1,-11,17:18.6
-9,-10,17:18.14
-8,-10,17:18.14
-6,-10,17:18.14
-5,-10,17:18.14
-4,-10,17:18.14
-3,-10,17:18.14
-2,-10,17:18.14
-8,-9,17:18.14
-7,-9,17:18.14
-5,-9,17:18.14
-4,-9,17:18.14
-2,-9,17:18.14
-7,-8,17:18.14
-5,-8,17:18.14
-4,-8,17:18.14
-3,-8,17:18.14
3,-8,17:18.6
-6,-7,17:18.14
-4,-7,17:18.14
3,-7,17:18.6
-6,-6,17:18.14
2,-6,17:18.6
2,-5,17:18.6
-11,-4,17:18.14
-10,-4,17:18.14
2,-4,17:18.6
-12,-1,17:18.14
-11,-1,17:18.14
-10,-1,17:18.14
-9,-1,17:18.14
-8,-1,17:18.14
-7,-1,17:18.14
-10,0,17:18.14
-9,0,17:18.14
-8,0,17:18.14
-7,0,17:18.14
-6,0,17:18.14
-9,1,17:18.14
-8,1,17:18.14
-7,1,17:18.14
-6,1,17:18.14
-10,2,17:18.14
-9,2,17:18.14
-8,2,17:18.14
-6,2,17:18.14
-5,2,17:18.14
-9,-13,18:18.6
-3,-13,18:18.6
-10,-12,18:18.6
-9,-12,18:18.6
-6,-12,18:18.6
-3,-12,18:18.6
-1,-12,18:18.6
-9,-11,18:18.6
-6,-11,18:18.6
-5,-11,18:18.6
-3,-11,18:18.6
-8,-10,18:18.14
-5,-10,18:18.14
-4,-10,18:18.14
-2,-10,18:18.14
-7,-9,18:18.14
-4,-9,18:18.14
-2,-9,18:18.14
-7,-8,18:18.14
-4,-8,18:18.14
3,-8,18:18.6
-6,-7,18:18.14
-4,-7,18:18.14
3,-7,18:18.6
-4,-6,18:18.14
-11,-1,18:18.14
-10,-1,18:18.14
-8,-1,18:18.14
-10,0,18:18.14
-9,0,18:18.14
-8,0,18:18.14
-7,0,18:18.14
-10,1,18:18.14
-9,1,18:18.14
-8,1,18:18.14
-7,1,18:18.14
-6,1,18:18.14
-7,2,18:18.14
-6,2,18:18.14
-5,2,18:18.14
-10,-13,19:18.6
-6,-13,19:18.6
-3,-13,19:18.6
-10,-12,19:18.6
-9,-12,19:18.6
-5,-12,19:18.6
-3,-12,19:18.6
-9,-11,19:18.6
-5,-11,19:18.6
-4,-11,19:18.6
-3,-11,19:18.6
-8,-10,19:18.14
-4,-10,19:18.14
-7,-9,19:18.14
-4,-9,19:18.14
-7,-8,19:18.14
-4,-8,19:18.14
-6,-7,19:18.14
-4,-7,19:18.14
-9,0,19:18.6
-10,1,19:18.6
-9,1,19:18.6
-8,1,19:18.6
-7,1,19:18.6
-7,2,19:18.6
-6,2,19:18.6
-5,-13,20:18.6
-4,-13,20:18.6
-3,-13,20:18.6
-4,-12,20:18.6
-3,-12,20:18.6
-4,-11,20:18.6
-3,-11,20:18.6
-8,-10,20:18.14
-4,-10,20:18.14
-4,-9,20:18.14
-4,-8,20:18.14
-10,1,20:18.6
-8,2,20:18.6
-7,2,20:18.6
-3,-14,21:18.6
-4,-13,21:18.6
-3,-13,21:18.6
-3,-12,21:18.6
-3,-11,21:18.6
-4,-10,21:18.6
-3,-10,21:18.6
-4,-9,21:18.6
-4,-8,21:18.6
-3,-14,22:18.6
-3,-13,22:18.6
-3,-12,22:18.6
-3,-10,22:18.6
-3,-14,23:18.6
-3,-13,23:18.6
