[META]
version=2.0
spawnOnBlockType=2
spawnSunlight=True
spawnDarkness=True
spawnWater=False
spawnLava=False
underFill=False
randomRotation=True
dig=True
tree=False
branch=False
needsFoundation=True
rarity=100
collisionPercentage=20
spawnElevationMin=0
spawnElevationMax=200
spawnInBiome=Custom
[DATA]
-9,-3,-8:17.12
-6,-2,-8:17.12
-5,-2,-8:17.12
-1,1,-8:17.12
-1,2,-8:17.12
-3,6,-8:17.12
-8,7,-8:17.12
-5,-4,-7:17.12
-10,-3,-7:17.12
-8,-3,-7:17.12
-6,-3,-7:17.12
-5,-3,-7:17.12
-10,-2,-7:17.12
-9,-2,-7:17.12
-8,-2,-7:17.12
-6,-2,-7:17.12
-5,-2,-7:17.12
-4,-2,-7:17.12
-10,-1,-7:17.12
-9,-1,-7:17.12
-8,-1,-7:17.12
-5,-1,-7:17.12
-4,-1,-7:17.12
-2,0,-7:17.12
-1,0,-7:17.12
-2,1,-7:17.12
-1,1,-7:17.12
0,1,-7:17.12
-1,2,-7:17.12
-8,5,-7:17.12
-3,5,-7:17.12
-7,6,-7:17.12
-3,6,-7:17.12
-9,7,-7:17.12
-8,7,-7:17.12
-7,7,-7:17.12
-6,-4,-6:17.12
-5,-4,-6:17.12
-4,-4,-6:17.12
-6,-3,-6:17.12
-5,-3,-6:17.12
-4,-3,-6:17.12
-9,-2,-6:17.12
-5,-2,-6:17.12
-4,-2,-6:17.12
-9,-1,-6:17.12
-5,-1,-6:17.12
-4,-1,-6:17.12
-9,0,-6:17.12
-1,0,-6:17.12
0,0,-6:17.12
-9,1,-6:17.12
-2,1,-6:17.12
-1,1,-6:17.12
0,1,-6:17.12
-1,2,-6:17.12
0,2,-6:17.12
-2,3,-6:17.12
-1,3,-6:17.12
-9,5,-6:17.12
-8,5,-6:17.12
-7,5,-6:17.12
-4,5,-6:17.12
-8,6,-6:17.12
-7,6,-6:17.12
-6,6,-6:17.12
-5,6,-6:17.12
-4,6,-6:17.12
-3,6,-6:17.12
-2,6,-6:17.12
-8,7,-6:17.12
-7,7,-6:17.12
-4,7,-6:17.12
-3,7,-6:17.12
-5,-4,-5:17.12
-5,-3,-5:17.12
-6,-2,-5:17.12
-5,-2,-5:17.12
-10,-1,-5:17.12
-9,-1,-5:17.12
-8,-1,-5:17.12
-5,-1,-5:17.12
-9,0,-5:17.12
-8,0,-5:17.12
-1,1,-5:17.12
0,1,-5:17.12
-3,2,-5:17.12
-2,2,-5:17.12
-1,2,-5:17.12
-1,3,-5:17.12
-8,4,-5:17.12
-9,5,-5:17.12
-8,5,-5:17.12
-6,5,-5:17.12
-5,5,-5:17.12
-4,5,-5:17.12
-3,5,-5:17.12
-9,6,-5:17.12
-8,6,-5:17.12
-7,6,-5:17.12
-6,6,-5:17.12
-5,6,-5:17.12
-4,6,-5:17.12
-3,6,-5:17.12
-8,7,-5:17.12
-6,7,-5:17.12
-5,7,-5:17.12
-4,7,-5:17.12
-3,7,-5:17.12
-5,-4,-4:17.12
-6,-3,-4:17.12
-5,-3,-4:17.12
-4,-3,-4:17.12
-9,-2,-4:17.12
-6,-2,-4:17.12
-5,-2,-4:17.12
-4,-2,-4:17.12
-9,-1,-4:17.12
-8,-1,-4:17.12
-9,0,-4:17.12
-8,0,-4:17.12
-9,1,-4:17.12
-2,2,-4:17.12
-1,2,-4:17.12
-3,3,-4:17.12
-2,3,-4:17.12
-1,3,-4:17.12
-9,4,-4:17.12
-8,4,-4:17.12
-7,4,-4:17.12
-9,5,-4:17.12
-8,5,-4:17.12
-7,5,-4:17.12
-6,5,-4:17.12
-5,5,-4:17.12
-4,5,-4:17.12
-8,6,-4:17.12
-6,6,-4:17.12
-5,6,-4:17.12
-4,6,-4:17.12
-5,7,-4:17.12
-4,7,-4:17.12
-6,-4,-3:17.12
-5,-4,-3:17.12
-7,-3,-3:17.12
-6,-3,-3:17.12
-5,-3,-3:17.12
-4,-3,-3:17.12
-7,-2,-3:17.12
-6,-2,-3:17.12
-5,-2,-3:17.12
-9,-1,-3:17.12
-8,-1,-3:17.12
-7,-1,-3:17.12
-10,0,-3:17.12
-8,0,-3:17.12
-7,0,-3:17.12
-9,1,-3:17.12
-8,1,-3:17.12
-4,1,-3:17.12
-3,1,-3:17.12
-2,1,-3:17.12
-1,1,-3:17.12
-3,2,-3:17.12
-2,2,-3:17.12
-1,2,-3:17.12
0,2,-3:17.12
-9,3,-3:17.12
-8,3,-3:17.12
-7,3,-3:17.12
-2,3,-3:17.12
-1,3,-3:17.12
-8,4,-3:17.12
-7,4,-3:17.12
-3,4,-3:17.12
-2,4,-3:17.12
-9,5,-3:17.12
-8,5,-3:17.12
-7,5,-3:17.12
-5,5,-3:17.12
-3,5,-3:17.12
-7,6,-3:17.12
-6,6,-3:17.12
-5,6,-3:17.12
-4,6,-3:17.12
-3,6,-3:17.12
-5,7,-3:17.12
-4,7,-3:17.12
-8,-4,-2:17.12
-7,-4,-2:17.12
-6,-4,-2:17.12
-5,-4,-2:17.12
-9,-3,-2:17.12
-8,-3,-2:17.12
-7,-3,-2:17.12
-6,-3,-2:17.12
-5,-3,-2:17.12
-4,-3,-2:17.12
-3,-3,-2:17.12
-9,-2,-2:17.12
-8,-2,-2:17.12
-7,-2,-2:17.12
-6,-2,-2:17.12
-5,-2,-2:17.12
-4,-2,-2:17.12
-3,-2,-2:17.12
-2,-2,-2:17.12
-10,-1,-2:17.12
-9,-1,-2:17.12
-8,-1,-2:17.12
-7,-1,-2:17.12
-6,-1,-2:17.12
-5,-1,-2:17.12
-4,-1,-2:17.12
-3,-1,-2:17.12
-2,-1,-2:17.12
-10,0,-2:17.12
-9,0,-2:17.12
-8,0,-2:17.12
-7,0,-2:17.12
-6,0,-2:17.12
-5,0,-2:17.12
-4,0,-2:17.12
-3,0,-2:17.12
-2,0,-2:17.12
-1,0,-2:17.12
-11,1,-2:17.12
-10,1,-2:17.12
-9,1,-2:17.12
-8,1,-2:17.12
-7,1,-2:17.12
-6,1,-2:17.12
-5,1,-2:17.12
-4,1,-2:17.12
-3,1,-2:17.12
-2,1,-2:17.12
-1,1,-2:17.12
0,1,-2:17.12
-11,2,-2:17.12
-10,2,-2:17.12
-9,2,-2:17.12
-8,2,-2:17.12
-7,2,-2:17.12
-6,2,-2:17.12
-5,2,-2:17.12
-4,2,-2:17.12
-3,2,-2:17.12
-2,2,-2:17.12
-1,2,-2:17.12
0,2,-2:17.12
-11,3,-2:17.12
-10,3,-2:17.12
-9,3,-2:17.12
-8,3,-2:17.12
-7,3,-2:17.12
-6,3,-2:17.12
-5,3,-2:17.12
-4,3,-2:17.12
-3,3,-2:17.12
-2,3,-2:17.12
-1,3,-2:17.12
0,3,-2:17.12
-10,4,-2:17.12
-9,4,-2:17.12
-8,4,-2:17.12
-7,4,-2:17.12
-6,4,-2:17.12
-5,4,-2:17.12
-4,4,-2:17.12
-3,4,-2:17.12
-2,4,-2:17.12
-1,4,-2:17.12
-10,5,-2:17.12
-9,5,-2:17.12
-8,5,-2:17.12
-7,5,-2:17.12
-6,5,-2:17.12
-5,5,-2:17.12
-4,5,-2:17.12
-3,5,-2:17.12
-2,5,-2:17.12
-1,5,-2:17.12
-9,6,-2:17.12
-8,6,-2:17.12
-7,6,-2:17.12
-6,6,-2:17.12
-5,6,-2:17.12
-4,6,-2:17.12
-3,6,-2:17.12
-2,6,-2:17.12
-9,7,-2:17.12
-8,7,-2:17.12
-7,7,-2:17.12
-6,7,-2:17.12
-5,7,-2:17.12
-4,7,-2:17.12
-3,7,-2:17.12
-8,-4,-1:17.12
-7,-4,-1:17.12
-6,-4,-1:17.12
-5,-4,-1:17.12
-8,-3,-1:17.12
-6,-3,-1:17.12
-5,-3,-1:17.12
-4,-3,-1:17.12
-3,-3,-1:17.12
-2,-3,-1:17.12
-9,-2,-1:17.12
-6,-2,-1:17.12
-2,-2,-1:17.12
-10,-1,-1:17.12
-9,-1,-1:17.12
-2,-1,-1:17.12
-1,-1,-1:17.12
-10,0,-1:17.12
-9,0,-1:17.12
-1,0,-1:17.12
-11,1,-1:17.12
-10,1,-1:17.12
-9,1,-1:17.12
-3,1,-1:17.12
-2,1,-1:17.12
-1,1,-1:17.12
0,1,-1:17.12
-10,2,-1:17.12
-2,2,-1:17.12
0,2,-1:17.12
-10,3,-1:17.12
-9,3,-1:17.12
-7,3,-1:17.12
-1,3,-1:17.12
-9,4,-1:17.12
-8,4,-1:17.12
-3,4,-1:17.12
-2,4,-1:17.12
-1,4,-1:17.12
-9,5,-1:17.12
-8,5,-1:17.12
-7,5,-1:17.12
-2,5,-1:17.12
-8,6,-1:17.12
-7,6,-1:17.12
-6,6,-1:17.12
-5,6,-1:17.12
-4,6,-1:17.12
-3,6,-1:17.12
-2,6,-1:17.12
-8,7,-1:17.12
-7,7,-1:17.12
-6,7,-1:17.12
-5,7,-1:17.12
-4,7,-1:17.12
-3,7,-1:17.12
-7,-4,0:17.12
-6,-4,0:17.12
-5,-4,0:17.12
-8,-3,0:17.12
-5,-3,0:17.12
-4,-3,0:17.12
-3,-3,0:17.12
-2,-3,0:17.12
-9,-2,0:17.12
-8,-2,0:17.12
-2,-2,0:17.12
-9,-1,0:17.12
-2,-1,0:17.12
-1,-1,0:17.12
-10,0,0:17.12
-9,0,0:17.12
-1,0,0:17.12
-10,1,0:17.12
-1,1,0:17.12
0,1,0:17.12
-10,2,0:17.12
-1,2,0:17.12
0,2,0:17.12
-9,3,0:17.12
-1,3,0:17.12
-9,4,0:17.12
-8,4,0:17.12
-2,4,0:17.12
-8,5,0:17.12
-3,5,0:17.12
-2,5,0:17.12
-8,6,0:17.12
-7,6,0:17.12
-6,6,0:17.12
-5,6,0:17.12
-4,6,0:17.12
-3,6,0:17.12
-7,-4,1:17.12
-6,-4,1:17.12
-8,-3,1:17.12
-7,-3,1:17.12
-6,-3,1:17.12
-5,-3,1:17.12
-4,-3,1:17.12
-3,-3,1:17.12
-8,-2,1:17.12
-3,-2,1:17.12
-2,-2,1:17.12
-9,-1,1:17.12
-8,-1,1:17.12
-2,-1,1:17.12
-9,0,1:17.12
-2,0,1:17.12
-1,0,1:17.12
-10,1,1:17.12
-9,1,1:17.12
-1,1,1:17.12
-9,2,1:17.12
-1,2,1:17.12
-9,3,1:17.12
-8,3,1:17.12
-2,3,1:17.12
-1,3,1:17.12
-8,4,1:17.12
-2,4,1:17.12
-8,5,1:17.12
-7,5,1:17.12
-6,5,1:17.12
-5,5,1:17.12
-4,5,1:17.12
-3,5,1:17.12
-5,6,1:17.12
-4,6,1:17.12
-3,6,1:17.12
-7,-3,2:17.12
-6,-3,2:17.12
-5,-3,2:17.12
-4,-3,2:17.12
-8,-2,2:17.12
-4,-2,2:17.12
-3,-2,2:17.12
-8,-1,2:17.12
-2,-1,2:17.12
-9,0,2:17.12
-2,0,2:17.12
-9,1,2:17.12
-1,1,2:17.12
-9,2,2:17.12
-8,2,2:17.12
-2,2,2:17.12
-1,2,2:17.12
-8,3,2:17.12
-2,3,2:17.12
-8,4,2:17.12
-7,4,2:17.12
-3,4,2:17.12
-2,4,2:17.12
-7,5,2:17.12
-6,5,2:17.12
-5,5,2:17.12
-4,5,2:17.12
-3,5,2:17.12
-7,-3,3:17.12
-6,-3,3:17.12
-8,-2,3:17.12
-7,-2,3:17.12
-6,-2,3:17.12
-5,-2,3:17.12
-4,-2,3:17.12
-3,-2,3:17.12
-8,-1,3:17.12
-3,-1,3:17.12
-2,-1,3:17.12
-9,0,3:17.12
-8,0,3:17.12
-2,0,3:17.12
-9,1,3:17.12
-8,1,3:17.12
-2,1,3:17.12
-8,2,3:17.12
-2,2,3:17.12
-8,3,3:17.12
-3,3,3:17.12
-2,3,3:17.12
-7,4,3:17.12
-3,4,3:17.12
-7,5,3:17.12
-6,5,3:17.12
-5,5,3:17.12
-4,5,3:17.12
-3,5,3:17.12
-7,-2,4:17.12
-6,-2,4:17.12
-5,-2,4:17.12
-4,-2,4:17.12
-3,-2,4:17.12
-8,-1,4:17.12
-7,-1,4:17.12
-3,-1,4:17.12
-2,-1,4:17.12
-8,0,4:17.12
-2,0,4:17.12
-8,1,4:17.12
-2,1,4:17.12
-8,2,4:17.12
-2,2,4:17.12
-7,3,4:17.12
-3,3,4:17.12
-7,4,4:17.12
-6,4,4:17.12
-5,4,4:17.12
-4,4,4:17.12
-3,4,4:17.12
-6,-3,5:17.12
-5,-3,5:17.12
-4,-3,5:17.12
-3,-3,5:17.12
-7,-2,5:17.12
-6,-2,5:17.12
-4,-2,5:17.12
-3,-2,5:17.12
-2,-2,5:17.12
-7,-1,5:17.12
-2,-1,5:17.12
-8,0,5:17.12
-7,0,5:17.12
-2,0,5:17.12
-1,0,5:17.12
-8,1,5:17.12
-2,1,5:17.12
-8,2,5:17.12
-7,2,5:17.12
-3,2,5:17.12
-2,2,5:17.12
-7,3,5:17.12
-3,3,5:17.12
-7,4,5:17.12
-6,4,5:17.12
-5,4,5:17.12
-4,4,5:17.12
-3,4,5:17.12
-6,-3,6:17.12
-5,-3,6:17.12
-4,-3,6:17.12
-3,-3,6:17.12
-6,-2,6:17.12
-3,-2,6:17.12
-2,-2,6:17.12
-7,-1,6:17.12
-2,-1,6:17.12
-7,0,6:17.12
-2,0,6:17.12
-1,0,6:17.12
-7,1,6:17.12
-2,1,6:17.12
-7,2,6:17.12
-3,2,6:17.12
-2,2,6:17.12
-7,3,6:17.12
-6,3,6:17.12
-5,3,6:17.12
-4,3,6:17.12
-3,3,6:17.12
-6,-3,7:17.12
-5,-3,7:17.12
-4,-3,7:17.12
-3,-3,7:17.12
-6,-2,7:17.12
-2,-2,7:17.12
-7,-1,7:17.12
-6,-1,7:17.12
-2,-1,7:17.12
-1,-1,7:17.12
-7,0,7:17.12
-2,0,7:17.12
-1,0,7:17.12
-7,1,7:17.12
-6,1,7:17.12
-2,1,7:17.12
-6,2,7:17.12
-3,2,7:17.12
-6,3,7:17.12
-5,3,7:17.12
-4,3,7:17.12
-3,3,7:17.12
-3,-4,8:17.12
-5,-3,8:17.12
-4,-3,8:17.12
-3,-3,8:17.12
-2,-3,8:17.12
-6,-2,8:17.12
-2,-2,8:17.12
-1,-2,8:17.12
-6,-1,8:17.12
-1,-1,8:17.12
-7,0,8:17.12
-6,0,8:17.12
-2,0,8:17.12
-1,0,8:17.12
-6,1,8:17.12
-3,1,8:17.12
-2,1,8:17.12
-6,2,8:17.12
-5,2,8:17.12
-4,2,8:17.12
-3,2,8:17.12
-2,-4,9:17.12
-1,-4,9:17.12
-5,-3,9:17.12
-4,-3,9:17.12
-3,-3,9:17.12
-2,-3,9:17.12
-1,-3,9:17.12
0,-3,9:17.12
-6,-2,9:17.12
-5,-2,9:17.12
-1,-2,9:17.12
0,-2,9:17.12
-6,-1,9:17.12
-2,-1,9:17.12
-1,-1,9:17.12
0,-1,9:17.12
-6,0,9:17.12
-2,0,9:17.12
-6,1,9:17.12
-5,1,9:17.12
-4,1,9:17.12
-3,1,9:17.12
-2,1,9:17.12
-5,2,9:17.12
-4,2,9:17.12
-3,2,9:17.12
-1,-4,10:17.12
0,-4,10:17.12
-3,-3,10:17.12
-2,-3,10:17.12
-1,-3,10:17.12
0,-3,10:17.12
1,-3,10:17.12
2,-3,10:17.12
-5,-2,10:17.12
-4,-2,10:17.12
-3,-2,10:17.12
1,-2,10:17.12
-6,-1,10:17.12
-5,-1,10:17.12
-2,-1,10:17.12
-1,-1,10:17.12
0,-1,10:17.12
1,-1,10:17.12
-8,0,10:17.12
-7,0,10:17.12
-6,0,10:17.12
-3,0,10:17.12
-2,0,10:17.12
-7,1,10:17.12
-6,1,10:17.12
-5,1,10:17.12
-4,1,10:17.12
-3,1,10:17.12
-7,2,10:17.12
-6,2,10:17.12
-5,2,10:17.12
-18,4,10:18.4
-17,4,10:18.4
-16,4,10:18.4
-15,4,10:18.12
0,-4,11:17.12
1,-4,11:17.12
2,-4,11:17.12
-1,-3,11:17.12
0,-3,11:17.12
2,-3,11:17.12
3,-3,11:17.12
-3,-2,11:17.12
-2,-2,11:17.12
-1,-2,11:17.12
1,-2,11:17.12
2,-2,11:17.12
3,-2,11:17.12
-5,-1,11:17.12
-4,-1,11:17.12
-3,-1,11:17.12
-2,-1,11:17.12
-1,-1,11:17.12
0,-1,11:17.12
1,-1,11:17.12
-8,0,11:17.12
-7,0,11:17.12
-6,0,11:17.12
-5,0,11:17.12
-4,0,11:17.12
-3,0,11:17.12
-9,1,11:17.12
-8,1,11:17.12
-6,1,11:17.12
-5,1,11:17.12
-8,2,11:17.12
-7,2,11:17.12
-6,2,11:17.12
-22,4,11:18.4
-20,4,11:18.4
-19,4,11:18.4
-18,4,11:18.4
-17,4,11:18.4
-16,4,11:18.12
-15,4,11:18.12
1,-4,12:17.12
2,-4,12:17.12
3,-4,12:17.12
0,-3,12:17.12
1,-3,12:17.12
3,-3,12:17.12
4,-3,12:17.12
-2,-2,12:17.12
-1,-2,12:17.12
0,-2,12:17.12
1,-2,12:17.12
2,-2,12:17.12
3,-2,12:17.12
4,-2,12:17.12
-3,-1,12:17.12
-2,-1,12:17.12
-1,-1,12:17.12
-14,0,12:18.12
-8,0,12:17.12
-7,0,12:17.12
-6,0,12:17.12
-5,0,12:17.12
-4,0,12:17.12
-14,1,12:18.12
-10,1,12:17.12
-9,1,12:17.12
-8,1,12:17.12
-6,1,12:17.12
-14,2,12:18.12
-13,2,12:18.12
-10,2,12:17.12
-9,2,12:17.12
-8,2,12:17.12
-7,2,12:17.12
-14,3,12:18.12
-13,3,12:18.12
-9,3,12:17.12
-22,4,12:18.4
-20,4,12:18.4
-19,4,12:18.4
-17,4,12:18.12
-16,4,12:18.12
-15,4,12:18.12
-13,4,12:18.12
-12,4,12:18.12
-12,5,12:18.12
-12,6,12:18.12
-13,8,12:18.12
-13,9,12:18.4
-14,10,12:18.4
-14,11,12:18.4
3,-5,13:18.12
2,-4,13:17.12
3,-4,13:17.12
4,-4,13:17.12
-5,-3,13:18.12
1,-3,13:17.12
2,-3,13:17.12
4,-3,13:17.12
-6,-2,13:18.12
-1,-2,13:17.12
0,-2,13:17.12
1,-2,13:17.12
2,-2,13:17.12
3,-2,13:17.12
4,-2,13:17.12
-7,-1,13:18.12
-14,0,13:18.12
-11,1,13:18.12
-10,1,13:17.12
-9,1,13:17.12
-8,1,13:17.12
-7,1,13:17.12
-6,1,13:17.12
-11,2,13:17.12
-10,2,13:17.12
-9,2,13:17.12
-8,2,13:17.12
-7,2,13:17.12
-21,3,13:18.4
-14,3,13:18.12
-11,3,13:18.12
-10,3,13:17.12
-9,3,13:17.12
-19,4,13:18.4
-18,4,13:18.12
-17,4,13:18.12
-16,4,13:18.12
-15,4,13:18.12
-14,4,13:18.12
-13,4,13:18.12
-11,4,13:18.12
-14,5,13:18.12
-13,5,13:18.12
-12,5,13:18.12
-11,5,13:18.12
-14,6,13:18.12
-13,6,13:18.12
-12,6,13:18.12
-14,7,13:18.12
-13,7,13:18.12
-12,7,13:18.12
-14,8,13:18.12
-13,8,13:18.12
-12,8,13:18.12
-11,8,13:18.12
-14,9,13:18.4
-13,9,13:18.4
-12,9,13:18.4
-11,9,13:18.4
-14,10,13:18.4
-13,10,13:18.4
-12,10,13:18.4
-11,10,13:18.4
-14,11,13:18.4
-13,11,13:18.4
-12,11,13:18.4
-14,12,13:18.4
-13,12,13:18.4
-12,12,13:18.4
-14,13,13:18.4
-13,13,13:18.4
-14,14,13:18.4
-13,14,13:18.4
-14,15,13:18.4
5,-16,14:18.4
5,-15,14:18.4
5,-14,14:18.4
5,-13,14:18.4
4,-12,14:18.4
4,-11,14:18.4
4,-10,14:18.12
4,-9,14:18.12
4,-8,14:18.12
4,-7,14:18.12
3,-6,14:18.12
4,-6,14:18.12
4,-5,14:18.12
3,-4,14:17.12
4,-4,14:17.12
-5,-3,14:18.12
1,-3,14:17.12
2,-3,14:17.12
3,-3,14:17.12
4,-3,14:17.12
5,-3,14:17.12
-6,-2,14:18.12
1,-2,14:17.12
2,-2,14:17.12
-7,-1,14:18.12
-6,-1,14:18.12
-14,0,14:18.12
-13,0,14:18.12
-8,0,14:18.12
-7,0,14:18.12
-13,1,14:18.12
-12,1,14:18.12
-11,1,14:18.12
-8,1,14:18.12
-22,2,14:18.4
-12,2,14:18.12
-11,2,14:17.12
-10,2,14:17.12
-9,2,14:17.12
-8,2,14:17.12
-22,3,14:18.4
-21,3,14:18.4
-20,3,14:18.4
-11,3,14:17.12
-10,3,14:17.12
-9,3,14:17.12
-22,4,14:18.4
-20,4,14:18.4
-19,4,14:18.4
-18,4,14:18.12
-17,4,14:18.12
-16,4,14:18.12
-15,4,14:18.12
-11,4,14:18.12
-21,5,14:18.4
-12,5,14:18.12
-21,6,14:18.4
-20,6,14:18.4
-14,6,14:18.12
-12,6,14:18.12
-20,7,14:18.4
-19,7,14:18.4
-14,7,14:18.12
-13,7,14:18.12
-19,8,14:18.4
-14,8,14:18.12
-13,8,14:18.12
-19,9,14:18.4
-18,9,14:18.4
-14,9,14:18.4
-13,9,14:18.4
-19,10,14:18.4
-18,10,14:18.4
-14,10,14:18.4
-13,10,14:18.4
-18,11,14:18.4
-17,11,14:18.4
-14,11,14:18.4
-17,12,14:18.4
-16,12,14:18.4
-15,12,14:18.4
-16,13,14:18.4
-15,13,14:18.4
5,-19,15:18.4
5,-18,15:18.4
5,-17,15:18.4
5,-16,15:18.4
5,-15,15:18.4
5,-14,15:18.4
4,-12,15:18.4
4,-11,15:18.4
4,-10,15:18.12
4,-9,15:18.12
4,-8,15:18.12
-13,-7,15:18.4
-12,-7,15:18.4
-11,-7,15:18.4
-10,-7,15:18.4
4,-7,15:18.12
-15,-6,15:18.12
-14,-6,15:18.4
-10,-6,15:18.4
4,-6,15:18.12
-16,-5,15:18.12
-8,-5,15:18.12
4,-5,15:17.12
-18,-4,15:18.12
-17,-4,15:18.12
-16,-4,15:18.12
-15,-4,15:18.12
-7,-4,15:18.12
2,-4,15:17.12
3,-4,15:17.12
4,-4,15:17.12
5,-4,15:17.12
-18,-3,15:18.12
-17,-3,15:18.12
-16,-3,15:18.12
-15,-3,15:18.12
-6,-3,15:18.12
-5,-3,15:18.12
2,-3,15:17.12
3,-3,15:17.12
4,-3,15:17.12
5,-3,15:17.12
-19,-2,15:18.12
-18,-2,15:18.12
-17,-2,15:18.12
-16,-2,15:18.12
-15,-2,15:18.12
-12,-2,15:18.12
-6,-2,15:18.12
-5,-2,15:18.12
-4,-2,15:18.12
-20,-1,15:18.4
-19,-1,15:18.4
-18,-1,15:18.4
-17,-1,15:18.4
-16,-1,15:18.12
-15,-1,15:18.12
-12,-1,15:18.12
-7,-1,15:18.12
-6,-1,15:18.12
-4,-1,15:18.12
-3,-1,15:18.12
-20,0,15:18.4
-19,0,15:18.4
-17,0,15:18.12
-16,0,15:18.12
-15,0,15:18.12
-14,0,15:18.12
-12,0,15:18.12
-8,0,15:18.12
-7,0,15:18.12
-21,1,15:18.4
-20,1,15:18.4
-19,1,15:18.4
-18,1,15:18.12
-17,1,15:18.12
-16,1,15:18.12
-15,1,15:18.12
-14,1,15:18.12
-13,1,15:18.12
-9,1,15:18.12
-8,1,15:18.12
-21,2,15:18.4
-20,2,15:18.4
-19,2,15:18.4
-18,2,15:18.12
-17,2,15:18.12
-16,2,15:18.12
-15,2,15:18.12
-13,2,15:18.12
-12,2,15:18.12
-11,2,15:17.12
-10,2,15:18.12
-9,2,15:18.12
-2,2,15:18.12
-22,3,15:18.4
-21,3,15:18.4
-20,3,15:18.4
-19,3,15:18.4
-18,3,15:18.12
-17,3,15:18.12
-16,3,15:18.12
-15,3,15:18.12
-12,3,15:17.12
-11,3,15:17.12
-10,3,15:17.12
-2,3,15:18.12
-20,4,15:18.4
-19,4,15:18.4
-18,4,15:18.12
-17,4,15:18.12
-16,4,15:18.12
-15,4,15:18.12
-12,4,15:18.12
-11,4,15:17.12
-2,4,15:18.12
-21,5,15:18.4
-20,5,15:18.4
-19,5,15:18.4
-18,5,15:18.12
-17,5,15:18.12
-16,5,15:18.12
-15,5,15:18.12
-12,5,15:18.12
-2,5,15:18.12
-20,6,15:18.4
-19,6,15:18.4
-18,6,15:18.12
-17,6,15:18.12
-16,6,15:18.12
-15,6,15:18.12
-13,6,15:18.12
-20,7,15:18.4
-19,7,15:18.4
-18,7,15:18.12
-17,7,15:18.12
-16,7,15:18.12
-15,7,15:18.12
-13,7,15:18.12
-10,7,15:18.12
-9,7,15:18.12
-2,7,15:18.4
-19,8,15:18.4
-18,8,15:18.12
-17,8,15:18.12
-16,8,15:18.12
-15,8,15:18.12
-14,8,15:18.12
-9,8,15:18.12
-8,8,15:18.12
-2,8,15:18.4
-18,9,15:18.4
-17,9,15:18.4
-16,9,15:18.4
-15,9,15:18.4
-14,9,15:18.4
-18,10,15:18.4
-17,10,15:18.4
-16,10,15:18.4
-15,10,15:18.4
-17,11,15:18.4
-16,11,15:18.4
-15,11,15:18.4
-17,12,15:18.4
-16,12,15:18.4
-15,12,15:18.4
-4,12,15:18.12
-8,13,15:18.4
-7,13,15:18.4
-12,14,15:18.4
-11,14,15:18.4
-10,14,15:18.4
-9,14,15:18.4
-14,15,15:18.4
-13,15,15:18.4
6,-23,16:18.4
5,-19,16:18.4
5,-16,16:18.4
5,-15,16:18.4
5,-14,16:18.4
4,-13,16:18.4
5,-13,16:18.4
4,-12,16:18.4
4,-11,16:18.4
4,-10,16:18.12
4,-9,16:18.12
4,-8,16:18.12
-12,-7,16:18.4
-11,-7,16:18.4
5,-7,16:18.12
-14,-6,16:18.4
-13,-6,16:18.4
-12,-6,16:18.4
-11,-6,16:18.4
-10,-6,16:18.4
4,-6,16:18.12
5,-6,16:18.12
-14,-5,16:18.4
-13,-5,16:18.4
-12,-5,16:18.4
-11,-5,16:18.4
-10,-5,16:18.4
-9,-5,16:18.4
-8,-5,16:18.4
4,-5,16:17.12
5,-5,16:17.12
-16,-4,16:18.12
-15,-4,16:18.12
-14,-4,16:18.4
-13,-4,16:18.4
-12,-4,16:18.12
-11,-4,16:18.12
-10,-4,16:18.12
-9,-4,16:18.12
-8,-4,16:18.12
-7,-4,16:18.12
3,-4,16:17.12
4,-4,16:17.12
5,-4,16:17.12
-16,-3,16:18.12
-15,-3,16:18.12
-14,-3,16:18.12
-12,-3,16:18.12
-10,-3,16:18.12
-9,-3,16:18.12
-8,-3,16:18.12
-7,-3,16:18.12
-6,-3,16:18.12
-17,-2,16:18.12
-16,-2,16:18.12
-15,-2,16:18.12
-12,-2,16:18.12
-9,-2,16:18.12
-8,-2,16:18.12
-7,-2,16:18.12
-6,-2,16:18.12
-5,-2,16:18.12
-17,-1,16:18.4
-16,-1,16:18.12
-15,-1,16:18.12
-12,-1,16:18.12
-8,-1,16:18.12
-7,-1,16:18.12
-6,-1,16:18.12
-5,-1,16:18.12
-4,-1,16:18.12
-17,0,16:18.12
-16,0,16:18.12
-15,0,16:18.12
-12,0,16:18.12
-8,0,16:18.12
-7,0,16:18.12
-6,0,16:18.12
-5,0,16:18.12
-4,0,16:18.12
-18,1,16:18.12
-17,1,16:18.12
-16,1,16:18.12
-15,1,16:18.12
-12,1,16:18.12
-9,1,16:18.12
-7,1,16:18.12
-6,1,16:18.12
-5,1,16:18.12
-4,1,16:18.12
-3,1,16:18.12
-18,2,16:18.12
-17,2,16:18.12
-16,2,16:18.12
-14,2,16:18.12
-13,2,16:18.12
-10,2,16:18.12
-7,2,16:18.12
-6,2,16:18.12
-5,2,16:18.12
-4,2,16:18.12
-3,2,16:18.12
-19,3,16:18.4
-18,3,16:18.12
-17,3,16:18.12
-16,3,16:18.12
-13,3,16:18.12
-12,3,16:17.12
-11,3,16:17.12
-10,3,16:18.12
-6,3,16:18.12
-5,3,16:18.12
-4,3,16:18.12
-3,3,16:18.12
-19,4,16:18.4
-18,4,16:18.12
-17,4,16:18.12
-16,4,16:18.12
-15,4,16:18.12
-13,4,16:17.12
-12,4,16:17.12
-6,4,16:18.12
-5,4,16:18.12
-4,4,16:18.12
-3,4,16:18.12
-18,5,16:18.12
-17,5,16:18.12
-16,5,16:18.12
-13,5,16:18.12
-12,5,16:18.12
-6,5,16:18.12
-5,5,16:18.12
-4,5,16:18.12
-3,5,16:18.12
-18,6,16:18.12
-17,6,16:18.12
-16,6,16:18.12
-15,6,16:18.12
-13,6,16:18.12
-11,6,16:18.12
-10,6,16:18.12
-6,6,16:18.12
-5,6,16:18.12
-4,6,16:18.12
-3,6,16:18.12
-17,7,16:18.12
-16,7,16:18.12
-15,7,16:18.12
-14,7,16:18.12
-10,7,16:18.12
-9,7,16:18.12
-5,7,16:18.12
-4,7,16:18.4
-3,7,16:18.4
-16,8,16:18.12
-15,8,16:18.12
-14,8,16:18.12
-9,8,16:18.12
-8,8,16:18.12
-5,8,16:18.4
-4,8,16:18.4
-3,8,16:18.4
-16,9,16:18.4
-15,9,16:18.4
-14,9,16:18.4
-7,9,16:18.4
-5,9,16:18.4
-4,9,16:18.4
-3,9,16:18.4
-15,10,16:18.4
-6,10,16:18.4
-5,10,16:18.4
-4,10,16:18.4
-3,10,16:18.4
-14,11,16:18.4
-13,11,16:18.4
-12,11,16:18.4
-11,11,16:18.4
-10,11,16:18.4
-9,11,16:18.4
-8,11,16:18.4
-7,11,16:18.4
-5,11,16:18.4
-4,11,16:18.4
-3,11,16:18.4
-14,12,16:18.4
-13,12,16:18.4
-12,12,16:18.4
-11,12,16:18.4
-10,12,16:18.4
-9,12,16:18.4
-8,12,16:18.4
-7,12,16:18.4
-6,12,16:18.4
-5,12,16:18.12
-4,12,16:18.12
-3,12,16:18.12
-14,13,16:18.4
-13,13,16:18.4
-12,13,16:18.4
-11,13,16:18.4
-10,13,16:18.4
-9,13,16:18.4
-8,13,16:18.4
-7,13,16:18.4
-6,13,16:18.12
-5,13,16:18.12
-14,14,16:18.4
-13,14,16:18.4
-12,14,16:18.4
-11,14,16:18.4
-10,14,16:18.4
-9,14,16:18.4
-6,14,16:18.12
-14,15,16:18.4
-13,15,16:18.4
6,-23,17:18.4
6,-22,17:18.4
6,-21,17:18.4
6,-20,17:18.4
5,-18,17:18.4
5,-17,17:18.4
5,-16,17:18.4
5,-15,17:18.4
5,-14,17:18.4
4,-12,17:18.4
4,-11,17:18.4
5,-11,17:18.4
5,-10,17:18.12
5,-9,17:18.12
5,-8,17:18.12
5,-7,17:18.12
5,-6,17:17.12
-13,-5,17:18.4
-12,-5,17:18.4
-11,-5,17:18.4
4,-5,17:17.12
5,-5,17:17.12
6,-5,17:17.12
-14,-4,17:18.4
-13,-4,17:18.4
-12,-4,17:18.4
-11,-4,17:18.4
-10,-4,17:18.4
3,-4,17:18.12
4,-4,17:17.12
5,-4,17:17.12
6,-4,17:18.12
7,-4,17:18.12
-14,-3,17:18.12
-13,-3,17:18.12
-12,-3,17:18.12
-11,-3,17:18.12
-10,-3,17:18.12
-9,-3,17:18.12
-14,-2,17:18.12
-13,-2,17:18.12
-12,-2,17:18.12
-11,-2,17:18.12
-9,-2,17:18.12
-8,-2,17:18.12
-14,-1,17:18.12
-13,-1,17:18.12
-12,-1,17:18.12
-11,-1,17:18.12
-10,-1,17:18.12
-9,-1,17:18.12
-8,-1,17:18.12
-7,-1,17:18.12
13,-1,17:18.4
14,-1,17:18.4
15,-1,17:18.4
-15,0,17:18.12
-14,0,17:18.12
-13,0,17:18.12
-12,0,17:18.12
-11,0,17:18.12
-10,0,17:18.12
-9,0,17:18.12
-8,0,17:18.12
-7,0,17:18.12
-6,0,17:18.12
15,0,17:18.4
16,0,17:18.4
17,0,17:18.4
-15,1,17:18.12
-14,1,17:18.12
-13,1,17:18.12
-12,1,17:18.12
-11,1,17:18.12
-10,1,17:18.12
-9,1,17:18.12
-8,1,17:18.12
-7,1,17:18.12
-6,1,17:18.12
-5,1,17:18.12
18,1,17:18.4
19,1,17:18.4
20,1,17:18.4
-16,2,17:18.12
-15,2,17:18.12
-14,2,17:18.12
-13,2,17:18.12
-12,2,17:18.12
-11,2,17:18.12
-10,2,17:18.12
-9,2,17:18.12
-8,2,17:18.12
-7,2,17:18.12
-6,2,17:18.12
-5,2,17:18.12
21,2,17:18.4
-19,3,17:18.4
-16,3,17:18.12
-15,3,17:18.12
-14,3,17:18.12
-13,3,17:18.12
-12,3,17:17.12
-11,3,17:18.12
-10,3,17:18.12
-9,3,17:18.12
-8,3,17:18.12
-7,3,17:18.12
-6,3,17:18.12
-5,3,17:18.12
-18,4,17:18.12
-17,4,17:18.12
-16,4,17:18.12
-15,4,17:18.12
-14,4,17:17.12
-13,4,17:17.12
-12,4,17:17.12
-11,4,17:18.12
-10,4,17:18.12
-8,4,17:18.12
-7,4,17:18.12
-6,4,17:18.12
-5,4,17:18.12
-16,5,17:18.12
-15,5,17:18.12
-14,5,17:18.12
-13,5,17:18.12
-12,5,17:18.12
-11,5,17:18.12
-10,5,17:18.12
-9,5,17:18.12
-8,5,17:18.12
-7,5,17:18.12
-6,5,17:18.12
-5,5,17:18.12
-15,6,17:18.12
-14,6,17:18.12
-13,6,17:18.12
-12,6,17:18.12
-11,6,17:18.12
-10,6,17:18.12
-9,6,17:18.12
-8,6,17:18.12
-7,6,17:18.12
-6,6,17:18.12
-5,6,17:18.12
-15,7,17:18.12
-14,7,17:18.12
-13,7,17:18.12
-12,7,17:18.12
-11,7,17:18.12
-10,7,17:18.12
-9,7,17:18.12
-8,7,17:18.12
-7,7,17:18.12
-6,7,17:18.12
-5,7,17:18.12
-14,8,17:18.12
-13,8,17:18.12
-12,8,17:18.12
-11,8,17:18.12
-10,8,17:18.12
-9,8,17:18.12
-8,8,17:18.12
-7,8,17:18.12
-6,8,17:18.4
-5,8,17:18.4
-15,9,17:18.4
-14,9,17:18.4
-13,9,17:18.4
-12,9,17:18.4
-11,9,17:18.4
-10,9,17:18.4
-9,9,17:18.4
-8,9,17:18.4
-7,9,17:18.4
-6,9,17:18.4
-5,9,17:18.4
-14,10,17:18.4
-13,10,17:18.4
-12,10,17:18.4
-11,10,17:18.4
-10,10,17:18.4
-9,10,17:18.4
-8,10,17:18.4
-7,10,17:18.4
-6,10,17:18.4
-5,10,17:18.4
-14,11,17:18.4
-13,11,17:18.4
-12,11,17:18.4
-11,11,17:18.4
-10,11,17:18.4
-9,11,17:18.4
-8,11,17:18.4
-7,11,17:18.4
-5,11,17:18.4
-4,11,17:18.4
-14,12,17:18.4
-13,12,17:18.4
-12,12,17:18.4
-11,12,17:18.4
-10,12,17:18.4
-9,12,17:18.4
6,-23,18:18.4
6,-22,18:18.4
6,-21,18:18.4
6,-20,18:18.4
5,-19,18:18.4
5,-18,18:18.4
5,-17,18:18.4
5,-16,18:18.4
5,-15,18:18.4
5,-13,18:18.4
5,-12,18:18.4
5,-11,18:18.4
5,-10,18:18.12
5,-9,18:18.12
5,-7,18:18.12
5,-6,18:17.12
4,-5,18:17.12
5,-5,18:17.12
6,-5,18:17.12
-11,-4,18:18.4
2,-4,18:18.12
3,-4,18:18.12
4,-4,18:17.12
5,-4,18:17.12
6,-4,18:18.12
7,-4,18:18.12
-12,-3,18:18.4
1,-3,18:18.12
2,-3,18:18.12
8,-3,18:18.12
9,-3,18:18.12
10,-3,18:18.12
-13,-2,18:18.12
-12,-2,18:18.12
-11,-2,18:18.12
10,-2,18:18.12
11,-2,18:18.4
12,-2,18:18.4
-14,-1,18:18.12
-13,-1,18:18.12
-12,-1,18:18.12
-11,-1,18:18.12
-10,-1,18:18.12
-2,-1,18:18.12
13,-1,18:18.4
14,-1,18:18.4
-14,0,18:18.12
-13,0,18:18.12
-12,0,18:18.12
-11,0,18:18.12
-10,0,18:18.12
-9,0,18:18.12
15,0,18:18.4
16,0,18:18.4
17,0,18:18.4
-14,1,18:18.12
-13,1,18:18.12
-12,1,18:18.12
-11,1,18:18.12
-10,1,18:18.12
-9,1,18:18.12
18,1,18:18.4
20,1,18:18.4
-11,2,18:18.12
-10,2,18:18.12
-9,2,18:18.12
-8,2,18:18.12
22,2,18:18.4
-14,3,18:18.12
-13,3,18:18.12
-12,3,18:18.12
-10,3,18:18.12
-9,3,18:18.12
-8,3,18:18.12
23,3,18:18.4
24,3,18:18.4
-18,4,18:18.12
-17,4,18:18.12
-16,4,18:18.12
-15,4,18:18.12
-13,4,18:17.12
-12,4,18:18.12
-10,4,18:18.12
-8,4,18:18.12
-14,5,18:18.12
-13,5,18:18.12
-12,5,18:18.12
-11,5,18:18.12
-10,5,18:18.12
-9,5,18:18.12
-8,5,18:18.12
-7,5,18:18.12
-13,6,18:18.12
-12,6,18:18.12
-11,6,18:18.12
-10,6,18:18.12
-9,6,18:18.12
-8,6,18:18.12
-7,6,18:18.12
-14,7,18:18.12
-13,7,18:18.12
-12,7,18:18.12
-11,7,18:18.12
-10,7,18:18.12
-9,7,18:18.12
-8,7,18:18.12
-7,7,18:18.12
-14,8,18:18.12
-13,8,18:18.12
-12,8,18:18.12
-11,8,18:18.12
-10,8,18:18.12
-9,8,18:18.12
-8,8,18:18.12
-7,8,18:18.12
-15,9,18:18.4
-14,9,18:18.4
-13,9,18:18.4
-12,9,18:18.4
-11,9,18:18.4
-10,9,18:18.4
-9,9,18:18.4
-8,9,18:18.4
-7,9,18:18.4
-6,9,18:18.4
-16,10,18:18.4
-15,10,18:18.4
-14,10,18:18.4
-13,10,18:18.4
-6,10,18:18.4
5,-18,19:18.4
5,-17,19:18.4
5,-16,19:18.4
5,-15,19:18.4
5,-14,19:18.4
5,-13,19:18.4
5,-12,19:18.4
5,-11,19:18.12
5,-10,19:18.12
5,-8,19:18.12
5,-7,19:18.12
5,-6,19:17.12
6,-6,19:17.12
4,-5,19:17.12
5,-5,19:17.12
6,-5,19:17.12
3,-4,19:18.12
4,-4,19:18.12
5,-4,19:17.12
6,-4,19:18.12
7,-4,19:18.12
-12,-3,19:18.4
1,-3,19:18.12
2,-3,19:18.12
9,-3,19:18.12
10,-3,19:18.12
-12,-2,19:18.12
-1,-2,19:18.12
0,-2,19:18.12
11,-2,19:18.12
12,-2,19:18.4
-12,-1,19:18.12
-2,-1,19:18.12
-1,-1,19:18.12
13,-1,19:18.4
14,-1,19:18.4
15,-1,19:18.4
-12,0,19:18.12
-4,0,19:18.4
15,0,19:18.4
16,0,19:18.4
17,0,19:18.4
-14,1,19:18.12
-13,1,19:18.12
-12,1,19:18.12
-5,1,19:18.4
18,1,19:18.4
19,1,19:18.4
20,1,19:18.4
-14,2,19:18.12
-13,2,19:18.12
-12,2,19:18.12
-11,2,19:18.12
21,2,19:18.4
22,2,19:18.4
-14,3,19:18.12
-13,3,19:18.12
-12,3,19:18.12
-11,3,19:18.12
-10,3,19:18.12
23,3,19:18.4
24,3,19:18.4
-16,4,19:18.12
-15,4,19:18.12
-13,4,19:17.12
-12,4,19:18.12
-11,4,19:18.12
-10,4,19:18.12
-14,5,19:18.12
-13,5,19:18.12
-12,5,19:18.12
-11,5,19:18.12
-10,5,19:18.12
-14,6,19:18.12
-13,6,19:18.12
-12,6,19:18.12
-11,6,19:18.12
-10,6,19:18.12
-14,7,19:18.12
-13,7,19:18.12
-12,7,19:18.12
-11,7,19:18.12
-10,7,19:18.12
-9,7,19:18.12
-8,8,19:18.12
-15,9,19:18.4
-14,9,19:18.4
-7,9,19:18.4
8,12,19:18.12
9,12,19:18.12
10,12,19:18.12
11,12,19:18.12
12,12,19:18.12
9,13,19:18.12
10,13,19:18.12
6,-22,20:18.4
6,-21,20:18.4
6,-20,20:18.4
5,-19,20:18.4
5,-18,20:18.4
5,-17,20:18.4
6,-17,20:18.4
5,-16,20:18.4
6,-16,20:18.4
6,-15,20:18.4
6,-14,20:18.4
6,-13,20:18.4
6,-12,20:18.4
6,-11,20:18.12
6,-10,20:18.12
6,-8,20:18.12
6,-7,20:18.12
5,-6,20:17.12
6,-6,20:17.12
4,-5,20:18.12
5,-5,20:17.12
6,-5,20:17.12
3,-4,20:18.12
4,-4,20:18.12
7,-4,20:18.12
8,-4,20:18.12
9,-4,20:18.12
-16,-3,20:18.12
1,-3,20:18.12
2,-3,20:18.12
9,-3,20:18.12
10,-3,20:18.12
11,-3,20:18.12
-14,-2,20:18.4
-1,-2,20:18.12
0,-2,20:18.12
11,-2,20:18.12
12,-2,20:18.4
13,-2,20:18.4
-12,-1,20:18.12
-2,-1,20:18.4
-1,-1,20:18.12
13,-1,20:18.4
14,-1,20:18.4
-12,0,20:18.12
-4,0,20:18.4
16,0,20:18.4
17,0,20:18.4
-12,1,20:18.12
-5,1,20:18.4
18,1,20:18.4
19,1,20:18.4
20,1,20:18.4
-13,2,20:18.12
-12,2,20:18.12
-7,2,20:18.12
-6,2,20:18.4
-13,3,20:18.12
24,3,20:18.4
-16,4,20:18.12
-15,4,20:18.12
-13,4,20:18.12
-12,5,20:18.12
-11,5,20:18.12
-11,6,20:18.12
-10,6,20:18.12
-10,7,20:18.12
-9,7,20:18.12
-8,8,20:18.12
-16,9,20:18.4
-15,9,20:18.4
-14,9,20:18.4
-16,10,20:18.4
-15,10,20:18.4
-7,11,20:18.4
-6,12,20:18.4
-4,13,20:18.12
-3,13,20:18.12
-3,14,20:18.12
10,14,20:18.12
6,-24,21:18.4
2,-23,21:18.4
3,-23,21:18.4
4,-23,21:18.4
5,-23,21:18.4
6,-23,21:18.4
11,-23,21:18.4
-2,-22,21:18.4
-1,-22,21:18.4
6,-22,21:18.4
12,-22,21:18.4
13,-22,21:18.4
-3,-21,21:18.4
6,-21,21:18.4
13,-21,21:18.4
14,-21,21:18.4
15,-21,21:18.4
-8,-20,21:18.4
6,-20,21:18.4
15,-20,21:18.4
16,-20,21:18.4
17,-20,21:18.4
-9,-19,21:18.4
6,-19,21:18.4
16,-19,21:18.4
17,-19,21:18.4
18,-19,21:18.4
6,-18,21:18.4
18,-18,21:18.4
19,-18,21:18.4
22,-18,21:18.12
-10,-17,21:18.4
6,-17,21:18.4
19,-17,21:18.4
20,-17,21:18.4
21,-17,21:18.4
22,-17,21:18.12
6,-16,21:18.4
22,-16,21:18.12
-11,-15,21:18.4
6,-15,21:18.4
23,-15,21:18.12
-12,-14,21:18.4
-3,-14,21:18.4
6,-14,21:18.4
-12,-13,21:18.4
-2,-13,21:18.4
6,-13,21:18.4
25,-13,21:18.4
-13,-12,21:18.4
-1,-12,21:18.4
6,-12,21:18.4
-14,-11,21:18.4
-13,-11,21:18.4
6,-11,21:18.12
25,-11,21:18.4
6,-10,21:18.12
15,-10,21:18.4
25,-10,21:18.4
6,-9,21:18.12
13,-9,21:18.4
14,-9,21:18.4
25,-9,21:18.4
26,-9,21:18.4
6,-8,21:18.12
12,-8,21:18.4
26,-8,21:18.4
6,-7,21:18.12
26,-7,21:18.4
5,-6,21:17.12
6,-6,21:17.12
26,-6,21:18.4
-14,-5,21:18.4
4,-5,21:18.12
5,-5,21:17.12
6,-5,21:17.12
7,-5,21:18.12
26,-5,21:18.4
-14,-4,21:18.4
2,-4,21:18.12
3,-4,21:18.12
4,-4,21:18.12
7,-4,21:18.12
8,-4,21:18.12
26,-4,21:18.4
-14,-3,21:18.4
1,-3,21:18.12
10,-3,21:18.12
11,-3,21:18.12
26,-3,21:18.4
-14,-2,21:18.4
-1,-2,21:18.4
0,-2,21:18.12
12,-2,21:18.4
13,-2,21:18.4
26,-2,21:18.4
-14,-1,21:18.12
-13,-1,21:18.12
-2,-1,21:18.4
14,-1,21:18.4
15,-1,21:18.4
-4,0,21:18.4
16,0,21:18.4
17,0,21:18.4
18,0,21:18.4
26,0,21:18.4
-13,1,21:18.12
-5,1,21:18.4
-4,1,21:18.4
11,1,21:18.4
18,1,21:18.4
19,1,21:18.4
20,1,21:18.4
25,1,21:18.4
26,1,21:18.4
-13,2,21:18.12
-7,2,21:18.4
-6,2,21:18.4
12,2,21:18.4
21,2,21:18.4
22,2,21:18.4
25,2,21:18.4
26,2,21:18.4
-13,3,21:18.12
-9,3,21:18.12
-8,3,21:18.12
13,3,21:18.4
23,3,21:18.4
24,3,21:18.4
25,3,21:18.4
-13,4,21:18.12
14,4,21:18.4
24,4,21:18.4
25,4,21:18.4
-12,5,21:18.12
23,5,21:18.4
24,5,21:18.4
-12,6,21:18.12
-10,6,21:18.12
23,6,21:18.4
-12,7,21:18.12
-10,7,21:18.12
22,7,21:18.4
23,7,21:18.4
-12,8,21:18.12
-11,8,21:18.12
22,8,21:18.4
-10,9,21:18.4
-9,9,21:18.4
-8,10,21:18.4
-7,10,21:18.4
21,10,21:18.4
-7,11,21:18.4
-5,11,21:18.4
20,11,21:18.4
21,11,21:18.4
-5,12,21:18.12
-4,12,21:18.12
18,12,21:18.4
19,12,21:18.4
20,12,21:18.4
-4,13,21:18.12
-3,13,21:18.12
-2,13,21:18.12
14,13,21:18.4
15,13,21:18.4
16,13,21:18.4
-2,14,21:18.12
-1,14,21:18.12
0,14,21:18.12
10,14,21:18.12
11,14,21:18.12
13,14,21:18.4
14,14,21:18.4
-2,15,21:18.12
-1,15,21:18.12
3,-23,22:18.4
4,-23,22:18.4
5,-23,22:18.4
6,-23,22:18.4
7,-23,22:18.4
8,-23,22:18.4
9,-23,22:18.4
10,-23,22:18.4
-1,-22,22:18.4
0,-22,22:18.4
1,-22,22:18.4
2,-22,22:18.4
3,-22,22:18.4
4,-22,22:18.4
5,-22,22:18.4
6,-22,22:18.4
7,-22,22:18.4
8,-22,22:18.4
9,-22,22:18.4
10,-22,22:18.4
11,-22,22:18.4
12,-22,22:18.4
-4,-21,22:18.4
-3,-21,22:18.4
-2,-21,22:18.4
-1,-21,22:18.4
0,-21,22:18.4
1,-21,22:18.4
4,-21,22:18.4
5,-21,22:18.4
6,-21,22:18.4
7,-21,22:18.4
8,-21,22:18.4
9,-21,22:18.4
10,-21,22:18.4
11,-21,22:18.4
12,-21,22:18.4
13,-21,22:18.4
14,-21,22:18.4
-8,-20,22:18.4
-7,-20,22:18.4
-6,-20,22:18.4
-5,-20,22:18.4
6,-20,22:18.4
12,-20,22:18.4
13,-20,22:18.4
14,-20,22:18.4
15,-20,22:18.4
-9,-19,22:18.4
-8,-19,22:18.4
6,-19,22:18.4
15,-19,22:18.4
16,-19,22:18.4
17,-19,22:18.4
-9,-18,22:18.4
6,-18,22:18.4
17,-18,22:18.4
18,-18,22:18.4
-10,-17,22:18.4
-9,-17,22:18.4
6,-17,22:18.4
19,-17,22:18.4
20,-17,22:18.4
-10,-16,22:18.4
6,-16,22:18.4
20,-16,22:18.4
21,-16,22:18.4
22,-16,22:18.12
-11,-15,22:18.4
-10,-15,22:18.4
-4,-15,22:18.4
6,-15,22:18.4
22,-15,22:18.12
23,-15,22:18.12
-11,-14,22:18.4
-3,-14,22:18.4
6,-14,22:18.4
23,-14,22:18.12
-12,-13,22:18.4
-11,-13,22:18.4
-2,-13,22:18.4
6,-13,22:18.4
24,-13,22:18.4
-12,-12,22:18.4
-1,-12,22:18.4
6,-12,22:18.4
24,-12,22:18.4
-13,-11,22:18.4
-12,-11,22:18.4
0,-11,22:18.4
6,-11,22:18.12
17,-11,22:18.4
18,-11,22:18.4
24,-11,22:18.4
25,-11,22:18.4
-13,-10,22:18.4
1,-10,22:18.12
6,-10,22:18.12
15,-10,22:18.4
16,-10,22:18.4
25,-10,22:18.4
-14,-9,22:18.4
-13,-9,22:18.4
-12,-9,22:18.4
6,-9,22:18.12
13,-9,22:18.4
14,-9,22:18.4
15,-9,22:18.4
25,-9,22:18.4
-13,-8,22:18.4
-12,-8,22:18.4
6,-8,22:18.12
11,-8,22:18.12
12,-8,22:18.4
13,-8,22:18.4
25,-8,22:18.4
-14,-7,22:18.4
-13,-7,22:18.4
-12,-7,22:18.4
6,-7,22:18.12
10,-7,22:18.12
11,-7,22:18.12
25,-7,22:18.4
26,-7,22:18.4
-14,-6,22:18.4
-13,-6,22:18.4
-12,-6,22:18.4
5,-6,22:17.12
6,-6,22:17.12
25,-6,22:18.4
26,-6,22:18.4
-14,-5,22:18.4
-13,-5,22:18.4
4,-5,22:18.12
5,-5,22:17.12
6,-5,22:17.12
7,-5,22:18.12
24,-5,22:18.4
25,-5,22:18.4
26,-5,22:18.4
-14,-4,22:18.4
-13,-4,22:18.4
4,-4,22:18.12
8,-4,22:18.12
9,-4,22:18.12
24,-4,22:18.4
25,-4,22:18.4
26,-4,22:18.4
-14,-3,22:18.4
-13,-3,22:18.4
1,-3,22:18.12
2,-3,22:18.12
11,-3,22:18.12
12,-3,22:18.4
24,-3,22:18.4
25,-3,22:18.4
26,-3,22:18.4
-13,-2,22:18.4
-1,-2,22:18.4
0,-2,22:18.12
12,-2,22:18.4
13,-2,22:18.4
14,-2,22:18.4
24,-2,22:18.4
25,-2,22:18.4
26,-2,22:18.4
-13,-1,22:18.4
-2,-1,22:18.4
-1,-1,22:18.4
14,-1,22:18.4
15,-1,22:18.4
16,-1,22:18.4
24,-1,22:18.4
25,-1,22:18.4
26,-1,22:18.4
-13,0,22:18.12
-4,0,22:18.4
10,0,22:18.4
16,0,22:18.4
17,0,22:18.4
18,0,22:18.4
24,0,22:18.4
25,0,22:18.4
26,0,22:18.4
-13,1,22:18.12
-6,1,22:18.4
-5,1,22:18.4
-4,1,22:18.4
11,1,22:18.4
18,1,22:18.4
19,1,22:18.4
20,1,22:18.4
23,1,22:18.4
24,1,22:18.4
25,1,22:18.4
-13,2,22:18.12
-12,2,22:18.12
-7,2,22:18.4
-6,2,22:18.4
12,2,22:18.4
21,2,22:18.4
22,2,22:18.4
23,2,22:18.4
24,2,22:18.4
25,2,22:18.4
-13,3,22:18.12
-12,3,22:18.12
-9,3,22:18.12
-8,3,22:18.4
13,3,22:18.4
23,3,22:18.4
24,3,22:18.4
-12,4,22:18.12
13,4,22:18.4
14,4,22:18.4
23,4,22:18.4
24,4,22:18.4
-12,5,22:18.12
14,5,22:18.4
15,5,22:18.4
23,5,22:18.4
-12,6,22:18.12
16,6,22:18.4
22,6,22:18.4
23,6,22:18.4
-12,7,22:18.12
-11,7,22:18.12
22,7,22:18.4
-11,8,22:18.12
-10,8,22:18.12
21,8,22:18.4
22,8,22:18.4
-10,9,22:18.4
-9,9,22:18.4
-8,9,22:18.4
21,9,22:18.4
-8,10,22:18.4
-7,10,22:18.4
-6,10,22:18.4
20,10,22:18.4
21,10,22:18.4
-5,11,22:18.4
-4,11,22:18.4
19,11,22:18.4
20,11,22:18.4
-4,12,22:18.12
-3,12,22:18.12
-2,12,22:18.12
-1,12,22:18.12
16,12,22:18.4
17,12,22:18.4
18,12,22:18.4
19,12,22:18.4
-2,13,22:18.12
-1,13,22:18.12
0,13,22:18.12
1,13,22:18.12
2,13,22:18.12
3,13,22:18.4
5,13,22:18.4
6,13,22:18.4
7,13,22:18.4
10,13,22:18.12
12,13,22:18.12
13,13,22:18.4
14,13,22:18.4
15,13,22:18.4
16,13,22:18.4
0,14,22:18.12
1,14,22:18.12
2,14,22:18.12
3,14,22:18.12
4,14,22:18.4
5,14,22:18.12
6,14,22:18.12
7,14,22:18.12
8,14,22:18.12
9,14,22:18.12
10,14,22:18.12
11,14,22:18.12
12,14,22:18.12
13,14,22:18.12
2,15,22:18.12
3,15,22:18.12
4,15,22:18.12
5,15,22:18.12
3,-22,23:18.4
4,-22,23:18.4
5,-22,23:18.4
7,-22,23:18.4
-3,-21,23:18.4
-2,-21,23:18.4
-1,-21,23:18.4
0,-21,23:18.4
1,-21,23:18.4
2,-21,23:18.4
3,-21,23:18.4
4,-21,23:18.4
5,-21,23:18.4
6,-21,23:18.4
7,-21,23:18.4
8,-21,23:18.4
9,-21,23:18.4
10,-21,23:18.4
11,-21,23:18.4
13,-21,23:18.4
-7,-20,23:18.4
-6,-20,23:18.4
-5,-20,23:18.4
-4,-20,23:18.4
-3,-20,23:18.4
-2,-20,23:18.4
-1,-20,23:18.4
0,-20,23:18.4
1,-20,23:18.4
2,-20,23:18.4
3,-20,23:18.4
4,-20,23:18.4
5,-20,23:18.4
6,-20,23:18.4
7,-20,23:18.4
8,-20,23:18.4
9,-20,23:18.4
10,-20,23:18.4
11,-20,23:18.4
12,-20,23:18.4
13,-20,23:18.4
14,-20,23:18.4
-8,-19,23:18.4
-7,-19,23:18.4
-6,-19,23:18.4
-5,-19,23:18.4
-4,-19,23:18.4
-3,-19,23:18.4
-2,-19,23:18.4
-1,-19,23:18.4
0,-19,23:18.4
1,-19,23:18.4
2,-19,23:18.4
3,-19,23:18.4
4,-19,23:18.4
5,-19,23:18.4
6,-19,23:18.4
7,-19,23:18.4
8,-19,23:18.4
9,-19,23:18.4
10,-19,23:18.4
11,-19,23:18.4
12,-19,23:18.4
13,-19,23:18.4
14,-19,23:18.4
15,-19,23:18.4
-9,-18,23:18.4
-8,-18,23:18.4
-6,-18,23:18.4
-5,-18,23:18.4
-4,-18,23:18.4
-3,-18,23:18.4
-2,-18,23:18.4
-1,-18,23:18.4
0,-18,23:18.4
1,-18,23:18.4
2,-18,23:18.4
3,-18,23:18.4
4,-18,23:18.4
5,-18,23:18.4
6,-18,23:18.4
7,-18,23:18.4
8,-18,23:18.4
9,-18,23:18.4
10,-18,23:18.4
11,-18,23:18.4
12,-18,23:18.4
13,-18,23:18.4
14,-18,23:18.4
15,-18,23:18.4
16,-18,23:18.4
17,-18,23:18.4
18,-18,23:18.4
-9,-17,23:18.4
-8,-17,23:18.4
-7,-17,23:18.4
-6,-17,23:18.4
-5,-17,23:18.4
-4,-17,23:18.4
-3,-17,23:18.4
-2,-17,23:18.4
-1,-17,23:18.4
0,-17,23:18.4
1,-17,23:18.4
2,-17,23:18.4
3,-17,23:18.4
5,-17,23:18.4
6,-17,23:18.4
7,-17,23:18.4
8,-17,23:18.4
9,-17,23:18.4
10,-17,23:18.4
11,-17,23:18.4
13,-17,23:18.4
14,-17,23:18.4
15,-17,23:18.4
16,-17,23:18.4
17,-17,23:18.4
18,-17,23:18.4
19,-17,23:18.4
-10,-16,23:18.4
-9,-16,23:18.4
-8,-16,23:18.4
-7,-16,23:18.4
-6,-16,23:18.4
-5,-16,23:18.4
-2,-16,23:18.4
-1,-16,23:18.4
0,-16,23:18.4
1,-16,23:18.4
2,-16,23:18.4
3,-16,23:18.4
4,-16,23:18.4
5,-16,23:18.4
6,-16,23:18.4
7,-16,23:18.4
8,-16,23:18.4
9,-16,23:18.4
10,-16,23:18.4
11,-16,23:18.4
12,-16,23:18.4
13,-16,23:18.4
14,-16,23:18.4
15,-16,23:18.4
16,-16,23:18.4
17,-16,23:18.4
18,-16,23:18.4
19,-16,23:18.4
20,-16,23:18.4
21,-16,23:18.4
-10,-15,23:18.4
-9,-15,23:18.4
-8,-15,23:18.4
-7,-15,23:18.4
-6,-15,23:18.4
-4,-15,23:18.4
0,-15,23:18.4
1,-15,23:18.4
2,-15,23:18.4
3,-15,23:18.4
4,-15,23:18.4
5,-15,23:18.4
6,-15,23:18.4
7,-15,23:18.4
8,-15,23:18.4
9,-15,23:18.4
10,-15,23:18.4
11,-15,23:18.4
12,-15,23:18.4
13,-15,23:18.4
14,-15,23:18.4
15,-15,23:18.4
16,-15,23:18.4
17,-15,23:18.4
18,-15,23:18.4
19,-15,23:18.4
20,-15,23:18.4
21,-15,23:18.4
22,-15,23:18.4
-11,-14,23:18.4
-10,-14,23:18.4
-9,-14,23:18.4
-8,-14,23:18.4
-7,-14,23:18.4
-6,-14,23:18.4
-3,-14,23:18.4
2,-14,23:18.4
3,-14,23:18.4
4,-14,23:18.4
5,-14,23:18.4
6,-14,23:18.4
7,-14,23:18.4
8,-14,23:18.4
9,-14,23:18.4
10,-14,23:18.4
11,-14,23:18.4
12,-14,23:18.4
13,-14,23:18.4
14,-14,23:18.4
15,-14,23:18.4
16,-14,23:18.4
17,-14,23:18.4
18,-14,23:18.4
19,-14,23:18.4
20,-14,23:18.4
21,-14,23:18.4
22,-14,23:18.4
23,-14,23:18.4
-11,-13,23:18.4
-10,-13,23:18.4
-9,-13,23:18.4
-8,-13,23:18.4
-7,-13,23:18.4
-6,-13,23:18.4
-5,-13,23:18.4
-2,-13,23:18.4
5,-13,23:18.4
6,-13,23:18.4
7,-13,23:18.4
8,-13,23:18.4
9,-13,23:18.4
10,-13,23:18.4
11,-13,23:18.4
12,-13,23:18.4
13,-13,23:18.4
14,-13,23:18.4
15,-13,23:18.4
16,-13,23:18.4
17,-13,23:18.4
18,-13,23:18.4
19,-13,23:18.4
20,-13,23:18.4
21,-13,23:18.4
22,-13,23:18.4
23,-13,23:18.4
24,-13,23:18.4
-12,-12,23:18.4
-11,-12,23:18.4
-10,-12,23:18.4
-9,-12,23:18.4
-8,-12,23:18.4
-7,-12,23:18.4
-6,-12,23:18.4
-5,-12,23:18.4
-1,-12,23:18.4
6,-12,23:18.4
7,-12,23:18.4
8,-12,23:18.4
9,-12,23:18.4
10,-12,23:18.4
19,-12,23:18.4
20,-12,23:18.4
21,-12,23:18.4
22,-12,23:18.4
23,-12,23:18.4
24,-12,23:18.4
-12,-11,23:18.4
-11,-11,23:18.4
-10,-11,23:18.4
-9,-11,23:18.4
-8,-11,23:18.4
-7,-11,23:18.4
-6,-11,23:18.4
-5,-11,23:18.4
-4,-11,23:18.4
0,-11,23:18.4
6,-11,23:18.12
17,-11,23:18.4
18,-11,23:18.4
19,-11,23:18.4
21,-11,23:18.4
22,-11,23:18.4
23,-11,23:18.4
24,-11,23:18.4
-12,-10,23:18.4
-11,-10,23:18.4
-10,-10,23:18.4
-9,-10,23:18.4
-8,-10,23:18.4
-7,-10,23:18.4
-6,-10,23:18.4
-5,-10,23:18.4
-4,-10,23:18.4
0,-10,23:18.4
1,-10,23:18.12
6,-10,23:18.12
15,-10,23:18.4
16,-10,23:18.4
17,-10,23:18.4
20,-10,23:18.4
21,-10,23:18.4
22,-10,23:18.4
23,-10,23:18.4
24,-10,23:18.4
-13,-9,23:18.4
-12,-9,23:18.4
-11,-9,23:18.4
-10,-9,23:18.4
-9,-9,23:18.4
-8,-9,23:18.4
-7,-9,23:18.4
-6,-9,23:18.4
-5,-9,23:18.4
-4,-9,23:18.4
1,-9,23:18.12
2,-9,23:18.12
6,-9,23:18.12
13,-9,23:18.4
14,-9,23:18.4
15,-9,23:18.4
19,-9,23:18.4
20,-9,23:18.4
21,-9,23:18.4
22,-9,23:18.4
23,-9,23:18.4
24,-9,23:18.4
-13,-8,23:18.4
-12,-8,23:18.4
-11,-8,23:18.4
-10,-8,23:18.4
-9,-8,23:18.4
-8,-8,23:18.4
-7,-8,23:18.4
-6,-8,23:18.4
-5,-8,23:18.4
-3,-8,23:18.4
2,-8,23:18.12
3,-8,23:18.12
6,-8,23:18.12
12,-8,23:18.4
13,-8,23:18.4
18,-8,23:18.4
19,-8,23:18.4
20,-8,23:18.4
21,-8,23:18.4
22,-8,23:18.4
23,-8,23:18.4
24,-8,23:18.4
-13,-7,23:18.4
-12,-7,23:18.4
-11,-7,23:18.4
-10,-7,23:18.4
-9,-7,23:18.4
-7,-7,23:18.4
-6,-7,23:18.4
-5,-7,23:18.4
-4,-7,23:18.4
-3,-7,23:18.4
6,-7,23:17.12
10,-7,23:18.12
11,-7,23:18.12
17,-7,23:18.4
18,-7,23:18.4
19,-7,23:18.4
20,-7,23:18.4
21,-7,23:18.4
22,-7,23:18.4
23,-7,23:18.4
24,-7,23:18.4
-13,-6,23:18.4
-12,-6,23:18.4
-11,-6,23:18.4
-10,-6,23:18.4
-9,-6,23:18.4
-8,-6,23:18.4
-7,-6,23:18.4
-6,-6,23:18.4
-5,-6,23:18.4
-4,-6,23:18.4
-3,-6,23:18.4
-2,-6,23:18.4
6,-6,23:17.12
7,-6,23:17.12
8,-6,23:18.12
9,-6,23:18.12
16,-6,23:18.4
17,-6,23:18.4
18,-6,23:18.4
19,-6,23:18.4
20,-6,23:18.4
21,-6,23:18.4
22,-6,23:18.4
23,-6,23:18.4
24,-6,23:18.4
25,-6,23:18.4
-13,-5,23:18.4
-12,-5,23:18.4
-11,-5,23:18.4
-10,-5,23:18.4
-9,-5,23:18.4
-8,-5,23:18.4
-7,-5,23:18.4
-6,-5,23:18.4
-5,-5,23:18.4
-4,-5,23:18.4
-3,-5,23:18.4
4,-5,23:18.12
5,-5,23:18.12
6,-5,23:17.12
7,-5,23:18.12
8,-5,23:18.12
16,-5,23:18.4
17,-5,23:18.4
18,-5,23:18.4
19,-5,23:18.4
20,-5,23:18.4
21,-5,23:18.4
22,-5,23:18.4
23,-5,23:18.4
24,-5,23:18.4
25,-5,23:18.4
-13,-4,23:18.4
-12,-4,23:18.4
-11,-4,23:18.4
-10,-4,23:18.4
-9,-4,23:18.4
-8,-4,23:18.4
-7,-4,23:18.4
-6,-4,23:18.4
-5,-4,23:18.4
-4,-4,23:18.4
-3,-4,23:18.4
3,-4,23:18.12
4,-4,23:18.12
9,-4,23:18.12
10,-4,23:18.12
15,-4,23:18.4
16,-4,23:18.4
17,-4,23:18.4
18,-4,23:18.4
19,-4,23:18.4
20,-4,23:18.4
21,-4,23:18.4
22,-4,23:18.4
23,-4,23:18.4
24,-4,23:18.4
25,-4,23:18.4
-13,-3,23:18.4
-12,-3,23:18.4
-11,-3,23:18.4
-10,-3,23:18.4
-9,-3,23:18.4
-8,-3,23:18.4
-7,-3,23:18.4
-6,-3,23:18.4
-5,-3,23:18.4
-4,-3,23:18.4
1,-3,23:18.12
2,-3,23:18.12
11,-3,23:18.12
12,-3,23:18.4
14,-3,23:18.4
15,-3,23:18.4
16,-3,23:18.4
17,-3,23:18.4
18,-3,23:18.4
19,-3,23:18.4
21,-3,23:18.4
22,-3,23:18.4
23,-3,23:18.4
24,-3,23:18.4
-13,-2,23:18.4
-12,-2,23:18.4
-11,-2,23:18.4
-9,-2,23:18.4
-8,-2,23:18.4
-7,-2,23:18.4
-6,-2,23:18.4
-5,-2,23:18.4
-1,-2,23:18.4
0,-2,23:18.12
8,-2,23:18.12
13,-2,23:18.4
14,-2,23:18.4
15,-2,23:18.4
16,-2,23:18.4
17,-2,23:18.4
18,-2,23:18.4
19,-2,23:18.4
20,-2,23:18.4
21,-2,23:18.4
22,-2,23:18.4
23,-2,23:18.4
24,-2,23:18.4
-13,-1,23:18.4
-12,-1,23:18.4
-11,-1,23:18.4
-10,-1,23:18.4
-9,-1,23:18.4
-8,-1,23:18.4
-7,-1,23:18.4
-6,-1,23:18.4
-5,-1,23:18.4
-2,-1,23:18.4
-1,-1,23:18.4
9,-1,23:18.12
15,-1,23:18.4
16,-1,23:18.4
17,-1,23:18.4
18,-1,23:18.4
19,-1,23:18.4
20,-1,23:18.4
21,-1,23:18.4
22,-1,23:18.4
23,-1,23:18.4
-12,0,23:18.12
-11,0,23:18.12
-10,0,23:18.12
-9,0,23:18.12
-8,0,23:18.4
-7,0,23:18.4
-6,0,23:18.4
-4,0,23:18.4
10,0,23:18.4
15,0,23:18.4
16,0,23:18.4
17,0,23:18.4
18,0,23:18.4
19,0,23:18.4
20,0,23:18.4
21,0,23:18.4
22,0,23:18.4
23,0,23:18.4
24,0,23:18.4
-12,1,23:18.12
-11,1,23:18.12
-10,1,23:18.12
-9,1,23:18.12
-8,1,23:18.4
-7,1,23:18.4
-6,1,23:18.4
-5,1,23:18.4
-4,1,23:18.4
11,1,23:18.4
16,1,23:18.4
17,1,23:18.4
18,1,23:18.4
19,1,23:18.4
20,1,23:18.4
21,1,23:18.4
22,1,23:18.4
23,1,23:18.4
24,1,23:18.4
-12,2,23:18.12
-11,2,23:18.12
-10,2,23:18.12
-9,2,23:18.12
-8,2,23:18.4
-7,2,23:18.4
-6,2,23:18.4
11,2,23:18.4
12,2,23:18.4
16,2,23:18.4
17,2,23:18.4
18,2,23:18.4
19,2,23:18.4
20,2,23:18.4
21,2,23:18.4
22,2,23:18.4
23,2,23:18.4
24,2,23:18.4
-12,3,23:18.12
-11,3,23:18.12
-10,3,23:18.12
-9,3,23:18.12
-8,3,23:18.4
12,3,23:18.4
13,3,23:18.4
16,3,23:18.4
17,3,23:18.4
18,3,23:18.4
19,3,23:18.4
21,3,23:18.4
22,3,23:18.4
23,3,23:18.4
24,3,23:18.4
-12,4,23:18.12
-11,4,23:18.12
-10,4,23:18.12
2,4,23:18.4
3,4,23:18.4
4,4,23:18.4
5,4,23:18.4
6,4,23:18.4
13,4,23:18.4
14,4,23:18.4
17,4,23:18.4
18,4,23:18.4
19,4,23:18.4
20,4,23:18.4
21,4,23:18.4
22,4,23:18.4
23,4,23:18.4
-12,5,23:18.12
-11,5,23:18.12
-10,5,23:18.12
-9,5,23:18.12
-3,5,23:18.4
-2,5,23:18.4
-1,5,23:18.4
0,5,23:18.4
1,5,23:18.4
2,5,23:18.4
3,5,23:18.4
4,5,23:18.4
5,5,23:18.4
6,5,23:18.4
7,5,23:18.4
8,5,23:18.4
14,5,23:18.4
15,5,23:18.4
17,5,23:18.4
18,5,23:18.4
19,5,23:18.4
20,5,23:18.4
21,5,23:18.4
22,5,23:18.4
23,5,23:18.4
-11,6,23:18.12
-8,6,23:18.4
-7,6,23:18.4
-6,6,23:18.4
-5,6,23:18.4
-4,6,23:18.4
-3,6,23:18.4
-2,6,23:18.4
-1,6,23:18.4
0,6,23:18.4
1,6,23:18.4
2,6,23:18.4
3,6,23:18.4
4,6,23:18.4
5,6,23:18.4
6,6,23:18.4
7,6,23:18.4
8,6,23:18.4
9,6,23:18.4
10,6,23:18.4
15,6,23:18.4
16,6,23:18.4
17,6,23:18.4
18,6,23:18.4
19,6,23:18.4
20,6,23:18.4
21,6,23:18.4
22,6,23:18.4
-11,7,23:18.12
-9,7,23:18.12
-8,7,23:18.4
-7,7,23:18.4
-6,7,23:18.4
-5,7,23:18.4
-4,7,23:18.4
-3,7,23:18.4
-2,7,23:18.4
-1,7,23:18.4
0,7,23:18.4
1,7,23:18.4
2,7,23:18.4
3,7,23:18.4
4,7,23:18.4
5,7,23:18.4
6,7,23:18.4
7,7,23:18.4
8,7,23:18.4
9,7,23:18.4
10,7,23:18.4
11,7,23:18.4
12,7,23:18.4
13,7,23:18.4
16,7,23:18.4
17,7,23:18.4
18,7,23:18.4
19,7,23:18.4
20,7,23:18.4
21,7,23:18.4
22,7,23:18.4
-11,8,23:18.12
-10,8,23:18.12
-9,8,23:18.12
-8,8,23:18.4
-7,8,23:18.4
-6,8,23:18.4
-5,8,23:18.4
-4,8,23:18.4
-3,8,23:18.4
-2,8,23:18.4
-1,8,23:18.4
0,8,23:18.4
1,8,23:18.4
2,8,23:18.4
3,8,23:18.4
4,8,23:18.4
5,8,23:18.4
6,8,23:18.4
7,8,23:18.4
8,8,23:18.4
9,8,23:18.4
10,8,23:18.4
11,8,23:18.4
12,8,23:18.4
13,8,23:18.4
14,8,23:18.4
15,8,23:18.4
17,8,23:18.4
18,8,23:18.4
19,8,23:18.4
20,8,23:18.4
21,8,23:18.4
-9,9,23:18.4
-8,9,23:18.4
-7,9,23:18.4
-6,9,23:18.4
-5,9,23:18.4
-4,9,23:18.4
-3,9,23:18.4
-2,9,23:18.4
-1,9,23:18.4
0,9,23:18.4
1,9,23:18.4
2,9,23:18.4
3,9,23:18.4
4,9,23:18.4
5,9,23:18.4
6,9,23:18.4
7,9,23:18.4
8,9,23:18.4
9,9,23:18.4
10,9,23:18.4
11,9,23:18.4
12,9,23:18.4
13,9,23:18.4
14,9,23:18.4
15,9,23:18.4
16,9,23:18.4
17,9,23:18.4
18,9,23:18.4
19,9,23:18.4
20,9,23:18.4
21,9,23:18.4
-7,10,23:18.4
-6,10,23:18.4
-5,10,23:18.4
-4,10,23:18.4
-3,10,23:18.4
-2,10,23:18.4
-1,10,23:18.4
0,10,23:18.4
1,10,23:18.4
2,10,23:18.4
3,10,23:18.4
4,10,23:18.4
5,10,23:18.4
6,10,23:18.4
7,10,23:18.4
8,10,23:18.4
9,10,23:18.4
10,10,23:18.4
11,10,23:18.4
12,10,23:18.4
13,10,23:18.4
14,10,23:18.4
15,10,23:18.4
16,10,23:18.4
17,10,23:18.4
18,10,23:18.4
20,10,23:18.4
-5,11,23:18.4
-4,11,23:18.4
-3,11,23:18.4
-2,11,23:18.4
-1,11,23:18.4
0,11,23:18.4
1,11,23:18.4
2,11,23:18.4
3,11,23:18.4
4,11,23:18.4
5,11,23:18.4
6,11,23:18.4
7,11,23:18.4
8,11,23:18.4
9,11,23:18.4
10,11,23:18.4
11,11,23:18.4
12,11,23:18.4
13,11,23:18.4
15,11,23:18.4
16,11,23:18.4
17,11,23:18.4
18,11,23:18.4
19,11,23:18.4
-3,12,23:18.12
-2,12,23:18.12
-1,12,23:18.12
0,12,23:18.12
1,12,23:18.12
2,12,23:18.4
4,12,23:18.4
5,12,23:18.4
6,12,23:18.4
7,12,23:18.4
8,12,23:18.4
9,12,23:18.4
10,12,23:18.4
11,12,23:18.4
12,12,23:18.4
13,12,23:18.4
14,12,23:18.4
15,12,23:18.4
16,12,23:18.4
17,12,23:18.4
-1,13,23:18.12
0,13,23:18.12
1,13,23:18.12
2,13,23:18.12
3,13,23:18.4
4,13,23:18.4
5,13,23:18.4
6,13,23:18.4
7,13,23:18.4
8,13,23:18.12
9,13,23:18.12
10,13,23:18.12
11,13,23:18.12
12,13,23:18.12
13,13,23:18.4
14,13,23:18.4
5,14,23:18.12
6,14,23:18.12
7,14,23:18.12
8,14,23:18.12
13,15,23:18.12
-6,-19,24:18.4
-5,-19,24:18.4
-4,-19,24:18.4
-3,-19,24:18.4
-7,-18,24:18.4
-6,-18,24:18.4
-5,-18,24:18.4
-4,-18,24:18.4
-3,-18,24:18.4
-2,-18,24:18.4
-1,-18,24:18.4
0,-18,24:18.4
1,-18,24:18.4
2,-18,24:18.4
3,-18,24:18.4
4,-18,24:18.4
5,-18,24:18.4
6,-18,24:18.4
7,-18,24:18.4
8,-18,24:18.4
9,-18,24:18.4
10,-18,24:18.4
-8,-17,24:18.4
-7,-17,24:18.4
-6,-17,24:18.4
-5,-17,24:18.4
-4,-17,24:18.4
-3,-17,24:18.4
-2,-17,24:18.4
-1,-17,24:18.4
0,-17,24:18.4
1,-17,24:18.4
2,-17,24:18.4
3,-17,24:18.4
5,-17,24:18.4
6,-17,24:18.4
7,-17,24:18.4
8,-17,24:18.4
9,-17,24:18.4
10,-17,24:18.4
11,-17,24:18.4
13,-17,24:18.4
-8,-16,24:18.4
-7,-16,24:18.4
-6,-16,24:18.4
-5,-16,24:18.4
-4,-16,24:18.4
-3,-16,24:18.4
-2,-16,24:18.4
-1,-16,24:18.4
0,-16,24:18.4
1,-16,24:18.4
2,-16,24:18.4
3,-16,24:18.4
4,-16,24:18.4
5,-16,24:18.4
6,-16,24:18.4
7,-16,24:18.4
8,-16,24:18.4
9,-16,24:18.4
10,-16,24:18.4
11,-16,24:18.4
12,-16,24:18.4
13,-16,24:18.4
14,-16,24:18.4
15,-16,24:18.4
16,-16,24:18.4
-8,-15,24:18.4
-7,-15,24:18.4
-6,-15,24:18.4
-5,-15,24:18.4
-4,-15,24:18.4
-3,-15,24:18.4
-2,-15,24:18.4
-1,-15,24:18.4
0,-15,24:18.4
11,-15,24:18.4
12,-15,24:18.4
13,-15,24:18.4
14,-15,24:18.4
15,-15,24:18.4
16,-15,24:18.4
17,-15,24:18.4
18,-15,24:18.4
19,-15,24:18.4
-8,-14,24:18.4
-7,-14,24:18.4
-6,-14,24:18.4
-5,-14,24:18.4
-4,-14,24:18.4
-3,-14,24:18.4
-2,-14,24:18.4
-1,-14,24:18.4
0,-14,24:18.4
1,-14,24:18.4
2,-14,24:18.4
3,-14,24:18.4
14,-14,24:18.4
15,-14,24:18.4
16,-14,24:18.4
17,-14,24:18.4
18,-14,24:18.4
19,-14,24:18.4
20,-14,24:18.4
21,-14,24:18.4
22,-14,24:18.4
-8,-13,24:18.4
-7,-13,24:18.4
-6,-13,24:18.4
-5,-13,24:18.4
-4,-13,24:18.4
-3,-13,24:18.4
-2,-13,24:18.4
-1,-13,24:18.4
1,-13,24:18.4
2,-13,24:18.4
3,-13,24:18.4
4,-13,24:18.4
5,-13,24:18.4
16,-13,24:18.4
17,-13,24:18.4
18,-13,24:18.4
19,-13,24:18.4
20,-13,24:18.4
21,-13,24:18.4
22,-13,24:18.4
23,-13,24:18.4
-9,-12,24:18.4
-8,-12,24:18.4
-7,-12,24:18.4
-6,-12,24:18.4
-4,-12,24:18.4
-3,-12,24:18.4
-2,-12,24:18.4
-1,-12,24:18.4
0,-12,24:18.4
1,-12,24:18.4
3,-12,24:18.4
4,-12,24:18.4
5,-12,24:18.4
6,-12,24:18.4
7,-12,24:18.4
8,-12,24:18.4
9,-12,24:18.4
10,-12,24:18.4
11,-12,24:18.4
12,-12,24:18.4
13,-12,24:18.4
14,-12,24:18.4
15,-12,24:18.4
16,-12,24:18.4
17,-12,24:18.4
18,-12,24:18.4
19,-12,24:18.4
20,-12,24:18.4
21,-12,24:18.4
22,-12,24:18.4
23,-12,24:18.4
-9,-11,24:18.4
-8,-11,24:18.4
-7,-11,24:18.4
-6,-11,24:18.4
-4,-11,24:18.4
-3,-11,24:18.4
-2,-11,24:18.4
-1,-11,24:18.4
0,-11,24:18.4
1,-11,24:18.4
2,-11,24:18.12
3,-11,24:18.12
4,-11,24:18.12
5,-11,24:18.12
6,-11,24:18.12
7,-11,24:18.12
8,-11,24:18.12
9,-11,24:18.12
10,-11,24:18.12
11,-11,24:18.4
12,-11,24:18.4
13,-11,24:18.4
14,-11,24:18.4
15,-11,24:18.4
16,-11,24:18.4
17,-11,24:18.4
18,-11,24:18.4
19,-11,24:18.4
20,-11,24:18.4
21,-11,24:18.4
22,-11,24:18.4
-9,-10,24:18.4
-8,-10,24:18.4
-7,-10,24:18.4
-6,-10,24:18.4
-3,-10,24:18.4
-2,-10,24:18.4
-1,-10,24:18.4
0,-10,24:18.4
1,-10,24:18.12
2,-10,24:18.12
3,-10,24:18.12
4,-10,24:18.12
5,-10,24:18.12
6,-10,24:18.12
7,-10,24:18.12
8,-10,24:18.12
9,-10,24:18.12
10,-10,24:18.12
11,-10,24:18.12
12,-10,24:18.4
13,-10,24:18.4
14,-10,24:18.4
15,-10,24:18.4
16,-10,24:18.4
17,-10,24:18.4
18,-10,24:18.4
19,-10,24:18.4
20,-10,24:18.4
21,-10,24:18.4
22,-10,24:18.4
-9,-9,24:18.4
-8,-9,24:18.4
-7,-9,24:18.4
-3,-9,24:18.4
-2,-9,24:18.4
-1,-9,24:18.4
0,-9,24:18.4
1,-9,24:18.12
2,-9,24:18.12
3,-9,24:18.12
4,-9,24:18.12
5,-9,24:18.12
6,-9,24:18.12
7,-9,24:18.12
8,-9,24:18.12
9,-9,24:18.12
10,-9,24:18.12
11,-9,24:18.12
12,-9,24:18.4
13,-9,24:18.4
14,-9,24:18.4
15,-9,24:18.4
16,-9,24:18.4
17,-9,24:18.4
18,-9,24:18.4
19,-9,24:18.4
20,-9,24:18.4
21,-9,24:18.4
22,-9,24:18.4
-10,-8,24:18.4
-9,-8,24:18.4
-8,-8,24:18.4
-7,-8,24:18.4
-3,-8,24:18.4
-2,-8,24:18.4
-1,-8,24:18.4
0,-8,24:18.4
1,-8,24:18.12
2,-8,24:18.12
3,-8,24:18.12
4,-8,24:18.12
5,-8,24:18.12
6,-8,24:18.12
7,-8,24:18.12
8,-8,24:18.12
9,-8,24:18.12
10,-8,24:18.12
11,-8,24:18.12
12,-8,24:18.4
13,-8,24:18.4
14,-8,24:18.4
15,-8,24:18.4
16,-8,24:18.4
17,-8,24:18.4
18,-8,24:18.4
20,-8,24:18.4
21,-8,24:18.4
22,-8,24:18.4
-10,-7,24:18.4
-9,-7,24:18.4
-7,-7,24:18.4
-2,-7,24:18.4
-1,-7,24:18.4
0,-7,24:18.4
1,-7,24:18.12
2,-7,24:18.12
3,-7,24:18.12
4,-7,24:18.12
5,-7,24:18.12
6,-7,24:18.12
7,-7,24:18.12
8,-7,24:18.12
9,-7,24:18.12
10,-7,24:18.12
11,-7,24:18.12
12,-7,24:18.4
13,-7,24:18.4
14,-7,24:18.4
15,-7,24:18.4
16,-7,24:18.4
17,-7,24:18.4
19,-7,24:18.4
20,-7,24:18.4
21,-7,24:18.4
22,-7,24:18.4
-10,-6,24:18.4
-9,-6,24:18.4
-8,-6,24:18.4
-7,-6,24:18.4
-2,-6,24:18.4
-1,-6,24:18.4
0,-6,24:18.4
1,-6,24:18.12
2,-6,24:18.12
3,-6,24:18.12
4,-6,24:18.12
5,-6,24:18.12
6,-6,24:17.12
7,-6,24:17.12
8,-6,24:18.12
9,-6,24:18.12
10,-6,24:18.12
11,-6,24:18.12
12,-6,24:18.4
13,-6,24:18.4
14,-6,24:18.4
15,-6,24:18.4
16,-6,24:18.4
19,-6,24:18.4
20,-6,24:18.4
21,-6,24:18.4
-10,-5,24:18.4
-9,-5,24:18.4
-8,-5,24:18.4
-7,-5,24:18.4
-2,-5,24:18.4
-1,-5,24:18.4
0,-5,24:18.4
1,-5,24:18.12
2,-5,24:18.12
3,-5,24:18.12
4,-5,24:18.12
5,-5,24:18.12
6,-5,24:18.12
7,-5,24:18.12
8,-5,24:18.12
9,-5,24:18.12
10,-5,24:18.12
11,-5,24:18.12
12,-5,24:18.4
13,-5,24:18.4
14,-5,24:18.4
15,-5,24:18.4
19,-5,24:18.4
20,-5,24:18.4
21,-5,24:18.4
-10,-4,24:18.4
-9,-4,24:18.4
-8,-4,24:18.4
-7,-4,24:18.4
-3,-4,24:18.4
-2,-4,24:18.4
-1,-4,24:18.4
0,-4,24:18.4
1,-4,24:18.12
2,-4,24:18.12
3,-4,24:18.12
4,-4,24:18.12
5,-4,24:18.12
6,-4,24:18.12
7,-4,24:18.12
8,-4,24:18.12
9,-4,24:18.12
10,-4,24:18.12
11,-4,24:18.12
12,-4,24:18.4
13,-4,24:18.4
19,-4,24:18.4
20,-4,24:18.4
21,-4,24:18.4
-10,-3,24:18.4
-9,-3,24:18.4
-8,-3,24:18.4
-7,-3,24:18.4
-4,-3,24:18.4
-3,-3,24:18.4
-1,-3,24:18.4
0,-3,24:18.4
1,-3,24:18.12
2,-3,24:18.12
3,-3,24:18.12
4,-3,24:18.12
5,-3,24:18.12
6,-3,24:18.12
7,-3,24:18.12
8,-3,24:18.12
9,-3,24:18.12
10,-3,24:18.12
11,-3,24:18.12
12,-3,24:18.4
13,-3,24:18.4
14,-3,24:18.4
19,-3,24:18.4
21,-3,24:18.4
-9,-2,24:18.4
-8,-2,24:18.4
-7,-2,24:18.4
-4,-2,24:18.4
-3,-2,24:18.4
-2,-2,24:18.4
-1,-2,24:18.4
0,-2,24:18.4
1,-2,24:18.12
2,-2,24:18.12
3,-2,24:18.12
4,-2,24:18.12
5,-2,24:18.12
6,-2,24:18.12
7,-2,24:18.12
8,-2,24:18.12
9,-2,24:18.12
10,-2,24:18.12
11,-2,24:18.12
12,-2,24:18.4
13,-2,24:18.4
14,-2,24:18.4
18,-2,24:18.4
19,-2,24:18.4
20,-2,24:18.4
21,-2,24:18.4
-10,-1,24:18.4
-9,-1,24:18.4
-8,-1,24:18.4
-7,-1,24:18.4
-5,-1,24:18.4
-4,-1,24:18.4
-3,-1,24:18.4
-2,-1,24:18.4
-1,-1,24:18.4
0,-1,24:18.4
1,-1,24:18.12
2,-1,24:18.12
3,-1,24:18.12
4,-1,24:18.12
5,-1,24:18.12
6,-1,24:18.12
7,-1,24:18.12
8,-1,24:18.12
9,-1,24:18.12
10,-1,24:18.12
11,-1,24:18.4
12,-1,24:18.4
13,-1,24:18.4
14,-1,24:18.4
15,-1,24:18.4
16,-1,24:18.4
18,-1,24:18.4
19,-1,24:18.4
20,-1,24:18.4
21,-1,24:18.4
-10,0,24:18.4
-9,0,24:18.4
-8,0,24:18.4
-7,0,24:18.4
-6,0,24:18.4
-5,0,24:18.4
-4,0,24:18.4
-2,0,24:18.4
-1,0,24:18.4
0,0,24:18.4
1,0,24:18.4
2,0,24:18.4
3,0,24:18.4
4,0,24:18.4
5,0,24:18.4
6,0,24:18.4
7,0,24:18.4
8,0,24:18.4
9,0,24:18.4
10,0,24:18.4
11,0,24:18.4
12,0,24:18.4
13,0,24:18.4
14,0,24:18.4
15,0,24:18.4
18,0,24:18.4
19,0,24:18.4
20,0,24:18.4
-10,1,24:18.4
-9,1,24:18.4
-8,1,24:18.4
-6,1,24:18.4
-5,1,24:18.4
-4,1,24:18.4
-3,1,24:18.4
-2,1,24:18.4
-1,1,24:18.4
0,1,24:18.4
1,1,24:18.4
2,1,24:18.4
3,1,24:18.4
4,1,24:18.4
5,1,24:18.4
6,1,24:18.4
7,1,24:18.4
8,1,24:18.4
9,1,24:18.4
10,1,24:18.4
11,1,24:18.4
12,1,24:18.4
13,1,24:18.4
14,1,24:18.4
15,1,24:18.4
18,1,24:18.4
19,1,24:18.4
20,1,24:18.4
-10,2,24:18.4
-9,2,24:18.4
-8,2,24:18.4
-7,2,24:18.4
-6,2,24:18.4
-5,2,24:18.4
-4,2,24:18.4
-3,2,24:18.4
-2,2,24:18.4
-1,2,24:18.4
0,2,24:18.4
1,2,24:18.4
2,2,24:18.4
3,2,24:18.4
4,2,24:18.4
5,2,24:18.4
6,2,24:18.4
7,2,24:18.4
8,2,24:18.4
9,2,24:18.4
10,2,24:18.4
11,2,24:18.4
12,2,24:18.4
13,2,24:18.4
14,2,24:18.4
15,2,24:18.4
18,2,24:18.4
19,2,24:18.4
20,2,24:18.4
-10,3,24:18.4
-9,3,24:18.4
-8,3,24:18.4
-7,3,24:18.4
-6,3,24:18.4
-5,3,24:18.4
-4,3,24:18.4
-3,3,24:18.4
-2,3,24:18.4
-1,3,24:18.4
0,3,24:18.4
1,3,24:18.4
2,3,24:18.4
3,3,24:18.4
4,3,24:18.4
5,3,24:18.4
6,3,24:18.4
7,3,24:18.4
8,3,24:18.4
9,3,24:18.4
10,3,24:18.4
11,3,24:18.4
12,3,24:18.4
13,3,24:18.4
14,3,24:18.4
15,3,24:18.4
16,3,24:18.4
18,3,24:18.4
19,3,24:18.4
-10,4,24:18.4
-8,4,24:18.4
-7,4,24:18.4
-6,4,24:18.4
-5,4,24:18.4
-4,4,24:18.4
-3,4,24:18.4
-2,4,24:18.4
-1,4,24:18.4
0,4,24:18.4
1,4,24:18.4
2,4,24:18.4
3,4,24:18.4
4,4,24:18.4
5,4,24:18.4
6,4,24:18.4
7,4,24:18.4
8,4,24:18.4
9,4,24:18.4
10,4,24:18.4
11,4,24:18.4
12,4,24:18.4
13,4,24:18.4
14,4,24:18.4
15,4,24:18.4
16,4,24:18.4
18,4,24:18.4
19,4,24:18.4
20,4,24:18.4
-10,5,24:18.4
-9,5,24:18.4
-8,5,24:18.4
-7,5,24:18.4
-6,5,24:18.4
-5,5,24:18.4
-4,5,24:18.4
-3,5,24:18.4
-2,5,24:18.4
-1,5,24:18.4
8,5,24:18.4
9,5,24:18.4
10,5,24:18.4
11,5,24:18.4
12,5,24:18.4
13,5,24:18.4
14,5,24:18.4
15,5,24:18.4
16,5,24:18.4
17,5,24:18.4
18,5,24:18.4
19,5,24:18.4
20,5,24:18.4
-11,6,24:18.4
-10,6,24:18.4
-9,6,24:18.4
-8,6,24:18.4
-7,6,24:18.4
-6,6,24:18.4
-5,6,24:18.4
-4,6,24:18.4
-3,6,24:18.4
-2,6,24:18.4
10,6,24:18.4
11,6,24:18.4
12,6,24:18.4
13,6,24:18.4
14,6,24:18.4
15,6,24:18.4
16,6,24:18.4
17,6,24:18.4
18,6,24:18.4
19,6,24:18.4
20,6,24:18.4
-10,7,24:18.4
-9,7,24:18.4
-8,7,24:18.4
-7,7,24:18.4
-6,7,24:18.4
-5,7,24:18.4
-4,7,24:18.4
-3,7,24:18.4
-2,7,24:18.4
-1,7,24:18.4
0,7,24:18.4
1,7,24:18.4
2,7,24:18.4
3,7,24:18.4
12,7,24:18.4
13,7,24:18.4
14,7,24:18.4
15,7,24:18.4
16,7,24:18.4
17,7,24:18.4
18,7,24:18.4
19,7,24:18.4
20,7,24:18.4
-7,8,24:18.4
-6,8,24:18.4
-5,8,24:18.4
-4,8,24:18.4
-3,8,24:18.4
-2,8,24:18.4
-1,8,24:18.4
0,8,24:18.4
1,8,24:18.4
2,8,24:18.4
3,8,24:18.4
4,8,24:18.4
5,8,24:18.4
6,8,24:18.4
7,8,24:18.4
8,8,24:18.4
9,8,24:18.4
10,8,24:18.4
11,8,24:18.4
12,8,24:18.4
13,8,24:18.4
14,8,24:18.4
15,8,24:18.4
16,8,24:18.4
17,8,24:18.4
18,8,24:18.4
19,8,24:18.4
-2,9,24:18.4
-1,9,24:18.4
0,9,24:18.4
1,9,24:18.4
2,9,24:18.4
3,9,24:18.4
4,9,24:18.4
5,9,24:18.4
6,9,24:18.4
7,9,24:18.4
8,9,24:18.4
9,9,24:18.4
10,9,24:18.4
11,9,24:18.4
12,9,24:18.4
13,9,24:18.4
14,9,24:18.4
15,9,24:18.4
16,9,24:18.4
17,9,24:18.4
18,9,24:18.4
19,9,24:18.4
2,10,24:18.4
3,10,24:18.4
4,10,24:18.4
5,10,24:18.4
6,10,24:18.4
7,10,24:18.4
8,10,24:18.4
9,10,24:18.4
10,10,24:18.4
11,10,24:18.4
12,10,24:18.4
13,10,24:18.4
14,10,24:18.4
15,10,24:18.4
16,10,24:18.4
17,10,24:18.4
18,10,24:18.4
19,10,24:18.4
-4,-16,25:18.4
-3,-16,25:18.4
-2,-16,25:18.4
-1,-16,25:18.4
0,-16,25:18.4
1,-16,25:18.4
2,-16,25:18.4
3,-16,25:18.4
4,-16,25:18.4
5,-16,25:18.4
6,-16,25:18.4
7,-16,25:18.4
8,-16,25:18.4
-5,-15,25:18.4
-4,-15,25:18.4
-3,-15,25:18.4
-2,-15,25:18.4
-1,-15,25:18.4
0,-15,25:18.4
1,-15,25:18.4
2,-15,25:18.4
3,-15,25:18.4
4,-15,25:18.4
5,-15,25:18.4
6,-15,25:18.4
7,-15,25:18.4
8,-15,25:18.4
9,-15,25:18.4
10,-15,25:18.4
11,-15,25:18.4
-5,-14,25:18.4
-4,-14,25:18.4
-3,-14,25:18.4
-2,-14,25:18.4
-1,-14,25:18.4
0,-14,25:18.4
1,-14,25:18.4
2,-14,25:18.4
3,-14,25:18.4
4,-14,25:18.4
5,-14,25:18.4
6,-14,25:18.4
7,-14,25:18.4
8,-14,25:18.4
9,-14,25:18.4
10,-14,25:18.4
11,-14,25:18.4
12,-14,25:18.4
13,-14,25:18.4
14,-14,25:18.4
-5,-13,25:18.4
-4,-13,25:18.4
-3,-13,25:18.4
8,-13,25:18.4
9,-13,25:18.4
10,-13,25:18.4
11,-13,25:18.4
12,-13,25:18.4
13,-13,25:18.4
14,-13,25:18.4
15,-13,25:18.4
16,-13,25:18.4
17,-13,25:18.4
-5,-12,25:18.4
-4,-12,25:18.4
-3,-12,25:18.4
12,-12,25:18.4
13,-12,25:18.4
14,-12,25:18.4
15,-12,25:18.4
16,-12,25:18.4
17,-12,25:18.4
18,-12,25:18.4
19,-12,25:18.4
-6,-11,25:18.4
-5,-11,25:18.4
-4,-11,25:18.4
-3,-11,25:18.4
15,-11,25:18.4
16,-11,25:18.4
17,-11,25:18.4
18,-11,25:18.4
19,-11,25:18.4
20,-11,25:18.4
-6,-10,25:18.4
-5,-10,25:18.4
-4,-10,25:18.4
-3,-10,25:18.4
17,-10,25:18.4
18,-10,25:18.4
19,-10,25:18.4
-6,-9,25:18.4
-5,-9,25:18.4
-4,-9,25:18.4
-3,-9,25:18.4
17,-9,25:18.4
18,-9,25:18.4
19,-9,25:18.4
-6,-8,25:18.4
-5,-8,25:18.4
17,-8,25:18.4
18,-8,25:18.4
19,-8,25:18.4
-7,-7,25:18.4
-6,-7,25:18.4
-5,-7,25:18.4
-4,-7,25:18.4
6,-7,25:17.12
17,-7,25:18.4
18,-7,25:18.4
19,-7,25:18.4
-7,-6,25:18.4
-6,-6,25:18.4
-5,-6,25:18.4
-4,-6,25:18.4
6,-6,25:17.12
7,-6,25:17.12
16,-6,25:18.4
17,-6,25:18.4
18,-6,25:18.4
19,-6,25:18.4
-7,-5,25:18.4
-6,-5,25:18.4
-5,-5,25:18.4
-4,-5,25:18.4
16,-5,25:18.4
17,-5,25:18.4
18,-5,25:18.4
-7,-4,25:18.4
-6,-4,25:18.4
-5,-4,25:18.4
-4,-4,25:18.4
16,-4,25:18.4
17,-4,25:18.4
18,-4,25:18.4
-7,-3,25:18.4
-6,-3,25:18.4
-5,-3,25:18.4
-4,-3,25:18.4
16,-3,25:18.4
17,-3,25:18.4
18,-3,25:18.4
-7,-2,25:18.4
-6,-2,25:18.4
-5,-2,25:18.4
-4,-2,25:18.4
16,-2,25:18.4
17,-2,25:18.4
18,-2,25:18.4
-7,-1,25:18.4
-6,-1,25:18.4
-5,-1,25:18.4
-4,-1,25:18.4
16,-1,25:18.4
17,-1,25:18.4
18,-1,25:18.4
-7,0,25:18.4
-6,0,25:18.4
-5,0,25:18.4
-4,0,25:18.4
16,0,25:18.4
17,0,25:18.4
18,0,25:18.4
-7,1,25:18.4
-6,1,25:18.4
-5,1,25:18.4
-4,1,25:18.4
15,1,25:18.4
16,1,25:18.4
17,1,25:18.4
18,1,25:18.4
-7,2,25:18.4
-6,2,25:18.4
-5,2,25:18.4
-4,2,25:18.4
15,2,25:18.4
16,2,25:18.4
17,2,25:18.4
-7,3,25:18.4
-6,3,25:18.4
-5,3,25:18.4
-4,3,25:18.4
-3,3,25:18.4
-2,3,25:18.4
15,3,25:18.4
16,3,25:18.4
17,3,25:18.4
-7,4,25:18.4
-6,4,25:18.4
-5,4,25:18.4
-4,4,25:18.4
-3,4,25:18.4
-2,4,25:18.4
-1,4,25:18.4
0,4,25:18.4
1,4,25:18.4
2,4,25:18.4
15,4,25:18.4
16,4,25:18.4
17,4,25:18.4
-7,5,25:18.4
-6,5,25:18.4
-5,5,25:18.4
-4,5,25:18.4
-3,5,25:18.4
-2,5,25:18.4
-1,5,25:18.4
0,5,25:18.4
1,5,25:18.4
2,5,25:18.4
3,5,25:18.4
4,5,25:18.4
5,5,25:18.4
6,5,25:18.4
7,5,25:18.4
8,5,25:18.4
9,5,25:18.4
10,5,25:18.4
11,5,25:18.4
12,5,25:18.4
13,5,25:18.4
14,5,25:18.4
15,5,25:18.4
16,5,25:18.4
17,5,25:18.4
-3,6,25:18.4
-2,6,25:18.4
-1,6,25:18.4
0,6,25:18.4
1,6,25:18.4
2,6,25:18.4
3,6,25:18.4
4,6,25:18.4
5,6,25:18.4
6,6,25:18.4
7,6,25:18.4
8,6,25:18.4
9,6,25:18.4
10,6,25:18.4
11,6,25:18.4
12,6,25:18.4
13,6,25:18.4
14,6,25:18.4
15,6,25:18.4
16,6,25:18.4
17,6,25:18.4
1,7,25:18.4
2,7,25:18.4
3,7,25:18.4
4,7,25:18.4
5,7,25:18.4
6,7,25:18.4
7,7,25:18.4
8,7,25:18.4
9,7,25:18.4
10,7,25:18.4
11,7,25:18.4
12,7,25:18.4
13,7,25:18.4
14,7,25:18.4
15,7,25:18.4
16,7,25:18.4
17,7,25:18.4
-4,-15,26:18.4
-3,-15,26:18.4
-3,-14,26:18.4
-2,-14,26:18.4
-2,-13,26:18.4
-1,-13,26:18.4
1,-13,26:18.4
2,-13,26:18.4
3,-13,26:18.4
4,-13,26:18.4
5,-13,26:18.4
6,-13,26:18.4
7,-13,26:18.4
8,-13,26:18.4
9,-13,26:18.4
-2,-12,26:18.4
-1,-12,26:18.4
0,-12,26:18.4
1,-12,26:18.4
3,-12,26:18.4
4,-12,26:18.4
5,-12,26:18.4
6,-12,26:18.4
7,-12,26:18.4
8,-12,26:18.4
9,-12,26:18.4
10,-12,26:18.4
11,-12,26:18.4
12,-12,26:18.4
-2,-11,26:18.4
-1,-11,26:18.4
0,-11,26:18.4
1,-11,26:18.4
2,-11,26:18.12
3,-11,26:18.12
4,-11,26:18.12
5,-11,26:18.12
6,-11,26:18.12
7,-11,26:18.12
8,-11,26:18.12
9,-11,26:18.12
10,-11,26:18.12
11,-11,26:18.4
12,-11,26:18.4
13,-11,26:18.4
14,-11,26:18.4
15,-11,26:18.4
17,-11,26:18.4
18,-11,26:18.4
19,-11,26:18.4
-3,-10,26:18.4
-2,-10,26:18.4
-1,-10,26:18.4
0,-10,26:18.4
10,-10,26:18.12
11,-10,26:18.12
12,-10,26:18.4
13,-10,26:18.4
14,-10,26:18.4
15,-10,26:18.4
16,-10,26:18.4
17,-10,26:18.4
-3,-9,26:18.4
-2,-9,26:18.4
-1,-9,26:18.4
0,-9,26:18.4
13,-9,26:18.4
14,-9,26:18.4
15,-9,26:18.4
16,-9,26:18.4
-3,-8,26:18.4
-2,-8,26:18.4
-1,-8,26:18.4
0,-8,26:18.4
14,-8,26:18.4
15,-8,26:18.4
16,-8,26:18.4
-3,-7,26:18.4
-2,-7,26:18.4
-1,-7,26:18.4
14,-7,26:18.4
15,-7,26:18.4
16,-7,26:18.4
-4,-6,26:18.4
-3,-6,26:18.4
-2,-6,26:18.4
-1,-6,26:18.4
6,-6,26:17.12
14,-6,26:18.4
15,-6,26:18.4
16,-6,26:18.4
-4,-5,26:18.4
-3,-5,26:18.4
-2,-5,26:18.4
-1,-5,26:18.4
14,-5,26:18.4
15,-5,26:18.4
16,-5,26:18.4
-4,-4,26:18.4
-3,-4,26:18.4
-2,-4,26:18.4
-1,-4,26:18.4
13,-4,26:18.4
15,-4,26:18.4
16,-4,26:18.4
-4,-3,26:18.4
-3,-3,26:18.4
-1,-3,26:18.4
13,-3,26:18.4
14,-3,26:18.4
15,-3,26:18.4
-4,-2,26:18.4
-3,-2,26:18.4
-2,-2,26:18.4
-1,-2,26:18.4
13,-2,26:18.4
14,-2,26:18.4
15,-2,26:18.4
-4,-1,26:18.4
-3,-1,26:18.4
-2,-1,26:18.4
-1,-1,26:18.4
13,-1,26:18.4
14,-1,26:18.4
15,-1,26:18.4
-4,0,26:18.4
-2,0,26:18.4
-1,0,26:18.4
13,0,26:18.4
14,0,26:18.4
15,0,26:18.4
-4,1,26:18.4
-3,1,26:18.4
-2,1,26:18.4
-1,1,26:18.4
0,1,26:18.4
1,1,26:18.4
2,1,26:18.4
13,1,26:18.4
14,1,26:18.4
15,1,26:18.4
-4,2,26:18.4
-3,2,26:18.4
-2,2,26:18.4
-1,2,26:18.4
0,2,26:18.4
1,2,26:18.4
2,2,26:18.4
3,2,26:18.4
4,2,26:18.4
5,2,26:18.4
6,2,26:18.4
7,2,26:18.4
8,2,26:18.4
9,2,26:18.4
10,2,26:18.4
11,2,26:18.4
12,2,26:18.4
13,2,26:18.4
14,2,26:18.4
15,2,26:18.4
-5,3,26:18.4
-4,3,26:18.4
-3,3,26:18.4
-2,3,26:18.4
-1,3,26:18.4
0,3,26:18.4
1,3,26:18.4
2,3,26:18.4
3,3,26:18.4
4,3,26:18.4
5,3,26:18.4
6,3,26:18.4
7,3,26:18.4
8,3,26:18.4
9,3,26:18.4
10,3,26:18.4
11,3,26:18.4
12,3,26:18.4
13,3,26:18.4
14,3,26:18.4
15,3,26:18.4
-7,4,26:18.4
-6,4,26:18.4
1,4,26:18.4
2,4,26:18.4
3,4,26:18.4
4,4,26:18.4
5,4,26:18.4
6,4,26:18.4
7,4,26:18.4
8,4,26:18.4
9,4,26:18.4
10,4,26:18.4
11,4,26:18.4
12,4,26:18.4
13,4,26:18.4
14,4,26:18.4
-7,5,26:18.4
6,5,26:18.4
7,5,26:18.4
8,5,26:18.4
9,5,26:18.4
10,5,26:18.4
11,5,26:18.4
12,5,26:18.4
13,5,26:18.4
14,5,26:18.4
15,5,26:18.4
15,6,26:18.4
16,6,26:18.4
16,7,26:18.4
-3,-15,27:18.4
-3,-14,27:18.4
-2,-14,27:18.4
-2,-13,27:18.4
-1,-13,27:18.4
-1,-12,27:18.4
0,-12,27:18.4
0,-11,27:18.4
1,-11,27:18.4
2,-11,27:18.12
3,-11,27:18.12
4,-11,27:18.12
5,-11,27:18.12
6,-11,27:18.12
7,-11,27:18.12
17,-11,27:18.4
18,-11,27:18.4
1,-10,27:18.4
2,-10,27:18.12
3,-10,27:18.12
4,-10,27:18.12
5,-10,27:18.12
6,-10,27:18.12
7,-10,27:18.12
8,-10,27:18.12
9,-10,27:18.12
10,-10,27:18.12
16,-10,27:18.4
17,-10,27:18.4
0,-9,27:18.4
1,-9,27:18.4
2,-9,27:18.12
3,-9,27:18.12
4,-9,27:18.12
5,-9,27:18.12
6,-9,27:18.12
7,-9,27:18.12
8,-9,27:18.12
9,-9,27:18.12
10,-9,27:18.12
11,-9,27:18.12
12,-9,27:18.4
13,-9,27:18.4
14,-9,27:18.4
15,-9,27:18.4
0,-8,27:18.4
1,-8,27:18.4
2,-8,27:18.12
3,-8,27:18.12
6,-8,27:18.12
7,-8,27:18.12
8,-8,27:18.12
9,-8,27:18.12
10,-8,27:18.12
11,-8,27:18.12
12,-8,27:18.4
13,-8,27:18.4
14,-8,27:18.4
0,-7,27:18.4
1,-7,27:18.4
2,-7,27:18.12
3,-7,27:18.12
11,-7,27:18.12
12,-7,27:18.4
13,-7,27:18.4
0,-6,27:18.4
1,-6,27:18.4
2,-6,27:18.12
6,-6,27:17.12
11,-6,27:18.12
12,-6,27:18.4
13,-6,27:18.4
0,-5,27:18.4
1,-5,27:18.4
2,-5,27:18.12
11,-5,27:18.12
12,-5,27:18.4
13,-5,27:18.4
-1,-4,27:18.4
0,-4,27:18.4
1,-4,27:18.4
2,-4,27:18.12
11,-4,27:18.12
12,-4,27:18.4
13,-4,27:18.4
-1,-3,27:18.4
0,-3,27:18.4
1,-3,27:18.4
2,-3,27:18.12
11,-3,27:18.12
12,-3,27:18.4
13,-3,27:18.4
-1,-2,27:18.4
0,-2,27:18.4
1,-2,27:18.4
2,-2,27:18.12
10,-2,27:18.12
11,-2,27:18.12
12,-2,27:18.4
13,-2,27:18.4
-1,-1,27:18.4
0,-1,27:18.4
1,-1,27:18.4
2,-1,27:18.12
3,-1,27:18.12
4,-1,27:18.12
5,-1,27:18.12
6,-1,27:18.12
7,-1,27:18.12
8,-1,27:18.12
9,-1,27:18.12
10,-1,27:18.12
11,-1,27:18.4
12,-1,27:18.4
-1,0,27:18.4
0,0,27:18.4
1,0,27:18.4
2,0,27:18.4
3,0,27:18.4
4,0,27:18.4
5,0,27:18.4
6,0,27:18.4
7,0,27:18.4
8,0,27:18.4
9,0,27:18.4
10,0,27:18.4
11,0,27:18.4
12,0,27:18.4
-2,1,27:18.4
-1,1,27:18.4
0,1,27:18.4
1,1,27:18.4
2,1,27:18.4
3,1,27:18.4
4,1,27:18.4
5,1,27:18.4
6,1,27:18.4
7,1,27:18.4
8,1,27:18.4
9,1,27:18.4
10,1,27:18.4
11,1,27:18.4
12,1,27:18.4
-4,2,27:18.4
-3,2,27:18.4
5,2,27:18.4
6,2,27:18.4
7,2,27:18.4
8,2,27:18.4
9,2,27:18.4
10,2,27:18.4
11,2,27:18.4
12,2,27:18.4
-5,3,27:18.4
-4,3,27:18.4
13,3,27:18.4
-6,4,27:18.4
14,4,27:18.4
14,5,27:18.4
15,5,27:18.4
15,6,27:18.4
16,6,27:18.4
16,7,27:18.4
-2,-14,28:18.4
-2,-13,28:18.4
-1,-13,28:18.4
-1,-12,28:18.4
0,-12,28:18.4
0,-11,28:18.4
1,-11,28:18.4
1,-10,28:18.4
2,-10,28:18.12
15,-10,28:18.4
16,-10,28:18.4
2,-9,28:18.12
3,-9,28:18.12
14,-9,28:18.4
15,-9,28:18.4
3,-8,28:18.12
4,-8,28:18.12
5,-8,28:18.12
6,-8,28:18.12
7,-8,28:18.12
8,-8,28:18.12
12,-8,28:18.4
13,-8,28:18.4
3,-7,28:18.12
4,-7,28:18.12
5,-7,28:18.12
6,-7,28:18.12
7,-7,28:18.12
8,-7,28:18.12
9,-7,28:18.12
10,-7,28:18.12
11,-7,28:18.12
12,-7,28:18.4
3,-6,28:18.12
4,-6,28:18.12
5,-6,28:18.12
6,-6,28:18.12
7,-6,28:18.12
8,-6,28:18.12
9,-6,28:18.12
10,-6,28:18.12
11,-6,28:18.12
3,-5,28:18.12
4,-5,28:18.12
5,-5,28:18.12
8,-5,28:18.12
9,-5,28:18.12
10,-5,28:18.12
3,-4,28:18.12
4,-4,28:18.12
5,-4,28:18.12
8,-4,28:18.12
9,-4,28:18.12
10,-4,28:18.12
3,-3,28:18.12
4,-3,28:18.12
5,-3,28:18.12
6,-3,28:18.12
7,-3,28:18.12
8,-3,28:18.12
9,-3,28:18.12
10,-3,28:18.12
2,-2,28:18.12
3,-2,28:18.12
4,-2,28:18.12
5,-2,28:18.12
6,-2,28:18.12
7,-2,28:18.12
8,-2,28:18.12
9,-2,28:18.12
10,-2,28:18.12
1,-1,28:18.4
2,-1,28:18.4
4,-1,28:18.4
5,-1,28:18.4
6,-1,28:18.4
7,-1,28:18.4
8,-1,28:18.4
9,-1,28:18.4
10,-1,28:18.4
-1,0,28:18.4
0,0,28:18.4
10,0,28:18.4
11,0,28:18.4
-2,1,28:18.4
-1,1,28:18.4
11,1,28:18.4
12,1,28:18.4
-4,2,28:18.4
-3,2,28:18.4
12,2,28:18.4
-5,3,28:18.4
-4,3,28:18.4
13,3,28:18.4
13,4,28:18.4
14,4,28:18.4
14,5,28:18.4
15,5,28:18.4
15,6,28:18.4
16,7,28:18.4
-1,-13,29:18.4
0,-12,29:18.4
0,-11,29:18.4
1,-11,29:18.4
1,-10,29:18.4
2,-10,29:18.12
15,-10,29:18.4
2,-9,29:18.12
3,-9,29:18.12
14,-9,29:18.4
15,-9,29:18.4
3,-8,29:18.12
4,-8,29:18.12
12,-8,29:18.4
13,-8,29:18.4
4,-7,29:18.12
5,-7,29:18.12
10,-7,29:18.12
11,-7,29:18.12
5,-6,29:18.12
6,-6,29:18.12
8,-6,29:18.12
9,-6,29:18.12
10,-6,29:18.12
6,-5,29:18.12
7,-5,29:18.12
8,-5,29:18.12
5,-4,29:18.12
6,-4,29:18.12
7,-4,29:18.12
8,-4,29:18.12
4,-3,29:18.12
5,-3,29:18.12
8,-3,29:18.12
2,-2,29:18.12
3,-2,29:18.12
9,-2,29:18.12
1,-1,29:18.4
2,-1,29:18.4
9,-1,29:18.4
10,-1,29:18.4
-1,0,29:18.4
0,0,29:18.4
10,0,29:18.4
11,0,29:18.4
-2,1,29:18.4
-1,1,29:18.4
11,1,29:18.4
-4,2,29:18.4
-3,2,29:18.4
12,2,29:18.4
-4,3,29:18.4
12,3,29:18.4
13,3,29:18.4
13,4,29:18.4
14,4,29:18.4
14,5,29:18.4
-1,-13,30:18.4
0,-12,30:18.4
1,-11,30:18.4
2,-10,30:18.12
3,-9,30:18.12
3,-8,30:18.12
4,-8,30:18.12
12,-8,30:18.4
13,-8,30:18.4
4,-7,30:18.12
5,-7,30:18.12
10,-7,30:18.12
11,-7,30:18.4
9,-6,30:18.12
4,-3,30:18.12
2,-2,30:18.12
3,-2,30:18.12
9,-2,30:18.12
1,-1,30:18.4
2,-1,30:18.4
9,-1,30:18.4
10,-1,30:18.4
-1,0,30:18.4
0,0,30:18.4
10,0,30:18.4
-2,1,30:18.4
-1,1,30:18.4
11,1,30:18.4
12,2,30:18.4
12,3,30:18.4
13,3,30:18.4
13,4,30:18.4
14,4,30:18.4
14,5,30:18.4
15,6,30:18.4
1,-11,31:18.4
2,-10,31:18.12
3,-9,31:18.12
4,-8,31:18.12
11,-8,31:18.4
12,-8,31:18.4
10,-7,31:18.12
11,-7,31:18.4
9,-1,31:18.4
-1,0,31:18.4
0,0,31:18.4
10,0,31:18.4
-2,1,31:18.4
-1,1,31:18.4
11,1,31:18.4
12,2,31:18.4
12,3,31:18.4
13,3,31:18.4
13,4,31:18.4
1,-11,32:18.4
2,-10,32:18.4
3,-9,32:18.4
11,1,32:18.4
11,2,32:18.4
12,2,32:18.4
12,3,32:18.4
13,4,32:18.4
11,2,33:18.4
12,3,33:18.4
