[META]
version=2.0
spawnOnBlockType=2
spawnSunlight=True
spawnDarkness=True
spawnWater=False
spawnLava=False
underFill=False
randomRotation=True
dig=True
tree=False
branch=False
needsFoundation=True
rarity=100
collisionPercentage=20
spawnElevationMin=0
spawnElevationMax=200
spawnInBiome=Custom
[DATA]
-2,8,-7:17.12
-4,9,-7:17.12
-4,10,-7:17.12
0,10,-7:17.12
-1,11,-7:17.12
0,11,-7:17.12
1,11,-7:17.12
-1,12,-7:17.12
1,12,-7:17.12
-3,7,-6:17.12
-4,8,-6:17.12
-3,8,-6:17.12
-1,8,-6:17.12
-5,9,-6:17.12
-4,9,-6:17.12
-2,9,-6:17.12
0,9,-6:17.12
-3,10,-6:17.12
0,10,-6:17.12
2,10,-6:17.12
-3,11,-6:17.12
-2,11,-6:17.12
2,11,-6:17.12
0,12,-6:17.12
1,12,-6:17.12
0,13,-6:17.12
-2,6,-5:17.12
-3,7,-5:17.12
-2,7,-5:17.12
-5,8,-5:17.12
-4,8,-5:17.12
-3,8,-5:17.12
-2,8,-5:17.12
0,8,-5:17.12
-5,9,-5:17.12
-4,9,-5:17.12
-3,9,-5:17.12
-2,9,-5:17.12
-1,9,-5:17.12
0,9,-5:17.12
-7,10,-5:17.12
-4,10,-5:17.12
-3,10,-5:17.12
-2,10,-5:17.12
-1,10,-5:17.12
2,10,-5:17.12
-7,11,-5:17.12
-6,11,-5:17.12
-5,11,-5:17.12
-4,11,-5:17.12
-3,11,-5:17.12
-2,11,-5:17.12
0,11,-5:17.12
1,11,-5:17.12
-7,12,-5:17.12
-4,12,-5:17.12
-3,12,-5:17.12
-2,12,-5:17.12
-1,12,-5:17.12
0,12,-5:17.12
-4,13,-5:17.12
-3,13,-5:17.12
0,13,-5:17.12
1,13,-5:17.12
-2,14,-5:17.12
-3,6,-4:17.12
-2,6,-4:17.12
-1,6,-4:17.12
-4,7,-4:17.12
-3,7,-4:17.12
-2,7,-4:17.12
-1,7,-4:17.12
0,7,-4:17.12
-4,8,-4:17.12
-3,8,-4:17.12
-2,8,-4:17.12
-1,8,-4:17.12
0,8,-4:17.12
-6,9,-4:17.12
-5,9,-4:17.12
-4,9,-4:17.12
-3,9,-4:17.12
-2,9,-4:17.12
-1,9,-4:17.12
0,9,-4:17.12
-7,10,-4:17.12
-6,10,-4:17.12
-4,10,-4:17.12
-3,10,-4:17.12
-2,10,-4:17.12
0,10,-4:17.12
-6,11,-4:17.12
-5,11,-4:17.12
-4,11,-4:17.12
-3,11,-4:17.12
-2,11,-4:17.12
-1,11,-4:17.12
0,11,-4:17.12
-5,12,-4:17.12
-2,12,-4:17.12
0,12,-4:17.12
-5,13,-4:17.12
-4,13,-4:17.12
-3,13,-4:17.12
-2,13,-4:17.12
-1,13,-4:17.12
0,13,-4:17.12
1,13,-4:17.12
-3,14,-4:17.12
-5,7,-3:17.12
-4,7,-3:17.12
-3,7,-3:17.12
-2,7,-3:17.12
-4,8,-3:17.12
-3,8,-3:17.12
-2,8,-3:17.12
0,8,-3:17.12
-7,9,-3:17.12
-6,9,-3:17.12
-4,9,-3:17.12
-3,9,-3:17.12
-2,9,-3:17.12
-1,9,-3:17.12
0,9,-3:17.12
-8,10,-3:17.12
-6,10,-3:17.12
-5,10,-3:17.12
-4,10,-3:17.12
-3,10,-3:17.12
-2,10,-3:17.12
-1,10,-3:17.12
0,10,-3:17.12
1,10,-3:17.12
-8,11,-3:17.12
-7,11,-3:17.12
-6,11,-3:17.12
-5,11,-3:17.12
-4,11,-3:17.12
-3,11,-3:17.12
-2,11,-3:17.12
-1,11,-3:17.12
0,11,-3:17.12
1,11,-3:17.12
-7,12,-3:17.12
-6,12,-3:17.12
-5,12,-3:17.12
-3,12,-3:17.12
-2,12,-3:17.12
0,12,-3:17.12
1,12,-3:17.12
2,12,-3:17.12
-7,13,-3:17.12
-6,13,-3:17.12
-5,13,-3:17.12
-3,13,-3:17.12
-2,13,-3:17.12
-1,13,-3:17.12
0,13,-3:17.12
-4,14,-3:17.12
-3,14,-3:17.12
-2,14,-3:17.12
-1,14,-3:17.12
-4,15,-3:17.12
-3,15,-3:17.12
-1,15,-3:17.12
-3,7,-2:17.12
-2,7,-2:17.12
-6,8,-2:17.12
-5,8,-2:17.12
-4,8,-2:17.12
-3,8,-2:17.12
-2,8,-2:17.12
-1,8,-2:17.12
-6,9,-2:17.12
-5,9,-2:17.12
-4,9,-2:17.12
-3,9,-2:17.12
-2,9,-2:17.12
-1,9,-2:17.12
0,9,-2:17.12
1,9,-2:17.12
-6,10,-2:17.12
-5,10,-2:17.12
-4,10,-2:17.12
-3,10,-2:17.12
-2,10,-2:17.12
-1,10,-2:17.12
2,10,-2:17.12
-6,11,-2:17.12
-4,11,-2:17.12
-3,11,-2:17.12
0,11,-2:17.12
1,11,-2:17.12
-5,12,-2:17.12
-4,12,-2:17.12
-3,12,-2:17.12
-2,12,-2:17.12
-1,12,-2:17.12
0,12,-2:17.12
-5,13,-2:17.12
-4,13,-2:17.12
-3,13,-2:17.12
-2,13,-2:17.12
-1,13,-2:17.12
1,13,-2:17.12
-5,14,-2:17.12
-3,14,-2:17.12
-2,14,-2:17.12
-1,14,-2:17.12
-2,15,-2:17.12
0,15,-2:17.12
-4,5,-1:17.12
-3,5,-1:17.12
-5,6,-1:17.12
-3,6,-1:17.12
-2,6,-1:17.12
-6,7,-1:17.12
-2,7,-1:17.12
-1,7,-1:17.12
0,7,-1:17.12
-6,8,-1:17.12
-3,8,-1:17.12
-2,8,-1:17.12
1,8,-1:17.12
-7,9,-1:17.12
-5,9,-1:17.12
-4,9,-1:17.12
-3,9,-1:17.12
-2,9,-1:17.12
-1,9,-1:17.12
0,9,-1:17.12
1,9,-1:17.12
-8,10,-1:17.12
-7,10,-1:17.12
-6,10,-1:17.12
-4,10,-1:17.12
-3,10,-1:17.12
-2,10,-1:17.12
-1,10,-1:17.12
0,10,-1:17.12
1,10,-1:17.12
-7,11,-1:17.12
-6,11,-1:17.12
-5,11,-1:17.12
-4,11,-1:17.12
-3,11,-1:17.12
-2,11,-1:17.12
-1,11,-1:17.12
0,11,-1:17.12
-7,12,-1:17.12
-6,12,-1:17.12
-4,12,-1:17.12
-3,12,-1:17.12
0,12,-1:17.12
1,12,-1:17.12
-6,13,-1:17.12
-5,13,-1:17.12
-3,13,-1:17.12
-2,13,-1:17.12
0,13,-1:17.12
1,13,-1:17.12
-4,14,-1:17.12
-2,14,-1:17.12
-3,15,-1:17.12
-2,15,-1:17.12
-1,15,-1:17.12
-3,16,-1:17.12
-2,16,-1:17.12
-4,5,0:17.12
-3,5,0:17.12
-5,6,0:17.12
-4,6,0:17.12
-3,6,0:17.12
-2,6,0:17.12
-6,7,0:17.12
-5,7,0:17.12
-2,7,0:17.12
-1,7,0:17.12
0,7,0:17.12
-6,8,0:17.12
-2,8,0:17.12
0,8,0:17.12
1,8,0:17.12
-7,9,0:17.12
-6,9,0:17.12
-2,9,0:17.12
-1,9,0:17.12
1,9,0:17.12
-7,10,0:17.12
-3,10,0:17.12
-2,10,0:17.12
1,10,0:17.12
-7,11,0:17.12
1,11,0:17.12
-7,12,0:17.12
-6,12,0:17.12
-5,12,0:17.12
-5,13,0:17.12
-4,13,0:17.12
-1,13,0:17.12
0,13,0:17.12
0,14,0:17.12
-3,15,0:17.12
-2,15,0:17.12
-1,15,0:17.12
-5,6,1:17.12
-4,6,1:17.12
-3,6,1:17.12
-5,7,1:17.12
-2,7,1:17.12
-1,7,1:17.12
-6,8,1:17.12
-5,8,1:17.12
0,8,1:17.12
-7,9,1:17.12
-6,9,1:17.12
1,9,1:17.12
-7,10,1:17.12
1,10,1:17.12
-7,11,1:17.12
1,11,1:17.12
-4,12,1:17.12
0,12,1:17.12
-4,13,1:17.12
0,13,1:17.12
-3,14,1:17.12
-1,14,1:17.12
0,14,1:17.12
-5,6,2:17.12
-4,6,2:17.12
-3,6,2:17.12
-5,7,2:17.12
-2,7,2:17.12
-1,7,2:17.12
-6,8,2:17.12
-5,8,2:17.12
-1,8,2:17.12
0,8,2:17.12
-6,9,2:17.12
0,9,2:17.12
1,9,2:17.12
1,10,2:17.12
-6,11,2:17.12
0,11,2:17.12
-4,12,2:17.12
0,12,2:17.12
-3,13,2:17.12
0,13,2:17.12
-1,14,2:17.12
-4,6,3:17.12
-3,6,3:17.12
2,6,3:18.14
-5,7,3:17.12
-2,7,3:17.12
-1,7,3:17.12
0,7,3:18.14
-5,8,3:17.12
-1,8,3:17.12
0,8,3:17.12
-6,9,3:17.12
0,9,3:17.12
0,10,3:17.12
-5,11,3:17.12
0,11,3:17.12
-4,12,3:17.12
0,12,3:17.12
-3,13,3:17.12
-2,13,3:17.12
-1,13,3:17.12
-2,14,3:17.12
-9,5,4:18.14
-7,6,4:18.14
-3,6,4:17.12
1,6,4:18.14
2,6,4:18.14
-2,7,4:17.12
-1,7,4:17.12
0,7,4:18.14
-5,8,4:17.12
-1,8,4:17.12
0,8,4:17.12
-6,9,4:17.12
0,9,4:17.12
-6,10,4:17.12
0,10,4:17.12
-6,11,4:17.12
-5,11,4:17.12
-4,11,4:17.12
0,11,4:17.12
-4,12,4:17.12
-3,12,4:17.12
-1,12,4:17.12
0,12,4:17.12
-3,13,4:17.12
-2,13,4:17.12
-1,13,4:17.12
3,3,5:18.14
3,4,5:18.14
-9,5,5:18.14
-7,6,5:18.14
1,6,5:18.14
2,6,5:18.14
-5,7,5:17.12
-2,7,5:17.12
0,7,5:18.14
-6,8,5:17.12
-5,8,5:17.12
-6,9,5:17.12
0,9,5:17.12
-6,10,5:17.12
0,10,5:17.12
-5,11,5:17.12
-4,11,5:17.12
-1,11,5:17.12
0,11,5:17.12
-4,12,5:17.12
-3,12,5:17.12
-2,12,5:17.12
-1,12,5:17.12
-3,13,5:17.12
-2,13,5:17.12
3,3,6:18.14
3,4,6:18.14
-9,5,6:18.14
4,5,6:18.14
-8,6,6:18.14
-7,6,6:18.14
-5,6,6:17.12
-4,6,6:17.12
-3,6,6:17.12
1,6,6:18.14
2,6,6:18.14
4,6,6:18.14
-5,7,6:17.12
-2,7,6:17.12
-6,8,6:17.12
-6,9,6:17.12
-6,10,6:17.12
-5,10,6:17.12
-5,11,6:17.12
-4,11,6:17.12
-3,11,6:18.14
-1,11,6:17.12
0,11,6:17.12
-3,12,6:17.12
-2,12,6:17.12
-1,12,6:17.12
3,3,7:18.14
3,4,7:18.14
-10,5,7:18.14
-9,5,7:18.14
-4,5,7:17.12
-8,6,7:18.14
-7,6,7:18.14
-5,6,7:17.12
-4,6,7:17.12
-3,6,7:17.12
1,6,7:18.14
2,6,7:18.14
4,6,7:18.14
5,6,7:18.14
-5,7,7:17.12
-2,7,7:17.12
-1,7,7:17.12
0,7,7:18.14
-6,8,7:17.12
-1,8,7:17.12
-6,9,7:17.12
-1,9,7:17.12
-6,10,7:17.12
-5,10,7:17.12
-4,11,7:17.12
-2,15,7:18.14
-2,16,7:18.14
3,3,8:18.14
3,4,8:18.14
-10,5,8:18.14
-9,5,8:18.14
-4,5,8:17.12
4,5,8:18.14
-8,6,8:18.14
-7,6,8:18.14
-5,6,8:17.12
-4,6,8:17.12
-3,6,8:17.12
-2,6,8:17.12
1,6,8:18.14
2,6,8:18.14
4,6,8:18.14
5,6,8:18.14
-6,7,8:17.12
-2,7,8:17.12
0,7,8:18.14
-6,8,8:17.12
-2,8,8:17.12
-1,8,8:17.12
-1,9,8:17.12
-2,10,8:17.12
-1,10,8:17.12
-2,12,8:18.14
-2,13,8:18.14
-2,15,8:18.14
-2,16,8:18.14
8,-3,9:18.6
-4,-2,9:18.6
-3,0,9:18.6
-3,1,9:18.14
3,3,9:18.14
3,4,9:18.14
-10,5,9:18.14
-9,5,9:18.14
-5,5,9:17.12
-4,5,9:17.12
4,5,9:18.14
-8,6,9:18.14
-7,6,9:18.14
-6,6,9:17.12
-5,6,9:17.12
-3,6,9:17.12
-2,6,9:17.12
1,6,9:18.14
2,6,9:18.14
4,6,9:18.14
5,6,9:18.14
-2,7,9:17.12
-1,7,9:17.12
0,7,9:18.14
-6,8,9:17.12
-2,8,9:17.12
-1,8,9:17.12
-6,9,9:17.12
-2,9,9:17.12
-5,10,9:17.12
-4,10,9:17.12
-3,10,9:17.12
-2,10,9:17.12
-4,11,9:18.14
-3,11,9:18.14
-4,12,9:18.14
-3,12,9:18.14
-2,12,9:18.14
-4,13,9:18.14
-2,13,9:18.14
-2,15,9:18.14
-2,16,9:18.14
5,-9,10:18.6
5,-8,10:18.6
4,-6,10:18.6
1,-5,10:18.14
4,-5,10:18.14
9,-5,10:18.6
2,-4,10:18.14
8,-4,10:18.6
7,-3,10:18.14
8,-3,10:18.6
-4,-2,10:18.6
-3,0,10:18.6
-3,1,10:18.14
3,3,10:18.14
3,4,10:18.14
-10,5,10:18.14
-9,5,10:18.14
-5,5,10:17.12
-4,5,10:17.12
3,5,10:18.14
-9,6,10:17.12
-8,6,10:17.12
-5,6,10:17.12
-4,6,10:17.12
-3,6,10:17.12
-2,6,10:17.12
-1,6,10:17.12
0,6,10:17.12
1,6,10:17.12
2,6,10:17.12
4,6,10:18.14
5,6,10:18.14
-8,7,10:17.12
-7,7,10:17.12
-2,7,10:17.12
-1,7,10:17.12
0,7,10:17.12
1,7,10:17.12
-7,8,10:17.12
-6,8,10:17.12
-2,8,10:17.12
-1,8,10:17.12
0,8,10:17.12
-6,9,10:17.12
-2,9,10:17.12
-5,10,10:17.12
-4,10,10:17.12
-3,10,10:17.12
-4,11,10:18.14
-3,11,10:18.14
-4,12,10:18.14
-3,12,10:18.14
-2,12,10:18.14
-4,13,10:18.14
-2,13,10:18.14
-2,15,10:18.14
-2,16,10:18.14
-1,18,10:18.14
5,-12,11:18.6
5,-11,11:18.6
5,-9,11:18.6
5,-8,11:18.6
-1,-7,11:18.6
5,-7,11:18.6
6,-7,11:18.6
5,-6,11:18.6
6,-6,11:18.6
9,-6,11:18.6
1,-5,11:18.14
4,-5,11:18.14
5,-5,11:18.14
8,-5,11:18.6
9,-5,11:18.6
-1,-4,11:18.14
1,-4,11:18.14
2,-4,11:18.14
7,-4,11:18.14
8,-4,11:18.6
-1,-3,11:18.14
2,-3,11:18.14
7,-3,11:18.14
-4,-2,11:18.6
6,-2,11:18.14
-3,0,11:18.14
-3,1,11:18.14
2,2,11:17.12
3,2,11:17.12
2,3,11:17.12
3,3,11:17.12
-4,4,11:18.14
2,4,11:17.12
3,4,11:17.12
-11,5,11:17.12
-10,5,11:17.12
-9,5,11:17.12
-8,5,11:17.12
-7,5,11:17.12
-5,5,11:17.12
-4,5,11:17.12
2,5,11:17.12
3,5,11:17.12
4,5,11:18.14
-11,6,11:17.12
-10,6,11:17.12
-9,6,11:17.12
-7,6,11:17.12
-4,6,11:17.12
-3,6,11:17.12
-2,6,11:17.12
0,6,11:17.12
1,6,11:17.12
2,6,11:17.12
3,6,11:17.12
4,6,11:18.14
5,6,11:18.14
-9,7,11:17.12
-8,7,11:17.12
-2,7,11:17.12
-1,7,11:17.12
0,7,11:17.12
1,7,11:17.12
2,7,11:17.12
-7,8,11:17.12
-6,8,11:17.12
-2,8,11:17.12
-1,8,11:17.12
-6,9,11:17.12
-5,9,11:17.12
-3,9,11:17.12
-2,9,11:17.12
-5,10,11:17.12
-4,10,11:17.12
-3,10,11:17.12
-3,11,11:18.14
-3,12,11:18.14
-2,13,11:18.14
-2,15,11:18.14
-2,16,11:18.14
-19,17,11:18.6
-20,18,11:18.6
-1,18,11:18.14
0,19,11:18.6
-20,20,11:18.6
5,-11,12:18.6
4,-10,12:18.6
5,-10,12:18.6
4,-9,12:18.6
5,-9,12:18.6
-1,-8,12:18.6
0,-8,12:18.6
4,-8,12:18.6
8,-8,12:18.6
-1,-7,12:18.6
0,-7,12:18.6
4,-7,12:18.6
7,-7,12:18.6
9,-7,12:18.6
-1,-6,12:18.6
0,-6,12:18.6
4,-6,12:18.6
6,-6,12:18.6
7,-6,12:18.6
8,-6,12:18.6
-1,-5,12:18.14
0,-5,12:18.14
1,-5,12:18.14
4,-5,12:18.14
5,-5,12:18.14
6,-5,12:18.14
7,-5,12:18.14
8,-5,12:18.6
-1,-4,12:18.14
0,-4,12:18.14
1,-4,12:18.14
4,-4,12:18.14
5,-4,12:18.14
7,-4,12:18.14
0,-3,12:18.14
2,-3,12:18.14
4,-3,12:18.14
5,-3,12:18.14
6,-3,12:18.14
7,-3,12:18.14
-4,-2,12:18.6
0,-2,12:18.14
1,-2,12:18.14
2,-2,12:18.14
3,-2,12:18.14
4,-2,12:18.14
6,-2,12:18.14
-4,-1,12:18.14
3,-1,12:18.14
4,-1,12:18.14
5,-1,12:18.14
-3,0,12:18.14
4,0,12:18.14
-3,1,12:18.14
3,1,12:17.12
3,2,12:17.12
-4,3,12:18.14
-11,4,12:17.12
-10,4,12:17.12
-9,4,12:17.12
-4,4,12:18.14
-13,5,12:17.12
-12,5,12:17.12
-11,5,12:17.12
-9,5,12:17.12
-8,5,12:17.12
-7,5,12:17.12
-5,5,12:17.12
-4,5,12:17.12
3,5,12:17.12
4,5,12:17.12
-12,6,12:17.12
-11,6,12:17.12
-6,6,12:17.12
-3,6,12:17.12
-2,6,12:17.12
3,6,12:17.12
4,6,12:17.12
5,6,12:18.14
14,6,12:18.6
15,6,12:18.6
-10,7,12:17.12
-9,7,12:17.12
-8,7,12:17.12
-2,7,12:17.12
-7,8,12:17.12
-6,8,12:17.12
-2,8,12:17.12
-6,9,12:17.12
-5,9,12:17.12
-3,9,12:17.12
-2,9,12:17.12
-4,10,12:17.12
-3,10,12:17.12
-2,10,12:17.12
-3,11,12:18.14
-3,12,12:18.14
-2,13,12:18.14
-18,15,12:18.14
-2,15,12:18.14
-18,16,12:18.6
-14,16,12:18.6
-13,16,12:18.6
-2,16,12:18.14
-19,17,12:18.6
-18,17,12:18.6
-14,17,12:18.6
-13,17,12:18.6
-19,18,12:18.6
-14,18,12:18.6
-1,18,12:18.14
-19,19,12:18.6
-14,19,12:18.6
0,19,12:18.14
-14,20,12:18.6
4,-12,13:18.6
-1,-11,13:18.6
4,-11,13:18.6
0,-10,13:18.6
4,-10,13:18.6
0,-9,13:18.6
4,-9,13:18.6
10,-9,13:18.6
0,-8,13:18.6
4,-8,13:18.6
9,-8,13:18.6
-1,-7,13:18.6
0,-7,13:18.6
1,-7,13:18.6
4,-7,13:18.6
8,-7,13:18.6
-1,-6,13:18.6
1,-6,13:18.6
4,-6,13:18.6
7,-6,13:18.6
8,-6,13:18.6
0,-5,13:18.14
1,-5,13:18.14
4,-5,13:18.14
7,-5,13:18.14
0,-4,13:18.14
1,-4,13:18.14
3,-4,13:18.14
6,-4,13:18.14
7,-4,13:18.14
1,-3,13:18.14
2,-3,13:18.14
3,-3,13:18.14
5,-3,13:18.14
6,-3,13:18.14
-4,-2,13:18.6
1,-2,13:18.14
2,-2,13:18.14
3,-2,13:18.14
4,-2,13:18.14
5,-2,13:18.14
-4,-1,13:18.14
2,-1,13:18.14
3,-1,13:18.14
4,-1,13:18.14
-3,0,13:18.14
3,0,13:18.14
4,0,13:18.14
-3,1,13:18.14
3,1,13:17.12
-5,3,13:18.14
-4,3,13:18.14
-13,4,13:17.12
-12,4,13:17.12
-11,4,13:17.12
-13,5,13:17.12
-11,5,13:17.12
-10,5,13:17.12
-9,5,13:17.12
-8,5,13:17.12
-5,5,13:17.12
-4,5,13:17.12
-3,5,13:17.12
14,5,13:18.6
15,5,13:18.6
16,5,13:18.6
17,5,13:18.6
18,5,13:18.6
-14,6,13:17.12
-13,6,13:17.12
-12,6,13:17.12
-11,6,13:17.12
-10,6,13:17.12
-9,6,13:17.12
-8,6,13:17.12
-7,6,13:17.12
-6,6,13:17.12
-5,6,13:17.12
-3,6,13:17.12
-2,6,13:17.12
4,6,13:17.12
5,6,13:17.12
14,6,13:18.6
-14,7,13:17.12
-13,7,13:17.12
-12,7,13:17.12
-6,7,13:17.12
-2,7,13:17.12
5,7,13:18.14
6,7,13:18.14
-14,8,13:17.12
-6,8,13:17.12
-2,8,13:17.12
6,8,13:18.14
-6,9,13:17.12
-5,9,13:17.12
-2,9,13:17.12
7,9,13:18.14
-5,10,13:17.12
-4,10,13:17.12
-2,10,13:17.12
-16,11,13:18.14
-14,11,13:18.14
-4,11,13:17.12
-3,11,13:17.12
-2,11,13:17.12
7,11,13:18.14
-17,12,13:18.14
-16,12,13:18.14
-14,12,13:18.14
-3,12,13:17.12
-2,12,13:17.12
-17,13,13:18.14
-14,13,13:18.14
-2,13,13:18.14
7,13,13:18.14
8,13,13:18.14
9,13,13:18.14
-17,14,13:18.14
-14,14,13:18.14
-2,14,13:18.14
-21,15,13:18.14
-20,15,13:18.14
-17,15,13:18.14
-15,15,13:18.14
-14,15,13:18.14
-2,15,13:18.14
5,15,13:18.14
6,15,13:18.14
-18,16,13:18.6
-17,16,13:18.6
-15,16,13:18.6
-14,16,13:18.6
-2,16,13:18.14
4,16,13:18.14
6,16,13:18.14
-18,17,13:18.6
-15,17,13:18.6
-14,17,13:18.6
5,17,13:18.14
-18,18,13:18.6
-15,18,13:18.6
-1,18,13:18.14
-19,19,13:18.6
-18,19,13:18.6
-15,19,13:18.6
0,19,13:18.14
-19,20,13:18.6
-18,20,13:18.6
-16,20,13:18.6
-15,20,13:18.6
4,-12,14:18.6
0,-11,14:18.6
4,-11,14:18.6
1,-10,14:18.6
4,-10,14:18.6
1,-9,14:18.6
3,-9,14:18.6
4,-9,14:18.6
1,-8,14:18.6
3,-8,14:18.6
9,-8,14:18.6
1,-7,14:18.6
2,-7,14:18.6
3,-7,14:18.6
8,-7,14:18.6
2,-6,14:18.6
3,-6,14:18.6
7,-6,14:18.6
8,-6,14:18.6
0,-5,14:18.14
2,-5,14:18.14
3,-5,14:18.14
7,-5,14:18.14
0,-4,14:18.14
1,-4,14:18.14
2,-4,14:18.14
3,-4,14:18.14
6,-4,14:18.14
-4,-3,14:18.6
1,-3,14:18.14
3,-3,14:18.14
5,-3,14:18.14
6,-3,14:18.14
-4,-2,14:18.14
2,-2,14:18.14
3,-2,14:18.14
4,-2,14:18.14
5,-2,14:18.14
-4,-1,14:18.14
2,-1,14:18.14
3,-1,14:17.12
4,-1,14:18.14
-3,0,14:18.14
3,0,14:17.12
13,0,14:18.6
-3,1,14:18.14
12,1,14:18.6
13,1,14:18.6
-5,3,14:18.14
11,3,14:18.14
-14,4,14:17.12
-13,4,14:17.12
-12,4,14:17.12
9,4,14:18.14
-14,5,14:17.12
-13,5,14:17.12
-12,5,14:17.12
-11,5,14:17.12
-5,5,14:17.12
-4,5,14:17.12
-3,5,14:17.12
8,5,14:18.14
12,5,14:18.6
13,5,14:18.6
14,5,14:18.6
15,5,14:18.6
16,5,14:18.6
17,5,14:18.6
-14,6,14:17.12
-13,6,14:17.12
-12,6,14:17.12
-11,6,14:17.12
-6,6,14:17.12
-5,6,14:17.12
-3,6,14:17.12
-2,6,14:17.12
5,6,14:17.12
6,6,14:17.12
7,6,14:18.14
8,6,14:18.14
9,6,14:18.14
10,6,14:18.14
11,6,14:18.14
-14,7,14:17.12
-13,7,14:17.12
-6,7,14:17.12
-2,7,14:17.12
5,7,14:18.14
6,7,14:18.14
-16,8,14:18.14
-15,8,14:17.12
-14,8,14:17.12
-13,8,14:17.12
-6,8,14:17.12
-5,8,14:17.12
-3,8,14:17.12
-2,8,14:17.12
6,8,14:18.14
7,8,14:18.14
8,8,14:18.14
9,8,14:18.14
-26,9,14:18.14
-24,9,14:18.14
-22,9,14:18.14
-21,9,14:18.14
-20,9,14:18.14
-19,9,14:18.14
-18,9,14:18.14
-17,9,14:18.14
-16,9,14:18.14
-15,9,14:18.14
-14,9,14:17.12
-5,9,14:17.12
-2,9,14:17.12
7,9,14:18.14
8,9,14:18.14
10,9,14:18.14
11,9,14:18.14
12,9,14:18.6
-25,10,14:18.14
-24,10,14:18.14
-23,10,14:18.14
-17,10,14:18.14
-16,10,14:18.14
-15,10,14:18.14
-14,10,14:18.14
-4,10,14:17.12
-2,10,14:17.12
8,10,14:18.14
9,10,14:18.14
-17,11,14:18.14
-16,11,14:18.14
-15,11,14:18.14
-14,11,14:18.14
-4,11,14:17.12
-1,11,14:17.12
6,11,14:18.14
7,11,14:18.14
8,11,14:18.14
9,11,14:18.14
10,11,14:18.14
-19,12,14:18.14
-18,12,14:18.14
-16,12,14:18.14
-15,12,14:18.14
-14,12,14:18.14
-3,12,14:17.12
-1,12,14:17.12
5,12,14:18.14
6,12,14:18.14
7,12,14:18.14
8,12,14:18.14
9,12,14:18.14
10,12,14:18.14
-20,13,14:18.14
-19,13,14:18.14
-16,13,14:18.14
-15,13,14:18.14
-3,13,14:17.12
-2,13,14:17.12
-1,13,14:17.12
0,13,14:17.12
1,13,14:17.12
2,13,14:17.12
3,13,14:17.12
5,13,14:18.14
6,13,14:18.14
7,13,14:18.14
8,13,14:18.14
9,13,14:18.14
-21,14,14:18.14
-20,14,14:18.14
-16,14,14:18.14
-15,14,14:18.14
-2,14,14:17.12
-1,14,14:17.12
3,14,14:18.14
-22,15,14:18.6
-21,15,14:18.6
-16,15,14:18.14
-2,15,14:18.14
3,15,14:18.14
4,15,14:18.14
5,15,14:18.14
-24,16,14:18.6
-23,16,14:18.6
-17,16,14:18.14
-16,16,14:18.14
-15,16,14:18.14
-2,16,14:18.14
4,16,14:18.14
5,16,14:18.14
6,16,14:18.14
-17,17,14:18.6
-16,17,14:18.6
-2,17,14:18.14
5,17,14:18.14
6,17,14:18.14
-17,18,14:18.6
-16,18,14:18.6
-1,18,14:18.14
-18,19,14:18.6
-17,19,14:18.6
-16,19,14:18.6
-1,19,14:18.14
0,19,14:18.14
-18,20,14:18.6
-16,20,14:18.6
-18,21,14:18.6
-17,21,14:18.6
-19,22,14:18.6
-18,22,14:18.6
-17,22,14:18.6
-18,23,14:18.6
3,-12,15:18.6
1,-11,15:18.6
3,-11,15:18.6
2,-10,15:18.6
3,-10,15:18.6
2,-9,15:18.6
3,-9,15:18.6
2,-8,15:18.6
3,-8,15:18.6
2,-7,15:18.6
3,-7,15:18.6
8,-7,15:18.6
3,-6,15:18.6
7,-6,15:18.6
0,-5,15:18.14
3,-5,15:18.14
6,-5,15:18.14
7,-5,15:18.14
0,-4,15:18.14
1,-4,15:18.14
3,-4,15:18.14
6,-4,15:18.14
-4,-3,15:18.14
1,-3,15:18.14
3,-3,15:18.14
5,-3,15:18.14
-4,-2,15:18.14
3,-2,15:18.14
4,-2,15:18.14
5,-2,15:18.14
-4,-1,15:18.14
11,-1,15:18.6
-3,0,15:18.14
16,0,15:18.6
-3,1,15:18.14
14,1,15:18.6
15,1,15:18.6
12,2,15:18.6
13,2,15:18.6
14,2,15:18.6
11,3,15:18.14
12,3,15:18.6
13,3,15:18.6
-14,4,15:17.12
-13,4,15:17.12
-12,4,15:17.12
-4,4,15:17.12
-3,4,15:17.12
11,4,15:18.14
-14,5,15:17.12
-13,5,15:17.12
-12,5,15:17.12
-5,5,15:17.12
-4,5,15:17.12
-3,5,15:17.12
-2,5,15:17.12
8,5,15:18.14
9,5,15:18.14
10,5,15:18.14
11,5,15:18.14
12,5,15:18.6
13,5,15:18.6
14,5,15:18.6
15,5,15:18.6
16,5,15:18.6
17,5,15:18.6
-32,6,15:18.14
-13,6,15:17.12
-5,6,15:17.12
-2,6,15:17.12
6,6,15:17.12
7,6,15:18.14
8,6,15:18.14
9,6,15:18.14
-5,7,15:17.12
-4,7,15:17.12
-3,7,15:17.12
-2,7,15:17.12
6,7,15:18.14
-14,8,15:17.12
-5,8,15:17.12
-4,8,15:17.12
-3,8,15:17.12
7,8,15:18.14
8,8,15:18.14
-18,9,15:18.14
-17,9,15:18.14
-16,9,15:18.14
-15,9,15:17.12
-14,9,15:17.12
-4,9,15:17.12
-3,9,15:17.12
5,9,15:18.14
8,9,15:18.14
9,9,15:18.14
10,9,15:18.14
11,9,15:18.14
-27,10,15:18.6
-26,10,15:18.6
-25,10,15:18.6
-24,10,15:18.6
-23,10,15:18.6
-22,10,15:18.6
-21,10,15:18.6
-20,10,15:18.14
-19,10,15:18.14
-18,10,15:18.14
-17,10,15:18.14
-15,10,15:17.12
-4,10,15:17.12
-3,10,15:17.12
-2,10,15:17.12
4,10,15:18.14
5,10,15:18.14
6,10,15:18.14
9,10,15:18.14
12,10,15:18.6
13,10,15:18.6
-29,11,15:18.6
-28,11,15:18.6
-27,11,15:18.6
-26,11,15:18.6
-25,11,15:18.6
-24,11,15:18.6
-19,11,15:18.14
-18,11,15:18.14
-15,11,15:18.14
-4,11,15:17.12
-3,11,15:17.12
-2,11,15:17.12
-1,11,15:17.12
4,11,15:18.14
5,11,15:18.14
10,11,15:18.14
-20,12,15:18.14
-19,12,15:18.14
-15,12,15:18.14
-3,12,15:17.12
-2,12,15:17.12
-1,12,15:17.12
4,12,15:18.14
7,12,15:18.14
8,12,15:18.14
9,12,15:18.14
10,12,15:18.14
11,12,15:18.6
-21,13,15:18.6
-20,13,15:18.14
-15,13,15:18.14
-11,13,15:18.14
-10,13,15:18.14
-3,13,15:17.12
-2,13,15:17.12
-1,13,15:17.12
0,13,15:17.12
1,13,15:17.12
2,13,15:17.12
3,13,15:17.12
4,13,15:18.14
5,13,15:18.14
6,13,15:18.14
7,13,15:18.14
11,13,15:18.6
-23,14,15:18.6
-22,14,15:18.6
-21,14,15:18.6
-16,14,15:18.14
-2,14,15:17.12
-1,14,15:17.12
0,14,15:17.12
1,14,15:17.12
2,14,15:17.12
3,14,15:17.12
4,14,15:17.12
-23,15,15:18.6
-16,15,15:18.14
-2,15,15:18.14
4,15,15:18.14
-24,16,15:18.6
-16,16,15:18.14
-2,16,15:18.14
5,16,15:18.14
-16,17,15:18.14
-2,17,15:18.14
6,17,15:18.14
-17,18,15:18.6
-2,18,15:18.14
-1,18,15:18.14
-17,19,15:18.6
-1,19,15:18.14
0,19,15:18.14
-17,20,15:18.6
9,20,15:18.6
11,21,15:18.6
-18,22,15:18.6
-18,23,15:18.6
6,-14,16:18.6
1,-13,16:18.6
2,-13,16:18.6
3,-13,16:18.6
2,-12,16:18.6
3,-12,16:18.6
2,-11,16:18.6
3,-11,16:18.6
2,-10,16:18.6
3,-10,16:18.6
2,-9,16:18.6
3,-9,16:18.6
3,-8,16:18.6
3,-7,16:18.6
8,-7,16:18.6
3,-6,16:18.6
3,-5,16:18.14
7,-5,16:18.14
3,-4,16:18.14
6,-4,16:18.14
-4,-3,16:18.14
3,-3,16:18.14
-4,-2,16:18.14
14,-2,16:18.6
-4,-1,16:18.14
9,-1,16:18.6
10,-1,16:18.6
13,-1,16:18.6
-3,0,16:18.14
-3,1,16:18.14
11,1,16:18.6
16,1,16:18.6
8,2,16:18.14
10,2,16:18.14
14,2,16:18.6
15,2,16:18.6
16,2,16:18.6
-14,3,16:17.12
-13,3,16:17.12
-3,3,16:17.12
8,3,16:18.14
9,3,16:18.14
13,3,16:18.6
14,3,16:18.6
15,3,16:18.6
-14,4,16:17.12
-13,4,16:17.12
-4,4,16:17.12
-3,4,16:17.12
-2,4,16:17.12
8,4,16:18.14
13,4,16:18.6
14,4,16:18.6
15,4,16:18.6
16,4,16:18.6
17,4,16:18.6
-14,5,16:17.12
-13,5,16:17.12
-5,5,16:17.12
-2,5,16:17.12
7,5,16:18.14
10,5,16:18.14
11,5,16:18.14
12,5,16:18.6
13,5,16:18.6
14,5,16:18.6
15,5,16:18.6
-32,6,16:18.14
-31,6,16:18.14
-5,6,16:17.12
-4,6,16:17.12
-3,6,16:17.12
-2,6,16:17.12
6,6,16:17.12
7,6,16:17.12
9,6,16:18.14
-5,7,16:17.12
-4,7,16:17.12
-3,7,16:17.12
6,7,16:18.14
-24,8,16:18.14
7,8,16:18.14
8,8,16:18.14
-24,9,16:18.14
-20,9,16:18.14
5,9,16:18.14
6,9,16:18.14
8,9,16:18.14
9,9,16:18.14
-25,10,16:18.6
-24,10,16:18.6
-21,10,16:18.6
-20,10,16:18.14
-19,10,16:18.14
-18,10,16:18.14
-17,10,16:18.14
-16,10,16:17.12
-15,10,16:17.12
5,10,16:18.14
6,10,16:18.14
9,10,16:18.14
10,10,16:18.14
11,10,16:18.14
12,10,16:18.6
-26,11,16:18.6
-25,11,16:18.6
-24,11,16:18.6
-23,11,16:18.6
-22,11,16:18.6
-21,11,16:18.6
-20,11,16:18.14
-19,11,16:18.14
-15,11,16:17.12
5,11,16:18.14
10,11,16:18.14
-28,12,16:18.6
-27,12,16:18.6
-22,12,16:18.6
-21,12,16:18.6
4,12,16:18.14
7,12,16:18.14
8,12,16:18.14
9,12,16:18.14
10,12,16:18.14
11,12,16:18.6
-23,13,16:18.6
-22,13,16:18.6
-15,13,16:18.14
-14,13,16:18.14
-13,13,16:18.14
-12,13,16:18.14
-2,13,16:17.12
-1,13,16:17.12
6,13,16:18.14
-24,14,16:18.6
-23,14,16:18.6
-16,14,16:18.14
-11,14,16:18.14
-10,14,16:18.14
-3,14,16:17.12
-2,14,16:17.12
-1,14,16:17.12
4,14,16:17.12
5,14,16:17.12
-25,15,16:18.6
-24,15,16:18.6
-20,15,16:18.14
-16,15,16:18.14
-3,15,16:17.12
-2,15,16:17.12
-1,15,16:17.12
4,15,16:18.14
5,15,16:18.14
-21,16,16:18.6
-17,16,16:18.14
-16,16,16:18.14
-2,16,16:18.14
5,16,16:18.14
-22,17,16:18.6
-17,17,16:18.14
-16,17,16:18.14
-2,17,16:18.14
7,17,16:18.14
12,17,16:18.6
13,17,16:18.6
-17,18,16:18.6
-2,18,16:18.14
-1,18,16:18.14
8,18,16:18.14
-17,19,16:18.6
-1,19,16:18.14
0,19,16:18.14
7,19,16:18.14
8,19,16:18.14
9,19,16:18.14
10,19,16:18.14
-17,20,16:18.6
10,20,16:18.6
11,20,16:18.6
-17,21,16:18.6
11,21,16:18.6
-18,22,16:18.6
-18,23,16:18.6
5,26,16:18.6
-6,27,16:18.6
6,27,16:18.6
-7,28,16:18.6
2,-14,17:18.6
3,-14,17:18.6
5,-14,17:18.6
2,-13,17:18.6
4,-13,17:18.6
5,-13,17:18.6
2,-12,17:18.6
2,-11,17:18.6
2,-10,17:18.6
2,-9,17:18.6
2,-8,17:18.6
3,-8,17:18.6
2,-7,17:18.6
8,-7,17:18.6
2,-6,17:18.6
3,-6,17:18.6
7,-6,17:18.6
2,-5,17:18.14
3,-5,17:18.14
3,-4,17:18.14
8,-4,17:18.6
-4,-3,17:18.14
3,-3,17:18.14
8,-3,17:18.14
13,-3,17:18.6
-4,-2,17:18.14
8,-2,17:18.14
11,-2,17:18.6
12,-2,17:18.6
13,-2,17:18.6
-4,-1,17:18.14
9,-1,17:18.6
10,-1,17:18.6
12,-1,17:18.6
13,-1,17:18.6
-4,0,17:18.14
-3,0,17:18.14
8,0,17:18.14
11,0,17:18.6
12,0,17:18.6
-14,1,17:18.14
-3,1,17:18.14
8,1,17:18.14
11,1,17:18.6
-16,2,17:18.14
-15,2,17:18.14
-14,2,17:18.14
8,2,17:18.14
9,2,17:18.14
17,2,17:18.6
-15,3,17:18.14
-14,3,17:18.14
-13,3,17:18.14
-4,3,17:17.12
-3,3,17:17.12
-2,3,17:17.12
8,3,17:18.14
9,3,17:18.14
15,3,17:18.6
16,3,17:18.6
17,3,17:18.6
-15,4,17:17.12
-14,4,17:17.12
-13,4,17:17.12
-4,4,17:17.12
-2,4,17:17.12
8,4,17:18.14
14,4,17:18.6
15,4,17:18.6
16,4,17:18.6
17,4,17:18.6
18,4,17:18.6
19,4,17:18.6
-28,5,17:18.6
-14,5,17:17.12
-4,5,17:17.12
-3,5,17:17.12
-2,5,17:17.12
7,5,17:18.14
10,5,17:18.14
11,5,17:18.14
12,5,17:18.6
13,5,17:18.6
14,5,17:18.6
-30,6,17:18.6
-29,6,17:18.6
-28,6,17:18.6
-4,6,17:17.12
-3,6,17:17.12
9,6,17:18.14
-23,7,17:18.14
6,7,17:18.14
-24,8,17:18.14
-23,8,17:18.14
-21,8,17:18.14
7,8,17:18.14
8,8,17:18.14
-28,9,17:18.6
-27,9,17:18.6
-26,9,17:18.14
-24,9,17:18.14
-23,9,17:18.14
-21,9,17:18.14
-20,9,17:18.14
6,9,17:18.14
9,9,17:18.14
-28,10,17:18.6
-24,10,17:18.14
-23,10,17:18.14
-22,10,17:18.14
-21,10,17:18.14
-18,10,17:18.14
-17,10,17:18.14
-15,10,17:17.12
5,10,17:18.14
10,10,17:18.14
11,10,17:18.14
-24,11,17:18.6
-23,11,17:18.6
-22,11,17:18.6
-21,11,17:18.6
-20,11,17:18.14
-19,11,17:18.14
-16,11,17:17.12
-15,11,17:17.12
4,11,17:18.14
5,11,17:18.14
12,11,17:18.6
-27,12,17:18.6
-26,12,17:18.6
-25,12,17:18.6
-24,12,17:18.6
-23,12,17:18.6
-22,12,17:18.6
-21,12,17:18.6
-15,12,17:18.14
4,12,17:18.14
7,12,17:18.14
8,12,17:18.14
9,12,17:18.14
-26,13,17:18.6
-24,13,17:18.6
-23,13,17:18.6
-18,13,17:18.14
-16,13,17:18.14
-15,13,17:18.14
-14,13,17:18.14
-25,14,17:18.6
-24,14,17:18.6
-19,14,17:18.14
-16,14,17:18.14
-15,14,17:18.14
-14,14,17:18.14
-13,14,17:18.14
-12,14,17:18.14
-11,14,17:18.14
-10,14,17:18.14
-3,14,17:17.12
-2,14,17:17.12
-1,14,17:17.12
5,14,17:17.12
-20,15,17:18.14
-19,15,17:18.14
-17,15,17:18.14
-16,15,17:18.14
-14,15,17:18.14
-10,15,17:18.14
-9,15,17:18.14
-8,15,17:18.14
-3,15,17:17.12
-2,15,17:17.12
-1,15,17:17.12
5,15,17:17.12
6,15,17:17.12
7,15,17:18.14
-20,16,17:18.14
-17,16,17:18.14
-16,16,17:18.14
-14,16,17:18.14
-6,16,17:18.14
-3,16,17:17.12
-2,16,17:17.12
6,16,17:18.14
7,16,17:18.14
8,16,17:18.14
9,16,17:18.14
10,16,17:18.14
-21,17,17:18.6
-18,17,17:18.14
-17,17,17:18.14
-16,17,17:18.14
-14,17,17:18.14
-2,17,17:18.14
7,17,17:18.14
8,17,17:18.14
9,17,17:18.14
10,17,17:18.14
11,17,17:18.6
12,17,17:18.6
-21,18,17:18.6
-19,18,17:18.6
-18,18,17:18.6
-17,18,17:18.6
-16,18,17:18.6
-2,18,17:18.14
-1,18,17:18.14
7,18,17:18.14
9,18,17:18.14
10,18,17:18.14
12,18,17:18.6
13,18,17:18.6
-19,19,17:18.6
-17,19,17:18.6
-1,19,17:18.14
0,19,17:18.14
8,19,17:18.14
10,19,17:18.14
11,19,17:18.6
8,20,17:18.14
11,20,17:18.6
12,20,17:18.6
5,25,17:18.14
5,26,17:18.6
6,26,17:18.6
-6,27,17:18.6
7,27,17:18.6
8,27,17:18.6
-6,28,17:18.6
8,28,17:18.6
8,-17,18:18.6
7,-16,18:18.6
8,-16,18:18.6
2,-15,18:18.6
7,-15,18:18.6
5,-14,18:18.6
2,-13,18:18.6
4,-13,18:18.6
5,-13,18:18.6
2,-12,18:18.6
2,-11,18:18.6
2,-10,18:18.6
-21,-9,18:18.6
2,-9,18:18.6
8,-9,18:18.6
2,-8,18:18.6
2,-7,18:18.6
7,-7,18:18.6
-24,-6,18:18.6
-19,-6,18:18.6
2,-6,18:18.6
7,-6,18:18.6
2,-5,18:18.14
2,-4,18:18.14
-4,-3,18:18.14
9,-3,18:18.6
13,-3,18:18.6
14,-3,18:18.6
-4,-2,18:18.14
9,-2,18:18.6
11,-2,18:18.6
12,-2,18:18.6
13,-2,18:18.6
-4,-1,18:18.14
9,-1,18:18.6
10,-1,18:18.6
12,-1,18:18.6
-20,0,18:18.14
-14,0,18:18.14
-4,0,18:18.14
-3,0,18:18.14
7,0,18:18.14
8,0,18:18.14
9,0,18:18.6
11,0,18:18.6
-18,1,18:18.14
-17,1,18:18.14
-15,1,18:18.14
-14,1,18:18.14
-3,1,18:18.14
5,1,18:18.14
6,1,18:18.14
9,1,18:18.6
10,1,18:18.6
-29,2,18:18.6
-16,2,18:18.14
-15,2,18:18.14
-14,2,18:18.14
-3,2,18:17.12
-2,2,18:17.12
9,2,18:18.14
19,2,18:18.6
-28,3,18:18.6
-27,3,18:18.6
-26,3,18:18.14
-15,3,18:17.12
-14,3,18:17.12
-4,3,18:17.12
-2,3,18:17.12
8,3,18:18.14
9,3,18:18.14
18,3,18:18.6
19,3,18:18.6
-16,4,18:17.12
-15,4,18:17.12
-14,4,18:17.12
-4,4,18:17.12
-2,4,18:17.12
8,4,18:18.14
15,4,18:18.6
16,4,18:18.6
17,4,18:18.6
19,4,18:18.6
-27,5,18:18.6
-26,5,18:18.14
-21,5,18:18.14
-4,5,18:17.12
-3,5,18:17.12
-2,5,18:17.12
11,5,18:18.14
12,5,18:18.6
13,5,18:18.6
14,5,18:18.6
-29,6,18:18.6
-28,6,18:18.6
-27,6,18:18.6
-26,6,18:18.14
-22,6,18:18.14
-20,6,18:18.14
9,6,18:18.14
10,6,18:18.14
-30,7,18:18.6
-29,7,18:18.6
-28,7,18:18.6
-27,7,18:18.6
-26,7,18:18.14
-22,7,18:18.14
-21,7,18:18.14
-20,7,18:18.14
-32,8,18:18.6
-31,8,18:18.6
-30,8,18:18.6
-29,8,18:18.6
-28,8,18:18.6
-27,8,18:18.6
-26,8,18:18.14
-25,8,18:18.14
-23,8,18:18.14
-22,8,18:18.14
-21,8,18:18.14
7,8,18:18.14
8,8,18:18.14
-32,9,18:18.6
-31,9,18:18.6
-30,9,18:18.6
-29,9,18:18.6
-28,9,18:18.6
-27,9,18:18.6
-26,9,18:18.14
-23,9,18:18.14
-22,9,18:18.14
8,9,18:18.14
9,9,18:18.14
-23,10,18:18.14
-18,10,18:18.14
-17,10,18:18.14
5,10,18:18.14
10,10,18:18.14
11,10,18:18.14
-23,11,18:18.6
-20,11,18:18.14
-19,11,18:18.14
-16,11,18:17.12
-15,11,18:17.12
12,11,18:18.6
-24,12,18:18.6
-23,12,18:18.6
-22,12,18:18.6
-21,12,18:18.6
-16,12,18:17.12
-15,12,18:18.14
-28,13,18:18.6
-27,13,18:18.6
-26,13,18:18.6
-25,13,18:18.6
-24,13,18:18.6
-17,13,18:18.14
-16,13,18:18.14
-15,13,18:18.14
-28,14,18:18.6
-18,14,18:18.14
-17,14,18:18.14
-16,14,18:18.14
-15,14,18:18.14
-14,14,18:18.14
-13,14,18:18.14
-12,14,18:18.14
-2,14,18:17.12
-27,15,18:18.6
-19,15,18:18.14
-18,15,18:18.14
-17,15,18:18.14
-16,15,18:18.14
-15,15,18:18.14
-12,15,18:18.14
-11,15,18:18.14
-10,15,18:18.14
-9,15,18:18.14
-8,15,18:18.14
-3,15,18:17.12
-2,15,18:17.12
-1,15,18:17.12
6,15,18:17.12
7,15,18:18.14
8,15,18:18.14
9,15,18:18.14
-18,16,18:18.14
-16,16,18:18.14
-15,16,18:18.14
-8,16,18:18.14
-6,16,18:18.14
-5,16,18:18.14
-3,16,18:17.12
-2,16,18:17.12
6,16,18:18.14
7,16,18:18.14
8,16,18:18.14
9,16,18:18.14
10,16,18:18.14
-20,17,18:18.14
-19,17,18:18.14
-18,17,18:18.14
-16,17,18:18.14
-15,17,18:18.14
-5,17,18:18.14
-3,17,18:17.12
-2,17,18:18.14
7,17,18:18.14
8,17,18:18.14
9,17,18:18.14
10,17,18:18.14
-21,18,18:18.6
-20,18,18:18.6
-19,18,18:18.6
-17,18,18:18.6
-16,18,18:18.6
-15,18,18:18.6
-14,18,18:18.6
-13,18,18:18.14
-12,18,18:18.14
-11,18,18:18.14
-10,18,18:18.14
-9,18,18:18.14
-7,18,18:18.14
-2,18,18:18.14
7,18,18:18.14
8,18,18:18.14
9,18,18:18.14
10,18,18:18.14
11,18,18:18.14
12,18,18:18.6
-21,19,18:18.6
-20,19,18:18.6
-17,19,18:18.6
-16,19,18:18.6
-15,19,18:18.6
-12,19,18:18.14
-11,19,18:18.14
-1,19,18:18.14
0,19,18:18.14
8,19,18:18.14
9,19,18:18.14
10,19,18:18.14
11,19,18:18.14
12,19,18:18.6
13,19,18:18.6
-21,20,18:18.6
-17,20,18:18.6
8,20,18:18.14
9,20,18:18.14
10,20,18:18.14
11,20,18:18.14
12,20,18:18.6
13,20,18:18.6
14,20,18:18.6
-17,21,18:18.6
-12,21,18:18.14
10,21,18:18.14
14,21,18:18.6
-13,22,18:18.14
10,22,18:18.14
11,22,18:18.14
4,24,18:18.14
5,24,18:18.14
12,24,18:18.6
13,24,18:18.6
5,25,18:18.14
-10,26,18:18.6
6,26,18:18.6
7,26,18:18.6
8,26,18:18.6
-6,27,18:18.14
-2,27,18:18.14
8,27,18:18.6
9,27,18:18.6
-6,28,18:18.6
-2,28,18:18.14
-1,28,18:18.14
9,28,18:18.6
-7,29,18:18.6
-6,29,18:18.6
-1,29,18:18.6
-7,30,18:18.6
-3,-19,19:18.6
7,-16,19:18.6
6,-15,19:18.6
5,-14,19:18.6
4,-13,19:18.6
3,-12,19:18.6
2,-11,19:18.6
8,-10,19:18.6
2,-9,19:18.6
8,-9,19:18.6
-21,-8,19:18.6
2,-8,19:18.6
7,-8,19:18.6
-20,-7,19:18.6
2,-7,19:18.6
7,-7,19:18.6
-25,-6,19:18.6
-24,-6,19:18.6
-20,-6,19:18.6
-19,-6,19:18.6
2,-6,19:18.6
6,-6,19:18.6
7,-6,19:18.6
-24,-5,19:18.6
-23,-5,19:18.6
-22,-5,19:18.6
-19,-5,19:18.6
-16,-5,19:18.14
6,-5,19:18.6
7,-5,19:18.6
9,-5,19:18.6
10,-5,19:18.6
-24,-4,19:18.6
-23,-4,19:18.6
-22,-4,19:18.6
6,-4,19:18.6
7,-4,19:18.6
10,-4,19:18.6
-26,-3,19:18.6
-23,-3,19:18.6
-4,-3,19:18.14
9,-3,19:18.6
10,-3,19:18.6
12,-3,19:18.6
13,-3,19:18.6
-29,-2,19:18.6
-25,-2,19:18.6
-24,-2,19:18.6
-16,-2,19:18.14
-15,-2,19:18.14
-4,-2,19:18.14
5,-2,19:18.14
9,-2,19:18.6
10,-2,19:18.6
11,-2,19:18.6
12,-2,19:18.6
13,-2,19:18.6
-28,-1,19:18.6
-27,-1,19:18.6
-24,-1,19:18.6
-23,-1,19:18.6
-21,-1,19:18.14
-20,-1,19:18.14
-15,-1,19:18.14
-4,-1,19:18.14
-3,-1,19:17.12
8,-1,19:18.14
9,-1,19:18.6
10,-1,19:18.6
11,-1,19:18.6
12,-1,19:18.6
-27,0,19:18.6
-23,0,19:18.14
-20,0,19:18.14
-19,0,19:18.14
-18,0,19:18.14
-15,0,19:18.14
-4,0,19:17.12
-3,0,19:17.12
-2,0,19:17.12
4,0,19:18.14
7,0,19:18.14
8,0,19:18.14
10,0,19:18.6
11,0,19:18.6
-24,1,19:18.14
-17,1,19:18.14
-16,1,19:18.14
-15,1,19:18.14
-4,1,19:17.12
-3,1,19:17.12
-2,1,19:17.12
5,1,19:18.14
10,1,19:18.6
-22,2,19:18.14
-21,2,19:18.14
-15,2,19:18.14
-14,2,19:18.14
-4,2,19:17.12
-2,2,19:17.12
-1,2,19:17.12
0,2,19:17.12
1,2,19:17.12
2,2,19:17.12
3,2,19:18.14
4,2,19:18.14
9,2,19:18.14
-29,3,19:18.6
-28,3,19:18.6
-27,3,19:18.6
-26,3,19:18.14
-21,3,19:18.14
-20,3,19:18.14
-19,3,19:18.14
-17,3,19:17.12
-16,3,19:17.12
-15,3,19:17.12
-4,3,19:17.12
-2,3,19:17.12
-1,3,19:17.12
0,3,19:17.12
1,3,19:17.12
2,3,19:17.12
8,3,19:18.14
9,3,19:18.14
20,3,19:18.6
-27,4,19:18.6
-26,4,19:18.14
-25,4,19:18.14
-24,4,19:18.14
-23,4,19:18.14
-21,4,19:18.14
-20,4,19:17.12
-19,4,19:17.12
-18,4,19:17.12
-17,4,19:17.12
-16,4,19:17.12
-15,4,19:17.12
-4,4,19:17.12
-3,4,19:17.12
-2,4,19:17.12
15,4,19:18.6
16,4,19:18.6
17,4,19:18.6
18,4,19:18.6
-29,5,19:18.6
-28,5,19:18.6
-27,5,19:18.6
-26,5,19:18.14
-25,5,19:18.14
-24,5,19:18.14
-23,5,19:18.14
-22,5,19:18.14
-21,5,19:18.14
-20,5,19:18.14
11,5,19:18.14
12,5,19:18.6
13,5,19:18.6
14,5,19:18.6
15,5,19:18.6
-29,6,19:18.6
-28,6,19:18.6
-27,6,19:18.6
-26,6,19:18.14
-25,6,19:18.14
-24,6,19:18.14
-23,6,19:18.14
-22,6,19:18.14
-21,6,19:18.14
10,6,19:18.14
-29,7,19:18.6
-28,7,19:18.6
-27,7,19:18.6
-26,7,19:18.14
-25,7,19:18.14
-24,7,19:18.14
-23,7,19:18.14
-22,7,19:18.14
-21,7,19:18.14
-31,8,19:18.6
-30,8,19:18.6
-29,8,19:18.6
-28,8,19:18.6
-27,8,19:18.6
-26,8,19:18.14
-25,8,19:18.14
-22,8,19:18.14
7,8,19:18.14
8,8,19:18.14
-32,9,19:18.6
-23,9,19:18.14
-22,9,19:18.14
9,9,19:18.14
-23,10,19:18.14
-17,10,19:18.14
-23,11,19:18.6
-20,11,19:18.14
-19,11,19:18.14
-18,11,19:18.14
-23,12,19:18.6
-22,12,19:18.6
-21,12,19:18.6
-24,13,19:18.6
-23,13,19:18.6
-17,13,19:18.14
-16,13,19:17.12
-28,14,19:18.6
-27,14,19:18.6
-26,14,19:18.6
-17,14,19:18.14
-16,14,19:18.14
-15,14,19:18.14
-29,15,19:18.6
-28,15,19:18.6
-18,15,19:18.14
-17,15,19:18.14
-16,15,19:18.14
-15,15,19:18.14
-14,15,19:18.14
-13,15,19:18.14
-12,15,19:18.14
-11,15,19:18.14
-2,15,19:17.12
7,15,19:18.14
9,15,19:18.14
10,15,19:18.14
11,15,19:18.6
-18,16,19:18.14
-17,16,19:18.14
-16,16,19:18.14
-15,16,19:18.14
-11,16,19:18.14
-10,16,19:18.14
-9,16,19:18.14
-8,16,19:18.14
-7,16,19:18.14
-3,16,19:17.12
-2,16,19:17.12
7,16,19:18.14
8,16,19:18.14
9,16,19:18.14
10,16,19:18.14
-20,17,19:18.14
-19,17,19:18.14
-16,17,19:18.14
-15,17,19:18.14
-14,17,19:18.14
-13,17,19:18.14
-12,17,19:18.14
-11,17,19:18.14
-10,17,19:18.14
-8,17,19:18.14
-7,17,19:18.14
-6,17,19:18.14
-5,17,19:18.14
-4,17,19:18.14
-3,17,19:17.12
-2,17,19:17.12
7,17,19:18.14
8,17,19:18.14
9,17,19:18.14
10,17,19:18.14
11,17,19:18.14
12,17,19:18.14
-20,18,19:18.6
-17,18,19:18.6
-16,18,19:18.6
-15,18,19:18.6
-14,18,19:18.6
-13,18,19:18.14
-12,18,19:18.14
-11,18,19:18.14
-10,18,19:18.14
-9,18,19:18.14
-8,18,19:18.14
-7,18,19:18.14
-6,18,19:18.14
-5,18,19:18.14
-4,18,19:18.14
-3,18,19:17.12
-2,18,19:18.14
-1,18,19:18.14
7,18,19:18.14
8,18,19:18.14
9,18,19:18.14
10,18,19:18.14
11,18,19:18.14
-21,19,19:18.6
-15,19,19:18.6
-1,19,19:18.14
0,19,19:18.14
8,19,19:18.14
11,19,19:18.14
12,19,19:18.14
-21,20,19:18.6
-9,20,19:18.14
8,20,19:18.14
9,20,19:18.14
10,20,19:18.14
11,20,19:18.14
13,20,19:18.6
14,20,19:18.6
-12,21,19:18.14
-11,21,19:18.14
-10,21,19:18.14
-7,21,19:18.14
7,21,19:18.14
8,21,19:18.14
10,21,19:18.14
15,21,19:18.6
-13,22,19:18.14
-12,22,19:18.14
-11,22,19:18.14
-8,22,19:18.14
3,22,19:18.14
8,22,19:18.14
9,22,19:18.14
10,22,19:18.14
-14,23,19:18.6
-13,23,19:18.14
-9,23,19:18.14
4,23,19:18.14
5,23,19:18.14
9,23,19:18.14
10,23,19:18.14
11,23,19:18.14
-14,24,19:18.6
-10,24,19:18.14
-9,24,19:18.14
5,24,19:18.14
6,24,19:18.14
9,24,19:18.14
10,24,19:18.14
11,24,19:18.14
-11,25,19:18.6
-10,25,19:18.6
-4,25,19:18.14
7,25,19:18.6
11,25,19:18.6
12,25,19:18.6
-11,26,19:18.6
-5,26,19:18.14
-4,26,19:18.14
-2,26,19:18.14
1,26,19:18.14
7,26,19:18.6
8,26,19:18.6
9,26,19:18.6
-12,27,19:18.6
-5,27,19:18.14
-2,27,19:18.14
-1,27,19:18.14
1,27,19:18.14
2,27,19:18.14
9,27,19:18.6
-6,28,19:18.14
-5,28,19:18.14
-1,28,19:18.14
1,28,19:18.14
2,28,19:18.14
-6,29,19:18.14
0,29,19:18.14
1,29,19:18.14
-7,30,19:18.6
0,30,19:18.6
1,30,19:18.6
1,31,19:18.6
-4,33,19:18.6
0,-20,20:18.6
-3,-19,20:18.6
0,-19,20:18.6
-4,-18,20:18.6
-3,-18,20:18.6
-3,-17,20:18.6
-1,-17,20:18.6
8,-17,20:18.6
5,-15,20:18.6
6,-15,20:18.6
4,-14,20:18.6
5,-14,20:18.6
3,-13,20:18.6
4,-13,20:18.6
-11,-12,20:18.6
2,-12,20:18.14
3,-12,20:18.6
2,-11,20:18.14
3,-11,20:18.6
0,-10,20:18.14
1,-10,20:18.14
3,-10,20:18.6
8,-10,20:18.6
-22,-9,20:18.6
-1,-9,20:18.14
0,-9,20:18.14
3,-9,20:18.6
7,-9,20:18.6
-21,-8,20:18.6
2,-8,20:18.14
3,-8,20:18.6
7,-8,20:18.6
-25,-7,20:18.6
-24,-7,20:18.6
-21,-7,20:18.6
2,-7,20:18.14
3,-7,20:18.6
6,-7,20:18.6
7,-7,20:18.6
10,-7,20:18.6
-27,-6,20:18.6
-24,-6,20:18.6
-23,-6,20:18.6
-20,-6,20:18.6
-16,-6,20:18.14
3,-6,20:18.6
6,-6,20:18.6
9,-6,20:18.6
10,-6,20:18.6
-27,-5,20:18.6
-26,-5,20:18.6
-25,-5,20:18.6
-24,-5,20:18.6
-23,-5,20:18.6
-20,-5,20:18.6
-19,-5,20:18.6
-17,-5,20:18.6
-16,-5,20:18.14
3,-5,20:18.6
6,-5,20:18.6
8,-5,20:18.6
9,-5,20:18.6
10,-5,20:18.6
-26,-4,20:18.6
-25,-4,20:18.6
-24,-4,20:18.6
-23,-4,20:18.6
-22,-4,20:18.6
-19,-4,20:18.6
-16,-4,20:18.14
-4,-4,20:17.12
3,-4,20:18.6
5,-4,20:18.6
7,-4,20:18.6
8,-4,20:18.6
10,-4,20:18.6
11,-4,20:18.6
-25,-3,20:18.6
-24,-3,20:18.6
-23,-3,20:18.6
-22,-3,20:18.14
-21,-3,20:18.14
-16,-3,20:18.14
-4,-3,20:17.12
-3,-3,20:17.12
3,-3,20:18.14
7,-3,20:18.14
8,-3,20:18.14
10,-3,20:18.6
12,-3,20:18.6
13,-3,20:18.6
-24,-2,20:18.6
-23,-2,20:18.6
-21,-2,20:18.14
-18,-2,20:18.14
-16,-2,20:18.14
-4,-2,20:17.12
-3,-2,20:17.12
3,-2,20:18.14
4,-2,20:18.14
5,-2,20:18.14
6,-2,20:18.14
7,-2,20:18.14
10,-2,20:18.6
11,-2,20:18.6
12,-2,20:18.6
-31,-1,20:18.6
-30,-1,20:18.6
-29,-1,20:18.6
-28,-1,20:18.6
-23,-1,20:18.6
-22,-1,20:18.14
-20,-1,20:18.14
-19,-1,20:18.14
-16,-1,20:18.14
-4,-1,20:17.12
-3,-1,20:17.12
-2,-1,20:17.12
3,-1,20:18.14
4,-1,20:18.14
5,-1,20:18.14
6,-1,20:18.14
8,-1,20:18.14
9,-1,20:18.6
10,-1,20:18.6
11,-1,20:18.6
-29,0,20:18.6
-28,0,20:18.6
-27,0,20:18.6
-26,0,20:18.6
-18,0,20:18.14
-17,0,20:18.14
-16,0,20:18.14
-4,0,20:17.12
-3,0,20:17.12
-2,0,20:17.12
4,0,20:18.14
5,0,20:18.14
6,0,20:18.14
7,0,20:18.14
10,0,20:18.6
-27,1,20:18.6
-25,1,20:18.14
-16,1,20:18.14
-15,1,20:18.14
-4,1,20:17.12
-3,1,20:17.12
-2,1,20:17.12
3,1,20:18.14
4,1,20:18.14
5,1,20:18.14
6,1,20:18.14
10,1,20:18.6
-25,2,20:18.14
-24,2,20:18.14
-17,2,20:17.12
-15,2,20:18.14
-4,2,20:17.12
-3,2,20:17.12
-2,2,20:17.12
2,2,20:17.12
3,2,20:18.14
4,2,20:18.14
9,2,20:18.14
-23,3,20:18.14
-22,3,20:18.14
-21,3,20:18.14
-17,3,20:17.12
-16,3,20:17.12
-4,3,20:17.12
-3,3,20:17.12
-2,3,20:17.12
-1,3,20:17.12
0,3,20:17.12
1,3,20:17.12
2,3,20:17.12
3,3,20:17.12
8,3,20:18.14
-31,4,20:18.6
-30,4,20:18.6
-29,4,20:18.6
-28,4,20:18.6
-27,4,20:18.6
-26,4,20:18.14
-25,4,20:18.14
-24,4,20:18.14
-23,4,20:18.14
-22,4,20:18.14
-21,4,20:18.14
-20,4,20:18.14
-19,4,20:18.14
-18,4,20:17.12
-17,4,20:17.12
-16,4,20:17.12
-4,4,20:17.12
-3,4,20:17.12
-2,4,20:17.12
18,4,20:18.6
19,4,20:18.6
-30,5,20:18.6
-29,5,20:18.6
-28,5,20:18.6
-27,5,20:18.6
-26,5,20:18.14
-25,5,20:18.14
-24,5,20:18.14
-23,5,20:18.14
-22,5,20:18.14
-21,5,20:17.12
11,5,20:18.14
12,5,20:18.6
13,5,20:18.6
14,5,20:18.6
15,5,20:18.6
-25,6,20:18.14
-24,6,20:18.14
-23,6,20:18.14
-22,6,20:18.14
-21,6,20:18.14
10,6,20:18.14
11,6,20:18.14
-28,7,20:18.6
-27,7,20:18.6
-26,7,20:18.14
-25,7,20:18.14
-24,7,20:18.14
-23,7,20:18.14
-22,7,20:18.14
-31,8,20:18.6
-30,8,20:18.6
-29,8,20:18.6
-22,8,20:18.14
7,8,20:18.14
8,8,20:18.14
-23,9,20:18.14
-22,9,20:18.14
9,9,20:18.14
-23,10,20:18.14
-23,11,20:18.6
-20,11,20:18.14
-19,11,20:18.14
-18,11,20:18.14
-24,12,20:18.6
-22,12,20:18.6
-21,12,20:18.6
-20,12,20:18.14
-25,13,20:18.6
-24,13,20:18.6
-23,13,20:18.6
-27,14,20:18.6
-26,14,20:18.6
-17,14,20:18.14
-16,14,20:18.14
-15,14,20:18.14
-18,15,20:18.14
-17,15,20:18.14
-16,15,20:18.14
-15,15,20:18.14
7,15,20:18.14
-18,16,20:18.14
-17,16,20:18.14
-16,16,20:18.14
-15,16,20:18.14
-14,16,20:18.14
-13,16,20:18.14
-12,16,20:18.14
-11,16,20:18.14
-10,16,20:18.14
-3,16,20:17.12
-2,16,20:17.12
7,16,20:18.14
8,16,20:18.14
9,16,20:18.14
10,16,20:18.14
11,16,20:18.14
-19,17,20:18.14
-18,17,20:18.14
-16,17,20:18.14
-15,17,20:18.14
-14,17,20:18.14
-13,17,20:18.14
-12,17,20:18.14
-11,17,20:18.14
-10,17,20:18.14
-9,17,20:18.14
-8,17,20:18.14
-7,17,20:18.14
-6,17,20:18.14
-5,17,20:18.14
-4,17,20:17.12
-3,17,20:17.12
-2,17,20:17.12
-1,17,20:17.12
7,17,20:18.14
8,17,20:18.14
9,17,20:18.14
10,17,20:18.14
11,17,20:18.14
-15,18,20:18.6
-13,18,20:18.14
-12,18,20:18.14
-11,18,20:18.14
-10,18,20:18.14
-9,18,20:18.14
-8,18,20:18.14
-7,18,20:17.12
-6,18,20:17.12
-5,18,20:17.12
-4,18,20:17.12
-3,18,20:17.12
-2,18,20:17.12
-1,18,20:17.12
0,18,20:17.12
7,18,20:18.14
8,18,20:18.14
9,18,20:18.14
10,18,20:18.14
11,18,20:18.14
12,18,20:18.14
-8,19,20:18.14
-7,19,20:18.14
-6,19,20:17.12
-5,19,20:17.12
-2,19,20:17.12
-1,19,20:17.12
0,19,20:17.12
1,19,20:17.12
5,19,20:18.14
6,19,20:18.14
7,19,20:18.14
8,19,20:18.14
9,19,20:18.14
10,19,20:18.14
12,19,20:18.14
-9,20,20:18.14
-8,20,20:18.14
-7,20,20:18.14
1,20,20:18.14
2,20,20:18.14
3,20,20:18.14
4,20,20:18.14
5,20,20:18.14
6,20,20:18.14
7,20,20:18.14
8,20,20:18.14
9,20,20:18.14
11,20,20:18.14
12,20,20:18.14
13,20,20:18.6
14,20,20:18.6
15,20,20:18.6
-10,21,20:18.14
-9,21,20:18.14
-8,21,20:18.14
2,21,20:18.14
3,21,20:18.14
4,21,20:18.14
5,21,20:18.14
6,21,20:18.14
-11,22,20:18.14
-10,22,20:18.14
-9,22,20:18.14
3,22,20:18.14
4,22,20:18.14
5,22,20:18.14
6,22,20:18.14
7,22,20:18.14
8,22,20:18.14
-12,23,20:18.14
-11,23,20:18.14
-10,23,20:18.14
-9,23,20:18.14
5,23,20:18.14
6,23,20:18.14
7,23,20:18.14
8,23,20:18.14
9,23,20:18.14
10,23,20:18.14
-14,24,20:18.6
-13,24,20:18.14
-12,24,20:18.14
-11,24,20:18.14
-10,24,20:18.14
6,24,20:18.14
7,24,20:18.14
9,24,20:18.14
10,24,20:18.14
11,24,20:18.14
12,24,20:18.14
-14,25,20:18.6
-12,25,20:18.6
-11,25,20:18.6
-4,25,20:18.14
-3,25,20:18.14
0,25,20:18.14
1,25,20:18.14
8,25,20:18.6
9,25,20:18.6
10,25,20:18.6
11,25,20:18.6
-13,26,20:18.6
-12,26,20:18.6
-4,26,20:18.14
-2,26,20:18.14
-1,26,20:18.14
0,26,20:18.14
1,26,20:18.14
9,26,20:18.6
10,26,20:18.6
11,26,20:18.6
12,26,20:18.6
-5,27,20:18.14
-4,27,20:18.14
-1,27,20:18.14
0,27,20:18.14
1,27,20:18.14
10,27,20:18.6
11,27,20:18.6
12,27,20:18.6
13,27,20:18.6
-5,28,20:18.14
0,28,20:18.14
1,28,20:18.14
11,28,20:18.6
12,28,20:18.6
-6,29,20:18.14
-5,29,20:18.14
0,29,20:18.14
1,29,20:18.14
-6,30,20:18.6
1,30,20:18.6
-2,31,20:18.6
1,31,20:18.6
-3,32,20:18.6
-2,32,20:18.6
-3,33,20:18.6
-3,35,20:18.6
-4,-19,21:18.6
-4,-18,21:18.6
0,-18,21:18.6
1,-18,21:18.6
8,-18,21:18.6
-4,-17,21:18.6
0,-17,21:18.6
1,-17,21:18.6
7,-17,21:18.6
8,-17,21:18.6
-4,-16,21:18.6
0,-16,21:18.6
6,-16,21:18.6
7,-16,21:18.6
5,-15,21:18.6
6,-15,21:18.6
-4,-14,21:18.6
4,-14,21:18.6
5,-14,21:18.6
-12,-13,21:18.6
3,-13,21:18.6
4,-13,21:18.6
-12,-12,21:18.6
-11,-12,21:18.6
-4,-12,21:18.14
2,-12,21:18.14
3,-12,21:18.6
-24,-11,21:18.6
-11,-11,21:18.6
-10,-11,21:18.6
-4,-11,21:18.14
-3,-11,21:18.14
-25,-10,21:18.6
-23,-10,21:18.6
-15,-10,21:18.14
-10,-10,21:18.14
-4,-10,21:18.14
0,-10,21:18.14
3,-10,21:18.6
7,-10,21:18.6
-24,-9,21:18.6
-23,-9,21:18.6
-22,-9,21:18.6
-14,-9,21:18.14
-13,-9,21:18.14
-9,-9,21:18.14
-1,-9,21:18.14
3,-9,21:18.6
4,-9,21:18.6
7,-9,21:18.6
-24,-8,21:18.6
-23,-8,21:18.6
-22,-8,21:18.6
-13,-8,21:18.14
-11,-8,21:18.14
-2,-8,21:18.14
3,-8,21:18.6
4,-8,21:18.6
6,-8,21:18.6
7,-8,21:18.6
-24,-7,21:18.6
-23,-7,21:18.6
-22,-7,21:18.6
-21,-7,21:18.6
-19,-7,21:18.6
-16,-7,21:18.14
3,-7,21:18.6
4,-7,21:18.6
6,-7,21:18.6
-23,-6,21:18.6
-22,-6,21:18.6
-21,-6,21:18.6
-19,-6,21:18.6
-18,-6,21:18.6
-17,-6,21:18.6
-16,-6,21:18.14
-12,-6,21:17.12
-11,-6,21:17.12
3,-6,21:18.6
4,-6,21:18.6
6,-6,21:18.6
11,-6,21:18.6
-27,-5,21:18.6
-26,-5,21:18.6
-22,-5,21:18.6
-20,-5,21:18.6
-19,-5,21:18.6
-18,-5,21:18.6
-17,-5,21:18.6
-16,-5,21:18.14
-6,-5,21:17.12
-5,-5,21:17.12
-4,-5,21:17.12
3,-5,21:18.6
4,-5,21:18.6
10,-5,21:18.6
11,-5,21:18.6
12,-5,21:18.6
-25,-4,21:18.6
-24,-4,21:18.6
-22,-4,21:18.6
-21,-4,21:18.6
-19,-4,21:18.6
-18,-4,21:18.6
-17,-4,21:18.6
-16,-4,21:18.14
-5,-4,21:17.12
-4,-4,21:17.12
-3,-4,21:17.12
4,-4,21:18.6
5,-4,21:18.6
10,-4,21:18.6
11,-4,21:18.6
13,-4,21:18.6
14,-4,21:18.6
-24,-3,21:18.6
-23,-3,21:18.6
-22,-3,21:18.14
-21,-3,21:18.14
-19,-3,21:18.14
-18,-3,21:18.14
-17,-3,21:18.14
-16,-3,21:18.14
-5,-3,21:17.12
-4,-3,21:17.12
-3,-3,21:17.12
4,-3,21:18.14
5,-3,21:18.14
7,-3,21:18.14
8,-3,21:18.14
9,-3,21:18.6
10,-3,21:18.6
11,-3,21:18.6
12,-3,21:18.6
13,-3,21:18.6
-23,-2,21:18.6
-22,-2,21:18.14
-21,-2,21:18.14
-20,-2,21:18.14
-19,-2,21:18.14
-18,-2,21:18.14
-17,-2,21:18.14
-16,-2,21:18.14
-4,-2,21:17.12
-3,-2,21:17.12
3,-2,21:18.14
4,-2,21:18.14
6,-2,21:18.14
7,-2,21:18.14
8,-2,21:18.14
9,-2,21:18.6
10,-2,21:18.6
11,-2,21:18.6
12,-2,21:18.6
-31,-1,21:18.6
-30,-1,21:18.6
-21,-1,21:18.14
-20,-1,21:18.14
-19,-1,21:18.14
-18,-1,21:18.14
-17,-1,21:18.14
-16,-1,21:18.14
-4,-1,21:17.12
-3,-1,21:17.12
3,-1,21:18.14
4,-1,21:18.14
5,-1,21:18.14
6,-1,21:18.14
8,-1,21:18.14
9,-1,21:18.6
11,-1,21:18.6
-30,0,21:18.6
-29,0,21:18.6
-28,0,21:18.6
-21,0,21:18.14
-20,0,21:18.14
-19,0,21:18.14
-18,0,21:18.14
-17,0,21:18.14
-16,0,21:18.14
-4,0,21:17.12
-3,0,21:17.12
3,0,21:18.14
4,0,21:18.14
5,0,21:18.14
6,0,21:18.14
7,0,21:18.14
10,0,21:18.6
-29,1,21:18.6
-28,1,21:18.6
-27,1,21:18.6
-17,1,21:17.12
-16,1,21:18.14
3,1,21:17.12
4,1,21:17.12
5,1,21:18.14
6,1,21:18.14
10,1,21:18.6
-27,2,21:18.6
-26,2,21:18.14
-25,2,21:18.14
-18,2,21:17.12
-17,2,21:17.12
-15,2,21:18.14
3,2,21:17.12
4,2,21:18.14
9,2,21:18.6
-26,3,21:18.14
-25,3,21:18.14
-24,3,21:18.14
-23,3,21:18.14
-17,3,21:17.12
-14,3,21:18.14
-4,3,21:17.12
-3,3,21:17.12
8,3,21:18.14
9,3,21:18.6
-31,4,21:18.6
-30,4,21:18.6
-29,4,21:18.6
-28,4,21:18.6
-27,4,21:18.6
-26,4,21:18.14
-25,4,21:18.14
-22,4,21:18.14
-21,4,21:18.14
-4,4,21:17.12
-3,4,21:17.12
8,4,21:18.14
-26,5,21:18.14
-25,5,21:18.14
-24,5,21:18.14
-23,5,21:18.14
12,5,21:18.6
13,5,21:18.6
14,5,21:18.6
15,5,21:18.6
-24,6,21:18.14
-23,6,21:18.14
-22,6,21:17.12
-27,7,21:18.6
-26,7,21:18.14
-25,7,21:18.14
-29,8,21:18.6
-28,8,21:18.6
-22,8,21:18.14
-22,9,21:18.14
-23,10,21:18.14
-23,11,21:18.6
-22,12,21:18.6
-21,12,21:18.6
-20,12,21:18.14
-23,13,21:18.6
-27,14,21:18.6
-16,14,21:18.14
-18,15,21:18.14
-17,15,21:18.14
-16,15,21:18.14
-18,16,21:18.14
-17,16,21:18.14
-15,16,21:18.14
-14,16,21:18.14
-13,16,21:18.14
-12,16,21:18.14
-11,16,21:18.14
-10,16,21:18.14
7,16,21:18.14
8,16,21:18.14
9,16,21:18.14
10,16,21:18.14
11,16,21:18.14
12,16,21:18.14
-19,17,21:18.14
-18,17,21:18.14
-17,17,21:18.14
-16,17,21:18.14
-9,17,21:18.14
-8,17,21:18.14
-7,17,21:18.14
-2,17,21:17.12
8,17,21:18.14
9,17,21:18.14
10,17,21:18.14
11,17,21:18.14
12,17,21:18.14
-20,18,21:18.6
-18,18,21:18.6
-17,18,21:18.6
-16,18,21:18.6
-15,18,21:18.6
-14,18,21:18.6
-13,18,21:18.14
-12,18,21:18.14
-10,18,21:18.14
-9,18,21:18.14
-2,18,21:17.12
-1,18,21:17.12
0,18,21:17.12
9,18,21:18.14
10,18,21:18.14
11,18,21:18.14
12,18,21:18.14
-11,19,21:18.14
-10,19,21:18.14
-9,19,21:18.14
-8,19,21:17.12
-7,19,21:17.12
-1,19,21:17.12
0,19,21:17.12
1,19,21:17.12
2,19,21:17.12
3,19,21:17.12
7,19,21:18.14
8,19,21:18.14
9,19,21:18.14
12,19,21:18.14
13,19,21:18.6
14,19,21:18.6
15,19,21:18.6
-10,20,21:18.14
-9,20,21:18.14
-8,20,21:18.14
0,20,21:17.12
1,20,21:17.12
2,20,21:17.12
3,20,21:17.12
4,20,21:17.12
5,20,21:18.14
6,20,21:18.14
7,20,21:18.14
8,20,21:18.14
9,20,21:18.14
10,20,21:18.14
11,20,21:18.14
12,20,21:18.14
13,20,21:18.6
14,20,21:18.6
-12,21,21:18.14
-11,21,21:18.14
-9,21,21:18.14
-8,21,21:18.14
-2,21,21:18.14
-1,21,21:18.14
0,21,21:17.12
1,21,21:17.12
3,21,21:18.14
4,21,21:18.14
5,21,21:18.14
6,21,21:18.14
7,21,21:18.14
8,21,21:18.14
10,21,21:18.14
11,21,21:18.14
12,21,21:18.14
13,21,21:18.6
14,21,21:18.6
-10,22,21:18.14
-9,22,21:18.14
-3,22,21:18.14
-2,22,21:18.14
-1,22,21:17.12
0,22,21:17.12
5,22,21:18.14
6,22,21:18.14
7,22,21:18.14
8,22,21:18.14
9,22,21:18.14
-14,23,21:18.6
-11,23,21:18.14
-4,23,21:18.14
-2,23,21:18.14
-1,23,21:18.14
6,23,21:18.14
7,23,21:18.14
9,23,21:18.14
10,23,21:18.14
11,23,21:18.14
12,23,21:18.14
-12,24,21:18.14
-11,24,21:18.14
-3,24,21:18.14
-2,24,21:18.14
-1,24,21:18.14
0,24,21:18.14
7,24,21:18.14
8,24,21:18.14
12,24,21:18.14
-13,25,21:18.6
-12,25,21:18.6
-3,25,21:18.14
-1,25,21:18.14
0,25,21:18.14
9,25,21:18.6
10,25,21:18.6
-14,26,21:18.6
-13,26,21:18.6
-3,26,21:18.14
-2,26,21:18.14
-1,26,21:18.14
0,26,21:18.14
10,26,21:18.6
11,26,21:18.6
-14,27,21:18.6
-4,27,21:18.14
-2,27,21:18.14
0,27,21:18.14
11,27,21:18.6
12,27,21:18.6
-5,28,21:18.14
-2,28,21:18.14
0,28,21:18.14
13,28,21:18.6
-5,29,21:18.14
-3,29,21:18.14
-2,29,21:18.14
1,29,21:18.14
-6,30,21:18.6
-3,30,21:18.6
-2,30,21:18.6
-6,31,21:18.6
-3,31,21:18.6
-2,31,21:18.6
-3,32,21:18.6
-2,32,21:18.6
-3,33,21:18.6
-2,33,21:18.6
-3,34,21:18.6
-2,34,21:18.6
-4,-22,22:18.6
-4,-21,22:18.6
3,-21,22:18.6
-4,-20,22:18.6
3,-20,22:18.6
-4,-19,22:18.6
2,-19,22:18.6
3,-19,22:18.6
-4,-18,22:18.6
2,-18,22:18.6
3,-18,22:18.6
8,-18,22:18.6
-4,-17,22:18.6
1,-17,22:18.6
2,-17,22:18.6
7,-17,22:18.6
-4,-16,22:18.6
1,-16,22:18.6
2,-16,22:18.6
6,-16,22:18.6
-4,-15,22:18.6
0,-15,22:18.6
1,-15,22:18.6
5,-15,22:18.6
-4,-14,22:18.6
0,-14,22:18.6
1,-14,22:18.6
4,-14,22:18.6
-13,-13,22:18.6
-1,-13,22:18.14
0,-13,22:18.14
3,-13,22:18.6
-25,-12,22:18.6
-12,-12,22:18.6
-2,-12,22:18.14
2,-12,22:18.14
-25,-11,22:18.6
-24,-11,22:18.6
-15,-11,22:18.6
-12,-11,22:18.6
-11,-11,22:18.6
-4,-11,22:18.14
-2,-11,22:18.14
-1,-11,22:18.14
1,-11,22:18.14
4,-11,22:18.6
5,-11,22:18.6
-24,-10,22:18.6
-15,-10,22:18.14
-14,-10,22:18.14
-13,-10,22:18.14
-11,-10,22:18.14
-10,-10,22:18.14
-6,-10,22:18.14
-4,-10,22:18.14
-3,-10,22:18.14
-2,-10,22:18.14
-1,-10,22:18.14
0,-10,22:18.14
4,-10,22:18.6
7,-10,22:18.6
-23,-9,22:18.6
-13,-9,22:18.14
-12,-9,22:18.14
-11,-9,22:18.14
-10,-9,22:18.14
-5,-9,22:18.14
-4,-9,22:18.14
-3,-9,22:18.14
-2,-9,22:18.14
-1,-9,22:18.14
4,-9,22:18.6
5,-9,22:18.6
7,-9,22:18.6
-23,-8,22:18.6
-22,-8,22:18.6
-18,-8,22:18.6
-17,-8,22:18.6
-14,-8,22:18.14
-13,-8,22:18.14
-11,-8,22:18.14
-10,-8,22:18.14
-9,-8,22:18.14
-8,-8,22:18.14
-5,-8,22:18.14
-4,-8,22:18.14
-3,-8,22:18.14
-2,-8,22:18.14
4,-8,22:18.6
5,-8,22:18.6
6,-8,22:18.6
-23,-7,22:18.6
-22,-7,22:18.6
-18,-7,22:18.6
-17,-7,22:18.6
-16,-7,22:18.14
-12,-7,22:18.14
-10,-7,22:18.14
-9,-7,22:18.14
-8,-7,22:18.14
-4,-7,22:18.14
-3,-7,22:18.14
4,-7,22:18.6
5,-7,22:18.6
6,-7,22:18.6
-22,-6,22:18.6
-21,-6,22:18.6
-18,-6,22:18.6
-17,-6,22:18.6
-11,-6,22:17.12
-10,-6,22:17.12
-9,-6,22:17.12
-8,-6,22:17.12
-7,-6,22:17.12
-6,-6,22:17.12
-4,-6,22:17.12
-3,-6,22:17.12
4,-6,22:18.6
5,-6,22:18.6
11,-6,22:18.6
14,-6,22:18.6
-21,-5,22:18.6
-18,-5,22:18.6
-17,-5,22:18.6
-12,-5,22:18.14
-11,-5,22:18.14
-10,-5,22:18.14
-9,-5,22:18.14
-8,-5,22:18.14
-7,-5,22:18.14
-6,-5,22:17.12
-5,-5,22:17.12
-4,-5,22:17.12
-3,-5,22:17.12
5,-5,22:18.6
10,-5,22:18.6
12,-5,22:18.6
13,-5,22:18.6
14,-5,22:18.6
15,-5,22:18.6
-25,-4,22:18.6
-24,-4,22:18.6
-21,-4,22:18.6
-20,-4,22:18.6
-18,-4,22:18.6
-17,-4,22:18.6
-14,-4,22:18.14
-13,-4,22:18.14
-5,-4,22:17.12
-4,-4,22:17.12
-3,-4,22:17.12
4,-4,22:18.6
5,-4,22:18.6
8,-4,22:18.6
11,-4,22:18.6
12,-4,22:18.6
13,-4,22:18.6
14,-4,22:18.6
-24,-3,22:18.6
-23,-3,22:18.6
-21,-3,22:18.14
-19,-3,22:18.14
-18,-3,22:18.14
-17,-3,22:18.14
-4,-3,22:17.12
4,-3,22:18.14
7,-3,22:18.14
8,-3,22:18.14
11,-3,22:18.6
12,-3,22:18.6
-22,-2,22:18.14
-21,-2,22:18.14
-20,-2,22:18.14
-19,-2,22:18.14
-18,-2,22:18.14
-17,-2,22:18.14
4,-2,22:18.14
10,-2,22:18.6
11,-2,22:18.6
12,-2,22:18.6
-21,-1,22:18.14
-20,-1,22:18.14
-19,-1,22:18.14
-18,-1,22:18.14
-17,-1,22:18.14
4,-1,22:18.14
5,-1,22:18.14
8,-1,22:18.14
9,-1,22:18.6
11,-1,22:18.6
-31,0,22:18.6
-30,0,22:18.6
-20,0,22:18.14
-19,0,22:18.14
-18,0,22:18.14
-17,0,22:18.14
-16,0,22:18.14
4,0,22:18.14
7,0,22:18.14
8,0,22:18.14
10,0,22:18.6
-30,1,22:18.6
-29,1,22:18.6
-18,1,22:17.12
-17,1,22:17.12
-16,1,22:18.14
5,1,22:18.14
6,1,22:18.14
10,1,22:18.6
-29,2,22:18.6
-28,2,22:18.6
-27,2,22:18.6
-15,2,22:18.14
9,2,22:18.6
-30,3,22:18.6
-29,3,22:18.6
-28,3,22:18.6
-27,3,22:18.6
-26,3,22:18.14
-25,3,22:18.14
-24,3,22:18.14
-23,3,22:18.14
-4,3,22:17.12
8,3,22:18.14
9,3,22:18.6
-31,4,22:18.6
-29,4,22:18.6
-28,4,22:18.6
-27,4,22:18.6
-22,4,22:18.14
-21,4,22:18.14
-5,4,22:17.12
-4,4,22:17.12
-3,4,22:17.12
-27,5,22:18.6
-26,5,22:18.14
-25,5,22:18.14
-24,5,22:18.14
13,5,22:18.6
14,5,22:18.6
12,6,22:18.6
-27,7,22:18.6
-26,7,22:18.14
-25,7,22:18.14
-30,8,22:18.6
-29,8,22:18.6
-28,8,22:18.6
-21,12,22:18.6
-20,12,22:18.14
-24,13,22:18.6
-23,13,22:18.6
-22,13,22:18.6
-25,14,22:18.6
-17,15,22:18.14
-16,15,22:18.14
-17,16,22:18.14
-16,16,22:18.14
-15,16,22:18.14
-14,16,22:18.14
-13,16,22:18.14
-12,16,22:18.14
-11,16,22:18.14
-10,16,22:18.14
8,16,22:18.14
9,16,22:18.14
13,16,22:18.6
14,16,22:18.6
15,16,22:18.6
-17,17,22:18.14
-10,17,22:18.14
-9,17,22:18.14
-8,17,22:18.14
-7,17,22:18.14
10,17,22:18.14
11,17,22:18.14
12,17,22:18.14
13,17,22:18.6
-18,18,22:18.6
-17,18,22:18.6
-16,18,22:18.6
-15,18,22:18.6
-14,18,22:18.6
9,18,22:18.14
10,18,22:18.14
11,18,22:18.14
12,18,22:18.14
-16,19,22:18.6
-15,19,22:18.6
-14,19,22:18.6
-12,19,22:18.14
-11,19,22:18.14
-10,19,22:18.14
-9,19,22:18.14
-8,19,22:17.12
0,19,22:17.12
1,19,22:17.12
7,19,22:18.14
8,19,22:18.14
9,19,22:18.14
10,19,22:18.14
11,19,22:18.14
12,19,22:18.14
13,19,22:18.6
14,19,22:18.6
15,19,22:18.6
-11,20,22:18.14
-10,20,22:18.14
-9,20,22:17.12
-8,20,22:17.12
0,20,22:17.12
1,20,22:17.12
5,20,22:17.12
6,20,22:17.12
7,20,22:17.12
8,20,22:18.14
9,20,22:18.14
-13,21,22:18.14
-12,21,22:18.14
-9,21,22:18.14
-8,21,22:18.14
-1,21,22:18.14
0,21,22:17.12
4,21,22:18.14
6,21,22:18.14
7,21,22:18.14
8,21,22:18.14
-14,22,22:18.6
-13,22,22:18.14
-10,22,22:18.14
-9,22,22:18.14
-2,22,22:18.14
-1,22,22:17.12
0,22,22:17.12
5,22,22:18.14
8,22,22:18.14
9,22,22:18.14
10,22,22:18.14
11,22,22:18.14
12,22,22:18.14
13,22,22:18.6
14,22,22:18.6
-15,23,22:18.6
-14,23,22:18.6
-11,23,22:18.14
-10,23,22:18.14
-3,23,22:18.14
-2,23,22:17.12
-1,23,22:17.12
6,23,22:18.14
7,23,22:18.14
11,23,22:18.14
12,23,22:18.14
13,23,22:18.6
14,23,22:18.6
-12,24,22:18.14
-11,24,22:18.14
-4,24,22:18.14
-3,24,22:18.14
-2,24,22:18.14
-1,24,22:17.12
7,24,22:18.14
8,24,22:18.14
14,24,22:18.6
-12,25,22:18.6
-3,25,22:18.14
-1,25,22:18.14
9,25,22:18.6
10,25,22:18.6
-14,26,22:18.6
-13,26,22:18.6
-3,26,22:18.14
-2,26,22:18.14
0,26,22:18.14
10,26,22:18.6
11,26,22:18.6
-3,27,22:18.14
-2,27,22:18.14
0,27,22:18.14
12,27,22:18.6
-4,28,22:18.14
-3,28,22:18.14
-2,28,22:18.14
0,28,22:18.14
13,28,22:18.6
-5,29,22:18.14
-3,29,22:18.14
-2,29,22:18.14
1,29,22:18.14
-5,30,22:18.6
-3,30,22:18.6
-2,30,22:18.6
1,30,22:18.6
2,30,22:18.6
-6,31,22:18.6
-4,31,22:18.6
-3,31,22:18.6
-2,31,22:18.6
1,31,22:18.6
2,31,22:18.6
3,31,22:18.6
-6,32,22:18.6
-4,32,22:18.6
-3,32,22:18.6
-2,32,22:18.6
2,32,22:18.6
-4,33,22:18.6
-2,33,22:18.6
2,33,22:18.6
-2,34,22:18.6
-2,35,22:18.6
-2,36,22:18.6
-4,-21,23:18.6
5,-20,23:18.6
6,-20,23:18.6
-4,-19,23:18.6
4,-19,23:18.6
5,-19,23:18.6
9,-19,23:18.6
-4,-18,23:18.6
3,-18,23:18.6
4,-18,23:18.6
8,-18,23:18.6
-11,-17,23:18.6
-10,-17,23:18.6
-4,-17,23:18.6
3,-17,23:18.6
4,-17,23:18.6
5,-17,23:18.6
6,-17,23:18.6
7,-17,23:18.6
-10,-16,23:18.6
-9,-16,23:18.6
-4,-16,23:18.6
2,-16,23:18.6
3,-16,23:18.6
5,-16,23:18.6
6,-16,23:18.6
-9,-15,23:18.6
-4,-15,23:18.6
2,-15,23:18.6
3,-15,23:18.6
5,-15,23:18.6
-4,-14,23:18.6
1,-14,23:18.6
2,-14,23:18.6
3,-14,23:18.6
4,-14,23:18.6
-13,-13,23:18.6
-8,-13,23:18.6
-7,-13,23:18.14
1,-13,23:18.14
2,-13,23:18.14
3,-13,23:18.6
6,-13,23:18.6
8,-13,23:18.6
-13,-12,23:18.6
-7,-12,23:18.14
-4,-12,23:18.14
0,-12,23:18.14
1,-12,23:18.14
2,-12,23:18.14
6,-12,23:18.6
7,-12,23:18.6
-15,-11,23:18.6
-14,-11,23:18.6
-13,-11,23:18.6
-12,-11,23:18.6
-6,-11,23:18.14
-4,-11,23:18.14
0,-11,23:18.14
1,-11,23:18.14
6,-11,23:18.6
7,-11,23:18.6
-24,-10,23:18.6
-13,-10,23:18.14
-12,-10,23:18.14
-11,-10,23:18.14
-6,-10,23:18.14
-5,-10,23:18.14
-4,-10,23:18.14
-1,-10,23:18.14
0,-10,23:18.14
5,-10,23:18.6
6,-10,23:18.6
7,-10,23:18.6
-23,-9,23:18.6
-17,-9,23:18.6
-11,-9,23:18.14
-10,-9,23:18.14
-5,-9,23:18.14
-4,-9,23:18.14
-3,-9,23:17.12
-2,-9,23:18.14
-1,-9,23:18.14
5,-9,23:18.6
-23,-8,23:18.6
-17,-8,23:18.6
-15,-8,23:18.14
-14,-8,23:18.14
-10,-8,23:18.14
-9,-8,23:18.14
-4,-8,23:18.14
-3,-8,23:17.12
-2,-8,23:18.14
5,-8,23:18.6
6,-8,23:18.6
-22,-7,23:18.6
-17,-7,23:18.6
-14,-7,23:18.14
-13,-7,23:18.14
-12,-7,23:18.14
-9,-7,23:18.14
-8,-7,23:18.14
-4,-7,23:18.14
-3,-7,23:18.14
5,-7,23:18.6
6,-7,23:18.6
12,-7,23:18.6
-22,-6,23:18.6
-21,-6,23:18.6
-18,-6,23:18.6
-17,-6,23:18.6
-11,-6,23:18.14
-10,-6,23:18.14
-9,-6,23:18.14
-8,-6,23:17.12
-7,-6,23:17.12
-4,-6,23:17.12
-3,-6,23:17.12
5,-6,23:18.6
6,-6,23:18.6
10,-6,23:18.6
11,-6,23:18.6
-26,-5,23:18.6
-21,-5,23:18.6
-18,-5,23:18.6
-17,-5,23:18.6
-14,-5,23:18.14
-13,-5,23:18.14
-12,-5,23:18.14
-11,-5,23:18.14
-10,-5,23:18.14
-9,-5,23:18.14
-8,-5,23:18.14
-7,-5,23:18.14
5,-5,23:18.6
9,-5,23:18.6
10,-5,23:18.6
13,-5,23:18.6
14,-5,23:18.6
15,-5,23:18.6
16,-5,23:18.6
-26,-4,23:18.6
-25,-4,23:18.6
-20,-4,23:18.6
-18,-4,23:18.6
-17,-4,23:18.6
-16,-4,23:18.14
-15,-4,23:18.14
-14,-4,23:18.14
-8,-4,23:18.14
5,-4,23:18.6
8,-4,23:18.6
13,-4,23:18.6
14,-4,23:18.6
-24,-3,23:18.6
-23,-3,23:18.6
-19,-3,23:18.14
-18,-3,23:18.14
-17,-3,23:18.14
4,-3,23:18.14
5,-3,23:18.14
7,-3,23:18.14
8,-3,23:18.14
12,-3,23:18.6
-23,-2,23:18.6
-22,-2,23:18.14
-19,-2,23:18.14
-18,-2,23:18.14
-17,-2,23:18.14
4,-2,23:18.14
5,-2,23:18.14
6,-2,23:18.14
10,-2,23:18.6
11,-2,23:18.6
-21,-1,23:18.14
-20,-1,23:18.14
-17,-1,23:18.14
5,-1,23:18.14
9,-1,23:18.6
11,-1,23:18.6
-16,0,23:18.14
4,0,23:18.14
7,0,23:18.14
8,0,23:18.14
10,0,23:18.6
-33,1,23:18.6
-32,1,23:18.6
-31,1,23:18.6
-16,1,23:18.14
6,1,23:18.14
10,1,23:18.6
-30,2,23:18.6
-29,2,23:18.6
-15,2,23:18.14
9,2,23:18.6
-33,3,23:18.6
-32,3,23:18.6
-31,3,23:18.6
-30,3,23:18.6
-28,3,23:18.6
-27,3,23:18.6
-26,3,23:18.14
-25,3,23:18.14
-24,3,23:18.14
-22,4,23:18.14
-21,4,23:18.14
-5,4,23:17.12
-4,4,23:17.12
-27,5,23:18.6
-26,5,23:18.14
-5,5,23:17.12
-28,8,23:18.6
-20,12,23:18.14
-13,16,23:18.14
-12,16,23:18.14
-11,16,23:18.14
-10,16,23:18.14
-10,17,23:18.14
-9,17,23:18.14
-8,17,23:18.14
13,17,23:18.6
14,17,23:18.6
15,17,23:18.6
16,17,23:18.6
11,18,23:18.14
12,18,23:18.14
13,18,23:18.6
14,18,23:18.6
15,18,23:18.6
16,18,23:18.6
-18,19,23:18.6
-17,19,23:18.6
-16,19,23:18.6
-15,19,23:18.6
-14,19,23:18.6
-12,19,23:18.14
-11,19,23:18.14
-10,19,23:18.14
-9,19,23:18.14
9,19,23:18.14
10,19,23:18.14
11,19,23:18.14
12,19,23:18.14
-13,20,23:18.14
-12,20,23:18.14
-11,20,23:18.14
-10,20,23:18.14
-9,20,23:17.12
8,20,23:17.12
-14,21,23:18.6
-13,21,23:18.14
-12,21,23:18.14
-11,21,23:18.14
-10,21,23:18.14
-9,21,23:18.14
8,21,23:18.14
-15,22,23:18.6
-14,22,23:18.6
-11,22,23:18.14
-10,22,23:18.14
-9,22,23:18.14
-2,22,23:18.14
-1,22,23:18.14
5,22,23:18.14
6,22,23:18.14
9,22,23:18.14
10,22,23:18.14
11,22,23:18.14
-17,23,23:18.6
-16,23,23:18.6
-12,23,23:18.14
-11,23,23:18.14
-10,23,23:18.14
-3,23,23:18.14
-2,23,23:18.14
7,23,23:18.14
12,23,23:18.14
13,23,23:18.6
14,23,23:18.6
-12,24,23:18.14
-11,24,23:18.14
-2,24,23:17.12
-1,24,23:17.12
8,24,23:18.14
15,24,23:18.6
-2,25,23:17.12
-1,25,23:18.14
9,25,23:18.6
10,25,23:18.6
-3,26,23:18.14
-2,26,23:18.14
-1,26,23:18.14
0,26,23:18.14
10,26,23:18.6
11,26,23:18.6
-3,27,23:18.14
-2,27,23:18.14
-1,27,23:18.14
0,27,23:18.14
-4,28,23:18.14
-3,28,23:18.14
-2,28,23:18.14
-1,28,23:18.14
0,28,23:18.14
-4,29,23:18.14
-2,29,23:18.14
-1,29,23:18.14
0,29,23:18.14
1,29,23:18.14
-5,30,23:18.6
-4,30,23:18.6
-1,30,23:18.6
0,30,23:18.6
1,30,23:18.6
-6,31,23:18.6
-5,31,23:18.6
-4,31,23:18.6
-1,31,23:18.6
0,31,23:18.6
1,31,23:18.6
-6,32,23:18.6
-5,32,23:18.6
-4,32,23:18.6
-1,32,23:18.6
0,32,23:18.6
1,32,23:18.6
-6,33,23:18.6
-5,33,23:18.6
-1,33,23:18.6
1,33,23:18.6
2,33,23:18.6
-1,34,23:18.6
1,34,23:18.6
-1,35,23:18.6
1,35,23:18.6
-1,36,23:18.6
-1,37,23:18.6
-5,-22,24:18.6
8,-21,24:18.14
-5,-20,24:18.6
7,-20,24:18.6
10,-20,24:18.14
-4,-19,24:18.6
6,-19,24:18.6
7,-19,24:18.6
9,-19,24:18.14
-9,-18,24:18.6
-5,-18,24:18.6
-4,-18,24:18.6
5,-18,24:18.6
6,-18,24:18.6
7,-18,24:18.6
8,-18,24:18.6
-9,-17,24:18.6
-4,-17,24:18.6
4,-17,24:18.6
5,-17,24:18.6
6,-17,24:18.6
7,-17,24:18.6
-9,-16,24:18.6
-8,-16,24:18.6
-4,-16,24:18.6
4,-16,24:18.6
5,-16,24:18.6
6,-16,24:18.6
-8,-15,24:18.6
-7,-15,24:18.6
-4,-15,24:18.6
4,-15,24:18.6
5,-15,24:18.6
-15,-14,24:18.6
-7,-14,24:18.6
-6,-14,24:18.6
3,-14,24:18.6
4,-14,24:18.6
7,-14,24:18.6
-15,-13,24:18.6
-14,-13,24:18.6
-6,-13,24:18.14
-4,-13,24:18.14
2,-13,24:18.14
3,-13,24:18.6
7,-13,24:18.6
-15,-12,24:18.6
-14,-12,24:18.6
-13,-12,24:18.6
-5,-12,24:18.14
-4,-12,24:18.14
0,-12,24:18.14
1,-12,24:18.14
2,-12,24:18.14
7,-12,24:18.6
-13,-11,24:18.6
-12,-11,24:18.6
-5,-11,24:18.14
-4,-11,24:18.14
-1,-11,24:18.14
0,-11,24:18.14
1,-11,24:18.14
-12,-10,24:18.14
-11,-10,24:18.14
-4,-10,24:18.14
-2,-10,24:18.14
-1,-10,24:18.14
0,-10,24:18.14
6,-10,24:18.6
-17,-9,24:18.6
-11,-9,24:18.14
-10,-9,24:18.14
-4,-9,24:18.14
-3,-9,24:17.12
-2,-9,24:17.12
-1,-9,24:18.14
-23,-8,24:18.6
-17,-8,24:18.6
-10,-8,24:18.14
-9,-8,24:18.14
-3,-8,24:17.12
6,-8,24:18.6
7,-8,24:18.6
-22,-7,24:18.6
-17,-7,24:18.6
-15,-7,24:18.14
-14,-7,24:18.14
-13,-7,24:18.14
5,-7,24:18.6
6,-7,24:18.6
-22,-6,24:18.6
-17,-6,24:18.6
-13,-6,24:18.14
-12,-6,24:18.14
-11,-6,24:18.14
-10,-6,24:18.14
5,-6,24:18.6
6,-6,24:18.6
10,-6,24:18.6
14,-6,24:18.6
-21,-5,24:18.6
-19,-5,24:18.6
-17,-5,24:18.6
-16,-5,24:18.14
-15,-5,24:18.14
-14,-5,24:18.14
-13,-5,24:18.14
-11,-5,24:18.14
-10,-5,24:18.14
-9,-5,24:18.14
5,-5,24:18.6
6,-5,24:18.6
9,-5,24:18.6
10,-5,24:18.6
14,-5,24:18.6
-25,-4,24:18.6
-21,-4,24:18.6
-20,-4,24:18.6
-19,-4,24:18.6
-17,-4,24:18.6
-10,-4,24:18.14
-9,-4,24:18.14
-8,-4,24:18.14
4,-4,24:18.6
6,-4,24:18.6
8,-4,24:18.6
13,-4,24:18.6
14,-4,24:18.6
-24,-3,24:18.6
-23,-3,24:18.6
-19,-3,24:18.14
-17,-3,24:18.14
-8,-3,24:18.14
4,-3,24:18.14
6,-3,24:18.14
7,-3,24:18.14
12,-3,24:18.6
-23,-2,24:18.6
-22,-2,24:18.14
-19,-2,24:18.14
-18,-2,24:18.14
-17,-2,24:18.14
-12,-2,24:18.14
-8,-2,24:18.14
4,-2,24:18.14
6,-2,24:18.14
10,-2,24:18.6
11,-2,24:18.6
-17,-1,24:18.14
-15,-1,24:18.14
-14,-1,24:18.14
-11,-1,24:18.6
-7,-1,24:18.14
5,-1,24:18.14
9,-1,24:18.6
10,-1,24:18.6
-17,0,24:18.14
-16,0,24:18.14
-10,0,24:18.14
-9,0,24:18.14
-7,0,24:18.14
7,0,24:18.14
8,0,24:18.14
10,0,24:18.6
-33,1,24:18.6
-16,1,24:18.14
-8,1,24:18.14
-7,1,24:18.14
7,1,24:18.14
10,1,24:18.6
-33,2,24:18.6
-32,2,24:18.6
-31,2,24:18.6
-30,2,24:18.6
-7,2,24:18.14
-6,2,24:18.14
9,2,24:18.6
-29,3,24:18.6
-28,3,24:18.6
-27,3,24:18.6
-25,3,24:18.14
-6,3,24:17.12
-5,3,24:17.12
-24,4,24:18.14
-23,4,24:18.14
-22,4,24:18.14
-21,4,24:18.14
-6,4,24:17.12
-5,4,24:17.12
-15,16,24:18.6
-14,16,24:18.6
-13,16,24:18.14
-12,16,24:18.14
-11,16,24:18.14
-10,17,24:18.14
-9,17,24:18.14
16,17,24:18.6
17,17,24:18.6
12,18,24:18.14
13,18,24:18.6
14,18,24:18.6
15,18,24:18.6
-17,19,24:18.6
-10,19,24:18.14
-9,19,24:18.14
10,19,24:18.14
11,19,24:18.14
-17,20,24:18.6
-16,20,24:18.6
-15,20,24:18.6
-14,20,24:18.6
-13,20,24:18.14
-12,20,24:18.14
-11,20,24:18.14
-16,21,24:18.6
-15,21,24:18.6
-14,21,24:18.6
-13,21,24:18.14
-12,21,24:18.14
-11,21,24:18.14
-10,21,24:18.14
8,21,24:18.14
-17,22,24:18.6
-16,22,24:18.6
-15,22,24:18.6
-14,22,24:18.6
-13,22,24:18.14
-12,22,24:18.14
-11,22,24:18.14
6,22,24:18.14
8,22,24:18.14
9,22,24:18.14
10,22,24:18.14
11,22,24:18.14
-17,23,24:18.6
-13,23,24:18.14
-12,23,24:18.14
-10,23,24:18.14
6,23,24:18.14
7,23,24:18.14
12,23,24:18.14
13,23,24:18.6
14,23,24:18.6
-13,24,24:18.14
-12,24,24:18.14
-11,24,24:18.14
8,24,24:18.14
-12,25,24:18.6
-2,25,24:17.12
9,25,24:18.6
10,25,24:18.6
-13,26,24:18.6
-3,26,24:18.14
-2,26,24:17.12
10,26,24:18.6
-3,27,24:18.14
-1,27,24:18.14
-4,28,24:18.14
-1,28,24:18.14
-4,29,24:18.14
-1,29,24:18.14
-5,30,24:18.6
-4,30,24:18.6
-1,30,24:18.6
-5,31,24:18.6
-1,31,24:18.6
-5,32,24:18.6
-1,32,24:18.6
0,32,24:18.6
-6,33,24:18.6
-5,33,24:18.6
-1,33,24:18.6
0,33,24:18.6
-6,34,24:18.6
-1,34,24:18.6
0,34,24:18.6
-1,35,24:18.6
0,35,24:18.6
1,35,24:18.6
1,36,24:18.6
0,37,24:18.6
1,37,24:18.6
0,38,24:18.6
1,38,24:18.6
-5,-22,25:18.6
-11,-21,25:18.6
8,-21,25:18.14
-10,-20,25:18.6
8,-20,25:18.14
9,-20,25:18.14
-10,-19,25:18.6
-9,-19,25:18.6
-5,-19,25:18.6
-9,-18,25:18.6
-8,-18,25:18.6
-5,-18,25:18.6
5,-18,25:18.6
7,-18,25:18.6
-8,-17,25:18.6
-7,-17,25:18.6
-5,-17,25:18.6
4,-17,25:18.6
6,-17,25:18.6
-8,-16,25:18.6
-7,-16,25:18.6
-5,-16,25:18.6
3,-16,25:18.6
5,-16,25:18.6
6,-16,25:18.6
-7,-15,25:18.6
-6,-15,25:18.6
-5,-15,25:18.6
2,-15,25:18.6
4,-15,25:18.6
5,-15,25:18.6
-16,-14,25:18.6
-15,-14,25:18.6
-5,-14,25:18.6
1,-14,25:18.6
2,-14,25:18.6
3,-14,25:18.6
4,-14,25:18.6
7,-14,25:18.6
-15,-13,25:18.6
-5,-13,25:18.14
-4,-13,25:18.14
-3,-13,25:18.14
0,-13,25:18.14
2,-13,25:18.14
3,-13,25:18.6
7,-13,25:18.6
-14,-12,25:18.6
-4,-12,25:18.14
-3,-12,25:18.14
-1,-12,25:18.14
0,-12,25:18.14
2,-12,25:18.14
7,-12,25:18.6
-13,-11,25:18.6
-12,-11,25:18.6
-4,-11,25:18.14
-3,-11,25:18.14
-2,-11,25:18.14
-1,-11,25:18.14
0,-11,25:18.14
1,-11,25:18.14
6,-11,25:18.6
-12,-10,25:18.14
-4,-10,25:18.14
-3,-10,25:18.14
-2,-10,25:18.14
0,-10,25:18.14
6,-10,25:18.6
7,-10,25:18.6
-24,-9,25:18.6
-11,-9,25:18.14
-3,-9,25:18.14
-2,-9,25:17.12
7,-9,25:18.6
-10,-8,25:18.14
-9,-8,25:18.14
6,-8,25:18.6
7,-8,25:18.6
-23,-7,25:18.6
-22,-7,25:18.6
-16,-7,25:18.14
-15,-7,25:18.14
5,-7,25:18.6
7,-7,25:18.6
11,-7,25:18.6
-22,-6,25:18.6
-20,-6,25:18.6
-17,-6,25:18.6
-15,-6,25:18.14
-14,-6,25:18.14
-13,-6,25:18.14
-12,-6,25:18.14
-11,-6,25:18.14
-10,-6,25:18.14
-9,-6,25:18.14
5,-6,25:18.6
7,-6,25:18.6
10,-6,25:18.6
-21,-5,25:18.6
-20,-5,25:18.6
-17,-5,25:18.6
-16,-5,25:18.14
-15,-5,25:18.14
-12,-5,25:18.14
-11,-5,25:18.14
-10,-5,25:18.14
-9,-5,25:18.14
5,-5,25:18.6
7,-5,25:18.6
8,-5,25:18.6
9,-5,25:18.6
-21,-4,25:18.6
-20,-4,25:18.6
-19,-4,25:18.6
-17,-4,25:18.6
-13,-4,25:18.14
-11,-4,25:18.14
-9,-4,25:18.14
4,-4,25:18.6
7,-4,25:18.6
8,-4,25:18.6
13,-4,25:18.6
-24,-3,25:18.6
-19,-3,25:18.14
-17,-3,25:18.14
-13,-3,25:18.14
-12,-3,25:18.14
-11,-3,25:18.14
-10,-3,25:18.14
-9,-3,25:18.14
-8,-3,25:18.14
4,-3,25:18.14
6,-3,25:18.14
7,-3,25:18.14
-18,-2,25:18.14
-14,-2,25:18.14
-12,-2,25:18.14
-11,-2,25:18.14
-10,-2,25:18.14
-8,-2,25:18.14
6,-2,25:18.14
11,-2,25:18.6
12,-2,25:18.6
-17,-1,25:18.14
-14,-1,25:18.14
-13,-1,25:18.14
-12,-1,25:18.6
-11,-1,25:18.6
-10,-1,25:18.14
-9,-1,25:18.14
-8,-1,25:18.14
5,-1,25:18.14
9,-1,25:18.6
10,-1,25:18.6
11,-1,25:18.6
-17,0,25:18.14
-11,0,25:18.6
-10,0,25:18.14
-9,0,25:18.14
-8,0,25:18.14
-7,0,25:18.14
4,0,25:18.14
8,0,25:18.14
10,0,25:18.6
-16,1,25:18.14
-9,1,25:18.14
-8,1,25:18.14
-7,1,25:18.14
10,1,25:18.6
-34,2,25:18.6
-32,2,25:18.6
-31,2,25:18.6
-16,2,25:18.14
-14,2,25:18.14
-10,2,25:18.14
-9,2,25:18.14
-8,2,25:18.14
-7,2,25:18.14
-6,2,25:18.14
-30,3,25:18.6
-29,3,25:18.6
-28,3,25:18.6
-27,3,25:18.6
-26,3,25:18.14
-7,3,25:18.14
-6,3,25:18.14
-25,4,25:18.14
-24,4,25:18.14
-23,4,25:18.14
-22,4,25:18.14
-15,16,25:18.6
-13,16,25:18.14
-12,16,25:18.14
-11,16,25:18.14
16,17,25:18.6
12,18,25:18.14
13,18,25:18.6
14,18,25:18.6
15,18,25:18.6
-9,19,25:18.14
10,19,25:18.14
11,19,25:18.14
-19,20,25:18.6
-18,20,25:18.6
-17,20,25:18.6
-15,20,25:18.6
-14,20,25:18.6
-13,20,25:18.14
-12,20,25:18.14
-11,20,25:18.14
-10,20,25:18.14
-16,21,25:18.6
-15,21,25:18.6
-11,21,25:18.14
-10,21,25:18.14
-18,22,25:18.6
-17,22,25:18.6
-14,22,25:18.6
-13,22,25:18.14
-12,22,25:18.14
-11,22,25:18.14
9,22,25:18.14
10,22,25:18.14
11,22,25:18.14
-14,23,25:18.6
-13,23,25:18.14
7,23,25:18.14
12,23,25:18.14
-14,24,25:18.6
-13,24,25:18.14
-11,24,25:18.14
8,24,25:18.14
9,24,25:18.14
9,25,25:18.6
10,25,25:18.6
-3,26,25:18.14
-2,26,25:17.12
11,26,25:18.6
-3,27,25:18.14
-2,27,25:17.12
12,27,25:18.6
-4,28,25:18.14
-1,28,25:18.14
-4,29,25:18.14
-1,29,25:18.14
-5,30,25:18.6
-4,30,25:18.6
-1,30,25:18.6
-5,31,25:18.6
-1,31,25:18.6
-5,32,25:18.6
-1,32,25:18.6
-6,33,25:18.6
-1,33,25:18.6
-6,34,25:18.6
0,34,25:18.6
0,35,25:18.6
0,36,25:18.6
0,37,25:18.6
0,39,25:18.6
-5,-22,26:18.6
-9,-21,26:18.6
-8,-20,26:18.6
-5,-20,26:18.6
9,-20,26:18.14
-8,-19,26:18.6
-5,-19,26:18.6
8,-19,26:18.6
9,-19,26:18.14
-8,-18,26:18.6
-7,-18,26:18.6
-5,-18,26:18.6
4,-18,26:18.6
7,-18,26:18.6
-7,-17,26:18.6
-6,-17,26:18.6
-5,-17,26:18.6
3,-17,26:18.6
4,-17,26:18.6
6,-17,26:18.6
7,-17,26:18.6
-6,-16,26:18.6
-5,-16,26:18.6
3,-16,26:18.6
5,-16,26:18.6
6,-16,26:18.6
-5,-15,26:18.6
-2,-15,26:18.6
2,-15,26:18.6
5,-15,26:18.6
-5,-14,26:18.6
-2,-14,26:18.6
1,-14,26:18.6
-15,-13,26:18.6
-5,-13,26:18.14
-4,-13,26:18.14
-2,-13,26:18.14
2,-13,26:18.14
3,-13,26:18.6
-14,-12,26:18.6
-4,-12,26:18.14
-2,-12,26:18.14
-1,-12,26:18.14
2,-12,26:18.14
-13,-11,26:18.6
-4,-11,26:18.14
-2,-11,26:18.14
-1,-11,26:18.14
1,-11,26:18.14
-12,-10,26:18.14
-4,-10,26:18.14
-2,-10,26:18.14
0,-10,26:18.14
-11,-9,26:18.14
-2,-9,26:17.12
8,-9,26:18.6
-23,-8,26:18.6
-10,-8,26:18.14
6,-8,26:18.6
8,-8,26:18.6
-22,-7,26:18.6
-17,-7,26:18.6
-16,-7,26:18.6
5,-7,26:18.6
8,-7,26:18.6
11,-7,26:18.6
-22,-6,26:18.6
-17,-6,26:18.6
-16,-6,26:18.6
-15,-6,26:18.14
-14,-6,26:18.14
-13,-6,26:18.14
-12,-6,26:18.14
-10,-6,26:18.14
5,-6,26:18.6
8,-6,26:18.6
9,-6,26:18.6
10,-6,26:18.6
-21,-5,26:18.6
-20,-5,26:18.6
-17,-5,26:18.6
-12,-5,26:18.14
-11,-5,26:18.14
-10,-5,26:18.14
-9,-5,26:18.14
5,-5,26:18.6
8,-5,26:18.6
9,-5,26:18.6
-21,-4,26:18.6
-20,-4,26:18.6
-19,-4,26:18.6
-12,-4,26:18.14
-11,-4,26:18.14
-10,-4,26:18.14
-9,-4,26:18.14
7,-4,26:18.6
8,-4,26:18.6
-19,-3,26:18.14
-16,-3,26:18.14
-15,-3,26:18.14
-14,-3,26:18.14
-12,-3,26:18.14
-11,-3,26:18.14
-10,-3,26:18.14
-9,-3,26:18.14
6,-3,26:18.6
7,-3,26:18.6
-14,-2,26:18.14
-13,-2,26:18.14
-12,-2,26:18.14
-11,-2,26:18.14
-10,-2,26:18.14
-9,-2,26:18.14
6,-2,26:18.6
-17,-1,26:18.14
-12,-1,26:18.6
-11,-1,26:18.6
-10,-1,26:18.14
-9,-1,26:18.14
-8,-1,26:18.14
5,-1,26:18.6
-17,0,26:18.14
-10,0,26:18.14
-9,0,26:18.14
-8,0,26:18.14
-16,1,26:18.14
-14,1,26:18.14
-13,1,26:18.14
-12,1,26:18.6
-9,1,26:18.14
-8,1,26:18.14
-7,1,26:18.14
-33,2,26:18.6
-32,2,26:18.6
-15,2,26:18.14
-14,2,26:18.14
-11,2,26:18.6
-9,2,26:18.14
-8,2,26:18.14
-7,2,26:18.14
-28,3,26:18.6
-27,3,26:18.6
-26,4,26:18.6
-25,4,26:18.6
-24,4,26:18.6
12,18,26:18.14
13,18,26:18.6
14,18,26:18.6
11,19,26:18.14
-14,20,26:18.6
-13,20,26:18.14
-12,20,26:18.14
-11,20,26:18.14
-10,20,26:18.14
-19,21,26:18.6
-18,21,26:18.6
-17,21,26:18.6
-15,21,26:18.6
-11,21,26:18.14
-10,21,26:18.14
-19,22,26:18.6
-18,22,26:18.6
-13,22,26:18.14
-12,22,26:18.14
-11,22,26:18.14
10,22,26:18.14
11,22,26:18.14
-15,23,26:18.6
-14,23,26:18.6
-13,23,26:18.14
13,23,26:18.6
-15,24,26:18.6
-14,24,26:18.6
9,24,26:18.14
10,25,26:18.6
-3,27,26:18.14
-4,28,26:18.14
-1,28,26:18.14
-1,29,26:18.14
-5,30,26:18.6
-1,30,26:18.6
-5,31,26:18.6
-1,31,26:18.6
-5,32,26:18.6
-1,32,26:18.6
-6,33,26:18.6
-1,33,26:18.6
0,34,26:18.6
0,35,26:18.6
0,36,26:18.6
0,37,26:18.6
0,38,26:18.6
-5,-22,27:18.6
-8,-21,27:18.6
-2,-21,27:18.6
7,-21,27:18.6
-7,-20,27:18.6
-5,-20,27:18.6
-2,-20,27:18.6
6,-20,27:18.6
9,-20,27:18.14
-7,-19,27:18.6
-6,-19,27:18.6
-5,-19,27:18.6
-2,-19,27:18.6
5,-19,27:18.6
8,-19,27:18.6
9,-19,27:18.6
-6,-18,27:18.6
-5,-18,27:18.6
-2,-18,27:18.6
4,-18,27:18.6
5,-18,27:18.6
8,-18,27:18.6
-6,-17,27:18.6
-5,-17,27:18.6
-2,-17,27:18.6
3,-17,27:18.6
4,-17,27:18.6
7,-17,27:18.6
-5,-16,27:18.6
-2,-16,27:18.6
2,-16,27:18.6
3,-16,27:18.6
5,-16,27:18.6
6,-16,27:18.6
-5,-15,27:18.6
-2,-15,27:18.6
2,-15,27:18.6
5,-15,27:18.6
-5,-14,27:18.6
1,-14,27:18.6
4,-14,27:18.6
-4,-13,27:18.14
-1,-13,27:18.14
0,-13,27:18.14
3,-13,27:18.6
-4,-12,27:18.14
-1,-12,27:18.14
2,-12,27:18.14
-13,-11,27:18.6
-4,-11,27:18.14
-2,-11,27:18.14
1,-11,27:18.14
-12,-10,27:18.14
-4,-10,27:18.14
-2,-10,27:18.14
-11,-9,27:18.14
9,-8,27:18.6
5,-7,27:18.6
8,-7,27:18.6
9,-7,27:18.6
10,-7,27:18.6
-18,-6,27:18.6
-17,-6,27:18.6
-16,-6,27:18.6
-15,-6,27:18.6
-14,-6,27:18.6
-13,-6,27:18.6
-11,-6,27:18.14
8,-6,27:18.6
9,-6,27:18.6
10,-6,27:18.6
-22,-5,27:18.6
-14,-5,27:18.6
-13,-5,27:18.6
-12,-5,27:18.14
-11,-5,27:18.14
-10,-5,27:18.14
5,-5,27:18.6
8,-5,27:18.6
-15,-4,27:18.6
-14,-4,27:18.6
-13,-4,27:18.6
-12,-4,27:18.14
-11,-4,27:18.14
-10,-4,27:18.14
7,-4,27:18.6
8,-4,27:18.6
-14,-3,27:18.6
-13,-3,27:18.6
-12,-3,27:18.14
-11,-3,27:18.14
-10,-3,27:18.14
-9,-3,27:18.14
6,-3,27:18.6
7,-3,27:18.6
-18,-2,27:18.6
-12,-2,27:18.14
-11,-2,27:18.14
-9,-2,27:18.14
5,-2,27:18.6
6,-2,27:18.6
-18,-1,27:18.6
-11,-1,27:18.6
-10,-1,27:18.14
-9,-1,27:18.14
-8,-1,27:18.14
5,-1,27:18.6
-10,0,27:18.14
-9,0,27:18.14
-8,0,27:18.14
-15,1,27:18.6
-14,1,27:18.6
-13,1,27:18.6
-12,1,27:18.6
-11,1,27:18.6
-10,1,27:18.14
-9,1,27:18.14
-8,1,27:18.14
-8,2,27:18.14
-30,3,27:18.6
-29,3,27:18.6
-28,3,27:18.6
-26,4,27:18.6
-25,4,27:18.6
12,18,27:18.14
13,18,27:18.6
-14,20,27:18.6
-13,20,27:18.14
-12,20,27:18.14
-11,20,27:18.14
-19,21,27:18.6
-18,21,27:18.6
-17,21,27:18.6
-16,21,27:18.6
-15,21,27:18.6
-14,21,27:18.6
-12,22,27:18.14
-11,22,27:18.14
-14,23,27:18.6
-13,23,27:18.14
-3,27,27:18.14
-4,28,27:18.14
-4,29,27:18.14
-1,29,27:18.14
-5,30,27:18.6
-1,30,27:18.6
-5,31,27:18.6
-1,31,27:18.6
-1,32,27:18.6
-6,33,27:18.6
-1,33,27:18.6
-6,34,27:18.6
0,34,27:18.6
-6,-24,28:18.6
-6,-23,28:18.6
-5,-23,28:18.6
-7,-22,28:18.6
-7,-21,28:18.6
-6,-20,28:18.6
-1,-20,28:18.6
-6,-19,28:18.6
-5,-19,28:18.6
-1,-19,28:18.6
5,-19,28:18.6
-5,-18,28:18.6
-1,-18,28:18.6
4,-18,28:18.6
-5,-17,28:18.6
-1,-17,28:18.6
3,-17,28:18.6
-5,-16,28:18.6
-1,-16,28:18.6
2,-16,28:18.6
6,-16,28:18.6
-5,-15,28:18.6
1,-15,28:18.6
2,-15,28:18.6
5,-15,28:18.6
-5,-14,28:18.6
-1,-14,28:18.6
0,-14,28:18.6
4,-14,28:18.6
-4,-13,28:18.14
-1,-13,28:18.14
0,-13,28:18.14
3,-13,28:18.6
-4,-12,28:18.14
-1,-12,28:18.14
2,-12,28:18.14
-4,-11,28:18.14
-2,-11,28:18.14
-1,-11,28:18.14
-12,-10,28:18.6
10,-9,28:18.6
9,-8,28:18.6
10,-8,28:18.6
11,-8,28:18.6
-12,-7,28:18.6
9,-7,28:18.6
-17,-6,28:18.6
-16,-6,28:18.6
-14,-6,28:18.6
-13,-6,28:18.6
-12,-6,28:18.6
-11,-6,28:18.6
9,-6,28:18.6
-14,-5,28:18.6
-13,-5,28:18.6
-12,-5,28:18.6
-11,-5,28:18.6
8,-5,28:18.6
-14,-4,28:18.6
-13,-4,28:18.6
-12,-4,28:18.6
-10,-4,28:18.6
7,-4,28:18.6
8,-4,28:18.6
-13,-3,28:18.6
-12,-3,28:18.6
-10,-3,28:18.6
6,-3,28:18.6
7,-3,28:18.6
-13,-2,28:18.6
-12,-2,28:18.6
-11,-2,28:18.6
-9,-2,28:18.6
6,-2,28:18.6
-12,-1,28:18.6
-11,-1,28:18.6
-10,-1,28:18.14
-9,-1,28:18.14
-16,0,28:18.6
-15,0,28:18.6
-14,0,28:18.6
-13,0,28:18.6
-12,0,28:18.6
-11,0,28:18.6
-10,0,28:18.14
-9,0,28:18.14
-8,0,28:18.14
-10,1,28:18.14
-9,1,28:18.14
-8,1,28:18.14
-8,2,28:18.14
-29,3,28:18.6
-27,4,28:18.6
-13,20,28:18.6
-12,20,28:18.6
-18,21,28:18.6
-17,21,28:18.6
-14,21,28:18.6
-12,22,28:18.6
-13,23,28:18.6
-3,27,28:18.14
-4,28,28:18.14
-4,29,28:18.14
-5,30,28:18.6
-5,31,28:18.6
-1,31,28:18.6
-1,32,28:18.6
-1,33,28:18.6
0,34,28:18.6
0,35,28:18.6
0,36,28:18.6
-6,-24,29:18.6
-7,-23,29:18.6
-6,-23,29:18.6
-6,-21,29:18.6
-1,-21,29:18.6
0,-21,29:18.6
-1,-20,29:18.6
0,-20,29:18.6
5,-20,29:18.6
6,-20,29:18.6
-5,-19,29:18.6
-1,-19,29:18.6
0,-19,29:18.6
4,-19,29:18.6
5,-19,29:18.6
-5,-18,29:18.6
-1,-18,29:18.6
0,-18,29:18.6
3,-18,29:18.6
4,-18,29:18.6
-5,-17,29:18.6
0,-17,29:18.6
3,-17,29:18.6
7,-17,29:18.6
-5,-16,29:18.6
0,-16,29:18.6
2,-16,29:18.6
6,-16,29:18.6
-5,-15,29:18.6
0,-15,29:18.6
1,-15,29:18.6
5,-15,29:18.6
-5,-14,29:18.6
-4,-14,29:18.6
0,-14,29:18.6
4,-14,29:18.6
-4,-13,29:18.14
0,-13,29:18.14
3,-13,29:18.6
-4,-12,29:18.14
-1,-12,29:18.14
-2,-11,29:18.14
10,-9,29:18.6
10,-8,29:18.6
11,-8,29:18.6
-12,-7,29:18.6
10,-7,29:18.6
-15,-6,29:18.6
-12,-6,29:18.6
-11,-6,29:18.6
9,-6,29:18.6
-15,-5,29:18.6
-14,-5,29:18.6
-13,-5,29:18.6
-12,-5,29:18.6
-11,-5,29:18.6
8,-5,29:18.6
-13,-4,29:18.6
-11,-4,29:18.6
-10,-4,29:18.6
7,-4,29:18.6
8,-4,29:18.6
-14,-3,29:18.6
-12,-3,29:18.6
-10,-3,29:18.6
6,-3,29:18.6
7,-3,29:18.6
-13,-2,29:18.6
-12,-2,29:18.6
-11,-2,29:18.6
-9,-2,29:18.6
-15,-1,29:18.6
-13,-1,29:18.6
-12,-1,29:18.6
-11,-1,29:18.6
-10,-1,29:18.6
-9,-1,29:18.6
-15,0,29:18.6
-14,0,29:18.6
-13,0,29:18.6
-12,0,29:18.6
-11,0,29:18.6
-10,0,29:18.6
-9,0,29:18.6
-8,0,29:18.6
-10,1,29:18.6
-9,1,29:18.6
-8,1,29:18.6
-8,2,29:18.6
-12,20,29:18.6
-16,21,29:18.6
-15,21,29:18.6
-14,21,29:18.6
-13,21,29:18.6
-4,28,29:18.6
-4,29,29:18.6
-5,30,29:18.6
-5,31,29:18.6
-1,31,29:18.6
-6,-25,30:18.6
-7,-24,30:18.6
-6,-24,30:18.6
-6,-23,30:18.6
0,-23,30:18.6
-6,-22,30:18.6
0,-22,30:18.6
-6,-21,30:18.6
0,-21,30:18.6
-5,-20,30:18.6
0,-20,30:18.6
5,-20,30:18.6
-5,-19,30:18.6
0,-19,30:18.6
1,-19,30:18.6
5,-19,30:18.6
-5,-18,30:18.6
0,-18,30:18.6
1,-18,30:18.6
3,-18,30:18.6
-5,-17,30:18.6
0,-17,30:18.6
1,-17,30:18.6
2,-17,30:18.6
3,-17,30:18.6
-5,-16,30:18.6
1,-16,30:18.6
2,-16,30:18.6
-5,-15,30:18.6
1,-15,30:18.6
-4,-14,30:18.6
0,-14,30:18.6
-4,-13,30:18.14
0,-13,30:18.14
-1,-12,30:18.14
-2,-11,30:18.14
-1,-11,30:18.14
11,-9,30:18.6
-16,-7,30:18.6
-12,-7,30:18.6
10,-7,30:18.6
-15,-6,30:18.6
-12,-6,30:18.6
-14,-5,30:18.6
-11,-5,30:18.6
8,-5,30:18.6
-13,-4,30:18.6
-14,-3,30:18.6
-13,-3,30:18.6
-12,-3,30:18.6
-10,-3,30:18.6
-14,-2,30:18.6
-13,-2,30:18.6
-12,-2,30:18.6
-11,-2,30:18.6
-10,-2,30:18.6
-9,-2,30:18.6
-15,-1,30:18.6
-14,-1,30:18.6
-13,-1,30:18.6
-12,-1,30:18.6
-11,-1,30:18.6
-10,-1,30:18.6
-9,-1,30:18.6
-11,0,30:18.6
-10,0,30:18.6
-9,0,30:18.6
-10,1,30:18.6
-9,1,30:18.6
-8,2,30:18.6
-4,29,30:18.6
-5,30,30:18.6
-5,31,30:18.6
-6,32,30:18.6
-5,32,30:18.6
-6,-25,31:18.6
-6,-23,31:18.6
-6,-22,31:18.6
1,-22,31:18.6
1,-21,31:18.6
1,-20,31:18.6
5,-20,31:18.6
1,-19,31:18.6
4,-19,31:18.6
1,-18,31:18.6
2,-18,31:18.6
3,-18,31:18.6
-5,-17,31:18.6
1,-17,31:18.6
2,-17,31:18.6
3,-17,31:18.6
-5,-16,31:18.6
1,-16,31:18.6
2,-16,31:18.6
-5,-15,31:18.6
1,-15,31:18.6
-4,-14,31:18.6
0,-14,31:18.6
-4,-13,31:18.6
0,-13,31:18.6
-1,-12,31:18.6
-1,-11,31:18.6
11,-8,31:18.6
-15,-6,31:18.6
-14,-5,31:18.6
-11,-4,31:18.6
-15,-3,31:18.6
-12,-3,31:18.6
-10,-3,31:18.6
-15,-2,31:18.6
-14,-2,31:18.6
-13,-2,31:18.6
-12,-2,31:18.6
-11,-2,31:18.6
-10,-2,31:18.6
-13,-1,31:18.6
-12,-1,31:18.6
-11,-1,31:18.6
-9,-1,31:18.6
-11,0,31:18.6
-10,1,31:18.6
-9,1,31:18.6
-9,2,31:18.6
-8,2,31:18.6
-5,30,31:18.6
-5,31,31:18.6
2,-21,32:18.6
-5,-20,32:18.6
2,-20,32:18.6
4,-20,32:18.6
-5,-19,32:18.6
2,-19,32:18.6
4,-19,32:18.6
-5,-18,32:18.6
2,-18,32:18.6
3,-18,32:18.6
2,-17,32:18.6
-5,-16,32:18.6
1,-16,32:18.6
2,-16,32:18.6
1,-15,32:18.6
0,-14,32:18.6
0,-13,32:18.6
-1,-12,32:18.6
-1,-11,32:18.6
-13,-4,32:18.6
-16,-3,32:18.6
-15,-3,32:18.6
-13,-3,32:18.6
-16,-2,32:18.6
-14,-2,32:18.6
-12,-2,32:18.6
-13,-1,32:18.6
-12,-1,32:18.6
-11,-1,32:18.6
-12,0,32:18.6
-11,0,32:18.6
-10,1,32:18.6
-9,1,32:18.6
-9,2,32:18.6
3,-21,33:18.6
5,-21,33:18.6
3,-20,33:18.6
4,-20,33:18.6
3,-19,33:18.6
3,-18,33:18.6
2,-17,33:18.6
2,-16,33:18.6
1,-15,33:18.6
0,-14,33:18.6
1,-14,33:18.6
0,-13,33:18.6
-16,-3,33:18.6
-14,-2,33:18.6
-11,0,33:18.6
-10,1,33:18.6
-9,2,33:18.6
3,-22,34:18.6
4,-22,34:18.6
6,-22,34:18.6
3,-21,34:18.6
5,-21,34:18.6
3,-19,34:18.6
3,-18,34:18.6
2,-17,34:18.6
1,-16,34:18.6
2,-16,34:18.6
1,-15,34:18.6
0,-14,34:18.6
1,-14,34:18.6
0,-13,34:18.6
-15,-3,34:18.6
-12,0,34:18.6
-10,1,34:18.6
4,-22,35:18.6
5,-22,35:18.6
4,-21,35:18.6
5,-21,35:18.6
4,-20,35:18.6
3,-19,35:18.6
3,-18,35:18.6
1,-16,35:18.6
2,-16,35:18.6
1,-15,35:18.6
1,-14,35:18.6
5,-23,36:18.6
5,-22,36:18.6
4,-20,36:18.6
2,-16,36:18.6
6,-23,37:18.6
5,-22,37:18.6
2,-17,37:18.6
