[META]
version=2.0
spawnOnBlockType=2
spawnSunlight=True
spawnDarkness=True
spawnWater=False
spawnLava=False
underFill=False
randomRotation=True
dig=True
tree=False
branch=False
needsFoundation=True
rarity=100
collisionPercentage=20
spawnElevationMin=0
spawnElevationMax=200
spawnInBiome=Custom
[DATA]
-9,9,-8:17.12
-8,9,-8:17.12
-7,9,-8:17.12
-8,10,-8:17.12
-8,9,-7:17.12
-6,9,-7:17.12
-9,10,-7:17.12
-9,7,-6:17.12
-7,7,-6:17.12
-10,8,-6:17.12
-9,8,-6:17.12
-8,8,-6:17.12
-10,9,-6:17.12
-9,9,-6:17.12
-8,9,-6:17.12
-7,9,-6:17.12
-6,9,-6:17.12
-9,10,-6:17.12
-7,10,-6:17.12
-6,10,-6:17.12
-11,11,-6:17.12
-8,11,-6:17.12
-7,11,-6:17.12
-10,12,-6:17.12
-9,12,-6:17.12
-9,7,-5:17.12
-7,7,-5:17.12
-11,8,-5:17.12
-9,8,-5:17.12
-8,8,-5:17.12
-5,8,-5:17.12
-10,9,-5:17.12
-9,9,-5:17.12
-8,9,-5:17.12
-7,9,-5:17.12
-6,9,-5:17.12
-5,9,-5:17.12
-11,10,-5:17.12
-9,10,-5:17.12
-8,10,-5:17.12
-7,10,-5:17.12
-5,10,-5:17.12
-12,11,-5:17.12
-10,11,-5:17.12
-9,11,-5:17.12
-8,11,-5:17.12
-12,12,-5:17.12
-10,12,-5:17.12
-7,12,-5:17.12
-11,13,-5:17.12
-10,13,-5:17.12
-10,7,-4:17.12
-8,7,-4:17.12
-7,7,-4:17.12
-11,8,-4:17.12
-10,8,-4:17.12
-9,8,-4:17.12
-8,8,-4:17.12
-7,8,-4:17.12
-6,8,-4:17.12
-11,9,-4:17.12
-10,9,-4:17.12
-9,9,-4:17.12
-8,9,-4:17.12
-7,9,-4:17.12
-6,9,-4:17.12
-5,9,-4:17.12
-11,10,-4:17.12
-10,10,-4:17.12
-9,10,-4:17.12
-8,10,-4:17.12
-7,10,-4:17.12
-12,11,-4:17.12
-10,11,-4:17.12
-9,11,-4:17.12
-8,11,-4:17.12
-7,11,-4:17.12
-5,11,-4:17.12
-12,12,-4:17.12
-11,12,-4:17.12
-10,12,-4:17.12
-9,12,-4:17.12
-7,12,-4:17.12
-6,12,-4:17.12
-11,13,-4:17.12
-10,13,-4:17.12
-8,7,-3:17.12
-11,8,-3:17.12
-10,8,-3:17.12
-8,8,-3:17.12
-7,8,-3:17.12
-6,8,-3:17.12
-5,8,-3:17.12
-10,9,-3:17.12
-9,9,-3:17.12
-8,9,-3:17.12
-5,9,-3:17.12
-11,10,-3:17.12
-9,10,-3:17.12
-8,10,-3:17.12
-7,10,-3:17.12
-6,10,-3:17.12
-5,10,-3:17.12
-10,11,-3:17.12
-9,11,-3:17.12
-8,11,-3:17.12
-5,11,-3:17.12
-10,12,-3:17.12
-8,12,-3:17.12
-11,13,-3:17.12
-10,13,-3:17.12
-9,13,-3:17.12
-9,6,-2:17.12
-8,6,-2:17.12
-7,6,-2:17.12
-11,7,-2:17.12
-10,7,-2:17.12
-9,7,-2:17.12
-8,7,-2:17.12
-6,7,-2:17.12
-5,7,-2:17.12
-12,8,-2:17.12
-11,8,-2:17.12
-9,8,-2:17.12
-8,8,-2:17.12
-7,8,-2:17.12
-5,8,-2:17.12
-4,8,-2:17.12
-12,9,-2:17.12
-10,9,-2:17.12
-9,9,-2:17.12
-8,9,-2:17.12
-7,9,-2:17.12
-6,9,-2:17.12
-4,9,-2:17.12
-12,10,-2:17.12
-10,10,-2:17.12
-9,10,-2:17.12
-8,10,-2:17.12
-7,10,-2:17.12
-6,10,-2:17.12
-4,10,-2:17.12
-12,11,-2:17.12
-11,11,-2:17.12
-10,11,-2:17.12
-8,11,-2:17.12
-5,11,-2:17.12
-4,11,-2:17.12
-11,12,-2:17.12
-10,12,-2:17.12
-8,12,-2:17.12
-6,12,-2:17.12
-5,12,-2:17.12
-11,13,-2:17.12
-10,13,-2:17.12
-9,13,-2:17.12
-8,13,-2:17.12
-7,13,-2:17.12
-6,13,-2:17.12
-9,6,-1:17.12
-8,6,-1:17.12
-11,7,-1:17.12
-10,7,-1:17.12
-9,7,-1:17.12
-7,7,-1:17.12
-6,7,-1:17.12
-11,8,-1:17.12
-5,8,-1:17.12
-12,9,-1:17.12
-11,9,-1:17.12
-5,9,-1:17.12
-4,9,-1:17.12
-12,10,-1:17.12
-5,10,-1:17.12
-4,10,-1:17.12
-12,11,-1:17.12
-11,11,-1:17.12
-5,11,-1:17.12
-11,12,-1:17.12
-10,12,-1:17.12
-6,12,-1:17.12
-5,12,-1:17.12
-10,13,-1:17.12
-9,13,-1:17.12
-8,13,-1:17.12
-7,13,-1:17.12
-10,7,0:17.12
-9,7,0:17.12
-8,7,0:17.12
-7,7,0:17.12
-6,7,0:17.12
-11,8,0:17.12
-10,8,0:17.12
-6,8,0:17.12
-5,8,0:17.12
-11,9,0:17.12
-5,9,0:17.12
-12,10,0:17.12
-11,10,0:17.12
-5,10,0:17.12
-11,11,0:17.12
-5,11,0:17.12
-11,12,0:17.12
-10,12,0:17.12
-9,12,0:17.12
-7,12,0:17.12
-6,12,0:17.12
-5,12,0:17.12
-9,13,0:17.12
-8,13,0:17.12
-7,13,0:17.12
-10,7,1:17.12
-9,7,1:17.12
-8,7,1:17.12
-7,7,1:17.12
-6,7,1:17.12
-11,8,1:17.12
-10,8,1:17.12
-6,8,1:17.12
-11,9,1:17.12
-5,9,1:17.12
-11,10,1:17.12
-5,10,1:17.12
-11,11,1:17.12
-6,11,1:17.12
-5,11,1:17.12
-10,12,1:17.12
-9,12,1:17.12
-7,12,1:17.12
-6,12,1:17.12
-8,13,1:17.12
-9,7,2:17.12
-8,7,2:17.12
-7,7,2:17.12
-10,8,2:17.12
-9,8,2:17.12
-6,8,2:17.12
-11,9,2:17.12
-6,9,2:17.12
-5,9,2:17.12
-11,10,2:17.12
-5,10,2:17.12
-11,11,2:17.12
-10,11,2:17.12
-6,11,2:17.12
-10,12,2:17.12
-9,12,2:17.12
-8,12,2:17.12
-7,12,2:17.12
-6,12,2:17.12
-9,7,3:17.12
-8,7,3:17.12
-7,7,3:17.12
-10,8,3:17.12
-9,8,3:17.12
-7,8,3:17.12
-6,8,3:17.12
-11,9,3:17.12
-10,9,3:17.12
-6,9,3:17.12
-5,9,3:17.12
-11,10,3:17.12
-6,10,3:17.12
-5,10,3:17.12
-10,11,3:17.12
-6,11,3:17.12
-10,12,3:17.12
-9,12,3:17.12
-8,12,3:17.12
-7,12,3:17.12
-8,4,4:18.15
-8,5,4:18.15
-8,7,4:17.12
-10,8,4:17.12
-9,8,4:17.12
-7,8,4:17.12
-6,8,4:17.12
-11,9,4:17.12
-10,9,4:17.12
-6,9,4:17.12
-5,9,4:17.12
-14,10,4:18.15
-11,10,4:17.12
-6,10,4:17.12
-5,10,4:17.12
-15,11,4:18.15
-14,11,4:18.15
-10,11,4:17.12
-6,11,4:17.12
-10,12,4:17.12
-9,12,4:17.12
-8,12,4:17.12
-7,12,4:17.12
-8,2,5:18.7
-9,3,5:18.15
-8,4,5:18.15
-8,6,5:18.15
-8,7,5:17.12
-10,8,5:17.12
-9,8,5:17.12
-8,8,5:17.12
-7,8,5:17.12
-6,8,5:17.12
-10,9,5:17.12
-6,9,5:17.12
-14,10,5:18.15
-13,10,5:18.15
-11,10,5:17.12
-10,10,5:17.12
-6,10,5:17.12
-16,11,5:18.7
-15,11,5:18.15
-14,11,5:18.15
-10,11,5:17.12
-7,11,5:17.12
-6,11,5:17.12
-10,12,5:17.12
-9,12,5:17.12
-8,12,5:17.12
-7,12,5:17.12
-9,2,6:18.7
-8,2,6:18.7
-8,3,6:18.15
-8,5,6:18.15
-8,6,6:18.15
-10,8,6:17.12
-9,8,6:17.12
-8,8,6:17.12
-7,8,6:17.12
-6,8,6:17.12
-10,9,6:17.12
-6,9,6:17.12
-13,10,6:18.15
-12,10,6:18.15
-11,10,6:17.12
-10,10,6:17.12
-6,10,6:17.12
-16,11,6:18.7
-15,11,6:18.15
-14,11,6:18.15
-10,11,6:17.12
-7,11,6:17.12
-6,11,6:17.12
-9,12,6:17.12
-8,12,6:17.12
-7,12,6:17.12
-7,15,6:18.15
-9,2,7:18.7
-8,2,7:18.7
-8,3,7:18.15
-8,4,7:18.15
-8,5,7:18.15
-8,6,7:18.15
-10,8,7:17.12
-9,8,7:17.12
-8,8,7:17.12
-7,8,7:17.12
-6,8,7:17.12
-10,9,7:17.12
-6,9,7:17.12
-13,10,7:18.15
-12,10,7:18.15
-10,10,7:17.12
-6,10,7:17.12
-16,11,7:18.7
-15,11,7:18.15
-14,11,7:18.15
-10,11,7:17.12
-7,11,7:17.12
-6,11,7:17.12
-9,12,7:17.12
-8,12,7:17.12
-7,12,7:17.12
-7,14,7:18.15
-7,15,7:18.15
-9,1,8:18.7
-9,2,8:18.7
-8,2,8:18.7
-8,3,8:18.15
-8,4,8:18.15
-8,5,8:18.15
-10,8,8:17.12
-9,8,8:17.12
-8,8,8:17.12
-7,8,8:17.12
-6,8,8:17.12
-10,9,8:17.12
-6,9,8:17.12
-14,10,8:18.15
-12,10,8:18.15
-10,10,8:17.12
-6,10,8:17.12
-16,11,8:18.7
-14,11,8:18.15
-10,11,8:17.12
-7,11,8:17.12
-6,11,8:17.12
-9,12,8:17.12
-8,12,8:17.12
-7,12,8:17.12
-7,14,8:18.15
-9,1,9:18.7
-9,2,9:18.7
-8,2,9:18.7
-8,3,9:18.15
-8,4,9:18.15
-8,5,9:18.15
-8,6,9:18.15
-10,8,9:17.12
-9,8,9:17.12
-8,8,9:17.12
-7,8,9:17.12
-6,8,9:17.12
-10,9,9:17.12
-6,9,9:17.12
-14,10,9:18.15
-13,10,9:18.15
-12,10,9:18.15
-10,10,9:17.12
-6,10,9:17.12
-15,11,9:18.15
-14,11,9:18.15
-10,11,9:17.12
-7,11,9:17.12
-6,11,9:17.12
-9,12,9:17.12
-8,12,9:17.12
-7,12,9:17.12
-7,14,9:18.15
-9,1,10:18.15
-9,2,10:18.15
-8,2,10:18.15
-9,3,10:18.15
-8,3,10:18.15
-8,4,10:18.15
-8,6,10:18.15
-8,7,10:17.12
-10,8,10:17.12
-9,8,10:17.12
-8,8,10:17.12
-7,8,10:17.12
-6,8,10:17.12
-10,9,10:17.12
-6,9,10:17.12
-13,10,10:18.15
-12,10,10:18.15
-11,10,10:17.12
-10,10,10:17.12
-6,10,10:17.12
-5,10,10:17.12
-16,11,10:18.7
-15,11,10:18.15
-14,11,10:18.15
-10,11,10:17.12
-6,11,10:17.12
-9,12,10:17.12
-8,12,10:17.12
-7,12,10:17.12
-7,14,10:18.15
-7,15,10:18.15
-7,17,10:18.15
-9,1,11:18.15
-8,2,11:18.15
-9,3,11:18.15
-8,3,11:18.15
-8,4,11:18.15
-8,5,11:18.15
-8,6,11:18.15
-8,7,11:17.12
-10,8,11:17.12
-9,8,11:17.12
-7,8,11:17.12
-6,8,11:17.12
-10,9,11:17.12
-6,9,11:17.12
-5,9,11:17.12
-13,10,11:18.15
-12,10,11:18.15
-11,10,11:17.12
-10,10,11:17.12
-6,10,11:17.12
-5,10,11:17.12
-21,11,11:18.7
-16,11,11:18.15
-15,11,11:18.15
-14,11,11:18.15
-10,11,11:17.12
-6,11,11:17.12
-10,12,11:17.12
-9,12,11:17.12
-8,12,11:17.12
-7,12,11:17.12
-7,14,11:18.15
-7,15,11:18.15
-9,1,12:18.15
-8,2,12:18.15
-9,3,12:18.15
-8,3,12:18.15
-3,3,12:18.12
-8,4,12:18.15
-8,5,12:18.15
-8,6,12:18.15
-9,7,12:17.12
-8,7,12:17.12
-7,7,12:17.12
-18,8,12:18.12
-17,8,12:18.12
-16,8,12:18.12
-10,8,12:17.12
-9,8,12:17.12
-7,8,12:17.12
-6,8,12:17.12
-2,8,12:18.12
-1,8,12:18.12
0,8,12:18.12
1,8,12:18.12
2,8,12:18.12
-11,9,12:17.12
-10,9,12:17.12
-7,9,12:18.12
-6,9,12:18.12
-5,9,12:17.12
-13,10,12:18.15
-11,10,12:17.12
-10,10,12:18.12
-7,10,12:18.12
-5,10,12:17.12
-21,11,12:18.15
-16,11,12:18.15
-14,11,12:18.15
-10,11,12:17.12
-7,11,12:18.12
-6,11,12:17.12
-10,12,12:17.12
-9,12,12:17.12
-8,12,12:17.12
-7,12,12:17.12
-6,12,12:17.12
-7,14,12:18.15
-7,15,12:18.15
-7,17,12:18.15
-6,18,12:18.12
-13,-1,13:18.12
-12,-1,13:18.12
-13,0,13:18.12
-12,0,13:18.12
-12,1,13:18.12
-11,1,13:18.12
-9,1,13:18.15
-12,2,13:18.12
-11,2,13:18.12
-8,2,13:18.15
-2,2,13:18.12
-1,2,13:18.12
0,2,13:18.12
1,2,13:18.12
-11,3,13:18.12
-9,3,13:18.15
-8,3,13:18.15
-3,3,13:18.12
-2,3,13:18.12
-1,3,13:18.12
0,3,13:18.12
1,3,13:18.12
-8,4,13:18.15
-3,4,13:18.12
-2,4,13:18.12
0,4,13:18.12
-9,5,13:18.12
-8,5,13:18.15
-4,5,13:18.12
-3,5,13:18.12
-2,5,13:18.12
-9,6,13:18.12
-8,6,13:18.15
-5,6,13:18.12
-4,6,13:18.12
-3,6,13:18.12
2,6,13:18.12
-10,7,13:17.12
-9,7,13:17.12
-8,7,13:18.12
-7,7,13:17.12
-6,7,13:17.12
-5,7,13:18.12
-4,7,13:18.12
-3,7,13:18.12
-2,7,13:18.12
-1,7,13:18.12
0,7,13:18.12
1,7,13:18.12
2,7,13:18.12
3,7,13:18.12
-19,8,13:18.12
-18,8,13:18.12
-17,8,13:18.12
-16,8,13:18.12
-14,8,13:18.12
-10,8,13:17.12
-8,8,13:18.12
-7,8,13:17.12
-6,8,13:17.12
-5,8,13:18.12
-4,8,13:18.12
-3,8,13:18.12
-2,8,13:18.12
-1,8,13:18.12
0,8,13:18.12
1,8,13:18.12
2,8,13:18.12
3,8,13:18.12
-16,9,13:18.12
-15,9,13:18.12
-14,9,13:18.12
-13,9,13:18.12
-12,9,13:18.12
-11,9,13:17.12
-9,9,13:18.12
-8,9,13:18.12
-7,9,13:18.12
-6,9,13:18.12
-5,9,13:17.12
-4,9,13:18.12
-3,9,13:18.12
-2,9,13:18.12
-1,9,13:18.12
0,9,13:18.12
1,9,13:18.12
2,9,13:18.12
3,9,13:18.12
-17,10,13:18.12
-13,10,13:18.15
-12,10,13:18.12
-11,10,13:18.12
-10,10,13:18.12
-9,10,13:18.12
-8,10,13:18.12
-7,10,13:18.12
-6,10,13:18.12
-5,10,13:17.12
-4,10,13:18.12
-21,11,13:18.15
-16,11,13:18.15
-12,11,13:18.12
-11,11,13:17.12
-10,11,13:17.12
-9,11,13:18.12
-7,11,13:18.12
-6,11,13:18.12
-5,11,13:18.12
-4,11,13:18.12
-3,11,13:18.12
-10,12,13:17.12
-9,12,13:17.12
-7,12,13:17.12
-6,12,13:17.12
-4,12,13:18.12
-3,12,13:18.12
-2,12,13:18.12
-8,13,13:17.12
-7,13,13:17.12
-6,13,13:18.12
-16,14,13:18.12
-15,14,13:18.12
-14,14,13:18.12
-7,14,13:18.15
-6,14,13:18.12
-7,15,13:18.12
-6,16,13:18.12
-7,17,13:18.15
-6,17,13:18.12
-6,18,13:18.12
-9,-4,14:17.12
-9,-3,14:17.12
-12,-2,14:18.12
-9,-2,14:18.12
-8,-2,14:18.12
-2,-2,14:18.12
-1,-2,14:18.12
-12,-1,14:18.12
-11,-1,14:18.12
-9,-1,14:18.12
-8,-1,14:18.12
-7,-1,14:18.12
-3,-1,14:18.12
-2,-1,14:18.12
-1,-1,14:18.12
-11,0,14:18.12
-9,0,14:18.12
-8,0,14:18.12
-7,0,14:18.12
-4,0,14:18.12
-3,0,14:18.12
-2,0,14:18.12
-1,0,14:18.12
1,0,14:18.12
-11,1,14:18.12
-10,1,14:18.12
-9,1,14:18.15
-8,1,14:18.12
-7,1,14:18.12
-5,1,14:18.12
-4,1,14:18.12
-3,1,14:18.12
-2,1,14:18.12
0,1,14:18.12
1,1,14:18.12
-11,2,14:18.12
-10,2,14:18.12
-9,2,14:18.12
-8,2,14:18.12
-4,2,14:18.12
-3,2,14:18.12
-2,2,14:18.12
-1,2,14:18.12
0,2,14:18.12
1,2,14:18.12
-10,3,14:18.12
-9,3,14:18.12
-8,3,14:18.12
-4,3,14:18.12
-3,3,14:18.12
-2,3,14:18.12
-1,3,14:18.12
0,3,14:18.12
1,3,14:18.12
-10,4,14:18.12
-9,4,14:18.12
-8,4,14:18.12
-7,4,14:18.12
-5,4,14:18.12
-4,4,14:18.12
-3,4,14:18.12
-2,4,14:18.12
-1,4,14:18.12
0,4,14:18.12
-10,5,14:18.12
-9,5,14:18.12
-8,5,14:18.12
-7,5,14:18.12
-6,5,14:18.12
-5,5,14:18.12
-4,5,14:17.12
-2,5,14:18.12
-1,5,14:18.12
0,5,14:18.12
1,5,14:18.12
2,5,14:18.12
3,5,14:18.12
4,5,14:18.12
-10,6,14:18.12
-9,6,14:18.12
-8,6,14:17.12
-7,6,14:18.12
-6,6,14:17.12
-5,6,14:17.12
-4,6,14:17.12
-3,6,14:18.12
-2,6,14:18.12
-1,6,14:18.12
0,6,14:18.12
1,6,14:18.12
2,6,14:18.12
3,6,14:18.12
4,6,14:18.12
5,6,14:18.12
-10,7,14:17.12
-9,7,14:18.12
-8,7,14:17.12
-7,7,14:17.12
-6,7,14:17.12
-5,7,14:17.12
-3,7,14:18.12
-2,7,14:18.12
-1,7,14:18.12
-20,8,14:18.12
-19,8,14:18.12
-18,8,14:18.12
-17,8,14:18.12
-11,8,14:17.12
-10,8,14:17.12
-9,8,14:18.12
-8,8,14:17.12
-7,8,14:17.12
-6,8,14:17.12
-5,8,14:17.12
-4,8,14:18.12
-3,8,14:18.12
-2,8,14:18.12
-1,8,14:18.12
-20,9,14:18.12
-19,9,14:18.12
-18,9,14:18.12
-17,9,14:18.12
-16,9,14:18.12
-15,9,14:18.12
-14,9,14:18.12
-13,9,14:18.12
-12,9,14:18.12
-11,9,14:18.12
-10,9,14:18.12
-9,9,14:18.12
-7,9,14:18.12
-6,9,14:18.12
-5,9,14:18.12
-4,9,14:18.12
-3,9,14:18.12
-2,9,14:18.12
-1,9,14:18.12
0,9,14:18.12
1,9,14:18.12
2,9,14:18.12
3,9,14:18.12
4,9,14:18.12
-22,10,14:18.12
-21,10,14:18.12
-20,10,14:18.12
-19,10,14:18.12
-18,10,14:18.12
-17,10,14:18.12
-16,10,14:18.12
-15,10,14:18.12
-14,10,14:18.12
-13,10,14:18.12
-12,10,14:18.12
-11,10,14:18.12
-10,10,14:18.12
-9,10,14:18.12
-8,10,14:18.12
-7,10,14:18.12
-6,10,14:18.12
-5,10,14:18.12
-4,10,14:18.12
-3,10,14:18.12
-2,10,14:18.12
-1,10,14:18.12
0,10,14:18.12
4,10,14:18.12
6,10,14:18.12
-22,11,14:18.12
-21,11,14:18.12
-20,11,14:18.12
-19,11,14:18.12
-18,11,14:18.12
-17,11,14:18.12
-16,11,14:18.12
-15,11,14:18.12
-14,11,14:18.12
-13,11,14:18.12
-12,11,14:18.12
-11,11,14:18.12
-10,11,14:18.12
-9,11,14:18.12
-8,11,14:18.12
-7,11,14:18.12
-6,11,14:18.12
-5,11,14:18.12
-4,11,14:18.12
-3,11,14:18.12
-2,11,14:18.12
-1,11,14:18.12
6,11,14:18.12
7,11,14:18.12
8,11,14:18.12
-18,12,14:18.12
-17,12,14:18.12
-16,12,14:18.12
-15,12,14:18.12
-14,12,14:18.12
-13,12,14:18.12
-12,12,14:18.12
-11,12,14:18.12
-10,12,14:17.12
-9,12,14:17.12
-8,12,14:18.12
-7,12,14:18.12
-6,12,14:17.12
-5,12,14:18.12
-2,12,14:18.12
-21,13,14:18.12
-20,13,14:18.12
-19,13,14:18.12
-18,13,14:18.12
-17,13,14:18.12
-16,13,14:18.12
-15,13,14:18.12
-14,13,14:18.12
-13,13,14:18.12
-9,13,14:17.12
-8,13,14:17.12
-7,13,14:18.12
-6,13,14:18.12
-5,13,14:18.12
-21,14,14:18.12
-20,14,14:18.12
-19,14,14:18.12
-18,14,14:18.12
-8,14,14:18.12
-7,14,14:18.12
-6,14,14:18.12
-5,14,14:18.12
-8,15,14:18.12
-7,15,14:18.12
-6,15,14:18.12
-5,15,14:18.12
-8,16,14:18.12
-6,16,14:18.12
-6,17,14:18.12
-6,18,14:18.12
-6,19,14:18.12
-9,-7,15:18.12
-9,-6,15:18.12
-9,-5,15:18.12
-9,-4,15:18.12
-6,-4,15:18.12
-5,-4,15:18.12
-1,-4,15:18.12
-9,-3,15:17.12
-8,-3,15:18.12
-7,-3,15:18.12
-2,-3,15:18.12
-1,-3,15:18.12
-11,-2,15:18.12
-9,-2,15:17.12
-8,-2,15:18.12
-2,-2,15:18.12
-1,-2,15:18.12
-11,-1,15:18.12
-10,-1,15:18.12
-9,-1,15:17.12
-8,-1,15:18.12
-7,-1,15:18.12
-3,-1,15:18.12
-2,-1,15:18.12
-1,-1,15:18.12
0,-1,15:18.12
-10,0,15:18.12
-9,0,15:17.12
-8,0,15:18.12
-7,0,15:18.12
-3,0,15:18.12
-2,0,15:18.12
-1,0,15:18.12
0,0,15:18.12
-11,1,15:18.12
-10,1,15:18.12
-9,1,15:17.12
-8,1,15:18.12
-7,1,15:18.12
-6,1,15:18.12
-4,1,15:18.12
-3,1,15:18.12
-1,1,15:18.12
-10,2,15:18.12
-9,2,15:17.12
-8,2,15:17.12
-7,2,15:18.12
-6,2,15:18.12
-5,2,15:18.12
-4,2,15:18.12
-3,2,15:18.12
-2,2,15:18.12
-1,2,15:18.12
-10,3,15:18.12
-9,3,15:18.12
-8,3,15:17.12
-7,3,15:18.12
-6,3,15:18.12
-5,3,15:18.12
-4,3,15:18.12
-3,3,15:17.12
-2,3,15:18.12
1,3,15:18.12
2,3,15:18.12
3,3,15:18.12
4,3,15:18.12
-11,4,15:18.12
-10,4,15:18.12
-9,4,15:18.12
-8,4,15:17.12
-7,4,15:18.12
-6,4,15:18.12
-5,4,15:18.12
-4,4,15:17.12
-3,4,15:17.12
-2,4,15:17.12
0,4,15:18.12
1,4,15:18.12
2,4,15:18.12
3,4,15:18.12
5,4,15:18.12
6,4,15:18.12
-11,5,15:18.12
-10,5,15:18.12
-9,5,15:18.12
-8,5,15:17.12
-7,5,15:17.12
-6,5,15:18.12
-5,5,15:17.12
-4,5,15:17.12
-3,5,15:17.12
-1,5,15:18.12
0,5,15:18.12
2,5,15:18.12
5,5,15:18.12
6,5,15:18.12
-11,6,15:18.12
-10,6,15:18.12
-9,6,15:17.12
-8,6,15:17.12
-7,6,15:17.12
-6,6,15:17.12
-5,6,15:17.12
-4,6,15:17.12
-3,6,15:17.12
-2,6,15:18.12
-1,6,15:18.12
4,6,15:18.12
5,6,15:18.12
-13,7,15:18.12
-12,7,15:18.12
-11,7,15:18.12
-10,7,15:17.12
-9,7,15:17.12
-7,7,15:17.12
-6,7,15:17.12
-5,7,15:17.12
-4,7,15:17.12
-3,7,15:18.12
0,7,15:18.12
1,7,15:18.12
2,7,15:18.12
3,7,15:18.12
4,7,15:18.12
-21,8,15:18.12
-20,8,15:18.12
-19,8,15:18.12
-18,8,15:18.12
-15,8,15:18.12
-14,8,15:18.12
-13,8,15:18.12
-12,8,15:18.12
-11,8,15:18.12
-10,8,15:18.12
-9,8,15:18.12
-6,8,15:18.12
-5,8,15:17.12
-4,8,15:18.12
-3,8,15:17.12
-2,8,15:18.12
-1,8,15:18.12
0,8,15:18.12
1,8,15:18.12
2,8,15:18.12
3,8,15:18.12
-17,9,15:18.12
-16,9,15:18.12
-15,9,15:18.12
-14,9,15:18.12
-13,9,15:18.12
-12,9,15:18.12
-11,9,15:17.12
-9,9,15:18.12
-8,9,15:18.12
-7,9,15:18.12
-6,9,15:18.12
-5,9,15:17.12
-4,9,15:17.12
-3,9,15:17.12
-2,9,15:17.12
-1,9,15:18.12
0,9,15:17.12
1,9,15:17.12
2,9,15:17.12
3,9,15:18.12
4,9,15:18.12
-17,10,15:18.12
-16,10,15:18.12
-15,10,15:18.12
-14,10,15:17.12
-13,10,15:17.12
-12,10,15:17.12
-11,10,15:17.12
-8,10,15:18.12
-7,10,15:18.12
-6,10,15:18.12
-5,10,15:18.12
-4,10,15:18.12
-3,10,15:17.12
-2,10,15:17.12
-1,10,15:17.12
0,10,15:17.12
1,10,15:18.12
2,10,15:18.12
3,10,15:18.12
4,10,15:18.12
5,10,15:18.12
6,10,15:18.12
7,10,15:18.12
-21,11,15:18.15
-20,11,15:18.12
-19,11,15:18.12
-18,11,15:18.12
-17,11,15:18.12
-16,11,15:18.12
-15,11,15:18.12
-14,11,15:18.12
-13,11,15:18.12
-12,11,15:17.12
-11,11,15:17.12
-10,11,15:17.12
-9,11,15:18.12
-8,11,15:18.12
-6,11,15:17.12
-5,11,15:17.12
-4,11,15:18.12
-3,11,15:18.12
-2,11,15:18.12
-1,11,15:18.12
0,11,15:18.12
1,11,15:18.12
2,11,15:18.12
3,11,15:18.12
4,11,15:18.12
5,11,15:18.12
7,11,15:18.12
8,11,15:18.12
9,11,15:18.12
10,11,15:18.12
-22,12,15:18.12
-21,12,15:18.12
-20,12,15:18.12
-19,12,15:18.12
-18,12,15:18.12
-17,12,15:18.12
-16,12,15:18.12
-13,12,15:18.12
-12,12,15:18.12
-11,12,15:18.12
-10,12,15:17.12
-9,12,15:18.12
-6,12,15:17.12
-5,12,15:18.12
-4,12,15:18.12
-3,12,15:18.12
-2,12,15:18.12
-1,12,15:18.12
0,12,15:18.12
1,12,15:18.12
2,12,15:18.12
-23,13,15:18.12
-22,13,15:18.12
-21,13,15:18.12
-20,13,15:18.12
-13,13,15:18.12
-12,13,15:18.12
-11,13,15:18.12
-10,13,15:18.12
-9,13,15:17.12
-8,13,15:17.12
-7,13,15:17.12
-6,13,15:17.12
-4,13,15:18.12
-14,14,15:18.12
-13,14,15:18.12
-12,14,15:18.12
-10,14,15:18.12
-9,14,15:18.12
-8,14,15:17.12
-7,14,15:17.12
-6,14,15:18.12
-5,14,15:18.12
-4,14,15:18.12
-25,15,15:18.12
-10,15,15:18.12
-9,15,15:18.12
-8,15,15:18.12
-7,15,15:17.12
-6,15,15:18.12
-5,15,15:18.12
-4,15,15:18.12
-25,16,15:18.12
-10,16,15:18.12
-9,16,15:18.12
-8,16,15:18.12
-6,16,15:18.12
-5,16,15:18.12
-10,17,15:18.12
-9,17,15:18.12
-7,17,15:18.12
-6,17,15:18.12
-16,18,15:18.4
-6,18,15:18.12
-6,19,15:18.12
-5,20,15:18.12
-8,-8,16:18.12
-7,-8,16:18.12
-8,-7,16:18.12
-7,-7,16:18.12
-5,-7,16:18.12
-8,-6,16:18.12
-7,-6,16:18.12
-6,-6,16:18.12
-5,-6,16:18.12
-8,-5,16:18.12
-7,-5,16:18.12
-6,-5,16:18.12
-5,-5,16:18.12
-2,-5,16:18.12
-13,-4,16:18.12
-8,-4,16:18.12
-7,-4,16:18.12
-6,-4,16:18.12
-3,-4,16:18.12
-2,-4,16:18.12
-12,-3,16:18.12
-8,-3,16:18.12
-7,-3,16:18.12
-6,-3,16:18.12
-3,-3,16:18.12
-2,-3,16:18.12
-9,-2,16:17.12
-8,-2,16:18.12
-7,-2,16:18.12
-6,-2,16:18.12
-5,-2,16:18.12
-4,-2,16:18.12
-3,-2,16:18.12
-11,-1,16:18.12
-9,-1,16:17.12
-8,-1,16:17.12
-7,-1,16:18.12
-6,-1,16:18.12
-5,-1,16:18.12
-4,-1,16:18.12
-3,-1,16:18.12
-11,0,16:18.12
-10,0,16:18.12
-9,0,16:17.12
-8,0,16:17.12
-7,0,16:18.12
-6,0,16:18.12
-5,0,16:18.12
-4,0,16:18.12
-3,0,16:18.12
0,0,16:18.12
-11,1,16:18.12
-10,1,16:18.12
-9,1,16:17.12
-8,1,16:17.12
-7,1,16:18.12
-6,1,16:18.12
-5,1,16:18.12
-4,1,16:18.12
-1,1,16:18.12
0,1,16:18.12
-14,2,16:18.12
-13,2,16:18.12
-12,2,16:18.12
-11,2,16:18.12
-10,2,16:18.12
-9,2,16:18.12
-8,2,16:17.12
-7,2,16:18.12
-6,2,16:18.12
-5,2,16:18.12
-2,2,16:17.12
-1,2,16:18.12
-12,3,16:18.12
-11,3,16:18.12
-10,3,16:18.12
-9,3,16:17.12
-8,3,16:17.12
-7,3,16:18.12
-5,3,16:18.12
-4,3,16:17.12
-3,3,16:17.12
-2,3,16:17.12
2,3,16:18.12
3,3,16:18.12
6,3,16:18.4
7,3,16:18.4
-12,4,16:18.12
-11,4,16:18.12
-10,4,16:18.12
-9,4,16:18.12
-8,4,16:17.12
-7,4,16:17.12
-6,4,16:18.12
-5,4,16:18.12
-4,4,16:18.12
-3,4,16:17.12
-2,4,16:17.12
0,4,16:18.12
1,4,16:18.12
2,4,16:18.12
5,4,16:18.12
6,4,16:18.12
-12,5,16:18.12
-11,5,16:18.12
-10,5,16:18.12
-9,5,16:18.12
-8,5,16:17.12
-7,5,16:17.12
-6,5,16:18.12
-5,5,16:18.12
-4,5,16:18.12
-3,5,16:17.12
-1,5,16:18.12
0,5,16:18.12
4,5,16:18.12
5,5,16:18.12
6,5,16:18.12
7,5,16:18.12
-14,6,16:18.12
-13,6,16:18.12
-12,6,16:18.12
-11,6,16:18.12
-10,6,16:17.12
-9,6,16:18.12
-6,6,16:18.12
-5,6,16:18.12
-4,6,16:18.12
-2,6,16:18.12
0,6,16:18.12
1,6,16:18.12
3,6,16:18.12
4,6,16:18.12
5,6,16:18.12
6,6,16:18.12
-19,7,16:18.12
-18,7,16:18.12
-17,7,16:18.12
-16,7,16:18.12
-15,7,16:18.12
-13,7,16:18.12
-12,7,16:18.12
-11,7,16:18.12
-10,7,16:17.12
-9,7,16:17.12
-8,7,16:17.12
-7,7,16:17.12
-6,7,16:18.12
-5,7,16:18.12
-4,7,16:18.12
-3,7,16:18.12
-2,7,16:18.12
-1,7,16:18.12
0,7,16:18.12
1,7,16:18.12
2,7,16:18.12
3,7,16:18.12
4,7,16:18.12
-20,8,16:18.12
-19,8,16:18.12
-18,8,16:18.12
-17,8,16:18.12
-16,8,16:18.12
-15,8,16:18.12
-14,8,16:18.12
-13,8,16:18.12
-12,8,16:17.12
-11,8,16:17.12
-10,8,16:17.12
-9,8,16:17.12
-8,8,16:18.12
-7,8,16:17.12
-6,8,16:17.12
-5,8,16:18.12
-4,8,16:18.12
-3,8,16:18.12
-2,8,16:18.12
-1,8,16:18.12
0,8,16:18.12
1,8,16:18.12
2,8,16:18.12
3,8,16:17.12
4,8,16:18.12
5,8,16:18.12
-19,9,16:18.12
-18,9,16:18.12
-17,9,16:18.12
-16,9,16:18.12
-15,9,16:18.12
-14,9,16:18.12
-11,9,16:17.12
-10,9,16:17.12
-9,9,16:18.12
-8,9,16:18.12
-7,9,16:18.12
-6,9,16:17.12
-5,9,16:17.12
-1,9,16:17.12
0,9,16:18.12
1,9,16:18.12
2,9,16:17.12
3,9,16:17.12
4,9,16:18.12
5,9,16:18.12
6,9,16:18.12
-19,10,16:18.12
-18,10,16:17.12
-17,10,16:18.12
-16,10,16:18.12
-15,10,16:17.12
-14,10,16:17.12
-13,10,16:17.12
-10,10,16:17.12
-8,10,16:18.12
-7,10,16:18.12
-6,10,16:18.12
-5,10,16:18.12
-4,10,16:18.12
-3,10,16:18.12
-2,10,16:18.12
-1,10,16:18.12
0,10,16:18.12
1,10,16:17.12
2,10,16:17.12
3,10,16:17.12
4,10,16:18.12
5,10,16:18.12
6,10,16:18.12
7,10,16:18.12
8,10,16:18.12
-21,11,16:18.15
-20,11,16:17.12
-19,11,16:17.12
-18,11,16:17.12
-17,11,16:17.12
-16,11,16:18.12
-15,11,16:18.12
-14,11,16:18.12
-13,11,16:18.12
-10,11,16:17.12
-9,11,16:17.12
-8,11,16:18.12
-7,11,16:17.12
-6,11,16:17.12
-5,11,16:17.12
-4,11,16:17.12
-3,11,16:18.12
-2,11,16:18.12
-1,11,16:18.12
0,11,16:18.12
1,11,16:18.12
2,11,16:18.12
3,11,16:18.12
4,11,16:18.12
5,11,16:18.12
8,11,16:18.12
9,11,16:18.12
10,11,16:18.12
-22,12,16:18.12
-21,12,16:18.12
-20,12,16:18.12
-19,12,16:18.12
-18,12,16:18.12
-17,12,16:18.12
-16,12,16:18.12
-15,12,16:18.12
-14,12,16:18.12
-10,12,16:18.12
-9,12,16:18.12
-8,12,16:17.12
-7,12,16:17.12
-6,12,16:17.12
-5,12,16:17.12
-4,12,16:18.12
-3,12,16:18.12
-2,12,16:18.12
-1,12,16:18.12
0,12,16:18.12
1,12,16:18.12
2,12,16:18.12
4,12,16:18.12
5,12,16:18.12
6,12,16:18.12
-22,13,16:18.12
-21,13,16:18.12
-20,13,16:18.12
-19,13,16:18.12
-18,13,16:18.12
-17,13,16:18.12
-16,13,16:18.12
-15,13,16:18.12
-14,13,16:18.12
-13,13,16:18.12
-11,13,16:18.12
-10,13,16:18.12
-9,13,16:18.12
-8,13,16:17.12
-5,13,16:17.12
-4,13,16:18.12
-3,13,16:18.12
-2,13,16:18.12
0,13,16:18.12
-24,14,16:18.12
-23,14,16:18.12
-22,14,16:18.12
-21,14,16:18.12
-20,14,16:18.12
-19,14,16:18.12
-18,14,16:18.12
-17,14,16:18.12
-16,14,16:18.12
-15,14,16:18.12
-14,14,16:18.12
-13,14,16:18.12
-12,14,16:18.12
-10,14,16:18.12
-8,14,16:17.12
-7,14,16:17.12
-6,14,16:17.12
-4,14,16:18.12
-3,14,16:18.12
-2,14,16:18.12
-1,14,16:18.12
-25,15,16:18.12
-24,15,16:18.12
-23,15,16:18.12
-22,15,16:18.12
-21,15,16:18.12
-17,15,16:18.12
-16,15,16:18.12
-15,15,16:18.12
-14,15,16:18.12
-13,15,16:18.12
-12,15,16:18.12
-11,15,16:18.12
-10,15,16:18.12
-8,15,16:17.12
-7,15,16:17.12
-6,15,16:18.12
-5,15,16:18.12
-4,15,16:18.12
-3,15,16:18.12
-2,15,16:18.12
-1,15,16:18.12
-24,16,16:18.12
-17,16,16:18.4
-16,16,16:18.12
-12,16,16:18.12
-11,16,16:18.12
-10,16,16:18.12
-9,16,16:18.12
-8,16,16:17.12
-7,16,16:17.12
-6,16,16:18.12
-5,16,16:18.12
-4,16,16:18.12
-3,16,16:18.12
-2,16,16:18.12
-1,16,16:18.12
-18,17,16:18.4
-17,17,16:18.4
-16,17,16:18.12
-10,17,16:18.12
-9,17,16:18.12
-8,17,16:18.12
-7,17,16:17.12
-6,17,16:18.12
-5,17,16:18.12
-4,17,16:18.12
-18,18,16:18.4
-17,18,16:18.4
-16,18,16:18.4
-10,18,16:18.12
-9,18,16:18.12
-8,18,16:18.12
-7,18,16:18.12
-6,18,16:18.12
-5,18,16:18.12
-4,18,16:18.12
-18,19,16:18.4
-17,19,16:18.4
-8,19,16:18.12
-7,19,16:17.12
-6,19,16:17.12
-5,19,16:18.12
-4,19,16:18.12
-7,20,16:17.12
-6,20,16:17.12
-5,20,16:18.12
-4,20,16:18.12
-7,21,16:18.12
-6,21,16:18.12
-4,21,16:18.12
-6,22,16:18.12
-8,-8,17:18.12
-13,-7,17:18.12
-8,-7,17:18.12
-7,-7,17:18.12
-6,-7,17:18.12
-13,-6,17:18.12
-12,-6,17:18.12
-9,-6,17:18.12
-8,-6,17:18.12
-7,-6,17:18.12
-6,-6,17:18.12
-5,-6,17:18.12
-4,-6,17:18.12
-13,-5,17:18.12
-12,-5,17:18.12
-11,-5,17:18.12
-9,-5,17:18.12
-8,-5,17:18.12
-7,-5,17:18.12
-6,-5,17:18.12
-5,-5,17:18.12
-4,-5,17:18.12
2,-5,17:18.12
-12,-4,17:18.12
-11,-4,17:18.12
-10,-4,17:18.12
-9,-4,17:18.12
-8,-4,17:18.12
-6,-4,17:18.12
-5,-4,17:18.12
-3,-4,17:18.12
0,-4,17:18.12
1,-4,17:18.12
-11,-3,17:18.12
-10,-3,17:18.12
-9,-3,17:18.12
-8,-3,17:18.12
-6,-3,17:18.12
-5,-3,17:18.12
-4,-3,17:18.12
-3,-3,17:18.12
1,-3,17:18.12
-11,-2,17:18.12
-10,-2,17:18.12
-9,-2,17:18.12
-6,-2,17:18.12
-5,-2,17:18.12
-4,-2,17:18.12
1,-2,17:18.12
2,-2,17:18.12
3,-2,17:18.12
-11,-1,17:18.12
-10,-1,17:18.12
-9,-1,17:17.12
-8,-1,17:17.12
-7,-1,17:18.12
-6,-1,17:18.12
-4,-1,17:18.12
0,-1,17:18.12
1,-1,17:18.12
2,-1,17:18.12
-16,0,17:18.12
-11,0,17:18.12
-10,0,17:18.12
-9,0,17:17.12
-8,0,17:17.12
-7,0,17:18.12
-4,0,17:18.12
-3,0,17:18.12
-1,0,17:18.12
0,0,17:18.12
-16,1,17:18.12
-15,1,17:18.12
-14,1,17:18.12
-13,1,17:18.12
-12,1,17:18.12
-11,1,17:18.12
-10,1,17:18.12
-7,1,17:18.12
-4,1,17:18.12
-3,1,17:18.12
-2,1,17:18.12
-1,1,17:18.12
0,1,17:18.12
-16,2,17:18.12
-15,2,17:18.12
-14,2,17:18.12
-13,2,17:18.12
-12,2,17:18.12
-11,2,17:18.12
-10,2,17:18.12
-9,2,17:18.12
-8,2,17:18.12
-7,2,17:18.12
-4,2,17:18.12
-3,2,17:17.12
-2,2,17:17.12
-1,2,17:18.12
4,2,17:18.12
8,2,17:18.4
-15,3,17:18.12
-14,3,17:18.12
-13,3,17:18.12
-12,3,17:18.12
-10,3,17:18.12
-9,3,17:18.12
-8,3,17:18.12
-4,3,17:18.12
-3,3,17:17.12
-2,3,17:17.12
-1,3,17:18.12
2,3,17:18.12
6,3,17:18.4
7,3,17:18.4
-15,4,17:18.12
-14,4,17:18.12
-13,4,17:18.12
-12,4,17:18.12
-8,4,17:18.12
-6,4,17:18.12
-4,4,17:18.12
-3,4,17:18.12
-2,4,17:17.12
0,4,17:18.12
1,4,17:18.12
2,4,17:18.12
5,4,17:18.12
6,4,17:18.12
-20,5,17:18.4
-19,5,17:18.12
-15,5,17:18.12
-14,5,17:18.12
-13,5,17:18.12
-12,5,17:18.12
-6,5,17:18.12
-4,5,17:18.12
-3,5,17:18.12
-2,5,17:18.12
-1,5,17:18.12
0,5,17:18.12
4,5,17:18.12
5,5,17:18.12
6,5,17:18.12
7,5,17:18.12
-20,6,17:18.12
-19,6,17:18.12
-18,6,17:18.12
-17,6,17:18.12
-16,6,17:18.12
-15,6,17:18.12
-14,6,17:18.12
-13,6,17:18.12
-12,6,17:18.12
-11,6,17:17.12
-8,6,17:18.12
-4,6,17:18.12
-3,6,17:18.12
-2,6,17:18.12
-1,6,17:18.12
0,6,17:18.12
1,6,17:18.12
2,6,17:18.12
3,6,17:18.12
4,6,17:18.12
5,6,17:18.12
6,6,17:18.12
-20,7,17:18.12
-19,7,17:18.12
-18,7,17:18.12
-17,7,17:18.12
-16,7,17:18.12
-15,7,17:18.12
-13,7,17:17.12
-12,7,17:17.12
-11,7,17:18.12
-10,7,17:17.12
-8,7,17:18.12
-7,7,17:18.12
-5,7,17:18.12
-4,7,17:18.12
-3,7,17:18.12
-2,7,17:18.12
-1,7,17:18.12
0,7,17:18.12
1,7,17:18.12
2,7,17:18.12
3,7,17:18.12
4,7,17:18.12
7,7,17:18.12
-20,8,17:18.12
-19,8,17:18.12
-18,8,17:18.12
-17,8,17:18.12
-16,8,17:18.12
-13,8,17:18.12
-12,8,17:17.12
-11,8,17:17.12
-10,8,17:17.12
-9,8,17:17.12
-8,8,17:17.12
-7,8,17:18.12
-6,8,17:18.12
-5,8,17:18.12
1,8,17:18.12
2,8,17:18.12
3,8,17:17.12
4,8,17:18.12
5,8,17:17.12
6,8,17:18.12
7,8,17:18.12
8,8,17:18.12
-20,9,17:18.12
-19,9,17:18.12
-18,9,17:18.12
-16,9,17:18.12
-15,9,17:18.12
-14,9,17:18.12
-13,9,17:18.12
-12,9,17:18.12
-9,9,17:17.12
-8,9,17:17.12
-7,9,17:17.12
-6,9,17:18.12
2,9,17:18.12
3,9,17:18.12
4,9,17:17.12
5,9,17:17.12
6,9,17:17.12
7,9,17:18.12
8,9,17:18.12
9,9,17:18.12
-23,10,17:18.12
-22,10,17:18.12
-21,10,17:18.12
-20,10,17:18.12
-19,10,17:18.12
-18,10,17:18.12
-17,10,17:18.12
-16,10,17:18.12
-15,10,17:18.12
-14,10,17:18.12
-9,10,17:17.12
-8,10,17:17.12
-7,10,17:17.12
-6,10,17:18.12
-5,10,17:18.12
-4,10,17:18.12
-3,10,17:18.12
0,10,17:18.12
1,10,17:18.12
2,10,17:18.12
3,10,17:18.12
4,10,17:17.12
7,10,17:18.12
8,10,17:18.12
9,10,17:18.12
10,10,17:18.12
-24,11,17:18.12
-23,11,17:18.12
-22,11,17:18.12
-21,11,17:17.12
-20,11,17:17.12
-19,11,17:18.12
-18,11,17:18.12
-17,11,17:17.12
-16,11,17:18.12
-15,11,17:18.12
-14,11,17:18.12
-9,11,17:18.12
-8,11,17:17.12
-7,11,17:18.12
-6,11,17:18.12
-5,11,17:17.12
-3,11,17:18.12
-2,11,17:18.12
-1,11,17:18.12
0,11,17:18.12
1,11,17:18.12
2,11,17:18.12
3,11,17:18.12
4,11,17:18.12
5,11,17:18.12
6,11,17:18.12
7,11,17:18.12
8,11,17:18.12
9,11,17:18.12
10,11,17:18.12
-24,12,17:17.12
-23,12,17:17.12
-22,12,17:17.12
-21,12,17:18.12
-20,12,17:18.12
-19,12,17:18.12
-18,12,17:18.12
-17,12,17:18.12
-16,12,17:18.12
-10,12,17:18.12
-9,12,17:18.12
-8,12,17:18.12
-7,12,17:18.12
-6,12,17:17.12
-5,12,17:17.12
-4,12,17:17.12
-3,12,17:17.12
-2,12,17:18.12
0,12,17:18.12
1,12,17:18.12
2,12,17:18.12
3,12,17:18.12
4,12,17:18.12
5,12,17:18.12
6,12,17:18.12
-24,13,17:18.12
-23,13,17:18.12
-22,13,17:18.12
-21,13,17:18.12
-20,13,17:18.12
-19,13,17:18.12
-17,13,17:18.12
-16,13,17:18.12
-11,13,17:18.12
-10,13,17:18.12
-9,13,17:18.12
-8,13,17:18.12
-5,13,17:17.12
-4,13,17:17.12
-3,13,17:17.12
-2,13,17:18.12
0,13,17:18.12
1,13,17:18.12
2,13,17:18.12
6,13,17:18.12
-20,14,17:18.12
-19,14,17:18.12
-18,14,17:18.12
-17,14,17:18.12
-16,14,17:18.12
-15,14,17:18.12
-12,14,17:18.12
-10,14,17:18.12
-9,14,17:18.12
-3,14,17:17.12
-1,14,17:18.12
0,14,17:18.12
1,14,17:18.12
2,14,17:18.12
-22,15,17:18.12
-21,15,17:18.12
-20,15,17:18.12
-19,15,17:18.12
-18,15,17:18.12
-16,15,17:18.12
-15,15,17:18.12
-14,15,17:18.12
-13,15,17:18.12
-12,15,17:18.12
-11,15,17:18.12
-6,15,17:18.12
-3,15,17:18.12
-2,15,17:18.12
-1,15,17:18.12
0,15,17:18.12
1,15,17:18.12
-24,16,17:18.12
-23,16,17:18.12
-22,16,17:18.12
-21,16,17:18.12
-20,16,17:18.12
-19,16,17:18.12
-18,16,17:18.12
-15,16,17:18.12
-14,16,17:18.12
-13,16,17:18.12
-12,16,17:18.12
-11,16,17:18.12
-6,16,17:18.12
-5,16,17:18.12
-4,16,17:18.12
-3,16,17:18.12
-2,16,17:18.12
-1,16,17:18.12
0,16,17:18.12
1,16,17:18.12
-25,17,17:18.12
-24,17,17:18.12
-23,17,17:18.12
-22,17,17:18.12
-20,17,17:18.12
-19,17,17:18.4
-18,17,17:18.4
-15,17,17:18.12
-14,17,17:18.12
-13,17,17:18.12
-12,17,17:18.12
-11,17,17:18.12
-7,17,17:17.12
-6,17,17:17.12
-5,17,17:18.12
-4,17,17:18.12
-3,17,17:18.12
-2,17,17:18.12
-20,18,17:18.12
-19,18,17:18.4
-18,18,17:18.4
-12,18,17:18.12
-11,18,17:18.12
-10,18,17:18.12
-7,18,17:17.12
-6,18,17:17.12
-5,18,17:18.12
-3,18,17:18.12
-2,18,17:18.12
-20,19,17:18.12
-19,19,17:18.4
-18,19,17:18.4
-9,19,17:18.12
-8,19,17:18.12
-7,19,17:17.12
-6,19,17:17.12
-5,19,17:18.12
-4,19,17:18.12
-3,19,17:18.12
-2,19,17:18.12
-20,20,17:18.12
-19,20,17:18.4
-18,20,17:18.4
-7,20,17:17.12
-6,20,17:17.12
-5,20,17:18.12
-4,20,17:18.12
-3,20,17:18.12
-2,20,17:18.12
-7,21,17:17.12
-6,21,17:17.12
-5,21,17:18.12
-4,21,17:18.12
-3,21,17:18.12
-7,22,17:18.12
-6,22,17:18.12
-3,22,17:18.12
-7,23,17:18.12
-6,23,17:18.12
-7,24,17:18.12
-6,24,17:18.12
-6,25,17:18.12
-9,-9,18:18.12
-8,-9,18:18.12
-13,-8,18:18.12
-12,-8,18:18.12
-11,-8,18:18.12
-10,-8,18:18.12
-9,-8,18:18.12
-6,-8,18:18.12
-4,-8,18:18.4
-12,-7,18:18.12
-11,-7,18:18.12
-10,-7,18:18.12
-9,-7,18:18.12
-6,-7,18:18.12
-5,-7,18:18.12
-4,-7,18:18.12
-12,-6,18:18.12
-11,-6,18:18.12
-10,-6,18:18.12
-9,-6,18:18.12
-7,-6,18:18.12
-5,-6,18:18.12
-4,-6,18:18.12
-11,-5,18:18.12
-10,-5,18:18.12
-9,-5,18:18.12
-7,-5,18:18.12
-6,-5,18:18.12
-5,-5,18:18.12
-4,-5,18:18.12
2,-5,18:18.12
3,-5,18:18.12
4,-5,18:18.12
-12,-4,18:18.12
-11,-4,18:18.12
-10,-4,18:18.12
-8,-4,18:18.12
-7,-4,18:18.12
-6,-4,18:18.12
-5,-4,18:18.12
2,-4,18:18.12
3,-4,18:18.12
-13,-3,18:18.12
-12,-3,18:18.12
-11,-3,18:18.12
-9,-3,18:18.12
-6,-3,18:18.12
-5,-3,18:18.12
-4,-3,18:18.12
-3,-3,18:18.12
1,-3,18:18.12
2,-3,18:18.12
3,-3,18:18.12
-16,-2,18:18.4
-13,-2,18:18.12
-12,-2,18:18.12
-11,-2,18:18.12
-9,-2,18:17.12
-8,-2,18:17.12
-6,-2,18:18.12
-4,-2,18:18.12
-3,-2,18:18.12
-1,-2,18:18.12
0,-2,18:18.12
1,-2,18:18.12
2,-2,18:18.12
-15,-1,18:18.12
-14,-1,18:18.12
-13,-1,18:18.12
-12,-1,18:18.12
-9,-1,18:17.12
-8,-1,18:17.12
-7,-1,18:18.12
-4,-1,18:18.12
-3,-1,18:18.12
-2,-1,18:18.12
-1,-1,18:18.12
0,-1,18:18.12
1,-1,18:18.12
2,-1,18:18.12
-16,0,18:18.12
-15,0,18:18.12
-14,0,18:18.12
-13,0,18:18.12
-12,0,18:18.12
-7,0,18:18.12
-4,0,18:18.12
-3,0,18:18.12
-2,0,18:18.12
-1,0,18:17.12
0,0,18:17.12
1,0,18:18.12
2,0,18:18.12
3,0,18:18.12
4,0,18:18.12
5,0,18:18.12
6,0,18:18.4
-18,1,18:18.12
-17,1,18:18.12
-15,1,18:18.12
-11,1,18:18.12
-7,1,18:18.12
-4,1,18:18.12
-2,1,18:17.12
-1,1,18:17.12
0,1,18:18.12
1,1,18:18.12
2,1,18:18.12
3,1,18:18.12
4,1,18:18.12
5,1,18:18.12
6,1,18:18.4
-18,2,18:18.12
-17,2,18:18.12
-16,2,18:18.12
-15,2,18:18.12
-14,2,18:18.12
-11,2,18:18.12
-10,2,18:18.12
-4,2,18:18.12
-3,2,18:17.12
-2,2,18:17.12
-1,2,18:17.12
0,2,18:18.12
1,2,18:18.12
8,2,18:18.4
-18,3,18:18.12
-17,3,18:18.12
-16,3,18:18.12
-2,3,18:17.12
-1,3,18:18.12
0,3,18:18.12
1,3,18:18.12
2,3,18:18.12
3,3,18:18.12
6,3,18:18.4
7,3,18:18.4
-20,4,18:18.12
-19,4,18:18.12
-18,4,18:18.12
-17,4,18:18.12
-16,4,18:18.12
-15,4,18:18.12
-2,4,18:18.12
-1,4,18:18.12
1,4,18:18.12
2,4,18:18.12
3,4,18:18.12
4,4,18:18.12
5,4,18:18.12
6,4,18:18.12
-22,5,18:18.4
-21,5,18:18.4
-20,5,18:18.12
-19,5,18:18.12
-18,5,18:18.12
-17,5,18:18.12
-16,5,18:18.12
-15,5,18:18.12
-14,5,18:17.12
-13,5,18:17.12
-12,5,18:17.12
-2,5,18:18.12
-1,5,18:18.12
0,5,18:18.12
1,5,18:18.12
2,5,18:18.12
3,5,18:18.12
4,5,18:18.12
5,5,18:18.12
6,5,18:18.12
10,5,18:18.12
11,5,18:18.12
-22,6,18:18.12
-21,6,18:18.12
-19,6,18:18.12
-18,6,18:18.12
-17,6,18:18.12
-16,6,18:18.12
-15,6,18:18.12
-14,6,18:17.12
-13,6,18:17.12
-12,6,18:17.12
-11,6,18:18.12
-7,6,18:18.12
-3,6,18:18.12
-1,6,18:18.12
0,6,18:18.12
1,6,18:18.12
2,6,18:18.12
3,6,18:18.12
4,6,18:18.12
5,6,18:18.12
6,6,18:18.12
7,6,18:18.12
10,6,18:18.12
-21,7,18:18.12
-20,7,18:18.12
-19,7,18:18.12
-18,7,18:18.12
-17,7,18:18.12
-13,7,18:17.12
-12,7,18:17.12
-11,7,18:17.12
-10,7,18:18.12
-7,7,18:18.12
-6,7,18:18.12
-5,7,18:18.12
-4,7,18:18.12
3,7,18:18.12
4,7,18:18.12
5,7,18:18.12
6,7,18:18.12
7,7,18:18.12
8,7,18:18.12
9,7,18:18.12
-21,8,18:18.12
-20,8,18:18.12
-10,8,18:18.12
-9,8,18:18.12
-6,8,18:18.12
-5,8,18:18.12
3,8,18:18.12
4,8,18:18.12
5,8,18:18.12
6,8,18:18.12
7,8,18:17.12
8,8,18:18.12
9,8,18:18.12
10,8,18:18.12
-23,9,18:18.12
-22,9,18:18.12
-21,9,18:18.12
-20,9,18:18.12
-9,9,18:17.12
-8,9,18:17.12
-7,9,18:17.12
-6,9,18:18.12
-5,9,18:18.12
2,9,18:18.12
3,9,18:18.12
4,9,18:18.12
5,9,18:18.12
6,9,18:17.12
7,9,18:17.12
8,9,18:17.12
9,9,18:18.12
10,9,18:18.12
11,9,18:18.12
-24,10,18:18.12
-23,10,18:18.12
-22,10,18:18.12
-21,10,18:18.12
-20,10,18:18.12
-15,10,18:18.12
-14,10,18:18.12
-13,10,18:18.12
-12,10,18:18.12
-11,10,18:18.12
-10,10,18:18.12
-9,10,18:17.12
-8,10,18:17.12
-7,10,18:17.12
-5,10,18:18.12
-4,10,18:18.12
-3,10,18:18.12
1,10,18:18.12
2,10,18:18.12
3,10,18:18.12
4,10,18:18.12
5,10,18:18.12
10,10,18:18.12
-25,11,18:18.12
-24,11,18:18.12
-23,11,18:18.12
-22,11,18:18.12
-20,11,18:18.12
-19,11,18:18.12
-18,11,18:17.12
-17,11,18:17.12
-16,11,18:18.12
-15,11,18:18.12
-14,11,18:18.12
-13,11,18:18.12
-12,11,18:18.12
-11,11,18:18.12
-10,11,18:18.12
-9,11,18:17.12
-8,11,18:17.12
-6,11,18:18.12
-5,11,18:18.12
-2,11,18:18.12
2,11,18:18.12
3,11,18:18.12
4,11,18:18.12
9,11,18:18.12
10,11,18:18.12
11,11,18:18.12
-25,12,18:17.12
-22,12,18:18.12
-20,12,18:18.12
-19,12,18:18.12
-18,12,18:18.12
-17,12,18:18.12
-16,12,18:18.12
-15,12,18:18.12
-14,12,18:18.12
-13,12,18:18.12
-12,12,18:18.12
-11,12,18:18.12
-10,12,18:18.12
-7,12,18:18.12
-6,12,18:18.12
-5,12,18:17.12
-4,12,18:17.12
-3,12,18:17.12
-2,12,18:18.12
3,12,18:18.12
4,12,18:18.12
5,12,18:18.12
6,12,18:18.12
7,12,18:18.12
8,12,18:18.12
9,12,18:18.12
10,12,18:18.12
11,12,18:18.12
-25,13,18:18.12
-24,13,18:18.12
-23,13,18:18.12
-22,13,18:18.12
-21,13,18:18.12
-20,13,18:18.12
-19,13,18:18.12
-18,13,18:18.12
-17,13,18:18.12
-16,13,18:18.12
-15,13,18:18.12
-14,13,18:18.12
-13,13,18:18.12
-12,13,18:18.12
-11,13,18:18.12
-8,13,18:18.12
-7,13,18:18.12
-4,13,18:17.12
-3,13,18:17.12
-2,13,18:17.12
0,13,18:18.12
1,13,18:18.12
2,13,18:18.12
3,13,18:18.12
4,13,18:18.12
5,13,18:18.12
6,13,18:18.12
8,13,18:18.12
-25,14,18:18.12
-24,14,18:18.12
-23,14,18:18.12
-22,14,18:18.12
-21,14,18:18.12
-20,14,18:18.12
-18,14,18:18.12
-17,14,18:18.12
-16,14,18:18.12
-15,14,18:18.12
-14,14,18:18.12
-13,14,18:18.12
-8,14,18:18.12
-3,14,18:17.12
-2,14,18:17.12
0,14,18:18.12
1,14,18:18.12
2,14,18:18.12
3,14,18:18.12
-27,15,18:18.12
-21,15,18:18.12
-20,15,18:18.12
-19,15,18:18.12
-18,15,18:18.12
-17,15,18:18.12
-16,15,18:18.12
-15,15,18:18.12
-14,15,18:18.12
-13,15,18:18.12
-11,15,18:18.12
-6,15,18:18.12
2,15,18:18.12
-27,16,18:18.12
-21,16,18:18.12
-20,16,18:18.12
-19,16,18:18.12
-16,16,18:18.12
-15,16,18:18.12
-14,16,18:18.12
-12,16,18:18.12
-9,16,18:18.12
-6,16,18:18.12
-5,16,18:18.12
-1,16,18:18.12
0,16,18:18.12
1,16,18:18.12
2,16,18:18.12
5,16,18:18.12
6,16,18:18.12
7,16,18:18.4
-22,17,18:18.12
-21,17,18:18.12
-20,17,18:18.12
-14,17,18:18.12
-13,17,18:18.12
-5,17,18:18.12
-4,17,18:18.12
-3,17,18:18.12
-2,17,18:18.12
-1,17,18:18.12
0,17,18:18.12
1,17,18:18.12
8,17,18:18.4
-26,18,18:18.12
-25,18,18:18.12
-24,18,18:18.12
-23,18,18:18.12
-22,18,18:18.12
-21,18,18:18.12
-20,18,18:18.12
-15,18,18:18.12
-14,18,18:18.12
-13,18,18:18.12
-7,18,18:17.12
-6,18,18:17.12
-4,18,18:18.12
-2,18,18:18.12
-1,18,18:18.12
-22,19,18:18.12
-20,19,18:18.12
-15,19,18:18.12
-7,19,18:17.12
-6,19,18:17.12
-5,19,18:18.12
-4,19,18:18.12
-3,19,18:18.12
-2,19,18:18.12
-1,19,18:18.12
0,19,18:18.12
-21,20,18:18.12
-20,20,18:18.12
-7,20,18:17.12
-6,20,18:17.12
-5,20,18:18.12
-4,20,18:18.12
-2,20,18:18.12
-1,20,18:18.12
-21,21,18:18.12
-20,21,18:18.12
-7,21,18:17.12
-6,21,18:17.12
-5,21,18:18.12
-4,21,18:18.12
-3,21,18:18.12
-2,21,18:18.12
-1,21,18:18.4
-7,22,18:17.12
-6,22,18:17.12
-4,22,18:18.12
-3,22,18:18.12
-2,22,18:18.12
-1,22,18:18.12
-7,23,18:18.12
-6,23,18:17.12
-3,23,18:18.12
-7,24,18:18.12
-6,24,18:18.12
-7,25,18:18.12
-6,25,18:18.12
-6,26,18:18.12
-5,26,18:18.12
-11,-9,19:18.12
-4,-9,19:18.4
-11,-8,19:18.12
-10,-8,19:18.12
-4,-8,19:18.4
-10,-7,19:18.12
-6,-7,19:18.12
-5,-7,19:18.12
-10,-6,19:18.12
-7,-6,19:18.12
-6,-6,19:18.12
-5,-6,19:18.12
-4,-6,19:18.12
3,-6,19:18.12
-10,-5,19:18.12
-8,-5,19:18.12
-7,-5,19:18.12
-6,-5,19:18.12
-5,-5,19:18.12
-4,-5,19:18.12
-3,-5,19:18.12
1,-5,19:18.12
2,-5,19:18.12
3,-5,19:18.12
4,-5,19:18.12
5,-5,19:18.12
-16,-4,19:18.4
-13,-4,19:18.12
-9,-4,19:18.12
-8,-4,19:18.12
-7,-4,19:18.12
-3,-4,19:18.12
-2,-4,19:18.12
0,-4,19:18.12
1,-4,19:18.12
2,-4,19:18.12
4,-4,19:18.12
5,-4,19:18.12
-16,-3,19:18.4
-13,-3,19:18.12
-9,-3,19:17.12
-8,-3,19:18.12
-6,-3,19:18.12
-4,-3,19:18.12
-3,-3,19:18.12
-2,-3,19:18.12
-1,-3,19:18.12
1,-3,19:18.12
3,-3,19:18.12
-16,-2,19:18.12
-15,-2,19:18.12
-14,-2,19:18.12
-13,-2,19:18.12
-9,-2,19:17.12
-8,-2,19:17.12
-7,-2,19:18.12
-6,-2,19:18.12
-4,-2,19:18.12
-2,-2,19:18.12
-1,-2,19:18.12
2,-2,19:18.12
3,-2,19:18.12
4,-2,19:18.12
5,-2,19:18.12
6,-2,19:18.12
7,-2,19:18.4
-15,-1,19:18.12
-14,-1,19:18.12
-13,-1,19:18.12
-7,-1,19:18.12
-4,-1,19:18.12
-2,-1,19:18.12
0,-1,19:17.12
1,-1,19:17.12
2,-1,19:18.12
3,-1,19:18.12
4,-1,19:18.12
5,-1,19:18.12
6,-1,19:18.12
7,-1,19:18.4
-15,0,19:18.12
-13,0,19:18.12
-12,0,19:18.12
-7,0,19:18.12
-4,0,19:18.12
-2,0,19:18.12
-1,0,19:17.12
0,0,19:17.12
1,0,19:18.12
2,0,19:18.12
3,0,19:18.12
4,0,19:18.12
5,0,19:18.12
6,0,19:18.12
-15,1,19:18.12
-14,1,19:18.12
-12,1,19:18.12
-11,1,19:18.12
-7,1,19:18.12
-4,1,19:18.12
-2,1,19:18.12
-1,1,19:17.12
0,1,19:18.12
1,1,19:18.12
2,1,19:18.12
-14,2,19:18.12
-13,2,19:18.12
-12,2,19:18.12
-11,2,19:18.12
-10,2,19:18.12
-4,2,19:18.12
-1,2,19:18.12
0,2,19:18.12
1,2,19:18.12
2,2,19:18.12
3,2,19:18.12
4,2,19:18.12
8,2,19:18.4
-20,3,19:18.12
-19,3,19:18.12
-18,3,19:18.12
-14,3,19:18.12
-13,3,19:18.12
-1,3,19:18.12
2,3,19:18.12
3,3,19:18.12
4,3,19:18.12
5,3,19:18.12
6,3,19:18.4
7,3,19:18.4
-24,4,19:18.4
-23,4,19:18.12
-22,4,19:18.12
-18,4,19:18.12
-17,4,19:18.12
-14,4,19:17.12
-13,4,19:18.12
-11,4,19:18.12
-1,4,19:18.12
0,4,19:18.12
1,4,19:18.12
2,4,19:18.12
3,4,19:18.12
4,4,19:18.12
5,4,19:18.12
6,4,19:18.12
12,4,19:18.12
-23,5,19:18.12
-22,5,19:18.12
-21,5,19:18.12
-20,5,19:18.12
-19,5,19:18.12
-18,5,19:18.12
-17,5,19:18.12
-16,5,19:18.12
-15,5,19:17.12
-14,5,19:17.12
-13,5,19:17.12
-11,5,19:18.12
-2,5,19:18.12
-1,5,19:18.12
0,5,19:18.12
1,5,19:18.12
2,5,19:18.12
3,5,19:18.12
4,5,19:18.12
5,5,19:18.12
6,5,19:18.12
7,5,19:18.12
11,5,19:18.12
-23,6,19:18.12
-22,6,19:18.12
-19,6,19:18.12
-18,6,19:18.12
-15,6,19:18.12
-14,6,19:18.12
-13,6,19:17.12
-12,6,19:17.12
-11,6,19:18.12
-10,6,19:18.12
-3,6,19:18.12
5,6,19:18.12
6,6,19:18.12
7,6,19:18.12
8,6,19:18.12
10,6,19:18.12
-22,7,19:18.12
-12,7,19:18.12
-11,7,19:18.12
-6,7,19:18.12
-5,7,19:18.12
-4,7,19:18.12
2,7,19:18.12
4,7,19:18.12
5,7,19:18.12
6,7,19:18.12
7,7,19:18.12
8,7,19:18.12
9,7,19:18.12
10,7,19:18.12
-26,8,19:18.12
-23,8,19:18.12
-22,8,19:18.12
-6,8,19:18.12
-5,8,19:18.12
2,8,19:18.12
3,8,19:18.12
4,8,19:18.12
5,8,19:18.12
6,8,19:18.12
7,8,19:18.12
8,8,19:18.12
9,8,19:18.12
10,8,19:18.12
-25,9,19:18.12
-24,9,19:18.12
-23,9,19:18.12
-22,9,19:18.12
-21,9,19:18.12
-9,9,19:17.12
-8,9,19:17.12
-7,9,19:17.12
-5,9,19:18.12
-4,9,19:18.12
3,9,19:18.12
4,9,19:18.12
5,9,19:18.12
6,9,19:18.12
7,9,19:18.12
8,9,19:17.12
9,9,19:18.12
-25,10,19:18.12
-20,10,19:18.12
-12,10,19:18.12
-11,10,19:18.12
-10,10,19:18.12
-9,10,19:17.12
-8,10,19:17.12
-7,10,19:17.12
-6,10,19:17.12
-4,10,19:18.12
-3,10,19:18.12
2,10,19:18.12
3,10,19:18.12
4,10,19:18.12
5,10,19:18.12
6,10,19:18.12
-25,11,19:18.12
-24,11,19:18.12
-23,11,19:18.12
-18,11,19:17.12
-17,11,19:17.12
-16,11,19:18.12
-15,11,19:18.12
-14,11,19:18.12
-13,11,19:18.12
-12,11,19:18.12
-10,11,19:17.12
-9,11,19:17.12
-8,11,19:17.12
-2,11,19:18.12
2,11,19:18.12
3,11,19:18.12
-26,12,19:18.12
-24,12,19:18.12
-23,12,19:18.12
-20,12,19:18.12
-19,12,19:18.12
-18,12,19:18.12
-17,12,19:18.12
-16,12,19:18.12
-11,12,19:17.12
-10,12,19:17.12
-9,12,19:17.12
-6,12,19:18.12
-5,12,19:18.12
-2,12,19:18.12
2,12,19:18.12
4,12,19:18.12
-26,13,19:18.12
-23,13,19:18.12
-21,13,19:18.12
-20,13,19:18.12
-17,13,19:18.12
-12,13,19:18.12
-11,13,19:18.12
-10,13,19:18.12
-7,13,19:18.12
-6,13,19:18.12
-3,13,19:17.12
-2,13,19:18.12
0,13,19:18.12
5,13,19:18.12
8,13,19:18.12
9,13,19:18.12
10,13,19:18.12
-26,14,19:18.12
-25,14,19:18.12
-24,14,19:18.12
-23,14,19:18.12
-22,14,19:18.12
-21,14,19:18.12
-18,14,19:18.12
-17,14,19:18.12
-16,14,19:18.12
-13,14,19:18.12
-12,14,19:18.12
-10,14,19:18.12
-3,14,19:17.12
-2,14,19:17.12
0,14,19:18.12
1,14,19:18.12
2,14,19:18.12
3,14,19:18.12
4,14,19:18.12
-27,15,19:18.12
-26,15,19:18.12
-25,15,19:18.12
-24,15,19:18.12
-23,15,19:18.12
-22,15,19:18.12
-19,15,19:18.12
-18,15,19:18.12
-14,15,19:18.12
-13,15,19:18.12
-12,15,19:18.12
-11,15,19:18.12
-10,15,19:18.12
-9,15,19:18.12
-7,15,19:18.12
-6,15,19:18.12
2,15,19:18.12
3,15,19:18.12
4,15,19:18.12
-27,16,19:18.12
-23,16,19:18.12
-22,16,19:18.12
-20,16,19:18.12
-19,16,19:18.12
-15,16,19:18.12
-14,16,19:18.12
-13,16,19:18.12
-12,16,19:18.12
-11,16,19:18.12
-10,16,19:18.12
-6,16,19:18.12
-5,16,19:18.12
5,16,19:18.12
6,16,19:18.12
7,16,19:18.4
-23,17,19:18.12
-22,17,19:18.12
-21,17,19:18.12
-20,17,19:18.12
-13,17,19:18.12
-12,17,19:18.12
-11,17,19:18.12
-10,17,19:18.12
-5,17,19:18.12
-4,17,19:18.12
-1,17,19:18.12
0,17,19:18.12
1,17,19:18.12
2,17,19:18.12
7,17,19:18.4
8,17,19:18.4
9,17,19:18.4
-26,18,19:18.12
-22,18,19:18.12
-21,18,19:18.12
-13,18,19:18.12
-12,18,19:18.12
-11,18,19:18.12
-7,18,19:17.12
-6,18,19:17.12
-4,18,19:18.12
-3,18,19:18.12
-2,18,19:18.12
-1,18,19:18.12
0,18,19:18.12
1,18,19:18.12
2,18,19:18.12
-26,19,19:18.12
-25,19,19:18.12
-23,19,19:18.12
-22,19,19:18.12
-12,19,19:18.12
-11,19,19:18.12
-7,19,19:17.12
-6,19,19:17.12
-5,19,19:18.12
-4,19,19:18.12
-3,19,19:18.12
-2,19,19:18.12
-1,19,19:18.12
0,19,19:18.12
-25,20,19:18.12
-24,20,19:18.12
-23,20,19:18.12
-8,20,19:18.12
-7,20,19:18.12
-5,20,19:18.12
-4,20,19:18.12
-3,20,19:18.12
-2,20,19:18.12
-1,20,19:18.12
0,20,19:18.12
1,20,19:18.12
-7,21,19:17.12
-6,21,19:17.12
-5,21,19:18.12
-4,21,19:18.12
-3,21,19:18.12
-2,21,19:18.12
-1,21,19:18.4
0,21,19:18.4
-7,22,19:17.12
-6,22,19:17.12
-5,22,19:18.12
-4,22,19:18.12
-3,22,19:18.12
-7,23,19:17.12
-6,23,19:17.12
-4,23,19:18.12
-3,23,19:18.12
-7,24,19:17.12
-6,24,19:17.12
-7,25,19:17.12
-6,25,19:17.12
-6,26,19:18.12
-5,26,19:18.12
-5,27,19:18.12
-10,-9,20:18.12
-7,-9,20:18.12
-6,-9,20:18.12
-4,-9,20:18.4
-10,-8,20:18.12
-9,-8,20:18.12
-8,-8,20:18.12
-7,-8,20:18.12
-6,-8,20:18.12
-5,-8,20:18.12
-4,-8,20:18.4
-10,-7,20:18.12
-9,-7,20:18.12
-8,-7,20:18.12
-7,-7,20:18.12
-6,-7,20:18.12
-5,-7,20:18.12
-3,-7,20:18.4
-2,-7,20:18.12
2,-7,20:18.12
-10,-6,20:18.12
-8,-6,20:18.12
-7,-6,20:18.12
-6,-6,20:18.12
-5,-6,20:18.12
-3,-6,20:18.12
-2,-6,20:18.12
1,-6,20:18.12
2,-6,20:18.12
3,-6,20:18.12
-10,-5,20:18.12
-9,-5,20:18.12
-8,-5,20:18.12
-7,-5,20:18.12
-6,-5,20:18.12
-5,-5,20:18.12
-4,-5,20:18.12
-3,-5,20:18.12
-2,-5,20:18.12
-1,-5,20:18.12
0,-5,20:18.12
1,-5,20:18.12
-16,-4,20:18.4
-9,-4,20:17.12
-7,-4,20:18.12
-6,-4,20:18.12
-5,-4,20:18.12
-3,-4,20:18.12
-2,-4,20:18.12
-1,-4,20:18.12
0,-4,20:18.12
1,-4,20:18.12
-16,-3,20:18.4
-15,-3,20:18.4
-9,-3,20:17.12
-8,-3,20:17.12
-7,-3,20:18.12
-6,-3,20:18.12
-4,-3,20:18.12
-3,-3,20:18.12
-1,-3,20:18.12
5,-3,20:18.12
6,-3,20:18.12
-16,-2,20:18.12
-15,-2,20:18.12
-14,-2,20:18.12
-9,-2,20:18.12
-7,-2,20:18.12
-3,-2,20:18.12
-2,-2,20:18.12
-1,-2,20:18.12
3,-2,20:18.12
4,-2,20:18.12
5,-2,20:18.12
-15,-1,20:18.12
-14,-1,20:18.12
-13,-1,20:18.12
-12,-1,20:18.12
-11,-1,20:18.12
-10,-1,20:18.12
-7,-1,20:18.12
-4,-1,20:18.12
-3,-1,20:18.12
-2,-1,20:18.12
-1,-1,20:18.12
0,-1,20:17.12
1,-1,20:17.12
2,-1,20:18.12
3,-1,20:18.12
4,-1,20:18.12
-15,0,20:18.12
-14,0,20:18.12
-13,0,20:18.12
-12,0,20:18.12
-11,0,20:18.12
-10,0,20:18.12
-7,0,20:18.12
-4,0,20:18.12
-2,0,20:18.12
0,0,20:18.12
1,0,20:18.12
2,0,20:18.12
3,0,20:18.12
-15,1,20:18.12
-14,1,20:18.12
-13,1,20:18.12
-12,1,20:18.12
-11,1,20:18.12
-4,1,20:18.12
-2,1,20:18.12
2,1,20:18.12
3,1,20:18.12
4,1,20:18.12
5,1,20:18.12
-15,2,20:18.12
-14,2,20:18.12
-11,2,20:18.12
-10,2,20:18.12
-2,2,20:18.12
-1,2,20:18.12
0,2,20:18.12
1,2,20:18.12
3,2,20:18.12
4,2,20:18.12
5,2,20:18.12
6,2,20:18.4
7,2,20:18.4
-19,3,20:18.12
-18,3,20:18.12
-15,3,20:18.12
-11,3,20:18.12
-3,3,20:18.12
-1,3,20:18.12
0,3,20:18.12
1,3,20:18.12
2,3,20:18.12
3,3,20:18.12
4,3,20:18.12
5,3,20:18.12
6,3,20:18.4
7,3,20:18.4
-24,4,20:18.4
-23,4,20:18.12
-22,4,20:18.12
-21,4,20:18.12
-18,4,20:18.12
-17,4,20:18.12
-16,4,20:18.12
-15,4,20:17.12
-14,4,20:17.12
-11,4,20:18.12
-4,4,20:18.12
-3,4,20:18.12
4,4,20:18.12
5,4,20:18.12
6,4,20:18.12
7,4,20:18.12
12,4,20:18.12
13,4,20:18.12
-24,5,20:18.4
-23,5,20:18.12
-21,5,20:18.12
-20,5,20:18.12
-19,5,20:18.12
-18,5,20:18.12
-17,5,20:18.12
-16,5,20:18.12
-15,5,20:17.12
-14,5,20:17.12
-11,5,20:18.12
-5,5,20:18.12
-4,5,20:18.12
6,5,20:18.12
7,5,20:18.12
11,5,20:18.12
12,5,20:18.12
-24,6,20:18.4
-23,6,20:18.12
-17,6,20:18.12
-16,6,20:18.12
-15,6,20:18.12
-14,6,20:18.12
-13,6,20:18.12
-12,6,20:18.12
-11,6,20:18.12
-10,6,20:18.12
-9,6,20:18.12
-5,6,20:18.12
1,6,20:18.12
2,6,20:18.12
6,6,20:18.12
7,6,20:18.12
8,6,20:18.12
9,6,20:18.12
10,6,20:18.12
11,6,20:18.12
-24,7,20:18.12
-13,7,20:18.12
-9,7,20:18.12
-6,7,20:18.12
2,7,20:18.12
6,7,20:18.12
7,7,20:18.12
8,7,20:18.12
9,7,20:18.12
10,7,20:18.12
11,7,20:18.12
-26,8,20:18.12
-25,8,20:18.12
-24,8,20:18.12
-23,8,20:18.12
-22,8,20:18.12
-7,8,20:18.12
-6,8,20:18.12
3,8,20:18.12
6,8,20:18.12
7,8,20:18.12
9,8,20:17.12
10,8,20:18.12
11,8,20:18.12
12,8,20:18.12
-26,9,20:18.12
-25,9,20:18.12
-22,9,20:18.12
-21,9,20:18.12
-8,9,20:17.12
-7,9,20:18.12
-4,9,20:18.12
3,9,20:18.12
4,9,20:18.12
5,9,20:18.12
6,9,20:18.12
7,9,20:18.12
8,9,20:18.12
9,9,20:18.12
10,9,20:18.12
11,9,20:18.12
12,9,20:18.12
-26,10,20:18.12
-23,10,20:18.12
-20,10,20:18.12
-13,10,20:18.12
-12,10,20:18.12
-9,10,20:17.12
-8,10,20:17.12
-7,10,20:17.12
-6,10,20:17.12
4,10,20:18.12
9,10,20:18.12
-24,11,20:18.12
-23,11,20:18.12
-19,11,20:17.12
-18,11,20:17.12
-17,11,20:18.12
-16,11,20:18.12
-15,11,20:18.12
-14,11,20:18.12
-13,11,20:18.12
-11,11,20:17.12
-10,11,20:17.12
-9,11,20:17.12
-8,11,20:17.12
3,11,20:18.12
4,11,20:18.12
10,11,20:18.12
-26,12,20:18.12
-25,12,20:18.12
-24,12,20:18.12
-20,12,20:18.12
-19,12,20:18.12
-18,12,20:18.12
-17,12,20:18.12
-12,12,20:17.12
-11,12,20:17.12
-10,12,20:17.12
-9,12,20:17.12
2,12,20:18.12
3,12,20:18.12
5,12,20:18.12
-23,13,20:18.12
-21,13,20:18.12
-20,13,20:18.12
-17,13,20:18.12
-12,13,20:17.12
-11,13,20:17.12
-10,13,20:17.12
-9,13,20:17.12
-3,13,20:17.12
-2,13,20:17.12
0,13,20:18.12
2,13,20:18.12
-26,14,20:18.12
-23,14,20:18.12
-22,14,20:18.12
-21,14,20:18.12
-18,14,20:18.12
-15,14,20:18.12
-14,14,20:18.12
-13,14,20:18.12
-12,14,20:18.12
-11,14,20:17.12
-10,14,20:17.12
-2,14,20:17.12
-1,14,20:18.12
0,14,20:18.12
1,14,20:18.12
2,14,20:18.12
-27,15,20:18.12
-26,15,20:18.12
-25,15,20:18.12
-24,15,20:18.12
-23,15,20:18.12
-22,15,20:18.12
-19,15,20:18.12
-18,15,20:18.12
-17,15,20:18.12
-16,15,20:18.12
-15,15,20:18.12
-14,15,20:18.12
-13,15,20:18.12
-12,15,20:18.12
-7,15,20:18.12
-6,15,20:18.12
-2,15,20:18.12
-1,15,20:18.12
0,15,20:18.12
1,15,20:18.12
2,15,20:18.12
3,15,20:18.12
4,15,20:18.12
-27,16,20:18.12
-26,16,20:18.12
-25,16,20:18.12
-24,16,20:18.12
-23,16,20:18.12
-20,16,20:18.12
-19,16,20:18.12
-18,16,20:18.12
-17,16,20:18.12
-13,16,20:18.12
-12,16,20:18.12
-6,16,20:18.12
-5,16,20:18.12
-1,16,20:18.12
5,16,20:18.12
6,16,20:18.12
7,16,20:18.4
-26,17,20:18.12
-24,17,20:18.12
-23,17,20:18.12
-21,17,20:18.12
-20,17,20:18.12
-14,17,20:18.12
-13,17,20:18.12
-12,17,20:18.12
-7,17,20:17.12
-6,17,20:17.12
-5,17,20:18.12
-4,17,20:18.12
-1,17,20:18.12
7,17,20:18.4
8,17,20:18.4
9,17,20:18.4
-26,18,20:18.12
-24,18,20:18.12
-23,18,20:18.12
-22,18,20:18.12
-21,18,20:18.12
-14,18,20:18.12
-13,18,20:18.12
-12,18,20:18.12
-7,18,20:17.12
-4,18,20:18.12
-3,18,20:18.12
0,18,20:18.12
1,18,20:18.12
2,18,20:18.12
3,18,20:18.12
10,18,20:18.4
-24,19,20:18.12
-23,19,20:18.12
-22,19,20:18.12
-14,19,20:18.12
-6,19,20:18.12
-5,19,20:18.12
-3,19,20:18.12
-2,19,20:18.12
-1,19,20:18.12
0,19,20:18.12
1,19,20:18.12
2,19,20:18.12
-23,20,20:18.12
-8,20,20:18.12
-5,20,20:18.12
-4,20,20:18.12
-3,20,20:18.12
-2,20,20:18.12
-1,20,20:18.12
0,20,20:18.12
1,20,20:18.12
-4,21,20:18.12
-3,21,20:18.12
-2,21,20:18.12
-1,21,20:18.4
0,21,20:18.4
2,21,20:18.4
-6,22,20:18.12
-5,22,20:18.12
-4,22,20:18.12
-3,22,20:18.12
-2,22,20:18.12
-1,22,20:18.12
0,22,20:18.4
1,22,20:18.4
2,22,20:18.4
-5,23,20:18.12
-4,23,20:18.12
-3,23,20:18.12
-2,23,20:18.12
-4,24,20:18.12
-3,24,20:18.12
-2,24,20:18.12
-6,25,20:17.12
-4,25,20:18.12
-3,25,20:18.12
-6,26,20:17.12
-3,26,20:18.12
2,-10,21:18.4
-6,-9,21:18.12
-5,-9,21:18.12
1,-9,21:18.4
2,-9,21:18.4
-10,-8,21:18.12
-6,-8,21:18.12
-5,-8,21:18.12
-4,-8,21:18.4
-3,-8,21:18.4
0,-8,21:18.4
1,-8,21:18.4
2,-8,21:18.4
-11,-7,21:18.12
-10,-7,21:18.12
-9,-7,21:17.12
-8,-7,21:18.12
-7,-7,21:18.12
-6,-7,21:18.12
-5,-7,21:18.12
-4,-7,21:18.12
-3,-7,21:18.4
0,-7,21:18.12
1,-7,21:18.12
2,-7,21:18.12
-11,-6,21:18.12
-10,-6,21:18.12
-9,-6,21:17.12
-5,-6,21:18.12
-4,-6,21:18.12
-3,-6,21:18.12
-1,-6,21:18.12
0,-6,21:18.12
1,-6,21:18.12
2,-6,21:18.12
-11,-5,21:18.12
-10,-5,21:18.12
-9,-5,21:17.12
-5,-5,21:18.12
-4,-5,21:18.12
-3,-5,21:18.12
-2,-5,21:18.12
-1,-5,21:18.12
0,-5,21:18.12
1,-5,21:18.12
2,-5,21:18.12
-16,-4,21:18.4
-15,-4,21:18.4
-14,-4,21:18.12
-13,-4,21:18.12
-12,-4,21:18.12
-11,-4,21:18.12
-10,-4,21:18.12
-9,-4,21:18.12
-6,-4,21:18.12
-5,-4,21:18.12
-3,-4,21:18.12
-2,-4,21:18.12
-1,-4,21:18.12
1,-4,21:18.12
6,-4,21:18.12
7,-4,21:18.4
-16,-3,21:18.12
-15,-3,21:18.4
-13,-3,21:18.12
-12,-3,21:18.12
-11,-3,21:18.12
-9,-3,21:17.12
-2,-3,21:18.12
-1,-3,21:18.12
1,-3,21:18.12
2,-3,21:18.12
3,-3,21:18.12
5,-3,21:18.12
6,-3,21:18.12
7,-3,21:18.4
-16,-2,21:18.12
-15,-2,21:18.12
-14,-2,21:18.12
-13,-2,21:18.12
-12,-2,21:18.12
-11,-2,21:18.12
-10,-2,21:18.12
-9,-2,21:17.12
-2,-2,21:18.12
-1,-2,21:18.12
1,-2,21:18.12
2,-2,21:18.12
3,-2,21:18.12
4,-2,21:18.12
5,-2,21:18.12
-15,-1,21:18.12
-14,-1,21:18.12
-1,-1,21:18.12
0,-1,21:17.12
1,-1,21:18.12
2,-1,21:18.12
3,-1,21:18.12
4,-1,21:18.12
5,-1,21:18.12
-16,0,21:18.12
-15,0,21:18.12
-13,0,21:18.12
-11,0,21:18.12
-2,0,21:18.12
-1,0,21:18.12
1,0,21:18.12
3,0,21:18.12
4,0,21:18.12
5,0,21:18.12
6,0,21:18.12
-16,1,21:18.12
-15,1,21:18.12
-12,1,21:18.12
-11,1,21:18.12
-2,1,21:18.12
-1,1,21:18.12
1,1,21:18.12
2,1,21:18.12
3,1,21:18.12
4,1,21:18.12
5,1,21:18.12
6,1,21:18.12
7,1,21:18.4
-20,2,21:18.12
-19,2,21:18.12
-18,2,21:18.12
-16,2,21:18.12
-11,2,21:18.12
-2,2,21:18.12
-1,2,21:18.12
0,2,21:18.12
1,2,21:18.12
2,2,21:18.12
3,2,21:18.12
4,2,21:18.12
5,2,21:18.12
6,2,21:18.4
7,2,21:18.4
-21,3,21:18.12
-20,3,21:18.12
-19,3,21:18.12
-18,3,21:18.12
-11,3,21:18.12
-3,3,21:18.12
2,3,21:18.12
3,3,21:18.12
4,3,21:18.12
5,3,21:18.12
6,3,21:18.4
8,3,21:18.4
9,3,21:18.4
-27,4,21:18.12
-25,4,21:18.4
-24,4,21:18.12
-23,4,21:18.12
-22,4,21:18.12
-21,4,21:18.12
-20,4,21:18.12
-19,4,21:18.12
-18,4,21:18.12
-17,4,21:18.12
-16,4,21:18.12
-15,4,21:17.12
-14,4,21:17.12
-11,4,21:18.12
-4,4,21:18.12
-3,4,21:18.12
1,4,21:18.12
2,4,21:18.12
3,4,21:18.12
5,4,21:18.12
6,4,21:18.12
7,4,21:18.12
8,4,21:18.12
9,4,21:18.12
-26,5,21:18.12
-25,5,21:18.4
-24,5,21:18.12
-21,5,21:18.12
-20,5,21:18.12
-19,5,21:18.12
-16,5,21:18.12
-15,5,21:17.12
-14,5,21:17.12
-12,5,21:18.12
-11,5,21:18.12
-10,5,21:18.12
-9,5,21:18.12
-4,5,21:18.12
1,5,21:18.12
8,5,21:18.12
9,5,21:18.12
10,5,21:18.12
11,5,21:18.12
12,5,21:18.12
13,5,21:18.12
-26,6,21:18.12
-25,6,21:18.12
-24,6,21:18.4
-20,6,21:18.12
-19,6,21:18.12
-18,6,21:18.12
-14,6,21:18.12
-13,6,21:18.12
-12,6,21:18.12
-9,6,21:18.12
-8,6,21:18.12
-5,6,21:18.12
2,6,21:18.12
8,6,21:18.12
9,6,21:18.12
10,6,21:18.12
11,6,21:18.12
12,6,21:18.12
13,6,21:18.12
-25,7,21:18.12
-24,7,21:18.12
-18,7,21:18.12
-7,7,21:18.12
-6,7,21:18.12
2,7,21:18.12
3,7,21:18.12
8,7,21:18.12
12,7,21:18.12
13,7,21:18.12
-29,8,21:18.12
-28,8,21:18.12
-27,8,21:18.12
-26,8,21:18.12
-23,8,21:18.12
-22,8,21:18.12
-8,8,21:18.12
-7,8,21:18.12
-6,8,21:18.12
3,8,21:18.12
4,8,21:18.12
9,8,21:18.12
10,8,21:17.12
11,8,21:17.12
12,8,21:18.12
13,8,21:18.12
-23,9,21:18.12
-22,9,21:18.12
-21,9,21:18.12
-8,9,21:17.12
-7,9,21:17.12
-6,9,21:18.12
4,9,21:18.12
5,9,21:18.12
6,9,21:18.12
7,9,21:18.12
8,9,21:18.12
9,9,21:18.12
10,9,21:18.12
11,9,21:18.12
13,9,21:18.12
-29,10,21:18.12
-28,10,21:18.12
-27,10,21:18.12
-24,10,21:18.12
-23,10,21:18.12
-20,10,21:18.12
-15,10,21:18.12
-14,10,21:18.12
-13,10,21:18.12
-9,10,21:17.12
-8,10,21:17.12
-7,10,21:17.12
4,10,21:18.12
5,10,21:18.12
10,10,21:18.12
-24,11,21:18.12
-20,11,21:17.12
-19,11,21:17.12
-18,11,21:18.12
-17,11,21:18.12
-16,11,21:18.12
-15,11,21:18.12
-9,11,21:17.12
-8,11,21:17.12
-7,11,21:17.12
3,11,21:18.12
4,11,21:18.12
10,11,21:18.12
11,11,21:18.12
-26,12,21:18.12
-25,12,21:18.12
-24,12,21:18.12
-20,12,21:18.12
-19,12,21:18.12
2,12,21:18.12
3,12,21:18.12
10,12,21:18.12
11,12,21:18.12
-24,13,21:18.12
-21,13,21:18.12
-20,13,21:18.12
-18,13,21:18.12
-17,13,21:18.12
-12,13,21:17.12
-11,13,21:18.12
-10,13,21:18.12
-2,13,21:17.12
-1,13,21:17.12
1,13,21:18.12
2,13,21:18.12
3,13,21:18.12
11,13,21:18.12
-24,14,21:18.12
-23,14,21:18.12
-22,14,21:18.12
-18,14,21:18.12
-12,14,21:17.12
-11,14,21:17.12
-10,14,21:18.12
-9,14,21:18.12
-8,14,21:18.12
-7,14,21:18.12
-2,14,21:17.12
-1,14,21:17.12
0,14,21:17.12
2,14,21:18.12
3,14,21:18.12
-23,15,21:18.12
-22,15,21:18.12
-19,15,21:18.12
-14,15,21:18.12
-13,15,21:18.12
-12,15,21:17.12
-11,15,21:18.12
-10,15,21:18.12
-7,15,21:18.12
-2,15,21:18.12
-1,15,21:18.12
0,15,21:17.12
1,15,21:17.12
2,15,21:18.12
3,15,21:18.12
4,15,21:18.12
-26,16,21:18.12
-25,16,21:18.12
-24,16,21:18.12
-22,16,21:18.12
-20,16,21:18.12
-19,16,21:18.12
-18,16,21:18.12
-17,16,21:18.12
-16,16,21:18.12
-15,16,21:18.12
-14,16,21:18.12
-13,16,21:18.12
-6,16,21:18.12
-5,16,21:18.12
-2,16,21:18.12
-1,16,21:18.12
0,16,21:18.12
1,16,21:18.12
2,16,21:18.12
3,16,21:18.12
4,16,21:18.12
5,16,21:18.12
6,16,21:18.12
-26,17,21:18.12
-25,17,21:18.12
-21,17,21:18.4
-20,17,21:18.4
-19,17,21:18.12
-18,17,21:18.12
-17,17,21:18.12
-16,17,21:18.12
-14,17,21:18.12
-13,17,21:18.12
-7,17,21:17.12
-6,17,21:18.12
-5,17,21:18.12
-4,17,21:18.12
-1,17,21:18.12
0,17,21:18.12
1,17,21:18.12
2,17,21:18.12
7,17,21:18.12
8,17,21:18.12
9,17,21:18.12
-26,18,21:18.12
-22,18,21:18.4
-21,18,21:18.4
-14,18,21:18.12
-13,18,21:18.12
-7,18,21:17.12
-6,18,21:17.12
-4,18,21:18.12
-3,18,21:18.12
0,18,21:18.12
10,18,21:18.4
-22,19,21:18.4
-14,19,21:18.12
-13,19,21:18.12
-3,19,21:18.12
-2,19,21:18.12
-1,19,21:18.12
0,19,21:18.12
1,19,21:18.12
2,19,21:18.12
3,19,21:18.12
-14,20,21:18.12
-13,20,21:18.12
-8,20,21:18.12
-5,20,21:18.12
-2,20,21:18.12
-1,20,21:18.12
0,20,21:18.12
1,20,21:18.12
2,20,21:18.12
-8,21,21:18.12
-5,21,21:18.12
-4,21,21:18.12
-2,21,21:18.12
-1,21,21:18.12
-7,22,21:18.12
-5,22,21:18.12
-4,22,21:18.12
-3,22,21:18.12
-2,22,21:18.12
-1,22,21:18.12
0,22,21:18.4
1,22,21:18.12
2,22,21:18.12
-6,23,21:18.12
-5,23,21:18.12
-4,23,21:18.12
-3,23,21:18.12
-2,23,21:18.12
-1,23,21:18.12
0,23,21:18.12
1,23,21:18.4
2,23,21:18.4
-5,24,21:18.12
-4,24,21:18.12
-3,24,21:18.12
-2,24,21:18.12
-1,24,21:18.12
-4,25,21:18.12
-3,25,21:18.12
-2,25,21:18.12
-6,26,21:17.12
-5,26,21:17.12
-3,26,21:18.12
-2,26,21:18.12
-5,27,21:17.12
-3,27,21:18.12
-2,27,21:18.12
-10,-11,22:17.12
-9,-11,22:18.12
0,-11,22:18.4
1,-11,22:18.4
-14,-10,22:18.12
-13,-10,22:18.12
-10,-10,22:17.12
-9,-10,22:18.12
-8,-10,22:18.12
-5,-10,22:18.12
-4,-10,22:18.4
0,-10,22:18.4
1,-10,22:18.4
3,-10,22:18.4
4,-10,22:18.4
-14,-9,22:18.12
-13,-9,22:18.12
-12,-9,22:18.12
-10,-9,22:17.12
-9,-9,22:18.12
-8,-9,22:18.12
-7,-9,22:18.12
-6,-9,22:18.12
-5,-9,22:18.12
-4,-9,22:18.4
-3,-9,22:18.4
-1,-9,22:18.4
0,-9,22:18.4
2,-9,22:18.4
3,-9,22:18.4
4,-9,22:18.4
-13,-8,22:18.12
-12,-8,22:18.12
-10,-8,22:17.12
-9,-8,22:17.12
-8,-8,22:18.12
-7,-8,22:18.12
-6,-8,22:18.12
-4,-8,22:18.4
-3,-8,22:18.4
-2,-8,22:18.4
-1,-8,22:18.4
0,-8,22:18.4
2,-8,22:18.4
3,-8,22:18.4
4,-8,22:18.4
-13,-7,22:18.12
-12,-7,22:18.12
-10,-7,22:17.12
-9,-7,22:17.12
-8,-7,22:18.12
-3,-7,22:18.4
-2,-7,22:18.12
-1,-7,22:18.12
2,-7,22:18.12
3,-7,22:18.12
-13,-6,22:18.12
-12,-6,22:18.12
-9,-6,22:17.12
-2,-6,22:18.12
-1,-6,22:18.12
2,-6,22:18.12
3,-6,22:18.12
7,-6,22:18.4
8,-6,22:18.4
-16,-5,22:18.4
-15,-5,22:18.4
-14,-5,22:18.12
-13,-5,22:18.12
-12,-5,22:18.12
-11,-5,22:18.12
-9,-5,22:18.12
-2,-5,22:18.12
0,-5,22:18.12
2,-5,22:18.12
3,-5,22:18.12
4,-5,22:18.12
5,-5,22:18.12
6,-5,22:18.12
7,-5,22:18.4
8,-5,22:18.4
-17,-4,22:18.4
-16,-4,22:18.4
-15,-4,22:18.4
-10,-4,22:18.12
-2,-4,22:18.12
-1,-4,22:18.12
0,-4,22:18.12
2,-4,22:18.12
3,-4,22:18.12
4,-4,22:18.12
5,-4,22:18.12
6,-4,22:18.12
7,-4,22:18.4
8,-4,22:18.4
-2,-3,22:18.12
-1,-3,22:18.12
2,-3,22:18.12
5,-3,22:18.12
6,-3,22:18.12
7,-3,22:18.4
-17,-2,22:18.12
-16,-2,22:18.12
-9,-2,22:17.12
-2,-2,22:18.12
-1,-2,22:18.12
1,-2,22:17.12
3,-2,22:18.12
4,-2,22:18.12
5,-2,22:18.12
6,-2,22:18.12
7,-2,22:18.4
-17,-1,22:18.12
-1,-1,22:18.12
0,-1,22:18.12
1,-1,22:17.12
2,-1,22:18.12
3,-1,22:18.12
5,-1,22:18.12
6,-1,22:18.12
-17,0,22:18.12
-11,0,22:18.12
-1,0,22:18.12
1,0,22:18.12
2,0,22:18.12
3,0,22:18.12
4,0,22:18.12
5,0,22:18.12
6,0,22:18.12
7,0,22:18.4
-22,1,22:18.12
-21,1,22:18.12
-20,1,22:18.12
-19,1,22:18.12
-18,1,22:18.12
-17,1,22:18.12
-11,1,22:18.12
-1,1,22:18.12
1,1,22:18.12
2,1,22:18.12
3,1,22:18.12
4,1,22:18.12
5,1,22:18.12
6,1,22:18.12
-23,2,22:18.12
-22,2,22:18.12
-21,2,22:18.12
-20,2,22:18.12
-19,2,22:18.12
-17,2,22:18.12
-11,2,22:18.12
-2,2,22:18.12
-1,2,22:18.12
0,2,22:18.12
2,2,22:18.12
4,2,22:18.12
5,2,22:18.12
6,2,22:18.4
7,2,22:18.4
8,2,22:18.4
9,2,22:18.4
10,2,22:18.4
-26,3,22:18.12
-23,3,22:18.12
-22,3,22:18.12
-21,3,22:18.12
-20,3,22:18.12
-19,3,22:18.12
-16,3,22:17.12
-15,3,22:17.12
-11,3,22:18.12
-3,3,22:18.12
-2,3,22:18.12
2,3,22:18.12
3,3,22:18.12
5,3,22:18.12
6,3,22:18.4
7,3,22:18.4
8,3,22:18.4
9,3,22:18.4
10,3,22:18.4
-26,4,22:18.12
-25,4,22:18.4
-24,4,22:18.12
-23,4,22:18.12
-22,4,22:18.12
-21,4,22:18.12
-20,4,22:18.12
-19,4,22:18.12
-18,4,22:18.12
-17,4,22:18.12
-16,4,22:17.12
-15,4,22:17.12
-14,4,22:17.12
-12,4,22:18.12
-11,4,22:18.12
-10,4,22:18.12
-4,4,22:18.12
-3,4,22:18.12
9,4,22:18.12
10,4,22:18.12
11,4,22:18.12
12,4,22:18.12
13,4,22:18.12
-26,5,22:18.12
-25,5,22:18.4
-24,5,22:18.12
-23,5,22:18.12
-22,5,22:18.12
-21,5,22:18.12
-19,5,22:18.12
-18,5,22:18.12
-17,5,22:18.12
-16,5,22:18.12
-15,5,22:17.12
-14,5,22:17.12
-13,5,22:18.12
-12,5,22:18.12
-10,5,22:18.12
-9,5,22:18.12
-8,5,22:18.12
-4,5,22:18.12
2,5,22:18.12
8,5,22:18.12
9,5,22:18.12
10,5,22:18.12
11,5,22:18.12
-29,6,22:18.12
-28,6,22:18.12
-27,6,22:18.12
-26,6,22:18.12
-25,6,22:18.4
-22,6,22:18.12
-21,6,22:18.12
-20,6,22:18.12
-19,6,22:18.12
-18,6,22:18.12
-17,6,22:18.12
-15,6,22:18.12
-14,6,22:18.12
-13,6,22:18.12
-8,6,22:18.12
-7,6,22:18.12
-6,6,22:18.12
-5,6,22:18.12
2,6,22:18.12
3,6,22:18.12
14,6,22:18.12
-29,7,22:18.12
-28,7,22:18.12
-25,7,22:18.12
-24,7,22:18.12
-21,7,22:18.12
-20,7,22:18.12
-19,7,22:18.12
-15,7,22:18.12
-8,7,22:18.12
-7,7,22:18.12
-6,7,22:18.12
-5,7,22:18.12
3,7,22:18.12
14,7,22:18.12
-29,8,22:18.12
-23,8,22:18.12
-22,8,22:18.12
-19,8,22:18.12
-5,8,22:18.12
4,8,22:18.12
9,8,22:18.12
12,8,22:18.12
13,8,22:18.12
-29,9,22:18.12
-24,9,22:18.12
-23,9,22:18.12
-22,9,22:18.12
-21,9,22:18.12
-17,9,22:18.12
-8,9,22:17.12
-5,9,22:18.12
-4,9,22:18.12
4,9,22:18.12
5,9,22:18.12
6,9,22:18.12
7,9,22:18.12
8,9,22:18.12
9,9,22:18.12
10,9,22:18.12
11,9,22:18.12
12,9,22:18.12
-24,10,22:18.12
-17,10,22:18.12
-15,10,22:18.12
-8,10,22:17.12
-7,10,22:17.12
5,10,22:18.12
6,10,22:18.12
-25,11,22:18.12
-21,11,22:17.12
-20,11,22:18.12
-19,11,22:18.12
-18,11,22:18.12
-17,11,22:18.12
-9,11,22:17.12
-8,11,22:17.12
-7,11,22:17.12
-6,11,22:18.12
3,11,22:18.12
4,11,22:18.12
11,11,22:18.12
-26,12,22:18.12
-25,12,22:18.12
-21,12,22:17.12
-20,12,22:18.12
-17,12,22:18.12
2,12,22:18.12
3,12,22:18.12
4,12,22:18.12
11,12,22:18.12
12,12,22:18.12
-25,13,22:18.12
-24,13,22:18.12
-21,13,22:18.12
-10,13,22:18.12
3,13,22:18.12
4,13,22:18.12
5,13,22:18.12
11,13,22:18.12
12,13,22:18.12
-24,14,22:18.12
-22,14,22:18.12
-13,14,22:17.12
-12,14,22:17.12
-10,14,22:18.12
-2,14,22:18.12
-1,14,22:18.12
0,14,22:18.12
3,14,22:18.12
4,14,22:18.12
5,14,22:18.12
-24,15,22:18.12
-23,15,22:18.12
-19,15,22:18.12
-14,15,22:18.12
-13,15,22:18.12
-12,15,22:17.12
-11,15,22:17.12
-10,15,22:18.12
-9,15,22:18.12
-8,15,22:18.12
-7,15,22:18.12
-6,15,22:18.12
-5,15,22:18.12
-1,15,22:17.12
0,15,22:17.12
1,15,22:18.12
2,15,22:18.12
5,15,22:18.12
6,15,22:18.12
-25,16,22:18.12
-24,16,22:18.12
-23,16,22:18.12
-20,16,22:18.12
-14,16,22:18.12
-13,16,22:17.12
-12,16,22:18.12
-11,16,22:18.12
-10,16,22:18.12
-6,16,22:18.12
-5,16,22:18.12
-4,16,22:18.12
-3,16,22:18.12
0,16,22:18.12
1,16,22:17.12
2,16,22:17.12
5,16,22:18.12
6,16,22:18.12
7,16,22:18.12
-25,17,22:18.12
-23,17,22:18.4
-22,17,22:18.4
-21,17,22:18.4
-18,17,22:18.12
-17,17,22:18.12
-16,17,22:18.12
-15,17,22:18.12
-14,17,22:17.12
-12,17,22:18.12
-11,17,22:18.12
-10,17,22:18.12
-7,17,22:18.12
-6,17,22:18.12
-5,17,22:18.12
-4,17,22:18.12
-3,17,22:18.12
-2,17,22:18.12
-1,17,22:18.12
0,17,22:18.12
1,17,22:18.12
2,17,22:18.12
3,17,22:18.12
4,17,22:18.12
5,17,22:18.12
6,17,22:18.12
7,17,22:18.12
8,17,22:18.12
9,17,22:18.12
-22,18,22:18.4
-21,18,22:18.4
-20,18,22:18.4
-19,18,22:18.12
-18,18,22:18.12
-17,18,22:18.12
-16,18,22:18.12
-15,18,22:18.12
-11,18,22:18.12
-7,18,22:18.12
-4,18,22:18.12
-3,18,22:18.12
-1,18,22:18.12
0,18,22:18.12
1,18,22:18.12
2,18,22:18.12
3,18,22:18.12
4,18,22:18.12
5,18,22:18.12
6,18,22:18.12
9,18,22:18.12
-21,19,22:18.4
-20,19,22:18.4
-18,19,22:18.12
-16,19,22:18.12
-15,19,22:18.12
-14,19,22:18.12
-7,19,22:17.12
-6,19,22:17.12
-3,19,22:18.12
-2,19,22:18.12
0,19,22:18.12
1,19,22:18.12
2,19,22:18.12
3,19,22:18.12
-16,20,22:18.12
-15,20,22:18.12
-14,20,22:18.12
-8,20,22:18.12
-6,20,22:18.12
-5,20,22:18.12
-2,20,22:18.12
-1,20,22:18.12
0,20,22:18.12
1,20,22:18.12
2,20,22:18.12
-16,21,22:18.12
-15,21,22:18.12
-14,21,22:18.12
-8,21,22:18.12
-5,21,22:18.12
-4,21,22:18.12
-1,21,22:18.12
0,21,22:18.12
-16,22,22:18.12
-8,22,22:18.12
-4,22,22:18.12
-3,22,22:18.12
-2,22,22:18.12
-1,22,22:18.12
0,22,22:18.4
1,22,22:18.12
-7,23,22:18.12
-6,23,22:18.12
-5,23,22:18.12
-4,23,22:18.12
-3,23,22:18.12
-2,23,22:18.12
-1,23,22:18.12
0,23,22:18.12
1,23,22:18.4
2,23,22:18.4
-6,24,22:18.12
-5,24,22:18.12
-4,24,22:18.12
-3,24,22:18.12
-2,24,22:18.12
-1,24,22:18.12
0,24,22:18.12
1,24,22:18.4
2,24,22:18.4
-5,25,22:18.12
-4,25,22:18.12
-3,25,22:18.12
-2,25,22:18.12
-1,25,22:18.12
0,25,22:18.12
1,25,22:18.4
-5,26,22:18.12
-2,26,22:18.12
-1,26,22:18.12
-5,27,22:17.12
-4,27,22:17.12
-2,27,22:18.12
-1,27,22:18.12
-4,28,22:17.12
-10,-12,23:17.12
-10,-11,23:17.12
-9,-11,23:17.12
-8,-11,23:18.12
-7,-11,23:18.12
-5,-11,23:18.12
-3,-11,23:18.4
-2,-11,23:18.4
-1,-11,23:18.4
4,-11,23:18.4
5,-11,23:18.4
-15,-10,23:18.4
-8,-10,23:18.12
-7,-10,23:18.12
-6,-10,23:18.12
-5,-10,23:18.12
-3,-10,23:18.4
-2,-10,23:18.4
-1,-10,23:18.4
4,-10,23:18.4
5,-10,23:18.4
-15,-9,23:18.4
-14,-9,23:18.12
-7,-9,23:18.12
-6,-9,23:18.12
-3,-9,23:18.4
-2,-9,23:18.4
4,-9,23:18.4
5,-9,23:18.4
-15,-8,23:18.4
-14,-8,23:18.12
-7,-8,23:18.12
-2,-8,23:18.4
4,-8,23:18.4
5,-8,23:18.4
7,-8,23:18.4
8,-8,23:18.4
9,-8,23:18.4
-15,-7,23:18.4
-14,-7,23:18.12
-9,-7,23:17.12
-8,-7,23:18.12
-2,-7,23:18.12
4,-7,23:18.12
5,-7,23:18.12
6,-7,23:18.12
7,-7,23:18.4
8,-7,23:18.4
9,-7,23:18.4
-18,-6,23:18.4
-17,-6,23:18.4
-16,-6,23:18.4
-15,-6,23:18.4
-14,-6,23:18.12
-13,-6,23:18.12
-9,-6,23:18.12
-2,-6,23:18.12
4,-6,23:18.12
5,-6,23:18.12
6,-6,23:18.12
7,-6,23:18.4
8,-6,23:18.4
-18,-5,23:18.4
-16,-5,23:18.4
-12,-5,23:18.12
-11,-5,23:18.12
-2,-5,23:18.12
3,-5,23:18.12
4,-5,23:18.12
-19,-4,23:18.12
-18,-4,23:18.12
-10,-4,23:18.12
-2,-4,23:18.12
0,-4,23:18.12
2,-4,23:18.12
3,-4,23:18.12
8,-4,23:18.4
-19,-3,23:18.12
-18,-3,23:18.12
-1,-3,23:18.12
2,-3,23:17.12
5,-3,23:18.12
6,-3,23:18.12
8,-3,23:18.4
9,-3,23:18.4
-19,-2,23:18.12
-18,-2,23:18.12
1,-2,23:17.12
3,-2,23:18.12
4,-2,23:18.12
7,-2,23:18.4
8,-2,23:18.4
-19,-1,23:18.12
-18,-1,23:18.12
-1,-1,23:18.12
0,-1,23:18.12
1,-1,23:18.12
2,-1,23:18.12
3,-1,23:18.12
7,-1,23:18.4
8,-1,23:18.4
-18,0,23:18.12
-11,0,23:18.12
0,0,23:18.12
1,0,23:18.12
2,0,23:18.12
3,0,23:18.12
4,0,23:18.12
5,0,23:18.12
6,0,23:18.12
7,0,23:18.4
8,0,23:18.4
9,0,23:18.4
10,0,23:18.4
11,0,23:18.4
-18,1,23:18.12
-11,1,23:18.12
-1,1,23:18.12
1,1,23:18.12
2,1,23:18.12
5,1,23:18.12
6,1,23:18.12
7,1,23:18.4
8,1,23:18.4
9,1,23:18.4
10,1,23:18.4
11,1,23:18.4
-23,2,23:18.12
-22,2,23:18.12
-21,2,23:18.12
-20,2,23:18.12
-19,2,23:17.12
-18,2,23:17.12
-17,2,23:17.12
-11,2,23:18.12
-2,2,23:18.12
2,2,23:18.12
3,2,23:18.12
4,2,23:18.12
5,2,23:18.12
10,2,23:18.4
11,2,23:18.4
-26,3,23:18.12
-25,3,23:18.12
-23,3,23:18.12
-22,3,23:18.12
-21,3,23:18.12
-20,3,23:18.12
-19,3,23:18.12
-18,3,23:18.12
-17,3,23:17.12
-16,3,23:17.12
-11,3,23:18.12
-10,3,23:18.12
-8,3,23:18.12
-3,3,23:18.12
-2,3,23:18.12
2,3,23:18.12
3,3,23:18.12
-23,4,23:18.12
-22,4,23:18.12
-21,4,23:18.12
-20,4,23:18.12
-19,4,23:18.12
-18,4,23:18.12
-17,4,23:18.12
-16,4,23:17.12
-15,4,23:18.12
-14,4,23:18.12
-13,4,23:18.12
-12,4,23:18.12
-11,4,23:18.12
-10,4,23:18.12
-9,4,23:18.12
-8,4,23:18.12
-3,4,23:18.12
3,4,23:18.12
11,4,23:18.12
-24,5,23:18.12
-22,5,23:18.12
-21,5,23:18.12
-20,5,23:18.12
-15,5,23:17.12
-14,5,23:18.12
-13,5,23:18.12
-9,5,23:18.12
-8,5,23:18.12
-7,5,23:18.12
-6,5,23:18.12
-5,5,23:18.12
-4,5,23:18.12
2,5,23:18.12
-29,6,23:18.12
-28,6,23:18.12
-27,6,23:18.12
-26,6,23:18.4
-25,6,23:18.4
-24,6,23:18.4
-23,6,23:18.12
-22,6,23:18.12
-21,6,23:18.12
-20,6,23:18.12
-15,6,23:18.12
-14,6,23:18.12
-9,6,23:18.12
-8,6,23:18.12
-7,6,23:18.12
-6,6,23:18.12
-5,6,23:18.12
-4,6,23:18.12
3,6,23:18.4
-28,7,23:18.4
-27,7,23:18.4
-25,7,23:18.12
-24,7,23:18.12
-22,7,23:18.12
-21,7,23:18.12
-16,7,23:18.12
-4,7,23:18.12
3,7,23:18.4
4,7,23:18.12
-28,8,23:18.12
-27,8,23:18.12
-24,8,23:18.12
-23,8,23:18.12
-22,8,23:18.12
-16,8,23:18.12
-4,8,23:18.12
-3,8,23:18.12
4,8,23:18.12
5,8,23:18.12
9,8,23:18.12
10,8,23:18.12
13,8,23:18.12
14,8,23:18.12
-29,9,23:18.12
-28,9,23:18.12
-24,9,23:18.12
-22,9,23:18.12
-17,9,23:18.12
-8,9,23:17.12
-7,9,23:17.12
-3,9,23:18.12
5,9,23:18.12
7,9,23:18.12
8,9,23:18.12
9,9,23:18.12
10,9,23:18.12
11,9,23:18.12
12,9,23:18.12
13,9,23:18.12
-29,10,23:18.12
-28,10,23:18.12
-25,10,23:18.12
-24,10,23:18.12
-18,10,23:18.12
-17,10,23:18.12
-8,10,23:17.12
-7,10,23:17.12
5,10,23:18.12
6,10,23:18.12
7,10,23:18.12
12,10,23:18.12
-29,11,23:18.12
-26,11,23:18.12
-25,11,23:18.12
-21,11,23:18.12
-20,11,23:18.12
-19,11,23:18.12
-18,11,23:18.12
-17,11,23:18.12
-8,11,23:17.12
-6,11,23:18.12
-5,11,23:18.12
4,11,23:18.12
5,11,23:18.12
12,11,23:18.12
-27,12,23:18.12
-26,12,23:18.12
-24,12,23:17.12
-23,12,23:17.12
-22,12,23:17.12
-17,12,23:18.12
-6,12,23:18.12
-5,12,23:18.12
-4,12,23:18.12
-3,12,23:18.12
-2,12,23:18.12
0,12,23:18.12
4,12,23:18.12
5,12,23:18.12
6,12,23:18.12
12,12,23:18.12
-26,13,23:18.12
-25,13,23:18.12
-16,13,23:18.12
-11,13,23:18.12
-10,13,23:18.12
-6,13,23:18.12
-5,13,23:18.12
0,13,23:18.12
3,13,23:18.12
4,13,23:18.12
5,13,23:18.12
6,13,23:18.12
12,13,23:18.12
-25,14,23:18.12
-15,14,23:18.12
-10,14,23:18.12
-6,14,23:18.12
-1,14,23:18.12
0,14,23:18.12
1,14,23:18.12
3,14,23:18.12
6,14,23:18.12
7,14,23:18.12
8,14,23:18.12
-25,15,23:18.12
-24,15,23:18.12
-23,15,23:18.12
-14,15,23:18.12
-13,15,23:17.12
-12,15,23:17.12
-10,15,23:18.12
-9,15,23:18.12
-6,15,23:18.12
-2,15,23:18.12
-1,15,23:18.12
1,15,23:18.12
2,15,23:18.12
3,15,23:18.12
7,15,23:18.12
8,15,23:18.12
-24,16,23:18.12
-23,16,23:18.12
-15,16,23:18.12
-14,16,23:17.12
-13,16,23:18.12
-12,16,23:18.12
-10,16,23:18.12
-9,16,23:18.12
-8,16,23:18.12
-6,16,23:18.12
-5,16,23:18.12
1,16,23:18.12
2,16,23:18.12
3,16,23:18.12
4,16,23:18.12
5,16,23:18.12
7,16,23:18.12
8,16,23:18.12
9,16,23:18.12
-23,17,23:18.4
-16,17,23:18.12
-15,17,23:18.12
-14,17,23:17.12
-13,17,23:18.12
-12,17,23:18.12
-10,17,23:18.12
-9,17,23:18.12
-8,17,23:18.12
-7,17,23:18.12
-6,17,23:18.12
-5,17,23:18.12
-4,17,23:18.12
-3,17,23:18.12
1,17,23:18.12
2,17,23:18.12
8,17,23:18.12
9,17,23:18.12
10,17,23:18.4
-19,18,23:18.12
-18,18,23:18.12
-17,18,23:18.12
-16,18,23:18.12
-15,18,23:18.12
-14,18,23:18.12
-13,18,23:18.12
-12,18,23:18.12
-11,18,23:18.12
-10,18,23:18.12
-7,18,23:18.12
-5,18,23:18.12
-4,18,23:18.12
-3,18,23:18.12
-2,18,23:18.12
-1,18,23:18.12
0,18,23:18.12
1,18,23:18.12
2,18,23:18.12
6,18,23:18.12
7,18,23:18.12
8,18,23:18.12
9,18,23:18.12
10,18,23:18.4
-21,19,23:18.4
-20,19,23:18.12
-19,19,23:18.12
-18,19,23:18.12
-17,19,23:18.12
-16,19,23:18.12
-12,19,23:18.12
-11,19,23:18.12
-7,19,23:17.12
-6,19,23:17.12
-3,19,23:18.12
-2,19,23:18.12
-1,19,23:18.12
0,19,23:18.12
1,19,23:18.12
2,19,23:18.12
3,19,23:18.12
4,19,23:18.12
5,19,23:18.12
6,19,23:18.12
7,19,23:18.12
8,19,23:18.12
9,19,23:18.12
10,19,23:18.4
-21,20,23:18.4
-20,20,23:18.12
-19,20,23:18.12
-18,20,23:18.12
-17,20,23:18.12
-16,20,23:18.12
-12,20,23:18.12
-11,20,23:18.12
-7,20,23:17.12
-6,20,23:17.12
-5,20,23:18.12
-2,20,23:18.12
-1,20,23:18.12
0,20,23:18.12
1,20,23:18.12
2,20,23:18.12
3,20,23:18.12
4,20,23:18.12
5,20,23:18.12
6,20,23:18.12
7,20,23:18.12
-17,21,23:18.12
-16,21,23:18.12
-11,21,23:18.12
-5,21,23:18.12
-4,21,23:18.12
0,21,23:18.12
4,21,23:18.12
-17,22,23:18.12
-16,22,23:18.12
-11,22,23:18.12
-9,22,23:18.12
-8,22,23:18.12
-4,22,23:18.12
-3,22,23:18.12
-2,22,23:18.12
-1,22,23:18.12
0,22,23:18.4
1,22,23:18.12
-17,23,23:18.12
-16,23,23:18.12
-9,23,23:18.12
-4,23,23:18.12
-3,23,23:18.12
-2,23,23:18.12
-1,23,23:18.12
0,23,23:18.12
1,23,23:18.4
2,23,23:18.4
-7,24,23:18.12
-6,24,23:18.12
-5,24,23:18.12
-4,24,23:18.12
-3,24,23:18.12
-2,24,23:18.12
-1,24,23:18.12
2,24,23:18.4
-7,25,23:18.12
-6,25,23:18.12
-5,25,23:18.12
-4,25,23:18.12
-3,25,23:18.12
-2,25,23:18.12
-1,25,23:18.12
0,25,23:18.12
1,25,23:18.4
2,25,23:18.4
-6,26,23:18.12
-5,26,23:18.12
-4,26,23:18.12
-3,26,23:18.12
-2,26,23:18.12
-1,26,23:18.12
0,26,23:18.12
-1,27,23:18.12
0,27,23:18.12
-4,28,23:17.12
-4,29,23:17.12
-10,-13,24:17.12
-10,-12,24:17.12
6,-11,24:18.4
-6,-10,24:18.12
6,-10,24:18.4
-16,-9,24:18.4
-6,-9,24:18.12
-2,-9,24:18.4
6,-9,24:18.4
7,-9,24:18.4
8,-9,24:18.4
-16,-8,24:18.4
-7,-8,24:18.12
-2,-8,24:18.4
5,-8,24:18.4
6,-8,24:18.4
7,-8,24:18.4
8,-8,24:18.4
-18,-7,24:18.4
-17,-7,24:18.4
-16,-7,24:18.4
-15,-7,24:18.4
-10,-7,24:18.12
-9,-7,24:18.12
-7,-7,24:18.12
-2,-7,24:18.12
5,-7,24:18.12
-17,-6,24:18.4
-15,-6,24:18.4
-14,-6,24:18.12
-13,-6,24:18.12
-2,-6,24:18.12
4,-6,24:18.12
-21,-5,24:18.12
-20,-5,24:18.12
-13,-5,24:18.12
-12,-5,24:18.12
-11,-5,24:18.12
-2,-5,24:18.12
3,-5,24:18.12
-21,-4,24:18.12
-20,-4,24:18.12
-11,-4,24:18.12
-10,-4,24:18.12
-2,-4,24:18.12
2,-4,24:18.12
3,-4,24:18.12
-21,-3,24:18.12
-20,-3,24:18.12
5,-3,24:18.12
9,-3,24:18.4
10,-3,24:18.4
-20,-2,24:18.12
-19,-2,24:18.12
4,-2,24:18.12
5,-2,24:18.12
9,-2,24:18.4
10,-2,24:18.4
-20,-1,24:18.12
-19,-1,24:18.12
-1,-1,24:18.12
0,-1,24:18.12
1,-1,24:18.12
3,-1,24:18.12
4,-1,24:18.12
8,-1,24:18.4
9,-1,24:18.4
10,-1,24:18.4
11,-1,24:18.4
-24,0,24:18.12
-23,0,24:18.12
-22,0,24:18.12
-21,0,24:18.12
-20,0,24:18.12
-19,0,24:18.12
0,0,24:18.12
1,0,24:18.12
2,0,24:18.12
3,0,24:18.12
7,0,24:18.4
8,0,24:18.4
10,0,24:18.4
11,0,24:18.4
-25,1,24:18.12
-24,1,24:18.12
-23,1,24:18.12
-22,1,24:18.12
-21,1,24:18.12
-20,1,24:18.12
-19,1,24:18.12
-1,1,24:18.12
2,1,24:18.12
3,1,24:18.12
5,1,24:18.12
6,1,24:18.12
-23,2,24:18.12
-22,2,24:18.12
-21,2,24:18.12
-20,2,24:18.12
-19,2,24:17.12
-18,2,24:18.12
-17,2,24:18.12
-16,2,24:18.12
-11,2,24:18.12
-2,2,24:18.12
-1,2,24:18.12
3,2,24:18.12
4,2,24:18.12
-23,3,24:18.12
-22,3,24:18.12
-21,3,24:18.12
-20,3,24:18.12
-19,3,24:18.12
-18,3,24:18.12
-17,3,24:18.12
-16,3,24:18.12
-15,3,24:18.12
-14,3,24:18.12
-13,3,24:18.12
-12,3,24:18.12
-11,3,24:18.12
-10,3,24:18.12
-9,3,24:18.12
-8,3,24:18.12
-3,3,24:18.12
-2,3,24:18.12
3,3,24:18.12
-23,4,24:18.12
-22,4,24:18.12
-21,4,24:18.12
-20,4,24:18.12
-19,4,24:18.12
-18,4,24:18.12
-15,4,24:18.12
-14,4,24:18.12
-13,4,24:18.12
-9,4,24:18.12
-8,4,24:18.12
-6,4,24:18.12
-5,4,24:18.12
-4,4,24:18.12
-3,4,24:18.12
-15,5,24:18.12
-14,5,24:18.12
-10,5,24:18.12
-9,5,24:18.12
-8,5,24:18.12
-7,5,24:18.12
-6,5,24:18.12
-5,5,24:18.12
-4,5,24:18.12
-3,5,24:18.12
-29,6,24:18.12
-28,6,24:18.12
-27,6,24:18.12
-26,6,24:18.12
-25,6,24:18.4
-24,6,24:18.4
-8,6,24:18.12
-3,6,24:18.12
3,6,24:18.4
4,6,24:18.4
-29,7,24:18.4
-28,7,24:18.4
-16,7,24:18.12
-8,7,24:17.12
-3,7,24:18.12
-2,7,24:18.12
4,7,24:18.4
-29,8,24:18.12
-27,8,24:18.12
-26,8,24:18.12
-24,8,24:18.12
-17,8,24:18.12
-16,8,24:18.12
-8,8,24:17.12
-3,8,24:18.12
-2,8,24:18.12
5,8,24:18.12
9,8,24:18.12
10,8,24:18.12
-27,9,24:18.12
-25,9,24:18.12
-24,9,24:18.12
-17,9,24:18.12
-8,9,24:17.12
-7,9,24:17.12
-3,9,24:18.12
-2,9,24:18.12
5,9,24:18.12
6,9,24:18.12
9,9,24:18.12
10,9,24:18.12
11,9,24:18.12
12,9,24:18.12
13,9,24:18.12
14,9,24:18.12
-28,10,24:18.12
-27,10,24:18.12
-26,10,24:18.12
-25,10,24:18.12
-18,10,24:18.12
-17,10,24:18.12
-8,10,24:17.12
-7,10,24:17.12
-2,10,24:18.12
-1,10,24:18.12
5,10,24:18.12
6,10,24:18.12
7,10,24:18.12
12,10,24:18.12
13,10,24:18.12
-29,11,24:18.12
-28,11,24:18.12
-27,11,24:18.12
-26,11,24:18.12
-22,11,24:18.12
-21,11,24:18.12
-20,11,24:18.12
-19,11,24:18.12
-18,11,24:18.12
-17,11,24:18.12
-6,11,24:18.12
0,11,24:18.12
1,11,24:18.12
5,11,24:18.12
6,11,24:18.12
7,11,24:18.12
12,11,24:18.12
13,11,24:18.12
-29,12,24:18.12
-28,12,24:18.12
-27,12,24:18.12
-26,12,24:18.12
-17,12,24:18.12
-6,12,24:18.12
-5,12,24:18.12
-3,12,24:18.12
-2,12,24:18.12
-1,12,24:18.12
0,12,24:18.12
1,12,24:18.12
2,12,24:18.12
4,12,24:18.12
5,12,24:18.12
6,12,24:18.12
7,12,24:18.12
8,12,24:18.12
13,12,24:18.12
-27,13,24:18.12
-26,13,24:18.12
-16,13,24:18.12
-11,13,24:18.12
-10,13,24:18.12
-5,13,24:18.12
-4,13,24:18.12
-3,13,24:18.12
-2,13,24:18.12
0,13,24:18.12
1,13,24:18.12
4,13,24:18.12
8,13,24:18.4
9,13,24:18.4
13,13,24:18.4
-26,14,24:18.12
-25,14,24:18.12
-21,14,24:18.12
-20,14,24:18.12
-19,14,24:18.12
-16,14,24:18.12
-15,14,24:18.12
-10,14,24:18.12
-5,14,24:18.12
-4,14,24:18.12
0,14,24:18.12
1,14,24:18.12
8,14,24:18.12
9,14,24:18.12
10,14,24:18.4
-25,15,24:18.12
-18,15,24:18.12
-17,15,24:18.12
-16,15,24:18.12
-15,15,24:18.12
-14,15,24:18.12
-13,15,24:18.12
-10,15,24:18.12
-9,15,24:18.12
-7,15,24:18.12
-5,15,24:18.12
-4,15,24:18.12
-2,15,24:18.12
-1,15,24:18.12
0,15,24:18.12
1,15,24:18.12
2,15,24:18.12
3,15,24:18.12
9,15,24:18.12
10,15,24:18.4
-25,16,24:18.12
-24,16,24:18.12
-15,16,24:18.12
-14,16,24:18.12
-13,16,24:18.12
-11,16,24:18.12
-10,16,24:18.12
-9,16,24:18.12
-8,16,24:18.12
-6,16,24:18.12
-5,16,24:18.12
-4,16,24:18.12
-3,16,24:18.12
-2,16,24:18.12
3,16,24:18.12
4,16,24:18.12
5,16,24:18.12
10,16,24:18.4
-24,17,24:18.4
-16,17,24:18.12
-15,17,24:18.12
-14,17,24:18.12
-13,17,24:18.12
-12,17,24:18.12
-9,17,24:18.12
-8,17,24:18.12
-7,17,24:18.12
-6,17,24:18.12
-5,17,24:18.12
2,17,24:18.12
3,17,24:18.12
4,17,24:18.12
6,17,24:18.12
10,17,24:18.4
11,17,24:18.4
-17,18,24:18.12
-16,18,24:18.12
-15,18,24:17.12
-14,18,24:18.12
-13,18,24:18.12
-10,18,24:18.12
-9,18,24:18.12
-7,18,24:18.12
-6,18,24:18.12
-5,18,24:18.12
-4,18,24:18.12
2,18,24:18.12
3,18,24:18.12
-19,19,24:18.12
-18,19,24:18.12
-17,19,24:18.12
-16,19,24:18.12
-15,19,24:18.12
-14,19,24:18.12
-13,19,24:18.12
-10,19,24:18.12
-6,19,24:18.12
-5,19,24:18.12
-4,19,24:18.12
-3,19,24:18.12
-2,19,24:18.12
-1,19,24:18.12
1,19,24:18.12
2,19,24:18.12
3,19,24:18.12
10,19,24:18.4
-20,20,24:18.12
-19,20,24:18.12
-17,20,24:18.12
-16,20,24:18.12
-15,20,24:18.12
-14,20,24:18.12
-13,20,24:18.12
-12,20,24:18.12
-7,20,24:18.12
-6,20,24:17.12
-5,20,24:18.12
-4,20,24:18.12
-3,20,24:18.12
-2,20,24:18.12
-1,20,24:18.12
0,20,24:18.12
1,20,24:18.12
2,20,24:18.12
7,20,24:18.12
8,20,24:18.12
10,20,24:18.4
-21,21,24:18.4
-20,21,24:18.12
-19,21,24:18.12
-18,21,24:18.12
-13,21,24:18.12
-12,21,24:18.12
-5,21,24:18.12
-4,21,24:18.12
-2,21,24:18.12
-1,21,24:18.12
0,21,24:18.12
2,21,24:18.12
6,21,24:18.12
7,21,24:18.12
8,21,24:18.12
-19,22,24:18.12
-12,22,24:18.12
-11,22,24:18.12
-8,22,24:18.12
-4,22,24:18.12
-3,22,24:18.12
-1,22,24:18.12
0,22,24:18.4
1,22,24:18.12
2,22,24:18.12
-12,23,24:18.12
-11,23,24:18.12
-10,23,24:18.12
-9,23,24:18.12
-3,23,24:18.12
-2,23,24:18.12
-1,23,24:18.12
1,23,24:18.4
2,23,24:18.4
-12,24,24:18.12
-11,24,24:18.12
-10,24,24:18.12
-9,24,24:18.12
-8,24,24:18.12
-7,24,24:18.12
-5,24,24:18.12
-4,24,24:18.12
-3,24,24:18.12
-2,24,24:18.12
-11,25,24:18.4
-10,25,24:18.12
-8,25,24:18.12
-7,25,24:18.12
-6,25,24:18.12
-5,25,24:18.12
-4,25,24:18.12
-7,26,24:18.12
-6,26,24:18.12
-4,26,24:18.12
-3,26,24:18.12
-6,27,24:18.12
-5,27,24:18.12
-4,27,24:18.12
-3,27,24:18.12
-10,-14,25:17.12
-10,-11,25:18.12
-10,-10,25:18.12
-10,-9,25:18.12
-2,-9,25:18.4
-10,-8,25:18.12
-9,-8,25:17.12
-2,-8,25:18.4
5,-8,25:18.4
-17,-7,25:18.4
-16,-7,25:18.4
-11,-7,25:18.12
-10,-7,25:18.12
-9,-7,25:18.12
-8,-7,25:18.12
-2,-7,25:18.12
4,-7,25:18.12
5,-7,25:18.12
-22,-6,25:18.12
-15,-6,25:18.4
-14,-6,25:18.12
-2,-6,25:18.12
4,-6,25:18.12
-22,-5,25:18.12
-21,-5,25:18.12
-13,-5,25:18.12
-12,-5,25:18.12
-2,-5,25:18.12
3,-5,25:18.12
-22,-4,25:18.12
-21,-4,25:18.12
-11,-4,25:18.12
-2,-4,25:18.12
2,-4,25:18.12
-22,-3,25:18.12
-21,-3,25:18.12
-22,-2,25:18.12
-21,-2,25:18.12
4,-2,25:18.12
5,-2,25:18.12
-26,-1,25:18.12
-25,-1,25:18.12
-24,-1,25:18.12
-23,-1,25:18.12
-22,-1,25:18.12
-21,-1,25:18.12
-19,-1,25:18.12
-1,-1,25:18.12
0,-1,25:18.12
1,-1,25:18.12
3,-1,25:18.12
4,-1,25:18.12
8,-1,25:18.4
-25,0,25:18.12
-24,0,25:18.12
-23,0,25:18.12
-22,0,25:18.12
-21,0,25:18.12
-20,0,25:18.12
-18,0,25:18.12
0,0,25:18.12
2,0,25:18.12
3,0,25:18.12
6,0,25:18.12
7,0,25:18.4
-20,1,25:17.12
-19,1,25:18.12
-17,1,25:18.12
-1,1,25:18.12
3,1,25:18.12
5,1,25:18.12
6,1,25:18.12
-18,2,25:18.12
-16,2,25:18.12
-15,2,25:18.12
-14,2,25:18.12
-13,2,25:18.12
-12,2,25:18.12
-11,2,25:18.12
-10,2,25:18.12
-8,2,25:18.12
-2,2,25:18.12
-1,2,25:18.12
3,2,25:18.12
4,2,25:18.12
-21,3,25:18.12
-20,3,25:18.12
-19,3,25:18.12
-16,3,25:18.12
-15,3,25:18.12
-14,3,25:18.12
-13,3,25:18.12
-12,3,25:18.12
-9,3,25:18.12
-8,3,25:18.12
-7,3,25:18.12
-6,3,25:18.12
-5,3,25:18.12
-4,3,25:18.12
-3,3,25:18.12
-2,3,25:18.12
3,3,25:18.12
-23,4,25:18.12
-22,4,25:18.12
-21,4,25:18.12
-16,4,25:18.12
-14,4,25:18.12
-9,4,25:18.12
-8,4,25:18.12
-7,4,25:18.12
-6,4,25:18.12
-5,4,25:18.12
-4,4,25:18.12
-3,4,25:18.12
-2,4,25:18.4
1,4,25:18.4
2,4,25:18.4
-22,5,25:18.12
-21,5,25:18.12
-20,5,25:18.12
-16,5,25:18.12
-8,5,25:17.12
-7,5,25:18.12
-2,5,25:18.4
-1,5,25:18.4
0,5,25:18.4
1,5,25:18.4
-27,6,25:18.12
-26,6,25:18.12
-25,6,25:18.12
-24,6,25:18.4
-16,6,25:18.12
-8,6,25:17.12
-7,6,25:17.12
-3,6,25:18.12
-2,6,25:18.4
-1,6,25:18.4
4,6,25:18.4
-28,7,25:18.4
-27,7,25:18.4
-16,7,25:18.12
-9,7,25:17.12
-8,7,25:17.12
-7,7,25:17.12
-4,7,25:18.12
-3,7,25:18.12
-2,7,25:18.4
-1,7,25:18.4
4,7,25:18.4
5,7,25:18.4
-29,8,25:18.4
-28,8,25:18.12
-25,8,25:18.12
-17,8,25:18.12
-8,8,25:17.12
-7,8,25:17.12
-6,8,25:18.12
-5,8,25:18.12
-2,8,25:18.4
-1,8,25:18.4
5,8,25:18.4
6,8,25:18.12
10,8,25:18.12
-29,9,25:18.4
-26,9,25:18.12
-25,9,25:18.12
-17,9,25:18.12
-8,9,25:17.12
-7,9,25:17.12
-6,9,25:18.12
-1,9,25:18.12
0,9,25:18.12
6,9,25:18.12
11,9,25:18.12
12,9,25:18.12
-26,10,25:18.12
-20,10,25:18.12
-19,10,25:18.12
-18,10,25:18.12
-8,10,25:17.12
-7,10,25:17.12
-1,10,25:18.12
1,10,25:18.12
6,10,25:18.12
13,10,25:18.12
-27,11,25:18.12
-23,11,25:18.12
-22,11,25:18.12
-21,11,25:18.12
-20,11,25:18.12
-19,11,25:18.12
-18,11,25:18.12
-17,11,25:18.12
-6,11,25:18.12
1,11,25:18.12
6,11,25:18.12
13,11,25:18.12
14,11,25:18.12
-29,12,25:18.4
-28,12,25:18.12
-27,12,25:18.12
-17,12,25:18.12
-9,12,25:18.12
-6,12,25:18.12
-5,12,25:18.12
1,12,25:18.12
2,12,25:18.12
5,12,25:18.12
-27,13,25:18.12
-16,13,25:18.12
-10,13,25:18.12
-5,13,25:18.12
-4,13,25:18.12
-3,13,25:18.12
-2,13,25:18.12
0,13,25:18.12
1,13,25:18.12
2,13,25:18.12
3,13,25:18.12
5,13,25:18.12
9,13,25:18.4
10,13,25:18.4
-27,14,25:18.12
-26,14,25:18.12
-22,14,25:18.12
-21,14,25:18.12
-20,14,25:18.12
-16,14,25:18.12
-15,14,25:18.12
-10,14,25:18.12
-7,14,25:18.12
-4,14,25:18.12
-3,14,25:18.12
-2,14,25:18.12
-1,14,25:18.12
1,14,25:18.12
2,14,25:18.12
10,14,25:18.4
-26,15,25:18.12
-20,15,25:18.12
-19,15,25:18.12
-18,15,25:18.12
-17,15,25:18.12
-16,15,25:18.12
-15,15,25:18.12
-14,15,25:18.12
-13,15,25:18.12
-10,15,25:18.12
-9,15,25:18.12
-7,15,25:18.12
-4,15,25:18.12
-3,15,25:18.12
0,15,25:18.12
1,15,25:18.12
2,15,25:18.12
3,15,25:18.12
-25,16,25:18.12
-17,16,25:18.12
-16,16,25:18.12
-15,16,25:18.12
-11,16,25:18.12
-10,16,25:18.12
-9,16,25:18.12
-5,16,25:18.12
-4,16,25:18.12
-3,16,25:18.12
-2,16,25:18.12
-1,16,25:18.12
0,16,25:18.12
4,16,25:18.12
5,16,25:18.12
6,16,25:18.12
-16,17,25:18.12
-15,17,25:18.12
-12,17,25:18.12
-10,17,25:18.12
-9,17,25:18.12
-8,17,25:18.12
-7,17,25:18.12
-6,17,25:18.12
-4,17,25:18.12
-3,17,25:18.12
-2,17,25:18.12
3,17,25:17.12
4,17,25:18.12
6,17,25:18.12
7,17,25:18.12
-17,18,25:18.12
-16,18,25:18.12
-15,18,25:18.12
-14,18,25:17.12
-13,18,25:18.12
-8,18,25:18.12
-7,18,25:18.12
-4,18,25:18.12
4,18,25:18.12
5,18,25:17.12
-18,19,25:18.12
-17,19,25:18.12
-16,19,25:18.12
-15,19,25:18.12
-14,19,25:18.12
-13,19,25:18.12
-12,19,25:18.12
-11,19,25:18.12
-10,19,25:18.12
-7,19,25:18.12
-5,19,25:18.12
-4,19,25:18.12
-2,19,25:18.12
3,19,25:18.12
4,19,25:18.12
-19,20,25:18.12
-17,20,25:18.12
-16,20,25:18.12
-15,20,25:18.12
-14,20,25:18.12
-13,20,25:18.12
-12,20,25:18.12
-11,20,25:18.12
-10,20,25:18.12
-7,20,25:18.12
-5,20,25:18.12
-4,20,25:18.12
-3,20,25:18.12
2,20,25:18.12
3,20,25:18.12
4,20,25:18.12
-20,21,25:18.12
-19,21,25:18.12
-18,21,25:18.12
-17,21,25:18.12
-16,21,25:18.12
-15,21,25:18.12
-14,21,25:18.12
-13,21,25:18.12
-7,21,25:18.12
-4,21,25:18.12
-3,21,25:18.12
-2,21,25:18.12
-1,21,25:18.12
0,21,25:18.12
2,21,25:18.12
3,21,25:18.12
-20,22,25:18.12
-19,22,25:18.12
-18,22,25:18.12
-16,22,25:18.12
-15,22,25:18.12
-14,22,25:18.12
-13,22,25:18.12
-7,22,25:18.12
-6,22,25:17.12
-4,22,25:18.12
-3,22,25:18.12
-2,22,25:18.12
-1,22,25:18.12
0,22,25:18.4
1,22,25:18.12
2,22,25:18.12
3,22,25:18.12
-14,23,25:18.12
-13,23,25:18.12
-12,23,25:18.12
-10,23,25:18.12
-9,23,25:18.12
-2,23,25:18.12
-1,23,25:18.12
0,23,25:18.12
1,23,25:18.4
2,23,25:18.4
-13,24,25:18.12
-12,24,25:18.12
-10,24,25:18.12
-9,24,25:18.12
-8,24,25:18.12
-3,24,25:18.12
-2,24,25:18.12
-1,24,25:18.12
-13,25,25:18.4
-12,25,25:18.4
-10,25,25:18.12
-8,25,25:18.12
-7,25,25:18.12
-5,25,25:18.12
-4,25,25:18.12
-3,25,25:18.12
-2,25,25:18.12
-12,26,25:18.4
-11,26,25:18.4
-10,26,25:18.12
-8,26,25:18.12
-7,26,25:18.12
-6,26,25:18.12
-5,26,25:18.12
-7,27,25:18.12
-6,27,25:18.12
-6,28,25:18.12
-10,-12,26:18.12
-10,-11,26:18.12
-10,-10,26:18.12
-10,-9,26:18.12
-9,-9,26:17.12
-11,-8,26:18.12
-10,-8,26:18.12
-9,-8,26:18.12
-8,-8,26:18.12
5,-8,26:18.4
-12,-7,26:18.12
-11,-7,26:18.12
-8,-7,26:18.12
-7,-7,26:18.12
-6,-7,26:18.12
4,-7,26:18.12
5,-7,26:18.12
-15,-6,26:18.4
-14,-6,26:18.12
-12,-6,26:18.12
4,-6,26:18.12
-13,-5,26:18.12
3,-5,26:18.12
-24,-4,26:18.12
-23,-4,26:18.12
-25,-3,26:18.12
-24,-3,26:18.12
-23,-3,26:18.12
-25,-2,26:18.12
-24,-2,26:18.12
-23,-2,26:18.12
-22,-2,26:18.12
-22,-1,26:18.12
-21,-1,26:18.12
-19,-1,26:18.12
-18,-1,26:18.12
-5,-1,26:18.12
-4,-1,26:18.12
0,-1,26:18.12
1,-1,26:18.12
8,-1,26:18.4
-21,0,26:18.12
-20,0,26:18.12
-18,0,26:18.12
-17,0,26:18.12
-6,0,26:18.12
-5,0,26:18.12
0,0,26:18.12
2,0,26:18.12
3,0,26:18.12
6,0,26:18.12
7,0,26:18.4
-20,1,26:17.12
-19,1,26:18.12
-17,1,26:18.12
-16,1,26:18.12
-13,1,26:18.12
-12,1,26:18.12
-11,1,26:18.12
-6,1,26:18.12
-1,1,26:18.12
0,1,26:18.12
3,1,26:18.12
4,1,26:18.12
5,1,26:18.12
6,1,26:18.12
-16,2,26:18.12
-15,2,26:18.12
-14,2,26:18.12
-13,2,26:18.12
-8,2,26:18.12
-7,2,26:18.12
-6,2,26:18.12
-5,2,26:18.12
-4,2,26:18.12
-3,2,26:18.12
-2,2,26:18.12
-1,2,26:18.12
-16,3,26:18.12
-8,3,26:18.12
-7,3,26:18.12
-6,3,26:18.12
-5,3,26:18.12
-4,3,26:18.12
-3,3,26:18.12
-2,3,26:18.12
-1,3,26:18.12
-16,4,26:18.12
-8,4,26:17.12
-7,4,26:18.12
-6,4,26:18.12
-1,4,26:18.4
2,4,26:18.4
3,4,26:18.4
-17,5,26:18.12
-16,5,26:18.12
-9,5,26:17.12
-8,5,26:17.12
-7,5,26:18.12
-6,5,26:18.12
-5,5,26:18.12
-1,5,26:18.4
0,5,26:18.4
1,5,26:18.4
2,5,26:18.4
3,5,26:18.4
-26,6,26:18.12
-25,6,26:18.12
-17,6,26:18.12
-8,6,26:18.12
-1,6,26:18.4
0,6,26:18.4
1,6,26:18.4
-27,7,26:18.4
-26,7,26:18.4
-17,7,26:18.12
-16,7,26:18.12
-8,7,26:18.12
-3,7,26:18.12
-2,7,26:18.4
-1,7,26:18.4
0,7,26:18.4
-28,8,26:18.12
-27,8,26:18.12
-17,8,26:18.12
-8,8,26:18.12
-6,8,26:18.12
-5,8,26:18.12
-4,8,26:18.12
-3,8,26:18.12
-2,8,26:18.4
0,8,26:18.4
6,8,26:18.4
-26,9,26:18.12
-18,9,26:18.12
-17,9,26:18.12
-8,9,26:17.12
-7,9,26:17.12
-6,9,26:18.12
-5,9,26:18.12
-4,9,26:18.12
0,9,26:18.4
12,9,26:18.4
-27,10,26:18.12
-26,10,26:18.12
-22,10,26:18.12
-21,10,26:18.12
-20,10,26:18.12
-19,10,26:18.12
-18,10,26:18.12
-15,10,26:18.12
-13,10,26:18.12
-8,10,26:17.12
-7,10,26:17.12
-5,10,26:18.12
-4,10,26:18.12
2,10,26:18.4
-28,11,26:18.12
-27,11,26:18.12
-22,11,26:18.12
-18,11,26:18.12
-17,11,26:18.12
-8,11,26:18.12
-7,11,26:17.12
-4,11,26:18.12
2,11,26:18.12
-28,12,26:18.12
-17,12,26:18.12
-9,12,26:18.12
-5,12,26:18.12
2,12,26:18.12
-28,13,26:18.12
-16,13,26:18.12
-10,13,26:18.12
-5,13,26:18.12
-4,13,26:18.12
2,13,26:18.12
3,13,26:18.12
-27,14,26:18.12
-23,14,26:18.12
-22,14,26:18.12
-21,14,26:18.12
-16,14,26:18.12
-15,14,26:18.12
-14,14,26:18.12
-13,14,26:18.12
-10,14,26:18.12
-7,14,26:18.12
-3,14,26:18.12
-2,14,26:18.12
-1,14,26:18.12
0,14,26:18.12
1,14,26:18.12
2,14,26:18.12
3,14,26:18.12
4,14,26:18.12
-26,15,26:18.12
-21,15,26:18.12
-20,15,26:18.12
-19,15,26:18.12
-18,15,26:18.12
-16,15,26:18.12
-15,15,26:18.12
-14,15,26:18.12
-11,15,26:18.12
-7,15,26:18.12
-4,15,26:18.12
-3,15,26:18.12
-2,15,26:18.12
-1,15,26:18.12
0,15,26:18.12
1,15,26:18.12
2,15,26:18.12
3,15,26:18.12
4,15,26:18.12
-26,16,26:18.12
-18,16,26:18.12
-17,16,26:18.12
-16,16,26:18.12
-11,16,26:18.12
-5,16,26:18.12
-4,16,26:18.12
-3,16,26:18.12
-2,16,26:18.12
-1,16,26:18.12
0,16,26:18.12
1,16,26:18.12
4,16,26:18.12
5,16,26:18.12
6,16,26:18.12
-17,17,26:18.12
-16,17,26:18.12
-10,17,26:18.12
-9,17,26:18.12
-8,17,26:18.12
-7,17,26:18.12
-6,17,26:18.12
-3,17,26:18.12
-2,17,26:18.12
-1,17,26:18.12
6,17,26:18.12
7,17,26:18.12
-18,18,26:18.12
-17,18,26:18.12
-16,18,26:18.12
-15,18,26:17.12
-14,18,26:18.12
-13,18,26:18.12
-8,18,26:18.12
-7,18,26:18.12
-3,18,26:18.12
-19,19,26:18.12
-18,19,26:18.12
-17,19,26:18.12
-16,19,26:18.12
-15,19,26:17.12
-14,19,26:18.12
-13,19,26:18.12
-7,19,26:18.12
-4,19,26:18.12
-3,19,26:18.12
-2,19,26:18.12
-19,20,26:18.12
-16,20,26:18.12
-15,20,26:18.12
-14,20,26:18.12
-13,20,26:18.12
-12,20,26:18.12
-11,20,26:18.12
-10,20,26:18.12
-7,20,26:18.12
-4,20,26:18.12
-3,20,26:18.12
4,20,26:18.12
-16,21,26:18.12
-15,21,26:18.12
-14,21,26:18.12
-13,21,26:18.12
-12,21,26:18.12
-11,21,26:18.12
-10,21,26:18.12
-9,21,26:18.12
-7,21,26:18.12
-4,21,26:18.12
-3,21,26:18.12
-19,22,26:18.12
-18,22,26:18.12
-17,22,26:18.12
-16,22,26:18.12
-15,22,26:18.12
-14,22,26:18.12
-13,22,26:18.12
-7,22,26:18.12
-4,22,26:18.12
-3,22,26:18.12
-2,22,26:18.12
-20,23,26:18.12
-19,23,26:18.12
-18,23,26:18.12
-17,23,26:18.12
-16,23,26:18.12
-15,23,26:18.12
-14,23,26:18.12
-3,23,26:18.12
-2,23,26:18.12
-1,23,26:18.12
0,23,26:18.12
1,23,26:18.4
-20,24,26:18.12
-15,24,26:18.12
-14,24,26:18.12
-13,24,26:18.12
-10,24,26:18.12
-2,24,26:18.12
-1,24,26:18.12
0,24,26:18.12
1,24,26:18.4
-14,25,26:18.4
-13,25,26:18.4
-9,25,26:18.12
-8,25,26:18.12
-3,25,26:18.12
-2,25,26:18.12
-1,25,26:18.12
-14,26,26:18.4
-13,26,26:18.4
-8,26,26:18.12
-7,26,26:18.12
-6,26,26:18.12
-5,26,26:18.12
-4,26,26:18.12
-3,26,26:18.12
-11,27,26:18.4
-8,27,26:18.12
-6,27,26:18.12
-5,27,26:18.12
-6,28,26:18.12
-6,29,26:18.12
-10,-12,27:18.12
-10,-11,27:18.12
-10,-10,27:18.12
-11,-9,27:18.12
-10,-9,27:18.12
-9,-9,27:18.12
-12,-8,27:18.12
-11,-8,27:18.12
-9,-8,27:18.12
-8,-8,27:18.12
-7,-8,27:18.12
-13,-7,27:18.12
-12,-7,27:18.12
-7,-7,27:18.12
-6,-7,27:18.12
-9,-4,27:18.12
-9,-3,27:18.12
-8,-3,27:18.12
-4,-3,27:18.4
-3,-3,27:18.12
-23,-2,27:17.12
-22,-2,27:18.12
-19,-2,27:18.12
-9,-2,27:18.12
-8,-2,27:18.12
-6,-2,27:18.12
-5,-2,27:18.12
-4,-2,27:18.4
-22,-1,27:18.12
-21,-1,27:18.12
-19,-1,27:18.12
-18,-1,27:18.12
-9,-1,27:17.12
-8,-1,27:18.12
-7,-1,27:18.12
-6,-1,27:18.12
-5,-1,27:18.12
-4,-1,27:18.12
-21,0,27:17.12
-20,0,27:18.12
-18,0,27:18.12
-17,0,27:18.12
-12,0,27:18.12
-9,0,27:17.12
-8,0,27:18.12
-7,0,27:18.12
-5,0,27:18.12
-4,0,27:18.12
-20,1,27:18.12
-19,1,27:18.12
-17,1,27:18.12
-16,1,27:18.12
-15,1,27:18.12
-14,1,27:18.12
-13,1,27:18.12
-12,1,27:18.12
-9,1,27:17.12
-8,1,27:18.12
-5,1,27:18.12
-4,1,27:18.12
-3,1,27:18.12
-2,1,27:18.12
-1,1,27:18.12
-19,2,27:18.12
-18,2,27:18.12
-16,2,27:18.12
-9,2,27:17.12
-8,2,27:18.12
-7,2,27:18.12
-6,2,27:18.12
-5,2,27:18.12
-4,2,27:18.12
-3,2,27:18.12
-2,2,27:18.12
-17,3,27:18.12
-16,3,27:18.12
-9,3,27:17.12
-8,3,27:17.12
-6,3,27:18.12
-5,3,27:18.12
-17,4,27:18.12
-9,4,27:17.12
-8,4,27:17.12
-6,4,27:18.12
-5,4,27:18.12
-4,4,27:18.12
0,4,27:18.4
-17,5,27:18.12
-8,5,27:18.12
-7,5,27:18.12
-5,5,27:18.12
-4,5,27:18.12
-3,5,27:18.12
-2,5,27:18.4
0,5,27:18.4
1,5,27:18.4
2,5,27:18.4
3,5,27:18.4
4,5,27:18.4
-17,6,27:18.12
-8,6,27:18.12
-3,6,27:18.12
-2,6,27:18.4
-1,6,27:18.4
0,6,27:18.4
1,6,27:18.4
2,6,27:18.4
3,6,27:18.4
-17,7,27:18.12
-9,7,27:18.12
-8,7,27:18.12
-1,7,27:18.4
0,7,27:18.4
1,7,27:18.4
-17,8,27:18.12
-9,8,27:18.12
-8,8,27:18.12
-7,8,27:18.12
-6,8,27:18.12
-5,8,27:18.12
-4,8,27:18.12
-3,8,27:18.12
-2,8,27:18.4
-1,8,27:18.4
0,8,27:18.4
-18,9,27:18.12
-17,9,27:18.12
-9,9,27:18.12
-8,9,27:18.12
-7,9,27:18.12
-6,9,27:18.12
-4,9,27:18.12
-3,9,27:18.12
-2,9,27:18.4
-22,10,27:18.12
-21,10,27:18.12
-20,10,27:18.12
-19,10,27:18.12
-18,10,27:18.12
-10,10,27:18.12
-9,10,27:18.12
-8,10,27:18.12
-7,10,27:18.12
-5,10,27:18.12
-4,10,27:18.12
-3,10,27:18.12
-2,10,27:18.4
3,10,27:18.4
-18,11,27:18.12
-17,11,27:18.12
-16,11,27:18.12
-15,11,27:18.12
-14,11,27:18.12
-13,11,27:18.12
-12,11,27:18.12
-11,11,27:18.12
-10,11,27:18.12
-9,11,27:18.12
-8,11,27:18.12
-7,11,27:17.12
-3,11,27:18.12
-2,11,27:18.4
-1,11,27:18.4
3,11,27:18.4
-17,12,27:18.12
-10,12,27:18.12
-9,12,27:18.12
-8,12,27:17.12
-7,12,27:18.12
-5,12,27:18.12
-2,12,27:18.4
-1,12,27:18.4
3,12,27:18.4
-16,13,27:18.12
-13,13,27:18.12
-10,13,27:18.12
-9,13,27:18.12
-7,13,27:18.12
-4,13,27:18.12
-2,13,27:18.4
3,13,27:18.12
-23,14,27:18.12
-15,14,27:18.12
-14,14,27:18.12
-13,14,27:18.12
-10,14,27:18.12
-7,14,27:18.12
-3,14,27:18.12
-1,14,27:18.12
3,14,27:18.12
4,14,27:18.12
-23,15,27:18.12
-22,15,27:18.12
-21,15,27:18.12
-20,15,27:18.12
-17,15,27:18.12
-16,15,27:18.12
-15,15,27:18.12
-11,15,27:18.12
-10,15,27:18.12
-7,15,27:18.12
-4,15,27:18.12
-3,15,27:18.12
-2,15,27:18.12
-1,15,27:18.12
0,15,27:18.12
1,15,27:18.12
2,15,27:18.12
3,15,27:18.12
4,15,27:18.12
-20,16,27:18.12
-19,16,27:18.12
-18,16,27:18.12
-17,16,27:18.12
-11,16,27:18.12
-5,16,27:18.12
-4,16,27:18.12
-2,16,27:18.12
-1,16,27:18.12
0,16,27:18.12
1,16,27:18.12
2,16,27:18.12
3,16,27:18.12
4,16,27:18.12
5,16,27:18.12
6,16,27:18.12
-19,17,27:18.12
-18,17,27:18.12
-17,17,27:18.12
-11,17,27:18.12
-10,17,27:18.12
-9,17,27:18.12
-7,17,27:18.12
-6,17,27:18.12
-2,17,27:18.12
-1,17,27:18.12
0,17,27:18.12
1,17,27:18.12
7,17,27:18.12
-18,18,27:18.12
-17,18,27:18.12
-14,18,27:18.12
-13,18,27:18.12
-8,18,27:18.12
-7,18,27:18.12
-2,18,27:18.12
-1,18,27:18.12
-18,19,27:18.12
-17,19,27:18.12
-16,19,27:17.12
-15,19,27:17.12
-14,19,27:18.12
-13,19,27:18.12
-8,19,27:18.12
-7,19,27:18.12
-2,19,27:18.12
-1,19,27:18.12
-18,20,27:18.12
-17,20,27:18.12
-16,20,27:17.12
-15,20,27:18.12
-14,20,27:18.12
-13,20,27:18.12
-8,20,27:18.12
-7,20,27:18.12
-3,20,27:18.12
-2,20,27:18.12
-1,20,27:18.12
-18,21,27:18.12
-17,21,27:18.12
-15,21,27:18.12
-14,21,27:18.12
-12,21,27:18.12
-11,21,27:18.12
-7,21,27:18.12
-3,21,27:18.12
-2,21,27:18.12
-18,22,27:18.12
-17,22,27:18.12
-16,22,27:18.12
-15,22,27:18.12
-13,22,27:18.12
-12,22,27:18.12
-11,22,27:18.12
-7,22,27:18.12
-17,23,27:18.12
-15,23,27:18.12
-13,23,27:18.12
-20,24,27:18.12
-19,24,27:18.12
-18,24,27:18.12
-17,24,27:18.12
-16,24,27:18.12
-15,24,27:18.12
-18,25,27:18.4
-15,25,27:18.4
-14,25,27:18.4
-9,25,27:18.12
-2,25,27:18.12
-1,25,27:18.12
-14,26,27:18.4
-9,26,27:18.12
-8,26,27:18.12
-7,26,27:18.12
-4,26,27:18.12
-3,26,27:18.12
-2,26,27:18.12
-7,27,27:18.12
-6,27,27:18.12
-5,27,27:18.12
-4,27,27:18.12
-6,28,27:18.12
-10,-11,28:18.12
-10,-10,28:18.12
-12,-9,28:18.12
-11,-9,28:18.12
-10,-9,28:18.12
-9,-9,28:18.12
-8,-9,28:18.12
-12,-8,28:18.12
-8,-8,28:18.12
-7,-8,28:18.12
-8,-6,28:18.12
-8,-5,28:18.12
-7,-5,28:18.12
-6,-5,28:18.12
-9,-4,28:18.12
-8,-4,28:18.12
-7,-4,28:18.12
-6,-4,28:18.12
-5,-4,28:18.12
-9,-3,28:18.12
-8,-3,28:18.12
-7,-3,28:18.12
-6,-3,28:18.12
-5,-3,28:18.12
-4,-3,28:18.4
-19,-2,28:18.12
-9,-2,28:18.12
-7,-2,28:18.12
-6,-2,28:18.12
-22,-1,28:18.12
-21,-1,28:18.12
-18,-1,28:18.12
-10,-1,28:18.12
-9,-1,28:18.12
-7,-1,28:18.12
-6,-1,28:18.12
-4,-1,28:18.12
-3,-1,28:18.4
-21,0,28:18.12
-20,0,28:18.12
-17,0,28:18.12
-16,0,28:18.12
-15,0,28:18.12
-14,0,28:18.4
-13,0,28:18.12
-12,0,28:18.12
-11,0,28:18.12
-10,0,28:18.12
-9,0,28:18.12
-7,0,28:18.12
-4,0,28:18.12
-3,0,28:18.4
-20,1,28:18.12
-19,1,28:18.12
-17,1,28:18.12
-16,1,28:18.12
-15,1,28:18.12
-14,1,28:18.4
-4,1,28:18.12
-3,1,28:18.4
-17,2,28:18.12
-8,2,28:18.12
-4,2,28:18.12
-17,3,28:18.12
-11,3,28:18.12
-8,3,28:18.12
-5,3,28:18.12
-4,3,28:18.12
-3,3,28:18.12
-17,4,28:18.12
-11,4,28:18.12
-8,4,28:18.12
-7,4,28:18.12
-6,4,28:18.12
-5,4,28:18.12
-4,4,28:18.12
-3,4,28:18.12
-2,4,28:18.4
-1,4,28:18.4
-18,5,28:18.12
-17,5,28:18.12
-11,5,28:18.12
-9,5,28:18.12
-8,5,28:18.12
-7,5,28:18.12
-6,5,28:18.12
-2,5,28:18.4
-1,5,28:18.4
4,5,28:18.4
5,5,28:18.4
6,5,28:18.4
-18,6,28:18.12
-11,6,28:18.12
-9,6,28:18.12
-8,6,28:18.12
-7,6,28:18.12
-6,6,28:18.12
-5,6,28:18.12
2,6,28:18.4
3,6,28:18.4
4,6,28:18.4
-11,7,28:18.12
-10,7,28:18.12
-9,7,28:18.12
-8,7,28:18.12
-7,7,28:18.12
-6,7,28:18.12
-5,7,28:18.12
0,7,28:18.4
1,7,28:18.4
2,7,28:18.4
-10,8,28:18.12
-9,8,28:18.12
-8,8,28:18.12
-6,8,28:18.12
-5,8,28:18.12
-4,8,28:18.12
-3,8,28:18.12
-2,8,28:18.4
-1,8,28:18.4
0,8,28:18.4
1,8,28:18.4
-18,9,28:18.4
-11,9,28:18.12
-10,9,28:18.12
-9,9,28:18.12
-8,9,28:18.12
-7,9,28:18.12
-6,9,28:18.12
-3,9,28:18.12
-2,9,28:18.4
-1,9,28:18.4
0,9,28:18.4
-18,10,28:18.4
-13,10,28:18.12
-12,10,28:18.12
-11,10,28:18.12
-9,10,28:18.12
-8,10,28:18.12
-7,10,28:18.12
-5,10,28:18.12
-4,10,28:18.12
-3,10,28:18.12
-1,10,28:18.4
0,10,28:18.4
1,10,28:18.4
-18,11,28:18.4
-17,11,28:18.4
-16,11,28:18.4
-15,11,28:18.4
-14,11,28:18.4
-13,11,28:18.12
-12,11,28:18.12
-10,11,28:18.12
-9,11,28:18.12
-8,11,28:18.12
-7,11,28:18.12
-6,11,28:18.12
-5,11,28:18.12
-1,11,28:18.4
0,11,28:18.4
1,11,28:18.4
4,11,28:18.4
-17,12,28:18.4
-16,12,28:18.4
-15,12,28:18.4
-14,12,28:18.4
-13,12,28:18.4
-12,12,28:18.12
-11,12,28:18.12
-10,12,28:18.12
-9,12,28:18.12
-8,12,28:18.12
-7,12,28:18.12
-6,12,28:18.12
-5,12,28:18.12
-1,12,28:18.4
0,12,28:18.4
1,12,28:18.4
4,12,28:18.4
-16,13,28:18.4
-14,13,28:18.4
-13,13,28:18.4
-12,13,28:18.12
-11,13,28:18.12
-10,13,28:18.12
-9,13,28:18.12
-8,13,28:18.12
-7,13,28:18.12
-6,13,28:18.12
-5,13,28:18.12
-4,13,28:18.12
0,13,28:18.12
1,13,28:18.12
4,13,28:18.12
-16,14,28:18.12
-15,14,28:18.12
-12,14,28:18.12
-10,14,28:18.12
-9,14,28:18.12
-8,14,28:18.12
-7,14,28:18.12
-5,14,28:18.12
-4,14,28:18.12
-3,14,28:18.12
0,14,28:18.12
1,14,28:18.12
4,14,28:18.12
-23,15,28:18.4
-22,15,28:18.4
-18,15,28:18.12
-17,15,28:18.12
-16,15,28:18.12
-12,15,28:18.12
-11,15,28:18.12
-10,15,28:18.12
-9,15,28:18.12
-8,15,28:18.12
-7,15,28:18.12
-5,15,28:18.12
-4,15,28:18.12
-2,15,28:18.4
4,15,28:18.12
5,15,28:18.12
-21,16,28:18.4
-20,16,28:18.12
-19,16,28:18.12
-18,16,28:18.12
-12,16,28:18.12
-11,16,28:18.12
-10,16,28:18.12
-9,16,28:18.12
-8,16,28:18.12
-5,16,28:18.12
-4,16,28:18.12
-1,16,28:18.12
0,16,28:18.12
1,16,28:18.12
2,16,28:18.12
3,16,28:18.12
4,16,28:18.12
5,16,28:18.12
-20,17,28:18.12
-19,17,28:18.12
-12,17,28:18.12
-11,17,28:18.12
-10,17,28:18.12
-9,17,28:18.12
-8,17,28:18.12
-7,17,28:18.12
-6,17,28:18.12
-1,17,28:18.12
0,17,28:18.12
1,17,28:18.12
2,17,28:18.12
-20,18,28:18.12
-19,18,28:18.12
-9,18,28:18.12
-8,18,28:18.12
-7,18,28:18.12
-1,18,28:18.12
0,18,28:18.12
-20,19,28:18.12
-19,19,28:18.12
-17,19,28:18.12
-16,19,28:18.12
-14,19,28:18.12
-13,19,28:18.12
-8,19,28:18.12
-2,19,28:18.12
-1,19,28:18.12
0,19,28:18.12
-19,20,28:18.12
-18,20,28:18.12
-17,20,28:18.12
-16,20,28:18.12
-15,20,28:18.12
-14,20,28:18.12
-13,20,28:18.12
-8,20,28:18.12
-1,20,28:18.12
0,20,28:18.12
-19,21,28:18.12
-18,21,28:18.12
-17,21,28:18.12
-15,21,28:18.12
-14,21,28:18.12
-12,21,28:18.12
-8,21,28:18.12
-1,21,28:18.12
-19,22,28:18.12
-18,22,28:18.12
-15,22,28:18.12
-12,22,28:18.12
-1,22,28:18.4
-20,23,28:18.12
-15,23,28:18.12
-16,24,28:18.12
-18,25,28:18.4
-17,25,28:18.4
-16,25,28:18.4
-7,27,28:18.4
-4,27,28:18.4
-11,-10,29:18.12
-10,-10,29:18.12
-9,-10,29:18.12
-12,-9,29:18.12
-9,-9,29:18.12
-8,-9,29:18.12
-9,-8,29:18.12
-9,-7,29:18.12
-8,-7,29:18.12
-9,-6,29:18.12
-8,-6,29:18.12
-13,-5,29:18.12
-12,-5,29:18.12
-11,-5,29:18.12
-10,-5,29:18.12
-9,-5,29:18.12
-8,-5,29:18.12
-5,-5,29:18.12
-13,-4,29:18.12
-12,-4,29:18.12
-11,-4,29:18.12
-10,-4,29:18.12
-9,-4,29:18.12
-5,-4,29:18.12
-11,-3,29:18.12
-10,-3,29:18.12
-9,-3,29:18.12
-5,-3,29:18.12
-10,-2,29:18.12
-9,-2,29:17.12
-6,-2,29:18.12
-5,-2,29:18.12
-14,-1,29:18.4
-13,-1,29:18.12
-12,-1,29:18.12
-11,-1,29:18.12
-10,-1,29:18.12
-6,-1,29:18.12
-3,-1,29:18.4
-2,-1,29:18.4
-17,0,29:18.12
-16,0,29:18.12
-15,0,29:18.4
-14,0,29:18.4
-13,0,29:18.12
-12,0,29:18.12
-9,0,29:18.12
-7,0,29:18.12
-6,0,29:18.12
-3,0,29:18.4
-2,0,29:18.4
-17,1,29:18.12
-3,1,29:18.4
-2,1,29:18.4
-17,2,29:18.12
-12,2,29:18.12
-9,2,29:18.12
-3,2,29:18.12
-2,2,29:18.4
-18,3,29:18.12
-17,3,29:18.12
-12,3,29:18.12
-9,3,29:18.12
-5,3,29:18.12
-4,3,29:18.12
-3,3,29:18.12
-2,3,29:18.4
-1,3,29:18.4
-18,4,29:18.12
-12,4,29:18.12
-10,4,29:18.12
-9,4,29:18.12
-7,4,29:18.12
-6,4,29:18.12
-5,4,29:18.12
-1,4,29:18.4
0,4,29:18.4
-18,5,29:18.12
-12,5,29:18.12
-11,5,29:18.12
-10,5,29:18.12
-9,5,29:18.12
-8,5,29:18.12
-7,5,29:18.12
-6,5,29:18.12
-5,5,29:18.12
-12,6,29:18.12
-11,6,29:18.12
-10,6,29:18.12
-9,6,29:18.12
-5,6,29:18.12
-4,6,29:18.12
4,6,29:18.4
5,6,29:18.4
-12,7,29:18.12
-11,7,29:18.12
-10,7,29:18.12
-9,7,29:18.12
-6,7,29:18.12
-5,7,29:18.12
-4,7,29:18.12
-3,7,29:18.12
-2,7,29:18.4
2,7,29:18.4
3,7,29:18.4
4,7,29:18.4
-12,8,29:18.12
-11,8,29:18.12
-10,8,29:18.12
-9,8,29:18.12
-8,8,29:18.12
-7,8,29:18.12
-6,8,29:18.12
-2,8,29:18.4
-1,8,29:18.4
0,8,29:18.4
1,8,29:18.4
2,8,29:18.4
-14,9,29:18.4
-13,9,29:18.12
-12,9,29:18.12
-11,9,29:18.12
-10,9,29:18.12
-9,9,29:18.12
-8,9,29:18.12
-7,9,29:18.12
-6,9,29:18.12
-1,9,29:18.4
0,9,29:18.4
1,9,29:18.4
2,9,29:18.4
-16,10,29:18.4
-15,10,29:18.4
-14,10,29:18.4
-13,10,29:18.12
-9,10,29:18.12
-8,10,29:18.12
-7,10,29:18.12
-6,10,29:18.12
-4,10,29:18.12
-3,10,29:18.12
-2,10,29:18.4
-1,10,29:18.4
1,10,29:18.4
2,10,29:18.4
3,10,29:18.4
-17,11,29:18.4
-16,11,29:18.4
-15,11,29:18.4
-10,11,29:18.12
-9,11,29:18.12
-8,11,29:18.12
-7,11,29:18.12
-6,11,29:18.12
-5,11,29:18.12
-4,11,29:18.12
-3,11,29:18.12
1,11,29:18.4
2,11,29:18.4
3,11,29:18.4
-17,12,29:18.4
-16,12,29:18.4
-12,12,29:18.12
-11,12,29:18.12
-9,12,29:18.12
-8,12,29:18.12
