[META]
version=2.0
spawnOnBlockType=2
spawnSunlight=True
spawnDarkness=True
spawnWater=False
spawnLava=False
underFill=False
randomRotation=True
dig=True
tree=False
branch=False
needsFoundation=True
rarity=100
collisionPercentage=20
spawnElevationMin=0
spawnElevationMax=200
spawnInBiome=Custom
[DATA]
-3,4,-8:17.15
-2,9,-8:17.15
-2,10,-8:17.15
-4,3,-7:17.15
-5,4,-7:17.15
-4,4,-7:17.15
-3,5,-7:17.15
-2,9,-7:17.15
-1,9,-7:17.15
-2,10,-7:17.15
-1,10,-7:17.15
-5,4,-6:17.15
-4,4,-6:17.15
-5,5,-6:17.15
-4,5,-6:17.15
-2,5,-6:17.15
-4,6,-6:17.15
-3,6,-6:17.15
-2,6,-6:17.15
-2,8,-6:17.15
-1,8,-6:17.15
0,8,-6:17.15
-2,9,-6:17.15
-1,9,-6:17.15
0,10,-6:17.15
-2,11,-6:17.15
-3,4,-5:17.15
-5,5,-5:17.15
-3,5,-5:17.15
-2,5,-5:17.15
-4,6,-5:17.15
-3,6,-5:17.15
-2,6,-5:17.15
-1,6,-5:17.15
-3,7,-5:17.15
-1,7,-5:17.15
-1,8,-5:17.15
-1,9,-5:17.15
0,9,-5:17.15
-4,5,-4:17.15
-3,5,-4:17.15
-2,5,-4:17.15
-4,6,-4:17.15
-3,6,-4:17.15
-2,6,-4:17.15
-1,6,-4:17.15
0,6,-4:17.15
-3,7,-4:17.15
-2,7,-4:17.15
-1,7,-4:17.15
-2,8,-4:17.15
-1,8,-4:17.15
0,8,-4:17.15
-1,9,-4:17.15
-4,5,-3:17.15
-3,5,-3:17.15
-2,5,-3:17.15
-4,6,-3:17.15
-3,6,-3:17.15
-2,6,-3:17.15
-4,7,-3:17.15
-3,7,-3:17.15
-2,7,-3:17.15
-1,7,-3:17.15
-3,8,-3:17.15
-1,8,-3:17.15
-3,4,-2:17.15
-1,4,-2:17.15
0,4,-2:17.15
-4,5,-2:17.15
-3,5,-2:17.15
-2,5,-2:17.15
-1,5,-2:17.15
0,5,-2:17.15
1,5,-2:17.15
-4,6,-2:17.15
-3,6,-2:17.15
-2,6,-2:17.15
-1,6,-2:17.15
0,6,-2:17.15
1,6,-2:17.15
-4,7,-2:17.15
-3,7,-2:17.15
-2,7,-2:17.15
-1,7,-2:17.15
0,7,-2:17.15
-4,8,-2:17.15
-3,8,-2:17.15
-2,8,-2:17.15
-1,8,-2:17.15
-3,4,-1:17.15
-1,4,-1:17.15
0,4,-1:17.15
1,4,-1:17.15
-4,5,-1:17.15
-3,5,-1:17.15
-2,5,-1:17.15
-1,5,-1:17.15
1,5,-1:17.15
-5,6,-1:17.15
-4,6,-1:17.15
-3,6,-1:17.15
-2,6,-1:17.15
-1,6,-1:17.15
1,6,-1:17.15
-4,7,-1:17.15
-3,7,-1:17.15
-2,7,-1:17.15
-1,7,-1:17.15
0,7,-1:17.15
-2,8,-1:17.15
-1,8,-1:17.15
2,3,0:17.15
-1,4,0:17.15
0,4,0:17.15
1,4,0:17.15
2,4,0:17.15
3,4,0:17.15
-5,5,0:17.15
-4,5,0:17.15
-3,5,0:17.15
-2,5,0:17.15
-1,5,0:17.15
2,5,0:17.15
-5,6,0:17.15
-4,6,0:17.15
-2,6,0:17.15
-1,6,0:17.15
0,6,0:17.15
1,6,0:17.15
-4,7,0:17.15
-3,7,0:17.15
-2,7,0:17.15
-1,7,0:17.15
0,7,0:17.15
1,3,1:17.15
2,3,1:17.15
3,3,1:17.15
4,3,1:17.15
0,4,1:17.15
1,4,1:17.15
3,4,1:17.15
4,4,1:17.15
-5,5,1:17.15
-4,5,1:17.15
-3,5,1:17.15
-2,5,1:17.15
-1,5,1:17.15
0,5,1:17.15
1,5,1:17.15
2,5,1:17.15
3,5,1:17.15
-5,6,1:17.15
-2,6,1:17.15
-1,6,1:17.15
0,6,1:17.15
1,6,1:17.15
-4,7,1:17.15
-3,7,1:17.15
-2,7,1:17.15
3,2,2:17.15
4,2,2:17.15
5,2,2:17.15
2,3,2:17.15
4,3,2:17.15
5,3,2:17.15
1,4,2:17.15
2,4,2:17.15
3,4,2:17.15
4,4,2:17.15
-5,5,2:17.15
-4,5,2:17.15
-3,5,2:17.15
1,5,2:17.15
2,5,2:17.15
-5,6,2:17.15
-3,6,2:17.15
-2,6,2:17.15
-4,7,2:17.15
-3,7,2:17.15
5,1,3:17.15
6,1,3:17.15
3,2,3:17.15
4,2,3:17.15
5,2,3:17.15
6,2,3:17.15
2,3,3:17.15
3,3,3:17.15
4,3,3:17.15
5,3,3:17.15
2,4,3:17.15
3,4,3:17.15
4,4,3:17.15
-6,5,3:17.15
-5,5,3:17.15
-4,5,3:17.15
-3,5,3:17.15
-5,6,3:17.15
-3,6,3:17.15
-4,7,3:17.15
5,1,4:17.15
6,1,4:17.15
7,1,4:17.15
4,2,4:17.15
5,2,4:17.15
6,2,4:17.15
7,2,4:17.15
4,3,4:17.15
5,3,4:17.15
-6,5,4:17.15
-5,5,4:17.15
-4,5,4:17.15
-6,6,4:17.15
-5,6,4:17.15
-4,6,4:17.15
-3,6,4:17.15
-4,7,4:17.15
6,0,5:17.15
7,0,5:17.15
8,0,5:17.15
5,1,5:17.15
6,1,5:17.15
7,1,5:17.15
8,1,5:17.15
5,2,5:17.15
6,2,5:17.15
7,2,5:17.15
-6,5,5:17.15
-5,5,5:17.15
-4,5,5:17.15
-6,6,5:17.15
-5,6,5:17.15
-4,6,5:17.15
6,0,6:17.15
7,0,6:17.15
8,0,6:17.15
6,1,6:17.15
7,1,6:17.15
8,1,6:17.15
6,2,6:17.15
7,2,6:17.15
-6,4,6:17.15
-7,5,6:17.15
-6,5,6:17.15
-5,5,6:17.15
-4,5,6:17.15
-7,6,6:17.15
-6,6,6:17.15
-5,6,6:17.15
-4,6,6:17.15
8,-1,7:17.15
7,0,7:17.15
8,0,7:17.15
9,0,7:17.15
7,1,7:17.15
8,1,7:17.15
-7,4,7:17.15
-6,4,7:17.15
-7,5,7:17.15
-5,5,7:17.15
-7,6,7:17.15
-6,6,7:17.15
-5,6,7:17.15
8,-1,8:17.15
9,-1,8:17.15
7,0,8:17.15
8,0,8:17.15
9,0,8:17.15
7,1,8:17.15
8,1,8:17.15
-7,4,8:17.15
-6,4,8:17.15
-8,5,8:17.15
-7,5,8:17.15
-6,5,8:17.15
-5,5,8:17.15
-7,6,8:17.15
-6,6,8:17.15
8,-1,9:17.15
9,-1,9:17.15
10,-1,9:17.15
8,0,9:17.15
9,0,9:17.15
-7,4,9:17.15
-6,4,9:17.15
-8,5,9:17.15
-6,5,9:17.15
-7,6,9:17.15
-6,6,9:17.15
13,-2,10:18.15
8,-1,10:17.15
9,-1,10:17.15
10,-1,10:17.15
8,0,10:17.15
9,0,10:17.15
10,0,10:17.15
-8,4,10:17.15
-7,4,10:17.15
-8,5,10:17.15
-6,5,10:17.15
-8,6,10:17.15
-7,6,10:17.15
-6,6,10:17.15
13,-3,11:18.15
10,-2,11:17.15
13,-2,11:18.15
9,-1,11:17.15
10,-1,11:17.15
12,-1,11:18.15
13,-1,11:18.15
9,0,11:17.15
10,0,11:17.15
-8,4,11:17.15
-7,4,11:17.15
-8,5,11:17.15
-7,5,11:17.15
-6,5,11:17.15
-8,6,11:17.15
-7,6,11:17.15
10,-4,12:18.15
13,-4,12:18.15
13,-3,12:18.15
10,-2,12:17.15
11,-2,12:17.15
13,-2,12:18.15
9,-1,12:17.15
10,-1,12:17.15
11,-1,12:17.15
12,-1,12:18.15
13,-1,12:18.15
7,0,12:18.15
10,0,12:17.15
12,0,12:18.15
-8,4,12:17.15
-7,4,12:17.15
-8,5,12:17.15
-7,5,12:17.15
-6,5,12:17.15
-8,6,12:17.15
-7,6,12:17.15
11,-6,13:18.15
12,-6,13:18.15
10,-4,13:18.15
13,-4,13:18.15
9,-3,13:18.15
13,-3,13:18.15
10,-2,13:17.15
11,-2,13:17.15
13,-2,13:18.15
7,-1,13:18.15
9,-1,13:17.15
10,-1,13:17.15
11,-1,13:17.15
13,-1,13:18.15
7,0,13:18.15
12,0,13:18.15
14,0,13:18.15
13,1,13:18.15
14,1,13:18.15
-8,4,13:17.15
-7,4,13:17.15
-8,5,13:17.15
-7,5,13:17.15
-8,6,13:17.15
-7,6,13:17.15
11,-7,14:18.15
10,-6,14:18.15
11,-6,14:18.15
12,-6,14:18.15
10,-4,14:18.15
11,-4,14:18.15
13,-4,14:18.15
9,-3,14:18.15
13,-3,14:18.15
7,-2,14:18.15
10,-2,14:17.15
11,-2,14:17.15
13,-2,14:18.15
14,-2,14:18.15
7,-1,14:18.15
10,-1,14:17.15
11,-1,14:17.15
13,-1,14:18.15
15,-1,14:18.15
7,0,14:18.15
13,0,14:18.15
14,0,14:18.15
15,0,14:18.15
8,1,14:18.15
13,1,14:18.15
14,1,14:18.15
-8,4,14:17.15
-7,4,14:17.15
-9,5,14:17.15
-8,5,14:17.15
-7,5,14:17.15
-8,6,14:17.15
11,-7,15:18.15
10,-6,15:18.15
11,-6,15:18.15
12,-6,15:18.15
13,-5,15:18.15
10,-4,15:18.15
11,-4,15:18.15
9,-3,15:18.15
13,-3,15:18.15
7,-2,15:18.15
10,-2,15:17.15
11,-2,15:17.15
13,-2,15:18.15
7,-1,15:18.15
10,-1,15:17.15
11,-1,15:17.15
13,-1,15:18.15
15,-1,15:18.15
6,0,15:18.15
7,0,15:18.15
12,0,15:18.15
14,0,15:18.15
15,0,15:18.15
8,1,15:18.15
13,1,15:18.15
14,1,15:18.15
-8,4,15:17.15
-7,4,15:17.15
-9,5,15:17.15
-8,5,15:17.15
-7,5,15:17.15
-8,6,15:17.15
5,-7,16:18.7
4,-6,16:18.7
5,-6,16:18.7
10,-6,16:18.15
11,-6,16:18.15
12,-6,16:18.15
9,-5,16:18.15
12,-5,16:18.15
13,-5,16:18.15
17,-5,16:18.7
18,-5,16:18.7
10,-4,16:18.15
11,-4,16:18.15
18,-4,16:18.7
7,-3,16:18.15
9,-3,16:18.15
12,-3,16:18.15
13,-3,16:18.15
7,-2,16:18.15
10,-2,16:17.15
11,-2,16:17.15
13,-2,16:18.15
14,-2,16:18.15
7,-1,16:18.15
10,-1,16:17.15
11,-1,16:17.15
13,-1,16:18.15
14,-1,16:18.15
7,0,16:18.15
8,0,16:18.15
12,0,16:18.15
14,0,16:18.15
8,1,16:18.15
9,1,16:18.15
12,1,16:18.15
13,1,16:18.15
14,1,16:18.15
12,2,16:18.15
-10,3,16:18.15
-9,3,16:18.15
-10,4,16:18.15
-9,4,16:17.15
-8,4,16:17.15
-7,4,16:17.15
-9,5,16:17.15
-8,5,16:17.15
-7,5,16:17.15
9,5,16:18.15
10,5,16:18.15
11,5,16:18.15
10,6,16:18.15
5,-7,17:18.7
6,-7,17:18.15
7,-7,17:18.15
5,-6,17:18.7
10,-6,17:18.15
11,-6,17:18.15
12,-6,17:18.15
16,-6,17:18.15
5,-5,17:18.15
9,-5,17:18.15
10,-5,17:18.15
12,-5,17:18.15
13,-5,17:18.15
17,-5,17:18.7
18,-5,17:18.7
5,-4,17:18.15
10,-4,17:18.15
11,-4,17:18.15
13,-4,17:18.15
17,-4,17:18.7
18,-4,17:18.7
7,-3,17:18.15
8,-3,17:18.15
9,-3,17:18.15
10,-3,17:17.15
11,-3,17:17.15
12,-3,17:18.15
17,-3,17:18.7
7,-2,17:18.15
10,-2,17:17.15
11,-2,17:17.15
12,-2,17:17.15
13,-2,17:18.15
14,-2,17:18.15
7,-1,17:18.15
10,-1,17:17.15
11,-1,17:17.15
12,-1,17:18.15
14,-1,17:18.15
7,0,17:18.15
8,0,17:18.15
12,0,17:18.15
14,0,17:18.15
8,1,17:18.15
9,1,17:18.15
11,1,17:18.15
12,1,17:18.15
13,1,17:18.15
14,1,17:18.15
-8,2,17:18.15
-10,3,17:18.15
-9,3,17:18.15
-11,4,17:18.15
-10,4,17:18.15
-9,4,17:17.15
-8,4,17:17.15
8,4,17:18.7
9,4,17:18.15
12,4,17:18.15
-9,5,17:17.15
-8,5,17:17.15
-7,5,17:17.15
9,5,17:18.15
10,5,17:18.15
11,5,17:18.15
6,-7,18:18.15
7,-7,18:18.15
8,-7,18:18.15
5,-6,18:18.7
6,-6,18:18.15
7,-6,18:18.15
15,-6,18:18.15
16,-6,18:18.15
5,-5,18:18.7
10,-5,18:18.15
11,-5,18:18.15
12,-5,18:18.15
16,-5,18:18.15
17,-5,18:18.7
5,-4,18:18.7
8,-4,18:18.15
9,-4,18:18.15
10,-4,18:18.15
11,-4,18:18.15
13,-4,18:18.15
17,-4,18:18.7
5,-3,18:18.7
8,-3,18:18.15
9,-3,18:18.15
10,-3,18:18.15
11,-3,18:17.15
12,-3,18:18.15
13,-3,18:18.15
14,-3,18:18.15
16,-3,18:18.15
17,-3,18:18.7
8,-2,18:18.15
9,-2,18:18.15
10,-2,18:17.15
12,-2,18:18.15
13,-2,18:18.15
14,-2,18:18.15
16,-2,18:18.15
17,-2,18:18.7
7,-1,18:18.15
8,-1,18:18.15
10,-1,18:17.15
11,-1,18:17.15
12,-1,18:18.15
13,-1,18:18.15
14,-1,18:18.15
8,0,18:18.15
9,0,18:18.15
10,0,18:18.15
12,0,18:18.15
13,0,18:18.15
14,0,18:18.15
-9,1,18:18.15
-8,1,18:18.15
9,1,18:18.15
10,1,18:18.15
11,1,18:18.15
12,1,18:18.15
13,1,18:18.15
-9,2,18:18.15
-8,2,18:18.15
-10,3,18:18.15
-9,3,18:18.15
8,3,18:18.15
12,3,18:18.15
-11,4,18:18.15
-10,4,18:18.15
-9,4,18:17.15
-8,4,18:17.15
8,4,18:18.15
9,4,18:18.15
11,4,18:18.15
12,4,18:18.7
-9,5,18:17.15
-8,5,18:17.15
-7,5,18:17.15
9,5,18:18.15
10,5,18:18.15
11,5,18:18.15
-4,6,18:18.15
-9,7,18:18.15
-8,7,18:18.15
-4,7,18:18.15
-11,8,18:18.15
9,-7,19:18.15
6,-6,19:18.15
7,-6,19:18.15
8,-6,19:18.15
9,-6,19:18.15
10,-6,19:18.15
13,-6,19:18.15
14,-6,19:18.15
6,-5,19:18.15
11,-5,19:18.15
14,-5,19:18.15
15,-5,19:18.15
16,-5,19:18.15
6,-4,19:18.15
9,-4,19:18.15
10,-4,19:18.15
11,-4,19:18.15
16,-4,19:18.15
17,-4,19:18.7
9,-3,19:18.15
10,-3,19:18.15
11,-3,19:17.15
12,-3,19:18.15
13,-3,19:18.15
16,-3,19:18.15
6,-2,19:18.15
7,-2,19:18.15
8,-2,19:18.15
9,-2,19:18.15
10,-2,19:17.15
12,-2,19:18.15
13,-2,19:18.15
15,-2,19:18.15
16,-2,19:18.15
8,-1,19:18.15
9,-1,19:18.15
10,-1,19:17.15
11,-1,19:17.15
12,-1,19:18.15
13,-1,19:18.15
15,-1,19:18.15
9,0,19:18.15
10,0,19:18.15
11,0,19:18.15
12,0,19:18.15
13,0,19:18.15
-9,1,19:18.15
-8,1,19:18.15
8,1,19:18.15
13,1,19:18.15
-9,2,19:18.15
-8,2,19:18.15
8,2,19:18.15
12,2,19:18.15
13,2,19:18.15
-10,3,19:18.15
8,3,19:18.15
9,3,19:18.15
11,3,19:18.15
12,3,19:18.15
-11,4,19:18.15
-9,4,19:17.15
-8,4,19:17.15
9,4,19:18.15
10,4,19:18.7
11,4,19:18.7
-9,5,19:17.15
-8,5,19:17.15
-7,5,19:17.15
-9,6,19:18.15
-4,6,19:18.15
-12,7,19:18.15
-9,7,19:18.15
-8,7,19:18.15
-5,7,19:18.15
-4,7,19:18.15
-12,8,19:18.15
-11,8,19:18.15
8,-6,20:18.15
9,-6,20:18.15
6,-5,20:18.15
7,-5,20:18.15
8,-5,20:18.15
9,-5,20:18.15
10,-5,20:18.15
11,-5,20:18.15
12,-5,20:18.15
13,-5,20:18.15
14,-5,20:18.15
15,-5,20:18.15
6,-4,20:18.15
7,-4,20:18.15
8,-4,20:18.15
10,-4,20:18.15
11,-4,20:18.15
13,-4,20:18.15
14,-4,20:18.15
15,-4,20:18.15
16,-4,20:18.15
7,-3,20:18.15
8,-3,20:18.15
10,-3,20:18.15
11,-3,20:18.15
14,-3,20:18.15
15,-3,20:18.15
16,-3,20:18.15
7,-2,20:18.15
8,-2,20:18.15
9,-2,20:18.15
10,-2,20:18.15
11,-2,20:18.15
12,-2,20:18.15
13,-2,20:18.15
14,-2,20:18.15
15,-2,20:18.15
8,-1,20:18.15
9,-1,20:18.15
10,-1,20:18.15
11,-1,20:18.15
12,-1,20:18.15
13,-1,20:18.15
14,-1,20:18.15
-9,0,20:18.15
8,0,20:18.15
9,0,20:18.15
12,0,20:18.15
13,0,20:18.15
-10,1,20:18.15
-9,1,20:18.15
-8,1,20:18.15
-7,1,20:18.15
8,1,20:18.15
9,1,20:18.15
10,1,20:18.15
11,1,20:18.15
12,1,20:18.15
13,1,20:18.15
-10,2,20:18.15
-9,2,20:18.15
-8,2,20:18.15
9,2,20:18.15
10,2,20:18.15
11,2,20:18.15
12,2,20:18.15
-10,3,20:18.15
9,3,20:18.15
10,3,20:18.15
11,3,20:18.15
-11,4,20:18.15
-10,4,20:18.15
-9,4,20:17.15
-8,4,20:17.15
-11,5,20:18.15
-9,5,20:17.15
-8,5,20:17.15
-4,5,20:18.15
-12,6,20:18.15
-10,6,20:18.15
-9,6,20:18.15
-7,6,20:18.15
-4,6,20:18.15
-12,7,20:18.15
-9,7,20:18.15
-8,7,20:18.15
-4,7,20:18.15
-12,8,20:18.15
-11,8,20:18.15
-10,8,20:18.15
-5,8,20:18.15
-10,9,20:18.15
8,-4,21:18.15
9,-4,21:18.15
10,-4,21:18.15
13,-4,21:18.15
8,-3,21:18.15
9,-3,21:18.15
10,-3,21:18.15
11,-3,21:18.15
12,-3,21:18.15
13,-3,21:18.15
14,-3,21:18.15
9,-2,21:18.15
10,-2,21:18.15
11,-2,21:18.15
12,-2,21:18.15
13,-2,21:18.15
10,-1,21:18.15
11,-1,21:18.15
-2,0,21:18.7
10,0,21:18.15
11,0,21:18.15
-10,1,21:18.15
-9,1,21:18.15
-8,1,21:18.15
-7,1,21:18.15
-2,1,21:18.7
10,1,21:18.15
11,1,21:18.15
-15,2,21:18.7
-10,2,21:18.15
-9,2,21:18.15
-8,2,21:18.15
-10,3,21:18.15
-9,3,21:18.15
-10,4,21:18.15
-9,4,21:17.15
-8,4,21:17.15
-11,5,21:18.15
-9,5,21:17.15
-8,5,21:17.15
-4,5,21:18.15
-12,6,21:18.15
-10,6,21:18.15
-9,6,21:18.15
-7,6,21:18.15
-4,6,21:18.15
-12,7,21:18.15
-9,7,21:18.15
-8,7,21:18.15
-5,7,21:18.15
-4,7,21:18.15
-12,8,21:18.15
-11,8,21:18.15
-10,8,21:18.15
-6,8,21:18.15
-5,8,21:18.15
-7,13,21:18.7
-3,0,22:18.15
-2,0,22:18.7
-14,1,22:18.7
-9,1,22:18.15
-8,1,22:18.15
-7,1,22:18.15
-2,1,22:18.7
-15,2,22:18.7
-14,2,22:18.7
-11,2,22:18.15
-10,2,22:18.15
-8,2,22:18.15
-7,2,22:18.15
-6,2,22:18.15
-2,2,22:18.7
-15,3,22:18.7
-10,3,22:18.15
-9,3,22:18.15
-10,4,22:18.15
-9,4,22:17.15
-8,4,22:17.15
-4,4,22:18.15
-12,5,22:18.15
-10,5,22:18.15
-9,5,22:17.15
-8,5,22:17.15
-7,5,22:17.15
-4,5,22:18.15
-12,6,22:18.15
-10,6,22:18.15
-9,6,22:18.15
-8,6,22:17.15
-7,6,22:18.15
-4,6,22:18.15
-12,7,22:18.15
-11,7,22:18.15
-9,7,22:18.15
-8,7,22:18.15
-5,7,22:18.15
-4,7,22:18.15
-11,8,22:18.15
-10,8,22:18.15
-6,8,22:18.15
-5,8,22:18.15
-9,9,22:18.15
-8,12,22:18.7
-7,12,22:18.7
-6,12,22:18.7
-7,13,22:18.7
-4,0,23:18.15
-3,0,23:18.15
-2,0,23:18.7
-14,1,23:18.7
-13,1,23:18.15
-9,1,23:18.15
-8,1,23:18.15
-2,1,23:18.7
-15,2,23:18.7
-14,2,23:18.7
-10,2,23:18.15
-9,2,23:18.15
-8,2,23:18.15
-7,2,23:18.15
-6,2,23:18.15
-2,2,23:18.7
-15,3,23:18.7
-11,3,23:18.15
-10,3,23:18.15
-9,3,23:18.15
-8,3,23:18.15
-6,3,23:18.15
-2,3,23:18.7
-14,4,23:18.7
-11,4,23:18.15
-10,4,23:18.15
-9,4,23:17.15
-8,4,23:17.15
-7,4,23:17.15
-5,4,23:18.15
-14,5,23:18.7
-12,5,23:18.15
-11,5,23:18.15
-10,5,23:18.15
-9,5,23:17.15
-8,5,23:17.15
-7,5,23:17.15
-5,5,23:18.15
-4,5,23:18.15
-11,6,23:18.15
-10,6,23:18.15
-9,6,23:18.15
-8,6,23:17.15
-7,6,23:18.15
-4,6,23:18.15
-11,7,23:18.15
-9,7,23:18.15
-8,7,23:18.15
-6,7,23:18.15
-5,7,23:18.15
-4,7,23:18.15
-11,8,23:18.15
-10,8,23:18.15
-9,8,23:18.15
-8,8,23:18.15
-7,8,23:18.15
-6,8,23:18.15
-9,11,23:18.7
-6,11,23:18.7
-8,12,23:18.7
-7,12,23:18.7
-6,12,23:18.7
-5,0,24:18.15
-4,0,24:18.15
-12,1,24:18.15
-5,1,24:18.15
-4,1,24:18.15
-3,1,24:18.15
-2,1,24:18.7
-14,2,24:18.7
-13,2,24:18.15
-12,2,24:18.15
-9,2,24:18.15
-8,2,24:18.15
-7,2,24:18.15
-3,2,24:18.15
-2,2,24:18.7
-14,3,24:18.7
-10,3,24:18.15
-9,3,24:18.15
-8,3,24:18.15
-7,3,24:18.15
-6,3,24:18.15
-3,3,24:18.15
-14,4,24:18.7
-11,4,24:18.15
-10,4,24:18.15
-9,4,24:18.15
-8,4,24:17.15
-6,4,24:18.15
-5,4,24:18.15
-3,4,24:18.15
-14,5,24:18.7
-13,5,24:18.15
-11,5,24:18.15
-10,5,24:18.15
-9,5,24:17.15
-8,5,24:17.15
-6,5,24:18.15
-5,5,24:18.15
-11,6,24:18.15
-10,6,24:18.15
-9,6,24:18.15
-8,6,24:18.15
-7,6,24:18.15
-6,6,24:18.15
-11,7,24:18.15
-10,7,24:18.15
-9,7,24:18.15
-8,7,24:18.15
-7,7,24:18.15
-6,7,24:18.15
-9,8,24:18.15
-8,8,24:18.15
-7,8,24:18.15
-10,10,24:18.15
-9,10,24:18.15
-6,10,24:18.15
-5,10,24:18.15
-9,11,24:18.7
-8,11,24:18.7
-7,11,24:18.7
-6,11,24:18.7
-8,12,24:18.7
-7,12,24:18.7
-11,1,25:18.15
-10,1,25:18.15
-7,1,25:18.15
-6,1,25:18.15
-5,1,25:18.15
-4,1,25:18.15
-3,1,25:18.15
-13,2,25:18.15
-12,2,25:18.15
-11,2,25:18.15
-10,2,25:18.15
-9,2,25:18.15
-8,2,25:18.15
-7,2,25:18.15
-4,2,25:18.15
-3,2,25:18.15
-14,3,25:18.7
-13,3,25:18.15
-9,3,25:18.15
-8,3,25:18.15
-7,3,25:18.15
-4,3,25:18.15
-3,3,25:18.15
-13,4,25:18.15
-10,4,25:18.15
-9,4,25:18.15
-8,4,25:18.15
-7,4,25:18.15
-6,4,25:18.15
-4,4,25:18.15
-3,4,25:18.15
-13,5,25:18.15
-12,5,25:18.15
-10,5,25:18.15
-9,5,25:18.15
-7,5,25:18.15
-6,5,25:18.15
-4,5,25:18.15
-3,5,25:18.15
-13,6,25:18.15
-12,6,25:18.15
-11,6,25:18.15
-10,6,25:18.15
-9,6,25:18.15
-8,6,25:18.15
-7,6,25:18.15
-6,6,25:18.15
-11,7,25:18.15
-10,7,25:18.15
-9,7,25:18.15
-8,7,25:18.15
-7,7,25:18.15
-5,7,25:18.15
-10,8,25:18.15
-6,8,25:18.15
-5,8,25:18.15
-10,9,25:18.15
-9,9,25:18.15
-6,9,25:18.15
-5,9,25:18.15
-10,10,25:18.15
-9,10,25:18.15
-8,10,25:18.15
-7,10,25:18.15
-6,10,25:18.15
-8,11,25:18.7
-7,11,25:18.7
-11,2,26:18.15
-10,2,26:18.15
-9,2,26:18.15
-8,2,26:18.15
-7,2,26:18.15
-6,2,26:18.15
-5,2,26:18.15
-4,2,26:18.15
-13,3,26:18.15
-12,3,26:18.15
-11,3,26:18.15
-10,3,26:18.15
-9,3,26:18.15
-8,3,26:18.15
-7,3,26:18.15
-6,3,26:18.15
-5,3,26:18.15
-4,3,26:18.15
-12,4,26:18.15
-11,4,26:18.15
-9,4,26:18.15
-8,4,26:18.15
-7,4,26:18.15
-6,4,26:18.15
-5,4,26:18.15
-4,4,26:18.15
-12,5,26:18.15
-11,5,26:18.15
-10,5,26:18.15
-9,5,26:18.15
-8,5,26:18.15
-7,5,26:18.15
-6,5,26:18.15
-5,5,26:18.15
-11,6,26:18.15
-10,6,26:18.15
-9,6,26:18.15
-8,6,26:18.15
-7,6,26:18.15
-6,6,26:18.15
-10,7,26:18.15
-9,7,26:18.15
-8,7,26:18.15
-7,7,26:18.15
-6,7,26:18.15
-9,8,26:18.15
-8,8,26:18.15
-7,8,26:18.15
-6,8,26:18.15
-9,9,26:18.15
-8,9,26:18.15
-7,9,26:18.15
-8,10,26:18.15
-7,10,26:18.15
-6,3,27:18.15
-10,4,27:18.15
-9,4,27:18.15
-7,4,27:18.15
-6,4,27:18.15
-10,5,27:18.15
-9,5,27:18.15
-8,5,27:18.15
-8,6,27:18.15
-8,7,27:18.15
-8,8,27:18.15
