[META]
version=2.0
spawnOnBlockType=2
spawnSunlight=True
spawnDarkness=True
spawnWater=False
spawnLava=False
underFill=False
randomRotation=True
dig=True
tree=False
branch=False
needsFoundation=True
rarity=100
collisionPercentage=20
spawnElevationMin=0
spawnElevationMax=200
spawnInBiome=Custom
[DATA]
-5,-2,-8:17.15
-6,-1,-8:17.15
-5,-1,-8:17.15
-7,3,-8:17.15
-4,4,-8:17.15
-4,5,-8:17.15
-6,-2,-7:17.15
-5,-2,-7:17.15
-4,-2,-7:17.15
-6,-1,-7:17.15
-5,-1,-7:17.15
-4,-1,-7:17.15
-5,1,-7:17.15
-8,2,-7:17.15
-7,2,-7:17.15
-8,3,-7:17.15
-7,3,-7:17.15
-6,3,-7:17.15
-7,4,-7:17.15
-6,4,-7:17.15
-5,4,-7:17.15
-5,5,-7:17.15
-4,5,-7:17.15
-3,5,-7:17.15
-5,6,-7:17.15
-4,6,-7:17.15
-3,6,-7:17.15
-6,-1,-6:17.15
-5,-1,-6:17.15
-6,0,-6:17.15
-5,0,-6:17.15
-5,1,-6:17.15
-4,1,-6:17.15
-8,2,-6:17.15
-7,2,-6:17.15
-5,2,-6:17.15
-8,3,-6:17.15
-7,3,-6:17.15
-6,3,-6:17.15
-5,3,-6:17.15
-7,4,-6:17.15
-6,4,-6:17.15
-4,4,-6:17.15
-5,5,-6:17.15
-4,5,-6:17.15
-3,5,-6:17.15
-5,-1,-5:17.15
-5,0,-5:17.15
-4,0,-5:17.15
-6,1,-5:17.15
-5,1,-5:17.15
-4,1,-5:17.15
-7,2,-5:17.15
-5,2,-5:17.15
-4,2,-5:17.15
-8,3,-5:17.15
-7,3,-5:17.15
-6,3,-5:17.15
-5,3,-5:17.15
-4,3,-5:17.15
-7,4,-5:17.15
-6,4,-5:17.15
-5,4,-5:17.15
-4,4,-5:17.15
-6,5,-5:17.15
-5,5,-5:17.15
-5,6,-5:17.15
-6,0,-4:17.15
-5,0,-4:17.15
-5,1,-4:17.15
-7,2,-4:17.15
-6,2,-4:17.15
-5,2,-4:17.15
-4,2,-4:17.15
-8,3,-4:17.15
-7,3,-4:17.15
-6,3,-4:17.15
-5,3,-4:17.15
-4,3,-4:17.15
-8,4,-4:17.15
-6,4,-4:17.15
-5,4,-4:17.15
-4,4,-4:17.15
-6,5,-4:17.15
-5,5,-4:17.15
-6,1,-3:17.15
-5,1,-3:17.15
-4,1,-3:17.15
-7,2,-3:17.15
-6,2,-3:17.15
-5,2,-3:17.15
-4,2,-3:17.15
-8,3,-3:17.15
-7,3,-3:17.15
-6,3,-3:17.15
-5,3,-3:17.15
-7,4,-3:17.15
-6,4,-3:17.15
-5,4,-3:17.15
-6,5,-3:17.15
-5,5,-3:17.15
-4,5,-3:17.15
-5,0,-2:17.15
-4,0,-2:17.15
-6,1,-2:17.15
-5,1,-2:17.15
-4,1,-2:17.15
-8,2,-2:17.15
-7,2,-2:17.15
-6,2,-2:17.15
-5,2,-2:17.15
-4,2,-2:17.15
-8,3,-2:17.15
-7,3,-2:17.15
-6,3,-2:17.15
-5,3,-2:17.15
-4,3,-2:17.15
-7,4,-2:17.15
-6,4,-2:17.15
-5,4,-2:17.15
-4,4,-2:17.15
-3,4,-2:17.15
-7,5,-2:17.15
-6,5,-2:17.15
-5,5,-2:17.15
-4,5,-2:17.15
-4,-1,-1:17.15
-5,0,-1:17.15
-4,0,-1:17.15
-6,1,-1:17.15
-5,1,-1:17.15
-4,1,-1:17.15
-9,2,-1:17.15
-8,2,-1:17.15
-7,2,-1:17.15
-6,2,-1:17.15
-5,2,-1:17.15
-4,2,-1:17.15
-8,3,-1:17.15
-7,3,-1:17.15
-6,3,-1:17.15
-5,3,-1:17.15
-4,3,-1:17.15
-7,4,-1:17.15
-6,4,-1:17.15
-4,4,-1:17.15
-6,5,-1:17.15
-5,5,-1:17.15
-4,5,-1:17.15
-4,-2,0:17.15
-3,-2,0:17.15
-5,-1,0:17.15
-4,-1,0:17.15
-3,-1,0:17.15
-5,0,0:17.15
-4,0,0:17.15
-5,1,0:17.15
-4,1,0:17.15
-9,2,0:17.15
-8,2,0:17.15
-8,3,0:17.15
-6,3,0:17.15
-5,3,0:17.15
-4,3,0:17.15
-6,4,0:17.15
-4,4,0:17.15
-6,5,0:17.15
-5,5,0:17.15
-4,-3,1:17.15
-3,-3,1:17.15
-4,-2,1:17.15
-3,-2,1:17.15
-4,-1,1:17.15
-3,-1,1:17.15
-4,0,1:17.15
-9,1,1:17.15
-9,2,1:17.15
-8,2,1:17.15
-6,3,1:17.15
-5,3,1:17.15
-4,3,1:17.15
-6,4,1:17.15
-4,4,1:17.15
-5,5,1:17.15
-3,-4,2:17.15
-4,-3,2:17.15
-3,-3,2:17.15
-4,-2,2:17.15
-3,-2,2:17.15
-10,1,2:17.15
-9,1,2:17.15
-10,2,2:17.15
-9,2,2:17.15
-6,3,2:17.15
-5,3,2:17.15
-4,3,2:17.15
-6,4,2:17.15
-4,4,2:17.15
-5,5,2:17.15
-3,-5,3:17.15
-3,-4,3:17.15
-2,-4,3:17.15
-3,-3,3:17.15
-10,1,3:17.15
-9,1,3:17.15
-10,2,3:17.15
-5,3,3:17.15
-4,3,3:17.15
-6,4,3:17.15
-4,4,3:17.15
-5,5,3:17.15
-4,5,3:17.15
-3,-5,4:17.15
-2,-5,4:17.15
-3,-4,4:17.15
-2,-4,4:17.15
-11,1,4:17.15
-10,1,4:17.15
-5,3,4:17.15
-4,3,4:17.15
-6,4,4:17.15
-5,4,4:17.15
-4,4,4:17.15
-5,5,4:17.15
-4,5,4:17.15
-3,-6,5:17.15
-2,-6,5:17.15
-3,-5,5:17.15
-2,-5,5:17.15
-11,1,5:17.15
-10,1,5:17.15
-5,3,5:17.15
-4,3,5:17.15
-5,4,5:17.15
-4,4,5:17.15
-5,5,5:17.15
-4,5,5:17.15
-2,-8,6:18.15
-1,-8,6:18.15
-1,-7,6:18.15
-3,-6,6:17.15
-2,-6,6:17.15
-3,-5,6:17.15
-2,-5,6:17.15
-12,0,6:18.15
-11,0,6:18.15
-11,1,6:17.15
-10,1,6:17.15
-5,3,6:17.15
-4,3,6:17.15
-5,4,6:17.15
-4,4,6:17.15
-5,5,6:17.15
-4,5,6:17.15
-1,7,6:18.12
-4,-9,7:18.15
-3,-9,7:18.15
-2,-8,7:18.15
-1,-8,7:18.15
-3,-7,7:18.15
-1,-7,7:18.15
0,-7,7:18.15
-3,-6,7:17.15
-2,-6,7:17.15
-1,-6,7:18.15
0,-6,7:18.15
-4,-5,7:18.15
-3,-4,7:18.15
-11,-1,7:18.15
-12,0,7:18.15
-11,0,7:18.15
-4,0,7:18.12
-3,0,7:18.12
-13,1,7:18.15
-11,1,7:17.15
-13,2,7:18.15
-5,3,7:17.15
-4,3,7:17.15
-5,4,7:17.15
-4,4,7:17.15
-9,5,7:18.12
-5,5,7:17.15
-4,5,7:17.15
-1,6,7:18.12
-2,7,7:18.12
-1,7,7:18.12
-4,-9,8:18.15
-3,-9,8:18.15
-4,-8,8:18.15
-3,-8,8:18.15
-2,-8,8:18.15
-1,-8,8:18.15
0,-8,8:18.15
-3,-7,8:18.15
-2,-7,8:17.15
-1,-7,8:18.15
0,-7,8:18.15
-3,-6,8:17.15
-2,-6,8:17.15
0,-6,8:18.15
-4,-5,8:18.15
-4,-4,8:18.15
-3,-4,8:18.15
-2,-4,8:18.15
-14,-1,8:18.15
-12,-1,8:18.15
-11,-1,8:18.15
-10,-1,8:18.15
-3,-1,8:18.12
-12,0,8:18.15
-11,0,8:17.15
-4,0,8:18.12
-3,0,8:18.12
-2,0,8:18.12
-13,1,8:18.15
-12,1,8:18.15
-11,1,8:17.15
-9,1,8:18.15
-2,1,8:18.12
-13,2,8:18.15
-12,2,8:18.15
-10,2,8:18.15
-9,2,8:18.15
-5,3,8:17.15
-4,3,8:17.15
-9,4,8:18.12
-8,4,8:18.12
-5,4,8:17.15
-4,4,8:17.15
-9,5,8:18.12
-8,5,8:18.12
-5,5,8:17.15
-4,5,8:17.15
-8,6,8:18.12
-1,6,8:18.12
-1,7,8:18.12
-2,8,8:18.12
-1,-10,9:18.15
0,-10,9:18.15
-3,-9,9:18.15
-2,-9,9:18.15
-4,-8,9:18.15
-3,-8,9:18.15
-2,-8,9:18.15
-1,-8,9:18.15
0,-8,9:18.15
-6,-7,9:18.15
-4,-7,9:18.15
-3,-7,9:18.15
-2,-7,9:17.15
-1,-7,9:18.15
0,-7,9:18.15
-6,-6,9:18.15
-4,-6,9:18.15
-3,-6,9:18.15
-2,-6,9:17.15
-1,-6,9:18.15
0,-6,9:18.15
-4,-5,9:18.15
-3,-5,9:18.15
-2,-5,9:18.15
0,-5,9:18.15
-3,-4,9:18.15
-2,-4,9:18.15
-1,-3,9:18.15
0,-3,9:18.15
-14,-1,9:18.15
-13,-1,9:18.15
-12,-1,9:18.15
-11,-1,9:18.15
-10,-1,9:18.15
-9,-1,9:18.15
-8,-1,9:18.15
-3,-1,9:18.12
-14,0,9:18.15
-13,0,9:18.15
-12,0,9:18.15
-11,0,9:18.15
-10,0,9:18.15
-8,0,9:18.15
-5,0,9:18.12
-4,0,9:18.12
-3,0,9:18.12
-2,0,9:18.12
-13,1,9:18.15
-12,1,9:18.15
-11,1,9:17.15
-10,1,9:18.15
-2,1,9:18.12
-1,1,9:18.12
-12,2,9:18.15
-11,2,9:18.15
-10,2,9:18.15
4,2,9:18.4
-12,3,9:18.15
-8,3,9:18.12
-4,3,9:17.15
-12,4,9:18.15
-11,4,9:18.15
-9,4,9:18.12
-8,4,9:18.12
-5,4,9:17.15
-4,4,9:17.15
-9,5,9:18.12
-4,5,9:17.15
0,5,9:18.12
-8,6,9:18.12
-1,6,9:18.12
-1,7,9:18.12
-3,8,9:18.12
-2,8,9:18.12
-2,-10,10:18.15
-1,-10,10:18.15
0,-10,10:18.15
0,-9,10:18.15
-5,-8,10:18.15
-3,-8,10:18.15
-2,-8,10:18.15
-1,-8,10:18.15
-6,-7,10:18.15
-5,-7,10:18.15
-4,-7,10:18.15
-3,-7,10:18.15
-2,-7,10:17.15
-1,-7,10:18.15
0,-7,10:18.15
-6,-6,10:18.15
-5,-6,10:18.15
-4,-6,10:18.15
-3,-6,10:18.15
-2,-6,10:17.15
-1,-6,10:18.15
0,-6,10:18.15
-5,-5,10:18.15
-3,-5,10:18.15
-2,-5,10:18.15
-1,-5,10:18.15
0,-5,10:18.15
0,-4,10:18.15
-1,-3,10:18.15
0,-3,10:18.15
-13,-1,10:18.15
-12,-1,10:18.15
-11,-1,10:18.15
-10,-1,10:18.15
-9,-1,10:18.15
-13,0,10:18.15
-12,0,10:18.15
-11,0,10:18.15
-10,0,10:18.15
-9,0,10:18.15
-5,0,10:18.12
-4,0,10:18.12
-3,0,10:18.12
-2,0,10:18.12
-13,1,10:18.15
-12,1,10:18.15
-11,1,10:18.15
-10,1,10:18.15
-9,1,10:18.15
-2,1,10:18.12
-1,1,10:18.12
3,1,10:18.4
-13,2,10:18.15
-12,2,10:18.15
-11,2,10:18.15
-10,2,10:18.15
-1,2,10:18.12
3,2,10:18.4
4,2,10:18.4
-12,3,10:18.15
-11,3,10:18.15
-8,3,10:18.12
-4,3,10:17.15
3,3,10:18.4
-8,4,10:18.12
-5,4,10:17.15
-4,4,10:17.15
-3,4,10:17.15
-9,5,10:18.12
-8,5,10:18.12
-5,5,10:17.15
-4,5,10:17.15
-1,5,10:18.12
0,5,10:18.12
-8,6,10:18.12
-7,6,10:18.12
-1,6,10:18.12
-7,7,10:18.12
-2,7,10:18.12
-1,7,10:18.12
-3,8,10:18.12
-7,11,10:18.4
-6,11,10:18.4
-5,11,10:18.4
-6,12,10:18.4
-2,-9,11:18.15
-1,-9,11:18.15
0,-9,11:18.15
-5,-8,11:18.15
-4,-8,11:18.15
-3,-8,11:18.15
-2,-8,11:18.15
-1,-8,11:18.15
0,-8,11:18.15
-5,-7,11:18.15
-4,-7,11:18.15
-3,-7,11:18.15
-2,-7,11:18.15
-1,-7,11:18.15
0,-7,11:18.15
-5,-6,11:18.15
-4,-6,11:18.15
-3,-6,11:18.15
-2,-6,11:18.15
-1,-6,11:18.15
0,-6,11:18.15
-4,-5,11:18.15
-3,-5,11:18.15
-2,-5,11:18.15
-1,-5,11:18.15
0,-5,11:18.15
-2,-4,11:18.15
-1,-4,11:18.15
0,-4,11:18.15
-9,-2,11:18.12
-8,-2,11:18.12
-10,-1,11:18.12
-12,0,11:18.15
-11,0,11:18.15
-10,0,11:18.15
-5,0,11:18.12
-4,0,11:18.12
-3,0,11:18.12
-12,1,11:18.15
-11,1,11:18.15
-10,1,11:18.15
-2,1,11:18.12
2,1,11:18.4
-12,2,11:18.15
-11,2,11:18.15
-1,2,11:18.12
3,2,11:18.4
-8,3,11:18.12
-5,3,11:17.15
-4,3,11:17.15
-3,3,11:17.15
3,3,11:18.4
-8,4,11:18.12
-5,4,11:17.15
-3,4,11:17.15
-1,4,11:18.12
2,4,11:18.4
3,4,11:18.4
-8,5,11:18.12
-5,5,11:17.15
-4,5,11:17.15
-3,5,11:17.15
-1,5,11:18.12
-8,6,11:18.12
-7,6,11:18.12
-1,6,11:18.12
-7,7,11:18.12
-6,7,11:18.12
-3,7,11:18.12
-2,7,11:18.12
-1,7,11:18.12
-4,8,11:18.12
-3,8,11:18.12
-7,10,11:18.4
-7,11,11:18.4
-6,11,11:18.4
-5,11,11:18.4
-4,11,11:18.4
-2,-8,12:18.15
-1,-8,12:18.15
-4,-7,12:18.15
-3,-7,12:18.15
-2,-7,12:18.15
-3,-6,12:18.15
-2,-6,12:18.15
-9,-2,12:18.12
-8,-2,12:18.12
-7,-2,12:18.12
-9,-1,12:18.12
-10,0,12:18.12
-9,0,12:18.12
-4,0,12:18.12
-3,0,12:18.12
-10,1,12:18.12
-6,1,12:18.12
-5,1,12:18.12
-4,1,12:18.12
-3,1,12:18.12
-2,1,12:18.12
1,1,12:18.12
2,1,12:18.4
-7,2,12:18.12
-6,2,12:18.12
-2,2,12:18.12
-1,2,12:18.12
2,2,12:18.4
3,2,12:18.4
-7,3,12:18.12
-5,3,12:17.15
-4,3,12:17.15
-3,3,12:17.15
-1,3,12:18.12
2,3,12:18.4
3,3,12:18.4
-8,4,12:18.12
-7,4,12:18.12
-5,4,12:17.15
-3,4,12:17.15
-1,4,12:18.12
2,4,12:18.4
-8,5,12:18.12
-7,5,12:18.12
-5,5,12:17.15
-4,5,12:17.15
-3,5,12:17.15
-1,5,12:18.12
2,5,12:18.4
-7,6,12:18.12
-6,6,12:18.12
-2,6,12:18.12
-1,6,12:18.12
-6,7,12:18.12
-5,7,12:18.12
-4,7,12:18.12
-3,7,12:18.12
-2,7,12:18.12
-7,9,12:18.12
-7,10,12:18.4
-5,10,12:18.4
-4,10,12:18.4
-3,10,12:18.4
-6,11,12:18.4
-5,11,12:18.4
-9,-1,13:18.12
-8,-1,13:18.12
-7,-1,13:18.12
-6,-1,13:18.12
-9,0,13:18.12
-9,1,13:18.12
-4,1,13:18.12
-3,1,13:18.12
0,1,13:18.12
1,1,13:18.12
-9,2,13:18.12
-6,2,13:18.12
-5,2,13:18.12
-4,2,13:18.12
-3,2,13:18.12
-2,2,13:18.12
1,2,13:18.12
2,2,13:18.4
-6,3,13:18.12
-5,3,13:18.12
-4,3,13:17.15
-3,3,13:17.15
-2,3,13:18.12
2,3,13:18.4
-7,4,13:18.12
-6,4,13:18.12
-5,4,13:17.15
-3,4,13:17.15
-2,4,13:18.12
1,4,13:18.12
2,4,13:18.4
-7,5,13:18.12
-6,5,13:18.12
-5,5,13:17.15
-4,5,13:17.15
-3,5,13:17.15
-2,5,13:18.12
1,5,13:18.12
-6,6,13:18.12
-5,6,13:18.12
-4,6,13:18.12
-3,6,13:18.12
-2,6,13:18.12
0,6,13:18.12
-5,7,13:18.12
-4,7,13:18.12
-8,8,13:18.12
-7,8,13:18.12
-2,8,13:18.12
-7,9,13:18.12
-6,9,13:18.12
-4,9,13:18.12
-3,9,13:18.12
-6,10,13:18.4
-5,10,13:18.4
-4,10,13:18.4
-6,11,13:18.4
-8,-1,14:18.12
-6,-1,14:18.12
-5,-1,14:18.12
-8,0,14:18.12
-7,0,14:18.12
-6,0,14:18.12
-5,0,14:18.12
-4,0,14:18.12
-8,1,14:18.12
-4,1,14:18.12
-3,1,14:18.12
-2,1,14:18.12
-1,1,14:18.12
0,1,14:18.12
-9,2,14:18.12
-8,2,14:18.12
-4,2,14:18.12
-3,2,14:18.12
-2,2,14:18.12
-1,2,14:18.12
0,2,14:18.12
1,2,14:18.12
-8,3,14:18.12
-7,3,14:18.12
-5,3,14:18.12
-4,3,14:18.12
-3,3,14:18.12
0,3,14:18.12
1,3,14:18.12
-8,4,14:18.12
-7,4,14:18.12
-6,4,14:18.12
-5,4,14:18.12
-4,4,14:18.12
-3,4,14:18.12
0,4,14:18.12
1,4,14:18.12
-7,5,14:18.12
-6,5,14:18.12
-5,5,14:18.12
-4,5,14:18.12
-3,5,14:18.12
-2,5,14:18.12
-1,5,14:18.12
0,5,14:18.12
-7,6,14:18.12
-6,6,14:18.12
-3,6,14:18.12
-2,6,14:18.12
-1,6,14:18.12
-7,7,14:18.12
-6,7,14:18.12
-3,7,14:18.12
-2,7,14:18.12
-7,8,14:18.12
-6,8,14:18.12
-4,8,14:18.12
-3,8,14:18.12
-6,9,14:18.12
-5,9,14:18.12
-4,9,14:18.12
-5,10,14:18.4
-7,0,15:18.12
-6,0,15:18.12
-8,1,15:18.12
-7,1,15:18.12
-6,1,15:18.12
-5,1,15:18.12
-4,1,15:18.12
-7,2,15:18.12
-6,2,15:18.12
-5,2,15:18.12
-4,2,15:18.12
-2,2,15:18.12
-7,3,15:18.12
-6,3,15:18.12
-5,3,15:18.12
-4,3,15:18.12
-3,3,15:18.12
-2,3,15:18.12
-1,3,15:18.12
0,3,15:18.12
-7,4,15:18.12
-6,4,15:18.12
-5,4,15:18.12
-4,4,15:18.12
-3,4,15:18.12
-2,4,15:18.12
-1,4,15:18.12
-6,5,15:18.12
-5,5,15:18.12
-4,5,15:18.12
-3,5,15:18.12
-2,5,15:18.12
-6,6,15:18.12
-5,6,15:18.12
-4,6,15:18.12
-3,6,15:18.12
-6,7,15:18.12
-5,7,15:18.12
-4,7,15:18.12
-3,7,15:18.12
-5,8,15:18.12
-4,8,15:18.12
1,8,15:18.12
-3,-2,16:18.4
-4,-1,16:18.12
-3,-1,16:18.12
-2,-1,16:18.12
-4,0,16:18.12
-2,0,16:18.12
-5,1,16:18.12
-2,1,16:18.12
-1,1,16:18.12
-5,2,16:18.12
-4,2,16:18.12
-2,2,16:18.12
-1,2,16:18.12
-6,3,16:18.12
-5,3,16:18.12
-4,3,16:18.12
-3,3,16:18.12
-2,3,16:18.12
-8,4,16:18.12
-6,4,16:18.12
-5,4,16:18.12
-4,4,16:18.12
-3,4,16:18.12
-2,4,16:18.12
-1,4,16:18.12
-9,5,16:18.12
-5,5,16:18.12
-4,5,16:18.12
-3,5,16:18.12
-2,5,16:18.12
-1,5,16:18.12
0,5,16:18.12
-10,6,16:18.4
-9,6,16:18.12
-6,6,16:18.12
-5,6,16:18.12
-4,6,16:18.12
-3,6,16:18.12
-2,6,16:18.12
-1,6,16:18.12
0,6,16:18.12
1,6,16:18.12
-8,7,16:18.12
-7,7,16:18.12
-6,7,16:18.12
-3,7,16:18.12
-2,7,16:18.12
-1,7,16:18.12
0,7,16:18.12
1,7,16:18.12
-2,8,16:18.12
-1,8,16:18.12
0,8,16:18.12
1,8,16:18.12
-3,-1,17:18.12
-2,-1,17:18.12
-4,0,17:18.12
-3,0,17:18.12
-2,0,17:18.12
-4,1,17:18.12
-3,1,17:18.12
-2,1,17:18.12
-4,2,17:18.12
-3,2,17:18.12
-8,4,17:18.12
-7,4,17:18.12
-6,4,17:18.12
-5,4,17:18.12
-9,5,17:18.12
-8,5,17:18.12
-7,5,17:18.12
-6,5,17:18.12
-5,5,17:18.12
-9,6,17:18.12
-8,6,17:18.12
-7,6,17:18.12
-6,6,17:18.12
-2,6,17:18.12
-1,6,17:18.12
-1,7,17:18.12
0,7,17:18.12
