[META]
version=2.0
spawnOnBlockType=2
spawnSunlight=True
spawnDarkness=True
spawnWater=False
spawnLava=False
underFill=False
randomRotation=True
dig=True
tree=False
branch=False
needsFoundation=True
rarity=100
collisionPercentage=20
spawnElevationMin=0
spawnElevationMax=200
spawnInBiome=Custom
[DATA]
9,-10,-8:17.15
3,-9,-8:17.15
8,-9,-8:17.15
9,-9,-8:17.15
2,-8,-8:17.15
8,-5,-8:17.15
8,-4,-8:17.15
8,-10,-7:17.15
2,-9,-7:17.15
8,-9,-7:17.15
9,-9,-7:17.15
10,-9,-7:17.15
2,-8,-7:17.15
3,-8,-7:17.15
9,-8,-7:17.15
4,-7,-7:17.15
7,-6,-7:17.15
8,-6,-7:17.15
9,-6,-7:17.15
8,-5,-7:17.15
9,-5,-7:17.15
8,-4,-7:17.15
3,-9,-6:17.15
5,-9,-6:17.15
8,-9,-6:17.15
9,-9,-6:17.15
4,-8,-6:17.15
5,-8,-6:17.15
8,-8,-6:17.15
9,-8,-6:17.15
3,-7,-6:17.15
4,-7,-6:17.15
9,-7,-6:17.15
10,-7,-6:17.15
8,-6,-6:17.15
9,-6,-6:17.15
8,-5,-6:17.15
9,-5,-6:17.15
4,-9,-5:17.15
5,-9,-5:17.15
8,-9,-5:17.15
9,-9,-5:17.15
10,-9,-5:17.15
4,-8,-5:17.15
5,-8,-5:17.15
6,-8,-5:17.15
7,-8,-5:17.15
8,-8,-5:17.15
9,-8,-5:17.15
10,-8,-5:17.15
4,-7,-5:17.15
6,-7,-5:17.15
8,-7,-5:17.15
9,-7,-5:17.15
9,-6,-5:17.15
10,-6,-5:17.15
9,-5,-5:17.15
8,-11,-4:17.15
7,-10,-4:17.15
8,-10,-4:17.15
9,-10,-4:17.15
5,-9,-4:17.15
6,-9,-4:17.15
7,-9,-4:17.15
8,-9,-4:17.15
9,-9,-4:17.15
5,-8,-4:17.15
6,-8,-4:17.15
7,-8,-4:17.15
8,-8,-4:17.15
9,-8,-4:17.15
10,-8,-4:17.15
7,-7,-4:17.15
8,-7,-4:17.15
9,-7,-4:17.15
10,-7,-4:17.15
10,-6,-4:17.15
8,-11,-3:17.15
7,-10,-3:17.15
8,-10,-3:17.15
10,-10,-3:17.15
8,-9,-3:17.15
5,-8,-3:17.15
7,-8,-3:17.15
8,-8,-3:17.15
9,-8,-3:17.15
6,-7,-3:17.15
7,-7,-3:17.15
8,-7,-3:17.15
9,-7,-3:17.15
10,-7,-3:17.15
9,-6,-3:17.15
10,-6,-3:17.15
8,-11,-2:17.15
9,-11,-2:17.15
7,-10,-2:17.15
8,-10,-2:17.15
9,-10,-2:17.15
10,-10,-2:17.15
6,-9,-2:17.15
7,-9,-2:17.15
8,-9,-2:17.15
9,-9,-2:17.15
10,-9,-2:17.15
11,-9,-2:17.15
6,-8,-2:17.15
7,-8,-2:17.15
8,-8,-2:17.15
9,-8,-2:17.15
10,-8,-2:17.15
11,-8,-2:17.15
6,-7,-2:17.15
7,-7,-2:17.15
8,-7,-2:17.15
9,-7,-2:17.15
10,-7,-2:17.15
11,-7,-2:17.15
7,-6,-2:17.15
8,-6,-2:17.15
9,-6,-2:17.15
10,-6,-2:17.15
9,-11,-1:17.15
8,-10,-1:17.15
10,-10,-1:17.15
7,-9,-1:17.15
8,-9,-1:17.15
9,-9,-1:17.15
10,-9,-1:17.15
7,-8,-1:17.15
8,-8,-1:17.15
10,-8,-1:17.15
7,-7,-1:17.15
10,-7,-1:17.15
8,-6,-1:17.15
9,-6,-1:17.15
7,-9,0:17.15
8,-9,0:17.15
9,-9,0:17.15
10,-9,0:17.15
7,-8,0:17.15
10,-8,0:17.15
7,-7,0:17.15
8,-7,0:17.15
9,-7,0:17.15
10,-7,0:17.15
8,-6,0:17.15
9,-6,0:17.15
8,-9,1:17.15
9,-9,1:17.15
7,-8,1:17.15
8,-8,1:17.15
9,-8,1:17.15
10,-8,1:17.15
7,-7,1:17.15
8,-7,1:17.15
9,-7,1:17.15
10,-7,1:17.15
8,-6,1:17.15
8,-9,2:17.15
7,-8,2:17.15
8,-8,2:17.15
9,-8,2:17.15
10,-8,2:17.15
7,-7,2:17.15
8,-7,2:17.15
9,-7,2:17.15
10,-7,2:17.15
8,-6,2:17.15
9,-6,2:17.15
7,-8,3:17.15
8,-8,3:17.15
9,-8,3:17.15
7,-7,3:17.15
8,-7,3:17.15
9,-7,3:17.15
10,-7,3:17.15
8,-6,3:17.15
9,-6,3:17.15
8,-8,4:17.15
9,-8,4:17.15
7,-7,4:17.15
8,-7,4:17.15
9,-7,4:17.15
8,-6,4:17.15
9,-6,4:17.15
8,-8,5:17.15
9,-8,5:17.15
7,-7,5:17.15
8,-7,5:17.15
9,-7,5:17.15
8,-6,5:17.15
9,-6,5:17.15
8,-8,6:17.15
9,-8,6:17.15
8,-7,6:17.15
9,-7,6:17.15
8,-6,6:17.15
9,-6,6:17.15
8,-8,7:17.15
9,-8,7:17.15
7,-7,7:17.15
8,-7,7:17.15
9,-7,7:17.15
8,-6,7:17.15
9,-6,7:17.15
8,-8,8:17.15
9,-8,8:17.15
8,-7,8:17.15
9,-7,8:17.15
8,-6,8:17.15
9,-6,8:17.15
10,-2,8:18.12
12,-10,9:18.12
4,-9,9:18.12
4,-8,9:18.12
8,-8,9:17.15
9,-8,9:17.15
8,-7,9:17.15
9,-7,9:17.15
8,-6,9:17.15
9,-6,9:17.15
9,-2,9:18.12
10,-2,9:18.12
11,-11,10:18.12
12,-10,10:18.12
13,-10,10:18.12
4,-9,10:18.12
13,-9,10:18.12
4,-8,10:18.12
8,-8,10:17.15
9,-8,10:17.15
4,-7,10:18.12
8,-7,10:17.15
9,-7,10:17.15
8,-6,10:17.15
9,-6,10:17.15
11,-3,10:18.12
9,-2,10:18.12
10,-2,10:18.12
11,-2,10:18.12
10,-1,10:18.12
11,-11,11:18.12
12,-11,11:18.12
5,-10,11:18.12
12,-10,11:18.12
13,-10,11:18.12
4,-9,11:18.12
5,-9,11:18.12
13,-9,11:18.12
3,-8,11:18.12
4,-8,11:18.12
13,-8,11:18.12
4,-7,11:18.12
8,-7,11:17.15
9,-7,11:17.15
4,-6,11:18.12
8,-6,11:17.15
9,-6,11:17.15
11,-3,11:18.12
7,-2,11:18.12
9,-2,11:18.12
10,-2,11:18.12
11,-2,11:18.12
9,-1,11:18.12
10,-1,11:18.12
10,-11,12:18.12
11,-11,12:18.12
5,-10,12:18.12
6,-10,12:18.12
12,-10,12:18.12
13,-10,12:18.12
4,-9,12:18.12
5,-9,12:18.12
13,-9,12:18.12
4,-8,12:18.12
13,-8,12:18.12
4,-7,12:18.12
8,-7,12:17.15
9,-7,12:17.15
4,-6,12:18.12
8,-6,12:17.15
9,-6,12:17.15
17,-4,12:18.4
11,-3,12:18.12
7,-2,12:18.12
9,-2,12:18.12
10,-2,12:18.12
11,-2,12:18.12
2,-1,12:18.4
2,0,12:18.4
3,0,12:18.4
7,-16,13:18.4
6,-15,13:18.4
7,-15,13:18.4
10,-11,13:18.12
6,-10,13:18.12
11,-10,13:18.12
12,-10,13:18.12
4,-9,13:18.12
5,-9,13:18.12
12,-9,13:18.12
13,-9,13:18.12
4,-8,13:18.12
8,-8,13:17.15
9,-8,13:17.15
13,-8,13:18.12
4,-7,13:18.12
7,-7,13:17.15
8,-7,13:17.15
9,-7,13:17.15
10,-7,13:17.15
13,-7,13:18.12
4,-6,13:18.12
7,-6,13:17.15
8,-6,13:17.15
9,-6,13:17.15
10,-6,13:17.15
4,-5,13:18.12
8,-5,13:17.15
9,-5,13:17.15
17,-5,13:18.4
12,-4,13:18.12
17,-4,13:18.4
7,-3,13:18.12
11,-3,13:18.12
16,-3,13:18.4
17,-3,13:18.4
2,-2,13:18.4
7,-2,13:18.12
9,-2,13:18.12
10,-2,13:18.12
2,-1,13:18.4
2,0,13:18.4
3,0,13:18.4
4,0,13:18.4
6,-15,14:18.4
7,-15,14:18.4
8,-15,14:18.4
6,-10,14:18.12
10,-10,14:18.12
11,-10,14:18.12
12,-10,14:18.12
5,-9,14:18.12
6,-9,14:18.12
12,-9,14:18.12
4,-8,14:18.12
5,-8,14:18.12
8,-8,14:17.15
9,-8,14:17.15
12,-8,14:18.12
13,-8,14:18.12
4,-7,14:18.12
7,-7,14:17.15
8,-7,14:17.15
9,-7,14:17.15
10,-7,14:17.15
12,-7,14:18.12
13,-7,14:18.12
4,-6,14:18.12
5,-6,14:18.12
7,-6,14:17.15
10,-6,14:17.15
12,-6,14:18.12
16,-6,14:18.4
5,-5,14:18.12
8,-5,14:17.15
9,-5,14:17.15
12,-5,14:18.12
16,-5,14:18.4
17,-5,14:18.4
6,-4,14:18.12
11,-4,14:18.12
12,-4,14:18.12
17,-4,14:18.4
2,-3,14:18.4
6,-3,14:18.12
7,-3,14:18.12
8,-3,14:18.12
10,-3,14:18.12
11,-3,14:18.12
15,-3,14:18.4
16,-3,14:18.4
2,-2,14:18.4
9,-2,14:18.12
10,-2,14:18.12
14,-2,14:18.12
15,-2,14:18.4
2,-1,14:18.4
3,0,14:18.4
4,0,14:18.4
5,0,14:18.4
7,-15,15:18.4
7,-14,15:18.4
8,-14,15:18.4
9,-14,15:18.4
5,-13,15:18.4
6,-13,15:18.4
9,-13,15:18.4
5,-12,15:18.12
7,-10,15:18.12
8,-10,15:18.12
9,-10,15:18.12
10,-10,15:18.12
11,-10,15:18.12
6,-9,15:18.12
7,-9,15:18.12
9,-9,15:18.12
10,-9,15:18.12
11,-9,15:18.12
12,-9,15:18.12
5,-8,15:18.12
6,-8,15:18.12
8,-8,15:17.15
9,-8,15:17.15
12,-8,15:18.12
5,-7,15:18.12
7,-7,15:17.15
8,-7,15:17.15
9,-7,15:17.15
10,-7,15:17.15
12,-7,15:18.12
15,-7,15:18.4
5,-6,15:18.12
6,-6,15:18.12
7,-6,15:17.15
9,-6,15:17.15
10,-6,15:17.15
12,-6,15:18.12
15,-6,15:18.4
16,-6,15:18.4
5,-5,15:18.12
6,-5,15:18.12
8,-5,15:17.15
9,-5,15:17.15
11,-5,15:18.12
12,-5,15:18.12
16,-5,15:18.4
2,-4,15:18.4
3,-4,15:18.12
6,-4,15:18.12
7,-4,15:18.12
10,-4,15:18.12
11,-4,15:18.12
16,-4,15:18.4
2,-3,15:18.4
3,-3,15:18.12
7,-3,15:18.12
8,-3,15:18.12
9,-3,15:18.12
10,-3,15:18.12
14,-3,15:18.12
15,-3,15:18.4
16,-3,15:18.4
2,-2,15:18.4
3,-2,15:18.12
13,-2,15:18.12
14,-2,15:18.12
2,-1,15:18.4
4,-1,15:18.12
5,-1,15:18.12
6,-1,15:18.12
6,0,15:18.4
7,-14,16:18.4
8,-14,16:18.4
6,-13,16:18.4
7,-13,16:18.4
8,-13,16:18.4
9,-13,16:18.4
10,-13,16:18.4
5,-12,16:18.12
6,-12,16:18.12
10,-12,16:18.12
5,-11,16:18.12
7,-9,16:18.12
9,-9,16:18.12
10,-9,16:18.12
11,-9,16:18.12
6,-8,16:18.12
7,-8,16:18.12
8,-8,16:18.12
9,-8,16:18.12
10,-8,16:18.12
11,-8,16:18.12
5,-7,16:18.12
6,-7,16:18.12
7,-7,16:17.15
8,-7,16:17.15
9,-7,16:17.15
11,-7,16:18.12
15,-7,16:18.4
6,-6,16:18.12
7,-6,16:17.15
8,-6,16:17.15
9,-6,16:17.15
10,-6,16:18.12
11,-6,16:18.12
15,-6,16:18.4
3,-5,16:18.12
6,-5,16:18.12
7,-5,16:18.12
8,-5,16:17.15
9,-5,16:17.15
10,-5,16:18.12
11,-5,16:18.12
15,-5,16:18.4
3,-4,16:18.12
7,-4,16:18.12
8,-4,16:18.12
9,-4,16:18.12
10,-4,16:18.12
15,-4,16:18.4
16,-4,16:18.4
3,-3,16:18.12
9,-3,16:18.12
13,-3,16:18.12
14,-3,16:18.12
15,-3,16:18.4
3,-2,16:18.12
4,-2,16:18.12
11,-2,16:18.12
12,-2,16:18.12
13,-2,16:18.12
4,-1,16:18.12
5,-1,16:18.12
6,-1,16:18.12
7,-1,16:18.12
8,-1,16:18.12
7,-13,17:18.4
8,-13,17:18.4
6,-12,17:18.12
7,-12,17:18.12
8,-12,17:18.12
9,-12,17:18.12
10,-12,17:18.12
5,-11,17:18.12
6,-11,17:18.12
9,-11,17:18.12
10,-11,17:18.12
11,-11,17:18.12
5,-10,17:18.12
6,-10,17:18.12
10,-10,17:18.12
11,-10,17:18.12
5,-9,17:18.12
6,-9,17:18.12
11,-9,17:18.12
5,-8,17:18.12
6,-8,17:18.12
8,-8,17:18.12
9,-8,17:18.12
10,-8,17:18.12
11,-8,17:18.12
12,-8,17:18.12
13,-8,17:18.12
5,-7,17:18.12
6,-7,17:18.12
7,-7,17:18.12
8,-7,17:18.12
9,-7,17:18.12
10,-7,17:18.12
12,-7,17:18.12
13,-7,17:18.12
14,-7,17:18.12
4,-6,17:18.12
5,-6,17:18.12
7,-6,17:18.12
8,-6,17:18.12
9,-6,17:18.12
10,-6,17:18.12
13,-6,17:18.12
14,-6,17:18.12
4,-5,17:18.12
5,-5,17:18.12
8,-5,17:18.12
9,-5,17:18.12
10,-5,17:18.12
14,-5,17:18.12
15,-5,17:18.4
4,-4,17:18.12
5,-4,17:18.12
9,-4,17:18.12
10,-4,17:18.12
11,-4,17:18.12
12,-4,17:18.12
13,-4,17:18.12
14,-4,17:18.12
15,-4,17:18.4
4,-3,17:18.12
5,-3,17:18.12
6,-3,17:18.12
7,-3,17:18.12
8,-3,17:18.12
9,-3,17:18.12
10,-3,17:18.12
11,-3,17:18.12
13,-3,17:18.12
4,-2,17:18.12
5,-2,17:18.12
6,-2,17:18.12
7,-2,17:18.12
7,-12,18:18.12
8,-12,18:18.12
6,-11,18:18.12
7,-11,18:18.12
8,-11,18:18.12
9,-11,18:18.12
6,-10,18:18.12
7,-10,18:18.12
8,-10,18:18.12
9,-10,18:18.12
10,-10,18:18.12
6,-9,18:18.12
7,-9,18:18.12
9,-9,18:18.12
10,-9,18:18.12
6,-8,18:18.12
7,-8,18:18.12
9,-8,18:18.12
10,-8,18:18.12
6,-7,18:18.12
7,-7,18:18.12
8,-7,18:18.12
9,-7,18:18.12
10,-7,18:18.12
11,-7,18:18.12
12,-7,18:18.12
6,-6,18:18.12
7,-6,18:18.12
8,-6,18:18.12
9,-6,18:18.12
10,-6,18:18.12
11,-6,18:18.12
12,-6,18:18.12
13,-6,18:18.12
5,-5,18:18.12
6,-5,18:18.12
7,-5,18:18.12
8,-5,18:18.12
9,-5,18:18.12
10,-5,18:18.12
11,-5,18:18.12
12,-5,18:18.12
13,-5,18:18.12
5,-4,18:18.12
6,-4,18:18.12
7,-4,18:18.12
8,-4,18:18.12
9,-4,18:18.12
10,-4,18:18.12
11,-4,18:18.12
12,-4,18:18.12
13,-4,18:18.12
5,-3,18:18.12
6,-3,18:18.12
7,-3,18:18.12
8,-10,19:18.12
7,-9,19:18.12
9,-9,19:18.12
2,-8,19:18.4
7,-8,19:18.12
8,-8,19:18.12
9,-8,19:18.12
2,-7,19:18.4
7,-7,19:18.12
8,-7,19:18.12
9,-7,19:18.12
12,-7,19:18.12
3,-6,19:18.12
7,-6,19:18.12
8,-6,19:18.12
9,-6,19:18.12
10,-6,19:18.12
11,-6,19:18.12
12,-6,19:18.12
4,-5,19:18.12
5,-5,19:18.12
6,-5,19:18.12
7,-5,19:18.12
8,-5,19:18.12
9,-5,19:18.12
10,-5,19:18.12
11,-5,19:18.12
6,-4,19:18.12
7,-4,19:18.12
8,-4,19:18.12
10,-4,19:18.12
11,-4,19:18.12
7,-3,19:18.12
8,-3,19:18.12
11,-3,19:18.12
11,-2,19:18.12
8,-1,19:18.12
9,-1,19:18.12
11,-1,19:18.12
9,0,19:18.4
10,0,19:18.4
11,0,19:18.4
10,1,19:18.4
11,1,19:18.4
11,-11,20:18.12
12,-11,20:18.12
13,-11,20:18.12
10,-10,20:18.12
11,-10,20:18.12
12,-10,20:18.12
13,-10,20:18.12
5,-9,20:18.12
9,-9,20:18.12
10,-9,20:18.12
11,-9,20:18.12
12,-9,20:18.12
13,-9,20:18.12
2,-8,20:18.4
3,-8,20:18.12
4,-8,20:18.12
5,-8,20:18.12
6,-8,20:18.12
9,-8,20:18.12
10,-8,20:18.12
11,-8,20:18.12
12,-8,20:18.12
13,-8,20:18.12
2,-7,20:18.4
3,-7,20:18.12
4,-7,20:18.12
5,-7,20:18.12
6,-7,20:18.12
7,-7,20:18.12
9,-7,20:18.12
10,-7,20:18.12
11,-7,20:18.12
12,-7,20:18.12
3,-6,20:18.12
4,-6,20:18.12
5,-6,20:18.12
6,-6,20:18.12
7,-6,20:18.12
5,-5,20:18.12
9,-5,20:18.12
9,-4,20:18.12
10,-4,20:18.12
8,-3,20:18.12
9,-3,20:18.12
10,-3,20:18.12
11,-3,20:18.12
9,-2,20:18.12
10,-2,20:18.12
11,-2,20:18.12
9,-1,20:18.12
10,-1,20:18.12
10,0,20:18.4
12,-10,21:18.4
11,-9,21:18.4
12,-9,21:18.4
11,-8,21:18.4
5,-7,21:18.4
