[META]
version=2.0
spawnOnBlockType=2
spawnSunlight=True
spawnDarkness=True
spawnWater=False
spawnLava=False
underFill=False
randomRotation=True
dig=True
tree=False
branch=False
needsFoundation=True
rarity=100
collisionPercentage=20
spawnElevationMin=0
spawnElevationMax=200
spawnInBiome=Custom
[DATA]
0,-3,-8:17.12
1,-3,-8:17.12
1,-2,-8:17.12
0,-4,-7:17.12
0,-3,-7:17.12
1,-3,-7:17.12
2,-3,-7:17.12
0,-2,-7:17.12
1,-4,-6:17.12
1,-3,-6:17.12
2,-3,-6:17.12
1,-2,-6:17.12
2,-1,-6:17.12
2,-4,-5:17.12
0,-3,-5:17.12
1,-3,-5:17.12
2,-3,-5:17.12
3,-3,-5:17.12
1,-2,-5:17.12
2,-2,-5:17.12
3,-2,-5:17.12
2,-1,-5:17.12
3,-1,-5:17.12
1,-4,-4:17.12
0,-3,-4:17.12
1,-3,-4:17.12
2,-3,-4:17.12
1,-2,-4:17.12
2,-2,-4:17.12
0,-4,-3:17.12
1,-4,-3:17.12
2,-4,-3:17.12
0,-3,-3:17.12
1,-3,-3:17.12
2,-3,-3:17.12
0,-2,-3:17.12
1,-2,-3:17.12
2,-2,-3:17.12
1,-1,-3:17.12
2,0,-3:17.12
1,-4,-2:17.12
0,-3,-2:17.12
2,-3,-2:17.12
0,-2,-2:17.12
1,-2,-2:17.12
2,-2,-2:17.12
1,-1,-2:17.12
2,0,-2:17.12
3,0,-2:17.12
1,-4,-1:17.12
0,-3,-1:17.12
1,-3,-1:17.12
2,-3,-1:17.12
0,-2,-1:17.12
1,-2,-1:17.12
2,-2,-1:17.12
2,0,-1:17.12
3,0,-1:17.12
0,-3,0:17.12
1,-3,0:17.12
0,-2,0:17.12
1,-2,0:17.12
2,-2,0:17.12
3,0,0:17.12
0,-3,1:17.12
1,-3,1:17.12
0,-2,1:17.12
1,-2,1:17.12
3,0,1:17.12
4,0,1:17.12
0,-3,2:17.12
1,-3,2:17.12
0,-2,2:17.12
1,-2,2:17.12
3,0,2:17.12
4,0,2:17.12
0,-3,3:17.12
1,-3,3:17.12
0,-2,3:17.12
1,-2,3:17.12
4,-1,3:18.15
3,0,3:18.15
4,0,3:18.15
3,1,3:18.15
4,1,3:18.15
0,-3,4:17.12
1,-3,4:17.12
0,-2,4:17.12
1,-2,4:17.12
3,-1,4:18.15
4,-1,4:18.15
3,0,4:18.15
4,0,4:18.15
5,0,4:18.15
2,1,4:18.15
3,1,4:18.15
4,1,4:18.15
5,1,4:18.15
1,-5,5:18.15
0,-3,5:17.12
1,-3,5:17.12
-3,-2,5:18.7
-2,-2,5:18.7
0,-2,5:17.12
1,-2,5:18.7
3,-1,5:18.7
4,-1,5:18.7
2,0,5:18.7
3,0,5:18.7
4,0,5:18.7
3,1,5:18.7
4,1,5:18.7
0,-5,6:18.15
1,-5,6:18.15
-2,-3,6:18.7
0,-3,6:17.12
1,-3,6:18.7
-3,-2,6:18.7
0,-2,6:17.12
1,-2,6:18.7
2,-2,6:18.7
-2,-1,6:18.7
1,-1,6:18.7
2,-1,6:18.7
1,0,6:18.7
2,0,6:18.7
-3,-6,7:18.7
0,-5,7:18.15
1,-5,7:18.15
0,-4,7:18.7
2,-4,7:18.7
5,-4,7:18.7
-2,-3,7:18.7
-1,-3,7:18.7
0,-3,7:17.12
1,-3,7:18.7
5,-3,7:18.7
-3,-2,7:18.7
-2,-2,7:18.7
0,-2,7:17.12
1,-2,7:18.7
2,-2,7:18.7
-2,-1,7:18.7
1,-1,7:18.7
2,-1,7:18.7
1,0,7:18.7
2,0,7:18.7
-2,2,7:18.7
-1,2,7:18.7
-3,-6,8:18.7
-2,-6,8:18.7
-3,-5,8:18.7
0,-5,8:18.7
1,-5,8:18.7
-3,-4,8:18.7
-1,-4,8:18.7
0,-4,8:18.7
1,-4,8:18.7
2,-4,8:18.7
4,-4,8:18.7
-2,-3,8:18.7
-1,-3,8:18.7
0,-3,8:17.12
1,-3,8:18.7
2,-3,8:18.7
4,-3,8:18.7
5,-3,8:18.7
-2,-2,8:18.7
-1,-2,8:17.12
0,-2,8:17.12
1,-2,8:18.7
2,-2,8:18.7
4,-2,8:18.7
-2,-1,8:18.7
-1,-1,8:18.7
0,-1,8:18.7
1,-1,8:18.7
2,-1,8:18.7
0,0,8:18.7
1,0,8:18.7
-2,1,8:18.7
0,1,8:18.7
-2,2,8:18.7
-1,2,8:18.7
0,2,8:18.7
-2,-6,9:18.7
-1,-6,9:18.7
-3,-5,9:18.7
-2,-5,9:18.7
-1,-5,9:18.7
0,-5,9:18.7
-3,-4,9:18.7
-1,-4,9:18.7
0,-4,9:18.7
1,-4,9:18.7
2,-4,9:18.7
3,-4,9:18.7
4,-4,9:18.7
-3,-3,9:18.7
-2,-3,9:18.7
-1,-3,9:18.7
0,-3,9:18.7
1,-3,9:18.7
2,-3,9:18.7
3,-3,9:18.7
4,-3,9:18.7
-2,-2,9:18.7
-1,-2,9:18.7
0,-2,9:17.12
1,-2,9:18.7
2,-2,9:18.7
3,-2,9:18.7
4,-2,9:18.7
-2,-1,9:18.7
-1,-1,9:18.7
0,-1,9:18.7
1,-1,9:18.7
2,-1,9:18.7
3,-1,9:18.7
0,0,9:18.7
1,0,9:18.7
-2,1,9:18.7
-1,1,9:18.7
0,1,9:18.7
-2,-5,10:18.7
-1,-5,10:18.7
-2,-4,10:18.7
-1,-4,10:18.7
0,-4,10:18.7
1,-4,10:18.7
2,-4,10:18.7
-2,-3,10:18.7
-1,-3,10:18.7
0,-3,10:18.7
1,-3,10:18.7
2,-3,10:18.7
3,-3,10:18.7
-2,-2,10:18.7
-1,-2,10:18.7
0,-2,10:18.7
1,-2,10:18.7
2,-2,10:18.7
3,-2,10:18.7
-1,-1,10:18.7
0,-1,10:18.7
1,-1,10:18.7
-1,0,10:18.7
0,0,10:18.7
1,-6,11:18.7
0,-5,11:18.7
1,-5,11:18.7
2,-5,11:18.7
-1,-4,11:18.7
0,-4,11:18.7
1,-4,11:18.7
0,-3,11:18.7
1,-3,11:18.7
0,-2,11:18.7
1,-2,11:18.7
0,-1,11:18.7
1,-1,11:18.7
2,-1,11:18.7
0,0,11:18.7
1,0,11:18.7
2,0,11:18.7
1,1,11:18.7
2,1,11:18.7
