[META]
version=2.0
spawnOnBlockType=2
spawnSunlight=True
spawnDarkness=True
spawnWater=False
spawnLava=False
underFill=False
randomRotation=True
dig=True
tree=False
branch=False
needsFoundation=True
rarity=100
collisionPercentage=20
spawnElevationMin=0
spawnElevationMax=200
spawnInBiome=Custom
[DATA]
-3,-3,-8:17.12
4,2,-8:17.12
-3,3,-8:17.12
-2,5,-8:17.12
3,5,-8:17.12
-2,-4,-7:17.12
-3,-3,-7:17.12
-2,-3,-7:17.12
-1,-3,-7:17.12
1,-3,-7:17.12
-4,-2,-7:17.12
-2,-2,-7:17.12
1,-2,-7:17.12
3,-2,-7:17.12
4,-1,-7:17.12
5,-1,-7:17.12
-5,0,-7:17.12
4,0,-7:17.12
-3,2,-7:17.12
4,2,-7:17.12
-4,3,-7:17.12
-3,3,-7:17.12
-2,3,-7:17.12
2,3,-7:17.12
3,3,-7:17.12
4,3,-7:17.12
-3,4,-7:17.12
-2,4,-7:17.12
-1,4,-7:17.12
3,4,-7:17.12
-2,5,-7:17.12
3,5,-7:17.12
-2,-4,-6:17.12
-1,-4,-6:17.12
-3,-3,-6:17.12
-2,-3,-6:17.12
-1,-3,-6:17.12
1,-3,-6:17.12
-4,-2,-6:17.12
-3,-2,-6:17.12
-2,-2,-6:17.12
-1,-2,-6:17.12
1,-2,-6:17.12
3,-2,-6:17.12
-3,-1,-6:17.12
-2,-1,-6:17.12
3,-1,-6:17.12
4,-1,-6:17.12
-4,1,-6:17.12
-4,2,-6:17.12
-3,2,-6:17.12
2,2,-6:17.12
3,2,-6:17.12
4,2,-6:17.12
-4,3,-6:17.12
-3,3,-6:17.12
-2,3,-6:17.12
-1,3,-6:17.12
2,3,-6:17.12
3,3,-6:17.12
4,3,-6:17.12
5,3,-6:17.12
-4,4,-6:17.12
-3,4,-6:17.12
-2,4,-6:17.12
-1,4,-6:17.12
2,4,-6:17.12
3,4,-6:17.12
4,4,-6:17.12
-3,5,-6:17.12
-2,5,-6:17.12
-1,5,-6:17.12
-2,6,-6:17.12
-2,-4,-5:17.12
-4,-3,-5:17.12
-3,-3,-5:17.12
-2,-3,-5:17.12
-1,-3,-5:17.12
-4,-2,-5:17.12
-3,-2,-5:17.12
-2,-2,-5:17.12
-1,-2,-5:17.12
1,-2,-5:17.12
-4,-1,-5:17.12
-3,-1,-5:17.12
-2,-1,-5:17.12
-1,-1,-5:17.12
3,-1,-5:17.12
4,-1,-5:17.12
-3,0,-5:17.12
-2,0,-5:17.12
-1,0,-5:17.12
3,0,-5:17.12
4,0,-5:17.12
-2,1,-5:17.12
-3,2,-5:17.12
3,2,-5:17.12
4,2,-5:17.12
5,2,-5:17.12
-4,3,-5:17.12
-3,3,-5:17.12
-2,3,-5:17.12
2,3,-5:17.12
3,3,-5:17.12
4,3,-5:17.12
5,3,-5:17.12
-3,4,-5:17.12
-2,4,-5:17.12
-1,4,-5:17.12
3,4,-5:17.12
4,4,-5:17.12
-3,5,-5:17.12
-2,5,-5:17.12
-1,5,-5:17.12
-3,6,-5:17.12
-2,6,-5:17.12
-3,-3,-4:17.12
-2,-3,-4:17.12
0,-3,-4:17.12
-4,-2,-4:17.12
-3,-2,-4:17.12
-2,-2,-4:17.12
-1,-2,-4:17.12
0,-2,-4:17.12
1,-2,-4:17.12
-4,-1,-4:17.12
-3,-1,-4:17.12
-2,-1,-4:17.12
-1,-1,-4:17.12
0,-1,-4:17.12
3,-1,-4:17.12
-4,0,-4:17.12
-3,0,-4:17.12
-2,0,-4:17.12
-1,0,-4:17.12
0,0,-4:17.12
3,0,-4:17.12
-3,1,-4:17.12
-2,1,-4:17.12
-1,1,-4:17.12
3,2,-4:17.12
4,2,-4:17.12
5,2,-4:17.12
-3,3,-4:17.12
-2,3,-4:17.12
-1,3,-4:17.12
2,3,-4:17.12
3,3,-4:17.12
4,3,-4:17.12
5,3,-4:17.12
-3,4,-4:17.12
-2,4,-4:17.12
-1,4,-4:17.12
3,4,-4:17.12
4,4,-4:17.12
-3,5,-4:17.12
-2,5,-4:17.12
-1,5,-4:17.12
-2,6,-4:17.12
-1,-3,-3:17.12
0,-3,-3:17.12
-3,-2,-3:17.12
-1,-2,-3:17.12
0,-2,-3:17.12
1,-2,-3:17.12
2,-2,-3:17.12
3,-2,-3:17.12
-4,-1,-3:17.12
-3,-1,-3:17.12
-2,-1,-3:17.12
-1,-1,-3:17.12
0,-1,-3:17.12
1,-1,-3:17.12
3,-1,-3:17.12
-3,0,-3:17.12
-2,0,-3:17.12
-1,0,-3:17.12
0,0,-3:17.12
3,0,-3:17.12
-3,1,-3:17.12
-2,1,-3:17.12
-1,1,-3:17.12
0,1,-3:17.12
-3,2,-3:17.12
-2,2,-3:17.12
-1,2,-3:17.12
2,2,-3:17.12
3,2,-3:17.12
4,2,-3:17.12
-3,3,-3:17.12
-2,3,-3:17.12
-1,3,-3:17.12
2,3,-3:17.12
3,3,-3:17.12
4,3,-3:17.12
5,3,-3:17.12
-3,4,-3:17.12
-2,4,-3:17.12
-1,4,-3:17.12
3,4,-3:17.12
4,4,-3:17.12
-2,5,-3:17.12
-1,-3,-2:17.12
0,-3,-2:17.12
-2,-2,-2:17.12
-1,-2,-2:17.12
0,-2,-2:17.12
1,-2,-2:17.12
2,-2,-2:17.12
3,-2,-2:17.12
4,-2,-2:17.12
-4,-1,-2:17.12
-3,-1,-2:17.12
-2,-1,-2:17.12
-1,-1,-2:17.12
0,-1,-2:17.12
1,-1,-2:17.12
2,-1,-2:17.12
3,-1,-2:17.12
4,-1,-2:17.12
-4,0,-2:17.12
-3,0,-2:17.12
-2,0,-2:17.12
-1,0,-2:17.12
0,0,-2:17.12
1,0,-2:17.12
2,0,-2:17.12
3,0,-2:17.12
-4,1,-2:17.12
-3,1,-2:17.12
-2,1,-2:17.12
-1,1,-2:17.12
0,1,-2:17.12
1,1,-2:17.12
2,1,-2:17.12
3,1,-2:17.12
-3,2,-2:17.12
-2,2,-2:17.12
-1,2,-2:17.12
0,2,-2:17.12
1,2,-2:17.12
2,2,-2:17.12
3,2,-2:17.12
4,2,-2:17.12
-4,3,-2:17.12
-3,3,-2:17.12
-2,3,-2:17.12
-1,3,-2:17.12
0,3,-2:17.12
1,3,-2:17.12
2,3,-2:17.12
3,3,-2:17.12
4,3,-2:17.12
5,3,-2:17.12
-4,4,-2:17.12
-3,4,-2:17.12
-2,4,-2:17.12
-1,4,-2:17.12
0,4,-2:17.12
1,4,-2:17.12
2,4,-2:17.12
3,4,-2:17.12
-3,5,-2:17.12
-2,5,-2:17.12
-1,5,-2:17.12
0,5,-2:17.12
1,5,-2:17.12
1,6,-2:17.12
-1,-3,-1:17.12
0,-3,-1:17.12
-2,-2,-1:17.12
-1,-2,-1:17.12
0,-2,-1:17.12
1,-2,-1:17.12
2,-2,-1:17.12
-4,-1,-1:17.12
-3,-1,-1:17.12
-2,-1,-1:17.12
-1,-1,-1:17.12
0,-1,-1:17.12
1,-1,-1:17.12
2,-1,-1:17.12
3,-1,-1:17.12
-4,0,-1:17.12
0,0,-1:17.12
2,0,-1:17.12
3,0,-1:17.12
-4,1,-1:17.12
-3,1,-1:17.12
-2,1,-1:17.12
-1,1,-1:17.12
0,1,-1:17.12
3,1,-1:17.12
-3,2,-1:17.12
-2,2,-1:17.12
-1,2,-1:17.12
3,2,-1:17.12
4,2,-1:17.12
-3,3,-1:17.12
-2,3,-1:17.12
2,3,-1:17.12
3,3,-1:17.12
4,3,-1:17.12
-3,4,-1:17.12
-2,4,-1:17.12
-1,4,-1:17.12
1,4,-1:17.12
2,4,-1:17.12
3,4,-1:17.12
-2,5,-1:17.12
0,5,-1:17.12
1,5,-1:17.12
-1,-3,0:17.12
-2,-2,0:17.12
-1,-2,0:17.12
0,-2,0:17.12
1,-2,0:17.12
-4,-1,0:17.12
-3,-1,0:17.12
-2,-1,0:17.12
1,-1,0:17.12
2,-1,0:17.12
-4,0,0:17.12
2,0,0:17.12
-4,1,0:17.12
-3,1,0:17.12
2,1,0:17.12
3,1,0:17.12
-3,2,0:17.12
3,2,0:17.12
-3,3,0:17.12
1,3,0:17.12
2,3,0:17.12
3,3,0:17.12
-3,4,0:17.12
-2,4,0:17.12
-1,4,0:17.12
0,4,0:17.12
1,4,0:17.12
0,5,0:17.12
-2,-2,1:17.12
-1,-2,1:17.12
0,-2,1:17.12
-3,-1,1:17.12
-2,-1,1:17.12
0,-1,1:17.12
1,-1,1:17.12
-4,0,1:17.12
2,0,1:17.12
-3,1,1:17.12
2,1,1:17.12
-3,2,1:17.12
2,2,1:17.12
3,2,1:17.12
-3,3,1:17.12
-2,3,1:17.12
0,3,1:17.12
1,3,1:17.12
2,3,1:17.12
-1,4,1:17.12
0,4,1:17.12
-2,-2,2:17.12
-1,-2,2:17.12
0,-2,2:17.12
-3,-1,2:17.12
-2,-1,2:17.12
0,-1,2:17.12
1,-1,2:17.12
-4,0,2:17.12
-3,0,2:17.12
1,0,2:17.12
2,0,2:17.12
-3,1,2:17.12
2,1,2:17.12
-3,2,2:17.12
2,2,2:17.12
-3,3,2:17.12
-2,3,2:17.12
-1,3,2:17.12
0,3,2:17.12
1,3,2:17.12
-1,4,2:17.12
-1,-2,3:17.12
-3,-1,3:17.12
-2,-1,3:17.12
0,-1,3:17.12
1,-1,3:17.12
-4,0,3:17.12
-3,0,3:17.12
1,0,3:17.12
-3,1,3:17.12
1,1,3:17.12
2,1,3:17.12
-3,2,3:17.12
1,2,3:17.12
2,2,3:17.12
-3,3,3:17.12
-2,3,3:17.12
-1,3,3:17.12
0,3,3:17.12
1,3,3:17.12
-1,-2,4:17.12
-3,-1,4:17.12
-2,-1,4:17.12
0,-1,4:17.12
1,-1,4:17.12
-3,0,4:17.12
1,0,4:17.12
-3,1,4:17.12
1,1,4:17.12
2,1,4:17.12
-3,2,4:17.12
1,2,4:17.12
2,2,4:17.12
-2,3,4:17.12
-1,3,4:17.12
0,3,4:17.12
-1,-2,5:17.12
-3,-1,5:17.12
-2,-1,5:17.12
-1,-1,5:17.12
0,-1,5:17.12
1,-1,5:17.12
-3,0,5:17.12
1,0,5:17.12
-3,1,5:17.12
1,1,5:17.12
-3,2,5:17.12
1,2,5:17.12
2,2,5:17.12
-2,3,5:17.12
-1,3,5:17.12
0,3,5:17.12
-1,-2,6:17.12
-3,-1,6:17.12
-2,-1,6:17.12
-1,-1,6:17.12
0,-1,6:17.12
1,-1,6:17.12
-3,0,6:17.12
1,0,6:17.12
-3,1,6:17.12
1,1,6:17.12
-3,2,6:17.12
1,2,6:17.12
2,2,6:17.12
-2,3,6:17.12
-1,3,6:17.12
0,3,6:17.12
-1,-2,7:17.12
-2,-1,7:17.12
-1,-1,7:17.12
0,-1,7:17.12
1,-1,7:17.12
-3,0,7:17.12
1,0,7:17.12
-3,1,7:17.12
1,1,7:17.12
-3,2,7:17.12
1,2,7:17.12
2,2,7:17.12
-2,3,7:17.12
-1,3,7:17.12
0,3,7:17.12
-2,-1,8:17.12
-1,-1,8:17.12
0,-1,8:17.12
1,-1,8:17.12
-3,0,8:17.12
1,0,8:17.12
-3,1,8:17.12
1,1,8:17.12
-3,2,8:17.12
-2,2,8:17.12
1,2,8:17.12
2,2,8:17.12
-2,3,8:17.12
-1,3,8:17.12
0,3,8:17.12
-2,-1,9:17.12
-1,-1,9:17.12
0,-1,9:17.12
1,-1,9:17.12
-3,0,9:17.12
1,0,9:17.12
-3,1,9:17.12
1,1,9:17.12
-3,2,9:17.12
-2,2,9:17.12
1,2,9:17.12
2,2,9:17.12
-2,3,9:17.12
-1,3,9:17.12
0,3,9:17.12
-2,-1,10:17.12
-1,-1,10:17.12
0,-1,10:17.12
1,-1,10:17.12
-3,0,10:17.12
-2,0,10:17.12
1,0,10:17.12
-3,1,10:17.12
1,1,10:17.12
-3,2,10:17.12
-2,2,10:17.12
1,2,10:17.12
2,2,10:17.12
-2,3,10:17.12
-1,3,10:17.12
0,3,10:17.12
-2,-1,11:17.12
-1,-1,11:17.12
0,-1,11:17.12
1,-1,11:17.12
-3,0,11:17.12
-2,0,11:17.12
1,0,11:17.12
-3,1,11:17.12
1,1,11:17.12
-2,2,11:17.12
1,2,11:17.12
2,2,11:17.12
-2,3,11:17.12
-1,3,11:17.12
0,3,11:17.12
-2,-1,12:17.12
-1,-1,12:17.12
0,-1,12:17.12
1,-1,12:17.12
-3,0,12:17.12
-2,0,12:17.12
1,0,12:17.12
-3,1,12:17.12
-2,1,12:17.12
1,1,12:17.12
2,1,12:17.12
-2,2,12:17.12
1,2,12:17.12
2,2,12:17.12
-1,3,12:17.12
0,3,12:17.12
-1,-1,13:17.12
0,-1,13:17.12
1,-1,13:17.12
-3,0,13:17.12
-2,0,13:17.12
1,0,13:17.12
-2,1,13:17.12
1,1,13:17.12
2,1,13:17.12
-2,2,13:17.12
1,2,13:17.12
2,2,13:17.12
-1,3,13:17.12
0,3,13:17.12
-1,-1,14:17.12
0,-1,14:17.12
1,-1,14:17.12
-2,0,14:17.12
1,0,14:17.12
-2,1,14:17.12
1,1,14:17.12
-2,2,14:17.12
1,2,14:17.12
2,2,14:17.12
-1,3,14:17.12
0,3,14:17.12
-1,-1,15:17.12
0,-1,15:17.12
1,-1,15:17.12
-2,0,15:17.12
1,0,15:17.12
-2,1,15:17.12
1,1,15:17.12
-2,2,15:17.12
1,2,15:17.12
-1,3,15:17.12
0,3,15:17.12
-1,-1,16:17.12
0,-1,16:17.12
1,-1,16:17.12
-2,0,16:17.12
1,0,16:17.12
-2,1,16:17.12
1,1,16:17.12
-2,2,16:17.12
1,2,16:17.12
-1,3,16:17.12
0,3,16:17.12
-5,-6,17:18.6
-5,-5,17:18.14
-4,-5,17:18.14
-1,-5,17:18.14
-4,-4,17:18.14
-1,-4,17:18.14
5,-4,17:18.14
-4,-3,17:18.14
-3,-3,17:18.14
-1,-3,17:18.14
3,-3,17:18.14
4,-3,17:18.14
5,-3,17:18.14
-3,-2,17:18.14
3,-2,17:18.14
4,-2,17:18.14
5,-2,17:18.14
-1,-1,17:17.12
0,-1,17:17.12
1,-1,17:18.14
2,-1,17:18.14
3,-1,17:18.14
-2,0,17:17.12
-1,0,17:18.14
0,0,17:18.14
1,0,17:17.12
4,0,17:18.14
-5,1,17:18.14
-4,1,17:18.14
-3,1,17:18.14
-2,1,17:18.14
-1,1,17:18.14
0,1,17:18.14
1,1,17:17.12
-6,2,17:18.14
-2,2,17:17.12
-1,2,17:18.14
1,2,17:17.12
-4,3,17:18.14
-3,3,17:18.14
-2,3,17:18.14
-1,3,17:18.14
0,3,17:17.12
1,3,17:18.14
-5,4,17:18.14
-4,4,17:18.14
-1,4,17:18.14
1,4,17:18.14
2,4,17:18.14
-7,5,17:18.6
-6,5,17:18.14
0,5,17:18.14
2,5,17:18.14
0,6,17:18.14
3,6,17:18.14
3,7,17:18.14
-1,-7,18:18.6
-1,-6,18:18.6
-5,-5,18:18.14
-1,-5,18:18.14
0,-5,18:18.14
5,-5,18:18.14
-5,-4,18:18.14
-4,-4,18:18.14
-1,-4,18:18.14
0,-4,18:18.14
3,-4,18:18.14
4,-4,18:18.14
5,-4,18:18.14
6,-4,18:18.6
-4,-3,18:18.14
-1,-3,18:18.14
0,-3,18:18.14
2,-3,18:18.14
3,-3,18:18.14
4,-3,18:18.14
5,-3,18:18.14
-4,-2,18:18.14
-3,-2,18:18.14
0,-2,18:18.14
1,-2,18:18.14
2,-2,18:18.14
3,-2,18:18.14
-3,-1,18:18.14
-2,-1,18:18.14
-1,-1,18:17.12
0,-1,18:18.14
1,-1,18:18.14
-4,0,18:18.14
-3,0,18:18.14
-2,0,18:18.14
-1,0,18:18.14
0,0,18:18.14
1,0,18:17.12
3,0,18:18.14
4,0,18:18.14
5,0,18:18.14
6,0,18:18.14
-7,1,18:18.6
-6,1,18:18.14
-5,1,18:18.14
-4,1,18:18.14
-3,1,18:18.14
-2,1,18:18.14
0,1,18:18.14
1,1,18:18.14
2,1,18:18.14
3,1,18:18.14
4,1,18:18.14
-7,2,18:18.6
-2,2,18:18.14
-1,2,18:18.14
0,2,18:18.14
1,2,18:18.14
-3,3,18:18.14
-2,3,18:18.14
-1,3,18:18.14
0,3,18:17.12
1,3,18:18.14
2,3,18:18.14
-4,4,18:18.14
-3,4,18:18.14
-2,4,18:18.14
-1,4,18:18.14
2,4,18:18.14
-6,5,18:18.14
-5,5,18:18.14
-4,5,18:18.14
-1,5,18:18.14
2,5,18:18.14
3,5,18:18.14
-7,6,18:18.6
-6,6,18:18.14
-1,6,18:18.14
3,6,18:18.14
-1,7,18:18.14
0,7,18:18.14
3,7,18:18.14
4,7,18:18.14
0,8,18:18.6
-2,-10,19:18.6
-2,-9,19:18.6
-1,-9,19:18.6
-1,-8,19:18.6
0,-8,19:18.6
-1,-7,19:18.6
0,-7,19:18.6
0,-6,19:18.6
6,-6,19:18.6
-6,-5,19:18.6
0,-5,19:18.14
4,-5,19:18.14
5,-5,19:18.14
6,-5,19:18.6
-6,-4,19:18.14
-5,-4,19:18.14
0,-4,19:18.14
1,-4,19:18.14
2,-4,19:18.14
3,-4,19:18.14
4,-4,19:18.14
5,-4,19:18.14
-5,-3,19:18.14
0,-3,19:18.14
1,-3,19:18.14
2,-3,19:18.14
3,-3,19:18.14
-5,-2,19:18.14
-4,-2,19:18.14
-1,-2,19:18.14
0,-2,19:18.14
1,-2,19:18.14
-4,-1,19:18.14
-3,-1,19:18.14
-2,-1,19:18.14
-1,-1,19:17.12
0,-1,19:17.12
1,-1,19:18.14
-6,0,19:18.14
-5,0,19:18.14
-4,0,19:18.14
-3,0,19:18.14
-2,0,19:17.12
1,0,19:18.14
2,0,19:18.14
5,0,19:18.14
6,0,19:18.6
7,0,19:18.6
-9,1,19:18.6
-8,1,19:18.6
-7,1,19:18.6
-6,1,19:18.14
-3,1,19:18.14
-2,1,19:17.12
1,1,19:17.12
2,1,19:18.14
3,1,19:18.14
4,1,19:18.14
5,1,19:18.14
6,1,19:18.6
-11,2,19:18.6
-10,2,19:18.6
-9,2,19:18.6
-3,2,19:18.14
-2,2,19:17.12
-1,2,19:17.12
0,2,19:17.12
1,2,19:18.14
2,2,19:18.14
3,2,19:18.14
-3,3,19:18.14
-2,3,19:18.14
-1,3,19:18.14
0,3,19:18.14
1,3,19:18.14
2,3,19:18.14
3,3,19:18.14
-3,4,19:18.14
-2,4,19:18.14
-1,4,19:18.14
3,4,19:18.14
-4,5,19:18.14
-3,5,19:18.14
-2,5,19:18.14
3,5,19:18.14
4,5,19:18.14
-6,6,19:18.14
-5,6,19:18.14
-4,6,19:18.14
-2,6,19:18.14
4,6,19:18.14
-9,7,19:18.6
-8,7,19:18.6
-7,7,19:18.6
-6,7,19:18.6
-2,7,19:18.14
-1,7,19:18.14
4,7,19:18.14
-2,8,19:18.6
-1,8,19:18.6
-1,9,19:18.6
-1,-10,20:18.6
-1,-9,20:18.6
0,-9,20:18.6
0,-8,20:18.6
-7,-7,20:18.6
0,-7,20:18.6
1,-7,20:18.6
-7,-6,20:18.6
0,-6,20:18.6
1,-6,20:18.6
4,-6,20:18.6
5,-6,20:18.6
6,-6,20:18.6
-7,-5,20:18.6
1,-5,20:18.14
2,-5,20:18.14
3,-5,20:18.14
4,-5,20:18.14
5,-5,20:18.14
-7,-4,20:18.6
-6,-4,20:18.14
1,-4,20:18.14
2,-4,20:18.14
3,-4,20:18.14
-6,-3,20:18.14
-5,-3,20:18.14
-1,-3,20:18.14
0,-3,20:18.14
1,-3,20:18.14
2,-3,20:18.14
-6,-2,20:18.14
-5,-2,20:18.14
-3,-2,20:18.14
-2,-2,20:18.14
-1,-2,20:18.14
1,-2,20:18.14
2,-2,20:18.14
-5,-1,20:18.14
-4,-1,20:18.14
-3,-1,20:18.14
-1,-1,20:17.12
0,-1,20:17.12
2,-1,20:18.14
-9,0,20:18.6
-8,0,20:18.6
-7,0,20:18.6
-6,0,20:18.14
-5,0,20:18.14
-4,0,20:18.14
-2,0,20:17.12
1,0,20:17.12
2,0,20:18.14
7,0,20:18.6
8,0,20:18.6
-11,1,20:18.6
-10,1,20:18.6
-9,1,20:18.6
-8,1,20:18.6
-4,1,20:18.14
-2,1,20:17.12
1,1,20:17.12
2,1,20:18.14
3,1,20:18.14
4,1,20:18.14
5,1,20:18.14
6,1,20:18.6
7,1,20:18.6
8,1,20:18.6
-11,2,20:18.6
-10,2,20:18.6
-4,2,20:18.14
-2,2,20:17.12
-1,2,20:17.12
0,2,20:17.12
1,2,20:17.12
2,2,20:18.14
3,2,20:18.14
4,2,20:18.14
-12,3,20:18.6
-11,3,20:18.6
-4,3,20:18.14
-3,3,20:18.14
-1,3,20:17.12
0,3,20:17.12
1,3,20:18.14
2,3,20:18.14
3,3,20:18.14
-4,4,20:18.14
-3,4,20:18.14
-1,4,20:18.14
0,4,20:18.14
3,4,20:18.14
-3,5,20:18.14
-2,5,20:18.14
-1,5,20:18.14
4,5,20:18.14
-5,6,20:18.14
-4,6,20:18.14
-3,6,20:18.14
-2,6,20:18.14
4,6,20:18.14
5,6,20:18.14
-6,7,20:18.6
-5,7,20:18.14
-4,7,20:18.14
-3,7,20:18.14
-2,7,20:18.14
5,7,20:18.6
-8,8,20:18.6
-7,8,20:18.6
-6,8,20:18.6
-3,8,20:18.6
-2,8,20:18.6
5,8,20:18.6
-2,9,20:18.6
-2,10,20:18.6
-1,10,20:18.6
-1,-11,21:18.6
-1,-10,21:18.6
0,-10,21:18.6
0,-9,21:18.6
1,-9,21:18.6
1,-8,21:18.6
1,-7,21:18.6
4,-7,21:18.6
5,-7,21:18.6
7,-7,21:18.6
-8,-6,21:18.6
1,-6,21:18.6
2,-6,21:18.6
3,-6,21:18.6
4,-6,21:18.6
-8,-5,21:18.6
-7,-5,21:18.6
1,-5,21:18.14
2,-5,21:18.14
3,-5,21:18.14
-8,-4,21:18.6
-7,-4,21:18.6
-1,-4,21:18.14
0,-4,21:18.14
1,-4,21:18.14
2,-4,21:18.14
-7,-3,21:18.6
-6,-3,21:18.14
-3,-3,21:18.14
-2,-3,21:18.14
-1,-3,21:18.14
2,-3,21:18.14
-6,-2,21:18.14
-5,-2,21:18.14
-4,-2,21:18.14
-3,-2,21:18.14
2,-2,21:18.14
3,-2,21:18.14
-8,-1,21:18.6
-7,-1,21:18.6
-6,-1,21:18.14
-5,-1,21:18.14
-1,-1,21:17.12
0,-1,21:17.12
2,-1,21:18.14
3,-1,21:18.14
-10,0,21:18.6
-9,0,21:18.6
-8,0,21:18.6
-7,0,21:18.6
-6,0,21:18.14
-5,0,21:18.14
-2,0,21:17.12
1,0,21:17.12
3,0,21:18.14
8,0,21:18.6
-12,1,21:18.6
-11,1,21:18.6
-10,1,21:18.6
-5,1,21:18.14
-2,1,21:17.12
1,1,21:17.12
3,1,21:18.14
6,1,21:18.6
7,1,21:18.6
8,1,21:18.6
9,1,21:18.6
-12,2,21:18.6
-11,2,21:18.6
-5,2,21:18.14
-4,2,21:18.14
-2,2,21:17.12
-1,2,21:17.12
0,2,21:17.12
1,2,21:17.12
3,2,21:18.14
4,2,21:18.14
5,2,21:18.14
6,2,21:18.6
7,2,21:18.6
-5,3,21:18.14
-4,3,21:18.14
-1,3,21:17.12
0,3,21:17.12
2,3,21:18.14
3,3,21:18.14
4,3,21:18.14
-5,4,21:18.14
-4,4,21:18.14
0,4,21:18.14
1,4,21:18.14
2,4,21:18.14
5,4,21:18.14
-4,5,21:18.14
-1,5,21:18.14
0,5,21:18.14
4,5,21:18.14
5,5,21:18.14
-4,6,21:18.14
-3,6,21:18.14
-2,6,21:18.14
-1,6,21:18.14
5,6,21:18.14
6,6,21:18.6
-5,7,21:18.14
-4,7,21:18.14
-3,7,21:18.14
5,7,21:18.6
6,7,21:18.6
-11,8,21:18.6
-6,8,21:18.6
-5,8,21:18.6
-4,8,21:18.6
-3,8,21:18.6
5,8,21:18.6
6,8,21:18.6
-7,9,21:18.6
-6,9,21:18.6
-3,9,21:18.6
-3,10,21:18.6
-2,10,21:18.6
-1,11,21:18.6
0,11,21:18.6
-1,-12,22:18.6
0,-11,22:18.6
0,-10,22:18.6
1,-10,22:18.6
-8,-9,22:18.6
1,-9,22:18.6
2,-9,22:18.6
-8,-8,22:18.6
2,-8,22:18.6
4,-8,22:18.6
5,-8,22:18.6
6,-8,22:18.6
7,-8,22:18.6
2,-7,22:18.6
3,-7,22:18.6
4,-7,22:18.6
5,-7,22:18.6
7,-7,22:18.6
-9,-6,22:18.6
1,-6,22:18.6
2,-6,22:18.6
3,-6,22:18.6
-9,-5,22:18.6
-8,-5,22:18.6
-1,-5,22:18.14
0,-5,22:18.14
1,-5,22:18.14
2,-5,22:18.14
3,-5,22:18.14
-8,-4,22:18.6
-3,-4,22:18.14
-2,-4,22:18.14
-1,-4,22:18.14
3,-4,22:18.14
-8,-3,22:18.6
-7,-3,22:18.6
-5,-3,22:18.14
-4,-3,22:18.14
-3,-3,22:18.14
3,-3,22:18.14
-7,-2,22:18.6
-6,-2,22:18.14
-5,-2,22:18.14
3,-2,22:18.14
-10,-1,22:18.6
-9,-1,22:18.6
-8,-1,22:18.6
-7,-1,22:18.6
-6,-1,22:18.14
-1,-1,22:17.12
0,-1,22:17.12
3,-1,22:18.14
4,-1,22:18.14
-12,0,22:18.6
-10,0,22:18.6
-6,0,22:18.14
-2,0,22:17.12
1,0,22:17.12
3,0,22:18.14
4,0,22:18.14
9,0,22:18.6
-12,1,22:18.6
-11,1,22:18.6
-6,1,22:18.14
-2,1,22:17.12
1,1,22:17.12
4,1,22:18.14
7,1,22:18.6
8,1,22:18.6
9,1,22:18.6
-12,2,22:18.6
-6,2,22:18.14
-5,2,22:18.14
-2,2,22:17.12
-1,2,22:17.12
0,2,22:17.12
1,2,22:17.12
4,2,22:18.14
5,2,22:18.14
6,2,22:18.6
7,2,22:18.6
8,2,22:18.6
9,2,22:18.6
-6,3,22:18.14
-5,3,22:18.14
-1,3,22:17.12
0,3,22:17.12
3,3,22:18.14
4,3,22:18.14
5,3,22:18.14
6,3,22:18.6
-6,4,22:18.14
-5,4,22:18.14
2,4,22:18.14
3,4,22:18.14
5,4,22:18.14
6,4,22:18.6
-5,5,22:18.14
0,5,22:18.14
1,5,22:18.14
2,5,22:18.14
5,5,22:18.14
6,5,22:18.6
-5,6,22:18.14
-4,6,22:18.14
-2,6,22:18.14
-1,6,22:18.14
0,6,22:18.14
6,6,22:18.6
7,6,22:18.6
-5,7,22:18.14
-4,7,22:18.14
-3,7,22:18.14
-2,7,22:18.14
6,7,22:18.6
-5,8,22:18.6
-4,8,22:18.6
-3,8,22:18.6
6,8,22:18.6
-10,9,22:18.6
-9,9,22:18.6
-8,9,22:18.6
-7,9,22:18.6
-6,9,22:18.6
-5,9,22:18.6
-4,9,22:18.6
-4,10,22:18.6
-3,10,22:18.6
-3,11,22:18.6
-2,11,22:18.6
-2,-14,23:18.6
-1,-13,23:18.6
-1,-12,23:18.6
0,-12,23:18.6
1,-11,23:18.6
1,-10,23:18.6
2,-10,23:18.6
-9,-9,23:18.6
2,-9,23:18.6
3,-9,23:18.6
4,-9,23:18.6
5,-9,23:18.6
6,-9,23:18.6
8,-9,23:18.6
-9,-8,23:18.6
2,-8,23:18.6
3,-8,23:18.6
4,-8,23:18.6
5,-8,23:18.6
6,-8,23:18.6
7,-8,23:18.6
8,-8,23:18.6
-9,-7,23:18.6
1,-7,23:18.6
2,-7,23:18.6
3,-7,23:18.6
-9,-6,23:18.6
-1,-6,23:18.6
0,-6,23:18.6
1,-6,23:18.6
3,-6,23:18.6
-9,-5,23:18.6
-3,-5,23:18.14
-2,-5,23:18.14
-1,-5,23:18.14
0,-5,23:18.14
3,-5,23:18.14
4,-5,23:18.14
-9,-4,23:18.6
-5,-4,23:18.14
-4,-4,23:18.14
-3,-4,23:18.14
0,-4,23:18.14
3,-4,23:18.14
4,-4,23:18.14
-9,-3,23:18.6
-8,-3,23:18.6
-7,-3,23:18.6
-6,-3,23:18.14
-5,-3,23:18.14
0,-3,23:18.14
4,-3,23:18.14
-9,-2,23:18.6
-8,-2,23:18.6
-7,-2,23:18.6
-4,-2,23:18.14
4,-2,23:18.14
-11,-1,23:18.6
-10,-1,23:18.6
-9,-1,23:18.6
-8,-1,23:18.6
-7,-1,23:18.6
-2,-1,23:18.14
-1,-1,23:17.12
0,-1,23:17.12
4,-1,23:18.14
5,-1,23:18.14
-12,0,23:18.6
-7,0,23:18.6
-6,0,23:18.14
-5,0,23:18.14
-4,0,23:18.14
-2,0,23:17.12
-1,0,23:18.14
0,0,23:18.14
1,0,23:17.12
4,0,23:18.14
5,0,23:18.14
10,0,23:18.6
-12,1,23:18.6
-7,1,23:18.6
-2,1,23:18.14
-1,1,23:18.14
0,1,23:18.14
1,1,23:17.12
4,1,23:18.14
5,1,23:18.14
9,1,23:18.6
10,1,23:18.6
-7,2,23:18.6
-6,2,23:18.14
-2,2,23:17.12
-1,2,23:17.12
0,2,23:17.12
1,2,23:17.12
3,2,23:18.14
4,2,23:18.14
5,2,23:18.14
6,2,23:18.6
7,2,23:18.6
8,2,23:18.6
9,2,23:18.6
-7,3,23:18.6
-6,3,23:18.14
-1,3,23:17.12
0,3,23:17.12
5,3,23:18.14
6,3,23:18.6
7,3,23:18.6
8,3,23:18.6
-6,4,23:18.14
-1,4,23:18.14
3,4,23:18.14
5,4,23:18.14
6,4,23:18.6
-6,5,23:18.14
-2,5,23:18.14
1,5,23:18.14
2,5,23:18.14
3,5,23:18.14
6,5,23:18.6
7,5,23:18.6
-6,6,23:18.14
-5,6,23:18.14
-2,6,23:18.14
0,6,23:18.14
1,6,23:18.14
6,6,23:18.6
7,6,23:18.6
-6,7,23:18.6
-5,7,23:18.14
-3,7,23:18.14
-2,7,23:18.14
-1,7,23:18.14
0,7,23:18.14
6,7,23:18.6
7,7,23:18.6
-5,8,23:18.6
-3,8,23:18.6
-2,8,23:18.6
7,8,23:18.6
-5,9,23:18.6
-4,9,23:18.6
-3,9,23:18.6
6,9,23:18.6
7,9,23:18.6
-7,10,23:18.6
-6,10,23:18.6
-5,10,23:18.6
-4,10,23:18.6
6,10,23:18.6
7,10,23:18.6
-5,11,23:18.6
-4,11,23:18.6
-3,11,23:18.6
-2,12,23:18.6
-1,-13,24:18.6
0,-13,24:18.6
0,-12,24:18.6
1,-12,24:18.6
2,-11,24:18.6
2,-10,24:18.6
3,-10,24:18.6
3,-9,24:18.6
4,-9,24:18.6
5,-9,24:18.6
6,-9,24:18.6
7,-9,24:18.6
8,-9,24:18.6
9,-9,24:18.6
1,-8,24:18.6
2,-8,24:18.6
3,-8,24:18.6
4,-8,24:18.6
-10,-7,24:18.6
-9,-7,24:18.6
-1,-7,24:18.6
0,-7,24:18.6
1,-7,24:18.6
3,-7,24:18.6
4,-7,24:18.6
-10,-6,24:18.6
-9,-6,24:18.6
-2,-6,24:18.6
-1,-6,24:18.6
0,-6,24:18.6
4,-6,24:18.6
-10,-5,24:18.6
-5,-5,24:18.14
-4,-5,24:18.14
-3,-5,24:18.14
-1,-5,24:18.14
0,-5,24:18.14
4,-5,24:18.14
-10,-4,24:18.6
-9,-4,24:18.6
-7,-4,24:18.6
-6,-4,24:18.14
-5,-4,24:18.14
-1,-4,24:18.14
0,-4,24:18.14
3,-4,24:18.14
4,-4,24:18.14
5,-4,24:18.14
-9,-3,24:18.6
-8,-3,24:18.6
-7,-3,24:18.6
-6,-3,24:18.14
-5,-3,24:18.14
-4,-3,24:18.14
-1,-3,24:18.14
2,-3,24:18.14
3,-3,24:18.14
4,-3,24:18.14
5,-3,24:18.14
-11,-2,24:18.6
-10,-2,24:18.6
-9,-2,24:18.6
-8,-2,24:18.6
-4,-2,24:18.14
-3,-2,24:18.14
-2,-2,24:18.14
-1,-2,24:18.14
2,-2,24:18.14
5,-2,24:18.14
-12,-1,24:18.6
-11,-1,24:18.6
-9,-1,24:18.6
-8,-1,24:18.6
-2,-1,24:18.14
-1,-1,24:18.14
0,-1,24:17.12
1,-1,24:18.14
5,-1,24:18.14
6,-1,24:18.6
-12,0,24:18.6
-8,0,24:18.6
-7,0,24:18.6
-6,0,24:18.14
-5,0,24:18.14
-2,0,24:18.14
-1,0,24:18.14
0,0,24:18.14
1,0,24:18.14
5,0,24:18.14
6,0,24:18.6
-13,1,24:18.6
-8,1,24:18.6
-5,1,24:18.14
-4,1,24:18.14
-3,1,24:18.14
-2,1,24:18.14
0,1,24:18.14
1,1,24:17.12
2,1,24:18.14
3,1,24:18.14
4,1,24:18.14
5,1,24:18.14
6,1,24:18.6
9,1,24:18.6
10,1,24:18.6
11,1,24:18.6
-8,2,24:18.6
-7,2,24:18.6
-3,2,24:18.14
-2,2,24:17.12
-1,2,24:18.14
0,2,24:18.14
1,2,24:17.12
4,2,24:18.14
5,2,24:18.14
6,2,24:18.6
7,2,24:18.6
8,2,24:18.6
9,2,24:18.6
10,2,24:18.6
-7,3,24:18.6
-4,3,24:18.14
-3,3,24:18.14
-1,3,24:18.14
0,3,24:18.14
1,3,24:18.14
2,3,24:18.14
6,3,24:18.6
7,3,24:18.6
8,3,24:18.6
9,3,24:18.6
-7,4,24:18.6
-4,4,24:18.14
-1,4,24:18.14
2,4,24:18.14
3,4,24:18.14
5,4,24:18.14
6,4,24:18.6
7,4,24:18.6
-7,5,24:18.6
-5,5,24:18.14
-4,5,24:18.14
-1,5,24:18.14
3,5,24:18.14
4,5,24:18.14
5,5,24:18.14
6,5,24:18.6
7,5,24:18.6
-7,6,24:18.6
-6,6,24:18.14
-2,6,24:18.14
-1,6,24:18.14
1,6,24:18.14
3,6,24:18.14
7,6,24:18.6
8,6,24:18.6
-7,7,24:18.6
-6,7,24:18.6
-2,7,24:18.14
0,7,24:18.14
1,7,24:18.14
7,7,24:18.6
8,7,24:18.6
-6,8,24:18.6
-2,8,24:18.6
-1,8,24:18.6
0,8,24:18.6
7,8,24:18.6
-6,9,24:18.6
-5,9,24:18.6
-4,9,24:18.6
-3,9,24:18.6
-2,9,24:18.6
7,9,24:18.6
-6,10,24:18.6
-5,10,24:18.6
-4,10,24:18.6
7,10,24:18.6
-7,11,24:18.6
-6,11,24:18.6
-5,11,24:18.6
-4,11,24:18.6
7,11,24:18.6
-4,12,24:18.6
-3,12,24:18.6
-2,13,24:18.6
7,-10,25:18.6
8,-10,25:18.6
4,-9,25:18.6
-10,-8,25:18.6
0,-8,25:18.6
-3,-7,25:18.6
-2,-7,25:18.6
-1,-7,25:18.6
0,-7,25:18.6
-3,-6,25:18.6
-1,-6,25:18.6
0,-6,25:18.6
5,-6,25:18.6
-11,-5,25:18.6
-10,-5,25:18.6
-7,-5,25:18.6
-6,-5,25:18.6
-5,-5,25:18.14
-1,-5,25:18.14
4,-5,25:18.14
5,-5,25:18.6
-11,-4,25:18.6
-10,-4,25:18.6
-8,-4,25:18.6
-7,-4,25:18.6
-6,-4,25:18.14
-5,-4,25:18.14
-4,-4,25:18.14
-2,-4,25:18.14
-1,-4,25:18.14
3,-4,25:18.14
4,-4,25:18.14
5,-4,25:18.14
-11,-3,25:18.6
-10,-3,25:18.6
-9,-3,25:18.6
-8,-3,25:18.6
-4,-3,25:18.14
-3,-3,25:18.14
-2,-3,25:18.14
-1,-3,25:18.14
3,-3,25:18.14
5,-3,25:18.14
-12,-2,25:18.6
-11,-2,25:18.6
-10,-2,25:18.6
-9,-2,25:18.6
-3,-2,25:18.14
-2,-2,25:18.14
-1,-2,25:18.14
2,-2,25:18.14
3,-2,25:18.14
-13,-1,25:18.6
-12,-1,25:18.6
-11,-1,25:18.6
-9,-1,25:18.6
-3,-1,25:18.14
-2,-1,25:18.14
-1,-1,25:17.12
0,-1,25:18.14
1,-1,25:18.14
2,-1,25:18.14
6,-1,25:18.6
-14,0,25:18.6
-13,0,25:18.6
-9,0,25:18.6
-8,0,25:18.6
-7,0,25:18.6
-3,0,25:18.14
-2,0,25:17.12
0,0,25:17.12
1,0,25:18.14
2,0,25:18.14
3,0,25:18.14
6,0,25:18.6
7,0,25:18.6
-15,1,25:18.6
-14,1,25:18.6
-9,1,25:18.6
-8,1,25:18.6
-7,1,25:18.6
-6,1,25:18.14
-5,1,25:18.14
-4,1,25:18.14
-3,1,25:18.14
-2,1,25:17.12
1,1,25:18.14
3,1,25:18.14
4,1,25:18.14
5,1,25:18.14
6,1,25:18.6
7,1,25:18.6
10,1,25:18.6
11,1,25:18.6
-15,2,25:18.6
-9,2,25:18.6
-8,2,25:18.6
-4,2,25:18.14
-3,2,25:18.14
-2,2,25:18.14
-1,2,25:17.12
0,2,25:17.12
1,2,25:18.14
6,2,25:18.6
7,2,25:18.6
9,2,25:18.6
10,2,25:18.6
-9,3,25:18.6
-8,3,25:18.6
-4,3,25:18.14
-1,3,25:18.14
0,3,25:18.14
6,3,25:18.6
7,3,25:18.6
8,3,25:18.6
9,3,25:18.6
10,3,25:18.6
-5,4,25:18.14
-4,4,25:18.14
-1,4,25:18.14
0,4,25:18.14
1,4,25:18.14
2,4,25:18.14
6,4,25:18.6
7,4,25:18.6
8,4,25:18.6
9,4,25:18.6
-5,5,25:18.14
-1,5,25:18.14
0,5,25:18.14
2,5,25:18.14
3,5,25:18.14
4,5,25:18.14
5,5,25:18.14
6,5,25:18.6
7,5,25:18.6
8,5,25:18.6
-6,6,25:18.14
-1,6,25:18.14
3,6,25:18.14
4,6,25:18.14
5,6,25:18.14
8,6,25:18.6
-7,7,25:18.6
-2,7,25:18.14
-1,7,25:18.14
3,7,25:18.14
6,7,25:18.6
8,7,25:18.6
-2,8,25:18.6
-1,8,25:18.6
0,8,25:18.6
1,8,25:18.6
7,8,25:18.6
8,8,25:18.6
-2,9,25:18.6
-1,9,25:18.6
0,9,25:18.6
7,9,25:18.6
8,9,25:18.6
-9,11,25:18.6
-6,11,25:18.6
-1,-9,26:18.6
0,-9,26:18.6
-11,-8,26:18.6
-1,-8,26:18.6
-11,-7,26:18.6
-1,-7,26:18.6
-11,-6,26:18.6
-9,-6,26:18.6
-8,-6,26:18.6
-7,-6,26:18.6
-6,-6,26:18.6
-2,-6,26:18.6
-1,-6,26:18.6
5,-6,26:18.6
-11,-5,26:18.6
-7,-5,26:18.6
-6,-5,26:18.6
-5,-5,26:18.14
-2,-5,26:18.14
5,-5,26:18.6
-11,-4,26:18.6
-10,-4,26:18.6
-5,-4,26:18.14
-4,-4,26:18.14
-3,-4,26:18.14
-2,-4,26:18.14
4,-4,26:18.14
-11,-3,26:18.6
-10,-3,26:18.6
-3,-3,26:18.14
-2,-3,26:18.14
-1,-3,26:18.14
3,-3,26:18.14
4,-3,26:18.14
-12,-2,26:18.6
-11,-2,26:18.6
-10,-2,26:18.6
-3,-2,26:18.14
-2,-2,26:18.14
-1,-2,26:18.14
0,-2,26:18.14
3,-2,26:18.14
-13,-1,26:18.6
-3,-1,26:18.14
-1,-1,26:17.12
0,-1,26:18.14
1,-1,26:18.14
2,-1,26:18.14
3,-1,26:18.14
6,-1,26:18.6
7,-1,26:18.6
-14,0,26:18.6
-10,0,26:18.6
-9,0,26:18.6
-8,0,26:18.6
-4,0,26:18.14
-3,0,26:18.14
-2,0,26:17.12
0,0,26:17.12
1,0,26:17.12
2,0,26:18.14
3,0,26:18.14
4,0,26:18.14
5,0,26:18.14
6,0,26:18.6
7,0,26:18.6
12,0,26:18.6
-15,1,26:18.6
-14,1,26:18.6
-9,1,26:18.6
-8,1,26:18.6
-7,1,26:18.6
-6,1,26:18.14
-5,1,26:18.14
-4,1,26:18.14
-2,1,26:17.12
1,1,26:17.12
2,1,26:18.14
5,1,26:18.14
6,1,26:18.6
7,1,26:18.6
8,1,26:18.6
11,1,26:18.6
12,1,26:18.6
-9,2,26:18.6
-5,2,26:18.14
-4,2,26:18.14
-3,2,26:18.14
-2,2,26:17.12
-1,2,26:17.12
0,2,26:17.12
1,2,26:18.14
7,2,26:18.6
8,2,26:18.6
10,2,26:18.6
11,2,26:18.6
-5,3,26:18.14
-3,3,26:18.14
-2,3,26:18.14
-1,3,26:18.14
0,3,26:18.14
1,3,26:18.14
7,3,26:18.6
8,3,26:18.6
9,3,26:18.6
10,3,26:18.6
-6,4,26:18.14
-5,4,26:18.14
-1,4,26:18.14
0,4,26:18.14
1,4,26:18.14
7,4,26:18.6
8,4,26:18.6
9,4,26:18.6
10,4,26:18.6
-6,5,26:18.14
0,5,26:18.14
1,5,26:18.14
2,5,26:18.14
3,5,26:18.14
6,5,26:18.6
7,5,26:18.6
8,5,26:18.6
9,5,26:18.6
-7,6,26:18.6
-6,6,26:18.14
-1,6,26:18.14
0,6,26:18.14
3,6,26:18.14
4,6,26:18.14
5,6,26:18.14
6,6,26:18.6
8,6,26:18.6
9,6,26:18.6
-7,7,26:18.6
-1,7,26:18.14
4,7,26:18.14
5,7,26:18.6
6,7,26:18.6
7,7,26:18.6
8,7,26:18.6
9,7,26:18.6
-7,8,26:18.6
-1,8,26:18.6
-2,9,26:18.6
-1,9,26:18.6
0,9,26:18.6
8,9,26:18.6
-2,10,26:18.6
8,10,26:18.6
-2,11,26:18.6
-1,-9,27:18.6
0,-9,27:18.6
-2,-8,27:18.6
-1,-8,27:18.6
6,-8,27:18.6
-8,-7,27:18.6
-7,-7,27:18.6
-2,-7,27:18.6
-9,-6,27:18.6
-7,-6,27:18.6
-6,-6,27:18.6
-5,-6,27:18.6
-2,-6,27:18.6
6,-6,27:18.6
-5,-5,27:18.14
-4,-5,27:18.14
-3,-5,27:18.14
-2,-5,27:18.14
5,-5,27:18.6
6,-5,27:18.6
-11,-4,27:18.6
-3,-4,27:18.14
-2,-4,27:18.14
5,-4,27:18.14
-3,-3,27:18.14
-2,-3,27:18.14
-1,-3,27:18.14
0,-3,27:18.14
4,-3,27:18.14
-4,-2,27:18.14
-3,-2,27:18.14
0,-2,27:18.14
1,-2,27:18.14
2,-2,27:18.14
3,-2,27:18.14
4,-2,27:18.14
-11,-1,27:18.6
-4,-1,27:18.14
-1,-1,27:17.12
0,-1,27:17.12
2,-1,27:18.14
3,-1,27:18.14
4,-1,27:18.14
-10,0,27:18.6
-4,0,27:18.14
-2,0,27:17.12
0,0,27:17.12
1,0,27:17.12
2,0,27:18.14
3,0,27:18.14
4,0,27:18.14
5,0,27:18.14
6,0,27:18.6
7,0,27:18.6
13,0,27:18.6
-10,1,27:18.6
-9,1,27:18.6
-8,1,27:18.6
-7,1,27:18.6
-5,1,27:18.14
-4,1,27:18.14
-2,1,27:17.12
1,1,27:17.12
2,1,27:18.14
6,1,27:18.6
7,1,27:18.6
8,1,27:18.6
12,1,27:18.6
-7,2,27:18.6
-6,2,27:18.14
-5,2,27:18.14
-4,2,27:18.14
-2,2,27:17.12
-1,2,27:17.12
0,2,27:17.12
1,2,27:18.14
2,2,27:18.14
8,2,27:18.6
9,2,27:18.6
-6,3,27:18.14
-5,3,27:18.14
-4,3,27:18.14
-3,3,27:18.14
-2,3,27:18.14
1,3,27:18.14
2,3,27:18.14
8,3,27:18.6
9,3,27:18.6
10,3,27:18.6
-6,4,27:18.14
-2,4,27:18.14
-1,4,27:18.14
0,4,27:18.14
1,4,27:18.14
8,4,27:18.6
9,4,27:18.6
10,4,27:18.6
-7,5,27:18.6
-6,5,27:18.14
0,5,27:18.14
1,5,27:18.14
8,5,27:18.6
9,5,27:18.6
-7,6,27:18.6
0,6,27:18.14
1,6,27:18.14
3,6,27:18.14
6,6,27:18.6
9,6,27:18.6
-8,7,27:18.6
0,7,27:18.14
3,7,27:18.14
4,7,27:18.14
5,7,27:18.6
6,7,27:18.6
7,7,27:18.6
8,7,27:18.6
9,7,27:18.6
-8,8,27:18.6
-1,8,27:18.6
0,8,27:18.6
5,8,27:18.6
6,8,27:18.6
7,8,27:18.6
9,8,27:18.6
-8,9,27:18.6
-1,9,27:18.6
8,9,27:18.6
9,9,27:18.6
-2,10,27:18.6
-1,10,27:18.6
8,10,27:18.6
-3,11,27:18.6
-2,11,27:18.6
-1,-10,28:18.6
-2,-9,28:18.6
-1,-9,28:18.6
-2,-8,28:18.6
-9,-7,28:18.6
-8,-7,28:18.6
-7,-7,28:18.6
-6,-7,28:18.6
-5,-7,28:18.6
-3,-7,28:18.6
-2,-7,28:18.6
-5,-6,28:18.6
-4,-6,28:18.6
-3,-6,28:18.6
6,-6,28:18.6
-4,-5,28:18.14
-3,-5,28:18.14
-2,-5,28:18.14
6,-5,28:18.6
-4,-4,28:18.14
-3,-4,28:18.14
-2,-4,28:18.14
-1,-4,28:18.14
0,-4,28:18.14
5,-4,28:18.14
6,-4,28:18.6
-4,-3,28:18.14
0,-3,28:18.14
1,-3,28:18.14
5,-3,28:18.14
-5,-2,28:18.14
-4,-2,28:18.14
1,-2,28:18.14
2,-2,28:18.14
3,-2,28:18.14
4,-2,28:18.14
-5,-1,28:18.14
-4,-1,28:18.14
-1,-1,28:17.12
0,-1,28:17.12
3,-1,28:18.14
4,-1,28:18.14
5,-1,28:18.14
-5,0,28:18.14
-2,0,28:17.12
0,0,28:17.12
1,0,28:17.12
3,0,28:18.14
5,0,28:18.14
6,0,28:18.6
7,0,28:18.6
8,0,28:18.6
-11,1,28:18.6
-10,1,28:18.6
-9,1,28:18.6
-6,1,28:18.14
-5,1,28:18.14
-2,1,28:17.12
1,1,28:17.12
3,1,28:18.14
9,1,28:18.6
-9,2,28:18.6
-8,2,28:18.6
-7,2,28:18.6
-6,2,28:18.14
-5,2,28:18.14
-2,2,28:17.12
-1,2,28:17.12
0,2,28:17.12
2,2,28:18.14
3,2,28:18.14
-6,3,28:18.14
-5,3,28:18.14
-4,3,28:18.14
2,3,28:18.14
-7,4,28:18.6
-6,4,28:18.14
-4,4,28:18.14
-3,4,28:18.14
-2,4,28:18.14
1,4,28:18.14
2,4,28:18.14
-7,5,28:18.6
-2,5,28:18.14
-1,5,28:18.14
0,5,28:18.14
1,5,28:18.14
-8,6,28:18.6
0,6,28:18.14
1,6,28:18.14
-8,7,28:18.6
0,7,28:18.6
1,7,28:18.6
2,7,28:18.6
3,7,28:18.6
4,7,28:18.6
7,7,28:18.6
8,7,28:18.6
0,8,28:18.6
4,8,28:18.6
5,8,28:18.6
6,8,28:18.6
7,8,28:18.6
0,9,28:18.6
-1,10,28:18.6
0,10,28:18.6
-2,11,28:18.6
-1,11,28:18.6
0,-11,29:18.6
-2,-10,29:18.6
-1,-10,29:18.6
-3,-9,29:18.6
-2,-9,29:18.6
-9,-8,29:18.6
-8,-8,29:18.6
-7,-8,29:18.6
-6,-8,29:18.6
-3,-8,29:18.6
-9,-7,29:18.6
-8,-7,29:18.6
-6,-7,29:18.6
-5,-7,29:18.6
-4,-7,29:18.6
-3,-7,29:18.6
7,-7,29:18.6
-4,-6,29:18.6
-3,-6,29:18.6
6,-6,29:18.6
7,-6,29:18.6
-4,-5,29:18.14
-3,-5,29:18.14
-2,-5,29:18.14
-1,-5,29:18.14
6,-5,29:18.6
7,-5,29:18.6
-5,-4,29:18.14
-4,-4,29:18.14
-1,-4,29:18.14
0,-4,29:18.14
1,-4,29:18.14
6,-4,29:18.6
-5,-3,29:18.14
-4,-3,29:18.14
1,-3,29:18.14
2,-3,29:18.14
3,-3,29:18.14
5,-3,29:18.14
6,-3,29:18.6
-5,-2,29:18.14
3,-2,29:18.14
4,-2,29:18.14
5,-2,29:18.14
-13,-1,29:18.6
-6,-1,29:18.14
-5,-1,29:18.14
-1,-1,29:17.12
4,-1,29:18.14
5,-1,29:18.14
6,-1,29:18.6
7,-1,29:18.6
-6,0,29:18.14
-5,0,29:18.14
-2,0,29:17.12
0,0,29:17.12
4,0,29:18.14
7,0,29:18.6
8,0,29:18.6
9,0,29:18.6
-11,1,29:18.6
-6,1,29:18.14
-2,1,29:17.12
1,1,29:17.12
3,1,29:18.14
4,1,29:18.14
9,1,29:18.6
-11,2,29:18.6
-10,2,29:18.6
-9,2,29:18.6
-8,2,29:18.6
-7,2,29:18.6
-6,2,29:18.14
-2,2,29:17.12
-1,2,29:17.12
0,2,29:17.12
3,2,29:18.14
-7,3,29:18.6
-6,3,29:18.14
-5,3,29:18.14
2,3,29:18.14
3,3,29:18.14
-8,4,29:18.6
-7,4,29:18.6
-5,4,29:18.14
-4,4,29:18.14
-3,4,29:18.14
2,4,29:18.14
-3,5,29:18.14
-2,5,29:18.14
-1,5,29:18.14
2,5,29:18.14
-9,6,29:18.6
-8,6,29:18.6
-1,6,29:18.14
0,6,29:18.14
1,6,29:18.14
-9,7,29:18.6
1,7,29:18.6
2,7,29:18.6
-9,8,29:18.6
1,8,29:18.6
3,8,29:18.6
4,8,29:18.6
5,8,29:18.6
6,8,29:18.6
7,8,29:18.6
-9,9,29:18.6
0,9,29:18.6
1,9,29:18.6
4,9,29:18.6
5,9,29:18.6
0,10,29:18.6
-1,11,29:18.6
0,11,29:18.6
0,-12,30:18.6
1,-12,30:18.6
-2,-11,30:18.6
-1,-11,30:18.6
0,-11,30:18.6
-3,-10,30:18.6
-2,-10,30:18.6
-6,-9,30:18.6
-4,-9,30:18.6
-3,-9,30:18.6
-9,-8,30:18.6
-8,-8,30:18.6
-7,-8,30:18.6
-6,-8,30:18.6
-5,-8,30:18.6
-4,-8,30:18.6
-3,-8,30:18.6
7,-8,30:18.6
-5,-7,30:18.6
-4,-7,30:18.6
-3,-7,30:18.6
7,-7,30:18.6
-5,-6,30:18.6
-4,-6,30:18.6
-3,-6,30:18.6
-2,-6,30:18.6
-1,-6,30:18.6
7,-6,30:18.6
-5,-5,30:18.14
-4,-5,30:18.14
-1,-5,30:18.14
0,-5,30:18.14
7,-5,30:18.6
-5,-4,30:18.14
0,-4,30:18.14
1,-4,30:18.14
2,-4,30:18.14
6,-4,30:18.6
7,-4,30:18.6
-6,-3,30:18.14
-5,-3,30:18.14
2,-3,30:18.14
3,-3,30:18.14
4,-3,30:18.14
6,-3,30:18.6
-6,-2,30:18.14
4,-2,30:18.14
5,-2,30:18.14
6,-2,30:18.6
-14,-1,30:18.6
-13,-1,30:18.6
-6,-1,30:18.14
-1,-1,30:17.12
5,-1,30:18.14
6,-1,30:18.6
7,-1,30:18.6
8,-1,30:18.6
-13,0,30:18.6
-7,0,30:18.6
-6,0,30:18.14
-2,0,30:17.12
0,0,30:17.12
4,0,30:18.14
5,0,30:18.14
9,0,30:18.6
-12,1,30:18.6
-7,1,30:18.6
-2,1,30:17.12
0,1,30:17.12
1,1,30:17.12
4,1,30:18.14
10,1,30:18.6
-11,2,30:18.6
-10,2,30:18.6
-9,2,30:18.6
-7,2,30:18.6
-2,2,30:17.12
-1,2,30:17.12
0,2,30:17.12
3,2,30:18.14
4,2,30:18.14
11,2,30:18.6
-9,3,30:18.6
-8,3,30:18.6
-7,3,30:18.6
3,3,30:18.14
4,3,30:18.14
11,3,30:18.6
-8,4,30:18.6
-7,4,30:18.6
-6,4,30:18.14
-5,4,30:18.14
3,4,30:18.14
-9,5,30:18.6
-5,5,30:18.14
-4,5,30:18.14
-3,5,30:18.14
2,5,30:18.14
3,5,30:18.14
-9,6,30:18.6
-3,6,30:18.14
-2,6,30:18.14
-1,6,30:18.14
-9,7,30:18.6
-1,7,30:18.6
0,7,30:18.6
1,7,30:18.6
2,7,30:18.6
-9,8,30:18.6
1,8,30:18.6
2,8,30:18.6
3,8,30:18.6
-9,9,30:18.6
1,9,30:18.6
3,9,30:18.6
4,9,30:18.6
5,9,30:18.6
6,9,30:18.6
7,9,30:18.6
0,10,30:18.6
1,10,30:18.6
-1,11,30:18.6
0,11,30:18.6
1,11,30:18.6
-3,12,30:18.6
-2,12,30:18.6
-1,12,30:18.6
0,12,30:18.6
-3,13,30:18.6
-2,13,30:18.6
-1,-12,31:18.6
0,-12,31:18.6
-2,-11,31:18.6
-1,-11,31:18.6
-4,-10,31:18.6
-3,-10,31:18.6
-8,-9,31:18.6
-7,-9,31:18.6
-6,-9,31:18.6
-5,-9,31:18.6
-4,-9,31:18.6
-10,-8,31:18.6
-9,-8,31:18.6
-5,-8,31:18.6
-4,-8,31:18.6
-3,-8,31:18.6
-5,-7,31:18.6
-4,-7,31:18.6
-3,-7,31:18.6
-2,-7,31:18.6
7,-7,31:18.6
8,-7,31:18.6
-5,-6,31:18.6
-2,-6,31:18.6
-1,-6,31:18.6
0,-6,31:18.6
7,-6,31:18.6
8,-6,31:18.6
-6,-5,31:18.6
-5,-5,31:18.14
0,-5,31:18.14
1,-5,31:18.14
2,-5,31:18.14
7,-5,31:18.6
8,-5,31:18.6
-6,-4,31:18.14
2,-4,31:18.14
3,-4,31:18.14
4,-4,31:18.14
7,-4,31:18.6
-6,-3,31:18.14
3,-3,31:18.14
4,-3,31:18.14
5,-3,31:18.14
6,-3,31:18.6
7,-3,31:18.6
-7,-2,31:18.6
-6,-2,31:18.14
5,-2,31:18.14
6,-2,31:18.6
7,-2,31:18.6
8,-2,31:18.6
-14,-1,31:18.6
-7,-1,31:18.6
-1,-1,31:17.12
5,-1,31:18.14
6,-1,31:18.6
8,-1,31:18.6
9,-1,31:18.6
-14,0,31:18.6
-13,0,31:18.6
-7,0,31:18.6
-2,0,31:17.12
0,0,31:17.12
5,0,31:18.14
9,0,31:18.6
10,0,31:18.6
-13,1,31:18.6
-12,1,31:18.6
-8,1,31:18.6
-7,1,31:18.6
-2,1,31:17.12
0,1,31:17.12
5,1,31:18.14
10,1,31:18.6
11,1,31:18.6
-12,2,31:18.6
-11,2,31:18.6
-8,2,31:18.6
-2,2,31:17.12
-1,2,31:17.12
0,2,31:17.12
4,2,31:18.14
5,2,31:18.14
11,2,31:18.6
12,2,31:18.6
-11,3,31:18.6
-10,3,31:18.6
-9,3,31:18.6
-8,3,31:18.6
-5,3,31:18.14
4,3,31:18.14
-9,4,31:18.6
-8,4,31:18.6
-7,4,31:18.6
-6,4,31:18.14
3,4,31:18.14
-10,5,31:18.6
-9,5,31:18.6
-6,5,31:18.14
-5,5,31:18.14
-4,5,31:18.14
3,5,31:18.14
-10,6,31:18.6
-4,6,31:18.14
-3,6,31:18.14
-2,6,31:18.14
3,6,31:18.14
-10,7,31:18.6
-2,7,31:18.6
-1,7,31:18.6
0,7,31:18.6
2,7,31:18.6
3,7,31:18.6
-10,8,31:18.6
0,8,31:18.6
1,8,31:18.6
2,8,31:18.6
1,9,31:18.6
2,9,31:18.6
3,9,31:18.6
5,9,31:18.6
6,9,31:18.6
7,9,31:18.6
1,10,31:18.6
3,10,31:18.6
4,10,31:18.6
5,10,31:18.6
0,11,31:18.6
1,11,31:18.6
-2,12,31:18.6
-1,12,31:18.6
0,12,31:18.6
-2,13,31:18.6
-1,13,31:18.6
-3,14,31:18.6
-1,-12,32:18.6
-4,-11,32:18.6
-3,-11,32:18.6
-7,-10,32:18.6
-6,-10,32:18.6
-5,-10,32:18.6
-4,-10,32:18.6
-10,-9,32:18.6
-9,-9,32:18.6
-8,-9,32:18.6
-7,-9,32:18.6
-6,-9,32:18.6
-5,-9,32:18.6
-4,-9,32:18.6
-5,-8,32:18.6
-4,-8,32:18.6
-3,-8,32:18.6
-2,-8,32:18.6
8,-8,32:18.6
-6,-7,32:18.6
-5,-7,32:18.6
-2,-7,32:18.6
-1,-7,32:18.6
0,-7,32:18.6
8,-7,32:18.6
-6,-6,32:18.6
0,-6,32:18.6
1,-6,32:18.6
8,-6,32:18.6
-6,-5,32:18.6
1,-5,32:18.14
2,-5,32:18.14
3,-5,32:18.14
8,-5,32:18.6
-7,-4,32:18.6
-6,-4,32:18.14
3,-4,32:18.14
4,-4,32:18.14
5,-4,32:18.14
8,-4,32:18.6
-7,-3,32:18.6
-2,-3,32:18.14
3,-3,32:18.14
5,-3,32:18.14
6,-3,32:18.6
7,-3,32:18.6
-7,-2,32:18.6
-2,-2,32:18.14
2,-2,32:18.14
3,-2,32:18.14
6,-2,32:18.6
7,-2,32:18.6
8,-2,32:18.6
9,-2,32:18.6
-8,-1,32:18.6
-7,-1,32:18.6
-1,-1,32:17.12
0,-1,32:18.14
1,-1,32:18.14
6,-1,32:18.6
9,-1,32:18.6
10,-1,32:18.6
-8,0,32:18.6
-2,0,32:17.12
-1,0,32:18.14
0,0,32:17.12
6,0,32:18.6
10,0,32:18.6
11,0,32:18.6
-13,1,32:18.6
-9,1,32:18.6
-8,1,32:18.6
-2,1,32:17.12
-1,1,32:18.14
0,1,32:17.12
5,1,32:18.14
6,1,32:18.6
11,1,32:18.6
-13,2,32:18.6
-12,2,32:18.6
-9,2,32:18.6
-8,2,32:18.6
-3,2,32:18.14
-2,2,32:17.12
-1,2,32:17.12
0,2,32:17.12
5,2,32:18.14
12,2,32:18.6
-12,3,32:18.6
-11,3,32:18.6
-10,3,32:18.6
-9,3,32:18.6
-5,3,32:18.14
-4,3,32:18.14
4,3,32:18.14
5,3,32:18.14
-10,4,32:18.6
-9,4,32:18.6
-8,4,32:18.6
-5,4,32:18.14
-10,5,32:18.6
-7,5,32:18.6
-6,5,32:18.14
4,5,32:18.14
-11,6,32:18.6
-10,6,32:18.6
-5,6,32:18.14
-4,6,32:18.14
3,6,32:18.14
4,6,32:18.14
-11,7,32:18.6
-10,7,32:18.6
-4,7,32:18.6
-3,7,32:18.6
-2,7,32:18.6
3,7,32:18.6
-10,8,32:18.6
-2,8,32:18.6
-1,8,32:18.6
0,8,32:18.6
2,8,32:18.6
3,8,32:18.6
-10,9,32:18.6
0,9,32:18.6
1,9,32:18.6
2,9,32:18.6
-10,10,32:18.6
2,10,32:18.6
3,10,32:18.6
4,10,32:18.6
5,10,32:18.6
6,10,32:18.6
7,10,32:18.6
0,11,32:18.6
1,11,32:18.6
2,11,32:18.6
3,11,32:18.6
4,11,32:18.6
-1,12,32:18.6
0,12,32:18.6
1,12,32:18.6
-2,13,32:18.6
-1,13,32:18.6
0,13,32:18.6
-3,-12,33:18.6
-2,-12,33:18.6
-3,-11,33:18.6
-10,-10,33:18.6
-9,-10,33:18.6
-8,-10,33:18.6
-7,-10,33:18.6
-5,-10,33:18.6
-12,-9,33:18.6
-11,-9,33:18.6
-10,-9,33:18.6
-9,-9,33:18.6
-5,-9,33:18.6
-4,-9,33:18.6
-2,-8,33:18.6
-1,-8,33:18.6
8,-8,33:18.6
9,-8,33:18.6
-1,-7,33:18.6
0,-7,33:18.6
9,-7,33:18.6
-6,-6,33:18.6
3,-6,33:18.6
8,-6,33:18.6
9,-6,33:18.6
-7,-5,33:18.6
-2,-5,33:18.14
3,-5,33:18.14
4,-5,33:18.6
8,-5,33:18.6
9,-5,33:18.6
-8,-4,33:18.6
-7,-4,33:18.6
-2,-4,33:18.14
4,-4,33:18.14
5,-4,33:18.6
6,-4,33:18.6
8,-4,33:18.6
9,-4,33:18.6
-8,-3,33:18.6
-7,-3,33:18.6
-2,-3,33:18.14
-1,-3,33:18.14
2,-3,33:18.14
6,-3,33:18.6
7,-3,33:18.6
8,-3,33:18.6
-1,-2,33:18.14
1,-2,33:18.14
2,-2,33:18.14
7,-2,33:18.6
8,-2,33:18.6
9,-2,33:18.6
10,-2,33:18.6
-9,-1,33:18.6
-8,-1,33:18.6
-1,-1,33:18.14
0,-1,33:18.14
1,-1,33:18.14
7,-1,33:18.6
10,-1,33:18.6
-15,0,33:18.6
-9,0,33:18.6
-2,0,33:18.14
-1,0,33:18.14
0,0,33:17.12
6,0,33:18.6
7,0,33:18.6
11,0,33:18.6
-14,1,33:18.6
-9,1,33:18.6
-2,1,33:18.14
-1,1,33:18.14
0,1,33:17.12
6,1,33:18.6
12,1,33:18.6
-13,2,33:18.6
-10,2,33:18.6
-9,2,33:18.6
-3,2,33:18.14
-2,2,33:18.14
-1,2,33:17.12
0,2,33:17.12
5,2,33:18.14
6,2,33:18.6
-12,3,33:18.6
-11,3,33:18.6
-10,3,33:18.6
-4,3,33:18.14
-3,3,33:18.14
-1,3,33:18.14
5,3,33:18.14
-11,4,33:18.6
-10,4,33:18.6
-9,4,33:18.6
-5,4,33:18.14
-4,4,33:18.14
-1,4,33:18.14
5,4,33:18.14
-11,5,33:18.6
-10,5,33:18.6
-9,5,33:18.6
-7,5,33:18.6
-1,5,33:18.14
4,5,33:18.14
5,5,33:18.14
-11,6,33:18.6
-7,6,33:18.6
-6,6,33:18.14
-5,6,33:18.14
4,6,33:18.14
-11,7,33:18.6
-5,7,33:18.6
-3,7,33:18.6
3,7,33:18.6
4,7,33:18.6
-11,8,33:18.6
-3,8,33:18.6
-2,8,33:18.6
-1,8,33:18.6
3,8,33:18.6
-11,9,33:18.6
-1,9,33:18.6
0,9,33:18.6
1,9,33:18.6
3,9,33:18.6
-11,10,33:18.6
1,10,33:18.6
2,10,33:18.6
3,10,33:18.6
5,10,33:18.6
6,10,33:18.6
7,10,33:18.6
-11,11,33:18.6
1,11,33:18.6
2,11,33:18.6
4,11,33:18.6
5,11,33:18.6
-11,12,33:18.6
1,12,33:18.6
2,12,33:18.6
-1,13,33:18.6
-2,14,33:18.6
-2,-13,34:18.6
-1,-13,34:18.6
-3,-12,34:18.6
-11,-10,34:18.6
-10,-10,34:18.6
9,-10,34:18.14
-12,-9,34:18.6
9,-9,34:18.14
9,-8,34:18.14
9,-7,34:18.14
-2,-6,34:18.6
3,-6,34:18.6
4,-6,34:18.6
9,-6,34:18.6
-8,-5,34:18.6
-2,-5,34:18.14
4,-5,34:18.6
9,-5,34:18.6
-8,-4,34:18.6
-1,-4,34:18.14
3,-4,34:18.14
6,-4,34:18.6
7,-4,34:18.6
9,-4,34:18.6
-1,-3,34:18.14
1,-3,34:18.14
2,-3,34:18.14
3,-3,34:18.14
8,-3,34:18.6
9,-3,34:18.6
-1,-2,34:18.14
0,-2,34:18.14
1,-2,34:18.14
8,-2,34:18.6
10,-2,34:18.6
-2,-1,34:18.14
-1,-1,34:18.14
0,-1,34:18.14
7,-1,34:18.6
8,-1,34:18.6
11,-1,34:18.6
-9,0,34:18.6
-3,0,34:18.14
-2,0,34:17.12
-1,0,34:17.12
0,0,34:18.14
7,0,34:18.6
-15,1,34:18.6
-10,1,34:18.6
-3,1,34:18.14
-2,1,34:17.12
0,1,34:18.14
1,1,34:18.14
7,1,34:18.6
-14,2,34:18.6
-10,2,34:18.6
-2,2,34:18.14
-1,2,34:18.14
0,2,34:18.14
6,2,34:18.6
-13,3,34:18.6
-12,3,34:18.6
-11,3,34:18.6
-10,3,34:18.6
-3,3,34:18.14
-2,3,34:18.14
-12,4,34:18.6
-11,4,34:18.6
-10,4,34:18.6
-5,4,34:18.14
-4,4,34:18.14
-2,4,34:18.14
-1,4,34:18.14
-11,5,34:18.6
-10,5,34:18.6
-9,5,34:18.6
-5,5,34:18.14
-1,5,34:18.14
5,5,34:18.14
-12,6,34:18.6
-11,6,34:18.6
-8,6,34:18.6
-7,6,34:18.6
-6,6,34:18.14
-1,6,34:18.14
5,6,34:18.6
-12,7,34:18.6
-11,7,34:18.6
-7,7,34:18.6
-6,7,34:18.6
-5,7,34:18.6
-1,7,34:18.6
-11,8,34:18.6
-3,8,34:18.6
-11,9,34:18.6
-1,9,34:18.6
-11,10,34:18.6
0,10,34:18.6
3,10,34:18.6
7,10,34:18.6
8,10,34:18.6
9,10,34:18.6
10,10,34:18.6
-12,11,34:18.6
-11,11,34:18.6
2,11,34:18.6
3,11,34:18.6
4,11,34:18.6
5,11,34:18.6
6,11,34:18.6
7,11,34:18.6
8,11,34:18.6
-11,12,34:18.6
1,12,34:18.6
0,13,34:18.6
1,13,34:18.6
-1,14,34:18.6
-2,-6,35:18.6
-1,-6,35:18.6
-1,-5,35:18.14
-1,-4,35:18.14
2,-4,35:18.14
3,-4,35:18.14
4,-4,35:18.14
8,-4,35:18.6
-1,-3,35:18.14
0,-3,35:18.14
1,-3,35:18.14
2,-3,35:18.14
9,-3,35:18.6
-1,-2,35:18.14
0,-2,35:18.14
9,-2,35:18.6
-3,-1,35:18.14
-2,-1,35:18.14
-1,-1,35:18.14
0,-1,35:18.14
11,-1,35:18.6
12,-1,35:18.6
-4,0,35:18.14
-3,0,35:18.14
-2,0,35:17.12
-1,0,35:17.12
0,0,35:17.12
1,0,35:18.14
12,0,35:18.6
-15,1,35:18.6
-3,1,35:18.14
-2,1,35:17.12
0,1,35:17.12
1,1,35:18.14
-15,2,35:18.6
-14,2,35:18.6
-3,2,35:18.14
-2,2,35:18.14
-1,2,35:17.12
0,2,35:18.14
1,2,35:18.14
-3,3,35:18.14
-2,3,35:18.14
-1,3,35:18.14
-12,4,35:18.6
-11,4,35:18.6
-4,4,35:18.14
-3,4,35:18.14
-2,4,35:18.14
-12,5,35:18.6
-11,5,35:18.6
-6,5,35:18.14
-5,5,35:18.14
-4,5,35:18.14
-2,5,35:18.14
-2,6,35:18.14
-1,6,35:18.14
5,6,35:18.6
-7,7,35:18.6
-6,7,35:18.6
-1,7,35:18.6
0,7,35:18.6
0,8,35:18.6
-12,11,35:18.6
7,11,35:18.6
8,11,35:18.6
9,11,35:18.6
-1,14,35:18.6
0,14,35:18.6
1,-13,36:18.6
1,-12,36:18.6
1,-8,36:18.6
2,-8,36:18.6
-2,-7,36:18.6
1,-7,36:18.6
-2,-6,36:18.6
-1,-6,36:18.6
-1,-5,36:18.14
3,-5,36:18.14
-1,-4,36:18.14
0,-4,36:18.14
1,-4,36:18.14
2,-4,36:18.14
3,-4,36:18.14
-1,-3,36:18.14
0,-3,36:18.14
1,-3,36:18.14
-2,-2,36:18.14
-1,-2,36:18.14
0,-2,36:18.14
-4,-1,36:18.14
-3,-1,36:18.14
0,-1,36:18.14
1,-1,36:18.14
-4,0,36:18.14
-2,0,36:17.12
-1,0,36:17.12
0,0,36:17.12
1,0,36:18.14
-4,1,36:18.14
-3,1,36:18.14
-2,1,36:17.12
0,1,36:17.12
1,1,36:18.14
2,1,36:18.14
-3,2,36:18.14
-1,2,36:17.12
0,2,36:18.14
1,2,36:18.14
2,2,36:18.14
-3,3,36:18.14
-2,3,36:18.14
-1,3,36:18.14
0,3,36:18.14
-3,4,36:18.14
-2,4,36:18.14
-5,5,36:18.14
-4,5,36:18.14
-2,5,36:18.14
-6,6,36:18.14
-5,6,36:18.14
-2,6,36:18.14
-2,7,36:18.6
-1,7,36:18.6
0,-14,37:18.14
1,-14,37:18.14
1,-13,37:18.14
1,-12,37:18.14
1,-11,37:18.14
2,-10,37:18.6
2,-9,37:18.6
3,-9,37:18.6
4,-9,37:18.14
1,-8,37:18.6
2,-8,37:18.6
4,-8,37:18.14
-2,-7,37:18.6
-1,-7,37:18.6
1,-7,37:18.6
-1,-6,37:18.6
0,-6,37:18.6
-1,-5,37:18.6
0,-5,37:18.6
2,-5,37:18.6
3,-5,37:18.6
4,-5,37:18.6
5,-5,37:18.6
0,-4,37:18.14
1,-4,37:18.14
-2,-3,37:18.14
-1,-3,37:18.14
0,-3,37:18.14
1,-3,37:18.14
-4,-2,37:18.14
-3,-2,37:18.14
-2,-2,37:18.14
1,-2,37:18.14
-5,-1,37:18.14
-4,-1,37:18.14
1,-1,37:18.14
-5,0,37:18.14
-4,0,37:18.14
-2,0,37:17.12
-1,0,37:17.12
0,0,37:17.12
1,0,37:18.14
2,0,37:18.14
-4,1,37:18.14
-2,1,37:17.12
-1,1,37:17.12
0,1,37:17.12
2,1,37:18.14
-4,2,37:18.14
-1,2,37:17.12
1,2,37:18.14
2,2,37:18.14
3,2,37:18.14
-4,3,37:18.14
-3,3,37:18.14
-1,3,37:18.14
0,3,37:18.14
1,3,37:18.14
-3,4,37:18.14
-2,4,37:18.14
-1,4,37:18.14
-4,5,37:18.14
-3,5,37:18.14
-2,5,37:18.14
-8,6,37:18.6
-7,6,37:18.6
-6,6,37:18.6
-5,6,37:18.14
-4,6,37:18.14
-3,6,37:18.14
-2,6,37:18.14
-2,7,37:18.6
-1,8,37:18.6
2,-11,38:18.14
2,-10,38:18.14
2,-9,38:18.6
3,-9,38:18.6
4,-9,38:18.14
-2,-8,38:18.6
1,-8,38:18.6
2,-8,38:18.6
-1,-7,38:18.6
0,-7,38:18.6
1,-7,38:18.6
0,-6,38:18.6
3,-6,38:18.6
-1,-5,38:18.6
0,-5,38:18.6
1,-5,38:18.6
2,-5,38:18.6
3,-5,38:18.6
4,-5,38:18.6
5,-5,38:18.6
-2,-4,38:18.14
-1,-4,38:18.14
0,-4,38:18.14
1,-4,38:18.14
-3,-3,38:18.14
-2,-3,38:18.14
-1,-3,38:18.14
1,-3,38:18.14
-5,-2,38:18.14
-4,-2,38:18.14
-3,-2,38:18.14
1,-2,38:18.14
2,-2,38:18.14
-6,-1,38:18.14
-5,-1,38:18.14
2,-1,38:18.14
-5,0,38:18.14
-2,0,38:18.14
-1,0,38:18.14
0,0,38:17.12
2,0,38:18.14
-5,1,38:18.14
-4,1,38:18.14
-2,1,38:18.14
-1,1,38:18.14
0,1,38:17.12
2,1,38:18.14
3,1,38:18.14
-4,2,38:18.14
-1,2,38:17.12
3,2,38:18.14
-4,3,38:18.14
1,3,38:18.14
2,3,38:18.14
-4,4,38:18.14
-3,4,38:18.14
-2,4,38:18.14
-1,4,38:18.14
0,4,38:18.14
-4,5,38:18.14
-3,5,38:18.14
-2,5,38:18.14
-8,6,38:18.6
-7,6,38:18.6
-6,6,38:18.6
-5,6,38:18.14
-4,6,38:18.14
-3,6,38:18.14
-3,7,38:18.6
-2,7,38:18.6
-2,8,38:18.6
-1,8,38:18.6
2,-10,39:18.14
-3,-9,39:18.6
2,-9,39:18.14
3,-9,39:18.14
4,-9,39:18.14
5,-9,39:18.14
-2,-8,39:18.6
-1,-8,39:18.6
1,-8,39:18.6
2,-8,39:18.14
-1,-7,39:18.6
0,-7,39:18.6
1,-7,39:18.6
0,-6,39:18.6
1,-6,39:18.6
2,-6,39:18.6
3,-6,39:18.6
4,-6,39:18.6
-1,-5,39:18.6
0,-5,39:18.6
1,-5,39:18.6
-2,-4,39:18.14
-1,-4,39:18.14
1,-4,39:18.14
-4,-3,39:18.14
-3,-3,39:18.14
-2,-3,39:18.14
1,-3,39:18.14
2,-3,39:18.14
-5,-2,39:18.14
-4,-2,39:18.14
0,-2,39:18.14
2,-2,39:18.14
-6,-1,39:18.14
-2,-1,39:18.14
-1,-1,39:18.14
2,-1,39:18.14
3,-1,39:18.14
-6,0,39:18.14
-5,0,39:18.14
-3,0,39:18.14
-2,0,39:17.12
-1,0,39:17.12
0,0,39:18.14
3,0,39:18.14
-5,1,39:18.14
-3,1,39:18.14
-2,1,39:17.12
-1,1,39:17.12
0,1,39:18.14
3,1,39:18.14
-5,2,39:18.14
-2,2,39:18.14
-1,2,39:18.14
3,2,39:18.14
4,2,39:18.14
-5,3,39:18.14
-4,3,39:18.14
2,3,39:18.14
3,3,39:18.14
4,3,39:18.14
-4,4,39:18.14
0,4,39:18.14
1,4,39:18.14
2,4,39:18.14
-4,5,39:18.14
-3,5,39:18.14
-2,5,39:18.14
-1,5,39:18.14
-4,6,39:18.14
-3,6,39:18.14
-7,7,39:18.6
-6,7,39:18.6
-5,7,39:18.6
-4,7,39:18.6
-3,7,39:18.6
-3,8,39:18.6
-2,8,39:18.6
-1,9,39:18.6
-2,-9,40:18.6
2,-9,40:18.14
-1,-8,40:18.6
1,-8,40:18.14
2,-8,40:18.14
0,-7,40:18.6
1,-7,40:18.14
0,-6,40:18.6
1,-6,40:18.6
2,-6,40:18.6
3,-6,40:18.6
4,-6,40:18.6
-1,-5,40:18.6
0,-5,40:18.6
1,-5,40:18.6
-3,-4,40:18.14
-2,-4,40:18.14
1,-4,40:18.14
2,-4,40:18.14
-4,-3,40:18.14
0,-3,40:18.14
2,-3,40:18.14
-1,-2,40:18.14
0,-2,40:18.14
2,-2,40:18.14
3,-2,40:18.14
-3,-1,40:18.14
-2,-1,40:18.14
-1,-1,40:18.14
0,-1,40:18.14
3,-1,40:18.14
-4,0,40:18.14
-3,0,40:18.14
-2,0,40:17.12
-1,0,40:17.12
0,0,40:18.14
3,0,40:18.14
-6,1,40:18.14
-3,1,40:18.14
-2,1,40:17.12
-1,1,40:17.12
0,1,40:18.14
1,1,40:18.14
4,1,40:18.14
-5,2,40:18.14
-3,2,40:18.14
-2,2,40:18.14
-1,2,40:18.14
0,2,40:18.14
4,2,40:18.14
-5,3,40:18.14
-3,3,40:18.14
-2,3,40:18.14
3,3,40:18.14
4,3,40:18.14
-5,4,40:18.14
-4,4,40:18.14
1,4,40:18.14
2,4,40:18.14
3,4,40:18.14
-4,5,40:18.14
-1,5,40:18.14
0,5,40:18.14
1,5,40:18.14
-4,6,40:18.14
-3,6,40:18.14
-2,6,40:18.14
-1,6,40:18.14
-5,7,40:18.6
-4,7,40:18.6
-3,7,40:18.6
-3,8,40:18.6
-2,8,40:18.6
-2,9,40:18.6
-1,9,40:18.6
-1,10,40:18.6
0,10,40:18.6
1,-8,41:18.14
1,-7,41:18.14
3,-7,41:18.14
4,-7,41:18.6
0,-6,41:18.6
1,-6,41:18.6
2,-5,41:18.6
0,-4,41:18.14
0,-3,41:18.14
-7,-2,41:18.6
-2,-2,41:18.14
-1,-2,41:18.14
0,-2,41:18.14
3,-2,41:18.14
-6,-1,41:18.14
-4,-1,41:18.14
-3,-1,41:18.14
-2,-1,41:18.14
0,-1,41:18.14
3,-1,41:18.14
-4,0,41:18.14
-2,0,41:17.12
-1,0,41:17.12
0,0,41:18.14
1,0,41:18.14
-4,1,41:18.14
-3,1,41:18.14
-2,1,41:17.12
-1,1,41:17.12
1,1,41:18.14
-3,2,41:18.14
-1,2,41:18.14
0,2,41:18.14
1,2,41:18.14
3,2,41:18.14
-3,3,41:18.14
-2,3,41:18.14
-1,3,41:18.14
-3,4,41:18.14
2,4,41:18.14
3,4,41:18.14
-4,5,41:18.14
-3,5,41:18.14
0,5,41:18.14
1,5,41:18.14
-4,6,41:18.14
-2,6,41:18.14
-1,6,41:18.14
-7,7,41:18.6
-6,7,41:18.6
-4,7,41:18.6
-3,7,41:18.6
-7,8,41:18.6
-6,8,41:18.6
-3,8,41:18.6
-2,9,41:18.6
-1,10,41:18.6
1,-8,42:18.14
1,-7,42:18.14
0,-6,42:18.6
1,-6,42:18.6
1,-5,42:18.6
0,-4,42:18.14
-1,-3,42:18.14
0,-3,42:18.14
-7,-2,42:18.6
-3,-2,42:18.14
-2,-2,42:18.14
-1,-2,42:18.14
0,-2,42:18.14
-6,-1,42:18.14
-5,-1,42:18.14
-4,-1,42:18.14
-3,-1,42:18.14
0,-1,42:18.14
1,-1,42:18.14
-5,0,42:18.14
-4,0,42:18.14
-2,0,42:17.0
-1,0,42:17.0
1,0,42:18.14
-4,1,42:18.14
-2,1,42:18.14
-1,1,42:17.0
1,1,42:18.14
-4,2,42:18.14
0,2,42:18.14
1,2,42:18.14
2,2,42:18.14
3,2,42:18.14
-3,3,42:18.14
-2,3,42:18.14
-1,3,42:18.14
0,3,42:18.14
4,3,42:18.14
-3,4,42:18.14
-2,4,42:18.14
-4,5,42:18.14
-3,5,42:18.14
1,-8,43:18.14
1,-7,43:18.14
0,-6,43:18.6
1,-6,43:18.6
1,-5,43:18.6
0,-4,43:18.14
-2,-3,43:18.14
-1,-3,43:18.14
0,-3,43:18.14
1,-3,43:18.14
-8,-2,43:18.6
-7,-2,43:18.6
-4,-2,43:18.14
-3,-2,43:18.14
-2,-2,43:18.14
1,-2,43:18.14
-6,-1,43:18.14
-5,-1,43:18.14
-4,-1,43:18.14
1,-1,43:18.14
-5,0,43:18.14
-2,0,43:17.0
-1,0,43:17.0
1,0,43:18.14
2,0,43:18.14
-5,1,43:18.14
-4,1,43:18.14
-2,1,43:17.0
-1,1,43:17.0
2,1,43:18.14
-4,2,43:18.14
-2,2,43:18.14
1,2,43:18.14
2,2,43:18.14
3,2,43:18.14
-4,3,43:18.14
-1,3,43:18.14
0,3,43:18.14
1,3,43:18.14
4,3,43:18.6
-4,4,43:18.14
-3,4,43:18.14
-2,4,43:18.14
-4,5,43:18.14
-3,5,43:18.14
-4,6,43:18.6
1,-8,44:18.14
1,-7,44:18.14
1,-5,44:18.6
-1,-4,44:18.14
0,-4,44:18.14
1,-4,44:18.14
-3,-3,44:18.14
-2,-3,44:18.14
-1,-3,44:18.14
1,-3,44:18.14
-9,-2,44:18.6
-8,-2,44:18.6
-7,-2,44:18.6
-5,-2,44:18.14
-4,-2,44:18.14
-3,-2,44:18.14
1,-2,44:18.14
-6,-1,44:18.14
-5,-1,44:18.14
-3,-1,44:18.14
1,-1,44:18.14
-6,0,44:18.14
-5,0,44:18.14
-2,0,44:18.14
-1,0,44:17.0
2,0,44:18.14
-5,1,44:18.14
-2,1,44:18.14
-1,1,44:18.14
0,1,44:18.14
2,1,44:18.14
-5,2,44:18.14
-2,2,44:18.14
1,2,44:18.14
2,2,44:18.14
3,2,44:18.14
-5,3,44:18.14
-4,3,44:18.14
-2,3,44:18.14
0,3,44:18.14
1,3,44:18.14
5,3,44:18.6
-4,4,44:18.14
-2,4,44:18.14
-1,4,44:18.14
-4,5,44:18.14
-3,5,44:18.14
-4,6,44:18.6
-4,7,44:18.6
-2,-4,45:18.14
0,-4,45:18.14
1,-4,45:18.14
-2,-3,45:18.14
1,-3,45:18.14
-8,-2,45:18.6
-7,-2,45:18.6
-6,-2,45:18.14
-5,-2,45:18.14
-4,-2,45:18.14
1,-2,45:18.14
-6,-1,45:18.14
-3,-1,45:18.14
2,-1,45:18.14
-6,0,45:18.14
-3,0,45:18.14
-2,0,45:18.14
-1,0,45:17.0
2,0,45:18.14
-6,1,45:18.14
-5,1,45:18.14
-2,1,45:18.14
-1,1,45:18.14
0,1,45:18.14
2,1,45:18.14
3,1,45:18.14
-2,2,45:18.14
1,2,45:18.14
2,2,45:18.14
3,2,45:18.14
-3,3,45:18.14
-2,3,45:18.14
1,3,45:18.14
2,3,45:18.14
4,3,45:18.6
5,3,45:18.6
-4,4,45:18.14
-3,4,45:18.14
-1,4,45:18.14
-4,5,45:18.14
-3,-1,46:18.6
-3,0,46:18.6
-2,0,46:18.6
-1,0,46:17.0
-2,1,46:17.0
-1,1,46:18.6
0,1,46:18.6
-2,2,46:18.6
0,2,46:18.6
1,2,46:18.6
2,2,46:18.6
3,2,46:18.6
-3,3,46:18.6
-2,3,46:18.6
-3,4,46:18.6
-4,5,46:18.6
-4,-2,47:18.6
-4,-1,47:18.6
-3,-1,47:18.6
-3,0,47:18.6
-2,0,47:18.6
-1,0,47:17.0
-2,1,47:18.6
-1,1,47:18.6
0,1,47:18.6
-2,2,47:18.6
0,2,47:18.6
1,2,47:18.6
2,2,47:18.6
-2,3,47:18.6
-3,4,47:18.6
-4,5,47:18.6
-3,5,47:18.6
-4,6,47:18.6
-3,-1,48:18.6
-3,0,48:18.6
-2,0,48:18.6
-2,1,48:18.6
-1,1,48:18.6
-2,2,48:18.6
0,2,48:18.6
1,2,48:18.6
2,2,48:18.6
-2,3,48:18.6
3,3,48:18.6
-3,4,48:18.6
-2,0,49:17.0
-2,1,49:17.0
-1,1,49:18.6
-2,0,50:17.0
