[META]
version=2.0
spawnOnBlockType=2
spawnSunlight=True
spawnDarkness=True
spawnWater=False
spawnLava=False
underFill=False
randomRotation=True
dig=True
tree=False
branch=False
needsFoundation=True
rarity=100
collisionPercentage=20
spawnElevationMin=0
spawnElevationMax=200
spawnInBiome=Custom
[DATA]
8,-9,-8:17.12
7,-8,-8:17.12
8,-8,-8:17.12
9,-7,-8:17.12
8,-10,-7:17.12
6,-9,-7:17.12
7,-9,-7:17.12
8,-9,-7:17.12
6,-8,-7:17.12
8,-8,-7:17.12
10,-8,-7:17.12
8,-7,-7:17.12
8,-6,-7:17.12
8,-10,-6:17.12
8,-9,-6:17.12
10,-9,-6:17.12
6,-8,-6:17.12
7,-8,-6:17.12
8,-8,-6:17.12
9,-8,-6:17.12
10,-8,-6:17.12
9,-7,-6:17.12
8,-6,-6:17.12
8,-10,-5:17.12
9,-10,-5:17.12
6,-9,-5:17.12
8,-9,-5:17.12
6,-8,-5:17.12
7,-8,-5:17.12
8,-8,-5:17.12
9,-8,-5:17.12
10,-8,-5:17.12
7,-7,-5:17.12
8,-7,-5:17.12
9,-6,-5:17.12
6,-9,-4:17.12
7,-9,-4:17.12
6,-8,-4:17.12
7,-8,-4:17.12
8,-8,-4:17.12
9,-8,-4:17.12
6,-7,-4:17.12
7,-7,-4:17.12
8,-7,-4:17.12
7,-9,-3:17.12
8,-9,-3:17.12
7,-8,-3:17.12
8,-8,-3:17.12
9,-8,-3:17.12
7,-7,-3:17.12
8,-7,-3:17.12
9,-7,-3:17.12
7,-9,-2:17.12
8,-9,-2:17.12
7,-8,-2:17.12
8,-8,-2:17.12
9,-8,-2:17.12
7,-7,-2:17.12
8,-7,-2:17.12
9,-7,-2:17.12
8,-6,-2:17.12
7,-9,-1:17.12
8,-9,-1:17.12
7,-8,-1:17.12
8,-8,-1:17.12
9,-8,-1:17.12
7,-7,-1:17.12
8,-7,-1:17.12
9,-7,-1:17.12
8,-6,-1:17.12
9,-6,-1:17.12
8,-10,0:18.14
9,-10,0:18.14
7,-9,0:17.12
8,-9,0:18.14
9,-9,0:18.14
6,-8,0:17.12
7,-8,0:17.12
8,-8,0:17.12
9,-8,0:17.12
10,-8,0:17.12
7,-7,0:17.12
8,-7,0:17.12
9,-7,0:17.12
8,-6,0:17.12
9,-6,0:17.12
8,-10,1:18.14
9,-10,1:18.14
7,-9,1:17.12
8,-9,1:18.14
9,-9,1:18.14
6,-8,1:17.12
7,-8,1:17.12
8,-8,1:17.12
9,-8,1:17.12
10,-8,1:17.12
7,-7,1:17.12
8,-7,1:17.12
9,-7,1:17.12
10,-7,1:17.12
6,-6,1:18.14
7,-6,1:18.14
8,-6,1:18.14
9,-6,1:18.14
7,-5,1:18.14
9,-5,1:18.14
10,-5,1:18.14
7,-4,1:18.14
8,-4,1:18.14
7,-9,2:17.12
8,-9,2:17.12
9,-9,2:17.12
10,-9,2:17.12
6,-8,2:17.12
7,-8,2:17.12
8,-8,2:17.12
9,-8,2:17.12
10,-8,2:17.12
7,-7,2:17.12
8,-7,2:17.12
9,-7,2:17.12
10,-7,2:17.12
7,-6,2:18.14
8,-6,2:18.14
9,-6,2:17.12
10,-6,2:17.12
7,-5,2:18.14
8,-5,2:18.14
9,-5,2:18.14
8,-4,2:18.14
7,-9,3:17.12
9,-9,3:17.12
10,-9,3:17.12
6,-8,3:17.12
7,-8,3:17.12
8,-8,3:17.12
9,-8,3:17.12
10,-8,3:17.12
7,-7,3:17.12
10,-7,3:17.12
8,-6,3:18.14
9,-6,3:17.12
10,-6,3:17.12
13,-5,3:18.14
12,-3,3:18.14
14,-11,4:18.14
15,-11,4:18.6
16,-11,4:18.6
17,-11,4:18.6
6,-9,4:17.12
7,-9,4:17.12
9,-9,4:17.12
10,-9,4:17.12
11,-9,4:17.12
6,-8,4:17.12
7,-8,4:17.12
8,-8,4:17.12
10,-8,4:17.12
16,-8,4:18.6
7,-7,4:17.12
12,-7,4:18.14
9,-6,4:18.14
10,-6,4:17.12
12,-6,4:18.14
8,-5,4:18.14
9,-5,4:18.14
12,-5,4:18.14
13,-5,4:18.14
11,-4,4:18.14
12,-4,4:18.14
13,-4,4:18.14
13,-3,4:18.6
11,-14,5:18.6
11,-13,5:18.14
12,-13,5:18.14
12,-12,5:18.14
13,-12,5:18.14
13,-11,5:18.14
14,-11,5:18.14
15,-11,5:18.6
16,-11,5:18.6
17,-11,5:18.6
10,-10,5:17.12
17,-10,5:18.6
6,-9,5:17.12
7,-9,5:17.12
10,-9,5:17.12
11,-9,5:17.12
15,-9,5:18.6
16,-9,5:18.6
17,-9,5:18.6
6,-8,5:17.12
7,-8,5:17.12
10,-8,5:18.14
11,-8,5:18.14
12,-8,5:18.14
14,-8,5:18.14
15,-8,5:18.6
16,-8,5:18.6
8,-7,5:18.14
9,-7,5:18.14
10,-7,5:18.14
11,-7,5:18.14
12,-7,5:18.14
14,-7,5:18.14
7,-6,5:18.14
8,-6,5:18.14
9,-6,5:18.14
10,-6,5:17.12
11,-6,5:18.14
12,-6,5:18.14
8,-5,5:18.14
11,-5,5:18.14
12,-5,5:18.14
10,-4,5:18.14
11,-4,5:18.14
12,-4,5:18.14
13,-4,5:18.14
10,-14,6:18.6
11,-13,6:18.14
12,-12,6:18.14
13,-12,6:18.14
9,-11,6:18.14
13,-11,6:18.14
14,-11,6:18.14
9,-10,6:18.14
10,-10,6:18.14
11,-10,6:18.14
12,-10,6:18.14
13,-10,6:18.14
14,-10,6:18.14
15,-10,6:18.6
16,-10,6:18.6
17,-10,6:18.6
6,-9,6:17.12
7,-9,6:17.12
8,-9,6:18.14
9,-9,6:18.14
10,-9,6:17.12
11,-9,6:18.14
12,-9,6:18.14
13,-9,6:18.14
14,-9,6:18.14
15,-9,6:18.6
6,-8,6:17.12
7,-8,6:17.12
8,-8,6:18.14
10,-8,6:18.14
11,-8,6:18.14
13,-8,6:18.14
14,-8,6:18.14
9,-7,6:18.14
10,-7,6:18.14
11,-7,6:18.14
12,-7,6:18.14
8,-6,6:18.14
9,-6,6:18.14
10,-6,6:18.14
11,-6,6:18.14
12,-6,6:18.14
8,-5,6:18.14
9,-5,6:18.14
10,-5,6:18.14
11,-5,6:18.14
12,-5,6:18.14
10,-4,6:18.14
11,-4,6:18.14
12,-4,6:18.14
13,-4,6:18.14
4,-16,7:18.6
9,-16,7:18.6
4,-15,7:18.6
9,-15,7:18.6
4,-14,7:18.6
4,-13,7:18.6
9,-13,7:18.6
10,-13,7:18.6
11,-13,7:18.6
4,-12,7:18.14
9,-12,7:18.14
10,-12,7:18.14
11,-12,7:18.14
12,-12,7:18.14
13,-12,7:18.14
14,-12,7:18.14
9,-11,7:18.14
10,-11,7:18.14
11,-11,7:18.14
12,-11,7:18.14
13,-11,7:18.14
10,-10,7:17.12
11,-10,7:17.12
12,-10,7:18.14
13,-10,7:18.14
14,-10,7:18.14
15,-10,7:18.6
16,-10,7:18.6
17,-10,7:18.6
6,-9,7:17.12
7,-9,7:17.12
8,-9,7:18.14
9,-9,7:18.14
10,-9,7:18.14
11,-9,7:17.12
13,-9,7:18.14
15,-9,7:18.6
6,-8,7:17.12
7,-8,7:17.12
8,-8,7:18.14
9,-8,7:18.14
10,-8,7:18.14
14,-8,7:18.14
7,-7,7:18.14
8,-7,7:18.14
9,-7,7:18.14
10,-7,7:18.14
11,-7,7:18.14
12,-7,7:18.14
7,-6,7:18.14
8,-6,7:18.14
9,-6,7:18.14
10,-6,7:18.14
11,-6,7:18.14
12,-6,7:18.14
8,-5,7:18.14
9,-5,7:18.14
10,-5,7:18.14
11,-5,7:18.14
12,-5,7:18.14
9,-4,7:18.14
10,-4,7:18.14
11,-4,7:18.14
12,-4,7:18.14
5,-17,8:18.6
7,-17,8:18.6
8,-17,8:18.6
5,-16,8:18.6
8,-16,8:18.6
5,-15,8:18.6
8,-15,8:18.6
9,-15,8:18.6
5,-14,8:18.6
8,-14,8:18.6
9,-14,8:18.6
5,-13,8:18.6
8,-13,8:18.6
9,-13,8:18.6
10,-13,8:18.6
11,-13,8:18.6
3,-12,8:18.14
4,-12,8:18.14
5,-12,8:18.14
9,-12,8:18.14
11,-12,8:18.14
12,-12,8:18.14
2,-11,8:18.14
3,-11,8:18.14
5,-11,8:18.14
11,-11,8:18.14
12,-11,8:18.14
13,-11,8:18.14
14,-11,8:18.14
1,-10,8:18.6
2,-10,8:18.14
10,-10,8:18.14
11,-10,8:17.12
14,-10,8:18.14
15,-10,8:18.6
16,-10,8:18.6
1,-9,8:18.6
6,-9,8:17.12
7,-9,8:18.14
10,-9,8:18.14
11,-9,8:17.12
14,-9,8:18.14
15,-9,8:18.6
6,-8,8:17.12
7,-8,8:17.12
8,-8,8:18.14
9,-8,8:18.14
10,-8,8:18.14
13,-8,8:18.14
14,-8,8:18.14
5,-7,8:18.14
6,-7,8:18.14
7,-7,8:18.14
8,-7,8:18.14
9,-7,8:18.14
10,-7,8:18.14
12,-7,8:18.14
13,-7,8:18.14
7,-6,8:18.14
8,-6,8:18.14
9,-6,8:18.14
10,-6,8:18.14
11,-6,8:18.14
12,-6,8:18.14
8,-5,8:18.14
9,-5,8:18.14
10,-5,8:18.14
11,-5,8:18.14
12,-5,8:18.14
13,-5,8:18.14
9,-4,8:18.14
10,-4,8:18.14
11,-4,8:18.14
12,-4,8:18.14
13,-4,8:18.14
12,-3,8:18.6
13,-3,8:18.6
6,-17,9:18.6
7,-17,9:18.6
5,-16,9:18.6
6,-16,9:18.6
7,-16,9:18.6
6,-15,9:18.6
7,-15,9:18.6
6,-14,9:18.6
7,-14,9:18.6
8,-14,9:18.6
5,-13,9:18.6
6,-13,9:18.6
7,-13,9:18.6
8,-13,9:18.6
10,-13,9:18.6
11,-13,9:18.6
4,-12,9:18.14
5,-12,9:18.14
6,-12,9:18.14
7,-12,9:18.14
8,-12,9:18.14
11,-12,9:18.14
12,-12,9:18.6
13,-12,9:18.6
3,-11,9:18.14
4,-11,9:18.14
6,-11,9:18.14
7,-11,9:18.14
8,-11,9:18.14
10,-11,9:18.14
11,-11,9:18.14
13,-11,9:18.6
14,-11,9:18.6
15,-11,9:18.6
2,-10,9:18.14
3,-10,9:18.14
6,-10,9:18.14
7,-10,9:18.14
8,-10,9:18.14
9,-10,9:18.14
10,-10,9:18.14
11,-10,9:18.14
12,-10,9:18.6
13,-10,9:18.6
14,-10,9:18.6
15,-10,9:18.6
1,-9,9:18.6
2,-9,9:18.14
5,-9,9:18.14
6,-9,9:18.14
7,-9,9:17.12
8,-9,9:18.14
10,-9,9:18.14
11,-9,9:18.14
12,-9,9:18.6
13,-9,9:18.6
4,-8,9:18.14
5,-8,9:18.14
6,-8,9:17.12
7,-8,9:17.12
10,-8,9:18.14
11,-8,9:18.14
12,-8,9:18.6
13,-8,9:18.6
3,-7,9:18.14
4,-7,9:18.14
5,-7,9:18.14
7,-7,9:18.14
8,-7,9:18.14
9,-7,9:18.14
10,-7,9:18.14
11,-7,9:18.14
12,-7,9:18.6
3,-6,9:18.14
7,-6,9:18.14
8,-6,9:18.14
9,-6,9:18.14
10,-6,9:18.14
11,-6,9:18.14
12,-6,9:18.6
8,-5,9:18.14
9,-5,9:18.14
10,-5,9:18.14
11,-5,9:18.14
12,-5,9:18.6
9,-4,9:18.14
10,-4,9:18.14
11,-4,9:18.14
12,-4,9:18.6
13,-4,9:18.6
13,-3,9:18.6
6,-17,10:18.6
6,-16,10:18.6
6,-15,10:18.6
6,-14,10:18.6
7,-14,10:18.6
6,-13,10:18.6
7,-13,10:18.6
9,-13,10:18.6
12,-13,10:18.6
5,-12,10:18.14
6,-12,10:18.14
7,-12,10:18.14
9,-12,10:18.14
10,-12,10:18.14
15,-12,10:18.6
4,-11,10:18.14
5,-11,10:18.14
6,-11,10:18.14
7,-11,10:18.14
10,-11,10:18.14
11,-11,10:18.14
14,-11,10:18.6
15,-11,10:18.6
3,-10,10:18.14
4,-10,10:18.14
5,-10,10:18.14
6,-10,10:18.14
10,-10,10:18.14
11,-10,10:17.12
12,-10,10:18.6
13,-10,10:18.6
14,-10,10:18.6
2,-9,10:18.14
3,-9,10:18.14
4,-9,10:18.14
5,-9,10:18.14
6,-9,10:17.12
7,-9,10:17.12
8,-9,10:18.14
9,-9,10:18.14
10,-9,10:18.14
11,-9,10:18.14
12,-9,10:18.6
13,-9,10:18.6
2,-8,10:18.14
3,-8,10:18.14
4,-8,10:18.14
6,-8,10:17.12
7,-8,10:17.12
8,-8,10:18.14
9,-8,10:18.14
10,-8,10:18.14
11,-8,10:18.14
14,-8,10:18.6
3,-7,10:18.14
7,-7,10:18.14
8,-7,10:18.14
9,-7,10:18.14
10,-7,10:18.14
8,-6,10:18.14
9,-6,10:18.14
10,-6,10:18.14
9,-5,10:18.14
10,-5,10:18.14
11,-5,10:18.14
12,-5,10:18.6
9,-4,10:18.14
10,-4,10:18.14
11,-4,10:18.14
12,-4,10:18.6
6,-17,11:18.6
6,-16,11:18.6
6,-15,11:18.6
6,-14,11:18.6
7,-14,11:18.6
8,-14,11:18.6
6,-13,11:18.6
7,-13,11:18.6
8,-13,11:18.6
4,-12,11:18.14
5,-12,11:18.14
6,-12,11:18.14
7,-12,11:18.14
8,-12,11:18.14
9,-12,11:18.14
10,-12,11:18.14
13,-12,11:18.6
14,-12,11:18.6
15,-12,11:18.6
16,-12,11:18.6
17,-12,11:18.6
5,-11,11:18.14
9,-11,11:18.14
10,-11,11:18.14
11,-11,11:18.14
14,-11,11:18.6
15,-11,11:18.6
4,-10,11:18.14
5,-10,11:18.14
9,-10,11:18.14
10,-10,11:18.14
11,-10,11:18.14
12,-10,11:17.12
13,-10,11:18.6
14,-10,11:18.6
3,-9,11:18.14
5,-9,11:18.14
6,-9,11:18.14
7,-9,11:17.12
8,-9,11:18.14
9,-9,11:18.14
10,-9,11:18.14
11,-9,11:18.14
12,-9,11:18.6
13,-9,11:18.6
16,-9,11:18.6
2,-8,11:18.14
3,-8,11:18.14
6,-8,11:18.14
7,-8,11:17.12
8,-8,11:18.14
9,-8,11:18.14
10,-8,11:18.14
11,-8,11:18.14
13,-8,11:18.6
5,-7,11:18.14
6,-7,11:18.14
8,-7,11:18.14
9,-7,11:18.14
10,-7,11:18.14
11,-7,11:18.14
12,-7,11:18.6
5,-6,11:18.14
6,-6,11:18.14
8,-6,11:18.14
9,-6,11:18.14
10,-6,11:18.14
11,-6,11:18.14
12,-6,11:18.6
6,-5,11:18.14
9,-5,11:18.14
10,-5,11:18.14
11,-5,11:18.14
12,-5,11:18.6
7,-4,11:18.14
10,-4,11:18.14
11,-4,11:18.14
8,-3,11:18.6
11,-3,11:18.6
6,-16,12:18.6
6,-15,12:18.6
6,-14,12:18.6
5,-13,12:18.6
6,-13,12:18.6
7,-13,12:18.6
11,-13,12:18.6
5,-12,12:18.14
6,-12,12:18.14
7,-12,12:18.14
8,-12,12:18.14
12,-12,12:18.6
13,-12,12:18.6
14,-12,12:18.6
15,-12,12:18.6
5,-11,12:18.14
6,-11,12:18.14
7,-11,12:18.14
8,-11,12:18.14
9,-11,12:18.14
10,-11,12:18.14
14,-11,12:18.6
15,-11,12:18.6
16,-11,12:18.6
17,-11,12:18.6
4,-10,12:18.14
6,-10,12:18.14
8,-10,12:18.14
9,-10,12:18.14
10,-10,12:18.14
11,-10,12:18.14
12,-10,12:17.12
13,-10,12:18.6
14,-10,12:18.6
15,-10,12:18.6
16,-10,12:18.6
17,-10,12:18.6
3,-9,12:18.14
6,-9,12:18.14
7,-9,12:17.12
9,-9,12:18.14
10,-9,12:18.14
11,-9,12:18.14
12,-9,12:18.6
13,-9,12:18.6
14,-9,12:18.6
15,-9,12:18.6
16,-9,12:18.6
2,-8,12:18.14
4,-8,12:18.14
6,-8,12:18.14
7,-8,12:18.14
8,-8,12:18.14
9,-8,12:18.14
10,-8,12:18.14
11,-8,12:18.14
12,-8,12:18.6
13,-8,12:18.6
14,-8,12:18.6
5,-7,12:18.14
6,-7,12:18.14
7,-7,12:18.14
8,-7,12:18.14
9,-7,12:18.14
10,-7,12:18.14
12,-7,12:18.6
6,-6,12:18.14
7,-6,12:18.14
8,-6,12:18.14
9,-6,12:18.14
10,-6,12:18.14
11,-6,12:18.14
7,-5,12:18.14
8,-5,12:18.14
10,-5,12:18.14
11,-5,12:18.14
8,-4,12:18.14
9,-4,12:18.14
11,-4,12:18.14
9,-3,12:18.6
11,-3,12:18.6
6,-15,13:18.6
6,-13,13:18.6
12,-13,13:18.6
6,-12,13:18.14
7,-12,13:18.14
10,-12,13:18.14
11,-12,13:18.14
12,-12,13:18.6
14,-12,13:18.6
4,-11,13:18.14
5,-11,13:18.14
6,-11,13:18.14
7,-11,13:18.14
8,-11,13:18.14
9,-11,13:18.14
10,-11,13:18.14
11,-11,13:18.14
12,-11,13:18.6
13,-11,13:18.6
14,-11,13:18.6
15,-11,13:18.6
16,-11,13:18.6
17,-11,13:18.6
4,-10,13:18.14
6,-10,13:18.14
7,-10,13:18.14
8,-10,13:18.14
9,-10,13:18.14
10,-10,13:18.14
11,-10,13:18.14
12,-10,13:17.12
13,-10,13:18.6
14,-10,13:18.6
15,-10,13:18.6
3,-9,13:18.14
5,-9,13:18.14
6,-9,13:18.14
7,-9,13:18.14
8,-9,13:18.14
12,-9,13:18.6
13,-9,13:18.6
4,-8,13:18.14
5,-8,13:18.14
6,-8,13:18.14
7,-8,13:17.12
8,-8,13:18.14
9,-8,13:18.14
10,-8,13:18.14
11,-8,13:18.14
12,-8,13:18.6
13,-8,13:18.6
14,-8,13:18.6
4,-7,13:18.14
7,-7,13:18.14
8,-7,13:18.14
9,-7,13:18.14
10,-7,13:18.14
11,-7,13:18.14
8,-6,13:18.14
9,-6,13:18.14
10,-6,13:18.14
9,-5,13:18.14
10,-5,13:18.14
11,-5,13:18.14
8,-4,13:18.14
9,-4,13:18.14
10,-4,13:18.14
11,-4,13:18.14
6,-13,14:18.6
14,-13,14:18.6
6,-12,14:18.14
12,-12,14:18.6
13,-12,14:18.6
14,-12,14:18.6
7,-11,14:18.14
8,-11,14:18.14
9,-11,14:18.14
10,-11,14:18.14
11,-11,14:18.14
12,-11,14:18.6
13,-11,14:18.6
14,-11,14:18.6
15,-11,14:18.6
16,-11,14:18.6
6,-10,14:18.14
7,-10,14:18.14
8,-10,14:18.14
9,-10,14:18.14
10,-10,14:18.14
11,-10,14:18.14
12,-10,14:18.6
13,-10,14:18.6
6,-9,14:18.14
7,-9,14:18.14
8,-9,14:18.14
9,-9,14:18.14
10,-9,14:18.14
11,-9,14:18.14
12,-9,14:18.6
13,-9,14:18.6
5,-8,14:18.14
6,-8,14:18.14
7,-8,14:17.12
8,-8,14:18.14
9,-8,14:18.14
10,-8,14:18.14
11,-8,14:18.14
12,-8,14:18.6
5,-7,14:18.14
7,-7,14:18.14
8,-7,14:18.14
9,-7,14:18.14
10,-7,14:18.14
11,-7,14:18.14
12,-7,14:18.6
4,-6,14:18.14
8,-6,14:18.14
9,-6,14:18.14
10,-6,14:18.14
8,-5,14:18.14
9,-5,14:18.14
10,-5,14:18.14
7,-4,14:18.14
8,-4,14:18.14
4,-13,15:18.6
6,-13,15:18.6
14,-13,15:18.6
6,-12,15:18.14
13,-12,15:18.6
14,-12,15:18.6
4,-11,15:18.14
7,-11,15:18.14
11,-11,15:18.14
12,-11,15:18.6
13,-11,15:18.6
14,-11,15:18.6
15,-11,15:18.6
16,-11,15:18.6
7,-10,15:18.14
8,-10,15:18.14
9,-10,15:18.14
10,-10,15:18.14
11,-10,15:18.14
12,-10,15:18.6
6,-9,15:18.14
7,-9,15:18.14
8,-9,15:18.14
9,-9,15:18.14
10,-9,15:18.14
11,-9,15:18.14
12,-9,15:18.6
6,-8,15:18.14
7,-8,15:18.14
8,-8,15:18.14
9,-8,15:18.14
10,-8,15:18.14
11,-8,15:18.14
12,-8,15:18.6
5,-7,15:18.14
6,-7,15:18.14
8,-7,15:18.14
9,-7,15:18.14
5,-6,15:18.14
6,-6,15:18.14
7,-6,15:18.14
8,-6,15:18.14
6,-5,15:18.14
7,-5,15:18.14
6,-4,15:18.14
6,-3,15:18.6
6,-2,15:18.6
5,-15,16:18.6
8,-15,16:18.6
5,-14,16:18.6
8,-14,16:18.6
9,-14,16:18.6
4,-13,16:18.6
5,-13,16:18.6
8,-13,16:18.6
9,-13,16:18.6
4,-12,16:18.14
5,-12,16:18.14
6,-12,16:18.14
7,-12,16:18.14
9,-12,16:18.14
11,-12,16:18.14
13,-12,16:18.6
4,-11,16:18.14
5,-11,16:18.14
7,-11,16:18.14
8,-11,16:18.14
9,-11,16:18.14
12,-11,16:18.6
13,-11,16:18.6
4,-10,16:18.14
5,-10,16:18.14
7,-10,16:18.14
9,-10,16:18.14
10,-10,16:18.14
12,-10,16:18.6
13,-10,16:18.6
14,-10,16:18.6
15,-10,16:18.6
7,-9,16:18.14
8,-9,16:18.14
9,-9,16:18.14
10,-9,16:18.14
11,-9,16:18.14
12,-9,16:18.6
6,-8,16:17.12
7,-8,16:17.12
8,-8,16:18.14
9,-8,16:18.14
6,-7,16:18.14
7,-7,16:18.14
8,-7,16:18.14
9,-7,16:18.14
5,-6,16:18.14
6,-6,16:18.14
7,-6,16:18.14
10,-6,16:18.14
5,-5,16:18.14
6,-5,16:18.14
7,-5,16:18.14
10,-5,16:18.14
6,-4,16:18.14
7,-4,16:18.14
10,-4,16:18.14
6,-3,16:18.6
7,-3,16:18.6
10,-3,16:18.6
11,-3,16:18.6
6,-2,16:18.6
7,-2,16:18.6
11,-2,16:18.6
8,-15,17:18.6
5,-14,17:18.6
6,-14,17:18.6
7,-14,17:18.6
8,-14,17:18.6
5,-13,17:18.6
6,-13,17:18.6
7,-13,17:18.6
8,-13,17:18.6
5,-12,17:18.14
6,-12,17:18.14
7,-12,17:18.14
8,-12,17:18.14
11,-12,17:18.14
12,-12,17:18.6
13,-12,17:18.6
14,-12,17:18.6
5,-11,17:18.14
6,-11,17:18.14
7,-11,17:18.14
8,-11,17:18.14
12,-11,17:18.6
13,-11,17:18.6
5,-10,17:18.14
7,-10,17:18.14
8,-10,17:18.14
9,-10,17:18.14
10,-10,17:18.14
12,-10,17:18.6
14,-10,17:18.6
15,-10,17:18.6
3,-9,17:18.14
5,-9,17:18.14
7,-9,17:17.0
8,-9,17:18.14
9,-9,17:18.14
10,-9,17:18.14
11,-9,17:18.14
12,-9,17:18.6
3,-8,17:18.14
4,-8,17:18.14
5,-8,17:18.14
6,-8,17:17.0
7,-8,17:17.0
8,-8,17:18.14
4,-7,17:18.14
5,-7,17:18.14
6,-7,17:18.14
7,-7,17:18.14
9,-7,17:18.14
5,-6,17:18.14
6,-6,17:18.14
7,-6,17:18.14
9,-6,17:18.14
5,-5,17:18.14
6,-5,17:18.14
7,-5,17:18.14
9,-5,17:18.14
7,-4,17:18.14
9,-4,17:18.14
10,-4,17:18.14
7,-3,17:18.6
9,-3,17:18.6
10,-3,17:18.6
7,-2,17:18.6
9,-2,17:18.6
10,-2,17:18.6
7,-1,17:18.6
10,-1,17:18.6
6,-15,18:18.6
6,-14,18:18.6
7,-14,18:18.6
6,-13,18:18.6
7,-13,18:18.6
5,-12,18:18.14
6,-12,18:18.14
7,-12,18:18.14
11,-12,18:18.14
12,-12,18:18.6
5,-11,18:18.14
6,-11,18:18.14
7,-11,18:18.14
12,-11,18:18.6
13,-11,18:18.6
14,-11,18:18.6
6,-10,18:18.14
7,-10,18:18.14
8,-10,18:18.14
14,-10,18:18.6
15,-10,18:18.6
3,-9,18:18.14
4,-9,18:18.14
6,-9,18:18.14
7,-9,18:18.14
8,-9,18:18.14
9,-9,18:18.14
4,-8,18:18.14
5,-8,18:18.14
6,-8,18:18.14
7,-8,18:18.14
8,-8,18:18.14
9,-8,18:18.14
10,-8,18:18.14
11,-8,18:18.14
5,-7,18:18.14
6,-7,18:18.14
7,-7,18:18.14
8,-7,18:18.14
11,-7,18:18.14
5,-6,18:18.14
6,-6,18:18.14
7,-6,18:18.14
8,-6,18:18.14
7,-5,18:18.14
8,-5,18:18.14
8,-4,18:18.14
9,-4,18:18.14
8,-3,18:18.6
9,-3,18:18.6
8,-2,18:18.6
9,-2,18:18.6
8,-1,18:18.6
9,-1,18:18.6
6,-15,19:18.6
6,-14,19:18.6
6,-13,19:18.6
6,-12,19:18.14
11,-12,19:18.14
12,-12,19:18.6
13,-12,19:18.6
5,-11,19:18.14
6,-11,19:18.14
13,-11,19:18.6
14,-11,19:18.6
4,-10,19:18.14
5,-10,19:18.14
6,-10,19:18.14
15,-10,19:18.6
4,-9,19:18.14
5,-9,19:18.14
6,-9,19:18.14
7,-9,19:18.14
8,-9,19:18.14
5,-8,19:18.14
6,-8,19:18.14
7,-8,19:18.14
8,-8,19:18.14
9,-8,19:18.14
6,-7,19:18.14
7,-7,19:18.14
8,-7,19:18.14
9,-7,19:18.14
10,-7,19:18.14
6,-6,19:18.14
7,-6,19:18.14
8,-6,19:18.14
9,-6,19:18.14
8,-5,19:18.14
9,-5,19:18.14
8,-4,19:18.14
8,-3,19:18.6
8,-2,19:18.6
6,-13,20:18.6
6,-12,20:18.14
13,-12,20:18.6
4,-11,20:18.14
6,-11,20:18.14
4,-10,20:18.14
5,-10,20:18.14
6,-10,20:18.14
5,-9,20:18.14
6,-9,20:18.14
7,-8,20:18.14
8,-8,20:18.14
8,-7,20:18.14
9,-7,20:18.14
8,-6,20:18.14
9,-6,20:18.14
8,-5,20:18.14
8,-4,20:18.14
8,-3,20:18.6
8,-2,20:18.6
6,-13,21:18.6
6,-12,21:18.6
4,-11,21:18.6
6,-11,21:18.6
4,-10,21:18.6
5,-10,21:18.6
6,-10,21:18.6
8,-10,21:18.6
5,-9,21:18.6
6,-9,21:18.6
7,-9,21:18.6
6,-8,21:18.6
7,-8,21:18.6
6,-7,21:18.6
8,-7,21:18.6
9,-7,21:18.6
9,-6,21:18.6
8,-5,21:18.6
8,-4,21:18.6
8,-3,21:18.6
8,-2,21:18.6
8,-11,22:18.6
7,-10,22:18.6
8,-10,22:18.6
6,-9,22:18.6
7,-9,22:18.6
6,-8,22:18.6
7,-8,22:18.6
6,-7,22:18.6
8,-7,22:18.6
9,-7,22:18.6
5,-6,22:18.6
9,-6,22:18.6
8,-11,23:18.6
5,-10,23:18.6
7,-10,23:18.6
8,-10,23:18.6
6,-9,23:18.6
7,-9,23:18.6
6,-8,23:18.6
7,-8,23:18.6
6,-7,23:18.6
8,-7,23:18.6
5,-6,23:18.6
8,-11,24:18.6
7,-10,24:18.6
8,-10,24:18.6
7,-9,24:18.6
6,-8,24:18.6
7,-8,24:18.6
6,-7,24:18.6
5,-6,24:18.6
8,-11,25:18.6
7,-10,25:18.6
8,-10,25:18.6
7,-9,25:18.6
6,-8,25:18.6
7,-8,25:18.6
6,-7,25:18.6
5,-6,25:18.6
8,-10,26:18.6
7,-9,26:18.6
6,-8,26:18.6
6,-7,26:18.6
