[META]
version=2.0
spawnOnBlockType=2
spawnSunlight=True
spawnDarkness=True
spawnWater=False
spawnLava=False
underFill=False
randomRotation=True
dig=True
tree=False
branch=False
needsFoundation=True
rarity=100
collisionPercentage=20
spawnElevationMin=0
spawnElevationMax=200
spawnInBiome=Custom
[DATA]
-1,3,-8:17.12
0,3,-8:17.12
0,4,-8:17.12
-1,7,-8:17.12
0,3,-7:17.12
-1,4,-7:17.12
0,4,-7:17.12
-1,6,-7:17.12
-2,7,-7:17.12
-1,8,-7:17.12
-1,3,-6:17.12
0,3,-6:17.12
-2,4,-6:17.12
-1,4,-6:17.12
0,4,-6:17.12
-1,6,-6:17.12
-2,7,-6:17.12
-1,7,-6:17.12
0,7,-6:17.12
-2,8,-6:17.12
-1,8,-6:17.12
-2,3,-5:17.12
-1,3,-5:17.12
0,3,-5:17.12
-2,4,-5:17.12
-1,4,-5:17.12
0,4,-5:17.12
1,4,-5:17.12
-2,5,-5:17.12
-1,5,-5:17.12
0,5,-5:17.12
0,6,-5:17.12
-2,7,-5:17.12
-1,7,-5:17.12
-2,3,-4:17.12
-3,4,-4:17.12
-2,4,-4:17.12
-1,4,-4:17.12
-3,5,-4:17.12
-2,5,-4:17.12
-2,6,-4:17.12
-2,7,-4:17.12
-1,7,-4:17.12
-3,8,-4:17.12
-2,8,-4:17.12
-2,3,-3:17.12
-2,4,-3:17.12
-1,4,-3:17.12
-3,5,-3:17.12
-2,5,-3:17.12
-1,5,-3:17.12
-2,6,-3:17.12
-1,6,-3:17.12
-2,8,-3:17.12
-3,3,-2:17.12
-2,3,-2:17.12
-1,3,-2:17.12
-3,4,-2:17.12
-2,4,-2:17.12
-1,4,-2:17.12
0,4,-2:17.12
-4,5,-2:17.12
-3,5,-2:17.12
-2,5,-2:17.12
-1,5,-2:17.12
-3,6,-2:17.12
-2,6,-2:17.12
-1,6,-2:17.12
-3,3,-1:17.12
-2,3,-1:17.12
-1,3,-1:17.12
-3,4,-1:17.12
-1,4,-1:17.12
-3,5,-1:17.12
-1,5,-1:17.12
-3,6,-1:17.12
-2,6,-1:17.12
-1,6,-1:17.12
-3,3,0:17.12
-2,3,0:17.12
-1,3,0:17.12
-3,4,0:17.12
-1,4,0:17.12
-3,5,0:17.12
-2,5,0:17.12
-1,5,0:17.12
-2,6,0:17.12
-3,3,1:17.12
-2,3,1:17.12
-1,3,1:17.12
-3,4,1:17.12
-1,4,1:17.12
-3,5,1:17.12
-2,5,1:17.12
-1,5,1:17.12
-3,3,2:17.12
-2,3,2:17.12
-1,3,2:17.12
-3,4,2:17.12
-1,4,2:17.12
-2,5,2:17.12
-1,5,2:17.12
-3,3,3:17.12
-2,3,3:17.12
-1,3,3:17.12
-3,4,3:17.12
-1,4,3:17.12
-2,5,3:17.12
-1,5,3:17.12
-2,3,4:17.12
-1,3,4:17.12
-3,4,4:17.12
-1,4,4:17.12
-2,5,4:17.12
-1,5,4:17.12
1,-4,5:18.4
1,-3,5:18.4
0,-2,5:18.4
0,-1,5:18.12
0,0,5:18.12
-1,1,5:18.12
-1,2,5:18.12
-2,3,5:17.12
-1,3,5:18.12
-3,4,5:17.12
-2,4,5:18.12
-1,4,5:17.12
-7,5,5:18.4
-6,5,5:18.12
-5,5,5:18.12
-3,5,5:18.12
-2,5,5:17.12
-1,5,5:17.12
-9,6,5:18.4
-8,6,5:18.4
1,-4,6:18.4
1,-3,6:18.4
0,-2,6:18.4
0,-1,6:18.12
0,0,6:18.12
-1,1,6:18.12
-1,2,6:18.12
-2,3,6:17.12
-1,3,6:18.12
-3,4,6:17.12
-2,4,6:18.12
-1,4,6:17.12
-7,5,6:18.4
-6,5,6:18.12
-5,5,6:18.12
-4,5,6:18.12
-3,5,6:18.12
-2,5,6:17.12
-1,5,6:18.12
-11,6,6:18.4
-10,6,6:18.4
-9,6,6:18.4
-8,6,6:18.4
-7,6,6:18.4
-1,6,6:18.12
0,6,6:18.12
0,7,6:18.12
1,8,6:18.12
2,9,6:18.12
3,10,6:18.4
1,-4,7:18.4
1,-3,7:18.4
0,-2,7:18.4
0,-1,7:18.12
0,0,7:18.12
-1,1,7:18.12
-1,2,7:18.12
-2,3,7:17.12
-1,3,7:18.12
-2,4,7:17.12
-1,4,7:17.12
-6,5,7:18.12
-5,5,7:18.12
-4,5,7:18.12
-3,5,7:18.12
-2,5,7:17.12
-1,5,7:18.12
-10,6,7:18.4
-9,6,7:18.4
-8,6,7:18.4
-7,6,7:18.4
-1,6,7:18.12
0,6,7:18.12
0,7,7:18.12
1,8,7:18.12
2,9,7:18.12
3,10,7:18.4
3,11,7:18.4
4,12,7:18.4
1,-4,8:18.4
-2,-3,8:18.4
0,-3,8:18.4
1,-3,8:18.4
2,-3,8:18.4
0,-2,8:18.4
0,-1,8:18.12
0,0,8:18.12
-1,1,8:18.12
-1,2,8:18.12
-2,3,8:18.12
-1,3,8:18.12
-2,4,8:17.12
-6,5,8:18.12
-5,5,8:18.12
-4,5,8:18.12
-3,5,8:18.12
-2,5,8:17.12
-1,5,8:18.12
-11,6,8:18.4
-10,6,8:18.4
-9,6,8:18.4
-8,6,8:18.4
-7,6,8:18.4
-1,6,8:18.12
0,6,8:18.12
-11,7,8:18.4
0,7,8:18.12
1,8,8:18.12
2,9,8:18.12
2,10,8:18.4
3,10,8:18.4
3,11,8:18.4
4,12,8:18.4
-6,-3,9:18.4
-5,-3,9:18.4
-4,-3,9:18.4
-3,-3,9:18.4
-2,-3,9:18.4
-1,-3,9:18.4
0,-3,9:18.4
1,-3,9:18.4
-7,-2,9:18.4
-6,-2,9:18.4
-5,-2,9:18.4
-4,-2,9:18.4
-3,-2,9:18.4
-2,-2,9:18.4
-1,-2,9:18.4
0,-2,9:18.4
1,-2,9:18.4
2,-2,9:18.4
-8,-1,9:18.4
-7,-1,9:18.4
-6,-1,9:18.12
-5,-1,9:18.12
-4,-1,9:18.12
-3,-1,9:18.12
-2,-1,9:18.12
-1,-1,9:18.12
0,-1,9:18.12
1,-1,9:18.12
2,-1,9:18.12
3,-1,9:18.4
-9,0,9:18.4
-8,0,9:18.4
-7,0,9:18.4
-6,0,9:18.12
-5,0,9:18.12
-4,0,9:18.12
-3,0,9:18.12
-2,0,9:18.12
-1,0,9:18.12
0,0,9:18.12
1,0,9:18.12
2,0,9:18.12
4,0,9:18.4
-9,1,9:18.4
-8,1,9:18.4
-7,1,9:18.4
-6,1,9:18.12
-4,1,9:18.12
-3,1,9:18.12
-2,1,9:18.12
-1,1,9:18.12
0,1,9:18.12
1,1,9:18.12
2,1,9:18.12
3,1,9:18.4
4,1,9:18.4
5,1,9:18.4
-10,2,9:18.4
-9,2,9:18.4
-8,2,9:18.4
-7,2,9:18.4
-1,2,9:18.12
1,2,9:18.12
2,2,9:18.12
3,2,9:18.4
4,2,9:18.4
5,2,9:18.4
6,2,9:18.4
-10,3,9:18.4
-9,3,9:18.4
-8,3,9:18.4
-7,3,9:18.4
-1,3,9:18.12
2,3,9:18.12
3,3,9:18.4
4,3,9:18.4
5,3,9:18.4
6,3,9:18.4
-10,4,9:18.4
-9,4,9:18.4
-8,4,9:18.4
-2,4,9:17.12
3,4,9:18.4
4,4,9:18.4
5,4,9:18.4
6,4,9:18.4
-11,5,9:18.4
-10,5,9:18.4
-9,5,9:18.4
-8,5,9:18.4
-6,5,9:18.12
-5,5,9:18.12
-4,5,9:18.12
-3,5,9:18.12
-2,5,9:17.12
-1,5,9:18.12
3,5,9:18.4
4,5,9:18.4
5,5,9:18.4
6,5,9:18.4
-11,6,9:18.4
-10,6,9:18.4
-9,6,9:18.4
-8,6,9:18.4
-7,6,9:18.4
-1,6,9:18.12
0,6,9:18.12
3,6,9:18.4
4,6,9:18.4
5,6,9:18.4
6,6,9:18.4
-11,7,9:18.4
-10,7,9:18.4
-9,7,9:18.4
-8,7,9:18.4
0,7,9:18.12
3,7,9:18.4
4,7,9:18.4
5,7,9:18.4
6,7,9:18.4
-10,8,9:18.4
-8,8,9:18.4
1,8,9:18.12
2,8,9:18.12
3,8,9:18.4
4,8,9:18.4
5,8,9:18.4
-9,9,9:18.4
-8,9,9:18.4
2,9,9:18.12
3,9,9:18.4
4,9,9:18.4
5,9,9:18.4
-9,10,9:18.4
-8,10,9:18.4
2,10,9:18.4
3,10,9:18.4
4,10,9:18.4
5,10,9:18.4
-8,11,9:18.4
0,11,9:18.4
1,11,9:18.4
2,11,9:18.4
3,11,9:18.4
-1,12,9:18.4
0,12,9:18.4
1,12,9:18.4
2,12,9:18.4
3,12,9:18.4
4,12,9:18.4
-2,13,9:18.4
-1,13,9:18.4
0,13,9:18.4
1,13,9:18.4
0,-2,10:18.4
-7,-1,10:18.4
-6,-1,10:18.12
-5,-1,10:18.12
-4,-1,10:18.12
-3,-1,10:18.12
-2,-1,10:18.12
-1,-1,10:18.12
0,-1,10:18.12
-7,0,10:18.4
-6,0,10:18.12
-5,0,10:18.12
-4,0,10:18.12
-3,0,10:18.12
-2,0,10:18.12
-1,0,10:18.12
0,0,10:18.12
1,0,10:18.12
2,0,10:18.12
-8,1,10:18.4
-7,1,10:18.4
-6,1,10:18.12
-5,1,10:18.12
-4,1,10:18.12
-3,1,10:18.12
-2,1,10:18.12
-1,1,10:18.12
0,1,10:18.12
1,1,10:18.12
2,1,10:18.12
3,1,10:18.4
-8,2,10:18.4
-7,2,10:18.4
-6,2,10:18.12
-5,2,10:18.12
-4,2,10:18.12
-3,2,10:18.12
-2,2,10:18.12
-1,2,10:18.12
0,2,10:18.12
1,2,10:18.12
2,2,10:18.12
3,2,10:18.4
4,2,10:18.4
-9,3,10:18.4
-8,3,10:18.4
-7,3,10:18.4
-5,3,10:18.12
-4,3,10:18.12
-3,3,10:18.12
-2,3,10:18.12
-1,3,10:18.12
0,3,10:18.12
1,3,10:18.12
2,3,10:18.12
3,3,10:18.4
4,3,10:18.4
5,3,10:18.4
-9,4,10:18.4
-8,4,10:18.4
-7,4,10:18.4
-6,4,10:18.12
-5,4,10:18.12
-4,4,10:18.12
-3,4,10:18.12
-2,4,10:18.12
-1,4,10:18.12
0,4,10:18.12
1,4,10:18.12
2,4,10:18.12
3,4,10:18.4
4,4,10:18.4
5,4,10:18.4
-9,5,10:18.4
-8,5,10:18.4
-7,5,10:18.4
-6,5,10:18.12
-5,5,10:18.12
-4,5,10:18.12
-3,5,10:18.12
-2,5,10:18.12
-1,5,10:18.12
0,5,10:18.12
1,5,10:18.12
2,5,10:18.12
3,5,10:18.4
4,5,10:18.4
5,5,10:18.4
-10,6,10:18.4
-9,6,10:18.4
-8,6,10:18.4
-7,6,10:18.4
-6,6,10:18.12
-5,6,10:18.12
-4,6,10:18.12
-2,6,10:18.12
-1,6,10:18.12
0,6,10:18.12
1,6,10:18.12
2,6,10:18.12
3,6,10:18.4
4,6,10:18.4
-10,7,10:18.4
-9,7,10:18.4
-8,7,10:18.4
-7,7,10:18.4
-6,7,10:18.12
-5,7,10:18.12
-4,7,10:18.12
-3,7,10:18.12
-2,7,10:18.12
-1,7,10:18.12
0,7,10:18.12
1,7,10:18.12
2,7,10:18.12
3,7,10:18.4
4,7,10:18.4
-8,8,10:18.4
-7,8,10:18.4
-6,8,10:18.12
-5,8,10:18.12
-4,8,10:18.12
-3,8,10:18.12
-2,8,10:18.12
-1,8,10:18.12
0,8,10:18.12
1,8,10:18.12
2,8,10:18.12
3,8,10:18.4
4,8,10:18.4
-8,9,10:18.4
-7,9,10:18.4
-6,9,10:18.12
-5,9,10:18.12
-4,9,10:18.12
-3,9,10:18.12
-2,9,10:18.12
-1,9,10:18.12
0,9,10:18.12
1,9,10:18.12
2,9,10:18.12
3,9,10:18.4
-8,10,10:18.4
-7,10,10:18.4
-6,10,10:18.4
-5,10,10:18.4
-4,10,10:18.4
-3,10,10:18.4
-2,10,10:18.4
-1,10,10:18.4
0,10,10:18.4
1,10,10:18.4
2,10,10:18.4
3,10,10:18.4
-7,11,10:18.4
-6,11,10:18.4
-5,11,10:18.4
-4,11,10:18.4
-3,11,10:18.4
-2,11,10:18.4
-1,11,10:18.4
0,11,10:18.4
1,11,10:18.4
2,11,10:18.4
3,11,10:18.4
-7,12,10:18.4
-6,12,10:18.4
-5,12,10:18.4
-4,12,10:18.4
-3,12,10:18.4
-2,12,10:18.4
-1,12,10:18.4
0,12,10:18.4
1,12,10:18.4
-6,13,10:18.4
-5,13,10:18.4
-4,13,10:18.4
-3,13,10:18.4
-2,13,10:18.4
0,-2,11:18.4
0,-1,11:18.12
-1,0,11:18.12
0,0,11:18.12
-5,1,11:18.12
-4,1,11:18.12
-3,1,11:18.12
-2,1,11:18.12
-1,1,11:18.12
0,1,11:18.12
-6,2,11:18.12
-5,2,11:18.12
-4,2,11:18.12
-3,2,11:18.12
-2,2,11:18.12
-1,2,11:18.12
0,2,11:18.12
1,2,11:18.12
-5,3,11:18.12
-4,3,11:18.12
-2,3,11:18.12
-1,3,11:18.12
0,3,11:18.12
1,3,11:18.12
2,3,11:18.12
-7,4,11:18.4
-6,4,11:18.12
-5,4,11:18.12
-2,4,11:18.12
1,4,11:18.12
2,4,11:18.12
3,4,11:18.4
-9,5,11:18.4
-8,5,11:18.4
-7,5,11:18.4
-6,5,11:18.12
-5,5,11:18.12
-4,5,11:18.12
-3,5,11:18.12
-2,5,11:18.12
-1,5,11:18.12
1,5,11:18.12
2,5,11:18.12
-9,6,11:18.4
-8,6,11:18.4
-7,6,11:18.4
-6,6,11:18.12
-5,6,11:18.12
-1,6,11:18.12
0,6,11:18.12
1,6,11:18.12
2,6,11:18.12
-7,7,11:18.4
-6,7,11:18.12
-5,7,11:18.12
-4,7,11:18.12
-1,7,11:18.12
0,7,11:18.12
1,7,11:18.12
2,7,11:18.12
-6,8,11:18.12
-5,8,11:18.12
-4,8,11:18.12
-3,8,11:18.12
-2,8,11:18.12
-1,8,11:18.12
0,8,11:18.12
1,8,11:18.12
-5,9,11:18.12
-4,9,11:18.12
-3,9,11:18.12
-2,9,11:18.12
-1,9,11:18.12
0,9,11:18.12
1,9,11:18.12
2,9,11:18.12
-5,10,11:18.4
-4,10,11:18.4
-3,10,11:18.4
-2,10,11:18.4
-1,10,11:18.4
2,10,11:18.4
-4,11,11:18.4
0,-1,12:18.4
-5,0,12:18.12
0,0,12:18.12
-5,1,12:18.12
-4,1,12:18.12
-1,1,12:18.12
-4,2,12:18.12
-3,2,12:18.12
-1,2,12:18.12
-4,3,12:18.12
-3,3,12:18.12
-2,3,12:18.12
-1,3,12:18.12
-4,4,12:18.12
-3,4,12:18.12
-2,4,12:18.12
-1,4,12:18.12
0,4,12:18.12
2,4,12:18.12
3,4,12:18.4
4,4,12:18.4
5,4,12:18.4
-8,5,12:18.4
-7,5,12:18.4
-6,5,12:18.12
-5,5,12:18.12
-4,5,12:18.12
-3,5,12:18.12
-2,5,12:18.12
-1,5,12:18.12
0,5,12:18.12
1,5,12:18.12
-4,6,12:18.12
-2,6,12:18.12
-1,6,12:18.12
0,6,12:18.12
-4,7,12:18.12
-3,7,12:18.12
-2,7,12:18.12
-1,7,12:18.12
0,7,12:18.12
-3,8,12:18.12
1,8,12:18.12
-4,9,12:18.12
1,9,12:18.12
2,9,12:18.12
0,-1,13:18.4
-5,0,13:18.12
0,0,13:18.12
-5,1,13:18.12
-4,1,13:18.12
-1,1,13:18.12
-4,2,13:18.12
-1,2,13:18.12
-3,3,13:18.12
-1,3,13:18.12
-7,4,13:18.4
-6,4,13:18.12
-5,4,13:18.12
-4,4,13:18.12
-3,4,13:18.12
-2,4,13:18.12
2,4,13:18.12
3,4,13:18.4
4,4,13:18.4
-2,5,13:18.12
-1,5,13:18.12
0,5,13:18.12
1,5,13:18.12
-2,6,13:18.12
-1,6,13:18.12
-3,7,13:18.12
0,7,13:18.12
-4,8,13:18.12
-3,8,13:18.12
1,8,13:18.12
-4,9,13:18.12
-5,10,13:18.4
-6,-1,14:18.4
-4,-1,14:18.4
-2,-1,14:18.4
-5,0,14:18.4
1,0,14:18.4
-5,1,14:18.4
-4,1,14:18.4
1,1,14:18.4
2,1,14:18.4
-4,2,14:18.4
2,2,14:18.4
3,2,14:18.4
-3,3,14:18.4
2,3,14:18.4
3,3,14:18.4
-2,4,14:18.4
2,4,14:18.4
3,4,14:18.4
4,4,14:18.4
-2,5,14:18.4
-1,5,14:18.4
0,5,14:18.4
1,5,14:18.4
2,5,14:18.4
3,5,14:18.4
4,5,14:18.4
-2,6,14:18.4
2,6,14:18.4
3,6,14:18.4
-3,7,14:18.4
2,7,14:18.4
3,7,14:18.4
-4,8,14:18.4
-3,8,14:18.4
2,8,14:18.4
-4,9,14:18.4
1,9,14:18.4
2,9,14:18.4
-5,10,14:18.4
-1,10,14:18.4
0,10,14:18.4
-5,-1,15:18.4
-4,-1,15:18.4
-3,-1,15:18.4
-2,-1,15:18.4
-1,-1,15:18.4
0,-1,15:18.4
-6,0,15:18.4
-5,0,15:18.4
-4,0,15:18.4
-3,0,15:18.4
-2,0,15:18.4
-1,0,15:18.4
0,0,15:18.4
1,0,15:18.4
-7,1,15:18.4
-6,1,15:18.4
-5,1,15:18.4
-4,1,15:18.4
-3,1,15:18.4
-2,1,15:18.4
-1,1,15:18.4
0,1,15:18.4
1,1,15:18.4
-7,2,15:18.4
-6,2,15:18.4
-5,2,15:18.4
-4,2,15:18.4
-3,2,15:18.4
-2,2,15:18.4
-1,2,15:18.4
0,2,15:18.4
1,2,15:18.4
2,2,15:18.4
-8,3,15:18.4
-7,3,15:18.4
-5,3,15:18.4
-4,3,15:18.4
-3,3,15:18.4
-2,3,15:18.4
-1,3,15:18.4
0,3,15:18.4
1,3,15:18.4
2,3,15:18.4
-8,4,15:18.4
-7,4,15:18.4
-6,4,15:18.4
-5,4,15:18.4
-4,4,15:18.4
-3,4,15:18.4
-2,4,15:18.4
-1,4,15:18.4
0,4,15:18.4
1,4,15:18.4
2,4,15:18.4
3,4,15:18.4
-8,5,15:18.4
-7,5,15:18.4
-6,5,15:18.4
-5,5,15:18.4
-4,5,15:18.4
-3,5,15:18.4
-2,5,15:18.4
-1,5,15:18.4
0,5,15:18.4
1,5,15:18.4
2,5,15:18.4
3,5,15:18.4
-8,6,15:18.4
-7,6,15:18.4
-6,6,15:18.4
-5,6,15:18.4
-4,6,15:18.4
-2,6,15:18.4
-1,6,15:18.4
0,6,15:18.4
1,6,15:18.4
2,6,15:18.4
-8,7,15:18.4
-7,7,15:18.4
-6,7,15:18.4
-5,7,15:18.4
-4,7,15:18.4
-3,7,15:18.4
-2,7,15:18.4
-1,7,15:18.4
0,7,15:18.4
1,7,15:18.4
2,7,15:18.4
-7,8,15:18.4
-6,8,15:18.4
-5,8,15:18.4
-4,8,15:18.4
-3,8,15:18.4
-2,8,15:18.4
-1,8,15:18.4
0,8,15:18.4
1,8,15:18.4
2,8,15:18.4
-6,9,15:18.4
-5,9,15:18.4
-4,9,15:18.4
-3,9,15:18.4
-2,9,15:18.4
-1,9,15:18.4
0,9,15:18.4
1,9,15:18.4
-5,10,15:18.4
-4,10,15:18.4
-3,10,15:18.4
-2,10,15:18.4
-1,10,15:18.4
0,10,15:18.4
1,10,15:18.4
-1,0,16:18.4
-4,1,16:18.4
-1,1,16:18.4
-5,2,16:18.4
-4,2,16:18.4
-3,2,16:18.4
-2,2,16:18.4
-1,2,16:18.4
0,2,16:18.4
-5,3,16:18.4
-4,3,16:18.4
-3,3,16:18.4
-2,3,16:18.4
-1,3,16:18.4
0,3,16:18.4
-6,4,16:18.4
-5,4,16:18.4
-4,4,16:18.4
-3,4,16:18.4
-2,4,16:18.4
-1,4,16:18.4
0,4,16:18.4
1,4,16:18.4
2,4,16:18.4
3,4,16:18.4
-7,5,16:18.4
-6,5,16:18.4
-5,5,16:18.4
-4,5,16:18.4
-2,5,16:18.4
-1,5,16:18.4
0,5,16:18.4
1,5,16:18.4
-6,6,16:18.4
-5,6,16:18.4
-4,6,16:18.4
-2,6,16:18.4
-1,6,16:18.4
0,6,16:18.4
-5,7,16:18.4
-4,7,16:18.4
-3,7,16:18.4
-2,7,16:18.4
-1,7,16:18.4
0,7,16:18.4
-4,8,16:18.4
-3,8,16:18.4
-2,8,16:18.4
-1,8,16:18.4
-4,9,16:18.4
-1,0,17:18.4
-3,1,17:18.4
-1,1,17:18.4
-3,2,17:18.4
-1,2,17:18.4
-3,3,17:18.4
-2,3,17:18.4
-4,4,17:18.4
-3,4,17:18.4
-2,4,17:18.4
-1,4,17:18.4
-6,5,17:18.4
-5,5,17:18.4
-4,5,17:18.4
-3,5,17:18.4
-2,5,17:18.4
-1,5,17:18.4
0,5,17:18.4
1,5,17:18.4
2,5,17:18.4
-2,6,17:18.4
-1,6,17:18.4
0,6,17:18.4
-3,7,17:18.4
0,7,17:18.4
-4,8,17:18.4
-2,0,18:18.4
-1,0,18:18.4
-4,1,18:18.4
-3,1,18:18.4
-2,1,18:18.4
-1,1,18:18.4
0,1,18:18.4
-1,2,18:18.4
0,2,18:18.4
1,2,18:18.4
-2,3,18:18.4
-4,4,18:18.4
-3,4,18:18.4
-2,4,18:18.4
-6,5,18:18.4
-5,5,18:18.4
-4,5,18:18.4
-1,5,18:18.4
-1,6,18:18.4
0,6,18:18.4
-3,7,18:18.4
0,7,18:18.4
1,7,18:18.4
1,8,18:18.4
-5,1,19:18.4
-4,1,19:18.4
-3,1,19:18.4
-2,1,19:18.4
-1,1,19:18.4
-5,2,19:18.4
-4,2,19:18.4
-3,2,19:18.4
-2,2,19:18.4
-1,2,19:18.4
0,2,19:18.4
-5,3,19:18.4
-4,3,19:18.4
-3,3,19:18.4
-2,3,19:18.4
-1,3,19:18.4
0,3,19:18.4
1,3,19:18.4
-6,4,19:18.4
-5,4,19:18.4
-4,4,19:18.4
-3,4,19:18.4
-2,4,19:18.4
-1,4,19:18.4
0,4,19:18.4
1,4,19:18.4
2,4,19:18.4
-6,5,19:18.4
-5,5,19:18.4
-4,5,19:18.4
-3,5,19:18.4
-2,5,19:18.4
-1,5,19:18.4
0,5,19:18.4
1,5,19:18.4
2,5,19:18.4
-6,6,19:18.4
-5,6,19:18.4
-4,6,19:18.4
-2,6,19:18.4
-1,6,19:18.4
0,6,19:18.4
1,6,19:18.4
-5,7,19:18.4
-4,7,19:18.4
-3,7,19:18.4
-2,7,19:18.4
-1,7,19:18.4
0,7,19:18.4
1,7,19:18.4
-4,8,19:18.4
-3,8,19:18.4
-2,8,19:18.4
-1,8,19:18.4
0,8,19:18.4
-1,1,20:18.4
-1,2,20:18.4
-3,3,20:18.4
-2,3,20:18.4
-1,3,20:18.4
-5,4,20:18.4
-4,4,20:18.4
-3,4,20:18.4
-2,4,20:18.4
-1,4,20:18.4
0,4,20:18.4
-4,5,20:18.4
-3,5,20:18.4
-2,5,20:18.4
-1,5,20:18.4
-2,6,20:18.4
-1,6,20:18.4
0,6,20:18.4
