[META]
version=2.0
spawnOnBlockType=2
spawnSunlight=True
spawnDarkness=True
spawnWater=False
spawnLava=False
underFill=False
randomRotation=True
dig=True
tree=False
branch=False
needsFoundation=True
rarity=100
collisionPercentage=20
spawnElevationMin=0
spawnElevationMax=200
spawnInBiome=Custom
[DATA]
-10,-6,-4:17.12
-9,-5,-4:17.12
-4,-5,-4:17.12
-8,-4,-4:17.12
-7,-4,-4:17.12
-6,-4,-4:17.12
-4,-4,-4:17.12
3,-4,-4:17.12
-8,-3,-4:17.12
-7,-3,-4:17.12
-5,-3,-4:17.12
1,-3,-4:17.12
-8,-2,-4:17.12
-7,-2,-4:17.12
-6,-2,-4:17.12
-4,-2,-4:17.12
-3,-2,-4:17.12
-1,-2,-4:17.12
-10,-1,-4:17.12
-9,-1,-4:17.12
-8,-1,-4:17.12
-7,-1,-4:17.12
-6,-1,-4:17.12
-5,-1,-4:17.12
-4,-1,-4:17.12
-3,-1,-4:17.12
-6,0,-4:17.12
-4,0,-4:17.12
-3,0,-4:17.12
-1,0,-4:17.12
3,0,-4:17.12
-4,1,-4:17.12
-2,1,-4:17.12
-1,1,-4:17.12
-5,2,-4:17.12
0,2,-4:17.12
1,2,-4:17.12
-5,3,-4:17.12
3,3,-4:17.12
2,4,-4:17.12
-6,5,-4:17.12
-10,-7,-3:17.12
-11,-6,-3:17.12
-10,-6,-3:17.12
-9,-6,-3:17.12
-4,-6,-3:17.12
-10,-5,-3:17.12
-9,-5,-3:17.12
-8,-5,-3:17.12
-5,-5,-3:17.12
-4,-5,-3:17.12
-1,-5,-3:17.12
3,-5,-3:17.12
-9,-4,-3:17.12
-8,-4,-3:17.12
-6,-4,-3:17.12
-5,-4,-3:17.12
-4,-4,-3:17.12
-3,-4,-3:17.12
-2,-4,-3:17.12
3,-4,-3:17.12
4,-4,-3:17.12
-9,-3,-3:17.12
-8,-3,-3:17.12
-7,-3,-3:17.12
-6,-3,-3:17.12
-5,-3,-3:17.12
-4,-3,-3:17.12
-3,-3,-3:17.12
-2,-3,-3:17.12
-1,-3,-3:17.12
0,-3,-3:17.12
1,-3,-3:17.12
2,-3,-3:17.12
3,-3,-3:17.12
-10,-2,-3:17.12
-9,-2,-3:17.12
-8,-2,-3:17.12
-7,-2,-3:17.12
-6,-2,-3:17.12
-5,-2,-3:17.12
-4,-2,-3:17.12
-3,-2,-3:17.12
-2,-2,-3:17.12
-1,-2,-3:17.12
0,-2,-3:17.12
1,-2,-3:17.12
-11,-1,-3:17.12
-10,-1,-3:17.12
-9,-1,-3:17.12
-8,-1,-3:17.12
-7,-1,-3:17.12
-6,-1,-3:17.12
-5,-1,-3:17.12
-4,-1,-3:17.12
-3,-1,-3:17.12
-2,-1,-3:17.12
-1,-1,-3:17.12
3,-1,-3:17.12
-10,0,-3:17.12
-8,0,-3:17.12
-7,0,-3:17.12
-6,0,-3:17.12
-5,0,-3:17.12
-4,0,-3:17.12
-3,0,-3:17.12
-2,0,-3:17.12
-1,0,-3:17.12
0,0,-3:17.12
2,0,-3:17.12
3,0,-3:17.12
4,0,-3:17.12
-6,1,-3:17.12
-5,1,-3:17.12
-4,1,-3:17.12
-3,1,-3:17.12
-2,1,-3:17.12
-1,1,-3:17.12
0,1,-3:17.12
1,1,-3:17.12
3,1,-3:17.12
-6,2,-3:17.12
-5,2,-3:17.12
-4,2,-3:17.12
-2,2,-3:17.12
-1,2,-3:17.12
0,2,-3:17.12
1,2,-3:17.12
2,2,-3:17.12
-5,3,-3:17.12
-4,3,-3:17.12
0,3,-3:17.12
1,3,-3:17.12
4,3,-3:17.12
-5,4,-3:17.12
1,4,-3:17.12
2,4,-3:17.12
3,4,-3:17.12
-7,5,-3:17.12
-6,5,-3:17.12
-5,5,-3:17.12
2,5,-3:17.12
-6,6,-3:17.12
-9,-6,-2:17.12
-8,-5,-2:17.12
-4,-5,-2:17.12
-9,-4,-2:17.12
-8,-4,-2:17.12
-4,-4,-2:17.12
-2,-4,-2:17.12
3,-4,-2:17.12
-8,-3,-2:17.12
-6,-3,-2:17.12
-5,-3,-2:17.12
-4,-3,-2:17.12
1,-3,-2:17.12
-8,-2,-2:17.12
-7,-2,-2:17.12
-6,-2,-2:17.12
-5,-2,-2:17.12
-4,-2,-2:17.12
-3,-2,-2:17.12
-2,-2,-2:17.12
-1,-2,-2:17.12
-10,-1,-2:17.12
-9,-1,-2:17.12
-7,-1,-2:17.12
-6,-1,-2:17.12
-5,-1,-2:17.12
-4,-1,-2:17.12
-3,-1,-2:17.12
-2,-1,-2:17.12
-1,-1,-2:17.12
-6,0,-2:17.12
-5,0,-2:17.12
-4,0,-2:17.12
-3,0,-2:17.12
-2,0,-2:17.12
-1,0,-2:17.12
3,0,-2:17.12
-5,1,-2:17.12
-4,1,-2:17.12
-2,1,-2:17.12
-1,1,-2:17.12
0,1,-2:17.12
-5,2,-2:17.12
-1,2,-2:17.12
0,2,-2:17.12
1,2,-2:17.12
1,4,-2:17.12
-6,5,-2:17.12
2,5,-2:17.12
-5,-3,-1:17.12
-8,-2,-1:17.12
-7,-2,-1:17.12
-6,-2,-1:17.12
-5,-2,-1:17.12
-4,-2,-1:17.12
-2,-2,-1:17.12
-6,-1,-1:17.12
-5,-1,-1:17.12
-4,-1,-1:17.12
-3,-1,-1:17.12
-2,-1,-1:17.12
-1,-1,-1:17.12
-5,0,-1:17.12
-4,0,-1:17.12
-3,0,-1:17.12
-2,0,-1:17.12
-1,1,-1:17.12
-5,-2,0:17.12
-4,-2,0:17.12
-3,-2,0:17.12
-2,-2,0:17.12
-4,-1,0:17.12
-3,-1,0:17.12
-2,-1,0:17.12
-3,0,0:17.12
-2,0,0:17.12
-1,0,0:17.12
-2,1,0:17.12
-3,-2,1:17.12
-4,-1,1:17.12
-3,-1,1:17.12
-2,-1,1:17.12
-3,0,1:17.12
-2,0,1:17.12
-1,0,1:17.12
-2,1,1:17.12
-1,1,1:17.12
-3,-1,2:17.12
-2,-1,2:17.12
-3,0,2:17.12
-2,0,2:17.12
-1,0,2:17.12
-2,1,2:17.12
-1,1,2:17.12
0,1,2:17.12
-1,2,2:17.12
2,-9,3:18.12
2,-7,3:18.12
-2,0,3:17.12
-1,0,3:17.12
-2,1,3:17.12
-1,1,3:17.12
0,1,3:17.12
-2,2,3:17.12
-1,2,3:17.12
0,2,3:17.12
-1,3,3:17.12
2,-9,4:18.12
2,-8,4:18.12
3,-8,4:18.12
2,-7,4:18.12
2,-6,4:18.12
-1,0,4:17.12
-2,1,4:17.12
-1,1,4:17.12
0,1,4:17.12
-2,2,4:17.12
-1,2,4:17.12
0,2,4:17.12
-2,3,4:17.12
-1,3,4:17.12
0,3,4:17.12
-1,4,4:17.12
1,-10,5:18.12
-6,-9,5:18.12
0,-9,5:18.12
1,-9,5:18.12
2,-9,5:18.12
3,-9,5:18.12
4,-9,5:18.12
1,-8,5:18.12
2,-8,5:18.12
3,-8,5:18.12
2,-7,5:18.12
3,-7,5:18.12
1,-6,5:18.12
2,-6,5:18.12
-2,-1,5:18.12
-2,0,5:18.12
-1,1,5:17.12
0,1,5:17.12
-2,2,5:17.12
-1,2,5:17.12
0,2,5:17.12
-1,3,5:17.12
0,3,5:17.12
-2,4,5:18.12
1,-12,6:18.12
1,-11,6:18.12
-7,-10,6:18.12
0,-10,6:18.12
1,-10,6:18.12
3,-10,6:18.12
4,-10,6:18.12
-6,-9,6:18.12
-2,-9,6:18.12
-1,-9,6:18.12
0,-9,6:18.12
2,-9,6:18.12
3,-9,6:18.12
-2,-8,6:18.12
-1,-8,6:18.12
3,-8,6:18.12
-12,-7,6:18.12
-10,-5,6:18.12
-10,-4,6:18.12
-10,-3,6:18.12
-9,-3,6:18.12
-10,-2,6:18.12
-4,-2,6:18.12
-1,-2,6:18.12
0,-2,6:18.12
-9,-1,6:18.12
-2,-1,6:18.12
-1,-1,6:18.12
0,1,6:17.12
2,1,6:17.12
-1,2,6:17.12
0,2,6:17.12
1,2,6:17.12
2,2,6:17.12
0,3,6:17.12
1,3,6:17.12
-2,4,6:18.12
-1,4,6:18.12
-8,-13,7:18.12
-7,-12,7:18.12
0,-12,7:18.12
-9,-11,7:18.12
-8,-11,7:18.12
-7,-11,7:18.12
-6,-11,7:18.12
-3,-11,7:18.12
0,-11,7:18.12
2,-11,7:18.12
4,-11,7:18.12
-8,-10,7:18.12
-7,-10,7:18.12
-6,-10,7:18.12
-5,-10,7:18.12
0,-10,7:18.12
1,-10,7:18.12
2,-10,7:18.12
3,-10,7:18.12
4,-10,7:18.12
5,-10,7:18.12
6,-10,7:18.12
-9,-9,7:18.12
-8,-9,7:18.12
-7,-9,7:18.12
-6,-9,7:18.12
-5,-9,7:18.12
-4,-9,7:18.12
-3,-9,7:18.12
0,-9,7:18.12
-8,-8,7:18.12
-7,-8,7:18.12
-6,-8,7:18.12
-3,-8,7:18.12
-2,-8,7:18.12
-12,-7,7:18.12
-11,-7,7:18.12
-9,-7,7:18.12
-6,-7,7:18.12
-2,-7,7:18.12
4,-7,7:18.12
5,-7,7:18.12
-12,-6,7:18.12
-10,-6,7:18.12
6,-6,7:18.12
-12,-5,7:18.12
-10,-5,7:18.12
-9,-5,7:18.12
-8,-5,7:18.12
-13,-4,7:18.12
-12,-4,7:18.12
-11,-4,7:18.12
-10,-4,7:18.12
-9,-4,7:18.12
-8,-4,7:18.12
-7,-4,7:18.12
-11,-3,7:18.12
-10,-3,7:18.12
-9,-3,7:18.12
-8,-3,7:18.12
-7,-3,7:18.12
-1,-3,7:18.12
0,-3,7:17.12
1,-3,7:17.12
9,-3,7:18.12
-10,-2,7:18.12
-9,-2,7:18.12
-5,-2,7:18.12
-4,-2,7:18.12
-1,-2,7:18.12
0,-2,7:18.12
-9,-1,7:18.12
-2,-1,7:18.12
-1,-1,7:18.12
0,-1,7:17.12
5,-1,7:18.12
-10,0,7:18.12
-9,0,7:18.12
-8,0,7:18.12
-7,0,7:18.12
0,0,7:17.12
2,0,7:17.12
5,0,7:18.12
0,1,7:17.12
1,1,7:17.12
3,1,7:17.12
-2,2,7:17.12
-1,2,7:17.12
0,2,7:17.12
1,2,7:17.12
-3,3,7:17.12
-1,3,7:18.12
2,3,7:17.12
-3,4,7:18.12
-2,4,7:18.12
-1,4,7:18.12
1,4,7:17.12
9,4,7:18.12
-4,5,7:17.12
-3,5,7:17.12
-2,5,7:17.12
2,5,7:18.12
-5,6,7:17.12
-9,8,7:18.12
1,8,7:18.12
-8,9,7:18.12
-7,9,7:18.12
-6,9,7:18.12
5,9,7:18.12
3,10,7:18.12
4,10,7:18.12
0,11,7:18.12
-9,-13,8:18.12
-8,-13,8:18.12
-10,-12,8:18.12
-9,-12,8:18.12
-8,-12,8:18.12
-7,-12,8:18.12
-6,-12,8:18.12
-5,-12,8:18.12
-4,-12,8:18.12
-2,-12,8:18.12
2,-12,8:18.12
-10,-11,8:18.12
-9,-11,8:18.12
-8,-11,8:18.12
-7,-11,8:18.12
-6,-11,8:18.12
-5,-11,8:18.12
-4,-11,8:18.12
-3,-11,8:18.12
-2,-11,8:18.12
0,-11,8:18.12
1,-11,8:18.12
2,-11,8:18.12
3,-11,8:18.12
4,-11,8:18.12
5,-11,8:18.12
-8,-10,8:18.12
-7,-10,8:18.12
-6,-10,8:18.12
-5,-10,8:18.12
-4,-10,8:18.12
-3,-10,8:18.12
-1,-10,8:18.12
0,-10,8:18.12
1,-10,8:18.12
2,-10,8:18.12
3,-10,8:18.12
4,-10,8:18.12
5,-10,8:18.12
6,-10,8:18.12
-11,-9,8:18.12
-10,-9,8:18.12
-9,-9,8:18.12
-8,-9,8:18.12
-7,-9,8:18.12
-6,-9,8:18.12
-5,-9,8:18.12
-4,-9,8:18.12
-3,-9,8:18.12
-1,-9,8:18.12
0,-9,8:18.12
2,-9,8:18.12
5,-9,8:18.12
6,-9,8:18.12
-10,-8,8:18.12
-9,-8,8:18.12
-8,-8,8:18.12
-6,-8,8:18.12
-5,-8,8:18.12
-4,-8,8:18.12
-3,-8,8:18.12
-2,-8,8:18.12
1,-8,8:18.12
5,-8,8:18.12
-10,-7,8:18.12
-9,-7,8:18.12
-8,-7,8:18.12
-6,-7,8:18.12
-5,-7,8:18.12
-4,-7,8:18.12
-3,-7,8:18.12
4,-7,8:18.12
5,-7,8:18.12
6,-7,8:18.12
7,-7,8:18.12
-13,-6,8:18.12
-12,-6,8:18.12
-11,-6,8:18.12
-10,-6,8:18.12
-9,-6,8:18.12
-6,-6,8:18.12
-2,-6,8:18.12
-1,-6,8:18.12
4,-6,8:18.12
5,-6,8:18.12
6,-6,8:18.12
-12,-5,8:18.12
-10,-5,8:18.12
-9,-5,8:18.12
-8,-5,8:18.12
-7,-5,8:18.12
-6,-5,8:18.12
-5,-5,8:18.12
2,-5,8:17.12
6,-5,8:18.12
7,-5,8:18.12
8,-5,8:18.12
9,-5,8:18.12
-11,-4,8:18.12
-10,-4,8:18.12
-9,-4,8:18.12
-8,-4,8:18.12
-7,-4,8:18.12
-6,-4,8:18.12
1,-4,8:17.12
2,-4,8:17.12
6,-4,8:18.12
8,-4,8:18.12
-11,-3,8:18.12
-10,-3,8:18.12
-9,-3,8:18.12
-8,-3,8:18.12
-7,-3,8:18.12
-6,-3,8:18.12
-5,-3,8:18.12
-4,-3,8:18.12
-3,-3,8:18.12
-1,-3,8:17.12
0,-3,8:17.12
1,-3,8:17.12
2,-3,8:17.12
6,-3,8:18.12
7,-3,8:18.12
9,-3,8:18.12
10,-3,8:18.12
-11,-2,8:18.12
-10,-2,8:18.12
-9,-2,8:18.12
-8,-2,8:18.12
-7,-2,8:18.12
-6,-2,8:18.12
-5,-2,8:18.12
-4,-2,8:18.12
-2,-2,8:17.12
-1,-2,8:17.12
0,-2,8:17.12
1,-2,8:17.12
9,-2,8:18.12
-10,-1,8:18.12
-9,-1,8:18.12
-4,-1,8:18.12
-2,-1,8:17.12
-1,-1,8:17.12
0,-1,8:17.12
1,-1,8:17.12
7,-1,8:18.12
-10,0,8:18.12
-9,0,8:18.12
-7,0,8:18.12
-1,0,8:17.12
0,0,8:17.12
1,0,8:17.12
2,0,8:17.12
4,0,8:18.12
5,0,8:18.12
6,0,8:18.12
7,0,8:18.12
-10,1,8:18.12
-7,1,8:17.12
-6,1,8:17.12
-1,1,8:17.12
0,1,8:17.12
1,1,8:18.12
2,1,8:17.12
3,1,8:18.12
6,1,8:18.12
7,1,8:18.12
8,1,8:18.12
-8,2,8:18.12
-7,2,8:18.12
-6,2,8:18.12
-2,2,8:17.12
-1,2,8:17.12
0,2,8:17.12
1,2,8:18.12
2,2,8:18.12
3,2,8:18.12
9,2,8:18.12
-8,3,8:18.12
-6,3,8:17.12
-5,3,8:17.12
-4,3,8:18.12
-2,3,8:17.12
1,3,8:17.12
-9,4,8:18.12
-6,4,8:18.12
-5,4,8:17.12
-4,4,8:18.12
-2,4,8:17.12
-1,4,8:18.12
0,4,8:18.12
6,4,8:18.12
9,4,8:18.12
-9,5,8:18.12
-8,5,8:18.12
-7,5,8:18.12
-5,5,8:18.12
-4,5,8:18.12
-3,5,8:18.12
-2,5,8:18.12
-1,5,8:18.12
2,5,8:18.12
-8,6,8:18.12
-7,6,8:18.12
-6,6,8:17.12
-5,6,8:18.12
-4,6,8:18.12
-3,6,8:18.12
-2,6,8:17.12
-9,7,8:18.12
-8,7,8:18.12
-7,7,8:18.12
-6,7,8:17.12
-5,7,8:17.12
-4,7,8:18.12
-3,7,8:18.12
1,7,8:17.12
-9,8,8:18.12
-7,8,8:18.12
0,8,8:18.12
1,8,8:18.12
-10,9,8:18.12
-9,9,8:18.12
-8,9,8:18.12
-7,9,8:18.12
-6,9,8:18.12
-5,9,8:18.12
-4,9,8:18.12
-3,9,8:18.12
5,9,8:18.12
-5,10,8:18.12
-3,10,8:18.12
2,10,8:18.12
3,10,8:18.12
4,10,8:18.12
5,10,8:18.12
-5,11,8:18.12
-4,11,8:18.12
-3,11,8:18.12
-2,11,8:18.12
-1,11,8:18.12
0,11,8:18.12
2,11,8:18.12
3,11,8:18.12
5,11,8:18.12
-3,12,8:18.12
1,12,8:18.12
-8,-13,9:18.12
-8,-12,9:18.12
-7,-12,9:18.12
-6,-12,9:18.12
-5,-12,9:18.12
-4,-12,9:18.12
-3,-12,9:18.12
3,-12,9:18.12
-8,-11,9:18.12
-7,-11,9:18.12
-6,-11,9:18.12
-5,-11,9:18.12
-4,-11,9:18.12
-3,-11,9:18.12
-2,-11,9:18.12
-1,-11,9:18.12
0,-11,9:18.12
2,-11,9:18.12
3,-11,9:18.12
4,-11,9:18.12
5,-11,9:18.12
-8,-10,9:18.12
-7,-10,9:18.12
-6,-10,9:18.12
-5,-10,9:18.12
-4,-10,9:18.12
-3,-10,9:18.12
-2,-10,9:18.12
-1,-10,9:18.12
0,-10,9:18.12
1,-10,9:18.12
2,-10,9:18.12
3,-10,9:18.12
4,-10,9:18.12
-10,-9,9:18.12
-8,-9,9:18.12
-7,-9,9:18.12
-6,-9,9:18.12
-5,-9,9:18.12
-4,-9,9:18.12
-3,-9,9:18.12
-2,-9,9:18.12
-1,-9,9:18.12
2,-9,9:18.12
3,-9,9:18.12
4,-9,9:18.12
5,-9,9:18.12
6,-9,9:18.12
-10,-8,9:18.12
-8,-8,9:18.12
-7,-8,9:18.12
-6,-8,9:18.12
-5,-8,9:18.12
-4,-8,9:18.12
-3,-8,9:18.12
-2,-8,9:18.12
-1,-8,9:18.12
1,-8,9:18.12
2,-8,9:18.12
5,-8,9:18.12
6,-8,9:18.12
-10,-7,9:18.12
-9,-7,9:18.12
-8,-7,9:18.12
-7,-7,9:18.12
-6,-7,9:18.12
-5,-7,9:18.12
-4,-7,9:18.12
-3,-7,9:18.12
-2,-7,9:18.12
-1,-7,9:18.12
0,-7,9:18.12
3,-7,9:18.12
4,-7,9:18.12
5,-7,9:18.12
6,-7,9:18.12
7,-7,9:18.12
8,-7,9:18.12
-10,-6,9:18.12
-9,-6,9:18.12
-8,-6,9:18.12
-7,-6,9:18.12
-6,-6,9:18.12
-5,-6,9:18.12
-4,-6,9:18.12
-3,-6,9:18.12
-2,-6,9:18.12
-1,-6,9:18.12
2,-6,9:17.12
4,-6,9:18.12
5,-6,9:18.12
6,-6,9:18.12
7,-6,9:18.12
8,-6,9:18.12
-11,-5,9:18.12
-10,-5,9:18.12
-9,-5,9:18.12
-8,-5,9:18.12
-7,-5,9:18.12
-6,-5,9:18.12
-5,-5,9:18.12
-2,-5,9:18.12
-1,-5,9:18.12
1,-5,9:17.12
2,-5,9:17.12
4,-5,9:18.12
5,-5,9:18.12
6,-5,9:18.12
7,-5,9:18.12
8,-5,9:18.12
10,-5,9:18.12
-12,-4,9:18.12
-11,-4,9:18.12
-9,-4,9:18.12
-8,-4,9:18.12
-7,-4,9:18.12
-6,-4,9:18.12
-5,-4,9:18.12
-1,-4,9:18.12
0,-4,9:17.12
1,-4,9:17.12
2,-4,9:18.12
3,-4,9:18.12
5,-4,9:18.12
8,-4,9:18.12
10,-4,9:18.12
11,-4,9:18.12
-11,-3,9:18.12
-10,-3,9:18.12
-9,-3,9:18.12
-8,-3,9:18.12
-6,-3,9:18.12
-5,-3,9:18.12
-4,-3,9:17.12
-3,-3,9:17.12
-2,-3,9:17.12
0,-3,9:17.12
1,-3,9:17.12
2,-3,9:17.12
4,-3,9:18.12
5,-3,9:18.12
6,-3,9:18.12
7,-3,9:18.12
9,-3,9:18.12
10,-3,9:18.12
11,-3,9:18.12
12,-3,9:18.12
-9,-2,9:18.12
-7,-2,9:18.12
-6,-2,9:18.12
-5,-2,9:18.12
-4,-2,9:18.12
-3,-2,9:17.12
-2,-2,9:17.12
-1,-2,9:17.12
0,-2,9:17.12
2,-2,9:18.12
4,-2,9:18.12
7,-2,9:18.12
9,-2,9:18.12
11,-2,9:18.12
-9,-1,9:18.12
-8,-1,9:18.12
-7,-1,9:17.12
-5,-1,9:18.12
-4,-1,9:18.12
-2,-1,9:17.12
-1,-1,9:17.12
0,-1,9:17.12
4,-1,9:17.12
5,-1,9:18.12
-10,0,9:18.12
-9,0,9:18.12
-8,0,9:18.12
-7,0,9:18.12
-4,0,9:18.12
-3,0,9:18.12
-2,0,9:18.12
-1,0,9:17.12
0,0,9:17.12
2,0,9:17.12
4,0,9:17.12
5,0,9:18.12
7,0,9:18.12
9,0,9:18.12
-10,1,9:18.12
-9,1,9:18.12
-8,1,9:18.12
-7,1,9:18.12
-6,1,9:18.12
-5,1,9:18.12
-3,1,9:18.12
-2,1,9:18.12
0,1,9:17.12
2,1,9:17.12
3,1,9:18.12
4,1,9:17.12
5,1,9:18.12
6,1,9:18.12
7,1,9:18.12
8,1,9:18.12
10,1,9:18.12
-9,2,9:18.12
-8,2,9:18.12
-7,2,9:18.12
-6,2,9:18.12
-5,2,9:18.12
-3,2,9:18.12
-1,2,9:17.12
1,2,9:17.12
2,2,9:18.12
3,2,9:18.12
4,2,9:18.12
5,2,9:18.12
6,2,9:18.12
8,2,9:18.12
9,2,9:18.12
-9,3,9:18.12
-8,3,9:18.12
-7,3,9:18.12
-6,3,9:18.12
-5,3,9:18.12
-4,3,9:18.12
-3,3,9:18.12
1,3,9:17.12
2,3,9:18.12
4,3,9:18.12
5,3,9:18.12
6,3,9:18.12
-10,4,9:18.12
-9,4,9:18.12
-8,4,9:18.12
-7,4,9:18.12
-6,4,9:18.12
-5,4,9:18.12
-4,4,9:18.12
-3,4,9:18.12
-2,4,9:17.12
2,4,9:18.12
3,4,9:18.12
6,4,9:18.12
9,4,9:18.12
11,4,9:18.12
12,4,9:18.12
-8,5,9:18.12
-7,5,9:18.12
-6,5,9:18.12
-5,5,9:18.12
-4,5,9:18.12
-3,5,9:18.12
0,5,9:18.12
1,5,9:17.12
2,5,9:18.12
3,5,9:18.12
9,5,9:18.12
12,5,9:18.12
-8,6,9:18.12
-7,6,9:17.12
-6,6,9:18.12
-5,6,9:18.12
-4,6,9:18.12
-3,6,9:18.12
0,6,9:18.12
2,6,9:18.12
9,6,9:18.12
-9,7,9:18.12
-8,7,9:18.12
-7,7,9:17.12
-6,7,9:17.12
-5,7,9:18.12
-4,7,9:18.12
-3,7,9:18.12
-1,7,9:18.12
1,7,9:18.12
2,7,9:18.12
3,7,9:18.12
-11,8,9:18.12
-8,8,9:18.12
-6,8,9:18.12
-5,8,9:17.12
-4,8,9:18.12
-3,8,9:18.12
-2,8,9:18.12
0,8,9:18.12
1,8,9:18.12
2,8,9:18.12
-9,9,9:18.12
-7,9,9:18.12
-6,9,9:18.12
-5,9,9:18.12
-4,9,9:18.12
-3,9,9:18.12
-2,9,9:18.12
-1,9,9:18.12
0,9,9:18.12
1,9,9:18.12
2,9,9:18.12
3,9,9:18.12
4,9,9:18.12
-9,10,9:18.12
-6,10,9:18.12
-5,10,9:18.12
-4,10,9:18.12
-3,10,9:18.12
-1,10,9:18.12
2,10,9:18.12
3,10,9:18.12
4,10,9:18.12
5,10,9:18.12
-4,11,9:18.12
-3,11,9:18.12
-2,11,9:18.12
-1,11,9:18.12
0,11,9:18.12
1,11,9:18.12
2,11,9:18.12
-4,12,9:18.12
0,12,9:18.12
1,12,9:18.12
2,12,9:18.12
-4,13,9:18.12
1,13,9:18.12
-2,-12,10:18.12
1,-12,10:18.12
-7,-11,10:18.12
-4,-11,10:18.12
-2,-11,10:18.12
-1,-11,10:18.12
1,-11,10:18.12
2,-11,10:18.12
-4,-10,10:18.12
-3,-10,10:18.12
-2,-10,10:18.12
-1,-10,10:18.12
0,-10,10:18.12
1,-10,10:18.12
2,-10,10:18.12
4,-10,10:18.12
-7,-9,10:18.12
-4,-9,10:18.12
-3,-9,10:18.12
-2,-9,10:18.12
-1,-9,10:18.12
0,-9,10:18.12
1,-9,10:18.12
2,-9,10:18.12
3,-9,10:18.12
4,-9,10:18.12
5,-9,10:18.12
-8,-8,10:18.12
-7,-8,10:18.12
-6,-8,10:18.12
-5,-8,10:18.12
-4,-8,10:18.12
-3,-8,10:18.12
-2,-8,10:18.12
-1,-8,10:18.12
0,-8,10:18.12
1,-8,10:18.12
2,-8,10:18.12
3,-8,10:18.12
4,-8,10:18.12
5,-8,10:18.12
6,-8,10:18.12
-11,-7,10:18.12
-10,-7,10:18.12
-8,-7,10:18.12
-7,-7,10:18.12
-6,-7,10:18.12
-5,-7,10:18.12
-4,-7,10:18.12
-3,-7,10:18.12
-2,-7,10:18.12
-1,-7,10:18.12
0,-7,10:18.12
1,-7,10:18.12
2,-7,10:18.12
3,-7,10:18.12
4,-7,10:18.12
5,-7,10:18.12
6,-7,10:18.12
7,-7,10:18.12
8,-7,10:18.12
-9,-6,10:18.12
-8,-6,10:18.12
-7,-6,10:18.12
-6,-6,10:18.12
-5,-6,10:18.12
-4,-6,10:18.12
-3,-6,10:18.12
-2,-6,10:18.12
-1,-6,10:18.12
0,-6,10:18.12
2,-6,10:17.12
3,-6,10:18.12
4,-6,10:18.12
5,-6,10:18.12
6,-6,10:18.12
7,-6,10:18.12
8,-6,10:18.12
10,-6,10:18.12
-10,-5,10:18.12
-9,-5,10:18.12
-8,-5,10:18.12
-6,-5,10:18.12
-5,-5,10:18.12
-4,-5,10:17.12
-3,-5,10:18.12
-2,-5,10:18.12
-1,-5,10:18.12
0,-5,10:18.12
1,-5,10:18.12
2,-5,10:17.12
3,-5,10:18.12
4,-5,10:17.12
6,-5,10:18.12
7,-5,10:18.12
8,-5,10:18.12
9,-5,10:18.12
10,-5,10:18.12
11,-5,10:18.12
-11,-4,10:18.12
-10,-4,10:18.12
-9,-4,10:18.12
-8,-4,10:18.12
-7,-4,10:18.12
-5,-4,10:18.12
-4,-4,10:18.12
-3,-4,10:17.12
-2,-4,10:18.12
-1,-4,10:18.12
1,-4,10:17.12
2,-4,10:18.12
3,-4,10:18.12
4,-4,10:18.12
6,-4,10:18.12
7,-4,10:18.12
8,-4,10:18.12
9,-4,10:18.12
10,-4,10:18.12
11,-4,10:18.12
-9,-3,10:18.12
-8,-3,10:18.12
-6,-3,10:18.12
-5,-3,10:18.12
-4,-3,10:17.12
-3,-3,10:17.12
-2,-3,10:17.12
1,-3,10:17.12
2,-3,10:18.12
3,-3,10:18.12
4,-3,10:18.12
5,-3,10:18.12
6,-3,10:18.12
7,-3,10:18.12
8,-3,10:18.12
9,-3,10:18.12
10,-3,10:18.12
11,-3,10:18.12
12,-3,10:18.12
-9,-2,10:18.12
-8,-2,10:18.12
-7,-2,10:18.12
-6,-2,10:18.12
-5,-2,10:18.12
-4,-2,10:18.12
-3,-2,10:18.12
0,-2,10:18.12
1,-2,10:18.12
2,-2,10:18.12
4,-2,10:18.12
5,-2,10:18.12
6,-2,10:18.12
8,-2,10:18.12
9,-2,10:18.12
10,-2,10:18.12
11,-2,10:18.12
12,-2,10:18.12
-10,-1,10:18.12
-9,-1,10:18.12
-8,-1,10:18.12
-7,-1,10:18.12
-6,-1,10:18.12
-5,-1,10:18.12
-4,-1,10:18.12
-2,-1,10:17.12
0,-1,10:18.12
2,-1,10:18.12
4,-1,10:18.12
5,-1,10:18.12
7,-1,10:18.12
9,-1,10:18.12
10,-1,10:18.12
11,-1,10:18.12
12,-1,10:18.12
-9,0,10:18.12
-8,0,10:18.12
-7,0,10:18.12
-6,0,10:18.12
-5,0,10:18.12
-4,0,10:18.12
-3,0,10:18.12
1,0,10:18.12
2,0,10:18.12
5,0,10:18.12
6,0,10:17.12
7,0,10:18.12
8,0,10:18.12
9,0,10:18.12
10,0,10:18.12
-10,1,10:18.12
-9,1,10:18.12
-8,1,10:18.12
-7,1,10:18.12
-6,1,10:18.12
-5,1,10:18.12
-4,1,10:18.12
-3,1,10:18.12
-1,1,10:17.12
2,1,10:17.12
3,1,10:17.12
4,1,10:17.12
5,1,10:17.12
6,1,10:18.12
7,1,10:18.12
8,1,10:18.12
9,1,10:18.12
10,1,10:18.12
-9,2,10:18.12
-7,2,10:18.12
-6,2,10:18.12
-5,2,10:18.12
-4,2,10:18.12
-3,2,10:18.12
-2,2,10:18.12
-1,2,10:17.12
2,2,10:18.12
3,2,10:18.12
8,2,10:18.12
9,2,10:18.12
10,2,10:18.12
-9,3,10:18.12
-8,3,10:18.12
-7,3,10:18.12
-6,3,10:18.12
-5,3,10:18.12
-4,3,10:18.12
-3,3,10:18.12
2,3,10:18.12
3,3,10:17.12
4,3,10:18.12
5,3,10:18.12
6,3,10:18.12
9,3,10:18.12
10,3,10:18.12
11,3,10:18.12
-8,4,10:18.12
-7,4,10:18.12
-4,4,10:18.12
-3,4,10:18.12
2,4,10:18.12
4,4,10:18.12
5,4,10:18.12
6,4,10:18.12
8,4,10:18.12
9,4,10:18.12
10,4,10:18.12
11,4,10:18.12
12,4,10:18.12
13,4,10:18.12
-7,5,10:18.12
-6,5,10:18.12
-5,5,10:18.12
-4,5,10:18.12
-1,5,10:18.12
0,5,10:18.12
1,5,10:18.12
2,5,10:18.12
3,5,10:18.12
4,5,10:18.12
5,5,10:18.12
6,5,10:18.12
7,5,10:18.12
8,5,10:18.12
9,5,10:18.12
10,5,10:18.12
-9,6,10:18.12
-8,6,10:18.12
-7,6,10:18.12
-6,6,10:18.12
-5,6,10:18.12
-4,6,10:18.12
-2,6,10:18.12
-1,6,10:18.12
0,6,10:18.12
1,6,10:17.12
2,6,10:17.12
3,6,10:18.12
7,6,10:18.12
8,6,10:18.12
9,6,10:18.12
-12,7,10:18.12
-10,7,10:18.12
-8,7,10:18.12
-7,7,10:17.12
-6,7,10:18.12
-5,7,10:18.12
-4,7,10:18.12
-3,7,10:18.12
-2,7,10:18.12
-1,7,10:18.12
0,7,10:18.12
1,7,10:18.12
2,7,10:18.12
3,7,10:18.12
6,7,10:18.12
7,7,10:18.12
8,7,10:18.12
-13,8,10:18.12
-12,8,10:18.12
-11,8,10:18.12
-10,8,10:18.12
-9,8,10:18.12
-8,8,10:18.12
-7,8,10:18.12
-6,8,10:18.12
-5,8,10:18.12
-4,8,10:18.12
-3,8,10:18.12
-2,8,10:18.12
-1,8,10:18.12
0,8,10:18.12
1,8,10:18.12
2,8,10:18.12
5,8,10:18.12
6,8,10:18.12
7,8,10:18.12
8,8,10:18.12
-11,9,10:18.12
-10,9,10:18.12
-9,9,10:18.12
-7,9,10:18.12
-6,9,10:18.12
-4,9,10:18.12
-3,9,10:18.12
-2,9,10:18.12
-1,9,10:18.12
0,9,10:18.12
1,9,10:18.12
2,9,10:18.12
3,9,10:18.12
4,9,10:18.12
5,9,10:18.12
6,9,10:18.12
-11,10,10:18.12
-6,10,10:18.12
-5,10,10:18.12
-4,10,10:18.12
-3,10,10:18.12
-2,10,10:18.12
-1,10,10:18.12
0,10,10:18.12
1,10,10:18.12
2,10,10:18.12
3,10,10:18.12
4,10,10:18.12
-5,11,10:18.12
-4,11,10:18.12
-3,11,10:18.12
1,11,10:18.12
2,11,10:18.12
-4,12,10:18.12
1,-12,11:18.12
0,-11,11:18.12
4,-11,11:18.12
-1,-10,11:18.12
0,-10,11:18.12
1,-10,11:18.12
2,-10,11:18.12
3,-10,11:18.12
4,-10,11:18.12
-6,-9,11:18.12
-5,-9,11:18.12
-4,-9,11:18.12
-2,-9,11:18.12
-1,-9,11:18.12
0,-9,11:18.12
1,-9,11:18.12
2,-9,11:18.12
3,-9,11:18.12
4,-9,11:18.12
5,-9,11:18.12
-8,-8,11:18.12
-7,-8,11:18.12
-6,-8,11:18.12
-5,-8,11:18.12
-3,-8,11:18.12
-2,-8,11:18.12
-1,-8,11:18.12
0,-8,11:18.12
1,-8,11:18.12
2,-8,11:18.12
3,-8,11:18.12
4,-8,11:18.12
5,-8,11:18.12
-9,-7,11:18.12
-8,-7,11:18.12
-7,-7,11:18.12
-6,-7,11:18.12
-5,-7,11:18.12
-4,-7,11:18.12
-3,-7,11:18.12
-2,-7,11:18.12
-1,-7,11:18.12
0,-7,11:18.12
1,-7,11:18.12
2,-7,11:18.12
4,-7,11:18.12
5,-7,11:18.12
7,-7,11:18.12
-9,-6,11:18.12
-8,-6,11:18.12
-7,-6,11:18.12
-6,-6,11:18.12
-5,-6,11:18.12
-4,-6,11:18.12
-3,-6,11:18.12
-2,-6,11:18.12
-1,-6,11:18.12
0,-6,11:18.12
1,-6,11:18.12
3,-6,11:17.12
4,-6,11:18.12
5,-6,11:18.12
6,-6,11:18.12
8,-6,11:18.12
-7,-5,11:18.12
-6,-5,11:18.12
-5,-5,11:18.12
-4,-5,11:18.12
-3,-5,11:18.12
-2,-5,11:18.12
-1,-5,11:18.12
0,-5,11:18.12
1,-5,11:17.12
3,-5,11:18.12
4,-5,11:18.12
5,-5,11:18.12
7,-5,11:18.12
8,-5,11:18.12
-7,-4,11:18.12
-6,-4,11:18.12
-5,-4,11:18.12
-4,-4,11:18.12
-3,-4,11:18.12
-2,-4,11:18.12
-1,-4,11:18.12
0,-4,11:18.12
2,-4,11:18.12
3,-4,11:18.12
4,-4,11:18.12
5,-4,11:18.12
6,-4,11:18.12
7,-4,11:18.12
8,-4,11:18.12
9,-4,11:18.12
10,-4,11:18.12
11,-4,11:18.12
-7,-3,11:18.12
-6,-3,11:18.12
-5,-3,11:18.12
-4,-3,11:18.12
-3,-3,11:18.12
-2,-3,11:18.12
-1,-3,11:18.12
0,-3,11:18.12
2,-3,11:18.12
3,-3,11:18.12
4,-3,11:18.12
5,-3,11:18.12
6,-3,11:18.12
7,-3,11:18.12
8,-3,11:18.12
9,-3,11:18.12
10,-3,11:18.12
11,-3,11:18.12
12,-3,11:18.12
-8,-2,11:18.12
-6,-2,11:18.12
-5,-2,11:18.12
-4,-2,11:18.12
-3,-2,11:18.12
-2,-2,11:18.12
-1,-2,11:18.12
0,-2,11:18.12
1,-2,11:18.12
2,-2,11:17.12
3,-2,11:18.12
4,-2,11:18.12
5,-2,11:18.12
6,-2,11:18.12
7,-2,11:18.12
8,-2,11:18.12
9,-2,11:18.12
10,-2,11:18.12
11,-2,11:18.12
-9,-1,11:18.12
-8,-1,11:18.12
-7,-1,11:18.12
-6,-1,11:18.12
-3,-1,11:18.12
0,-1,11:18.12
1,-1,11:17.12
2,-1,11:17.12
4,-1,11:18.12
5,-1,11:18.12
6,-1,11:18.12
7,-1,11:18.12
8,-1,11:18.12
9,-1,11:18.12
10,-1,11:18.12
12,-1,11:18.12
-10,0,11:18.12
-9,0,11:18.12
-8,0,11:18.12
-7,0,11:18.12
-6,0,11:18.12
-5,0,11:18.12
-4,0,11:18.12
-3,0,11:18.12
-1,0,11:17.12
0,0,11:18.12
2,0,11:18.12
5,0,11:17.12
6,0,11:18.12
7,0,11:18.12
8,0,11:18.12
9,0,11:18.12
-8,1,11:18.12
-7,1,11:18.12
-6,1,11:18.12
-5,1,11:18.12
-4,1,11:18.12
-3,1,11:18.12
-2,1,11:18.12
-1,1,11:17.12
0,1,11:17.12
2,1,11:18.12
4,1,11:18.12
5,1,11:18.12
6,1,11:18.12
7,1,11:18.12
8,1,11:18.12
9,1,11:18.12
-7,2,11:18.12
-6,2,11:18.12
-5,2,11:18.12
-4,2,11:18.12
-3,2,11:18.12
-2,2,11:18.12
-1,2,11:18.12
0,2,11:17.12
1,2,11:18.12
3,2,11:18.12
6,2,11:18.12
7,2,11:18.12
8,2,11:18.12
9,2,11:18.12
10,2,11:18.12
-8,3,11:18.12
-7,3,11:18.12
-6,3,11:18.12
-5,3,11:18.12
-4,3,11:18.12
-3,3,11:18.12
-2,3,11:18.12
1,3,11:18.12
3,3,11:18.12
4,3,11:18.12
6,3,11:18.12
7,3,11:18.12
8,3,11:18.12
10,3,11:18.12
-7,4,11:18.12
-5,4,11:18.12
-4,4,11:18.12
-3,4,11:18.12
-1,4,11:18.12
0,4,11:18.12
1,4,11:18.12
2,4,11:18.12
4,4,11:18.12
7,4,11:18.12
8,4,11:18.12
9,4,11:18.12
10,4,11:18.12
11,4,11:18.12
12,4,11:18.12
-7,5,11:18.12
-6,5,11:18.12
-5,5,11:18.12
-4,5,11:18.12
-3,5,11:18.4
-2,5,11:18.12
2,5,11:18.12
3,5,11:18.12
4,5,11:17.12
6,5,11:18.12
7,5,11:18.12
9,5,11:18.12
12,5,11:18.12
-8,6,11:18.12
-7,6,11:18.12
-6,6,11:18.12
-5,6,11:18.12
-4,6,11:18.12
-3,6,11:18.12
-2,6,11:18.12
-1,6,11:18.12
0,6,11:18.12
1,6,11:18.12
2,6,11:18.12
3,6,11:18.12
4,6,11:18.12
5,6,11:18.12
6,6,11:18.12
7,6,11:18.12
8,6,11:18.12
-9,7,11:18.12
-8,7,11:18.12
-7,7,11:17.12
-6,7,11:18.12
-5,7,11:18.12
-4,7,11:18.12
-3,7,11:18.12
-2,7,11:17.12
-1,7,11:17.12
0,7,11:18.12
1,7,11:18.12
2,7,11:18.12
3,7,11:18.12
4,7,11:18.12
5,7,11:18.12
6,7,11:18.12
7,7,11:18.12
8,7,11:18.12
-13,8,11:18.12
-10,8,11:18.12
-7,8,11:18.12
-6,8,11:18.12
-5,8,11:18.12
-4,8,11:18.12
-3,8,11:18.12
-2,8,11:18.12
-1,8,11:18.12
0,8,11:18.12
1,8,11:18.12
2,8,11:18.12
3,8,11:18.12
4,8,11:18.12
5,8,11:18.12
6,8,11:18.12
7,8,11:18.12
8,8,11:18.12
-10,9,11:18.12
-6,9,11:18.12
-5,9,11:18.12
-4,9,11:18.12
-3,9,11:18.12
-2,9,11:18.12
-1,9,11:18.12
0,9,11:18.12
1,9,11:18.12
2,9,11:18.12
3,9,11:18.12
6,9,11:18.12
7,9,11:18.12
-6,10,11:18.12
-4,10,11:18.12
-3,10,11:18.12
1,10,11:18.12
3,10,11:18.12
-5,11,11:18.12
-3,11,11:18.12
0,-10,12:18.12
3,-10,12:18.12
4,-10,12:18.12
-6,-9,12:18.12
-5,-9,12:18.12
-2,-9,12:18.12
-1,-9,12:18.12
1,-9,12:18.12
2,-9,12:18.12
3,-9,12:18.12
4,-9,12:18.12
-6,-8,12:18.12
-5,-8,12:18.12
-2,-8,12:18.12
-1,-8,12:18.12
0,-8,12:18.12
1,-8,12:18.12
2,-8,12:18.12
3,-8,12:18.12
-7,-7,12:18.12
-6,-7,12:18.12
-5,-7,12:18.12
-4,-7,12:18.12
-3,-7,12:18.12
-2,-7,12:18.12
-1,-7,12:18.12
0,-7,12:18.12
1,-7,12:18.12
2,-7,12:18.12
3,-7,12:18.12
4,-7,12:18.12
-8,-6,12:18.12
-7,-6,12:18.12
-6,-6,12:18.12
-5,-6,12:18.12
-3,-6,12:18.12
-2,-6,12:18.12
-1,-6,12:18.12
0,-6,12:18.12
1,-6,12:18.12
2,-6,12:18.12
3,-6,12:18.12
4,-6,12:18.12
5,-6,12:18.12
-6,-5,12:18.12
-5,-5,12:18.12
-4,-5,12:18.12
-3,-5,12:18.12
-2,-5,12:18.12
-1,-5,12:18.12
0,-5,12:18.12
1,-5,12:18.12
2,-5,12:18.12
3,-5,12:18.12
4,-5,12:18.12
-5,-4,12:18.12
-4,-4,12:18.12
-3,-4,12:18.12
-2,-4,12:18.12
-1,-4,12:18.12
0,-4,12:18.12
1,-4,12:18.12
2,-4,12:18.12
3,-4,12:18.12
4,-4,12:18.12
5,-4,12:18.12
6,-4,12:18.12
7,-4,12:18.12
10,-4,12:18.12
-6,-3,12:18.12
-5,-3,12:18.12
-4,-3,12:18.12
-3,-3,12:18.12
-2,-3,12:18.12
-1,-3,12:18.12
0,-3,12:18.12
1,-3,12:18.12
2,-3,12:18.12
3,-3,12:18.12
4,-3,12:18.12
5,-3,12:18.12
6,-3,12:18.12
7,-3,12:18.12
10,-3,12:18.12
-4,-2,12:18.12
-3,-2,12:18.12
-2,-2,12:18.12
-1,-2,12:18.12
0,-2,12:18.12
1,-2,12:18.12
2,-2,12:18.12
3,-2,12:17.12
4,-2,12:18.12
5,-2,12:18.12
6,-2,12:18.12
7,-2,12:18.12
8,-2,12:18.12
9,-2,12:18.12
10,-2,12:18.12
11,-2,12:18.12
-8,-1,12:18.12
-4,-1,12:18.12
0,-1,12:18.12
1,-1,12:18.12
2,-1,12:18.12
3,-1,12:17.12
4,-1,12:18.12
5,-1,12:18.12
6,-1,12:18.12
7,-1,12:18.12
10,-1,12:18.12
-9,0,12:18.12
-4,0,12:18.12
-3,0,12:17.12
-2,0,12:17.12
-1,0,12:18.12
0,0,12:18.12
1,0,12:18.12
2,0,12:18.12
4,0,12:18.12
5,0,12:17.12
6,0,12:18.12
7,0,12:18.12
8,0,12:18.12
9,0,12:18.12
-5,1,12:18.12
-4,1,12:18.12
-3,1,12:18.12
-2,1,12:18.12
-1,1,12:18.12
0,1,12:18.12
1,1,12:18.12
2,1,12:18.12
3,1,12:18.12
4,1,12:18.12
5,1,12:18.12
6,1,12:18.12
7,1,12:18.12
8,1,12:18.12
9,1,12:18.12
10,1,12:18.12
11,1,12:18.12
-7,2,12:18.12
-6,2,12:18.12
-5,2,12:18.12
-3,2,12:18.12
-2,2,12:18.12
-1,2,12:18.12
0,2,12:18.12
1,2,12:18.12
5,2,12:18.12
6,2,12:18.12
7,2,12:18.12
8,2,12:18.4
9,2,12:18.4
10,2,12:18.12
-7,3,12:18.12
-6,3,12:18.12
-5,3,12:18.12
-4,3,12:18.12
-3,3,12:18.12
-1,3,12:18.12
0,3,12:18.12
1,3,12:18.12
2,3,12:18.12
3,3,12:18.12
4,3,12:18.12
5,3,12:18.4
7,3,12:18.12
8,3,12:18.12
9,3,12:18.12
10,3,12:18.12
-5,4,12:18.12
-4,4,12:18.4
-3,4,12:18.12
-2,4,12:18.12
-1,4,12:18.12
0,4,12:18.12
1,4,12:18.12
2,4,12:18.12
3,4,12:18.12
4,4,12:18.12
5,4,12:18.12
6,4,12:18.12
7,4,12:18.12
8,4,12:18.12
9,4,12:18.12
-6,5,12:18.12
-5,5,12:18.12
-4,5,12:18.12
-3,5,12:18.4
-2,5,12:18.12
0,5,12:18.12
3,5,12:18.12
4,5,12:18.12
5,5,12:18.12
6,5,12:18.12
7,5,12:18.12
8,5,12:18.12
9,5,12:18.12
10,5,12:18.12
-9,6,12:18.12
-8,6,12:18.12
-6,6,12:18.12
-5,6,12:18.12
-4,6,12:18.12
-3,6,12:18.12
-2,6,12:18.12
-1,6,12:18.12
4,6,12:18.12
5,6,12:18.12
6,6,12:18.12
7,6,12:18.12
8,6,12:18.12
9,6,12:18.12
10,6,12:18.12
-9,7,12:18.12
-8,7,12:18.12
-6,7,12:18.12
-5,7,12:18.12
-3,7,12:18.12
-2,7,12:18.12
0,7,12:18.12
1,7,12:18.12
3,7,12:18.12
4,7,12:18.12
5,7,12:18.12
6,7,12:18.12
7,7,12:18.12
8,7,12:18.12
-8,8,12:18.12
-2,8,12:18.12
-1,8,12:18.12
0,8,12:18.12
1,8,12:18.12
2,8,12:18.12
3,8,12:18.12
4,8,12:18.12
5,8,12:18.12
6,8,12:18.12
-5,9,12:18.12
-4,9,12:18.12
-3,9,12:18.12
-1,9,12:18.12
1,9,12:18.12
2,9,12:18.12
5,9,12:18.12
-6,-9,13:18.12
-6,-8,13:18.12
0,-8,13:18.12
1,-8,13:18.12
2,-8,13:18.12
-6,-7,13:18.12
-5,-7,13:18.12
-4,-7,13:18.12
-3,-7,13:18.12
-2,-7,13:18.12
-1,-7,13:18.12
0,-7,13:18.12
1,-7,13:18.12
-4,-6,13:18.12
-3,-6,13:18.12
-2,-6,13:18.12
-1,-6,13:18.12
0,-6,13:18.12
1,-6,13:18.12
2,-6,13:18.12
-2,-5,13:18.12
-1,-5,13:18.12
0,-5,13:18.12
1,-5,13:18.12
2,-5,13:18.12
3,-5,13:18.12
4,-5,13:18.12
-5,-4,13:18.12
-3,-4,13:18.12
-2,-4,13:18.12
-1,-4,13:18.12
0,-4,13:18.12
1,-4,13:18.12
2,-4,13:18.12
5,-4,13:18.12
6,-4,13:18.12
-5,-3,13:18.12
-4,-3,13:18.12
-3,-3,13:18.12
-2,-3,13:18.12
-1,-3,13:18.12
0,-3,13:18.12
1,-3,13:18.12
2,-3,13:18.12
4,-3,13:18.12
5,-3,13:18.12
10,-3,13:18.12
-5,-2,13:18.12
-4,-2,13:18.12
-3,-2,13:18.12
-2,-2,13:18.12
-1,-2,13:18.12
0,-2,13:18.12
1,-2,13:18.12
2,-2,13:18.12
3,-2,13:18.12
4,-2,13:18.12
8,-2,13:18.12
-6,-1,13:18.12
-5,-1,13:18.12
-3,-1,13:18.12
-2,-1,13:18.12
-1,-1,13:18.12
0,-1,13:18.12
1,-1,13:18.12
2,-1,13:18.12
3,-1,13:18.12
4,-1,13:18.12
5,-1,13:18.12
6,-1,13:18.12
7,-1,13:18.12
-5,0,13:18.12
-4,0,13:18.12
-1,0,13:18.12
0,0,13:18.12
1,0,13:18.12
2,0,13:18.12
3,0,13:18.12
4,0,13:18.12
5,0,13:18.12
6,0,13:18.12
7,0,13:18.12
8,0,13:18.12
9,0,13:18.12
-6,1,13:18.12
-5,1,13:18.12
-4,1,13:18.12
-3,1,13:18.12
-2,1,13:18.12
-1,1,13:18.12
0,1,13:18.12
1,1,13:18.12
2,1,13:18.12
4,1,13:18.12
5,1,13:18.12
6,1,13:18.4
7,1,13:18.12
8,1,13:18.12
9,1,13:18.12
10,1,13:18.12
-6,2,13:18.12
-5,2,13:18.12
-4,2,13:18.12
-3,2,13:18.12
-2,2,13:18.12
-1,2,13:18.4
0,2,13:18.12
1,2,13:18.12
2,2,13:18.12
3,2,13:18.12
4,2,13:18.12
5,2,13:18.12
6,2,13:18.12
7,2,13:18.12
8,2,13:18.4
-5,3,13:18.4
-4,3,13:18.4
-3,3,13:18.4
-1,3,13:18.4
0,3,13:18.12
1,3,13:18.12
2,3,13:18.12
3,3,13:18.4
6,3,13:18.12
7,3,13:18.12
8,3,13:18.12
-6,4,13:18.12
-5,4,13:18.4
-4,4,13:18.4
-1,4,13:18.12
0,4,13:18.12
1,4,13:18.12
2,4,13:18.12
3,4,13:18.12
4,4,13:18.12
5,4,13:17.12
6,4,13:18.12
7,4,13:18.12
8,4,13:18.12
-6,5,13:18.12
-5,5,13:18.4
-2,5,13:18.12
-1,5,13:18.12
0,5,13:18.12
1,5,13:18.12
2,5,13:18.12
3,5,13:18.12
4,5,13:18.12
5,5,13:17.12
6,5,13:18.12
7,5,13:18.12
8,5,13:18.12
9,5,13:18.12
10,5,13:18.12
-6,6,13:18.12
-5,6,13:18.12
-3,6,13:18.12
-2,6,13:18.12
-1,6,13:18.12
7,6,13:18.12
9,6,13:18.12
10,6,13:18.12
-2,7,13:18.12
-1,7,13:18.12
6,7,13:18.12
8,7,13:18.12
9,7,13:18.12
10,7,13:18.12
4,8,13:18.12
5,8,13:18.12
-1,9,13:18.12
1,9,13:18.12
2,9,13:18.12
-6,-7,14:18.12
-5,-7,14:18.12
-2,-7,14:18.12
0,-7,14:18.12
-2,-6,14:18.12
0,-6,14:18.12
1,-6,14:18.12
2,-6,14:18.12
3,-6,14:18.12
-2,-5,14:18.12
-1,-5,14:18.12
0,-5,14:18.12
1,-5,14:18.12
2,-5,14:18.12
-4,-4,14:18.12
-3,-4,14:18.12
1,-4,14:18.12
2,-4,14:18.12
3,-4,14:18.12
4,-4,14:18.12
5,-4,14:18.12
-5,-3,14:18.12
-4,-3,14:18.12
-3,-3,14:18.12
-2,-3,14:18.12
-1,-3,14:18.12
0,-3,14:18.12
1,-3,14:18.12
2,-3,14:18.12
3,-3,14:18.12
4,-3,14:18.12
7,-3,14:18.12
-6,-2,14:18.12
-5,-2,14:18.12
-4,-2,14:18.12
-3,-2,14:18.12
-1,-2,14:18.12
0,-2,14:18.12
1,-2,14:18.12
2,-2,14:18.12
3,-2,14:18.12
7,-2,14:18.12
-6,-1,14:18.12
-5,-1,14:18.12
-4,-1,14:18.12
-3,-1,14:18.12
-2,-1,14:18.12
-1,-1,14:18.12
0,-1,14:18.12
1,-1,14:18.12
2,-1,14:18.12
3,-1,14:18.12
4,-1,14:18.12
6,-1,14:18.12
7,-1,14:18.12
8,-1,14:18.12
-5,0,14:18.12
-4,0,14:18.12
-3,0,14:18.12
-2,0,14:18.12
-1,0,14:18.12
0,0,14:18.12
1,0,14:18.12
2,0,14:18.12
3,0,14:18.12
5,0,14:18.12
6,0,14:18.12
7,0,14:18.12
-6,1,14:18.12
-5,1,14:18.12
-4,1,14:18.12
-2,1,14:18.12
-1,1,14:18.12
0,1,14:18.4
1,1,14:18.12
-6,2,14:18.12
-5,2,14:18.12
-4,2,14:18.12
1,2,14:18.12
3,2,14:18.12
6,2,14:18.12
7,2,14:18.12
-6,3,14:18.12
-5,3,14:18.12
-4,3,14:18.12
1,3,14:18.12
4,3,14:18.4
5,3,14:18.12
-5,4,14:18.12
3,4,14:18.12
4,4,14:18.12
5,4,14:18.12
6,4,14:18.12
2,5,14:18.12
3,5,14:18.12
4,5,14:18.12
5,5,14:18.12
6,5,14:18.12
2,6,14:18.12
3,6,14:18.12
6,6,14:18.12
5,7,14:18.12
6,7,14:18.12
3,-5,15:18.12
4,-5,15:18.12
5,-5,15:18.12
-3,-4,15:18.12
1,-4,15:18.12
2,-4,15:18.12
3,-4,15:18.12
4,-4,15:18.12
5,-4,15:18.12
-5,-3,15:18.12
-4,-3,15:18.12
-1,-3,15:18.12
0,-3,15:18.12
1,-3,15:18.12
2,-3,15:18.12
3,-3,15:18.12
4,-3,15:18.12
5,-3,15:18.12
-5,-2,15:18.12
-3,-2,15:18.12
-2,-2,15:18.12
-1,-2,15:18.12
0,-2,15:18.12
1,-2,15:18.12
2,-2,15:18.12
3,-2,15:18.12
4,-2,15:18.12
-5,-1,15:18.12
-1,-1,15:18.12
0,-1,15:18.12
1,-1,15:18.12
2,-1,15:18.12
3,-1,15:18.12
8,-1,15:18.12
-5,0,15:18.12
-4,0,15:18.12
-3,0,15:18.12
1,0,15:18.12
2,0,15:18.12
3,0,15:18.12
6,0,15:18.12
7,0,15:18.12
8,0,15:18.12
-4,1,15:18.12
-3,1,15:18.12
0,1,15:18.12
1,1,15:18.12
3,1,15:18.12
7,1,15:18.12
-4,2,15:18.12
1,2,15:18.12
4,3,15:18.12
5,3,15:18.12
4,4,15:18.12
5,4,15:18.12
3,5,15:18.12
4,-4,16:18.12
-2,-3,16:18.12
-1,-3,16:18.12
2,-3,16:18.12
3,-3,16:18.12
4,-3,16:18.12
-5,-2,16:18.12
-3,-2,16:18.12
-2,-2,16:18.12
-1,-2,16:18.12
1,-2,16:18.12
2,-2,16:17.12
3,-2,16:18.12
4,-2,16:18.12
-5,-1,16:18.12
-3,-1,16:18.12
-2,-1,16:18.12
-1,-1,16:18.12
1,-1,16:18.12
2,-1,16:18.12
3,-1,16:18.12
4,-1,16:18.12
1,0,16:18.12
3,-3,17:18.12
4,-3,17:18.12
2,-2,17:18.12
3,-2,17:18.12
4,-2,17:18.12
0,-1,17:18.12
1,-1,17:18.12
2,-1,17:18.12
3,-1,17:18.12
1,0,17:18.12
2,0,17:18.12
