[META]
version=2.0
spawnOnBlockType=2
spawnSunlight=True
spawnDarkness=True
spawnWater=False
spawnLava=False
underFill=False
randomRotation=True
dig=True
tree=False
branch=False
needsFoundation=True
rarity=100
collisionPercentage=20
spawnElevationMin=0
spawnElevationMax=200
spawnInBiome=Custom
[DATA]
-1,-5,-3:17.12
-2,-4,-3:17.12
-1,-4,-3:17.12
0,-4,-3:17.12
1,-4,-3:17.12
-1,-3,-3:17.12
0,-3,-3:17.12
1,-3,-3:17.12
2,-3,-3:17.12
0,-2,-3:17.12
1,-2,-3:17.12
-1,-1,-3:17.12
0,-1,-3:17.12
1,-1,-3:17.12
-2,0,-3:17.12
0,0,-3:17.12
1,0,-3:17.12
2,0,-3:17.12
-3,1,-3:17.12
-2,1,-3:17.12
-1,1,-3:17.12
0,1,-3:17.12
1,1,-3:17.12
-2,2,-3:17.12
-1,2,-3:17.12
0,2,-3:17.12
1,2,-3:17.12
-1,3,-3:17.12
0,3,-3:17.12
1,3,-3:17.12
-2,4,-3:17.12
-1,4,-3:17.12
0,4,-3:17.12
1,4,-3:17.12
2,4,-3:17.12
-1,5,-3:17.12
1,5,-3:17.12
-2,-7,-2:17.12
-8,-6,-2:17.12
-1,-6,-2:17.12
3,-6,-2:17.12
-2,-5,-2:17.12
-1,-5,-2:17.12
0,-5,-2:17.12
2,-5,-2:17.12
3,-5,-2:17.12
-7,-4,-2:17.12
-5,-4,-2:17.12
-2,-4,-2:17.12
-1,-4,-2:17.12
0,-4,-2:17.12
1,-4,-2:17.12
2,-4,-2:17.12
3,-4,-2:17.12
6,-4,-2:17.12
7,-4,-2:17.12
-5,-3,-2:17.12
-2,-3,-2:17.12
-1,-3,-2:17.12
0,-3,-2:17.12
1,-3,-2:17.12
2,-3,-2:17.12
5,-3,-2:17.12
6,-3,-2:17.12
-5,-2,-2:17.12
-1,-2,-2:17.12
0,-2,-2:17.12
1,-2,-2:17.12
2,-2,-2:17.12
4,-2,-2:17.12
5,-2,-2:17.12
-4,-1,-2:17.12
-3,-1,-2:17.12
-1,-1,-2:17.12
0,-1,-2:17.12
1,-1,-2:17.12
2,-1,-2:17.12
4,-1,-2:17.12
-3,0,-2:17.12
-2,0,-2:17.12
-1,0,-2:17.12
0,0,-2:17.12
1,0,-2:17.12
2,0,-2:17.12
3,0,-2:17.12
-3,1,-2:17.12
-2,1,-2:17.12
-1,1,-2:17.12
0,1,-2:17.12
1,1,-2:17.12
2,1,-2:17.12
-3,2,-2:17.12
-2,2,-2:17.12
-1,2,-2:17.12
0,2,-2:17.12
1,2,-2:17.12
-2,3,-2:17.12
-1,3,-2:17.12
0,3,-2:17.12
1,3,-2:17.12
2,3,-2:17.12
-2,4,-2:17.12
-1,4,-2:17.12
0,4,-2:17.12
1,4,-2:17.12
2,4,-2:17.12
-2,5,-2:17.12
-1,5,-2:17.12
0,5,-2:17.12
1,5,-2:17.12
-6,-5,-1:17.12
-5,-5,-1:17.12
-1,-5,-1:17.12
-4,-4,-1:17.12
-1,-4,-1:17.12
0,-4,-1:17.12
1,-4,-1:17.12
-4,-3,-1:17.12
-1,-3,-1:17.12
0,-3,-1:17.12
1,-3,-1:17.12
2,-3,-1:17.12
4,-3,-1:17.12
5,-3,-1:17.12
-4,-2,-1:17.12
-3,-2,-1:17.12
-2,-2,-1:17.12
-1,-2,-1:17.12
0,-2,-1:17.12
1,-2,-1:17.12
2,-2,-1:17.12
3,-2,-1:17.12
4,-2,-1:17.12
-2,-1,-1:17.12
-1,-1,-1:17.12
0,-1,-1:17.12
1,-1,-1:17.12
2,-1,-1:17.12
3,-1,-1:17.12
-2,0,-1:17.12
-1,0,-1:17.12
0,0,-1:17.12
1,0,-1:17.12
2,0,-1:17.12
3,0,-1:17.12
-3,1,-1:17.12
-2,1,-1:17.12
-1,1,-1:17.12
0,1,-1:17.12
1,1,-1:17.12
2,1,-1:17.12
-3,2,-1:17.12
-2,2,-1:17.12
-1,2,-1:17.12
0,2,-1:17.12
1,2,-1:17.12
2,2,-1:17.12
-3,3,-1:17.12
-2,3,-1:17.12
-1,3,-1:17.12
0,3,-1:17.12
1,3,-1:17.12
-2,4,-1:17.12
-1,4,-1:17.12
0,4,-1:17.12
1,4,-1:17.12
-1,5,-1:17.12
-1,-2,0:17.12
0,-2,0:17.12
-1,-1,0:17.12
0,-1,0:17.12
1,-1,0:17.12
2,-1,0:17.12
-2,0,0:17.12
-1,0,0:17.12
0,0,0:17.12
1,0,0:17.12
2,0,0:17.12
-2,1,0:17.12
-1,1,0:17.12
0,1,0:17.12
1,1,0:17.12
2,1,0:17.12
-2,2,0:17.12
-1,2,0:17.12
0,2,0:17.12
1,2,0:17.12
-1,3,0:17.12
0,3,0:17.12
1,3,0:17.12
-1,-2,1:17.12
0,-2,1:17.12
1,-2,1:17.12
-2,-1,1:17.12
-1,-1,1:17.12
0,-1,1:17.12
1,-1,1:17.12
-2,0,1:17.12
-1,0,1:17.12
0,0,1:17.12
1,0,1:17.12
2,0,1:17.12
-2,1,1:17.12
-1,1,1:17.12
0,1,1:17.12
1,1,1:17.12
2,1,1:17.12
-1,2,1:17.12
0,2,1:17.12
1,2,1:17.12
-1,-2,2:17.12
0,-2,2:17.12
-2,-1,2:17.12
-1,-1,2:17.12
0,-1,2:17.12
1,-1,2:17.12
-2,0,2:17.12
-1,0,2:17.12
0,0,2:17.12
1,0,2:17.12
2,0,2:17.12
-1,1,2:17.12
0,1,2:17.12
1,1,2:17.12
0,2,2:17.12
1,2,2:17.12
-1,-2,3:17.12
-2,-1,3:17.12
-1,-1,3:17.12
0,-1,3:17.12
1,-1,3:17.12
2,-1,3:17.12
-1,0,3:17.12
0,0,3:17.12
1,0,3:17.12
2,0,3:17.12
3,0,3:17.12
-1,1,3:17.12
0,1,3:17.12
1,1,3:17.12
2,1,3:17.12
0,2,3:17.12
-1,-2,4:17.12
0,-2,4:17.12
-2,-1,4:17.12
-1,-1,4:17.12
0,-1,4:17.12
1,-1,4:17.12
2,-1,4:17.12
3,-1,4:17.12
-1,0,4:17.12
0,0,4:17.12
1,0,4:17.12
2,0,4:17.12
3,0,4:17.12
0,1,4:17.12
1,1,4:17.12
2,1,4:17.12
3,1,4:17.12
-1,-3,5:17.12
0,-3,5:17.12
-2,-2,5:17.12
-1,-2,5:17.12
0,-2,5:17.12
-2,-1,5:17.12
-1,-1,5:17.12
0,-1,5:17.12
1,-1,5:17.12
2,-1,5:17.12
3,-1,5:17.12
4,-1,5:17.12
-1,0,5:17.12
0,0,5:17.12
1,0,5:17.12
2,0,5:17.12
3,0,5:17.12
4,0,5:17.12
1,1,5:17.12
2,1,5:17.12
3,1,5:17.12
4,1,5:17.12
0,-4,6:17.12
-2,-3,6:17.12
-1,-3,6:17.12
0,-3,6:17.12
-2,-2,6:17.12
-1,-2,6:17.12
0,-2,6:17.12
-1,-1,6:17.12
0,-1,6:17.12
3,-1,6:17.12
4,-1,6:17.12
5,-1,6:17.12
3,0,6:17.12
4,0,6:17.12
5,0,6:17.12
3,1,6:17.12
4,1,6:17.12
5,1,6:17.12
4,2,6:17.12
-1,-4,7:17.12
0,-4,7:17.12
-2,-3,7:17.12
-1,-3,7:17.12
0,-3,7:17.12
-2,-2,7:17.12
-1,-2,7:17.12
0,-2,7:17.12
-1,-1,7:17.12
0,-1,7:17.12
4,-1,7:18.12
6,-1,7:18.12
3,0,7:17.12
4,0,7:17.12
5,0,7:17.12
3,1,7:17.12
4,1,7:17.12
5,1,7:17.12
3,2,7:17.12
4,2,7:17.12
5,2,7:17.12
4,3,7:17.12
-2,-4,8:17.12
-1,-4,8:17.12
0,-4,8:17.12
-2,-3,8:17.12
-1,-3,8:17.12
0,-3,8:17.12
-2,-2,8:17.12
-1,-2,8:17.12
0,-2,8:17.12
4,-2,8:18.12
6,-2,8:18.12
-1,-1,8:17.12
4,-1,8:18.12
5,-1,8:18.12
6,-1,8:18.12
4,0,8:18.12
3,1,8:18.12
4,1,8:18.12
5,1,8:17.12
3,2,8:17.12
4,2,8:17.12
5,2,8:17.12
3,3,8:17.12
4,3,8:17.12
5,3,8:17.12
4,4,8:17.12
-10,7,8:18.12
-9,-13,9:18.12
2,-7,9:18.12
1,-6,9:18.12
2,-6,9:18.12
2,-5,9:18.12
-2,-4,9:17.12
-1,-4,9:17.12
0,-4,9:17.12
-3,-3,9:17.12
-2,-3,9:17.12
-1,-3,9:17.12
0,-3,9:17.12
-3,-2,9:17.12
-2,-2,9:17.12
-1,-2,9:17.12
-2,-1,9:17.12
-1,-1,9:17.12
3,-1,9:18.12
4,-1,9:18.12
4,1,9:17.12
5,1,9:17.12
3,2,9:17.12
4,2,9:17.12
5,2,9:17.12
6,2,9:17.12
3,3,9:17.12
4,3,9:17.12
5,3,9:17.12
6,3,9:17.12
3,4,9:17.12
4,4,9:17.12
5,4,9:17.12
-10,5,9:18.12
4,5,9:17.12
-10,6,9:18.12
5,6,9:17.12
-11,7,9:18.12
-10,7,9:18.12
-10,8,9:18.12
-7,-14,10:18.12
-6,-14,10:18.12
-10,-13,10:18.12
-9,-13,10:18.12
-7,-13,10:18.12
-6,-13,10:18.12
-5,-13,10:18.12
-3,-10,10:18.12
10,-7,10:18.12
2,-6,10:18.12
1,-5,10:18.12
2,-5,10:18.12
3,-5,10:18.12
-3,-4,10:17.12
-2,-4,10:17.12
-1,-4,10:17.12
0,-4,10:18.12
1,-4,10:18.12
-3,-3,10:17.12
-2,-3,10:17.12
-1,-3,10:17.12
-3,-2,10:17.12
-2,-2,10:17.12
-1,-2,10:17.12
-4,-1,10:17.12
-3,-1,10:17.12
-2,-1,10:17.12
3,-1,10:18.12
-4,0,10:17.12
-3,0,10:17.12
4,0,10:17.12
5,0,10:17.12
4,1,10:17.12
5,1,10:17.12
6,1,10:17.12
-15,2,10:18.12
4,2,10:17.12
5,2,10:17.12
6,2,10:17.12
7,2,10:17.12
4,3,10:17.12
5,3,10:17.12
6,3,10:17.12
4,4,10:17.12
5,4,10:17.12
6,4,10:17.12
4,5,10:17.12
5,5,10:17.12
-11,6,10:18.12
4,6,10:17.12
5,6,10:17.12
-11,7,10:18.12
-10,7,10:18.12
5,7,10:17.12
13,7,10:18.12
-12,8,10:18.12
-11,8,10:18.12
12,8,10:18.12
13,8,10:18.12
-10,9,10:18.12
1,16,10:18.12
10,16,10:18.12
-7,-15,11:18.12
0,-14,11:18.12
1,-14,11:18.12
2,-14,11:18.12
-9,-13,11:18.12
-8,-13,11:18.12
-7,-13,11:18.12
-6,-13,11:18.12
-1,-13,11:18.12
0,-13,11:18.12
1,-13,11:18.12
5,-13,11:18.12
-8,-12,11:18.12
-7,-12,11:18.12
-11,-10,11:18.12
-8,-10,11:18.12
-3,-10,11:18.12
-9,-9,11:18.12
-8,-9,11:18.12
-7,-9,11:18.12
-3,-9,11:18.12
7,-9,11:18.12
6,-8,11:18.12
7,-8,11:18.12
8,-8,11:18.12
6,-7,11:18.12
9,-7,11:18.12
10,-7,11:18.12
-7,-6,11:18.12
0,-6,11:18.12
2,-6,11:18.12
9,-6,11:18.12
10,-6,11:18.12
2,-5,11:18.12
10,-5,11:18.12
-3,-4,11:17.12
-2,-4,11:17.12
-1,-4,11:17.12
3,-4,11:18.12
12,-4,11:18.12
-3,-3,11:17.12
-2,-3,11:17.12
-1,-3,11:17.12
3,-3,11:18.12
5,-3,11:18.12
12,-3,11:18.12
-4,-2,11:17.12
-3,-2,11:17.12
-2,-2,11:17.12
2,-2,11:18.12
3,-2,11:18.12
5,-2,11:18.12
12,-2,11:18.12
14,-2,11:18.12
-5,-1,11:17.12
-4,-1,11:17.12
-3,-1,11:17.12
-2,-1,11:17.12
2,-1,11:18.12
4,-1,11:17.12
5,-1,11:17.12
9,-1,11:18.12
11,-1,11:18.12
-5,0,11:17.12
-4,0,11:17.12
-3,0,11:17.12
-2,0,11:17.12
5,0,11:17.12
6,0,11:17.12
11,0,11:18.12
-17,1,11:18.12
-15,1,11:18.12
-4,1,11:17.12
5,1,11:17.12
6,1,11:17.12
7,1,11:17.12
8,1,11:17.12
10,1,11:18.12
11,1,11:18.12
-17,2,11:18.12
-15,2,11:18.12
5,2,11:17.12
6,2,11:17.12
7,2,11:17.12
8,2,11:17.12
10,2,11:18.12
12,2,11:18.12
-16,3,11:18.12
-15,3,11:18.12
-14,3,11:18.12
-10,3,11:18.12
3,3,11:18.12
4,3,11:18.12
5,3,11:18.12
6,3,11:17.12
7,3,11:17.12
9,3,11:18.12
10,3,11:18.12
12,3,11:18.12
-2,4,11:18.12
3,4,11:18.12
4,4,11:18.12
5,4,11:17.12
6,4,11:17.12
11,4,11:18.12
4,5,11:18.12
5,5,11:17.12
6,5,11:17.12
12,5,11:18.12
-10,6,11:18.12
4,6,11:17.12
5,6,11:17.12
6,6,11:17.12
11,6,11:18.12
12,6,11:18.12
13,6,11:18.12
14,6,11:18.12
15,6,11:18.12
-11,7,11:18.12
-10,7,11:18.12
4,7,11:17.12
5,7,11:17.12
6,7,11:17.12
13,7,11:18.12
14,7,11:18.12
15,7,11:18.12
-12,8,11:18.12
-10,8,11:18.12
5,8,11:17.12
13,8,11:18.12
14,8,11:18.12
-11,9,11:18.12
-10,9,11:18.12
9,9,11:18.12
10,9,11:18.12
11,9,11:18.12
10,10,11:18.12
11,10,11:18.12
-10,11,11:18.12
11,11,11:18.12
9,12,11:18.12
1,14,11:18.12
10,14,11:18.12
11,14,11:18.12
1,15,11:18.12
2,15,11:18.12
10,15,11:18.12
0,16,11:18.12
1,16,11:18.12
9,16,11:18.12
10,16,11:18.12
2,-16,12:18.12
-7,-15,12:18.12
2,-15,12:18.12
-10,-14,12:18.12
-9,-14,12:18.12
-8,-14,12:18.12
-7,-14,12:18.12
2,-14,12:18.12
3,-14,12:18.12
5,-14,12:18.12
-10,-13,12:18.12
-9,-13,12:18.12
-8,-13,12:18.12
-7,-13,12:18.12
-6,-13,12:18.12
-1,-13,12:18.12
0,-13,12:18.12
1,-13,12:18.12
5,-13,12:18.12
7,-13,12:18.12
8,-13,12:18.12
-7,-12,12:18.12
0,-12,12:18.12
6,-12,12:18.12
7,-12,12:18.12
8,-12,12:18.12
9,-12,12:18.12
-8,-11,12:18.12
-7,-11,12:18.12
-5,-11,12:18.12
-4,-11,12:18.12
-3,-11,12:18.12
-2,-11,12:18.12
-1,-11,12:18.12
0,-11,12:18.12
5,-11,12:18.12
6,-11,12:18.12
7,-11,12:18.12
8,-11,12:18.12
-12,-10,12:18.12
-11,-10,12:18.12
-10,-10,12:18.12
-9,-10,12:18.12
-3,-10,12:18.12
-2,-10,12:18.12
5,-10,12:18.12
6,-10,12:18.12
-12,-9,12:18.12
-11,-9,12:18.12
-10,-9,12:18.12
-9,-9,12:18.12
-7,-9,12:18.12
-3,-9,12:18.12
-12,-8,12:18.12
-10,-8,12:18.12
-7,-8,12:18.12
-6,-8,12:18.12
2,-8,12:18.12
5,-8,12:18.12
-12,-7,12:18.12
-8,-7,12:18.12
-7,-7,12:18.12
-1,-7,12:18.12
0,-7,12:18.12
2,-7,12:18.12
5,-7,12:18.12
6,-7,12:18.12
11,-7,12:18.12
-9,-6,12:18.12
-8,-6,12:18.12
-7,-6,12:18.12
-2,-6,12:18.12
0,-6,12:18.12
1,-6,12:18.12
2,-6,12:18.12
6,-6,12:18.12
9,-6,12:18.12
11,-6,12:18.12
-8,-5,12:18.12
-2,-5,12:18.12
-1,-5,12:18.12
0,-5,12:18.12
9,-5,12:18.12
-5,-4,12:17.12
-3,-4,12:17.12
-2,-4,12:18.12
-1,-4,12:18.12
4,-4,12:18.12
5,-4,12:18.12
12,-4,12:18.12
13,-4,12:18.12
-16,-3,12:18.12
-6,-3,12:17.12
-5,-3,12:17.12
-4,-3,12:17.12
-3,-3,12:17.12
-2,-3,12:17.12
-1,-3,12:17.12
3,-3,12:18.12
5,-3,12:18.12
6,-3,12:18.12
14,-3,12:18.12
-16,-2,12:18.12
-15,-2,12:18.12
-5,-2,12:17.12
-4,-2,12:17.12
-3,-2,12:17.12
-2,-2,12:17.12
2,-2,12:18.12
3,-2,12:18.12
4,-2,12:18.12
5,-2,12:18.12
9,-2,12:18.12
10,-2,12:18.12
12,-2,12:18.12
13,-2,12:18.12
14,-2,12:18.12
-5,-1,12:18.12
-4,-1,12:17.12
-3,-1,12:17.12
-2,-1,12:17.12
3,-1,12:18.12
4,-1,12:18.12
5,-1,12:17.12
8,-1,12:18.12
9,-1,12:18.12
11,-1,12:18.12
12,-1,12:18.12
13,-1,12:18.12
-16,0,12:18.12
-15,0,12:18.12
-5,0,12:17.12
-4,0,12:17.12
-3,0,12:17.12
5,0,12:17.12
6,0,12:17.12
9,0,12:18.12
11,0,12:18.12
-17,1,12:18.12
-16,1,12:18.12
-15,1,12:18.12
-12,1,12:18.12
-8,1,12:18.12
-7,1,12:18.12
-5,1,12:17.12
-4,1,12:17.12
-3,1,12:17.12
3,1,12:18.12
4,1,12:18.12
5,1,12:17.12
6,1,12:18.12
7,1,12:17.12
8,1,12:17.12
10,1,12:18.12
11,1,12:18.12
-17,2,12:18.12
-16,2,12:18.12
-15,2,12:18.12
-13,2,12:18.12
-5,2,12:17.12
-4,2,12:17.12
1,2,12:18.12
2,2,12:18.12
3,2,12:18.12
4,2,12:18.12
5,2,12:18.12
6,2,12:17.12
7,2,12:17.12
8,2,12:17.12
9,2,12:18.12
10,2,12:18.12
11,2,12:18.12
-16,3,12:18.12
-15,3,12:18.12
-14,3,12:18.12
-10,3,12:18.12
-4,3,12:17.12
-2,3,12:18.12
3,3,12:18.12
4,3,12:18.12
5,3,12:18.12
6,3,12:18.12
7,3,12:18.12
8,3,12:18.12
10,3,12:18.12
12,3,12:18.12
13,3,12:18.12
14,3,12:18.12
-13,4,12:18.12
-2,4,12:18.12
5,4,12:18.12
6,4,12:18.12
8,4,12:18.12
9,4,12:18.12
10,4,12:18.12
11,4,12:18.12
12,4,12:18.12
13,4,12:18.12
-8,5,12:18.12
-3,5,12:18.12
4,5,12:18.12
5,5,12:18.12
8,5,12:18.12
12,5,12:18.12
-7,6,12:18.12
4,6,12:17.12
5,6,12:17.12
6,6,12:17.12
9,6,12:18.12
10,6,12:18.12
11,6,12:18.12
12,6,12:18.12
13,6,12:18.12
14,6,12:18.12
15,6,12:18.12
-11,7,12:18.12
-10,7,12:18.12
-9,7,12:18.12
4,7,12:17.12
5,7,12:17.12
6,7,12:17.12
12,7,12:18.12
13,7,12:18.12
14,7,12:18.12
-12,8,12:18.12
-11,8,12:18.12
4,8,12:17.12
5,8,12:17.12
6,8,12:17.12
10,8,12:18.12
11,8,12:18.12
12,8,12:18.12
13,8,12:18.12
-12,9,12:18.12
-11,9,12:18.12
-10,9,12:18.12
-9,9,12:18.12
9,9,12:18.12
10,9,12:18.12
11,9,12:18.12
-13,10,12:18.12
-12,10,12:18.12
-11,10,12:18.12
-10,10,12:18.12
9,10,12:18.12
10,10,12:18.12
11,10,12:18.12
12,10,12:18.12
-12,11,12:18.12
-10,11,12:18.12
9,11,12:18.12
10,11,12:18.12
11,11,12:18.12
-5,12,12:18.12
-4,12,12:18.12
-3,12,12:18.12
-2,12,12:18.12
-1,12,12:18.12
4,12,12:18.12
8,12,12:18.12
9,12,12:18.12
10,12,12:18.12
-4,13,12:18.12
-3,13,12:18.12
3,13,12:18.12
4,13,12:18.12
5,13,12:18.12
9,13,12:18.12
10,13,12:18.12
11,13,12:18.12
0,14,12:18.12
3,14,12:18.12
6,14,12:18.12
7,14,12:18.12
9,14,12:18.12
10,14,12:18.12
11,14,12:18.12
0,15,12:18.12
1,15,12:18.12
2,15,12:18.12
8,15,12:18.12
9,15,12:18.12
10,15,12:18.12
11,15,12:18.12
0,16,12:18.12
1,16,12:18.12
10,16,12:18.12
-1,-16,13:18.12
0,-16,13:18.12
1,-16,13:18.12
-7,-15,13:18.12
0,-15,13:18.12
1,-15,13:18.12
7,-15,13:18.12
-7,-14,13:18.12
-6,-14,13:18.12
0,-14,13:18.12
1,-14,13:18.12
2,-14,13:18.12
7,-14,13:18.12
-7,-13,13:18.12
-6,-13,13:18.12
-2,-13,13:18.12
-1,-13,13:18.12
0,-13,13:18.12
1,-13,13:18.12
2,-13,13:18.12
4,-13,13:18.12
5,-13,13:18.12
6,-13,13:18.12
7,-13,13:18.12
8,-13,13:18.12
-7,-12,13:18.12
-4,-12,13:18.12
-2,-12,13:18.12
-1,-12,13:18.12
1,-12,13:18.12
4,-12,13:18.12
5,-12,13:18.12
6,-12,13:18.12
7,-12,13:18.12
8,-12,13:18.12
-12,-11,13:18.12
-11,-11,13:18.12
-10,-11,13:18.12
-8,-11,13:18.12
-7,-11,13:18.12
-6,-11,13:18.12
-5,-11,13:18.12
-4,-11,13:18.12
-3,-11,13:18.12
-2,-11,13:18.12
4,-11,13:18.12
5,-11,13:18.12
6,-11,13:18.12
7,-11,13:18.12
8,-11,13:18.12
-12,-10,13:18.12
-11,-10,13:18.12
-10,-10,13:18.12
-9,-10,13:18.12
-8,-10,13:18.12
-7,-10,13:18.12
-6,-10,13:18.12
-5,-10,13:18.12
-4,-10,13:18.12
-3,-10,13:18.12
-2,-10,13:18.12
-1,-10,13:18.12
4,-10,13:18.12
6,-10,13:18.12
8,-10,13:18.12
9,-10,13:18.12
-12,-9,13:18.12
-10,-9,13:18.12
-7,-9,13:18.12
-3,-9,13:18.12
4,-9,13:18.12
6,-9,13:18.12
9,-9,13:18.12
-11,-8,13:18.12
-10,-8,13:18.12
-6,-8,13:18.12
-3,-8,13:18.12
3,-8,13:18.12
4,-8,13:18.12
5,-8,13:18.12
6,-8,13:18.12
7,-8,13:18.12
9,-8,13:18.12
10,-8,13:18.12
-12,-7,13:18.12
-8,-7,13:18.12
-7,-7,13:18.12
-6,-7,13:18.12
-3,-7,13:18.12
-1,-7,13:18.12
2,-7,13:18.12
3,-7,13:18.12
6,-7,13:18.12
9,-7,13:18.12
10,-7,13:18.12
11,-7,13:18.12
12,-7,13:18.12
-14,-6,13:18.12
-13,-6,13:18.12
-12,-6,13:18.12
-10,-6,13:18.12
-9,-6,13:18.12
-8,-6,13:18.12
-7,-6,13:18.12
-6,-6,13:18.12
-1,-6,13:18.12
0,-6,13:18.12
2,-6,13:18.12
3,-6,13:18.12
5,-6,13:18.12
9,-6,13:18.12
10,-6,13:18.12
11,-6,13:18.12
-14,-5,13:18.12
-10,-5,13:18.12
-6,-5,13:18.12
-4,-5,13:17.12
-2,-5,13:18.12
-1,-5,13:18.12
0,-5,13:18.12
1,-5,13:18.12
2,-5,13:18.12
3,-5,13:18.12
4,-5,13:17.12
10,-5,13:18.12
11,-5,13:18.12
12,-5,13:18.12
-15,-4,13:18.12
-14,-4,13:18.12
-6,-4,13:17.12
-5,-4,13:17.12
-4,-4,13:17.12
-3,-4,13:17.12
-2,-4,13:17.12
-1,-4,13:18.12
1,-4,13:18.12
2,-4,13:18.12
3,-4,13:17.12
4,-4,13:17.12
5,-4,13:17.12
9,-4,13:18.12
11,-4,13:18.12
12,-4,13:18.12
13,-4,13:18.12
-16,-3,13:18.12
-15,-3,13:18.12
-7,-3,13:17.12
-6,-3,13:17.12
-5,-3,13:18.12
-4,-3,13:17.12
-3,-3,13:17.12
-2,-3,13:18.12
-1,-3,13:18.12
3,-3,13:18.12
4,-3,13:17.12
5,-3,13:17.12
6,-3,13:17.12
8,-3,13:18.12
10,-3,13:18.12
11,-3,13:18.12
12,-3,13:18.12
-17,-2,13:18.12
-16,-2,13:18.12
-15,-2,13:18.12
-14,-2,13:18.12
-6,-2,13:18.12
-5,-2,13:18.12
-4,-2,13:17.12
-3,-2,13:17.12
-2,-2,13:17.12
-1,-2,13:18.12
3,-2,13:18.12
4,-2,13:18.12
5,-2,13:18.12
6,-2,13:17.12
9,-2,13:18.12
10,-2,13:18.12
11,-2,13:18.12
12,-2,13:18.12
13,-2,13:18.12
-15,-1,13:18.12
-6,-1,13:18.12
-5,-1,13:18.12
-4,-1,13:17.12
-3,-1,13:17.12
2,-1,13:18.12
4,-1,13:18.12
5,-1,13:18.12
8,-1,13:18.12
9,-1,13:18.12
11,-1,13:18.12
12,-1,13:18.12
-17,0,13:18.12
-16,0,13:18.12
-15,0,13:18.12
-8,0,13:18.12
-6,0,13:18.12
-5,0,13:18.12
-4,0,13:17.12
-1,0,13:18.12
9,0,13:18.12
10,0,13:18.12
11,0,13:18.12
12,0,13:18.12
13,0,13:18.12
-17,1,13:18.12
-16,1,13:18.12
-15,1,13:18.12
-14,1,13:18.12
-12,1,13:18.12
-9,1,13:18.12
-8,1,13:18.12
-7,1,13:18.12
-6,1,13:18.12
-5,1,13:17.12
-4,1,13:17.12
-2,1,13:18.12
-1,1,13:18.12
4,1,13:18.12
6,1,13:18.12
7,1,13:17.12
8,1,13:17.12
9,1,13:18.12
10,1,13:18.12
11,1,13:18.12
12,1,13:18.12
13,1,13:18.12
-17,2,13:18.12
-16,2,13:18.12
-15,2,13:18.12
-14,2,13:18.12
-13,2,13:18.12
-12,2,13:18.12
-6,2,13:18.12
-5,2,13:17.12
-4,2,13:17.12
-3,2,13:17.12
0,2,13:18.12
1,2,13:18.12
2,2,13:18.12
3,2,13:18.12
4,2,13:18.12
5,2,13:18.12
6,2,13:18.12
7,2,13:17.12
8,2,13:18.12
9,2,13:18.12
10,2,13:18.12
11,2,13:18.12
12,2,13:18.12
-16,3,13:18.12
-15,3,13:18.12
-14,3,13:18.12
-13,3,13:18.12
-12,3,13:18.12
-10,3,13:18.12
-5,3,13:17.12
-4,3,13:17.12
-2,3,13:18.12
3,3,13:18.12
4,3,13:18.12
5,3,13:18.12
6,3,13:18.12
7,3,13:18.12
8,3,13:18.12
9,3,13:18.12
10,3,13:18.12
11,3,13:18.12
12,3,13:18.12
13,3,13:18.12
14,3,13:18.12
-15,4,13:18.12
-14,4,13:18.12
-13,4,13:18.12
-8,4,13:18.12
-5,4,13:17.12
-4,4,13:17.12
-3,4,13:18.12
-2,4,13:18.12
1,4,13:18.12
6,4,13:18.12
7,4,13:18.12
8,4,13:18.12
9,4,13:18.12
10,4,13:18.12
11,4,13:18.12
12,4,13:18.12
13,4,13:18.12
-15,5,13:18.12
-10,5,13:18.12
-9,5,13:18.12
-8,5,13:18.12
-7,5,13:18.12
-5,5,13:18.12
-4,5,13:18.12
-3,5,13:18.12
0,5,13:18.12
2,5,13:18.12
8,5,13:18.12
9,5,13:18.12
10,5,13:18.12
11,5,13:18.12
12,5,13:18.12
13,5,13:18.12
14,5,13:18.12
-7,6,13:18.12
-1,6,13:18.12
0,6,13:18.12
2,6,13:18.12
4,6,13:17.12
5,6,13:17.12
6,6,13:17.12
7,6,13:18.12
10,6,13:18.12
11,6,13:18.12
12,6,13:18.12
14,6,13:18.12
-13,7,13:18.12
-12,7,13:18.12
-11,7,13:18.12
1,7,13:18.12
4,7,13:17.12
5,7,13:17.12
6,7,13:17.12
7,7,13:18.12
10,7,13:18.12
12,7,13:18.12
13,7,13:18.12
14,7,13:18.12
-12,8,13:18.12
-11,8,13:18.12
-10,8,13:18.12
4,8,13:18.12
5,8,13:17.12
6,8,13:17.12
10,8,13:18.12
11,8,13:18.12
12,8,13:18.12
-11,9,13:18.12
-10,9,13:18.12
5,9,13:17.12
11,9,13:18.12
12,9,13:18.12
-13,10,13:18.12
-12,10,13:18.12
-11,10,13:18.12
-10,10,13:18.12
9,10,13:18.12
10,10,13:18.12
11,10,13:18.12
12,10,13:18.12
13,10,13:18.12
-13,11,13:18.12
-12,11,13:18.12
-11,11,13:18.12
-10,11,13:18.12
-4,11,13:18.12
-3,11,13:18.12
7,11,13:18.12
8,11,13:18.12
9,11,13:18.12
10,11,13:18.12
11,11,13:18.12
-11,12,13:18.12
-3,12,13:18.12
-1,12,13:18.12
3,12,13:18.12
4,12,13:18.12
6,12,13:18.12
7,12,13:18.12
8,12,13:18.12
9,12,13:18.12
10,12,13:18.12
-11,13,13:18.12
-3,13,13:18.12
-2,13,13:18.12
-1,13,13:18.12
0,13,13:18.12
1,13,13:18.12
2,13,13:18.12
3,13,13:18.12
4,13,13:18.12
5,13,13:18.12
6,13,13:18.12
8,13,13:18.12
9,13,13:18.12
10,13,13:18.12
-1,14,13:18.12
0,14,13:18.12
1,14,13:18.12
2,14,13:18.12
3,14,13:18.12
4,14,13:18.12
5,14,13:18.12
6,14,13:18.12
7,14,13:18.12
8,14,13:18.12
9,14,13:18.12
10,14,13:18.12
11,14,13:18.12
-2,15,13:18.12
-1,15,13:18.12
1,15,13:18.12
2,15,13:18.12
9,15,13:18.12
10,15,13:18.12
11,15,13:18.12
1,16,13:18.12
10,16,13:18.12
2,-17,14:18.12
0,-16,14:18.12
1,-16,14:18.12
2,-16,14:18.12
3,-16,14:18.12
-7,-15,14:18.12
0,-15,14:18.12
1,-15,14:18.12
2,-15,14:18.12
3,-15,14:18.12
-11,-14,14:18.12
-7,-14,14:18.12
-6,-14,14:18.12
-1,-14,14:18.12
0,-14,14:18.12
1,-14,14:18.12
2,-14,14:18.12
3,-14,14:18.12
5,-14,14:18.12
8,-14,14:18.12
-11,-13,14:18.12
-9,-13,14:18.12
-8,-13,14:18.12
-7,-13,14:18.12
-6,-13,14:18.12
-5,-13,14:18.12
-4,-13,14:18.12
-1,-13,14:18.12
0,-13,14:18.12
1,-13,14:18.12
2,-13,14:18.12
3,-13,14:18.12
4,-13,14:18.12
5,-13,14:18.12
6,-13,14:18.12
7,-13,14:18.12
8,-13,14:18.12
-9,-12,14:18.12
-8,-12,14:18.12
-7,-12,14:18.12
-6,-12,14:18.12
-5,-12,14:18.12
-4,-12,14:18.12
-3,-12,14:18.12
-2,-12,14:18.12
0,-12,14:18.12
1,-12,14:18.12
3,-12,14:18.12
4,-12,14:18.12
5,-12,14:18.12
6,-12,14:18.12
7,-12,14:18.12
8,-12,14:18.12
9,-12,14:18.12
-11,-11,14:18.12
-9,-11,14:18.12
-7,-11,14:18.12
-6,-11,14:18.12
-5,-11,14:18.12
-4,-11,14:18.12
-3,-11,14:18.12
4,-11,14:18.12
5,-11,14:18.12
6,-11,14:18.12
7,-11,14:18.12
8,-11,14:18.12
-12,-10,14:18.12
-11,-10,14:18.12
-10,-10,14:18.12
-9,-10,14:18.12
-8,-10,14:18.12
-7,-10,14:18.12
-6,-10,14:18.12
-5,-10,14:18.12
-4,-10,14:18.12
-3,-10,14:18.12
5,-10,14:18.12
6,-10,14:18.12
-12,-9,14:18.12
-11,-9,14:18.12
-10,-9,14:18.12
-9,-9,14:18.12
-6,-9,14:18.12
-5,-9,14:18.12
-2,-9,14:18.12
6,-9,14:18.12
-13,-8,14:18.12
-12,-8,14:18.12
-11,-8,14:18.12
-10,-8,14:18.12
-5,-8,14:18.12
-4,-8,14:18.12
5,-8,14:18.12
6,-8,14:18.12
8,-8,14:18.12
9,-8,14:18.12
10,-8,14:18.12
11,-8,14:18.12
-15,-7,14:18.12
-14,-7,14:18.12
-13,-7,14:18.12
-12,-7,14:18.12
-11,-7,14:18.12
-10,-7,14:18.12
-8,-7,14:18.12
-7,-7,14:18.12
-6,-7,14:18.12
-5,-7,14:18.12
2,-7,14:18.12
5,-7,14:18.12
6,-7,14:18.12
7,-7,14:18.12
8,-7,14:18.12
9,-7,14:18.12
10,-7,14:18.12
11,-7,14:18.12
12,-7,14:18.12
-15,-6,14:18.12
-14,-6,14:18.12
-13,-6,14:18.12
-12,-6,14:18.12
-10,-6,14:18.12
-9,-6,14:18.12
-8,-6,14:18.12
-7,-6,14:18.12
-6,-6,14:18.12
-5,-6,14:18.12
-4,-6,14:18.12
0,-6,14:18.12
1,-6,14:18.12
2,-6,14:18.12
3,-6,14:18.12
4,-6,14:18.12
5,-6,14:18.12
6,-6,14:18.12
7,-6,14:18.12
8,-6,14:18.12
10,-6,14:18.12
11,-6,14:18.12
12,-6,14:18.12
-16,-5,14:18.12
-15,-5,14:18.12
-14,-5,14:18.12
-13,-5,14:18.12
-12,-5,14:18.12
-7,-5,14:18.12
-6,-5,14:17.12
-5,-5,14:18.12
-4,-5,14:17.12
-3,-5,14:17.12
-1,-5,14:18.12
0,-5,14:18.12
2,-5,14:18.12
3,-5,14:18.12
4,-5,14:18.12
5,-5,14:17.12
8,-5,14:18.12
10,-5,14:18.12
11,-5,14:18.12
12,-5,14:18.12
14,-5,14:18.12
-16,-4,14:18.12
-15,-4,14:18.12
-14,-4,14:18.12
-13,-4,14:18.12
-12,-4,14:18.12
-7,-4,14:17.12
-6,-4,14:17.12
-5,-4,14:17.12
-4,-4,14:17.12
-3,-4,14:17.12
-1,-4,14:18.12
0,-4,14:18.12
1,-4,14:18.12
2,-4,14:18.12
3,-4,14:18.12
4,-4,14:17.12
5,-4,14:17.12
6,-4,14:17.12
7,-4,14:18.12
8,-4,14:18.12
9,-4,14:18.12
10,-4,14:18.12
11,-4,14:18.12
12,-4,14:18.12
13,-4,14:18.12
-16,-3,14:18.12
-15,-3,14:18.12
-14,-3,14:18.12
-13,-3,14:18.12
-7,-3,14:17.12
-6,-3,14:17.12
-5,-3,14:17.12
-4,-3,14:17.12
-3,-3,14:17.12
-2,-3,14:17.12
-1,-3,14:18.12
2,-3,14:18.12
3,-3,14:18.12
4,-3,14:17.12
5,-3,14:17.12
6,-3,14:17.12
7,-3,14:18.12
8,-3,14:18.12
9,-3,14:18.12
10,-3,14:17.12
12,-3,14:18.12
14,-3,14:18.12
-17,-2,14:18.12
-16,-2,14:18.12
-15,-2,14:18.12
-14,-2,14:18.12
-13,-2,14:18.12
-7,-2,14:17.12
-6,-2,14:17.12
-5,-2,14:17.12
-4,-2,14:17.12
-3,-2,14:17.12
-2,-2,14:17.12
2,-2,14:18.12
5,-2,14:17.12
6,-2,14:18.12
7,-2,14:18.12
8,-2,14:18.12
9,-2,14:18.12
10,-2,14:18.12
12,-2,14:18.12
13,-2,14:18.12
14,-2,14:18.12
-14,-1,14:18.12
-11,-1,14:18.12
-8,-1,14:18.12
-6,-1,14:17.12
-4,-1,14:17.12
-3,-1,14:17.12
-2,-1,14:17.12
-1,-1,14:17.12
1,-1,14:18.12
2,-1,14:18.12
3,-1,14:18.12
4,-1,14:18.12
5,-1,14:18.12
8,-1,14:18.12
9,-1,14:18.12
10,-1,14:18.12
11,-1,14:18.12
12,-1,14:18.12
-14,0,14:18.12
-11,0,14:18.12
-9,0,14:18.12
-8,0,14:18.12
-7,0,14:18.12
-2,0,14:17.12
1,0,14:18.12
2,0,14:18.12
3,0,14:18.12
4,0,14:18.12
8,0,14:18.12
9,0,14:18.12
10,0,14:18.12
11,0,14:18.12
-15,1,14:18.12
-12,1,14:18.12
-11,1,14:18.12
-10,1,14:18.12
-8,1,14:18.12
-7,1,14:18.12
-6,1,14:18.12
-2,1,14:18.12
-1,1,14:18.12
0,1,14:18.12
1,1,14:18.12
8,1,14:18.12
9,1,14:18.12
10,1,14:18.12
11,1,14:18.12
12,1,14:18.12
13,1,14:18.12
14,1,14:18.12
-15,2,14:18.12
-11,2,14:18.12
-10,2,14:18.12
-9,2,14:18.12
-8,2,14:18.12
-6,2,14:18.12
-4,2,14:17.12
-1,2,14:18.12
0,2,14:18.12
1,2,14:18.12
2,2,14:18.12
3,2,14:18.12
9,2,14:18.12
10,2,14:18.12
11,2,14:18.12
12,2,14:18.12
13,2,14:18.12
14,2,14:18.12
-15,3,14:18.12
-14,3,14:18.12
-11,3,14:18.12
-10,3,14:18.12
-7,3,14:18.12
-4,3,14:17.12
-3,3,14:18.12
0,3,14:18.12
1,3,14:18.12
7,3,14:18.12
8,3,14:18.12
9,3,14:18.12
10,3,14:18.12
11,3,14:18.12
12,3,14:18.12
13,3,14:18.12
-15,4,14:18.12
-14,4,14:18.12
-13,4,14:18.12
-7,4,14:18.12
-6,4,14:18.12
-5,4,14:18.12
-4,4,14:17.12
-3,4,14:18.12
-2,4,14:18.12
-1,4,14:17.12
0,4,14:18.12
1,4,14:18.12
2,4,14:18.12
7,4,14:18.12
8,4,14:18.12
9,4,14:18.12
10,4,14:18.12
11,4,14:18.12
12,4,14:18.12
13,4,14:18.12
14,4,14:18.12
-13,5,14:18.12
-7,5,14:18.12
-5,5,14:18.12
-4,5,14:18.12
-3,5,14:18.12
-2,5,14:17.12
-1,5,14:18.12
0,5,14:18.12
1,5,14:18.12
2,5,14:18.12
3,5,14:18.12
4,5,14:18.12
8,5,14:18.12
9,5,14:18.12
10,5,14:18.12
12,5,14:18.12
13,5,14:18.12
14,5,14:18.12
-12,6,14:18.12
-11,6,14:18.12
-9,6,14:18.12
-7,6,14:18.12
-5,6,14:17.12
-1,6,14:18.12
0,6,14:18.12
1,6,14:18.12
2,6,14:18.12
4,6,14:18.12
5,6,14:17.12
6,6,14:17.12
7,6,14:18.12
10,6,14:18.12
11,6,14:18.12
12,6,14:18.12
13,6,14:18.12
-11,7,14:18.12
-10,7,14:18.12
-9,7,14:18.12
-1,7,14:17.12
0,7,14:17.12
1,7,14:18.12
2,7,14:18.12
3,7,14:18.12
4,7,14:18.12
5,7,14:17.12
6,7,14:17.12
7,7,14:17.12
8,7,14:17.12
9,7,14:18.12
10,7,14:18.12
11,7,14:18.12
13,7,14:18.12
-13,8,14:18.12
-12,8,14:18.12
-11,8,14:18.12
-10,8,14:18.12
-9,8,14:18.12
-8,8,14:18.12
0,8,14:18.12
1,8,14:18.12
3,8,14:18.12
4,8,14:18.12
5,8,14:18.12
6,8,14:17.12
7,8,14:18.12
8,8,14:18.12
9,8,14:18.12
10,8,14:18.12
11,8,14:18.12
12,8,14:18.12
-12,9,14:18.12
-11,9,14:18.12
-10,9,14:18.12
-9,9,14:18.12
-8,9,14:18.12
-7,9,14:18.12
-3,9,14:18.12
0,9,14:18.12
1,9,14:18.12
4,9,14:17.12
5,9,14:17.12
6,9,14:17.12
9,9,14:18.12
11,9,14:18.12
-12,10,14:18.12
-11,10,14:18.12
-10,10,14:18.12
-9,10,14:18.12
-4,10,14:18.12
-3,10,14:18.12
5,10,14:17.12
8,10,14:18.12
10,10,14:18.12
-11,11,14:18.12
-9,11,14:18.12
-8,11,14:18.12
-7,11,14:18.12
-5,11,14:18.12
-4,11,14:18.12
-3,11,14:18.12
-2,11,14:18.12
-1,11,14:18.12
0,11,14:18.12
6,11,14:18.12
8,11,14:18.12
9,11,14:18.12
11,11,14:18.12
-6,12,14:18.12
-5,12,14:18.12
-4,12,14:18.12
-3,12,14:18.12
-2,12,14:18.12
-1,12,14:18.12
0,12,14:18.12
3,12,14:18.12
5,12,14:18.12
6,12,14:18.12
7,12,14:18.12
8,12,14:18.12
-9,13,14:18.12
-8,13,14:18.12
-6,13,14:18.12
-5,13,14:18.12
-4,13,14:18.12
-3,13,14:18.12
-2,13,14:18.12
-1,13,14:18.12
1,13,14:18.12
2,13,14:18.12
3,13,14:18.12
5,13,14:18.12
6,13,14:18.12
7,13,14:18.12
8,13,14:18.12
9,13,14:18.12
10,13,14:18.12
11,13,14:18.12
-3,14,14:18.12
-2,14,14:18.12
-1,14,14:18.12
0,14,14:18.12
1,14,14:18.12
2,14,14:18.12
3,14,14:18.12
4,14,14:18.12
6,14,14:18.12
7,14,14:18.12
8,14,14:18.12
9,14,14:18.12
10,14,14:18.12
11,14,14:18.12
12,14,14:18.12
-3,15,14:18.12
1,15,14:18.12
2,15,14:18.12
4,15,14:18.12
5,15,14:18.12
9,15,14:18.12
3,16,14:18.12
4,16,14:18.12
0,-16,15:18.12
-7,-15,15:18.12
-3,-15,15:18.12
-1,-15,15:18.12
0,-15,15:18.12
1,-15,15:18.12
2,-15,15:18.12
3,-15,15:18.12
8,-15,15:18.12
-11,-14,15:18.12
-10,-14,15:18.12
-8,-14,15:18.12
-7,-14,15:18.12
-6,-14,15:18.12
-4,-14,15:18.12
-3,-14,15:18.12
-2,-14,15:18.12
-1,-14,15:18.12
0,-14,15:18.12
1,-14,15:18.12
2,-14,15:18.12
3,-14,15:18.12
8,-14,15:18.12
9,-14,15:18.12
-12,-13,15:18.12
-11,-13,15:18.12
-10,-13,15:18.12
-9,-13,15:18.12
-8,-13,15:18.12
-7,-13,15:18.12
-6,-13,15:18.12
-5,-13,15:18.12
-4,-13,15:18.12
-3,-13,15:18.12
-2,-13,15:18.12
-1,-13,15:18.12
0,-13,15:18.12
1,-13,15:18.12
2,-13,15:18.12
3,-13,15:18.12
4,-13,15:18.12
5,-13,15:18.12
6,-13,15:18.12
7,-13,15:18.12
8,-13,15:18.12
-12,-12,15:18.12
-11,-12,15:18.12
-10,-12,15:18.12
-9,-12,15:18.12
-8,-12,15:18.12
-7,-12,15:18.12
-6,-12,15:18.12
-5,-12,15:18.12
-4,-12,15:18.12
-3,-12,15:18.12
-2,-12,15:18.12
-1,-12,15:18.12
0,-12,15:18.12
2,-12,15:18.12
4,-12,15:18.12
5,-12,15:18.12
6,-12,15:18.12
7,-12,15:18.12
8,-12,15:18.12
9,-12,15:18.12
10,-12,15:18.12
-14,-11,15:18.12
-13,-11,15:18.12
-12,-11,15:18.12
-11,-11,15:18.12
-10,-11,15:18.12
-9,-11,15:18.12
-8,-11,15:18.12
-6,-11,15:18.12
-5,-11,15:18.12
-4,-11,15:18.12
-3,-11,15:18.12
-2,-11,15:18.12
6,-11,15:18.12
7,-11,15:18.12
8,-11,15:18.12
9,-11,15:18.12
10,-11,15:18.12
-13,-10,15:18.12
-12,-10,15:18.12
-11,-10,15:18.12
-10,-10,15:18.12
-8,-10,15:18.12
-6,-10,15:18.12
-5,-10,15:18.12
-4,-10,15:18.12
-3,-10,15:18.12
-1,-10,15:18.12
0,-10,15:18.12
6,-10,15:18.12
7,-10,15:18.12
8,-10,15:18.12
9,-10,15:18.12
10,-10,15:18.12
-12,-9,15:18.12
-11,-9,15:18.12
-10,-9,15:18.12
-9,-9,15:18.12
-8,-9,15:18.12
-7,-9,15:18.12
-6,-9,15:18.12
-4,-9,15:18.12
-3,-9,15:18.12
-2,-9,15:18.12
-1,-9,15:18.12
0,-9,15:18.12
1,-9,15:18.12
2,-9,15:17.12
3,-9,15:17.12
4,-9,15:18.12
8,-9,15:18.12
9,-9,15:18.12
10,-9,15:18.12
11,-9,15:18.12
-11,-8,15:18.12
-10,-8,15:18.12
-9,-8,15:18.12
-8,-8,15:18.12
-7,-8,15:18.12
-6,-8,15:18.12
-5,-8,15:18.12
-2,-8,15:18.12
-1,-8,15:18.12
0,-8,15:18.12
2,-8,15:17.12
4,-8,15:18.12
5,-8,15:18.12
7,-8,15:18.12
8,-8,15:18.12
9,-8,15:18.12
10,-8,15:18.12
11,-8,15:18.12
-15,-7,15:18.12
-13,-7,15:18.12
-12,-7,15:18.12
-11,-7,15:18.12
-10,-7,15:18.12
-9,-7,15:18.12
-8,-7,15:18.12
-7,-7,15:18.12
-6,-7,15:18.12
-5,-7,15:18.12
-3,-7,15:18.12
-2,-7,15:18.12
-1,-7,15:18.12
0,-7,15:18.12
1,-7,15:18.12
2,-7,15:18.12
3,-7,15:17.12
4,-7,15:18.12
5,-7,15:18.12
6,-7,15:18.12
7,-7,15:18.12
8,-7,15:18.12
9,-7,15:18.12
10,-7,15:18.12
11,-7,15:18.12
12,-7,15:18.12
13,-7,15:18.12
-15,-6,15:18.12
-14,-6,15:18.12
-13,-6,15:18.12
-12,-6,15:18.12
-11,-6,15:18.12
-10,-6,15:18.12
-9,-6,15:18.12
-8,-6,15:18.12
-7,-6,15:18.12
-6,-6,15:18.12
-5,-6,15:18.12
-4,-6,15:18.12
-3,-6,15:18.12
-2,-6,15:18.12
-1,-6,15:18.12
0,-6,15:18.12
1,-6,15:18.12
2,-6,15:18.12
3,-6,15:17.12
4,-6,15:18.12
5,-6,15:18.12
9,-6,15:18.12
10,-6,15:18.12
11,-6,15:18.12
12,-6,15:18.12
13,-6,15:18.12
-16,-5,15:18.12
-13,-5,15:18.12
-12,-5,15:18.12
-11,-5,15:18.12
-10,-5,15:18.12
-9,-5,15:18.12
-7,-5,15:18.12
-6,-5,15:18.12
-5,-5,15:18.12
-4,-5,15:18.12
-2,-5,15:18.12
-1,-5,15:18.12
0,-5,15:18.12
1,-5,15:18.12
2,-5,15:18.12
3,-5,15:18.12
4,-5,15:18.12
5,-5,15:18.12
8,-5,15:18.12
9,-5,15:18.12
10,-5,15:18.12
11,-5,15:18.12
12,-5,15:18.12
13,-5,15:18.12
14,-5,15:18.12
-17,-4,15:18.12
-16,-4,15:18.12
-15,-4,15:18.12
-14,-4,15:18.12
-13,-4,15:18.12
-12,-4,15:18.12
-9,-4,15:18.12
-7,-4,15:18.12
-6,-4,15:18.12
-5,-4,15:18.12
-4,-4,15:17.12
-3,-4,15:17.12
-2,-4,15:18.12
-1,-4,15:18.12
0,-4,15:18.12
1,-4,15:18.12
2,-4,15:18.12
3,-4,15:18.12
4,-4,15:17.12
5,-4,15:18.12
7,-4,15:18.12
8,-4,15:18.12
9,-4,15:18.12
10,-4,15:18.12
11,-4,15:18.12
12,-4,15:18.12
14,-4,15:18.12
-17,-3,15:18.12
-16,-3,15:18.12
-14,-3,15:18.12
-13,-3,15:18.12
-9,-3,15:18.12
-8,-3,15:18.12
-7,-3,15:17.12
-6,-3,15:17.12
-5,-3,15:18.12
-4,-3,15:17.12
-3,-3,15:17.12
-2,-3,15:18.12
-1,-3,15:18.12
0,-3,15:18.12
1,-3,15:18.12
2,-3,15:18.12
3,-3,15:18.12
4,-3,15:17.12
5,-3,15:17.12
6,-3,15:17.12
7,-3,15:17.12
8,-3,15:17.12
9,-3,15:18.12
10,-3,15:18.12
11,-3,15:17.12
12,-3,15:18.12
13,-3,15:18.12
14,-3,15:18.12
15,-3,15:18.12
-15,-2,15:18.12
-14,-2,15:18.12
-13,-2,15:18.12
-8,-2,15:17.12
-7,-2,15:17.12
-6,-2,15:17.12
-5,-2,15:17.12
-4,-2,15:17.12
-3,-2,15:17.12
-2,-2,15:17.12
-1,-2,15:18.12
0,-2,15:18.12
1,-2,15:18.12
6,-2,15:18.12
7,-2,15:18.12
8,-2,15:18.12
9,-2,15:18.12
10,-2,15:17.12
11,-2,15:17.12
12,-2,15:17.12
13,-2,15:18.12
14,-2,15:18.12
-16,-1,15:18.12
-15,-1,15:18.12
-14,-1,15:18.12
-9,-1,15:17.12
-8,-1,15:17.12
-7,-1,15:17.12
-6,-1,15:17.12
-5,-1,15:17.12
-4,-1,15:17.12
-3,-1,15:17.12
-2,-1,15:17.12
-1,-1,15:18.12
0,-1,15:18.12
1,-1,15:18.12
2,-1,15:18.12
3,-1,15:18.12
4,-1,15:18.12
11,-1,15:18.12
14,-1,15:18.12
-15,0,15:18.12
-14,0,15:18.12
-13,0,15:18.12
-12,0,15:18.12
-9,0,15:18.12
-8,0,15:18.12
-7,0,15:18.12
-4,0,15:18.12
-3,0,15:17.12
-2,0,15:17.12
-1,0,15:17.12
0,0,15:18.12
1,0,15:18.12
2,0,15:18.12
3,0,15:18.12
4,0,15:18.12
10,0,15:18.12
11,0,15:18.12
14,0,15:18.12
-16,1,15:18.12
-15,1,15:18.12
-14,1,15:18.12
-12,1,15:18.12
-10,1,15:18.12
-9,1,15:18.12
-8,1,15:18.12
-7,1,15:18.12
-6,1,15:18.12
-5,1,15:18.12
-2,1,15:17.12
0,1,15:18.12
1,1,15:18.12
2,1,15:18.12
3,1,15:18.12
4,1,15:18.12
5,1,15:18.12
9,1,15:18.12
10,1,15:18.12
11,1,15:18.12
12,1,15:18.12
13,1,15:18.12
14,1,15:18.12
-16,2,15:18.12
-15,2,15:18.12
-13,2,15:18.12
-12,2,15:18.12
-11,2,15:18.12
-10,2,15:18.12
-9,2,15:18.12
-8,2,15:18.12
-6,2,15:18.12
-4,2,15:18.12
1,2,15:18.12
2,2,15:18.12
3,2,15:18.12
4,2,15:18.12
10,2,15:18.12
11,2,15:18.12
13,2,15:18.12
14,2,15:18.12
-14,3,15:18.12
-13,3,15:18.12
-12,3,15:18.12
-10,3,15:18.12
-9,3,15:18.12
-8,3,15:18.12
-6,3,15:18.12
-4,3,15:18.12
-1,3,15:18.12
1,3,15:18.12
2,3,15:18.12
3,3,15:18.12
9,3,15:18.12
12,3,15:18.12
-14,4,15:18.12
-13,4,15:18.12
-12,4,15:18.12
-11,4,15:18.12
-10,4,15:18.12
-9,4,15:18.12
-8,4,15:18.12
-7,4,15:18.12
-6,4,15:18.12
-5,4,15:18.12
-2,4,15:18.12
-1,4,15:18.12
1,4,15:18.12
2,4,15:18.12
8,4,15:18.12
9,4,15:18.12
10,4,15:18.12
11,4,15:18.12
13,4,15:18.12
-13,5,15:18.12
-12,5,15:18.12
-11,5,15:18.12
-10,5,15:18.12
-9,5,15:18.12
-8,5,15:18.12
-7,5,15:18.12
-6,5,15:18.12
-5,5,15:18.12
-4,5,15:18.12
-2,5,15:17.12
-1,5,15:18.12
0,5,15:18.12
1,5,15:18.12
7,5,15:18.12
8,5,15:18.12
9,5,15:18.12
10,5,15:18.12
13,5,15:18.12
14,5,15:18.12
-11,6,15:18.12
-10,6,15:18.12
-9,6,15:18.12
-8,6,15:18.12
-7,6,15:18.12
-6,6,15:18.12
-5,6,15:17.12
-4,6,15:17.12
-2,6,15:17.12
-1,6,15:17.12
0,6,15:18.12
1,6,15:17.12
2,6,15:18.12
5,6,15:18.12
6,6,15:17.12
7,6,15:18.12
8,6,15:18.12
9,6,15:18.12
10,6,15:18.12
11,6,15:18.12
12,6,15:18.12
-11,7,15:18.12
-10,7,15:18.12
-9,7,15:18.12
-8,7,15:18.12
-6,7,15:17.12
-5,7,15:17.12
-2,7,15:17.12
-1,7,15:17.12
0,7,15:17.12
1,7,15:17.12
2,7,15:18.12
3,7,15:18.12
4,7,15:18.12
5,7,15:18.12
6,7,15:18.12
7,7,15:18.12
8,7,15:18.12
9,7,15:17.12
10,7,15:18.12
11,7,15:18.12
12,7,15:18.12
13,7,15:18.12
-12,8,15:18.12
-11,8,15:18.12
-10,8,15:18.12
-9,8,15:18.12
-8,8,15:18.12
-4,8,15:18.12
-1,8,15:17.12
0,8,15:17.12
1,8,15:18.12
2,8,15:18.12
4,8,15:17.12
5,8,15:17.12
6,8,15:17.12
7,8,15:18.12
8,8,15:18.12
9,8,15:18.12
10,8,15:18.12
11,8,15:18.12
12,8,15:18.12
-13,9,15:18.12
-12,9,15:18.12
-11,9,15:18.12
-10,9,15:18.12
-9,9,15:18.12
-8,9,15:18.12
-7,9,15:18.12
-5,9,15:18.12
-3,9,15:18.12
0,9,15:18.12
1,9,15:18.12
2,9,15:18.12
3,9,15:18.12
4,9,15:17.12
5,9,15:17.12
6,9,15:18.12
7,9,15:18.12
8,9,15:18.12
9,9,15:18.12
10,9,15:18.12
11,9,15:18.12
12,9,15:18.12
-12,10,15:18.12
-11,10,15:18.12
-9,10,15:18.12
-5,10,15:18.12
-4,10,15:18.12
-3,10,15:18.12
2,10,15:18.12
3,10,15:18.12
4,10,15:17.12
5,10,15:18.12
6,10,15:18.12
7,10,15:18.12
8,10,15:18.12
9,10,15:18.12
-9,11,15:18.12
-8,11,15:18.12
-5,11,15:18.12
-4,11,15:18.12
-3,11,15:18.12
-2,11,15:18.12
-1,11,15:18.12
0,11,15:18.12
1,11,15:18.12
3,11,15:18.12
5,11,15:18.12
6,11,15:18.12
7,11,15:18.12
8,11,15:18.12
9,11,15:18.12
11,11,15:18.12
-10,12,15:18.12
-9,12,15:18.12
-8,12,15:18.12
-7,12,15:18.12
-6,12,15:18.12
-5,12,15:18.12
-2,12,15:18.12
-1,12,15:18.12
0,12,15:18.12
1,12,15:18.12
2,12,15:18.12
3,12,15:18.12
4,12,15:18.12
5,12,15:18.12
6,12,15:18.12
7,12,15:18.12
8,12,15:18.12
9,12,15:18.12
-9,13,15:18.12
-6,13,15:18.12
-5,13,15:18.12
-4,13,15:18.12
-2,13,15:18.12
-1,13,15:18.12
0,13,15:18.12
1,13,15:18.12
2,13,15:18.12
3,13,15:18.12
4,13,15:18.12
5,13,15:18.12
6,13,15:18.12
7,13,15:18.12
8,13,15:18.12
10,13,15:18.12
-9,14,15:18.12
-4,14,15:18.12
1,14,15:18.12
2,14,15:18.12
3,14,15:18.12
4,14,15:18.12
5,14,15:18.12
6,14,15:18.12
7,14,15:18.12
8,14,15:18.12
9,14,15:18.12
1,15,15:18.12
3,15,15:18.12
4,15,15:18.12
6,15,15:18.12
9,15,15:18.12
3,16,15:18.12
4,16,15:18.12
3,17,15:18.12
0,-15,16:18.12
1,-15,16:18.12
2,-15,16:18.12
3,-15,16:18.12
-10,-14,16:18.12
-9,-14,16:18.12
-6,-14,16:18.12
-4,-14,16:18.12
-1,-14,16:18.12
0,-14,16:18.12
1,-14,16:18.12
2,-14,16:18.12
3,-14,16:18.12
8,-14,16:18.12
9,-14,16:18.12
-13,-13,16:18.12
-12,-13,16:18.12
-11,-13,16:18.12
-10,-13,16:18.12
-9,-13,16:18.12
-8,-13,16:18.12
-6,-13,16:18.12
-4,-13,16:18.12
-3,-13,16:18.12
-2,-13,16:18.12
-1,-13,16:18.12
0,-13,16:18.12
1,-13,16:18.12
2,-13,16:18.12
3,-13,16:18.12
4,-13,16:18.12
7,-13,16:18.12
8,-13,16:18.12
9,-13,16:18.12
-10,-12,16:18.12
-9,-12,16:18.12
-6,-12,16:18.12
-5,-12,16:18.12
-4,-12,16:18.12
-3,-12,16:18.12
-2,-12,16:18.12
-1,-12,16:18.12
0,-12,16:18.12
1,-12,16:18.12
2,-12,16:18.12
3,-12,16:18.12
4,-12,16:18.12
5,-12,16:18.12
6,-12,16:18.12
7,-12,16:18.12
8,-12,16:18.12
9,-12,16:18.12
-12,-11,16:18.12
-11,-11,16:18.12
-10,-11,16:18.12
-9,-11,16:18.12
-8,-11,16:18.12
-6,-11,16:18.12
-5,-11,16:18.12
-4,-11,16:18.12
-3,-11,16:18.12
-2,-11,16:18.12
-1,-11,16:18.12
0,-11,16:18.12
4,-11,16:18.12
5,-11,16:18.12
6,-11,16:18.12
7,-11,16:18.12
8,-11,16:18.12
9,-11,16:18.12
10,-11,16:18.12
-12,-10,16:18.12
-11,-10,16:18.12
-10,-10,16:18.12
-9,-10,16:18.12
-8,-10,16:18.12
-7,-10,16:18.12
-6,-10,16:18.12
-5,-10,16:18.12
-4,-10,16:18.12
-3,-10,16:18.12
-2,-10,16:18.12
-1,-10,16:18.12
0,-10,16:18.12
1,-10,16:18.12
2,-10,16:17.12
6,-10,16:18.12
7,-10,16:18.12
8,-10,16:18.12
9,-10,16:18.12
10,-10,16:18.12
-13,-9,16:18.12
-12,-9,16:18.12
-11,-9,16:18.12
-10,-9,16:18.12
-9,-9,16:18.12
-8,-9,16:18.12
-7,-9,16:18.12
-5,-9,16:18.12
-4,-9,16:18.12
-3,-9,16:18.12
-2,-9,16:18.12
-1,-9,16:18.12
0,-9,16:18.12
1,-9,16:18.12
2,-9,16:17.12
3,-9,16:17.12
6,-9,16:18.12
7,-9,16:18.12
8,-9,16:18.12
10,-9,16:18.12
-14,-8,16:18.12
-13,-8,16:18.12
-12,-8,16:18.12
-11,-8,16:18.12
-10,-8,16:18.12
-9,-8,16:18.12
-8,-8,16:18.12
-7,-8,16:18.12
-6,-8,16:18.12
-2,-8,16:18.12
-1,-8,16:18.12
0,-8,16:18.12
1,-8,16:18.12
2,-8,16:18.12
3,-8,16:17.12
5,-8,16:18.12
9,-8,16:18.12
10,-8,16:18.12
12,-8,16:18.12
-14,-7,16:18.12
-13,-7,16:18.12
-12,-7,16:18.12
-11,-7,16:18.12
-10,-7,16:18.12
-9,-7,16:18.12
-8,-7,16:18.12
-7,-7,16:18.12
-6,-7,16:18.12
-5,-7,16:18.12
-4,-7,16:18.12
-3,-7,16:18.12
-2,-7,16:18.12
-1,-7,16:18.12
0,-7,16:18.12
1,-7,16:18.12
2,-7,16:17.12
3,-7,16:17.12
4,-7,16:18.12
5,-7,16:18.12
6,-7,16:18.12
9,-7,16:18.12
10,-7,16:18.12
11,-7,16:18.12
12,-7,16:18.12
13,-7,16:18.12
-15,-6,16:18.12
-14,-6,16:18.12
-13,-6,16:18.12
-12,-6,16:18.12
-11,-6,16:18.12
-10,-6,16:18.12
-9,-6,16:18.12
-8,-6,16:18.12
-7,-6,16:18.12
-6,-6,16:18.12
-5,-6,16:17.12
-4,-6,16:18.12
-3,-6,16:18.12
-2,-6,16:18.12
-1,-6,16:18.12
0,-6,16:18.12
1,-6,16:18.12
2,-6,16:17.12
3,-6,16:18.12
4,-6,16:18.12
5,-6,16:18.12
8,-6,16:18.12
9,-6,16:18.12
10,-6,16:18.12
11,-6,16:18.12
12,-6,16:18.12
13,-6,16:18.12
14,-6,16:18.12
-14,-5,16:18.12
-13,-5,16:18.12
-12,-5,16:18.12
-11,-5,16:18.12
-10,-5,16:18.12
-8,-5,16:18.12
-7,-5,16:18.12
-6,-5,16:18.12
-5,-5,16:18.12
-3,-5,16:18.12
-1,-5,16:18.12
0,-5,16:18.12
1,-5,16:18.12
2,-5,16:18.12
3,-5,16:18.12
4,-5,16:18.12
5,-5,16:17.12
9,-5,16:18.12
10,-5,16:18.12
11,-5,16:18.12
12,-5,16:18.12
13,-5,16:18.12
14,-5,16:18.12
-16,-4,16:18.12
-15,-4,16:18.12
-14,-4,16:18.12
-13,-4,16:18.12
-7,-4,16:18.12
-6,-4,16:17.12
-5,-4,16:17.12
-2,-4,16:18.12
-1,-4,16:18.12
0,-4,16:18.12
1,-4,16:18.12
2,-4,16:18.12
3,-4,16:18.12
4,-4,16:17.12
5,-4,16:18.12
8,-4,16:18.12
9,-4,16:18.12
10,-4,16:18.12
11,-4,16:18.12
12,-4,16:18.12
13,-4,16:18.12
14,-4,16:18.12
15,-4,16:18.12
-16,-3,16:18.12
-14,-3,16:18.12
-13,-3,16:18.12
-9,-3,16:18.12
-8,-3,16:17.12
-7,-3,16:18.12
-6,-3,16:17.12
-5,-3,16:18.12
-3,-3,16:18.12
-2,-3,16:18.12
-1,-3,16:18.12
0,-3,16:18.12
1,-3,16:18.12
2,-3,16:18.12
8,-3,16:17.12
9,-3,16:18.12
10,-3,16:18.12
11,-3,16:18.12
12,-3,16:18.12
13,-3,16:18.12
14,-3,16:18.12
15,-3,16:18.12
16,-3,16:18.12
-16,-2,16:18.12
-14,-2,16:18.12
-9,-2,16:18.12
-8,-2,16:17.12
-7,-2,16:17.12
-6,-2,16:17.12
-5,-2,16:17.12
-2,-2,16:17.12
-1,-2,16:18.12
0,-2,16:18.12
1,-2,16:18.12
2,-2,16:18.12
4,-2,16:18.12
9,-2,16:17.12
10,-2,16:18.12
11,-2,16:18.12
12,-2,16:18.12
13,-2,16:18.12
14,-2,16:18.12
-16,-1,16:18.12
-15,-1,16:18.12
-14,-1,16:18.12
-13,-1,16:18.12
-10,-1,16:17.12
-9,-1,16:17.12
-8,-1,16:17.12
-7,-1,16:17.12
-6,-1,16:18.12
-4,-1,16:17.12
-3,-1,16:17.12
-2,-1,16:17.12
-1,-1,16:17.12
0,-1,16:18.12
1,-1,16:18.12
2,-1,16:18.12
3,-1,16:18.12
4,-1,16:18.12
10,-1,16:18.12
11,-1,16:18.12
12,-1,16:18.12
14,-1,16:18.12
-15,0,16:18.12
-14,0,16:18.12
-13,0,16:18.12
-11,0,16:17.12
-10,0,16:17.12
-9,0,16:18.12
-8,0,16:17.12
-7,0,16:17.12
-4,0,16:18.12
-3,0,16:18.12
-2,0,16:17.12
-1,0,16:18.12
0,0,16:18.12
1,0,16:18.12
2,0,16:18.12
3,0,16:18.12
4,0,16:18.12
5,0,16:18.12
9,0,16:18.12
10,0,16:18.12
11,0,16:18.12
-16,1,16:18.12
-15,1,16:18.12
-14,1,16:18.12
-13,1,16:18.12
-10,1,16:17.12
-8,1,16:18.12
-7,1,16:18.12
-6,1,16:18.12
-5,1,16:18.12
-4,1,16:18.12
-3,1,16:17.12
-2,1,16:17.12
-1,1,16:17.12
0,1,16:18.12
1,1,16:18.12
2,1,16:18.12
3,1,16:18.12
4,1,16:18.12
5,1,16:18.12
6,1,16:18.12
8,1,16:18.12
9,1,16:18.12
10,1,16:18.12
11,1,16:18.12
12,1,16:18.12
13,1,16:18.12
-15,2,16:18.12
-14,2,16:18.12
-13,2,16:18.12
-12,2,16:18.12
-11,2,16:18.12
-10,2,16:18.12
-8,2,16:18.12
-7,2,16:18.12
-6,2,16:18.12
-5,2,16:18.12
-4,2,16:18.12
2,2,16:18.12
3,2,16:18.12
4,2,16:18.12
8,2,16:18.12
12,2,16:18.12
13,2,16:18.12
14,2,16:18.12
-14,3,16:18.12
-13,3,16:18.12
-12,3,16:18.12
-11,3,16:18.12
-10,3,16:18.12
-9,3,16:18.12
-8,3,16:18.12
-7,3,16:18.12
-6,3,16:18.12
-5,3,16:18.12
9,3,16:18.12
10,3,16:18.12
11,3,16:18.12
12,3,16:18.12
-13,4,16:18.12
-12,4,16:18.12
-11,4,16:18.12
-10,4,16:18.12
-8,4,16:18.12
-7,4,16:18.12
-6,4,16:18.12
-2,4,16:18.12
8,4,16:18.12
9,4,16:18.12
10,4,16:18.12
11,4,16:18.12
12,4,16:18.12
13,4,16:18.12
-14,5,16:18.12
-13,5,16:18.12
-12,5,16:18.12
-11,5,16:18.12
-8,5,16:18.12
-7,5,16:18.12
-6,5,16:18.12
-4,5,16:18.12
-1,5,16:18.12
1,5,16:18.12
7,5,16:18.12
8,5,16:18.12
9,5,16:18.12
10,5,16:18.12
11,5,16:18.12
12,5,16:18.12
13,5,16:18.12
-12,6,16:18.12
-11,6,16:18.12
-10,6,16:18.12
-8,6,16:18.12
-7,6,16:18.12
-6,6,16:18.12
-5,6,16:17.12
-2,6,16:17.12
-1,6,16:17.12
0,6,16:17.12
3,6,16:18.12
7,6,16:18.12
8,6,16:18.12
9,6,16:18.12
10,6,16:18.12
11,6,16:18.12
12,6,16:18.12
-12,7,16:18.12
-11,7,16:18.12
-10,7,16:18.12
-9,7,16:18.12
-8,7,16:18.12
-7,7,16:17.12
-6,7,16:17.12
-5,7,16:18.12
-4,7,16:18.12
-3,7,16:18.12
-2,7,16:18.12
-1,7,16:17.12
0,7,16:17.12
1,7,16:17.12
3,7,16:18.12
4,7,16:18.12
6,7,16:18.12
7,7,16:17.12
8,7,16:18.12
9,7,16:18.12
10,7,16:18.12
11,7,16:18.12
12,7,16:18.12
13,7,16:18.12
-12,8,16:18.12
-11,8,16:18.12
-10,8,16:18.12
-9,8,16:18.12
-8,8,16:18.12
-7,8,16:18.12
-6,8,16:17.12
-5,8,16:18.12
-4,8,16:18.12
-3,8,16:18.12
-1,8,16:17.12
0,8,16:17.12
1,8,16:18.12
5,8,16:17.12
7,8,16:17.12
8,8,16:18.12
9,8,16:18.12
10,8,16:18.12
11,8,16:18.12
13,8,16:18.12
-12,9,16:18.12
-11,9,16:18.12
-10,9,16:18.12
-9,9,16:18.12
-8,9,16:18.12
-7,9,16:18.12
-6,9,16:18.12
-5,9,16:18.12
-3,9,16:18.12
-2,9,16:18.12
-1,9,16:17.12
0,9,16:18.12
1,9,16:18.12
2,9,16:18.12
4,9,16:18.12
5,9,16:17.12
6,9,16:17.12
7,9,16:18.12
8,9,16:18.12
9,9,16:18.12
11,9,16:18.12
-12,10,16:18.12
-11,10,16:18.12
-10,10,16:18.12
-9,10,16:18.12
-8,10,16:18.12
-7,10,16:18.12
-6,10,16:18.12
-5,10,16:18.12
-3,10,16:18.12
-2,10,16:18.12
-1,10,16:18.12
0,10,16:18.12
2,10,16:18.12
3,10,16:18.12
4,10,16:18.12
5,10,16:18.12
6,10,16:18.12
7,10,16:18.12
8,10,16:18.12
-11,11,16:18.12
-10,11,16:18.12
-9,11,16:18.12
-8,11,16:18.12
-7,11,16:18.12
-6,11,16:18.12
-5,11,16:18.12
-4,11,16:18.12
-3,11,16:18.12
-1,11,16:18.12
0,11,16:18.12
3,11,16:18.12
4,11,16:18.12
5,11,16:18.12
6,11,16:18.12
7,11,16:18.12
8,11,16:18.12
-9,12,16:18.12
-8,12,16:18.12
-7,12,16:18.12
-6,12,16:18.12
-5,12,16:18.12
-4,12,16:18.12
-3,12,16:18.12
-2,12,16:18.12
-1,12,16:18.12
0,12,16:18.12
1,12,16:18.12
6,12,16:17.12
7,12,16:18.12
8,12,16:18.12
-9,13,16:18.12
-8,13,16:18.12
-7,13,16:18.12
-6,13,16:18.12
-1,13,16:18.12
0,13,16:18.12
1,13,16:18.12
2,13,16:18.12
3,13,16:18.12
4,13,16:18.12
6,13,16:18.12
7,13,16:18.12
-1,14,16:18.12
1,14,16:18.12
2,14,16:18.12
3,14,16:18.12
4,14,16:18.12
5,14,16:18.12
6,14,16:18.12
9,14,16:18.12
10,14,16:18.12
1,15,16:18.12
-4,-15,17:18.12
0,-15,17:18.12
1,-15,17:18.12
3,-15,17:18.12
-12,-14,17:18.12
-11,-14,17:18.12
-4,-14,17:18.12
-3,-14,17:18.12
0,-14,17:18.12
1,-14,17:18.12
2,-14,17:18.12
3,-14,17:18.12
4,-14,17:18.12
5,-14,17:18.12
-12,-13,17:18.12
-11,-13,17:18.12
-10,-13,17:18.12
-9,-13,17:18.12
-6,-13,17:18.12
-4,-13,17:18.12
-3,-13,17:18.12
-2,-13,17:18.12
-1,-13,17:18.12
0,-13,17:18.12
1,-13,17:18.12
2,-13,17:18.12
3,-13,17:18.12
4,-13,17:18.12
5,-13,17:18.12
7,-13,17:18.12
-12,-12,17:18.12
-11,-12,17:18.12
-9,-12,17:18.12
-8,-12,17:18.12
-5,-12,17:18.12
-4,-12,17:18.12
-3,-12,17:18.12
-2,-12,17:18.12
-1,-12,17:18.12
0,-12,17:18.12
1,-12,17:18.12
2,-12,17:18.12
3,-12,17:18.12
4,-12,17:18.12
5,-12,17:18.12
6,-12,17:18.12
7,-12,17:18.12
8,-12,17:18.12
11,-12,17:18.12
-12,-11,17:18.12
-10,-11,17:18.12
-9,-11,17:18.12
-8,-11,17:18.12
-7,-11,17:18.12
-6,-11,17:18.12
-5,-11,17:18.12
-4,-11,17:18.12
-3,-11,17:18.12
-2,-11,17:18.12
-1,-11,17:18.12
0,-11,17:18.12
1,-11,17:18.12
2,-11,17:18.12
3,-11,17:18.12
4,-11,17:18.12
5,-11,17:18.12
6,-11,17:18.12
8,-11,17:18.12
11,-11,17:18.12
12,-11,17:18.12
-12,-10,17:18.12
-11,-10,17:18.12
-9,-10,17:18.12
-8,-10,17:18.12
-7,-10,17:18.12
-6,-10,17:18.12
-5,-10,17:18.12
-4,-10,17:18.12
-3,-10,17:18.12
-2,-10,17:18.12
-1,-10,17:18.12
0,-10,17:18.12
1,-10,17:18.12
2,-10,17:18.12
3,-10,17:17.12
5,-10,17:18.12
7,-10,17:18.12
8,-10,17:18.12
9,-10,17:18.12
10,-10,17:18.12
11,-10,17:18.12
-11,-9,17:18.12
-9,-9,17:18.12
-8,-9,17:18.12
-7,-9,17:18.12
-5,-9,17:18.12
-4,-9,17:18.12
-3,-9,17:18.12
-2,-9,17:18.12
-1,-9,17:18.12
0,-9,17:18.12
1,-9,17:18.12
2,-9,17:18.12
3,-9,17:18.12
5,-9,17:18.12
6,-9,17:18.12
7,-9,17:18.12
8,-9,17:18.12
9,-9,17:18.12
10,-9,17:18.12
12,-9,17:18.12
13,-9,17:18.12
-15,-8,17:18.12
-13,-8,17:18.12
-12,-8,17:18.12
-11,-8,17:18.12
-10,-8,17:18.12
-9,-8,17:18.12
-8,-8,17:18.12
-7,-8,17:18.12
-6,-8,17:18.12
-5,-8,17:18.12
-4,-8,17:18.12
-3,-8,17:18.12
-2,-8,17:18.12
-1,-8,17:18.12
0,-8,17:18.12
1,-8,17:18.12
2,-8,17:18.12
3,-8,17:18.12
4,-8,17:18.12
5,-8,17:18.12
6,-8,17:18.12
7,-8,17:18.12
8,-8,17:18.12
9,-8,17:18.12
10,-8,17:18.12
15,-8,17:18.12
-15,-7,17:18.12
-13,-7,17:18.12
-12,-7,17:18.12
-10,-7,17:18.12
-9,-7,17:18.12
-8,-7,17:18.12
-7,-7,17:18.12
-6,-7,17:18.12
-5,-7,17:18.12
-4,-7,17:18.12
-3,-7,17:18.12
-2,-7,17:18.12
-1,-7,17:18.12
0,-7,17:18.12
1,-7,17:18.12
2,-7,17:18.12
3,-7,17:18.12
4,-7,17:18.12
5,-7,17:18.12
6,-7,17:18.12
8,-7,17:18.12
9,-7,17:18.12
10,-7,17:18.12
11,-7,17:18.12
12,-7,17:18.12
13,-7,17:18.12
15,-7,17:18.12
-16,-6,17:18.12
-15,-6,17:18.12
-14,-6,17:18.12
-13,-6,17:18.12
-12,-6,17:18.12
-11,-6,17:18.12
-10,-6,17:18.12
-9,-6,17:18.12
-8,-6,17:18.12
-7,-6,17:18.12
-6,-6,17:18.12
-5,-6,17:18.12
-4,-6,17:18.12
-2,-6,17:18.12
-1,-6,17:18.12
0,-6,17:18.12
1,-6,17:18.12
2,-6,17:18.12
3,-6,17:18.12
4,-6,17:18.12
5,-6,17:18.12
6,-6,17:18.12
7,-6,17:18.12
9,-6,17:18.12
10,-6,17:18.12
11,-6,17:18.12
12,-6,17:18.12
13,-6,17:18.12
14,-6,17:18.12
-16,-5,17:18.12
-15,-5,17:18.12
-14,-5,17:18.12
-13,-5,17:18.12
-12,-5,17:18.12
-11,-5,17:18.12
-10,-5,17:18.12
-9,-5,17:17.12
-8,-5,17:17.12
-7,-5,17:17.12
-6,-5,17:17.12
-2,-5,17:18.12
-1,-5,17:18.12
0,-5,17:18.12
1,-5,17:18.12
2,-5,17:18.12
3,-5,17:18.12
4,-5,17:17.12
5,-5,17:18.12
6,-5,17:18.12
7,-5,17:18.12
8,-5,17:18.12
9,-5,17:18.12
10,-5,17:18.12
11,-5,17:18.12
12,-5,17:18.12
13,-5,17:18.12
14,-5,17:18.12
15,-5,17:18.12
-16,-4,17:18.12
-15,-4,17:18.12
-14,-4,17:18.12
-13,-4,17:18.12
-12,-4,17:18.12
-11,-4,17:18.12
-8,-4,17:18.12
-7,-4,17:17.12
-6,-4,17:17.12
-1,-4,17:18.12
0,-4,17:18.12
1,-4,17:18.12
2,-4,17:18.12
3,-4,17:18.12
4,-4,17:18.12
5,-4,17:18.12
8,-4,17:18.12
9,-4,17:18.12
10,-4,17:17.12
13,-4,17:18.12
-16,-3,17:18.12
-15,-3,17:18.12
-14,-3,17:18.12
-13,-3,17:18.12
-12,-3,17:18.12
-9,-3,17:18.12
-8,-3,17:18.12
-7,-3,17:18.12
-6,-3,17:18.12
-2,-3,17:18.12
-1,-3,17:18.12
0,-3,17:18.12
1,-3,17:18.12
2,-3,17:18.12
3,-3,17:18.12
4,-3,17:18.12
8,-3,17:18.12
10,-3,17:18.12
11,-3,17:18.12
12,-3,17:18.12
13,-3,17:18.12
14,-3,17:18.12
15,-3,17:18.12
-15,-2,17:18.12
-14,-2,17:18.12
-13,-2,17:18.12
-10,-2,17:17.12
-9,-2,17:17.12
-8,-2,17:17.12
-7,-2,17:17.12
-6,-2,17:17.12
-3,-2,17:18.12
0,-2,17:18.12
1,-2,17:18.12
2,-2,17:18.12
3,-2,17:18.12
9,-2,17:18.12
10,-2,17:18.12
11,-2,17:18.12
12,-2,17:18.12
13,-2,17:18.12
14,-2,17:18.12
15,-2,17:18.12
-15,-1,17:18.12
-14,-1,17:18.12
-13,-1,17:18.12
-11,-1,17:17.12
-10,-1,17:17.12
-9,-1,17:17.12
-8,-1,17:17.12
-7,-1,17:18.12
-6,-1,17:18.12
-5,-1,17:18.12
-1,-1,17:17.12
0,-1,17:17.12
2,-1,17:18.12
3,-1,17:18.12
4,-1,17:18.12
8,-1,17:18.12
9,-1,17:18.12
10,-1,17:17.12
11,-1,17:18.12
12,-1,17:18.12
13,-1,17:18.12
-16,0,17:18.12
-15,0,17:18.12
-14,0,17:18.12
-13,0,17:18.12
-11,0,17:17.12
-10,0,17:17.12
-9,0,17:17.12
-8,0,17:18.12
-7,0,17:18.12
-6,0,17:18.12
-4,0,17:18.12
-2,0,17:17.12
-1,0,17:17.12
0,0,17:18.12
1,0,17:17.12
2,0,17:18.12
3,0,17:18.12
4,0,17:18.12
9,0,17:18.12
10,0,17:18.12
11,0,17:18.12
12,0,17:18.12
14,0,17:18.12
-15,1,17:18.12
-14,1,17:18.12
-11,1,17:17.12
-10,1,17:17.12
-9,1,17:17.12
-8,1,17:18.12
-7,1,17:18.12
-6,1,17:18.12
-5,1,17:18.12
-4,1,17:18.12
-2,1,17:17.12
-1,1,17:17.12
0,1,17:17.12
1,1,17:17.12
2,1,17:18.12
3,1,17:18.12
4,1,17:18.12
8,1,17:18.12
9,1,17:18.12
10,1,17:18.12
11,1,17:18.12
12,1,17:18.12
-13,2,17:18.12
-10,2,17:18.12
-9,2,17:18.12
-7,2,17:18.12
-6,2,17:18.12
-4,2,17:18.12
-1,2,17:17.12
1,2,17:18.12
2,2,17:18.12
10,2,17:18.12
11,2,17:18.12
12,2,17:18.12
13,2,17:18.12
-15,3,17:18.12
-14,3,17:18.12
-13,3,17:18.12
-10,3,17:18.12
-9,3,17:18.12
-8,3,17:18.12
-7,3,17:18.12
-6,3,17:18.12
-4,3,17:18.12
2,3,17:17.12
9,3,17:18.12
10,3,17:18.12
12,3,17:18.12
-14,4,17:18.12
-13,4,17:18.12
-12,4,17:18.12
-10,4,17:18.12
-9,4,17:18.12
-8,4,17:18.12
-7,4,17:18.12
-6,4,17:18.12
-5,4,17:18.12
8,4,17:18.12
9,4,17:18.12
10,4,17:18.12
11,4,17:18.12
12,4,17:18.12
-12,5,17:18.12
-11,5,17:18.12
-6,5,17:18.12
8,5,17:18.12
9,5,17:18.12
10,5,17:18.12
-12,6,17:18.12
-11,6,17:18.12
-10,6,17:18.12
-7,6,17:18.12
-6,6,17:18.12
-5,6,17:18.12
-4,6,17:18.12
4,6,17:18.12
7,6,17:18.12
8,6,17:18.12
9,6,17:18.12
10,6,17:18.12
-13,7,17:18.12
-12,7,17:18.12
-11,7,17:18.12
-10,7,17:18.12
-9,7,17:18.12
-8,7,17:18.12
-7,7,17:18.12
-6,7,17:17.12
-5,7,17:17.12
-4,7,17:18.12
-3,7,17:18.12
-2,7,17:18.12
2,7,17:18.12
4,7,17:18.12
6,7,17:18.12
7,7,17:18.12
8,7,17:18.12
9,7,17:18.12
10,7,17:18.12
-12,8,17:18.12
-11,8,17:18.12
-10,8,17:18.12
-9,8,17:18.12
-8,8,17:18.12
-7,8,17:17.12
-6,8,17:17.12
-5,8,17:17.12
-4,8,17:18.12
-3,8,17:18.12
-2,8,17:18.12
-1,8,17:17.12
0,8,17:17.12
1,8,17:18.12
2,8,17:18.12
8,8,17:18.12
9,8,17:18.12
10,8,17:18.12
-12,9,17:18.12
-11,9,17:18.12
-10,9,17:18.12
-9,9,17:18.12
-8,9,17:18.12
-7,9,17:17.12
-4,9,17:18.12
-3,9,17:18.12
-1,9,17:18.12
0,9,17:18.12
1,9,17:18.12
2,9,17:18.12
3,9,17:18.12
4,9,17:18.12
5,9,17:17.12
6,9,17:17.12
7,9,17:18.12
8,9,17:18.12
9,9,17:18.12
-12,10,17:18.12
-11,10,17:18.12
-10,10,17:18.12
-9,10,17:18.12
-8,10,17:18.12
-7,10,17:17.12
-4,10,17:18.12
-1,10,17:18.12
0,10,17:18.12
1,10,17:18.12
2,10,17:18.12
3,10,17:18.12
4,10,17:18.12
5,10,17:17.12
6,10,17:17.12
7,10,17:17.12
8,10,17:18.12
-10,11,17:18.12
-9,11,17:18.12
-8,11,17:18.12
-7,11,17:18.12
-6,11,17:18.12
-5,11,17:18.12
-4,11,17:18.12
-3,11,17:18.12
-2,11,17:18.12
-1,11,17:18.12
0,11,17:18.12
2,11,17:18.12
5,11,17:17.12
6,11,17:18.12
7,11,17:18.12
-10,12,17:18.12
-9,12,17:18.12
-8,12,17:18.12
-7,12,17:18.12
-6,12,17:18.12
-5,12,17:18.12
-3,12,17:18.12
-2,12,17:18.12
-1,12,17:18.12
0,12,17:18.12
5,12,17:18.12
6,12,17:18.12
7,12,17:18.12
-9,13,17:18.12
-7,13,17:18.12
-6,13,17:18.12
-1,13,17:18.12
0,13,17:18.12
1,13,17:18.12
6,13,17:18.12
7,13,17:18.12
8,13,17:18.12
9,13,17:18.12
-6,14,17:18.12
2,14,17:18.12
3,14,17:18.12
4,14,17:18.12
6,14,17:18.12
7,14,17:18.12
8,14,17:18.12
3,15,17:18.12
6,15,17:18.12
-3,-14,18:18.12
1,-14,18:18.12
-9,-13,18:18.12
-4,-13,18:18.12
-3,-13,18:18.12
0,-13,18:18.12
1,-13,18:18.12
3,-13,18:18.12
4,-13,18:18.12
5,-13,18:18.12
7,-13,18:18.12
-8,-12,18:18.12
-7,-12,18:18.12
-6,-12,18:18.12
-4,-12,18:18.12
-3,-12,18:18.12
-2,-12,18:18.12
-1,-12,18:18.12
0,-12,18:18.12
1,-12,18:18.12
2,-12,18:18.12
3,-12,18:18.12
4,-12,18:18.12
5,-12,18:18.12
6,-12,18:18.12
7,-12,18:18.12
-12,-11,18:18.12
-10,-11,18:18.12
-9,-11,18:18.12
-8,-11,18:18.12
-7,-11,18:18.12
-6,-11,18:18.12
-5,-11,18:18.12
-4,-11,18:18.12
-3,-11,18:18.12
0,-11,18:18.12
1,-11,18:18.12
2,-11,18:18.12
3,-11,18:18.12
4,-11,18:18.12
5,-11,18:18.12
6,-11,18:18.12
7,-11,18:18.12
8,-11,18:18.12
9,-11,18:18.12
10,-11,18:18.12
11,-11,18:18.12
12,-11,18:18.12
-12,-10,18:18.12
-11,-10,18:18.12
-10,-10,18:18.12
-9,-10,18:18.12
-8,-10,18:18.12
-7,-10,18:18.12
-6,-10,18:18.12
-5,-10,18:18.12
-4,-10,18:18.12
-3,-10,18:18.12
-2,-10,18:18.12
-1,-10,18:18.12
0,-10,18:18.12
1,-10,18:18.12
2,-10,18:18.12
3,-10,18:18.12
4,-10,18:18.12
5,-10,18:18.12
6,-10,18:18.12
7,-10,18:18.12
8,-10,18:18.12
9,-10,18:18.12
10,-10,18:18.12
11,-10,18:18.12
-13,-9,18:18.12
-11,-9,18:18.12
-10,-9,18:18.12
-9,-9,18:18.12
-8,-9,18:18.12
-7,-9,18:18.12
-6,-9,18:18.12
-5,-9,18:18.12
-4,-9,18:18.12
-3,-9,18:18.12
-2,-9,18:18.12
0,-9,18:18.12
1,-9,18:18.12
2,-9,18:18.12
3,-9,18:17.12
4,-9,18:18.12
5,-9,18:18.12
6,-9,18:18.12
7,-9,18:18.12
8,-9,18:18.12
9,-9,18:18.12
10,-9,18:18.12
11,-9,18:18.12
12,-9,18:18.12
13,-9,18:18.12
-14,-8,18:18.12
-13,-8,18:18.12
-12,-8,18:18.12
-11,-8,18:18.12
-10,-8,18:18.12
-9,-8,18:18.12
-8,-8,18:18.12
-7,-8,18:18.12
-5,-8,18:18.12
-4,-8,18:18.12
-3,-8,18:18.12
-2,-8,18:18.12
-1,-8,18:18.12
0,-8,18:18.12
2,-8,18:18.12
3,-8,18:18.12
5,-8,18:18.12
6,-8,18:18.12
7,-8,18:18.12
9,-8,18:18.12
10,-8,18:18.12
11,-8,18:18.12
12,-8,18:18.12
13,-8,18:18.12
16,-8,18:18.12
-13,-7,18:18.12
-12,-7,18:18.12
-11,-7,18:18.12
-10,-7,18:18.12
-9,-7,18:18.12
-8,-7,18:18.12
-7,-7,18:18.12
-6,-7,18:18.12
-5,-7,18:18.12
-4,-7,18:18.12
-3,-7,18:18.12
-2,-7,18:18.12
-1,-7,18:18.12
0,-7,18:18.12
2,-7,18:18.12
3,-7,18:18.12
5,-7,18:18.12
7,-7,18:18.12
8,-7,18:18.12
9,-7,18:18.12
10,-7,18:18.12
11,-7,18:18.12
12,-7,18:18.12
13,-7,18:18.12
14,-7,18:18.12
15,-7,18:18.12
16,-7,18:18.12
-13,-6,18:18.12
-12,-6,18:18.12
-11,-6,18:18.12
-10,-6,18:18.12
-9,-6,18:18.12
-8,-6,18:18.12
-7,-6,18:18.12
-6,-6,18:18.12
-5,-6,18:18.12
-4,-6,18:18.12
-3,-6,18:18.12
-2,-6,18:18.12
0,-6,18:18.12
2,-6,18:18.12
3,-6,18:18.12
4,-6,18:18.12
5,-6,18:18.12
6,-6,18:18.12
7,-6,18:18.12
8,-6,18:18.12
9,-6,18:18.12
10,-6,18:18.12
11,-6,18:18.12
12,-6,18:18.12
13,-6,18:18.12
14,-6,18:18.12
15,-6,18:18.12
-13,-5,18:18.12
-12,-5,18:18.12
-11,-5,18:18.12
-10,-5,18:18.12
-9,-5,18:18.12
-8,-5,18:17.12
-7,-5,18:18.12
-6,-5,18:18.12
-5,-5,18:18.12
-4,-5,18:18.12
-3,-5,18:18.12
-1,-5,18:18.12
0,-5,18:18.12
1,-5,18:18.12
2,-5,18:18.12
5,-5,18:18.12
6,-5,18:18.12
7,-5,18:18.12
8,-5,18:18.12
9,-5,18:18.12
11,-5,18:18.12
12,-5,18:18.12
13,-5,18:18.12
14,-5,18:18.12
15,-5,18:18.12
16,-5,18:18.12
-16,-4,18:18.12
-12,-4,18:18.12
-11,-4,18:18.12
-9,-4,18:18.12
-7,-4,18:18.12
-5,-4,18:18.12
-3,-4,18:18.12
-2,-4,18:18.12
-1,-4,18:18.12
0,-4,18:18.12
1,-4,18:18.12
2,-4,18:18.12
4,-4,18:18.12
5,-4,18:18.12
6,-4,18:18.12
7,-4,18:18.12
8,-4,18:18.12
9,-4,18:18.12
11,-4,18:18.12
12,-4,18:18.12
13,-4,18:18.12
14,-4,18:18.12
15,-4,18:18.12
16,-4,18:18.12
-15,-3,18:18.12
-14,-3,18:18.12
-13,-3,18:18.12
-12,-3,18:18.12
-11,-3,18:18.12
-10,-3,18:18.12
-9,-3,18:18.12
-8,-3,18:18.12
-7,-3,18:18.12
-6,-3,18:18.12
-3,-3,18:18.12
-2,-3,18:18.12
0,-3,18:18.12
1,-3,18:18.12
2,-3,18:18.12
3,-3,18:18.12
6,-3,18:18.12
7,-3,18:18.12
10,-3,18:18.12
11,-3,18:18.12
12,-3,18:18.12
13,-3,18:18.12
14,-3,18:18.12
15,-3,18:18.12
-15,-2,18:18.12
-14,-2,18:18.12
-13,-2,18:18.12
-12,-2,18:18.12
-10,-2,18:18.12
-9,-2,18:17.12
-8,-2,18:18.12
-7,-2,18:18.12
-6,-2,18:18.12
-4,-2,18:18.12
-3,-2,18:18.12
-1,-2,18:18.12
0,-2,18:18.12
2,-2,18:18.12
3,-2,18:18.12
4,-2,18:18.12
5,-2,18:18.12
7,-2,18:18.12
10,-2,18:18.12
11,-2,18:18.12
12,-2,18:18.12
13,-2,18:18.12
14,-2,18:18.12
-15,-1,18:18.12
-14,-1,18:18.12
-13,-1,18:18.12
-12,-1,18:18.12
-11,-1,18:17.12
-10,-1,18:18.12
-9,-1,18:18.12
-8,-1,18:18.12
-7,-1,18:18.12
-6,-1,18:18.12
-3,-1,18:18.12
0,-1,18:18.12
2,-1,18:18.12
3,-1,18:18.12
4,-1,18:18.12
8,-1,18:18.12
11,-1,18:17.12
12,-1,18:18.12
13,-1,18:18.12
-14,0,18:18.12
-13,0,18:18.12
-12,0,18:18.12
-11,0,18:17.12
-10,0,18:17.12
-9,0,18:17.12
-8,0,18:18.12
-7,0,18:18.12
-1,0,18:17.12
0,0,18:18.12
1,0,18:18.12
3,0,18:18.12
4,0,18:18.12
11,0,18:18.12
12,0,18:18.12
13,0,18:18.12
14,0,18:18.12
-14,1,18:18.12
-13,1,18:18.12
-12,1,18:18.12
-11,1,18:17.12
-10,1,18:17.12
-9,1,18:17.12
-8,1,18:18.12
-7,1,18:18.12
-6,1,18:18.12
-5,1,18:18.12
-1,1,18:17.12
0,1,18:18.12
1,1,18:17.12
2,1,18:18.12
3,1,18:18.12
9,1,18:18.12
10,1,18:18.12
11,1,18:18.12
12,1,18:18.12
13,1,18:18.12
14,1,18:18.12
15,1,18:18.12
-14,2,18:18.12
-13,2,18:18.12
-12,2,18:17.12
-11,2,18:17.12
-10,2,18:18.12
-9,2,18:18.12
-8,2,18:18.12
-7,2,18:18.12
-6,2,18:18.12
-5,2,18:18.12
-2,2,18:18.12
1,2,18:17.12
2,2,18:17.12
3,2,18:17.12
4,2,18:17.12
10,2,18:18.12
13,2,18:18.12
14,2,18:18.12
-15,3,18:18.12
-14,3,18:18.12
-13,3,18:18.12
-12,3,18:17.12
-11,3,18:18.12
-10,3,18:18.12
-9,3,18:18.12
-8,3,18:18.12
-7,3,18:18.12
-6,3,18:18.12
-5,3,18:18.12
1,3,18:18.12
2,3,18:17.12
3,3,18:17.12
4,3,18:18.12
6,3,18:18.12
8,3,18:18.12
9,3,18:18.12
10,3,18:18.12
13,3,18:18.12
-13,4,18:18.12
-12,4,18:18.12
-11,4,18:18.12
-10,4,18:18.12
-9,4,18:18.12
-8,4,18:18.12
3,4,18:18.12
7,4,18:18.12
8,4,18:18.12
9,4,18:18.12
10,4,18:18.12
11,4,18:18.12
-14,5,18:18.12
-13,5,18:18.12
-12,5,18:18.12
-11,5,18:18.12
-10,5,18:18.12
-6,5,18:18.12
-13,6,18:18.12
-12,6,18:18.12
-11,6,18:18.12
-10,6,18:18.12
-9,6,18:18.12
-8,6,18:18.12
-7,6,18:18.12
-6,6,18:18.12
1,6,18:18.12
6,6,18:18.12
7,6,18:18.12
8,6,18:18.12
9,6,18:18.12
-12,7,18:18.12
-11,7,18:18.12
-10,7,18:18.12
-9,7,18:18.12
-8,7,18:18.12
-7,7,18:18.12
-6,7,18:18.12
-3,7,18:18.12
-2,7,18:18.12
4,7,18:18.12
6,7,18:18.12
7,7,18:18.12
9,7,18:18.12
10,7,18:18.12
-12,8,18:18.12
-11,8,18:18.12
-10,8,18:18.12
-9,8,18:18.12
-8,8,18:18.12
-7,8,18:18.12
-6,8,18:17.12
-4,8,18:18.12
-3,8,18:18.12
-2,8,18:18.12
1,8,18:18.12
2,8,18:18.12
7,8,18:18.12
8,8,18:18.12
9,8,18:18.12
-11,9,18:18.12
-10,9,18:18.12
-9,9,18:18.12
-8,9,18:18.12
-7,9,18:18.12
-6,9,18:18.12
-5,9,18:18.12
-4,9,18:18.12
-3,9,18:18.12
-2,9,18:18.12
-1,9,18:18.12
0,9,18:18.12
2,9,18:18.12
3,9,18:18.12
4,9,18:18.12
8,9,18:18.12
-10,10,18:18.12
-9,10,18:18.12
-8,10,18:18.12
-7,10,18:18.12
-6,10,18:18.12
-5,10,18:18.12
-4,10,18:18.12
-3,10,18:18.12
-2,10,18:18.12
-1,10,18:18.12
0,10,18:18.12
1,10,18:18.12
2,10,18:18.12
4,10,18:18.12
5,10,18:18.12
6,10,18:17.12
7,10,18:18.4
8,10,18:18.12
-9,11,18:18.12
-8,11,18:18.12
-6,11,18:18.12
-5,11,18:18.12
-4,11,18:18.12
-3,11,18:18.12
-2,11,18:18.12
-1,11,18:18.12
0,11,18:18.12
2,11,18:18.12
3,11,18:18.12
4,11,18:18.12
5,11,18:18.12
6,11,18:18.12
7,11,18:17.12
8,11,18:18.12
-7,12,18:18.12
-6,12,18:18.12
-4,12,18:18.12
0,12,18:18.12
4,12,18:18.12
5,12,18:18.12
6,12,18:18.12
7,12,18:18.12
8,12,18:18.4
-1,13,18:18.12
5,13,18:18.12
6,13,18:18.12
7,13,18:18.12
8,13,18:18.12
9,13,18:18.12
4,14,18:18.12
5,14,18:18.12
6,14,18:18.12
5,15,18:18.12
5,16,18:18.12
-7,-13,19:18.12
-4,-13,19:18.12
-3,-13,19:18.12
0,-13,19:18.12
4,-13,19:18.12
-7,-12,19:18.12
-6,-12,19:18.12
-5,-12,19:18.12
-4,-12,19:18.12
-3,-12,19:18.12
0,-12,19:18.12
1,-12,19:18.12
2,-12,19:18.12
3,-12,19:18.12
4,-12,19:18.12
5,-12,19:18.12
6,-12,19:18.12
-9,-11,19:18.12
-7,-11,19:18.12
-6,-11,19:18.12
-5,-11,19:18.12
-4,-11,19:18.12
0,-11,19:18.12
2,-11,19:18.12
3,-11,19:18.12
4,-11,19:18.12
5,-11,19:18.12
6,-11,19:18.12
7,-11,19:18.12
8,-11,19:18.12
-11,-10,19:18.12
-10,-10,19:18.12
-9,-10,19:18.12
-8,-10,19:18.12
-7,-10,19:18.12
-6,-10,19:18.12
-4,-10,19:18.12
1,-10,19:18.12
2,-10,19:18.12
3,-10,19:18.12
4,-10,19:18.12
5,-10,19:18.12
6,-10,19:18.12
9,-10,19:18.12
10,-10,19:18.12
11,-10,19:18.12
12,-10,19:18.12
-10,-9,19:18.12
-8,-9,19:18.12
-7,-9,19:18.12
-4,-9,19:18.12
-3,-9,19:18.12
-2,-9,19:18.12
0,-9,19:18.12
1,-9,19:18.12
2,-9,19:18.12
3,-9,19:18.12
4,-9,19:18.12
5,-9,19:18.12
6,-9,19:18.12
10,-9,19:18.12
11,-9,19:18.12
12,-9,19:18.12
13,-9,19:18.12
14,-9,19:18.12
-10,-8,19:18.12
-9,-8,19:18.12
-8,-8,19:18.12
-7,-8,19:18.12
-6,-8,19:18.12
-4,-8,19:18.12
-3,-8,19:18.12
-2,-8,19:18.12
-1,-8,19:18.12
3,-8,19:18.12
5,-8,19:18.12
6,-8,19:18.12
10,-8,19:18.12
11,-8,19:18.12
12,-8,19:18.12
13,-8,19:18.12
-12,-7,19:18.12
-11,-7,19:18.12
-10,-7,19:18.12
-8,-7,19:18.12
-6,-7,19:18.12
-5,-7,19:18.12
-4,-7,19:18.12
-3,-7,19:18.12
-2,-7,19:18.12
-1,-7,19:18.12
0,-7,19:18.12
1,-7,19:18.12
3,-7,19:18.12
6,-7,19:18.12
7,-7,19:18.12
8,-7,19:18.12
9,-7,19:18.12
11,-7,19:18.12
12,-7,19:18.12
13,-7,19:18.12
14,-7,19:18.12
15,-7,19:18.12
-13,-6,19:18.12
-11,-6,19:18.12
-10,-6,19:18.12
-9,-6,19:18.12
-8,-6,19:18.12
-7,-6,19:18.12
-6,-6,19:18.12
-5,-6,19:18.12
-4,-6,19:18.12
-3,-6,19:18.12
-2,-6,19:18.12
-1,-6,19:18.12
0,-6,19:18.12
1,-6,19:18.12
2,-6,19:18.12
3,-6,19:18.12
4,-6,19:18.12
5,-6,19:18.12
6,-6,19:18.12
7,-6,19:18.12
8,-6,19:18.12
9,-6,19:18.12
10,-6,19:18.12
11,-6,19:18.12
12,-6,19:18.12
13,-6,19:18.12
14,-6,19:18.12
15,-6,19:18.12
-13,-5,19:18.12
-12,-5,19:18.12
-11,-5,19:18.12
-9,-5,19:18.12
-8,-5,19:18.12
-7,-5,19:18.12
-6,-5,19:18.12
-5,-5,19:18.12
-4,-5,19:18.12
-3,-5,19:18.12
-2,-5,19:18.12
-1,-5,19:18.12
0,-5,19:18.12
1,-5,19:18.12
2,-5,19:18.12
3,-5,19:18.12
4,-5,19:18.12
5,-5,19:18.12
6,-5,19:18.12
7,-5,19:18.12
8,-5,19:18.12
9,-5,19:18.12
10,-5,19:18.12
11,-5,19:18.12
12,-5,19:18.12
13,-5,19:18.12
14,-5,19:18.12
15,-5,19:18.12
16,-5,19:18.12
-13,-4,19:18.12
-12,-4,19:18.12
-11,-4,19:18.12
-9,-4,19:18.12
-8,-4,19:18.12
-6,-4,19:18.12
-5,-4,19:18.12
-4,-4,19:18.12
-3,-4,19:18.12
-2,-4,19:18.12
-1,-4,19:18.12
0,-4,19:18.12
1,-4,19:18.12
3,-4,19:18.12
4,-4,19:18.12
5,-4,19:18.12
6,-4,19:18.12
7,-4,19:18.12
8,-4,19:18.12
9,-4,19:18.12
10,-4,19:18.12
12,-4,19:18.12
13,-4,19:18.12
14,-4,19:18.12
15,-4,19:18.12
16,-4,19:18.12
-13,-3,19:18.12
-12,-3,19:18.12
-10,-3,19:18.12
-9,-3,19:18.12
-8,-3,19:18.12
-7,-3,19:18.12
-6,-3,19:18.12
-4,-3,19:18.12
-3,-3,19:18.12
-2,-3,19:18.12
-1,-3,19:18.12
0,-3,19:18.12
1,-3,19:18.12
2,-3,19:18.12
3,-3,19:18.12
4,-3,19:18.12
5,-3,19:18.12
6,-3,19:18.12
7,-3,19:18.12
8,-3,19:18.12
9,-3,19:18.12
10,-3,19:18.12
11,-3,19:18.12
12,-3,19:18.12
13,-3,19:18.12
-15,-2,19:18.12
-14,-2,19:18.12
-13,-2,19:18.12
-12,-2,19:18.12
-10,-2,19:18.12
-9,-2,19:18.12
-8,-2,19:18.12
-7,-2,19:18.12
-6,-2,19:18.12
-5,-2,19:18.12
-3,-2,19:18.12
-2,-2,19:18.12
-1,-2,19:18.12
0,-2,19:18.12
1,-2,19:18.12
2,-2,19:18.12
3,-2,19:18.12
4,-2,19:18.12
7,-2,19:18.12
8,-2,19:18.12
10,-2,19:18.12
11,-2,19:18.12
12,-2,19:18.12
13,-2,19:18.12
-14,-1,19:18.12
-13,-1,19:18.12
-12,-1,19:18.12
-11,-1,19:18.12
-10,-1,19:18.12
-9,-1,19:18.12
-8,-1,19:18.12
-5,-1,19:18.12
-3,-1,19:18.12
-2,-1,19:18.12
-1,-1,19:18.12
0,-1,19:18.12
1,-1,19:18.12
2,-1,19:18.12
3,-1,19:18.12
8,-1,19:18.12
10,-1,19:18.12
11,-1,19:18.12
12,-1,19:18.12
13,-1,19:18.12
14,-1,19:18.12
-14,0,19:18.12
-13,0,19:18.12
-12,0,19:18.12
-11,0,19:18.12
-10,0,19:17.12
-9,0,19:18.12
-8,0,19:18.12
-7,0,19:18.12
-6,0,19:18.12
-5,0,19:18.12
-4,0,19:18.12
-3,0,19:18.12
0,0,19:18.12
1,0,19:18.12
2,0,19:18.12
3,0,19:18.12
9,0,19:18.12
11,0,19:18.12
12,0,19:17.12
13,0,19:18.12
14,0,19:18.12
15,0,19:18.12
-15,1,19:18.12
-14,1,19:18.12
-13,1,19:18.12
-12,1,19:18.12
-11,1,19:18.12
-10,1,19:18.12
-9,1,19:18.12
-8,1,19:18.12
-7,1,19:18.12
-5,1,19:18.12
-1,1,19:18.12
0,1,19:18.12
1,1,19:18.12
2,1,19:18.12
4,1,19:17.12
5,1,19:17.12
6,1,19:18.12
8,1,19:18.12
9,1,19:18.12
10,1,19:18.12
12,1,19:18.12
13,1,19:18.12
14,1,19:18.12
-14,2,19:18.12
-13,2,19:18.12
-12,2,19:18.12
-11,2,19:18.12
-10,2,19:18.12
-9,2,19:18.12
-8,2,19:18.12
-7,2,19:18.12
-5,2,19:18.12
-3,2,19:18.12
-2,2,19:18.12
-1,2,19:18.12
0,2,19:18.12
2,2,19:17.12
3,2,19:17.12
4,2,19:17.12
5,2,19:17.12
6,2,19:18.12
7,2,19:18.12
8,2,19:18.12
9,2,19:18.12
10,2,19:18.12
12,2,19:18.12
13,2,19:18.12
16,2,19:18.12
-14,3,19:18.12
-13,3,19:18.12
-12,3,19:17.12
-11,3,19:17.12
-10,3,19:18.12
-9,3,19:18.12
-8,3,19:18.12
-7,3,19:18.12
-6,3,19:18.12
-5,3,19:18.12
-4,3,19:18.12
-1,3,19:18.12
1,3,19:18.12
2,3,19:18.12
3,3,19:18.12
4,3,19:18.12
5,3,19:17.12
6,3,19:18.12
7,3,19:17.12
8,3,19:18.12
9,3,19:18.12
10,3,19:18.12
11,3,19:18.12
12,3,19:18.12
-13,4,19:18.12
-12,4,19:18.12
-11,4,19:18.12
-10,4,19:18.12
-9,4,19:18.12
-8,4,19:18.12
-7,4,19:18.12
-6,4,19:18.12
1,4,19:18.12
2,4,19:18.12
3,4,19:18.12
6,4,19:17.12
7,4,19:18.12
8,4,19:18.12
9,4,19:18.12
11,4,19:18.12
12,4,19:18.12
13,4,19:18.12
-13,5,19:18.12
-12,5,19:18.12
-11,5,19:18.12
-10,5,19:18.12
-9,5,19:18.12
-7,5,19:18.12
0,5,19:18.12
3,5,19:18.12
5,5,19:18.12
6,5,19:18.12
7,5,19:18.12
8,5,19:18.12
-12,6,19:18.12
-9,6,19:18.12
-7,6,19:18.12
-6,6,19:18.12
1,6,19:18.12
5,6,19:18.12
6,6,19:18.12
7,6,19:18.12
8,6,19:18.12
9,6,19:18.12
10,6,19:18.12
-11,7,19:18.12
-9,7,19:18.12
-7,7,19:18.12
-6,7,19:18.12
-5,7,19:18.12
-3,7,19:18.12
6,7,19:18.12
7,7,19:18.12
-9,8,19:18.12
-8,8,19:18.12
-7,8,19:17.12
-5,8,19:18.12
-4,8,19:18.12
-3,8,19:18.12
-2,8,19:18.12
-1,8,19:18.12
3,8,19:18.12
4,8,19:18.12
7,8,19:18.12
-9,9,19:18.12
-8,9,19:18.12
-7,9,19:18.12
-6,9,19:18.12
-5,9,19:18.12
-4,9,19:18.12
-3,9,19:18.12
-1,9,19:18.12
0,9,19:18.12
1,9,19:18.12
2,9,19:18.12
3,9,19:18.12
4,9,19:18.12
5,9,19:18.12
-10,10,19:18.12
-9,10,19:18.12
-8,10,19:18.12
-7,10,19:18.12
-5,10,19:18.12
-4,10,19:18.12
2,10,19:18.12
3,10,19:18.12
4,10,19:18.12
5,10,19:18.12
7,10,19:18.12
8,10,19:18.12
-7,11,19:18.12
-5,11,19:18.12
-2,11,19:18.12
0,11,19:18.12
4,11,19:18.12
5,11,19:18.12
6,11,19:18.12
7,11,19:18.12
-5,12,19:18.12
7,12,19:18.12
9,13,19:18.12
6,14,19:18.12
-6,-12,20:18.12
3,-12,20:18.12
5,-12,20:18.12
4,-11,20:18.12
5,-11,20:18.12
6,-11,20:18.12
10,-11,20:18.12
-8,-10,20:18.12
-6,-10,20:18.12
-4,-10,20:18.12
-3,-10,20:18.12
-2,-10,20:18.12
1,-10,20:18.12
3,-10,20:18.12
4,-10,20:18.12
5,-10,20:18.12
6,-10,20:18.12
10,-10,20:18.12
-4,-9,20:18.12
-3,-9,20:18.12
-1,-9,20:18.12
1,-9,20:18.12
2,-9,20:18.12
3,-9,20:18.12
4,-9,20:18.12
6,-9,20:18.12
9,-9,20:18.12
-10,-8,20:18.12
-9,-8,20:18.12
-8,-8,20:18.12
-4,-8,20:18.12
-3,-8,20:18.12
-2,-8,20:18.12
-1,-8,20:18.12
0,-8,20:18.12
1,-8,20:18.12
2,-8,20:18.12
3,-8,20:18.12
4,-8,20:18.12
5,-8,20:18.12
6,-8,20:18.12
7,-8,20:18.12
8,-8,20:18.12
9,-8,20:18.12
10,-8,20:18.12
11,-8,20:18.12
12,-8,20:18.12
-10,-7,20:18.12
-9,-7,20:18.12
-7,-7,20:18.12
-4,-7,20:18.12
-3,-7,20:18.12
-2,-7,20:18.12
-1,-7,20:18.12
0,-7,20:18.12
1,-7,20:18.12
2,-7,20:18.12
3,-7,20:18.12
4,-7,20:18.12
5,-7,20:18.12
6,-7,20:18.12
7,-7,20:18.12
8,-7,20:18.12
9,-7,20:18.12
10,-7,20:18.12
11,-7,20:18.12
12,-7,20:18.12
13,-7,20:18.12
14,-7,20:18.12
-11,-6,20:18.12
-10,-6,20:18.12
-9,-6,20:18.12
-8,-6,20:18.12
-7,-6,20:18.12
-6,-6,20:18.12
-5,-6,20:18.12
-4,-6,20:18.12
-3,-6,20:18.12
-2,-6,20:18.12
-1,-6,20:18.12
0,-6,20:18.12
1,-6,20:18.12
2,-6,20:18.12
3,-6,20:18.12
4,-6,20:18.12
5,-6,20:18.12
6,-6,20:18.12
7,-6,20:18.12
8,-6,20:18.12
9,-6,20:18.12
10,-6,20:18.12
11,-6,20:18.12
12,-6,20:18.12
13,-6,20:18.12
14,-6,20:18.12
-13,-5,20:18.12
-12,-5,20:18.12
-11,-5,20:18.12
-10,-5,20:18.12
-9,-5,20:18.12
-8,-5,20:18.12
-7,-5,20:18.12
-5,-5,20:18.12
-4,-5,20:18.12
-3,-5,20:18.12
-2,-5,20:18.12
-1,-5,20:18.12
0,-5,20:18.12
1,-5,20:18.12
2,-5,20:18.12
3,-5,20:18.12
4,-5,20:18.12
5,-5,20:18.12
6,-5,20:18.12
7,-5,20:18.12
8,-5,20:18.12
9,-5,20:18.12
10,-5,20:18.12
11,-5,20:18.12
12,-5,20:18.12
13,-5,20:18.12
14,-5,20:18.12
-12,-4,20:18.12
-11,-4,20:18.12
-10,-4,20:18.12
-9,-4,20:18.12
-8,-4,20:18.12
-7,-4,20:18.12
-6,-4,20:18.12
-5,-4,20:18.12
-4,-4,20:18.12
-3,-4,20:18.12
-2,-4,20:18.12
-1,-4,20:18.12
0,-4,20:18.12
1,-4,20:18.12
2,-4,20:18.12
3,-4,20:18.12
4,-4,20:18.12
5,-4,20:18.12
6,-4,20:18.12
7,-4,20:18.12
8,-4,20:18.12
9,-4,20:18.12
10,-4,20:18.12
11,-4,20:18.12
12,-4,20:18.12
13,-4,20:18.12
14,-4,20:18.12
15,-4,20:18.12
-12,-3,20:18.12
-11,-3,20:18.12
-10,-3,20:18.12
-9,-3,20:18.12
-8,-3,20:18.12
-7,-3,20:18.12
-5,-3,20:18.12
-4,-3,20:18.12
-3,-3,20:18.12
-2,-3,20:18.12
-1,-3,20:18.12
0,-3,20:18.12
1,-3,20:18.12
2,-3,20:18.12
3,-3,20:18.12
4,-3,20:18.12
5,-3,20:18.12
6,-3,20:18.12
7,-3,20:18.12
8,-3,20:18.12
9,-3,20:18.12
10,-3,20:18.12
11,-3,20:18.12
13,-3,20:18.12
-12,-2,20:18.12
-11,-2,20:18.12
-10,-2,20:18.12
-9,-2,20:18.12
-8,-2,20:18.12
-7,-2,20:18.12
-6,-2,20:18.12
-5,-2,20:18.12
-4,-2,20:18.12
-3,-2,20:18.12
-2,-2,20:18.12
-1,-2,20:18.12
0,-2,20:18.12
1,-2,20:18.12
2,-2,20:18.12
3,-2,20:18.12
4,-2,20:18.12
5,-2,20:18.12
6,-2,20:18.12
7,-2,20:18.12
8,-2,20:18.12
9,-2,20:18.12
10,-2,20:18.12
11,-2,20:18.12
12,-2,20:18.12
-12,-1,20:18.12
-11,-1,20:18.12
-10,-1,20:18.12
-9,-1,20:18.12
-8,-1,20:18.12
-7,-1,20:18.12
-6,-1,20:18.12
-5,-1,20:18.12
-4,-1,20:18.12
-3,-1,20:18.12
-2,-1,20:18.12
-1,-1,20:18.12
0,-1,20:18.12
1,-1,20:18.12
2,-1,20:18.12
3,-1,20:18.12
4,-1,20:18.12
5,-1,20:18.12
6,-1,20:18.12
7,-1,20:18.12
8,-1,20:18.12
9,-1,20:18.12
10,-1,20:18.12
11,-1,20:18.12
12,-1,20:18.12
13,-1,20:18.12
14,-1,20:18.12
-14,0,20:18.12
-12,0,20:18.12
-11,0,20:18.12
-9,0,20:18.12
-8,0,20:18.12
-7,0,20:18.12
-6,0,20:18.12
-5,0,20:18.12
-4,0,20:18.12
-3,0,20:18.12
-2,0,20:18.12
-1,0,20:18.12
0,0,20:18.12
2,0,20:18.12
3,0,20:18.12
4,0,20:18.12
5,0,20:18.12
6,0,20:18.12
7,0,20:18.12
9,0,20:18.12
10,0,20:18.12
11,0,20:18.12
12,0,20:18.12
13,0,20:18.12
14,0,20:18.12
15,0,20:18.12
-13,1,20:18.12
-12,1,20:18.12
-11,1,20:18.12
-10,1,20:17.12
-9,1,20:18.12
-8,1,20:18.12
-7,1,20:18.12
-6,1,20:18.12
-5,1,20:18.12
-4,1,20:18.12
-3,1,20:18.12
-1,1,20:18.12
0,1,20:18.12
1,1,20:18.12
2,1,20:18.12
3,1,20:18.12
4,1,20:18.12
5,1,20:18.12
6,1,20:18.12
7,1,20:18.12
8,1,20:18.12
12,1,20:18.12
13,1,20:18.12
14,1,20:18.12
15,1,20:18.12
-13,2,20:18.12
-12,2,20:18.12
-11,2,20:18.12
-10,2,20:18.12
-9,2,20:18.12
-8,2,20:18.12
-7,2,20:18.12
-6,2,20:18.12
-5,2,20:18.12
-1,2,20:18.12
0,2,20:18.12
1,2,20:18.12
2,2,20:18.12
3,2,20:18.12
4,2,20:18.12
5,2,20:17.12
6,2,20:18.12
7,2,20:18.12
8,2,20:18.12
9,2,20:18.12
10,2,20:18.12
11,2,20:18.12
12,2,20:18.12
13,2,20:18.12
14,2,20:18.12
15,2,20:18.12
16,2,20:18.12
-13,3,20:18.12
-12,3,20:18.12
-11,3,20:18.12
-10,3,20:18.12
-8,3,20:18.12
-7,3,20:18.12
-5,3,20:18.12
-2,3,20:18.12
-1,3,20:18.12
0,3,20:18.12
1,3,20:18.12
2,3,20:18.12
3,3,20:18.12
4,3,20:18.12
5,3,20:17.12
6,3,20:18.12
7,3,20:18.12
8,3,20:18.12
9,3,20:18.12
10,3,20:18.12
11,3,20:18.12
13,3,20:18.12
14,3,20:18.12
15,3,20:18.12
-14,4,20:18.12
-13,4,20:18.12
-12,4,20:18.12
-11,4,20:18.12
-10,4,20:18.12
-8,4,20:18.12
-7,4,20:18.12
-5,4,20:18.12
0,4,20:18.12
1,4,20:18.12
2,4,20:18.12
3,4,20:18.12
4,4,20:18.12
5,4,20:17.12
6,4,20:18.12
7,4,20:18.12
8,4,20:18.12
9,4,20:18.12
10,4,20:18.12
11,4,20:18.12
12,4,20:18.12
13,4,20:18.12
-13,5,20:18.12
-12,5,20:18.12
-11,5,20:18.12
-9,5,20:18.12
-8,5,20:18.12
-7,5,20:18.12
-6,5,20:18.12
0,5,20:18.12
1,5,20:18.12
3,5,20:18.12
4,5,20:18.12
6,5,20:18.12
7,5,20:18.12
8,5,20:18.12
9,5,20:18.12
10,5,20:18.12
11,5,20:18.12
12,5,20:18.12
13,5,20:18.12
-12,6,20:18.12
-8,6,20:18.12
-7,6,20:18.12
-6,6,20:18.12
-5,6,20:18.12
-4,6,20:18.12
-2,6,20:18.12
0,6,20:18.12
1,6,20:18.12
4,6,20:18.12
7,6,20:18.12
9,6,20:18.12
10,6,20:18.12
11,6,20:18.12
-11,7,20:18.12
-10,7,20:18.12
-9,7,20:18.12
-8,7,20:18.12
-7,7,20:18.12
-6,7,20:18.12
-5,7,20:18.12
-4,7,20:18.12
-3,7,20:18.12
-2,7,20:18.12
-1,7,20:18.12
1,7,20:18.12
3,7,20:18.12
10,7,20:18.12
11,7,20:18.12
-10,8,20:18.12
-9,8,20:18.12
-8,8,20:18.12
-7,8,20:18.4
-6,8,20:18.12
-5,8,20:18.12
-4,8,20:18.12
-3,8,20:18.12
-2,8,20:18.12
-1,8,20:18.12
0,8,20:18.12
1,8,20:18.12
2,8,20:18.12
3,8,20:18.12
4,8,20:18.12
10,8,20:18.12
11,8,20:18.12
-10,9,20:18.12
-9,9,20:18.12
-6,9,20:18.12
-5,9,20:18.12
-4,9,20:18.12
-3,9,20:18.12
-1,9,20:18.12
1,9,20:18.12
2,9,20:18.12
3,9,20:18.12
4,9,20:18.12
5,9,20:18.12
8,9,20:18.12
9,9,20:18.12
10,9,20:18.12
-8,10,20:18.12
-7,10,20:18.12
-4,10,20:18.12
-3,10,20:18.12
-2,10,20:18.12
1,10,20:18.12
2,10,20:18.12
3,10,20:18.12
4,10,20:18.12
6,10,20:18.12
7,10,20:18.12
8,10,20:18.12
12,10,20:18.12
-7,11,20:18.12
-4,11,20:18.12
-2,11,20:18.12
-1,11,20:18.12
3,11,20:18.12
5,11,20:18.12
6,11,20:18.12
7,11,20:18.12
3,-12,21:18.12
-4,-11,21:18.12
-3,-11,21:18.12
-2,-11,21:18.12
3,-11,21:18.12
4,-11,21:18.12
-5,-10,21:18.12
-4,-10,21:18.12
-3,-10,21:18.12
-2,-10,21:18.12
2,-10,21:18.12
3,-10,21:18.12
4,-10,21:18.12
-4,-9,21:18.12
-3,-9,21:18.12
-2,-9,21:18.12
-1,-9,21:18.12
0,-9,21:18.12
3,-9,21:18.12
4,-9,21:18.12
10,-9,21:18.12
-4,-8,21:18.12
-3,-8,21:18.12
-2,-8,21:18.12
-1,-8,21:18.12
0,-8,21:18.12
1,-8,21:18.12
3,-8,21:18.12
9,-8,21:18.12
10,-8,21:18.12
-8,-7,21:18.12
-7,-7,21:18.12
-4,-7,21:18.12
-3,-7,21:18.12
-2,-7,21:18.12
-1,-7,21:18.12
0,-7,21:18.12
1,-7,21:18.12
4,-7,21:18.12
5,-7,21:18.12
6,-7,21:18.12
8,-7,21:18.12
9,-7,21:18.12
14,-7,21:18.12
-9,-6,21:18.12
-8,-6,21:18.12
-7,-6,21:18.12
-5,-6,21:18.12
-4,-6,21:18.12
-3,-6,21:18.12
-2,-6,21:18.12
-1,-6,21:18.12
0,-6,21:18.12
1,-6,21:18.12
2,-6,21:18.12
3,-6,21:18.12
4,-6,21:18.12
5,-6,21:18.12
6,-6,21:18.12
7,-6,21:18.12
9,-6,21:18.12
10,-6,21:18.12
11,-6,21:18.12
13,-6,21:18.12
-13,-5,21:18.12
-12,-5,21:18.12
-9,-5,21:18.12
-8,-5,21:18.12
-7,-5,21:18.12
-6,-5,21:18.12
-5,-5,21:18.12
-4,-5,21:18.12
-3,-5,21:18.12
-2,-5,21:18.12
-1,-5,21:18.12
0,-5,21:18.12
1,-5,21:18.12
2,-5,21:18.12
3,-5,21:18.12
4,-5,21:18.12
5,-5,21:18.12
6,-5,21:18.12
7,-5,21:18.12
8,-5,21:18.12
9,-5,21:18.12
10,-5,21:18.12
11,-5,21:18.12
12,-5,21:18.12
14,-5,21:18.12
-11,-4,21:18.12
-10,-4,21:18.12
-9,-4,21:18.12
-8,-4,21:18.12
-7,-4,21:18.12
-6,-4,21:18.12
-5,-4,21:18.12
-4,-4,21:18.12
-3,-4,21:18.12
-1,-4,21:18.12
0,-4,21:18.12
1,-4,21:18.12
2,-4,21:18.12
3,-4,21:18.12
4,-4,21:18.12
5,-4,21:18.12
6,-4,21:18.12
7,-4,21:18.12
8,-4,21:18.12
9,-4,21:18.12
10,-4,21:18.12
11,-4,21:18.12
12,-4,21:18.12
13,-4,21:18.12
-11,-3,21:18.12
-10,-3,21:18.12
-9,-3,21:18.12
-8,-3,21:18.12
-7,-3,21:18.12
-6,-3,21:18.12
-5,-3,21:18.12
-4,-3,21:18.12
-3,-3,21:18.12
-2,-3,21:18.12
-1,-3,21:18.12
1,-3,21:18.12
2,-3,21:18.12
3,-3,21:18.12
4,-3,21:18.12
6,-3,21:18.12
7,-3,21:18.12
8,-3,21:18.12
9,-3,21:18.12
10,-3,21:18.12
-10,-2,21:18.12
-9,-2,21:18.12
-8,-2,21:18.12
-7,-2,21:18.12
-6,-2,21:18.12
-5,-2,21:18.12
-4,-2,21:18.12
-3,-2,21:18.12
-2,-2,21:18.12
-1,-2,21:18.12
0,-2,21:18.12
1,-2,21:18.12
2,-2,21:18.12
3,-2,21:18.12
5,-2,21:18.12
6,-2,21:18.12
7,-2,21:18.12
8,-2,21:18.12
9,-2,21:18.12
10,-2,21:18.12
12,-2,21:18.12
-14,-1,21:18.12
-13,-1,21:18.12
-12,-1,21:18.12
-11,-1,21:18.12
-10,-1,21:18.12
-9,-1,21:18.12
-8,-1,21:18.12
-7,-1,21:18.12
-6,-1,21:18.12
-5,-1,21:18.12
-4,-1,21:18.12
-3,-1,21:18.12
-1,-1,21:18.12
0,-1,21:18.12
1,-1,21:18.12
2,-1,21:18.12
5,-1,21:18.12
6,-1,21:18.12
7,-1,21:18.12
9,-1,21:18.12
10,-1,21:18.12
11,-1,21:18.12
12,-1,21:18.12
13,-1,21:18.12
14,-1,21:18.12
-14,0,21:18.12
-13,0,21:18.12
-11,0,21:18.12
-10,0,21:18.12
-9,0,21:18.12
-8,0,21:18.12
-7,0,21:18.12
-6,0,21:18.12
-5,0,21:18.12
-4,0,21:18.12
-3,0,21:18.12
-2,0,21:18.12
-1,0,21:18.12
0,0,21:18.12
2,0,21:18.12
3,0,21:18.12
4,0,21:18.12
5,0,21:18.12
6,0,21:18.12
7,0,21:18.12
9,0,21:18.12
10,0,21:18.12
11,0,21:18.12
12,0,21:18.12
13,0,21:18.12
14,0,21:18.12
15,0,21:18.12
-14,1,21:18.12
-13,1,21:18.12
-12,1,21:18.12
-11,1,21:18.12
-9,1,21:18.12
-8,1,21:18.12
-6,1,21:18.12
-5,1,21:18.12
-4,1,21:18.12
-3,1,21:18.12
-2,1,21:18.12
-1,1,21:18.12
0,1,21:18.12
1,1,21:18.12
2,1,21:18.12
3,1,21:18.12
5,1,21:18.12
6,1,21:18.12
7,1,21:18.12
8,1,21:18.12
9,1,21:18.12
10,1,21:18.12
12,1,21:18.12
13,1,21:18.12
15,1,21:18.12
-13,2,21:18.12
-12,2,21:18.12
-11,2,21:18.12
-10,2,21:18.12
-9,2,21:18.12
-8,2,21:18.12
-6,2,21:18.12
-4,2,21:18.12
-3,2,21:18.12
-2,2,21:18.12
-1,2,21:18.12
0,2,21:18.12
1,2,21:18.12
2,2,21:18.12
3,2,21:18.12
4,2,21:18.12
5,2,21:18.12
6,2,21:18.12
7,2,21:18.12
8,2,21:18.12
9,2,21:18.12
10,2,21:18.12
11,2,21:18.12
12,2,21:18.12
13,2,21:18.12
14,2,21:18.12
15,2,21:18.12
16,2,21:18.12
-13,3,21:18.12
-12,3,21:17.12
-11,3,21:18.12
-10,3,21:18.12
-9,3,21:18.12
-8,3,21:18.12
-7,3,21:18.12
-3,3,21:18.12
-1,3,21:18.12
0,3,21:18.12
1,3,21:18.12
2,3,21:18.12
3,3,21:18.12
4,3,21:18.12
5,3,21:18.12
6,3,21:18.12
7,3,21:18.12
8,3,21:18.12
9,3,21:18.12
12,3,21:18.12
13,3,21:18.12
15,3,21:18.12
16,3,21:18.12
-13,4,21:18.12
-12,4,21:18.12
-8,4,21:18.12
-7,4,21:18.12
-6,4,21:18.12
-5,4,21:18.12
-4,4,21:18.12
-3,4,21:18.12
-2,4,21:18.12
-1,4,21:18.12
0,4,21:18.12
1,4,21:18.12
2,4,21:18.12
3,4,21:18.12
4,4,21:18.12
7,4,21:18.12
8,4,21:18.12
9,4,21:18.12
10,4,21:18.12
11,4,21:18.12
12,4,21:18.12
13,4,21:18.12
-12,5,21:18.12
-9,5,21:18.12
-8,5,21:18.12
-7,5,21:18.12
-6,5,21:18.12
-5,5,21:18.12
0,5,21:18.12
1,5,21:18.12
2,5,21:18.12
3,5,21:18.12
4,5,21:18.12
5,5,21:18.12
6,5,21:18.12
8,5,21:18.12
9,5,21:18.12
10,5,21:18.12
11,5,21:18.12
13,5,21:18.12
-9,6,21:18.12
-8,6,21:18.12
-7,6,21:18.12
-6,6,21:18.12
-5,6,21:18.12
-4,6,21:18.12
-2,6,21:18.12
-1,6,21:18.12
0,6,21:18.12
1,6,21:18.12
4,6,21:18.12
8,6,21:18.12
9,6,21:18.12
10,6,21:18.12
11,6,21:18.12
-10,7,21:18.12
-9,7,21:18.12
-8,7,21:18.12
-7,7,21:18.12
-6,7,21:18.12
-5,7,21:18.12
-3,7,21:18.12
-2,7,21:18.12
0,7,21:18.12
1,7,21:18.12
2,7,21:18.12
3,7,21:18.12
4,7,21:18.12
5,7,21:18.12
6,7,21:18.12
9,7,21:18.12
10,7,21:18.12
11,7,21:18.12
-9,8,21:18.12
-6,8,21:18.12
-5,8,21:18.12
-4,8,21:18.12
-3,8,21:18.12
-2,8,21:18.12
-1,8,21:18.12
0,8,21:18.12
1,8,21:18.12
2,8,21:18.12
3,8,21:18.12
4,8,21:18.12
6,8,21:18.12
7,8,21:18.12
8,8,21:18.12
9,8,21:18.12
10,8,21:18.12
11,8,21:18.12
-6,9,21:18.12
-5,9,21:18.12
-3,9,21:18.12
-2,9,21:18.12
-1,9,21:18.12
2,9,21:18.12
3,9,21:18.12
4,9,21:18.12
5,9,21:18.12
6,9,21:18.12
9,9,21:18.12
10,9,21:18.12
11,9,21:18.12
12,9,21:18.12
-4,10,21:18.12
-3,10,21:18.12
-2,10,21:18.12
2,10,21:18.12
4,10,21:18.12
5,10,21:18.12
6,10,21:18.12
7,10,21:18.12
8,10,21:18.12
11,10,21:18.12
12,10,21:18.12
-4,11,21:18.12
-3,11,21:18.12
-2,11,21:18.12
5,11,21:18.12
6,11,21:18.12
7,11,21:18.12
3,-11,22:18.12
-3,-10,22:18.12
3,-10,22:18.12
4,-10,22:18.12
-3,-9,22:18.12
-2,-9,22:18.12
-1,-9,22:18.12
0,-9,22:18.12
-4,-8,22:18.12
-3,-8,22:18.12
-2,-8,22:18.12
0,-8,22:18.12
-4,-7,22:18.12
-3,-7,22:18.12
-2,-7,22:18.12
-1,-7,22:18.12
0,-7,22:18.12
1,-7,22:18.12
9,-7,22:18.12
-8,-6,22:18.12
-4,-6,22:18.12
-3,-6,22:18.12
-2,-6,22:18.12
-1,-6,22:18.12
2,-6,22:18.12
3,-6,22:18.12
4,-6,22:18.12
7,-6,22:18.12
11,-6,22:18.12
13,-6,22:18.12
-2,-5,22:18.12
-1,-5,22:18.12
0,-5,22:18.12
1,-5,22:18.12
2,-5,22:18.12
3,-5,22:18.12
4,-5,22:18.12
5,-5,22:18.12
7,-5,22:18.12
8,-5,22:18.12
9,-5,22:18.12
10,-5,22:18.12
11,-5,22:18.12
12,-5,22:18.12
-11,-4,22:18.12
-10,-4,22:18.12
-9,-4,22:18.12
-8,-4,22:18.12
-7,-4,22:18.12
-5,-4,22:18.12
-3,-4,22:18.12
-2,-4,22:18.12
-1,-4,22:18.12
0,-4,22:18.12
2,-4,22:18.12
4,-4,22:18.12
5,-4,22:18.12
6,-4,22:18.12
8,-4,22:18.12
9,-4,22:18.12
11,-4,22:18.12
12,-4,22:18.12
-11,-3,22:18.12
-10,-3,22:18.12
-9,-3,22:18.12
-8,-3,22:18.12
-7,-3,22:18.12
-5,-3,22:18.12
-4,-3,22:18.12
-3,-3,22:18.12
2,-3,22:18.12
3,-3,22:18.12
5,-3,22:18.12
7,-3,22:18.12
8,-3,22:18.12
9,-3,22:18.12
10,-3,22:18.12
11,-3,22:18.12
12,-3,22:18.12
-11,-2,22:18.12
-10,-2,22:18.12
-9,-2,22:18.12
-8,-2,22:18.12
-6,-2,22:18.12
-5,-2,22:18.12
-4,-2,22:18.12
-2,-2,22:18.12
1,-2,22:18.12
2,-2,22:18.12
3,-2,22:18.12
5,-2,22:18.12
7,-2,22:18.12
8,-2,22:18.12
9,-2,22:18.12
13,-2,22:18.12
-13,-1,22:18.12
-11,-1,22:18.12
-10,-1,22:18.12
-9,-1,22:18.12
-8,-1,22:18.12
-7,-1,22:18.12
-6,-1,22:18.12
-5,-1,22:18.12
-4,-1,22:18.12
-3,-1,22:18.12
-2,-1,22:18.12
-1,-1,22:18.12
0,-1,22:18.12
2,-1,22:18.12
3,-1,22:18.12
4,-1,22:18.12
5,-1,22:18.12
7,-1,22:18.12
8,-1,22:18.12
9,-1,22:18.12
11,-1,22:18.12
12,-1,22:18.12
13,-1,22:18.12
-15,0,22:18.12
-14,0,22:18.12
-13,0,22:18.12
-12,0,22:18.12
-11,0,22:18.12
-10,0,22:18.12
-9,0,22:18.12
-8,0,22:18.12
-7,0,22:18.12
-6,0,22:18.12
-5,0,22:18.12
-4,0,22:18.12
-3,0,22:18.12
-2,0,22:18.12
-1,0,22:18.12
0,0,22:18.12
1,0,22:18.12
2,0,22:18.12
3,0,22:18.12
4,0,22:18.12
5,0,22:18.12
6,0,22:18.12
7,0,22:18.12
9,0,22:18.12
10,0,22:18.12
12,0,22:18.12
13,0,22:18.12
-14,1,22:18.12
-13,1,22:18.12
-12,1,22:18.12
-11,1,22:18.12
-10,1,22:18.12
-8,1,22:18.12
-7,1,22:18.12
-6,1,22:18.12
-5,1,22:18.12
-4,1,22:18.12
-3,1,22:18.12
-2,1,22:18.12
-1,1,22:18.12
0,1,22:18.12
2,1,22:18.12
3,1,22:18.12
4,1,22:18.12
5,1,22:18.12
6,1,22:18.12
7,1,22:18.12
9,1,22:18.12
10,1,22:18.12
12,1,22:18.12
13,1,22:18.12
-12,2,22:18.12
-11,2,22:18.12
-10,2,22:18.12
-8,2,22:18.12
-7,2,22:18.12
-6,2,22:18.12
-4,2,22:18.12
-3,2,22:18.12
-1,2,22:18.12
0,2,22:18.12
1,2,22:18.12
2,2,22:18.12
3,2,22:18.12
4,2,22:18.12
5,2,22:18.12
6,2,22:18.12
7,2,22:18.12
8,2,22:18.12
9,2,22:18.12
13,2,22:18.12
14,2,22:18.12
15,2,22:18.12
16,2,22:18.12
-13,3,22:18.12
-12,3,22:18.4
-11,3,22:18.12
-8,3,22:18.12
-4,3,22:18.12
-3,3,22:18.12
-2,3,22:18.12
-1,3,22:18.12
0,3,22:18.12
1,3,22:18.12
2,3,22:18.12
3,3,22:18.12
4,3,22:18.12
5,3,22:18.12
6,3,22:18.12
7,3,22:18.12
8,3,22:18.12
9,3,22:18.12
10,3,22:18.12
15,3,22:18.12
-14,4,22:18.12
-13,4,22:18.12
-8,4,22:18.12
-7,4,22:18.12
-6,4,22:18.12
-5,4,22:18.12
-4,4,22:18.12
-3,4,22:18.12
-2,4,22:18.12
-1,4,22:18.12
2,4,22:18.12
3,4,22:18.12
4,4,22:18.12
5,4,22:18.12
6,4,22:18.12
7,4,22:18.12
8,4,22:18.12
9,4,22:18.12
13,4,22:18.12
14,4,22:18.12
-8,5,22:18.12
-7,5,22:18.12
-6,5,22:18.12
-3,5,22:18.12
-2,5,22:18.12
-1,5,22:18.12
0,5,22:18.12
1,5,22:18.12
2,5,22:18.12
3,5,22:18.12
4,5,22:18.12
5,5,22:18.12
8,5,22:18.12
9,5,22:18.12
10,5,22:18.12
-9,6,22:18.12
-8,6,22:18.12
-7,6,22:18.12
-5,6,22:18.12
-4,6,22:18.12
-3,6,22:18.12
-2,6,22:18.12
-1,6,22:18.12
0,6,22:18.12
1,6,22:18.12
2,6,22:18.12
3,6,22:18.12
4,6,22:18.12
5,6,22:18.12
10,6,22:18.12
11,6,22:18.12
-10,7,22:18.12
-9,7,22:18.12
-8,7,22:18.12
-7,7,22:18.12
-6,7,22:18.12
-5,7,22:18.12
-4,7,22:18.12
-3,7,22:18.12
-2,7,22:18.12
-1,7,22:18.12
0,7,22:18.12
3,7,22:18.12
4,7,22:18.12
5,7,22:18.12
6,7,22:18.12
7,7,22:18.12
10,7,22:18.12
11,7,22:18.12
-8,8,22:18.12
-6,8,22:18.12
-5,8,22:18.12
-1,8,22:18.12
0,8,22:18.12
1,8,22:18.12
2,8,22:18.12
3,8,22:18.12
4,8,22:18.12
6,8,22:18.12
7,8,22:18.12
9,8,22:18.12
10,8,22:18.12
-8,9,22:18.12
-4,9,22:18.12
-3,9,22:18.12
-2,9,22:18.12
-1,9,22:18.12
0,9,22:18.12
2,9,22:18.12
3,9,22:18.12
4,9,22:18.12
5,9,22:18.12
7,9,22:18.12
10,9,22:18.12
-5,10,22:18.12
-4,10,22:18.12
-3,10,22:18.12
-2,10,22:18.12
-1,10,22:18.12
1,10,22:18.12
2,10,22:18.12
3,10,22:18.12
4,10,22:18.12
5,10,22:18.12
6,10,22:18.12
7,10,22:18.12
8,10,22:18.12
-3,11,22:18.12
-2,11,22:18.12
-1,11,22:18.12
0,11,22:18.12
6,11,22:18.12
7,11,22:18.12
8,11,22:18.12
-3,12,22:18.12
-2,12,22:18.12
7,12,22:18.12
4,-10,23:18.12
-2,-9,23:18.12
-2,-8,23:18.12
0,-8,23:18.12
-2,-7,23:18.12
-1,-7,23:18.12
0,-7,23:18.12
1,-7,23:18.12
11,-7,23:18.12
-1,-6,23:18.12
4,-6,23:18.12
6,-6,23:18.12
7,-6,23:18.12
11,-6,23:18.12
-1,-5,23:18.12
0,-5,23:18.12
2,-5,23:18.12
4,-5,23:18.12
6,-5,23:18.12
8,-5,23:18.12
11,-5,23:18.12
12,-5,23:18.12
-11,-4,23:18.12
-9,-4,23:18.12
-8,-4,23:18.12
-7,-4,23:18.12
0,-4,23:18.12
2,-4,23:18.12
6,-4,23:18.12
11,-4,23:18.12
-9,-3,23:18.12
-8,-3,23:18.12
0,-3,23:18.12
3,-3,23:18.12
4,-3,23:18.12
5,-3,23:18.12
6,-3,23:18.12
8,-3,23:18.12
10,-3,23:18.12
11,-3,23:18.12
12,-3,23:18.12
-12,-2,23:18.12
-11,-2,23:18.12
-10,-2,23:18.12
-9,-2,23:18.12
-6,-2,23:18.12
-5,-2,23:18.12
-4,-2,23:18.12
-3,-2,23:18.12
-2,-2,23:18.12
1,-2,23:18.12
2,-2,23:18.12
3,-2,23:18.12
5,-2,23:18.12
6,-2,23:18.12
11,-2,23:18.12
12,-2,23:18.12
-13,-1,23:18.12
-12,-1,23:18.12
-11,-1,23:18.12
-10,-1,23:18.12
-9,-1,23:18.12
-8,-1,23:18.12
-6,-1,23:18.12
-5,-1,23:18.12
-4,-1,23:18.12
-3,-1,23:18.12
1,-1,23:18.12
2,-1,23:18.12
3,-1,23:18.12
4,-1,23:18.12
5,-1,23:18.12
10,-1,23:18.12
11,-1,23:18.12
12,-1,23:18.12
13,-1,23:18.12
-12,0,23:18.12
-11,0,23:18.12
-10,0,23:18.12
-9,0,23:18.12
-8,0,23:18.12
-7,0,23:18.12
-6,0,23:18.12
-5,0,23:18.12
-4,0,23:18.12
-3,0,23:18.12
0,0,23:18.12
2,0,23:18.12
3,0,23:18.12
4,0,23:18.12
5,0,23:18.12
10,0,23:18.12
11,0,23:18.12
-12,1,23:18.12
-11,1,23:18.12
-10,1,23:18.12
-6,1,23:18.12
-5,1,23:18.12
-2,1,23:18.12
2,1,23:18.12
3,1,23:18.12
4,1,23:18.12
5,1,23:18.12
6,1,23:18.12
7,1,23:18.12
8,1,23:18.12
9,1,23:18.12
10,1,23:18.12
-13,2,23:18.12
-12,2,23:18.12
-11,2,23:18.12
-10,2,23:18.12
-8,2,23:18.12
-7,2,23:18.12
-4,2,23:18.12
-1,2,23:18.12
1,2,23:18.12
2,2,23:18.12
3,2,23:18.12
4,2,23:18.12
5,2,23:18.12
6,2,23:18.12
8,2,23:18.12
9,2,23:18.12
10,2,23:18.12
-13,3,23:18.12
-11,3,23:18.12
-9,3,23:18.12
-8,3,23:18.12
-7,3,23:18.12
-4,3,23:18.12
-3,3,23:18.12
-2,3,23:18.12
-1,3,23:18.12
1,3,23:18.12
5,3,23:18.12
6,3,23:18.12
7,3,23:18.12
8,3,23:18.12
-8,4,23:18.12
-7,4,23:18.12
-6,4,23:18.12
-5,4,23:18.12
-4,4,23:18.12
4,4,23:18.12
5,4,23:18.12
6,4,23:18.12
7,4,23:18.12
13,4,23:18.12
-7,5,23:18.12
-6,5,23:18.12
-5,5,23:18.12
-3,5,23:18.12
-1,5,23:18.12
0,5,23:18.12
2,5,23:18.12
3,5,23:18.12
4,5,23:18.12
5,5,23:18.12
6,5,23:18.12
7,5,23:18.12
8,5,23:18.12
10,5,23:18.12
-8,6,23:18.12
-7,6,23:18.12
-6,6,23:18.12
-3,6,23:18.12
-2,6,23:18.12
2,6,23:18.12
3,6,23:18.12
4,6,23:18.12
5,6,23:18.12
6,6,23:18.12
7,6,23:18.12
8,6,23:18.12
9,6,23:18.12
10,6,23:18.12
-8,7,23:18.12
-4,7,23:18.12
-3,7,23:18.12
-2,7,23:18.12
0,7,23:18.12
3,7,23:18.12
4,7,23:18.12
5,7,23:18.12
6,7,23:18.12
7,7,23:18.12
8,7,23:18.12
9,7,23:18.12
10,7,23:18.12
-3,8,23:18.12
-2,8,23:18.12
-1,8,23:18.12
0,8,23:18.12
2,8,23:18.12
4,8,23:18.12
5,8,23:18.12
6,8,23:18.12
7,8,23:18.12
8,8,23:18.12
9,8,23:18.12
10,8,23:18.12
-2,9,23:18.12
-1,9,23:18.12
3,9,23:18.12
4,9,23:18.12
5,9,23:18.12
6,9,23:18.12
7,9,23:18.12
8,9,23:18.12
9,9,23:18.12
10,9,23:18.12
-4,10,23:18.12
-3,10,23:18.12
-2,10,23:18.12
-1,10,23:18.12
0,10,23:18.12
1,10,23:18.12
4,10,23:18.12
8,10,23:18.12
10,10,23:18.12
-4,11,23:18.12
-3,11,23:18.12
-2,11,23:18.12
-1,11,23:18.12
0,11,23:18.12
4,11,23:18.12
8,11,23:18.12
-3,12,23:18.12
-2,12,23:18.12
-1,12,23:18.12
0,12,23:18.12
0,-7,24:18.12
6,-6,24:18.12
7,-6,24:18.12
10,-5,24:18.12
11,-5,24:18.12
12,-5,24:18.12
-8,-4,24:18.12
6,-4,24:18.12
-9,-3,24:18.12
-8,-3,24:18.12
3,-3,24:18.12
-11,-2,24:18.12
-9,-2,24:18.12
-8,-2,24:18.12
-7,-2,24:18.12
-6,-2,24:18.12
-3,-2,24:18.12
6,-2,24:18.12
12,-2,24:18.12
-12,-1,24:18.12
-5,-1,24:18.12
-4,-1,24:18.12
-3,-1,24:18.12
12,-1,24:18.12
-9,0,24:18.12
-6,0,24:18.12
-4,0,24:18.12
2,0,24:18.12
5,0,24:18.12
12,0,24:18.12
-12,1,24:18.12
-11,1,24:18.12
-10,1,24:18.12
-9,1,24:18.12
-7,1,24:18.12
-6,1,24:18.12
-4,1,24:18.12
1,1,24:18.12
2,1,24:18.12
5,1,24:18.12
7,1,24:18.12
-12,2,24:18.12
-7,2,24:18.12
-5,2,24:18.12
-4,2,24:18.12
-3,2,24:18.12
1,2,24:18.12
2,2,24:18.12
5,2,24:18.12
6,2,24:18.12
-9,3,24:18.12
-8,3,24:18.12
-5,3,24:18.12
-4,3,24:18.12
-3,3,24:18.12
-2,3,24:18.12
1,3,24:18.12
5,3,24:18.12
8,3,24:18.12
-5,4,24:18.12
-4,4,24:18.12
-3,4,24:18.12
5,4,24:18.12
6,4,24:18.12
-5,5,24:18.12
-4,5,24:18.12
-3,5,24:18.12
-1,5,24:18.12
2,5,24:18.12
4,5,24:18.12
5,5,24:18.12
6,5,24:18.12
7,5,24:18.12
-8,6,24:18.12
-7,6,24:18.12
-6,6,24:18.12
-1,6,24:18.12
4,6,24:18.12
5,6,24:18.12
6,6,24:18.12
7,6,24:18.12
3,7,24:18.12
4,7,24:18.12
5,7,24:18.12
6,7,24:18.12
8,7,24:18.12
10,7,24:18.12
3,8,24:18.12
5,8,24:18.12
6,8,24:18.12
8,8,24:18.12
4,9,24:18.12
5,9,24:18.12
-3,10,24:18.12
1,10,24:18.12
5,10,24:18.12
-3,11,24:18.12
-2,11,24:18.12
-3,12,24:18.12
6,-5,25:18.12
11,-5,25:18.12
6,-4,25:18.12
-4,-1,25:18.12
-12,2,25:18.12
-6,2,25:18.12
-5,2,25:18.12
-4,2,25:18.12
-8,3,25:18.12
-5,3,25:18.12
6,4,25:18.12
-1,5,25:18.12
2,5,25:18.12
4,5,25:18.12
5,5,25:18.12
7,5,25:18.12
4,6,25:18.12
7,6,25:18.12
4,7,25:18.12
5,7,25:18.12
7,7,25:18.12
8,7,25:18.12
10,7,25:18.12
5,8,25:18.12
8,8,25:18.12
-6,2,26:18.12
4,6,26:18.12
4,6,27:18.12
