[META]
version=2.0
spawnOnBlockType=2
spawnSunlight=True
spawnDarkness=True
spawnWater=False
spawnLava=False
underFill=False
randomRotation=True
dig=True
tree=False
branch=False
needsFoundation=True
rarity=100
collisionPercentage=20
spawnElevationMin=0
spawnElevationMax=200
spawnInBiome=Custom
[DATA]
-3,4,-8:17.12
-9,5,-8:17.12
-9,6,-8:17.12
-8,6,-8:17.12
1,6,-8:17.12
-8,10,-8:17.12
-1,10,-8:17.12
-8,11,-8:17.12
-3,3,-7:17.12
-4,4,-7:17.12
-3,4,-7:17.12
-4,5,-7:17.12
-3,5,-7:17.12
-9,6,-7:17.12
0,6,-7:17.12
1,6,-7:17.12
-9,7,-7:17.12
0,7,-7:17.12
1,7,-7:17.12
2,7,-7:17.12
2,8,-7:17.12
-8,9,-7:17.12
-7,9,-7:17.12
-3,9,-7:17.12
-2,9,-7:17.12
-8,10,-7:17.12
-7,10,-7:17.12
-6,10,-7:17.12
-4,10,-7:17.12
-3,10,-7:17.12
-2,10,-7:17.12
-7,11,-7:17.12
-3,11,-7:17.12
-4,4,-6:17.12
-3,4,-6:17.12
-3,5,-6:17.12
-10,6,-6:17.12
-9,6,-6:17.12
-8,6,-6:17.12
-1,6,-6:17.12
0,6,-6:17.12
1,6,-6:17.12
-9,7,-6:17.12
-1,7,-6:17.12
0,7,-6:17.12
1,7,-6:17.12
2,7,-6:17.12
-1,8,-6:17.12
0,8,-6:17.12
-8,9,-6:17.12
-7,9,-6:17.12
-4,9,-6:17.12
-1,9,-6:17.12
-7,10,-6:17.12
-3,10,-6:17.12
-2,10,-6:17.12
-1,10,-6:17.12
-4,11,-6:17.12
-3,3,-5:17.12
-3,4,-5:17.12
-2,4,-5:17.12
-9,5,-5:17.12
-7,5,-5:17.12
-5,5,-5:17.12
-4,5,-5:17.12
-3,5,-5:17.12
-2,5,-5:17.12
-10,6,-5:17.12
-9,6,-5:17.12
-8,6,-5:17.12
-7,6,-5:17.12
-4,6,-5:17.12
-3,6,-5:17.12
-1,6,-5:17.12
-9,7,-5:17.12
-8,7,-5:17.12
-1,7,-5:17.12
0,7,-5:17.12
1,7,-5:17.12
-2,8,-5:17.12
-1,8,-5:17.12
0,8,-5:17.12
-7,9,-5:17.12
-2,9,-5:17.12
-1,9,-5:17.12
-8,10,-5:17.12
-7,10,-5:17.12
-6,10,-5:17.12
-3,10,-5:17.12
-2,10,-5:17.12
-7,4,-4:17.12
-5,4,-4:17.12
-4,4,-4:17.12
-8,5,-4:17.12
-7,5,-4:17.12
-6,5,-4:17.12
-5,5,-4:17.12
-4,5,-4:17.12
-3,5,-4:17.12
-8,6,-4:17.12
-7,6,-4:17.12
-6,6,-4:17.12
-3,6,-4:17.12
0,6,-4:17.12
-8,7,-4:17.12
-7,7,-4:17.12
-6,7,-4:17.12
-1,7,-4:17.12
1,7,-4:17.12
-3,8,-4:17.12
-2,8,-4:17.12
-7,9,-4:17.12
-3,9,-4:17.12
-2,9,-4:17.12
-7,10,-4:17.12
-6,10,-4:17.12
-3,10,-4:17.12
-2,10,-4:17.12
-8,11,-4:17.12
-7,11,-4:17.12
-3,11,-4:17.12
-8,4,-3:17.12
-7,4,-3:17.12
-6,4,-3:17.12
-4,4,-3:17.12
-3,4,-3:17.12
-7,5,-3:17.12
-6,5,-3:17.12
-5,5,-3:17.12
-4,5,-3:17.12
-3,5,-3:17.12
-8,6,-3:17.12
-7,6,-3:17.12
-6,6,-3:17.12
-3,6,-3:17.12
-4,8,-3:17.12
-3,8,-3:17.12
-2,8,-3:17.12
-1,8,-3:17.12
-7,9,-3:17.12
-3,9,-3:17.12
-2,9,-3:17.12
-8,10,-3:17.12
-7,10,-3:17.12
-6,10,-3:17.12
-4,10,-3:17.12
-3,10,-3:17.12
-8,11,-3:17.12
-6,3,-2:17.12
-5,3,-2:17.12
-4,3,-2:17.12
-7,4,-2:17.12
-6,4,-2:17.12
-5,4,-2:17.12
-4,4,-2:17.12
-3,4,-2:17.12
-2,4,-2:17.12
-8,5,-2:17.12
-7,5,-2:17.12
-6,5,-2:17.12
-5,5,-2:17.12
-4,5,-2:17.12
-3,5,-2:17.12
-2,5,-2:17.12
-9,6,-2:17.12
-8,6,-2:17.12
-7,6,-2:17.12
-6,6,-2:17.12
-5,6,-2:17.12
-4,6,-2:17.12
-3,6,-2:17.12
-2,6,-2:17.12
-1,6,-2:17.12
-9,7,-2:17.12
-8,7,-2:17.12
-7,7,-2:17.12
-6,7,-2:17.12
-5,7,-2:17.12
-4,7,-2:17.12
-3,7,-2:17.12
-2,7,-2:17.12
-1,7,-2:17.12
-9,8,-2:17.12
-8,8,-2:17.12
-7,8,-2:17.12
-6,8,-2:17.12
-5,8,-2:17.12
-4,8,-2:17.12
-3,8,-2:17.12
-2,8,-2:17.12
-1,8,-2:17.12
-9,9,-2:17.12
-8,9,-2:17.12
-7,9,-2:17.12
-6,9,-2:17.12
-5,9,-2:17.12
-4,9,-2:17.12
-3,9,-2:17.12
-2,9,-2:17.12
-1,9,-2:17.12
-8,10,-2:17.12
-7,10,-2:17.12
-6,10,-2:17.12
-5,10,-2:17.12
-4,10,-2:17.12
-3,10,-2:17.12
-2,10,-2:17.12
-8,11,-2:17.12
-7,11,-2:17.12
-6,11,-2:17.12
-5,11,-2:17.12
-4,11,-2:17.12
-3,11,-2:17.12
-6,12,-2:17.12
-5,12,-2:17.12
-4,12,-2:17.12
-6,3,-1:17.12
-5,3,-1:17.12
-4,3,-1:17.12
-7,4,-1:17.12
-6,4,-1:17.12
-4,4,-1:17.12
-3,4,-1:17.12
-2,4,-1:17.12
-8,5,-1:17.12
-7,5,-1:17.12
-2,5,-1:17.12
-8,6,-1:17.12
-1,6,-1:17.12
0,6,-1:17.12
-9,7,-1:17.12
-1,7,-1:17.12
0,7,-1:17.12
-9,8,-1:17.12
-4,8,-1:17.12
-1,8,-1:17.12
0,8,-1:17.12
-8,9,-1:17.12
-7,9,-1:17.12
-5,9,-1:17.12
-4,9,-1:17.12
-2,9,-1:17.12
-1,9,-1:17.12
-8,10,-1:17.12
-7,10,-1:17.12
-6,10,-1:17.12
-2,10,-1:17.12
-8,11,-1:17.12
-7,11,-1:17.12
-6,11,-1:17.12
-5,11,-1:17.12
-3,11,-1:17.12
-5,12,-1:17.12
-4,12,-1:17.12
-6,3,0:17.12
-5,3,0:17.12
-7,4,0:17.12
-6,4,0:17.12
-4,4,0:17.12
-3,4,0:17.12
-2,4,0:17.12
-7,5,0:17.12
-2,5,0:17.12
-8,6,0:17.12
-2,6,0:17.12
-1,6,0:17.12
-9,7,0:17.12
-8,7,0:17.12
-1,7,0:17.12
-9,8,0:17.12
-8,8,0:17.12
-1,8,0:17.12
-8,9,0:17.12
-2,9,0:17.12
-1,9,0:17.12
-8,10,0:17.12
-7,10,0:17.12
-3,10,0:17.12
-2,10,0:17.12
-7,11,0:17.12
-6,11,0:17.12
-5,11,0:17.12
-4,11,0:17.12
-3,11,0:17.12
-6,4,1:17.12
-5,4,1:17.12
-4,4,1:17.12
-3,4,1:17.12
-2,4,1:17.12
-7,5,1:17.12
-2,5,1:17.12
-8,6,1:17.12
-7,6,1:17.12
-2,6,1:17.12
-8,7,1:17.12
-1,7,1:17.12
-8,8,1:17.12
-1,8,1:17.12
-8,9,1:17.12
-7,9,1:17.12
-2,9,1:17.12
-7,10,1:17.12
-6,10,1:17.12
-3,10,1:17.12
-6,11,1:17.12
-5,11,1:17.12
-4,11,1:17.12
-3,11,1:17.12
-6,4,2:17.12
-5,4,2:17.12
-4,4,2:17.12
-3,4,2:17.12
-2,4,2:17.12
-7,5,2:17.12
-2,5,2:17.12
-8,6,2:17.12
-7,6,2:17.12
-2,6,2:17.12
-8,7,2:17.12
-2,7,2:17.12
-1,7,2:17.12
-8,8,2:17.12
-2,8,2:17.12
-1,8,2:17.12
-7,9,2:17.12
-3,9,2:17.12
-2,9,2:17.12
-7,10,2:17.12
-6,10,2:17.12
-5,10,2:17.12
-4,10,2:17.12
-3,10,2:17.12
-4,11,2:17.12
-6,4,3:17.12
-5,4,3:17.12
-4,4,3:17.12
-3,4,3:17.12
-7,5,3:17.12
-6,5,3:17.12
-2,5,3:17.12
-7,6,3:17.12
-2,6,3:17.12
-8,7,3:17.12
-2,7,3:17.12
-8,8,3:17.12
-2,8,3:17.12
-7,9,3:17.12
-3,9,3:17.12
-2,9,3:17.12
-7,10,3:17.12
-6,10,3:17.12
-5,10,3:17.12
-4,10,3:17.12
-3,10,3:17.12
-6,4,4:17.12
-5,4,4:17.12
-4,4,4:17.12
-7,5,4:17.12
-6,5,4:17.12
-4,5,4:17.12
-3,5,4:17.12
-2,5,4:17.12
-7,6,4:17.12
-2,6,4:17.12
-8,7,4:17.12
-7,7,4:17.12
-2,7,4:17.12
-8,8,4:17.12
-7,8,4:17.12
-2,8,4:17.12
-7,9,4:17.12
-3,9,4:17.12
-2,9,4:17.12
-7,10,4:17.12
-6,10,4:17.12
-5,10,4:17.12
-4,10,4:17.12
-3,10,4:17.12
-5,4,5:17.12
-6,5,5:17.12
-5,5,5:17.12
-4,5,5:17.12
-3,5,5:17.12
-7,6,5:17.12
-3,6,5:17.12
-2,6,5:17.12
-8,7,5:17.12
-7,7,5:17.12
-2,7,5:17.12
-8,8,5:17.12
-7,8,5:17.12
-2,8,5:17.12
-7,9,5:17.12
-3,9,5:17.12
-2,9,5:17.12
-7,10,5:17.12
-6,10,5:17.12
-5,10,5:17.12
-4,10,5:17.12
-3,10,5:17.12
-6,5,6:17.12
-5,5,6:17.12
-4,5,6:17.12
-3,5,6:17.12
-7,6,6:17.12
-6,6,6:17.12
-3,6,6:17.12
-8,7,6:17.12
-7,7,6:17.12
-2,7,6:17.12
-8,8,6:17.12
-7,8,6:17.12
-2,8,6:17.12
-7,9,6:17.12
-3,9,6:17.12
-7,10,6:17.12
-6,10,6:17.12
-5,10,6:17.12
-4,10,6:17.12
-3,10,6:17.12
-6,5,7:17.12
-5,5,7:17.12
-4,5,7:17.12
-3,5,7:17.12
-7,6,7:17.12
-6,6,7:17.12
-3,6,7:17.12
-7,7,7:17.12
-3,7,7:17.12
-2,7,7:18.12
-8,8,7:17.12
-7,8,7:17.12
-2,8,7:17.12
-7,9,7:17.12
-3,9,7:17.12
-7,10,7:17.12
-6,10,7:17.12
-5,10,7:17.12
-4,10,7:17.12
-6,5,8:17.12
-5,5,8:17.12
-4,5,8:17.12
-3,5,8:17.12
-6,6,8:17.12
-3,6,8:17.12
-7,7,8:17.12
-3,7,8:17.12
-9,8,8:17.12
-8,8,8:17.12
-7,8,8:17.12
-3,8,8:17.12
-8,9,8:17.12
-7,9,8:17.12
-3,9,8:17.12
-7,10,8:17.12
-6,10,8:17.12
-5,10,8:17.12
-4,10,8:17.12
-22,-3,9:18.4
-4,5,9:17.12
-6,6,9:17.12
-5,6,9:17.12
-4,6,9:17.12
-3,6,9:17.12
-7,7,9:17.12
-6,7,9:17.12
-3,7,9:17.12
-10,8,9:17.12
-9,8,9:17.12
-8,8,9:17.12
-7,8,9:17.12
-3,8,9:17.12
-10,9,9:17.12
-9,9,9:17.12
-8,9,9:17.12
-7,9,9:17.12
-3,9,9:17.12
-8,10,9:17.12
-7,10,9:17.12
-6,10,9:17.12
-5,10,9:17.12
-4,10,9:17.12
-25,-5,10:18.4
-24,-4,10:18.4
-23,-4,10:18.4
-22,-3,10:18.4
-21,-3,10:18.4
-21,-2,10:18.4
-20,-2,10:18.4
-19,-1,10:18.4
-18,-1,10:18.4
-17,0,10:18.4
-16,1,10:18.4
-15,1,10:18.4
12,1,10:18.4
-14,2,10:18.4
-13,2,10:18.4
8,2,10:18.4
9,2,10:18.4
6,3,10:18.12
7,3,10:18.12
3,4,10:18.12
4,4,10:18.12
5,4,10:18.12
-5,5,10:17.12
-4,5,10:17.12
-3,5,10:17.12
-6,6,10:17.12
-5,6,10:17.12
-4,6,10:17.12
-9,7,10:17.12
-6,7,10:17.12
-4,7,10:17.12
-3,7,10:17.12
-11,8,10:17.12
-10,8,10:17.12
-9,8,10:17.12
-8,8,10:17.12
-7,8,10:17.12
-6,8,10:17.12
-4,8,10:17.12
-3,8,10:17.12
-11,9,10:17.12
-10,9,10:17.12
-6,9,10:17.12
-4,9,10:17.12
-3,9,10:17.12
-9,10,10:17.12
-8,10,10:17.12
-7,10,10:17.12
-6,10,10:17.12
-5,10,10:17.12
-4,10,10:17.12
-25,-5,11:18.4
-24,-4,11:18.4
-23,-4,11:18.4
-22,-3,11:18.4
-20,-2,11:18.4
-18,-1,11:18.4
-17,0,11:18.4
-16,0,11:18.4
13,0,11:18.4
-16,1,11:18.4
-15,1,11:18.4
11,1,11:18.4
-13,2,11:18.4
10,2,11:18.4
-13,3,11:18.12
-12,3,11:18.12
6,3,11:18.4
7,3,11:18.4
-11,4,11:18.12
-10,4,11:18.12
-5,4,11:17.12
-4,4,11:17.12
-3,4,11:17.12
3,4,11:18.12
5,4,11:18.12
-10,5,11:18.12
-9,5,11:18.12
-5,5,11:17.12
-4,5,11:17.12
-3,5,11:17.12
0,5,11:18.12
1,5,11:18.12
2,5,11:18.12
3,5,11:18.12
-8,6,11:18.12
-7,6,11:18.12
-5,6,11:17.12
-4,6,11:17.12
-2,6,11:18.12
-1,6,11:18.12
0,6,11:18.12
-10,7,11:17.12
-7,7,11:18.12
-6,7,11:18.12
-5,7,11:17.12
-4,7,11:18.12
-3,7,11:18.12
-12,8,11:17.12
-11,8,11:17.12
-10,8,11:17.12
-9,8,11:17.12
-8,8,11:17.12
-7,8,11:17.12
-6,8,11:17.12
-5,8,11:17.12
-4,8,11:17.12
-3,8,11:17.12
-12,9,11:17.12
-11,9,11:17.12
-8,9,11:17.12
-7,9,11:17.12
-6,9,11:17.12
-5,9,11:17.12
-4,9,11:17.12
-3,9,11:17.12
-11,10,11:17.12
-10,10,11:17.12
-9,10,11:17.12
-8,10,11:17.12
-6,10,11:18.12
-5,10,11:17.12
-4,10,11:17.12
-3,10,11:17.12
-6,11,11:18.12
-6,12,11:18.12
-6,13,11:18.12
-6,14,11:18.12
-7,15,11:18.12
-7,16,11:18.4
-7,17,11:18.4
-7,18,11:18.4
-7,19,11:18.4
-7,20,11:18.4
-8,21,11:18.4
-8,22,11:18.4
-8,23,11:18.4
-8,24,11:18.4
-8,25,11:18.4
-9,26,11:18.4
-9,27,11:18.4
-25,-5,12:18.4
-24,-5,12:18.4
-24,-4,12:18.4
-22,-3,12:18.4
-21,-3,12:18.4
-20,-2,12:18.4
-19,-1,12:18.4
-18,-1,12:18.4
-17,0,12:18.4
13,0,12:18.4
14,0,12:18.4
15,0,12:18.4
-16,1,12:18.4
-15,1,12:18.4
11,1,12:18.4
12,1,12:18.4
-14,2,12:18.4
-13,2,12:18.4
9,2,12:18.4
10,2,12:18.4
-13,3,12:18.12
-12,3,12:18.12
-4,3,12:17.12
-3,3,12:17.12
6,3,12:18.4
7,3,12:18.4
-11,4,12:18.12
-10,4,12:18.12
-5,4,12:17.12
-4,4,12:17.12
-3,4,12:17.12
4,4,12:18.12
5,4,12:18.12
-10,5,12:18.12
-9,5,12:18.12
-5,5,12:17.12
-4,5,12:17.12
-3,5,12:17.12
0,5,12:18.12
1,5,12:18.12
2,5,12:18.12
3,5,12:18.12
-8,6,12:18.12
-7,6,12:18.12
-5,6,12:17.12
-4,6,12:17.12
-2,6,12:18.12
-1,6,12:18.12
0,6,12:18.12
-11,7,12:17.12
-10,7,12:17.12
-7,7,12:18.12
-6,7,12:18.12
-5,7,12:17.12
-4,7,12:18.12
-3,7,12:18.12
-13,8,12:17.12
-12,8,12:17.12
-11,8,12:17.12
-10,8,12:17.12
-9,8,12:17.12
-8,8,12:17.12
-7,8,12:17.12
-5,8,12:18.12
-13,9,12:17.12
-12,9,12:17.12
-10,9,12:17.12
-9,9,12:17.12
-8,9,12:17.12
-7,9,12:17.12
-6,9,12:17.12
-5,9,12:17.12
-4,9,12:17.12
-3,9,12:17.12
-2,9,12:17.12
-12,10,12:17.12
-11,10,12:17.12
-10,10,12:17.12
-9,10,12:17.12
-6,10,12:18.12
-4,10,12:17.12
-3,10,12:17.12
-6,11,12:18.12
-6,12,12:18.12
-6,13,12:18.12
-6,14,12:18.12
-7,15,12:18.12
-7,16,12:18.4
-7,17,12:18.4
-7,18,12:18.4
-7,19,12:18.4
-8,21,12:18.4
-8,22,12:18.4
-8,25,12:18.4
-9,26,12:18.4
-9,28,12:18.4
-9,29,12:18.4
-9,30,12:18.4
1,-6,13:18.4
-20,-2,13:18.4
-19,-1,13:18.4
-18,-1,13:18.4
-17,0,13:18.4
-16,0,13:18.4
14,0,13:18.4
-16,1,13:18.4
11,1,13:18.4
12,1,13:18.4
-14,2,13:18.4
-13,2,13:18.4
-3,2,13:17.12
8,2,13:18.4
9,2,13:18.4
10,2,13:18.4
-13,3,13:18.12
-12,3,13:18.12
-4,3,13:17.12
-3,3,13:17.12
-2,3,13:17.12
5,3,13:18.4
6,3,13:18.4
7,3,13:18.4
-15,4,13:18.12
-11,4,13:18.12
-10,4,13:18.12
-4,4,13:17.12
-3,4,13:17.12
3,4,13:18.12
4,4,13:18.4
5,4,13:18.4
-10,5,13:18.12
-9,5,13:18.12
-4,5,13:17.12
-3,5,13:17.12
0,5,13:18.12
1,5,13:18.12
-4,6,13:17.12
-2,6,13:18.12
-1,6,13:18.12
0,6,13:18.12
-11,7,13:17.12
-6,7,13:18.12
-5,7,13:18.12
-4,7,13:18.12
-14,8,13:17.12
-13,8,13:17.12
-12,8,13:17.12
-11,8,13:17.12
-10,8,13:17.12
-5,8,13:18.12
-13,9,13:17.12
-12,9,13:17.12
-11,9,13:17.12
-10,9,13:17.12
-5,9,13:17.12
-4,9,13:17.12
-3,9,13:17.12
-2,9,13:17.12
-13,10,13:17.12
-12,10,13:17.12
-11,10,13:17.12
-4,10,13:17.12
-3,10,13:17.12
-2,10,13:17.12
-6,11,13:18.12
-3,11,13:17.12
9,11,13:18.4
-6,12,13:18.12
-6,13,13:18.12
-6,14,13:18.12
-9,16,13:18.4
-7,16,13:18.4
-7,17,13:18.4
-7,18,13:18.4
-7,19,13:18.4
-7,20,13:18.4
-8,21,13:18.4
-8,22,13:18.4
-8,23,13:18.4
-8,24,13:18.4
-8,25,13:18.4
-9,26,13:18.4
-9,27,13:18.4
-9,28,13:18.4
-9,29,13:18.4
-9,30,13:18.4
-10,31,13:18.4
-11,-18,14:18.4
-9,-18,14:18.4
-8,-18,14:18.4
-7,-18,14:18.4
-6,-18,14:18.4
-5,-18,14:18.4
-4,-18,14:18.4
-3,-18,14:18.4
-2,-18,14:18.4
-1,-18,14:18.4
0,-18,14:18.4
1,-18,14:18.4
2,-18,14:18.4
3,-18,14:18.4
4,-18,14:18.4
5,-18,14:18.4
6,-18,14:18.4
7,-18,14:18.4
-12,-17,14:18.4
-9,-17,14:18.4
-7,-17,14:18.4
-6,-17,14:18.4
-5,-17,14:18.4
8,-17,14:18.4
9,-16,14:18.4
-18,-15,14:18.4
-19,-14,14:18.4
10,-14,14:18.4
11,-14,14:18.4
-20,-13,14:18.4
11,-13,14:18.4
12,-13,14:18.4
-21,-12,14:18.4
12,-12,14:18.4
13,-12,14:18.4
-22,-11,14:18.4
-21,-11,14:18.4
-22,-10,14:18.4
3,-9,14:18.4
-24,-8,14:18.4
2,-8,14:18.4
-25,-7,14:18.4
-26,-6,14:18.4
1,-6,14:18.4
-27,-5,14:18.4
-24,-5,14:18.4
1,-5,14:18.4
-24,-4,14:18.4
-23,-4,14:18.4
-22,-3,14:18.4
-21,-3,14:18.4
-29,-2,14:18.4
-20,-2,14:18.4
-19,-2,14:18.4
-30,-1,14:18.4
-19,-1,14:18.4
-18,-1,14:18.4
-17,0,14:18.4
-16,0,14:18.4
14,0,14:18.4
-30,1,14:18.4
-16,1,14:18.4
-15,1,14:18.4
11,1,14:18.4
12,1,14:18.4
21,1,14:18.4
-14,2,14:18.4
-13,2,14:18.4
-3,2,14:17.12
-2,2,14:17.12
8,2,14:18.4
9,2,14:18.4
10,2,14:18.4
21,2,14:18.4
-19,3,14:18.4
-18,3,14:18.4
-13,3,14:18.12
-12,3,14:18.12
-3,3,14:17.12
-2,3,14:17.12
6,3,14:18.4
7,3,14:18.4
21,3,14:18.4
-30,4,14:18.4
-18,4,14:18.12
-17,4,14:18.12
-16,4,14:18.12
-15,4,14:18.12
-11,4,14:18.12
-10,4,14:18.12
-3,4,14:17.12
3,4,14:18.12
4,4,14:18.4
21,4,14:18.4
-30,5,14:18.4
-14,5,14:18.12
-9,5,14:18.12
0,5,14:18.12
1,5,14:18.12
2,5,14:18.12
21,5,14:18.4
-30,6,14:18.4
-8,6,14:18.12
-7,6,14:18.12
-2,6,14:18.12
0,6,14:18.12
-30,7,14:18.4
-6,7,14:18.12
-5,7,14:18.12
-4,7,14:18.12
-3,7,14:18.12
21,7,14:18.4
-30,8,14:18.4
-14,8,14:17.12
-13,8,14:17.12
-12,8,14:17.12
-5,8,14:18.12
21,8,14:18.4
-30,9,14:18.4
-14,9,14:17.12
-13,9,14:17.12
-5,9,14:18.12
-4,9,14:17.12
-3,9,14:17.12
-2,9,14:17.12
-30,10,14:18.4
-13,10,14:17.12
-6,10,14:18.12
-4,10,14:17.12
-3,10,14:17.12
-2,10,14:17.12
-1,10,14:17.12
-30,11,14:18.4
-6,11,14:18.12
-3,11,14:17.12
-2,11,14:17.12
7,11,14:18.4
8,11,14:18.4
9,11,14:18.4
10,11,14:18.4
-30,12,14:18.4
11,12,14:18.4
12,12,14:18.4
-30,13,14:18.4
-6,13,14:18.12
-30,14,14:18.4
-6,14,14:18.12
-8,15,14:18.4
-7,15,14:18.12
-6,15,14:18.12
-9,16,14:18.4
-7,16,14:18.4
-10,17,14:18.4
-9,17,14:18.4
-7,17,14:18.4
-10,18,14:18.4
-7,18,14:18.4
-11,19,14:18.4
-27,20,14:18.4
-11,20,14:18.4
-26,21,14:18.4
-8,21,14:18.4
-25,22,14:18.4
-8,22,14:18.4
-25,23,14:18.4
-24,23,14:18.4
-8,23,14:18.4
-23,24,14:18.4
-8,24,14:18.4
12,24,14:18.4
-23,25,14:18.4
-22,25,14:18.4
-8,25,14:18.4
11,25,14:18.4
12,25,14:18.4
-22,26,14:18.4
-21,26,14:18.4
-21,27,14:18.4
8,28,14:18.4
9,28,14:18.4
-19,29,14:18.4
-18,30,14:18.4
-17,30,14:18.4
-15,30,14:18.4
-14,30,14:18.4
-12,30,14:18.4
-11,30,14:18.4
-10,30,14:18.4
-9,30,14:18.4
-8,30,14:18.4
-6,30,14:18.4
-5,30,14:18.4
-11,31,14:18.4
-10,31,14:18.4
-9,31,14:18.4
-6,31,14:18.4
-5,31,14:18.4
-4,31,14:18.4
-3,31,14:18.4
-2,31,14:18.4
-1,31,14:18.4
0,31,14:18.4
4,-18,15:18.4
5,-18,15:18.4
6,-18,15:18.4
-14,-17,15:18.4
-13,-17,15:18.4
-12,-17,15:18.4
-11,-17,15:18.4
-10,-17,15:18.4
-9,-17,15:18.4
-8,-17,15:18.4
-7,-17,15:18.4
-6,-17,15:18.4
-5,-17,15:18.4
-4,-17,15:18.4
-3,-17,15:18.4
-2,-17,15:18.4
-1,-17,15:18.4
0,-17,15:18.4
1,-17,15:18.4
2,-17,15:18.4
3,-17,15:18.4
4,-17,15:18.4
5,-17,15:18.4
6,-17,15:18.4
7,-17,15:18.4
8,-17,15:18.4
-16,-16,15:18.4
-15,-16,15:18.4
-14,-16,15:18.4
-13,-16,15:18.4
-12,-16,15:18.4
-11,-16,15:18.4
-10,-16,15:18.4
-9,-16,15:18.4
8,-16,15:18.4
9,-16,15:18.4
-17,-15,15:18.4
-16,-15,15:18.4
-15,-15,15:18.4
-14,-15,15:18.4
-13,-15,15:18.4
-12,-15,15:18.4
-11,-15,15:18.4
9,-15,15:18.4
-18,-14,15:18.4
-17,-14,15:18.4
-16,-14,15:18.4
-15,-14,15:18.4
-14,-14,15:18.4
-13,-14,15:18.4
-12,-14,15:18.4
10,-14,15:18.4
-19,-13,15:18.4
-18,-13,15:18.4
-17,-13,15:18.4
-16,-13,15:18.4
-15,-13,15:18.4
-14,-13,15:18.4
11,-13,15:18.4
-20,-12,15:18.4
-19,-12,15:18.4
-18,-12,15:18.4
-17,-12,15:18.4
4,-12,15:18.4
11,-12,15:18.4
12,-12,15:18.4
-21,-11,15:18.4
-20,-11,15:18.4
-19,-11,15:18.4
4,-11,15:18.4
12,-11,15:18.4
13,-11,15:18.4
-22,-10,15:18.4
-21,-10,15:18.4
3,-10,15:18.4
-23,-9,15:18.4
-22,-9,15:18.4
3,-9,15:18.4
-24,-8,15:18.4
-23,-8,15:18.4
2,-8,15:18.4
-25,-7,15:18.4
-24,-7,15:18.4
-26,-6,15:18.4
-25,-6,15:18.4
1,-6,15:18.4
-26,-5,15:18.4
-25,-5,15:18.4
-24,-5,15:18.4
1,-5,15:18.4
-28,-4,15:18.4
-24,-4,15:18.4
-23,-4,15:18.4
0,-4,15:18.12
1,-4,15:18.12
-28,-3,15:18.4
-27,-3,15:18.4
-22,-3,15:18.4
-21,-3,15:18.4
0,-3,15:18.12
17,-3,15:18.4
18,-3,15:18.4
19,-3,15:18.4
-29,-2,15:18.4
-28,-2,15:18.4
-21,-2,15:18.4
-20,-2,15:18.4
0,-2,15:18.12
17,-2,15:18.4
18,-2,15:18.4
19,-2,15:18.4
-30,-1,15:18.4
-29,-1,15:18.4
-19,-1,15:18.4
-18,-1,15:18.4
17,-1,15:18.4
18,-1,15:18.4
19,-1,15:18.4
20,-1,15:18.4
-30,0,15:18.4
-17,0,15:18.4
-16,0,15:18.4
13,0,15:18.4
14,0,15:18.4
15,0,15:18.4
17,0,15:18.4
18,0,15:18.4
19,0,15:18.4
20,0,15:18.4
-30,1,15:18.4
-16,1,15:18.4
-15,1,15:18.4
-3,1,15:17.12
-2,1,15:17.12
10,1,15:18.4
11,1,15:18.4
12,1,15:18.4
13,1,15:18.4
18,1,15:18.4
19,1,15:18.4
20,1,15:18.4
-30,2,15:18.4
-23,2,15:18.4
-22,2,15:18.4
-21,2,15:18.4
-14,2,15:18.4
-13,2,15:18.4
-3,2,15:17.12
-2,2,15:17.12
8,2,15:18.4
9,2,15:18.4
10,2,15:18.4
19,2,15:18.4
20,2,15:18.4
-30,3,15:18.4
-20,3,15:18.4
-19,3,15:18.4
-18,3,15:18.4
-13,3,15:18.12
-12,3,15:18.12
-3,3,15:17.12
-2,3,15:17.12
6,3,15:18.4
7,3,15:18.4
8,3,15:18.4
19,3,15:18.4
20,3,15:18.4
-30,4,15:18.4
-29,4,15:18.4
-17,4,15:18.12
-16,4,15:18.12
-15,4,15:18.12
-11,4,15:18.12
-10,4,15:18.12
3,4,15:18.12
4,4,15:18.4
5,4,15:18.4
20,4,15:18.4
21,4,15:18.4
-30,5,15:18.4
-29,5,15:18.4
-14,5,15:18.12
-13,5,15:18.12
-12,5,15:18.12
-10,5,15:18.12
-9,5,15:18.12
0,5,15:18.12
1,5,15:18.12
2,5,15:18.12
20,5,15:18.4
21,5,15:18.4
-30,6,15:18.4
-29,6,15:18.4
-2,6,15:18.12
-1,6,15:18.12
0,6,15:18.12
20,6,15:18.4
21,6,15:18.4
-30,7,15:18.4
-29,7,15:18.4
-7,7,15:18.12
-6,7,15:18.12
-5,7,15:18.12
-4,7,15:18.12
20,7,15:18.4
21,7,15:18.4
-29,8,15:18.4
-15,8,15:17.12
-14,8,15:17.12
-13,8,15:17.12
-5,8,15:18.12
20,8,15:18.4
21,8,15:18.4
-29,9,15:18.4
-15,9,15:17.12
-14,9,15:17.12
-5,9,15:18.12
21,9,15:18.4
-29,10,15:18.4
-14,10,15:17.12
-4,10,15:17.12
-3,10,15:17.12
-2,10,15:17.12
-1,10,15:17.12
5,10,15:18.4
6,10,15:18.4
7,10,15:18.4
21,10,15:18.4
-29,11,15:18.4
-6,11,15:18.12
-3,11,15:17.12
-2,11,15:17.12
-1,11,15:17.12
7,11,15:18.4
8,11,15:18.4
9,11,15:18.4
10,11,15:18.4
21,11,15:18.4
-29,12,15:18.4
-28,12,15:18.4
-6,12,15:18.12
11,12,15:18.4
12,12,15:18.4
13,12,15:18.4
14,12,15:18.4
21,12,15:18.4
-29,13,15:18.4
-27,13,15:18.4
-6,13,15:18.12
15,13,15:18.4
21,13,15:18.4
-29,14,15:18.4
-28,14,15:18.4
-27,14,15:18.4
-26,14,15:18.4
-8,14,15:18.12
-6,14,15:18.12
21,14,15:18.4
-29,15,15:18.4
-28,15,15:18.4
-27,15,15:18.4
-26,15,15:18.4
-9,15,15:18.4
-8,15,15:18.4
-7,15,15:18.12
20,15,15:18.4
21,15,15:18.4
-29,16,15:18.4
-28,16,15:18.4
-27,16,15:18.4
-26,16,15:18.4
-25,16,15:18.4
-9,16,15:18.4
-7,16,15:18.4
19,16,15:18.4
20,16,15:18.4
-28,17,15:18.4
-27,17,15:18.4
-26,17,15:18.4
-25,17,15:18.4
-10,17,15:18.4
-7,17,15:18.4
18,17,15:18.4
19,17,15:18.4
-28,18,15:18.4
-27,18,15:18.4
-26,18,15:18.4
-25,18,15:18.4
-10,18,15:18.4
-7,18,15:18.4
17,18,15:18.4
-27,19,15:18.4
-26,19,15:18.4
-11,19,15:18.4
-7,19,15:18.4
16,19,15:18.4
17,19,15:18.4
-26,20,15:18.4
-25,20,15:18.4
-12,20,15:18.4
-11,20,15:18.4
-7,20,15:18.4
15,20,15:18.4
16,20,15:18.4
-26,21,15:18.4
-25,21,15:18.4
-12,21,15:18.4
-8,21,15:18.4
14,21,15:18.4
15,21,15:18.4
-25,22,15:18.4
-24,22,15:18.4
-13,22,15:18.4
-8,22,15:18.4
13,22,15:18.4
14,22,15:18.4
-24,23,15:18.4
-23,23,15:18.4
-13,23,15:18.4
-8,23,15:18.4
12,23,15:18.4
13,23,15:18.4
-23,24,15:18.4
-22,24,15:18.4
-14,24,15:18.4
-8,24,15:18.4
10,24,15:18.4
11,24,15:18.4
12,24,15:18.4
-22,25,15:18.4
-21,25,15:18.4
-8,25,15:18.4
8,25,15:18.4
9,25,15:18.4
10,25,15:18.4
11,25,15:18.4
-21,26,15:18.4
-20,26,15:18.4
-9,26,15:18.4
6,26,15:18.4
7,26,15:18.4
8,26,15:18.4
9,26,15:18.4
10,26,15:18.4
-20,27,15:18.4
-19,27,15:18.4
-9,27,15:18.4
3,27,15:18.4
4,27,15:18.4
5,27,15:18.4
6,27,15:18.4
7,27,15:18.4
8,27,15:18.4
9,27,15:18.4
-19,28,15:18.4
-9,28,15:18.4
1,28,15:18.4
2,28,15:18.4
3,28,15:18.4
4,28,15:18.4
5,28,15:18.4
6,28,15:18.4
7,28,15:18.4
8,28,15:18.4
-18,29,15:18.4
-17,29,15:18.4
-9,29,15:18.4
-2,29,15:18.4
-1,29,15:18.4
0,29,15:18.4
1,29,15:18.4
2,29,15:18.4
3,29,15:18.4
4,29,15:18.4
5,29,15:18.4
6,29,15:18.4
-17,30,15:18.4
-16,30,15:18.4
-15,30,15:18.4
-14,30,15:18.4
-13,30,15:18.4
-12,30,15:18.4
-11,30,15:18.4
-10,30,15:18.4
-9,30,15:18.4
-8,30,15:18.4
-7,30,15:18.4
-6,30,15:18.4
-5,30,15:18.4
-4,30,15:18.4
-2,30,15:18.4
-1,30,15:18.4
0,30,15:18.4
1,30,15:18.4
2,30,15:18.4
3,30,15:18.4
4,30,15:18.4
-7,-17,16:18.4
-6,-17,16:18.4
-4,-17,16:18.4
-3,-17,16:18.4
-2,-17,16:18.4
-1,-17,16:18.4
0,-17,16:18.4
1,-17,16:18.4
2,-17,16:18.4
3,-17,16:18.4
4,-17,16:18.4
5,-17,16:18.4
6,-17,16:18.4
7,-17,16:18.4
-11,-16,16:18.4
-10,-16,16:18.4
-9,-16,16:18.4
-8,-16,16:18.4
-7,-16,16:18.4
-6,-16,16:18.4
-5,-16,16:18.4
-4,-16,16:18.4
-3,-16,16:18.4
-2,-16,16:18.4
-1,-16,16:18.4
0,-16,16:18.4
1,-16,16:18.4
2,-16,16:18.4
3,-16,16:18.4
4,-16,16:18.4
7,-16,16:18.4
8,-16,16:18.4
-14,-15,16:18.4
-13,-15,16:18.4
-12,-15,16:18.4
-11,-15,16:18.4
-10,-15,16:18.4
-9,-15,16:18.4
-8,-15,16:18.4
-7,-15,16:18.4
-6,-15,16:18.4
-5,-15,16:18.4
-4,-15,16:18.4
-3,-15,16:18.4
-2,-15,16:18.4
-1,-15,16:18.4
0,-15,16:18.4
1,-15,16:18.4
2,-15,16:18.4
3,-15,16:18.4
7,-15,16:18.4
8,-15,16:18.4
9,-15,16:18.4
-16,-14,16:18.4
-15,-14,16:18.4
-13,-14,16:18.4
-12,-14,16:18.4
-11,-14,16:18.4
-10,-14,16:18.4
-9,-14,16:18.4
-8,-14,16:18.4
-7,-14,16:18.4
-6,-14,16:18.4
-5,-14,16:18.4
-4,-14,16:18.4
-3,-14,16:18.4
-2,-14,16:18.4
-1,-14,16:18.4
0,-14,16:18.4
5,-14,16:18.4
7,-14,16:18.4
8,-14,16:18.4
9,-14,16:18.4
10,-14,16:18.4
-17,-13,16:18.4
-16,-13,16:18.4
-15,-13,16:18.4
-14,-13,16:18.4
-13,-13,16:18.4
-12,-13,16:18.4
-11,-13,16:18.4
-10,-13,16:18.4
-9,-13,16:18.4
-8,-13,16:18.4
-7,-13,16:18.4
-6,-13,16:18.4
-5,-13,16:18.4
-4,-13,16:18.4
-2,-13,16:18.4
-1,-13,16:18.4
4,-13,16:18.4
5,-13,16:18.4
7,-13,16:18.4
8,-13,16:18.4
9,-13,16:18.4
10,-13,16:18.4
-18,-12,16:18.4
-17,-12,16:18.4
-16,-12,16:18.4
-15,-12,16:18.4
-14,-12,16:18.4
-13,-12,16:18.4
-12,-12,16:18.4
-11,-12,16:18.4
-10,-12,16:18.4
-9,-12,16:18.4
-8,-12,16:18.4
-7,-12,16:18.4
-6,-12,16:18.4
-5,-12,16:18.4
-4,-12,16:18.4
-3,-12,16:18.4
4,-12,16:18.4
8,-12,16:18.4
9,-12,16:18.4
10,-12,16:18.4
11,-12,16:18.4
-20,-11,16:18.4
-19,-11,16:18.4
-18,-11,16:18.4
-17,-11,16:18.4
-16,-11,16:18.4
-15,-11,16:18.4
-14,-11,16:18.4
-13,-11,16:18.4
-12,-11,16:18.4
-11,-11,16:18.4
-10,-11,16:18.4
-9,-11,16:18.4
-8,-11,16:18.4
-7,-11,16:18.4
-6,-11,16:18.4
-5,-11,16:18.4
4,-11,16:18.4
8,-11,16:18.4
9,-11,16:18.4
10,-11,16:18.4
11,-11,16:18.4
12,-11,16:18.4
-21,-10,16:18.4
-20,-10,16:18.4
-19,-10,16:18.4
-18,-10,16:18.4
-17,-10,16:18.4
-16,-10,16:18.4
-15,-10,16:18.4
-14,-10,16:18.4
-13,-10,16:18.4
-12,-10,16:18.4
-11,-10,16:18.4
-10,-10,16:18.4
-9,-10,16:18.4
-8,-10,16:18.4
-7,-10,16:18.4
-6,-10,16:18.4
3,-10,16:18.4
8,-10,16:18.4
9,-10,16:18.4
10,-10,16:18.4
11,-10,16:18.4
12,-10,16:18.4
13,-10,16:18.4
-22,-9,16:18.4
-21,-9,16:18.4
-20,-9,16:18.4
-19,-9,16:18.4
-18,-9,16:18.4
-17,-9,16:18.4
-16,-9,16:18.4
-15,-9,16:18.4
-14,-9,16:18.4
-13,-9,16:18.4
-12,-9,16:18.4
-11,-9,16:18.4
-10,-9,16:18.4
-9,-9,16:18.4
-8,-9,16:18.4
3,-9,16:18.4
8,-9,16:18.4
9,-9,16:18.4
10,-9,16:18.4
11,-9,16:18.4
12,-9,16:18.4
-23,-8,16:18.4
-22,-8,16:18.4
-21,-8,16:18.4
-20,-8,16:18.4
-19,-8,16:18.4
-18,-8,16:18.4
-17,-8,16:18.4
-16,-8,16:18.4
-15,-8,16:18.4
-14,-8,16:18.4
-13,-8,16:18.4
-12,-8,16:18.4
-11,-8,16:18.4
-10,-8,16:18.4
2,-8,16:18.4
9,-8,16:18.4
10,-8,16:18.4
11,-8,16:18.4
12,-8,16:18.4
-24,-7,16:18.4
-23,-7,16:18.4
-22,-7,16:18.4
-21,-7,16:18.4
-20,-7,16:18.4
-19,-7,16:18.4
-18,-7,16:18.4
-17,-7,16:18.4
-16,-7,16:18.4
-15,-7,16:18.4
-14,-7,16:18.4
-13,-7,16:18.4
-12,-7,16:18.4
9,-7,16:18.4
10,-7,16:18.4
-25,-6,16:18.4
-24,-6,16:18.4
-23,-6,16:18.4
-22,-6,16:18.4
-21,-6,16:18.4
-20,-6,16:18.4
-19,-6,16:18.4
-18,-6,16:18.4
-17,-6,16:18.4
-16,-6,16:18.4
-15,-6,16:18.4
1,-6,16:18.4
2,-6,16:18.4
9,-6,16:18.4
10,-6,16:18.4
-26,-5,16:18.4
-25,-5,16:18.4
-24,-5,16:18.4
-23,-5,16:18.4
-22,-5,16:18.4
-21,-5,16:18.4
-20,-5,16:18.4
-19,-5,16:18.4
-18,-5,16:18.4
-17,-5,16:18.4
1,-5,16:18.4
11,-5,16:18.4
12,-5,16:18.4
-26,-4,16:18.4
-25,-4,16:18.4
-24,-4,16:18.4
-23,-4,16:18.4
-22,-4,16:18.4
-21,-4,16:18.4
-20,-4,16:18.4
0,-4,16:18.12
1,-4,16:18.12
9,-4,16:18.4
10,-4,16:18.4
11,-4,16:18.4
12,-4,16:18.4
13,-4,16:18.4
14,-4,16:18.4
15,-4,16:18.4
16,-4,16:18.4
-27,-3,16:18.4
-26,-3,16:18.4
-25,-3,16:18.4
-24,-3,16:18.4
-23,-3,16:18.4
-22,-3,16:18.4
-21,-3,16:18.4
0,-3,16:18.12
10,-3,16:18.4
11,-3,16:18.4
12,-3,16:18.4
13,-3,16:18.4
14,-3,16:18.4
15,-3,16:18.4
16,-3,16:18.4
17,-3,16:18.4
-28,-2,16:18.4
-27,-2,16:18.4
-26,-2,16:18.4
-25,-2,16:18.4
-24,-2,16:18.4
-20,-2,16:18.4
-19,-2,16:18.4
-1,-2,16:18.12
0,-2,16:18.12
10,-2,16:18.4
11,-2,16:18.4
12,-2,16:18.4
13,-2,16:18.4
14,-2,16:18.4
15,-2,16:18.4
16,-2,16:18.4
17,-2,16:18.4
-29,-1,16:18.4
-28,-1,16:18.4
-19,-1,16:18.4
-18,-1,16:18.4
-1,-1,16:18.12
10,-1,16:18.4
11,-1,16:18.4
12,-1,16:18.4
13,-1,16:18.4
14,-1,16:18.4
15,-1,16:18.4
16,-1,16:18.4
17,-1,16:18.4
18,-1,16:18.4
-29,0,16:18.4
-17,0,16:18.4
-16,0,16:18.4
-1,0,16:18.12
10,0,16:18.4
11,0,16:18.4
12,0,16:18.4
13,0,16:18.4
14,0,16:18.4
15,0,16:18.4
16,0,16:18.4
17,0,16:18.4
18,0,16:18.4
-29,1,16:18.4
-26,1,16:18.4
-25,1,16:18.4
-24,1,16:18.4
-16,1,16:18.4
-15,1,16:18.4
-2,1,16:17.12
-1,1,16:17.12
10,1,16:18.4
11,1,16:18.4
12,1,16:18.4
13,1,16:18.4
14,1,16:18.4
15,1,16:18.4
16,1,16:18.4
17,1,16:18.4
18,1,16:18.4
19,1,16:18.4
-29,2,16:18.4
-28,2,16:18.4
-23,2,16:18.4
-22,2,16:18.4
-21,2,16:18.4
-14,2,16:18.4
-13,2,16:18.4
-2,2,16:17.12
8,2,16:18.4
9,2,16:18.4
10,2,16:18.4
11,2,16:18.4
12,2,16:18.4
13,2,16:18.4
14,2,16:18.4
15,2,16:18.4
16,2,16:18.4
17,2,16:18.4
18,2,16:18.4
19,2,16:18.4
-29,3,16:18.4
-28,3,16:18.4
-27,3,16:18.4
-20,3,16:18.4
-19,3,16:18.4
-18,3,16:18.4
-13,3,16:18.12
-12,3,16:18.12
6,3,16:18.4
7,3,16:18.4
12,3,16:18.4
13,3,16:18.4
14,3,16:18.4
15,3,16:18.4
16,3,16:18.4
17,3,16:18.4
18,3,16:18.4
19,3,16:18.4
-29,4,16:18.4
-28,4,16:18.4
-27,4,16:18.4
-26,4,16:18.4
-17,4,16:18.12
-16,4,16:18.12
-15,4,16:18.12
-14,4,16:18.12
-11,4,16:18.12
-10,4,16:18.12
3,4,16:18.12
4,4,16:18.4
5,4,16:18.4
13,4,16:18.4
14,4,16:18.4
15,4,16:18.4
16,4,16:18.4
17,4,16:18.4
18,4,16:18.4
19,4,16:18.4
20,4,16:18.4
-29,5,16:18.4
-28,5,16:18.4
-27,5,16:18.4
-26,5,16:18.4
-25,5,16:18.4
-14,5,16:18.12
-13,5,16:18.12
-12,5,16:18.12
-11,5,16:18.12
-10,5,16:18.12
0,5,16:18.12
1,5,16:18.12
2,5,16:18.12
13,5,16:18.4
14,5,16:18.4
15,5,16:18.4
16,5,16:18.4
17,5,16:18.4
18,5,16:18.4
19,5,16:18.4
20,5,16:18.4
-29,6,16:18.4
-28,6,16:18.4
-27,6,16:18.4
-26,6,16:18.4
-25,6,16:18.4
-11,6,16:18.12
-10,6,16:18.12
-8,6,16:18.12
-7,6,16:18.12
-1,6,16:18.12
0,6,16:18.12
14,6,16:18.4
15,6,16:18.4
16,6,16:18.4
17,6,16:18.4
18,6,16:18.4
19,6,16:18.4
20,6,16:18.4
-29,7,16:18.4
-28,7,16:18.4
-27,7,16:18.4
-26,7,16:18.4
-25,7,16:18.4
-24,7,16:18.4
-6,7,16:18.12
-5,7,16:18.12
-4,7,16:18.12
-3,7,16:18.12
15,7,16:18.4
16,7,16:18.4
17,7,16:18.4
18,7,16:18.4
19,7,16:18.4
20,7,16:18.4
-29,8,16:18.4
-28,8,16:18.4
-27,8,16:18.4
-26,8,16:18.4
-25,8,16:18.4
-23,8,16:18.4
-15,8,16:17.12
-14,8,16:17.12
-5,8,16:18.12
16,8,16:18.4
17,8,16:18.4
18,8,16:18.4
19,8,16:18.4
20,8,16:18.4
-28,9,16:18.4
-27,9,16:18.4
-26,9,16:18.4
-25,9,16:18.4
-24,9,16:18.4
-23,9,16:18.4
-15,9,16:17.12
-14,9,16:17.12
-5,9,16:18.12
2,9,16:18.12
3,9,16:18.12
16,9,16:18.4
17,9,16:18.4
18,9,16:18.4
19,9,16:18.4
20,9,16:18.4
-29,10,16:18.4
-28,10,16:18.4
-27,10,16:18.4
-26,10,16:18.4
-25,10,16:18.4
-24,10,16:18.4
-22,10,16:18.4
-6,10,16:18.12
-3,10,16:17.12
-2,10,16:17.12
-1,10,16:17.12
4,10,16:18.12
5,10,16:18.4
6,10,16:18.4
7,10,16:18.4
17,10,16:18.4
18,10,16:18.4
19,10,16:18.4
-28,11,16:18.4
-27,11,16:18.4
-26,11,16:18.4
-25,11,16:18.4
-24,11,16:18.4
-23,11,16:18.4
-22,11,16:18.4
-21,11,16:18.4
-2,11,16:17.12
-1,11,16:17.12
7,11,16:18.4
8,11,16:18.4
9,11,16:18.4
10,11,16:18.4
11,11,16:18.4
18,11,16:18.4
19,11,16:18.4
20,11,16:18.4
-28,12,16:18.4
-27,12,16:18.4
-26,12,16:18.4
-25,12,16:18.4
-24,12,16:18.4
-23,12,16:18.4
-22,12,16:18.4
-21,12,16:18.4
-7,12,16:18.12
11,12,16:18.4
12,12,16:18.4
13,12,16:18.4
14,12,16:18.4
19,12,16:18.4
20,12,16:18.4
21,12,16:18.4
-27,13,16:18.4
-26,13,16:18.4
-25,13,16:18.4
-24,13,16:18.4
-23,13,16:18.4
-22,13,16:18.4
-21,13,16:18.4
-20,13,16:18.12
-7,13,16:18.12
-6,13,16:18.12
15,13,16:18.4
16,13,16:18.4
17,13,16:18.4
18,13,16:18.4
20,13,16:18.4
21,13,16:18.4
-27,14,16:18.4
-26,14,16:18.4
-25,14,16:18.4
-24,14,16:18.4
-23,14,16:18.4
-22,14,16:18.4
-21,14,16:18.4
-20,14,16:18.4
-8,14,16:18.12
-6,14,16:18.12
20,14,16:18.4
21,14,16:18.4
-27,15,16:18.4
-26,15,16:18.4
-25,15,16:18.4
-24,15,16:18.4
-23,15,16:18.4
-22,15,16:18.4
-21,15,16:18.4
-20,15,16:18.4
-19,15,16:18.4
-9,15,16:18.4
-7,15,16:18.12
-6,15,16:18.12
19,15,16:18.4
20,15,16:18.4
-27,16,16:18.4
-26,16,16:18.4
-25,16,16:18.4
-24,16,16:18.4
-23,16,16:18.4
-22,16,16:18.4
-21,16,16:18.4
-20,16,16:18.4
-19,16,16:18.4
-9,16,16:18.4
-7,16,16:18.4
14,16,16:18.4
15,16,16:18.4
16,16,16:18.4
17,16,16:18.4
18,16,16:18.4
19,16,16:18.4
-26,17,16:18.4
-25,17,16:18.4
-24,17,16:18.4
-23,17,16:18.4
-22,17,16:18.4
-21,17,16:18.4
-20,17,16:18.4
-19,17,16:18.4
-10,17,16:18.4
-7,17,16:18.4
12,17,16:18.4
13,17,16:18.4
14,17,16:18.4
15,17,16:18.4
16,17,16:18.4
17,17,16:18.4
18,17,16:18.4
-26,18,16:18.4
-25,18,16:18.4
-24,18,16:18.4
-23,18,16:18.4
-22,18,16:18.4
-21,18,16:18.4
-20,18,16:18.4
-19,18,16:18.4
-11,18,16:18.4
-10,18,16:18.4
-7,18,16:18.4
10,18,16:18.4
11,18,16:18.4
12,18,16:18.4
13,18,16:18.4
14,18,16:18.4
15,18,16:18.4
16,18,16:18.4
17,18,16:18.4
-24,19,16:18.4
-23,19,16:18.4
-22,19,16:18.4
-21,19,16:18.4
-20,19,16:18.4
-19,19,16:18.4
-11,19,16:18.4
-7,19,16:18.4
7,19,16:18.4
8,19,16:18.4
9,19,16:18.4
10,19,16:18.4
11,19,16:18.4
13,19,16:18.4
14,19,16:18.4
15,19,16:18.4
16,19,16:18.4
-25,20,16:18.4
-24,20,16:18.4
-23,20,16:18.4
-22,20,16:18.4
-21,20,16:18.4
-20,20,16:18.4
-19,20,16:18.4
-12,20,16:18.4
-11,20,16:18.4
-7,20,16:18.4
5,20,16:18.4
6,20,16:18.4
7,20,16:18.4
8,20,16:18.4
9,20,16:18.4
10,20,16:18.4
11,20,16:18.4
12,20,16:18.4
13,20,16:18.4
14,20,16:18.4
15,20,16:18.4
-24,21,16:18.4
-23,21,16:18.4
-22,21,16:18.4
-21,21,16:18.4
-20,21,16:18.4
-19,21,16:18.4
-18,21,16:18.4
-12,21,16:18.4
-8,21,16:18.4
2,21,16:18.4
3,21,16:18.4
4,21,16:18.4
5,21,16:18.4
6,21,16:18.4
7,21,16:18.4
8,21,16:18.4
9,21,16:18.4
10,21,16:18.4
11,21,16:18.4
12,21,16:18.4
13,21,16:18.4
14,21,16:18.4
-23,22,16:18.4
-22,22,16:18.4
-21,22,16:18.4
-20,22,16:18.4
-19,22,16:18.4
-18,22,16:18.4
-13,22,16:18.4
-8,22,16:18.4
0,22,16:18.4
1,22,16:18.4
2,22,16:18.4
3,22,16:18.4
4,22,16:18.4
5,22,16:18.4
6,22,16:18.4
7,22,16:18.4
8,22,16:18.4
9,22,16:18.4
10,22,16:18.4
11,22,16:18.4
12,22,16:18.4
13,22,16:18.4
-23,23,16:18.4
-22,23,16:18.4
-21,23,16:18.4
-20,23,16:18.4
-19,23,16:18.4
-18,23,16:18.4
-14,23,16:18.4
-13,23,16:18.4
-8,23,16:18.4
-3,23,16:18.4
-2,23,16:18.4
-1,23,16:18.4
0,23,16:18.4
1,23,16:18.4
2,23,16:18.4
3,23,16:18.4
4,23,16:18.4
5,23,16:18.4
6,23,16:18.4
7,23,16:18.4
8,23,16:18.4
9,23,16:18.4
10,23,16:18.4
11,23,16:18.4
-22,24,16:18.4
-21,24,16:18.4
-20,24,16:18.4
-19,24,16:18.4
-18,24,16:18.4
-14,24,16:18.4
-8,24,16:18.4
-5,24,16:18.4
-4,24,16:18.4
-3,24,16:18.4
-2,24,16:18.4
-1,24,16:18.4
0,24,16:18.4
1,24,16:18.4
2,24,16:18.4
3,24,16:18.4
4,24,16:18.4
5,24,16:18.4
6,24,16:18.4
7,24,16:18.4
8,24,16:18.4
9,24,16:18.4
10,24,16:18.4
-21,25,16:18.4
-20,25,16:18.4
-19,25,16:18.4
-18,25,16:18.4
-15,25,16:18.4
-14,25,16:18.4
-8,25,16:18.4
-7,25,16:18.4
-6,25,16:18.4
-5,25,16:18.4
-4,25,16:18.4
-3,25,16:18.4
-2,25,16:18.4
-1,25,16:18.4
0,25,16:18.4
2,25,16:18.4
3,25,16:18.4
4,25,16:18.4
5,25,16:18.4
6,25,16:18.4
7,25,16:18.4
8,25,16:18.4
9,25,16:18.4
-20,26,16:18.4
-19,26,16:18.4
-18,26,16:18.4
-15,26,16:18.4
-10,26,16:18.4
-9,26,16:18.4
-8,26,16:18.4
-7,26,16:18.4
-6,26,16:18.4
-5,26,16:18.4
-4,26,16:18.4
-3,26,16:18.4
-2,26,16:18.4
-1,26,16:18.4
0,26,16:18.4
1,26,16:18.4
2,26,16:18.4
3,26,16:18.4
4,26,16:18.4
5,26,16:18.4
6,26,16:18.4
7,26,16:18.4
8,26,16:18.4
-19,27,16:18.4
-18,27,16:18.4
-13,27,16:18.4
-12,27,16:18.4
-11,27,16:18.4
-10,27,16:18.4
-9,27,16:18.4
-8,27,16:18.4
-7,27,16:18.4
-6,27,16:18.4
-5,27,16:18.4
-4,27,16:18.4
-3,27,16:18.4
-2,27,16:18.4
-1,27,16:18.4
0,27,16:18.4
1,27,16:18.4
2,27,16:18.4
3,27,16:18.4
4,27,16:18.4
5,27,16:18.4
6,27,16:18.4
-18,28,16:18.4
-17,28,16:18.4
-14,28,16:18.4
-13,28,16:18.4
-12,28,16:18.4
-11,28,16:18.4
-10,28,16:18.4
-9,28,16:18.4
-8,28,16:18.4
-7,28,16:18.4
-6,28,16:18.4
-5,28,16:18.4
-4,28,16:18.4
-3,28,16:18.4
-2,28,16:18.4
-1,28,16:18.4
0,28,16:18.4
1,28,16:18.4
2,28,16:18.4
3,28,16:18.4
4,28,16:18.4
5,28,16:18.4
-18,29,16:18.4
-17,29,16:18.4
-16,29,16:18.4
-15,29,16:18.4
-14,29,16:18.4
-13,29,16:18.4
-12,29,16:18.4
-11,29,16:18.4
-10,29,16:18.4
-9,29,16:18.4
-8,29,16:18.4
-7,29,16:18.4
-6,29,16:18.4
-5,29,16:18.4
-4,29,16:18.4
-3,29,16:18.4
-2,29,16:18.4
-1,29,16:18.4
0,29,16:18.4
1,29,16:18.4
2,29,16:18.4
-9,30,16:18.4
3,-16,17:18.4
4,-16,17:18.4
5,-16,17:18.4
6,-16,17:18.4
-2,-15,17:18.4
-1,-15,17:18.4
0,-15,17:18.4
1,-15,17:18.4
2,-15,17:18.4
3,-15,17:18.4
4,-15,17:18.4
5,-15,17:18.4
6,-15,17:18.4
7,-15,17:18.4
-6,-14,17:18.4
-5,-14,17:18.4
-4,-14,17:18.4
-3,-14,17:18.4
-2,-14,17:18.4
-1,-14,17:18.4
0,-14,17:18.4
2,-14,17:18.4
3,-14,17:18.4
4,-14,17:18.4
5,-14,17:18.4
6,-14,17:18.4
7,-14,17:18.4
8,-14,17:18.4
-10,-13,17:18.4
-9,-13,17:18.4
-8,-13,17:18.4
-7,-13,17:18.4
-6,-13,17:18.4
-5,-13,17:18.4
-4,-13,17:18.4
-3,-13,17:18.4
-2,-13,17:18.4
-1,-13,17:18.4
0,-13,17:18.4
1,-13,17:18.4
2,-13,17:18.4
3,-13,17:18.4
4,-13,17:18.4
5,-13,17:18.4
6,-13,17:18.4
7,-13,17:18.4
8,-13,17:18.4
-13,-12,17:18.4
-12,-12,17:18.4
-11,-12,17:18.4
-10,-12,17:18.4
-9,-12,17:18.4
-8,-12,17:18.4
-7,-12,17:18.4
-6,-12,17:18.4
-5,-12,17:18.4
-4,-12,17:18.4
-3,-12,17:18.4
-2,-12,17:18.4
-1,-12,17:18.4
0,-12,17:18.4
1,-12,17:18.4
2,-12,17:18.4
3,-12,17:18.4
4,-12,17:18.4
5,-12,17:18.4
6,-12,17:18.4
7,-12,17:18.4
8,-12,17:18.4
9,-12,17:18.4
-15,-11,17:18.4
-14,-11,17:18.4
-13,-11,17:18.4
-12,-11,17:18.4
-11,-11,17:18.4
-10,-11,17:18.4
-9,-11,17:18.4
-8,-11,17:18.4
-7,-11,17:18.4
-6,-11,17:18.4
-5,-11,17:18.4
-4,-11,17:18.4
-3,-11,17:18.4
-2,-11,17:18.4
-1,-11,17:18.4
0,-11,17:18.4
1,-11,17:18.4
2,-11,17:18.4
3,-11,17:18.4
4,-11,17:18.4
5,-11,17:18.4
6,-11,17:18.4
7,-11,17:18.4
8,-11,17:18.4
9,-11,17:18.4
-16,-10,17:18.4
-15,-10,17:18.4
-14,-10,17:18.4
-13,-10,17:18.4
-12,-10,17:18.4
-11,-10,17:18.4
-10,-10,17:18.4
-9,-10,17:18.4
-8,-10,17:18.4
-7,-10,17:18.4
-6,-10,17:18.4
-5,-10,17:18.4
-4,-10,17:18.4
-3,-10,17:18.4
-2,-10,17:18.4
-1,-10,17:18.4
0,-10,17:18.4
1,-10,17:18.4
2,-10,17:18.4
3,-10,17:18.4
4,-10,17:18.4
5,-10,17:18.4
6,-10,17:18.4
7,-10,17:18.4
8,-10,17:18.4
9,-10,17:18.4
10,-10,17:18.4
-17,-9,17:18.4
-16,-9,17:18.4
-15,-9,17:18.4
-14,-9,17:18.4
-13,-9,17:18.4
-12,-9,17:18.4
-9,-9,17:18.4
-8,-9,17:18.4
-7,-9,17:18.4
-6,-9,17:18.4
-5,-9,17:18.4
-4,-9,17:18.4
-3,-9,17:18.4
-2,-9,17:18.4
-1,-9,17:18.4
0,-9,17:18.4
1,-9,17:18.4
2,-9,17:18.4
3,-9,17:18.4
4,-9,17:18.4
5,-9,17:18.4
6,-9,17:18.4
7,-9,17:18.4
8,-9,17:18.4
9,-9,17:18.4
10,-9,17:18.4
-19,-8,17:18.4
-18,-8,17:18.4
-17,-8,17:18.4
-16,-8,17:18.4
-15,-8,17:18.4
-14,-8,17:18.4
-10,-8,17:18.4
-9,-8,17:18.4
-8,-8,17:18.4
-6,-8,17:18.4
-5,-8,17:18.4
-4,-8,17:18.4
-3,-8,17:18.4
-2,-8,17:18.4
-1,-8,17:18.4
0,-8,17:18.4
1,-8,17:18.4
2,-8,17:18.4
3,-8,17:18.4
4,-8,17:18.4
5,-8,17:18.4
7,-8,17:18.4
8,-8,17:18.4
9,-8,17:18.4
10,-8,17:18.4
11,-8,17:18.4
-20,-7,17:18.4
-19,-7,17:18.4
-18,-7,17:18.4
-17,-7,17:18.4
-16,-7,17:18.4
-15,-7,17:18.4
-13,-7,17:18.4
-12,-7,17:18.4
-11,-7,17:18.4
-10,-7,17:18.4
-9,-7,17:18.4
-8,-7,17:18.4
-7,-7,17:18.4
-6,-7,17:18.4
-5,-7,17:18.4
-4,-7,17:18.4
-3,-7,17:18.4
-2,-7,17:18.4
-1,-7,17:18.4
0,-7,17:18.4
1,-7,17:18.4
3,-7,17:18.4
4,-7,17:18.4
5,-7,17:18.4
6,-7,17:18.4
7,-7,17:18.4
8,-7,17:18.4
9,-7,17:18.4
10,-7,17:18.4
11,-7,17:18.4
-21,-6,17:18.4
-20,-6,17:18.4
-19,-6,17:18.4
-18,-6,17:18.4
-17,-6,17:18.4
-16,-6,17:18.4
-15,-6,17:18.4
-14,-6,17:18.4
-13,-6,17:18.4
-12,-6,17:18.4
-11,-6,17:18.4
-10,-6,17:18.4
-9,-6,17:18.4
-8,-6,17:18.4
-7,-6,17:18.4
-6,-6,17:18.4
-5,-6,17:18.4
-4,-6,17:18.4
-3,-6,17:18.4
-2,-6,17:18.4
-1,-6,17:18.4
1,-6,17:18.4
2,-6,17:18.4
3,-6,17:18.4
4,-6,17:18.4
5,-6,17:18.4
6,-6,17:18.4
7,-6,17:18.4
8,-6,17:18.4
9,-6,17:18.4
10,-6,17:18.4
11,-6,17:18.4
12,-6,17:18.4
-22,-5,17:18.4
-21,-5,17:18.4
-20,-5,17:18.4
-19,-5,17:18.4
-18,-5,17:18.4
-17,-5,17:18.4
-16,-5,17:18.4
-15,-5,17:18.4
-14,-5,17:18.4
-13,-5,17:18.4
-12,-5,17:18.4
-11,-5,17:18.4
-10,-5,17:18.4
-9,-5,17:18.4
-8,-5,17:18.4
-7,-5,17:18.4
-6,-5,17:18.4
-5,-5,17:18.4
-4,-5,17:18.4
-3,-5,17:18.4
-2,-5,17:18.4
1,-5,17:18.4
3,-5,17:18.4
4,-5,17:18.4
5,-5,17:18.4
6,-5,17:18.4
7,-5,17:18.4
8,-5,17:18.4
9,-5,17:18.4
10,-5,17:18.4
11,-5,17:18.4
12,-5,17:18.4
-24,-4,17:18.4
-23,-4,17:18.4
-22,-4,17:18.4
-21,-4,17:18.4
-20,-4,17:18.4
-19,-4,17:18.4
-18,-4,17:18.4
-17,-4,17:18.4
-16,-4,17:18.4
-15,-4,17:18.4
-14,-4,17:18.4
-13,-4,17:18.4
-12,-4,17:18.4
-11,-4,17:18.4
-10,-4,17:18.4
-9,-4,17:18.4
-8,-4,17:18.4
-7,-4,17:18.4
-6,-4,17:18.12
-5,-4,17:18.12
-4,-4,17:18.12
0,-4,17:18.12
1,-4,17:18.12
3,-4,17:18.4
4,-4,17:18.4
5,-4,17:18.4
6,-4,17:18.4
7,-4,17:18.4
8,-4,17:18.4
9,-4,17:18.4
10,-4,17:18.4
11,-4,17:18.4
12,-4,17:18.4
13,-4,17:18.4
-25,-3,17:18.4
-24,-3,17:18.4
-23,-3,17:18.4
-22,-3,17:18.4
-21,-3,17:18.4
-20,-3,17:18.4
-19,-3,17:18.4
-18,-3,17:18.4
-17,-3,17:18.4
-16,-3,17:18.4
-15,-3,17:18.4
-14,-3,17:18.4
-13,-3,17:18.4
-12,-3,17:18.4
-11,-3,17:18.4
-10,-3,17:18.4
-9,-3,17:18.4
-8,-3,17:18.4
-7,-3,17:18.12
-6,-3,17:18.12
0,-3,17:18.12
3,-3,17:18.12
4,-3,17:18.4
5,-3,17:18.4
6,-3,17:18.4
7,-3,17:18.4
8,-3,17:18.4
9,-3,17:18.4
10,-3,17:18.4
11,-3,17:18.4
12,-3,17:18.4
13,-3,17:18.4
-26,-2,17:18.4
-25,-2,17:18.4
-24,-2,17:18.4
-23,-2,17:18.4
-22,-2,17:18.4
-21,-2,17:18.4
-20,-2,17:18.4
-19,-2,17:18.4
-18,-2,17:18.4
-17,-2,17:18.4
-16,-2,17:18.4
-15,-2,17:18.4
-14,-2,17:18.4
-13,-2,17:18.4
-12,-2,17:18.4
-11,-2,17:18.4
-10,-2,17:18.4
-9,-2,17:18.4
-8,-2,17:18.4
0,-2,17:18.12
4,-2,17:18.4
5,-2,17:18.4
6,-2,17:18.4
7,-2,17:18.4
8,-2,17:18.4
9,-2,17:18.4
11,-2,17:18.4
12,-2,17:18.4
13,-2,17:18.4
14,-2,17:18.4
-27,-1,17:18.4
-26,-1,17:18.4
-25,-1,17:18.4
-24,-1,17:18.4
-23,-1,17:18.4
-22,-1,17:18.4
-21,-1,17:18.4
-20,-1,17:18.4
-19,-1,17:18.4
-18,-1,17:18.4
-17,-1,17:18.4
-16,-1,17:18.4
-15,-1,17:18.4
-14,-1,17:18.4
-13,-1,17:18.4
-12,-1,17:18.4
-11,-1,17:18.4
-10,-1,17:18.4
-1,-1,17:18.12
4,-1,17:18.4
5,-1,17:18.4
6,-1,17:18.4
7,-1,17:18.4
8,-1,17:18.4
9,-1,17:18.4
10,-1,17:18.4
11,-1,17:18.4
12,-1,17:18.4
13,-1,17:18.4
14,-1,17:18.4
-28,0,17:18.4
-27,0,17:18.4
-26,0,17:18.4
-25,0,17:18.4
-24,0,17:18.4
-23,0,17:18.4
-22,0,17:18.4
-21,0,17:18.4
-20,0,17:18.4
-19,0,17:18.4
-18,0,17:18.4
-17,0,17:18.4
-16,0,17:18.4
-15,0,17:18.4
-14,0,17:18.4
-13,0,17:18.4
-2,0,17:17.12
-1,0,17:18.12
4,0,17:18.4
5,0,17:18.4
6,0,17:18.4
7,0,17:18.4
8,0,17:18.4
9,0,17:18.4
10,0,17:18.4
12,0,17:18.4
13,0,17:18.4
14,0,17:18.4
15,0,17:18.4
-28,1,17:18.4
-27,1,17:18.4
-26,1,17:18.4
-25,1,17:18.4
-24,1,17:18.4
-23,1,17:18.4
-22,1,17:18.4
-21,1,17:18.4
-20,1,17:18.4
-19,1,17:18.4
-18,1,17:18.4
-17,1,17:18.4
-16,1,17:18.4
-15,1,17:18.4
-2,1,17:17.12
-1,1,17:17.12
4,1,17:18.4
5,1,17:18.4
6,1,17:18.4
7,1,17:18.4
8,1,17:18.4
9,1,17:18.4
10,1,17:18.4
12,1,17:18.4
13,1,17:18.4
14,1,17:18.4
15,1,17:18.4
-28,2,17:18.4
-27,2,17:18.4
-26,2,17:18.4
-25,2,17:18.4
-24,2,17:18.4
-23,2,17:18.4
-22,2,17:18.4
-21,2,17:18.4
-20,2,17:18.4
-19,2,17:18.4
-18,2,17:18.4
-14,2,17:18.4
-13,2,17:18.4
-2,2,17:18.12
5,2,17:18.4
6,2,17:18.4
7,2,17:18.4
8,2,17:18.4
9,2,17:18.4
10,2,17:18.4
11,2,17:18.4
13,2,17:18.4
14,2,17:18.4
15,2,17:18.4
16,2,17:18.4
-28,3,17:18.4
-27,3,17:18.4
-26,3,17:18.4
-25,3,17:18.4
-24,3,17:18.4
-23,3,17:18.4
-22,3,17:18.4
-21,3,17:18.4
-20,3,17:18.4
-19,3,17:18.4
-18,3,17:18.4
-17,3,17:18.4
-13,3,17:18.12
-12,3,17:18.12
5,3,17:18.4
6,3,17:18.4
7,3,17:18.4
8,3,17:18.4
9,3,17:18.4
10,3,17:18.4
11,3,17:18.4
13,3,17:18.4
14,3,17:18.4
15,3,17:18.4
16,3,17:18.4
-27,4,17:18.4
-26,4,17:18.4
-25,4,17:18.4
-24,4,17:18.4
-23,4,17:18.4
-22,4,17:18.4
-21,4,17:18.4
-20,4,17:18.12
-19,4,17:18.12
-17,4,17:18.12
-16,4,17:18.12
-15,4,17:18.12
-14,4,17:18.12
-11,4,17:18.12
-10,4,17:18.12
3,4,17:18.12
4,4,17:18.4
5,4,17:18.4
6,4,17:18.4
7,4,17:18.4
8,4,17:18.4
9,4,17:18.4
10,4,17:18.4
11,4,17:18.4
12,4,17:18.4
13,4,17:18.4
14,4,17:18.4
15,4,17:18.4
16,4,17:18.4
-27,5,17:18.4
-26,5,17:18.4
-25,5,17:18.4
-24,5,17:18.4
-23,5,17:18.4
-22,5,17:18.4
-21,5,17:18.4
-20,5,17:18.12
-19,5,17:18.12
-18,5,17:18.12
-14,5,17:18.12
-13,5,17:18.12
-12,5,17:18.12
-11,5,17:18.12
-10,5,17:18.12
-9,5,17:18.12
0,5,17:18.12
1,5,17:18.12
2,5,17:18.12
6,5,17:18.4
7,5,17:18.4
8,5,17:18.4
9,5,17:18.4
10,5,17:18.4
11,5,17:18.4
12,5,17:18.4
13,5,17:18.4
14,5,17:18.4
15,5,17:18.4
16,5,17:18.4
17,5,17:18.4
-27,6,17:18.4
-26,6,17:18.4
-25,6,17:18.4
-24,6,17:18.4
-23,6,17:18.4
-22,6,17:18.4
-21,6,17:18.4
-20,6,17:18.12
-19,6,17:18.12
-18,6,17:18.12
-17,6,17:18.12
-11,6,17:18.12
-10,6,17:18.12
-9,6,17:18.12
-8,6,17:18.12
-7,6,17:18.12
-2,6,17:18.12
-1,6,17:18.12
0,6,17:18.12
7,6,17:18.4
8,6,17:18.4
9,6,17:18.4
10,6,17:18.4
11,6,17:18.4
12,6,17:18.4
13,6,17:18.4
14,6,17:18.4
15,6,17:18.4
16,6,17:18.4
17,6,17:18.4
-26,7,17:18.4
-25,7,17:18.4
-24,7,17:18.4
-23,7,17:18.4
-22,7,17:18.4
-21,7,17:18.4
-20,7,17:18.12
-19,7,17:18.12
-18,7,17:18.12
-7,7,17:18.12
-6,7,17:18.12
-5,7,17:18.12
-4,7,17:18.12
-3,7,17:18.12
7,7,17:18.4
8,7,17:18.4
9,7,17:18.4
10,7,17:18.4
11,7,17:18.4
12,7,17:18.4
13,7,17:18.4
14,7,17:18.4
15,7,17:18.4
16,7,17:18.4
17,7,17:18.4
-26,8,17:18.4
-25,8,17:18.4
-23,8,17:18.4
-22,8,17:18.4
-21,8,17:18.4
-20,8,17:18.12
-19,8,17:18.12
-18,8,17:18.12
-17,8,17:18.12
-16,8,17:17.12
-15,8,17:17.12
-5,8,17:18.12
8,8,17:18.4
9,8,17:18.4
10,8,17:18.4
12,8,17:18.4
13,8,17:18.4
14,8,17:18.4
15,8,17:18.4
16,8,17:18.4
17,8,17:18.4
18,8,17:18.4
-26,9,17:18.4
-25,9,17:18.4
-24,9,17:18.4
-23,9,17:18.4
-22,9,17:18.4
-21,9,17:18.4
-20,9,17:18.12
-19,9,17:18.12
-18,9,17:18.12
-17,9,17:18.12
-16,9,17:17.12
-15,9,17:17.12
-5,9,17:18.12
0,9,17:18.12
1,9,17:18.12
2,9,17:18.12
3,9,17:18.12
9,9,17:18.4
10,9,17:18.4
11,9,17:18.4
12,9,17:18.4
13,9,17:18.4
14,9,17:18.4
15,9,17:18.4
16,9,17:18.4
17,9,17:18.4
18,9,17:18.4
-25,10,17:18.4
-24,10,17:18.4
-21,10,17:18.4
-20,10,17:18.12
-19,10,17:18.12
-18,10,17:18.12
-17,10,17:18.12
-16,10,17:18.12
-15,10,17:18.12
-6,10,17:18.12
-3,10,17:17.12
-2,10,17:17.12
-1,10,17:17.12
4,10,17:18.12
5,10,17:18.4
6,10,17:18.4
7,10,17:18.4
10,10,17:18.4
11,10,17:18.4
12,10,17:18.4
13,10,17:18.4
14,10,17:18.4
15,10,17:18.4
16,10,17:18.4
17,10,17:18.4
18,10,17:18.4
-25,11,17:18.4
-24,11,17:18.4
-23,11,17:18.4
-21,11,17:18.4
-20,11,17:18.12
-19,11,17:18.12
-18,11,17:18.12
-17,11,17:18.12
-16,11,17:18.12
-15,11,17:18.12
-7,11,17:18.12
-6,11,17:18.12
-2,11,17:17.12
-1,11,17:17.12
7,11,17:18.4
8,11,17:18.4
9,11,17:18.4
10,11,17:18.4
11,11,17:18.4
12,11,17:18.4
13,11,17:18.4
14,11,17:18.4
15,11,17:18.4
16,11,17:18.4
17,11,17:18.4
18,11,17:18.4
19,11,17:18.4
-25,12,17:18.4
-24,12,17:18.4
-23,12,17:18.4
-22,12,17:18.4
-20,12,17:18.12
-19,12,17:18.12
-18,12,17:18.12
-17,12,17:18.12
-16,12,17:18.12
-15,12,17:18.12
-14,12,17:18.12
-7,12,17:18.12
-6,12,17:18.12
-1,12,17:17.12
9,12,17:18.4
10,12,17:18.4
11,12,17:18.4
12,12,17:18.4
13,12,17:18.4
14,12,17:18.4
15,12,17:18.4
16,12,17:18.4
18,12,17:18.4
19,12,17:18.4
-25,13,17:18.4
-24,13,17:18.4
-23,13,17:18.4
-22,13,17:18.4
-19,13,17:18.12
-18,13,17:18.12
-17,13,17:18.12
-16,13,17:18.12
-15,13,17:18.12
-14,13,17:18.12
-7,13,17:18.12
-6,13,17:18.12
6,13,17:18.4
7,13,17:18.4
8,13,17:18.4
9,13,17:18.4
10,13,17:18.4
11,13,17:18.4
12,13,17:18.4
13,13,17:18.4
14,13,17:18.4
15,13,17:18.4
16,13,17:18.4
17,13,17:18.4
18,13,17:18.4
19,13,17:18.4
-24,14,17:18.4
-23,14,17:18.4
-22,14,17:18.4
-18,14,17:18.12
-17,14,17:18.12
-16,14,17:18.12
-15,14,17:18.12
-14,14,17:18.12
-13,14,17:18.12
-8,14,17:18.12
-6,14,17:18.12
4,14,17:18.12
5,14,17:18.4
6,14,17:18.4
7,14,17:18.4
8,14,17:18.4
9,14,17:18.4
10,14,17:18.4
11,14,17:18.4
12,14,17:18.4
13,14,17:18.4
14,14,17:18.4
15,14,17:18.4
16,14,17:18.4
17,14,17:18.4
18,14,17:18.4
19,14,17:18.4
-24,15,17:18.4
-23,15,17:18.4
-22,15,17:18.4
-21,15,17:18.4
-19,15,17:18.4
-18,15,17:18.4
-17,15,17:18.4
-16,15,17:18.4
-15,15,17:18.4
-14,15,17:18.4
-13,15,17:18.4
-9,15,17:18.4
-7,15,17:18.12
-6,15,17:18.12
1,15,17:18.12
2,15,17:18.12
3,15,17:18.12
4,15,17:18.12
5,15,17:18.4
6,15,17:18.4
7,15,17:18.4
8,15,17:18.4
9,15,17:18.4
10,15,17:18.4
11,15,17:18.4
12,15,17:18.4
13,15,17:18.4
14,15,17:18.4
15,15,17:18.4
16,15,17:18.4
17,15,17:18.4
18,15,17:18.4
-24,16,17:18.4
-23,16,17:18.4
-22,16,17:18.4
-21,16,17:18.4
-19,16,17:18.4
-18,16,17:18.4
-17,16,17:18.4
-16,16,17:18.4
-15,16,17:18.4
-14,16,17:18.4
-13,16,17:18.4
-10,16,17:18.4
-9,16,17:18.4
-7,16,17:18.4
-1,16,17:18.12
0,16,17:18.12
1,16,17:18.12
2,16,17:18.12
3,16,17:18.12
4,16,17:18.12
5,16,17:18.4
6,16,17:18.4
7,16,17:18.4
8,16,17:18.4
9,16,17:18.4
10,16,17:18.4
11,16,17:18.4
12,16,17:18.4
13,16,17:18.4
14,16,17:18.4
15,16,17:18.4
16,16,17:18.4
17,16,17:18.4
-23,17,17:18.4
-22,17,17:18.4
-21,17,17:18.4
-20,17,17:18.4
-19,17,17:18.4
-18,17,17:18.4
-17,17,17:18.4
-16,17,17:18.4
-15,17,17:18.4
-14,17,17:18.4
-13,17,17:18.4
-10,17,17:18.4
-7,17,17:18.4
-4,17,17:18.4
-3,17,17:18.4
-2,17,17:18.4
-1,17,17:18.4
0,17,17:18.4
1,17,17:18.4
2,17,17:18.4
3,17,17:18.4
4,17,17:18.4
5,17,17:18.4
6,17,17:18.4
7,17,17:18.4
9,17,17:18.4
10,17,17:18.4
11,17,17:18.4
12,17,17:18.4
13,17,17:18.4
14,17,17:18.4
15,17,17:18.4
-22,18,17:18.4
-21,18,17:18.4
-20,18,17:18.4
-19,18,17:18.4
-18,18,17:18.4
-17,18,17:18.4
-16,18,17:18.4
-15,18,17:18.4
-14,18,17:18.4
-13,18,17:18.4
-11,18,17:18.4
-10,18,17:18.4
-7,18,17:18.4
-6,18,17:18.4
-5,18,17:18.4
-4,18,17:18.4
-3,18,17:18.4
-2,18,17:18.4
-1,18,17:18.4
0,18,17:18.4
1,18,17:18.4
2,18,17:18.4
3,18,17:18.4
4,18,17:18.4
5,18,17:18.4
6,18,17:18.4
7,18,17:18.4
8,18,17:18.4
9,18,17:18.4
10,18,17:18.4
11,18,17:18.4
12,18,17:18.4
13,18,17:18.4
14,18,17:18.4
-22,19,17:18.4
-21,19,17:18.4
-20,19,17:18.4
-19,19,17:18.4
-18,19,17:18.4
-17,19,17:18.4
-16,19,17:18.4
-15,19,17:18.4
-14,19,17:18.4
-13,19,17:18.4
-12,19,17:18.4
-11,19,17:18.4
-9,19,17:18.4
-8,19,17:18.4
-7,19,17:18.4
-6,19,17:18.4
-4,19,17:18.4
-3,19,17:18.4
-2,19,17:18.4
-1,19,17:18.4
0,19,17:18.4
1,19,17:18.4
2,19,17:18.4
3,19,17:18.4
4,19,17:18.4
5,19,17:18.4
6,19,17:18.4
7,19,17:18.4
8,19,17:18.4
9,19,17:18.4
10,19,17:18.4
11,19,17:18.4
13,19,17:18.4
-21,20,17:18.4
-20,20,17:18.4
-19,20,17:18.4
-18,20,17:18.4
-17,20,17:18.4
-16,20,17:18.4
-15,20,17:18.4
-14,20,17:18.4
-13,20,17:18.4
-12,20,17:18.4
-11,20,17:18.4
-10,20,17:18.4
-9,20,17:18.4
-8,20,17:18.4
-7,20,17:18.4
-6,20,17:18.4
-5,20,17:18.4
-4,20,17:18.4
-3,20,17:18.4
-2,20,17:18.4
-1,20,17:18.4
0,20,17:18.4
1,20,17:18.4
2,20,17:18.4
3,20,17:18.4
4,20,17:18.4
5,20,17:18.4
6,20,17:18.4
7,20,17:18.4
8,20,17:18.4
9,20,17:18.4
10,20,17:18.4
11,20,17:18.4
-21,21,17:18.4
-20,21,17:18.4
-19,21,17:18.4
-18,21,17:18.4
-17,21,17:18.4
-16,21,17:18.4
-15,21,17:18.4
-14,21,17:18.4
-13,21,17:18.4
-12,21,17:18.4
-11,21,17:18.4
-10,21,17:18.4
-9,21,17:18.4
-8,21,17:18.4
-7,21,17:18.4
-6,21,17:18.4
-5,21,17:18.4
-4,21,17:18.4
-3,21,17:18.4
-2,21,17:18.4
-1,21,17:18.4
0,21,17:18.4
1,21,17:18.4
2,21,17:18.4
3,21,17:18.4
5,21,17:18.4
6,21,17:18.4
7,21,17:18.4
8,21,17:18.4
9,21,17:18.4
10,21,17:18.4
-20,22,17:18.4
-19,22,17:18.4
-18,22,17:18.4
-17,22,17:18.4
-16,22,17:18.4
-15,22,17:18.4
-14,22,17:18.4
-13,22,17:18.4
-12,22,17:18.4
-11,22,17:18.4
-10,22,17:18.4
-9,22,17:18.4
-8,22,17:18.4
-7,22,17:18.4
-6,22,17:18.4
-5,22,17:18.4
-4,22,17:18.4
-3,22,17:18.4
-2,22,17:18.4
-1,22,17:18.4
0,22,17:18.4
4,22,17:18.4
5,22,17:18.4
6,22,17:18.4
7,22,17:18.4
8,22,17:18.4
-20,23,17:18.4
-19,23,17:18.4
-18,23,17:18.4
-17,23,17:18.4
-16,23,17:18.4
-15,23,17:18.4
-14,23,17:18.4
-13,23,17:18.4
-12,23,17:18.4
-11,23,17:18.4
-10,23,17:18.4
-9,23,17:18.4
-8,23,17:18.4
-7,23,17:18.4
-6,23,17:18.4
-4,23,17:18.4
-3,23,17:18.4
2,23,17:18.4
3,23,17:18.4
4,23,17:18.4
5,23,17:18.4
6,23,17:18.4
7,23,17:18.4
-19,24,17:18.4
-18,24,17:18.4
-17,24,17:18.4
-16,24,17:18.4
-15,24,17:18.4
-14,24,17:18.4
-13,24,17:18.4
-12,24,17:18.4
-11,24,17:18.4
-10,24,17:18.4
-9,24,17:18.4
-8,24,17:18.4
-7,24,17:18.4
-6,24,17:18.4
-5,24,17:18.4
-4,24,17:18.4
-3,24,17:18.4
-2,24,17:18.4
-1,24,17:18.4
0,24,17:18.4
1,24,17:18.4
2,24,17:18.4
3,24,17:18.4
4,24,17:18.4
5,24,17:18.4
6,24,17:18.4
-19,25,17:18.4
-18,25,17:18.4
-17,25,17:18.4
-16,25,17:18.4
-15,25,17:18.4
-14,25,17:18.4
-13,25,17:18.4
-12,25,17:18.4
-11,25,17:18.4
-10,25,17:18.4
-9,25,17:18.4
-8,25,17:18.4
-7,25,17:18.4
-6,25,17:18.4
-5,25,17:18.4
-4,25,17:18.4
-3,25,17:18.4
-2,25,17:18.4
-1,25,17:18.4
0,25,17:18.4
2,25,17:18.4
3,25,17:18.4
4,25,17:18.4
-18,26,17:18.4
-17,26,17:18.4
-16,26,17:18.4
-15,26,17:18.4
-14,26,17:18.4
-13,26,17:18.4
-12,26,17:18.4
-11,26,17:18.4
-10,26,17:18.4
-9,26,17:18.4
-8,26,17:18.4
-7,26,17:18.4
-6,26,17:18.4
-5,26,17:18.4
-4,26,17:18.4
-3,26,17:18.4
-2,26,17:18.4
-1,26,17:18.4
0,26,17:18.4
1,26,17:18.4
2,26,17:18.4
3,26,17:18.4
-18,27,17:18.4
-17,27,17:18.4
-16,27,17:18.4
-15,27,17:18.4
-14,27,17:18.4
-13,27,17:18.4
-12,27,17:18.4
-11,27,17:18.4
-10,27,17:18.4
-9,27,17:18.4
-8,27,17:18.4
-7,27,17:18.4
-6,27,17:18.4
-5,27,17:18.4
-4,27,17:18.4
-3,27,17:18.4
-17,28,17:18.4
-16,28,17:18.4
-15,28,17:18.4
-14,28,17:18.4
-13,28,17:18.4
-12,28,17:18.4
-11,28,17:18.4
-9,28,17:18.4
-9,29,17:18.4
3,-13,18:18.4
4,-13,18:18.4
5,-13,18:18.4
-1,-12,18:18.4
0,-12,18:18.4
1,-12,18:18.4
2,-12,18:18.4
3,-12,18:18.4
4,-12,18:18.4
5,-12,18:18.4
-5,-11,18:18.4
-4,-11,18:18.4
-3,-11,18:18.4
-2,-11,18:18.4
-1,-11,18:18.4
0,-11,18:18.4
1,-11,18:18.4
2,-11,18:18.4
3,-11,18:18.4
4,-11,18:18.4
5,-11,18:18.4
6,-11,18:18.4
-9,-10,18:18.4
-8,-10,18:18.4
-7,-10,18:18.4
-6,-10,18:18.4
-5,-10,18:18.4
-4,-10,18:18.4
-3,-10,18:18.4
-2,-10,18:18.4
-1,-10,18:18.4
0,-10,18:18.4
1,-10,18:18.4
2,-10,18:18.4
3,-10,18:18.4
4,-10,18:18.4
5,-10,18:18.4
6,-10,18:18.4
-12,-9,18:18.4
-11,-9,18:18.4
-10,-9,18:18.4
-9,-9,18:18.4
-8,-9,18:18.4
-7,-9,18:18.4
-6,-9,18:18.4
-5,-9,18:18.4
-4,-9,18:18.4
-3,-9,18:18.4
-2,-9,18:18.4
-1,-9,18:18.4
0,-9,18:18.4
1,-9,18:18.4
4,-9,18:18.4
5,-9,18:18.4
6,-9,18:18.4
7,-9,18:18.4
-14,-8,18:18.4
-13,-8,18:18.4
-12,-8,18:18.4
-11,-8,18:18.4
-10,-8,18:18.4
-9,-8,18:18.4
-8,-8,18:18.4
-6,-8,18:18.4
-5,-8,18:18.4
-4,-8,18:18.4
-3,-8,18:18.4
4,-8,18:18.4
5,-8,18:18.4
7,-8,18:18.4
-15,-7,18:18.4
-14,-7,18:18.4
-13,-7,18:18.4
-12,-7,18:18.4
-11,-7,18:18.4
-10,-7,18:18.4
-9,-7,18:18.4
-8,-7,18:18.4
1,-7,18:18.4
5,-7,18:18.4
6,-7,18:18.4
7,-7,18:18.4
8,-7,18:18.4
-16,-6,18:18.4
-15,-6,18:18.4
-14,-6,18:18.4
-13,-6,18:18.4
-12,-6,18:18.4
-11,-6,18:18.4
-1,-6,18:18.4
0,-6,18:18.4
1,-6,18:18.4
2,-6,18:18.4
5,-6,18:18.4
6,-6,18:18.4
7,-6,18:18.4
8,-6,18:18.4
-18,-5,18:18.4
-17,-5,18:18.4
-16,-5,18:18.4
-15,-5,18:18.4
-14,-5,18:18.4
-13,-5,18:18.4
-3,-5,18:18.4
-2,-5,18:18.4
-1,-5,18:18.4
0,-5,18:18.4
1,-5,18:18.4
2,-5,18:18.4
6,-5,18:18.4
7,-5,18:18.4
8,-5,18:18.4
9,-5,18:18.4
-19,-4,18:18.4
-18,-4,18:18.4
-17,-4,18:18.4
-16,-4,18:18.4
-15,-4,18:18.4
-14,-4,18:18.4
-5,-4,18:18.12
-4,-4,18:18.12
-3,-4,18:18.12
-1,-4,18:18.12
0,-4,18:18.12
1,-4,18:18.12
2,-4,18:18.12
3,-4,18:18.4
6,-4,18:18.4
7,-4,18:18.4
8,-4,18:18.4
9,-4,18:18.4
-20,-3,18:18.4
-19,-3,18:18.4
-18,-3,18:18.4
-17,-3,18:18.4
-16,-3,18:18.4
-15,-3,18:18.4
-6,-3,18:18.12
-5,-3,18:18.12
-4,-3,18:18.12
-3,-3,18:18.12
-2,-3,18:18.12
-1,-3,18:18.12
0,-3,18:18.12
2,-3,18:18.12
3,-3,18:18.12
7,-3,18:18.4
8,-3,18:18.4
9,-3,18:18.4
10,-3,18:18.4
-21,-2,18:18.4
-20,-2,18:18.4
-19,-2,18:18.4
-18,-2,18:18.4
-17,-2,18:18.4
-8,-2,18:18.4
-7,-2,18:18.12
-6,-2,18:18.12
-5,-2,18:18.12
-4,-2,18:18.12
-3,-2,18:18.12
-2,-2,18:18.12
-1,-2,18:18.12
0,-2,18:18.12
1,-2,18:18.12
2,-2,18:18.12
3,-2,18:18.12
7,-2,18:18.4
8,-2,18:18.4
9,-2,18:18.4
10,-2,18:18.4
-23,-1,18:18.4
-22,-1,18:18.4
-21,-1,18:18.4
-20,-1,18:18.4
-19,-1,18:18.4
-18,-1,18:18.4
-11,-1,18:18.4
-10,-1,18:18.4
-9,-1,18:18.4
-8,-1,18:18.4
-7,-1,18:18.12
-6,-1,18:18.12
-5,-1,18:18.12
-4,-1,18:18.12
-3,-1,18:18.12
-2,-1,18:18.12
-1,-1,18:18.12
0,-1,18:18.12
1,-1,18:18.12
2,-1,18:18.12
3,-1,18:18.12
8,-1,18:18.4
9,-1,18:18.4
10,-1,18:18.4
11,-1,18:18.4
-24,0,18:18.4
-23,0,18:18.4
-22,0,18:18.4
-21,0,18:18.4
-20,0,18:18.4
-19,0,18:18.4
-13,0,18:18.4
-12,0,18:18.4
-11,0,18:18.4
-10,0,18:18.4
-9,0,18:18.4
-8,0,18:18.4
-7,0,18:18.12
-6,0,18:18.12
-5,0,18:18.12
-4,0,18:18.12
-3,0,18:18.12
-2,0,18:18.12
-1,0,18:18.12
0,0,18:18.12
1,0,18:18.12
2,0,18:18.12
3,0,18:18.12
4,0,18:18.4
8,0,18:18.4
9,0,18:18.4
10,0,18:18.4
11,0,18:18.4
12,0,18:18.4
-25,1,18:18.4
-24,1,18:18.4
-23,1,18:18.4
-22,1,18:18.4
-21,1,18:18.4
-16,1,18:18.4
-15,1,18:18.4
-14,1,18:18.4
-13,1,18:18.4
-12,1,18:18.4
-11,1,18:18.4
-10,1,18:18.4
-9,1,18:18.4
-8,1,18:18.4
-7,1,18:18.12
-6,1,18:18.12
-5,1,18:18.12
-4,1,18:18.12
-3,1,18:18.12
-2,1,18:18.12
-1,1,18:18.12
0,1,18:18.12
1,1,18:18.12
2,1,18:18.12
3,1,18:18.12
4,1,18:18.4
9,1,18:18.4
10,1,18:18.4
11,1,18:18.4
12,1,18:18.4
-25,2,18:18.4
-24,2,18:18.4
-23,2,18:18.4
-22,2,18:18.4
-18,2,18:18.4
-17,2,18:18.4
-16,2,18:18.4
-15,2,18:18.4
-14,2,18:18.4
-13,2,18:18.4
-12,2,18:18.4
-11,2,18:18.4
-10,2,18:18.4
-9,2,18:18.4
-8,2,18:18.4
-7,2,18:18.12
-6,2,18:18.12
-5,2,18:18.12
-4,2,18:18.12
-3,2,18:18.12
-2,2,18:18.12
-1,2,18:18.12
0,2,18:18.12
1,2,18:18.12
2,2,18:18.12
3,2,18:18.12
4,2,18:18.4
9,2,18:18.4
10,2,18:18.4
11,2,18:18.4
12,2,18:18.4
-25,3,18:18.4
-24,3,18:18.4
-23,3,18:18.4
-22,3,18:18.4
-19,3,18:18.4
-18,3,18:18.4
-17,3,18:18.4
-16,3,18:18.4
-15,3,18:18.4
-14,3,18:18.4
-13,3,18:18.4
-12,3,18:18.4
-11,3,18:18.4
-10,3,18:18.4
-9,3,18:18.4
-8,3,18:18.4
-7,3,18:18.12
-6,3,18:18.12
-5,3,18:18.12
-4,3,18:18.12
-3,3,18:18.12
-2,3,18:18.12
-1,3,18:18.12
0,3,18:18.12
1,3,18:18.12
2,3,18:18.12
3,3,18:18.12
4,3,18:18.4
10,3,18:18.4
11,3,18:18.4
12,3,18:18.4
13,3,18:18.4
-24,4,18:18.4
-23,4,18:18.4
-22,4,18:18.4
-18,4,18:18.12
-17,4,18:18.12
-16,4,18:18.12
-15,4,18:18.12
-14,4,18:18.12
-13,4,18:18.12
-12,4,18:18.12
-11,4,18:18.12
-10,4,18:18.12
-8,4,18:18.12
-7,4,18:18.12
-6,4,18:18.12
-3,4,18:18.12
-1,4,18:18.12
0,4,18:18.12
1,4,18:18.12
2,4,18:18.12
3,4,18:18.12
4,4,18:18.4
5,4,18:18.4
10,4,18:18.4
11,4,18:18.4
12,4,18:18.4
13,4,18:18.4
-24,5,18:18.4
-23,5,18:18.4
-22,5,18:18.4
-21,5,18:18.4
-18,5,18:18.12
-17,5,18:18.12
-16,5,18:18.12
-15,5,18:18.12
-14,5,18:18.12
-13,5,18:18.12
-12,5,18:18.12
-11,5,18:18.12
-10,5,18:18.12
-9,5,18:18.12
-8,5,18:18.12
-1,5,18:18.12
0,5,18:18.12
1,5,18:18.12
2,5,18:18.12
3,5,18:18.12
4,5,18:18.4
5,5,18:18.4
10,5,18:18.4
11,5,18:18.4
12,5,18:18.4
13,5,18:18.4
-24,6,18:18.4
-23,6,18:18.4
-22,6,18:18.4
-21,6,18:18.4
-17,6,18:18.12
-16,6,18:18.12
-15,6,18:18.12
-14,6,18:18.12
-13,6,18:18.12
-12,6,18:18.12
-11,6,18:18.12
-10,6,18:18.12
-9,6,18:18.12
-8,6,18:18.12
-7,6,18:18.12
-2,6,18:18.12
-1,6,18:18.12
0,6,18:18.12
1,6,18:18.12
2,6,18:18.12
3,6,18:18.12
4,6,18:18.4
5,6,18:18.4
6,6,18:18.4
11,6,18:18.4
12,6,18:18.4
13,6,18:18.4
14,6,18:18.4
-23,7,18:18.4
-22,7,18:18.4
-21,7,18:18.4
-16,7,18:18.12
-15,7,18:18.12
-14,7,18:18.12
-13,7,18:18.12
-12,7,18:18.12
-11,7,18:18.12
-10,7,18:18.12
-9,7,18:18.12
-7,7,18:18.12
-6,7,18:18.12
-5,7,18:18.12
-4,7,18:18.12
-3,7,18:18.12
0,7,18:18.12
1,7,18:18.12
2,7,18:18.12
3,7,18:18.12
4,7,18:18.12
5,7,18:18.4
6,7,18:18.4
7,7,18:18.4
11,7,18:18.4
12,7,18:18.4
13,7,18:18.4
14,7,18:18.4
-23,8,18:18.4
-22,8,18:18.4
-21,8,18:18.4
-20,8,18:18.12
-16,8,18:17.12
-15,8,18:18.12
-14,8,18:18.12
-13,8,18:18.12
-12,8,18:18.12
-11,8,18:18.12
-10,8,18:18.12
-9,8,18:18.12
-5,8,18:18.12
-2,8,18:18.12
-1,8,18:18.12
0,8,18:18.12
1,8,18:18.12
2,8,18:18.12
3,8,18:18.12
4,8,18:18.12
5,8,18:18.4
6,8,18:18.4
7,8,18:18.4
8,8,18:18.4
12,8,18:18.4
13,8,18:18.4
14,8,18:18.4
-23,9,18:18.4
-22,9,18:18.4
-21,9,18:18.4
-20,9,18:18.12
-16,9,18:17.12
-15,9,18:18.12
-14,9,18:18.12
-13,9,18:18.12
-12,9,18:18.12
-11,9,18:18.12
-10,9,18:18.12
-9,9,18:18.12
-8,9,18:18.12
-6,9,18:18.12
-5,9,18:18.12
0,9,18:18.12
1,9,18:18.12
2,9,18:18.12
3,9,18:18.12
4,9,18:18.12
5,9,18:18.4
6,9,18:18.4
7,9,18:18.4
8,9,18:18.4
12,9,18:18.4
13,9,18:18.4
14,9,18:18.4
15,9,18:18.4
-22,10,18:18.4
-21,10,18:18.4
-20,10,18:18.12
-14,10,18:18.12
-13,10,18:18.12
-12,10,18:18.12
-11,10,18:18.12
-10,10,18:18.12
-9,10,18:18.12
-8,10,18:18.12
-6,10,18:18.12
-2,10,18:18.12
-1,10,18:18.12
0,10,18:18.12
1,10,18:18.12
2,10,18:18.12
3,10,18:18.12
4,10,18:18.12
5,10,18:18.4
6,10,18:18.4
7,10,18:18.4
9,10,18:18.4
12,10,18:18.4
13,10,18:18.4
14,10,18:18.4
15,10,18:18.4
-22,11,18:18.4
-21,11,18:18.4
-20,11,18:18.12
-13,11,18:18.12
-12,11,18:18.12
-11,11,18:18.12
-10,11,18:18.12
-9,11,18:18.12
-8,11,18:18.12
-7,11,18:18.12
-6,11,18:18.12
-5,11,18:18.12
-4,11,18:18.12
-3,11,18:18.12
-2,11,18:17.12
-1,11,18:17.12
0,11,18:18.12
1,11,18:18.12
2,11,18:18.12
3,11,18:18.12
4,11,18:18.12
5,11,18:18.4
6,11,18:18.4
7,11,18:18.4
8,11,18:18.4
9,11,18:18.4
10,11,18:18.4
13,11,18:18.4
14,11,18:18.4
15,11,18:18.4
-22,12,18:18.4
-21,12,18:18.4
-20,12,18:18.12
-19,12,18:18.12
-13,12,18:18.12
-12,12,18:18.12
-11,12,18:18.12
-10,12,18:18.12
-9,12,18:18.12
-8,12,18:18.12
-7,12,18:18.12
-6,12,18:18.12
-5,12,18:18.12
-4,12,18:18.12
-3,12,18:18.12
-2,12,18:18.12
-1,12,18:17.12
0,12,18:18.12
1,12,18:18.12
2,12,18:18.12
3,12,18:18.12
4,12,18:18.12
5,12,18:18.4
6,12,18:18.4
7,12,18:18.4
8,12,18:18.4
9,12,18:18.4
13,12,18:18.4
14,12,18:18.4
15,12,18:18.4
16,12,18:18.4
-22,13,18:18.4
-21,13,18:18.4
-20,13,18:18.12
-19,13,18:18.12
-13,13,18:18.12
-12,13,18:18.12
-11,13,18:18.12
-10,13,18:18.12
-9,13,18:18.12
-7,13,18:18.12
-6,13,18:18.12
-5,13,18:18.12
-4,13,18:18.12
-3,13,18:18.12
-2,13,18:18.12
-1,13,18:18.12
0,13,18:18.12
1,13,18:18.12
2,13,18:18.12
3,13,18:18.12
4,13,18:18.12
5,13,18:18.4
6,13,18:18.4
7,13,18:18.4
12,13,18:18.4
13,13,18:18.4
14,13,18:18.4
15,13,18:18.4
16,13,18:18.4
17,13,18:18.4
-21,14,18:18.4
-20,14,18:18.4
-18,14,18:18.12
-13,14,18:18.12
-12,14,18:18.12
-11,14,18:18.12
-10,14,18:18.12
-9,14,18:18.12
-8,14,18:18.12
-7,14,18:18.12
-6,14,18:18.12
-5,14,18:18.12
-4,14,18:18.12
-3,14,18:18.12
-2,14,18:18.12
-1,14,18:18.12
0,14,18:18.12
1,14,18:18.12
2,14,18:18.12
3,14,18:18.12
4,14,18:18.12
10,14,18:18.4
11,14,18:18.4
12,14,18:18.4
13,14,18:18.4
14,14,18:18.4
15,14,18:18.4
-21,15,18:18.4
-20,15,18:18.4
-19,15,18:18.4
-18,15,18:18.4
-13,15,18:18.4
-12,15,18:18.4
-11,15,18:18.4
-10,15,18:18.4
-9,15,18:18.4
-8,15,18:18.4
-7,15,18:18.12
-6,15,18:18.12
-5,15,18:18.12
-4,15,18:18.12
-3,15,18:18.12
-2,15,18:18.12
-1,15,18:18.12
0,15,18:18.12
1,15,18:18.12
2,15,18:18.12
9,15,18:18.4
10,15,18:18.4
11,15,18:18.4
12,15,18:18.4
13,15,18:18.4
-20,16,18:18.4
-19,16,18:18.4
-18,16,18:18.4
-17,16,18:18.4
-13,16,18:18.4
-12,16,18:18.4
-11,16,18:18.4
-10,16,18:18.4
-9,16,18:18.4
-8,16,18:18.4
-7,16,18:18.4
-6,16,18:18.4
-5,16,18:18.12
-4,16,18:18.12
-3,16,18:18.12
-2,16,18:18.12
-1,16,18:18.12
7,16,18:18.4
8,16,18:18.4
9,16,18:18.4
10,16,18:18.4
11,16,18:18.4
12,16,18:18.4
-20,17,18:18.4
-19,17,18:18.4
-18,17,18:18.4
-17,17,18:18.4
-12,17,18:18.4
-11,17,18:18.4
-10,17,18:18.4
-9,17,18:18.4
-8,17,18:18.4
-7,17,18:18.4
-6,17,18:18.4
-5,17,18:18.4
-4,17,18:18.4
-3,17,18:18.4
6,17,18:18.4
7,17,18:18.4
9,17,18:18.4
10,17,18:18.4
11,17,18:18.4
-19,18,18:18.4
-18,18,18:18.4
-17,18,18:18.4
-16,18,18:18.4
-12,18,18:18.4
-11,18,18:18.4
-10,18,18:18.4
-9,18,18:18.4
-8,18,18:18.4
-7,18,18:18.4
-6,18,18:18.4
5,18,18:18.4
6,18,18:18.4
7,18,18:18.4
8,18,18:18.4
9,18,18:18.4
-19,19,18:18.4
-18,19,18:18.4
-17,19,18:18.4
-16,19,18:18.4
-12,19,18:18.4
-11,19,18:18.4
-10,19,18:18.4
-9,19,18:18.4
-8,19,18:18.4
-7,19,18:18.4
3,19,18:18.4
4,19,18:18.4
5,19,18:18.4
6,19,18:18.4
7,19,18:18.4
8,19,18:18.4
-18,20,18:18.4
-17,20,18:18.4
-16,20,18:18.4
-15,20,18:18.4
-12,20,18:18.4
-11,20,18:18.4
-7,20,18:18.4
2,20,18:18.4
3,20,18:18.4
4,20,18:18.4
5,20,18:18.4
6,20,18:18.4
-17,21,18:18.4
-16,21,18:18.4
-15,21,18:18.4
-14,21,18:18.4
-8,21,18:18.4
-3,21,18:18.4
-2,21,18:18.4
-1,21,18:18.4
0,21,18:18.4
1,21,18:18.4
2,21,18:18.4
3,21,18:18.4
4,21,18:18.4
5,21,18:18.4
-17,22,18:18.4
-16,22,18:18.4
-15,22,18:18.4
-14,22,18:18.4
-10,22,18:18.4
-9,22,18:18.4
-8,22,18:18.4
-7,22,18:18.4
-6,22,18:18.4
-5,22,18:18.4
-4,22,18:18.4
-3,22,18:18.4
-2,22,18:18.4
-1,22,18:18.4
0,22,18:18.4
1,22,18:18.4
2,22,18:18.4
3,22,18:18.4
4,22,18:18.4
-16,23,18:18.4
-15,23,18:18.4
-14,23,18:18.4
-13,23,18:18.4
-12,23,18:18.4
-11,23,18:18.4
-10,23,18:18.4
-9,23,18:18.4
-8,23,18:18.4
-7,23,18:18.4
-6,23,18:18.4
-4,23,18:18.4
-3,23,18:18.4
-2,23,18:18.4
-1,23,18:18.4
0,23,18:18.4
1,23,18:18.4
2,23,18:18.4
-16,24,18:18.4
-15,24,18:18.4
-14,24,18:18.4
-13,24,18:18.4
-12,24,18:18.4
-11,24,18:18.4
-10,24,18:18.4
-9,24,18:18.4
-8,24,18:18.4
-7,24,18:18.4
-6,24,18:18.4
-5,24,18:18.4
-4,24,18:18.4
-3,24,18:18.4
-2,24,18:18.4
-15,25,18:18.4
-14,25,18:18.4
-13,25,18:18.4
-12,25,18:18.4
-11,25,18:18.4
-10,25,18:18.4
-9,25,18:18.4
-8,25,18:18.4
-15,26,18:18.4
3,-10,19:18.4
0,-9,19:18.4
1,-9,19:18.4
2,-9,19:18.4
3,-9,19:18.4
-4,-8,19:18.4
-3,-8,19:18.4
-2,-8,19:18.4
-1,-8,19:18.4
0,-8,19:18.4
1,-8,19:18.4
2,-8,19:18.4
3,-8,19:18.4
4,-8,19:18.4
-9,-7,19:18.4
-8,-7,19:18.4
-7,-7,19:18.4
-6,-7,19:18.4
-5,-7,19:18.4
-4,-7,19:18.4
-3,-7,19:18.4
-2,-7,19:18.4
-1,-7,19:18.4
0,-7,19:18.4
1,-7,19:18.4
3,-7,19:18.4
4,-7,19:18.4
-11,-6,19:18.4
-10,-6,19:18.4
-9,-6,19:18.4
-8,-6,19:18.4
-7,-6,19:18.4
-6,-6,19:18.4
-5,-6,19:18.4
-4,-6,19:18.4
-3,-6,19:18.4
-2,-6,19:18.4
-1,-6,19:18.4
0,-6,19:18.4
1,-6,19:18.4
2,-6,19:18.4
3,-6,19:18.4
4,-6,19:18.4
5,-6,19:18.4
-13,-5,19:18.4
-12,-5,19:18.4
-11,-5,19:18.4
-10,-5,19:18.4
-9,-5,19:18.4
-8,-5,19:18.4
-7,-5,19:18.4
-6,-5,19:18.4
-5,-5,19:18.4
-4,-5,19:18.4
-3,-5,19:18.4
2,-5,19:18.4
3,-5,19:18.4
4,-5,19:18.4
5,-5,19:18.4
-14,-4,19:18.4
-13,-4,19:18.4
-12,-4,19:18.4
-11,-4,19:18.4
-10,-4,19:18.4
-9,-4,19:18.4
-8,-4,19:18.4
-7,-4,19:18.4
3,-4,19:18.4
4,-4,19:18.4
5,-4,19:18.4
6,-4,19:18.4
-15,-3,19:18.4
-14,-3,19:18.4
-13,-3,19:18.4
-12,-3,19:18.4
-11,-3,19:18.4
-10,-3,19:18.4
3,-3,19:18.12
4,-3,19:18.4
5,-3,19:18.4
6,-3,19:18.4
-16,-2,19:18.4
-15,-2,19:18.4
-14,-2,19:18.4
-13,-2,19:18.4
-12,-2,19:18.4
4,-2,19:18.4
5,-2,19:18.4
6,-2,19:18.4
7,-2,19:18.4
-18,-1,19:18.4
-17,-1,19:18.4
-16,-1,19:18.4
-15,-1,19:18.4
-14,-1,19:18.4
-13,-1,19:18.4
4,-1,19:18.4
5,-1,19:18.4
6,-1,19:18.4
7,-1,19:18.4
-19,0,19:18.4
-18,0,19:18.4
-17,0,19:18.4
-16,0,19:18.4
-15,0,19:18.4
-14,0,19:18.4
5,0,19:18.4
6,0,19:18.4
7,0,19:18.4
8,0,19:18.4
-20,1,19:18.4
-19,1,19:18.4
-18,1,19:18.4
-17,1,19:18.4
-16,1,19:18.4
5,1,19:18.4
6,1,19:18.4
7,1,19:18.4
8,1,19:18.4
9,1,19:18.4
-23,2,19:18.4
-22,2,19:18.4
-21,2,19:18.4
-20,2,19:18.4
-19,2,19:18.4
-18,2,19:18.4
-17,2,19:18.4
-3,2,19:18.12
-2,2,19:18.12
6,2,19:18.4
7,2,19:18.4
8,2,19:18.4
9,2,19:18.4
-21,3,19:18.4
-20,3,19:18.4
-19,3,19:18.4
-18,3,19:18.4
-4,3,19:18.12
-3,3,19:18.12
-2,3,19:18.12
6,3,19:18.4
7,3,19:18.4
8,3,19:18.4
9,3,19:18.4
-21,4,19:18.4
-20,4,19:18.12
-19,4,19:18.12
-6,4,19:18.12
-5,4,19:18.12
-4,4,19:18.12
-3,4,19:18.12
-2,4,19:18.12
7,4,19:18.4
8,4,19:18.4
9,4,19:18.4
10,4,19:18.4
-21,5,19:18.4
-20,5,19:18.12
-19,5,19:18.12
-18,5,19:18.12
-9,5,19:18.12
-8,5,19:18.4
-7,5,19:18.12
-6,5,19:18.12
-5,5,19:18.12
-4,5,19:18.12
-3,5,19:18.12
-2,5,19:18.12
7,5,19:18.4
8,5,19:18.4
9,5,19:18.4
10,5,19:18.4
-21,6,19:18.4
-20,6,19:18.12
-19,6,19:18.12
-18,6,19:18.12
-10,6,19:18.12
-9,6,19:18.12
-8,6,19:18.12
-7,6,19:18.12
-6,6,19:18.12
-5,6,19:18.12
-4,6,19:18.12
-3,6,19:18.12
-2,6,19:18.12
-1,6,19:18.12
8,6,19:18.4
9,6,19:18.4
10,6,19:18.4
-20,7,19:18.12
-19,7,19:18.12
-18,7,19:18.12
-9,7,19:18.12
-8,7,19:18.12
-7,7,19:18.12
-6,7,19:18.12
-5,7,19:18.12
-4,7,19:18.12
-3,7,19:18.12
-2,7,19:18.12
-1,7,19:18.12
8,7,19:18.4
9,7,19:18.4
10,7,19:18.4
11,7,19:18.4
-20,8,19:18.12
-19,8,19:18.12
-18,8,19:18.12
-17,8,19:18.12
-8,8,19:18.12
-7,8,19:18.12
-6,8,19:18.12
-5,8,19:18.12
-4,8,19:18.12
-3,8,19:18.12
-2,8,19:18.12
-1,8,19:18.12
0,8,19:18.12
8,8,19:18.4
9,8,19:18.4
10,8,19:18.4
-20,9,19:18.12
-19,9,19:18.12
-18,9,19:18.12
-17,9,19:18.12
-8,9,19:18.12
-7,9,19:18.12
-6,9,19:18.12
-5,9,19:18.12
-4,9,19:18.12
-3,9,19:18.12
-2,9,19:18.12
-1,9,19:18.12
0,9,19:18.12
9,9,19:18.4
10,9,19:18.4
11,9,19:18.4
-19,10,19:18.12
-18,10,19:18.12
-17,10,19:18.12
-7,10,19:18.12
-6,10,19:18.12
-5,10,19:18.12
-4,10,19:18.12
-3,10,19:18.12
-2,10,19:18.12
9,10,19:18.4
10,10,19:18.4
11,10,19:18.4
12,10,19:18.4
-19,11,19:18.12
-18,11,19:18.12
-17,11,19:18.12
-16,11,19:18.12
-7,11,19:18.12
-6,11,19:18.12
-5,11,19:18.12
-4,11,19:18.12
-1,11,19:17.12
0,11,19:17.12
9,11,19:18.4
10,11,19:18.4
11,11,19:18.4
12,11,19:18.4
-19,12,19:18.12
-18,12,19:18.12
-17,12,19:18.12
-16,12,19:18.12
-7,12,19:18.12
-6,12,19:18.12
-1,12,19:17.12
0,12,19:17.12
8,12,19:18.4
9,12,19:18.4
10,12,19:18.4
11,12,19:18.4
12,12,19:18.4
13,12,19:18.4
-18,13,19:18.12
-17,13,19:18.12
-16,13,19:18.12
7,13,19:18.4
8,13,19:18.4
9,13,19:18.4
10,13,19:18.4
11,13,19:18.4
14,13,19:18.4
-18,14,19:18.12
-17,14,19:18.12
-16,14,19:18.12
-15,14,19:18.12
5,14,19:18.4
6,14,19:18.4
7,14,19:18.4
8,14,19:18.4
9,14,19:18.4
10,14,19:18.4
-17,15,19:18.4
-16,15,19:18.4
-15,15,19:18.4
-14,15,19:18.4
4,15,19:18.12
5,15,19:18.4
6,15,19:18.4
7,15,19:18.4
8,15,19:18.4
9,15,19:18.4
-17,16,19:18.4
-16,16,19:18.4
-15,16,19:18.4
-14,16,19:18.4
3,16,19:18.12
4,16,19:18.12
5,16,19:18.4
6,16,19:18.4
7,16,19:18.4
-16,17,19:18.4
-15,17,19:18.4
-14,17,19:18.4
-13,17,19:18.4
1,17,19:18.4
2,17,19:18.4
3,17,19:18.4
4,17,19:18.4
5,17,19:18.4
6,17,19:18.4
-16,18,19:18.4
-15,18,19:18.4
-14,18,19:18.4
-13,18,19:18.4
-1,18,19:18.4
0,18,19:18.4
1,18,19:18.4
2,18,19:18.4
3,18,19:18.4
4,18,19:18.4
-15,19,19:18.4
-14,19,19:18.4
-13,19,19:18.4
-12,19,19:18.4
-8,19,19:18.4
-7,19,19:18.4
-6,19,19:18.4
-4,19,19:18.4
-3,19,19:18.4
-2,19,19:18.4
-1,19,19:18.4
0,19,19:18.4
1,19,19:18.4
2,19,19:18.4
3,19,19:18.4
-15,20,19:18.4
-14,20,19:18.4
-13,20,19:18.4
-12,20,19:18.4
-11,20,19:18.4
-10,20,19:18.4
-9,20,19:18.4
-8,20,19:18.4
-7,20,19:18.4
-6,20,19:18.4
-5,20,19:18.4
-4,20,19:18.4
-3,20,19:18.4
-2,20,19:18.4
-1,20,19:18.4
0,20,19:18.4
1,20,19:18.4
2,20,19:18.4
-14,21,19:18.4
-13,21,19:18.4
-12,21,19:18.4
-11,21,19:18.4
-10,21,19:18.4
-9,21,19:18.4
-8,21,19:18.4
-7,21,19:18.4
-6,21,19:18.4
-5,21,19:18.4
-4,21,19:18.4
-3,21,19:18.4
-2,21,19:18.4
-1,21,19:18.4
0,21,19:18.4
-14,22,19:18.4
-13,22,19:18.4
-12,22,19:18.4
-11,22,19:18.4
-10,22,19:18.4
-9,22,19:18.4
-8,22,19:18.4
-7,22,19:18.4
-14,23,19:18.4
-13,23,19:18.4
-14,24,19:18.4
3,-11,20:18.4
3,-10,20:18.4
3,-9,20:18.4
2,-8,20:18.4
1,-6,20:18.4
-4,-5,20:18.4
-3,-5,20:18.4
-2,-5,20:18.4
-1,-5,20:18.4
0,-5,20:18.4
1,-5,20:18.4
2,-5,20:18.4
-8,-4,20:18.4
-7,-4,20:18.4
-6,-4,20:18.12
-5,-4,20:18.12
-4,-4,20:18.12
-3,-4,20:18.12
-1,-4,20:18.12
0,-4,20:18.12
1,-4,20:18.12
2,-4,20:18.12
-10,-3,20:18.4
-9,-3,20:18.4
-8,-3,20:18.4
-7,-3,20:18.4
-6,-3,20:18.12
-5,-3,20:18.12
-4,-3,20:18.12
-3,-3,20:18.12
-2,-3,20:18.12
-1,-3,20:18.12
0,-3,20:18.12
2,-3,20:18.12
3,-3,20:18.12
-11,-2,20:18.4
-10,-2,20:18.4
-9,-2,20:18.4
-8,-2,20:18.4
-7,-2,20:18.4
-6,-2,20:18.12
-5,-2,20:18.12
-4,-2,20:18.12
-3,-2,20:18.12
-2,-2,20:18.12
0,-2,20:18.12
1,-2,20:18.12
2,-2,20:18.12
3,-2,20:18.12
-13,-1,20:18.4
-12,-1,20:18.4
-11,-1,20:18.4
-10,-1,20:18.4
-9,-1,20:18.4
-8,-1,20:18.4
-7,-1,20:18.4
-6,-1,20:18.12
1,-1,20:18.12
2,-1,20:18.12
3,-1,20:18.12
4,-1,20:18.4
-14,0,20:18.4
-13,0,20:18.4
-12,0,20:18.4
-11,0,20:18.4
-10,0,20:18.4
-9,0,20:18.4
1,0,20:18.12
2,0,20:18.12
3,0,20:18.12
4,0,20:18.4
-15,1,20:18.4
-14,1,20:18.4
-13,1,20:18.4
-12,1,20:18.4
-11,1,20:18.4
2,1,20:18.12
3,1,20:18.12
4,1,20:18.4
5,1,20:18.4
-23,2,20:18.4
-22,2,20:18.4
-21,2,20:18.4
-17,2,20:18.4
-16,2,20:18.4
-15,2,20:18.4
-14,2,20:18.4
-13,2,20:18.4
-12,2,20:18.4
2,2,20:18.12
3,2,20:18.12
4,2,20:18.4
5,2,20:18.4
6,2,20:18.4
-21,3,20:18.4
-20,3,20:18.4
-19,3,20:18.4
-18,3,20:18.4
-17,3,20:18.4
-16,3,20:18.4
-15,3,20:18.4
-14,3,20:18.4
-13,3,20:18.4
3,3,20:18.12
4,3,20:18.4
5,3,20:18.4
6,3,20:18.4
-18,4,20:18.12
-17,4,20:18.12
-16,4,20:18.12
-15,4,20:18.12
3,4,20:18.12
4,4,20:18.4
5,4,20:18.4
6,4,20:18.4
-18,5,20:18.12
-17,5,20:18.12
-16,5,20:18.12
-15,5,20:18.12
4,5,20:18.4
5,5,20:18.4
6,5,20:18.4
7,5,20:18.4
-17,6,20:18.12
-16,6,20:18.12
-15,6,20:18.12
4,6,20:18.4
5,6,20:18.4
6,6,20:18.4
7,6,20:18.4
-16,7,20:18.12
-15,7,20:18.12
5,7,20:18.4
6,7,20:18.4
7,7,20:18.4
-17,8,20:18.12
-16,8,20:18.12
-15,8,20:18.12
-14,8,20:18.12
5,8,20:18.4
6,8,20:18.4
7,8,20:18.4
8,8,20:18.4
-17,9,20:18.12
-16,9,20:18.12
-15,9,20:18.12
-14,9,20:18.12
5,9,20:18.4
6,9,20:18.4
7,9,20:18.4
8,9,20:18.4
-16,10,20:18.12
-15,10,20:18.12
-14,10,20:18.12
6,10,20:18.4
7,10,20:18.4
-16,11,20:18.12
-15,11,20:18.12
-13,11,20:18.12
-1,11,20:17.12
5,11,20:18.4
6,11,20:18.4
7,11,20:18.4
8,11,20:18.4
9,11,20:18.4
-16,12,20:18.12
-15,12,20:18.12
-14,12,20:18.12
-13,12,20:18.12
3,12,20:18.12
4,12,20:18.12
5,12,20:18.4
6,12,20:18.4
7,12,20:18.4
8,12,20:18.4
10,12,20:18.4
11,12,20:18.4
12,12,20:18.4
13,12,20:18.4
-15,13,20:18.12
-14,13,20:18.12
-13,13,20:18.12
-12,13,20:18.12
2,13,20:18.12
3,13,20:18.12
4,13,20:18.12
5,13,20:18.4
6,13,20:18.4
7,13,20:18.4
13,13,20:18.4
14,13,20:18.4
15,13,20:18.4
-15,14,20:18.4
-14,14,20:18.4
-13,14,20:18.4
-12,14,20:18.4
1,14,20:18.12
2,14,20:18.12
3,14,20:18.12
4,14,20:18.12
5,14,20:18.4
-14,15,20:18.4
-13,15,20:18.4
-12,15,20:18.4
-11,15,20:18.4
-1,15,20:18.12
0,15,20:18.12
1,15,20:18.12
2,15,20:18.12
3,15,20:18.12
4,15,20:18.12
-13,16,20:18.4
-12,16,20:18.4
-11,16,20:18.4
-7,16,20:18.4
-6,16,20:18.4
-5,16,20:18.12
-4,16,20:18.12
-3,16,20:18.12
-2,16,20:18.12
-1,16,20:18.12
0,16,20:18.12
1,16,20:18.12
2,16,20:18.12
-13,17,20:18.4
-12,17,20:18.4
-11,17,20:18.4
-10,17,20:18.4
-9,17,20:18.4
-8,17,20:18.4
-7,17,20:18.4
-6,17,20:18.4
-5,17,20:18.4
-4,17,20:18.4
-3,17,20:18.4
-2,17,20:18.4
-1,17,20:18.4
0,17,20:18.4
1,17,20:18.4
-12,18,20:18.4
-11,18,20:18.4
-10,18,20:18.4
-9,18,20:18.4
-8,18,20:18.4
-7,18,20:18.4
-6,18,20:18.4
-5,18,20:18.4
-4,18,20:18.4
-3,18,20:18.4
-2,18,20:18.4
-1,18,20:18.4
-12,19,20:18.4
-11,19,20:18.4
-10,19,20:18.4
-9,19,20:18.4
-8,19,20:18.4
-7,19,20:18.4
-6,19,20:18.4
-12,20,20:18.4
-13,21,20:18.4
-12,21,20:18.4
-13,22,20:18.4
-14,23,20:18.4
-14,24,20:18.4
-15,25,20:18.4
3,-11,21:18.4
3,-10,21:18.4
2,-9,21:18.4
3,-9,21:18.4
2,-8,21:18.4
1,-6,21:18.4
1,-5,21:18.4
0,-4,21:18.12
0,-3,21:18.12
-3,-2,21:18.12
-2,-2,21:18.12
-1,-2,21:18.12
0,-2,21:18.12
-7,-1,21:18.4
-6,-1,21:18.12
-5,-1,21:18.12
-4,-1,21:18.12
-3,-1,21:18.12
-2,-1,21:18.12
-1,-1,21:18.12
0,-1,21:18.12
-9,0,21:18.4
-8,0,21:18.4
-7,0,21:18.4
-6,0,21:18.12
-5,0,21:18.12
-4,0,21:18.12
-3,0,21:18.12
-2,0,21:18.12
-1,0,21:18.12
0,0,21:18.12
1,0,21:18.12
-10,1,21:18.4
-9,1,21:18.4
-8,1,21:18.4
-7,1,21:18.4
-6,1,21:18.12
-5,1,21:18.12
-4,1,21:18.12
-3,1,21:18.12
-2,1,21:18.12
-1,1,21:18.12
0,1,21:18.12
1,1,21:18.12
-22,2,21:18.4
-12,2,21:18.4
-11,2,21:18.4
-10,2,21:18.4
-9,2,21:18.4
-8,2,21:18.4
-7,2,21:18.4
-6,2,21:18.12
-5,2,21:18.12
-1,2,21:18.12
0,2,21:18.12
1,2,21:18.12
2,2,21:18.12
-21,3,21:18.4
-20,3,21:18.4
-19,3,21:18.4
-13,3,21:18.4
-12,3,21:18.4
-11,3,21:18.4
-10,3,21:18.4
-9,3,21:18.4
-8,3,21:18.4
-1,3,21:18.12
0,3,21:18.12
1,3,21:18.12
2,3,21:18.12
-18,4,21:18.12
-17,4,21:18.12
-16,4,21:18.12
-15,4,21:18.12
-14,4,21:18.12
-13,4,21:18.12
-12,4,21:18.12
-11,4,21:18.12
-10,4,21:18.4
0,4,21:18.12
1,4,21:18.12
2,4,21:18.12
3,4,21:18.12
-15,5,21:18.12
-14,5,21:18.12
-13,5,21:18.12
-12,5,21:18.12
-11,5,21:18.12
0,5,21:18.12
1,5,21:18.12
2,5,21:18.12
3,5,21:18.12
-14,6,21:18.12
-13,6,21:18.12
-12,6,21:18.12
1,6,21:18.12
2,6,21:18.12
3,6,21:18.12
4,6,21:18.4
-14,7,21:18.12
-13,7,21:18.12
-12,7,21:18.12
-11,7,21:18.12
1,7,21:18.12
2,7,21:18.12
3,7,21:18.12
4,7,21:18.12
-14,8,21:18.12
-13,8,21:18.12
-12,8,21:18.12
-11,8,21:18.12
2,8,21:18.12
3,8,21:18.12
4,8,21:18.12
-13,9,21:18.12
-12,9,21:18.12
-11,9,21:18.12
2,9,21:18.12
3,9,21:18.12
4,9,21:18.12
5,9,21:18.4
-13,10,21:18.12
-12,10,21:18.12
-11,10,21:18.12
-10,10,21:18.4
1,10,21:18.12
2,10,21:18.12
3,10,21:18.12
4,10,21:18.12
5,10,21:18.4
-13,11,21:18.12
-12,11,21:18.12
-11,11,21:18.12
-10,11,21:18.4
0,11,21:18.12
1,11,21:18.12
2,11,21:18.12
3,11,21:18.12
4,11,21:18.12
5,11,21:18.4
6,11,21:18.4
7,11,21:18.4
8,11,21:18.4
9,11,21:18.4
-12,12,21:18.12
-11,12,21:18.12
-10,12,21:18.4
-9,12,21:18.4
-1,12,21:18.12
0,12,21:18.12
1,12,21:18.12
2,12,21:18.12
3,12,21:18.12
9,12,21:18.4
10,12,21:18.4
11,12,21:18.4
12,12,21:18.4
-12,13,21:18.12
-11,13,21:18.12
-10,13,21:18.4
-9,13,21:18.4
-5,13,21:18.12
-4,13,21:18.12
-3,13,21:18.12
-2,13,21:18.12
-1,13,21:18.12
0,13,21:18.12
1,13,21:18.12
2,13,21:18.12
12,13,21:18.4
13,13,21:18.4
14,13,21:18.4
-11,14,21:18.4
-10,14,21:18.4
-9,14,21:18.4
-8,14,21:18.4
-7,14,21:18.12
-6,14,21:18.12
-5,14,21:18.12
-4,14,21:18.12
-3,14,21:18.12
-2,14,21:18.12
-1,14,21:18.12
0,14,21:18.12
-11,15,21:18.4
-10,15,21:18.4
-9,15,21:18.4
-8,15,21:18.4
-7,15,21:18.4
-6,15,21:18.12
-5,15,21:18.12
-4,15,21:18.12
-3,15,21:18.12
-2,15,21:18.12
-1,15,21:18.12
-10,16,21:18.4
-9,16,21:18.4
-8,16,21:18.4
-7,16,21:18.4
-6,16,21:18.4
-5,16,21:18.12
-4,16,21:18.12
-10,17,21:18.4
-11,18,21:18.4
-12,19,21:18.4
-11,19,21:18.4
-12,20,21:18.4
-13,21,21:18.4
-12,21,21:18.4
-13,22,21:18.4
-14,23,21:18.4
-15,24,21:18.4
-14,24,21:18.4
-15,25,21:18.4
3,-10,22:18.4
2,-9,22:18.4
3,-9,22:18.4
2,-8,22:18.4
1,-6,22:18.4
1,-5,22:18.4
0,-4,22:18.4
0,-3,22:18.4
4,-3,22:18.4
-1,-2,22:18.4
0,-2,22:18.4
3,-2,22:18.4
-1,-1,22:18.4
2,-1,22:18.4
-2,0,22:18.4
-1,0,22:18.4
1,0,22:18.4
-2,1,22:18.4
0,1,22:18.4
1,1,22:18.4
-6,2,22:18.4
-5,2,22:18.4
-4,2,22:18.4
-3,2,22:18.4
-2,2,22:18.4
-1,2,22:18.4
0,2,22:18.4
-21,3,22:18.4
-20,3,22:18.4
-19,3,22:18.4
-8,3,22:18.4
-7,3,22:18.4
-6,3,22:18.4
-5,3,22:18.4
-4,3,22:18.4
-3,3,22:18.4
-2,3,22:18.4
-1,3,22:18.4
-18,4,22:18.12
-17,4,22:18.12
-16,4,22:18.12
-15,4,22:18.12
-8,4,22:18.4
-7,4,22:18.4
-6,4,22:18.4
-5,4,22:18.4
-4,4,22:18.4
-3,4,22:18.4
-2,4,22:18.4
-1,4,22:18.4
-15,5,22:18.12
-14,5,22:18.12
-13,5,22:18.12
-12,5,22:18.12
-11,5,22:18.4
-10,5,22:18.4
-9,5,22:18.4
-8,5,22:18.4
-7,5,22:18.4
-6,5,22:18.4
-5,5,22:18.4
-3,5,22:18.4
-2,5,22:18.4
-1,5,22:18.4
0,5,22:18.4
-12,6,22:18.12
-11,6,22:18.4
-10,6,22:18.4
-9,6,22:18.4
-8,6,22:18.4
-7,6,22:18.4
-3,6,22:18.4
-2,6,22:18.4
-1,6,22:18.4
0,6,22:18.4
-13,7,22:18.12
-12,7,22:18.12
-11,7,22:18.4
-10,7,22:18.4
-9,7,22:18.4
-8,7,22:18.4
-2,7,22:18.12
-1,7,22:18.12
0,7,22:18.12
1,7,22:18.12
-11,8,22:18.4
-10,8,22:18.4
-9,8,22:18.4
-8,8,22:18.4
-2,8,22:18.12
-1,8,22:18.12
0,8,22:18.12
1,8,22:18.12
-10,9,22:18.4
-9,9,22:18.4
-8,9,22:18.4
-2,9,22:18.12
-1,9,22:18.12
0,9,22:18.12
1,9,22:18.12
2,9,22:18.12
-10,10,22:18.4
-9,10,22:18.4
-8,10,22:18.4
-7,10,22:18.4
-4,10,22:18.12
-3,10,22:18.12
-2,10,22:18.12
-1,10,22:18.12
0,10,22:18.12
1,10,22:18.12
2,10,22:18.12
3,10,22:18.12
4,10,22:18.12
-10,11,22:18.4
-9,11,22:18.4
-8,11,22:18.4
-7,11,22:18.4
-6,11,22:18.12
-5,11,22:18.12
-4,11,22:18.12
-3,11,22:18.12
-2,11,22:18.12
-1,11,22:18.12
0,11,22:18.12
5,11,22:18.4
6,11,22:18.4
7,11,22:18.4
8,11,22:18.4
-9,12,22:18.4
-8,12,22:18.4
-7,12,22:18.4
-6,12,22:18.12
-5,12,22:18.12
-4,12,22:18.12
-3,12,22:18.12
-2,12,22:18.12
8,12,22:18.4
9,12,22:18.4
10,12,22:18.4
11,12,22:18.4
-7,13,22:18.4
-6,13,22:18.12
-5,13,22:18.12
-4,13,22:18.12
-3,13,22:18.12
12,13,22:18.4
13,13,22:18.4
-9,14,22:18.4
-8,14,22:18.4
-9,15,22:18.4
-10,16,22:18.4
-10,17,22:18.4
-11,18,22:18.4
-12,19,22:18.4
-11,19,22:18.4
-12,20,22:18.4
-13,21,22:18.4
-13,22,22:18.4
1,-6,23:18.4
1,-5,23:18.4
0,-4,23:18.4
0,-3,23:18.4
4,-3,23:18.4
-1,-2,23:18.4
3,-2,23:18.4
-1,-1,23:18.4
2,-1,23:18.4
-2,0,23:18.4
-1,0,23:18.4
1,0,23:18.4
-2,1,23:18.4
0,1,23:18.4
1,1,23:18.4
-3,2,23:18.4
-2,2,23:18.4
0,2,23:18.4
-3,3,23:18.4
-1,3,23:18.4
-18,4,23:18.4
-17,4,23:18.4
-16,4,23:18.4
-3,4,23:18.4
-2,4,23:18.4
-15,5,23:18.4
-14,5,23:18.4
-13,5,23:18.4
-6,5,23:18.4
-5,5,23:18.4
-4,5,23:18.4
-3,5,23:18.4
-2,5,23:18.4
-18,6,23:18.4
-17,6,23:18.4
-15,6,23:18.4
-12,6,23:18.4
-11,6,23:18.4
-10,6,23:18.4
-9,6,23:18.4
-7,6,23:18.4
-6,6,23:18.4
-5,6,23:18.4
-4,6,23:18.4
-3,6,23:18.4
-13,7,23:18.4
-12,7,23:18.4
-11,7,23:18.4
-10,7,23:18.4
-9,7,23:18.4
-8,7,23:18.4
-7,7,23:18.4
-6,7,23:18.4
-5,7,23:18.12
-4,7,23:18.12
-3,7,23:18.12
-8,8,23:18.4
-7,8,23:18.4
-6,8,23:18.4
-5,8,23:18.12
-4,8,23:18.12
-3,8,23:18.12
-2,8,23:18.12
-7,9,23:18.4
-6,9,23:18.4
-5,9,23:18.12
-4,9,23:18.12
-3,9,23:18.12
-2,9,23:18.12
-1,9,23:18.12
0,9,23:18.12
-7,10,23:18.4
-6,10,23:18.4
-5,10,23:18.12
-4,10,23:18.12
1,10,23:18.12
2,10,23:18.12
3,10,23:18.12
4,10,23:18.12
-7,11,23:18.4
4,11,23:18.12
5,11,23:18.4
6,11,23:18.4
7,11,23:18.4
-8,12,23:18.4
-7,12,23:18.4
-3,12,23:18.12
8,12,23:18.4
9,12,23:18.4
10,12,23:18.4
-3,13,23:18.12
11,13,23:18.4
12,13,23:18.4
13,13,23:18.4
-9,14,23:18.4
-8,14,23:18.4
-2,14,23:18.12
-9,15,23:18.4
-2,15,23:18.12
-10,16,23:18.4
-1,16,23:18.12
-11,17,23:18.4
-10,17,23:18.4
-11,18,23:18.4
-12,19,23:18.4
-11,19,23:18.4
-12,20,23:18.4
-13,21,23:18.4
-14,22,23:18.4
-13,22,23:18.4
-14,23,23:18.4
-15,24,23:18.4
-14,24,23:18.4
2,-8,24:18.4
1,-7,24:18.4
1,-6,24:18.4
1,-5,24:18.4
0,-4,24:18.4
0,-3,24:18.4
-1,-2,24:18.4
-1,-1,24:18.4
2,-1,24:18.4
-2,0,24:18.4
1,0,24:18.4
-2,1,24:18.4
0,1,24:18.4
1,1,24:18.4
-3,2,24:18.4
-2,2,24:18.4
0,2,24:18.4
-3,3,24:18.4
-1,3,24:18.4
-18,4,24:18.4
-17,4,24:18.4
-16,4,24:18.4
-4,4,24:18.4
-3,4,24:18.4
-2,4,24:18.4
-15,5,24:18.4
-14,5,24:18.4
-13,5,24:18.4
-4,5,24:18.4
-3,5,24:18.4
-18,6,24:18.4
-17,6,24:18.4
-16,6,24:18.4
-15,6,24:18.4
-12,6,24:18.4
-11,6,24:18.4
-10,6,24:18.4
-4,6,24:18.4
-3,6,24:18.4
-14,7,24:18.4
-13,7,24:18.4
-12,7,24:18.4
-11,7,24:18.4
-10,7,24:18.4
-9,7,24:18.4
-8,7,24:18.4
-7,7,24:18.4
-6,7,24:18.4
-5,7,24:18.12
-4,7,24:18.12
-5,8,24:18.12
-4,8,24:18.12
-3,8,24:18.12
-4,9,24:18.12
-2,9,24:18.12
-1,9,24:18.12
0,9,24:18.12
-6,10,24:18.4
-4,10,24:18.12
1,10,24:18.12
2,10,24:18.12
3,10,24:18.12
4,10,24:18.4
-7,11,24:18.4
-3,11,24:18.12
4,11,24:18.4
5,11,24:18.4
6,11,24:18.4
7,11,24:18.4
-8,12,24:18.4
-7,12,24:18.4
-3,12,24:18.12
8,12,24:18.4
9,12,24:18.4
10,12,24:18.4
-3,13,24:18.12
11,13,24:18.4
12,13,24:18.4
-9,14,24:18.4
-8,14,24:18.4
-2,14,24:18.12
-9,15,24:18.4
-2,15,24:18.12
-10,16,24:18.4
-1,16,24:18.4
-11,17,24:18.4
-10,17,24:18.4
-1,17,24:18.4
-11,18,24:18.4
-1,18,24:18.4
-12,19,24:18.4
-11,19,24:18.4
0,19,24:18.4
-12,20,24:18.4
0,20,24:18.4
-13,21,24:18.4
1,-6,25:18.4
0,-4,25:18.4
-1,-3,25:18.4
0,-3,25:18.4
-1,-2,25:18.4
3,-2,25:18.4
-1,-1,25:18.4
2,-1,25:18.4
1,0,25:18.4
2,0,25:18.4
-2,1,25:18.4
0,1,25:18.4
1,1,25:18.4
-3,2,25:18.4
0,2,25:18.4
-3,3,25:18.4
-1,3,25:18.4
-16,4,25:18.4
-4,4,25:18.4
-2,4,25:18.4
-15,5,25:18.4
-4,5,25:18.4
-3,5,25:18.4
-2,5,25:18.4
-3,6,25:18.4
-14,7,25:18.4
-13,7,25:18.4
-12,7,25:18.4
-11,7,25:18.4
-10,7,25:18.4
-9,7,25:18.4
-8,7,25:18.4
-7,7,25:18.4
-5,7,25:18.4
-4,7,25:18.4
-5,8,25:18.4
-4,8,25:18.4
-4,9,25:18.4
-1,9,25:18.4
0,9,25:18.4
1,9,25:18.4
-4,10,25:18.4
1,10,25:18.4
2,10,25:18.4
3,10,25:18.4
4,10,25:18.4
-3,11,25:18.4
5,11,25:18.4
6,11,25:18.4
7,11,25:18.4
-3,12,25:18.4
8,12,25:18.4
-3,13,25:18.4
-9,14,25:18.4
-8,14,25:18.4
-2,14,25:18.4
-9,15,25:18.4
-2,15,25:18.4
-10,16,25:18.4
-10,17,25:18.4
-1,17,25:18.4
-11,18,25:18.4
-1,18,25:18.4
-12,19,25:18.4
-11,19,25:18.4
0,19,25:18.4
-12,20,25:18.4
0,20,25:18.4
-1,-3,26:18.4
-1,-2,26:18.4
3,-2,26:18.4
-2,-1,26:18.4
2,-1,26:18.4
-2,0,26:18.4
1,0,26:18.4
2,0,26:18.4
-3,1,26:18.4
0,1,26:18.4
1,1,26:18.4
-3,2,26:18.4
0,2,26:18.4
-1,3,26:18.4
-2,4,26:18.4
-3,5,26:18.4
-2,5,26:18.4
-17,6,26:18.4
-16,6,26:18.4
-15,6,26:18.4
-4,6,26:18.4
-15,7,26:18.4
-14,7,26:18.4
-13,7,26:18.4
-12,7,26:18.4
-11,7,26:18.4
-10,7,26:18.4
-9,7,26:18.4
-8,7,26:18.4
-6,7,26:18.4
-5,7,26:18.4
-4,7,26:18.4
-5,8,26:18.4
-4,8,26:18.4
-4,10,26:18.4
3,10,26:18.4
4,10,26:18.4
-3,11,26:18.4
5,11,26:18.4
6,11,26:18.4
7,11,26:18.4
-3,12,26:18.4
8,12,26:18.4
-3,13,26:18.4
-2,13,26:18.4
-2,14,26:18.4
-2,15,26:18.4
-10,16,26:18.4
-1,16,26:18.4
-10,17,26:18.4
-1,17,26:18.4
-11,18,26:18.4
-1,18,26:18.4
-11,19,26:18.4
-12,20,26:18.4
-2,-3,27:18.4
-1,-3,27:18.4
-1,-2,27:18.4
0,-2,27:18.4
1,-2,27:18.4
2,-2,27:18.4
3,-2,27:18.4
-2,-1,27:18.4
2,-1,27:18.4
3,-1,27:18.4
-3,0,27:18.4
-2,0,27:18.4
1,0,27:18.4
2,0,27:18.4
3,0,27:18.4
-3,1,27:18.4
0,1,27:18.4
1,1,27:18.4
3,1,27:18.4
4,1,27:18.4
-3,2,27:18.4
0,2,27:18.4
4,2,27:18.4
5,2,27:18.4
-1,3,27:18.4
5,3,27:18.4
-2,4,27:18.4
-3,5,27:18.4
-2,5,27:18.4
6,5,27:18.4
-18,6,27:18.4
-17,6,27:18.4
-16,6,27:18.4
-4,6,27:18.4
-3,6,27:18.4
-15,7,27:18.4
-14,7,27:18.4
-13,7,27:18.4
-12,7,27:18.4
-11,7,27:18.4
-10,7,27:18.4
-9,7,27:18.4
-8,7,27:18.4
-7,7,27:18.4
-6,7,27:18.4
-5,7,27:18.4
-4,7,27:18.4
-5,8,27:18.4
-4,8,27:18.4
-4,9,27:18.4
-4,10,27:18.4
-3,11,27:18.4
6,11,27:18.4
-3,12,27:18.4
-3,13,27:18.4
-2,14,27:18.4
-2,15,27:18.4
-2,16,27:18.4
-1,16,27:18.4
-1,17,27:18.4
-1,18,27:18.4
-1,19,27:18.4
-1,20,27:18.4
-7,-4,28:18.4
-10,-3,28:18.4
-9,-3,28:18.4
-8,-3,28:18.4
-7,-3,28:18.4
-6,-3,28:18.4
-5,-3,28:18.4
-4,-3,28:18.4
-12,-2,28:18.4
-11,-2,28:18.4
-10,-2,28:18.4
-9,-2,28:18.4
-8,-2,28:18.4
-7,-2,28:18.4
-6,-2,28:18.4
-5,-2,28:18.4
-4,-2,28:18.4
-3,-2,28:18.4
-2,-2,28:18.4
-1,-2,28:18.4
0,-2,28:18.4
-13,-1,28:18.4
-12,-1,28:18.4
-11,-1,28:18.4
-10,-1,28:18.4
-9,-1,28:18.4
-8,-1,28:18.4
-7,-1,28:18.4
-6,-1,28:18.4
-5,-1,28:18.4
-4,-1,28:18.4
-3,-1,28:18.4
-2,-1,28:18.4
-1,-1,28:18.4
0,-1,28:18.4
1,-1,28:18.4
2,-1,28:18.4
-14,0,28:18.4
-13,0,28:18.4
-12,0,28:18.4
-11,0,28:18.4
-10,0,28:18.4
-7,0,28:18.4
-6,0,28:18.4
-5,0,28:18.4
-4,0,28:18.4
-3,0,28:18.4
-2,0,28:18.4
-1,0,28:18.4
0,0,28:18.4
1,0,28:18.4
2,0,28:18.4
3,0,28:18.4
-14,1,28:18.4
-13,1,28:18.4
-12,1,28:18.4
-11,1,28:18.4
-5,1,28:18.4
-4,1,28:18.4
-3,1,28:18.4
-2,1,28:18.4
-1,1,28:18.4
0,1,28:18.4
1,1,28:18.4
2,1,28:18.4
3,1,28:18.4
-15,2,28:18.4
-14,2,28:18.4
-13,2,28:18.4
-12,2,28:18.4
-3,2,28:18.4
-2,2,28:18.4
-1,2,28:18.4
0,2,28:18.4
1,2,28:18.4
2,2,28:18.4
3,2,28:18.4
4,2,28:18.4
-16,3,28:18.4
-15,3,28:18.4
-14,3,28:18.4
-13,3,28:18.4
-1,3,28:18.4
0,3,28:18.4
1,3,28:18.4
2,3,28:18.4
3,3,28:18.4
4,3,28:18.4
-16,4,28:18.4
-15,4,28:18.4
-14,4,28:18.4
-2,4,28:18.4
0,4,28:18.4
1,4,28:18.4
2,4,28:18.4
3,4,28:18.4
4,4,28:18.4
5,4,28:18.4
-18,5,28:18.4
-17,5,28:18.4
-16,5,28:18.4
-15,5,28:18.4
-14,5,28:18.4
-3,5,28:18.4
-2,5,28:18.4
1,5,28:18.4
2,5,28:18.4
3,5,28:18.4
4,5,28:18.4
5,5,28:18.4
-18,6,28:18.4
-17,6,28:18.4
-16,6,28:18.4
-15,6,28:18.4
-3,6,28:18.4
2,6,28:18.4
3,6,28:18.4
4,6,28:18.4
5,6,28:18.4
6,6,28:18.4
-18,7,28:18.4
-16,7,28:18.4
-15,7,28:18.4
-14,7,28:18.4
-13,7,28:18.4
-12,7,28:18.4
-11,7,28:18.4
-10,7,28:18.4
-9,7,28:18.4
-8,7,28:18.4
-7,7,28:18.4
-6,7,28:18.4
-5,7,28:18.4
-4,7,28:18.4
2,7,28:18.4
3,7,28:18.4
4,7,28:18.4
5,7,28:18.4
6,7,28:18.4
-18,8,28:18.4
-17,8,28:18.4
-16,8,28:18.4
-5,8,28:18.4
-4,8,28:18.4
3,8,28:18.4
4,8,28:18.4
5,8,28:18.4
6,8,28:18.4
7,8,28:18.4
-17,9,28:18.4
-16,9,28:18.4
-4,9,28:18.4
4,9,28:18.4
5,9,28:18.4
6,9,28:18.4
7,9,28:18.4
-17,10,28:18.4
-4,10,28:18.4
5,10,28:18.4
6,10,28:18.4
7,10,28:18.4
-17,11,28:18.4
-3,11,28:18.4
4,11,28:18.4
5,11,28:18.4
6,11,28:18.4
-3,12,28:18.4
3,12,28:18.4
4,12,28:18.4
5,12,28:18.4
6,12,28:18.4
-3,13,28:18.4
-2,13,28:18.4
2,13,28:18.4
3,13,28:18.4
4,13,28:18.4
5,13,28:18.4
6,13,28:18.4
-2,14,28:18.4
2,14,28:18.4
3,14,28:18.4
4,14,28:18.4
5,14,28:18.4
-2,15,28:18.4
1,15,28:18.4
2,15,28:18.4
3,15,28:18.4
4,15,28:18.4
-2,16,28:18.4
0,16,28:18.4
1,16,28:18.4
2,16,28:18.4
3,16,28:18.4
-2,17,28:18.4
-1,17,28:18.4
0,17,28:18.4
1,17,28:18.4
2,17,28:18.4
3,17,28:18.4
-2,18,28:18.4
-1,18,28:18.4
0,18,28:18.4
1,18,28:18.4
2,18,28:18.4
-4,19,28:18.4
-3,19,28:18.4
-2,19,28:18.4
-1,19,28:18.4
0,19,28:18.4
-6,20,28:18.4
-5,20,28:18.4
-4,20,28:18.4
-3,20,28:18.4
-2,20,28:18.4
-1,20,28:18.4
0,20,28:18.4
-2,21,28:18.4
-1,21,28:18.4
-10,-2,29:18.4
-9,-2,29:18.4
-8,-2,29:18.4
-7,-2,29:18.4
-6,-2,29:18.4
-11,-1,29:18.4
-10,-1,29:18.4
-9,-1,29:18.4
-8,-1,29:18.4
-7,-1,29:18.4
-6,-1,29:18.4
-5,-1,29:18.4
-4,-1,29:18.4
-3,-1,29:18.4
-12,0,29:18.4
-11,0,29:18.4
-10,0,29:18.4
-9,0,29:18.4
-8,0,29:18.4
-7,0,29:18.4
-6,0,29:18.4
-5,0,29:18.4
-4,0,29:18.4
-3,0,29:18.4
-2,0,29:18.4
-1,0,29:18.4
0,0,29:18.4
1,0,29:18.4
-12,1,29:18.4
-11,1,29:18.4
-10,1,29:18.4
-9,1,29:18.4
-8,1,29:18.4
-7,1,29:18.4
-6,1,29:18.4
-5,1,29:18.4
-4,1,29:18.4
-3,1,29:18.4
-2,1,29:18.4
-1,1,29:18.4
0,1,29:18.4
1,1,29:18.4
-13,2,29:18.4
-12,2,29:18.4
-11,2,29:18.4
-10,2,29:18.4
-9,2,29:18.4
-8,2,29:18.4
-7,2,29:18.4
-6,2,29:18.4
-5,2,29:18.4
-4,2,29:18.4
-3,2,29:18.4
-1,2,29:18.4
0,2,29:18.4
1,2,29:18.4
2,2,29:18.4
-14,3,29:18.4
-13,3,29:18.4
-12,3,29:18.4
-11,3,29:18.4
-10,3,29:18.4
-9,3,29:18.4
-8,3,29:18.4
-7,3,29:18.4
-6,3,29:18.4
-5,3,29:18.4
-4,3,29:18.4
-3,3,29:18.4
-2,3,29:18.4
-1,3,29:18.4
1,3,29:18.4
2,3,29:18.4
-15,4,29:18.4
-14,4,29:18.4
-13,4,29:18.4
-12,4,29:18.4
-11,4,29:18.4
-10,4,29:18.4
-8,4,29:18.4
-7,4,29:18.4
-6,4,29:18.4
-5,4,29:18.4
-4,4,29:18.4
-3,4,29:18.4
-2,4,29:18.4
-1,4,29:18.4
0,4,29:18.4
1,4,29:18.4
2,4,29:18.4
3,4,29:18.4
-16,5,29:18.4
-15,5,29:18.4
-14,5,29:18.4
-13,5,29:18.4
-12,5,29:18.4
-11,5,29:18.4
-10,5,29:18.4
-9,5,29:18.4
-8,5,29:18.4
-7,5,29:18.4
-6,5,29:18.4
-5,5,29:18.4
-4,5,29:18.4
-3,5,29:18.4
-2,5,29:18.4
-1,5,29:18.4
0,5,29:18.4
1,5,29:18.4
2,5,29:18.4
3,5,29:18.4
-17,6,29:18.4
-16,6,29:18.4
-15,6,29:18.4
-14,6,29:18.4
-13,6,29:18.4
-12,6,29:18.4
-11,6,29:18.4
-10,6,29:18.4
-9,6,29:18.4
-8,6,29:18.4
-4,6,29:18.4
-3,6,29:18.4
-2,6,29:18.4
-1,6,29:18.4
0,6,29:18.4
1,6,29:18.4
2,6,29:18.4
3,6,29:18.4
4,6,29:18.4
-16,7,29:18.4
-15,7,29:18.4
-14,7,29:18.4
-13,7,29:18.4
-12,7,29:18.4
-11,7,29:18.4
-10,7,29:18.4
-9,7,29:18.4
-8,7,29:18.4
-6,7,29:18.4
-5,7,29:18.4
-4,7,29:18.4
-3,7,29:18.4
-2,7,29:18.4
-1,7,29:18.4
0,7,29:18.4
1,7,29:18.4
2,7,29:18.4
3,7,29:18.4
4,7,29:18.4
-17,8,29:18.4
-16,8,29:18.4
-15,8,29:18.4
-14,8,29:18.4
-13,8,29:18.4
-12,8,29:18.4
-11,8,29:18.4
-10,8,29:18.4
-9,8,29:18.4
-5,8,29:18.4
-4,8,29:18.4
-2,8,29:18.4
-1,8,29:18.4
0,8,29:18.4
1,8,29:18.4
2,8,29:18.4
3,8,29:18.4
4,8,29:18.4
5,8,29:18.4
-16,9,29:18.4
-15,9,29:18.4
-14,9,29:18.4
-13,9,29:18.4
-12,9,29:18.4
-11,9,29:18.4
-10,9,29:18.4
-9,9,29:18.4
-2,9,29:18.4
-1,9,29:18.4
0,9,29:18.4
1,9,29:18.4
2,9,29:18.4
3,9,29:18.4
4,9,29:18.4
5,9,29:18.4
6,9,29:18.4
-16,10,29:18.4
-15,10,29:18.4
-14,10,29:18.4
-13,10,29:18.4
-12,10,29:18.4
-11,10,29:18.4
-10,10,29:18.4
-9,10,29:18.4
-4,10,29:18.4
-3,10,29:18.4
-2,10,29:18.4
-1,10,29:18.4
0,10,29:18.4
1,10,29:18.4
2,10,29:18.4
3,10,29:18.4
4,10,29:18.4
5,10,29:18.4
6,10,29:18.4
-16,11,29:18.4
-15,11,29:18.4
-13,11,29:18.4
-12,11,29:18.4
-11,11,29:18.4
-10,11,29:18.4
-9,11,29:18.4
-3,11,29:18.4
-2,11,29:18.4
-1,11,29:18.4
0,11,29:18.4
1,11,29:18.4
2,11,29:18.4
3,11,29:18.4
4,11,29:18.4
5,11,29:18.4
-16,12,29:18.4
-15,12,29:18.4
-14,12,29:18.4
-13,12,29:18.4
-12,12,29:18.4
-11,12,29:18.4
-10,12,29:18.4
-5,12,29:18.4
-4,12,29:18.4
-3,12,29:18.4
-2,12,29:18.4
-1,12,29:18.4
0,12,29:18.4
1,12,29:18.4
2,12,29:18.4
3,12,29:18.4
4,12,29:18.4
5,12,29:18.4
-16,13,29:18.4
-15,13,29:18.4
-14,13,29:18.4
-13,13,29:18.4
-12,13,29:18.4
-11,13,29:18.4
-10,13,29:18.4
-9,13,29:18.4
-7,13,29:18.4
-6,13,29:18.4
-5,13,29:18.4
-4,13,29:18.4
-3,13,29:18.4
-2,13,29:18.4
-1,13,29:18.4
0,13,29:18.4
1,13,29:18.4
2,13,29:18.4
3,13,29:18.4
4,13,29:18.4
-15,14,29:18.4
-14,14,29:18.4
-13,14,29:18.4
-12,14,29:18.4
-11,14,29:18.4
-10,14,29:18.4
-9,14,29:18.4
-8,14,29:18.4
-7,14,29:18.4
-6,14,29:18.4
-5,14,29:18.4
-4,14,29:18.4
-3,14,29:18.4
-2,14,29:18.4
-1,14,29:18.4
0,14,29:18.4
1,14,29:18.4
2,14,29:18.4
3,14,29:18.4
-15,15,29:18.4
-14,15,29:18.4
-13,15,29:18.4
-12,15,29:18.4
-11,15,29:18.4
-10,15,29:18.4
-9,15,29:18.4
-8,15,29:18.4
-7,15,29:18.4
-6,15,29:18.4
-5,15,29:18.4
-4,15,29:18.4
-3,15,29:18.4
-2,15,29:18.4
-1,15,29:18.4
0,15,29:18.4
1,15,29:18.4
2,15,29:18.4
-15,16,29:18.4
-14,16,29:18.4
-13,16,29:18.4
-12,16,29:18.4
-11,16,29:18.4
-10,16,29:18.4
-9,16,29:18.4
-8,16,29:18.4
-7,16,29:18.4
-6,16,29:18.4
-5,16,29:18.4
-4,16,29:18.4
-3,16,29:18.4
-2,16,29:18.4
-1,16,29:18.4
0,16,29:18.4
1,16,29:18.4
2,16,29:18.4
-14,17,29:18.4
-13,17,29:18.4
-12,17,29:18.4
-11,17,29:18.4
-10,17,29:18.4
-9,17,29:18.4
-8,17,29:18.4
-7,17,29:18.4
-6,17,29:18.4
-5,17,29:18.4
-4,17,29:18.4
-3,17,29:18.4
-2,17,29:18.4
-1,17,29:18.4
0,17,29:18.4
1,17,29:18.4
-13,18,29:18.4
-12,18,29:18.4
-11,18,29:18.4
-10,18,29:18.4
-9,18,29:18.4
-8,18,29:18.4
-7,18,29:18.4
-6,18,29:18.4
-5,18,29:18.4
-4,18,29:18.4
-3,18,29:18.4
-2,18,29:18.4
-1,18,29:18.4
0,18,29:18.4
-11,19,29:18.4
-10,19,29:18.4
-9,19,29:18.4
-8,19,29:18.4
-7,19,29:18.4
-6,19,29:18.4
-4,19,29:18.4
-3,19,29:18.4
-2,19,29:18.4
-1,19,29:18.4
-9,0,30:18.4
-8,0,30:18.4
-7,0,30:18.4
-6,0,30:18.4
1,0,30:18.4
-10,1,30:18.4
-9,1,30:18.4
-8,1,30:18.4
-7,1,30:18.4
-6,1,30:18.4
-5,1,30:18.4
-4,1,30:18.4
-3,1,30:18.4
0,1,30:18.4
1,1,30:18.4
-10,2,30:18.4
-9,2,30:18.4
-8,2,30:18.4
-7,2,30:18.4
-6,2,30:18.4
-5,2,30:18.4
-4,2,30:18.4
-3,2,30:18.4
-2,2,30:18.4
-1,2,30:18.4
0,2,30:18.4
-11,3,30:18.4
-10,3,30:18.4
-9,3,30:18.4
-3,3,30:18.4
-2,3,30:18.4
-1,3,30:18.4
0,3,30:18.4
-12,4,30:18.4
-11,4,30:18.4
-10,4,30:18.4
-2,4,30:18.4
-1,4,30:18.4
0,4,30:18.4
1,4,30:18.4
-13,5,30:18.4
-12,5,30:18.4
-11,5,30:18.4
-6,5,30:18.4
-3,5,30:18.4
-2,5,30:18.4
0,5,30:18.4
1,5,30:18.4
-16,6,30:18.4
-15,6,30:18.4
-14,6,30:18.4
-13,6,30:18.4
-12,6,30:18.4
-11,6,30:18.4
-7,6,30:18.4
-6,6,30:18.4
-5,6,30:18.4
-4,6,30:18.4
-3,6,30:18.4
0,6,30:18.4
1,6,30:18.4
2,6,30:18.4
-14,7,30:18.4
-13,7,30:18.4
-12,7,30:18.4
-11,7,30:18.4
-10,7,30:18.4
-9,7,30:18.4
-8,7,30:18.4
-7,7,30:18.4
-6,7,30:18.4
-5,7,30:18.4
-4,7,30:18.4
-3,7,30:18.4
1,7,30:18.4
2,7,30:18.4
-14,8,30:18.4
-13,8,30:18.4
-12,8,30:18.4
-9,8,30:18.4
-8,8,30:18.4
-7,8,30:18.4
-6,8,30:18.4
-5,8,30:18.4
-4,8,30:18.4
-3,8,30:18.4
1,8,30:18.4
2,8,30:18.4
3,8,30:18.4
-14,9,30:18.4
-13,9,30:18.4
-12,9,30:18.4
-9,9,30:18.4
-8,9,30:18.4
-7,9,30:18.4
-6,9,30:18.4
-5,9,30:18.4
-4,9,30:18.4
-3,9,30:18.4
-2,9,30:18.4
2,9,30:18.4
3,9,30:18.4
-14,10,30:18.4
-13,10,30:18.4
-12,10,30:18.4
-9,10,30:18.4
-8,10,30:18.4
-7,10,30:18.4
-6,10,30:18.4
-5,10,30:18.4
-4,10,30:18.4
-3,10,30:18.4
1,10,30:18.4
2,10,30:18.4
3,10,30:18.4
-13,11,30:18.4
-12,11,30:18.4
-11,11,30:18.4
-9,11,30:18.4
-8,11,30:18.4
-7,11,30:18.4
-6,11,30:18.4
-5,11,30:18.4
-4,11,30:18.4
-3,11,30:18.4
0,11,30:18.4
1,11,30:18.4
2,11,30:18.4
3,11,30:18.4
-13,12,30:18.4
-12,12,30:18.4
-11,12,30:18.4
-9,12,30:18.4
-8,12,30:18.4
-7,12,30:18.4
-6,12,30:18.4
-5,12,30:18.4
-3,12,30:18.4
-1,12,30:18.4
0,12,30:18.4
1,12,30:18.4
2,12,30:18.4
-13,13,30:18.4
-12,13,30:18.4
-11,13,30:18.4
-9,13,30:18.4
-3,13,30:18.4
-1,13,30:18.4
0,13,30:18.4
1,13,30:18.4
-13,14,30:18.4
-12,14,30:18.4
-11,14,30:18.4
-3,14,30:18.4
-2,14,30:18.4
-1,14,30:18.4
0,14,30:18.4
-13,15,30:18.4
-12,15,30:18.4
-11,15,30:18.4
-10,15,30:18.4
-9,15,30:18.4
-8,15,30:18.4
-7,15,30:18.4
-6,15,30:18.4
-5,15,30:18.4
-4,15,30:18.4
-3,15,30:18.4
-2,15,30:18.4
-1,15,30:18.4
0,15,30:18.4
-12,16,30:18.4
-11,16,30:18.4
-10,16,30:18.4
-9,16,30:18.4
-8,16,30:18.4
-7,16,30:18.4
-6,16,30:18.4
-5,16,30:18.4
-4,16,30:18.4
-3,16,30:18.4
-2,16,30:18.4
-1,16,30:18.4
-12,17,30:18.4
-11,17,30:18.4
-10,17,30:18.4
-9,17,30:18.4
-8,17,30:18.4
-7,17,30:18.4
-6,17,30:18.4
-5,17,30:18.4
-4,17,30:18.4
-3,17,30:18.4
-2,17,30:18.4
-1,18,30:18.4
1,0,31:18.4
0,1,31:18.4
1,1,31:18.4
-8,2,31:18.4
-7,2,31:18.4
-6,2,31:18.4
0,2,31:18.4
-8,3,31:18.4
-7,3,31:18.4
-6,3,31:18.4
-5,3,31:18.4
-4,3,31:18.4
-3,3,31:18.4
-2,3,31:18.4
-1,3,31:18.4
-8,4,31:18.4
-7,4,31:18.4
-6,4,31:18.4
-5,4,31:18.4
-4,4,31:18.4
-3,4,31:18.4
-2,4,31:18.4
-1,4,31:18.4
-10,5,31:18.4
-9,5,31:18.4
-8,5,31:18.4
-3,5,31:18.4
-2,5,31:18.4
-1,5,31:18.4
-15,6,31:18.4
-14,6,31:18.4
-13,6,31:18.4
-12,6,31:18.4
-11,6,31:18.4
-10,6,31:18.4
-9,6,31:18.4
-8,6,31:18.4
-4,6,31:18.4
-3,6,31:18.4
-2,6,31:18.4
-1,6,31:18.4
0,6,31:18.4
-12,7,31:18.4
-11,7,31:18.4
-10,7,31:18.4
-9,7,31:18.4
-8,7,31:18.4
-7,7,31:18.4
-6,7,31:18.4
-5,7,31:18.4
-4,7,31:18.4
-1,7,31:18.4
0,7,31:18.4
-11,8,31:18.4
-10,8,31:18.4
-9,8,31:18.4
-5,8,31:18.4
-4,8,31:18.4
-1,8,31:18.4
0,8,31:18.4
1,8,31:18.4
-11,9,31:18.4
-10,9,31:18.4
-9,9,31:18.4
-4,9,31:18.4
-1,9,31:18.4
0,9,31:18.4
1,9,31:18.4
-11,10,31:18.4
-10,10,31:18.4
-9,10,31:18.4
-4,10,31:18.4
-2,10,31:18.4
-1,10,31:18.4
0,10,31:18.4
1,10,31:18.4
-11,11,31:18.4
-10,11,31:18.4
-9,11,31:18.4
-4,11,31:18.4
-3,11,31:18.4
-2,11,31:18.4
-1,11,31:18.4
0,11,31:18.4
-11,12,31:18.4
-10,12,31:18.4
-9,12,31:18.4
-8,12,31:18.4
-7,12,31:18.4
-6,12,31:18.4
-5,12,31:18.4
-4,12,31:18.4
-3,12,31:18.4
-2,12,31:18.4
-1,12,31:18.4
-10,13,31:18.4
-9,13,31:18.4
-7,13,31:18.4
-6,13,31:18.4
-5,13,31:18.4
-4,13,31:18.4
-3,13,31:18.4
-2,13,31:18.4
-10,14,31:18.4
-9,14,31:18.4
-8,14,31:18.4
-7,14,31:18.4
-6,14,31:18.4
-5,14,31:18.4
-4,14,31:18.4
-3,14,31:18.4
-2,14,31:18.4
-2,15,31:18.4
-2,16,31:18.4
-2,17,31:18.4
1,0,32:18.4
0,1,32:18.4
1,1,32:18.4
0,2,32:18.4
-1,3,32:18.4
-6,4,32:18.4
-2,4,32:18.4
-14,5,32:18.4
-13,5,32:18.4
-7,5,32:18.4
-6,5,32:18.4
-5,5,32:18.4
-4,5,32:18.4
-3,5,32:18.4
-2,5,32:18.4
-13,6,32:18.4
-12,6,32:18.4
-11,6,32:18.4
-10,6,32:18.4
-8,6,32:18.4
-7,6,32:18.4
-6,6,32:18.4
-5,6,32:18.4
-4,6,32:18.4
-3,6,32:18.4
-2,6,32:18.4
-10,7,32:18.4
-9,7,32:18.4
-8,7,32:18.4
-7,7,32:18.4
-6,7,32:18.4
-4,7,32:18.4
-3,7,32:18.4
-2,7,32:18.4
-9,8,32:18.4
-8,8,32:18.4
-7,8,32:18.4
-4,8,32:18.4
-3,8,32:18.4
-2,8,32:18.4
-1,8,32:18.4
-9,9,32:18.4
-8,9,32:18.4
-7,9,32:18.4
-6,9,32:18.4
-5,9,32:18.4
-4,9,32:18.4
-3,9,32:18.4
-2,9,32:18.4
-1,9,32:18.4
-8,10,32:18.4
-7,10,32:18.4
-6,10,32:18.4
-5,10,32:18.4
-4,10,32:18.4
-3,10,32:18.4
-2,10,32:18.4
-8,11,32:18.4
-7,11,32:18.4
-6,11,32:18.4
-5,11,32:18.4
-4,11,32:18.4
-3,11,32:18.4
-7,12,32:18.4
-6,12,32:18.4
-5,12,32:18.4
-4,12,32:18.4
-3,12,32:18.4
-3,13,32:18.4
-3,14,32:18.4
-2,15,32:18.4
-2,16,32:18.4
0,2,33:18.4
-1,3,33:18.4
-2,4,33:18.4
-12,5,33:18.4
-11,5,33:18.4
-3,5,33:18.4
-2,5,33:18.4
-11,6,33:18.4
-10,6,33:18.4
-9,6,33:18.4
-8,6,33:18.4
-5,6,33:18.4
-4,6,33:18.4
-3,6,33:18.4
-8,7,33:18.4
-7,7,33:18.4
-6,7,33:18.4
-5,7,33:18.4
-4,7,33:18.4
-6,8,33:18.4
-5,8,33:18.4
-4,8,33:18.4
-6,9,33:18.4
-5,9,33:18.4
-4,9,33:18.4
-4,10,33:18.4
-4,11,33:18.4
-3,11,33:18.4
-3,12,33:18.4
-3,13,33:18.4
-3,14,33:18.4
-2,15,33:18.4
0,2,34:18.4
-1,3,34:18.4
-2,4,34:18.4
-11,5,34:18.4
-10,5,34:18.4
-9,6,34:18.4
-8,6,34:18.4
-4,10,34:18.4
-4,11,34:18.4
-3,11,34:18.4
-3,12,34:18.4
-3,13,34:18.4
-3,14,34:18.4
