[META]
version=2.0
spawnOnBlockType=2
spawnSunlight=True
spawnDarkness=True
spawnWater=False
spawnLava=False
underFill=False
randomRotation=True
dig=True
tree=False
branch=False
needsFoundation=True
rarity=100
collisionPercentage=20
spawnElevationMin=0
spawnElevationMax=200
spawnInBiome=Custom
[DATA]
22,-8,-10:17.12
7,-1,-10:17.12
8,-1,-10:17.12
9,-1,-10:17.12
6,0,-10:17.12
7,0,-10:17.12
8,0,-10:17.12
9,0,-10:17.12
10,0,-10:17.12
6,1,-10:17.12
7,1,-10:17.12
8,1,-10:17.12
9,1,-10:17.12
10,1,-10:17.12
6,2,-10:17.12
7,2,-10:17.12
8,2,-10:17.12
9,2,-10:17.12
10,2,-10:17.12
7,3,-10:17.12
8,3,-10:17.12
9,3,-10:17.12
4,7,-10:17.12
5,10,-10:17.12
-5,-10,-9:17.12
21,-10,-9:17.12
22,-10,-9:17.12
23,-10,-9:17.12
20,-9,-9:17.12
21,-9,-9:17.12
22,-9,-9:17.12
23,-9,-9:17.12
24,-9,-9:17.12
-3,-8,-9:17.12
20,-8,-9:17.12
21,-8,-9:17.12
22,-8,-9:17.12
23,-8,-9:17.12
24,-8,-9:17.12
-3,-7,-9:17.12
20,-7,-9:17.12
21,-7,-9:17.12
22,-7,-9:17.12
23,-7,-9:17.12
24,-7,-9:17.12
21,-6,-9:17.12
22,-6,-9:17.12
23,-6,-9:17.12
-2,-5,-9:17.12
1,-4,-9:17.12
7,-2,-9:17.12
8,-2,-9:17.12
9,-2,-9:17.12
6,-1,-9:17.12
7,-1,-9:17.12
8,-1,-9:17.12
9,-1,-9:17.12
10,-1,-9:17.12
15,-1,-9:17.12
5,0,-9:17.12
6,0,-9:17.12
7,0,-9:17.12
8,0,-9:17.12
9,0,-9:17.12
10,0,-9:17.12
11,0,-9:17.12
4,1,-9:17.12
5,1,-9:17.12
6,1,-9:17.12
7,1,-9:17.12
8,1,-9:17.12
9,1,-9:17.12
10,1,-9:17.12
11,1,-9:17.12
2,2,-9:17.12
5,2,-9:17.12
6,2,-9:17.12
7,2,-9:17.12
8,2,-9:17.12
9,2,-9:17.12
10,2,-9:17.12
11,2,-9:17.12
6,3,-9:17.12
7,3,-9:17.12
8,3,-9:17.12
9,3,-9:17.12
10,3,-9:17.12
-1,4,-9:17.12
7,4,-9:17.12
8,4,-9:17.12
9,4,-9:17.12
-11,5,-9:17.12
-4,5,-9:17.12
3,5,-9:17.12
4,5,-9:17.12
5,5,-9:17.12
-8,6,-9:17.12
-6,6,-9:17.12
2,6,-9:17.12
3,6,-9:17.12
4,6,-9:17.12
5,6,-9:17.12
6,6,-9:17.12
2,7,-9:17.12
3,7,-9:17.12
4,7,-9:17.12
5,7,-9:17.12
6,7,-9:17.12
2,8,-9:17.12
3,8,-9:17.12
4,8,-9:17.12
5,8,-9:17.12
6,8,-9:17.12
3,9,-9:17.12
4,9,-9:17.12
5,9,-9:17.12
6,9,-9:17.12
7,9,-9:17.12
3,10,-9:17.12
4,10,-9:17.12
5,10,-9:17.12
6,10,-9:17.12
7,10,-9:17.12
3,11,-9:17.12
4,11,-9:17.12
5,11,-9:17.12
6,11,-9:17.12
7,11,-9:17.12
4,12,-9:17.12
5,12,-9:17.12
6,12,-9:17.12
7,13,-9:17.12
9,15,-9:17.12
10,17,-9:17.12
10,20,-9:17.12
-8,-13,-8:17.12
-7,-13,-8:17.12
-7,-12,-8:17.12
-6,-11,-8:17.12
-5,-11,-8:17.12
-4,-11,-8:17.12
-6,-10,-8:17.12
-5,-10,-8:17.12
-4,-10,-8:17.12
20,-10,-8:17.12
21,-10,-8:17.12
22,-10,-8:17.12
23,-10,-8:17.12
24,-10,-8:17.12
-6,-9,-8:17.12
-5,-9,-8:17.12
-4,-9,-8:17.12
-3,-9,-8:17.12
-2,-9,-8:17.12
20,-9,-8:17.12
21,-9,-8:17.12
22,-9,-8:17.12
23,-9,-8:17.12
24,-9,-8:17.12
27,-9,-8:17.12
-4,-8,-8:17.12
-3,-8,-8:17.12
-2,-8,-8:17.12
20,-8,-8:17.12
21,-8,-8:17.12
22,-8,-8:17.12
23,-8,-8:17.12
24,-8,-8:17.12
26,-8,-8:17.12
-4,-7,-8:17.12
-3,-7,-8:17.12
-2,-7,-8:17.12
20,-7,-8:17.12
21,-7,-8:17.12
22,-7,-8:17.12
23,-7,-8:17.12
24,-7,-8:17.12
-4,-6,-8:17.12
-3,-6,-8:17.12
-2,-6,-8:17.12
-1,-6,-8:17.12
20,-6,-8:17.12
21,-6,-8:17.12
22,-6,-8:17.12
23,-6,-8:17.12
24,-6,-8:17.12
-3,-5,-8:17.12
-2,-5,-8:17.12
-1,-5,-8:17.12
0,-5,-8:17.12
1,-5,-8:17.12
2,-5,-8:17.12
-3,-4,-8:17.12
-2,-4,-8:17.12
-1,-4,-8:17.12
0,-4,-8:17.12
1,-4,-8:17.12
2,-4,-8:17.12
0,-3,-8:17.12
1,-3,-8:17.12
2,-3,-8:17.12
3,-3,-8:17.12
4,-2,-8:17.12
6,-2,-8:17.12
7,-2,-8:17.12
8,-2,-8:17.12
9,-2,-8:17.12
10,-2,-8:17.12
14,-2,-8:17.12
15,-2,-8:17.12
16,-2,-8:17.12
5,-1,-8:17.12
6,-1,-8:17.12
7,-1,-8:17.12
8,-1,-8:17.12
9,-1,-8:17.12
10,-1,-8:17.12
11,-1,-8:17.12
14,-1,-8:17.12
15,-1,-8:17.12
16,-1,-8:17.12
3,0,-8:17.12
4,0,-8:17.12
5,0,-8:17.12
6,0,-8:17.12
7,0,-8:17.12
8,0,-8:17.12
9,0,-8:17.12
10,0,-8:17.12
11,0,-8:17.12
14,0,-8:17.12
15,0,-8:17.12
16,0,-8:17.12
1,1,-8:17.12
2,1,-8:17.12
3,1,-8:17.12
4,1,-8:17.12
5,1,-8:17.12
6,1,-8:17.12
7,1,-8:17.12
8,1,-8:17.12
9,1,-8:17.12
10,1,-8:17.12
11,1,-8:17.12
14,1,-8:17.12
1,2,-8:17.12
2,2,-8:17.12
3,2,-8:17.12
4,2,-8:17.12
5,2,-8:17.12
6,2,-8:17.12
7,2,-8:17.12
8,2,-8:17.12
9,2,-8:17.12
10,2,-8:17.12
11,2,-8:17.12
-17,3,-8:17.12
-2,3,-8:17.12
-1,3,-8:17.12
0,3,-8:17.12
1,3,-8:17.12
2,3,-8:17.12
3,3,-8:17.12
5,3,-8:17.12
6,3,-8:17.12
7,3,-8:17.12
8,3,-8:17.12
9,3,-8:17.12
10,3,-8:17.12
11,3,-8:17.12
-18,4,-8:17.12
-17,4,-8:17.12
-15,4,-8:17.12
-13,4,-8:17.12
-12,4,-8:17.12
-11,4,-8:17.12
-10,4,-8:17.12
-5,4,-8:17.12
-4,4,-8:17.12
-3,4,-8:17.12
-2,4,-8:17.12
-1,4,-8:17.12
0,4,-8:17.12
6,4,-8:17.12
7,4,-8:17.12
8,4,-8:17.12
9,4,-8:17.12
10,4,-8:17.12
-12,5,-8:17.12
-11,5,-8:17.12
-10,5,-8:17.12
-9,5,-8:17.12
-8,5,-8:17.12
-7,5,-8:17.12
-6,5,-8:17.12
-5,5,-8:17.12
-4,5,-8:17.12
-3,5,-8:17.12
-2,5,-8:17.12
-1,5,-8:17.12
0,5,-8:17.12
2,5,-8:17.12
3,5,-8:17.12
4,5,-8:17.12
5,5,-8:17.12
6,5,-8:17.12
-12,6,-8:17.12
-11,6,-8:17.12
-10,6,-8:17.12
-9,6,-8:17.12
-8,6,-8:17.12
-7,6,-8:17.12
-6,6,-8:17.12
-5,6,-8:17.12
-4,6,-8:17.12
-3,6,-8:17.12
-1,6,-8:17.12
2,6,-8:17.12
3,6,-8:17.12
4,6,-8:17.12
5,6,-8:17.12
6,6,-8:17.12
-9,7,-8:17.12
-8,7,-8:17.12
-7,7,-8:17.12
-6,7,-8:17.12
-5,7,-8:17.12
2,7,-8:17.12
3,7,-8:17.12
4,7,-8:17.12
5,7,-8:17.12
6,7,-8:17.12
2,8,-8:17.12
3,8,-8:17.12
4,8,-8:17.12
5,8,-8:17.12
6,8,-8:17.12
7,8,-8:17.12
2,9,-8:17.12
3,9,-8:17.12
4,9,-8:17.12
5,9,-8:17.12
6,9,-8:17.12
7,9,-8:17.12
3,10,-8:17.12
4,10,-8:17.12
5,10,-8:17.12
6,10,-8:17.12
7,10,-8:17.12
3,11,-8:17.12
4,11,-8:17.12
5,11,-8:17.12
6,11,-8:17.12
7,11,-8:17.12
3,12,-8:17.12
4,12,-8:17.12
5,12,-8:17.12
6,12,-8:17.12
7,12,-8:17.12
8,12,-8:17.12
6,13,-8:17.12
7,13,-8:17.12
8,13,-8:17.12
6,14,-8:17.12
7,14,-8:17.12
8,14,-8:17.12
9,14,-8:17.12
10,14,-8:17.12
8,15,-8:17.12
9,15,-8:17.12
10,15,-8:17.12
8,16,-8:17.12
9,16,-8:17.12
10,16,-8:17.12
11,16,-8:17.12
9,17,-8:17.12
10,17,-8:17.12
11,17,-8:17.12
9,18,-8:17.12
10,18,-8:17.12
11,18,-8:17.12
9,19,-8:17.12
10,19,-8:17.12
11,19,-8:17.12
9,20,-8:17.12
10,20,-8:17.12
11,20,-8:17.12
9,21,-8:17.12
10,21,-8:17.12
11,21,-8:17.12
8,25,-8:17.12
8,26,-8:17.12
6,27,-8:17.12
8,27,-8:17.12
5,28,-8:17.12
-8,-14,-7:17.12
-7,-14,-7:17.12
-9,-13,-7:17.12
-8,-13,-7:17.12
-7,-13,-7:17.12
-6,-13,-7:17.12
-8,-12,-7:17.12
-7,-12,-7:17.12
-6,-12,-7:17.12
-5,-12,-7:17.12
-7,-11,-7:17.12
-6,-11,-7:17.12
-5,-11,-7:17.12
-4,-11,-7:17.12
22,-11,-7:17.12
-7,-10,-7:17.12
-6,-10,-7:17.12
-5,-10,-7:17.12
-4,-10,-7:17.12
-3,-10,-7:17.12
20,-10,-7:17.12
21,-10,-7:17.12
22,-10,-7:17.12
23,-10,-7:17.12
24,-10,-7:17.12
27,-10,-7:17.12
-6,-9,-7:17.12
-5,-9,-7:17.12
-4,-9,-7:17.12
-3,-9,-7:17.12
-2,-9,-7:17.12
20,-9,-7:17.12
21,-9,-7:17.12
22,-9,-7:17.12
23,-9,-7:17.12
24,-9,-7:17.12
25,-9,-7:17.12
26,-9,-7:17.12
27,-9,-7:17.12
28,-9,-7:17.12
-5,-8,-7:17.12
-4,-8,-7:17.12
-3,-8,-7:17.12
-2,-8,-7:17.12
-1,-8,-7:17.12
19,-8,-7:17.12
20,-8,-7:17.12
21,-8,-7:17.12
22,-8,-7:17.12
23,-8,-7:17.12
24,-8,-7:17.12
25,-8,-7:17.12
26,-8,-7:17.12
27,-8,-7:17.12
-5,-7,-7:17.12
-4,-7,-7:17.12
-3,-7,-7:17.12
-2,-7,-7:17.12
-1,-7,-7:17.12
20,-7,-7:17.12
21,-7,-7:17.12
22,-7,-7:17.12
23,-7,-7:17.12
24,-7,-7:17.12
26,-7,-7:17.12
-4,-6,-7:17.12
-3,-6,-7:17.12
-2,-6,-7:17.12
-1,-6,-7:17.12
1,-6,-7:17.12
20,-6,-7:17.12
21,-6,-7:17.12
22,-6,-7:17.12
23,-6,-7:17.12
24,-6,-7:17.12
25,-6,-7:17.12
-4,-5,-7:17.12
-3,-5,-7:17.12
-2,-5,-7:17.12
-1,-5,-7:17.12
0,-5,-7:17.12
1,-5,-7:17.12
2,-5,-7:17.12
22,-5,-7:17.12
-3,-4,-7:17.12
-2,-4,-7:17.12
-1,-4,-7:17.12
0,-4,-7:17.12
1,-4,-7:17.12
2,-4,-7:17.12
3,-4,-7:17.12
4,-4,-7:17.12
5,-4,-7:18.12
6,-4,-7:18.12
-2,-3,-7:17.12
-1,-3,-7:17.12
0,-3,-7:17.12
1,-3,-7:17.12
2,-3,-7:17.12
3,-3,-7:17.12
4,-3,-7:17.12
5,-3,-7:17.12
8,-3,-7:17.12
15,-3,-7:17.12
1,-2,-7:17.12
2,-2,-7:17.12
3,-2,-7:17.12
4,-2,-7:17.12
5,-2,-7:17.12
6,-2,-7:17.12
7,-2,-7:17.12
8,-2,-7:17.12
9,-2,-7:17.12
10,-2,-7:17.12
14,-2,-7:17.12
15,-2,-7:17.12
16,-2,-7:17.12
3,-1,-7:17.12
4,-1,-7:17.12
5,-1,-7:17.12
6,-1,-7:17.12
7,-1,-7:17.12
8,-1,-7:17.12
9,-1,-7:17.12
10,-1,-7:17.12
11,-1,-7:17.12
13,-1,-7:17.12
14,-1,-7:17.12
15,-1,-7:17.12
16,-1,-7:17.12
17,-1,-7:17.12
2,0,-7:17.12
3,0,-7:17.12
4,0,-7:17.12
5,0,-7:17.12
6,0,-7:17.12
7,0,-7:17.12
8,0,-7:17.12
9,0,-7:17.12
10,0,-7:17.12
11,0,-7:17.12
14,0,-7:17.12
15,0,-7:17.12
16,0,-7:17.12
1,1,-7:17.12
2,1,-7:17.12
3,1,-7:17.12
4,1,-7:17.12
5,1,-7:17.12
6,1,-7:17.12
7,1,-7:17.12
8,1,-7:17.12
9,1,-7:17.12
10,1,-7:17.12
11,1,-7:17.12
12,1,-7:17.12
13,1,-7:17.12
14,1,-7:17.12
15,1,-7:17.12
-17,2,-7:17.12
-1,2,-7:17.12
0,2,-7:17.12
1,2,-7:17.12
2,2,-7:17.12
3,2,-7:17.12
4,2,-7:17.12
5,2,-7:17.12
6,2,-7:17.12
7,2,-7:17.12
8,2,-7:17.12
9,2,-7:17.12
10,2,-7:17.12
11,2,-7:17.12
14,2,-7:17.12
-18,3,-7:17.12
-17,3,-7:17.12
-16,3,-7:17.12
-15,3,-7:17.12
-13,3,-7:17.12
-11,3,-7:17.12
-4,3,-7:17.12
-2,3,-7:17.12
-1,3,-7:17.12
0,3,-7:17.12
1,3,-7:17.12
2,3,-7:17.12
3,3,-7:17.12
4,3,-7:17.12
5,3,-7:17.12
6,3,-7:17.12
7,3,-7:17.12
8,3,-7:17.12
9,3,-7:17.12
10,3,-7:17.12
11,3,-7:17.12
-19,4,-7:17.12
-18,4,-7:17.12
-17,4,-7:17.12
-16,4,-7:17.12
-15,4,-7:17.12
-14,4,-7:17.12
-13,4,-7:17.12
-12,4,-7:17.12
-11,4,-7:17.12
-10,4,-7:17.12
-9,4,-7:17.12
-8,4,-7:17.12
-7,4,-7:17.12
-6,4,-7:17.12
-5,4,-7:17.12
-4,4,-7:17.12
-3,4,-7:17.12
-2,4,-7:17.12
-1,4,-7:17.12
0,4,-7:17.12
1,4,-7:17.12
2,4,-7:17.12
4,4,-7:17.12
6,4,-7:17.12
7,4,-7:17.12
8,4,-7:17.12
9,4,-7:17.12
10,4,-7:17.12
-18,5,-7:17.12
-17,5,-7:17.12
-15,5,-7:17.12
-14,5,-7:17.12
-13,5,-7:17.12
-12,5,-7:17.12
-11,5,-7:17.12
-10,5,-7:17.12
-9,5,-7:17.12
-8,5,-7:17.12
-7,5,-7:17.12
-6,5,-7:17.12
-5,5,-7:17.12
-4,5,-7:17.12
-3,5,-7:17.12
-2,5,-7:17.12
-1,5,-7:17.12
0,5,-7:17.12
2,5,-7:17.12
3,5,-7:17.12
4,5,-7:17.12
5,5,-7:17.12
6,5,-7:17.12
8,5,-7:17.12
-12,6,-7:17.12
-11,6,-7:17.12
-10,6,-7:17.12
-9,6,-7:17.12
-8,6,-7:17.12
-7,6,-7:17.12
-6,6,-7:17.12
-5,6,-7:17.12
-4,6,-7:17.12
-3,6,-7:17.12
-2,6,-7:17.12
-1,6,-7:17.12
0,6,-7:17.12
2,6,-7:17.12
3,6,-7:17.12
4,6,-7:17.12
5,6,-7:17.12
6,6,-7:17.12
-11,7,-7:17.12
-10,7,-7:17.12
-9,7,-7:17.12
-8,7,-7:17.12
-7,7,-7:17.12
-6,7,-7:17.12
-5,7,-7:17.12
-4,7,-7:17.12
-1,7,-7:17.12
1,7,-7:17.12
2,7,-7:17.12
3,7,-7:17.12
4,7,-7:17.12
5,7,-7:17.12
6,7,-7:17.12
7,7,-7:17.12
-8,8,-7:17.12
-6,8,-7:17.12
2,8,-7:17.12
3,8,-7:17.12
4,8,-7:17.12
5,8,-7:17.12
6,8,-7:17.12
7,8,-7:17.12
2,9,-7:17.12
3,9,-7:17.12
4,9,-7:17.12
5,9,-7:17.12
6,9,-7:17.12
7,9,-7:17.12
2,10,-7:17.12
3,10,-7:17.12
4,10,-7:17.12
5,10,-7:17.12
6,10,-7:17.12
7,10,-7:17.12
8,10,-7:17.12
3,11,-7:17.12
4,11,-7:17.12
5,11,-7:17.12
6,11,-7:17.12
7,11,-7:17.12
8,11,-7:17.12
3,12,-7:17.12
4,12,-7:17.12
5,12,-7:17.12
6,12,-7:17.12
7,12,-7:17.12
8,12,-7:17.12
9,12,-7:17.12
4,13,-7:18.12
5,13,-7:17.12
6,13,-7:17.12
7,13,-7:17.12
8,13,-7:17.12
9,13,-7:17.12
10,13,-7:17.12
4,14,-7:18.12
5,14,-7:18.12
6,14,-7:17.12
7,14,-7:17.12
8,14,-7:17.12
9,14,-7:17.12
10,14,-7:17.12
6,15,-7:17.12
7,15,-7:17.12
8,15,-7:17.12
9,15,-7:17.12
10,15,-7:17.12
11,15,-7:17.12
8,16,-7:17.12
9,16,-7:17.12
10,16,-7:17.12
11,16,-7:17.12
8,17,-7:17.12
9,17,-7:17.12
10,17,-7:17.12
11,17,-7:17.12
12,17,-7:17.12
9,18,-7:17.12
10,18,-7:17.12
11,18,-7:17.12
9,19,-7:17.12
10,19,-7:17.12
11,19,-7:17.12
8,20,-7:17.12
9,20,-7:17.12
10,20,-7:17.12
11,20,-7:17.12
12,20,-7:17.12
9,21,-7:17.12
10,21,-7:17.12
11,21,-7:17.12
10,22,-7:17.12
8,24,-7:17.12
7,25,-7:17.12
8,25,-7:17.12
9,25,-7:17.12
6,26,-7:17.12
7,26,-7:17.12
8,26,-7:17.12
9,26,-7:17.12
5,27,-7:17.12
6,27,-7:17.12
7,27,-7:17.12
8,27,-7:17.12
9,27,-7:17.12
4,28,-7:17.12
5,28,-7:17.12
6,28,-7:17.12
8,28,-7:17.12
5,29,-7:17.12
-9,-13,-6:17.12
-8,-13,-6:17.12
-7,-13,-6:17.12
-8,-12,-6:17.12
-7,-12,-6:17.12
-6,-12,-6:17.12
-5,-12,-6:17.12
-7,-11,-6:17.12
-6,-11,-6:17.12
-5,-11,-6:17.12
-4,-11,-6:17.12
-6,-10,-6:17.12
-5,-10,-6:17.12
-4,-10,-6:17.12
20,-10,-6:17.12
21,-10,-6:17.12
22,-10,-6:17.12
23,-10,-6:17.12
24,-10,-6:17.12
-6,-9,-6:17.12
-5,-9,-6:17.12
-4,-9,-6:17.12
-3,-9,-6:17.12
-2,-9,-6:17.12
20,-9,-6:17.12
21,-9,-6:17.12
22,-9,-6:17.12
23,-9,-6:17.12
24,-9,-6:17.12
25,-9,-6:17.12
27,-9,-6:17.12
-5,-8,-6:17.12
-4,-8,-6:17.12
-3,-8,-6:17.12
-2,-8,-6:17.12
20,-8,-6:17.12
21,-8,-6:17.12
22,-8,-6:17.12
23,-8,-6:17.12
24,-8,-6:17.12
25,-8,-6:17.12
-4,-7,-6:17.12
-3,-7,-6:17.12
-2,-7,-6:17.12
20,-7,-6:17.12
21,-7,-6:17.12
22,-7,-6:17.12
23,-7,-6:17.12
24,-7,-6:17.12
25,-7,-6:17.12
-4,-6,-6:17.12
-3,-6,-6:17.12
-2,-6,-6:17.12
-1,-6,-6:17.12
0,-6,-6:17.12
20,-6,-6:17.12
21,-6,-6:17.12
22,-6,-6:17.12
23,-6,-6:17.12
24,-6,-6:17.12
-3,-5,-6:17.12
-2,-5,-6:17.12
-1,-5,-6:17.12
0,-5,-6:17.12
1,-5,-6:17.12
2,-5,-6:17.12
3,-5,-6:17.12
-3,-4,-6:17.12
-2,-4,-6:17.12
-1,-4,-6:17.12
0,-4,-6:17.12
1,-4,-6:17.12
2,-4,-6:17.12
3,-4,-6:17.12
4,-4,-6:17.12
-1,-3,-6:17.12
0,-3,-6:17.12
1,-3,-6:17.12
2,-3,-6:17.12
3,-3,-6:17.12
4,-3,-6:17.12
5,-3,-6:17.12
7,-3,-6:17.12
8,-3,-6:17.12
9,-3,-6:17.12
14,-3,-6:17.12
15,-3,-6:17.12
0,-2,-6:17.12
2,-2,-6:17.12
3,-2,-6:17.12
4,-2,-6:17.12
5,-2,-6:17.12
6,-2,-6:17.12
7,-2,-6:17.12
8,-2,-6:17.12
9,-2,-6:17.12
10,-2,-6:17.12
12,-2,-6:17.12
13,-2,-6:17.12
14,-2,-6:17.12
15,-2,-6:17.12
16,-2,-6:17.12
3,-1,-6:17.12
4,-1,-6:17.12
5,-1,-6:17.12
6,-1,-6:17.12
7,-1,-6:17.12
8,-1,-6:17.12
9,-1,-6:17.12
10,-1,-6:17.12
11,-1,-6:17.12
12,-1,-6:17.12
13,-1,-6:17.12
14,-1,-6:17.12
15,-1,-6:17.12
16,-1,-6:17.12
3,0,-6:17.12
4,0,-6:17.12
5,0,-6:17.12
6,0,-6:17.12
7,0,-6:17.12
8,0,-6:17.12
9,0,-6:17.12
10,0,-6:17.12
11,0,-6:17.12
12,0,-6:17.12
13,0,-6:17.12
14,0,-6:17.12
15,0,-6:17.12
16,0,-6:17.12
1,1,-6:17.12
2,1,-6:17.12
3,1,-6:17.12
4,1,-6:17.12
5,1,-6:17.12
6,1,-6:17.12
7,1,-6:17.12
8,1,-6:17.12
9,1,-6:17.12
10,1,-6:17.12
11,1,-6:17.12
12,1,-6:17.12
13,1,-6:17.12
14,1,-6:17.12
15,1,-6:17.12
-15,2,-6:17.12
1,2,-6:17.12
2,2,-6:17.12
3,2,-6:17.12
4,2,-6:17.12
5,2,-6:17.12
6,2,-6:17.12
7,2,-6:17.12
8,2,-6:17.12
9,2,-6:17.12
10,2,-6:17.12
11,2,-6:17.12
12,2,-6:17.12
13,2,-6:17.12
14,2,-6:17.12
-17,3,-6:17.12
-16,3,-6:17.12
-15,3,-6:17.12
-14,3,-6:17.12
-13,3,-6:17.12
-2,3,-6:17.12
-1,3,-6:17.12
0,3,-6:17.12
1,3,-6:17.12
2,3,-6:17.12
3,3,-6:17.12
4,3,-6:17.12
5,3,-6:17.12
6,3,-6:17.12
7,3,-6:17.12
8,3,-6:17.12
9,3,-6:17.12
10,3,-6:17.12
11,3,-6:17.12
12,3,-6:17.12
13,3,-6:17.12
-18,4,-6:17.12
-17,4,-6:17.12
-16,4,-6:17.12
-15,4,-6:17.12
-14,4,-6:17.12
-13,4,-6:17.12
-12,4,-6:17.12
-11,4,-6:17.12
-10,4,-6:17.12
-9,4,-6:17.12
-8,4,-6:17.12
-7,4,-6:17.12
-6,4,-6:17.12
-5,4,-6:17.12
-4,4,-6:17.12
-3,4,-6:17.12
-2,4,-6:17.12
-1,4,-6:17.12
0,4,-6:17.12
3,4,-6:17.12
4,4,-6:17.12
5,4,-6:17.12
6,4,-6:17.12
7,4,-6:17.12
8,4,-6:17.12
9,4,-6:17.12
10,4,-6:17.12
11,4,-6:17.12
12,4,-6:17.12
-14,5,-6:17.12
-13,5,-6:17.12
-12,5,-6:17.12
-11,5,-6:17.12
-10,5,-6:17.12
-9,5,-6:17.12
-8,5,-6:17.12
-7,5,-6:17.12
-6,5,-6:17.12
-5,5,-6:17.12
-4,5,-6:17.12
-3,5,-6:17.12
-2,5,-6:17.12
-1,5,-6:17.12
0,5,-6:17.12
2,5,-6:17.12
3,5,-6:17.12
4,5,-6:17.12
5,5,-6:17.12
6,5,-6:17.12
7,5,-6:17.12
-12,6,-6:17.12
-11,6,-6:17.12
-10,6,-6:17.12
-9,6,-6:17.12
-8,6,-6:17.12
-7,6,-6:17.12
-6,6,-6:17.12
-5,6,-6:17.12
-4,6,-6:17.12
-3,6,-6:17.12
-2,6,-6:17.12
-1,6,-6:17.12
2,6,-6:17.12
3,6,-6:17.12
4,6,-6:17.12
5,6,-6:17.12
6,6,-6:17.12
7,6,-6:17.12
-9,7,-6:17.12
-8,7,-6:17.12
-7,7,-6:17.12
-6,7,-6:17.12
-5,7,-6:17.12
-4,7,-6:17.12
-3,7,-6:17.12
-2,7,-6:17.12
-1,7,-6:17.12
2,7,-6:17.12
3,7,-6:17.12
4,7,-6:17.12
5,7,-6:17.12
6,7,-6:17.12
7,7,-6:17.12
2,8,-6:17.12
3,8,-6:17.12
4,8,-6:17.12
5,8,-6:17.12
6,8,-6:17.12
7,8,-6:17.12
2,9,-6:17.12
3,9,-6:17.12
4,9,-6:17.12
5,9,-6:17.12
6,9,-6:17.12
7,9,-6:17.12
8,9,-6:17.12
3,10,-6:17.12
4,10,-6:17.12
5,10,-6:17.12
6,10,-6:17.12
7,10,-6:17.12
8,10,-6:17.12
3,11,-6:17.12
4,11,-6:17.12
5,11,-6:17.12
6,11,-6:17.12
7,11,-6:17.12
8,11,-6:17.12
3,12,-6:17.12
4,12,-6:17.12
5,12,-6:17.12
6,12,-6:17.12
7,12,-6:17.12
8,12,-6:18.12
9,12,-6:17.12
4,13,-6:17.12
5,13,-6:17.12
6,13,-6:17.12
7,13,-6:17.12
8,13,-6:17.12
9,13,-6:17.12
5,14,-6:18.12
6,14,-6:17.12
7,14,-6:17.12
8,14,-6:17.12
9,14,-6:17.12
6,15,-6:17.12
7,15,-6:17.12
8,15,-6:17.12
9,15,-6:17.12
10,15,-6:17.12
8,16,-6:17.12
9,16,-6:17.12
10,16,-6:17.12
11,16,-6:17.12
9,17,-6:17.12
10,17,-6:17.12
11,17,-6:17.12
9,18,-6:17.12
10,18,-6:17.12
11,18,-6:17.12
9,19,-6:17.12
10,19,-6:17.12
11,19,-6:17.12
9,20,-6:17.12
10,20,-6:17.12
11,20,-6:17.12
9,21,-6:17.12
10,21,-6:17.12
11,21,-6:17.12
7,25,-6:17.12
8,25,-6:17.12
6,26,-6:17.12
7,26,-6:17.12
8,26,-6:17.12
9,26,-6:17.12
4,27,-6:17.12
5,27,-6:17.12
6,27,-6:17.12
7,27,-6:17.12
3,28,-6:17.12
4,28,-6:17.12
5,28,-6:17.12
6,28,-6:17.12
4,29,-6:17.12
-5,-10,-5:17.12
-3,-10,-5:17.12
21,-10,-5:17.12
22,-10,-5:17.12
23,-10,-5:17.12
24,-10,-5:17.12
-5,-9,-5:17.12
-4,-9,-5:17.12
-3,-9,-5:17.12
20,-9,-5:17.12
21,-9,-5:17.12
22,-9,-5:17.12
23,-9,-5:17.12
24,-9,-5:17.12
-4,-8,-5:17.12
-3,-8,-5:17.12
-2,-8,-5:17.12
19,-8,-5:17.12
20,-8,-5:17.12
21,-8,-5:17.12
22,-8,-5:17.12
23,-8,-5:17.12
24,-8,-5:17.12
25,-8,-5:17.12
-4,-7,-5:17.12
-3,-7,-5:17.12
-2,-7,-5:17.12
-1,-7,-5:17.12
19,-7,-5:17.12
20,-7,-5:17.12
21,-7,-5:17.12
22,-7,-5:17.12
23,-7,-5:17.12
24,-7,-5:17.12
-4,-6,-5:17.12
-3,-6,-5:17.12
-2,-6,-5:17.12
-1,-6,-5:17.12
0,-6,-5:17.12
1,-6,-5:17.12
19,-6,-5:17.12
20,-6,-5:17.12
21,-6,-5:17.12
22,-6,-5:17.12
23,-6,-5:17.12
24,-6,-5:17.12
-4,-5,-5:17.12
-3,-5,-5:17.12
-2,-5,-5:17.12
-1,-5,-5:17.12
0,-5,-5:17.12
1,-5,-5:17.12
2,-5,-5:17.12
3,-5,-5:17.12
20,-5,-5:17.12
21,-5,-5:17.12
-2,-4,-5:17.12
-1,-4,-5:17.12
0,-4,-5:17.12
1,-4,-5:17.12
2,-4,-5:17.12
3,-4,-5:17.12
4,-4,-5:17.12
5,-4,-5:18.12
15,-4,-5:17.12
16,-4,-5:17.12
17,-4,-5:17.12
-2,-3,-5:17.12
-1,-3,-5:17.12
0,-3,-5:17.12
1,-3,-5:17.12
2,-3,-5:17.12
3,-3,-5:17.12
4,-3,-5:17.12
5,-3,-5:17.12
6,-3,-5:17.12
7,-3,-5:17.12
8,-3,-5:17.12
9,-3,-5:17.12
10,-3,-5:17.12
11,-3,-5:17.12
12,-3,-5:17.12
13,-3,-5:17.12
14,-3,-5:17.12
15,-3,-5:17.12
16,-3,-5:17.12
2,-2,-5:17.12
3,-2,-5:17.12
4,-2,-5:17.12
5,-2,-5:17.12
6,-2,-5:17.12
7,-2,-5:17.12
8,-2,-5:17.12
9,-2,-5:17.12
10,-2,-5:17.12
11,-2,-5:17.12
12,-2,-5:17.12
13,-2,-5:17.12
14,-2,-5:17.12
15,-2,-5:17.12
16,-2,-5:17.12
2,-1,-5:17.12
3,-1,-5:17.12
4,-1,-5:17.12
5,-1,-5:17.12
6,-1,-5:17.12
7,-1,-5:17.12
8,-1,-5:17.12
9,-1,-5:17.12
10,-1,-5:17.12
11,-1,-5:17.12
12,-1,-5:17.12
13,-1,-5:17.12
14,-1,-5:17.12
15,-1,-5:17.12
16,-1,-5:17.12
3,0,-5:17.12
4,0,-5:17.12
5,0,-5:17.12
6,0,-5:17.12
7,0,-5:17.12
8,0,-5:17.12
9,0,-5:17.12
10,0,-5:17.12
11,0,-5:17.12
12,0,-5:17.12
13,0,-5:17.12
14,0,-5:17.12
15,0,-5:17.12
1,1,-5:17.12
2,1,-5:17.12
3,1,-5:17.12
4,1,-5:17.12
5,1,-5:17.12
6,1,-5:17.12
7,1,-5:17.12
8,1,-5:17.12
9,1,-5:17.12
10,1,-5:17.12
11,1,-5:17.12
12,1,-5:17.12
13,1,-5:17.12
14,1,-5:17.12
-1,2,-5:17.12
1,2,-5:17.12
2,2,-5:17.12
3,2,-5:17.12
4,2,-5:17.12
5,2,-5:17.12
6,2,-5:17.12
7,2,-5:17.12
8,2,-5:17.12
9,2,-5:17.12
10,2,-5:17.12
11,2,-5:17.12
12,2,-5:17.12
13,2,-5:17.12
-7,3,-5:17.12
-2,3,-5:17.12
-1,3,-5:17.12
0,3,-5:17.12
1,3,-5:17.12
2,3,-5:17.12
3,3,-5:17.12
4,3,-5:17.12
5,3,-5:17.12
6,3,-5:17.12
7,3,-5:17.12
8,3,-5:17.12
9,3,-5:17.12
10,3,-5:17.12
11,3,-5:17.12
12,3,-5:17.12
13,3,-5:17.12
-9,4,-5:17.12
-8,4,-5:17.12
-7,4,-5:17.12
-6,4,-5:17.12
-4,4,-5:17.12
-3,4,-5:17.12
-2,4,-5:17.12
-1,4,-5:17.12
0,4,-5:17.12
1,4,-5:17.12
3,4,-5:17.12
4,4,-5:17.12
5,4,-5:17.12
6,4,-5:17.12
7,4,-5:17.12
8,4,-5:17.12
9,4,-5:17.12
10,4,-5:17.12
11,4,-5:17.12
12,4,-5:17.12
-11,5,-5:17.12
-10,5,-5:17.12
-9,5,-5:17.12
-8,5,-5:17.12
-7,5,-5:17.12
-6,5,-5:17.12
-5,5,-5:17.12
-4,5,-5:17.12
-3,5,-5:17.12
-2,5,-5:17.12
-1,5,-5:17.12
0,5,-5:17.12
1,5,-5:17.12
2,5,-5:17.12
3,5,-5:17.12
4,5,-5:17.12
5,5,-5:17.12
6,5,-5:17.12
7,5,-5:17.12
8,5,-5:18.12
-9,6,-5:17.12
-8,6,-5:17.12
-7,6,-5:17.12
-6,6,-5:17.12
-5,6,-5:17.12
-4,6,-5:17.12
-3,6,-5:17.12
-2,6,-5:17.12
-1,6,-5:17.12
1,6,-5:17.12
2,6,-5:17.12
3,6,-5:17.12
4,6,-5:17.12
5,6,-5:17.12
6,6,-5:17.12
7,6,-5:17.12
-8,7,-5:17.12
-7,7,-5:17.12
-6,7,-5:17.12
-4,7,-5:17.12
-3,7,-5:17.12
-2,7,-5:17.12
-1,7,-5:17.12
2,7,-5:17.12
3,7,-5:17.12
4,7,-5:17.12
5,7,-5:17.12
6,7,-5:17.12
7,7,-5:18.12
2,8,-5:17.12
3,8,-5:17.12
4,8,-5:17.12
5,8,-5:17.12
6,8,-5:17.12
7,8,-5:17.12
3,9,-5:17.12
4,9,-5:17.12
5,9,-5:17.12
6,9,-5:17.12
7,9,-5:18.12
3,10,-5:17.12
4,10,-5:17.12
5,10,-5:17.12
6,10,-5:17.12
7,10,-5:18.12
8,10,-5:17.12
3,11,-5:17.12
4,11,-5:17.12
5,11,-5:17.12
6,11,-5:17.12
7,11,-5:18.12
8,11,-5:18.12
4,12,-5:17.12
5,12,-5:17.12
6,12,-5:17.12
7,12,-5:18.12
8,12,-5:18.12
4,13,-5:17.12
5,13,-5:17.12
6,13,-5:18.12
7,13,-5:18.12
8,13,-5:17.12
5,14,-5:17.12
6,14,-5:18.12
7,14,-5:18.12
8,14,-5:17.12
10,17,-5:17.12
10,18,-5:17.12
10,19,-5:17.12
4,27,-5:17.12
3,28,-5:17.12
23,-10,-4:17.12
19,-9,-4:17.12
20,-9,-4:17.12
21,-9,-4:17.12
22,-9,-4:17.12
23,-9,-4:17.12
24,-9,-4:17.12
-3,-8,-4:17.12
-2,-8,-4:17.12
18,-8,-4:17.12
19,-8,-4:17.12
20,-8,-4:17.12
21,-8,-4:17.12
22,-8,-4:17.12
23,-8,-4:17.12
24,-8,-4:17.12
-3,-7,-4:17.12
-2,-7,-4:17.12
-1,-7,-4:17.12
17,-7,-4:17.12
18,-7,-4:17.12
19,-7,-4:17.12
20,-7,-4:17.12
21,-7,-4:17.12
22,-7,-4:17.12
23,-7,-4:17.12
24,-7,-4:17.12
-4,-6,-4:17.12
-3,-6,-4:17.12
-2,-6,-4:17.12
-1,-6,-4:17.12
0,-6,-4:17.12
1,-6,-4:17.12
16,-6,-4:17.12
17,-6,-4:17.12
18,-6,-4:17.12
19,-6,-4:17.12
20,-6,-4:17.12
21,-6,-4:17.12
22,-6,-4:17.12
23,-6,-4:17.12
-3,-5,-4:17.12
-2,-5,-4:17.12
-1,-5,-4:17.12
0,-5,-4:17.12
1,-5,-4:17.12
2,-5,-4:17.12
15,-5,-4:17.12
16,-5,-4:17.12
17,-5,-4:17.12
18,-5,-4:17.12
19,-5,-4:17.12
20,-5,-4:17.12
21,-5,-4:17.12
22,-5,-4:17.12
-2,-4,-4:17.12
-1,-4,-4:17.12
0,-4,-4:17.12
1,-4,-4:17.12
2,-4,-4:17.12
3,-4,-4:17.12
4,-4,-4:18.12
5,-4,-4:18.12
12,-4,-4:17.12
13,-4,-4:17.12
14,-4,-4:17.12
15,-4,-4:17.12
16,-4,-4:17.12
17,-4,-4:17.12
18,-4,-4:17.12
19,-4,-4:17.12
20,-4,-4:17.12
-2,-3,-4:17.12
-1,-3,-4:17.12
0,-3,-4:17.12
1,-3,-4:17.12
2,-3,-4:17.12
3,-3,-4:17.12
4,-3,-4:17.12
5,-3,-4:17.12
6,-3,-4:17.12
7,-3,-4:17.12
8,-3,-4:17.12
9,-3,-4:17.12
10,-3,-4:17.12
11,-3,-4:17.12
12,-3,-4:17.12
13,-3,-4:17.12
14,-3,-4:17.12
15,-3,-4:17.12
16,-3,-4:17.12
17,-3,-4:17.12
18,-3,-4:17.12
19,-3,-4:17.12
2,-2,-4:17.12
3,-2,-4:17.12
4,-2,-4:17.12
5,-2,-4:17.12
6,-2,-4:17.12
7,-2,-4:17.12
8,-2,-4:17.12
9,-2,-4:17.12
10,-2,-4:17.12
11,-2,-4:17.12
12,-2,-4:17.12
13,-2,-4:17.12
14,-2,-4:17.12
15,-2,-4:17.12
16,-2,-4:17.12
17,-2,-4:17.12
18,-2,-4:17.12
1,-1,-4:17.12
2,-1,-4:17.12
3,-1,-4:17.12
4,-1,-4:17.12
5,-1,-4:17.12
6,-1,-4:17.12
7,-1,-4:17.12
8,-1,-4:17.12
9,-1,-4:17.12
10,-1,-4:17.12
11,-1,-4:17.12
12,-1,-4:17.12
13,-1,-4:17.12
14,-1,-4:17.12
15,-1,-4:17.12
16,-1,-4:17.12
2,0,-4:17.12
3,0,-4:17.12
4,0,-4:17.12
5,0,-4:17.12
6,0,-4:17.12
7,0,-4:17.12
8,0,-4:17.12
9,0,-4:17.12
10,0,-4:17.12
11,0,-4:17.12
12,0,-4:17.12
13,0,-4:17.12
14,0,-4:17.12
15,0,-4:17.12
1,1,-4:17.12
2,1,-4:17.12
3,1,-4:17.12
4,1,-4:17.12
5,1,-4:17.12
6,1,-4:17.12
7,1,-4:17.12
8,1,-4:17.12
9,1,-4:17.12
10,1,-4:17.12
11,1,-4:17.12
12,1,-4:17.12
13,1,-4:17.12
14,1,-4:17.12
0,2,-4:17.12
1,2,-4:17.12
2,2,-4:17.12
3,2,-4:17.12
4,2,-4:17.12
5,2,-4:17.12
6,2,-4:17.12
7,2,-4:17.12
8,2,-4:17.12
9,2,-4:17.12
10,2,-4:17.12
11,2,-4:17.12
12,2,-4:17.12
13,2,-4:17.12
-2,3,-4:17.12
-1,3,-4:17.12
0,3,-4:17.12
1,3,-4:17.12
2,3,-4:17.12
3,3,-4:17.12
4,3,-4:17.12
5,3,-4:17.12
6,3,-4:17.12
7,3,-4:17.12
8,3,-4:17.12
9,3,-4:17.12
10,3,-4:17.12
11,3,-4:17.12
12,3,-4:17.12
-7,4,-4:17.12
-6,4,-4:17.12
-4,4,-4:17.12
-3,4,-4:17.12
-2,4,-4:17.12
-1,4,-4:17.12
0,4,-4:17.12
1,4,-4:17.12
2,4,-4:17.12
3,4,-4:17.12
4,4,-4:17.12
5,4,-4:17.12
6,4,-4:17.12
7,4,-4:17.12
8,4,-4:18.12
9,4,-4:17.12
10,4,-4:17.12
11,4,-4:17.12
-7,5,-4:17.12
-6,5,-4:17.12
-4,5,-4:17.12
-3,5,-4:17.12
-2,5,-4:17.12
-1,5,-4:17.12
0,5,-4:17.12
1,5,-4:17.12
2,5,-4:17.12
3,5,-4:17.12
4,5,-4:17.12
5,5,-4:17.12
6,5,-4:17.12
7,5,-4:17.12
8,5,-4:18.12
9,5,-4:18.12
-8,6,-4:17.12
-7,6,-4:17.12
-6,6,-4:17.12
-5,6,-4:17.12
-4,6,-4:17.12
-3,6,-4:17.12
-2,6,-4:17.12
-1,6,-4:17.12
0,6,-4:17.12
1,6,-4:17.12
2,6,-4:17.12
3,6,-4:17.12
4,6,-4:17.12
5,6,-4:17.12
6,6,-4:17.12
7,6,-4:18.12
-4,7,-4:17.12
-3,7,-4:17.12
-2,7,-4:17.12
-1,7,-4:17.12
3,7,-4:17.12
4,7,-4:17.12
5,7,-4:17.12
6,7,-4:18.12
7,7,-4:18.12
3,8,-4:17.12
4,8,-4:17.12
5,8,-4:17.12
6,8,-4:18.12
7,8,-4:18.12
4,9,-4:17.12
5,9,-4:17.12
6,9,-4:17.12
7,9,-4:18.12
8,9,-4:18.12
9,9,-4:18.12
4,10,-4:17.12
5,10,-4:17.12
6,10,-4:17.12
7,10,-4:18.12
8,10,-4:18.12
4,11,-4:17.12
5,11,-4:17.12
6,11,-4:18.12
7,11,-4:18.12
8,11,-4:18.12
5,12,-4:17.12
6,12,-4:17.12
7,12,-4:18.12
8,12,-4:18.12
5,13,-4:17.12
6,13,-4:17.12
7,13,-4:18.12
8,13,-4:18.12
21,-10,-3:17.12
19,-9,-3:17.12
20,-9,-3:17.12
21,-9,-3:17.12
22,-9,-3:17.12
23,-9,-3:17.12
24,-9,-3:17.12
17,-8,-3:17.12
18,-8,-3:17.12
19,-8,-3:17.12
20,-8,-3:17.12
21,-8,-3:17.12
22,-8,-3:17.12
23,-8,-3:17.12
24,-8,-3:17.12
0,-7,-3:17.12
17,-7,-3:17.12
18,-7,-3:17.12
19,-7,-3:17.12
20,-7,-3:17.12
21,-7,-3:17.12
22,-7,-3:17.12
23,-7,-3:17.12
24,-7,-3:17.12
-2,-6,-3:17.12
-1,-6,-3:17.12
0,-6,-3:17.12
1,-6,-3:17.12
15,-6,-3:17.12
16,-6,-3:17.12
17,-6,-3:17.12
18,-6,-3:17.12
19,-6,-3:17.12
20,-6,-3:17.12
21,-6,-3:17.12
22,-6,-3:17.12
23,-6,-3:17.12
-2,-5,-3:17.12
-1,-5,-3:17.12
0,-5,-3:17.12
1,-5,-3:17.12
2,-5,-3:17.12
3,-5,-3:17.12
15,-5,-3:17.12
16,-5,-3:17.12
17,-5,-3:17.12
18,-5,-3:17.12
19,-5,-3:17.12
20,-5,-3:17.12
21,-5,-3:17.12
22,-5,-3:17.12
-3,-4,-3:17.12
-2,-4,-3:17.12
-1,-4,-3:17.12
0,-4,-3:17.12
1,-4,-3:17.12
2,-4,-3:17.12
3,-4,-3:17.12
4,-4,-3:17.12
5,-4,-3:18.12
11,-4,-3:17.12
12,-4,-3:17.12
13,-4,-3:17.12
14,-4,-3:17.12
15,-4,-3:17.12
16,-4,-3:17.12
17,-4,-3:17.12
18,-4,-3:17.12
19,-4,-3:17.12
20,-4,-3:17.12
21,-4,-3:17.12
-2,-3,-3:17.12
0,-3,-3:17.12
1,-3,-3:17.12
2,-3,-3:17.12
3,-3,-3:17.12
4,-3,-3:17.12
5,-3,-3:18.12
6,-3,-3:17.12
7,-3,-3:17.12
8,-3,-3:17.12
9,-3,-3:17.12
10,-3,-3:17.12
11,-3,-3:17.12
12,-3,-3:17.12
13,-3,-3:17.12
14,-3,-3:17.12
15,-3,-3:17.12
16,-3,-3:17.12
17,-3,-3:17.12
18,-3,-3:17.12
19,-3,-3:17.12
1,-2,-3:17.12
2,-2,-3:17.12
3,-2,-3:17.12
4,-2,-3:17.12
5,-2,-3:17.12
6,-2,-3:17.12
7,-2,-3:17.12
8,-2,-3:17.12
9,-2,-3:17.12
10,-2,-3:17.12
11,-2,-3:17.12
12,-2,-3:17.12
13,-2,-3:17.12
14,-2,-3:17.12
15,-2,-3:17.12
16,-2,-3:17.12
17,-2,-3:17.12
18,-2,-3:17.12
1,-1,-3:17.12
2,-1,-3:17.12
3,-1,-3:17.12
4,-1,-3:17.12
5,-1,-3:17.12
6,-1,-3:17.12
7,-1,-3:17.12
8,-1,-3:17.12
9,-1,-3:17.12
10,-1,-3:17.12
11,-1,-3:17.12
12,-1,-3:17.12
13,-1,-3:17.12
14,-1,-3:17.12
15,-1,-3:17.12
16,-1,-3:17.12
17,-1,-3:17.12
1,0,-3:17.12
2,0,-3:17.12
3,0,-3:17.12
4,0,-3:17.12
5,0,-3:17.12
6,0,-3:17.12
7,0,-3:17.12
8,0,-3:17.12
9,0,-3:17.12
10,0,-3:17.12
11,0,-3:17.12
12,0,-3:17.12
13,0,-3:17.12
0,1,-3:17.12
1,1,-3:17.12
2,1,-3:17.12
3,1,-3:17.12
4,1,-3:17.12
5,1,-3:17.12
6,1,-3:17.12
7,1,-3:17.12
8,1,-3:17.12
9,1,-3:17.12
10,1,-3:17.12
11,1,-3:17.12
12,1,-3:17.12
13,1,-3:17.12
0,2,-3:17.12
1,2,-3:17.12
2,2,-3:17.12
3,2,-3:17.12
4,2,-3:17.12
5,2,-3:17.12
6,2,-3:17.12
7,2,-3:17.12
8,2,-3:17.12
9,2,-3:17.12
10,2,-3:17.12
11,2,-3:17.12
12,2,-3:17.12
13,2,-3:17.12
-1,3,-3:17.12
0,3,-3:17.12
1,3,-3:17.12
2,3,-3:17.12
3,3,-3:17.12
4,3,-3:17.12
5,3,-3:17.12
6,3,-3:17.12
7,3,-3:17.12
8,3,-3:18.12
9,3,-3:17.12
10,3,-3:17.12
11,3,-3:17.12
-3,4,-3:17.12
-2,4,-3:17.12
-1,4,-3:17.12
0,4,-3:17.12
1,4,-3:17.12
2,4,-3:17.12
3,4,-3:17.12
4,4,-3:17.12
5,4,-3:17.12
6,4,-3:17.12
7,4,-3:17.12
8,4,-3:18.12
9,4,-3:17.12
-3,5,-3:17.12
-2,5,-3:17.12
-1,5,-3:17.12
0,5,-3:17.12
1,5,-3:17.12
2,5,-3:17.12
3,5,-3:17.12
4,5,-3:17.12
5,5,-3:17.12
6,5,-3:17.12
7,5,-3:18.12
8,5,-3:18.12
-3,6,-3:17.12
-2,6,-3:17.12
-1,6,-3:17.12
0,6,-3:17.12
1,6,-3:17.12
2,6,-3:17.12
3,6,-3:17.12
4,6,-3:17.12
5,6,-3:17.12
6,6,-3:17.12
7,6,-3:18.12
3,7,-3:17.12
4,7,-3:17.12
5,7,-3:17.12
6,7,-3:17.12
7,7,-3:18.12
4,8,-3:17.12
5,8,-3:17.12
6,8,-3:17.12
7,8,-3:18.12
4,9,-3:17.12
5,9,-3:17.12
6,9,-3:17.12
7,9,-3:18.12
8,9,-3:18.12
5,10,-3:17.12
6,10,-3:17.12
7,10,-3:17.12
5,11,-3:17.12
6,11,-3:17.12
8,13,-3:18.12
20,-9,-2:17.12
21,-9,-2:17.12
22,-9,-2:17.12
23,-9,-2:17.12
18,-8,-2:17.12
19,-8,-2:17.12
20,-8,-2:17.12
21,-8,-2:17.12
22,-8,-2:17.12
23,-8,-2:17.12
16,-7,-2:17.12
17,-7,-2:17.12
18,-7,-2:17.12
19,-7,-2:17.12
20,-7,-2:17.12
21,-7,-2:17.12
22,-7,-2:17.12
23,-7,-2:17.12
15,-6,-2:17.12
16,-6,-2:17.12
17,-6,-2:17.12
18,-6,-2:17.12
19,-6,-2:17.12
20,-6,-2:17.12
21,-6,-2:17.12
22,-6,-2:17.12
0,-5,-2:17.12
1,-5,-2:17.12
2,-5,-2:17.12
3,-5,-2:17.12
4,-5,-2:17.12
14,-5,-2:17.12
15,-5,-2:17.12
16,-5,-2:17.12
17,-5,-2:17.12
18,-5,-2:17.12
19,-5,-2:17.12
20,-5,-2:17.12
21,-5,-2:17.12
22,-5,-2:17.12
0,-4,-2:17.12
1,-4,-2:17.12
2,-4,-2:17.12
3,-4,-2:17.12
4,-4,-2:17.12
5,-4,-2:17.12
11,-4,-2:17.12
12,-4,-2:17.12
13,-4,-2:17.12
14,-4,-2:17.12
15,-4,-2:17.12
16,-4,-2:17.12
17,-4,-2:17.12
18,-4,-2:17.12
19,-4,-2:17.12
20,-4,-2:17.12
21,-4,-2:17.12
1,-3,-2:17.12
2,-3,-2:17.12
3,-3,-2:17.12
4,-3,-2:17.12
5,-3,-2:17.12
6,-3,-2:17.12
7,-3,-2:17.12
8,-3,-2:17.12
9,-3,-2:17.12
10,-3,-2:17.12
11,-3,-2:17.12
12,-3,-2:17.12
13,-3,-2:17.12
14,-3,-2:17.12
15,-3,-2:17.12
16,-3,-2:17.12
17,-3,-2:17.12
18,-3,-2:17.12
19,-3,-2:17.12
20,-3,-2:17.12
1,-2,-2:17.12
2,-2,-2:17.12
3,-2,-2:17.12
4,-2,-2:17.12
5,-2,-2:17.12
6,-2,-2:17.12
7,-2,-2:17.12
8,-2,-2:17.12
9,-2,-2:17.12
10,-2,-2:17.12
11,-2,-2:17.12
12,-2,-2:17.12
13,-2,-2:17.12
14,-2,-2:17.12
15,-2,-2:17.12
16,-2,-2:17.12
17,-2,-2:17.12
18,-2,-2:17.12
19,-2,-2:17.12
1,-1,-2:17.12
2,-1,-2:17.12
3,-1,-2:17.12
4,-1,-2:17.12
5,-1,-2:17.12
6,-1,-2:17.12
7,-1,-2:17.12
8,-1,-2:17.12
9,-1,-2:17.12
10,-1,-2:17.12
11,-1,-2:17.12
12,-1,-2:17.12
13,-1,-2:17.12
14,-1,-2:17.12
16,-1,-2:17.12
17,-1,-2:17.12
18,-1,-2:17.12
2,0,-2:17.12
3,0,-2:17.12
4,0,-2:17.12
5,0,-2:17.12
6,0,-2:17.12
7,0,-2:17.12
8,0,-2:17.12
9,0,-2:17.12
10,0,-2:17.12
11,0,-2:17.12
12,0,-2:17.12
1,1,-2:17.12
2,1,-2:17.12
3,1,-2:17.12
4,1,-2:17.12
5,1,-2:17.12
6,1,-2:17.12
7,1,-2:17.12
8,1,-2:17.12
9,1,-2:17.12
10,1,-2:17.12
11,1,-2:17.12
12,1,-2:17.12
1,2,-2:17.12
2,2,-2:17.12
3,2,-2:17.12
4,2,-2:17.12
5,2,-2:17.12
6,2,-2:17.12
7,2,-2:17.12
8,2,-2:17.12
9,2,-2:17.12
10,2,-2:17.12
11,2,-2:17.12
-1,3,-2:17.12
0,3,-2:17.12
1,3,-2:17.12
2,3,-2:17.12
3,3,-2:17.12
4,3,-2:17.12
5,3,-2:17.12
6,3,-2:17.12
7,3,-2:17.12
8,3,-2:17.12
9,3,-2:17.12
10,3,-2:17.12
-1,4,-2:17.12
0,4,-2:17.12
1,4,-2:17.12
2,4,-2:17.12
3,4,-2:17.12
4,4,-2:17.12
5,4,-2:17.12
6,4,-2:17.12
7,4,-2:17.12
8,4,-2:18.12
-2,5,-2:17.12
-1,5,-2:17.12
0,5,-2:17.12
1,5,-2:17.12
2,5,-2:17.12
3,5,-2:17.12
4,5,-2:17.12
5,5,-2:17.12
6,5,-2:17.12
7,5,-2:17.12
-1,6,-2:17.12
0,6,-2:17.12
1,6,-2:17.12
2,6,-2:17.12
3,6,-2:17.12
4,6,-2:17.12
5,6,-2:17.12
6,6,-2:17.12
3,7,-2:17.12
4,7,-2:17.12
5,7,-2:17.12
6,7,-2:17.12
7,7,-2:17.12
5,8,-2:17.12
6,8,-2:17.12
7,8,-2:17.12
5,9,-2:17.12
6,9,-2:17.12
20,-9,-1:17.12
21,-9,-1:17.12
22,-9,-1:17.12
18,-8,-1:17.12
19,-8,-1:17.12
20,-8,-1:17.12
21,-8,-1:17.12
22,-8,-1:17.12
17,-7,-1:17.12
18,-7,-1:17.12
19,-7,-1:17.12
20,-7,-1:17.12
21,-7,-1:17.12
22,-7,-1:17.12
15,-6,-1:17.12
16,-6,-1:17.12
17,-6,-1:17.12
18,-6,-1:17.12
19,-6,-1:17.12
20,-6,-1:17.12
21,-6,-1:17.12
22,-6,-1:17.12
3,-5,-1:17.12
4,-5,-1:18.12
5,-5,-1:17.12
15,-5,-1:17.12
16,-5,-1:17.12
17,-5,-1:17.12
18,-5,-1:17.12
19,-5,-1:17.12
20,-5,-1:17.12
21,-5,-1:17.12
1,-4,-1:17.12
2,-4,-1:18.12
3,-4,-1:17.12
4,-4,-1:18.12
5,-4,-1:17.12
6,-4,-1:17.12
15,-4,-1:17.12
16,-4,-1:17.12
17,-4,-1:17.12
18,-4,-1:17.12
19,-4,-1:17.12
20,-4,-1:17.12
1,-3,-1:17.12
2,-3,-1:17.12
3,-3,-1:17.12
4,-3,-1:17.12
5,-3,-1:17.12
6,-3,-1:17.12
7,-3,-1:17.12
8,-3,-1:17.12
9,-3,-1:17.12
10,-3,-1:17.12
11,-3,-1:17.12
12,-3,-1:17.12
13,-3,-1:17.12
14,-3,-1:17.12
15,-3,-1:17.12
16,-3,-1:17.12
17,-3,-1:17.12
18,-3,-1:17.12
19,-3,-1:17.12
20,-3,-1:17.12
2,-2,-1:17.12
3,-2,-1:17.12
4,-2,-1:17.12
5,-2,-1:17.12
6,-2,-1:17.12
7,-2,-1:17.12
8,-2,-1:17.12
9,-2,-1:17.12
10,-2,-1:17.12
11,-2,-1:17.12
12,-2,-1:17.12
13,-2,-1:17.12
14,-2,-1:17.12
15,-2,-1:17.12
16,-2,-1:17.12
17,-2,-1:17.12
18,-2,-1:17.12
19,-2,-1:17.12
2,-1,-1:17.12
3,-1,-1:17.12
4,-1,-1:17.12
5,-1,-1:17.12
6,-1,-1:17.12
7,-1,-1:17.12
8,-1,-1:17.12
9,-1,-1:17.12
10,-1,-1:17.12
11,-1,-1:17.12
12,-1,-1:17.12
13,-1,-1:17.12
14,-1,-1:17.12
18,-1,-1:17.12
2,0,-1:17.12
3,0,-1:17.12
4,0,-1:17.12
5,0,-1:17.12
6,0,-1:17.12
7,0,-1:17.12
8,0,-1:17.12
9,0,-1:17.12
10,0,-1:17.12
11,0,-1:17.12
2,1,-1:17.12
3,1,-1:17.12
4,1,-1:17.12
5,1,-1:17.12
6,1,-1:17.12
7,1,-1:17.12
8,1,-1:17.12
9,1,-1:17.12
10,1,-1:17.12
11,1,-1:17.12
2,2,-1:17.12
3,2,-1:17.12
4,2,-1:17.12
5,2,-1:17.12
6,2,-1:17.12
7,2,-1:17.12
8,2,-1:17.12
9,2,-1:17.12
10,2,-1:17.12
0,3,-1:17.12
1,3,-1:17.12
2,3,-1:17.12
3,3,-1:17.12
4,3,-1:17.12
5,3,-1:17.12
6,3,-1:17.12
7,3,-1:17.12
8,3,-1:17.12
9,3,-1:17.12
0,4,-1:17.12
1,4,-1:17.12
2,4,-1:17.12
3,4,-1:17.12
4,4,-1:17.12
5,4,-1:17.12
6,4,-1:17.12
7,4,-1:18.12
8,4,-1:18.12
0,5,-1:17.12
1,5,-1:17.12
2,5,-1:17.12
3,5,-1:17.12
4,5,-1:17.12
5,5,-1:17.12
6,5,-1:17.12
3,6,-1:17.12
4,6,-1:17.12
5,6,-1:17.12
5,7,-1:17.12
6,7,-1:17.12
7,7,-1:17.12
7,8,-1:17.12
20,-8,0:17.12
3,-7,0:18.12
18,-7,0:17.12
19,-7,0:17.12
20,-7,0:17.12
21,-7,0:17.12
3,-6,0:18.12
4,-6,0:18.12
17,-6,0:17.12
18,-6,0:17.12
19,-6,0:17.12
20,-6,0:17.12
21,-6,0:17.12
2,-5,0:18.12
3,-5,0:18.12
4,-5,0:18.12
16,-5,0:17.12
17,-5,0:17.12
18,-5,0:17.12
19,-5,0:17.12
20,-5,0:17.12
2,-4,0:18.12
3,-4,0:18.12
4,-4,0:18.12
5,-4,0:17.12
6,-4,0:17.12
16,-4,0:17.12
17,-4,0:17.12
18,-4,0:17.12
19,-4,0:17.12
2,-3,0:17.12
3,-3,0:17.12
4,-3,0:17.12
5,-3,0:17.12
6,-3,0:17.12
7,-3,0:17.12
8,-3,0:17.12
9,-3,0:17.12
17,-3,0:17.12
18,-3,0:17.12
19,-3,0:17.12
2,-2,0:17.12
3,-2,0:17.12
4,-2,0:17.12
5,-2,0:17.12
6,-2,0:17.12
7,-2,0:17.12
8,-2,0:17.12
9,-2,0:17.12
10,-2,0:17.12
18,-2,0:17.12
2,-1,0:17.12
3,-1,0:17.12
4,-1,0:17.12
5,-1,0:17.12
6,-1,0:17.12
7,-1,0:17.12
8,-1,0:17.12
9,-1,0:17.12
10,-1,0:17.12
3,0,0:17.12
4,0,0:17.12
5,0,0:17.12
6,0,0:17.12
7,0,0:17.12
8,0,0:17.12
9,0,0:17.12
10,0,0:17.12
3,1,0:17.12
4,1,0:17.12
5,1,0:17.12
6,1,0:17.12
7,1,0:17.12
8,1,0:17.12
9,1,0:17.12
10,1,0:17.12
2,2,0:17.12
3,2,0:17.12
4,2,0:17.12
5,2,0:17.12
6,2,0:17.12
7,2,0:17.12
8,2,0:17.12
9,2,0:17.12
10,2,0:17.12
2,3,0:17.12
3,3,0:17.12
4,3,0:17.12
5,3,0:17.12
6,3,0:17.12
7,3,0:17.12
8,3,0:17.12
9,3,0:17.12
1,4,0:17.12
2,4,0:17.12
3,4,0:17.12
4,4,0:17.12
5,4,0:17.12
6,4,0:17.12
7,4,0:17.12
2,5,0:17.12
3,5,0:17.12
4,5,0:17.12
5,5,0:17.12
6,5,0:17.12
4,6,0:17.12
5,6,0:17.12
4,-5,1:18.12
3,-4,1:18.12
4,-4,1:18.12
5,-4,1:17.12
6,-4,1:17.12
3,-3,1:17.12
4,-3,1:18.12
5,-3,1:17.12
6,-3,1:17.12
7,-3,1:17.12
8,-3,1:17.12
2,-2,1:17.12
3,-2,1:17.12
4,-2,1:17.12
5,-2,1:17.12
6,-2,1:17.12
7,-2,1:17.12
8,-2,1:17.12
9,-2,1:17.12
3,-1,1:17.12
4,-1,1:17.12
5,-1,1:17.12
6,-1,1:17.12
7,-1,1:17.12
8,-1,1:17.12
9,-1,1:17.12
3,0,1:17.12
4,0,1:17.12
5,0,1:17.12
6,0,1:17.12
7,0,1:17.12
8,0,1:17.12
9,0,1:17.12
3,1,1:17.12
4,1,1:17.12
5,1,1:17.12
6,1,1:17.12
7,1,1:17.12
8,1,1:17.12
9,1,1:17.12
10,1,1:17.12
3,2,1:17.12
4,2,1:17.12
5,2,1:17.12
6,2,1:17.12
7,2,1:17.12
8,2,1:17.12
9,2,1:17.12
10,2,1:17.12
3,3,1:17.12
4,3,1:17.12
5,3,1:17.12
6,3,1:17.12
7,3,1:17.12
8,3,1:18.12
9,3,1:17.12
1,4,1:17.12
3,4,1:17.12
4,4,1:17.12
5,4,1:17.12
6,4,1:18.12
7,4,1:18.12
8,4,1:18.12
9,4,1:18.12
10,4,1:18.12
4,5,1:17.12
5,5,1:17.12
6,5,1:17.12
7,5,1:18.12
4,-4,2:18.12
5,-4,2:18.12
6,-4,2:17.12
3,-3,2:18.12
4,-3,2:18.12
5,-3,2:17.12
6,-3,2:17.12
7,-3,2:17.12
4,-2,2:17.12
5,-2,2:17.12
6,-2,2:17.12
7,-2,2:17.12
8,-2,2:17.12
9,-2,2:17.12
3,-1,2:17.12
4,-1,2:17.12
5,-1,2:17.12
6,-1,2:17.12
7,-1,2:17.12
8,-1,2:17.12
9,-1,2:17.12
3,0,2:17.12
4,0,2:17.12
5,0,2:17.12
6,0,2:17.12
7,0,2:17.12
8,0,2:17.12
9,0,2:17.12
3,1,2:17.12
4,1,2:17.12
5,1,2:17.12
6,1,2:17.12
7,1,2:17.12
8,1,2:17.12
9,1,2:17.12
10,1,2:17.12
3,2,2:17.12
4,2,2:17.12
5,2,2:17.12
6,2,2:17.12
7,2,2:17.12
8,2,2:17.12
9,2,2:17.12
4,3,2:17.12
5,3,2:17.12
6,3,2:17.12
7,3,2:17.12
8,3,2:17.12
4,4,2:17.12
5,4,2:17.12
6,4,2:18.12
7,4,2:18.12
8,4,2:18.12
3,5,2:17.12
5,5,2:17.12
5,-5,3:18.12
5,-4,3:18.12
6,-4,3:17.12
4,-3,3:17.12
5,-3,3:17.12
6,-3,3:17.12
7,-3,3:17.12
3,-2,3:17.12
4,-2,3:17.12
5,-2,3:17.12
6,-2,3:17.12
7,-2,3:17.12
8,-2,3:17.12
3,-1,3:17.12
4,-1,3:17.12
5,-1,3:17.12
6,-1,3:17.12
7,-1,3:17.12
8,-1,3:17.12
9,-1,3:17.12
3,0,3:17.12
4,0,3:17.12
5,0,3:17.12
6,0,3:17.12
7,0,3:17.12
8,0,3:17.12
3,1,3:17.12
4,1,3:17.12
5,1,3:17.12
6,1,3:17.12
7,1,3:17.12
8,1,3:17.12
9,1,3:17.12
3,2,3:17.12
4,2,3:18.12
5,2,3:17.12
6,2,3:17.12
7,2,3:17.12
8,2,3:17.12
4,3,3:18.12
5,3,3:18.12
6,3,3:17.12
7,3,3:17.12
5,4,3:18.12
6,4,3:17.12
4,5,3:18.12
5,5,3:18.12
5,-4,4:17.12
6,-4,4:17.12
4,-3,4:17.12
5,-3,4:17.12
6,-3,4:17.12
7,-3,4:17.12
3,-2,4:17.12
4,-2,4:17.12
5,-2,4:17.12
6,-2,4:17.12
7,-2,4:17.12
8,-2,4:17.12
3,-1,4:17.12
4,-1,4:17.12
5,-1,4:17.12
6,-1,4:17.12
7,-1,4:17.12
8,-1,4:17.12
3,0,4:17.12
4,0,4:17.12
5,0,4:17.12
6,0,4:17.12
7,0,4:17.12
8,0,4:17.12
3,1,4:17.12
4,1,4:17.12
5,1,4:17.12
6,1,4:17.12
7,1,4:17.12
8,1,4:17.12
4,2,4:17.12
5,2,4:18.12
6,2,4:17.12
7,2,4:17.12
4,3,4:18.12
5,3,4:18.12
6,3,4:18.12
5,-5,5:18.12
5,-4,5:18.12
6,-4,5:17.12
3,-3,5:17.12
4,-3,5:17.12
5,-3,5:17.12
6,-3,5:17.12
7,-3,5:17.12
3,-2,5:17.12
4,-2,5:17.12
5,-2,5:17.12
6,-2,5:17.12
7,-2,5:17.12
8,-2,5:17.12
2,-1,5:17.12
3,-1,5:17.12
4,-1,5:17.12
5,-1,5:17.12
6,-1,5:17.12
7,-1,5:17.12
8,-1,5:17.12
2,0,5:17.12
3,0,5:17.12
4,0,5:17.12
5,0,5:17.12
6,0,5:17.12
7,0,5:17.12
8,0,5:17.12
3,1,5:17.12
4,1,5:17.12
5,1,5:17.12
6,1,5:17.12
7,1,5:17.12
3,2,5:18.12
4,2,5:18.12
5,2,5:17.12
6,2,5:17.12
7,2,5:17.12
3,3,5:18.12
4,3,5:18.12
5,3,5:17.12
6,3,5:17.12
5,-6,6:18.12
5,-5,6:18.12
6,-5,6:18.12
5,-4,6:18.12
6,-4,6:17.12
7,-4,6:17.12
3,-3,6:17.12
4,-3,6:17.12
5,-3,6:17.12
6,-3,6:17.12
7,-3,6:17.12
3,-2,6:17.12
4,-2,6:17.12
5,-2,6:17.12
6,-2,6:17.12
7,-2,6:17.12
8,-2,6:17.12
2,-1,6:17.12
3,-1,6:17.12
4,-1,6:17.12
5,-1,6:17.12
6,-1,6:17.12
7,-1,6:17.12
8,-1,6:17.12
2,0,6:17.12
3,0,6:17.12
4,0,6:17.12
5,0,6:17.12
6,0,6:17.12
7,0,6:17.12
8,0,6:17.12
3,1,6:18.12
4,1,6:18.12
5,1,6:17.12
6,1,6:17.12
7,1,6:17.12
3,2,6:18.12
4,2,6:18.12
5,2,6:17.12
6,2,6:17.12
7,2,6:17.12
4,3,6:17.12
5,3,6:17.12
6,3,6:17.12
5,-5,7:18.12
4,-4,7:17.12
5,-4,7:18.12
6,-4,7:17.12
7,-4,7:17.12
3,-3,7:17.12
4,-3,7:17.12
5,-3,7:18.12
6,-3,7:17.12
7,-3,7:17.12
8,-3,7:17.12
2,-2,7:17.12
3,-2,7:17.12
4,-2,7:17.12
5,-2,7:17.12
6,-2,7:17.12
7,-2,7:17.12
8,-2,7:17.12
2,-1,7:17.12
3,-1,7:17.12
4,-1,7:17.12
5,-1,7:17.12
6,-1,7:17.12
7,-1,7:17.12
8,-1,7:17.12
2,0,7:17.12
3,0,7:17.12
4,0,7:17.12
5,0,7:17.12
6,0,7:17.12
7,0,7:17.12
8,0,7:17.12
3,1,7:17.12
4,1,7:18.12
5,1,7:17.12
6,1,7:17.12
7,1,7:17.12
8,1,7:17.12
4,2,7:18.12
5,2,7:18.12
6,2,7:17.12
7,2,7:17.12
5,3,7:17.12
6,3,7:17.12
5,-5,8:18.12
7,-5,8:18.12
4,-4,8:17.12
5,-4,8:18.12
6,-4,8:18.12
7,-4,8:18.12
8,-4,8:18.12
3,-3,8:17.12
4,-3,8:17.12
5,-3,8:17.12
6,-3,8:17.12
7,-3,8:17.12
8,-3,8:17.12
2,-2,8:17.12
3,-2,8:17.12
4,-2,8:17.12
5,-2,8:17.12
6,-2,8:17.12
7,-2,8:17.12
8,-2,8:17.12
2,-1,8:17.12
3,-1,8:17.12
4,-1,8:17.12
5,-1,8:17.12
6,-1,8:17.12
7,-1,8:17.12
8,-1,8:17.12
2,0,8:17.12
3,0,8:17.12
4,0,8:17.12
5,0,8:17.12
6,0,8:17.12
7,0,8:17.12
8,0,8:17.12
3,1,8:17.12
4,1,8:17.12
5,1,8:17.12
6,1,8:17.12
7,1,8:17.12
8,1,8:17.12
4,2,8:17.12
5,2,8:17.12
6,2,8:17.12
7,2,8:17.12
5,3,8:17.12
5,-5,9:18.12
6,-5,9:18.12
7,-5,9:18.12
4,-4,9:17.12
5,-4,9:17.12
6,-4,9:18.12
7,-4,9:17.12
8,-4,9:17.12
3,-3,9:17.12
4,-3,9:17.12
5,-3,9:17.12
6,-3,9:17.12
7,-3,9:17.12
8,-3,9:17.12
9,-3,9:17.12
2,-2,9:17.12
3,-2,9:17.12
4,-2,9:17.12
5,-2,9:17.12
6,-2,9:17.12
7,-2,9:17.12
8,-2,9:17.12
9,-2,9:17.12
2,-1,9:17.12
3,-1,9:17.12
4,-1,9:17.12
5,-1,9:17.12
6,-1,9:17.12
7,-1,9:17.12
8,-1,9:17.12
2,0,9:17.12
3,0,9:17.12
4,0,9:17.12
5,0,9:17.12
6,0,9:17.12
7,0,9:17.12
8,0,9:17.12
3,1,9:17.12
4,1,9:17.12
5,1,9:17.12
6,1,9:17.12
7,1,9:17.12
8,1,9:17.12
4,2,9:17.12
5,2,9:17.12
6,2,9:17.12
7,2,9:17.12
4,-4,10:17.12
5,-4,10:17.12
6,-4,10:18.12
7,-4,10:18.12
8,-4,10:17.12
3,-3,10:17.12
4,-3,10:17.12
5,-3,10:17.12
6,-3,10:17.12
7,-3,10:17.12
8,-3,10:17.12
9,-3,10:17.12
2,-2,10:17.12
3,-2,10:17.12
4,-2,10:17.12
5,-2,10:17.12
6,-2,10:17.12
7,-2,10:17.12
8,-2,10:17.12
9,-2,10:17.12
2,-1,10:17.12
3,-1,10:17.12
4,-1,10:17.12
5,-1,10:17.12
6,-1,10:17.12
7,-1,10:17.12
8,-1,10:17.12
9,-1,10:17.12
2,0,10:17.12
3,0,10:17.12
4,0,10:17.12
5,0,10:17.12
6,0,10:17.12
7,0,10:17.12
8,0,10:17.12
3,1,10:17.12
4,1,10:17.12
5,1,10:17.12
6,1,10:17.12
7,1,10:17.12
8,1,10:17.12
4,2,10:17.12
5,2,10:17.12
6,2,10:17.12
7,2,10:17.12
7,-5,11:18.12
4,-4,11:17.12
5,-4,11:17.12
6,-4,11:17.12
7,-4,11:18.12
8,-4,11:17.12
9,-4,11:17.12
3,-3,11:17.12
4,-3,11:17.12
5,-3,11:17.12
6,-3,11:17.12
7,-3,11:17.12
8,-3,11:17.12
9,-3,11:17.12
2,-2,11:17.12
3,-2,11:17.12
4,-2,11:17.12
5,-2,11:17.12
6,-2,11:17.12
7,-2,11:17.12
8,-2,11:17.12
9,-2,11:17.12
2,-1,11:17.12
3,-1,11:17.12
4,-1,11:17.12
5,-1,11:17.12
6,-1,11:17.12
7,-1,11:17.12
8,-1,11:17.12
9,-1,11:17.12
2,0,11:17.12
3,0,11:17.12
4,0,11:17.12
5,0,11:17.12
6,0,11:17.12
7,0,11:17.12
8,0,11:17.12
2,1,11:17.12
3,1,11:17.12
4,1,11:17.12
5,1,11:17.12
6,1,11:17.12
7,1,11:17.12
8,1,11:17.12
4,2,11:17.12
5,2,11:17.12
6,2,11:17.12
7,2,11:17.12
6,-5,12:18.12
7,-5,12:18.12
8,-5,12:17.12
9,-5,12:17.12
5,-4,12:17.12
6,-4,12:17.12
7,-4,12:17.12
8,-4,12:17.12
9,-4,12:17.12
3,-3,12:17.12
4,-3,12:17.12
5,-3,12:17.12
6,-3,12:17.12
7,-3,12:17.12
8,-3,12:17.12
9,-3,12:17.12
2,-2,12:17.12
3,-2,12:17.12
4,-2,12:17.12
5,-2,12:17.12
6,-2,12:17.12
7,-2,12:17.12
8,-2,12:17.12
9,-2,12:17.12
1,-1,12:17.12
2,-1,12:17.12
3,-1,12:17.12
4,-1,12:17.12
5,-1,12:17.12
6,-1,12:17.12
7,-1,12:17.12
8,-1,12:17.12
9,-1,12:17.12
1,0,12:17.12
2,0,12:17.12
3,0,12:17.12
4,0,12:17.12
5,0,12:17.12
6,0,12:17.12
7,0,12:17.12
8,0,12:17.12
2,1,12:17.12
3,1,12:17.12
4,1,12:17.12
5,1,12:17.12
6,1,12:17.12
7,1,12:17.12
3,2,12:17.12
4,2,12:17.12
5,2,12:17.12
6,2,12:17.12
8,-6,13:17.12
9,-6,13:17.12
10,-6,13:17.12
6,-5,13:17.12
7,-5,13:18.12
8,-5,13:17.12
9,-5,13:17.12
10,-5,13:17.12
5,-4,13:18.12
6,-4,13:17.12
7,-4,13:18.12
8,-4,13:17.12
9,-4,13:17.12
10,-4,13:17.12
2,-3,13:17.12
3,-3,13:17.12
4,-3,13:17.12
5,-3,13:18.12
6,-3,13:17.12
7,-3,13:17.12
8,-3,13:17.12
9,-3,13:17.12
10,-3,13:17.12
0,-2,13:17.12
1,-2,13:17.12
2,-2,13:17.12
3,-2,13:17.12
4,-2,13:17.12
5,-2,13:17.12
6,-2,13:17.12
7,-2,13:17.12
8,-2,13:17.12
9,-2,13:17.12
10,-2,13:17.12
0,-1,13:17.12
1,-1,13:17.12
2,-1,13:17.12
3,-1,13:17.12
4,-1,13:17.12
5,-1,13:17.12
6,-1,13:17.12
7,-1,13:17.12
8,-1,13:17.12
9,-1,13:17.12
0,0,13:17.12
1,0,13:17.12
2,0,13:17.12
3,0,13:17.12
4,0,13:17.12
5,0,13:17.12
6,0,13:17.12
7,0,13:17.12
8,0,13:17.12
0,1,13:17.12
1,1,13:17.12
2,1,13:17.12
3,1,13:17.12
4,1,13:17.12
5,1,13:17.12
6,1,13:17.12
7,1,13:17.12
2,2,13:17.12
3,2,13:17.12
4,2,13:17.12
5,2,13:17.12
6,2,13:17.12
4,3,13:17.12
5,3,13:17.12
17,12,13:18.12
9,-7,14:17.12
10,-7,14:17.12
7,-6,14:17.12
8,-6,14:17.12
9,-6,14:17.12
10,-6,14:17.12
11,-6,14:17.12
6,-5,14:17.12
7,-5,14:17.12
8,-5,14:17.12
9,-5,14:17.12
10,-5,14:17.12
5,-4,14:18.12
6,-4,14:17.12
7,-4,14:17.12
8,-4,14:17.12
9,-4,14:17.12
10,-4,14:17.12
2,-3,14:17.12
3,-3,14:17.12
4,-3,14:18.12
5,-3,14:17.12
6,-3,14:17.12
7,-3,14:17.12
8,-3,14:17.12
9,-3,14:17.12
10,-3,14:17.12
0,-2,14:17.12
1,-2,14:17.12
2,-2,14:17.12
3,-2,14:17.12
4,-2,14:18.12
5,-2,14:17.12
6,-2,14:17.12
7,-2,14:17.12
8,-2,14:17.12
9,-2,14:17.12
10,-2,14:17.12
-1,-1,14:17.12
0,-1,14:17.12
1,-1,14:17.12
2,-1,14:17.12
3,-1,14:17.12
4,-1,14:17.12
5,-1,14:17.12
6,-1,14:17.12
7,-1,14:17.12
8,-1,14:17.12
9,-1,14:17.12
-1,0,14:17.12
0,0,14:17.12
1,0,14:17.12
2,0,14:17.12
3,0,14:17.12
4,0,14:17.12
5,0,14:17.12
6,0,14:17.12
7,0,14:17.12
0,1,14:17.12
1,1,14:17.12
2,1,14:17.12
3,1,14:17.12
4,1,14:17.12
5,1,14:17.12
6,1,14:17.12
7,1,14:17.12
1,2,14:17.12
2,2,14:17.12
3,2,14:17.12
4,2,14:17.12
5,2,14:17.12
6,2,14:17.12
7,2,14:17.12
4,3,14:17.12
5,3,14:17.12
6,3,14:17.12
4,4,14:17.12
5,4,14:17.12
6,4,14:17.12
16,6,14:18.12
17,6,14:18.12
16,7,14:18.12
17,12,14:18.12
17,13,14:18.12
17,14,14:18.12
9,-8,15:17.12
10,-8,15:17.12
8,-7,15:17.12
9,-7,15:17.12
10,-7,15:17.12
11,-7,15:17.12
7,-6,15:17.12
8,-6,15:17.12
9,-6,15:17.12
10,-6,15:17.12
11,-6,15:17.12
6,-5,15:17.12
7,-5,15:17.12
8,-5,15:17.12
9,-5,15:17.12
10,-5,15:17.12
11,-5,15:17.12
6,-4,15:17.12
7,-4,15:17.12
8,-4,15:17.12
9,-4,15:17.12
10,-4,15:17.12
11,-4,15:17.12
5,-3,15:18.12
6,-3,15:17.12
7,-3,15:17.12
8,-3,15:17.12
9,-3,15:17.12
10,-3,15:17.12
-1,-2,15:17.12
0,-2,15:17.12
1,-2,15:17.12
2,-2,15:17.12
3,-2,15:17.12
4,-2,15:17.12
5,-2,15:18.12
6,-2,15:17.12
7,-2,15:17.12
8,-2,15:17.12
9,-2,15:17.12
-1,-1,15:17.12
0,-1,15:17.12
1,-1,15:17.12
2,-1,15:17.12
3,-1,15:17.12
4,-1,15:17.12
5,-1,15:17.12
-1,0,15:17.12
0,0,15:17.12
1,0,15:17.12
2,0,15:17.12
3,0,15:17.12
4,0,15:17.12
5,0,15:17.12
20,0,15:18.12
0,1,15:17.12
1,1,15:17.12
2,1,15:17.12
3,1,15:17.12
4,1,15:17.12
6,1,15:17.12
0,2,15:17.12
1,2,15:17.12
2,2,15:17.12
3,2,15:17.12
4,2,15:17.12
5,2,15:17.12
6,2,15:17.12
7,2,15:17.12
19,2,15:18.12
20,2,15:18.12
4,3,15:17.12
5,3,15:17.12
6,3,15:17.12
7,3,15:17.12
8,3,15:17.12
5,4,15:17.12
7,4,15:17.12
17,4,15:18.12
18,4,15:18.12
14,5,15:18.12
17,5,15:18.12
18,5,15:18.12
8,6,15:18.12
10,6,15:18.12
13,6,15:18.12
16,6,15:18.12
17,6,15:18.12
9,7,15:18.12
16,7,15:18.12
17,7,15:18.12
18,7,15:18.12
16,8,15:18.12
12,11,15:18.12
14,11,15:18.12
13,12,15:18.12
17,12,15:18.12
17,13,15:18.12
18,13,15:18.12
14,18,15:18.12
15,18,15:18.12
9,-8,16:17.12
10,-8,16:17.12
11,-8,16:17.12
12,-8,16:17.12
8,-7,16:17.12
9,-7,16:17.12
10,-7,16:17.12
11,-7,16:17.12
12,-7,16:17.12
7,-6,16:17.12
8,-6,16:17.12
9,-6,16:17.12
10,-6,16:17.12
11,-6,16:17.12
12,-6,16:17.12
7,-5,16:17.12
8,-5,16:17.12
9,-5,16:17.12
10,-5,16:17.12
11,-5,16:17.12
6,-4,16:17.12
7,-4,16:17.12
8,-4,16:17.12
9,-4,16:17.12
10,-4,16:17.12
11,-4,16:17.12
6,-3,16:17.12
7,-3,16:17.12
8,-3,16:17.12
9,-3,16:17.12
10,-3,16:17.12
0,-2,16:17.12
1,-2,16:17.12
2,-2,16:17.12
3,-2,16:17.12
8,-2,16:17.12
-1,-1,16:17.12
0,-1,16:17.12
1,-1,16:17.12
2,-1,16:17.12
3,-1,16:17.12
20,-1,16:18.12
-1,0,16:17.12
0,0,16:17.12
1,0,16:17.12
2,0,16:17.12
3,0,16:17.12
20,0,16:18.12
-1,1,16:17.12
0,1,16:17.12
1,1,16:17.12
2,1,16:17.12
3,1,16:17.12
0,2,16:17.12
1,2,16:17.12
2,2,16:17.12
6,2,16:17.12
7,2,16:17.12
17,2,16:18.12
18,2,16:18.12
20,2,16:18.12
5,3,16:17.12
6,3,16:17.12
7,3,16:17.12
8,3,16:17.12
13,3,16:18.12
17,3,16:18.12
18,3,16:18.12
6,4,16:17.12
7,4,16:17.12
8,4,16:17.12
13,4,16:18.12
21,4,16:18.12
6,5,16:17.12
8,5,16:17.12
9,5,16:17.12
11,5,16:18.12
12,5,16:18.12
13,5,16:18.12
14,5,16:18.12
17,5,16:18.12
18,5,16:18.12
8,6,16:18.12
9,6,16:17.12
10,6,16:18.12
11,6,16:18.12
12,6,16:18.12
13,6,16:18.12
14,6,16:18.12
16,6,16:18.12
17,6,16:18.12
18,6,16:18.12
9,7,16:18.12
10,7,16:18.12
12,7,16:18.12
13,7,16:18.12
15,7,16:18.12
16,7,16:18.12
17,7,16:18.12
18,7,16:18.12
7,8,16:18.12
8,8,16:18.12
9,8,16:18.12
10,8,16:18.12
15,8,16:18.12
16,8,16:18.12
10,9,16:18.12
14,10,16:18.12
12,11,16:18.12
14,11,16:18.12
15,11,16:18.12
16,11,16:18.12
17,11,16:18.12
12,12,16:18.12
13,12,16:18.12
14,12,16:18.12
15,12,16:18.12
16,12,16:18.12
12,13,16:18.12
13,13,16:18.12
14,13,16:18.12
15,13,16:18.12
16,13,16:18.12
17,13,16:18.12
18,13,16:18.12
19,13,16:18.12
14,14,16:18.12
16,14,16:18.12
17,14,16:18.12
18,14,16:18.12
14,17,16:18.12
15,17,16:18.12
14,18,16:18.12
15,18,16:18.12
14,21,16:18.12
10,-9,17:17.12
11,-9,17:17.12
12,-9,17:17.12
9,-8,17:17.12
10,-8,17:17.12
11,-8,17:17.12
12,-8,17:17.12
13,-8,17:17.12
8,-7,17:17.12
9,-7,17:17.12
10,-7,17:17.12
11,-7,17:17.12
12,-7,17:17.12
13,-7,17:17.12
8,-6,17:17.12
9,-6,17:17.12
10,-6,17:17.12
11,-6,17:17.12
12,-6,17:17.12
7,-5,17:17.12
8,-5,17:17.12
9,-5,17:17.12
10,-5,17:17.12
11,-5,17:17.12
12,-5,17:17.12
7,-4,17:17.12
8,-4,17:17.12
9,-4,17:17.12
10,-4,17:17.12
11,-4,17:17.12
22,-4,17:18.12
7,-3,17:17.12
8,-3,17:17.12
9,-3,17:17.12
21,-3,17:18.12
22,-3,17:18.12
23,-3,17:18.12
-1,-2,17:17.12
0,-2,17:17.12
1,-2,17:17.12
2,-2,17:17.12
-1,-1,17:17.12
0,-1,17:17.12
1,-1,17:17.12
2,-1,17:17.12
-2,0,17:17.12
-1,0,17:17.12
0,0,17:17.12
1,0,17:17.12
2,0,17:17.12
19,0,17:18.12
20,0,17:18.12
21,0,17:18.12
-1,1,17:17.12
0,1,17:17.12
1,1,17:17.12
2,1,17:17.12
11,1,17:18.12
12,1,17:18.12
18,1,17:18.12
19,1,17:18.12
20,1,17:18.12
-1,2,17:17.12
0,2,17:17.12
1,2,17:17.12
12,2,17:18.12
17,2,17:18.12
18,2,17:18.12
20,2,17:18.12
21,2,17:18.12
22,2,17:18.12
7,3,17:17.12
12,3,17:18.12
13,3,17:18.12
17,3,17:18.12
18,3,17:18.12
19,3,17:18.12
20,3,17:18.12
21,3,17:18.12
7,4,17:17.12
10,4,17:18.12
11,4,17:18.12
12,4,17:18.12
13,4,17:18.12
16,4,17:18.12
17,4,17:18.12
18,4,17:18.12
21,4,17:18.12
22,4,17:18.12
25,4,17:18.12
6,5,17:18.12
7,5,17:18.12
8,5,17:18.12
9,5,17:17.12
10,5,17:18.12
11,5,17:18.12
12,5,17:18.12
13,5,17:18.12
14,5,17:18.12
16,5,17:18.12
17,5,17:18.12
18,5,17:18.12
19,5,17:18.12
20,5,17:18.12
22,5,17:18.12
24,5,17:18.12
7,6,17:18.12
8,6,17:18.12
9,6,17:18.12
10,6,17:18.12
11,6,17:18.12
12,6,17:18.12
13,6,17:18.12
14,6,17:18.12
16,6,17:18.12
17,6,17:18.12
19,6,17:18.12
20,6,17:18.12
6,7,17:18.12
8,7,17:18.12
9,7,17:18.12
11,7,17:18.12
13,7,17:18.12
14,7,17:18.12
15,7,17:18.12
16,7,17:18.12
7,8,17:18.12
8,8,17:18.12
9,8,17:18.12
10,8,17:18.12
11,8,17:18.12
13,8,17:18.12
8,9,17:18.12
10,9,17:18.12
13,9,17:18.12
10,10,17:18.12
13,10,17:18.12
14,10,17:18.12
19,10,17:18.12
12,11,17:18.12
13,11,17:18.12
14,11,17:18.12
15,11,17:18.12
19,11,17:18.12
12,12,17:18.12
13,12,17:18.12
14,12,17:18.12
15,12,17:18.12
16,12,17:18.12
17,12,17:18.12
18,12,17:18.12
19,12,17:18.12
12,13,17:18.12
13,13,17:18.12
14,13,17:18.12
15,13,17:18.12
16,13,17:18.12
17,13,17:18.12
18,13,17:18.12
13,14,17:18.12
14,14,17:18.12
15,14,17:18.12
18,14,17:18.12
13,15,17:18.12
14,15,17:18.12
19,15,17:18.12
21,15,17:18.12
13,16,17:18.12
15,16,17:18.12
12,17,17:18.12
13,17,17:18.12
14,17,17:18.12
15,17,17:18.12
12,18,17:18.12
15,18,17:18.12
16,18,17:18.12
11,19,17:18.12
13,19,17:18.12
14,19,17:18.12
11,20,17:18.12
12,20,17:18.12
13,20,17:18.12
12,21,17:18.12
13,21,17:18.12
14,21,17:18.12
13,22,17:18.12
14,22,17:18.12
12,-10,18:17.12
9,-9,18:17.12
10,-9,18:17.12
11,-9,18:17.12
12,-9,18:17.12
13,-9,18:17.12
14,-9,18:17.12
9,-8,18:17.12
10,-8,18:17.12
11,-8,18:17.12
12,-8,18:17.12
13,-8,18:17.12
14,-8,18:17.12
8,-7,18:17.12
9,-7,18:17.12
10,-7,18:17.12
11,-7,18:17.12
12,-7,18:17.12
13,-7,18:17.12
8,-6,18:17.12
9,-6,18:17.12
10,-6,18:17.12
11,-6,18:17.12
12,-6,18:17.12
8,-5,18:17.12
9,-5,18:17.12
10,-5,18:17.12
11,-5,18:17.12
22,-5,18:18.12
8,-4,18:17.12
9,-4,18:17.12
10,-4,18:17.12
22,-4,18:18.12
22,-3,18:18.12
23,-3,18:18.12
-2,-2,18:17.12
-1,-2,18:17.12
0,-2,18:17.12
1,-2,18:17.12
2,-2,18:17.12
21,-2,18:18.12
22,-2,18:18.12
-2,-1,18:17.12
-1,-1,18:17.12
0,-1,18:17.12
1,-1,18:17.12
2,-1,18:17.12
22,-1,18:18.12
23,-1,18:18.12
-2,0,18:17.12
-1,0,18:17.12
0,0,18:17.12
1,0,18:17.12
2,0,18:17.12
19,0,18:18.12
21,0,18:18.12
22,0,18:18.12
-2,1,18:17.12
-1,1,18:17.12
0,1,18:17.12
1,1,18:17.12
2,1,18:17.12
11,1,18:18.12
19,1,18:18.12
20,1,18:18.12
21,1,18:18.12
22,1,18:18.12
23,1,18:18.12
-1,2,18:17.12
0,2,18:17.12
1,2,18:17.12
11,2,18:18.12
12,2,18:18.12
13,2,18:18.12
16,2,18:18.12
18,2,18:18.12
19,2,18:18.12
20,2,18:18.12
21,2,18:18.12
22,2,18:18.12
23,2,18:18.12
-1,3,18:17.12
0,3,18:17.12
12,3,18:18.12
13,3,18:18.12
14,3,18:18.12
16,3,18:18.12
17,3,18:18.12
20,3,18:18.12
21,3,18:18.12
22,3,18:18.12
23,3,18:18.12
25,3,18:18.12
11,4,18:18.12
12,4,18:18.12
13,4,18:18.12
14,4,18:18.12
15,4,18:18.12
16,4,18:18.12
18,4,18:18.12
20,4,18:18.12
21,4,18:18.12
22,4,18:18.12
23,4,18:18.12
24,4,18:18.12
25,4,18:18.12
26,4,18:18.12
27,4,18:18.12
8,5,18:18.12
10,5,18:18.12
11,5,18:18.12
12,5,18:18.12
13,5,18:18.12
14,5,18:18.12
15,5,18:18.12
16,5,18:18.12
18,5,18:18.12
19,5,18:18.12
20,5,18:18.12
21,5,18:18.12
22,5,18:18.12
23,5,18:18.12
24,5,18:18.12
26,5,18:18.12
7,6,18:18.12
8,6,18:18.12
9,6,18:18.12
10,6,18:18.12
11,6,18:18.12
12,6,18:18.12
13,6,18:18.12
14,6,18:18.12
15,6,18:18.12
16,6,18:18.12
17,6,18:18.12
18,6,18:18.12
19,6,18:18.12
20,6,18:18.12
21,6,18:18.12
22,6,18:18.12
6,7,18:18.12
8,7,18:18.12
9,7,18:18.12
10,7,18:18.12
11,7,18:18.12
12,7,18:18.12
13,7,18:18.12
14,7,18:18.12
15,7,18:18.12
16,7,18:18.12
17,7,18:18.12
11,8,18:18.12
12,8,18:18.12
13,8,18:18.12
14,8,18:18.12
15,8,18:18.12
19,8,18:18.12
10,9,18:18.12
11,9,18:18.12
14,9,18:18.12
15,9,18:18.12
18,9,18:18.12
19,9,18:18.12
13,10,18:18.12
14,10,18:18.12
15,10,18:18.12
17,10,18:18.12
19,10,18:18.12
11,11,18:18.12
12,11,18:18.12
13,11,18:18.12
14,11,18:18.12
15,11,18:18.12
16,11,18:18.12
12,12,18:18.12
13,12,18:18.12
14,12,18:18.12
15,12,18:18.12
16,12,18:18.12
17,12,18:18.12
19,12,18:18.12
20,12,18:18.12
13,13,18:18.12
14,13,18:18.12
15,13,18:18.12
16,13,18:18.12
17,13,18:18.12
18,13,18:18.12
19,13,18:18.12
13,14,18:18.12
14,14,18:18.12
15,14,18:18.12
16,14,18:18.12
18,14,18:18.12
19,14,18:18.12
13,15,18:18.12
14,15,18:18.12
15,15,18:18.12
16,15,18:18.12
18,15,18:18.12
19,15,18:18.12
20,15,18:18.12
21,15,18:18.12
14,16,18:18.12
19,16,18:18.12
20,16,18:18.12
12,17,18:18.12
13,17,18:18.12
14,17,18:18.12
16,17,18:18.12
13,18,18:18.12
14,18,18:18.12
15,18,18:18.12
16,18,18:18.12
17,18,18:18.12
12,19,18:18.12
13,19,18:18.12
14,19,18:18.12
10,20,18:18.12
11,20,18:18.12
12,20,18:18.12
13,20,18:18.12
14,20,18:18.12
15,20,18:18.12
11,21,18:18.12
12,21,18:18.12
14,21,18:18.12
10,-10,19:17.12
11,-10,19:17.12
12,-10,19:17.12
13,-10,19:17.12
14,-10,19:17.12
9,-9,19:17.12
10,-9,19:17.12
11,-9,19:17.12
12,-9,19:17.12
13,-9,19:17.12
14,-9,19:17.12
9,-8,19:17.12
10,-8,19:17.12
11,-8,19:17.12
12,-8,19:17.12
13,-8,19:17.12
14,-8,19:17.12
9,-7,19:17.12
10,-7,19:17.12
11,-7,19:17.12
12,-7,19:17.12
13,-7,19:17.12
14,-7,19:17.12
9,-6,19:17.12
10,-6,19:17.12
11,-6,19:17.12
12,-6,19:17.12
13,-6,19:17.12
10,-5,19:17.12
0,-3,19:17.12
22,-3,19:18.12
-1,-2,19:17.12
0,-2,19:17.12
1,-2,19:17.12
22,-2,19:18.12
-2,-1,19:17.12
-1,-1,19:17.12
0,-1,19:17.12
1,-1,19:17.12
2,-1,19:17.12
18,-1,19:18.12
21,-1,19:18.12
-2,0,19:17.12
-1,0,19:17.12
0,0,19:17.12
1,0,19:17.12
2,0,19:17.12
18,0,19:18.12
20,0,19:18.12
21,0,19:18.12
22,0,19:18.12
23,0,19:18.12
-2,1,19:17.12
-1,1,19:17.12
0,1,19:17.12
1,1,19:17.12
2,1,19:17.12
9,1,19:18.12
11,1,19:18.12
16,1,19:18.12
17,1,19:18.12
18,1,19:18.12
19,1,19:18.12
20,1,19:18.12
21,1,19:18.12
22,1,19:18.12
-2,2,19:17.12
-1,2,19:17.12
0,2,19:17.12
1,2,19:17.12
2,2,19:17.12
8,2,19:18.12
9,2,19:18.12
10,2,19:18.12
11,2,19:18.12
12,2,19:18.12
13,2,19:18.12
14,2,19:18.12
15,2,19:18.12
16,2,19:18.12
17,2,19:18.12
18,2,19:18.12
19,2,19:18.12
20,2,19:18.12
21,2,19:18.12
-1,3,19:17.12
0,3,19:17.12
1,3,19:17.12
10,3,19:18.12
11,3,19:18.12
12,3,19:18.12
13,3,19:18.12
14,3,19:18.12
16,3,19:18.12
17,3,19:18.12
19,3,19:18.12
20,3,19:18.12
21,3,19:18.12
23,3,19:18.12
8,4,19:18.12
9,4,19:18.12
10,4,19:18.12
11,4,19:18.12
12,4,19:18.12
13,4,19:18.12
15,4,19:18.12
16,4,19:18.12
17,4,19:18.12
18,4,19:18.12
19,4,19:18.12
20,4,19:18.12
21,4,19:18.12
22,4,19:18.12
23,4,19:18.12
24,4,19:18.12
25,4,19:18.12
7,5,19:18.12
8,5,19:18.12
9,5,19:18.12
10,5,19:18.12
11,5,19:18.12
12,5,19:18.12
13,5,19:18.12
14,5,19:18.12
15,5,19:18.12
16,5,19:18.12
17,5,19:18.12
18,5,19:18.12
19,5,19:18.12
20,5,19:18.12
21,5,19:18.12
22,5,19:18.12
23,5,19:18.12
24,5,19:18.12
25,5,19:18.12
26,5,19:18.12
6,6,19:18.12
7,6,19:18.12
8,6,19:18.12
9,6,19:18.12
10,6,19:18.12
11,6,19:18.12
12,6,19:18.12
13,6,19:18.12
14,6,19:18.12
15,6,19:18.12
16,6,19:18.12
17,6,19:18.12
18,6,19:18.12
19,6,19:18.12
20,6,19:18.12
21,6,19:18.12
22,6,19:18.12
24,6,19:18.12
25,6,19:18.12
6,7,19:18.12
7,7,19:18.12
8,7,19:18.12
9,7,19:18.12
10,7,19:18.12
11,7,19:18.12
12,7,19:18.12
13,7,19:18.12
14,7,19:18.12
15,7,19:18.12
16,7,19:18.12
17,7,19:18.12
18,7,19:18.12
20,7,19:18.12
24,7,19:18.12
25,7,19:18.12
6,8,19:18.12
8,8,19:18.12
9,8,19:18.12
10,8,19:18.12
11,8,19:18.12
12,8,19:18.12
13,8,19:18.12
14,8,19:18.12
15,8,19:18.12
16,8,19:18.12
19,8,19:18.12
13,9,19:18.12
15,9,19:18.12
16,9,19:18.12
17,9,19:18.12
18,9,19:18.12
19,9,19:18.12
20,9,19:18.12
21,9,19:18.12
12,10,19:18.12
13,10,19:18.12
14,10,19:18.12
15,10,19:18.12
16,10,19:18.12
17,10,19:18.12
18,10,19:18.12
19,10,19:18.12
10,11,19:18.12
11,11,19:18.12
12,11,19:18.12
13,11,19:18.12
14,11,19:18.12
15,11,19:18.12
16,11,19:18.12
17,11,19:18.12
18,11,19:18.12
20,11,19:18.12
21,11,19:18.12
11,12,19:18.12
13,12,19:18.12
14,12,19:18.12
15,12,19:18.12
16,12,19:18.12
17,12,19:18.12
18,12,19:18.12
19,12,19:18.12
20,12,19:18.12
11,13,19:18.12
12,13,19:18.12
13,13,19:18.12
14,13,19:18.12
15,13,19:18.12
16,13,19:18.12
17,13,19:18.12
18,13,19:18.12
19,13,19:18.12
20,13,19:18.12
21,13,19:18.12
12,14,19:18.12
13,14,19:18.12
16,14,19:18.12
17,14,19:18.12
18,14,19:18.12
19,14,19:18.12
20,14,19:18.12
21,14,19:18.12
23,14,19:18.12
13,15,19:18.12
14,15,19:18.12
15,15,19:18.12
16,15,19:18.12
18,15,19:18.12
19,15,19:18.12
20,15,19:18.12
21,15,19:18.12
22,15,19:18.12
23,15,19:18.12
24,15,19:18.12
13,16,19:18.12
14,16,19:18.12
15,16,19:18.12
18,16,19:18.12
20,16,19:18.12
22,16,19:18.12
13,17,19:18.12
14,17,19:18.12
16,17,19:18.12
13,18,19:18.12
14,18,19:18.12
15,18,19:18.12
16,18,19:18.12
9,19,19:18.12
10,19,19:18.12
11,19,19:18.12
12,19,19:18.12
13,19,19:18.12
14,19,19:18.12
16,19,19:18.12
10,20,19:18.12
12,20,19:18.12
13,20,19:18.12
14,20,19:18.12
15,20,19:18.12
12,21,19:18.12
14,21,19:18.12
8,-11,20:17.12
9,-11,20:17.12
11,-11,20:17.12
12,-11,20:17.12
13,-11,20:17.12
8,-10,20:17.12
9,-10,20:17.12
10,-10,20:17.12
11,-10,20:17.12
12,-10,20:17.12
13,-10,20:17.12
14,-10,20:17.12
15,-10,20:17.12
8,-9,20:17.12
9,-9,20:17.12
10,-9,20:17.12
11,-9,20:17.12
12,-9,20:17.12
13,-9,20:17.12
14,-9,20:17.12
15,-9,20:17.12
9,-8,20:17.12
10,-8,20:17.12
11,-8,20:17.12
12,-8,20:17.12
13,-8,20:17.12
14,-8,20:17.12
15,-8,20:17.12
10,-7,20:17.12
11,-7,20:17.12
12,-7,20:17.12
13,-7,20:17.12
14,-7,20:17.12
10,-6,20:17.12
11,-6,20:17.12
-2,-3,20:17.12
-1,-3,20:17.12
0,-3,20:17.12
-2,-2,20:17.12
-1,-2,20:17.12
0,-2,20:17.12
1,-2,20:17.12
20,-2,20:18.12
-2,-1,20:17.12
-1,-1,20:17.12
0,-1,20:17.12
1,-1,20:17.12
19,-1,20:18.12
20,-1,20:18.12
-2,0,20:17.12
-1,0,20:17.12
0,0,20:17.12
1,0,20:17.12
2,0,20:17.12
18,0,20:18.12
20,0,20:18.12
21,0,20:18.12
-2,1,20:17.12
-1,1,20:17.12
0,1,20:17.12
1,1,20:17.12
2,1,20:17.12
18,1,20:18.12
19,1,20:18.12
20,1,20:18.12
-2,2,20:17.12
-1,2,20:17.12
0,2,20:17.12
1,2,20:17.12
2,2,20:17.12
9,2,20:18.12
10,2,20:18.12
11,2,20:18.12
15,2,20:18.12
17,2,20:18.12
18,2,20:18.12
19,2,20:18.12
20,2,20:18.12
-2,3,20:17.12
-1,3,20:17.12
0,3,20:17.12
1,3,20:17.12
11,3,20:18.12
12,3,20:18.12
14,3,20:18.12
15,3,20:18.12
16,3,20:18.12
17,3,20:18.12
18,3,20:18.12
19,3,20:18.12
20,3,20:18.12
23,3,20:18.12
-2,4,20:17.12
-1,4,20:17.12
0,4,20:17.12
1,4,20:17.12
8,4,20:18.12
11,4,20:18.12
12,4,20:18.12
13,4,20:18.12
14,4,20:18.12
15,4,20:18.12
16,4,20:18.12
17,4,20:18.12
18,4,20:18.12
19,4,20:18.12
20,4,20:18.12
21,4,20:18.12
22,4,20:18.12
23,4,20:18.12
8,5,20:18.12
10,5,20:18.12
11,5,20:18.12
12,5,20:18.12
13,5,20:18.12
14,5,20:18.12
15,5,20:18.12
16,5,20:18.12
17,5,20:18.12
18,5,20:18.12
19,5,20:18.12
24,5,20:18.12
6,6,20:18.12
9,6,20:18.12
10,6,20:18.12
11,6,20:18.12
12,6,20:18.12
13,6,20:18.12
14,6,20:18.12
15,6,20:18.12
16,6,20:18.12
17,6,20:18.12
18,6,20:18.12
20,6,20:18.12
21,6,20:18.12
6,7,20:18.12
7,7,20:18.12
9,7,20:18.12
10,7,20:18.12
11,7,20:18.12
12,7,20:18.12
13,7,20:18.12
14,7,20:18.12
15,7,20:18.12
16,7,20:18.12
17,7,20:18.12
18,7,20:18.12
20,7,20:18.12
11,8,20:18.12
12,8,20:18.12
13,8,20:18.12
14,8,20:18.12
15,8,20:18.12
16,8,20:18.12
17,8,20:18.12
18,8,20:18.12
19,8,20:18.12
13,9,20:18.12
14,9,20:18.12
15,9,20:18.12
16,9,20:18.12
17,9,20:18.12
18,9,20:18.12
19,9,20:18.12
13,10,20:18.12
14,10,20:18.12
15,10,20:18.12
16,10,20:18.12
17,10,20:18.12
18,10,20:18.12
19,10,20:18.12
20,10,20:18.12
21,10,20:18.12
14,11,20:18.12
15,11,20:18.12
16,11,20:18.12
17,11,20:18.12
18,11,20:18.12
19,11,20:18.12
20,11,20:18.12
21,11,20:18.12
13,12,20:18.12
14,12,20:18.12
15,12,20:18.12
17,12,20:18.12
18,12,20:18.12
19,12,20:18.12
20,12,20:18.12
14,13,20:18.12
15,13,20:18.12
16,13,20:18.12
17,13,20:18.12
18,13,20:18.12
19,13,20:18.12
20,13,20:18.12
13,14,20:18.12
14,14,20:18.12
15,14,20:18.12
17,14,20:18.12
18,14,20:18.12
19,14,20:18.12
20,14,20:18.12
21,14,20:18.12
11,15,20:18.12
12,15,20:18.12
13,15,20:18.12
14,15,20:18.12
15,15,20:18.12
16,15,20:18.12
17,15,20:18.12
18,15,20:18.12
19,15,20:18.12
21,15,20:18.12
13,16,20:18.12
14,16,20:18.12
15,16,20:18.12
18,16,20:18.12
12,17,20:18.12
13,17,20:18.12
14,17,20:18.12
13,18,20:18.12
14,18,20:18.12
10,19,20:18.12
12,19,20:18.12
13,20,20:18.12
14,20,20:18.12
12,21,20:18.12
14,21,20:18.12
7,-12,21:17.12
8,-12,21:17.12
9,-12,21:17.12
7,-11,21:17.12
8,-11,21:17.12
9,-11,21:17.12
10,-11,21:17.12
11,-11,21:17.12
12,-11,21:17.12
13,-11,21:17.12
14,-11,21:17.12
15,-11,21:17.12
7,-10,21:17.12
8,-10,21:17.12
9,-10,21:17.12
10,-10,21:17.12
11,-10,21:17.12
12,-10,21:17.12
13,-10,21:17.12
14,-10,21:17.12
15,-10,21:17.12
16,-10,21:17.12
8,-9,21:17.12
9,-9,21:17.12
10,-9,21:17.12
11,-9,21:17.12
12,-9,21:17.12
13,-9,21:17.12
14,-9,21:17.12
15,-9,21:17.12
16,-9,21:17.12
9,-8,21:17.12
10,-8,21:17.12
11,-8,21:17.12
12,-8,21:17.12
13,-8,21:17.12
14,-8,21:17.12
15,-8,21:17.12
16,-8,21:17.12
10,-7,21:17.12
11,-7,21:17.12
12,-7,21:17.12
13,-7,21:17.12
14,-7,21:17.12
15,-7,21:17.12
-2,-4,21:17.12
-3,-3,21:17.12
-2,-3,21:17.12
-1,-3,21:17.12
0,-3,21:17.12
-2,-2,21:17.12
-1,-2,21:17.12
0,-2,21:17.12
1,-2,21:17.12
-2,-1,21:17.12
-1,-1,21:17.12
0,-1,21:17.12
1,-1,21:17.12
-2,0,21:17.12
-1,0,21:17.12
0,0,21:17.12
1,0,21:17.12
2,0,21:17.12
20,0,21:18.12
21,0,21:18.12
-2,1,21:17.12
-1,1,21:17.12
0,1,21:17.12
1,1,21:17.12
2,1,21:17.12
13,1,21:18.12
14,1,21:18.12
19,1,21:18.12
-2,2,21:17.12
-1,2,21:17.12
0,2,21:17.12
1,2,21:17.12
2,2,21:17.12
13,2,21:18.12
18,2,21:18.12
20,2,21:18.12
21,2,21:18.12
-2,3,21:17.12
-1,3,21:17.12
0,3,21:17.12
1,3,21:17.12
2,3,21:17.12
11,3,21:18.12
12,3,21:18.12
13,3,21:18.12
14,3,21:18.12
15,3,21:18.12
16,3,21:18.12
18,3,21:18.12
19,3,21:18.12
20,3,21:18.12
21,3,21:18.12
22,3,21:18.12
-2,4,21:17.12
-1,4,21:17.12
0,4,21:17.12
1,4,21:17.12
11,4,21:18.12
13,4,21:18.12
14,4,21:18.12
15,4,21:18.12
16,4,21:18.12
17,4,21:18.12
18,4,21:18.12
19,4,21:18.12
22,4,21:18.12
-1,5,21:17.12
0,5,21:17.12
8,5,21:18.12
9,5,21:18.12
10,5,21:18.12
11,5,21:18.12
12,5,21:18.12
13,5,21:18.12
14,5,21:18.12
15,5,21:18.12
16,5,21:18.12
17,5,21:18.12
19,5,21:18.12
20,5,21:18.12
10,6,21:18.12
11,6,21:18.12
12,6,21:18.12
13,6,21:18.12
14,6,21:18.12
15,6,21:18.12
16,6,21:18.12
17,6,21:18.12
20,6,21:18.12
11,7,21:18.12
12,7,21:18.12
13,7,21:18.12
14,7,21:18.12
15,7,21:18.12
16,7,21:18.12
17,7,21:18.12
20,7,21:18.12
13,8,21:18.12
14,8,21:18.12
15,8,21:18.12
16,8,21:18.12
17,8,21:18.12
18,8,21:18.12
11,9,21:18.12
12,9,21:18.12
13,9,21:18.12
14,9,21:18.12
15,9,21:18.12
16,9,21:18.12
17,9,21:18.12
18,9,21:18.12
13,10,21:18.12
14,10,21:18.12
15,10,21:18.12
16,10,21:18.12
17,10,21:18.12
18,10,21:18.12
19,10,21:18.12
13,11,21:18.12
14,11,21:18.12
15,11,21:18.12
16,11,21:18.12
19,11,21:18.12
13,12,21:18.12
15,12,21:18.12
16,12,21:18.12
18,12,21:18.12
13,13,21:18.12
15,13,21:18.12
16,13,21:18.12
17,13,21:18.12
18,13,21:18.12
20,13,21:18.12
13,14,21:18.12
15,14,21:18.12
17,14,21:18.12
18,14,21:18.12
19,14,21:18.12
12,15,21:18.12
13,15,21:18.12
17,15,21:18.12
18,15,21:18.12
19,15,21:18.12
12,16,21:18.12
13,16,21:18.12
14,16,21:18.12
12,17,21:18.12
13,17,21:18.12
14,17,21:18.12
15,17,21:18.12
16,17,21:18.12
14,18,21:18.12
15,18,21:18.12
14,19,21:18.12
15,19,21:18.12
16,19,21:18.12
6,-13,22:17.12
7,-13,22:17.12
8,-13,22:17.12
6,-12,22:17.12
7,-12,22:17.12
8,-12,22:17.12
9,-12,22:17.12
6,-11,22:17.12
7,-11,22:17.12
8,-11,22:17.12
9,-11,22:17.12
10,-11,22:17.12
12,-11,22:17.12
13,-11,22:17.12
14,-11,22:17.12
15,-11,22:17.12
16,-11,22:17.12
7,-10,22:17.12
8,-10,22:17.12
9,-10,22:17.12
10,-10,22:17.12
11,-10,22:17.12
12,-10,22:17.12
13,-10,22:17.12
14,-10,22:17.12
15,-10,22:17.12
16,-10,22:17.12
8,-9,22:17.12
9,-9,22:17.12
10,-9,22:17.12
11,-9,22:17.12
12,-9,22:17.12
13,-9,22:17.12
14,-9,22:17.12
15,-9,22:17.12
16,-9,22:17.12
17,-9,22:17.12
9,-8,22:17.12
10,-8,22:17.12
11,-8,22:17.12
12,-8,22:17.12
13,-8,22:17.12
14,-8,22:17.12
15,-8,22:17.12
16,-8,22:17.12
17,-8,22:17.12
14,-7,22:17.12
15,-7,22:17.12
-3,-5,22:17.12
-4,-4,22:17.12
-3,-4,22:17.12
-2,-4,22:17.12
-1,-4,22:17.12
-3,-3,22:17.12
-2,-3,22:17.12
-1,-3,22:17.12
-2,-2,22:17.12
-1,-2,22:17.12
0,-2,22:17.12
-1,-1,22:17.12
0,-1,22:17.12
1,-1,22:17.12
-1,0,22:17.12
0,0,22:17.12
1,0,22:17.12
21,0,22:18.12
-1,1,22:17.12
0,1,22:17.12
1,1,22:17.12
2,1,22:17.12
19,1,22:18.12
-2,2,22:17.12
-1,2,22:17.12
0,2,22:17.12
1,2,22:17.12
2,2,22:17.12
3,2,22:17.12
13,2,22:18.12
20,2,22:18.12
-3,3,22:17.12
-2,3,22:17.12
-1,3,22:17.12
0,3,22:17.12
1,3,22:17.12
2,3,22:17.12
3,3,22:17.12
12,3,22:18.12
13,3,22:18.12
17,3,22:18.12
20,3,22:18.12
-3,4,22:17.12
-2,4,22:17.12
-1,4,22:17.12
0,4,22:17.12
1,4,22:17.12
2,4,22:17.12
13,4,22:18.12
15,4,22:18.12
16,4,22:18.12
17,4,22:18.12
20,4,22:18.12
-2,5,22:17.12
-1,5,22:17.12
0,5,22:17.12
1,5,22:17.12
11,5,22:18.12
13,5,22:18.12
14,5,22:18.12
16,5,22:18.12
17,5,22:18.12
13,6,22:18.12
15,6,22:18.12
16,6,22:18.12
20,6,22:18.12
12,7,22:18.12
13,7,22:18.12
14,7,22:18.12
15,7,22:18.12
16,7,22:18.12
17,7,22:18.12
18,7,22:18.12
13,8,22:18.12
17,8,22:18.12
18,8,22:18.12
18,9,22:18.12
17,10,22:18.12
19,10,22:18.12
13,11,22:18.12
15,11,22:18.12
13,12,22:18.12
14,12,22:18.12
15,12,22:18.12
16,12,22:18.12
13,13,22:18.12
16,13,22:18.12
15,14,22:18.12
16,14,22:18.12
18,14,22:18.12
13,15,22:18.12
15,15,22:18.12
16,15,22:18.12
17,15,22:18.12
19,15,22:18.12
13,17,22:18.12
14,19,22:18.12
7,-14,23:17.12
5,-13,23:17.12
6,-13,23:17.12
7,-13,23:17.12
8,-13,23:17.12
5,-12,23:17.12
6,-12,23:17.12
7,-12,23:17.12
8,-12,23:17.12
9,-12,23:17.12
14,-12,23:17.12
15,-12,23:17.12
5,-11,23:17.12
6,-11,23:17.12
7,-11,23:17.12
8,-11,23:17.12
9,-11,23:17.12
13,-11,23:17.12
14,-11,23:17.12
15,-11,23:17.12
16,-11,23:17.12
7,-10,23:17.12
8,-10,23:17.12
9,-10,23:17.12
12,-10,23:17.12
13,-10,23:17.12
14,-10,23:17.12
15,-10,23:17.12
16,-10,23:17.12
17,-10,23:17.12
13,-9,23:17.12
14,-9,23:17.12
15,-9,23:17.12
16,-9,23:17.12
17,-9,23:17.12
14,-8,23:17.12
15,-8,23:17.12
16,-8,23:17.12
17,-8,23:17.12
-6,-7,23:17.12
15,-7,23:17.12
16,-7,23:17.12
17,-7,23:17.12
-5,-6,23:17.12
-4,-6,23:17.12
-3,-6,23:17.12
-5,-5,23:17.12
-4,-5,23:17.12
-3,-5,23:17.12
-2,-5,23:17.12
-4,-4,23:17.12
-3,-4,23:17.12
-2,-4,23:17.12
-4,-3,23:17.12
-3,-3,23:17.12
-2,-3,23:17.12
-1,-3,23:17.12
0,0,23:17.12
1,0,23:17.12
-1,1,23:17.12
0,1,23:17.12
1,1,23:17.12
2,1,23:17.12
3,1,23:17.12
-2,2,23:17.12
-1,2,23:17.12
0,2,23:17.12
1,2,23:17.12
2,2,23:17.12
3,2,23:17.12
-3,3,23:17.12
-2,3,23:17.12
-1,3,23:17.12
0,3,23:17.12
1,3,23:17.12
2,3,23:17.12
3,3,23:17.12
4,3,23:17.12
-3,4,23:17.12
-2,4,23:17.12
-1,4,23:17.12
0,4,23:17.12
1,4,23:17.12
2,4,23:17.12
3,4,23:17.12
13,4,23:18.12
17,4,23:18.12
-3,5,23:17.12
-2,5,23:17.12
-1,5,23:17.12
0,5,23:17.12
1,5,23:17.12
-2,6,23:17.12
-1,6,23:17.12
0,6,23:17.12
13,6,23:18.12
14,6,23:18.12
16,6,23:18.12
17,6,23:18.12
14,7,23:18.12
15,7,23:18.12
16,7,23:18.12
17,7,23:18.12
18,7,23:18.12
12,8,23:18.12
13,8,23:18.12
14,8,23:18.12
15,8,23:18.12
16,8,23:18.12
12,9,23:18.12
13,9,23:18.12
14,9,23:18.12
13,10,23:18.12
12,14,23:18.12
13,14,23:18.12
13,15,23:18.12
19,15,23:18.12
13,16,23:18.12
5,-14,24:17.12
6,-14,24:17.12
4,-13,24:17.12
5,-13,24:17.12
6,-13,24:17.12
7,-13,24:17.12
8,-13,24:17.12
15,-13,24:17.12
4,-12,24:17.12
5,-12,24:17.12
6,-12,24:17.12
7,-12,24:17.12
8,-12,24:17.12
14,-12,24:17.12
15,-12,24:17.12
16,-12,24:17.12
5,-11,24:17.12
6,-11,24:17.12
7,-11,24:17.12
8,-11,24:17.12
9,-11,24:17.12
14,-11,24:17.12
15,-11,24:17.12
16,-11,24:17.12
5,-10,24:17.12
6,-10,24:17.12
7,-10,24:17.12
8,-10,24:17.12
13,-10,24:17.12
14,-10,24:17.12
15,-10,24:17.12
16,-10,24:17.12
17,-10,24:17.12
14,-9,24:17.12
15,-9,24:17.12
16,-9,24:17.12
17,-9,24:17.12
18,-9,24:17.12
-8,-8,24:17.12
-7,-8,24:17.12
-6,-8,24:17.12
-5,-8,24:17.12
14,-8,24:17.12
15,-8,24:17.12
16,-8,24:17.12
17,-8,24:17.12
18,-8,24:17.12
-7,-7,24:17.12
-6,-7,24:17.12
-5,-7,24:17.12
-4,-7,24:17.12
15,-7,24:17.12
16,-7,24:17.12
17,-7,24:17.12
18,-7,24:17.12
-7,-6,24:17.12
-6,-6,24:17.12
-5,-6,24:17.12
-4,-6,24:17.12
-3,-6,24:17.12
-6,-5,24:17.12
-5,-5,24:17.12
-4,-5,24:17.12
-3,-5,24:17.12
-5,-4,24:17.12
-4,-4,24:17.12
-3,-4,24:17.12
-2,-4,24:17.12
-3,-3,24:17.12
0,1,24:17.12
1,1,24:17.12
2,1,24:17.12
-1,2,24:17.12
0,2,24:17.12
1,2,24:17.12
2,2,24:17.12
3,2,24:17.12
4,2,24:17.12
-3,3,24:17.12
-2,3,24:17.12
-1,3,24:17.12
0,3,24:17.12
1,3,24:17.12
2,3,24:17.12
3,3,24:17.12
4,3,24:17.12
-3,4,24:17.12
-2,4,24:17.12
-1,4,24:17.12
0,4,24:17.12
1,4,24:17.12
2,4,24:17.12
3,4,24:17.12
4,4,24:17.12
-3,5,24:17.12
-2,5,24:17.12
-1,5,24:17.12
0,5,24:17.12
1,5,24:17.12
2,5,24:17.12
-3,6,24:17.12
-2,6,24:17.12
-1,6,24:17.12
0,6,24:17.12
15,6,24:18.12
16,6,24:18.12
17,6,24:18.12
-2,7,24:17.12
-1,7,24:17.12
0,7,24:17.12
14,7,24:18.12
15,7,24:18.12
16,7,24:18.12
14,8,24:18.12
16,8,24:18.12
17,8,24:18.12
16,9,24:18.12
15,-20,25:18.12
4,-15,25:17.12
3,-14,25:17.12
4,-14,25:17.12
5,-14,25:17.12
6,-14,25:17.12
15,-14,25:17.12
16,-14,25:17.12
17,-14,25:17.12
4,-13,25:17.12
5,-13,25:17.12
6,-13,25:17.12
7,-13,25:17.12
14,-13,25:17.12
15,-13,25:17.12
16,-13,25:17.12
4,-12,25:17.12
5,-12,25:17.12
6,-12,25:17.12
7,-12,25:17.12
15,-12,25:17.12
16,-12,25:17.12
4,-11,25:17.12
5,-11,25:17.12
6,-11,25:17.12
7,-11,25:17.12
8,-11,25:17.12
15,-11,25:17.12
16,-11,25:17.12
5,-10,25:17.12
6,-10,25:17.12
7,-10,25:17.12
15,-10,25:17.12
16,-10,25:17.12
-9,-9,25:17.12
-8,-9,25:17.12
-7,-9,25:17.12
-6,-9,25:17.12
15,-9,25:17.12
16,-9,25:17.12
17,-9,25:17.12
18,-9,25:17.12
-8,-8,25:17.12
-7,-8,25:17.12
-6,-8,25:17.12
-5,-8,25:17.12
16,-8,25:17.12
17,-8,25:17.12
18,-8,25:17.12
19,-8,25:17.12
-8,-7,25:17.12
-7,-7,25:17.12
-6,-7,25:17.12
-5,-7,25:17.12
-4,-7,25:17.12
16,-7,25:17.12
17,-7,25:17.12
18,-7,25:17.12
19,-7,25:17.12
-7,-6,25:17.12
-6,-6,25:17.12
-5,-6,25:17.12
-4,-6,25:17.12
-3,-6,25:17.12
-6,-5,25:17.12
-5,-5,25:17.12
-4,-5,25:17.12
-3,-5,25:17.12
-4,-4,25:17.12
1,2,25:17.12
2,2,25:17.12
3,2,25:17.12
4,2,25:17.12
-3,3,25:17.12
-2,3,25:17.12
-1,3,25:17.12
0,3,25:17.12
1,3,25:17.12
2,3,25:17.12
3,3,25:17.12
4,3,25:17.12
-3,4,25:17.12
-2,4,25:17.12
-1,4,25:17.12
0,4,25:17.12
1,4,25:17.12
2,4,25:17.12
3,4,25:17.12
4,4,25:17.12
5,4,25:17.12
-3,5,25:17.12
-2,5,25:17.12
-1,5,25:17.12
0,5,25:17.12
1,5,25:17.12
4,5,25:17.12
-4,6,25:17.12
-3,6,25:17.12
-2,6,25:17.12
-1,6,25:17.12
0,6,25:17.12
-4,7,25:17.12
-3,7,25:17.12
-2,7,25:17.12
-1,7,25:17.12
0,7,25:17.12
-3,8,25:17.12
-2,8,25:17.12
-1,8,25:17.12
16,-23,26:18.12
15,-20,26:18.12
15,-19,26:18.12
3,-16,26:17.12
2,-15,26:17.12
3,-15,26:17.12
4,-15,26:17.12
5,-15,26:17.12
16,-15,26:17.12
3,-14,26:17.12
4,-14,26:17.12
5,-14,26:17.12
6,-14,26:17.12
15,-14,26:17.12
16,-14,26:17.12
17,-14,26:17.12
3,-13,26:17.12
4,-13,26:17.12
5,-13,26:17.12
6,-13,26:17.12
15,-13,26:17.12
16,-13,26:17.12
4,-12,26:17.12
5,-12,26:17.12
6,-12,26:17.12
7,-12,26:17.12
15,-12,26:17.12
5,-11,26:17.12
6,-11,26:17.12
7,-11,26:17.12
-8,-10,26:17.12
5,-10,26:17.12
6,-10,26:17.12
7,-10,26:17.12
-9,-9,26:17.12
-8,-9,26:17.12
-7,-9,26:17.12
-9,-8,26:17.12
-8,-8,26:17.12
-7,-8,26:17.12
-6,-8,26:17.12
-5,-8,26:17.12
17,-8,26:17.12
18,-8,26:17.12
19,-8,26:17.12
20,-8,26:17.12
-9,-7,26:17.12
-8,-7,26:17.12
-7,-7,26:17.12
-6,-7,26:17.12
-5,-7,26:17.12
-4,-7,26:17.12
17,-7,26:17.12
18,-7,26:17.12
19,-7,26:17.12
20,-7,26:17.12
-8,-6,26:17.12
-7,-6,26:17.12
-6,-6,26:17.12
-5,-6,26:17.12
-4,-6,26:17.12
18,-6,26:17.12
19,-6,26:17.12
20,-6,26:17.12
-6,-5,26:17.12
-5,-5,26:17.12
2,2,26:17.12
3,2,26:17.12
4,2,26:17.12
1,3,26:17.12
2,3,26:17.12
3,3,26:17.12
4,3,26:17.12
5,3,26:17.12
-1,4,26:17.12
2,4,26:17.12
3,4,26:17.12
4,4,26:17.12
5,4,26:17.12
-3,5,26:17.12
-2,5,26:17.12
-1,5,26:17.12
0,5,26:17.12
3,5,26:17.12
4,5,26:17.12
5,5,26:17.12
6,5,26:17.12
-4,6,26:17.12
-3,6,26:17.12
-2,6,26:17.12
-1,6,26:17.12
0,6,26:17.12
-4,7,26:17.12
-3,7,26:17.12
-2,7,26:17.12
-1,7,26:17.12
-4,8,26:17.12
-3,8,26:17.12
-2,8,26:17.12
-1,8,26:17.12
14,-24,27:18.12
15,-24,27:18.12
15,-23,27:18.12
16,-23,27:18.12
16,-22,27:18.12
14,-21,27:18.12
16,-21,27:18.12
18,-21,27:18.12
14,-20,27:18.12
15,-20,27:18.12
16,-20,27:18.12
17,-20,27:18.12
15,-19,27:18.12
16,-19,27:18.12
17,-19,27:18.12
15,-18,27:18.12
17,-18,27:18.12
1,-17,27:17.12
2,-17,27:17.12
3,-17,27:17.12
1,-16,27:17.12
2,-16,27:17.12
3,-16,27:17.12
4,-16,27:17.12
2,-15,27:17.12
3,-15,27:17.12
4,-15,27:17.12
17,-15,27:17.12
2,-14,27:17.12
3,-14,27:17.12
4,-14,27:17.12
5,-14,27:17.12
15,-14,27:17.12
16,-14,27:17.12
17,-14,27:17.12
4,-13,27:17.12
5,-13,27:17.12
6,-13,27:17.12
16,-13,27:17.12
17,-13,27:17.12
5,-12,27:17.12
6,-12,27:17.12
7,-12,27:17.12
4,-11,27:17.12
5,-11,27:17.12
6,-11,27:17.12
7,-11,27:17.12
8,-11,27:17.12
5,-10,27:17.12
6,-10,27:17.12
7,-10,27:17.12
8,-10,27:17.12
20,-10,27:17.12
-9,-9,27:17.12
-8,-9,27:17.12
6,-9,27:17.12
7,-9,27:17.12
8,-9,27:17.12
19,-9,27:17.12
20,-9,27:17.12
-10,-8,27:17.12
-9,-8,27:17.12
-8,-8,27:17.12
-7,-8,27:17.12
18,-8,27:17.12
19,-8,27:17.12
20,-8,27:17.12
21,-8,27:17.12
-10,-7,27:17.12
-9,-7,27:17.12
-8,-7,27:17.12
-7,-7,27:17.12
-6,-7,27:17.12
18,-7,27:17.12
19,-7,27:17.12
20,-7,27:17.12
21,-7,27:17.12
-9,-6,27:17.12
-8,-6,27:17.12
-7,-6,27:17.12
-6,-6,27:17.12
-5,-6,27:17.12
18,-6,27:17.12
19,-6,27:17.12
20,-6,27:17.12
21,-6,27:17.12
19,-5,27:17.12
20,-5,27:17.12
21,-5,27:17.12
2,2,27:17.12
3,2,27:17.12
4,2,27:17.12
2,3,27:17.12
3,3,27:17.12
4,3,27:17.12
5,3,27:17.12
2,4,27:17.12
3,4,27:17.12
4,4,27:17.12
5,4,27:17.12
6,4,27:17.12
7,4,27:17.12
3,5,27:17.12
4,5,27:17.12
5,5,27:17.12
6,5,27:17.12
7,5,27:17.12
-3,6,27:17.12
-2,6,27:17.12
-1,6,27:17.12
4,6,27:17.12
5,6,27:17.12
6,6,27:17.12
7,6,27:17.12
-4,7,27:17.12
-3,7,27:17.12
-2,7,27:17.12
-1,7,27:17.12
-4,8,27:17.12
-3,8,27:17.12
-2,8,27:17.12
-1,8,27:17.12
-3,9,27:17.12
-2,9,27:17.12
25,-31,28:18.12
12,-30,28:18.12
21,-30,28:18.12
25,-30,28:18.12
15,-24,28:18.12
14,-23,28:18.12
15,-23,28:18.12
16,-23,28:18.12
14,-22,28:18.12
15,-22,28:18.12
16,-22,28:18.12
17,-22,28:18.12
18,-22,28:18.12
15,-21,28:18.12
16,-21,28:18.12
17,-21,28:18.12
18,-21,28:18.12
15,-20,28:18.12
16,-20,28:18.12
17,-20,28:18.12
1,-19,28:17.12
2,-19,28:17.12
15,-19,28:18.12
16,-19,28:18.12
1,-18,28:17.12
2,-18,28:17.12
3,-18,28:17.12
15,-18,28:18.12
16,-18,28:18.12
1,-17,28:17.12
2,-17,28:17.12
3,-17,28:17.12
1,-16,28:17.12
2,-16,28:17.12
3,-16,28:17.12
17,-16,28:17.12
18,-16,28:17.12
1,-15,28:17.12
2,-15,28:17.12
3,-15,28:17.12
4,-15,28:17.12
16,-15,28:17.12
17,-15,28:17.12
3,-14,28:17.12
15,-14,28:17.12
16,-14,28:17.12
17,-14,28:17.12
16,-13,28:17.12
5,-12,28:17.12
6,-12,28:17.12
7,-12,28:17.12
5,-11,28:17.12
6,-11,28:17.12
7,-11,28:17.12
8,-11,28:17.12
6,-10,28:17.12
7,-10,28:17.12
8,-10,28:17.12
9,-10,28:17.12
-10,-9,28:17.12
-9,-9,28:17.12
6,-9,28:17.12
7,-9,28:17.12
8,-9,28:17.12
20,-9,28:17.12
-11,-8,28:17.12
-10,-8,28:17.12
-9,-8,28:17.12
-8,-8,28:17.12
7,-8,28:17.12
20,-8,28:17.12
-10,-7,28:17.12
-9,-7,28:17.12
-8,-7,28:17.12
-7,-7,28:17.12
19,-7,28:17.12
20,-7,28:17.12
21,-7,28:17.12
-10,-6,28:17.12
-9,-6,28:17.12
-8,-6,28:17.12
19,-6,28:17.12
20,-6,28:17.12
21,-6,28:17.12
20,-5,28:17.12
21,-5,28:17.12
14,2,28:18.12
3,3,28:17.12
4,3,28:17.12
5,3,28:17.12
6,3,28:17.12
14,3,28:18.12
15,3,28:18.12
3,4,28:17.12
4,4,28:17.12
5,4,28:17.12
6,4,28:17.12
7,4,28:17.12
3,5,28:17.12
4,5,28:17.12
5,5,28:17.12
6,5,28:17.12
7,5,28:17.12
8,5,28:17.12
5,6,28:17.12
6,6,28:17.12
7,6,28:17.12
8,6,28:17.12
-4,7,28:17.12
-3,7,28:17.12
-2,7,28:17.12
7,7,28:17.12
8,7,28:17.12
9,7,28:17.12
-4,8,28:17.12
-3,8,28:17.12
-2,8,28:17.12
-4,9,28:17.12
-3,9,28:17.12
-2,9,28:17.12
-4,10,28:17.12
-3,10,28:17.12
-4,11,28:17.12
-3,11,28:17.12
19,-33,29:18.12
12,-32,29:18.12
12,-31,29:18.12
24,-31,29:18.12
25,-31,29:18.12
26,-31,29:18.12
12,-30,29:18.12
13,-30,29:18.12
14,-30,29:18.12
21,-30,29:18.12
25,-30,29:18.12
13,-29,29:18.12
11,-26,29:18.12
11,-24,29:18.12
12,-24,29:18.12
15,-24,29:18.12
16,-24,29:18.12
17,-24,29:18.12
15,-23,29:18.12
16,-23,29:18.12
17,-23,29:18.12
13,-22,29:18.12
14,-22,29:18.12
15,-22,29:18.12
16,-22,29:18.12
17,-22,29:18.12
11,-21,29:18.12
12,-21,29:18.12
13,-21,29:18.12
15,-21,29:18.12
16,-21,29:18.12
0,-20,29:17.12
14,-20,29:18.12
15,-20,29:18.12
16,-20,29:18.12
17,-20,29:18.12
20,-20,29:18.12
1,-19,29:17.12
2,-19,29:17.12
15,-19,29:18.12
16,-19,29:18.12
17,-19,29:18.12
18,-19,29:18.12
20,-19,29:18.12
21,-19,29:18.12
22,-19,29:18.12
1,-18,29:17.12
2,-18,29:17.12
3,-18,29:17.12
16,-18,29:18.12
21,-18,29:18.12
22,-18,29:18.12
1,-17,29:17.12
2,-17,29:17.12
3,-17,29:17.12
21,-17,29:18.12
2,-16,29:17.12
3,-16,29:17.12
17,-16,29:17.12
21,-16,29:18.12
2,-15,29:17.12
16,-15,29:17.12
17,-15,29:17.12
18,-15,29:17.12
15,-14,29:17.12
16,-14,29:17.12
17,-14,29:17.12
7,-11,29:17.12
8,-11,29:17.12
-10,-10,29:17.12
6,-10,29:17.12
7,-10,29:17.12
8,-10,29:17.12
-11,-9,29:17.12
-10,-9,29:17.12
-9,-9,29:17.12
6,-9,29:17.12
7,-9,29:17.12
8,-9,29:17.12
-11,-8,29:17.12
-10,-8,29:17.12
-9,-8,29:17.12
6,-8,29:17.12
7,-8,29:17.12
8,-8,29:17.12
-10,-7,29:17.12
-9,-7,29:17.12
7,-7,29:17.12
20,-7,29:17.12
21,-7,29:17.12
19,-6,29:17.12
20,-6,29:17.12
21,-6,29:17.12
22,-6,29:17.12
20,-5,29:17.12
21,-5,29:17.12
22,-5,29:17.12
21,-4,29:17.12
22,-4,29:17.12
22,-3,29:17.12
23,-3,29:17.12
13,1,29:18.12
14,1,29:18.12
14,2,29:18.12
4,4,29:17.12
5,4,29:17.12
6,4,29:17.12
7,4,29:17.12
12,4,29:18.12
13,4,29:18.12
5,5,29:17.12
6,5,29:17.12
7,5,29:17.12
8,5,29:17.12
9,5,29:17.12
12,5,29:18.12
13,5,29:18.12
6,6,29:17.12
7,6,29:17.12
8,6,29:17.12
9,6,29:17.12
10,6,29:17.12
13,6,29:18.12
7,7,29:17.12
8,7,29:17.12
9,7,29:17.12
10,7,29:17.12
-3,8,29:17.12
8,8,29:17.12
9,8,29:17.12
-4,9,29:17.12
-3,9,29:17.12
-2,9,29:17.12
-4,10,29:17.12
-3,10,29:17.12
-2,10,29:17.12
-5,11,29:17.12
-4,11,29:17.12
-3,11,29:17.12
-2,11,29:17.12
-4,12,29:17.12
-3,12,29:17.12
0,23,29:18.12
-2,24,29:18.12
0,24,29:18.12
17,-34,30:18.12
19,-34,30:18.12
17,-33,30:18.12
18,-33,30:18.12
19,-33,30:18.12
13,-32,30:18.12
14,-32,30:18.12
15,-32,30:18.12
19,-32,30:18.12
21,-32,30:18.12
22,-32,30:18.12
11,-31,30:18.12
12,-31,30:18.12
13,-31,30:18.12
14,-31,30:18.12
21,-31,30:18.12
25,-31,30:18.12
8,-30,30:18.12
13,-30,30:18.12
14,-30,30:18.12
15,-30,30:18.12
21,-30,30:18.12
22,-30,30:18.12
22,-29,30:18.12
21,-28,30:18.12
11,-26,30:18.12
12,-26,30:18.12
11,-25,30:18.12
11,-24,30:18.12
12,-24,30:18.12
13,-24,30:18.12
17,-24,30:18.12
11,-23,30:18.12
12,-23,30:18.12
14,-23,30:18.12
15,-23,30:18.12
16,-23,30:18.12
17,-23,30:18.12
18,-23,30:18.12
-4,-22,30:18.12
10,-22,30:18.12
11,-22,30:18.12
12,-22,30:18.12
14,-22,30:18.12
15,-22,30:18.12
16,-22,30:18.12
17,-22,30:18.12
18,-22,30:18.12
20,-22,30:18.12
-5,-21,30:18.12
-4,-21,30:18.12
0,-21,30:17.12
11,-21,30:18.12
12,-21,30:18.12
13,-21,30:18.12
14,-21,30:18.12
15,-21,30:18.12
16,-21,30:18.12
17,-21,30:18.12
-5,-20,30:18.12
-3,-20,30:17.12
-1,-20,30:17.12
12,-20,30:18.12
13,-20,30:18.12
14,-20,30:18.12
15,-20,30:18.12
16,-20,30:18.12
17,-20,30:18.12
18,-20,30:18.12
22,-20,30:18.12
23,-20,30:18.12
0,-19,30:17.12
1,-19,30:17.12
2,-19,30:17.12
15,-19,30:18.12
16,-19,30:18.12
17,-19,30:18.12
18,-19,30:18.12
2,-18,30:17.12
14,-18,30:18.12
15,-18,30:18.12
16,-18,30:18.12
17,-18,30:18.12
18,-18,30:18.12
19,-18,30:18.12
22,-18,30:18.12
23,-18,30:18.12
15,-17,30:18.12
16,-17,30:18.12
20,-17,30:18.12
21,-17,30:18.12
22,-17,30:18.12
17,-16,30:17.12
18,-16,30:17.12
22,-16,30:18.12
17,-15,30:17.12
18,-15,30:17.12
7,-10,30:17.12
-11,-9,30:17.12
-10,-9,30:17.12
6,-9,30:17.12
7,-9,30:17.12
8,-9,30:17.12
-11,-8,30:17.12
-10,-8,30:17.12
-9,-8,30:17.12
0,-8,30:18.12
6,-8,30:17.12
7,-8,30:17.12
8,-8,30:17.12
-18,-7,30:18.12
-10,-7,30:17.12
-1,-7,30:18.12
7,-7,30:17.12
8,-7,30:17.12
-19,-6,30:18.12
-18,-6,30:18.12
8,-6,30:17.12
21,-6,30:17.12
22,-6,30:17.12
-20,-5,30:18.12
-19,-5,30:18.12
21,-5,30:17.12
22,-5,30:17.12
-20,-4,30:18.12
21,-4,30:17.12
22,-4,30:17.12
-5,-3,30:18.12
-4,-3,30:18.12
13,-3,30:18.12
22,-3,30:17.12
-6,-2,30:18.12
-5,-2,30:18.12
22,-2,30:17.12
23,-2,30:17.12
13,-1,30:18.12
14,-1,30:18.12
15,-1,30:18.12
22,-1,30:17.12
23,-1,30:17.12
11,0,30:18.12
13,0,30:18.12
15,0,30:18.12
13,1,30:18.12
14,1,30:18.12
15,1,30:18.12
13,2,30:18.12
14,2,30:18.12
15,2,30:18.12
16,2,30:18.12
11,3,30:18.12
12,3,30:18.12
13,3,30:18.12
14,3,30:18.12
15,3,30:18.12
16,3,30:18.12
25,3,30:18.12
8,4,30:17.12
13,4,30:18.12
14,4,30:18.12
15,4,30:18.12
25,4,30:18.12
6,5,30:17.12
7,5,30:17.12
8,5,30:17.12
9,5,30:17.12
12,5,30:18.12
13,5,30:18.12
14,5,30:18.12
6,6,30:17.12
7,6,30:17.12
8,6,30:17.12
9,6,30:17.12
10,6,30:17.12
7,7,30:17.12
8,7,30:17.12
9,7,30:17.12
10,7,30:17.12
8,8,30:17.12
9,8,30:17.12
10,8,30:17.12
-3,9,30:17.12
9,9,30:17.12
10,9,30:17.12
-5,10,30:17.12
-4,10,30:17.12
-3,10,30:17.12
-6,11,30:17.12
-5,11,30:17.12
-4,11,30:17.12
-3,11,30:17.12
-2,11,30:17.12
-6,12,30:17.12
-5,12,30:17.12
-4,12,30:17.12
-3,12,30:17.12
-2,12,30:17.12
-5,13,30:17.12
-4,13,30:17.12
-3,13,30:17.12
-1,22,30:18.12
-2,23,30:18.12
-1,23,30:18.12
-3,24,30:18.12
-2,24,30:18.12
-1,24,30:18.12
0,24,30:18.12
-3,25,30:18.12
0,25,30:18.12
26,-37,31:18.12
26,-36,31:18.12
16,-35,31:18.12
17,-35,31:18.12
19,-35,31:18.12
24,-35,31:18.12
1,-34,31:18.12
18,-34,31:18.12
19,-34,31:18.12
-1,-33,31:18.12
0,-33,31:18.12
1,-33,31:18.12
2,-33,31:18.12
3,-33,31:18.12
17,-33,31:18.12
18,-33,31:18.12
19,-33,31:18.12
25,-33,31:18.12
1,-32,31:18.12
2,-32,31:18.12
17,-32,31:18.12
18,-32,31:18.12
19,-32,31:18.12
20,-32,31:18.12
21,-32,31:18.12
22,-32,31:18.12
24,-32,31:18.12
25,-32,31:18.12
11,-31,31:18.12
12,-31,31:18.12
13,-31,31:18.12
17,-31,31:18.12
18,-31,31:18.12
20,-31,31:18.12
21,-31,31:18.12
23,-31,31:18.12
25,-31,31:18.12
26,-31,31:18.12
27,-31,31:18.12
1,-30,31:18.12
2,-30,31:18.12
3,-30,31:18.12
4,-30,31:18.12
8,-30,31:18.12
13,-30,31:18.12
14,-30,31:18.12
21,-30,31:18.12
22,-30,31:18.12
23,-30,31:18.12
26,-30,31:18.12
2,-29,31:18.12
3,-29,31:18.12
6,-29,31:18.12
13,-29,31:18.12
20,-29,31:18.12
22,-29,31:18.12
21,-28,31:18.12
23,-27,31:18.12
5,-26,31:18.12
11,-26,31:18.12
-1,-25,31:18.12
11,-25,31:18.12
12,-25,31:18.12
-1,-24,31:18.12
10,-24,31:18.12
11,-24,31:18.12
12,-24,31:18.12
-5,-23,31:18.12
-3,-23,31:18.12
11,-23,31:18.12
12,-23,31:18.12
13,-23,31:18.12
14,-23,31:18.12
15,-23,31:18.12
23,-23,31:18.12
-6,-22,31:18.12
-5,-22,31:18.12
-4,-22,31:18.12
-3,-22,31:18.12
11,-22,31:18.12
12,-22,31:18.12
13,-22,31:18.12
14,-22,31:18.12
15,-22,31:18.12
16,-22,31:18.12
17,-22,31:18.12
20,-22,31:18.12
22,-22,31:18.12
-5,-21,31:18.12
-4,-21,31:18.12
0,-21,31:17.12
11,-21,31:18.12
12,-21,31:18.12
13,-21,31:18.12
14,-21,31:18.12
15,-21,31:18.12
16,-21,31:18.12
17,-21,31:18.12
20,-21,31:18.12
21,-21,31:18.12
22,-21,31:18.12
-6,-20,31:18.12
-5,-20,31:18.12
-4,-20,31:18.12
-3,-20,31:17.12
-2,-20,31:17.12
-1,-20,31:17.12
13,-20,31:18.12
14,-20,31:18.12
15,-20,31:18.12
16,-20,31:18.12
18,-20,31:18.12
20,-20,31:18.12
23,-20,31:18.12
-8,-19,31:18.12
-4,-19,31:18.12
-3,-19,31:17.12
13,-19,31:18.12
16,-19,31:18.12
18,-19,31:18.12
20,-19,31:18.12
21,-19,31:18.12
22,-19,31:18.12
23,-19,31:18.12
-8,-18,31:18.12
14,-18,31:18.12
15,-18,31:18.12
18,-18,31:18.12
19,-18,31:18.12
20,-18,31:18.12
21,-18,31:18.12
22,-18,31:18.12
15,-17,31:18.12
16,-17,31:18.12
18,-17,31:17.12
19,-17,31:18.12
20,-17,31:18.12
21,-17,31:18.12
22,-17,31:18.12
23,-17,31:18.12
-10,-16,31:18.12
-9,-16,31:18.12
17,-16,31:17.12
18,-16,31:17.12
19,-16,31:17.12
-9,-15,31:18.12
0,-15,31:18.12
1,-15,31:18.12
3,-15,31:18.12
4,-15,31:18.12
17,-15,31:17.12
18,-15,31:17.12
3,-14,31:18.12
-19,-12,31:18.12
-19,-11,31:18.12
-17,-9,31:18.12
-15,-9,31:18.12
-12,-9,31:17.12
-11,-9,31:17.12
-10,-9,31:17.12
-1,-9,31:18.12
7,-9,31:17.12
22,-9,31:18.12
23,-9,31:18.12
-15,-8,31:18.12
-14,-8,31:18.12
-12,-8,31:17.12
-11,-8,31:17.12
-10,-8,31:17.12
-1,-8,31:18.12
0,-8,31:18.12
7,-8,31:17.12
8,-8,31:17.12
-19,-7,31:18.12
-18,-7,31:18.12
-17,-7,31:18.12
-14,-7,31:18.12
-11,-7,31:17.12
-10,-7,31:17.12
-2,-7,31:18.12
-1,-7,31:18.12
7,-7,31:17.12
8,-7,31:17.12
9,-7,31:17.12
-20,-6,31:18.12
-19,-6,31:18.12
-18,-6,31:18.12
-17,-6,31:18.12
-16,-6,31:18.12
7,-6,31:17.12
8,-6,31:17.12
9,-6,31:17.12
-20,-5,31:18.12
-18,-5,31:18.12
8,-5,31:17.12
22,-5,31:17.12
22,-4,31:17.12
-14,-3,31:18.12
-12,-3,31:18.12
-11,-3,31:18.12
-6,-3,31:18.12
-5,-3,31:18.12
12,-3,31:18.12
13,-3,31:18.12
22,-3,31:17.12
23,-3,31:17.12
-13,-2,31:18.12
-7,-2,31:18.12
-6,-2,31:18.12
12,-2,31:18.12
13,-2,31:18.12
22,-2,31:17.12
23,-2,31:17.12
11,-1,31:18.12
13,-1,31:18.12
14,-1,31:18.12
16,-1,31:18.12
21,-1,31:18.12
22,-1,31:17.12
23,-1,31:17.12
35,-1,31:18.12
11,0,31:18.12
14,0,31:18.12
16,0,31:18.12
17,0,31:18.12
18,0,31:18.12
21,0,31:18.12
34,0,31:18.12
-5,1,31:18.12
11,1,31:18.12
13,1,31:18.12
14,1,31:18.12
15,1,31:18.12
13,2,31:18.12
14,2,31:18.12
11,3,31:18.12
13,3,31:18.12
25,3,31:18.12
13,4,31:18.12
23,4,31:18.12
25,4,31:18.12
26,4,31:18.12
7,5,31:17.12
8,5,31:17.12
9,5,31:17.12
14,5,31:18.12
15,5,31:18.12
7,6,31:17.12
8,6,31:17.12
9,6,31:17.12
7,7,31:17.12
8,7,31:17.12
9,7,31:17.12
10,7,31:17.12
8,8,31:17.12
9,8,31:17.12
10,8,31:17.12
8,9,31:17.12
9,9,31:17.12
10,9,31:17.12
8,10,31:17.12
9,10,31:17.12
10,10,31:17.12
-6,11,31:17.12
-5,11,31:17.12
-4,11,31:17.12
-3,11,31:17.12
-7,12,31:17.12
-6,12,31:17.12
-5,12,31:17.12
-4,12,31:17.12
-3,12,31:17.12
-2,12,31:18.12
0,12,31:18.12
-7,13,31:17.12
-6,13,31:17.12
-5,13,31:17.12
-4,13,31:17.12
-3,13,31:17.12
-2,13,31:17.12
-1,13,31:17.12
1,13,31:18.12
-6,14,31:17.12
0,14,31:17.12
-2,15,31:18.12
1,15,31:18.12
2,15,31:18.12
1,16,31:18.12
-2,22,31:18.12
-1,22,31:18.12
-3,23,31:18.12
-2,23,31:18.12
-1,23,31:18.12
0,23,31:18.12
-2,24,31:18.12
-1,24,31:18.12
-3,25,31:18.12
-1,25,31:18.12
0,25,31:18.12
-2,26,31:18.12
-1,26,31:18.12
3,26,31:18.12
0,27,31:18.12
1,28,31:18.12
27,-39,32:18.12
26,-38,32:18.12
27,-38,32:18.12
25,-37,32:18.12
26,-37,32:18.12
27,-37,32:18.12
18,-36,32:18.12
24,-36,32:18.12
26,-36,32:18.12
17,-35,32:18.12
18,-35,32:18.12
19,-35,32:18.12
23,-35,32:18.12
24,-35,32:18.12
25,-35,32:18.12
26,-35,32:18.12
27,-35,32:18.12
18,-34,32:18.12
20,-34,32:18.12
24,-34,32:18.12
26,-34,32:18.12
27,-34,32:18.12
28,-34,32:18.12
29,-34,32:18.12
30,-34,32:18.12
0,-33,32:18.12
1,-33,32:18.12
12,-33,32:18.12
13,-33,32:18.12
14,-33,32:18.12
18,-33,32:18.12
19,-33,32:18.12
20,-33,32:18.12
25,-33,32:18.12
26,-33,32:18.12
27,-33,32:18.12
28,-33,32:18.12
-1,-32,32:18.12
0,-32,32:18.12
1,-32,32:18.12
2,-32,32:18.12
12,-32,32:18.12
13,-32,32:18.12
14,-32,32:18.12
15,-32,32:18.12
17,-32,32:18.12
18,-32,32:18.12
19,-32,32:18.12
20,-32,32:18.12
21,-32,32:18.12
22,-32,32:18.12
24,-32,32:18.12
25,-32,32:18.12
26,-32,32:18.12
1,-31,32:18.12
2,-31,32:18.12
3,-31,32:18.12
4,-31,32:18.12
5,-31,32:18.12
7,-31,32:18.12
10,-31,32:18.12
11,-31,32:18.12
12,-31,32:18.12
13,-31,32:18.12
15,-31,32:18.12
16,-31,32:18.12
17,-31,32:18.12
18,-31,32:18.12
19,-31,32:18.12
20,-31,32:18.12
21,-31,32:18.12
22,-31,32:18.12
23,-31,32:18.12
24,-31,32:18.12
25,-31,32:18.12
26,-31,32:18.12
1,-30,32:18.12
2,-30,32:18.12
3,-30,32:18.12
4,-30,32:18.12
5,-30,32:18.12
6,-30,32:18.12
7,-30,32:18.12
8,-30,32:18.12
9,-30,32:18.12
13,-30,32:18.12
14,-30,32:18.12
15,-30,32:18.12
16,-30,32:18.12
17,-30,32:18.12
18,-30,32:18.12
20,-30,32:18.12
21,-30,32:18.12
22,-30,32:18.12
23,-30,32:18.12
24,-30,32:18.12
25,-30,32:18.12
26,-30,32:18.12
27,-30,32:18.12
1,-29,32:18.12
2,-29,32:18.12
3,-29,32:18.12
4,-29,32:18.12
5,-29,32:18.12
6,-29,32:18.12
12,-29,32:18.12
13,-29,32:18.12
18,-29,32:18.12
20,-29,32:18.12
21,-29,32:18.12
22,-29,32:18.12
2,-28,32:18.12
4,-28,32:18.12
5,-28,32:18.12
6,-28,32:18.12
8,-28,32:18.12
13,-28,32:18.12
21,-28,32:18.12
22,-28,32:18.12
6,-27,32:18.12
7,-27,32:18.12
8,-27,32:18.12
11,-27,32:18.12
14,-27,32:18.12
15,-27,32:18.12
22,-27,32:18.12
23,-27,32:18.12
-4,-26,32:18.12
-3,-26,32:18.12
4,-26,32:18.12
5,-26,32:18.12
6,-26,32:18.12
7,-26,32:18.12
8,-26,32:18.12
11,-26,32:18.12
17,-26,32:18.12
23,-26,32:18.12
5,-25,32:18.12
11,-25,32:18.12
15,-25,32:18.12
22,-25,32:18.12
-5,-24,32:18.12
-4,-24,32:18.12
-3,-24,32:18.12
-1,-24,32:18.12
0,-24,32:18.12
10,-24,32:18.12
11,-24,32:18.12
12,-24,32:18.12
13,-24,32:18.12
14,-24,32:18.12
-7,-23,32:18.12
-5,-23,32:18.12
-4,-23,32:18.12
-3,-23,32:18.12
-1,-23,32:18.12
11,-23,32:18.12
12,-23,32:18.12
13,-23,32:18.12
14,-23,32:18.12
15,-23,32:18.12
21,-23,32:18.12
22,-23,32:18.12
23,-23,32:18.12
24,-23,32:18.12
-8,-22,32:18.12
-7,-22,32:18.12
-6,-22,32:18.12
-5,-22,32:18.12
-4,-22,32:18.12
11,-22,32:18.12
12,-22,32:18.12
13,-22,32:18.12
14,-22,32:18.12
15,-22,32:18.12
16,-22,32:18.12
21,-22,32:18.12
22,-22,32:18.12
23,-22,32:18.12
-6,-21,32:18.12
-5,-21,32:18.12
-4,-21,32:18.12
11,-21,32:18.12
12,-21,32:18.12
13,-21,32:18.12
14,-21,32:18.12
15,-21,32:18.12
20,-21,32:18.12
21,-21,32:18.12
22,-21,32:18.12
23,-21,32:18.12
-4,-20,32:18.12
10,-20,32:18.12
13,-20,32:18.12
14,-20,32:18.12
15,-20,32:18.12
16,-20,32:18.12
18,-20,32:18.12
19,-20,32:18.12
20,-20,32:18.12
21,-20,32:18.12
22,-20,32:18.12
23,-20,32:18.12
24,-20,32:18.12
-9,-19,32:18.12
-8,-19,32:18.12
4,-19,32:18.12
5,-19,32:18.12
16,-19,32:18.12
18,-19,32:18.12
20,-19,32:18.12
21,-19,32:18.12
22,-19,32:18.12
23,-19,32:18.12
24,-19,32:18.12
-8,-18,32:18.12
-7,-18,32:18.12
-2,-18,32:18.12
-1,-18,32:18.12
4,-18,32:18.12
16,-18,32:18.12
17,-18,32:18.12
18,-18,32:18.12
19,-18,32:18.12
22,-18,32:18.12
23,-18,32:18.12
24,-18,32:18.12
-8,-17,32:18.12
-6,-17,32:18.12
-2,-17,32:18.12
13,-17,32:18.12
18,-17,32:17.12
19,-17,32:17.12
20,-17,32:17.12
22,-17,32:18.12
23,-17,32:18.12
-10,-16,32:18.12
-9,-16,32:18.12
-6,-16,32:18.12
-2,-16,32:18.12
1,-16,32:18.12
4,-16,32:18.12
18,-16,32:17.12
19,-16,32:17.12
-7,-15,32:18.12
1,-15,32:18.12
3,-15,32:18.12
5,-15,32:18.12
1,-14,32:18.12
2,-14,32:18.12
5,-13,32:18.12
-21,-12,32:18.12
-19,-12,32:18.12
-3,-12,32:18.12
-22,-11,32:18.12
-21,-11,32:18.12
-19,-11,32:18.12
-4,-11,32:18.12
-3,-11,32:18.12
-2,-11,32:18.12
-19,-10,32:18.12
-17,-10,32:18.12
-15,-10,32:18.12
-12,-10,32:17.12
-3,-10,32:18.12
-2,-10,32:18.12
10,-10,32:18.12
22,-10,32:18.12
-19,-9,32:18.12
-17,-9,32:18.12
-16,-9,32:18.12
-15,-9,32:18.12
-14,-9,32:18.12
-13,-9,32:17.12
-12,-9,32:17.12
-11,-9,32:17.12
21,-9,32:18.12
22,-9,32:18.12
23,-9,32:18.12
24,-9,32:18.12
-18,-8,32:18.12
-17,-8,32:18.12
-16,-8,32:18.12
-15,-8,32:18.12
-14,-8,32:18.12
-12,-8,32:17.12
-11,-8,32:18.12
-10,-8,32:17.12
-2,-8,32:18.12
0,-8,32:18.12
1,-8,32:18.12
8,-8,32:17.12
22,-8,32:18.12
23,-8,32:18.12
-20,-7,32:18.12
-18,-7,32:18.12
-17,-7,32:18.12
-14,-7,32:18.12
-13,-7,32:18.12
-11,-7,32:18.12
-3,-7,32:18.12
-2,-7,32:18.12
-1,-7,32:18.12
0,-7,32:18.12
7,-7,32:17.12
8,-7,32:17.12
9,-7,32:17.12
22,-7,32:18.12
-21,-6,32:18.12
-20,-6,32:18.12
-19,-6,32:18.12
-18,-6,32:18.12
-17,-6,32:18.12
-2,-6,32:18.12
-1,-6,32:18.12
7,-6,32:17.12
8,-6,32:17.12
9,-6,32:17.12
22,-6,32:18.12
-21,-5,32:18.12
-20,-5,32:18.12
-13,-5,32:18.12
-12,-5,32:18.12
-6,-5,32:18.12
-5,-5,32:18.12
-2,-5,32:18.12
8,-5,32:17.12
9,-5,32:17.12
12,-5,32:18.12
13,-5,32:18.12
-12,-4,32:18.12
-10,-4,32:18.12
-7,-4,32:18.12
-6,-4,32:18.12
-5,-4,32:18.12
-2,-4,32:18.12
13,-4,32:18.12
-14,-3,32:18.12
-13,-3,32:18.12
-12,-3,32:18.12
-11,-3,32:18.12
-10,-3,32:18.12
-9,-3,32:18.12
-8,-3,32:18.12
-7,-3,32:18.12
-6,-3,32:18.12
-5,-3,32:18.12
-4,-3,32:18.12
13,-3,32:18.12
14,-3,32:18.12
22,-3,32:17.12
23,-3,32:17.12
-13,-2,32:18.12
-12,-2,32:18.12
-8,-2,32:18.12
-7,-2,32:18.12
-6,-2,32:18.12
-5,-2,32:18.12
-4,-2,32:18.12
-3,-2,32:18.12
12,-2,32:18.12
13,-2,32:18.12
14,-2,32:18.12
15,-2,32:18.12
22,-2,32:17.12
23,-2,32:18.12
24,-2,32:17.12
25,-2,32:18.12
-12,-1,32:18.12
-11,-1,32:18.12
-7,-1,32:18.12
-6,-1,32:18.12
-5,-1,32:18.12
-4,-1,32:18.12
12,-1,32:18.12
13,-1,32:18.12
14,-1,32:18.12
15,-1,32:18.12
21,-1,32:18.12
23,-1,32:17.12
24,-1,32:17.12
34,-1,32:18.12
35,-1,32:18.12
36,-1,32:18.12
-7,0,32:18.12
-6,0,32:18.12
-5,0,32:18.12
11,0,32:18.12
12,0,32:18.12
13,0,32:18.12
14,0,32:18.12
15,0,32:18.12
16,0,32:18.12
20,0,32:18.12
21,0,32:18.12
23,0,32:18.12
24,0,32:18.12
33,0,32:18.12
34,0,32:18.12
-7,1,32:18.12
-6,1,32:18.12
-5,1,32:18.12
12,1,32:18.12
13,1,32:18.12
14,1,32:18.12
15,1,32:18.12
16,1,32:18.12
17,1,32:18.12
18,1,32:18.12
23,1,32:18.12
34,1,32:18.12
-6,2,32:18.12
14,2,32:18.12
15,2,32:18.12
11,3,32:18.12
18,3,32:18.12
26,3,32:18.12
11,4,32:18.12
17,4,32:18.12
23,4,32:18.12
25,4,32:18.12
26,4,32:18.12
28,4,32:18.12
15,5,32:18.12
22,5,32:18.12
23,5,32:18.12
26,5,32:18.12
8,6,32:17.12
9,7,32:17.12
10,7,32:17.12
11,7,32:17.12
26,7,32:18.12
8,8,32:17.12
9,8,32:17.12
10,8,32:17.12
7,9,32:17.12
8,9,32:17.12
9,9,32:17.12
10,9,32:17.12
-12,10,32:18.12
8,10,32:17.12
9,10,32:17.12
10,10,32:17.12
-7,11,32:17.12
-6,11,32:17.12
-2,11,32:18.12
-1,11,32:18.12
0,11,32:18.12
9,11,32:17.12
-8,12,32:17.12
-7,12,32:17.12
-6,12,32:17.12
-5,12,32:17.12
-4,12,32:17.12
-3,12,32:17.12
-2,12,32:18.12
-1,12,32:18.12
0,12,32:18.12
1,12,32:18.12
-7,13,32:17.12
-6,13,32:17.12
-5,13,32:17.12
-4,13,32:17.12
-3,13,32:17.12
-2,13,32:17.12
-1,13,32:17.12
0,13,32:18.12
1,13,32:18.12
2,13,32:18.12
3,13,32:18.12
-7,14,32:17.12
-6,14,32:17.12
-5,14,32:17.12
-2,14,32:17.12
-1,14,32:17.12
0,14,32:18.12
4,14,32:18.12
-2,15,32:18.12
0,15,32:17.12
1,15,32:18.12
2,15,32:18.12
3,15,32:18.12
4,15,32:18.12
-2,16,32:18.12
-1,16,32:18.12
0,16,32:18.12
1,16,32:18.12
2,16,32:18.12
0,17,32:18.12
1,17,32:18.12
2,17,32:18.12
3,17,32:18.12
1,18,32:18.12
2,18,32:18.12
3,18,32:18.12
3,19,32:18.12
4,22,32:18.12
-2,23,32:18.12
2,23,32:18.12
4,23,32:18.12
-2,24,32:18.12
0,24,32:18.12
1,24,32:18.12
2,24,32:18.12
4,24,32:18.12
-3,25,32:18.12
-2,25,32:18.12
-1,25,32:18.12
0,25,32:18.12
1,25,32:18.12
2,25,32:18.12
-1,26,32:18.12
0,26,32:18.12
1,26,32:18.12
3,26,32:18.12
4,26,32:18.12
-1,27,32:18.12
0,27,32:18.12
1,27,32:18.12
1,28,32:18.12
26,-36,33:18.12
27,-36,33:18.12
1,-35,33:18.12
17,-35,33:18.12
25,-35,33:18.12
0,-34,33:18.12
1,-34,33:18.12
2,-34,33:18.12
3,-34,33:18.12
19,-34,33:18.12
24,-34,33:18.12
25,-34,33:18.12
26,-34,33:18.12
28,-34,33:18.12
0,-33,33:18.12
2,-33,33:18.12
3,-33,33:18.12
4,-33,33:18.12
12,-33,33:18.12
13,-33,33:18.12
14,-33,33:18.12
16,-33,33:18.12
17,-33,33:18.12
18,-33,33:18.12
19,-33,33:18.12
20,-33,33:18.12
21,-33,33:18.12
26,-33,33:18.12
28,-33,33:18.12
-1,-32,33:18.12
0,-32,33:18.12
1,-32,33:18.12
2,-32,33:18.12
3,-32,33:18.12
4,-32,33:18.12
12,-32,33:18.12
14,-32,33:18.12
15,-32,33:18.12
16,-32,33:18.12
17,-32,33:18.12
18,-32,33:18.12
19,-32,33:18.12
20,-32,33:18.12
21,-32,33:18.12
22,-32,33:18.12
23,-32,33:18.12
24,-32,33:18.12
25,-32,33:18.12
26,-32,33:18.12
27,-32,33:18.12
28,-32,33:18.12
1,-31,33:18.12
2,-31,33:18.12
3,-31,33:18.12
4,-31,33:18.12
11,-31,33:18.12
12,-31,33:18.12
13,-31,33:18.12
14,-31,33:18.12
15,-31,33:18.12
16,-31,33:18.12
17,-31,33:18.12
18,-31,33:18.12
19,-31,33:18.12
20,-31,33:18.12
21,-31,33:18.12
22,-31,33:18.12
23,-31,33:18.12
24,-31,33:18.12
27,-31,33:18.12
0,-30,33:18.12
1,-30,33:18.12
2,-30,33:18.12
3,-30,33:18.12
4,-30,33:18.12
5,-30,33:18.12
6,-30,33:18.12
7,-30,33:18.12
8,-30,33:18.12
9,-30,33:18.12
11,-30,33:18.12
12,-30,33:18.12
13,-30,33:18.12
14,-30,33:18.12
15,-30,33:18.12
17,-30,33:18.12
18,-30,33:18.12
19,-30,33:18.12
20,-30,33:18.12
21,-30,33:18.12
22,-30,33:18.12
23,-30,33:18.12
24,-30,33:18.12
25,-30,33:18.12
26,-30,33:18.12
27,-30,33:18.12
1,-29,33:18.12
2,-29,33:18.12
3,-29,33:18.12
4,-29,33:18.12
5,-29,33:18.12
6,-29,33:18.12
7,-29,33:18.12
8,-29,33:18.12
9,-29,33:18.12
13,-29,33:18.12
14,-29,33:18.12
16,-29,33:18.12
17,-29,33:18.12
18,-29,33:18.12
20,-29,33:18.12
21,-29,33:18.12
22,-29,33:18.12
25,-29,33:18.12
1,-28,33:18.12
2,-28,33:18.12
3,-28,33:18.12
4,-28,33:18.12
5,-28,33:18.12
6,-28,33:18.12
7,-28,33:18.12
8,-28,33:18.12
9,-28,33:18.12
13,-28,33:18.12
17,-28,33:18.12
18,-28,33:18.12
20,-28,33:18.12
21,-28,33:18.12
22,-28,33:18.12
2,-27,33:18.12
4,-27,33:18.12
6,-27,33:18.12
7,-27,33:18.12
8,-27,33:18.12
9,-27,33:18.12
11,-27,33:18.12
13,-27,33:18.12
14,-27,33:18.12
18,-27,33:18.12
22,-27,33:18.12
23,-27,33:18.12
-6,-26,33:18.12
-4,-26,33:18.12
-3,-26,33:18.12
-2,-26,33:18.12
-1,-26,33:18.12
5,-26,33:18.12
6,-26,33:18.12
7,-26,33:18.12
8,-26,33:18.12
9,-26,33:18.12
10,-26,33:18.12
11,-26,33:18.12
12,-26,33:18.12
15,-26,33:18.12
16,-26,33:18.12
17,-26,33:18.12
21,-26,33:18.12
23,-26,33:18.12
-6,-25,33:18.12
-5,-25,33:18.12
-3,-25,33:18.12
-2,-25,33:18.12
-1,-25,33:18.12
0,-25,33:18.12
5,-25,33:18.12
6,-25,33:18.12
8,-25,33:18.12
14,-25,33:18.12
15,-25,33:18.12
16,-25,33:18.12
17,-25,33:18.12
18,-25,33:18.12
21,-25,33:18.12
22,-25,33:18.12
-8,-24,33:18.12
-7,-24,33:18.12
-6,-24,33:18.12
-5,-24,33:18.12
-4,-24,33:18.12
-3,-24,33:18.12
-2,-24,33:18.12
-1,-24,33:18.12
0,-24,33:18.12
11,-24,33:18.12
12,-24,33:18.12
13,-24,33:18.12
14,-24,33:18.12
15,-24,33:18.12
16,-24,33:18.12
22,-24,33:18.12
23,-24,33:18.12
-9,-23,33:18.12
-8,-23,33:18.12
-7,-23,33:18.12
-6,-23,33:18.12
-5,-23,33:18.12
-4,-23,33:18.12
-3,-23,33:18.12
10,-23,33:18.12
11,-23,33:18.12
12,-23,33:18.12
13,-23,33:18.12
14,-23,33:18.12
15,-23,33:18.12
16,-23,33:18.12
22,-23,33:18.12
23,-23,33:18.12
24,-23,33:18.12
-6,-22,33:18.12
-5,-22,33:18.12
-4,-22,33:18.12
-3,-22,33:18.12
-2,-22,33:18.12
11,-22,33:18.12
12,-22,33:18.12
13,-22,33:18.12
14,-22,33:18.12
15,-22,33:18.12
16,-22,33:18.12
20,-22,33:18.12
21,-22,33:18.12
22,-22,33:18.12
23,-22,33:18.12
24,-22,33:18.12
25,-22,33:18.12
-6,-21,33:18.12
-5,-21,33:18.12
-4,-21,33:18.12
-3,-21,33:18.12
10,-21,33:18.12
11,-21,33:18.12
13,-21,33:18.12
14,-21,33:18.12
16,-21,33:18.12
18,-21,33:18.12
19,-21,33:18.12
20,-21,33:18.12
21,-21,33:18.12
22,-21,33:18.12
23,-21,33:18.12
25,-21,33:18.12
-8,-20,33:18.12
-7,-20,33:18.12
-6,-20,33:18.12
-5,-20,33:18.12
-4,-20,33:18.12
-3,-20,33:18.12
10,-20,33:18.12
11,-20,33:18.12
13,-20,33:18.12
14,-20,33:18.12
15,-20,33:18.12
16,-20,33:18.12
18,-20,33:18.12
20,-20,33:18.12
22,-20,33:18.12
23,-20,33:18.12
25,-20,33:18.12
-9,-19,33:18.12
-8,-19,33:18.12
-7,-19,33:18.12
-6,-19,33:18.12
-5,-19,33:18.12
-2,-19,33:18.12
4,-19,33:18.12
5,-19,33:18.12
10,-19,33:18.12
11,-19,33:18.12
13,-19,33:18.12
14,-19,33:18.12
15,-19,33:18.12
16,-19,33:18.12
17,-19,33:18.12
18,-19,33:18.12
19,-19,33:18.12
20,-19,33:18.12
21,-19,33:18.12
22,-19,33:18.12
23,-19,33:18.12
24,-19,33:18.12
25,-19,33:18.12
26,-19,33:18.12
27,-19,33:18.12
-18,-18,33:18.12
-17,-18,33:18.12
-9,-18,33:18.12
-8,-18,33:18.12
-6,-18,33:18.12
-5,-18,33:18.12
-3,-18,33:18.12
-2,-18,33:18.12
-1,-18,33:18.12
1,-18,33:18.12
3,-18,33:18.12
4,-18,33:18.12
5,-18,33:18.12
13,-18,33:18.12
14,-18,33:18.12
15,-18,33:18.12
16,-18,33:18.12
17,-18,33:18.12
18,-18,33:18.12
19,-18,33:18.12
20,-18,33:18.12
21,-18,33:18.12
22,-18,33:18.12
23,-18,33:18.12
25,-18,33:18.12
-9,-17,33:18.12
-8,-17,33:18.12
-7,-17,33:18.12
-6,-17,33:18.12
-4,-17,33:18.12
-3,-17,33:18.12
-2,-17,33:18.12
-1,-17,33:18.12
1,-17,33:18.12
6,-17,33:18.12
12,-17,33:18.12
13,-17,33:18.12
14,-17,33:18.12
15,-17,33:18.12
16,-17,33:18.12
19,-17,33:17.12
20,-17,33:17.12
21,-17,33:18.12
22,-17,33:18.12
23,-17,33:18.12
25,-17,33:18.12
-9,-16,33:18.12
-8,-16,33:18.12
-7,-16,33:18.12
-6,-16,33:18.12
-2,-16,33:18.12
-1,-16,33:18.12
1,-16,33:18.12
3,-16,33:18.12
4,-16,33:18.12
6,-16,33:18.12
11,-16,33:18.12
12,-16,33:18.12
-9,-15,33:18.12
-8,-15,33:18.12
-7,-15,33:18.12
-1,-15,33:18.12
0,-15,33:18.12
2,-15,33:18.12
3,-15,33:18.12
5,-15,33:18.12
6,-15,33:18.12
13,-15,33:18.12
-9,-14,33:18.12
-4,-14,33:18.12
-3,-14,33:18.12
-1,-14,33:18.12
0,-14,33:18.12
1,-14,33:18.12
2,-14,33:18.12
5,-14,33:18.12
6,-14,33:18.12
14,-14,33:18.12
-21,-13,33:18.12
-20,-13,33:18.12
-7,-13,33:18.12
-3,-13,33:18.12
0,-13,33:18.12
2,-13,33:18.12
4,-13,33:18.12
5,-13,33:18.12
9,-13,33:18.12
13,-13,33:18.12
14,-13,33:18.12
-21,-12,33:18.12
-20,-12,33:18.12
-18,-12,33:18.12
-7,-12,33:18.12
-4,-12,33:18.12
-3,-12,33:18.12
5,-12,33:18.12
9,-12,33:18.12
-20,-11,33:18.12
-18,-11,33:18.12
-3,-11,33:18.12
-2,-11,33:18.12
-1,-11,33:18.12
8,-11,33:18.12
9,-11,33:18.12
-20,-10,33:18.12
-19,-10,33:18.12
-18,-10,33:18.12
-17,-10,33:18.12
-15,-10,33:18.12
-3,-10,33:18.12
-2,-10,33:18.12
-1,-10,33:18.12
10,-10,33:18.12
-21,-9,33:18.12
-20,-9,33:18.12
-19,-9,33:18.12
-18,-9,33:18.12
-17,-9,33:18.12
-16,-9,33:18.12
-15,-9,33:18.12
-14,-9,33:18.12
-12,-9,33:17.12
-11,-9,33:17.12
-4,-9,33:18.12
-3,-9,33:18.12
1,-9,33:18.12
21,-9,33:18.12
22,-9,33:18.12
-21,-8,33:18.12
-17,-8,33:18.12
-16,-8,33:18.12
-15,-8,33:18.12
-14,-8,33:18.12
-12,-8,33:17.12
-11,-8,33:17.12
-5,-8,33:18.12
-4,-8,33:18.12
-3,-8,33:18.12
-2,-8,33:18.12
0,-8,33:18.12
1,-8,33:18.12
22,-8,33:18.12
23,-8,33:18.12
24,-8,33:18.12
-20,-7,33:18.12
-19,-7,33:18.12
-18,-7,33:18.12
-17,-7,33:18.12
-16,-7,33:18.12
-15,-7,33:18.12
-14,-7,33:18.12
-13,-7,33:18.12
-12,-7,33:18.12
-11,-7,33:18.12
-10,-7,33:18.12
-5,-7,33:18.12
-4,-7,33:18.12
-3,-7,33:18.12
-2,-7,33:18.12
-1,-7,33:18.12
0,-7,33:18.12
1,-7,33:18.12
8,-7,33:17.12
22,-7,33:18.12
23,-7,33:18.12
24,-7,33:18.12
-20,-6,33:18.12
-19,-6,33:18.12
-18,-6,33:18.12
-17,-6,33:18.12
-16,-6,33:18.12
-15,-6,33:18.12
-14,-6,33:18.12
-13,-6,33:18.12
-12,-6,33:18.12
-10,-6,33:18.12
-6,-6,33:18.12
-5,-6,33:18.12
-4,-6,33:18.12
-3,-6,33:18.12
-2,-6,33:18.12
0,-6,33:18.12
8,-6,33:17.12
