[META]
version=2.0
spawnOnBlockType=2
spawnSunlight=True
spawnDarkness=True
spawnWater=False
spawnLava=False
underFill=False
randomRotation=True
dig=True
tree=False
branch=False
needsFoundation=True
rarity=100
collisionPercentage=20
spawnElevationMin=0
spawnElevationMax=200
spawnInBiome=Custom
[DATA]
-4,-7,-10:17.12
1,-7,-10:17.12
-24,-2,-10:17.12
-9,-1,-10:17.12
-24,2,-10:17.12
-11,2,-10:17.12
-18,5,-10:17.12
-10,5,-10:17.12
-14,7,-10:17.12
-10,8,-10:17.12
-7,8,-10:17.12
-1,8,-10:17.12
-4,10,-10:17.12
-12,11,-10:17.12
-11,17,-10:17.12
-7,19,-10:17.12
-2,22,-10:17.12
3,-10,-9:17.12
-5,-9,-9:17.12
-4,-9,-9:17.12
-3,-9,-9:17.12
0,-9,-9:17.12
1,-9,-9:17.12
2,-9,-9:17.12
-6,-8,-9:17.12
-5,-8,-9:17.12
-4,-8,-9:17.12
-3,-8,-9:17.12
-2,-8,-9:17.12
-1,-8,-9:17.12
0,-8,-9:17.12
1,-8,-9:17.12
2,-8,-9:17.12
3,-8,-9:17.12
-6,-7,-9:17.12
-5,-7,-9:17.12
-4,-7,-9:17.12
-3,-7,-9:17.12
-2,-7,-9:17.12
-1,-7,-9:17.12
0,-7,-9:17.12
1,-7,-9:17.12
2,-7,-9:17.12
3,-7,-9:17.12
4,-7,-9:17.12
-6,-6,-9:17.12
-5,-6,-9:17.12
-4,-6,-9:17.12
-3,-6,-9:17.12
-2,-6,-9:17.12
-1,-6,-9:17.12
0,-6,-9:17.12
1,-6,-9:17.12
2,-6,-9:17.12
3,-6,-9:17.12
-5,-5,-9:17.12
-4,-5,-9:17.12
-3,-5,-9:17.12
0,-5,-9:17.12
1,-5,-9:17.12
2,-5,-9:17.12
-25,-3,-9:17.12
-24,-3,-9:17.12
-23,-3,-9:17.12
-10,-3,-9:17.12
-9,-3,-9:17.12
-8,-3,-9:17.12
-7,-3,-9:17.12
-2,-3,-9:17.12
-25,-2,-9:17.12
-24,-2,-9:17.12
-23,-2,-9:17.12
-13,-2,-9:17.12
-11,-2,-9:17.12
-10,-2,-9:17.12
-9,-2,-9:17.12
-8,-2,-9:17.12
-7,-2,-9:17.12
-26,-1,-9:17.12
-25,-1,-9:17.12
-24,-1,-9:17.12
-23,-1,-9:17.12
-16,-1,-9:17.12
-11,-1,-9:17.12
-10,-1,-9:17.12
-9,-1,-9:17.12
-8,-1,-9:17.12
-7,-1,-9:17.12
-25,0,-9:17.12
-24,0,-9:17.12
-23,0,-9:17.12
-21,0,-9:17.12
-18,0,-9:17.12
-12,0,-9:17.12
-11,0,-9:17.12
-10,0,-9:17.12
-9,0,-9:17.12
-8,0,-9:17.12
-7,0,-9:17.12
-28,1,-9:17.12
-26,1,-9:17.12
-25,1,-9:17.12
-24,1,-9:17.12
-23,1,-9:17.12
-22,1,-9:17.12
-16,1,-9:17.12
-14,1,-9:17.12
-13,1,-9:17.12
-12,1,-9:17.12
-11,1,-9:17.12
-10,1,-9:17.12
-9,1,-9:17.12
-8,1,-9:17.12
-26,2,-9:17.12
-25,2,-9:17.12
-24,2,-9:17.12
-23,2,-9:17.12
-22,2,-9:17.12
-13,2,-9:17.12
-12,2,-9:17.12
-11,2,-9:17.12
-10,2,-9:17.12
-9,2,-9:17.12
-26,3,-9:17.12
-25,3,-9:17.12
-24,3,-9:17.12
-23,3,-9:17.12
-22,3,-9:17.12
-19,3,-9:17.12
-18,3,-9:17.12
-17,3,-9:17.12
-13,3,-9:17.12
-12,3,-9:17.12
-11,3,-9:17.12
-10,3,-9:17.12
-9,3,-9:17.12
-25,4,-9:17.12
-24,4,-9:17.12
-23,4,-9:17.12
-20,4,-9:17.12
-19,4,-9:17.12
-18,4,-9:17.12
-17,4,-9:17.12
-16,4,-9:17.12
-12,4,-9:17.12
-11,4,-9:17.12
-10,4,-9:17.12
-9,4,-9:17.12
-8,4,-9:17.12
-5,4,-9:17.12
-20,5,-9:17.12
-19,5,-9:17.12
-18,5,-9:17.12
-17,5,-9:17.12
-16,5,-9:17.12
-15,5,-9:17.12
-14,5,-9:17.12
-13,5,-9:17.12
-12,5,-9:17.12
-11,5,-9:17.12
-10,5,-9:17.12
-9,5,-9:17.12
-8,5,-9:17.12
-20,6,-9:17.12
-19,6,-9:17.12
-18,6,-9:17.12
-17,6,-9:17.12
-16,6,-9:17.12
-15,6,-9:17.12
-14,6,-9:17.12
-13,6,-9:17.12
-12,6,-9:17.12
-11,6,-9:17.12
-10,6,-9:17.12
-9,6,-9:17.12
-8,6,-9:17.12
-7,6,-9:17.12
-6,6,-9:17.12
-2,6,-9:17.12
-1,6,-9:17.12
0,6,-9:17.12
-19,7,-9:17.12
-18,7,-9:17.12
-17,7,-9:17.12
-16,7,-9:17.12
-15,7,-9:17.12
-14,7,-9:17.12
-13,7,-9:17.12
-12,7,-9:17.12
-11,7,-9:17.12
-10,7,-9:17.12
-9,7,-9:17.12
-8,7,-9:17.12
-7,7,-9:17.12
-6,7,-9:17.12
-5,7,-9:17.12
-3,7,-9:17.12
-2,7,-9:17.12
-1,7,-9:17.12
0,7,-9:17.12
1,7,-9:17.12
2,7,-9:17.12
-16,8,-9:17.12
-15,8,-9:17.12
-14,8,-9:17.12
-13,8,-9:17.12
-12,8,-9:17.12
-11,8,-9:17.12
-10,8,-9:17.12
-9,8,-9:17.12
-8,8,-9:17.12
-7,8,-9:17.12
-6,8,-9:17.12
-5,8,-9:17.12
-4,8,-9:17.12
-3,8,-9:17.12
-2,8,-9:17.12
-1,8,-9:17.12
0,8,-9:17.12
1,8,-9:17.12
-15,9,-9:17.12
-14,9,-9:17.12
-13,9,-9:17.12
-12,9,-9:17.12
-11,9,-9:17.12
-10,9,-9:17.12
-9,9,-9:17.12
-8,9,-9:17.12
-7,9,-9:17.12
-6,9,-9:17.12
-5,9,-9:17.12
-4,9,-9:17.12
-3,9,-9:17.12
-2,9,-9:17.12
-1,9,-9:17.12
0,9,-9:17.12
1,9,-9:17.12
-14,10,-9:17.12
-13,10,-9:17.12
-12,10,-9:17.12
-11,10,-9:17.12
-10,10,-9:17.12
-9,10,-9:17.12
-8,10,-9:17.12
-7,10,-9:17.12
-6,10,-9:17.12
-5,10,-9:17.12
-4,10,-9:17.12
-3,10,-9:17.12
-2,10,-9:17.12
-1,10,-9:17.12
0,10,-9:17.12
-17,11,-9:17.12
-14,11,-9:17.12
-13,11,-9:17.12
-12,11,-9:17.12
-11,11,-9:17.12
-10,11,-9:17.12
-6,11,-9:17.12
-5,11,-9:17.12
-4,11,-9:17.12
-3,11,-9:17.12
-2,11,-9:17.12
-14,12,-9:17.12
-13,12,-9:17.12
-12,12,-9:17.12
-11,12,-9:17.12
-10,12,-9:17.12
-5,12,-9:17.12
-4,12,-9:17.12
-3,12,-9:17.12
-16,13,-9:17.12
-13,13,-9:17.12
-12,13,-9:17.12
-11,13,-9:17.12
-12,15,-9:17.12
-11,15,-9:17.12
-10,15,-9:17.12
-13,16,-9:17.12
-12,16,-9:17.12
-11,16,-9:17.12
-10,16,-9:17.12
-9,16,-9:17.12
-13,17,-9:17.12
-12,17,-9:17.12
-11,17,-9:17.12
-10,17,-9:17.12
-9,17,-9:17.12
-8,17,-9:17.12
-7,17,-9:17.12
-6,17,-9:17.12
-13,18,-9:17.12
-12,18,-9:17.12
-11,18,-9:17.12
-10,18,-9:17.12
-9,18,-9:17.12
-8,18,-9:17.12
-7,18,-9:17.12
-6,18,-9:17.12
-5,18,-9:17.12
-12,19,-9:17.12
-11,19,-9:17.12
-10,19,-9:17.12
-9,19,-9:17.12
-8,19,-9:17.12
-7,19,-9:17.12
-6,19,-9:17.12
-5,19,-9:17.12
-9,20,-9:17.12
-8,20,-9:17.12
-7,20,-9:17.12
-6,20,-9:17.12
-5,20,-9:17.12
-3,20,-9:17.12
-2,20,-9:17.12
-1,20,-9:17.12
-8,21,-9:17.12
-7,21,-9:17.12
-6,21,-9:17.12
-4,21,-9:17.12
-3,21,-9:17.12
-2,21,-9:17.12
-1,21,-9:17.12
0,21,-9:17.12
-4,22,-9:17.12
-3,22,-9:17.12
-2,22,-9:17.12
-1,22,-9:17.12
0,22,-9:17.12
-4,23,-9:17.12
-3,23,-9:17.12
-2,23,-9:17.12
-1,23,-9:17.12
0,23,-9:17.12
-3,24,-9:17.12
-2,24,-9:17.12
-1,24,-9:17.12
2,-11,-8:17.12
3,-11,-8:17.12
4,-11,-8:17.12
2,-10,-8:17.12
3,-10,-8:17.12
4,-10,-8:17.12
-6,-9,-8:17.12
-5,-9,-8:17.12
-4,-9,-8:17.12
-3,-9,-8:17.12
-2,-9,-8:17.12
-1,-9,-8:17.12
0,-9,-8:17.12
1,-9,-8:17.12
2,-9,-8:17.12
3,-9,-8:17.12
4,-9,-8:17.12
-6,-8,-8:17.12
-5,-8,-8:17.12
-4,-8,-8:17.12
-3,-8,-8:17.12
-2,-8,-8:17.12
-1,-8,-8:17.12
0,-8,-8:17.12
1,-8,-8:17.12
2,-8,-8:17.12
3,-8,-8:17.12
4,-8,-8:17.12
5,-8,-8:17.12
-6,-7,-8:17.12
-5,-7,-8:17.12
-4,-7,-8:17.12
-3,-7,-8:17.12
-2,-7,-8:17.12
-1,-7,-8:17.12
0,-7,-8:17.12
1,-7,-8:17.12
2,-7,-8:17.12
3,-7,-8:17.12
4,-7,-8:17.12
5,-7,-8:17.12
-7,-6,-8:17.12
-6,-6,-8:17.12
-5,-6,-8:17.12
-4,-6,-8:17.12
-3,-6,-8:17.12
-2,-6,-8:17.12
-1,-6,-8:17.12
0,-6,-8:17.12
1,-6,-8:17.12
2,-6,-8:17.12
3,-6,-8:17.12
4,-6,-8:17.12
-8,-5,-8:17.12
-7,-5,-8:17.12
-6,-5,-8:17.12
-5,-5,-8:17.12
-4,-5,-8:17.12
-3,-5,-8:17.12
-2,-5,-8:17.12
-1,-5,-8:17.12
0,-5,-8:17.12
1,-5,-8:17.12
2,-5,-8:17.12
3,-5,-8:17.12
-24,-4,-8:17.12
-9,-4,-8:17.12
-8,-4,-8:17.12
-7,-4,-8:17.12
-6,-4,-8:17.12
-5,-4,-8:17.12
-3,-4,-8:17.12
-2,-4,-8:17.12
-1,-4,-8:17.12
-25,-3,-8:17.12
-24,-3,-8:17.12
-23,-3,-8:17.12
-14,-3,-8:17.12
-13,-3,-8:17.12
-12,-3,-8:17.12
-11,-3,-8:17.12
-10,-3,-8:17.12
-9,-3,-8:17.12
-8,-3,-8:17.12
-7,-3,-8:17.12
-6,-3,-8:17.12
-5,-3,-8:17.12
-3,-3,-8:17.12
-2,-3,-8:17.12
-1,-3,-8:17.12
-27,-2,-8:17.12
-26,-2,-8:17.12
-25,-2,-8:17.12
-24,-2,-8:17.12
-23,-2,-8:17.12
-22,-2,-8:17.12
-17,-2,-8:17.12
-16,-2,-8:17.12
-15,-2,-8:17.12
-14,-2,-8:17.12
-13,-2,-8:17.12
-12,-2,-8:17.12
-11,-2,-8:17.12
-10,-2,-8:17.12
-9,-2,-8:17.12
-8,-2,-8:17.12
-7,-2,-8:17.12
-6,-2,-8:17.12
-5,-2,-8:17.12
-3,-2,-8:17.12
-2,-2,-8:17.12
-1,-2,-8:17.12
-27,-1,-8:17.12
-26,-1,-8:17.12
-25,-1,-8:17.12
-24,-1,-8:17.12
-23,-1,-8:17.12
-22,-1,-8:17.12
-21,-1,-8:17.12
-20,-1,-8:17.12
-19,-1,-8:17.12
-18,-1,-8:17.12
-17,-1,-8:17.12
-16,-1,-8:17.12
-15,-1,-8:17.12
-14,-1,-8:17.12
-13,-1,-8:17.12
-12,-1,-8:17.12
-11,-1,-8:17.12
-10,-1,-8:17.12
-9,-1,-8:17.12
-8,-1,-8:17.12
-7,-1,-8:17.12
-6,-1,-8:17.12
-29,0,-8:17.12
-28,0,-8:17.12
-27,0,-8:17.12
-26,0,-8:17.12
-25,0,-8:17.12
-24,0,-8:17.12
-23,0,-8:17.12
-22,0,-8:17.12
-21,0,-8:17.12
-20,0,-8:17.12
-19,0,-8:17.12
-18,0,-8:17.12
-17,0,-8:17.12
-16,0,-8:17.12
-15,0,-8:17.12
-14,0,-8:17.12
-13,0,-8:17.12
-12,0,-8:17.12
-11,0,-8:17.12
-10,0,-8:17.12
-9,0,-8:17.12
-8,0,-8:17.12
-7,0,-8:17.12
-29,1,-8:17.12
-28,1,-8:17.12
-27,1,-8:17.12
-26,1,-8:17.12
-25,1,-8:17.12
-24,1,-8:17.12
-23,1,-8:17.12
-22,1,-8:17.12
-21,1,-8:17.12
-20,1,-8:17.12
-19,1,-8:17.12
-18,1,-8:17.12
-17,1,-8:17.12
-16,1,-8:17.12
-15,1,-8:17.12
-14,1,-8:17.12
-13,1,-8:17.12
-12,1,-8:17.12
-11,1,-8:17.12
-10,1,-8:17.12
-9,1,-8:17.12
-8,1,-8:17.12
-7,1,-8:17.12
-29,2,-8:17.12
-28,2,-8:17.12
-27,2,-8:17.12
-26,2,-8:17.12
-25,2,-8:17.12
-24,2,-8:17.12
-23,2,-8:17.12
-22,2,-8:17.12
-21,2,-8:17.12
-20,2,-8:17.12
-17,2,-8:17.12
-16,2,-8:17.12
-15,2,-8:17.12
-14,2,-8:17.12
-13,2,-8:17.12
-12,2,-8:17.12
-11,2,-8:17.12
-10,2,-8:17.12
-9,2,-8:17.12
-26,3,-8:17.12
-25,3,-8:17.12
-24,3,-8:17.12
-23,3,-8:17.12
-22,3,-8:17.12
-21,3,-8:17.12
-20,3,-8:17.12
-19,3,-8:17.12
-18,3,-8:17.12
-17,3,-8:17.12
-16,3,-8:17.12
-13,3,-8:17.12
-12,3,-8:17.12
-11,3,-8:17.12
-10,3,-8:17.12
-9,3,-8:17.12
-8,3,-8:17.12
-6,3,-8:17.12
-5,3,-8:17.12
-4,3,-8:17.12
-26,4,-8:17.12
-25,4,-8:17.12
-24,4,-8:17.12
-23,4,-8:17.12
-22,4,-8:17.12
-21,4,-8:17.12
-20,4,-8:17.12
-19,4,-8:17.12
-18,4,-8:17.12
-17,4,-8:17.12
-16,4,-8:17.12
-13,4,-8:17.12
-12,4,-8:17.12
-11,4,-8:17.12
-10,4,-8:17.12
-9,4,-8:17.12
-8,4,-8:17.12
-6,4,-8:17.12
-5,4,-8:17.12
-4,4,-8:17.12
-23,5,-8:17.12
-22,5,-8:17.12
-21,5,-8:17.12
-20,5,-8:17.12
-19,5,-8:17.12
-18,5,-8:17.12
-17,5,-8:17.12
-16,5,-8:17.12
-15,5,-8:17.12
-14,5,-8:17.12
-13,5,-8:17.12
-12,5,-8:17.12
-11,5,-8:17.12
-10,5,-8:17.12
-9,5,-8:17.12
-8,5,-8:17.12
-6,5,-8:17.12
-5,5,-8:17.12
-4,5,-8:17.12
-20,6,-8:17.12
-19,6,-8:17.12
-18,6,-8:17.12
-17,6,-8:17.12
-16,6,-8:17.12
-15,6,-8:17.12
-14,6,-8:17.12
-13,6,-8:17.12
-12,6,-8:17.12
-11,6,-8:17.12
-10,6,-8:17.12
-9,6,-8:17.12
-8,6,-8:17.12
-7,6,-8:17.12
-6,6,-8:17.12
-5,6,-8:17.12
-3,6,-8:17.12
-2,6,-8:17.12
-1,6,-8:17.12
0,6,-8:17.12
1,6,-8:17.12
2,6,-8:17.12
3,6,-8:17.12
-20,7,-8:17.12
-19,7,-8:17.12
-18,7,-8:17.12
-17,7,-8:17.12
-16,7,-8:17.12
-15,7,-8:17.12
-14,7,-8:17.12
-13,7,-8:17.12
-12,7,-8:17.12
-11,7,-8:17.12
-10,7,-8:17.12
-9,7,-8:17.12
-8,7,-8:17.12
-7,7,-8:17.12
-6,7,-8:17.12
-5,7,-8:17.12
-3,7,-8:17.12
-2,7,-8:17.12
-1,7,-8:17.12
0,7,-8:17.12
1,7,-8:17.12
2,7,-8:17.12
3,7,-8:17.12
-16,8,-8:17.12
-15,8,-8:17.12
-14,8,-8:17.12
-13,8,-8:17.12
-12,8,-8:17.12
-11,8,-8:17.12
-10,8,-8:17.12
-9,8,-8:17.12
-8,8,-8:17.12
-7,8,-8:17.12
-6,8,-8:17.12
-5,8,-8:17.12
-4,8,-8:17.12
-3,8,-8:17.12
-2,8,-8:17.12
-1,8,-8:17.12
0,8,-8:17.12
1,8,-8:17.12
2,8,-8:17.12
-16,9,-8:17.12
-15,9,-8:17.12
-14,9,-8:17.12
-13,9,-8:17.12
-12,9,-8:17.12
-11,9,-8:17.12
-10,9,-8:17.12
-9,9,-8:17.12
-8,9,-8:17.12
-7,9,-8:17.12
-6,9,-8:17.12
-5,9,-8:17.12
-4,9,-8:17.12
-3,9,-8:17.12
-2,9,-8:17.12
-1,9,-8:17.12
0,9,-8:17.12
1,9,-8:17.12
2,9,-8:17.12
-18,10,-8:17.12
-17,10,-8:17.12
-16,10,-8:17.12
-14,10,-8:17.12
-13,10,-8:17.12
-12,10,-8:17.12
-11,10,-8:17.12
-10,10,-8:17.12
-9,10,-8:17.12
-8,10,-8:17.12
-7,10,-8:17.12
-6,10,-8:17.12
-5,10,-8:17.12
-4,10,-8:17.12
-3,10,-8:17.12
-2,10,-8:17.12
-1,10,-8:17.12
0,10,-8:17.12
-18,11,-8:17.12
-17,11,-8:17.12
-16,11,-8:17.12
-14,11,-8:17.12
-13,11,-8:17.12
-12,11,-8:17.12
-11,11,-8:17.12
-10,11,-8:17.12
-6,11,-8:17.12
-5,11,-8:17.12
-4,11,-8:17.12
-3,11,-8:17.12
-2,11,-8:17.12
-1,11,-8:17.12
-18,12,-8:17.12
-17,12,-8:17.12
-16,12,-8:17.12
-15,12,-8:17.12
-14,12,-8:17.12
-13,12,-8:17.12
-12,12,-8:17.12
-11,12,-8:17.12
-10,12,-8:17.12
-6,12,-8:17.12
-5,12,-8:17.12
-4,12,-8:17.12
-3,12,-8:17.12
-2,12,-8:17.12
-17,13,-8:17.12
-16,13,-8:17.12
-15,13,-8:17.12
-14,13,-8:17.12
-13,13,-8:17.12
-12,13,-8:17.12
-11,13,-8:17.12
-10,13,-8:17.12
-17,14,-8:17.12
-16,14,-8:17.12
-15,14,-8:17.12
-9,14,-8:17.12
-13,15,-8:17.12
-12,15,-8:17.12
-11,15,-8:17.12
-10,15,-8:17.12
-9,15,-8:17.12
-13,16,-8:17.12
-12,16,-8:17.12
-11,16,-8:17.12
-10,16,-8:17.12
-9,16,-8:17.12
-13,17,-8:17.12
-12,17,-8:17.12
-11,17,-8:17.12
-10,17,-8:17.12
-9,17,-8:17.12
-8,17,-8:17.12
-7,17,-8:17.12
-6,17,-8:17.12
-5,17,-8:17.12
-13,18,-8:17.12
-12,18,-8:17.12
-11,18,-8:17.12
-10,18,-8:17.12
-9,18,-8:17.12
-8,18,-8:17.12
-7,18,-8:17.12
-6,18,-8:17.12
-5,18,-8:17.12
-13,19,-8:17.12
-12,19,-8:17.12
-11,19,-8:17.12
-10,19,-8:17.12
-9,19,-8:17.12
-8,19,-8:17.12
-7,19,-8:17.12
-6,19,-8:17.12
-5,19,-8:17.12
-9,20,-8:17.12
-8,20,-8:17.12
-7,20,-8:17.12
-6,20,-8:17.12
-5,20,-8:17.12
-4,20,-8:17.12
-3,20,-8:17.12
-2,20,-8:17.12
-1,20,-8:17.12
0,20,-8:17.12
-9,21,-8:17.12
-8,21,-8:17.12
-7,21,-8:17.12
-6,21,-8:17.12
-5,21,-8:17.12
-4,21,-8:17.12
-3,21,-8:17.12
-2,21,-8:17.12
-1,21,-8:17.12
0,21,-8:17.12
-4,22,-8:17.12
-3,22,-8:17.12
-2,22,-8:17.12
-1,22,-8:17.12
0,22,-8:17.12
-4,23,-8:17.12
-3,23,-8:17.12
-2,23,-8:17.12
-1,23,-8:17.12
0,23,-8:17.12
-4,24,-8:17.12
-3,24,-8:17.12
-2,24,-8:17.12
-1,24,-8:17.12
0,24,-8:17.12
3,-12,-7:17.12
2,-11,-7:17.12
3,-11,-7:17.12
4,-11,-7:17.12
-4,-10,-7:17.12
-3,-10,-7:17.12
-2,-10,-7:17.12
1,-10,-7:17.12
2,-10,-7:17.12
3,-10,-7:17.12
4,-10,-7:17.12
5,-10,-7:17.12
-6,-9,-7:17.12
-5,-9,-7:17.12
-4,-9,-7:17.12
-3,-9,-7:17.12
-2,-9,-7:17.12
-1,-9,-7:17.12
0,-9,-7:17.12
1,-9,-7:17.12
2,-9,-7:17.12
3,-9,-7:17.12
4,-9,-7:17.12
5,-9,-7:17.12
-7,-8,-7:17.12
-6,-8,-7:17.12
-5,-8,-7:17.12
-4,-8,-7:17.12
-3,-8,-7:17.12
-2,-8,-7:17.12
-1,-8,-7:17.12
0,-8,-7:17.12
1,-8,-7:17.12
2,-8,-7:17.12
3,-8,-7:17.12
4,-8,-7:17.12
5,-8,-7:17.12
-8,-7,-7:17.12
-7,-7,-7:17.12
-6,-7,-7:17.12
-5,-7,-7:17.12
-4,-7,-7:17.12
-3,-7,-7:17.12
-2,-7,-7:17.12
-1,-7,-7:17.12
0,-7,-7:17.12
1,-7,-7:17.12
2,-7,-7:17.12
3,-7,-7:17.12
4,-7,-7:17.12
5,-7,-7:17.12
-9,-6,-7:17.12
-8,-6,-7:17.12
-7,-6,-7:17.12
-6,-6,-7:17.12
-5,-6,-7:17.12
-4,-6,-7:17.12
-3,-6,-7:17.12
-2,-6,-7:17.12
-1,-6,-7:17.12
0,-6,-7:17.12
1,-6,-7:17.12
2,-6,-7:17.12
3,-6,-7:17.12
4,-6,-7:17.12
5,-6,-7:17.12
-9,-5,-7:17.12
-8,-5,-7:17.12
-7,-5,-7:17.12
-6,-5,-7:17.12
-5,-5,-7:17.12
-4,-5,-7:17.12
-3,-5,-7:17.12
-2,-5,-7:17.12
-1,-5,-7:17.12
0,-5,-7:17.12
1,-5,-7:17.12
2,-5,-7:17.12
3,-5,-7:17.12
-13,-4,-7:17.12
-9,-4,-7:17.12
-8,-4,-7:17.12
-7,-4,-7:17.12
-6,-4,-7:17.12
-5,-4,-7:17.12
-4,-4,-7:17.12
-3,-4,-7:17.12
-2,-4,-7:17.12
-1,-4,-7:17.12
0,-4,-7:17.12
1,-4,-7:17.12
-25,-3,-7:17.12
-24,-3,-7:17.12
-23,-3,-7:17.12
-16,-3,-7:17.12
-14,-3,-7:17.12
-13,-3,-7:17.12
-12,-3,-7:17.12
-11,-3,-7:17.12
-10,-3,-7:17.12
-9,-3,-7:17.12
-8,-3,-7:17.12
-7,-3,-7:17.12
-6,-3,-7:17.12
-5,-3,-7:17.12
-4,-3,-7:17.12
-3,-3,-7:17.12
-2,-3,-7:17.12
-1,-3,-7:17.12
0,-3,-7:17.12
-27,-2,-7:17.12
-26,-2,-7:17.12
-25,-2,-7:17.12
-24,-2,-7:17.12
-23,-2,-7:17.12
-21,-2,-7:17.12
-18,-2,-7:17.12
-17,-2,-7:17.12
-16,-2,-7:17.12
-15,-2,-7:17.12
-14,-2,-7:17.12
-13,-2,-7:17.12
-12,-2,-7:17.12
-11,-2,-7:17.12
-10,-2,-7:17.12
-9,-2,-7:17.12
-8,-2,-7:17.12
-7,-2,-7:17.12
-6,-2,-7:17.12
-5,-2,-7:17.12
-3,-2,-7:17.12
-2,-2,-7:17.12
-1,-2,-7:17.12
-28,-1,-7:17.12
-27,-1,-7:17.12
-26,-1,-7:17.12
-25,-1,-7:17.12
-24,-1,-7:17.12
-23,-1,-7:17.12
-22,-1,-7:17.12
-21,-1,-7:17.12
-20,-1,-7:17.12
-19,-1,-7:17.12
-18,-1,-7:17.12
-17,-1,-7:17.12
-16,-1,-7:17.12
-15,-1,-7:17.12
-14,-1,-7:17.12
-13,-1,-7:17.12
-12,-1,-7:17.12
-11,-1,-7:17.12
-10,-1,-7:17.12
-9,-1,-7:17.12
-8,-1,-7:17.12
-7,-1,-7:17.12
-6,-1,-7:17.12
-5,-1,-7:17.12
-2,-1,-7:17.12
-29,0,-7:17.12
-28,0,-7:17.12
-27,0,-7:17.12
-26,0,-7:17.12
-25,0,-7:17.12
-24,0,-7:17.12
-23,0,-7:17.12
-22,0,-7:17.12
-21,0,-7:17.12
-20,0,-7:17.12
-19,0,-7:17.12
-18,0,-7:17.12
-17,0,-7:17.12
-16,0,-7:17.12
-15,0,-7:17.12
-14,0,-7:17.12
-13,0,-7:17.12
-12,0,-7:17.12
-11,0,-7:17.12
-10,0,-7:17.12
-9,0,-7:17.12
-8,0,-7:17.12
-7,0,-7:17.12
-30,1,-7:17.12
-29,1,-7:17.12
-28,1,-7:17.12
-27,1,-7:17.12
-26,1,-7:17.12
-25,1,-7:17.12
-24,1,-7:17.12
-23,1,-7:17.12
-22,1,-7:17.12
-21,1,-7:17.12
-20,1,-7:17.12
-19,1,-7:17.12
-18,1,-7:17.12
-17,1,-7:17.12
-16,1,-7:17.12
-15,1,-7:17.12
-14,1,-7:17.12
-13,1,-7:17.12
-12,1,-7:17.12
-11,1,-7:17.12
-10,1,-7:17.12
-9,1,-7:17.12
-8,1,-7:17.12
-7,1,-7:17.12
-29,2,-7:17.12
-28,2,-7:17.12
-27,2,-7:17.12
-26,2,-7:17.12
-25,2,-7:17.12
-24,2,-7:17.12
-23,2,-7:17.12
-22,2,-7:17.12
-21,2,-7:17.12
-20,2,-7:17.12
-19,2,-7:17.12
-18,2,-7:17.12
-17,2,-7:17.12
-16,2,-7:17.12
-15,2,-7:17.12
-14,2,-7:17.12
-13,2,-7:17.12
-12,2,-7:17.12
-11,2,-7:17.12
-10,2,-7:17.12
-9,2,-7:17.12
-8,2,-7:17.12
-5,2,-7:17.12
-28,3,-7:17.12
-26,3,-7:17.12
-25,3,-7:17.12
-24,3,-7:17.12
-23,3,-7:17.12
-22,3,-7:17.12
-21,3,-7:17.12
-20,3,-7:17.12
-19,3,-7:17.12
-18,3,-7:17.12
-17,3,-7:17.12
-16,3,-7:17.12
-14,3,-7:17.12
-13,3,-7:17.12
-12,3,-7:17.12
-11,3,-7:17.12
-10,3,-7:17.12
-9,3,-7:17.12
-8,3,-7:17.12
-6,3,-7:17.12
-5,3,-7:17.12
-4,3,-7:17.12
-26,4,-7:17.12
-25,4,-7:17.12
-24,4,-7:17.12
-23,4,-7:17.12
-22,4,-7:17.12
-21,4,-7:17.12
-20,4,-7:17.12
-19,4,-7:17.12
-18,4,-7:17.12
-17,4,-7:17.12
-16,4,-7:17.12
-14,4,-7:17.12
-13,4,-7:17.12
-12,4,-7:17.12
-11,4,-7:17.12
-10,4,-7:17.12
-9,4,-7:17.12
-8,4,-7:17.12
-7,4,-7:17.12
-6,4,-7:17.12
-5,4,-7:17.12
-4,4,-7:17.12
-3,4,-7:17.12
-24,5,-7:17.12
-23,5,-7:17.12
-22,5,-7:17.12
-21,5,-7:17.12
-20,5,-7:17.12
-19,5,-7:17.12
-18,5,-7:17.12
-17,5,-7:17.12
-16,5,-7:17.12
-15,5,-7:17.12
-14,5,-7:17.12
-13,5,-7:17.12
-12,5,-7:17.12
-11,5,-7:17.12
-10,5,-7:17.12
-9,5,-7:17.12
-8,5,-7:17.12
-7,5,-7:17.12
-6,5,-7:17.12
-5,5,-7:17.12
-4,5,-7:17.12
-2,5,-7:17.12
-1,5,-7:17.12
0,5,-7:17.12
1,5,-7:17.12
2,5,-7:17.12
-20,6,-7:17.12
-19,6,-7:17.12
-18,6,-7:17.12
-17,6,-7:17.12
-16,6,-7:17.12
-15,6,-7:17.12
-14,6,-7:17.12
-13,6,-7:17.12
-12,6,-7:17.12
-11,6,-7:17.12
-10,6,-7:17.12
-9,6,-7:17.12
-8,6,-7:17.12
-7,6,-7:17.12
-6,6,-7:17.12
-5,6,-7:17.12
-4,6,-7:17.12
-3,6,-7:17.12
-2,6,-7:17.12
-1,6,-7:17.12
0,6,-7:17.12
1,6,-7:17.12
2,6,-7:17.12
3,6,-7:17.12
-20,7,-7:17.12
-19,7,-7:17.12
-18,7,-7:17.12
-17,7,-7:17.12
-16,7,-7:17.12
-15,7,-7:17.12
-14,7,-7:17.12
-13,7,-7:17.12
-12,7,-7:17.12
-11,7,-7:17.12
-10,7,-7:17.12
-9,7,-7:17.12
-8,7,-7:17.12
-7,7,-7:17.12
-6,7,-7:17.12
-5,7,-7:17.12
-4,7,-7:17.12
-3,7,-7:17.12
-2,7,-7:17.12
-1,7,-7:17.12
0,7,-7:17.12
1,7,-7:17.12
2,7,-7:17.12
3,7,-7:17.12
4,7,-7:17.12
-18,8,-7:17.12
-17,8,-7:17.12
-16,8,-7:17.12
-15,8,-7:17.12
-14,8,-7:17.12
-13,8,-7:17.12
-12,8,-7:17.12
-11,8,-7:17.12
-10,8,-7:17.12
-9,8,-7:17.12
-8,8,-7:17.12
-7,8,-7:17.12
-6,8,-7:17.12
-5,8,-7:17.12
-4,8,-7:17.12
-3,8,-7:17.12
-2,8,-7:17.12
-1,8,-7:17.12
0,8,-7:17.12
1,8,-7:17.12
2,8,-7:17.12
3,8,-7:17.12
-18,9,-7:17.12
-17,9,-7:17.12
-16,9,-7:17.12
-15,9,-7:17.12
-14,9,-7:17.12
-13,9,-7:17.12
-12,9,-7:17.12
-11,9,-7:17.12
-10,9,-7:17.12
-9,9,-7:17.12
-8,9,-7:17.12
-7,9,-7:17.12
-6,9,-7:17.12
-5,9,-7:17.12
-4,9,-7:17.12
-3,9,-7:17.12
-2,9,-7:17.12
-1,9,-7:17.12
0,9,-7:17.12
1,9,-7:17.12
2,9,-7:17.12
-18,10,-7:17.12
-17,10,-7:17.12
-16,10,-7:17.12
-15,10,-7:17.12
-14,10,-7:17.12
-13,10,-7:17.12
-12,10,-7:17.12
-11,10,-7:17.12
-10,10,-7:17.12
-9,10,-7:17.12
-8,10,-7:17.12
-7,10,-7:17.12
-6,10,-7:17.12
-5,10,-7:17.12
-4,10,-7:17.12
-3,10,-7:17.12
-2,10,-7:17.12
-1,10,-7:17.12
0,10,-7:17.12
1,10,-7:17.12
-19,11,-7:17.12
-18,11,-7:17.12
-17,11,-7:17.12
-16,11,-7:17.12
-15,11,-7:17.12
-14,11,-7:17.12
-13,11,-7:17.12
-12,11,-7:17.12
-11,11,-7:17.12
-10,11,-7:17.12
-9,11,-7:17.12
-7,11,-7:17.12
-6,11,-7:17.12
-5,11,-7:17.12
-4,11,-7:17.12
-3,11,-7:17.12
-2,11,-7:17.12
-1,11,-7:17.12
0,11,-7:17.12
-18,12,-7:17.12
-17,12,-7:17.12
-16,12,-7:17.12
-15,12,-7:17.12
-14,12,-7:17.12
-13,12,-7:17.12
-12,12,-7:17.12
-11,12,-7:17.12
-10,12,-7:17.12
-9,12,-7:17.12
-6,12,-7:17.12
-5,12,-7:17.12
-4,12,-7:17.12
-3,12,-7:17.12
-2,12,-7:17.12
-18,13,-7:17.12
-17,13,-7:17.12
-16,13,-7:17.12
-15,13,-7:17.12
-14,13,-7:17.12
-13,13,-7:17.12
-12,13,-7:17.12
-11,13,-7:17.12
-10,13,-7:17.12
-9,13,-7:17.12
-8,13,-7:17.12
-4,13,-7:17.12
-17,14,-7:17.12
-16,14,-7:17.12
-15,14,-7:17.12
-14,14,-7:17.12
-13,14,-7:17.12
-12,14,-7:17.12
-11,14,-7:17.12
-10,14,-7:17.12
-9,14,-7:17.12
-8,14,-7:17.12
-16,15,-7:17.12
-13,15,-7:17.12
-12,15,-7:17.12
-11,15,-7:17.12
-10,15,-7:17.12
-9,15,-7:17.12
-8,15,-7:17.12
-13,16,-7:17.12
-12,16,-7:17.12
-11,16,-7:17.12
-10,16,-7:17.12
-9,16,-7:17.12
-7,16,-7:17.12
-14,17,-7:17.12
-13,17,-7:17.12
-12,17,-7:17.12
-11,17,-7:17.12
-10,17,-7:17.12
-9,17,-7:17.12
-8,17,-7:17.12
-7,17,-7:17.12
-6,17,-7:17.12
-5,17,-7:17.12
-13,18,-7:17.12
-12,18,-7:17.12
-11,18,-7:17.12
-10,18,-7:17.12
-9,18,-7:17.12
-8,18,-7:17.12
-7,18,-7:17.12
-6,18,-7:17.12
-5,18,-7:17.12
-13,19,-7:17.12
-12,19,-7:17.12
-11,19,-7:17.12
-10,19,-7:17.12
-9,19,-7:17.12
-8,19,-7:17.12
-7,19,-7:17.12
-6,19,-7:17.12
-5,19,-7:17.12
-4,19,-7:17.12
-2,19,-7:17.12
-11,20,-7:17.12
-9,20,-7:17.12
-8,20,-7:17.12
-7,20,-7:17.12
-6,20,-7:17.12
-5,20,-7:17.12
-4,20,-7:17.12
-3,20,-7:17.12
-2,20,-7:17.12
-1,20,-7:17.12
0,20,-7:17.12
-9,21,-7:17.12
-8,21,-7:17.12
-7,21,-7:17.12
-6,21,-7:17.12
-5,21,-7:17.12
-4,21,-7:17.12
-3,21,-7:17.12
-2,21,-7:17.12
-1,21,-7:17.12
0,21,-7:17.12
-7,22,-7:17.12
-5,22,-7:17.12
-4,22,-7:17.12
-3,22,-7:17.12
-2,22,-7:17.12
-1,22,-7:17.12
0,22,-7:17.12
1,22,-7:17.12
-4,23,-7:17.12
-3,23,-7:17.12
-2,23,-7:17.12
-1,23,-7:17.12
0,23,-7:17.12
-4,24,-7:17.12
-3,24,-7:17.12
-2,24,-7:17.12
-1,24,-7:17.12
0,24,-7:17.12
-2,25,-7:17.12
3,-11,-6:17.12
2,-10,-6:17.12
3,-10,-6:17.12
4,-10,-6:17.12
-5,-9,-6:17.12
-4,-9,-6:17.12
-3,-9,-6:17.12
-2,-9,-6:17.12
-1,-9,-6:17.12
0,-9,-6:17.12
1,-9,-6:17.12
2,-9,-6:17.12
3,-9,-6:17.12
4,-9,-6:17.12
-6,-8,-6:17.12
-5,-8,-6:17.12
-4,-8,-6:17.12
-3,-8,-6:17.12
-2,-8,-6:17.12
-1,-8,-6:17.12
0,-8,-6:17.12
1,-8,-6:17.12
2,-8,-6:17.12
3,-8,-6:17.12
4,-8,-6:17.12
-8,-7,-6:17.12
-7,-7,-6:17.12
-6,-7,-6:17.12
-5,-7,-6:17.12
-4,-7,-6:17.12
-3,-7,-6:17.12
-2,-7,-6:17.12
-1,-7,-6:17.12
0,-7,-6:17.12
1,-7,-6:17.12
2,-7,-6:17.12
3,-7,-6:17.12
4,-7,-6:17.12
-8,-6,-6:17.12
-7,-6,-6:17.12
-6,-6,-6:17.12
-5,-6,-6:17.12
-4,-6,-6:17.12
-3,-6,-6:17.12
-2,-6,-6:17.12
-1,-6,-6:17.12
0,-6,-6:17.12
1,-6,-6:17.12
2,-6,-6:17.12
3,-6,-6:17.12
-9,-5,-6:17.12
-8,-5,-6:17.12
-7,-5,-6:17.12
-6,-5,-6:17.12
-5,-5,-6:17.12
-4,-5,-6:17.12
-3,-5,-6:17.12
-2,-5,-6:17.12
-1,-5,-6:17.12
0,-5,-6:17.12
1,-5,-6:17.12
-9,-4,-6:17.12
-8,-4,-6:17.12
-7,-4,-6:17.12
-6,-4,-6:17.12
-5,-4,-6:17.12
-4,-4,-6:17.12
-3,-4,-6:17.12
-2,-4,-6:17.12
-1,-4,-6:17.12
0,-4,-6:17.12
-14,-3,-6:17.12
-13,-3,-6:17.12
-12,-3,-6:17.12
-11,-3,-6:17.12
-10,-3,-6:17.12
-9,-3,-6:17.12
-8,-3,-6:17.12
-7,-3,-6:17.12
-6,-3,-6:17.12
-5,-3,-6:17.12
-4,-3,-6:17.12
-3,-3,-6:17.12
-2,-3,-6:17.12
-1,-3,-6:17.12
-17,-2,-6:17.12
-16,-2,-6:17.12
-15,-2,-6:17.12
-14,-2,-6:17.12
-13,-2,-6:17.12
-12,-2,-6:17.12
-11,-2,-6:17.12
-10,-2,-6:17.12
-9,-2,-6:17.12
-8,-2,-6:17.12
-7,-2,-6:17.12
-6,-2,-6:17.12
-5,-2,-6:17.12
-3,-2,-6:17.12
-26,-1,-6:17.12
-19,-1,-6:17.12
-18,-1,-6:17.12
-17,-1,-6:17.12
-16,-1,-6:17.12
-15,-1,-6:17.12
-14,-1,-6:17.12
-13,-1,-6:17.12
-12,-1,-6:17.12
-11,-1,-6:17.12
-10,-1,-6:17.12
-9,-1,-6:17.12
-8,-1,-6:17.12
-7,-1,-6:17.12
-6,-1,-6:17.12
-5,-1,-6:17.12
-28,0,-6:17.12
-27,0,-6:17.12
-26,0,-6:17.12
-25,0,-6:17.12
-24,0,-6:17.12
-23,0,-6:17.12
-22,0,-6:17.12
-21,0,-6:17.12
-20,0,-6:17.12
-19,0,-6:17.12
-18,0,-6:17.12
-17,0,-6:17.12
-16,0,-6:17.12
-15,0,-6:17.12
-14,0,-6:17.12
-13,0,-6:17.12
-12,0,-6:17.12
-11,0,-6:17.12
-10,0,-6:17.12
-9,0,-6:17.12
-8,0,-6:17.12
-7,0,-6:17.12
-28,1,-6:17.12
-27,1,-6:17.12
-26,1,-6:17.12
-25,1,-6:17.12
-24,1,-6:17.12
-23,1,-6:17.12
-22,1,-6:17.12
-21,1,-6:17.12
-20,1,-6:17.12
-19,1,-6:17.12
-18,1,-6:17.12
-17,1,-6:17.12
-16,1,-6:17.12
-15,1,-6:17.12
-14,1,-6:17.12
-13,1,-6:17.12
-12,1,-6:17.12
-11,1,-6:17.12
-10,1,-6:17.12
-9,1,-6:17.12
-8,1,-6:17.12
-7,1,-6:17.12
-27,2,-6:17.12
-26,2,-6:17.12
-25,2,-6:17.12
-24,2,-6:17.12
-23,2,-6:17.12
-22,2,-6:17.12
-21,2,-6:17.12
-20,2,-6:17.12
-19,2,-6:17.12
-18,2,-6:17.12
-17,2,-6:17.12
-16,2,-6:17.12
-15,2,-6:17.12
-14,2,-6:17.12
-13,2,-6:17.12
-12,2,-6:17.12
-11,2,-6:17.12
-10,2,-6:17.12
-9,2,-6:17.12
-26,3,-6:17.12
-25,3,-6:17.12
-24,3,-6:17.12
-23,3,-6:17.12
-22,3,-6:17.12
-21,3,-6:17.12
-20,3,-6:17.12
-19,3,-6:17.12
-18,3,-6:17.12
-17,3,-6:17.12
-16,3,-6:17.12
-15,3,-6:17.12
-13,3,-6:17.12
-12,3,-6:17.12
-11,3,-6:17.12
-10,3,-6:17.12
-9,3,-6:17.12
-8,3,-6:17.12
-7,3,-6:17.12
-6,3,-6:17.12
-5,3,-6:17.12
-4,3,-6:17.12
-26,4,-6:17.12
-25,4,-6:17.12
-24,4,-6:17.12
-23,4,-6:17.12
-22,4,-6:17.12
-21,4,-6:17.12
-20,4,-6:17.12
-19,4,-6:17.12
-18,4,-6:17.12
-17,4,-6:17.12
-16,4,-6:17.12
-15,4,-6:17.12
-13,4,-6:17.12
-12,4,-6:17.12
-11,4,-6:17.12
-10,4,-6:17.12
-9,4,-6:17.12
-8,4,-6:17.12
-7,4,-6:17.12
-6,4,-6:17.12
-5,4,-6:17.12
-4,4,-6:17.12
-24,5,-6:17.12
-23,5,-6:17.12
-22,5,-6:17.12
-21,5,-6:17.12
-20,5,-6:17.12
-19,5,-6:17.12
-18,5,-6:17.12
-17,5,-6:17.12
-16,5,-6:17.12
-15,5,-6:17.12
-14,5,-6:17.12
-13,5,-6:17.12
-12,5,-6:17.12
-11,5,-6:17.12
-10,5,-6:17.12
-9,5,-6:17.12
-8,5,-6:17.12
-7,5,-6:17.12
-6,5,-6:17.12
-5,5,-6:17.12
-4,5,-6:17.12
-3,5,-6:17.12
-21,6,-6:17.12
-20,6,-6:17.12
-19,6,-6:17.12
-18,6,-6:17.12
-17,6,-6:17.12
-16,6,-6:17.12
-15,6,-6:17.12
-14,6,-6:17.12
-13,6,-6:17.12
-12,6,-6:17.12
-11,6,-6:17.12
-10,6,-6:17.12
-9,6,-6:17.12
-8,6,-6:17.12
-7,6,-6:17.12
-6,6,-6:17.12
-5,6,-6:17.12
-4,6,-6:17.12
-3,6,-6:17.12
-2,6,-6:17.12
-1,6,-6:17.12
0,6,-6:17.12
1,6,-6:17.12
2,6,-6:17.12
-20,7,-6:17.12
-19,7,-6:17.12
-18,7,-6:17.12
-17,7,-6:17.12
-16,7,-6:17.12
-15,7,-6:17.12
-14,7,-6:17.12
-13,7,-6:17.12
-12,7,-6:17.12
-11,7,-6:17.12
-10,7,-6:17.12
-9,7,-6:17.12
-8,7,-6:17.12
-7,7,-6:17.12
-6,7,-6:17.12
-5,7,-6:17.12
-4,7,-6:17.12
-3,7,-6:17.12
-2,7,-6:17.12
-1,7,-6:17.12
0,7,-6:17.12
1,7,-6:17.12
2,7,-6:17.12
3,7,-6:17.12
-20,8,-6:17.12
-19,8,-6:17.12
-18,8,-6:17.12
-17,8,-6:17.12
-16,8,-6:17.12
-15,8,-6:17.12
-14,8,-6:17.12
-13,8,-6:17.12
-12,8,-6:17.12
-11,8,-6:17.12
-10,8,-6:17.12
-9,8,-6:17.12
-8,8,-6:17.12
-7,8,-6:17.12
-6,8,-6:17.12
-5,8,-6:17.12
-4,8,-6:17.12
-3,8,-6:17.12
-2,8,-6:17.12
-1,8,-6:17.12
0,8,-6:17.12
1,8,-6:17.12
2,8,-6:17.12
-19,9,-6:17.12
-18,9,-6:17.12
-17,9,-6:17.12
-16,9,-6:17.12
-15,9,-6:17.12
-14,9,-6:17.12
-13,9,-6:17.12
-12,9,-6:17.12
-11,9,-6:17.12
-10,9,-6:17.12
-9,9,-6:17.12
-8,9,-6:17.12
-7,9,-6:17.12
-6,9,-6:17.12
-5,9,-6:17.12
-4,9,-6:17.12
-3,9,-6:17.12
-2,9,-6:17.12
-1,9,-6:17.12
0,9,-6:17.12
1,9,-6:17.12
2,9,-6:17.12
-19,10,-6:17.12
-18,10,-6:17.12
-17,10,-6:17.12
-16,10,-6:17.12
-15,10,-6:17.12
-14,10,-6:17.12
-13,10,-6:17.12
-12,10,-6:17.12
-11,10,-6:17.12
-10,10,-6:17.12
-9,10,-6:17.12
-8,10,-6:17.12
-7,10,-6:17.12
-6,10,-6:17.12
-5,10,-6:17.12
-4,10,-6:17.12
-3,10,-6:17.12
-2,10,-6:17.12
-1,10,-6:17.12
0,10,-6:17.12
-18,11,-6:17.12
-17,11,-6:17.12
-16,11,-6:17.12
-15,11,-6:17.12
-14,11,-6:17.12
-13,11,-6:17.12
-12,11,-6:17.12
-11,11,-6:17.12
-10,11,-6:17.12
-9,11,-6:17.12
-8,11,-6:17.12
-6,11,-6:17.12
-5,11,-6:17.12
-4,11,-6:17.12
-3,11,-6:17.12
-2,11,-6:17.12
-1,11,-6:17.12
-18,12,-6:17.12
-17,12,-6:17.12
-16,12,-6:17.12
-15,12,-6:17.12
-14,12,-6:17.12
-13,12,-6:17.12
-12,12,-6:17.12
-11,12,-6:17.12
-10,12,-6:17.12
-9,12,-6:17.12
-8,12,-6:17.12
-6,12,-6:17.12
-5,12,-6:17.12
-4,12,-6:17.12
-3,12,-6:17.12
-17,13,-6:17.12
-16,13,-6:17.12
-15,13,-6:17.12
-14,13,-6:17.12
-13,13,-6:17.12
-12,13,-6:17.12
-11,13,-6:17.12
-10,13,-6:17.12
-9,13,-6:17.12
-8,13,-6:17.12
-16,14,-6:17.12
-15,14,-6:17.12
-14,14,-6:17.12
-13,14,-6:17.12
-12,14,-6:17.12
-11,14,-6:17.12
-10,14,-6:17.12
-9,14,-6:17.12
-8,14,-6:17.12
-7,14,-6:17.12
-14,15,-6:17.12
-13,15,-6:17.12
-12,15,-6:17.12
-11,15,-6:17.12
-10,15,-6:17.12
-9,15,-6:17.12
-8,15,-6:17.12
-13,16,-6:17.12
-12,16,-6:17.12
-11,16,-6:17.12
-10,16,-6:17.12
-9,16,-6:17.12
-13,17,-6:17.12
-12,17,-6:17.12
-11,17,-6:17.12
-10,17,-6:17.12
-9,17,-6:17.12
-8,17,-6:17.12
-7,17,-6:17.12
-6,17,-6:17.12
-5,17,-6:17.12
-13,18,-6:17.12
-12,18,-6:17.12
-11,18,-6:17.12
-10,18,-6:17.12
-9,18,-6:17.12
-8,18,-6:17.12
-7,18,-6:17.12
-6,18,-6:17.12
-5,18,-6:17.12
-13,19,-6:17.12
-12,19,-6:17.12
-11,19,-6:17.12
-10,19,-6:17.12
-9,19,-6:17.12
-8,19,-6:17.12
-7,19,-6:17.12
-6,19,-6:17.12
-5,19,-6:17.12
-9,20,-6:17.12
-8,20,-6:17.12
-7,20,-6:17.12
-6,20,-6:17.12
-5,20,-6:17.12
-4,20,-6:17.12
-3,20,-6:17.12
-2,20,-6:17.12
-1,20,-6:17.12
0,20,-6:17.12
-9,21,-6:17.12
-8,21,-6:17.12
-7,21,-6:17.12
-6,21,-6:17.12
-5,21,-6:17.12
-4,21,-6:17.12
-3,21,-6:17.12
-2,21,-6:17.12
-1,21,-6:17.12
0,21,-6:17.12
-5,22,-6:17.12
-4,22,-6:17.12
-3,22,-6:17.12
-2,22,-6:17.12
-1,22,-6:17.12
0,22,-6:17.12
-4,23,-6:17.12
-3,23,-6:17.12
-2,23,-6:17.12
-1,23,-6:17.12
0,23,-6:17.12
-4,24,-6:17.12
-3,24,-6:17.12
-2,24,-6:17.12
-1,24,-6:17.12
0,24,-6:17.12
-4,-8,-5:17.12
-3,-8,-5:17.12
-2,-8,-5:17.12
-1,-8,-5:17.12
0,-8,-5:17.12
1,-8,-5:17.12
-5,-7,-5:17.12
-4,-7,-5:17.12
-3,-7,-5:17.12
-2,-7,-5:17.12
-1,-7,-5:17.12
0,-7,-5:17.12
1,-7,-5:17.12
-7,-6,-5:17.12
-6,-6,-5:17.12
-5,-6,-5:17.12
-4,-6,-5:17.12
-3,-6,-5:17.12
-2,-6,-5:17.12
-1,-6,-5:17.12
0,-6,-5:17.12
1,-6,-5:17.12
-8,-5,-5:17.12
-7,-5,-5:17.12
-6,-5,-5:17.12
-5,-5,-5:17.12
-4,-5,-5:17.12
-3,-5,-5:17.12
-2,-5,-5:17.12
-1,-5,-5:17.12
-9,-4,-5:17.12
-8,-4,-5:17.12
-7,-4,-5:17.12
-6,-4,-5:17.12
-5,-4,-5:17.12
-4,-4,-5:17.12
-3,-4,-5:17.12
-2,-4,-5:17.12
-10,-3,-5:17.12
-9,-3,-5:17.12
-8,-3,-5:17.12
-7,-3,-5:17.12
-6,-3,-5:17.12
-5,-3,-5:17.12
-11,-2,-5:17.12
-10,-2,-5:17.12
-9,-2,-5:17.12
-8,-2,-5:17.12
-7,-2,-5:17.12
-6,-2,-5:17.12
-5,-2,-5:17.12
-16,-1,-5:17.12
-15,-1,-5:17.12
-14,-1,-5:17.12
-13,-1,-5:17.12
-12,-1,-5:17.12
-11,-1,-5:17.12
-10,-1,-5:17.12
-9,-1,-5:17.12
-8,-1,-5:17.12
-7,-1,-5:17.12
-6,-1,-5:17.12
-17,0,-5:17.12
-16,0,-5:17.12
-15,0,-5:17.12
-14,0,-5:17.12
-13,0,-5:17.12
-12,0,-5:17.12
-11,0,-5:17.12
-10,0,-5:17.12
-9,0,-5:17.12
-8,0,-5:17.12
-7,0,-5:17.12
-25,1,-5:17.12
-24,1,-5:17.12
-18,1,-5:17.12
-17,1,-5:17.12
-16,1,-5:17.12
-15,1,-5:17.12
-14,1,-5:17.12
-13,1,-5:17.12
-12,1,-5:17.12
-11,1,-5:17.12
-10,1,-5:17.12
-9,1,-5:17.12
-8,1,-5:17.12
-25,2,-5:17.12
-24,2,-5:17.12
-23,2,-5:17.12
-22,2,-5:17.12
-21,2,-5:17.12
-20,2,-5:17.12
-19,2,-5:17.12
-18,2,-5:17.12
-17,2,-5:17.12
-16,2,-5:17.12
-15,2,-5:17.12
-14,2,-5:17.12
-13,2,-5:17.12
-12,2,-5:17.12
-11,2,-5:17.12
-10,2,-5:17.12
-9,2,-5:17.12
-7,2,-5:17.12
-26,3,-5:17.12
-25,3,-5:17.12
-24,3,-5:17.12
-23,3,-5:17.12
-22,3,-5:17.12
-21,3,-5:17.12
-20,3,-5:17.12
-19,3,-5:17.12
-18,3,-5:17.12
-17,3,-5:17.12
-16,3,-5:17.12
-15,3,-5:17.12
-13,3,-5:17.12
-12,3,-5:17.12
-11,3,-5:17.12
-10,3,-5:17.12
-9,3,-5:17.12
-8,3,-5:17.12
-7,3,-5:17.12
-6,3,-5:17.12
-25,4,-5:17.12
-24,4,-5:17.12
-23,4,-5:17.12
-22,4,-5:17.12
-21,4,-5:17.12
-20,4,-5:17.12
-19,4,-5:17.12
-18,4,-5:17.12
-17,4,-5:17.12
-16,4,-5:17.12
-15,4,-5:17.12
-14,4,-5:17.12
-13,4,-5:17.12
-12,4,-5:17.12
-11,4,-5:17.12
-10,4,-5:17.12
-9,4,-5:17.12
-8,4,-5:17.12
-7,4,-5:17.12
-6,4,-5:17.12
-5,4,-5:17.12
-23,5,-5:17.12
-22,5,-5:17.12
-21,5,-5:17.12
-20,5,-5:17.12
-19,5,-5:17.12
-18,5,-5:17.12
-17,5,-5:17.12
-16,5,-5:17.12
-15,5,-5:17.12
-14,5,-5:17.12
-13,5,-5:17.12
-12,5,-5:17.12
-11,5,-5:17.12
-10,5,-5:17.12
-9,5,-5:17.12
-8,5,-5:17.12
-7,5,-5:17.12
-6,5,-5:17.12
-5,5,-5:17.12
-20,6,-5:17.12
-19,6,-5:17.12
-18,6,-5:17.12
-17,6,-5:17.12
-16,6,-5:17.12
-15,6,-5:17.12
-14,6,-5:17.12
-13,6,-5:17.12
-12,6,-5:17.12
-11,6,-5:17.12
-10,6,-5:17.12
-9,6,-5:17.12
-8,6,-5:17.12
-7,6,-5:17.12
-6,6,-5:17.12
-5,6,-5:17.12
-19,7,-5:17.12
-18,7,-5:17.12
-17,7,-5:17.12
-16,7,-5:17.12
-15,7,-5:17.12
-14,7,-5:17.12
-13,7,-5:17.12
-12,7,-5:17.12
-11,7,-5:17.12
-10,7,-5:17.12
-9,7,-5:17.12
-8,7,-5:17.12
-7,7,-5:17.12
-6,7,-5:17.12
-5,7,-5:17.12
-4,7,-5:17.12
-3,7,-5:17.12
-2,7,-5:17.12
-1,7,-5:17.12
0,7,-5:17.12
1,7,-5:17.12
-19,8,-5:17.12
-18,8,-5:17.12
-17,8,-5:17.12
-16,8,-5:17.12
-15,8,-5:17.12
-14,8,-5:17.12
-13,8,-5:17.12
-12,8,-5:17.12
-11,8,-5:17.12
-10,8,-5:17.12
-9,8,-5:17.12
-8,8,-5:17.12
-7,8,-5:17.12
-6,8,-5:17.12
-5,8,-5:17.12
-4,8,-5:17.12
-3,8,-5:17.12
-2,8,-5:17.12
-1,8,-5:17.12
0,8,-5:17.12
1,8,-5:17.12
-19,9,-5:17.12
-18,9,-5:17.12
-17,9,-5:17.12
-16,9,-5:17.12
-15,9,-5:17.12
-14,9,-5:17.12
-13,9,-5:17.12
-12,9,-5:17.12
-11,9,-5:17.12
-10,9,-5:17.12
-9,9,-5:17.12
-8,9,-5:17.12
-7,9,-5:17.12
-6,9,-5:17.12
-5,9,-5:17.12
-4,9,-5:17.12
-3,9,-5:17.12
-2,9,-5:17.12
-1,9,-5:17.12
0,9,-5:17.12
-19,10,-5:17.12
-18,10,-5:17.12
-17,10,-5:17.12
-16,10,-5:17.12
-15,10,-5:17.12
-14,10,-5:17.12
-13,10,-5:17.12
-12,10,-5:17.12
-11,10,-5:17.12
-10,10,-5:17.12
-9,10,-5:17.12
-8,10,-5:17.12
-7,10,-5:17.12
-6,10,-5:17.12
-5,10,-5:17.12
-4,10,-5:17.12
-3,10,-5:17.12
-2,10,-5:17.12
-18,11,-5:17.12
-17,11,-5:17.12
-16,11,-5:17.12
-15,11,-5:17.12
-14,11,-5:17.12
-13,11,-5:17.12
-12,11,-5:17.12
-11,11,-5:17.12
-10,11,-5:17.12
-9,11,-5:17.12
-8,11,-5:17.12
-6,11,-5:17.12
-5,11,-5:17.12
-4,11,-5:17.12
-3,11,-5:17.12
-17,12,-5:17.12
-16,12,-5:17.12
-15,12,-5:17.12
-14,12,-5:17.12
-13,12,-5:17.12
-12,12,-5:17.12
-11,12,-5:17.12
-10,12,-5:17.12
-9,12,-5:17.12
-8,12,-5:17.12
-7,12,-5:17.12
-5,12,-5:17.12
-15,13,-5:17.12
-14,13,-5:17.12
-13,13,-5:17.12
-12,13,-5:17.12
-11,13,-5:17.12
-10,13,-5:17.12
-9,13,-5:17.12
-8,13,-5:17.12
-14,14,-5:17.12
-13,14,-5:17.12
-12,14,-5:17.12
-11,14,-5:17.12
-10,14,-5:17.12
-9,14,-5:17.12
-8,14,-5:17.12
-12,15,-5:17.12
-11,15,-5:17.12
-10,15,-5:17.12
-9,15,-5:17.12
-8,15,-5:17.12
-12,16,-5:17.12
-11,16,-5:17.12
-10,16,-5:17.12
-9,16,-5:17.12
-12,17,-5:17.12
-11,17,-5:17.12
-10,17,-5:17.12
-9,17,-5:17.12
-8,17,-5:17.12
-7,17,-5:17.12
-6,17,-5:17.12
-13,18,-5:17.12
-12,18,-5:17.12
-11,18,-5:17.12
-10,18,-5:17.12
-9,18,-5:17.12
-8,18,-5:17.12
-7,18,-5:17.12
-6,18,-5:17.12
-9,19,-5:17.12
-8,19,-5:17.12
-7,19,-5:17.12
-6,19,-5:17.12
-9,20,-5:17.12
-8,20,-5:17.12
-7,20,-5:17.12
-6,20,-5:17.12
-1,20,-5:17.12
-3,21,-5:17.12
-2,21,-5:17.12
-1,21,-5:17.12
0,21,-5:17.12
-3,22,-5:17.12
-2,22,-5:17.12
-1,22,-5:17.12
0,22,-5:17.12
-3,23,-5:17.12
-2,23,-5:17.12
-1,23,-5:17.12
0,23,-5:17.12
-3,24,-5:17.12
-2,24,-5:17.12
-1,24,-5:17.12
-7,-4,-4:17.12
-9,-3,-4:17.12
-8,-3,-4:17.12
-7,-3,-4:17.12
-6,-3,-4:17.12
-9,-2,-4:17.12
-8,-2,-4:17.12
-7,-2,-4:17.12
-6,-2,-4:17.12
-9,-1,-4:17.12
-8,-1,-4:17.12
-15,0,-4:17.12
-14,0,-4:17.12
-13,0,-4:17.12
-12,0,-4:17.12
-11,0,-4:17.12
-10,0,-4:17.12
-9,0,-4:17.12
-17,1,-4:17.12
-16,1,-4:17.12
-15,1,-4:17.12
-14,1,-4:17.12
-13,1,-4:17.12
-12,1,-4:17.12
-11,1,-4:17.12
-10,1,-4:17.12
-9,1,-4:17.12
-8,1,-4:17.12
-18,2,-4:17.12
-17,2,-4:17.12
-16,2,-4:17.12
-15,2,-4:17.12
-14,2,-4:17.12
-13,2,-4:17.12
-12,2,-4:17.12
-11,2,-4:17.12
-10,2,-4:17.12
-9,2,-4:17.12
-8,2,-4:17.12
-18,3,-4:17.12
-17,3,-4:17.12
-16,3,-4:17.12
-15,3,-4:17.12
-13,3,-4:17.12
-12,3,-4:17.12
-11,3,-4:17.12
-10,3,-4:17.12
-9,3,-4:17.12
-8,3,-4:17.12
-6,3,-4:17.12
-19,4,-4:17.12
-18,4,-4:17.12
-17,4,-4:17.12
-16,4,-4:17.12
-15,4,-4:17.12
-13,4,-4:17.12
-12,4,-4:17.12
-11,4,-4:17.12
-10,4,-4:17.12
-9,4,-4:17.12
-8,4,-4:17.12
-7,4,-4:17.12
-19,5,-4:17.12
-18,5,-4:17.12
-17,5,-4:17.12
-16,5,-4:17.12
-15,5,-4:17.12
-13,5,-4:17.12
-12,5,-4:17.12
-11,5,-4:17.12
-10,5,-4:17.12
-9,5,-4:17.12
-8,5,-4:17.12
-7,5,-4:17.12
-6,5,-4:17.12
-19,6,-4:17.12
-18,6,-4:17.12
-17,6,-4:17.12
-16,6,-4:17.12
-15,6,-4:17.12
-14,6,-4:17.12
-13,6,-4:17.12
-12,6,-4:17.12
-11,6,-4:17.12
-10,6,-4:17.12
-9,6,-4:17.12
-8,6,-4:17.12
-7,6,-4:17.12
-6,6,-4:17.12
-19,7,-4:17.12
-18,7,-4:17.12
-17,7,-4:17.12
-16,7,-4:17.12
-15,7,-4:17.12
-14,7,-4:17.12
-13,7,-4:17.12
-12,7,-4:17.12
-11,7,-4:17.12
-10,7,-4:17.12
-9,7,-4:17.12
-8,7,-4:17.12
-7,7,-4:17.12
-6,7,-4:17.12
-19,8,-4:17.12
-18,8,-4:17.12
-17,8,-4:17.12
-16,8,-4:17.12
-15,8,-4:17.12
-14,8,-4:17.12
-13,8,-4:17.12
-12,8,-4:17.12
-11,8,-4:17.12
-10,8,-4:17.12
-9,8,-4:17.12
-8,8,-4:17.12
-7,8,-4:17.12
-6,8,-4:17.12
-19,9,-4:17.12
-18,9,-4:17.12
-17,9,-4:17.12
-16,9,-4:17.12
-15,9,-4:17.12
-14,9,-4:17.12
-13,9,-4:17.12
-12,9,-4:17.12
-11,9,-4:17.12
-10,9,-4:17.12
-9,9,-4:17.12
-8,9,-4:17.12
-7,9,-4:17.12
-6,9,-4:17.12
-18,10,-4:17.12
-17,10,-4:17.12
-16,10,-4:17.12
-15,10,-4:17.12
-14,10,-4:17.12
-13,10,-4:17.12
-12,10,-4:17.12
-11,10,-4:17.12
-10,10,-4:17.12
-9,10,-4:17.12
-8,10,-4:17.12
-7,10,-4:17.12
-16,11,-4:17.12
-15,11,-4:17.12
-14,11,-4:17.12
-13,11,-4:17.12
-12,11,-4:17.12
-11,11,-4:17.12
-10,11,-4:17.12
-9,11,-4:17.12
-8,11,-4:17.12
-7,11,-4:17.12
-15,12,-4:17.12
-14,12,-4:17.12
-13,12,-4:17.12
-12,12,-4:17.12
-11,12,-4:17.12
-10,12,-4:17.12
-9,12,-4:17.12
-8,12,-4:17.12
-14,13,-4:17.12
-13,13,-4:17.12
-12,13,-4:17.12
-11,13,-4:17.12
-10,13,-4:17.12
-9,13,-4:17.12
-13,14,-4:17.12
-12,14,-4:17.12
-11,14,-4:17.12
-10,14,-4:17.12
-9,14,-4:17.12
-12,0,-3:17.12
-11,0,-3:17.12
-10,0,-3:17.12
-9,0,-3:17.12
-13,1,-3:17.12
-12,1,-3:17.12
-11,1,-3:17.12
-10,1,-3:17.12
-9,1,-3:17.12
-17,2,-3:17.12
-16,2,-3:17.12
-15,2,-3:17.12
-14,2,-3:17.12
-13,2,-3:17.12
-12,2,-3:17.12
-11,2,-3:17.12
-10,2,-3:17.12
-9,2,-3:17.12
-17,3,-3:17.12
-16,3,-3:17.12
-15,3,-3:17.12
-14,3,-3:17.12
-13,3,-3:17.12
-12,3,-3:17.12
-11,3,-3:17.12
-10,3,-3:17.12
-9,3,-3:17.12
-18,4,-3:17.12
-17,4,-3:17.12
-16,4,-3:17.12
-15,4,-3:17.12
-14,4,-3:17.12
-13,4,-3:17.12
-12,4,-3:17.12
-11,4,-3:17.12
-10,4,-3:17.12
-9,4,-3:17.12
-8,4,-3:17.12
-18,5,-3:17.12
-17,5,-3:17.12
-16,5,-3:17.12
-15,5,-3:17.12
-14,5,-3:17.12
-13,5,-3:17.12
-12,5,-3:17.12
-11,5,-3:17.12
-10,5,-3:17.12
-9,5,-3:17.12
-18,6,-3:17.12
-17,6,-3:17.12
-16,6,-3:17.12
-15,6,-3:17.12
-14,6,-3:17.12
-13,6,-3:17.12
-12,6,-3:17.12
-11,6,-3:17.12
-10,6,-3:17.12
-9,6,-3:17.12
-8,6,-3:17.12
-7,6,-3:17.12
-18,7,-3:17.12
-17,7,-3:17.12
-16,7,-3:17.12
-15,7,-3:17.12
-14,7,-3:17.12
-13,7,-3:17.12
-12,7,-3:17.12
-11,7,-3:17.12
-10,7,-3:17.12
-9,7,-3:17.12
-8,7,-3:17.12
-7,7,-3:17.12
-18,8,-3:17.12
-17,8,-3:17.12
-16,8,-3:17.12
-15,8,-3:17.12
-14,8,-3:17.12
-13,8,-3:17.12
-12,8,-3:17.12
-11,8,-3:17.12
-10,8,-3:17.12
-9,8,-3:17.12
-8,8,-3:17.12
-7,8,-3:17.12
-18,9,-3:17.12
-17,9,-3:17.12
-16,9,-3:17.12
-15,9,-3:17.12
-14,9,-3:17.12
-13,9,-3:17.12
-12,9,-3:17.12
-11,9,-3:17.12
-10,9,-3:17.12
-9,9,-3:17.12
-8,9,-3:17.12
-7,9,-3:17.12
-17,10,-3:17.12
-16,10,-3:17.12
-15,10,-3:17.12
-14,10,-3:17.12
-13,10,-3:17.12
-12,10,-3:17.12
-11,10,-3:17.12
-10,10,-3:17.12
-9,10,-3:17.12
-8,10,-3:17.12
-7,10,-3:17.12
-6,10,-3:17.12
-16,11,-3:17.12
-15,11,-3:17.12
-14,11,-3:17.12
-13,11,-3:17.12
-12,11,-3:17.12
-11,11,-3:17.12
-10,11,-3:17.12
-9,11,-3:17.12
-8,11,-3:17.12
-15,12,-3:17.12
-14,12,-3:17.12
-13,12,-3:17.12
-12,12,-3:17.12
-11,12,-3:17.12
-10,12,-3:17.12
-9,12,-3:17.12
-12,13,-3:17.12
-11,13,-3:17.12
-10,13,-3:17.12
-12,0,-2:17.12
-11,0,-2:17.12
-10,0,-2:17.12
-13,1,-2:17.12
-12,1,-2:17.12
-11,1,-2:17.12
-10,1,-2:17.12
-14,2,-2:17.12
-13,2,-2:17.12
-12,2,-2:17.12
-11,2,-2:17.12
-10,2,-2:17.12
-16,3,-2:17.12
-15,3,-2:17.12
-14,3,-2:17.12
-13,3,-2:17.12
-12,3,-2:17.12
-11,3,-2:17.12
-10,3,-2:17.12
-17,4,-2:17.12
-16,4,-2:17.12
-15,4,-2:17.12
-14,4,-2:17.12
-13,4,-2:17.12
-12,4,-2:17.12
-11,4,-2:17.12
-10,4,-2:17.12
-9,4,-2:17.12
-17,5,-2:17.12
-16,5,-2:17.12
-15,5,-2:17.12
-14,5,-2:17.12
-13,5,-2:17.12
-12,5,-2:17.12
-11,5,-2:17.12
-10,5,-2:17.12
-9,5,-2:17.12
-18,6,-2:17.12
-17,6,-2:17.12
-16,6,-2:17.12
-15,6,-2:17.12
-14,6,-2:17.12
-13,6,-2:17.12
-12,6,-2:17.12
-11,6,-2:17.12
-10,6,-2:17.12
-9,6,-2:17.12
-8,6,-2:17.12
-18,7,-2:17.12
-17,7,-2:17.12
-16,7,-2:17.12
-15,7,-2:17.12
-14,7,-2:17.12
-13,7,-2:17.12
-12,7,-2:17.12
-11,7,-2:17.12
-10,7,-2:17.12
-9,7,-2:17.12
-8,7,-2:17.12
-18,8,-2:17.12
-17,8,-2:17.12
-16,8,-2:17.12
-15,8,-2:17.12
-14,8,-2:17.12
-13,8,-2:17.12
-12,8,-2:17.12
-11,8,-2:17.12
-10,8,-2:17.12
-9,8,-2:17.12
-8,8,-2:17.12
-17,9,-2:17.12
-16,9,-2:17.12
-15,9,-2:17.12
-14,9,-2:17.12
-13,9,-2:17.12
-12,9,-2:17.12
-11,9,-2:17.12
-10,9,-2:17.12
-9,9,-2:17.12
-8,9,-2:17.12
-17,10,-2:17.12
-16,10,-2:17.12
-15,10,-2:17.12
-14,10,-2:17.12
-13,10,-2:17.12
-12,10,-2:17.12
-11,10,-2:17.12
-10,10,-2:17.12
-9,10,-2:17.12
-8,10,-2:17.12
-15,11,-2:17.12
-14,11,-2:17.12
-13,11,-2:17.12
-12,11,-2:17.12
-11,11,-2:17.12
-10,11,-2:17.12
-9,11,-2:17.12
-13,12,-2:17.12
-12,12,-2:17.12
-11,12,-2:17.12
-14,2,-1:17.12
-13,2,-1:17.12
-12,2,-1:17.12
-11,2,-1:17.12
-15,3,-1:17.12
-14,3,-1:17.12
-13,3,-1:17.12
-12,3,-1:17.12
-11,3,-1:17.12
-10,3,-1:17.12
-16,4,-1:17.12
-15,4,-1:17.12
-14,4,-1:17.12
-13,4,-1:17.12
-12,4,-1:17.12
-11,4,-1:17.12
-10,4,-1:17.12
-17,5,-1:17.12
-16,5,-1:17.12
-15,5,-1:17.12
-14,5,-1:17.12
-13,5,-1:17.12
-12,5,-1:17.12
-11,5,-1:17.12
-10,5,-1:17.12
-9,5,-1:17.12
-18,6,-1:17.12
-17,6,-1:17.12
-16,6,-1:17.12
-15,6,-1:17.12
-14,6,-1:17.12
-13,6,-1:17.12
-12,6,-1:17.12
-11,6,-1:17.12
-10,6,-1:17.12
-9,6,-1:17.12
-8,6,-1:17.12
-18,7,-1:17.12
-17,7,-1:17.12
-16,7,-1:17.12
-15,7,-1:17.12
-14,7,-1:17.12
-13,7,-1:17.12
-12,7,-1:17.12
-11,7,-1:17.12
-10,7,-1:17.12
-9,7,-1:17.12
-8,7,-1:17.12
-18,8,-1:17.12
-17,8,-1:17.12
-16,8,-1:17.12
-15,8,-1:17.12
-14,8,-1:17.12
-13,8,-1:17.12
-12,8,-1:17.12
-11,8,-1:17.12
-10,8,-1:17.12
-9,8,-1:17.12
-8,8,-1:17.12
-17,9,-1:17.12
-16,9,-1:17.12
-15,9,-1:17.12
-14,9,-1:17.12
-13,9,-1:17.12
-12,9,-1:17.12
-11,9,-1:17.12
-10,9,-1:17.12
-9,9,-1:17.12
-17,10,-1:17.12
-16,10,-1:17.12
-15,10,-1:17.12
-14,10,-1:17.12
-13,10,-1:17.12
-12,10,-1:17.12
-11,10,-1:17.12
-10,10,-1:17.12
-15,11,-1:17.12
-14,11,-1:17.12
-13,11,-1:17.12
-12,11,-1:17.12
-11,11,-1:17.12
-13,12,-1:17.12
-12,12,-1:17.12
-15,3,0:17.12
-14,3,0:17.12
-13,3,0:17.12
-12,3,0:17.12
-11,3,0:17.12
-16,4,0:17.12
-15,4,0:17.12
-14,4,0:17.12
-13,4,0:17.12
-12,4,0:17.12
-11,4,0:17.12
-10,4,0:17.12
-17,5,0:17.12
-16,5,0:17.12
-15,5,0:17.12
-14,5,0:17.12
-13,5,0:17.12
-12,5,0:17.12
-11,5,0:17.12
-10,5,0:17.12
-9,5,0:17.12
-17,6,0:17.12
-16,6,0:17.12
-15,6,0:17.12
-14,6,0:17.12
-13,6,0:17.12
-12,6,0:17.12
-11,6,0:17.12
-10,6,0:17.12
-9,6,0:17.12
-8,6,0:17.12
-18,7,0:17.12
-17,7,0:17.12
-16,7,0:17.12
-15,7,0:17.12
-14,7,0:17.12
-13,7,0:17.12
-12,7,0:17.12
-11,7,0:17.12
-10,7,0:17.12
-9,7,0:17.12
-8,7,0:17.12
-17,8,0:17.12
-16,8,0:17.12
-15,8,0:17.12
-14,8,0:17.12
-13,8,0:17.12
-12,8,0:17.12
-11,8,0:17.12
-10,8,0:17.12
-9,8,0:17.12
-17,9,0:17.12
-16,9,0:17.12
-15,9,0:17.12
-14,9,0:17.12
-13,9,0:17.12
-12,9,0:17.12
-11,9,0:17.12
-10,9,0:17.12
-17,10,0:17.12
-16,10,0:17.12
-15,10,0:17.12
-14,10,0:17.12
-13,10,0:17.12
-12,10,0:17.12
-11,10,0:17.12
-15,11,0:17.12
-14,11,0:17.12
-13,11,0:17.12
-12,11,0:17.12
-11,11,0:17.12
-13,12,0:17.12
-16,4,1:17.12
-15,4,1:17.12
-14,4,1:17.12
-13,4,1:17.12
-12,4,1:17.12
-11,4,1:17.12
-10,4,1:17.12
-17,5,1:17.12
-16,5,1:17.12
-15,5,1:17.12
-14,5,1:17.12
-13,5,1:17.12
-12,5,1:17.12
-11,5,1:17.12
-10,5,1:17.12
-17,6,1:17.12
-16,6,1:17.12
-15,6,1:17.12
-14,6,1:17.12
-13,6,1:17.12
-12,6,1:17.12
-11,6,1:17.12
-10,6,1:17.12
-9,6,1:17.12
-17,7,1:17.12
-16,7,1:17.12
-15,7,1:17.12
-14,7,1:17.12
-13,7,1:17.12
-12,7,1:17.12
-11,7,1:17.12
-10,7,1:17.12
-9,7,1:17.12
-17,8,1:17.12
-16,8,1:17.12
-15,8,1:17.12
-14,8,1:17.12
-13,8,1:17.12
-12,8,1:17.12
-11,8,1:17.12
-10,8,1:17.12
-17,9,1:17.12
-16,9,1:17.12
-15,9,1:17.12
-14,9,1:17.12
-13,9,1:17.12
-12,9,1:17.12
-11,9,1:17.12
-16,10,1:17.12
-15,10,1:17.12
-14,10,1:17.12
-13,10,1:17.12
-12,10,1:17.12
-11,10,1:17.12
-15,11,1:17.12
-14,11,1:17.12
-13,11,1:17.12
-12,11,1:17.12
-16,4,2:17.12
-15,4,2:17.12
-14,4,2:17.12
-13,4,2:17.12
-12,4,2:17.12
-11,4,2:17.12
-16,5,2:17.12
-15,5,2:17.12
-14,5,2:17.12
-13,5,2:17.12
-12,5,2:17.12
-11,5,2:17.12
-10,5,2:17.12
-17,6,2:17.12
-16,6,2:17.12
-15,6,2:17.12
-14,6,2:17.12
-13,6,2:17.12
-12,6,2:17.12
-11,6,2:17.12
-10,6,2:17.12
-17,7,2:17.12
-16,7,2:17.12
-15,7,2:17.12
-14,7,2:17.12
-13,7,2:17.12
-12,7,2:17.12
-11,7,2:17.12
-10,7,2:17.12
-17,8,2:17.12
-16,8,2:17.12
-15,8,2:17.12
-14,8,2:17.12
-13,8,2:17.12
-12,8,2:17.12
-11,8,2:17.12
-17,9,2:17.12
-16,9,2:17.12
-15,9,2:17.12
-14,9,2:17.12
-13,9,2:17.12
-12,9,2:17.12
-11,9,2:17.12
-16,10,2:17.12
-15,10,2:17.12
-14,10,2:17.12
-13,10,2:17.12
-12,10,2:17.12
-14,11,2:17.12
-13,11,2:17.12
-15,4,3:17.12
-14,4,3:17.12
-13,4,3:17.12
-12,4,3:17.12
-16,5,3:17.12
-15,5,3:17.12
-14,5,3:17.12
-13,5,3:17.12
-12,5,3:17.12
-11,5,3:17.12
-17,6,3:17.12
-16,6,3:17.12
-15,6,3:17.12
-14,6,3:17.12
-13,6,3:17.12
-12,6,3:17.12
-11,6,3:17.12
-10,6,3:17.12
-17,7,3:17.12
-16,7,3:17.12
-15,7,3:17.12
-14,7,3:17.12
-13,7,3:17.12
-12,7,3:17.12
-11,7,3:17.12
-17,8,3:17.12
-16,8,3:17.12
-15,8,3:17.12
-14,8,3:17.12
-13,8,3:17.12
-12,8,3:17.12
-11,8,3:17.12
-17,9,3:17.12
-16,9,3:17.12
-15,9,3:17.12
-14,9,3:17.12
-13,9,3:17.12
-12,9,3:17.12
-11,9,3:17.12
-16,10,3:17.12
-15,10,3:17.12
-14,10,3:17.12
-13,10,3:17.12
-12,10,3:17.12
-13,11,3:17.12
-15,4,4:17.12
-14,4,4:17.12
-13,4,4:17.12
-16,5,4:17.12
-15,5,4:17.12
-14,5,4:17.12
-13,5,4:17.12
-12,5,4:17.12
-11,5,4:17.12
-17,6,4:17.12
-16,6,4:17.12
-15,6,4:17.12
-14,6,4:17.12
-13,6,4:17.12
-12,6,4:17.12
-11,6,4:17.12
-17,7,4:17.12
-16,7,4:17.12
-15,7,4:17.12
-14,7,4:17.12
-13,7,4:17.12
-12,7,4:17.12
-11,7,4:17.12
-17,8,4:17.12
-16,8,4:17.12
-15,8,4:17.12
-14,8,4:17.12
-13,8,4:17.12
-12,8,4:17.12
-11,8,4:17.12
-16,9,4:17.12
-15,9,4:17.12
-14,9,4:17.12
-13,9,4:17.12
-12,9,4:17.12
-15,10,4:17.12
-14,10,4:17.12
-13,10,4:17.12
-15,4,5:17.12
-14,4,5:17.12
-13,4,5:17.12
-12,4,5:17.12
-16,5,5:17.12
-15,5,5:17.12
-14,5,5:17.12
-13,5,5:17.12
-12,5,5:17.12
-16,6,5:17.12
-15,6,5:17.12
-14,6,5:17.12
-13,6,5:17.12
-12,6,5:17.12
-11,6,5:17.12
-16,7,5:17.12
-15,7,5:17.12
-14,7,5:17.12
-13,7,5:17.12
-12,7,5:17.12
-11,7,5:17.12
-16,8,5:17.12
-15,8,5:17.12
-14,8,5:17.12
-13,8,5:17.12
-12,8,5:17.12
-11,8,5:17.12
-16,9,5:17.12
-15,9,5:17.12
-14,9,5:17.12
-13,9,5:17.12
-12,9,5:17.12
-14,10,5:17.12
-13,10,5:17.12
-14,3,6:17.12
-13,3,6:17.12
-16,4,6:17.12
-15,4,6:17.12
-14,4,6:17.12
-13,4,6:17.12
-12,4,6:17.12
-16,5,6:17.12
-15,5,6:17.12
-14,5,6:17.12
-13,5,6:17.12
-12,5,6:17.12
-11,5,6:17.12
-10,5,6:17.12
-16,6,6:17.12
-15,6,6:17.12
-14,6,6:17.12
-13,6,6:17.12
-12,6,6:17.12
-11,6,6:17.12
-16,7,6:17.12
-15,7,6:17.12
-14,7,6:17.12
-13,7,6:17.12
-12,7,6:17.12
-11,7,6:17.12
-16,8,6:17.12
-15,8,6:17.12
-14,8,6:17.12
-13,8,6:17.12
-12,8,6:17.12
-11,8,6:17.12
-15,9,6:17.12
-14,9,6:17.12
-13,9,6:17.12
-12,9,6:17.12
-15,3,7:17.12
-14,3,7:17.12
-13,3,7:17.12
-16,4,7:17.12
-15,4,7:17.12
-14,4,7:17.12
-13,4,7:17.12
-12,4,7:17.12
-11,4,7:17.12
-17,5,7:17.12
-16,5,7:17.12
-15,5,7:17.12
-14,5,7:17.12
-13,5,7:17.12
-12,5,7:17.12
-11,5,7:17.12
-16,6,7:17.12
-15,6,7:17.12
-14,6,7:17.12
-13,6,7:17.12
-12,6,7:17.12
-11,6,7:17.12
-16,7,7:17.12
-15,7,7:17.12
-14,7,7:17.12
-13,7,7:17.12
-12,7,7:17.12
-11,7,7:17.12
-15,8,7:17.12
-14,8,7:17.12
-13,8,7:17.12
-12,8,7:17.12
-11,8,7:17.12
-14,9,7:17.12
-13,9,7:17.12
-12,9,7:17.12
-15,3,8:17.12
-14,3,8:17.12
-13,3,8:17.12
-12,3,8:17.12
-16,4,8:17.12
-15,4,8:17.12
-14,4,8:17.12
-13,4,8:17.12
-12,4,8:17.12
-11,4,8:17.12
-17,5,8:17.12
-16,5,8:17.12
-15,5,8:17.12
-14,5,8:17.12
-13,5,8:17.12
-12,5,8:17.12
-11,5,8:17.12
-16,6,8:17.12
-15,6,8:17.12
-14,6,8:17.12
-13,6,8:17.12
-12,6,8:17.12
-11,6,8:17.12
-10,6,8:17.12
-15,7,8:17.12
-14,7,8:17.12
-13,7,8:17.12
-12,7,8:17.12
-11,7,8:17.12
-15,8,8:17.12
-14,8,8:17.12
-13,8,8:17.12
-12,8,8:17.12
-11,8,8:17.12
-13,9,8:17.12
-12,9,8:17.12
-15,3,9:17.12
-14,3,9:17.12
-13,3,9:17.12
-12,3,9:17.12
-16,4,9:17.12
-15,4,9:17.12
-14,4,9:17.12
-13,4,9:17.12
-12,4,9:17.12
-11,4,9:17.12
-17,5,9:17.12
-16,5,9:17.12
-15,5,9:17.12
-14,5,9:17.12
-13,5,9:17.12
-12,5,9:17.12
-11,5,9:17.12
-10,5,9:17.12
-16,6,9:17.12
-15,6,9:17.12
-14,6,9:17.12
-13,6,9:17.12
-12,6,9:17.12
-11,6,9:17.12
-10,6,9:17.12
-15,7,9:17.12
-14,7,9:17.12
-13,7,9:17.12
-12,7,9:17.12
-11,7,9:17.12
-10,7,9:17.12
-14,8,9:17.12
-13,8,9:17.12
-12,8,9:17.12
-11,8,9:17.12
-13,9,9:17.12
-12,9,9:17.12
-15,3,10:17.12
-14,3,10:17.12
-13,3,10:17.12
-12,3,10:17.12
-16,4,10:17.12
-15,4,10:17.12
-14,4,10:17.12
-13,4,10:17.12
-12,4,10:17.12
-11,4,10:17.12
-10,4,10:17.12
-17,5,10:17.12
-16,5,10:17.12
-15,5,10:17.12
-14,5,10:17.12
-13,5,10:17.12
-12,5,10:17.12
-11,5,10:17.12
-10,5,10:17.12
-16,6,10:17.12
-15,6,10:17.12
-14,6,10:17.12
-13,6,10:17.12
-12,6,10:17.12
-11,6,10:17.12
-10,6,10:17.12
-15,7,10:17.12
-14,7,10:17.12
-13,7,10:17.12
-12,7,10:17.12
-11,7,10:17.12
-10,7,10:17.12
-15,8,10:17.12
-14,8,10:17.12
-13,8,10:17.12
-12,8,10:17.12
-11,8,10:17.12
-13,9,10:17.12
-12,9,10:17.12
-15,3,11:17.12
-14,3,11:17.12
-13,3,11:17.12
-12,3,11:17.12
-17,4,11:17.12
-16,4,11:17.12
-15,4,11:17.12
-14,4,11:17.12
-13,4,11:17.12
-12,4,11:17.12
-11,4,11:17.12
-16,5,11:17.12
-15,5,11:17.12
-14,5,11:17.12
-13,5,11:17.12
-12,5,11:17.12
-11,5,11:17.12
-10,5,11:17.12
-16,6,11:17.12
-15,6,11:17.12
-14,6,11:17.12
-13,6,11:17.12
-12,6,11:17.12
-11,6,11:17.12
-10,6,11:17.12
-9,6,11:17.12
-15,7,11:17.12
-14,7,11:17.12
-13,7,11:17.12
-12,7,11:17.12
-11,7,11:17.12
-10,7,11:17.12
-9,7,11:17.12
-15,8,11:17.12
-14,8,11:17.12
-13,8,11:17.12
-12,8,11:17.12
-11,8,11:17.12
-13,9,11:17.12
-12,9,11:17.12
-15,3,12:17.12
-14,3,12:17.12
-13,3,12:17.12
-12,3,12:17.12
-15,4,12:17.12
-14,4,12:17.12
-13,4,12:17.12
-12,4,12:17.12
-11,4,12:17.12
-16,5,12:17.12
-15,5,12:17.12
-14,5,12:17.12
-13,5,12:17.12
-12,5,12:17.12
-11,5,12:17.12
-10,5,12:17.12
-16,6,12:17.12
-15,6,12:17.12
-14,6,12:17.12
-13,6,12:17.12
-12,6,12:17.12
-11,6,12:17.12
-10,6,12:17.12
-9,6,12:17.12
-15,7,12:17.12
-14,7,12:17.12
-13,7,12:17.12
-12,7,12:17.12
-11,7,12:17.12
-10,7,12:17.12
-9,7,12:17.12
-14,8,12:17.12
-13,8,12:17.12
-12,8,12:17.12
-11,8,12:17.12
-10,8,12:17.12
-14,3,13:17.12
-13,3,13:17.12
-12,3,13:17.12
-15,4,13:17.12
-14,4,13:17.12
-13,4,13:17.12
-12,4,13:17.12
-11,4,13:17.12
-15,5,13:17.12
-14,5,13:17.12
-13,5,13:17.12
-12,5,13:17.12
-11,5,13:17.12
-10,5,13:17.12
-15,6,13:17.12
-14,6,13:17.12
-13,6,13:17.12
-12,6,13:17.12
-11,6,13:17.12
-10,6,13:17.12
-9,6,13:17.12
-15,7,13:17.12
-14,7,13:17.12
-13,7,13:17.12
-12,7,13:17.12
-11,7,13:17.12
-10,7,13:17.12
-9,7,13:17.12
-8,7,13:17.12
-13,8,13:17.12
-12,8,13:17.12
-11,8,13:17.12
-10,8,13:17.12
-9,8,13:17.12
-8,8,13:17.12
-7,8,13:17.12
-14,3,14:17.12
-13,3,14:17.12
-12,3,14:17.12
-11,3,14:17.12
-14,4,14:17.12
-13,4,14:17.12
-12,4,14:17.12
-11,4,14:17.12
-10,4,14:17.12
-15,5,14:17.12
-14,5,14:17.12
-13,5,14:17.12
-12,5,14:17.12
-11,5,14:17.12
-10,5,14:17.12
-15,6,14:17.12
-14,6,14:17.12
-13,6,14:17.12
-12,6,14:17.12
-11,6,14:17.12
-10,6,14:17.12
-9,6,14:17.12
-8,6,14:17.12
-7,6,14:17.12
-14,7,14:17.12
-13,7,14:17.12
-12,7,14:17.12
-11,7,14:17.12
-10,7,14:17.12
-9,7,14:17.12
-8,7,14:17.12
-7,7,14:17.12
-6,7,14:17.12
-11,8,14:17.12
-10,8,14:17.12
-9,8,14:17.12
-8,8,14:17.12
-7,8,14:17.12
-6,8,14:17.12
-12,2,15:17.12
-11,2,15:17.12
-14,3,15:17.12
-13,3,15:17.12
-12,3,15:17.12
-11,3,15:17.12
-10,3,15:17.12
-14,4,15:17.12
-13,4,15:17.12
-12,4,15:17.12
-11,4,15:17.12
-10,4,15:17.12
-15,5,15:17.12
-14,5,15:17.12
-13,5,15:17.12
-12,5,15:17.12
-11,5,15:17.12
-10,5,15:17.12
-8,5,15:17.12
-15,6,15:17.12
-14,6,15:17.12
-13,6,15:17.12
-12,6,15:17.12
-11,6,15:17.12
-10,6,15:17.12
-9,6,15:17.12
-8,6,15:17.12
-7,6,15:17.12
-6,6,15:17.12
-5,6,15:17.12
-14,7,15:17.12
-13,7,15:17.12
-12,7,15:17.12
-11,7,15:17.12
-10,7,15:17.12
-9,7,15:17.12
-8,7,15:17.12
-7,7,15:17.12
-6,7,15:17.12
-5,7,15:17.12
-4,7,15:17.12
-10,8,15:17.12
-9,8,15:17.12
-8,8,15:17.12
-7,8,15:17.12
-6,8,15:17.12
-5,8,15:17.12
-4,8,15:17.12
-3,8,15:17.12
-8,9,15:17.12
-3,9,15:17.12
-12,0,16:17.12
-11,1,16:17.12
-12,2,16:17.12
-11,2,16:17.12
-10,2,16:17.12
-14,3,16:17.12
-13,3,16:17.12
-12,3,16:17.12
-11,3,16:17.12
-10,3,16:17.12
-15,4,16:17.12
-14,4,16:17.12
-13,4,16:17.12
-12,4,16:17.12
-11,4,16:17.12
-10,4,16:17.12
-9,4,16:17.12
-15,5,16:17.12
-14,5,16:17.12
-13,5,16:17.12
-12,5,16:17.12
-11,5,16:17.12
-10,5,16:17.12
-9,5,16:17.12
-6,5,16:17.12
-14,6,16:17.12
-13,6,16:17.12
-12,6,16:17.12
-11,6,16:17.12
-10,6,16:17.12
-9,6,16:17.12
-8,6,16:17.12
-7,6,16:17.12
-6,6,16:17.12
-5,6,16:17.12
-3,6,16:17.12
-14,7,16:17.12
-13,7,16:17.12
-12,7,16:17.12
-11,7,16:17.12
-10,7,16:17.12
-9,7,16:17.12
-8,7,16:17.12
-7,7,16:17.12
-6,7,16:17.12
-5,7,16:17.12
-4,7,16:17.12
-3,7,16:17.12
-10,8,16:17.12
-9,8,16:17.12
-8,8,16:17.12
-7,8,16:17.12
-6,8,16:17.12
-5,8,16:17.12
-4,8,16:17.12
-3,8,16:17.12
-2,8,16:17.12
-6,9,16:17.12
-5,9,16:17.12
-4,9,16:17.12
-3,9,16:17.12
-2,9,16:17.12
-1,9,16:18.12
-3,10,16:17.12
-2,10,16:17.12
2,11,16:18.12
1,14,16:18.12
-12,0,17:17.12
-11,0,17:17.12
-12,1,17:17.12
-11,1,17:17.12
-13,2,17:17.12
-12,2,17:17.12
-11,2,17:17.12
-10,2,17:17.12
-9,2,17:17.12
-14,3,17:17.12
-13,3,17:17.12
-12,3,17:17.12
-11,3,17:17.12
-10,3,17:17.12
-9,3,17:17.12
-15,4,17:17.12
-14,4,17:17.12
-13,4,17:17.12
-12,4,17:17.12
-11,4,17:17.12
-10,4,17:17.12
-9,4,17:17.12
-15,5,17:17.12
-14,5,17:17.12
-13,5,17:17.12
-12,5,17:17.12
-11,5,17:17.12
-10,5,17:17.12
-9,5,17:17.12
-14,6,17:17.12
-13,6,17:17.12
-12,6,17:17.12
-11,6,17:17.12
-10,6,17:17.12
-9,6,17:17.12
-5,6,17:17.12
-13,7,17:17.12
-12,7,17:17.12
-11,7,17:17.12
-10,7,17:17.12
-9,7,17:17.12
-8,7,17:17.12
-7,7,17:17.12
-6,7,17:17.12
-5,7,17:17.12
-4,7,17:17.12
-3,7,17:17.12
-11,8,17:17.12
-10,8,17:17.12
-9,8,17:17.12
-7,8,17:17.12
-6,8,17:17.12
-5,8,17:17.12
-4,8,17:17.12
-3,8,17:17.12
-2,8,17:17.12
0,8,17:18.12
1,8,17:18.12
-4,9,17:17.12
-3,9,17:17.12
-2,9,17:17.12
-1,9,17:18.12
-3,10,17:17.12
-2,10,17:17.12
-1,10,17:17.12
1,11,17:18.12
2,11,17:18.12
-1,12,17:18.12
0,12,17:18.12
1,12,17:18.12
0,13,17:18.12
1,13,17:18.12
1,14,17:18.12
-12,0,18:17.12
-11,0,18:17.12
-8,0,18:17.12
-12,1,18:17.12
-11,1,18:17.12
-10,1,18:17.12
-9,1,18:17.12
-8,1,18:17.12
-12,2,18:17.12
-11,2,18:17.12
-10,2,18:17.12
-9,2,18:17.12
-8,2,18:17.12
1,2,18:18.12
-14,3,18:17.12
-13,3,18:17.12
-12,3,18:17.12
-11,3,18:17.12
-10,3,18:17.12
-9,3,18:17.12
4,3,18:18.12
-15,4,18:17.12
-14,4,18:17.12
-13,4,18:17.12
-12,4,18:17.12
-11,4,18:17.12
-10,4,18:17.12
-9,4,18:17.12
1,4,18:18.12
-15,5,18:17.12
-14,5,18:17.12
-13,5,18:17.12
-12,5,18:17.12
-11,5,18:17.12
-10,5,18:17.12
-9,5,18:17.12
0,5,18:18.12
1,5,18:18.12
-14,6,18:17.12
-13,6,18:17.12
-12,6,18:17.12
-11,6,18:17.12
-10,6,18:17.12
-9,6,18:17.12
-1,6,18:18.12
0,6,18:18.12
-14,7,18:17.12
-13,7,18:17.12
-12,7,18:17.12
-11,7,18:17.12
-10,7,18:17.12
-9,7,18:17.12
-2,7,18:18.12
-1,7,18:18.12
0,7,18:18.12
1,7,18:18.12
6,7,18:18.12
-11,8,18:17.12
-10,8,18:17.12
-9,8,18:17.12
-2,8,18:18.12
-1,8,18:18.12
0,8,18:18.12
1,8,18:18.12
-3,9,18:17.12
-2,9,18:17.12
-1,9,18:18.12
-3,10,18:17.12
-2,10,18:17.12
-1,10,18:17.12
0,10,18:18.12
1,10,18:17.12
-2,11,18:17.12
-1,11,18:17.12
0,11,18:18.12
1,11,18:18.12
2,11,18:18.12
-1,12,18:18.12
0,12,18:18.12
1,12,18:18.12
2,12,18:18.12
3,12,18:18.12
-1,13,18:18.12
0,13,18:18.12
1,13,18:18.12
2,13,18:18.12
1,14,18:18.12
-9,-1,19:17.12
-8,-1,19:17.12
-7,-1,19:17.12
-11,0,19:17.12
-10,0,19:17.12
-9,0,19:17.12
-8,0,19:17.12
-7,0,19:17.12
-12,1,19:17.12
-11,1,19:17.12
-10,1,19:17.12
-9,1,19:17.12
-8,1,19:17.12
-7,1,19:17.12
-13,2,19:17.12
-12,2,19:17.12
-11,2,19:17.12
-10,2,19:17.12
-9,2,19:17.12
-8,2,19:17.12
1,2,19:18.12
3,2,19:18.12
4,2,19:18.12
-14,3,19:17.12
-13,3,19:17.12
-12,3,19:17.12
-11,3,19:17.12
-10,3,19:17.12
-9,3,19:17.12
-8,3,19:17.12
0,3,19:18.12
2,3,19:18.12
3,3,19:18.12
4,3,19:18.12
-15,4,19:17.12
-14,4,19:17.12
-13,4,19:17.12
-12,4,19:17.12
-11,4,19:17.12
-10,4,19:17.12
-9,4,19:17.12
1,4,19:18.12
2,4,19:18.12
3,4,19:18.12
4,4,19:18.12
-15,5,19:17.12
-14,5,19:17.12
-13,5,19:17.12
-12,5,19:17.12
-11,5,19:17.12
-10,5,19:17.12
0,5,19:18.12
1,5,19:18.12
-15,6,19:17.12
-14,6,19:17.12
-13,6,19:17.12
-12,6,19:17.12
-11,6,19:17.12
-10,6,19:17.12
-4,6,19:18.12
0,6,19:18.12
5,6,19:18.12
-14,7,19:17.12
-13,7,19:17.12
-12,7,19:17.12
-11,7,19:17.12
-10,7,19:17.12
-4,7,19:18.12
-2,7,19:18.12
-1,7,19:18.12
0,7,19:18.12
1,7,19:18.12
5,7,19:18.12
6,7,19:18.12
-13,8,19:17.12
-12,8,19:17.12
-11,8,19:17.12
-10,8,19:17.12
-2,8,19:18.12
-1,8,19:18.12
0,8,19:18.12
1,8,19:18.12
2,8,19:18.12
3,8,19:18.12
5,8,19:18.12
-2,9,19:18.12
-1,9,19:18.12
0,9,19:18.12
1,9,19:18.12
2,9,19:18.12
3,9,19:18.12
4,9,19:18.12
-3,10,19:17.12
-2,10,19:17.12
-1,10,19:17.12
0,10,19:18.12
1,10,19:18.12
2,10,19:18.12
4,10,19:18.12
5,10,19:18.12
6,10,19:18.12
10,10,19:18.12
11,10,19:18.12
-2,11,19:17.12
-1,11,19:17.12
0,11,19:18.12
1,11,19:18.12
2,11,19:18.12
3,11,19:18.12
4,11,19:18.12
-1,12,19:18.12
0,12,19:18.12
1,12,19:18.12
2,12,19:18.12
-2,13,19:18.12
-1,13,19:18.12
0,13,19:17.12
1,13,19:18.12
-1,14,19:18.12
0,14,19:18.12
-8,-2,20:17.12
-7,-2,20:17.12
-6,-2,20:17.12
-9,-1,20:17.12
-8,-1,20:17.12
-7,-1,20:17.12
-6,-1,20:17.12
-10,0,20:17.12
-9,0,20:17.12
-8,0,20:17.12
-7,0,20:17.12
-6,0,20:17.12
-11,1,20:17.12
-10,1,20:17.12
-9,1,20:17.12
-8,1,20:17.12
-7,1,20:17.12
3,1,20:18.12
4,1,20:18.12
-13,2,20:17.12
-12,2,20:17.12
-11,2,20:17.12
-10,2,20:17.12
-9,2,20:17.12
-8,2,20:17.12
1,2,20:18.12
3,2,20:18.12
4,2,20:18.12
5,2,20:18.12
6,2,20:18.12
-14,3,20:17.12
-13,3,20:17.12
-12,3,20:17.12
-11,3,20:17.12
-10,3,20:17.12
-9,3,20:17.12
0,3,20:18.12
1,3,20:18.12
2,3,20:18.12
3,3,20:18.12
4,3,20:18.12
-15,4,20:17.12
-14,4,20:17.12
-13,4,20:17.12
-12,4,20:17.12
-11,4,20:17.12
-10,4,20:17.12
0,4,20:18.12
1,4,20:18.12
2,4,20:18.12
5,4,20:18.12
6,4,20:18.12
-15,5,20:17.12
-14,5,20:17.12
-13,5,20:17.12
-12,5,20:17.12
-11,5,20:17.12
-10,5,20:17.12
-4,5,20:18.12
-2,5,20:18.12
-1,5,20:18.12
0,5,20:18.12
1,5,20:18.12
3,5,20:18.12
-15,6,20:17.12
-14,6,20:17.12
-13,6,20:17.12
-12,6,20:17.12
-11,6,20:17.12
-4,6,20:18.12
-1,6,20:18.12
0,6,20:18.12
1,6,20:18.12
3,6,20:18.12
4,6,20:18.12
5,6,20:18.12
-15,7,20:17.12
-14,7,20:17.12
-13,7,20:17.12
-12,7,20:17.12
-11,7,20:17.12
-2,7,20:18.12
-1,7,20:18.12
0,7,20:18.12
3,7,20:18.12
4,7,20:18.12
5,7,20:18.12
9,7,20:18.12
-14,8,20:17.12
-13,8,20:17.12
-12,8,20:17.12
-11,8,20:17.12
-2,8,20:18.12
-1,8,20:18.12
0,8,20:18.12
2,8,20:18.12
3,8,20:18.12
5,8,20:18.12
6,8,20:18.12
7,8,20:18.12
9,8,20:18.12
11,8,20:18.12
-13,9,20:17.12
-12,9,20:17.12
-2,9,20:18.12
-1,9,20:18.12
0,9,20:18.12
1,9,20:18.12
2,9,20:18.12
3,9,20:18.12
4,9,20:18.12
9,9,20:18.12
10,9,20:18.12
11,9,20:18.12
12,9,20:18.12
13,9,20:18.12
-13,10,20:17.12
0,10,20:18.12
1,10,20:18.12
2,10,20:18.12
3,10,20:18.12
4,10,20:18.12
5,10,20:18.12
6,10,20:18.12
8,10,20:18.12
10,10,20:18.12
0,11,20:18.12
1,11,20:18.12
2,11,20:18.12
3,11,20:18.12
4,11,20:18.12
5,11,20:18.12
8,11,20:18.12
9,11,20:18.12
10,11,20:18.12
11,11,20:18.12
-1,12,20:17.12
1,12,20:18.12
2,12,20:18.12
4,12,20:18.12
5,12,20:18.12
6,12,20:18.12
9,12,20:18.12
11,12,20:18.12
1,13,20:18.12
2,13,20:18.12
9,13,20:18.12
-1,14,20:18.12
9,14,20:18.12
-1,15,20:18.12
-5,-4,21:17.12
-7,-3,21:17.12
-6,-3,21:17.12
-5,-3,21:17.12
-8,-2,21:17.12
-7,-2,21:17.12
-5,-2,21:17.12
-9,-1,21:17.12
-8,-1,21:17.12
-7,-1,21:17.12
-6,-1,21:17.12
-5,-1,21:17.12
-10,0,21:17.12
-9,0,21:17.12
-8,0,21:17.12
-7,0,21:17.12
-6,0,21:17.12
3,0,21:18.12
-10,1,21:17.12
-9,1,21:17.12
-8,1,21:17.12
2,1,21:18.12
4,1,21:18.12
-13,2,21:17.12
-12,2,21:17.12
-11,2,21:17.12
-10,2,21:17.12
-9,2,21:17.12
-3,2,21:18.12
0,2,21:18.12
2,2,21:18.12
3,2,21:18.12
4,2,21:18.12
-14,3,21:17.12
-13,3,21:17.12
-12,3,21:17.12
-11,3,21:17.12
-10,3,21:17.12
-4,3,21:18.12
-3,3,21:18.12
-2,3,21:18.12
-1,3,21:18.12
0,3,21:18.12
1,3,21:18.12
2,3,21:18.12
3,3,21:18.12
4,3,21:18.12
5,3,21:18.12
-15,4,21:17.12
-14,4,21:17.12
-13,4,21:17.12
-12,4,21:17.12
-11,4,21:17.12
-4,4,21:18.12
-1,4,21:18.12
1,4,21:18.12
2,4,21:18.12
3,4,21:18.12
4,4,21:18.12
5,4,21:18.12
-15,5,21:17.12
-14,5,21:17.12
-13,5,21:17.12
-12,5,21:17.12
-11,5,21:17.12
-2,5,21:18.12
-1,5,21:18.12
0,5,21:18.12
1,5,21:18.12
2,5,21:18.12
3,5,21:18.12
4,5,21:18.12
5,5,21:18.12
-16,6,21:17.12
-15,6,21:17.12
-14,6,21:17.12
-13,6,21:17.12
-12,6,21:17.12
-11,6,21:17.12
-4,6,21:18.12
-3,6,21:18.12
-2,6,21:18.12
-1,6,21:18.12
0,6,21:18.12
1,6,21:18.12
2,6,21:18.12
3,6,21:18.12
4,6,21:18.12
5,6,21:18.12
7,6,21:18.12
-15,7,21:17.12
-14,7,21:17.12
-13,7,21:17.12
-12,7,21:17.12
-11,7,21:17.12
-4,7,21:18.12
-3,7,21:18.12
-2,7,21:18.12
-1,7,21:18.12
0,7,21:18.12
1,7,21:18.12
2,7,21:18.12
3,7,21:18.12
4,7,21:18.12
5,7,21:18.12
6,7,21:18.12
7,7,21:18.12
-15,8,21:17.12
-14,8,21:17.12
-13,8,21:17.12
-12,8,21:17.12
-11,8,21:17.12
-2,8,21:18.12
-1,8,21:18.12
0,8,21:18.12
1,8,21:18.12
2,8,21:18.12
3,8,21:18.12
4,8,21:18.12
5,8,21:18.12
6,8,21:18.12
7,8,21:18.12
9,8,21:18.12
11,8,21:18.12
-15,9,21:17.12
-14,9,21:17.12
-13,9,21:17.12
-12,9,21:17.12
-2,9,21:18.12
-1,9,21:18.12
0,9,21:18.12
1,9,21:18.12
2,9,21:18.12
3,9,21:18.12
4,9,21:18.12
5,9,21:18.12
7,9,21:18.12
10,9,21:18.12
12,9,21:18.12
-14,10,21:17.12
-13,10,21:17.12
0,10,21:18.12
1,10,21:18.12
2,10,21:18.12
3,10,21:18.12
4,10,21:18.12
5,10,21:18.12
6,10,21:18.12
8,10,21:18.12
9,10,21:18.12
10,10,21:18.12
11,10,21:18.12
1,11,21:18.12
2,11,21:18.12
3,11,21:18.12
4,11,21:18.12
5,11,21:18.12
6,11,21:18.12
8,11,21:18.12
9,11,21:18.12
10,11,21:18.12
11,11,21:18.12
1,12,21:18.12
2,12,21:18.12
3,12,21:18.12
4,12,21:18.12
6,12,21:18.12
7,12,21:18.12
8,12,21:18.12
9,12,21:18.12
-1,13,21:18.12
0,13,21:18.12
1,13,21:18.12
2,13,21:18.12
3,13,21:18.12
4,13,21:18.12
5,13,21:18.12
0,14,21:18.12
1,14,21:18.12
3,14,21:18.12
4,14,21:18.12
5,14,21:18.12
6,14,21:18.12
9,14,21:18.12
3,15,21:18.12
4,15,21:18.12
5,15,21:18.12
3,16,21:18.12
2,18,21:18.12
3,18,21:18.12
4,18,21:18.12
3,20,21:18.12
5,-18,22:18.12
-2,-7,22:17.12
-3,-6,22:17.12
-6,-5,22:17.12
-5,-5,22:17.12
-4,-5,22:17.12
-7,-4,22:17.12
-6,-4,22:17.12
-5,-4,22:17.12
-4,-4,22:17.12
-7,-3,22:17.12
-6,-3,22:17.12
-5,-3,22:17.12
-4,-3,22:17.12
-8,-2,22:17.12
-7,-2,22:17.12
-6,-2,22:17.12
-5,-2,22:17.12
-4,-2,22:17.12
-8,-1,22:17.12
-7,-1,22:17.12
-6,-1,22:17.12
-5,-1,22:17.12
-8,0,22:17.12
-7,0,22:17.12
-6,0,22:17.12
3,0,22:18.12
2,1,22:18.12
3,1,22:18.12
4,1,22:18.12
5,1,22:18.12
6,1,22:18.12
-14,2,22:17.12
-13,2,22:17.12
-3,2,22:18.12
0,2,22:18.12
1,2,22:18.12
2,2,22:18.12
3,2,22:18.12
4,2,22:18.12
5,2,22:18.12
-15,3,22:17.12
-14,3,22:17.12
-13,3,22:17.12
-12,3,22:17.12
-11,3,22:17.12
-3,3,22:18.12
0,3,22:18.12
2,3,22:18.12
3,3,22:18.12
4,3,22:18.12
-16,4,22:17.12
-15,4,22:17.12
-14,4,22:17.12
-13,4,22:17.12
-12,4,22:17.12
-11,4,22:17.12
-3,4,22:18.12
-2,4,22:18.12
-1,4,22:18.12
3,4,22:18.12
4,4,22:18.12
-16,5,22:17.12
-15,5,22:17.12
-14,5,22:17.12
-13,5,22:17.12
-12,5,22:17.12
-11,5,22:17.12
-4,5,22:18.12
-3,5,22:18.12
-2,5,22:18.12
-1,5,22:18.12
0,5,22:18.12
1,5,22:18.12
2,5,22:18.12
3,5,22:18.12
4,5,22:18.12
-16,6,22:17.12
-15,6,22:17.12
-14,6,22:17.12
-13,6,22:17.12
-12,6,22:17.12
-11,6,22:17.12
-2,6,22:18.12
-1,6,22:18.12
1,6,22:18.12
2,6,22:18.12
3,6,22:18.12
4,6,22:18.12
5,6,22:18.12
6,6,22:18.12
-16,7,22:17.12
-15,7,22:17.12
-14,7,22:17.12
-13,7,22:17.12
-12,7,22:17.12
-11,7,22:17.12
-3,7,22:18.12
-2,7,22:18.12
-1,7,22:18.12
0,7,22:18.12
1,7,22:18.12
2,7,22:18.12
3,7,22:18.12
4,7,22:18.12
5,7,22:18.12
6,7,22:18.12
7,7,22:18.12
8,7,22:18.12
-16,8,22:17.12
-15,8,22:17.12
-14,8,22:17.12
-13,8,22:17.12
-12,8,22:17.12
-11,8,22:17.12
-2,8,22:18.12
-1,8,22:18.12
0,8,22:18.12
1,8,22:18.12
2,8,22:18.12
3,8,22:18.12
4,8,22:18.12
5,8,22:18.12
6,8,22:18.12
7,8,22:18.12
8,8,22:18.12
9,8,22:18.12
10,8,22:18.12
11,8,22:18.12
-15,9,22:17.12
-14,9,22:17.12
-13,9,22:17.12
-12,9,22:17.12
-1,9,22:18.12
0,9,22:18.12
1,9,22:18.12
2,9,22:18.12
3,9,22:18.12
4,9,22:18.12
6,9,22:18.12
7,9,22:18.12
8,9,22:18.12
9,9,22:18.12
-15,10,22:17.12
-14,10,22:17.12
-13,10,22:17.12
0,10,22:18.12
1,10,22:18.12
2,10,22:18.12
3,10,22:18.12
4,10,22:18.12
5,10,22:18.12
6,10,22:18.12
7,10,22:18.12
8,10,22:18.12
9,10,22:18.12
10,10,22:18.12
11,10,22:18.12
-14,11,22:17.12
0,11,22:18.12
1,11,22:18.12
2,11,22:18.12
3,11,22:18.12
4,11,22:18.12
5,11,22:18.12
6,11,22:18.12
7,11,22:18.12
8,11,22:18.12
9,11,22:18.12
10,11,22:18.12
11,11,22:18.12
1,12,22:18.12
2,12,22:18.12
3,12,22:18.12
4,12,22:18.12
6,12,22:18.12
7,12,22:18.12
8,12,22:18.12
0,13,22:18.12
1,13,22:18.12
2,13,22:18.12
3,13,22:18.12
7,13,22:18.12
8,13,22:18.12
9,13,22:18.12
2,14,22:18.12
3,14,22:18.12
4,14,22:18.12
1,15,22:18.12
2,15,22:18.12
3,15,22:18.12
4,15,22:18.12
1,16,22:18.12
2,16,22:18.12
3,16,22:18.12
4,16,22:18.12
1,17,22:18.12
2,17,22:18.12
3,17,22:18.12
1,18,22:18.12
2,18,22:18.12
3,18,22:18.12
4,18,22:18.12
2,19,22:18.12
3,19,22:18.12
5,19,22:18.12
2,20,22:18.12
3,20,22:18.12
4,20,22:18.12
5,20,22:18.12
2,21,22:18.12
3,21,22:18.12
4,21,22:18.12
5,21,22:18.12
6,21,22:18.12
1,22,22:18.12
2,22,22:18.12
-1,-19,23:18.12
4,-19,23:18.12
5,-19,23:18.12
2,-18,23:18.12
3,-18,23:18.12
4,-18,23:18.12
5,-18,23:18.12
2,-17,23:18.12
3,-17,23:18.12
5,-17,23:18.12
-3,-16,23:18.12
1,-16,23:18.12
0,-10,23:17.12
-5,-8,23:18.12
-3,-8,23:17.12
-2,-8,23:17.12
-1,-8,23:17.12
-5,-7,23:18.12
-4,-7,23:18.12
-3,-7,23:17.12
-2,-7,23:17.12
-5,-6,23:17.12
-4,-6,23:18.12
-3,-6,23:17.12
-2,-6,23:17.12
-1,-6,23:17.12
-6,-5,23:17.12
-5,-5,23:17.12
-4,-5,23:17.12
-3,-5,23:17.12
-2,-5,23:17.12
-7,-4,23:17.12
-6,-4,23:17.12
-5,-4,23:17.12
-4,-4,23:18.12
-3,-4,23:17.12
-8,-3,23:17.12
-7,-3,23:17.12
-6,-3,23:17.12
-5,-3,23:17.12
-4,-3,23:17.12
-7,-2,23:17.12
-6,-2,23:17.12
-5,-2,23:17.12
-7,-1,23:17.12
-6,-1,23:17.12
2,0,23:18.12
3,0,23:18.12
1,1,23:18.12
2,1,23:18.12
3,1,23:18.12
-14,2,23:17.12
-13,2,23:17.12
-12,2,23:17.12
1,2,23:18.12
2,2,23:18.12
3,2,23:18.12
-15,3,23:17.12
-14,3,23:17.12
-13,3,23:17.12
-12,3,23:17.12
-11,3,23:17.12
0,3,23:18.12
1,3,23:18.12
2,3,23:18.12
3,3,23:18.12
-16,4,23:17.12
-15,4,23:17.12
-14,4,23:17.12
-13,4,23:17.12
-12,4,23:17.12
-11,4,23:17.12
-10,4,23:17.12
-3,4,23:18.12
-2,4,23:18.12
0,4,23:18.12
2,4,23:18.12
3,4,23:18.12
4,4,23:18.12
5,4,23:18.12
-17,5,23:17.12
-16,5,23:17.12
-15,5,23:17.12
-14,5,23:17.12
-13,5,23:17.12
-12,5,23:17.12
-11,5,23:17.12
-10,5,23:17.12
0,5,23:18.12
1,5,23:18.12
2,5,23:18.12
3,5,23:18.12
4,5,23:18.12
5,5,23:18.12
6,5,23:18.12
-17,6,23:17.12
-16,6,23:17.12
-15,6,23:17.12
-14,6,23:17.12
-13,6,23:17.12
-12,6,23:17.12
-11,6,23:17.12
-10,6,23:17.12
-2,6,23:18.12
2,6,23:18.12
3,6,23:18.12
4,6,23:18.12
5,6,23:18.12
6,6,23:18.12
7,6,23:18.12
8,6,23:18.12
-17,7,23:17.12
-16,7,23:17.12
-15,7,23:17.12
-14,7,23:17.12
-13,7,23:17.12
-12,7,23:17.12
-11,7,23:17.12
-10,7,23:17.12
-3,7,23:18.12
-2,7,23:18.12
0,7,23:18.12
1,7,23:18.12
2,7,23:18.12
3,7,23:18.12
4,7,23:18.12
5,7,23:18.12
6,7,23:18.12
7,7,23:18.12
8,7,23:18.12
9,7,23:18.12
-16,8,23:17.12
-15,8,23:17.12
-14,8,23:17.12
-13,8,23:17.12
-12,8,23:17.12
-11,8,23:17.12
-3,8,23:18.12
-2,8,23:18.12
-1,8,23:18.12
0,8,23:18.12
1,8,23:18.12
2,8,23:18.12
3,8,23:18.12
4,8,23:18.12
5,8,23:18.12
6,8,23:18.12
7,8,23:18.12
8,8,23:18.12
9,8,23:18.12
10,8,23:18.12
11,8,23:18.12
-17,9,23:17.12
-16,9,23:17.12
-15,9,23:17.12
-14,9,23:17.12
-13,9,23:17.12
-12,9,23:17.12
-1,9,23:18.12
1,9,23:18.12
4,9,23:18.12
5,9,23:18.12
6,9,23:18.12
7,9,23:18.12
8,9,23:18.12
9,9,23:18.12
10,9,23:18.12
11,9,23:18.12
12,9,23:18.12
-17,10,23:17.12
-16,10,23:17.12
-15,10,23:17.12
-14,10,23:17.12
-13,10,23:17.12
-12,10,23:17.12
0,10,23:18.12
1,10,23:18.12
2,10,23:18.12
3,10,23:18.12
4,10,23:18.12
5,10,23:18.12
6,10,23:18.12
7,10,23:18.12
8,10,23:18.12
9,10,23:18.12
10,10,23:18.12
11,10,23:18.12
12,10,23:18.12
-16,11,23:17.12
-15,11,23:17.12
-14,11,23:17.12
-13,11,23:17.12
-12,11,23:17.12
-1,11,23:18.12
0,11,23:18.12
1,11,23:18.12
2,11,23:18.12
3,11,23:18.12
4,11,23:18.12
7,11,23:18.12
10,11,23:18.12
12,11,23:18.12
-14,12,23:17.12
-13,12,23:17.12
2,12,23:18.12
3,12,23:18.12
4,12,23:18.12
6,12,23:18.12
10,12,23:18.12
2,13,23:18.12
3,13,23:18.12
4,13,23:18.12
5,13,23:18.12
6,13,23:18.12
7,13,23:18.12
0,14,23:18.12
1,14,23:18.12
2,14,23:18.12
3,14,23:18.12
4,14,23:18.12
5,14,23:18.12
6,14,23:18.12
7,14,23:18.12
-2,15,23:18.12
-1,15,23:18.12
0,15,23:18.12
2,15,23:18.12
3,15,23:18.12
4,15,23:18.12
7,15,23:18.12
-1,16,23:18.12
2,16,23:18.12
3,16,23:18.12
3,17,23:18.12
2,18,23:18.12
3,18,23:18.12
4,18,23:18.12
2,19,23:18.12
5,19,23:18.12
2,20,23:18.12
4,20,23:18.12
1,21,23:18.12
4,21,23:18.12
1,22,23:18.12
2,22,23:18.12
2,-21,24:18.12
2,-20,24:18.12
3,-20,24:18.12
-1,-19,24:18.12
0,-19,24:18.12
5,-19,24:18.12
-3,-18,24:18.12
-2,-18,24:18.12
-1,-18,24:18.12
2,-18,24:18.12
3,-18,24:18.12
1,-17,24:18.12
2,-17,24:18.12
3,-17,24:18.12
4,-17,24:18.12
-3,-16,24:18.12
-2,-16,24:18.12
1,-16,24:18.12
2,-16,24:18.12
3,-16,24:18.12
2,-15,24:18.12
3,-15,24:18.12
-7,-14,24:18.12
-6,-14,24:18.12
-1,-14,24:18.12
4,-14,24:18.12
-7,-13,24:18.12
-6,-13,24:18.12
-8,-12,24:18.12
1,-12,24:18.12
-1,-11,24:17.12
0,-11,24:17.12
1,-11,24:17.12
-2,-10,24:17.12
-1,-10,24:17.12
0,-10,24:17.12
1,-10,24:17.12
-7,-9,24:18.12
-3,-9,24:17.12
-1,-9,24:17.12
0,-9,24:18.12
1,-9,24:18.12
-6,-8,24:18.12
-4,-8,24:18.12
-3,-8,24:17.12
-2,-8,24:17.12
-1,-8,24:18.12
0,-8,24:18.12
1,-8,24:18.12
-7,-7,24:18.12
-4,-7,24:18.12
-3,-7,24:18.12
-2,-7,24:18.12
-1,-7,24:17.12
0,-7,24:17.12
1,-7,24:18.12
-5,-6,24:17.12
-4,-6,24:18.12
-3,-6,24:18.12
-2,-6,24:17.12
-1,-6,24:17.12
-6,-5,24:17.12
-5,-5,24:17.12
-4,-5,24:18.12
-3,-5,24:17.12
-2,-5,24:17.12
-7,-4,24:17.12
-6,-4,24:17.12
-5,-4,24:18.12
-4,-4,24:18.12
-3,-4,24:17.12
-6,-3,24:17.12
-5,-3,24:17.12
-4,-3,24:17.12
-6,-2,24:17.12
-15,2,24:17.12
-14,2,24:17.12
-13,2,24:17.12
-12,2,24:17.12
2,2,24:18.12
3,2,24:18.12
-16,3,24:17.12
-15,3,24:17.12
-14,3,24:17.12
-13,3,24:17.12
-12,3,24:17.12
-11,3,24:17.12
-10,3,24:17.12
0,3,24:18.12
1,3,24:18.12
2,3,24:18.12
3,3,24:18.12
4,3,24:18.12
5,3,24:18.12
-17,4,24:17.12
-16,4,24:17.12
-15,4,24:17.12
-14,4,24:17.12
-13,4,24:17.12
-12,4,24:17.12
-11,4,24:17.12
-10,4,24:17.12
-9,4,24:17.12
1,4,24:18.12
2,4,24:18.12
3,4,24:18.12
-17,5,24:17.12
-16,5,24:17.12
-15,5,24:17.12
-14,5,24:17.12
-13,5,24:17.12
-12,5,24:17.12
-11,5,24:17.12
-10,5,24:17.12
-9,5,24:17.12
2,5,24:18.12
3,5,24:18.12
4,5,24:18.12
5,5,24:18.12
-18,6,24:17.12
-17,6,24:17.12
-16,6,24:17.12
-15,6,24:17.12
-14,6,24:17.12
-13,6,24:17.12
-12,6,24:17.12
-11,6,24:17.12
-10,6,24:17.12
-9,6,24:17.12
1,6,24:18.12
2,6,24:18.12
3,6,24:18.12
4,6,24:18.12
5,6,24:18.12
6,6,24:18.12
7,6,24:18.12
-18,7,24:17.12
-17,7,24:17.12
-16,7,24:17.12
-15,7,24:17.12
-14,7,24:17.12
-13,7,24:17.12
-12,7,24:17.12
-11,7,24:17.12
-10,7,24:17.12
-9,7,24:17.12
2,7,24:18.12
3,7,24:18.12
4,7,24:18.12
5,7,24:18.12
6,7,24:18.12
7,7,24:18.12
-18,8,24:17.12
-17,8,24:17.12
-16,8,24:17.12
-15,8,24:17.12
-14,8,24:17.12
-13,8,24:17.12
-12,8,24:17.12
-11,8,24:17.12
-10,8,24:17.12
-3,8,24:18.12
-2,8,24:18.12
2,8,24:18.12
3,8,24:18.12
4,8,24:18.12
5,8,24:18.12
6,8,24:18.12
11,8,24:18.12
-17,9,24:17.12
-16,9,24:17.12
-15,9,24:17.12
-14,9,24:17.12
-13,9,24:17.12
-12,9,24:17.12
-11,9,24:17.12
4,9,24:18.12
5,9,24:18.12
7,9,24:18.12
8,9,24:18.12
9,9,24:18.12
12,9,24:18.12
13,9,24:18.12
-18,10,24:17.12
-17,10,24:17.12
-16,10,24:17.12
-15,10,24:17.12
-14,10,24:17.12
-13,10,24:17.12
-12,10,24:17.12
-11,10,24:17.12
2,10,24:18.12
10,10,24:18.12
12,10,24:18.12
-17,11,24:17.12
-16,11,24:17.12
-15,11,24:17.12
-14,11,24:17.12
-13,11,24:17.12
-12,11,24:17.12
-11,11,24:17.12
2,11,24:18.12
4,11,24:18.12
-16,12,24:17.12
-14,12,24:17.12
-13,12,24:17.12
-12,12,24:17.12
-10,12,24:17.12
2,12,24:18.12
5,12,24:18.12
6,12,24:18.12
-14,13,24:17.12
-13,13,24:17.12
-12,13,24:17.12
-11,13,24:17.12
-9,13,24:17.12
3,13,24:18.12
4,13,24:18.12
5,13,24:18.12
6,13,24:18.12
-8,14,24:17.12
-6,14,24:17.12
-4,14,24:17.12
3,14,24:18.12
4,14,24:18.12
5,14,24:18.12
6,14,24:18.12
7,14,24:18.12
-1,15,24:18.12
0,15,24:18.12
2,15,24:18.12
5,15,24:18.12
7,15,24:18.12
-4,16,24:17.12
0,16,24:18.12
1,16,24:18.12
2,16,24:18.12
3,16,24:18.12
1,17,24:18.12
3,17,24:18.12
4,17,24:18.12
-1,18,24:18.12
0,18,24:18.12
1,18,24:18.12
2,18,24:18.12
3,18,24:18.12
4,18,24:18.12
5,18,24:18.12
6,18,24:18.12
0,19,24:18.12
1,19,24:18.12
2,19,24:18.12
3,19,24:18.12
4,19,24:18.12
2,20,24:18.12
3,20,24:18.12
2,21,24:18.12
3,21,24:18.12
1,22,24:18.12
2,22,24:18.12
2,23,24:18.12
0,-21,25:18.12
2,-21,25:18.12
2,-20,25:18.12
3,-20,25:18.12
-2,-19,25:18.12
-1,-19,25:18.12
0,-19,25:18.12
3,-19,25:18.12
-1,-18,25:18.12
1,-18,25:18.12
2,-18,25:18.12
3,-18,25:18.12
4,-18,25:18.12
-4,-17,25:18.12
-3,-17,25:18.12
-1,-17,25:18.12
0,-17,25:18.12
1,-17,25:18.12
2,-17,25:18.12
3,-17,25:18.12
4,-17,25:18.12
5,-17,25:18.12
-3,-16,25:18.12
0,-16,25:18.12
1,-16,25:18.12
2,-16,25:18.12
3,-16,25:18.12
4,-16,25:18.12
-9,-15,25:18.12
-8,-15,25:18.12
-7,-15,25:18.12
-6,-15,25:18.12
-3,-15,25:18.12
-2,-15,25:18.12
-1,-15,25:18.12
0,-15,25:18.12
1,-15,25:18.12
2,-15,25:18.12
3,-15,25:18.12
4,-15,25:18.12
6,-15,25:18.12
-9,-14,25:18.12
-6,-14,25:18.12
-5,-14,25:18.12
-4,-14,25:18.12
-3,-14,25:18.12
-1,-14,25:18.12
1,-14,25:18.12
2,-14,25:18.12
3,-14,25:18.12
4,-14,25:18.12
-11,-13,25:18.12
-9,-13,25:18.12
-7,-13,25:18.12
-6,-13,25:18.12
-5,-13,25:18.12
-4,-13,25:18.12
-3,-13,25:18.12
-1,-13,25:18.12
0,-13,25:18.12
1,-13,25:18.12
2,-13,25:18.12
4,-13,25:18.12
5,-13,25:18.12
-9,-12,25:18.12
-8,-12,25:18.12
-7,-12,25:18.12
-6,-12,25:18.12
-5,-12,25:18.12
1,-12,25:18.12
2,-12,25:18.12
-8,-11,25:18.12
-6,-11,25:18.12
-5,-11,25:18.12
-4,-11,25:18.12
-1,-11,25:17.12
0,-11,25:18.12
1,-11,25:18.12
-5,-10,25:18.12
-2,-10,25:18.12
-1,-10,25:18.12
0,-10,25:18.12
1,-10,25:18.12
2,-10,25:17.12
-7,-9,25:18.12
-5,-9,25:18.12
-3,-9,25:18.12
-2,-9,25:17.12
-1,-9,25:18.12
0,-9,25:18.12
1,-9,25:18.12
2,-9,25:18.12
-7,-8,25:18.12
-6,-8,25:18.12
-5,-8,25:18.12
-4,-8,25:18.12
-3,-8,25:18.12
-2,-8,25:18.12
-1,-8,25:18.12
0,-8,25:17.12
1,-8,25:18.12
-8,-7,25:18.12
-7,-7,25:18.12
-5,-7,25:18.12
-4,-7,25:18.12
-3,-7,25:17.12
-2,-7,25:18.12
1,-7,25:18.12
2,-7,25:18.12
-5,-6,25:18.12
-4,-6,25:18.12
-3,-6,25:18.12
-2,-6,25:17.12
-5,-5,25:18.12
-4,-5,25:18.12
-3,-5,25:18.12
-2,-5,25:18.12
-5,-4,25:18.12
-4,-4,25:18.12
-3,-4,25:17.12
-15,1,25:17.12
-14,1,25:17.12
-13,1,25:17.12
-16,2,25:17.12
-15,2,25:17.12
-14,2,25:17.12
-13,2,25:17.12
-12,2,25:17.12
-10,2,25:17.12
-9,2,25:17.12
-8,2,25:17.12
-16,3,25:17.12
-15,3,25:17.12
-14,3,25:17.12
-13,3,25:17.12
-12,3,25:17.12
-11,3,25:17.12
-10,3,25:17.12
-9,3,25:17.12
3,3,25:18.12
4,3,25:18.12
-17,4,25:17.12
-16,4,25:17.12
-15,4,25:17.12
-14,4,25:17.12
-13,4,25:17.12
-12,4,25:17.12
-11,4,25:17.12
-10,4,25:17.12
-9,4,25:17.12
2,4,25:18.12
3,4,25:18.12
6,4,25:18.12
-18,5,25:17.12
-17,5,25:17.12
-16,5,25:17.12
-15,5,25:17.12
-14,5,25:17.12
-13,5,25:17.12
-12,5,25:17.12
-11,5,25:17.12
-10,5,25:17.12
-9,5,25:17.12
3,5,25:18.12
4,5,25:18.12
6,5,25:18.12
-18,6,25:17.12
-17,6,25:17.12
-16,6,25:17.12
-15,6,25:17.12
-14,6,25:17.12
-13,6,25:17.12
-12,6,25:17.12
-11,6,25:17.12
-10,6,25:17.12
-9,6,25:17.12
-8,6,25:17.12
-1,6,25:18.12
2,6,25:18.12
3,6,25:18.12
4,6,25:18.12
5,6,25:18.12
6,6,25:18.12
-19,7,25:17.12
-18,7,25:17.12
-17,7,25:17.12
-16,7,25:17.12
-15,7,25:17.12
-14,7,25:17.12
-13,7,25:17.12
-12,7,25:17.12
-11,7,25:17.12
-10,7,25:17.12
-9,7,25:17.12
-8,7,25:17.12
-1,7,25:18.12
0,7,25:18.12
1,7,25:18.12
2,7,25:18.12
3,7,25:18.12
4,7,25:18.12
5,7,25:18.12
6,7,25:18.12
7,7,25:18.12
-19,8,25:17.12
-18,8,25:17.12
-17,8,25:17.12
-16,8,25:17.12
-15,8,25:17.12
-14,8,25:17.12
-13,8,25:17.12
-12,8,25:17.12
-11,8,25:17.12
-10,8,25:17.12
-9,8,25:17.12
-1,8,25:18.12
1,8,25:18.12
2,8,25:18.12
4,8,25:18.12
6,8,25:18.12
-17,9,25:17.12
-16,9,25:17.12
-15,9,25:17.12
-13,9,25:17.12
-12,9,25:17.12
-11,9,25:17.12
-10,9,25:17.12
10,9,25:18.12
-17,10,25:17.12
-16,10,25:17.12
-15,10,25:17.12
-14,10,25:17.12
-13,10,25:17.12
-12,10,25:17.12
-11,10,25:17.12
-10,10,25:17.12
10,10,25:18.12
-17,11,25:17.12
-16,11,25:17.12
-15,11,25:17.12
-14,11,25:17.12
-13,11,25:17.12
-12,11,25:17.12
-11,11,25:17.12
-10,11,25:17.12
-9,11,25:17.12
-15,12,25:17.12
-14,12,25:17.12
-13,12,25:17.12
-12,12,25:17.12
-11,12,25:17.12
-10,12,25:17.12
-9,12,25:17.12
-8,12,25:17.12
-15,13,25:17.12
-14,13,25:17.12
-13,13,25:17.12
-12,13,25:17.12
-11,13,25:17.12
-10,13,25:17.12
-9,13,25:17.12
-8,13,25:17.12
-7,13,25:17.12
-6,13,25:17.12
-5,13,25:17.12
-4,13,25:17.12
-3,13,25:17.12
2,13,25:18.12
3,13,25:18.12
4,13,25:18.12
5,13,25:18.12
-13,14,25:17.12
-12,14,25:17.12
-11,14,25:17.12
-10,14,25:17.12
-9,14,25:17.12
-8,14,25:17.12
-7,14,25:17.12
-6,14,25:17.12
-5,14,25:17.12
-4,14,25:17.12
2,14,25:18.12
3,14,25:18.12
4,14,25:18.12
5,14,25:18.12
6,14,25:18.12
-9,15,25:17.12
-8,15,25:17.12
-7,15,25:17.12
-4,15,25:17.12
-3,15,25:17.12
1,15,25:18.12
2,15,25:18.12
6,15,25:18.12
7,15,25:18.12
-5,16,25:17.12
-4,16,25:17.12
-3,16,25:17.12
1,16,25:17.12
3,16,25:18.12
6,16,25:18.12
-5,17,25:17.12
-4,17,25:17.12
-3,17,25:17.12
-2,17,25:17.12
0,17,25:18.12
1,17,25:18.12
3,17,25:18.12
4,17,25:18.12
0,18,25:18.12
1,18,25:18.12
3,18,25:18.12
4,18,25:18.12
5,18,25:18.12
6,18,25:18.12
1,19,25:18.12
3,19,25:18.12
5,19,25:18.12
3,20,25:18.12
4,20,25:18.12
3,21,25:18.12
4,21,25:18.12
1,22,25:18.12
2,22,25:18.12
2,-22,26:18.12
3,-22,26:18.12
0,-21,26:18.12
1,-21,26:18.12
2,-21,26:18.12
2,-20,26:18.12
-1,-19,26:18.12
0,-19,26:18.12
1,-19,26:18.12
2,-19,26:18.12
-2,-18,26:18.12
-1,-18,26:18.12
0,-18,26:18.12
1,-18,26:18.12
2,-18,26:18.12
4,-18,26:18.12
-6,-17,26:18.12
-4,-17,26:18.12
-3,-17,26:18.12
-2,-17,26:18.12
-1,-17,26:18.12
0,-17,26:18.12
1,-17,26:18.12
2,-17,26:18.12
3,-17,26:18.12
4,-17,26:18.12
5,-17,26:18.12
6,-17,26:18.12
7,-17,26:18.12
-8,-16,26:18.12
-6,-16,26:18.12
-3,-16,26:18.12
-2,-16,26:18.12
-1,-16,26:18.12
0,-16,26:18.12
1,-16,26:18.12
2,-16,26:18.12
5,-16,26:18.12
6,-16,26:18.12
7,-16,26:18.12
-9,-15,26:18.12
-8,-15,26:18.12
-7,-15,26:18.12
-6,-15,26:18.12
-2,-15,26:18.12
-1,-15,26:18.12
0,-15,26:18.12
1,-15,26:18.12
2,-15,26:18.12
3,-15,26:18.12
4,-15,26:18.12
5,-15,26:18.12
6,-15,26:18.12
-10,-14,26:18.12
-9,-14,26:18.12
-8,-14,26:18.12
-7,-14,26:18.12
-6,-14,26:18.12
-2,-14,26:18.12
-1,-14,26:18.12
0,-14,26:18.12
1,-14,26:18.12
2,-14,26:18.12
3,-14,26:18.12
-11,-13,26:18.12
-10,-13,26:18.12
-9,-13,26:18.12
-8,-13,26:18.12
-7,-13,26:18.12
-6,-13,26:18.12
-5,-13,26:18.12
-4,-13,26:18.12
-3,-13,26:18.12
0,-13,26:18.12
1,-13,26:18.12
2,-13,26:18.12
-9,-12,26:18.12
-8,-12,26:18.12
-7,-12,26:18.12
-6,-12,26:18.12
-5,-12,26:18.12
-4,-12,26:18.12
-2,-12,26:18.12
0,-12,26:18.12
1,-12,26:18.12
3,-12,26:18.12
4,-12,26:18.12
5,-12,26:18.12
-8,-11,26:18.12
-7,-11,26:18.12
-5,-11,26:18.12
-3,-11,26:18.12
-2,-11,26:18.12
-1,-11,26:18.12
0,-11,26:18.12
1,-11,26:18.12
2,-11,26:18.12
-7,-10,26:18.12
-6,-10,26:18.12
-5,-10,26:18.12
-4,-10,26:18.12
-3,-10,26:18.12
-2,-10,26:18.12
-1,-10,26:18.12
0,-10,26:18.12
1,-10,26:18.12
2,-10,26:18.12
-6,-9,26:18.12
-5,-9,26:18.12
-4,-9,26:18.12
-3,-9,26:18.12
-2,-9,26:18.12
-1,-9,26:18.12
0,-9,26:18.12
1,-9,26:18.12
2,-9,26:18.12
-8,-8,26:18.12
-7,-8,26:18.12
-6,-8,26:18.12
-5,-8,26:18.12
-4,-8,26:18.12
-3,-8,26:18.12
-2,-8,26:18.12
-1,-8,26:18.12
0,-8,26:18.12
2,-8,26:18.12
-8,-7,26:18.12
-7,-7,26:18.12
-6,-7,26:18.12
-5,-7,26:18.12
-4,-7,26:18.12
-3,-7,26:18.12
-2,-7,26:18.12
-1,-7,26:18.12
0,-7,26:18.12
-8,-6,26:18.12
-7,-6,26:18.12
-6,-6,26:18.12
-5,-6,26:18.12
-4,-6,26:18.12
-3,-6,26:18.12
-2,-6,26:18.12
-1,-6,26:18.12
-7,-5,26:18.12
-5,-5,26:18.12
-4,-5,26:18.12
-3,-5,26:18.12
-7,-4,26:18.12
-7,-3,26:18.12
-14,0,26:17.12
-13,0,26:17.12
-12,0,26:17.12
-14,1,26:17.12
-13,1,26:17.12
-12,1,26:17.12
-9,1,26:17.12
-17,2,26:17.12
-16,2,26:17.12
-15,2,26:17.12
-14,2,26:17.12
-13,2,26:17.12
-12,2,26:17.12
-10,2,26:17.12
-9,2,26:17.12
-8,2,26:17.12
-17,3,26:17.12
-16,3,26:17.12
-15,3,26:17.12
-14,3,26:17.12
-13,3,26:17.12
-11,3,26:17.12
-10,3,26:17.12
-9,3,26:17.12
-8,3,26:17.12
-17,4,26:17.12
-16,4,26:17.12
-15,4,26:17.12
-14,4,26:17.12
-13,4,26:17.12
-11,4,26:17.12
-10,4,26:17.12
-9,4,26:17.12
-8,4,26:17.12
6,4,26:18.12
-18,5,26:17.12
-17,5,26:17.12
-16,5,26:17.12
-15,5,26:17.12
-14,5,26:17.12
-13,5,26:17.12
-11,5,26:17.12
-10,5,26:17.12
-9,5,26:17.12
-8,5,26:17.12
-19,6,26:17.12
-18,6,26:17.12
-17,6,26:17.12
-16,6,26:17.12
-15,6,26:17.12
-14,6,26:17.12
-13,6,26:17.12
-12,6,26:17.12
-11,6,26:17.12
-10,6,26:17.12
-9,6,26:17.12
-8,6,26:17.12
5,6,26:18.12
6,6,26:18.12
-20,7,26:17.12
-19,7,26:17.12
-18,7,26:17.12
-17,7,26:17.12
-16,7,26:17.12
-15,7,26:17.12
-14,7,26:17.12
-13,7,26:17.12
-12,7,26:17.12
-11,7,26:17.12
-10,7,26:17.12
-9,7,26:17.12
-8,7,26:17.12
-7,7,26:17.12
0,7,26:18.12
1,7,26:18.12
3,7,26:18.12
5,7,26:18.12
6,7,26:18.12
-22,8,26:17.12
-20,8,26:17.12
-19,8,26:17.12
-18,8,26:17.12
-17,8,26:17.12
-16,8,26:17.12
-14,8,26:17.12
-13,8,26:17.12
-12,8,26:17.12
-10,8,26:17.12
-9,8,26:17.12
-8,8,26:17.12
2,8,26:18.12
3,8,26:18.12
4,8,26:18.12
5,8,26:18.12
6,8,26:18.12
-20,9,26:17.12
-19,9,26:17.12
-18,9,26:17.12
-13,9,26:17.12
-12,9,26:17.12
-11,9,26:17.12
-9,9,26:17.12
2,9,26:18.12
5,9,26:18.12
6,9,26:18.12
-16,10,26:17.12
-13,10,26:17.12
-12,10,26:17.12
-11,10,26:17.12
-10,10,26:17.12
-14,11,26:17.12
-13,11,26:17.12
-12,11,26:17.12
-11,11,26:17.12
-10,11,26:17.12
-9,11,26:17.12
-20,12,26:17.12
-15,12,26:17.12
-14,12,26:17.12
-13,12,26:17.12
-12,12,26:17.12
-11,12,26:17.12
-10,12,26:17.12
-9,12,26:17.12
-8,12,26:17.12
-6,12,26:17.12
-4,12,26:17.12
-16,13,26:17.12
-15,13,26:17.12
-14,13,26:17.12
-11,13,26:17.12
-9,13,26:17.12
-8,13,26:17.12
-7,13,26:17.12
-6,13,26:17.12
-5,13,26:17.12
-4,13,26:17.12
2,13,26:18.12
4,13,26:18.12
-15,14,26:17.12
-14,14,26:17.12
-11,14,26:17.12
-6,14,26:17.12
-5,14,26:17.12
-4,14,26:17.12
-2,14,26:17.12
6,14,26:18.12
-15,15,26:17.12
-14,15,26:17.12
-12,15,26:17.12
-11,15,26:17.12
-9,15,26:17.12
-8,15,26:17.12
-7,15,26:17.12
-6,15,26:17.12
-5,15,26:17.12
-4,15,26:17.12
0,15,26:17.12
1,15,26:17.12
2,15,26:18.12
3,15,26:18.12
-8,16,26:17.12
-6,16,26:17.12
-5,16,26:17.12
-4,16,26:17.12
-3,16,26:17.12
-2,16,26:17.12
-1,16,26:17.12
0,16,26:17.12
2,16,26:17.12
-4,17,26:17.12
-3,17,26:17.12
-2,17,26:17.12
-1,17,26:17.12
0,17,26:17.12
1,17,26:17.12
-3,18,26:17.12
-2,18,26:17.12
-1,18,26:17.12
0,18,26:17.12
3,20,26:18.12
2,-22,27:18.12
0,-20,27:18.12
0,-19,27:18.12
1,-19,27:18.12
2,-19,27:18.12
3,-19,27:18.12
4,-19,27:18.12
-8,-18,27:18.12
-7,-18,27:18.12
-6,-18,27:18.12
-5,-18,27:18.12
-3,-18,27:18.12
-2,-18,27:18.12
0,-18,27:18.12
1,-18,27:18.12
2,-18,27:18.12
3,-18,27:18.12
4,-18,27:18.12
-9,-17,27:18.12
-8,-17,27:18.12
-7,-17,27:18.12
-6,-17,27:18.12
-5,-17,27:18.12
-4,-17,27:18.12
-3,-17,27:18.12
-2,-17,27:18.12
-1,-17,27:18.12
0,-17,27:18.12
1,-17,27:18.12
2,-17,27:18.12
3,-17,27:18.12
4,-17,27:18.12
5,-17,27:18.12
-9,-16,27:18.12
-8,-16,27:18.12
-7,-16,27:18.12
-3,-16,27:18.12
-2,-16,27:18.12
-1,-16,27:18.12
0,-16,27:18.12
1,-16,27:18.12
2,-16,27:18.12
3,-16,27:18.12
5,-16,27:18.12
6,-16,27:18.12
-8,-15,27:18.12
-7,-15,27:18.12
-6,-15,27:18.12
-3,-15,27:18.12
-2,-15,27:18.12
-1,-15,27:18.12
0,-15,27:18.12
1,-15,27:18.12
2,-15,27:18.12
3,-15,27:18.12
5,-15,27:18.12
6,-15,27:18.12
-9,-14,27:18.12
-7,-14,27:18.12
-6,-14,27:18.12
-4,-14,27:18.12
-3,-14,27:18.12
-2,-14,27:18.12
-1,-14,27:18.12
0,-14,27:18.12
1,-14,27:18.12
2,-14,27:18.12
3,-14,27:18.12
4,-14,27:18.12
5,-14,27:18.12
6,-14,27:18.12
-9,-13,27:18.12
-8,-13,27:18.12
-7,-13,27:18.12
-6,-13,27:18.12
-5,-13,27:18.12
-4,-13,27:18.12
-3,-13,27:18.12
-2,-13,27:18.12
-1,-13,27:18.12
0,-13,27:18.12
1,-13,27:18.12
2,-13,27:18.12
3,-13,27:18.12
4,-13,27:18.12
5,-13,27:18.12
-9,-12,27:18.12
-8,-12,27:18.12
-7,-12,27:18.12
-6,-12,27:18.12
-5,-12,27:18.12
-4,-12,27:18.12
-3,-12,27:18.12
-2,-12,27:18.12
-1,-12,27:18.12
0,-12,27:18.12
1,-12,27:18.12
2,-12,27:18.12
3,-12,27:18.12
4,-12,27:18.12
-8,-11,27:18.12
-7,-11,27:18.12
-6,-11,27:18.12
-5,-11,27:18.12
-4,-11,27:18.12
-3,-11,27:18.12
-1,-11,27:18.12
0,-11,27:18.12
4,-11,27:18.12
-7,-10,27:18.12
-5,-10,27:18.12
-4,-10,27:18.12
-1,-10,27:18.12
0,-10,27:18.12
1,-10,27:18.12
2,-10,27:18.12
4,-10,27:18.12
-5,-9,27:18.12
-3,-9,27:18.12
-2,-9,27:18.12
-1,-9,27:18.12
1,-9,27:18.12
2,-9,27:18.12
-7,-8,27:18.12
-6,-8,27:18.12
-5,-8,27:18.12
-3,-8,27:18.12
-2,-8,27:18.12
1,-8,27:18.12
2,-8,27:18.12
-5,-7,27:18.12
-4,-7,27:18.12
-3,-7,27:18.12
-2,-7,27:18.12
-1,-7,27:18.12
-6,-6,27:18.12
-5,-6,27:18.12
-3,-6,27:18.12
-2,-6,27:18.12
-1,-6,27:18.12
0,-6,27:18.12
-4,-5,27:18.12
-12,-2,27:17.12
-15,-1,27:17.12
-14,-1,27:17.12
-14,0,27:17.12
-13,0,27:17.12
-12,0,27:17.12
1,0,27:17.12
-17,1,27:17.12
-16,1,27:17.12
-13,1,27:17.12
-12,1,27:17.12
-11,1,27:17.12
-8,1,27:17.12
-18,2,27:17.12
-17,2,27:17.12
-16,2,27:17.12
-15,2,27:17.12
-14,2,27:17.12
-13,2,27:17.12
-12,2,27:17.12
-10,2,27:17.12
-9,2,27:17.12
-8,2,27:17.12
-7,2,27:17.12
-18,3,27:17.12
-17,3,27:17.12
-16,3,27:17.12
-15,3,27:17.12
-14,3,27:17.12
-13,3,27:17.12
-10,3,27:17.12
-9,3,27:17.12
-8,3,27:17.12
-7,3,27:17.12
-18,4,27:17.12
-17,4,27:17.12
-16,4,27:17.12
-15,4,27:17.12
-14,4,27:17.12
-13,4,27:17.12
-12,4,27:17.12
-10,4,27:17.12
-9,4,27:17.12
-8,4,27:17.12
-7,4,27:17.12
-18,5,27:17.12
-17,5,27:17.12
-16,5,27:17.12
-15,5,27:17.12
-14,5,27:17.12
-13,5,27:17.12
-10,5,27:17.12
-9,5,27:17.12
-8,5,27:17.12
-7,5,27:17.12
-19,6,27:17.12
-18,6,27:17.12
-17,6,27:17.12
-16,6,27:17.12
-15,6,27:17.12
-14,6,27:17.12
-13,6,27:17.12
-10,6,27:17.12
-9,6,27:17.12
-8,6,27:17.12
-7,6,27:17.12
6,6,27:18.12
-22,7,27:17.12
-20,7,27:17.12
-19,7,27:17.12
-18,7,27:17.12
-17,7,27:17.12
-16,7,27:17.12
-15,7,27:17.12
-14,7,27:17.12
-13,7,27:17.12
-10,7,27:17.12
-9,7,27:17.12
-8,7,27:17.12
-7,7,27:17.12
-6,7,27:17.12
4,7,27:18.12
5,7,27:18.12
6,7,27:18.12
7,7,27:18.12
8,7,27:18.12
-23,8,27:17.12
-20,8,27:17.12
-19,8,27:17.12
-18,8,27:17.12
-17,8,27:17.12
-9,8,27:17.12
-8,8,27:17.12
-7,8,27:17.12
-6,8,27:17.12
2,8,27:18.12
3,8,27:18.12
4,8,27:18.12
5,8,27:18.12
-23,9,27:17.12
-22,9,27:17.12
-21,9,27:17.12
-20,9,27:17.12
-19,9,27:17.12
-18,9,27:17.12
-8,9,27:17.12
-7,9,27:17.12
-6,9,27:17.12
5,9,27:18.12
-20,10,27:17.12
-12,10,27:17.12
-21,11,27:17.12
-20,11,27:17.12
-13,11,27:17.12
-12,11,27:17.12
-11,11,27:17.12
-10,11,27:17.12
-9,11,27:17.12
-20,12,27:17.12
-19,12,27:17.12
-15,12,27:17.12
-14,12,27:17.12
-13,12,27:17.12
-12,12,27:17.12
-11,12,27:17.12
-10,12,27:17.12
-9,12,27:17.12
-8,12,27:17.12
-21,13,27:17.12
-20,13,27:17.12
-19,13,27:17.12
-15,13,27:17.12
-14,13,27:17.12
-13,13,27:17.12
-12,13,27:17.12
-11,13,27:17.12
-10,13,27:17.12
-9,13,27:17.12
-8,13,27:17.12
-7,13,27:17.12
-4,13,27:17.12
-16,14,27:17.12
-15,14,27:17.12
-14,14,27:17.12
-13,14,27:17.12
-11,14,27:17.12
-9,14,27:17.12
-7,14,27:17.12
-5,14,27:17.12
1,14,27:17.12
6,14,27:18.12
-15,15,27:17.12
-14,15,27:17.12
-13,15,27:17.12
-12,15,27:17.12
-11,15,27:17.12
-7,15,27:17.12
-6,15,27:17.12
-5,15,27:17.12
-4,15,27:17.12
-3,15,27:17.12
0,15,27:17.12
-13,16,27:17.12
-12,16,27:17.12
-4,16,27:17.12
-3,16,27:17.12
-1,16,27:17.12
0,16,27:17.12
1,16,27:17.12
2,16,27:17.12
3,16,27:17.12
-3,17,27:17.12
-2,17,27:17.12
-1,17,27:17.12
0,17,27:17.12
1,17,27:17.12
2,17,27:17.12
0,18,27:17.12
2,-21,28:18.12
3,-21,28:18.12
-6,-20,28:18.12
2,-20,28:18.12
3,-20,28:18.12
-7,-19,28:18.12
-6,-19,28:18.12
1,-19,28:18.12
2,-19,28:18.12
3,-19,28:18.12
-7,-18,28:18.12
-5,-18,28:18.12
-2,-18,28:18.12
1,-18,28:18.12
2,-18,28:18.12
3,-18,28:18.12
4,-18,28:18.12
-7,-17,28:18.12
-6,-17,28:18.12
-5,-17,28:18.12
-1,-17,28:18.12
0,-17,28:18.12
1,-17,28:18.12
2,-17,28:18.12
3,-17,28:18.12
4,-17,28:18.12
-7,-16,28:18.12
-2,-16,28:18.12
-1,-16,28:18.12
0,-16,28:18.12
1,-16,28:18.12
2,-16,28:18.12
3,-16,28:18.12
-8,-15,28:18.12
-7,-15,28:18.12
-2,-15,28:18.12
-1,-15,28:18.12
0,-15,28:18.12
1,-15,28:18.12
2,-15,28:18.12
3,-15,28:18.12
4,-15,28:18.12
5,-15,28:18.12
6,-15,28:18.12
-7,-14,28:18.12
-6,-14,28:18.12
-4,-14,28:18.12
-3,-14,28:18.12
-2,-14,28:18.12
-1,-14,28:18.12
1,-14,28:18.12
3,-14,28:18.12
4,-14,28:18.12
-9,-13,28:18.12
-8,-13,28:18.12
-7,-13,28:18.12
-6,-13,28:18.12
-5,-13,28:18.12
-4,-13,28:18.12
-2,-13,28:18.12
-1,-13,28:18.12
0,-13,28:18.12
1,-13,28:18.12
2,-13,28:18.12
-8,-12,28:18.12
-6,-12,28:18.12
-5,-12,28:18.12
-2,-12,28:18.12
-1,-12,28:18.12
0,-12,28:18.12
1,-12,28:18.12
-8,-11,28:18.12
-7,-11,28:18.12
-5,-11,28:18.12
-4,-11,28:18.12
0,-11,28:18.12
1,-11,28:18.12
-6,-10,28:18.12
-5,-10,28:18.12
-4,-10,28:18.12
-3,-10,28:18.12
-1,-10,28:18.12
1,-10,28:18.12
-5,-9,28:18.12
-3,-9,28:18.12
-1,-9,28:18.12
2,-9,28:18.12
3,-9,28:18.12
-6,-8,28:18.12
-5,-8,28:18.12
-5,-7,28:18.12
-4,-7,28:18.12
-3,-7,28:18.12
-2,-7,28:18.12
-5,-6,28:18.12
-3,-6,28:18.12
-2,-6,28:18.12
-3,-5,28:18.12
-2,-5,28:18.12
-15,-3,28:17.12
-15,-2,28:17.12
-11,-2,28:17.12
-15,-1,28:17.12
-14,-1,28:17.12
-11,-1,28:17.12
-1,-1,28:17.12
0,-1,28:17.12
1,-1,28:17.12
-15,0,28:17.12
-14,0,28:17.12
-13,0,28:17.12
-12,0,28:17.12
-2,0,28:17.12
-1,0,28:17.12
-18,1,28:17.12
-17,1,28:17.12
-16,1,28:17.12
-15,1,28:17.12
-14,1,28:17.12
-13,1,28:17.12
-12,1,28:17.12
-7,1,28:17.12
-6,1,28:17.12
-4,1,28:17.12
-3,1,28:17.12
-2,1,28:17.12
-18,2,28:17.12
-17,2,28:17.12
-16,2,28:17.12
-15,2,28:17.12
-14,2,28:17.12
-13,2,28:17.12
-12,2,28:17.12
-9,2,28:17.12
-8,2,28:17.12
-7,2,28:17.12
-6,2,28:17.12
-5,2,28:17.12
-4,2,28:17.12
-3,2,28:17.12
-18,3,28:17.12
-17,3,28:17.12
-16,3,28:17.12
-15,3,28:17.12
-14,3,28:17.12
-13,3,28:17.12
-9,3,28:17.12
-8,3,28:17.12
-7,3,28:17.12
-6,3,28:17.12
-18,4,28:17.12
-17,4,28:17.12
-16,4,28:17.12
-15,4,28:17.12
-14,4,28:17.12
-13,4,28:17.12
-8,4,28:17.12
-7,4,28:17.12
-38,5,28:18.12
-18,5,28:17.12
-17,5,28:17.12
-16,5,28:17.12
-15,5,28:17.12
-14,5,28:17.12
-13,5,28:17.12
-8,5,28:17.12
-22,6,28:17.12
-20,6,28:17.12
-17,6,28:17.12
-16,6,28:17.12
-15,6,28:17.12
-14,6,28:17.12
-13,6,28:17.12
-8,6,28:17.12
-7,6,28:17.12
6,6,28:18.12
-24,7,28:17.12
-23,7,28:17.12
-22,7,28:17.12
-21,7,28:17.12
-20,7,28:17.12
-19,7,28:17.12
-18,7,28:17.12
-9,7,28:17.12
-8,7,28:17.12
-7,7,28:17.12
-6,7,28:17.12
5,7,28:18.12
7,7,28:18.12
-24,8,28:17.12
-23,8,28:17.12
-22,8,28:17.12
-21,8,28:17.12
-20,8,28:17.12
-18,8,28:17.12
-9,8,28:17.12
-8,8,28:17.12
-7,8,28:17.12
-6,8,28:17.12
-5,8,28:17.12
-3,8,28:17.12
2,8,28:18.12
5,8,28:18.12
-24,9,28:17.12
-21,9,28:17.12
-20,9,28:17.12
-19,9,28:17.12
-18,9,28:17.12
-8,9,28:17.12
-7,9,28:17.12
-6,9,28:17.12
-5,9,28:17.12
-20,10,28:17.12
-19,10,28:17.12
-18,10,28:17.12
-7,10,28:17.12
-20,11,28:17.12
-20,12,28:17.12
-19,12,28:17.12
-18,12,28:17.12
-12,12,28:17.12
-10,12,28:17.12
-19,13,28:17.12
-15,13,28:17.12
-14,13,28:17.12
-13,13,28:17.12
-12,13,28:17.12
-11,13,28:17.12
-9,13,28:17.12
-21,14,28:17.12
-20,14,28:17.12
-19,14,28:17.12
-15,14,28:17.12
-14,14,28:17.12
-13,14,28:17.12
-12,14,28:17.12
-11,14,28:17.12
-6,14,28:17.12
-4,14,28:17.12
-16,15,28:17.12
-15,15,28:17.12
-14,15,28:17.12
-13,15,28:17.12
-12,15,28:17.12
-11,15,28:17.12
0,15,28:17.12
1,15,28:17.12
-13,16,28:17.12
-4,16,28:17.12
1,16,28:17.12
2,16,28:17.12
-15,17,28:17.12
-14,17,28:17.12
0,17,28:17.12
1,17,28:17.12
2,17,28:17.12
1,-20,29:18.12
2,-20,29:18.12
-6,-19,29:18.12
1,-19,29:18.12
-8,-18,29:18.12
-7,-18,29:18.12
-6,-18,29:18.12
-5,-18,29:18.12
1,-18,29:18.12
2,-18,29:18.12
4,-18,29:18.12
-7,-17,29:18.12
-6,-17,29:18.12
-5,-17,29:18.12
-1,-17,29:18.12
0,-17,29:18.12
2,-17,29:18.12
-1,-16,29:18.12
0,-16,29:18.12
1,-16,29:18.12
-7,-15,29:18.12
-6,-15,29:18.12
1,-15,29:18.12
-7,-14,29:18.12
-6,-14,29:18.12
-5,-14,29:18.12
-4,-14,29:18.12
1,-14,29:18.12
3,-14,29:18.12
-7,-13,29:18.12
-5,-13,29:18.12
-4,-13,29:18.12
-3,-13,29:18.12
-2,-13,29:18.12
3,-13,29:18.12
-8,-12,29:18.12
-6,-12,29:18.12
-5,-12,29:18.12
-2,-12,29:18.12
-1,-12,29:18.12
-6,-11,29:18.12
-5,-11,29:18.12
0,-11,29:18.12
-5,-10,29:18.12
-1,-10,29:18.12
0,-10,29:18.12
-5,-9,29:18.12
-4,-7,29:18.12
-2,-7,29:18.12
-9,-6,29:17.12
-8,-6,29:17.12
-4,-6,29:18.12
-3,-6,29:18.12
-2,-6,29:18.12
-12,-5,29:17.12
-11,-5,29:17.12
-9,-5,29:17.12
-13,-4,29:17.12
-12,-4,29:17.12
-11,-4,29:17.12
-9,-4,29:17.12
-14,-3,29:17.12
-13,-3,29:17.12
-12,-3,29:17.12
-11,-3,29:17.12
1,-3,29:17.12
2,-3,29:17.12
3,-3,29:17.12
-16,-2,29:17.12
-14,-2,29:17.12
-13,-2,29:17.12
-12,-2,29:17.12
-11,-2,29:17.12
-10,-2,29:17.12
-1,-2,29:17.12
0,-2,29:17.12
1,-2,29:17.12
2,-2,29:17.12
3,-2,29:17.12
4,-2,29:17.12
5,-2,29:17.12
-15,-1,29:17.12
-13,-1,29:17.12
-12,-1,29:17.12
-11,-1,29:17.12
-2,-1,29:17.12
0,-1,29:17.12
1,-1,29:17.12
2,-1,29:17.12
3,-1,29:17.12
4,-1,29:17.12
5,-1,29:17.12
-18,0,29:17.12
-17,0,29:17.12
-16,0,29:17.12
-15,0,29:17.12
-13,0,29:17.12
-12,0,29:17.12
-3,0,29:17.12
-2,0,29:17.12
-1,0,29:17.12
-19,1,29:17.12
-18,1,29:17.12
-16,1,29:17.12
-15,1,29:17.12
-14,1,29:17.12
-13,1,29:17.12
-7,1,29:17.12
-6,1,29:17.12
-5,1,29:17.12
-4,1,29:17.12
-3,1,29:17.12
-2,1,29:17.12
-29,2,29:18.12
-19,2,29:17.12
-18,2,29:17.12
-17,2,29:17.12
-16,2,29:17.12
-15,2,29:17.12
-14,2,29:17.12
-8,2,29:17.12
-7,2,29:17.12
-6,2,29:17.12
-5,2,29:17.12
-4,2,29:17.12
-3,2,29:17.12
-2,2,29:17.12
-18,3,29:17.12
-17,3,29:17.12
-16,3,29:17.12
-15,3,29:17.12
-14,3,29:17.12
-13,3,29:17.12
-8,3,29:17.12
-7,3,29:17.12
-6,3,29:17.12
-5,3,29:17.12
-4,3,29:17.12
-38,4,29:18.12
-30,4,29:18.12
-29,4,29:18.12
-17,4,29:17.12
-16,4,29:17.12
-15,4,29:17.12
-14,4,29:17.12
-13,4,29:17.12
-8,4,29:17.12
-38,5,29:18.12
-18,5,29:17.12
-17,5,29:17.12
-16,5,29:17.12
-15,5,29:17.12
-14,5,29:17.12
-13,5,29:17.12
-40,6,29:18.12
-31,6,29:18.12
-17,6,29:18.12
-16,6,29:17.12
-15,6,29:17.12
-14,6,29:17.12
-6,6,29:17.12
-25,7,29:17.12
-21,7,29:17.12
-19,7,29:17.12
-17,7,29:18.12
-8,7,29:17.12
-7,7,29:17.12
-6,7,29:17.12
-5,7,29:17.12
-2,7,29:17.12
-39,8,29:18.12
-25,8,29:17.12
-23,8,29:17.12
-22,8,29:17.12
-21,8,29:17.12
-17,8,29:18.12
-8,8,29:17.12
-7,8,29:17.12
-6,8,29:17.12
-5,8,29:17.12
-4,8,29:17.12
-3,8,29:17.12
-2,8,29:17.12
-30,9,29:18.12
-23,9,29:17.12
-8,9,29:17.12
-7,9,29:17.12
-6,9,29:17.12
-5,9,29:17.12
-4,9,29:17.12
-3,9,29:17.12
-2,9,29:17.12
-6,10,29:17.12
-20,12,29:17.12
-19,12,29:17.12
-21,13,29:17.12
-20,13,29:17.12
-19,13,29:17.12
-18,13,29:17.12
-21,14,29:17.12
-20,14,29:17.12
-15,14,29:17.12
-14,14,29:17.12
-13,14,29:17.12
-12,14,29:17.12
-21,15,29:17.12
-20,15,29:17.12
-15,15,29:17.12
-14,15,29:17.12
-13,15,29:17.12
-21,16,29:18.12
-16,16,29:17.12
-15,16,29:17.12
-14,16,29:17.12
-13,16,29:17.12
-12,16,29:17.12
1,16,29:17.12
-23,17,29:18.12
-22,17,29:18.12
-15,17,29:17.12
-14,17,29:17.12
-15,18,29:17.12
-14,18,29:17.12
-13,18,29:17.12
-12,18,29:17.12
-7,23,29:18.12
-7,-19,30:18.12
-7,-18,30:18.12
-5,-18,30:18.12
-8,-17,30:18.12
-7,-17,30:18.12
-1,-17,30:18.12
0,-17,30:18.12
-1,-16,30:18.12
0,-16,30:18.12
-5,-15,30:18.12
-5,-14,30:18.12
-5,-13,30:18.12
-6,-12,30:18.12
-6,-11,30:18.12
-11,-9,30:17.12
-12,-7,30:17.12
-8,-7,30:17.12
-13,-6,30:17.12
-12,-6,30:17.12
-11,-6,30:17.12
-10,-6,30:17.12
-8,-6,30:17.12
-7,-6,30:18.12
-6,-6,30:18.12
-5,-6,30:18.12
-4,-6,30:18.12
0,-6,30:17.12
-13,-5,30:17.12
-12,-5,30:17.12
-11,-5,30:17.12
-10,-5,30:17.12
-9,-5,30:17.12
-8,-5,30:17.12
-7,-5,30:17.12
-6,-5,30:17.12
-5,-5,30:17.12
-13,-4,30:17.12
-12,-4,30:17.12
-11,-4,30:17.12
-10,-4,30:17.12
-7,-4,30:17.12
-6,-4,30:17.12
-27,-3,30:18.12
-26,-3,30:18.12
-14,-3,30:17.12
-13,-3,30:17.12
-12,-3,30:17.12
-11,-3,30:17.12
-10,-3,30:17.12
5,-3,30:17.12
8,-3,30:17.12
-15,-2,30:17.12
-14,-2,30:17.12
-13,-2,30:17.12
-12,-2,30:17.12
-11,-2,30:17.12
1,-2,30:17.12
2,-2,30:17.12
3,-2,30:17.12
4,-2,30:17.12
5,-2,30:17.12
6,-2,30:17.12
7,-2,30:17.12
-15,-1,30:17.12
-14,-1,30:17.12
-13,-1,30:17.12
-12,-1,30:17.12
-11,-1,30:17.12
-1,-1,30:17.12
0,-1,30:17.12
1,-1,30:17.12
2,-1,30:17.12
3,-1,30:17.12
5,-1,30:17.12
6,-1,30:17.12
7,-1,30:17.12
-19,0,30:17.12
-18,0,30:17.12
-17,0,30:17.12
-16,0,30:17.12
-15,0,30:17.12
-14,0,30:17.12
-13,0,30:17.12
-12,0,30:17.12
-29,1,30:18.12
-19,1,30:17.12
-18,1,30:17.12
-17,1,30:17.12
-16,1,30:17.12
-15,1,30:17.12
-14,1,30:17.12
-13,1,30:17.12
-7,1,30:17.12
-6,1,30:17.12
-5,1,30:17.12
-4,1,30:17.12
-3,1,30:17.12
-29,2,30:18.12
-19,2,30:17.12
-18,2,30:17.12
-17,2,30:17.12
-16,2,30:17.12
-15,2,30:17.12
-14,2,30:17.12
-7,2,30:17.12
-6,2,30:17.12
-5,2,30:17.12
-4,2,30:17.12
-31,3,30:18.12
-30,3,30:18.12
-29,3,30:18.12
-18,3,30:17.12
-17,3,30:17.12
-16,3,30:17.12
-15,3,30:17.12
-14,3,30:17.12
-6,3,30:17.12
-37,4,30:18.12
-36,4,30:18.12
-30,4,30:18.12
-29,4,30:18.12
-17,4,30:17.12
-16,4,30:17.12
-15,4,30:17.12
-14,4,30:17.12
-38,5,30:18.12
-37,5,30:18.12
-36,5,30:18.12
-18,5,30:17.12
-17,5,30:17.12
-16,5,30:17.12
-15,5,30:17.12
-14,5,30:17.12
-40,6,30:18.12
-39,6,30:18.12
-38,6,30:18.12
-37,6,30:18.12
-31,6,30:18.12
-24,6,30:17.12
-15,6,30:18.12
-11,6,30:18.12
-5,6,30:17.12
-3,6,30:17.12
-40,7,30:18.12
-38,7,30:18.12
-31,7,30:18.12
-26,7,30:17.12
-25,7,30:17.12
-24,7,30:17.12
-18,7,30:18.12
-17,7,30:18.12
-16,7,30:18.12
-15,7,30:18.12
-7,7,30:17.12
-6,7,30:17.12
-5,7,30:17.12
-4,7,30:17.12
-3,7,30:17.12
-39,8,30:18.12
-37,8,30:18.12
-26,8,30:17.12
-25,8,30:17.12
-24,8,30:17.12
-23,8,30:17.12
-17,8,30:18.12
-16,8,30:18.12
-13,8,30:18.12
-7,8,30:17.12
-6,8,30:17.12
-5,8,30:17.12
-4,8,30:17.12
-3,8,30:17.12
-2,8,30:17.12
-1,8,30:17.12
-39,9,30:18.12
-34,9,30:18.12
-30,9,30:18.12
-29,9,30:18.12
-15,9,30:18.12
-7,9,30:17.12
-6,9,30:17.12
-5,9,30:17.12
-4,9,30:17.12
-3,9,30:17.12
-2,9,30:17.12
-1,9,30:17.12
-35,10,30:18.12
-17,10,30:18.12
-15,10,30:18.12
-14,10,30:18.12
-3,10,30:17.12
-2,10,30:17.12
-1,10,30:17.12
-36,11,30:18.12
-22,13,30:18.12
-21,13,30:17.12
-20,13,30:17.12
-19,13,30:17.12
-22,14,30:17.12
-21,14,30:17.12
-20,14,30:17.12
-22,15,30:17.12
-21,15,30:17.12
-20,15,30:17.12
-15,15,30:17.12
-14,15,30:17.12
-13,15,30:17.12
-22,16,30:18.12
-21,16,30:18.12
-20,16,30:18.12
-15,16,30:17.12
-14,16,30:17.12
-13,16,30:17.12
-22,17,30:18.12
-16,17,30:17.12
-15,17,30:17.12
-14,17,30:17.12
-13,17,30:17.12
-11,17,30:17.12
-24,18,30:18.12
-23,18,30:18.12
-22,18,30:18.12
-15,18,30:17.12
-14,18,30:17.12
-13,18,30:17.12
-12,18,30:17.12
-11,18,30:17.12
-9,18,30:17.12
-14,19,30:17.12
-11,19,30:17.12
-15,20,30:17.12
-14,20,30:17.12
-12,20,30:17.12
-6,22,30:18.12
-7,23,30:18.12
-6,23,30:18.12
-5,23,30:18.12
-5,24,30:18.12
-5,25,30:18.12
-5,26,30:18.12
-7,-19,31:18.12
-7,-18,31:18.12
0,-17,31:18.12
-12,-10,31:17.12
-10,-10,31:17.12
-12,-9,31:17.12
-11,-9,31:17.12
-10,-9,31:17.12
-6,-9,31:18.12
-12,-8,31:17.12
-11,-8,31:17.12
-10,-8,31:17.12
-6,-8,31:18.12
-5,-8,31:18.12
-13,-7,31:17.12
-12,-7,31:17.12
-11,-7,31:17.12
-10,-7,31:17.12
-9,-7,31:17.12
-8,-7,31:17.12
-7,-7,31:17.12
-6,-7,31:17.12
-4,-7,31:17.12
-1,-7,31:17.12
0,-7,31:17.12
1,-7,31:17.12
-13,-6,31:17.12
-12,-6,31:17.12
-11,-6,31:17.12
-10,-6,31:17.12
-9,-6,31:17.12
-8,-6,31:17.12
-7,-6,31:17.12
-6,-6,31:18.12
-5,-6,31:17.12
-4,-6,31:17.12
-2,-6,31:17.12
-1,-6,31:17.12
1,-6,31:17.12
-13,-5,31:17.12
-12,-5,31:17.12
-11,-5,31:17.12
-10,-5,31:17.12
-9,-5,31:17.12
-8,-5,31:17.12
-7,-5,31:18.12
-6,-5,31:18.12
-5,-5,31:17.12
-4,-5,31:17.12
-3,-5,31:17.12
-2,-5,31:17.12
-1,-5,31:17.12
0,-5,31:17.12
15,-5,31:17.12
-29,-4,31:18.12
-13,-4,31:17.12
-12,-4,31:17.12
-11,-4,31:17.12
-10,-4,31:17.12
-9,-4,31:17.12
-8,-4,31:17.12
-6,-4,31:17.12
-5,-4,31:17.12
-4,-4,31:17.12
7,-4,31:17.12
8,-4,31:17.12
11,-4,31:18.12
12,-4,31:18.12
13,-4,31:18.12
-27,-3,31:18.12
-26,-3,31:18.12
-13,-3,31:17.12
-12,-3,31:17.12
-11,-3,31:17.12
-5,-3,31:17.12
6,-3,31:17.12
7,-3,31:17.12
8,-3,31:17.12
9,-3,31:17.12
10,-3,31:17.12
11,-3,31:17.12
14,-3,31:18.12
15,-3,31:18.12
-26,-2,31:18.12
-14,-2,31:17.12
-13,-2,31:17.12
-12,-2,31:17.12
-11,-2,31:17.12
5,-2,31:17.12
6,-2,31:17.12
-19,-1,31:17.12
-18,-1,31:17.12
-17,-1,31:17.12
-13,-1,31:17.12
7,-1,31:17.12
8,-1,31:17.12
-20,0,31:17.12
-19,0,31:17.12
-18,0,31:17.12
-17,0,31:17.12
-16,0,31:17.12
-15,0,31:17.12
-14,0,31:17.12
-13,0,31:17.12
-12,0,31:17.12
-20,1,31:17.12
-18,1,31:17.12
-17,1,31:17.12
-16,1,31:17.12
-15,1,31:17.12
-14,1,31:17.12
-13,1,31:17.12
-12,1,31:17.12
-19,2,31:17.12
-18,2,31:17.12
-17,2,31:17.12
-16,2,31:17.12
-15,2,31:17.12
-14,2,31:17.12
-13,2,31:17.12
-12,2,31:17.12
-10,2,31:17.12
-6,2,31:17.12
-4,2,31:17.12
-32,3,31:18.12
-31,3,31:18.12
-19,3,31:17.12
-18,3,31:17.12
-17,3,31:17.12
-16,3,31:17.12
-15,3,31:17.12
-14,3,31:17.12
-39,4,31:18.12
-32,4,31:18.12
-31,4,31:18.12
-30,4,31:18.12
-19,4,31:17.12
-17,4,31:17.12
-16,4,31:17.12
-15,4,31:17.12
-14,4,31:17.12
-38,5,31:18.12
-37,5,31:18.12
-34,5,31:18.12
-31,5,31:18.12
-30,5,31:18.12
-29,5,31:18.12
-28,5,31:18.12
-17,5,31:18.12
-16,5,31:17.12
-15,5,31:18.12
-14,5,31:18.12
-42,6,31:18.12
-41,6,31:18.12
-40,6,31:18.12
-39,6,31:18.12
-38,6,31:18.12
-37,6,31:18.12
-34,6,31:18.12
-32,6,31:18.12
-31,6,31:18.12
-30,6,31:18.12
-29,6,31:18.12
-28,6,31:18.12
-25,6,31:17.12
-17,6,31:18.12
-16,6,31:18.12
-15,6,31:18.12
-14,6,31:18.12
-12,6,31:18.12
-11,6,31:18.12
-41,7,31:18.12
-40,7,31:18.12
-38,7,31:18.12
-37,7,31:18.12
-36,7,31:18.12
-35,7,31:18.12
-34,7,31:18.12
-32,7,31:18.12
-31,7,31:18.12
-30,7,31:18.12
-29,7,31:18.12
-26,7,31:17.12
-25,7,31:17.12
-24,7,31:17.12
-19,7,31:18.12
-18,7,31:18.12
-17,7,31:18.12
-16,7,31:18.12
-15,7,31:18.12
-12,7,31:18.12
-6,7,31:17.12
-5,7,31:17.12
-4,7,31:17.12
-3,7,31:17.12
-2,7,31:17.12
-39,8,31:18.12
-38,8,31:18.12
-37,8,31:18.12
-35,8,31:18.12
-32,8,31:18.12
-31,8,31:18.12
-30,8,31:18.12
-29,8,31:18.12
-26,8,31:17.12
-25,8,31:17.12
-23,8,31:17.12
-17,8,31:18.12
-16,8,31:18.12
-15,8,31:18.12
-13,8,31:18.12
-6,8,31:17.12
-5,8,31:17.12
-4,8,31:17.12
-3,8,31:17.12
-2,8,31:17.12
-1,8,31:17.12
0,8,31:17.12
-38,9,31:18.12
-37,9,31:18.12
-35,9,31:18.12
-34,9,31:18.12
-33,9,31:18.12
-32,9,31:18.12
-31,9,31:18.12
-30,9,31:18.12
-29,9,31:18.12
-26,9,31:17.12
-18,9,31:18.12
-17,9,31:18.12
-16,9,31:18.12
-15,9,31:18.12
-13,9,31:18.12
-12,9,31:18.12
-6,9,31:17.12
-5,9,31:17.12
-4,9,31:17.12
-3,9,31:17.12
-2,9,31:17.12
-1,9,31:17.12
0,9,31:17.12
-37,10,31:18.12
-36,10,31:18.12
-35,10,31:18.12
-34,10,31:18.12
-32,10,31:18.12
-31,10,31:18.12
-30,10,31:18.12
-19,10,31:18.12
-18,10,31:18.12
-17,10,31:18.12
-16,10,31:18.12
-13,10,31:18.12
-3,10,31:17.12
-2,10,31:17.12
-1,10,31:17.12
0,10,31:17.12
1,10,31:17.12
-36,11,31:18.12
-35,11,31:18.12
-28,11,31:18.12
-20,11,31:18.12
-13,11,31:18.12
-2,11,31:17.12
-35,12,31:18.12
-34,12,31:18.12
-33,12,31:18.12
-32,12,31:18.12
-31,12,31:18.12
-28,12,31:18.12
-27,12,31:18.12
-26,12,31:18.12
-7,12,31:18.12
