[META]
version=2.0
spawnOnBlockType=2
spawnSunlight=True
spawnDarkness=True
spawnWater=False
spawnLava=False
underFill=False
randomRotation=True
dig=True
tree=False
branch=False
needsFoundation=True
rarity=100
collisionPercentage=20
spawnElevationMin=0
spawnElevationMax=200
spawnInBiome=Custom
[DATA]
0,-7,-10:17.12
1,-7,-10:17.12
2,-7,-10:17.12
-1,-6,-10:17.12
0,-6,-10:17.12
1,-6,-10:17.12
2,-6,-10:17.12
3,-6,-10:17.12
-1,-5,-10:17.12
0,-5,-10:17.12
1,-5,-10:17.12
2,-5,-10:17.12
3,-5,-10:17.12
-1,-4,-10:17.12
0,-4,-10:17.12
1,-4,-10:17.12
2,-4,-10:17.12
3,-4,-10:17.12
-4,-3,-10:17.12
-3,-3,-10:17.12
-2,-3,-10:17.12
0,-3,-10:17.12
1,-3,-10:17.12
2,-3,-10:17.12
-5,-2,-10:17.12
-4,-2,-10:17.12
-3,-2,-10:17.12
-2,-2,-10:17.12
-1,-2,-10:17.12
-5,-1,-10:17.12
-4,-1,-10:17.12
-3,-1,-10:17.12
-2,-1,-10:17.12
-1,-1,-10:17.12
-5,0,-10:17.12
-4,0,-10:17.12
-3,0,-10:17.12
-2,0,-10:17.12
-1,0,-10:17.12
-4,1,-10:17.12
-3,1,-10:17.12
-2,1,-10:17.12
0,-8,-9:17.12
1,-8,-9:17.12
2,-8,-9:17.12
-1,-7,-9:17.12
0,-7,-9:17.12
1,-7,-9:17.12
2,-7,-9:17.12
3,-7,-9:17.12
-2,-6,-9:17.12
-1,-6,-9:17.12
0,-6,-9:17.12
1,-6,-9:17.12
2,-6,-9:17.12
3,-6,-9:17.12
4,-6,-9:17.12
-2,-5,-9:17.12
-1,-5,-9:17.12
0,-5,-9:17.12
1,-5,-9:17.12
2,-5,-9:17.12
3,-5,-9:17.12
4,-5,-9:17.12
-4,-4,-9:17.12
-3,-4,-9:17.12
-2,-4,-9:17.12
-1,-4,-9:17.12
0,-4,-9:17.12
1,-4,-9:17.12
2,-4,-9:17.12
3,-4,-9:17.12
4,-4,-9:17.12
-5,-3,-9:17.12
-4,-3,-9:17.12
-3,-3,-9:17.12
-2,-3,-9:17.12
-1,-3,-9:17.12
0,-3,-9:17.12
1,-3,-9:17.12
2,-3,-9:17.12
3,-3,-9:17.12
-6,-2,-9:17.12
-5,-2,-9:17.12
-4,-2,-9:17.12
-3,-2,-9:17.12
-2,-2,-9:17.12
-1,-2,-9:17.12
0,-2,-9:17.12
1,-2,-9:17.12
2,-2,-9:17.12
-6,-1,-9:17.12
-5,-1,-9:17.12
-4,-1,-9:17.12
-3,-1,-9:17.12
-2,-1,-9:17.12
-1,-1,-9:17.12
0,-1,-9:17.12
-6,0,-9:17.12
-5,0,-9:17.12
-4,0,-9:17.12
-3,0,-9:17.12
-2,0,-9:17.12
-1,0,-9:17.12
0,0,-9:17.12
-6,1,-9:17.12
-5,1,-9:17.12
-4,1,-9:17.12
-3,1,-9:17.12
-2,1,-9:17.12
-1,1,-9:17.12
-5,2,-9:17.12
-4,2,-9:17.12
-3,2,-9:17.12
-2,2,-9:17.12
-9,-17,-8:17.12
-8,-17,-8:17.12
-7,-17,-8:17.12
-6,-17,-8:17.12
-6,-16,-8:17.12
17,-15,-8:17.12
-9,-14,-8:17.12
15,-13,-8:17.12
-5,-11,-8:17.12
-3,-11,-8:17.12
-2,-11,-8:17.12
5,-11,-8:17.12
13,-11,-8:17.12
-6,-10,-8:17.12
-3,-10,-8:17.12
4,-10,-8:17.12
-6,-9,-8:17.12
1,-9,-8:17.12
2,-9,-8:17.12
4,-9,-8:17.12
5,-9,-8:17.12
6,-9,-8:17.12
-6,-8,-8:17.12
-1,-8,-8:17.12
0,-8,-8:17.12
1,-8,-8:17.12
2,-8,-8:17.12
3,-8,-8:17.12
5,-8,-8:17.12
7,-8,-8:17.12
-5,-7,-8:17.12
-4,-7,-8:17.12
-2,-7,-8:17.12
-1,-7,-8:17.12
0,-7,-8:17.12
1,-7,-8:17.12
2,-7,-8:17.12
3,-7,-8:17.12
4,-7,-8:17.12
-7,-6,-8:17.12
-2,-6,-8:17.12
-1,-6,-8:17.12
0,-6,-8:17.12
1,-6,-8:17.12
2,-6,-8:17.12
3,-6,-8:17.12
4,-6,-8:17.12
5,-6,-8:17.12
-8,-5,-8:17.12
-6,-5,-8:17.12
-2,-5,-8:17.12
-1,-5,-8:17.12
0,-5,-8:17.12
1,-5,-8:17.12
2,-5,-8:17.12
3,-5,-8:17.12
4,-5,-8:17.12
5,-5,-8:17.12
7,-5,-8:17.12
-5,-4,-8:17.12
-4,-4,-8:17.12
-3,-4,-8:17.12
-2,-4,-8:17.12
-1,-4,-8:17.12
0,-4,-8:17.12
1,-4,-8:17.12
2,-4,-8:17.12
3,-4,-8:17.12
4,-4,-8:17.12
5,-4,-8:17.12
-8,-3,-8:17.12
-6,-3,-8:17.12
-5,-3,-8:17.12
-4,-3,-8:17.12
-3,-3,-8:17.12
-2,-3,-8:17.12
-1,-3,-8:17.12
0,-3,-8:17.12
1,-3,-8:17.12
2,-3,-8:17.12
3,-3,-8:17.12
4,-3,-8:17.12
5,-3,-8:17.12
-10,-2,-8:17.12
-6,-2,-8:17.12
-5,-2,-8:17.12
-4,-2,-8:17.12
-3,-2,-8:17.12
-2,-2,-8:17.12
-1,-2,-8:17.12
0,-2,-8:17.12
1,-2,-8:17.12
2,-2,-8:17.12
3,-2,-8:17.12
4,-2,-8:17.12
5,-2,-8:17.12
7,-2,-8:17.12
8,-2,-8:17.12
-7,-1,-8:17.12
-6,-1,-8:17.12
-5,-1,-8:17.12
-4,-1,-8:17.12
-3,-1,-8:17.12
-2,-1,-8:17.12
-1,-1,-8:17.12
0,-1,-8:17.12
3,-1,-8:17.12
6,-1,-8:17.12
-7,0,-8:17.12
-6,0,-8:17.12
-5,0,-8:17.12
-4,0,-8:17.12
-3,0,-8:17.12
-2,0,-8:17.12
-1,0,-8:17.12
0,0,-8:17.12
2,0,-8:17.12
4,0,-8:17.12
6,0,-8:17.12
-7,1,-8:17.12
-6,1,-8:17.12
-5,1,-8:17.12
-4,1,-8:17.12
-3,1,-8:17.12
-2,1,-8:17.12
-1,1,-8:17.12
0,1,-8:17.12
1,1,-8:17.12
3,1,-8:17.12
6,1,-8:17.12
7,1,-8:17.12
-5,2,-8:17.12
-4,2,-8:17.12
-3,2,-8:17.12
-2,2,-8:17.12
-1,2,-8:17.12
0,2,-8:17.12
2,2,-8:17.12
-5,3,-8:17.12
-4,3,-8:17.12
-3,3,-8:17.12
-1,3,-8:17.12
1,3,-8:17.12
-1,4,-8:17.12
1,4,-8:17.12
4,4,-8:17.12
-3,5,-8:17.12
1,5,-8:17.12
3,5,-8:17.12
6,5,-8:17.12
-9,6,-8:17.12
-4,6,-8:17.12
-3,6,-8:17.12
2,6,-8:17.12
4,6,-8:17.12
5,6,-8:17.12
6,7,-8:17.12
7,7,-8:17.12
-6,8,-8:17.12
7,8,-8:17.12
8,8,-8:17.12
-11,9,-8:17.12
-10,9,-8:17.12
-6,9,-8:17.12
7,9,-8:17.12
9,10,-8:17.12
-14,11,-8:17.12
-13,11,-8:17.12
8,11,-8:17.12
11,11,-8:17.12
13,11,-8:17.12
-14,12,-8:17.12
-11,12,-8:17.12
12,12,-8:17.12
-12,-21,-7:17.12
-11,-21,-7:17.12
-12,-20,-7:17.12
-11,-20,-7:17.12
-10,-20,-7:17.12
-12,-19,-7:17.12
-11,-19,-7:17.12
-10,-19,-7:17.12
-9,-19,-7:17.12
-6,-19,-7:17.12
-10,-18,-7:17.12
-9,-18,-7:17.12
-8,-18,-7:17.12
-7,-18,-7:17.12
-6,-18,-7:17.12
-5,-18,-7:17.12
-10,-17,-7:17.12
-9,-17,-7:17.12
-8,-17,-7:17.12
-7,-17,-7:17.12
-6,-17,-7:17.12
-5,-17,-7:17.12
-9,-16,-7:17.12
-8,-16,-7:17.12
-7,-16,-7:17.12
-6,-16,-7:17.12
-5,-16,-7:17.12
-4,-16,-7:17.12
17,-16,-7:17.12
-9,-15,-7:17.12
-8,-15,-7:17.12
-7,-15,-7:17.12
-6,-15,-7:17.12
-5,-15,-7:17.12
-4,-15,-7:17.12
-3,-15,-7:17.12
-2,-15,-7:17.12
-1,-15,-7:17.12
16,-15,-7:17.12
17,-15,-7:17.12
18,-15,-7:17.12
-10,-14,-7:17.12
-9,-14,-7:17.12
-8,-14,-7:17.12
-7,-14,-7:17.12
-6,-14,-7:17.12
-5,-14,-7:17.12
-4,-14,-7:17.12
-3,-14,-7:17.12
-2,-14,-7:17.12
-1,-14,-7:17.12
0,-14,-7:17.12
7,-14,-7:17.12
8,-14,-7:17.12
15,-14,-7:17.12
17,-14,-7:17.12
-9,-13,-7:17.12
-8,-13,-7:17.12
-7,-13,-7:17.12
-6,-13,-7:17.12
-5,-13,-7:17.12
-4,-13,-7:17.12
-3,-13,-7:17.12
-2,-13,-7:17.12
-1,-13,-7:17.12
0,-13,-7:17.12
1,-13,-7:17.12
2,-13,-7:17.12
4,-13,-7:17.12
5,-13,-7:17.12
6,-13,-7:17.12
7,-13,-7:17.12
8,-13,-7:17.12
14,-13,-7:17.12
15,-13,-7:17.12
16,-13,-7:17.12
17,-13,-7:17.12
-7,-12,-7:17.12
-6,-12,-7:17.12
-5,-12,-7:17.12
-4,-12,-7:17.12
-3,-12,-7:17.12
-2,-12,-7:17.12
-1,-12,-7:17.12
0,-12,-7:17.12
1,-12,-7:17.12
2,-12,-7:17.12
3,-12,-7:17.12
4,-12,-7:17.12
5,-12,-7:17.12
6,-12,-7:17.12
7,-12,-7:17.12
8,-12,-7:17.12
9,-12,-7:17.12
12,-12,-7:17.12
13,-12,-7:17.12
15,-12,-7:17.12
-6,-11,-7:17.12
-5,-11,-7:17.12
-4,-11,-7:17.12
-3,-11,-7:17.12
-2,-11,-7:17.12
-1,-11,-7:17.12
0,-11,-7:17.12
1,-11,-7:17.12
2,-11,-7:17.12
3,-11,-7:17.12
4,-11,-7:17.12
5,-11,-7:17.12
6,-11,-7:17.12
7,-11,-7:17.12
8,-11,-7:17.12
9,-11,-7:17.12
10,-11,-7:17.12
11,-11,-7:17.12
12,-11,-7:17.12
13,-11,-7:17.12
14,-11,-7:17.12
-7,-10,-7:17.12
-6,-10,-7:17.12
-5,-10,-7:17.12
-4,-10,-7:17.12
-3,-10,-7:17.12
-2,-10,-7:17.12
-1,-10,-7:17.12
0,-10,-7:17.12
1,-10,-7:17.12
2,-10,-7:17.12
3,-10,-7:17.12
4,-10,-7:17.12
5,-10,-7:17.12
6,-10,-7:17.12
7,-10,-7:17.12
8,-10,-7:17.12
9,-10,-7:17.12
10,-10,-7:17.12
11,-10,-7:17.12
12,-10,-7:17.12
13,-10,-7:17.12
-7,-9,-7:17.12
-6,-9,-7:17.12
-5,-9,-7:17.12
-3,-9,-7:17.12
-1,-9,-7:17.12
0,-9,-7:17.12
1,-9,-7:17.12
2,-9,-7:17.12
3,-9,-7:17.12
4,-9,-7:17.12
5,-9,-7:17.12
6,-9,-7:17.12
7,-9,-7:17.12
8,-9,-7:17.12
9,-9,-7:17.12
10,-9,-7:17.12
11,-9,-7:17.12
-7,-8,-7:17.12
-6,-8,-7:17.12
-5,-8,-7:17.12
-4,-8,-7:17.12
-1,-8,-7:17.12
0,-8,-7:17.12
1,-8,-7:17.12
2,-8,-7:17.12
3,-8,-7:17.12
4,-8,-7:17.12
5,-8,-7:17.12
6,-8,-7:17.12
7,-8,-7:17.12
8,-8,-7:17.12
9,-8,-7:17.12
10,-8,-7:17.12
-7,-7,-7:17.12
-6,-7,-7:17.12
-5,-7,-7:17.12
-4,-7,-7:17.12
-3,-7,-7:17.12
-2,-7,-7:17.12
-1,-7,-7:17.12
0,-7,-7:17.12
1,-7,-7:17.12
2,-7,-7:17.12
3,-7,-7:17.12
4,-7,-7:17.12
5,-7,-7:17.12
7,-7,-7:17.12
8,-7,-7:17.12
-8,-6,-7:17.12
-7,-6,-7:17.12
-6,-6,-7:17.12
-5,-6,-7:17.12
-4,-6,-7:17.12
-2,-6,-7:17.12
-1,-6,-7:17.12
0,-6,-7:17.12
1,-6,-7:17.12
2,-6,-7:17.12
3,-6,-7:17.12
4,-6,-7:17.12
5,-6,-7:17.12
6,-6,-7:17.12
7,-6,-7:17.12
-9,-5,-7:17.12
-8,-5,-7:17.12
-7,-5,-7:17.12
-6,-5,-7:17.12
-5,-5,-7:17.12
-4,-5,-7:17.12
-3,-5,-7:17.12
-2,-5,-7:17.12
-1,-5,-7:17.12
0,-5,-7:17.12
1,-5,-7:17.12
2,-5,-7:17.12
3,-5,-7:17.12
4,-5,-7:17.12
5,-5,-7:17.12
6,-5,-7:17.12
7,-5,-7:17.12
8,-5,-7:17.12
-8,-4,-7:17.12
-6,-4,-7:17.12
-5,-4,-7:17.12
-4,-4,-7:17.12
-3,-4,-7:17.12
-2,-4,-7:17.12
-1,-4,-7:17.12
0,-4,-7:17.12
1,-4,-7:17.12
2,-4,-7:17.12
3,-4,-7:17.12
4,-4,-7:17.12
5,-4,-7:17.12
6,-4,-7:17.12
7,-4,-7:17.12
-10,-3,-7:17.12
-9,-3,-7:17.12
-8,-3,-7:17.12
-7,-3,-7:17.12
-6,-3,-7:17.12
-5,-3,-7:17.12
-4,-3,-7:17.12
-3,-3,-7:17.12
-2,-3,-7:17.12
-1,-3,-7:17.12
0,-3,-7:17.12
1,-3,-7:17.12
2,-3,-7:17.12
3,-3,-7:17.12
4,-3,-7:17.12
5,-3,-7:17.12
6,-3,-7:17.12
7,-3,-7:17.12
8,-3,-7:17.12
-11,-2,-7:17.12
-10,-2,-7:17.12
-9,-2,-7:17.12
-8,-2,-7:17.12
-7,-2,-7:17.12
-6,-2,-7:17.12
-5,-2,-7:17.12
-4,-2,-7:17.12
-3,-2,-7:17.12
-2,-2,-7:17.12
-1,-2,-7:17.12
0,-2,-7:17.12
1,-2,-7:17.12
2,-2,-7:17.12
3,-2,-7:17.12
4,-2,-7:17.12
5,-2,-7:17.12
6,-2,-7:17.12
7,-2,-7:17.12
8,-2,-7:17.12
-10,-1,-7:17.12
-9,-1,-7:17.12
-8,-1,-7:17.12
-7,-1,-7:17.12
-6,-1,-7:17.12
-5,-1,-7:17.12
-4,-1,-7:17.12
-3,-1,-7:17.12
-2,-1,-7:17.12
-1,-1,-7:17.12
0,-1,-7:17.12
1,-1,-7:17.12
2,-1,-7:17.12
3,-1,-7:17.12
4,-1,-7:17.12
5,-1,-7:17.12
6,-1,-7:17.12
7,-1,-7:17.12
8,-1,-7:17.12
-9,0,-7:17.12
-8,0,-7:17.12
-7,0,-7:17.12
-6,0,-7:17.12
-5,0,-7:17.12
-4,0,-7:17.12
-3,0,-7:17.12
-2,0,-7:17.12
-1,0,-7:17.12
0,0,-7:17.12
1,0,-7:17.12
2,0,-7:17.12
3,0,-7:17.12
4,0,-7:17.12
5,0,-7:17.12
6,0,-7:17.12
7,0,-7:17.12
-9,1,-7:17.12
-8,1,-7:17.12
-7,1,-7:17.12
-6,1,-7:17.12
-5,1,-7:17.12
-4,1,-7:17.12
-3,1,-7:17.12
-2,1,-7:17.12
-1,1,-7:17.12
0,1,-7:17.12
1,1,-7:17.12
2,1,-7:17.12
3,1,-7:17.12
4,1,-7:17.12
5,1,-7:17.12
6,1,-7:17.12
7,1,-7:17.12
8,1,-7:17.12
-9,2,-7:17.12
-8,2,-7:17.12
-7,2,-7:17.12
-6,2,-7:17.12
-5,2,-7:17.12
-4,2,-7:17.12
-3,2,-7:17.12
-2,2,-7:17.12
-1,2,-7:17.12
0,2,-7:17.12
1,2,-7:17.12
2,2,-7:17.12
3,2,-7:17.12
5,2,-7:17.12
6,2,-7:17.12
7,2,-7:17.12
-9,3,-7:17.12
-8,3,-7:17.12
-7,3,-7:17.12
-6,3,-7:17.12
-5,3,-7:17.12
-4,3,-7:17.12
-3,3,-7:17.12
-2,3,-7:17.12
-1,3,-7:17.12
0,3,-7:17.12
1,3,-7:17.12
2,3,-7:17.12
4,3,-7:17.12
5,3,-7:17.12
6,3,-7:17.12
-9,4,-7:17.12
-8,4,-7:17.12
-7,4,-7:17.12
-6,4,-7:17.12
-5,4,-7:17.12
-4,4,-7:17.12
-3,4,-7:17.12
-2,4,-7:17.12
-1,4,-7:17.12
0,4,-7:17.12
1,4,-7:17.12
2,4,-7:17.12
3,4,-7:17.12
4,4,-7:17.12
5,4,-7:17.12
6,4,-7:17.12
-9,5,-7:17.12
-8,5,-7:17.12
-7,5,-7:17.12
-6,5,-7:17.12
-5,5,-7:17.12
-4,5,-7:17.12
-3,5,-7:17.12
-2,5,-7:17.12
-1,5,-7:17.12
0,5,-7:17.12
1,5,-7:17.12
2,5,-7:17.12
3,5,-7:17.12
4,5,-7:17.12
5,5,-7:17.12
6,5,-7:17.12
7,5,-7:17.12
-10,6,-7:17.12
-9,6,-7:17.12
-8,6,-7:17.12
-7,6,-7:17.12
-5,6,-7:17.12
-4,6,-7:17.12
-3,6,-7:17.12
-2,6,-7:17.12
1,6,-7:17.12
2,6,-7:17.12
3,6,-7:17.12
4,6,-7:17.12
5,6,-7:17.12
6,6,-7:17.12
7,6,-7:17.12
-11,7,-7:17.12
-10,7,-7:17.12
-9,7,-7:17.12
-8,7,-7:17.12
-7,7,-7:17.12
-6,7,-7:17.12
-4,7,-7:17.12
-3,7,-7:17.12
2,7,-7:17.12
4,7,-7:17.12
5,7,-7:17.12
6,7,-7:17.12
7,7,-7:17.12
8,7,-7:17.12
-11,8,-7:17.12
-10,8,-7:17.12
-9,8,-7:17.12
-8,8,-7:17.12
-7,8,-7:17.12
-6,8,-7:17.12
-5,8,-7:17.12
6,8,-7:17.12
7,8,-7:17.12
8,8,-7:17.12
9,8,-7:17.12
-13,9,-7:17.12
-12,9,-7:17.12
-11,9,-7:17.12
-10,9,-7:17.12
-9,9,-7:17.12
-8,9,-7:17.12
-7,9,-7:17.12
-6,9,-7:17.12
-5,9,-7:17.12
6,9,-7:17.12
7,9,-7:17.12
8,9,-7:17.12
9,9,-7:17.12
-14,10,-7:17.12
-13,10,-7:17.12
-12,10,-7:17.12
-11,10,-7:17.12
-10,10,-7:17.12
-9,10,-7:17.12
-8,10,-7:17.12
-7,10,-7:17.12
-6,10,-7:17.12
6,10,-7:17.12
7,10,-7:17.12
8,10,-7:17.12
9,10,-7:17.12
10,10,-7:17.12
11,10,-7:17.12
13,10,-7:17.12
-16,11,-7:17.12
-15,11,-7:17.12
-14,11,-7:17.12
-13,11,-7:17.12
-12,11,-7:17.12
-11,11,-7:17.12
-10,11,-7:17.12
-9,11,-7:17.12
-8,11,-7:17.12
7,11,-7:17.12
8,11,-7:17.12
9,11,-7:17.12
10,11,-7:17.12
11,11,-7:17.12
12,11,-7:17.12
13,11,-7:17.12
14,11,-7:17.12
-19,12,-7:17.12
-18,12,-7:17.12
-17,12,-7:17.12
-16,12,-7:17.12
-15,12,-7:17.12
-14,12,-7:17.12
-13,12,-7:17.12
-12,12,-7:17.12
-11,12,-7:17.12
-10,12,-7:17.12
-9,12,-7:17.12
8,12,-7:17.12
11,12,-7:17.12
12,12,-7:17.12
13,12,-7:17.12
-19,13,-7:17.12
-18,13,-7:17.12
-17,13,-7:17.12
-16,13,-7:17.12
-15,13,-7:17.12
-14,13,-7:17.12
-11,13,-7:17.12
12,13,-7:17.12
-19,14,-7:17.12
-18,14,-7:17.12
-7,-17,-6:17.12
-6,-17,-6:17.12
-8,-16,-6:17.12
-7,-16,-6:17.12
-6,-16,-6:17.12
-5,-16,-6:17.12
-9,-15,-6:17.12
-8,-15,-6:17.12
-7,-15,-6:17.12
-6,-15,-6:17.12
-5,-15,-6:17.12
-4,-15,-6:17.12
-3,-15,-6:17.12
-10,-14,-6:17.12
-9,-14,-6:17.12
-8,-14,-6:17.12
-7,-14,-6:17.12
-6,-14,-6:17.12
-5,-14,-6:17.12
-4,-14,-6:17.12
-3,-14,-6:17.12
-2,-14,-6:17.12
-1,-14,-6:17.12
0,-14,-6:17.12
1,-14,-6:17.12
15,-14,-6:17.12
16,-14,-6:17.12
17,-14,-6:17.12
-8,-13,-6:17.12
-7,-13,-6:17.12
-6,-13,-6:17.12
-5,-13,-6:17.12
-4,-13,-6:17.12
-3,-13,-6:17.12
-2,-13,-6:17.12
-1,-13,-6:17.12
0,-13,-6:17.12
1,-13,-6:17.12
2,-13,-6:17.12
3,-13,-6:17.12
6,-13,-6:17.12
7,-13,-6:17.12
14,-13,-6:17.12
15,-13,-6:17.12
16,-13,-6:17.12
17,-13,-6:17.12
-7,-12,-6:17.12
-6,-12,-6:17.12
-5,-12,-6:17.12
-4,-12,-6:17.12
-3,-12,-6:17.12
-2,-12,-6:17.12
-1,-12,-6:17.12
0,-12,-6:17.12
1,-12,-6:17.12
2,-12,-6:17.12
3,-12,-6:17.12
4,-12,-6:17.12
5,-12,-6:17.12
6,-12,-6:17.12
7,-12,-6:17.12
8,-12,-6:17.12
13,-12,-6:17.12
15,-12,-6:17.12
16,-12,-6:17.12
-6,-11,-6:17.12
-5,-11,-6:17.12
-4,-11,-6:17.12
-3,-11,-6:17.12
-2,-11,-6:17.12
-1,-11,-6:17.12
0,-11,-6:17.12
1,-11,-6:17.12
2,-11,-6:17.12
3,-11,-6:17.12
4,-11,-6:17.12
5,-11,-6:17.12
6,-11,-6:17.12
7,-11,-6:17.12
8,-11,-6:17.12
12,-11,-6:17.12
13,-11,-6:17.12
14,-11,-6:17.12
-6,-10,-6:17.12
-5,-10,-6:17.12
-4,-10,-6:17.12
-3,-10,-6:17.12
-2,-10,-6:17.12
-1,-10,-6:17.12
0,-10,-6:17.12
1,-10,-6:17.12
2,-10,-6:17.12
3,-10,-6:17.12
4,-10,-6:17.12
5,-10,-6:17.12
6,-10,-6:17.12
7,-10,-6:17.12
8,-10,-6:17.12
9,-10,-6:17.12
10,-10,-6:17.12
12,-10,-6:17.12
13,-10,-6:17.12
-7,-9,-6:17.12
-6,-9,-6:17.12
-5,-9,-6:17.12
-4,-9,-6:17.12
-3,-9,-6:17.12
-2,-9,-6:17.12
-1,-9,-6:17.12
0,-9,-6:17.12
1,-9,-6:17.12
2,-9,-6:17.12
3,-9,-6:17.12
4,-9,-6:17.12
5,-9,-6:17.12
6,-9,-6:17.12
7,-9,-6:17.12
8,-9,-6:17.12
9,-9,-6:17.12
10,-9,-6:17.12
-6,-8,-6:17.12
-5,-8,-6:17.12
-4,-8,-6:17.12
-3,-8,-6:17.12
-2,-8,-6:17.12
-1,-8,-6:17.12
0,-8,-6:17.12
1,-8,-6:17.12
2,-8,-6:17.12
3,-8,-6:17.12
4,-8,-6:17.12
5,-8,-6:17.12
6,-8,-6:17.12
7,-8,-6:17.12
8,-8,-6:17.12
9,-8,-6:17.12
10,-8,-6:17.12
-7,-7,-6:17.12
-6,-7,-6:17.12
-5,-7,-6:17.12
-4,-7,-6:17.12
-3,-7,-6:17.12
-2,-7,-6:17.12
-1,-7,-6:17.12
0,-7,-6:17.12
1,-7,-6:17.12
2,-7,-6:17.12
3,-7,-6:17.12
4,-7,-6:17.12
5,-7,-6:17.12
6,-7,-6:17.12
7,-7,-6:17.12
8,-7,-6:17.12
9,-7,-6:17.12
-7,-6,-6:17.12
-6,-6,-6:17.12
-5,-6,-6:17.12
-4,-6,-6:17.12
-3,-6,-6:17.12
-2,-6,-6:17.12
-1,-6,-6:17.12
0,-6,-6:17.12
1,-6,-6:17.12
2,-6,-6:17.12
3,-6,-6:17.12
4,-6,-6:17.12
5,-6,-6:17.12
7,-6,-6:17.12
8,-6,-6:17.12
-8,-5,-6:17.12
-7,-5,-6:17.12
-6,-5,-6:17.12
-5,-5,-6:17.12
-4,-5,-6:17.12
-3,-5,-6:17.12
-2,-5,-6:17.12
-1,-5,-6:17.12
0,-5,-6:17.12
1,-5,-6:17.12
2,-5,-6:17.12
3,-5,-6:17.12
4,-5,-6:17.12
5,-5,-6:17.12
6,-5,-6:17.12
7,-5,-6:17.12
8,-5,-6:17.12
-8,-4,-6:17.12
-6,-4,-6:17.12
-5,-4,-6:17.12
-4,-4,-6:17.12
-3,-4,-6:17.12
-2,-4,-6:17.12
-1,-4,-6:17.12
0,-4,-6:17.12
1,-4,-6:17.12
2,-4,-6:17.12
3,-4,-6:17.12
4,-4,-6:17.12
5,-4,-6:17.12
6,-4,-6:17.12
7,-4,-6:17.12
8,-4,-6:17.12
-9,-3,-6:17.12
-8,-3,-6:17.12
-7,-3,-6:17.12
-6,-3,-6:17.12
-5,-3,-6:17.12
-4,-3,-6:17.12
-3,-3,-6:17.12
-2,-3,-6:17.12
-1,-3,-6:17.12
0,-3,-6:17.12
1,-3,-6:17.12
2,-3,-6:17.12
3,-3,-6:17.12
4,-3,-6:17.12
5,-3,-6:17.12
6,-3,-6:17.12
7,-3,-6:17.12
8,-3,-6:17.12
-10,-2,-6:17.12
-9,-2,-6:17.12
-8,-2,-6:17.12
-7,-2,-6:17.12
-6,-2,-6:17.12
-5,-2,-6:17.12
-4,-2,-6:17.12
-3,-2,-6:17.12
-2,-2,-6:17.12
-1,-2,-6:17.12
0,-2,-6:17.12
1,-2,-6:17.12
2,-2,-6:17.12
3,-2,-6:17.12
4,-2,-6:17.12
5,-2,-6:17.12
6,-2,-6:17.12
7,-2,-6:17.12
-9,-1,-6:17.12
-8,-1,-6:17.12
-7,-1,-6:17.12
-6,-1,-6:17.12
-5,-1,-6:17.12
-4,-1,-6:17.12
-3,-1,-6:17.12
-2,-1,-6:17.12
-1,-1,-6:17.12
0,-1,-6:17.12
1,-1,-6:17.12
2,-1,-6:17.12
3,-1,-6:17.12
4,-1,-6:17.12
6,-1,-6:17.12
7,-1,-6:17.12
-8,0,-6:17.12
-7,0,-6:17.12
-6,0,-6:17.12
-5,0,-6:17.12
-4,0,-6:17.12
-3,0,-6:17.12
-2,0,-6:17.12
-1,0,-6:17.12
0,0,-6:17.12
1,0,-6:17.12
2,0,-6:17.12
3,0,-6:17.12
4,0,-6:17.12
5,0,-6:17.12
6,0,-6:17.12
7,0,-6:17.12
-8,1,-6:17.12
-7,1,-6:17.12
-6,1,-6:17.12
-5,1,-6:17.12
-4,1,-6:17.12
-3,1,-6:17.12
-2,1,-6:17.12
-1,1,-6:17.12
0,1,-6:17.12
1,1,-6:17.12
2,1,-6:17.12
3,1,-6:17.12
4,1,-6:17.12
5,1,-6:17.12
6,1,-6:17.12
7,1,-6:17.12
-9,2,-6:17.12
-8,2,-6:17.12
-7,2,-6:17.12
-6,2,-6:17.12
-5,2,-6:17.12
-4,2,-6:17.12
-3,2,-6:17.12
-2,2,-6:17.12
-1,2,-6:17.12
0,2,-6:17.12
1,2,-6:17.12
2,2,-6:17.12
3,2,-6:17.12
4,2,-6:17.12
5,2,-6:17.12
6,2,-6:17.12
7,2,-6:17.12
-8,3,-6:17.12
-7,3,-6:17.12
-6,3,-6:17.12
-5,3,-6:17.12
-4,3,-6:17.12
-3,3,-6:17.12
-2,3,-6:17.12
-1,3,-6:17.12
0,3,-6:17.12
1,3,-6:17.12
3,3,-6:17.12
4,3,-6:17.12
5,3,-6:17.12
6,3,-6:17.12
7,3,-6:17.12
-8,4,-6:17.12
-7,4,-6:17.12
-6,4,-6:17.12
-5,4,-6:17.12
-4,4,-6:17.12
-3,4,-6:17.12
-1,4,-6:17.12
1,4,-6:17.12
3,4,-6:17.12
4,4,-6:17.12
5,4,-6:17.12
6,4,-6:17.12
-9,5,-6:17.12
-8,5,-6:17.12
-7,5,-6:17.12
-6,5,-6:17.12
-5,5,-6:17.12
-4,5,-6:17.12
-3,5,-6:17.12
-2,5,-6:17.12
1,5,-6:17.12
2,5,-6:17.12
3,5,-6:17.12
4,5,-6:17.12
5,5,-6:17.12
6,5,-6:17.12
-10,6,-6:17.12
-9,6,-6:17.12
-8,6,-6:17.12
-7,6,-6:17.12
-6,6,-6:17.12
-5,6,-6:17.12
-4,6,-6:17.12
-3,6,-6:17.12
3,6,-6:17.12
4,6,-6:17.12
5,6,-6:17.12
-11,7,-6:17.12
-10,7,-6:17.12
-9,7,-6:17.12
-8,7,-6:17.12
-7,7,-6:17.12
-6,7,-6:17.12
-5,7,-6:17.12
-4,7,-6:17.12
-3,7,-6:17.12
6,7,-6:17.12
7,7,-6:17.12
-12,8,-6:17.12
-11,8,-6:17.12
-10,8,-6:17.12
-9,8,-6:17.12
-8,8,-6:17.12
-7,8,-6:17.12
-6,8,-6:17.12
-4,8,-6:17.12
6,8,-6:17.12
7,8,-6:17.12
8,8,-6:17.12
-13,9,-6:17.12
-12,9,-6:17.12
-11,9,-6:17.12
-10,9,-6:17.12
-9,9,-6:17.12
-8,9,-6:17.12
-6,9,-6:17.12
7,9,-6:17.12
8,9,-6:17.12
-14,10,-6:17.12
-13,10,-6:17.12
-12,10,-6:17.12
-11,10,-6:17.12
-10,10,-6:17.12
-9,10,-6:17.12
-8,10,-6:17.12
7,10,-6:17.12
8,10,-6:17.12
9,10,-6:17.12
-14,11,-6:17.12
-13,11,-6:17.12
-12,11,-6:17.12
-11,11,-6:17.12
-10,11,-6:17.12
-9,11,-6:17.12
11,11,-6:17.12
12,11,-6:17.12
-18,12,-6:17.12
-14,12,-6:17.12
-13,12,-6:17.12
-12,12,-6:17.12
-11,12,-6:17.12
12,12,-6:17.12
-19,13,-6:17.12
-18,13,-6:17.12
-11,13,-6:17.12
-5,-14,-5:17.12
-4,-14,-5:17.12
-3,-14,-5:17.12
-6,-13,-5:17.12
-5,-13,-5:17.12
-4,-13,-5:17.12
-3,-13,-5:17.12
0,-13,-5:17.12
1,-13,-5:17.12
2,-13,-5:17.12
15,-13,-5:17.12
-5,-12,-5:17.12
-4,-12,-5:17.12
-3,-12,-5:17.12
-2,-12,-5:17.12
-1,-12,-5:17.12
0,-12,-5:17.12
1,-12,-5:17.12
2,-12,-5:17.12
3,-12,-5:17.12
13,-12,-5:17.12
14,-12,-5:17.12
-6,-11,-5:17.12
-5,-11,-5:17.12
-4,-11,-5:17.12
-3,-11,-5:17.12
-2,-11,-5:17.12
-1,-11,-5:17.12
0,-11,-5:17.12
1,-11,-5:17.12
2,-11,-5:17.12
3,-11,-5:17.12
4,-11,-5:17.12
13,-11,-5:17.12
14,-11,-5:17.12
-6,-10,-5:17.12
-5,-10,-5:17.12
-4,-10,-5:17.12
-3,-10,-5:17.12
-2,-10,-5:17.12
-1,-10,-5:17.12
0,-10,-5:17.12
1,-10,-5:17.12
2,-10,-5:17.12
3,-10,-5:17.12
4,-10,-5:17.12
13,-10,-5:17.12
-6,-9,-5:17.12
-5,-9,-5:17.12
-4,-9,-5:17.12
-3,-9,-5:17.12
-2,-9,-5:17.12
-1,-9,-5:17.12
0,-9,-5:17.12
1,-9,-5:17.12
2,-9,-5:17.12
3,-9,-5:17.12
4,-9,-5:17.12
5,-9,-5:17.12
6,-9,-5:17.12
7,-9,-5:17.12
8,-9,-5:17.12
-5,-8,-5:17.12
-4,-8,-5:17.12
-3,-8,-5:17.12
-2,-8,-5:17.12
-1,-8,-5:17.12
0,-8,-5:17.12
1,-8,-5:17.12
2,-8,-5:17.12
3,-8,-5:17.12
4,-8,-5:17.12
5,-8,-5:17.12
6,-8,-5:17.12
7,-8,-5:17.12
8,-8,-5:17.12
9,-8,-5:17.12
10,-8,-5:17.12
-6,-7,-5:17.12
-5,-7,-5:17.12
-4,-7,-5:17.12
-3,-7,-5:17.12
-2,-7,-5:17.12
-1,-7,-5:17.12
0,-7,-5:17.12
1,-7,-5:17.12
2,-7,-5:17.12
3,-7,-5:17.12
4,-7,-5:17.12
5,-7,-5:17.12
6,-7,-5:17.12
7,-7,-5:17.12
8,-7,-5:17.12
9,-7,-5:17.12
-6,-6,-5:17.12
-5,-6,-5:17.12
-4,-6,-5:17.12
-3,-6,-5:17.12
-2,-6,-5:17.12
-1,-6,-5:17.12
0,-6,-5:17.12
1,-6,-5:17.12
2,-6,-5:17.12
3,-6,-5:17.12
4,-6,-5:17.12
5,-6,-5:17.12
6,-6,-5:17.12
-7,-5,-5:17.12
-6,-5,-5:17.12
-5,-5,-5:17.12
-4,-5,-5:17.12
-3,-5,-5:17.12
-2,-5,-5:17.12
-1,-5,-5:17.12
0,-5,-5:17.12
1,-5,-5:17.12
2,-5,-5:17.12
3,-5,-5:17.12
4,-5,-5:17.12
5,-5,-5:17.12
7,-5,-5:17.12
-6,-4,-5:17.12
-5,-4,-5:17.12
-4,-4,-5:17.12
-3,-4,-5:17.12
-2,-4,-5:17.12
-1,-4,-5:17.12
0,-4,-5:17.12
1,-4,-5:17.12
2,-4,-5:17.12
3,-4,-5:17.12
4,-4,-5:17.12
5,-4,-5:17.12
6,-4,-5:17.12
7,-4,-5:17.12
-8,-3,-5:17.12
-6,-3,-5:17.12
-5,-3,-5:17.12
-4,-3,-5:17.12
-3,-3,-5:17.12
-2,-3,-5:17.12
-1,-3,-5:17.12
0,-3,-5:17.12
1,-3,-5:17.12
2,-3,-5:17.12
3,-3,-5:17.12
4,-3,-5:17.12
5,-3,-5:17.12
6,-3,-5:17.12
-6,-2,-5:17.12
-5,-2,-5:17.12
-4,-2,-5:17.12
-3,-2,-5:17.12
-2,-2,-5:17.12
-1,-2,-5:17.12
0,-2,-5:17.12
1,-2,-5:17.12
2,-2,-5:17.12
3,-2,-5:17.12
4,-2,-5:17.12
-6,-1,-5:17.12
-5,-1,-5:17.12
-4,-1,-5:17.12
-3,-1,-5:17.12
-2,-1,-5:17.12
-1,-1,-5:17.12
0,-1,-5:17.12
1,-1,-5:17.12
2,-1,-5:17.12
3,-1,-5:17.12
4,-1,-5:17.12
5,-1,-5:17.12
-6,0,-5:17.12
-5,0,-5:17.12
-4,0,-5:17.12
-3,0,-5:17.12
-2,0,-5:17.12
-1,0,-5:17.12
0,0,-5:17.12
1,0,-5:17.12
2,0,-5:17.12
3,0,-5:17.12
4,0,-5:17.12
5,0,-5:17.12
6,0,-5:17.12
-6,1,-5:17.12
-5,1,-5:17.12
-4,1,-5:17.12
-3,1,-5:17.12
-2,1,-5:17.12
-1,1,-5:17.12
0,1,-5:17.12
1,1,-5:17.12
2,1,-5:17.12
3,1,-5:17.12
4,1,-5:17.12
5,1,-5:17.12
6,1,-5:17.12
-6,2,-5:17.12
-5,2,-5:17.12
-4,2,-5:17.12
-3,2,-5:17.12
-2,2,-5:17.12
-1,2,-5:17.12
0,2,-5:17.12
1,2,-5:17.12
2,2,-5:17.12
3,2,-5:17.12
4,2,-5:17.12
5,2,-5:17.12
6,2,-5:17.12
-6,3,-5:17.12
-5,3,-5:17.12
-4,3,-5:17.12
-3,3,-5:17.12
-2,3,-5:17.12
-1,3,-5:17.12
0,3,-5:17.12
1,3,-5:17.12
2,3,-5:17.12
3,3,-5:17.12
4,3,-5:17.12
5,3,-5:17.12
-7,4,-5:17.12
-6,4,-5:17.12
-5,4,-5:17.12
-4,4,-5:17.12
-3,4,-5:17.12
4,4,-5:17.12
-8,5,-5:17.12
-7,5,-5:17.12
-6,5,-5:17.12
-5,5,-5:17.12
-4,5,-5:17.12
-3,5,-5:17.12
-2,5,-5:17.12
-8,6,-5:17.12
-7,6,-5:17.12
-6,6,-5:17.12
-5,6,-5:17.12
-4,6,-5:17.12
-3,6,-5:17.12
-9,7,-5:17.12
-8,7,-5:17.12
-7,7,-5:17.12
-6,7,-5:17.12
-5,7,-5:17.12
-10,8,-5:17.12
-9,8,-5:17.12
-8,8,-5:17.12
-12,9,-5:17.12
-11,9,-5:17.12
-10,9,-5:17.12
-13,10,-5:17.12
-12,10,-5:17.12
-11,10,-5:17.12
-10,10,-5:17.12
1,-12,-4:17.12
2,-12,-4:17.12
-5,-11,-4:17.12
-4,-11,-4:17.12
1,-11,-4:17.12
2,-11,-4:17.12
-5,-10,-4:17.12
-4,-10,-4:17.12
-3,-10,-4:17.12
-2,-10,-4:17.12
-1,-10,-4:17.12
0,-10,-4:17.12
1,-10,-4:17.12
2,-10,-4:17.12
-5,-9,-4:17.12
-4,-9,-4:17.12
-3,-9,-4:17.12
-2,-9,-4:17.12
-1,-9,-4:17.12
0,-9,-4:17.12
1,-9,-4:17.12
2,-9,-4:17.12
3,-9,-4:17.12
-5,-8,-4:17.12
-4,-8,-4:17.12
-3,-8,-4:17.12
-2,-8,-4:17.12
-1,-8,-4:17.12
0,-8,-4:17.12
1,-8,-4:17.12
2,-8,-4:17.12
3,-8,-4:17.12
4,-8,-4:17.12
-5,-7,-4:17.12
-4,-7,-4:17.12
-3,-7,-4:17.12
-2,-7,-4:17.12
-1,-7,-4:17.12
0,-7,-4:17.12
1,-7,-4:17.12
2,-7,-4:17.12
3,-7,-4:17.12
4,-7,-4:17.12
5,-7,-4:17.12
-5,-6,-4:17.12
-4,-6,-4:17.12
-3,-6,-4:17.12
-2,-6,-4:17.12
-1,-6,-4:17.12
0,-6,-4:17.12
1,-6,-4:17.12
2,-6,-4:17.12
3,-6,-4:17.12
4,-6,-4:17.12
5,-6,-4:17.12
-6,-5,-4:17.12
-4,-5,-4:17.12
-3,-5,-4:17.12
-2,-5,-4:17.12
-1,-5,-4:17.12
0,-5,-4:17.12
1,-5,-4:17.12
2,-5,-4:17.12
3,-5,-4:17.12
4,-5,-4:17.12
5,-5,-4:17.12
-4,-4,-4:17.12
-3,-4,-4:17.12
-2,-4,-4:17.12
-1,-4,-4:17.12
0,-4,-4:17.12
1,-4,-4:17.12
2,-4,-4:17.12
3,-4,-4:17.12
4,-4,-4:17.12
5,-4,-4:17.12
-4,-3,-4:17.12
-3,-3,-4:17.12
-2,-3,-4:17.12
-1,-3,-4:17.12
0,-3,-4:17.12
1,-3,-4:17.12
2,-3,-4:17.12
3,-3,-4:17.12
4,-3,-4:17.12
-5,-2,-4:17.12
-4,-2,-4:17.12
-3,-2,-4:17.12
-2,-2,-4:17.12
-1,-2,-4:17.12
0,-2,-4:17.12
1,-2,-4:17.12
2,-2,-4:17.12
3,-2,-4:17.12
4,-2,-4:17.12
-5,-1,-4:17.12
-4,-1,-4:17.12
-3,-1,-4:17.12
-2,-1,-4:17.12
-1,-1,-4:17.12
0,-1,-4:17.12
1,-1,-4:17.12
2,-1,-4:17.12
3,-1,-4:17.12
4,-1,-4:17.12
-5,0,-4:17.12
-4,0,-4:17.12
-3,0,-4:17.12
-2,0,-4:17.12
-1,0,-4:17.12
0,0,-4:17.12
1,0,-4:17.12
2,0,-4:17.12
3,0,-4:17.12
4,0,-4:17.12
-5,1,-4:17.12
-4,1,-4:17.12
-3,1,-4:17.12
-2,1,-4:17.12
-1,1,-4:17.12
0,1,-4:17.12
1,1,-4:17.12
2,1,-4:17.12
3,1,-4:17.12
-5,2,-4:17.12
-4,2,-4:17.12
-3,2,-4:17.12
-2,2,-4:17.12
-1,2,-4:17.12
0,2,-4:17.12
1,2,-4:17.12
2,2,-4:17.12
3,2,-4:17.12
-5,3,-4:17.12
-4,3,-4:17.12
-5,4,-4:17.12
-4,4,-4:17.12
-6,5,-4:17.12
-5,5,-4:17.12
-4,5,-4:17.12
-5,6,-4:17.12
1,-9,-3:17.12
-3,-8,-3:17.12
-2,-8,-3:17.12
0,-8,-3:17.12
1,-8,-3:17.12
2,-8,-3:17.12
3,-8,-3:17.12
-4,-7,-3:17.12
-3,-7,-3:17.12
-2,-7,-3:17.12
-1,-7,-3:17.12
0,-7,-3:17.12
1,-7,-3:17.12
2,-7,-3:17.12
3,-7,-3:17.12
4,-7,-3:17.12
-4,-6,-3:17.12
-3,-6,-3:17.12
-2,-6,-3:17.12
-1,-6,-3:17.12
0,-6,-3:17.12
1,-6,-3:17.12
2,-6,-3:17.12
3,-6,-3:17.12
4,-6,-3:17.12
-4,-5,-3:17.12
-3,-5,-3:17.12
-2,-5,-3:17.12
-1,-5,-3:17.12
0,-5,-3:17.12
1,-5,-3:17.12
2,-5,-3:17.12
3,-5,-3:17.12
4,-5,-3:17.12
-4,-4,-3:17.12
-3,-4,-3:17.12
-2,-4,-3:17.12
-1,-4,-3:17.12
0,-4,-3:17.12
1,-4,-3:17.12
2,-4,-3:17.12
3,-4,-3:17.12
4,-4,-3:17.12
-4,-3,-3:17.12
-3,-3,-3:17.12
-2,-3,-3:17.12
-1,-3,-3:17.12
0,-3,-3:17.12
1,-3,-3:17.12
2,-3,-3:17.12
3,-3,-3:17.12
4,-3,-3:17.12
-4,-2,-3:17.12
-3,-2,-3:17.12
-2,-2,-3:17.12
-1,-2,-3:17.12
0,-2,-3:17.12
1,-2,-3:17.12
2,-2,-3:17.12
3,-2,-3:17.12
-4,-1,-3:17.12
-3,-1,-3:17.12
-2,-1,-3:17.12
-1,-1,-3:17.12
0,-1,-3:17.12
1,-1,-3:17.12
2,-1,-3:17.12
3,-1,-3:17.12
-4,0,-3:17.12
-3,0,-3:17.12
-2,0,-3:17.12
-1,0,-3:17.12
0,0,-3:17.12
2,0,-3:17.12
-5,1,-3:17.12
-4,1,-3:17.12
-3,1,-3:17.12
-2,1,-3:17.12
-1,1,-3:17.12
1,1,-3:17.12
-5,2,-3:17.12
-5,3,-3:17.12
-1,-8,-2:17.12
-4,-7,-2:17.12
-3,-7,-2:17.12
-2,-7,-2:17.12
-1,-7,-2:17.12
0,-7,-2:17.12
1,-7,-2:17.12
2,-7,-2:17.12
-5,-6,-2:17.12
-4,-6,-2:17.12
-3,-6,-2:17.12
-2,-6,-2:17.12
-1,-6,-2:17.12
0,-6,-2:17.12
1,-6,-2:17.12
2,-6,-2:17.12
3,-6,-2:17.12
-5,-5,-2:17.12
-4,-5,-2:17.12
-3,-5,-2:17.12
-2,-5,-2:17.12
-1,-5,-2:17.12
0,-5,-2:17.12
1,-5,-2:17.12
2,-5,-2:17.12
3,-5,-2:17.12
4,-5,-2:17.12
-5,-4,-2:17.12
-4,-4,-2:17.12
-3,-4,-2:17.12
-2,-4,-2:17.12
-1,-4,-2:17.12
0,-4,-2:17.12
1,-4,-2:17.12
2,-4,-2:17.12
3,-4,-2:17.12
-4,-3,-2:17.12
-3,-3,-2:17.12
-2,-3,-2:17.12
-1,-3,-2:17.12
0,-3,-2:17.12
1,-3,-2:17.12
2,-3,-2:17.12
3,-3,-2:17.12
-4,-2,-2:17.12
-3,-2,-2:17.12
-2,-2,-2:17.12
-1,-2,-2:17.12
0,-2,-2:17.12
1,-2,-2:17.12
2,-2,-2:17.12
-4,-1,-2:17.12
-3,-1,-2:17.12
-2,-1,-2:17.12
-1,-1,-2:17.12
0,-1,-2:17.12
1,-1,-2:17.12
-3,0,-2:17.12
-2,0,-2:17.12
-1,0,-2:17.12
0,0,-2:17.12
-2,-8,-1:17.12
-1,-8,-1:17.12
-4,-7,-1:17.12
-3,-7,-1:17.12
-2,-7,-1:17.12
-1,-7,-1:17.12
0,-7,-1:17.12
-5,-6,-1:17.12
-4,-6,-1:17.12
-3,-6,-1:17.12
-2,-6,-1:17.12
-1,-6,-1:17.12
0,-6,-1:17.12
1,-6,-1:17.12
-5,-5,-1:17.12
-4,-5,-1:17.12
-3,-5,-1:17.12
-2,-5,-1:17.12
-1,-5,-1:17.12
0,-5,-1:17.12
1,-5,-1:17.12
2,-5,-1:17.12
-5,-4,-1:17.12
-4,-4,-1:17.12
-3,-4,-1:17.12
-2,-4,-1:17.12
-1,-4,-1:17.12
0,-4,-1:17.12
1,-4,-1:17.12
2,-4,-1:17.12
-4,-3,-1:17.12
-3,-3,-1:17.12
-2,-3,-1:17.12
-1,-3,-1:17.12
0,-3,-1:17.12
1,-3,-1:17.12
2,-3,-1:17.12
-5,-2,-1:17.12
-4,-2,-1:17.12
-3,-2,-1:17.12
-2,-2,-1:17.12
-1,-2,-1:17.12
0,-2,-1:17.12
1,-2,-1:17.12
-4,-1,-1:17.12
-3,-1,-1:17.12
-2,-1,-1:17.12
-1,-1,-1:17.12
0,-1,-1:17.12
-3,-8,0:17.12
-2,-8,0:17.12
-1,-8,0:17.12
-4,-7,0:17.12
-3,-7,0:17.12
-2,-7,0:17.12
-1,-7,0:17.12
0,-7,0:17.12
-5,-6,0:17.12
-4,-6,0:17.12
-3,-6,0:17.12
-2,-6,0:17.12
-1,-6,0:17.12
0,-6,0:17.12
1,-6,0:17.12
-5,-5,0:17.12
-4,-5,0:17.12
-3,-5,0:17.12
-2,-5,0:17.12
-1,-5,0:17.12
0,-5,0:17.12
1,-5,0:17.12
2,-5,0:17.12
-5,-4,0:17.12
-4,-4,0:17.12
-3,-4,0:17.12
-2,-4,0:17.12
-1,-4,0:17.12
0,-4,0:17.12
1,-4,0:17.12
2,-4,0:17.12
-5,-3,0:17.12
-4,-3,0:17.12
-3,-3,0:17.12
-2,-3,0:17.12
-1,-3,0:17.12
0,-3,0:17.12
1,-3,0:17.12
-5,-2,0:17.12
-4,-2,0:17.12
-3,-2,0:17.12
-2,-2,0:17.12
-1,-2,0:17.12
0,-2,0:17.12
1,-2,0:17.12
-4,-1,0:17.12
-2,-1,0:17.12
-1,-1,0:17.12
-3,-8,1:17.12
-2,-8,1:17.12
-1,-8,1:17.12
-4,-7,1:17.12
-3,-7,1:17.12
-2,-7,1:17.12
-1,-7,1:17.12
0,-7,1:17.12
-5,-6,1:17.12
-4,-6,1:17.12
-3,-6,1:17.12
-2,-6,1:17.12
-1,-6,1:17.12
0,-6,1:17.12
1,-6,1:17.12
-5,-5,1:17.12
-4,-5,1:17.12
-3,-5,1:17.12
-2,-5,1:17.12
-1,-5,1:17.12
0,-5,1:17.12
1,-5,1:17.12
-5,-4,1:17.12
-4,-4,1:17.12
-3,-4,1:17.12
-2,-4,1:17.12
-1,-4,1:17.12
0,-4,1:17.12
1,-4,1:17.12
-5,-3,1:17.12
-4,-3,1:17.12
-3,-3,1:17.12
-2,-3,1:17.12
-1,-3,1:17.12
0,-3,1:17.12
1,-3,1:17.12
-4,-2,1:17.12
-3,-2,1:17.12
-2,-2,1:17.12
-1,-2,1:17.12
0,-2,1:17.12
-2,-1,1:17.12
-1,-1,1:17.12
-3,-8,2:17.12
-2,-8,2:17.12
-1,-8,2:17.12
-4,-7,2:17.12
-3,-7,2:17.12
-2,-7,2:17.12
-1,-7,2:17.12
0,-7,2:17.12
-5,-6,2:17.12
-4,-6,2:17.12
-3,-6,2:17.12
-2,-6,2:17.12
-1,-6,2:17.12
0,-6,2:17.12
1,-6,2:17.12
-5,-5,2:17.12
-4,-5,2:17.12
-3,-5,2:17.12
-2,-5,2:17.12
-1,-5,2:17.12
0,-5,2:17.12
1,-5,2:17.12
-5,-4,2:17.12
-4,-4,2:17.12
-3,-4,2:17.12
-2,-4,2:17.12
-1,-4,2:17.12
0,-4,2:17.12
1,-4,2:17.12
-5,-3,2:17.12
-4,-3,2:17.12
-3,-3,2:17.12
-2,-3,2:17.12
-1,-3,2:17.12
0,-3,2:17.12
1,-3,2:17.12
-4,-2,2:17.12
-3,-2,2:17.12
-2,-2,2:17.12
-1,-2,2:17.12
0,-2,2:17.12
-3,-1,2:17.12
-2,-1,2:17.12
-1,-1,2:17.12
-3,-8,3:17.12
-2,-8,3:17.12
-1,-8,3:17.12
-4,-7,3:17.12
-3,-7,3:17.12
-2,-7,3:17.12
-1,-7,3:17.12
0,-7,3:17.12
-5,-6,3:17.12
-4,-6,3:17.12
-3,-6,3:17.12
-2,-6,3:17.12
-1,-6,3:17.12
0,-6,3:17.12
-5,-5,3:17.12
-4,-5,3:17.12
-3,-5,3:17.12
-2,-5,3:17.12
-1,-5,3:17.12
0,-5,3:17.12
1,-5,3:17.12
-5,-4,3:17.12
-4,-4,3:17.12
-3,-4,3:17.12
-2,-4,3:17.12
-1,-4,3:17.12
0,-4,3:17.12
1,-4,3:17.12
-5,-3,3:17.12
-4,-3,3:17.12
-3,-3,3:17.12
-2,-3,3:17.12
-1,-3,3:17.12
0,-3,3:17.12
1,-3,3:17.12
-5,-2,3:17.12
-4,-2,3:17.12
-3,-2,3:17.12
-2,-2,3:17.12
-1,-2,3:17.12
0,-2,3:17.12
-4,-1,3:17.12
-3,-1,3:17.12
-2,-1,3:17.12
-1,-1,3:17.12
-4,-7,4:17.12
-3,-7,4:17.12
-2,-7,4:17.12
-1,-7,4:17.12
-5,-6,4:17.12
-4,-6,4:17.12
-3,-6,4:17.12
-2,-6,4:17.12
-1,-6,4:17.12
0,-6,4:17.12
-5,-5,4:17.12
-4,-5,4:17.12
-3,-5,4:17.12
-2,-5,4:17.12
-1,-5,4:17.12
0,-5,4:17.12
1,-5,4:17.12
-6,-4,4:17.12
-5,-4,4:17.12
-4,-4,4:17.12
-3,-4,4:17.12
-2,-4,4:17.12
-1,-4,4:17.12
0,-4,4:17.12
1,-4,4:17.12
-5,-3,4:17.12
-4,-3,4:17.12
-3,-3,4:17.12
-2,-3,4:17.12
-1,-3,4:17.12
0,-3,4:17.12
1,-3,4:17.12
-5,-2,4:17.12
-4,-2,4:17.12
-3,-2,4:17.12
-2,-2,4:17.12
-1,-2,4:17.12
0,-2,4:17.12
-4,-1,4:17.12
-3,-1,4:17.12
-2,-1,4:17.12
-1,-1,4:17.12
-4,-7,5:17.12
-3,-7,5:17.12
-2,-7,5:17.12
-1,-7,5:17.12
-5,-6,5:17.12
-4,-6,5:17.12
-3,-6,5:17.12
-2,-6,5:17.12
-1,-6,5:17.12
0,-6,5:17.12
-6,-5,5:17.12
-5,-5,5:17.12
-4,-5,5:17.12
-3,-5,5:17.12
-2,-5,5:17.12
-1,-5,5:17.12
0,-5,5:17.12
-6,-4,5:17.12
-5,-4,5:17.12
-4,-4,5:17.12
-3,-4,5:17.12
-2,-4,5:17.12
-1,-4,5:17.12
0,-4,5:17.12
1,-4,5:17.12
-6,-3,5:17.12
-5,-3,5:17.12
-4,-3,5:17.12
-3,-3,5:17.12
-2,-3,5:17.12
-1,-3,5:17.12
0,-3,5:17.12
-5,-2,5:17.12
-4,-2,5:17.12
-3,-2,5:17.12
-2,-2,5:17.12
-1,-2,5:17.12
0,-2,5:17.12
-4,-1,5:17.12
-3,-1,5:17.12
-2,-1,5:17.12
-1,-1,5:17.12
-4,-7,6:17.12
-3,-7,6:17.12
-2,-7,6:17.12
-6,-6,6:17.12
-5,-6,6:17.12
-4,-6,6:17.12
-3,-6,6:17.12
-2,-6,6:17.12
-1,-6,6:17.12
0,-6,6:17.12
-6,-5,6:17.12
-5,-5,6:17.12
-4,-5,6:17.12
-3,-5,6:17.12
-2,-5,6:17.12
-1,-5,6:17.12
0,-5,6:17.12
-6,-4,6:17.12
-5,-4,6:17.12
-4,-4,6:17.12
-3,-4,6:17.12
-2,-4,6:17.12
-1,-4,6:17.12
0,-4,6:17.12
-6,-3,6:17.12
-5,-3,6:17.12
-4,-3,6:17.12
-3,-3,6:17.12
-2,-3,6:17.12
-1,-3,6:17.12
0,-3,6:17.12
-6,-2,6:17.12
-5,-2,6:17.12
-4,-2,6:17.12
-3,-2,6:17.12
-2,-2,6:17.12
-1,-2,6:17.12
0,-2,6:17.12
-5,-1,6:17.12
-4,-1,6:17.12
-3,-1,6:17.12
-2,-1,6:17.12
-1,-1,6:17.12
-4,-7,7:17.12
-3,-7,7:17.12
-2,-7,7:17.12
-6,-6,7:17.12
-5,-6,7:17.12
-4,-6,7:17.12
-3,-6,7:17.12
-2,-6,7:17.12
-1,-6,7:17.12
-6,-5,7:17.12
-5,-5,7:17.12
-4,-5,7:17.12
-3,-5,7:17.12
-2,-5,7:17.12
-1,-5,7:17.12
0,-5,7:17.12
-7,-4,7:17.12
-6,-4,7:17.12
-5,-4,7:17.12
-4,-4,7:17.12
-3,-4,7:17.12
-2,-4,7:17.12
-1,-4,7:17.12
0,-4,7:17.12
-6,-3,7:17.12
-5,-3,7:17.12
-4,-3,7:17.12
-3,-3,7:17.12
-2,-3,7:17.12
-1,-3,7:17.12
0,-3,7:17.12
-6,-2,7:17.12
-5,-2,7:17.12
-4,-2,7:17.12
-3,-2,7:17.12
-2,-2,7:17.12
-1,-2,7:17.12
-5,-1,7:17.12
-4,-1,7:17.12
-3,-1,7:17.12
-2,-1,7:17.12
-1,-1,7:17.12
-4,-7,8:17.12
-3,-7,8:17.12
-2,-7,8:17.12
-6,-6,8:17.12
-5,-6,8:17.12
-4,-6,8:17.12
-3,-6,8:17.12
-2,-6,8:17.12
-1,-6,8:17.12
-6,-5,8:17.12
-5,-5,8:17.12
-4,-5,8:17.12
-3,-5,8:17.12
-2,-5,8:17.12
-1,-5,8:17.12
-7,-4,8:17.12
-6,-4,8:17.12
-5,-4,8:17.12
-4,-4,8:17.12
-3,-4,8:17.12
-2,-4,8:17.12
-1,-4,8:17.12
-7,-3,8:17.12
-6,-3,8:17.12
-5,-3,8:17.12
-4,-3,8:17.12
-3,-3,8:17.12
-2,-3,8:17.12
-1,-3,8:17.12
-7,-2,8:17.12
-6,-2,8:17.12
-5,-2,8:17.12
-4,-2,8:17.12
-3,-2,8:17.12
-2,-2,8:17.12
-1,-2,8:17.12
-6,-1,8:17.12
-5,-1,8:17.12
-4,-1,8:17.12
-3,-1,8:17.12
-2,-1,8:17.12
-5,0,8:17.12
-4,0,8:17.12
-3,0,8:17.12
-4,-7,9:17.12
-3,-7,9:17.12
-6,-6,9:17.12
-5,-6,9:17.12
-4,-6,9:17.12
-3,-6,9:17.12
-2,-6,9:17.12
-1,-6,9:17.12
-7,-5,9:17.12
-6,-5,9:17.12
-5,-5,9:17.12
-4,-5,9:17.12
-3,-5,9:17.12
-2,-5,9:17.12
-1,-5,9:17.12
-7,-4,9:17.12
-6,-4,9:17.12
-5,-4,9:17.12
-4,-4,9:17.12
-3,-4,9:17.12
-2,-4,9:17.12
-1,-4,9:17.12
-7,-3,9:17.12
-6,-3,9:17.12
-5,-3,9:17.12
-4,-3,9:17.12
-3,-3,9:17.12
-2,-3,9:17.12
-1,-3,9:17.12
-7,-2,9:17.12
-6,-2,9:17.12
-5,-2,9:17.12
-4,-2,9:17.12
-3,-2,9:17.12
-2,-2,9:17.12
-1,-2,9:17.12
-7,-1,9:17.12
-6,-1,9:17.12
-5,-1,9:17.12
-4,-1,9:17.12
-3,-1,9:17.12
-2,-1,9:17.12
-6,0,9:17.12
-5,0,9:17.12
-4,0,9:17.12
-3,0,9:17.12
-6,-6,10:17.12
-5,-6,10:17.12
-4,-6,10:17.12
-3,-6,10:17.12
-2,-6,10:17.12
-7,-5,10:17.12
-6,-5,10:17.12
-5,-5,10:17.12
-4,-5,10:17.12
-3,-5,10:17.12
-2,-5,10:17.12
-1,-5,10:17.12
-7,-4,10:17.12
-6,-4,10:17.12
-5,-4,10:17.12
-4,-4,10:17.12
-3,-4,10:17.12
-2,-4,10:17.12
-1,-4,10:17.12
0,-4,10:17.12
-7,-3,10:17.12
-6,-3,10:17.12
-5,-3,10:17.12
-4,-3,10:17.12
-3,-3,10:17.12
-2,-3,10:17.12
-1,-3,10:17.12
0,-3,10:17.12
-7,-2,10:17.12
-6,-2,10:17.12
-5,-2,10:17.12
-4,-2,10:17.12
-3,-2,10:17.12
-2,-2,10:17.12
-1,-2,10:17.12
0,-2,10:17.12
-7,-1,10:17.12
-6,-1,10:17.12
-5,-1,10:17.12
-4,-1,10:17.12
-3,-1,10:17.12
-2,-1,10:17.12
-1,-1,10:17.12
0,-1,10:17.12
1,-1,10:17.12
-6,0,10:17.12
-5,0,10:17.12
-4,0,10:17.12
-3,0,10:17.12
-2,0,10:17.12
-1,0,10:17.12
0,0,10:17.12
1,0,10:17.12
2,0,10:17.12
-4,1,10:17.12
-5,-6,11:17.12
-4,-6,11:17.12
-3,-6,11:17.12
-7,-5,11:17.12
-6,-5,11:17.12
-5,-5,11:17.12
-4,-5,11:17.12
-3,-5,11:17.12
-2,-5,11:17.12
-7,-4,11:17.12
-6,-4,11:17.12
-5,-4,11:17.12
-4,-4,11:17.12
-3,-4,11:17.12
-2,-4,11:17.12
-1,-4,11:17.12
0,-4,11:17.12
-7,-3,11:17.12
-6,-3,11:17.12
-5,-3,11:17.12
-4,-3,11:17.12
-3,-3,11:17.12
-2,-3,11:17.12
-1,-3,11:17.12
0,-3,11:17.12
1,-3,11:17.12
-7,-2,11:17.12
-6,-2,11:17.12
-5,-2,11:17.12
-4,-2,11:17.12
-3,-2,11:17.12
-2,-2,11:17.12
-1,-2,11:17.12
0,-2,11:17.12
1,-2,11:17.12
2,-2,11:17.12
-7,-1,11:17.12
-6,-1,11:17.12
-5,-1,11:17.12
-4,-1,11:17.12
-3,-1,11:17.12
-2,-1,11:17.12
-1,-1,11:17.12
0,-1,11:17.12
1,-1,11:17.12
2,-1,11:17.12
3,-1,11:17.12
-6,0,11:17.12
-5,0,11:17.12
-4,0,11:17.12
-3,0,11:17.12
-2,0,11:17.12
-1,0,11:17.12
0,0,11:17.12
1,0,11:17.12
2,0,11:17.12
3,0,11:17.12
-5,1,11:17.12
-4,1,11:17.12
-3,1,11:17.12
0,1,11:17.12
1,1,11:17.12
-5,-6,12:17.12
-4,-6,12:17.12
-3,-6,12:17.12
-6,-5,12:17.12
-5,-5,12:17.12
-4,-5,12:17.12
-3,-5,12:17.12
-2,-5,12:17.12
-1,-5,12:17.12
-7,-4,12:17.12
-6,-4,12:17.12
-5,-4,12:17.12
-4,-4,12:17.12
-3,-4,12:17.12
-2,-4,12:17.12
-1,-4,12:17.12
0,-4,12:17.12
-7,-3,12:17.12
-6,-3,12:17.12
-5,-3,12:17.12
-4,-3,12:17.12
-3,-3,12:17.12
-2,-3,12:17.12
-1,-3,12:17.12
0,-3,12:17.12
1,-3,12:17.12
2,-3,12:17.12
-7,-2,12:17.12
-6,-2,12:17.12
-5,-2,12:17.12
-4,-2,12:17.12
-3,-2,12:17.12
-2,-2,12:17.12
-1,-2,12:17.12
0,-2,12:17.12
1,-2,12:17.12
2,-2,12:17.12
3,-2,12:17.12
4,-2,12:17.12
5,-2,12:17.12
-7,-1,12:17.12
-6,-1,12:17.12
-5,-1,12:17.12
-4,-1,12:17.12
-3,-1,12:17.12
-2,-1,12:17.12
-1,-1,12:17.12
0,-1,12:17.12
1,-1,12:17.12
2,-1,12:17.12
3,-1,12:17.12
4,-1,12:17.12
5,-1,12:17.12
-7,0,12:17.12
-6,0,12:17.12
-5,0,12:17.12
-4,0,12:17.12
-3,0,12:17.12
-2,0,12:17.12
-1,0,12:17.12
0,0,12:17.12
1,0,12:17.12
2,0,12:17.12
3,0,12:17.12
4,0,12:17.12
-6,1,12:17.12
-5,1,12:17.12
-4,1,12:17.12
-3,1,12:17.12
-1,1,12:17.12
0,1,12:17.12
1,1,12:17.12
2,1,12:17.12
-6,-5,13:17.12
-5,-5,13:17.12
-4,-5,13:17.12
-3,-5,13:17.12
-7,-4,13:17.12
-6,-4,13:17.12
-5,-4,13:17.12
-4,-4,13:17.12
-3,-4,13:17.12
-2,-4,13:17.12
-1,-4,13:17.12
0,-4,13:17.12
-7,-3,13:17.12
-6,-3,13:17.12
-5,-3,13:17.12
-4,-3,13:17.12
-3,-3,13:17.12
-2,-3,13:17.12
-1,-3,13:17.12
0,-3,13:17.12
1,-3,13:17.12
2,-3,13:17.12
3,-3,13:17.12
-7,-2,13:17.12
-6,-2,13:17.12
-5,-2,13:17.12
-4,-2,13:17.12
-3,-2,13:17.12
-2,-2,13:17.12
-1,-2,13:17.12
0,-2,13:17.12
1,-2,13:17.12
2,-2,13:17.12
3,-2,13:17.12
4,-2,13:17.12
5,-2,13:17.12
6,-2,13:17.12
7,-2,13:17.12
-7,-1,13:17.12
-6,-1,13:17.12
-5,-1,13:17.12
-4,-1,13:17.12
-3,-1,13:17.12
-2,-1,13:17.12
-1,-1,13:17.12
0,-1,13:17.12
1,-1,13:17.12
2,-1,13:17.12
3,-1,13:17.12
4,-1,13:17.12
5,-1,13:17.12
6,-1,13:17.12
7,-1,13:17.12
8,-1,13:17.12
-7,0,13:17.12
-6,0,13:17.12
-5,0,13:17.12
-4,0,13:17.12
-3,0,13:17.12
-2,0,13:17.12
-1,0,13:17.12
0,0,13:17.12
1,0,13:17.12
2,0,13:17.12
3,0,13:17.12
4,0,13:17.12
5,0,13:17.12
6,0,13:17.12
7,0,13:17.12
-6,1,13:17.12
-5,1,13:17.12
-4,1,13:17.12
-3,1,13:17.12
-2,1,13:17.12
-1,1,13:17.12
0,1,13:17.12
1,1,13:17.12
2,1,13:17.12
3,1,13:17.12
4,1,13:17.12
-5,-5,14:17.12
-4,-5,14:17.12
-3,-5,14:17.12
-7,-4,14:17.12
-6,-4,14:17.12
-5,-4,14:17.12
-4,-4,14:17.12
-3,-4,14:17.12
-2,-4,14:17.12
-1,-4,14:17.12
0,-4,14:17.12
-7,-3,14:17.12
-6,-3,14:17.12
-5,-3,14:17.12
-4,-3,14:17.12
-3,-3,14:17.12
-2,-3,14:17.12
-1,-3,14:17.12
0,-3,14:17.12
1,-3,14:17.12
2,-3,14:17.12
3,-3,14:17.12
-7,-2,14:17.12
-6,-2,14:17.12
-5,-2,14:17.12
-4,-2,14:17.12
-3,-2,14:17.12
-2,-2,14:17.12
-1,-2,14:17.12
0,-2,14:17.12
1,-2,14:17.12
2,-2,14:17.12
3,-2,14:17.12
4,-2,14:17.12
5,-2,14:17.12
6,-2,14:17.12
7,-2,14:17.12
-7,-1,14:17.12
-6,-1,14:17.12
-5,-1,14:17.12
-4,-1,14:17.12
-3,-1,14:17.12
-2,-1,14:17.12
-1,-1,14:17.12
0,-1,14:17.12
1,-1,14:17.12
2,-1,14:17.12
3,-1,14:17.12
4,-1,14:17.12
5,-1,14:17.12
6,-1,14:17.12
7,-1,14:17.12
8,-1,14:17.12
-7,0,14:17.12
-6,0,14:17.12
-5,0,14:17.12
-4,0,14:17.12
-3,0,14:17.12
-2,0,14:17.12
-1,0,14:17.12
0,0,14:17.12
1,0,14:17.12
2,0,14:17.12
3,0,14:17.12
4,0,14:17.12
5,0,14:17.12
6,0,14:17.12
7,0,14:17.12
8,0,14:17.12
-6,1,14:17.12
-5,1,14:17.12
-4,1,14:17.12
-3,1,14:17.12
-2,1,14:17.12
-1,1,14:17.12
0,1,14:17.12
1,1,14:17.12
2,1,14:17.12
3,1,14:17.12
4,1,14:17.12
5,1,14:17.12
6,1,14:17.12
7,1,14:17.12
-5,2,14:17.12
-4,2,14:17.12
-3,2,14:17.12
-6,-4,15:17.12
-5,-4,15:17.12
-4,-4,15:17.12
-3,-4,15:17.12
-2,-4,15:17.12
-7,-3,15:17.12
-6,-3,15:17.12
-5,-3,15:17.12
-4,-3,15:17.12
-3,-3,15:17.12
-2,-3,15:17.12
-1,-3,15:17.12
0,-3,15:17.12
1,-3,15:17.12
2,-3,15:17.12
-7,-2,15:17.12
-6,-2,15:17.12
-5,-2,15:17.12
-4,-2,15:17.12
-3,-2,15:17.12
-2,-2,15:17.12
-1,-2,15:17.12
0,-2,15:17.12
1,-2,15:17.12
2,-2,15:17.12
3,-2,15:17.12
4,-2,15:17.12
5,-2,15:17.12
-7,-1,15:17.12
-6,-1,15:17.12
-5,-1,15:17.12
-4,-1,15:17.12
-3,-1,15:17.12
-2,-1,15:17.12
-1,-1,15:17.12
0,-1,15:17.12
1,-1,15:17.12
2,-1,15:17.12
3,-1,15:17.12
4,-1,15:17.12
5,-1,15:17.12
6,-1,15:17.12
7,-1,15:17.12
8,-1,15:17.12
9,-1,15:17.12
10,-1,15:17.12
-7,0,15:17.12
-6,0,15:17.12
-5,0,15:17.12
-4,0,15:17.12
-3,0,15:17.12
-2,0,15:17.12
-1,0,15:17.12
0,0,15:17.12
1,0,15:17.12
2,0,15:17.12
3,0,15:17.12
4,0,15:17.12
5,0,15:17.12
6,0,15:17.12
7,0,15:17.12
8,0,15:17.12
9,0,15:17.12
-7,1,15:17.12
-6,1,15:17.12
-5,1,15:17.12
-4,1,15:17.12
-3,1,15:17.12
-2,1,15:17.12
0,1,15:17.12
1,1,15:17.12
2,1,15:17.12
4,1,15:17.12
5,1,15:17.12
6,1,15:17.12
7,1,15:17.12
8,1,15:17.12
9,1,15:17.12
-6,2,15:17.12
-5,2,15:17.12
-4,2,15:17.12
-3,2,15:17.12
7,2,15:17.12
8,2,15:17.12
-6,-4,16:17.12
-5,-4,16:17.12
-4,-4,16:17.12
-3,-4,16:17.12
-2,-4,16:17.12
-7,-3,16:17.12
-6,-3,16:17.12
-5,-3,16:17.12
-4,-3,16:17.12
-3,-3,16:17.12
-2,-3,16:17.12
-1,-3,16:17.12
-7,-2,16:17.12
-6,-2,16:17.12
-5,-2,16:17.12
-4,-2,16:17.12
-3,-2,16:17.12
-2,-2,16:17.12
-1,-2,16:17.12
-7,-1,16:17.12
-6,-1,16:17.12
-5,-1,16:17.12
-4,-1,16:17.12
-3,-1,16:17.12
-2,-1,16:17.12
-1,-1,16:17.12
4,-1,16:17.12
5,-1,16:17.12
6,-1,16:17.12
7,-1,16:17.12
-7,0,16:17.12
-6,0,16:17.12
-5,0,16:17.12
-4,0,16:17.12
-3,0,16:17.12
-2,0,16:17.12
-1,0,16:17.12
4,0,16:17.12
5,0,16:17.12
6,0,16:17.12
7,0,16:17.12
8,0,16:17.12
9,0,16:17.12
11,0,16:17.12
-7,1,16:17.12
-6,1,16:17.12
-5,1,16:17.12
-4,1,16:17.12
-3,1,16:17.12
-2,1,16:17.12
5,1,16:17.12
6,1,16:17.12
7,1,16:17.12
8,1,16:17.12
9,1,16:17.12
10,1,16:17.12
-6,2,16:17.12
-5,2,16:17.12
-4,2,16:17.12
-3,2,16:17.12
-2,2,16:17.12
6,2,16:17.12
7,2,16:17.12
8,2,16:17.12
9,2,16:17.12
10,2,16:17.12
11,2,16:17.12
12,2,16:17.12
9,3,16:17.12
10,3,16:17.12
11,3,16:17.12
11,4,16:17.12
21,4,16:18.12
22,4,16:18.12
23,4,16:18.12
24,4,16:18.12
17,5,16:18.12
21,5,16:18.12
17,6,16:18.12
23,8,16:18.12
18,9,16:18.12
23,9,16:18.12
19,10,16:18.12
-6,-4,17:17.12
-5,-4,17:17.12
-4,-4,17:17.12
-3,-4,17:17.12
-2,-4,17:17.12
-7,-3,17:17.12
-6,-3,17:17.12
-5,-3,17:17.12
-4,-3,17:17.12
-3,-3,17:17.12
-2,-3,17:17.12
-1,-3,17:17.12
25,-3,17:18.12
-7,-2,17:17.12
-6,-2,17:17.12
-5,-2,17:17.12
-4,-2,17:17.12
-3,-2,17:17.12
-2,-2,17:17.12
-1,-2,17:17.12
-7,-1,17:17.12
-6,-1,17:17.12
-5,-1,17:17.12
-4,-1,17:17.12
-3,-1,17:17.12
-2,-1,17:17.12
-1,-1,17:17.12
-7,0,17:17.12
-6,0,17:17.12
-5,0,17:17.12
-4,0,17:17.12
-3,0,17:17.12
-2,0,17:17.12
-1,0,17:17.12
8,0,17:17.12
-7,1,17:17.12
-6,1,17:17.12
-5,1,17:17.12
-4,1,17:17.12
-3,1,17:17.12
-2,1,17:17.12
-1,1,17:17.12
7,1,17:17.12
8,1,17:17.12
9,1,17:17.12
10,1,17:17.12
11,1,17:17.12
-6,2,17:17.12
-5,2,17:17.12
-4,2,17:17.12
-3,2,17:17.12
-2,2,17:17.12
8,2,17:17.12
9,2,17:17.12
10,2,17:17.12
11,2,17:17.12
12,2,17:17.12
22,2,17:18.12
9,3,17:17.12
10,3,17:17.12
11,3,17:17.12
12,3,17:17.12
13,3,17:17.12
20,3,17:18.12
22,3,17:18.12
23,3,17:18.12
24,3,17:18.12
10,4,17:17.12
11,4,17:17.12
12,4,17:17.12
13,4,17:17.12
14,4,17:17.12
21,4,17:18.12
22,4,17:18.12
11,5,17:17.12
21,5,17:18.12
17,6,17:18.12
17,7,17:18.12
18,7,17:18.12
23,8,17:18.12
18,9,17:18.12
18,10,17:18.12
19,10,17:18.12
25,-5,18:18.12
-6,-4,18:17.12
-5,-4,18:17.12
-4,-4,18:17.12
-3,-4,18:17.12
-2,-4,18:17.12
24,-4,18:18.12
25,-4,18:18.12
-7,-3,18:17.12
-6,-3,18:17.12
-5,-3,18:17.12
-4,-3,18:17.12
-3,-3,18:17.12
-2,-3,18:17.12
-1,-3,18:17.12
24,-3,18:18.12
25,-3,18:18.12
26,-3,18:18.12
-7,-2,18:17.12
-6,-2,18:17.12
-5,-2,18:17.12
-4,-2,18:17.12
-3,-2,18:17.12
-2,-2,18:17.12
-1,-2,18:17.12
25,-2,18:18.12
-7,-1,18:17.12
-6,-1,18:17.12
-5,-1,18:17.12
-4,-1,18:17.12
-3,-1,18:17.12
-2,-1,18:17.12
-1,-1,18:17.12
24,-1,18:18.12
25,-1,18:18.12
-7,0,18:17.12
-6,0,18:17.12
-5,0,18:17.12
-4,0,18:17.12
-3,0,18:17.12
-2,0,18:17.12
-1,0,18:17.12
-7,1,18:17.12
-6,1,18:17.12
-5,1,18:17.12
-4,1,18:17.12
-3,1,18:17.12
-2,1,18:17.12
-1,1,18:17.12
19,1,18:18.12
20,1,18:18.12
21,1,18:18.12
22,1,18:18.12
-6,2,18:17.12
-5,2,18:17.12
-4,2,18:17.12
-3,2,18:17.12
-2,2,18:17.12
10,2,18:17.12
11,2,18:17.12
12,2,18:17.12
13,2,18:17.12
14,2,18:17.12
20,2,18:18.12
22,2,18:18.12
23,2,18:18.12
9,3,18:17.12
10,3,18:17.12
11,3,18:17.12
12,3,18:17.12
13,3,18:17.12
14,3,18:17.12
15,3,18:17.12
18,3,18:18.12
19,3,18:18.12
20,3,18:18.12
21,3,18:18.12
22,3,18:18.12
23,3,18:18.12
24,3,18:18.12
25,3,18:18.12
26,3,18:18.12
10,4,18:17.12
11,4,18:18.12
12,4,18:17.12
13,4,18:17.12
14,4,18:17.12
15,4,18:17.12
19,4,18:18.12
20,4,18:18.12
21,4,18:18.12
23,4,18:18.12
12,5,18:17.12
13,5,18:17.12
14,5,18:17.12
15,5,18:17.12
16,5,18:18.12
18,5,18:18.12
21,5,18:18.12
22,5,18:18.12
23,5,18:18.12
16,6,18:18.12
17,6,18:18.12
19,6,18:18.12
22,6,18:18.12
23,6,18:18.12
16,7,18:18.12
17,7,18:18.12
18,7,18:18.12
19,7,18:18.12
23,7,18:18.12
24,7,18:18.12
22,8,18:18.12
23,8,18:18.12
22,9,18:18.12
23,9,18:18.12
25,9,18:18.12
19,10,18:18.12
20,10,18:18.12
22,10,18:18.12
23,10,18:18.12
17,13,18:18.12
24,13,18:18.12
26,-8,19:18.12
28,-8,19:18.12
23,-7,19:18.12
24,-7,19:18.12
25,-7,19:18.12
26,-7,19:18.12
25,-6,19:18.12
26,-6,19:18.12
24,-5,19:18.12
25,-5,19:18.12
-6,-4,19:17.12
-5,-4,19:17.12
-4,-4,19:17.12
-3,-4,19:17.12
-2,-4,19:17.12
21,-4,19:18.12
24,-4,19:18.12
25,-4,19:18.12
-7,-3,19:17.12
-6,-3,19:17.12
-5,-3,19:17.12
-4,-3,19:17.12
-3,-3,19:17.12
-2,-3,19:17.12
-1,-3,19:17.12
21,-3,19:18.12
22,-3,19:18.12
24,-3,19:18.12
25,-3,19:18.12
26,-3,19:18.12
-7,-2,19:17.12
-6,-2,19:17.12
-5,-2,19:17.12
-4,-2,19:17.12
-3,-2,19:17.12
-2,-2,19:17.12
-1,-2,19:17.12
18,-2,19:18.12
19,-2,19:18.12
20,-2,19:18.12
23,-2,19:18.12
24,-2,19:18.12
26,-2,19:18.12
27,-2,19:18.12
-8,-1,19:17.12
-7,-1,19:17.12
-6,-1,19:17.12
-5,-1,19:17.12
-4,-1,19:17.12
-3,-1,19:17.12
-2,-1,19:17.12
-1,-1,19:17.12
19,-1,19:18.12
27,-1,19:18.12
28,-1,19:18.12
29,-1,19:18.12
-7,0,19:17.12
-6,0,19:17.12
-5,0,19:17.12
-4,0,19:17.12
-3,0,19:17.12
-2,0,19:17.12
-1,0,19:17.12
25,0,19:18.12
27,0,19:18.12
-7,1,19:17.12
-6,1,19:17.12
-5,1,19:17.12
-4,1,19:17.12
-3,1,19:17.12
-2,1,19:17.12
20,1,19:18.12
23,1,19:18.12
27,1,19:18.12
-6,2,19:17.12
-5,2,19:17.12
-4,2,19:17.12
-3,2,19:17.12
19,2,19:18.12
20,2,19:18.12
21,2,19:18.12
22,2,19:18.12
23,2,19:18.12
24,2,19:18.12
25,2,19:18.12
11,3,19:17.12
12,3,19:17.12
13,3,19:17.12
14,3,19:17.12
15,3,19:17.12
18,3,19:18.12
19,3,19:18.12
20,3,19:18.12
21,3,19:18.12
22,3,19:18.12
23,3,19:18.12
24,3,19:18.12
25,3,19:18.12
26,3,19:18.12
11,4,19:18.12
12,4,19:17.12
13,4,19:17.12
14,4,19:17.12
15,4,19:17.12
16,4,19:17.12
17,4,19:17.12
18,4,19:18.12
20,4,19:18.12
21,4,19:18.12
22,4,19:18.12
23,4,19:18.12
24,4,19:18.12
27,4,19:18.12
28,4,19:18.12
11,5,19:18.12
12,5,19:17.12
13,5,19:17.12
14,5,19:17.12
15,5,19:18.12
16,5,19:17.12
17,5,19:17.12
18,5,19:18.12
20,5,19:18.12
21,5,19:18.12
22,5,19:18.12
24,5,19:18.12
27,5,19:18.12
32,5,19:18.12
11,6,19:18.12
15,6,19:18.12
16,6,19:18.12
17,6,19:18.12
19,6,19:18.12
20,6,19:18.12
21,6,19:18.12
22,6,19:18.12
24,6,19:18.12
32,6,19:18.12
16,7,19:17.12
17,7,19:18.12
18,7,19:18.12
19,7,19:18.12
20,7,19:18.12
22,7,19:18.12
23,7,19:18.12
18,8,19:18.12
20,8,19:18.12
22,8,19:18.12
23,8,19:18.12
24,8,19:18.12
20,9,19:18.12
21,9,19:18.12
22,9,19:18.12
23,9,19:18.12
24,9,19:18.12
25,9,19:18.12
18,10,19:18.12
19,10,19:18.12
20,10,19:18.12
22,10,19:18.12
23,10,19:18.12
24,10,19:18.12
23,11,19:18.12
16,12,19:18.12
17,12,19:18.12
19,12,19:18.12
21,12,19:18.12
22,12,19:18.12
17,13,19:18.12
22,13,19:18.12
24,13,19:18.12
26,13,19:18.12
27,13,19:18.12
17,14,19:18.12
23,15,19:18.12
24,15,19:18.12
22,16,19:18.12
23,16,19:18.12
28,-9,20:18.12
26,-8,20:18.12
28,-8,20:18.12
25,-7,20:18.12
26,-7,20:18.12
27,-7,20:18.12
28,-7,20:18.12
24,-6,20:18.12
25,-6,20:18.12
26,-6,20:18.12
20,-5,20:18.12
21,-5,20:18.12
24,-5,20:18.12
25,-5,20:18.12
26,-5,20:18.12
27,-5,20:18.12
-5,-4,20:17.12
-4,-4,20:17.12
-3,-4,20:17.12
18,-4,20:18.12
19,-4,20:18.12
20,-4,20:18.12
21,-4,20:18.12
22,-4,20:18.12
23,-4,20:18.12
24,-4,20:18.12
25,-4,20:18.12
26,-4,20:18.12
-7,-3,20:17.12
-6,-3,20:17.12
-5,-3,20:17.12
-4,-3,20:17.12
-3,-3,20:17.12
-2,-3,20:17.12
18,-3,20:18.12
20,-3,20:18.12
21,-3,20:18.12
22,-3,20:18.12
24,-3,20:18.12
25,-3,20:18.12
26,-3,20:18.12
28,-3,20:18.12
-7,-2,20:17.12
-6,-2,20:17.12
-5,-2,20:17.12
-4,-2,20:17.12
-3,-2,20:17.12
-2,-2,20:17.12
-1,-2,20:17.12
17,-2,20:18.12
18,-2,20:18.12
19,-2,20:18.12
20,-2,20:18.12
22,-2,20:18.12
23,-2,20:18.12
24,-2,20:18.12
25,-2,20:18.12
26,-2,20:18.12
27,-2,20:18.12
28,-2,20:18.12
-8,-1,20:17.12
-7,-1,20:17.12
-6,-1,20:17.12
-5,-1,20:17.12
-4,-1,20:17.12
-3,-1,20:17.12
-2,-1,20:17.12
-1,-1,20:17.12
19,-1,20:18.12
20,-1,20:18.12
21,-1,20:18.12
22,-1,20:18.12
24,-1,20:18.12
25,-1,20:18.12
26,-1,20:18.12
27,-1,20:18.12
28,-1,20:18.12
29,-1,20:18.12
-8,0,20:17.12
-7,0,20:17.12
-6,0,20:17.12
-5,0,20:17.12
-4,0,20:17.12
-3,0,20:17.12
-2,0,20:17.12
-1,0,20:17.12
20,0,20:18.12
21,0,20:18.12
22,0,20:18.12
23,0,20:18.12
24,0,20:18.12
25,0,20:18.12
26,0,20:18.12
27,0,20:18.12
-8,1,20:17.12
-7,1,20:17.12
-6,1,20:17.12
-5,1,20:17.12
-4,1,20:17.12
-3,1,20:17.12
-2,1,20:17.12
20,1,20:18.12
21,1,20:18.12
22,1,20:18.12
23,1,20:18.12
24,1,20:18.12
25,1,20:18.12
26,1,20:18.12
28,1,20:18.12
-7,2,20:17.12
-6,2,20:17.12
-5,2,20:17.12
-4,2,20:17.12
-3,2,20:17.12
17,2,20:18.12
19,2,20:18.12
20,2,20:18.12
21,2,20:18.12
22,2,20:18.12
23,2,20:18.12
24,2,20:18.12
25,2,20:18.12
26,2,20:18.12
27,2,20:18.12
28,2,20:18.12
-6,3,20:17.12
-5,3,20:17.12
-4,3,20:17.12
14,3,20:17.12
16,3,20:18.12
17,3,20:18.12
18,3,20:18.12
19,3,20:18.12
20,3,20:18.12
21,3,20:18.12
22,3,20:18.12
23,3,20:18.12
24,3,20:18.12
25,3,20:18.12
26,3,20:18.12
27,3,20:18.12
28,3,20:18.12
11,4,20:18.12
12,4,20:18.12
13,4,20:17.12
14,4,20:17.12
15,4,20:17.12
16,4,20:17.12
18,4,20:18.12
19,4,20:18.12
20,4,20:18.12
21,4,20:18.12
22,4,20:18.12
23,4,20:18.12
24,4,20:18.12
26,4,20:18.12
27,4,20:18.12
28,4,20:18.12
30,4,20:18.12
31,4,20:18.12
10,5,20:18.12
11,5,20:18.12
12,5,20:18.12
14,5,20:18.12
15,5,20:17.12
16,5,20:17.12
17,5,20:17.12
18,5,20:18.12
19,5,20:18.12
20,5,20:18.12
21,5,20:18.12
22,5,20:18.12
23,5,20:18.12
24,5,20:18.12
25,5,20:18.12
26,5,20:18.12
27,5,20:18.12
28,5,20:18.12
29,5,20:18.12
32,5,20:18.12
11,6,20:18.12
12,6,20:18.12
13,6,20:18.12
14,6,20:18.12
15,6,20:18.12
16,6,20:18.12
17,6,20:18.12
18,6,20:18.12
19,6,20:18.12
20,6,20:18.12
21,6,20:18.12
22,6,20:18.12
23,6,20:18.12
24,6,20:18.12
25,6,20:18.12
26,6,20:18.12
28,6,20:18.12
29,6,20:18.12
31,6,20:18.12
32,6,20:18.12
13,7,20:18.12
14,7,20:18.12
15,7,20:17.12
16,7,20:18.12
17,7,20:18.12
18,7,20:18.12
19,7,20:18.12
20,7,20:18.12
21,7,20:18.12
22,7,20:18.12
23,7,20:18.12
24,7,20:18.12
30,7,20:18.12
31,7,20:18.12
32,7,20:18.12
16,8,20:18.12
17,8,20:17.12
18,8,20:18.12
20,8,20:18.12
21,8,20:18.12
22,8,20:18.12
23,8,20:18.12
24,8,20:18.12
29,8,20:18.12
16,9,20:18.12
22,9,20:18.12
23,9,20:18.12
29,9,20:18.12
18,10,20:18.12
19,10,20:18.12
22,10,20:18.12
23,10,20:18.12
24,10,20:18.12
17,11,20:18.12
18,11,20:18.12
19,11,20:18.12
21,11,20:18.12
22,11,20:18.12
23,11,20:18.12
17,12,20:18.12
18,12,20:18.12
19,12,20:18.12
20,12,20:18.12
22,12,20:18.12
23,12,20:18.12
27,12,20:18.12
17,13,20:18.12
18,13,20:18.12
19,13,20:18.12
20,13,20:18.12
22,13,20:18.12
23,13,20:18.12
24,13,20:18.12
26,13,20:18.12
27,13,20:18.12
22,14,20:18.12
23,14,20:18.12
27,14,20:18.12
29,14,20:18.12
23,15,20:18.12
24,15,20:18.12
26,15,20:18.12
27,15,20:18.12
18,17,20:18.12
19,17,20:18.12
24,18,20:18.12
15,19,20:18.12
16,19,20:18.12
17,19,20:18.12
17,21,20:18.12
18,22,20:18.12
26,-9,21:18.12
25,-8,21:18.12
26,-8,21:18.12
25,-7,21:18.12
20,-6,21:18.12
22,-6,21:18.12
23,-6,21:18.12
25,-6,21:18.12
27,-6,21:18.12
20,-5,21:18.12
21,-5,21:18.12
23,-5,21:18.12
24,-5,21:18.12
25,-5,21:18.12
26,-5,21:18.12
-5,-4,21:17.12
-4,-4,21:17.12
-3,-4,21:17.12
18,-4,21:18.12
21,-4,21:18.12
22,-4,21:18.12
23,-4,21:18.12
24,-4,21:18.12
25,-4,21:18.12
26,-4,21:18.12
27,-4,21:18.12
-7,-3,21:17.12
-6,-3,21:17.12
-5,-3,21:17.12
-4,-3,21:17.12
-3,-3,21:17.12
-2,-3,21:17.12
17,-3,21:18.12
18,-3,21:18.12
19,-3,21:18.12
20,-3,21:18.12
21,-3,21:18.12
22,-3,21:18.12
23,-3,21:18.12
24,-3,21:18.12
25,-3,21:18.12
26,-3,21:18.12
-8,-2,21:17.12
-7,-2,21:17.12
-6,-2,21:17.12
-5,-2,21:17.12
-4,-2,21:17.12
-3,-2,21:17.12
-2,-2,21:17.12
-1,-2,21:17.12
18,-2,21:18.12
19,-2,21:18.12
20,-2,21:18.12
21,-2,21:18.12
22,-2,21:18.12
23,-2,21:18.12
24,-2,21:18.12
25,-2,21:18.12
26,-2,21:18.12
28,-2,21:18.12
-8,-1,21:17.12
-7,-1,21:17.12
-6,-1,21:17.12
-5,-1,21:17.12
-4,-1,21:17.12
-3,-1,21:17.12
-2,-1,21:17.12
-1,-1,21:17.12
18,-1,21:18.12
19,-1,21:18.12
20,-1,21:18.12
21,-1,21:18.12
22,-1,21:18.12
24,-1,21:18.12
25,-1,21:18.12
26,-1,21:18.12
27,-1,21:18.12
28,-1,21:18.12
-8,0,21:17.12
-7,0,21:17.12
-6,0,21:17.12
-5,0,21:17.12
-4,0,21:17.12
-3,0,21:17.12
-2,0,21:17.12
-1,0,21:17.12
19,0,21:18.12
20,0,21:18.12
21,0,21:18.12
22,0,21:18.12
23,0,21:18.12
24,0,21:18.12
25,0,21:18.12
26,0,21:18.12
27,0,21:18.12
28,0,21:18.12
-8,1,21:17.12
-7,1,21:17.12
-6,1,21:17.12
-5,1,21:17.12
-4,1,21:17.12
-3,1,21:17.12
-2,1,21:17.12
18,1,21:18.12
19,1,21:18.12
20,1,21:18.12
21,1,21:18.12
22,1,21:18.12
23,1,21:18.12
24,1,21:18.12
25,1,21:18.12
26,1,21:18.12
27,1,21:18.12
28,1,21:18.12
-8,2,21:17.12
-7,2,21:17.12
-6,2,21:17.12
-5,2,21:17.12
-4,2,21:17.12
-3,2,21:17.12
18,2,21:18.12
19,2,21:18.12
20,2,21:18.12
21,2,21:18.12
22,2,21:18.12
23,2,21:18.12
24,2,21:18.12
25,2,21:18.12
26,2,21:18.12
27,2,21:18.12
28,2,21:18.12
29,2,21:18.12
-7,3,21:17.12
-6,3,21:17.12
-5,3,21:17.12
-4,3,21:17.12
17,3,21:18.12
19,3,21:18.12
20,3,21:18.12
21,3,21:18.12
22,3,21:18.12
23,3,21:18.12
25,3,21:18.12
26,3,21:18.12
27,3,21:18.12
28,3,21:18.12
29,3,21:18.12
10,4,21:18.12
11,4,21:18.12
12,4,21:18.12
16,4,21:18.12
17,4,21:18.12
18,4,21:18.12
19,4,21:18.12
22,4,21:18.12
23,4,21:18.12
24,4,21:18.12
26,4,21:18.12
27,4,21:18.12
29,4,21:18.12
30,4,21:18.12
31,4,21:18.12
32,4,21:18.12
15,5,21:18.12
16,5,21:18.12
17,5,21:18.12
18,5,21:18.12
19,5,21:18.12
20,5,21:18.12
21,5,21:18.12
22,5,21:18.12
23,5,21:18.12
24,5,21:18.12
25,5,21:18.12
26,5,21:18.12
27,5,21:18.12
28,5,21:18.12
29,5,21:18.12
30,5,21:18.12
31,5,21:18.12
32,5,21:18.12
33,5,21:18.12
11,6,21:18.12
12,6,21:18.12
14,6,21:18.12
15,6,21:18.12
16,6,21:18.12
17,6,21:18.12
18,6,21:18.12
19,6,21:18.12
20,6,21:18.12
21,6,21:18.12
23,6,21:18.12
24,6,21:18.12
25,6,21:18.12
26,6,21:18.12
27,6,21:18.12
28,6,21:18.12
31,6,21:18.12
32,6,21:18.12
14,7,21:18.12
15,7,21:18.12
16,7,21:18.12
17,7,21:18.12
18,7,21:18.12
19,7,21:18.12
20,7,21:18.12
21,7,21:18.12
22,7,21:18.12
23,7,21:18.12
24,7,21:18.12
25,7,21:18.12
26,7,21:18.12
28,7,21:18.12
29,7,21:18.12
31,7,21:18.12
32,7,21:18.12
13,8,21:18.12
14,8,21:18.12
15,8,21:18.12
16,8,21:18.12
17,8,21:18.12
18,8,21:18.12
19,8,21:18.12
20,8,21:18.12
21,8,21:18.12
22,8,21:18.12
23,8,21:18.12
24,8,21:18.12
25,8,21:18.12
29,8,21:18.12
30,8,21:18.12
32,8,21:18.12
33,8,21:18.12
16,9,21:18.12
17,9,21:17.12
18,9,21:18.12
19,9,21:18.12
20,9,21:18.12
21,9,21:18.12
23,9,21:18.12
24,9,21:18.12
25,9,21:18.12
27,9,21:18.12
29,9,21:18.12
16,10,21:18.12
18,10,21:18.12
19,10,21:18.12
20,10,21:18.12
21,10,21:18.12
22,10,21:18.12
23,10,21:18.12
24,10,21:18.12
27,10,21:18.12
29,10,21:18.12
17,11,21:18.12
19,11,21:18.12
20,11,21:18.12
21,11,21:18.12
22,11,21:18.12
23,11,21:17.12
24,11,21:18.12
25,11,21:18.12
27,11,21:18.12
28,11,21:18.12
29,11,21:18.12
16,12,21:18.12
17,12,21:18.12
18,12,21:18.12
19,12,21:18.12
20,12,21:18.12
21,12,21:18.12
22,12,21:18.12
23,12,21:18.12
25,12,21:18.12
26,12,21:18.12
27,12,21:18.12
16,13,21:18.12
17,13,21:18.12
18,13,21:18.12
19,13,21:18.12
20,13,21:18.12
21,13,21:18.12
22,13,21:18.12
23,13,21:18.12
24,13,21:18.12
25,13,21:18.12
26,13,21:18.12
27,13,21:18.12
28,13,21:18.12
29,13,21:18.12
18,14,21:18.12
19,14,21:18.12
20,14,21:18.12
21,14,21:18.12
22,14,21:18.12
23,14,21:18.12
24,14,21:18.12
25,14,21:18.12
27,14,21:18.12
28,14,21:18.12
29,14,21:18.12
20,15,21:18.12
22,15,21:18.12
23,15,21:18.12
24,15,21:18.12
28,15,21:18.12
21,16,21:18.12
23,16,21:18.12
25,16,21:18.12
28,16,21:18.12
17,17,21:18.12
18,17,21:18.12
19,17,21:18.12
20,17,21:18.12
21,17,21:18.12
22,17,21:18.12
24,17,21:18.12
27,17,21:18.12
29,17,21:18.12
30,17,21:18.12
16,18,21:18.12
17,18,21:18.12
19,18,21:18.12
21,18,21:18.12
22,18,21:18.12
24,18,21:18.12
25,18,21:18.12
26,18,21:18.12
29,18,21:18.12
17,19,21:18.12
18,19,21:18.12
19,19,21:18.12
20,19,21:18.12
21,19,21:18.12
26,19,21:18.12
15,20,21:18.12
16,20,21:18.12
17,20,21:18.12
18,20,21:18.12
22,20,21:18.12
24,20,21:18.12
27,20,21:18.12
17,21,21:18.12
18,21,21:18.12
24,21,21:18.12
27,21,21:18.12
18,22,21:18.12
19,22,21:18.12
18,23,21:18.12
24,-7,22:18.12
25,-7,22:18.12
26,-7,22:18.12
27,-7,22:18.12
25,-6,22:18.12
26,-6,22:18.12
27,-6,22:18.12
28,-6,22:18.12
-4,-5,22:17.12
19,-5,22:18.12
21,-5,22:18.12
22,-5,22:18.12
23,-5,22:18.12
24,-5,22:18.12
25,-5,22:18.12
27,-5,22:18.12
-6,-4,22:17.12
-5,-4,22:17.12
-4,-4,22:17.12
-3,-4,22:17.12
-2,-4,22:17.12
18,-4,22:18.12
20,-4,22:18.12
21,-4,22:18.12
22,-4,22:18.12
23,-4,22:18.12
25,-4,22:18.12
26,-4,22:18.12
27,-4,22:18.12
-7,-3,22:17.12
-6,-3,22:17.12
-5,-3,22:17.12
-4,-3,22:17.12
-3,-3,22:17.12
-2,-3,22:17.12
-1,-3,22:17.12
16,-3,22:18.12
17,-3,22:18.12
18,-3,22:18.12
19,-3,22:18.12
20,-3,22:18.12
21,-3,22:18.12
22,-3,22:18.12
23,-3,22:18.12
24,-3,22:18.12
25,-3,22:18.12
26,-3,22:18.12
-8,-2,22:17.12
-7,-2,22:17.12
-6,-2,22:17.12
-5,-2,22:17.12
-4,-2,22:17.12
-3,-2,22:17.12
-2,-2,22:17.12
-1,-2,22:17.12
17,-2,22:18.12
18,-2,22:18.12
19,-2,22:18.12
20,-2,22:18.12
21,-2,22:18.12
22,-2,22:18.12
23,-2,22:18.12
24,-2,22:18.12
25,-2,22:18.12
26,-2,22:18.12
27,-2,22:18.12
28,-2,22:18.12
-8,-1,22:17.12
-7,-1,22:17.12
-6,-1,22:17.12
-5,-1,22:17.12
-4,-1,22:17.12
-3,-1,22:17.12
-2,-1,22:17.12
-1,-1,22:17.12
19,-1,22:18.12
20,-1,22:18.12
21,-1,22:18.12
22,-1,22:18.12
23,-1,22:18.12
24,-1,22:18.12
25,-1,22:18.12
26,-1,22:18.12
27,-1,22:18.12
28,-1,22:18.12
-8,0,22:17.12
-7,0,22:17.12
-6,0,22:17.12
-5,0,22:17.12
-4,0,22:17.12
-3,0,22:17.12
-2,0,22:17.12
-1,0,22:17.12
19,0,22:18.12
20,0,22:18.12
21,0,22:18.12
23,0,22:18.12
24,0,22:18.12
25,0,22:18.12
26,0,22:18.12
27,0,22:18.12
28,0,22:18.12
29,0,22:18.12
30,0,22:18.12
-8,1,22:17.12
-7,1,22:17.12
-6,1,22:17.12
-5,1,22:17.12
-4,1,22:17.12
-3,1,22:17.12
-2,1,22:17.12
17,1,22:18.12
18,1,22:18.12
19,1,22:18.12
20,1,22:18.12
21,1,22:18.12
22,1,22:18.12
23,1,22:18.12
24,1,22:18.12
25,1,22:18.12
26,1,22:18.12
27,1,22:18.12
28,1,22:18.12
29,1,22:18.12
-8,2,22:17.12
-7,2,22:17.12
-6,2,22:17.12
-5,2,22:17.12
-4,2,22:17.12
-3,2,22:17.12
-2,2,22:17.12
18,2,22:18.12
19,2,22:18.12
20,2,22:18.12
21,2,22:18.12
22,2,22:18.12
23,2,22:18.12
24,2,22:18.12
25,2,22:18.12
26,2,22:18.12
27,2,22:18.12
28,2,22:18.12
-7,3,22:17.12
-6,3,22:17.12
-5,3,22:17.12
-4,3,22:17.12
-3,3,22:17.12
19,3,22:18.12
20,3,22:18.12
21,3,22:18.12
22,3,22:18.12
26,3,22:18.12
27,3,22:18.12
28,3,22:18.12
29,3,22:18.12
31,3,22:18.12
17,4,22:18.12
18,4,22:18.12
19,4,22:18.12
20,4,22:18.12
21,4,22:18.12
22,4,22:18.12
23,4,22:18.12
26,4,22:18.12
27,4,22:18.12
28,4,22:18.12
29,4,22:18.12
30,4,22:18.12
31,4,22:18.12
32,4,22:18.12
33,4,22:18.12
16,5,22:18.12
17,5,22:18.12
18,5,22:18.12
19,5,22:18.12
20,5,22:18.12
22,5,22:18.12
23,5,22:18.12
24,5,22:18.12
25,5,22:18.12
26,5,22:18.12
27,5,22:18.12
28,5,22:18.12
29,5,22:18.12
30,5,22:18.12
31,5,22:18.12
32,5,22:18.12
33,5,22:18.12
14,6,22:18.12
17,6,22:18.12
18,6,22:18.12
19,6,22:18.12
20,6,22:18.12
22,6,22:18.12
23,6,22:18.12
24,6,22:18.12
26,6,22:18.12
27,6,22:18.12
28,6,22:18.12
29,6,22:18.12
30,6,22:18.12
31,6,22:18.12
32,6,22:18.12
33,6,22:18.12
14,7,22:18.12
16,7,22:18.12
17,7,22:18.12
18,7,22:18.12
19,7,22:18.12
20,7,22:18.12
21,7,22:18.12
22,7,22:18.12
23,7,22:18.12
24,7,22:18.12
25,7,22:18.12
26,7,22:18.12
27,7,22:18.12
28,7,22:18.12
29,7,22:18.12
30,7,22:18.12
31,7,22:18.12
14,8,22:18.12
15,8,22:18.12
16,8,22:18.12
18,8,22:18.12
19,8,22:18.12
20,8,22:18.12
21,8,22:18.12
22,8,22:18.12
23,8,22:18.12
24,8,22:18.12
25,8,22:18.12
26,8,22:18.12
27,8,22:18.12
28,8,22:18.12
29,8,22:18.12
30,8,22:18.12
32,8,22:18.12
16,9,22:18.12
18,9,22:18.12
19,9,22:18.12
20,9,22:18.12
21,9,22:18.12
22,9,22:18.12
23,9,22:18.12
24,9,22:18.12
25,9,22:18.12
26,9,22:18.12
28,9,22:18.12
30,9,22:18.12
16,10,22:18.12
18,10,22:18.12
19,10,22:18.12
20,10,22:18.12
21,10,22:18.12
22,10,22:18.12
23,10,22:18.12
24,10,22:18.12
25,10,22:18.12
26,10,22:18.12
27,10,22:18.12
28,10,22:18.12
29,10,22:18.12
30,10,22:18.12
17,11,22:18.12
18,11,22:18.12
19,11,22:18.12
20,11,22:18.12
21,11,22:18.12
22,11,22:17.12
23,11,22:18.12
24,11,22:18.12
26,11,22:18.12
27,11,22:18.12
28,11,22:18.12
33,11,22:18.12
34,11,22:18.12
16,12,22:18.12
17,12,22:18.12
18,12,22:18.12
19,12,22:18.12
20,12,22:18.12
21,12,22:18.12
22,12,22:18.12
23,12,22:18.12
24,12,22:18.12
25,12,22:18.12
26,12,22:18.12
27,12,22:18.12
28,12,22:18.12
15,13,22:18.12
16,13,22:18.12
17,13,22:18.12
18,13,22:18.12
19,13,22:18.12
20,13,22:18.12
21,13,22:18.12
22,13,22:18.12
23,13,22:18.12
24,13,22:18.12
25,13,22:18.12
26,13,22:18.12
27,13,22:18.12
28,13,22:18.12
31,13,22:18.12
16,14,22:18.12
17,14,22:18.12
18,14,22:18.12
19,14,22:18.12
20,14,22:18.12
21,14,22:18.12
22,14,22:18.12
23,14,22:18.12
24,14,22:18.12
25,14,22:18.12
26,14,22:18.12
27,14,22:18.12
28,14,22:18.12
31,14,22:18.12
22,15,22:18.12
23,15,22:18.12
24,15,22:18.12
25,15,22:18.12
26,15,22:18.12
27,15,22:18.12
28,15,22:18.12
29,15,22:18.12
30,15,22:18.12
16,16,22:18.12
17,16,22:18.12
20,16,22:18.12
21,16,22:18.12
22,16,22:18.12
23,16,22:18.12
24,16,22:18.12
25,16,22:18.12
27,16,22:18.12
28,16,22:18.12
29,16,22:18.12
17,17,22:18.12
18,17,22:18.12
19,17,22:18.12
20,17,22:18.12
21,17,22:18.12
22,17,22:18.12
23,17,22:18.12
24,17,22:18.12
25,17,22:18.12
26,17,22:18.12
27,17,22:18.12
28,17,22:18.12
29,17,22:18.12
17,18,22:18.12
18,18,22:18.12
19,18,22:18.12
21,18,22:18.12
22,18,22:18.12
23,18,22:18.12
24,18,22:18.12
25,18,22:18.12
26,18,22:18.12
27,18,22:18.12
28,18,22:18.12
29,18,22:18.12
16,19,22:18.12
17,19,22:18.12
18,19,22:18.12
23,19,22:18.12
24,19,22:18.12
26,19,22:18.12
27,19,22:18.12
16,20,22:18.12
18,20,22:18.12
22,20,22:18.12
23,20,22:18.12
24,20,22:18.12
26,20,22:18.12
27,20,22:18.12
17,21,22:18.12
19,21,22:18.12
23,21,22:18.12
24,21,22:18.12
19,22,22:18.12
23,22,22:18.12
24,-9,23:18.12
24,-8,23:18.12
24,-7,23:18.12
25,-7,23:18.12
-5,-6,23:17.12
19,-6,23:18.12
22,-6,23:18.12
24,-6,23:18.12
-6,-5,23:17.12
-5,-5,23:17.12
-4,-5,23:17.12
-3,-5,23:17.12
-2,-5,23:17.12
-1,-5,23:17.12
19,-5,23:18.12
20,-5,23:18.12
22,-5,23:18.12
23,-5,23:18.12
24,-5,23:18.12
25,-5,23:18.12
27,-5,23:18.12
-6,-4,23:17.12
-5,-4,23:17.12
-4,-4,23:17.12
-3,-4,23:17.12
-2,-4,23:17.12
-1,-4,23:17.12
0,-4,23:17.12
18,-4,23:18.12
20,-4,23:18.12
21,-4,23:18.12
22,-4,23:18.12
23,-4,23:18.12
24,-4,23:18.12
25,-4,23:18.12
26,-4,23:18.12
-7,-3,23:17.12
-6,-3,23:17.12
-5,-3,23:17.12
-4,-3,23:17.12
-3,-3,23:17.12
-2,-3,23:17.12
-1,-3,23:17.12
0,-3,23:17.12
20,-3,23:18.12
21,-3,23:18.12
22,-3,23:18.12
23,-3,23:18.12
24,-3,23:18.12
25,-3,23:18.12
26,-3,23:18.12
27,-3,23:18.12
-7,-2,23:17.12
-6,-2,23:17.12
-5,-2,23:17.12
-4,-2,23:17.12
-3,-2,23:17.12
-2,-2,23:17.12
-1,-2,23:17.12
0,-2,23:17.12
18,-2,23:18.12
19,-2,23:18.12
20,-2,23:18.12
21,-2,23:18.12
22,-2,23:18.12
23,-2,23:18.12
24,-2,23:18.12
25,-2,23:18.12
26,-2,23:18.12
27,-2,23:18.12
28,-2,23:18.12
32,-2,23:18.12
-8,-1,23:17.12
-7,-1,23:17.12
-6,-1,23:17.12
-5,-1,23:17.12
-4,-1,23:17.12
-3,-1,23:17.12
-2,-1,23:17.12
-1,-1,23:17.12
0,-1,23:17.12
18,-1,23:18.12
19,-1,23:18.12
20,-1,23:18.12
21,-1,23:18.12
22,-1,23:18.12
23,-1,23:18.12
25,-1,23:18.12
26,-1,23:18.12
27,-1,23:18.12
28,-1,23:18.12
29,-1,23:18.12
30,-1,23:18.12
32,-1,23:18.12
33,-1,23:18.12
34,-1,23:18.12
-8,0,23:17.12
-7,0,23:17.12
-6,0,23:17.12
-5,0,23:17.12
-4,0,23:17.12
-3,0,23:17.12
-2,0,23:17.12
-1,0,23:17.12
17,0,23:18.12
18,0,23:18.12
19,0,23:18.12
20,0,23:18.12
21,0,23:18.12
22,0,23:18.12
24,0,23:18.12
25,0,23:18.12
26,0,23:18.12
27,0,23:18.12
28,0,23:18.12
29,0,23:18.12
30,0,23:18.12
32,0,23:18.12
-8,1,23:17.12
-7,1,23:17.12
-6,1,23:17.12
-5,1,23:17.12
-4,1,23:17.12
-3,1,23:17.12
-2,1,23:17.12
-1,1,23:17.12
17,1,23:18.12
18,1,23:18.12
19,1,23:18.12
20,1,23:18.12
21,1,23:18.12
22,1,23:18.12
23,1,23:18.12
24,1,23:18.12
25,1,23:18.12
26,1,23:18.12
27,1,23:18.12
32,1,23:18.12
-8,2,23:17.12
-7,2,23:17.12
-6,2,23:17.12
-5,2,23:17.12
-4,2,23:17.12
-3,2,23:17.12
-2,2,23:17.12
-1,2,23:17.12
19,2,23:18.12
21,2,23:18.12
22,2,23:18.12
23,2,23:18.12
25,2,23:18.12
26,2,23:18.12
27,2,23:18.12
28,2,23:18.12
29,2,23:18.12
-7,3,23:17.12
-6,3,23:17.12
-5,3,23:17.12
-4,3,23:17.12
-3,3,23:17.12
-2,3,23:17.12
17,3,23:18.12
19,3,23:18.12
20,3,23:18.12
21,3,23:18.12
22,3,23:18.12
26,3,23:18.12
27,3,23:18.12
28,3,23:18.12
29,3,23:18.12
-5,4,23:17.12
-4,4,23:17.12
-3,4,23:17.12
17,4,23:18.12
19,4,23:18.12
20,4,23:18.12
21,4,23:18.12
22,4,23:18.12
23,4,23:18.12
24,4,23:18.12
25,4,23:18.12
26,4,23:18.12
27,4,23:18.12
28,4,23:18.12
29,4,23:18.12
16,5,23:18.12
17,5,23:18.12
18,5,23:18.12
19,5,23:18.12
20,5,23:18.12
21,5,23:18.12
23,5,23:18.12
24,5,23:18.12
25,5,23:18.12
26,5,23:18.12
27,5,23:18.12
28,5,23:18.12
29,5,23:18.12
31,5,23:18.12
16,6,23:18.12
17,6,23:18.12
18,6,23:18.12
19,6,23:18.12
20,6,23:18.12
21,6,23:18.12
22,6,23:18.12
23,6,23:18.12
24,6,23:18.12
25,6,23:18.12
26,6,23:18.12
27,6,23:18.12
28,6,23:18.12
29,6,23:18.12
30,6,23:18.12
16,7,23:18.12
17,7,23:18.12
18,7,23:18.12
19,7,23:18.12
20,7,23:18.12
21,7,23:18.12
22,7,23:18.12
23,7,23:18.12
24,7,23:18.12
25,7,23:18.12
26,7,23:18.12
27,7,23:18.12
28,7,23:18.12
29,7,23:18.12
30,7,23:18.12
33,7,23:18.12
15,8,23:18.12
16,8,23:18.12
17,8,23:18.12
18,8,23:18.12
19,8,23:18.12
20,8,23:18.12
23,8,23:18.12
24,8,23:18.12
25,8,23:18.12
26,8,23:18.12
27,8,23:18.12
28,8,23:18.12
29,8,23:18.12
30,8,23:18.12
31,8,23:18.12
32,8,23:18.12
33,8,23:18.12
13,9,23:18.12
14,9,23:18.12
15,9,23:18.12
17,9,23:18.12
18,9,23:18.12
19,9,23:18.12
20,9,23:18.12
21,9,23:18.12
22,9,23:18.12
23,9,23:18.12
24,9,23:18.12
25,9,23:18.12
26,9,23:18.12
27,9,23:18.12
28,9,23:18.12
29,9,23:18.12
30,9,23:18.12
32,9,23:18.12
16,10,23:18.12
17,10,23:18.12
18,10,23:18.12
19,10,23:18.12
20,10,23:18.12
21,10,23:18.12
22,10,23:18.12
23,10,23:18.12
24,10,23:18.12
25,10,23:18.12
26,10,23:18.12
27,10,23:18.12
28,10,23:18.12
29,10,23:18.12
30,10,23:18.12
32,10,23:18.12
16,11,23:18.12
17,11,23:18.12
19,11,23:18.12
20,11,23:18.12
21,11,23:18.12
22,11,23:18.12
23,11,23:17.12
25,11,23:18.12
26,11,23:18.12
27,11,23:18.12
28,11,23:18.12
29,11,23:18.12
30,11,23:18.12
32,11,23:18.12
33,11,23:18.12
15,12,23:18.12
16,12,23:18.12
17,12,23:18.12
18,12,23:18.12
20,12,23:18.12
21,12,23:18.12
22,12,23:18.12
23,12,23:17.12
24,12,23:18.12
25,12,23:18.12
26,12,23:18.12
27,12,23:18.12
28,12,23:18.12
33,12,23:18.12
15,13,23:18.12
16,13,23:18.12
17,13,23:18.12
18,13,23:18.12
19,13,23:18.12
20,13,23:18.12
21,13,23:18.12
22,13,23:18.12
23,13,23:18.12
24,13,23:18.12
25,13,23:18.12
26,13,23:18.12
27,13,23:18.12
28,13,23:18.12
29,13,23:18.12
30,13,23:18.12
31,13,23:18.12
17,14,23:18.12
18,14,23:18.12
19,14,23:18.12
20,14,23:18.12
21,14,23:18.12
23,14,23:18.12
24,14,23:18.12
25,14,23:18.12
26,14,23:18.12
27,14,23:18.12
28,14,23:18.12
29,14,23:18.12
31,14,23:18.12
16,15,23:18.12
17,15,23:18.12
18,15,23:18.12
19,15,23:18.12
20,15,23:18.12
21,15,23:18.12
22,15,23:18.12
23,15,23:18.12
24,15,23:18.12
25,15,23:18.12
26,15,23:18.12
27,15,23:18.12
28,15,23:18.12
29,15,23:18.12
15,16,23:18.12
16,16,23:18.12
17,16,23:18.12
18,16,23:18.12
19,16,23:18.12
20,16,23:18.12
21,16,23:18.12
22,16,23:18.12
23,16,23:18.12
25,16,23:18.12
26,16,23:18.12
28,16,23:18.12
17,17,23:18.12
20,17,23:18.12
21,17,23:18.12
22,17,23:18.12
23,17,23:18.12
25,17,23:18.12
26,17,23:18.12
28,17,23:18.12
29,17,23:18.12
30,17,23:18.12
16,18,23:18.12
17,18,23:18.12
18,18,23:18.12
19,18,23:18.12
20,18,23:18.12
21,18,23:18.12
22,18,23:18.12
23,18,23:18.12
24,18,23:18.12
25,18,23:18.12
26,18,23:18.12
27,18,23:18.12
28,18,23:18.12
29,18,23:18.12
16,19,23:18.12
17,19,23:18.12
18,19,23:18.12
20,19,23:18.12
22,19,23:18.12
23,19,23:18.12
24,19,23:18.12
25,19,23:18.12
26,19,23:18.12
27,19,23:18.12
28,19,23:18.12
29,19,23:18.12
30,19,23:18.12
18,20,23:18.12
23,20,23:18.12
24,20,23:18.12
25,20,23:18.12
26,20,23:18.12
27,20,23:18.12
23,21,23:18.12
24,21,23:18.12
-4,-9,24:17.12
-5,-8,24:17.12
-4,-8,24:17.12
-3,-8,24:17.12
24,-8,24:18.12
-5,-7,24:17.12
-4,-7,24:17.12
-3,-7,24:17.12
-2,-7,24:17.12
24,-7,24:18.12
-6,-6,24:17.12
-5,-6,24:17.12
-4,-6,24:17.12
-3,-6,24:17.12
-2,-6,24:17.12
-1,-6,24:17.12
0,-6,24:17.12
19,-6,24:18.12
23,-6,24:18.12
-7,-5,24:17.12
-6,-5,24:17.12
-5,-5,24:17.12
-4,-5,24:17.12
-3,-5,24:17.12
-2,-5,24:17.12
-1,-5,24:17.12
0,-5,24:17.12
1,-5,24:17.12
20,-5,24:18.12
21,-5,24:18.12
22,-5,24:18.12
23,-5,24:18.12
-7,-4,24:17.12
-6,-4,24:17.12
-5,-4,24:17.12
-4,-4,24:17.12
-3,-4,24:17.12
-2,-4,24:17.12
-1,-4,24:17.12
0,-4,24:17.12
1,-4,24:17.12
19,-4,24:18.12
20,-4,24:18.12
21,-4,24:18.12
22,-4,24:18.12
23,-4,24:18.12
25,-4,24:18.12
29,-4,24:18.12
-7,-3,24:17.12
-6,-3,24:17.12
-5,-3,24:17.12
-4,-3,24:17.12
-3,-3,24:17.12
-2,-3,24:17.12
-1,-3,24:17.12
0,-3,24:17.12
1,-3,24:17.12
19,-3,24:18.12
20,-3,24:18.12
21,-3,24:18.12
22,-3,24:18.12
23,-3,24:18.12
24,-3,24:18.12
25,-3,24:18.12
29,-3,24:18.12
-7,-2,24:17.12
-6,-2,24:17.12
-5,-2,24:17.12
-4,-2,24:17.12
-3,-2,24:17.12
-2,-2,24:17.12
-1,-2,24:17.12
0,-2,24:17.12
18,-2,24:18.12
19,-2,24:18.12
20,-2,24:18.12
21,-2,24:18.12
22,-2,24:18.12
25,-2,24:18.12
27,-2,24:18.12
28,-2,24:18.12
29,-2,24:18.12
30,-2,24:18.12
31,-2,24:18.12
-8,-1,24:17.12
-7,-1,24:17.12
-6,-1,24:17.12
-5,-1,24:17.12
-4,-1,24:17.12
-3,-1,24:17.12
-2,-1,24:17.12
-1,-1,24:17.12
0,-1,24:17.12
18,-1,24:18.12
19,-1,24:18.12
20,-1,24:18.12
21,-1,24:18.12
22,-1,24:18.12
23,-1,24:18.12
26,-1,24:18.12
27,-1,24:18.12
28,-1,24:18.12
29,-1,24:18.12
30,-1,24:18.12
32,-1,24:18.12
33,-1,24:18.12
-8,0,24:17.12
-7,0,24:17.12
-6,0,24:17.12
-5,0,24:17.12
-4,0,24:17.12
-3,0,24:17.12
-2,0,24:17.12
-1,0,24:17.12
0,0,24:17.12
18,0,24:18.12
20,0,24:18.12
21,0,24:18.12
22,0,24:18.12
23,0,24:18.12
24,0,24:18.12
25,0,24:18.12
27,0,24:18.12
28,0,24:18.12
29,0,24:18.12
30,0,24:18.12
31,0,24:18.12
32,0,24:18.12
33,0,24:18.12
-8,1,24:17.12
-7,1,24:17.12
-6,1,24:17.12
-5,1,24:17.12
-4,1,24:17.12
-3,1,24:17.12
-2,1,24:17.12
-1,1,24:17.12
19,1,24:18.12
20,1,24:18.12
21,1,24:18.12
22,1,24:18.12
23,1,24:18.12
24,1,24:18.12
26,1,24:18.12
27,1,24:18.12
31,1,24:18.12
-8,2,24:17.12
-7,2,24:17.12
-6,2,24:17.12
-5,2,24:17.12
-4,2,24:17.12
-3,2,24:17.12
-2,2,24:17.12
-1,2,24:17.12
18,2,24:18.12
19,2,24:18.12
20,2,24:18.12
21,2,24:18.12
22,2,24:18.12
23,2,24:18.12
27,2,24:18.12
30,2,24:18.12
-7,3,24:17.12
-6,3,24:17.12
-5,3,24:17.12
-4,3,24:17.12
-3,3,24:17.12
-2,3,24:17.12
-1,3,24:17.12
19,3,24:18.12
20,3,24:18.12
21,3,24:18.12
23,3,24:18.12
27,3,24:18.12
29,3,24:18.12
30,3,24:18.12
-6,4,24:17.12
-5,4,24:17.12
-4,4,24:17.12
-3,4,24:17.12
-2,4,24:17.12
20,4,24:18.12
21,4,24:18.12
22,4,24:18.12
25,4,24:18.12
26,4,24:18.12
27,4,24:18.12
16,5,24:18.12
19,5,24:18.12
21,5,24:18.12
22,5,24:18.12
23,5,24:18.12
27,5,24:18.12
28,5,24:18.12
29,5,24:18.12
19,6,24:18.12
20,6,24:18.12
22,6,24:18.12
23,6,24:18.12
25,6,24:18.12
26,6,24:18.12
27,6,24:18.12
28,6,24:18.12
29,6,24:18.12
30,6,24:18.12
31,6,24:18.12
15,7,24:18.12
18,7,24:18.12
19,7,24:18.12
20,7,24:18.12
21,7,24:18.12
22,7,24:18.12
23,7,24:18.12
24,7,24:18.12
25,7,24:18.12
26,7,24:18.12
27,7,24:18.12
28,7,24:18.12
29,7,24:18.12
30,7,24:18.12
31,7,24:18.12
13,8,24:18.12
14,8,24:18.12
15,8,24:18.12
17,8,24:18.12
19,8,24:18.12
20,8,24:18.12
21,8,24:18.12
24,8,24:18.12
25,8,24:18.12
26,8,24:18.12
28,8,24:18.12
29,8,24:18.12
30,8,24:18.12
33,8,24:18.12
17,9,24:18.12
18,9,24:18.12
19,9,24:18.12
20,9,24:18.12
21,9,24:18.12
23,9,24:18.12
24,9,24:18.12
25,9,24:18.12
26,9,24:18.12
27,9,24:18.12
28,9,24:18.12
29,9,24:18.12
30,9,24:18.12
31,9,24:18.12
17,10,24:18.12
19,10,24:18.12
21,10,24:18.12
22,10,24:18.12
23,10,24:18.12
24,10,24:18.12
25,10,24:18.12
26,10,24:18.12
27,10,24:18.12
28,10,24:18.12
29,10,24:18.12
30,10,24:18.12
16,11,24:18.12
17,11,24:18.12
21,11,24:18.12
22,11,24:18.12
23,11,24:18.12
24,11,24:17.12
25,11,24:18.12
26,11,24:18.12
27,11,24:18.12
28,11,24:18.12
29,11,24:18.12
30,11,24:18.12
31,11,24:18.12
32,11,24:18.12
33,11,24:18.12
18,12,24:18.12
19,12,24:18.12
20,12,24:18.12
21,12,24:18.12
22,12,24:18.12
23,12,24:18.12
24,12,24:18.12
26,12,24:18.12
27,12,24:18.12
28,12,24:18.12
29,12,24:18.12
30,12,24:18.12
31,12,24:18.12
32,12,24:18.12
33,12,24:18.12
34,12,24:18.12
16,13,24:18.12
17,13,24:18.12
18,13,24:18.12
19,13,24:18.12
20,13,24:18.12
21,13,24:18.12
22,13,24:18.12
23,13,24:18.12
24,13,24:18.12
25,13,24:18.12
26,13,24:18.12
27,13,24:18.12
28,13,24:18.12
29,13,24:18.12
30,13,24:18.12
31,13,24:18.12
32,13,24:18.12
16,14,24:18.12
17,14,24:18.12
18,14,24:18.12
19,14,24:18.12
20,14,24:18.12
21,14,24:18.12
22,14,24:18.12
23,14,24:18.12
24,14,24:18.12
25,14,24:18.12
26,14,24:18.12
28,14,24:18.12
29,14,24:18.12
17,15,24:18.12
18,15,24:18.12
19,15,24:18.12
20,15,24:18.12
21,15,24:18.12
22,15,24:18.12
23,15,24:18.12
24,15,24:18.12
25,15,24:18.12
26,15,24:18.12
27,15,24:18.12
28,15,24:18.12
29,15,24:18.12
15,16,24:18.12
16,16,24:18.12
18,16,24:18.12
19,16,24:18.12
20,16,24:18.12
21,16,24:18.12
23,16,24:18.12
24,16,24:18.12
25,16,24:18.12
26,16,24:18.12
27,16,24:18.12
28,16,24:18.12
29,16,24:18.12
18,17,24:18.12
21,17,24:18.12
22,17,24:18.12
23,17,24:18.12
24,17,24:18.12
25,17,24:18.12
26,17,24:18.12
27,17,24:18.12
28,17,24:18.12
29,17,24:18.12
30,17,24:18.12
31,17,24:18.12
18,18,24:18.12
19,18,24:18.12
20,18,24:18.12
21,18,24:18.12
22,18,24:18.12
23,18,24:18.12
24,18,24:18.12
25,18,24:18.12
26,18,24:18.12
27,18,24:18.12
28,18,24:18.12
29,18,24:18.12
30,18,24:18.12
18,19,24:18.12
20,19,24:18.12
21,19,24:18.12
22,19,24:18.12
23,19,24:18.12
24,19,24:18.12
25,19,24:18.12
26,19,24:18.12
27,19,24:18.12
29,19,24:18.12
30,19,24:18.12
31,19,24:18.12
18,20,24:18.12
19,20,24:18.12
20,20,24:18.12
21,20,24:18.12
22,20,24:18.12
23,20,24:18.12
24,20,24:18.12
25,20,24:18.12
26,20,24:18.12
27,20,24:18.12
30,20,24:18.12
18,21,24:18.12
23,21,24:18.12
24,21,24:18.12
25,21,24:18.12
26,21,24:18.12
30,21,24:18.12
24,22,24:18.12
-4,-11,25:17.12
-5,-10,25:17.12
-4,-10,25:17.12
-3,-10,25:17.12
-6,-9,25:17.12
-5,-9,25:17.12
-4,-9,25:17.12
-3,-9,25:17.12
-2,-9,25:17.12
-6,-8,25:17.12
-5,-8,25:17.12
-4,-8,25:17.12
-3,-8,25:17.12
-2,-8,25:17.12
-1,-8,25:17.12
-6,-7,25:17.12
-5,-7,25:17.12
-4,-7,25:17.12
-3,-7,25:17.12
-2,-7,25:17.12
-1,-7,25:17.12
0,-7,25:17.12
24,-7,25:18.12
25,-7,25:18.12
-6,-6,25:17.12
-5,-6,25:17.12
-4,-6,25:17.12
-3,-6,25:17.12
-2,-6,25:17.12
-1,-6,25:17.12
0,-6,25:17.12
1,-6,25:17.12
23,-6,25:18.12
24,-6,25:18.12
-7,-5,25:17.12
-6,-5,25:17.12
-5,-5,25:17.12
-4,-5,25:17.12
-3,-5,25:17.12
-2,-5,25:17.12
-1,-5,25:17.12
0,-5,25:17.12
1,-5,25:17.12
2,-5,25:17.12
23,-5,25:18.12
-7,-4,25:17.12
-6,-4,25:17.12
-5,-4,25:17.12
-4,-4,25:17.12
-3,-4,25:17.12
-2,-4,25:17.12
-1,-4,25:17.12
0,-4,25:17.12
1,-4,25:17.12
2,-4,25:17.12
19,-4,25:18.12
20,-4,25:18.12
21,-4,25:18.12
22,-4,25:18.12
23,-4,25:18.12
-7,-3,25:17.12
-6,-3,25:17.12
-5,-3,25:17.12
-4,-3,25:17.12
-3,-3,25:17.12
-2,-3,25:17.12
-1,-3,25:17.12
0,-3,25:17.12
1,-3,25:17.12
19,-3,25:18.12
20,-3,25:18.12
21,-3,25:18.12
22,-3,25:18.12
25,-3,25:18.12
-7,-2,25:17.12
-6,-2,25:17.12
-5,-2,25:17.12
-4,-2,25:17.12
-3,-2,25:17.12
-2,-2,25:17.12
-1,-2,25:17.12
0,-2,25:17.12
1,-2,25:17.12
18,-2,25:18.12
19,-2,25:18.12
20,-2,25:18.12
21,-2,25:18.12
22,-2,25:18.12
23,-2,25:18.12
26,-2,25:18.12
27,-2,25:18.12
28,-2,25:18.12
29,-2,25:18.12
-7,-1,25:17.12
-6,-1,25:17.12
-5,-1,25:17.12
-4,-1,25:17.12
-3,-1,25:17.12
-2,-1,25:17.12
-1,-1,25:17.12
0,-1,25:17.12
18,-1,25:18.12
19,-1,25:18.12
20,-1,25:18.12
21,-1,25:18.12
22,-1,25:18.12
23,-1,25:18.12
24,-1,25:18.12
25,-1,25:18.12
26,-1,25:18.12
27,-1,25:18.12
28,-1,25:18.12
29,-1,25:18.12
30,-1,25:18.12
-8,0,25:17.12
-7,0,25:17.12
-6,0,25:17.12
-5,0,25:17.12
-4,0,25:17.12
-3,0,25:17.12
-2,0,25:17.12
-1,0,25:17.12
0,0,25:17.12
18,0,25:18.12
20,0,25:18.12
21,0,25:18.12
22,0,25:18.12
24,0,25:18.12
25,0,25:18.12
27,0,25:18.12
28,0,25:18.12
29,0,25:18.12
30,0,25:18.12
-8,1,25:17.12
-7,1,25:17.12
-6,1,25:17.12
-5,1,25:17.12
-4,1,25:17.12
-3,1,25:17.12
-2,1,25:17.12
-1,1,25:17.12
0,1,25:17.12
19,1,25:18.12
20,1,25:18.12
21,1,25:18.12
22,1,25:18.12
27,1,25:18.12
29,1,25:18.12
30,1,25:18.12
31,1,25:18.12
-8,2,25:17.12
-7,2,25:17.12
-6,2,25:17.12
-5,2,25:17.12
-4,2,25:17.12
-3,2,25:17.12
-2,2,25:17.12
-1,2,25:17.12
0,2,25:17.12
18,2,25:18.12
19,2,25:18.12
20,2,25:18.12
21,2,25:18.12
22,2,25:18.12
-8,3,25:17.12
-7,3,25:17.12
-6,3,25:17.12
-5,3,25:17.12
-4,3,25:17.12
-3,3,25:17.12
-2,3,25:17.12
-1,3,25:17.12
0,3,25:17.12
19,3,25:18.12
20,3,25:18.12
27,3,25:18.12
-6,4,25:17.12
-5,4,25:17.12
-4,4,25:17.12
-3,4,25:17.12
-2,4,25:17.12
-1,4,25:17.12
0,4,25:17.12
19,4,25:18.12
20,4,25:18.12
28,4,25:18.12
19,5,25:18.12
24,5,25:18.12
25,5,25:18.12
26,5,25:18.12
27,5,25:18.12
28,5,25:18.12
30,5,25:18.12
31,5,25:18.12
19,6,25:18.12
20,6,25:18.12
23,6,25:18.12
25,6,25:18.12
26,6,25:18.12
27,6,25:18.12
28,6,25:18.12
29,6,25:18.12
30,6,25:18.12
31,6,25:18.12
32,6,25:18.12
20,7,25:18.12
21,7,25:18.12
24,7,25:18.12
25,7,25:18.12
26,7,25:18.12
27,7,25:18.12
28,7,25:18.12
29,7,25:18.12
30,7,25:18.12
31,7,25:18.12
32,7,25:18.12
33,7,25:18.12
15,8,25:18.12
16,8,25:18.12
20,8,25:18.12
21,8,25:18.12
22,8,25:18.12
23,8,25:18.12
24,8,25:18.12
25,8,25:18.12
26,8,25:18.12
27,8,25:18.12
29,8,25:18.12
30,8,25:18.12
21,9,25:18.12
23,9,25:18.12
24,9,25:18.12
25,9,25:18.12
27,9,25:18.12
28,9,25:18.12
30,9,25:18.12
31,9,25:18.12
21,10,25:18.12
22,10,25:18.12
23,10,25:18.12
24,10,25:18.12
25,10,25:18.12
26,10,25:18.12
27,10,25:18.12
28,10,25:18.12
29,10,25:18.12
30,10,25:18.12
31,10,25:18.12
32,10,25:18.12
19,11,25:18.12
22,11,25:18.12
24,11,25:18.12
25,11,25:18.12
26,11,25:18.12
27,11,25:18.12
28,11,25:18.12
29,11,25:18.12
30,11,25:18.12
31,11,25:18.12
32,11,25:18.12
33,11,25:18.12
17,12,25:18.12
18,12,25:18.12
19,12,25:18.12
22,12,25:18.12
24,12,25:18.12
25,12,25:18.12
26,12,25:18.12
27,12,25:18.12
28,12,25:18.12
29,12,25:18.12
30,12,25:18.12
31,12,25:18.12
17,13,25:18.12
18,13,25:18.12
19,13,25:18.12
20,13,25:18.12
21,13,25:18.12
22,13,25:18.12
23,13,25:18.12
24,13,25:18.12
25,13,25:18.12
26,13,25:18.12
27,13,25:18.12
28,13,25:18.12
29,13,25:18.12
13,14,25:18.12
14,14,25:18.12
15,14,25:18.12
17,14,25:18.12
18,14,25:18.12
19,14,25:18.12
20,14,25:18.12
21,14,25:18.12
24,14,25:18.12
25,14,25:18.12
26,14,25:18.12
27,14,25:18.12
28,14,25:18.12
29,14,25:18.12
14,15,25:18.12
15,15,25:18.12
16,15,25:18.12
17,15,25:18.12
18,15,25:18.12
19,15,25:18.12
20,15,25:18.12
21,15,25:18.12
22,15,25:18.12
24,15,25:18.12
26,15,25:18.12
27,15,25:18.12
28,15,25:18.12
17,16,25:18.12
18,16,25:18.12
19,16,25:18.12
20,16,25:18.12
21,16,25:18.12
23,16,25:18.12
24,16,25:18.12
25,16,25:18.12
28,16,25:18.12
19,17,25:18.12
21,17,25:18.12
23,17,25:18.12
24,17,25:18.12
27,17,25:18.12
28,17,25:18.12
31,17,25:18.12
18,18,25:18.12
20,18,25:18.12
22,18,25:18.12
23,18,25:18.12
24,18,25:18.12
25,18,25:18.12
26,18,25:18.12
27,18,25:18.12
18,19,25:18.12
21,19,25:18.12
22,19,25:18.12
23,19,25:18.12
24,19,25:18.12
25,19,25:18.12
26,19,25:18.12
23,20,25:18.12
24,20,25:18.12
25,20,25:18.12
27,20,25:18.12
23,21,25:18.12
25,21,25:18.12
-5,-11,26:17.12
-4,-11,26:17.12
-3,-11,26:17.12
-6,-10,26:17.12
-5,-10,26:17.12
-4,-10,26:17.12
-3,-10,26:17.12
-6,-9,26:17.12
-5,-9,26:17.12
-4,-9,26:17.12
-3,-9,26:17.12
-2,-9,26:17.12
-6,-8,26:17.12
-5,-8,26:17.12
-4,-8,26:17.12
-3,-8,26:17.12
-2,-8,26:17.12
-1,-8,26:17.12
-6,-7,26:17.12
-5,-7,26:17.12
-4,-7,26:17.12
-3,-7,26:17.12
-2,-7,26:17.12
-1,-7,26:17.12
0,-7,26:17.12
1,-7,26:17.12
2,-7,26:17.12
-6,-6,26:17.12
-5,-6,26:17.12
-4,-6,26:17.12
-3,-6,26:17.12
-2,-6,26:17.12
-1,-6,26:17.12
0,-6,26:17.12
1,-6,26:17.12
2,-6,26:17.12
3,-6,26:17.12
23,-6,26:18.12
-7,-5,26:17.12
-6,-5,26:17.12
-5,-5,26:17.12
-4,-5,26:17.12
-3,-5,26:17.12
-2,-5,26:17.12
-1,-5,26:17.12
0,-5,26:17.12
1,-5,26:17.12
2,-5,26:17.12
3,-5,26:17.12
23,-5,26:18.12
-7,-4,26:17.12
-6,-4,26:17.12
-5,-4,26:17.12
-4,-4,26:17.12
-3,-4,26:17.12
-2,-4,26:17.12
-1,-4,26:17.12
0,-4,26:17.12
1,-4,26:17.12
2,-4,26:17.12
22,-4,26:18.12
23,-4,26:18.12
24,-4,26:18.12
-7,-3,26:17.12
-6,-3,26:17.12
-5,-3,26:17.12
-4,-3,26:17.12
-3,-3,26:17.12
-2,-3,26:17.12
-1,-3,26:17.12
0,-3,26:17.12
1,-3,26:17.12
2,-3,26:17.12
21,-3,26:18.12
22,-3,26:18.12
-7,-2,26:17.12
-6,-2,26:17.12
-5,-2,26:17.12
-4,-2,26:17.12
-3,-2,26:17.12
-2,-2,26:17.12
-1,-2,26:17.12
0,-2,26:17.12
1,-2,26:17.12
20,-2,26:18.12
21,-2,26:18.12
28,-2,26:18.12
30,-2,26:18.12
-7,-1,26:17.12
-6,-1,26:17.12
-5,-1,26:17.12
-4,-1,26:17.12
-3,-1,26:17.12
-2,-1,26:17.12
-1,-1,26:17.12
0,-1,26:17.12
22,-1,26:18.12
29,-1,26:18.12
30,-1,26:18.12
-7,0,26:17.12
-6,0,26:17.12
-5,0,26:17.12
-4,0,26:17.12
-3,0,26:17.12
-2,0,26:17.12
-1,0,26:17.12
0,0,26:17.12
19,0,26:18.12
20,0,26:18.12
21,0,26:18.12
25,0,26:18.12
29,0,26:18.12
30,0,26:18.12
-8,1,26:17.12
-7,1,26:17.12
-6,1,26:17.12
-5,1,26:17.12
-4,1,26:17.12
-3,1,26:17.12
-2,1,26:17.12
-1,1,26:17.12
0,1,26:17.12
18,1,26:18.12
19,1,26:18.12
20,1,26:18.12
21,1,26:18.12
28,1,26:18.12
29,1,26:18.12
30,1,26:18.12
-8,2,26:17.12
-7,2,26:17.12
-6,2,26:17.12
-5,2,26:17.12
-4,2,26:17.12
-3,2,26:17.12
-2,2,26:17.12
-1,2,26:17.12
0,2,26:18.12
1,2,26:17.12
19,2,26:18.12
21,2,26:18.12
29,2,26:18.12
30,2,26:18.12
-8,3,26:17.12
-7,3,26:17.12
-6,3,26:17.12
-5,3,26:17.12
-4,3,26:17.12
-3,3,26:17.12
-2,3,26:17.12
-1,3,26:18.12
0,3,26:18.12
1,3,26:17.12
20,3,26:18.12
-7,4,26:17.12
-6,4,26:17.12
-5,4,26:17.12
-4,4,26:17.12
-3,4,26:17.12
-2,4,26:17.12
-1,4,26:17.12
0,4,26:17.12
1,4,26:17.12
20,4,26:18.12
24,4,26:18.12
-5,5,26:17.12
-4,5,26:17.12
-3,5,26:17.12
-2,5,26:17.12
-1,5,26:17.12
0,5,26:17.12
1,5,26:17.12
20,5,26:18.12
24,5,26:18.12
25,5,26:18.12
28,5,26:18.12
23,6,26:18.12
24,6,26:18.12
25,6,26:18.12
27,6,26:18.12
28,6,26:18.12
32,6,26:18.12
19,7,26:18.12
20,7,26:18.12
22,7,26:18.12
23,7,26:18.12
24,7,26:18.12
25,7,26:18.12
26,7,26:18.12
27,7,26:18.12
28,7,26:18.12
29,7,26:18.12
30,7,26:18.12
31,7,26:18.12
32,7,26:18.12
33,7,26:18.12
15,8,26:18.12
20,8,26:18.12
21,8,26:18.12
22,8,26:18.12
23,8,26:18.12
24,8,26:18.12
25,8,26:18.12
26,8,26:18.12
27,8,26:18.12
28,8,26:18.12
29,8,26:18.12
30,8,26:18.12
31,8,26:18.12
32,8,26:18.12
24,9,26:18.12
25,9,26:18.12
26,9,26:18.12
27,9,26:18.12
29,9,26:18.12
30,9,26:18.12
31,9,26:18.12
32,9,26:18.12
23,10,26:18.12
24,10,26:18.12
28,10,26:18.12
29,10,26:18.12
31,10,26:18.12
32,10,26:18.12
33,10,26:18.12
34,10,26:18.12
35,10,26:18.12
22,11,26:18.12
23,11,26:18.12
24,11,26:18.12
27,11,26:18.12
28,11,26:18.12
29,11,26:18.12
30,11,26:18.12
31,11,26:18.12
32,11,26:18.12
33,11,26:18.12
22,12,26:18.12
24,12,26:18.12
26,12,26:18.12
28,12,26:18.12
29,12,26:18.12
31,12,26:18.12
32,12,26:18.12
21,13,26:18.12
22,13,26:18.12
24,13,26:18.12
25,13,26:18.12
26,13,26:18.12
27,13,26:18.12
28,13,26:18.12
29,13,26:18.12
18,14,26:18.12
19,14,26:18.12
20,14,26:18.12
21,14,26:18.12
26,14,26:18.12
28,14,26:18.12
16,15,26:18.12
18,15,26:18.12
19,15,26:18.12
20,15,26:18.12
21,15,26:18.12
26,15,26:18.12
28,15,26:18.12
17,16,26:18.12
18,16,26:18.12
19,16,26:18.12
21,16,26:18.12
22,16,26:18.12
25,16,26:18.12
28,16,26:18.12
29,16,26:18.12
30,16,26:18.12
31,16,26:18.12
19,17,26:18.12
22,17,26:18.12
27,17,26:18.12
28,17,26:18.12
29,17,26:18.12
22,18,26:18.12
23,18,26:18.12
24,18,26:18.12
25,18,26:18.12
26,18,26:18.12
23,19,26:18.12
28,19,26:18.12
23,20,26:18.12
24,20,26:18.12
25,20,26:18.12
26,20,26:18.12
27,20,26:18.12
24,21,26:18.12
25,21,26:18.12
-5,-12,27:17.12
-4,-12,27:17.12
-3,-12,27:17.12
-6,-11,27:17.12
-5,-11,27:17.12
-4,-11,27:17.12
-3,-11,27:17.12
-2,-11,27:17.12
-6,-10,27:17.12
-5,-10,27:17.12
-4,-10,27:17.12
-3,-10,27:17.12
-2,-10,27:17.12
-6,-9,27:17.12
-5,-9,27:17.12
-4,-9,27:17.12
-3,-9,27:17.12
-2,-9,27:17.12
-6,-8,27:17.12
-5,-8,27:17.12
-4,-8,27:17.12
-3,-8,27:17.12
-2,-8,27:17.12
-1,-8,27:17.12
3,-8,27:17.12
-6,-7,27:17.12
-5,-7,27:17.12
-4,-7,27:17.12
-3,-7,27:17.12
-2,-7,27:17.12
-1,-7,27:17.12
0,-7,27:17.12
1,-7,27:17.12
2,-7,27:17.12
3,-7,27:17.12
4,-7,27:17.12
-6,-6,27:17.12
-5,-6,27:17.12
-4,-6,27:17.12
-3,-6,27:17.12
-2,-6,27:17.12
-1,-6,27:17.12
0,-6,27:17.12
1,-6,27:17.12
2,-6,27:17.12
3,-6,27:17.12
4,-6,27:17.12
-7,-5,27:17.12
-6,-5,27:17.12
-5,-5,27:17.12
-4,-5,27:17.12
-3,-5,27:17.12
-2,-5,27:17.12
-1,-5,27:17.12
0,-5,27:17.12
1,-5,27:17.12
2,-5,27:17.12
3,-5,27:17.12
-7,-4,27:17.12
-6,-4,27:17.12
-5,-4,27:17.12
-4,-4,27:17.12
-3,-4,27:17.12
-2,-4,27:17.12
-1,-4,27:17.12
0,-4,27:17.12
1,-4,27:17.12
2,-4,27:17.12
3,-4,27:17.12
22,-4,27:18.12
-6,-3,27:17.12
-5,-3,27:17.12
-4,-3,27:17.12
-3,-3,27:17.12
-2,-3,27:17.12
-1,-3,27:17.12
0,-3,27:17.12
1,-3,27:17.12
2,-3,27:17.12
-6,-2,27:17.12
-5,-2,27:17.12
-4,-2,27:17.12
-3,-2,27:17.12
-2,-2,27:17.12
-1,-2,27:17.12
0,-2,27:17.12
28,-2,27:18.12
-7,-1,27:17.12
-6,-1,27:17.12
-5,-1,27:17.12
-4,-1,27:17.12
-3,-1,27:17.12
-2,-1,27:17.12
-1,-1,27:17.12
0,-1,27:17.12
28,-1,27:18.12
29,-1,27:18.12
-7,0,27:17.12
-6,0,27:17.12
-5,0,27:17.12
-4,0,27:17.12
-3,0,27:17.12
-2,0,27:17.12
-1,0,27:17.12
20,0,27:18.12
28,0,27:18.12
29,0,27:18.12
-8,1,27:17.12
-7,1,27:17.12
-6,1,27:17.12
-5,1,27:17.12
-4,1,27:17.12
-3,1,27:17.12
-2,1,27:17.12
-1,1,27:17.12
0,1,27:17.12
20,1,27:18.12
-8,2,27:17.12
-7,2,27:17.12
-6,2,27:17.12
-5,2,27:17.12
-4,2,27:17.12
-3,2,27:17.12
-2,2,27:17.12
-1,2,27:17.12
0,2,27:18.12
1,2,27:17.12
21,2,27:18.12
28,2,27:18.12
29,2,27:18.12
-8,3,27:17.12
-7,3,27:17.12
-6,3,27:17.12
-5,3,27:17.12
-4,3,27:17.12
-3,3,27:17.12
-2,3,27:17.12
-1,3,27:18.12
0,3,27:18.12
1,3,27:17.12
2,3,27:17.12
-8,4,27:17.12
-7,4,27:17.12
-6,4,27:17.12
-5,4,27:17.12
-4,4,27:17.12
-3,4,27:17.12
-2,4,27:17.12
-1,4,27:17.12
0,4,27:18.12
1,4,27:17.12
2,4,27:18.12
-6,5,27:17.12
-5,5,27:17.12
-4,5,27:17.12
-3,5,27:17.12
-2,5,27:17.12
-1,5,27:17.12
0,5,27:17.12
1,5,27:17.12
2,5,27:17.12
3,5,27:17.12
25,5,27:18.12
-4,6,27:17.12
-3,6,27:17.12
-2,6,27:17.12
-1,6,27:17.12
0,6,27:17.12
1,6,27:17.12
2,6,27:17.12
20,6,27:18.12
25,6,27:18.12
28,6,27:18.12
29,6,27:18.12
19,7,27:18.12
20,7,27:18.12
21,7,27:18.12
25,7,27:18.12
26,7,27:18.12
29,7,27:18.12
30,7,27:18.12
21,8,27:18.12
22,8,27:18.12
23,8,27:18.12
25,8,27:18.12
26,8,27:18.12
27,8,27:18.12
28,8,27:18.12
30,8,27:18.12
31,8,27:18.12
32,8,27:18.12
24,9,27:18.12
25,9,27:18.12
26,9,27:18.12
27,9,27:18.12
28,9,27:18.12
32,9,27:18.12
24,10,27:18.12
25,10,27:18.12
28,10,27:18.12
31,10,27:18.12
23,11,27:18.12
24,11,27:18.12
31,11,27:18.12
24,12,27:18.12
32,12,27:18.12
29,13,27:18.12
19,14,27:18.12
21,14,27:18.12
18,15,27:18.12
19,15,27:18.12
20,15,27:18.12
21,15,27:18.12
22,15,27:18.12
19,16,27:18.12
20,16,27:18.12
21,16,27:18.12
22,16,27:18.12
27,16,27:18.12
28,16,27:18.12
29,16,27:18.12
30,16,27:18.12
19,17,27:18.12
27,17,27:18.12
28,17,27:18.12
29,17,27:18.12
30,17,27:18.12
23,18,27:18.12
24,18,27:18.12
27,18,27:18.12
28,18,27:18.12
30,18,27:18.12
23,19,27:18.12
27,19,27:18.12
28,19,27:18.12
29,19,27:18.12
23,20,27:18.12
26,20,27:18.12
27,20,27:18.12
-4,-14,28:17.12
-3,-14,28:17.12
-2,-14,28:17.12
-1,-14,28:17.12
-4,-13,28:17.12
-3,-13,28:17.12
-2,-13,28:17.12
-1,-13,28:17.12
-5,-12,28:17.12
-4,-12,28:17.12
-3,-12,28:17.12
-2,-12,28:17.12
-1,-12,28:17.12
-6,-11,28:17.12
-5,-11,28:17.12
-4,-11,28:17.12
-3,-11,28:17.12
-2,-11,28:17.12
-6,-10,28:17.12
-5,-10,28:17.12
-4,-10,28:17.12
-3,-10,28:17.12
-2,-10,28:17.12
-6,-9,28:17.12
-5,-9,28:17.12
-4,-9,28:17.12
-3,-9,28:17.12
-2,-9,28:17.12
-5,-8,28:17.12
-4,-8,28:17.12
-3,-8,28:17.12
-2,-8,28:17.12
2,-8,28:17.12
3,-8,28:17.12
4,-8,28:17.12
-5,-7,28:17.12
-4,-7,28:17.12
-3,-7,28:17.12
-2,-7,28:17.12
-1,-7,28:17.12
0,-7,28:17.12
1,-7,28:17.12
2,-7,28:17.12
3,-7,28:17.12
4,-7,28:17.12
5,-7,28:17.12
-5,-6,28:17.12
-4,-6,28:17.12
-3,-6,28:17.12
-2,-6,28:17.12
-1,-6,28:17.12
0,-6,28:17.12
1,-6,28:17.12
2,-6,28:17.12
3,-6,28:17.12
4,-6,28:17.12
5,-6,28:17.12
-6,-5,28:17.12
-5,-5,28:17.12
-4,-5,28:17.12
-3,-5,28:17.12
-2,-5,28:17.12
-1,-5,28:17.12
0,-5,28:17.12
1,-5,28:17.12
2,-5,28:17.12
3,-5,28:17.12
4,-5,28:17.12
0,-4,28:17.12
1,-4,28:17.12
2,-4,28:17.12
3,-4,28:17.12
22,-4,28:18.12
-6,-1,28:17.12
-5,-1,28:17.12
-8,0,28:17.12
-7,0,28:17.12
-6,0,28:17.12
-5,0,28:17.12
-4,0,28:17.12
-3,0,28:17.12
-2,0,28:17.12
20,0,28:18.12
29,0,28:18.12
-8,1,28:17.12
-7,1,28:17.12
-6,1,28:17.12
-5,1,28:17.12
-4,1,28:17.12
-3,1,28:18.12
-2,1,28:17.12
-1,1,28:17.12
-9,2,28:17.12
-8,2,28:17.12
-7,2,28:17.12
-6,2,28:17.12
-5,2,28:17.12
-4,2,28:17.12
-3,2,28:18.12
-2,2,28:17.12
-1,2,28:17.12
0,2,28:17.12
1,2,28:18.12
2,2,28:18.12
-9,3,28:17.12
-8,3,28:17.12
-7,3,28:17.12
-6,3,28:17.12
-5,3,28:17.12
-4,3,28:17.12
-3,3,28:18.12
-2,3,28:17.12
-1,3,28:18.12
0,3,28:18.12
1,3,28:18.12
2,3,28:18.12
-8,4,28:17.12
-7,4,28:17.12
-6,4,28:17.12
-5,4,28:17.12
-4,4,28:17.12
-3,4,28:18.12
-2,4,28:17.12
-1,4,28:18.12
0,4,28:18.12
1,4,28:18.12
2,4,28:18.12
3,4,28:17.12
-7,5,28:17.12
-6,5,28:17.12
-5,5,28:17.12
-4,5,28:17.12
-3,5,28:17.12
-2,5,28:17.12
-1,5,28:18.12
0,5,28:18.12
1,5,28:18.12
2,5,28:17.12
3,5,28:17.12
4,5,28:17.12
5,5,28:17.12
-5,6,28:17.12
-4,6,28:17.12
-3,6,28:17.12
-2,6,28:18.12
-1,6,28:18.12
0,6,28:18.12
1,6,28:18.12
2,6,28:17.12
3,6,28:17.12
4,6,28:17.12
5,6,28:17.12
-3,7,28:17.12
-2,7,28:17.12
-1,7,28:17.12
0,7,28:17.12
1,7,28:18.12
2,7,28:17.12
28,7,28:18.12
29,7,28:18.12
21,8,28:18.12
26,8,28:18.12
24,9,28:18.12
20,14,28:18.12
20,15,28:18.12
19,16,28:18.12
21,16,28:18.12
21,17,28:18.12
26,17,28:18.12
27,17,28:18.12
28,17,28:18.12
29,17,28:18.12
30,17,28:18.12
26,18,28:18.12
27,18,28:18.12
28,18,28:18.12
27,19,28:18.12
28,19,28:18.12
-4,-16,29:17.12
-3,-16,29:17.12
-2,-16,29:17.12
-4,-15,29:17.12
-3,-15,29:17.12
-2,-15,29:17.12
-1,-15,29:17.12
-4,-14,29:17.12
-3,-14,29:17.12
-2,-14,29:17.12
-1,-14,29:17.12
-5,-13,29:17.12
-4,-13,29:17.12
-3,-13,29:17.12
-2,-13,29:17.12
-1,-13,29:17.12
-6,-12,29:17.12
-5,-12,29:17.12
-4,-12,29:17.12
-3,-12,29:17.12
-2,-12,29:17.12
-1,-12,29:17.12
-6,-11,29:17.12
-5,-11,29:17.12
-4,-11,29:17.12
-3,-11,29:17.12
-2,-11,29:17.12
-6,-10,29:17.12
-5,-10,29:17.12
-4,-10,29:17.12
-3,-10,29:17.12
-5,-9,29:17.12
-4,-9,29:17.12
-3,-9,29:17.12
4,-9,29:17.12
-4,-8,29:17.12
2,-8,29:17.12
3,-8,29:17.12
4,-8,29:17.12
5,-8,29:17.12
6,-8,29:17.12
1,-7,29:17.12
2,-7,29:17.12
3,-7,29:17.12
4,-7,29:17.12
5,-7,29:17.12
6,-7,29:17.12
1,-6,29:17.12
2,-6,29:17.12
3,-6,29:17.12
4,-6,29:17.12
5,-6,29:17.12
6,-6,29:17.12
1,-5,29:17.12
2,-5,29:17.12
3,-5,29:17.12
4,-5,29:17.12
5,-5,29:17.12
2,-4,29:17.12
3,-4,29:17.12
-8,0,29:17.12
-7,0,29:17.12
-6,0,29:17.12
-5,0,29:17.12
-9,1,29:17.12
-8,1,29:17.12
-7,1,29:17.12
-6,1,29:17.12
-5,1,29:17.12
-4,1,29:17.12
-3,1,29:17.12
-2,1,29:17.12
-9,2,29:17.12
-8,2,29:17.12
-7,2,29:17.12
-6,2,29:17.12
-5,2,29:17.12
-4,2,29:18.12
-3,2,29:18.12
-2,2,29:17.12
-1,2,29:18.12
0,2,29:18.12
1,2,29:18.12
2,2,29:18.12
-9,3,29:17.12
-8,3,29:17.12
-7,3,29:17.12
-6,3,29:17.12
-5,3,29:18.12
-4,3,29:18.12
-3,3,29:18.12
-2,3,29:18.12
-1,3,29:18.12
0,3,29:18.12
1,3,29:18.12
2,3,29:18.12
-9,4,29:17.12
-8,4,29:17.12
-7,4,29:17.12
-6,4,29:17.12
-5,4,29:18.12
-4,4,29:18.12
-3,4,29:18.12
-2,4,29:18.12
-1,4,29:18.12
0,4,29:18.12
1,4,29:18.12
2,4,29:17.12
3,4,29:17.12
4,4,29:17.12
-8,5,29:17.12
-7,5,29:17.12
-6,5,29:17.12
-5,5,29:17.12
-4,5,29:18.12
-3,5,29:18.12
-2,5,29:18.12
-1,5,29:18.12
0,5,29:18.12
1,5,29:18.12
2,5,29:17.12
3,5,29:17.12
4,5,29:17.12
5,5,29:17.12
6,5,29:17.12
-6,6,29:17.12
-5,6,29:17.12
-4,6,29:17.12
-3,6,29:18.12
-2,6,29:17.12
-1,6,29:18.12
0,6,29:18.12
1,6,29:17.12
2,6,29:17.12
3,6,29:17.12
4,6,29:17.12
5,6,29:17.12
6,6,29:17.12
-4,7,29:17.12
-3,7,29:17.12
-2,7,29:17.12
-1,7,29:18.12
0,7,29:18.12
1,7,29:17.12
2,7,29:17.12
3,7,29:17.12
4,7,29:17.12
5,7,29:17.12
6,7,29:17.12
7,7,29:17.12
-3,8,29:17.12
-2,8,29:17.12
29,17,29:18.12
-2,-18,30:17.12
-4,-17,30:17.12
-3,-17,30:17.12
-2,-17,30:17.12
-4,-16,30:17.12
-3,-16,30:17.12
-2,-16,30:17.12
-1,-16,30:17.12
-5,-15,30:17.12
-4,-15,30:17.12
-3,-15,30:17.12
-2,-15,30:17.12
-1,-15,30:17.12
-5,-14,30:17.12
-4,-14,30:17.12
-3,-14,30:17.12
-2,-14,30:17.12
-1,-14,30:17.12
-5,-13,30:17.12
-4,-13,30:17.12
-3,-13,30:17.12
-2,-13,30:17.12
-1,-13,30:17.12
-5,-12,30:17.12
-4,-12,30:17.12
-3,-12,30:17.12
-2,-12,30:17.12
-6,-11,30:17.12
-5,-11,30:17.12
-4,-11,30:17.12
-3,-11,30:17.12
-6,-10,30:17.12
-5,-10,30:17.12
-4,-10,30:17.12
4,-9,30:17.12
5,-9,30:17.12
6,-9,30:17.12
3,-8,30:17.12
4,-8,30:17.12
5,-8,30:17.12
6,-8,30:17.12
7,-8,30:17.12
2,-7,30:17.12
3,-7,30:17.12
4,-7,30:17.12
5,-7,30:17.12
6,-7,30:17.12
7,-7,30:17.12
2,-6,30:17.12
3,-6,30:17.12
4,-6,30:17.12
5,-6,30:17.12
6,-6,30:17.12
3,-5,30:17.12
4,-5,30:17.12
5,-5,30:17.12
-8,0,30:17.12
-7,0,30:17.12
-6,0,30:17.12
-9,1,30:17.12
-8,1,30:17.12
-7,1,30:17.12
-6,1,30:17.12
-5,1,30:17.12
-4,1,30:17.12
-3,1,30:18.12
-10,2,30:17.12
-9,2,30:17.12
-8,2,30:17.12
-7,2,30:17.12
-6,2,30:17.12
-5,2,30:17.12
-4,2,30:18.12
-3,2,30:18.12
-10,3,30:17.12
-9,3,30:17.12
-8,3,30:17.12
-7,3,30:17.12
-6,3,30:17.12
-5,3,30:18.12
-4,3,30:18.12
-3,3,30:18.12
-2,3,30:18.12
2,3,30:18.12
-10,4,30:17.12
-9,4,30:17.12
-8,4,30:17.12
-7,4,30:17.12
-6,4,30:17.12
-5,4,30:17.12
-4,4,30:18.12
-3,4,30:18.12
-2,4,30:18.12
-1,4,30:18.12
0,4,30:18.12
1,4,30:18.12
2,4,30:18.12
3,4,30:17.12
4,4,30:17.12
5,4,30:17.12
6,4,30:17.12
-9,5,30:17.12
-8,5,30:17.12
-7,5,30:17.12
-6,5,30:17.12
-5,5,30:17.12
-4,5,30:18.12
-3,5,30:18.12
-2,5,30:18.12
-1,5,30:18.12
0,5,30:18.12
1,5,30:18.12
2,5,30:18.12
3,5,30:17.12
4,5,30:17.12
5,5,30:17.12
6,5,30:17.12
-7,6,30:18.12
-6,6,30:17.12
-5,6,30:18.12
-4,6,30:17.12
-3,6,30:17.12
-2,6,30:18.12
-1,6,30:18.12
0,6,30:18.12
1,6,30:18.12
2,6,30:17.12
3,6,30:17.12
4,6,30:17.12
5,6,30:17.12
6,6,30:17.12
7,6,30:17.12
-4,7,30:17.12
-3,7,30:17.12
-2,7,30:17.12
-1,7,30:18.12
0,7,30:18.12
1,7,30:18.12
2,7,30:18.12
4,7,30:17.12
5,7,30:17.12
6,7,30:17.12
7,7,30:17.12
8,7,30:17.12
-3,8,30:17.12
-2,8,30:17.12
-1,8,30:17.12
1,8,30:18.12
5,8,30:17.12
6,8,30:17.12
7,8,30:17.12
8,8,30:17.12
-3,9,30:17.12
-2,9,30:17.12
11,9,30:18.12
-2,10,30:17.12
7,13,30:18.12
-3,-19,31:17.12
-2,-19,31:17.12
-4,-18,31:17.12
-3,-18,31:17.12
-2,-18,31:17.12
-4,-17,31:17.12
-3,-17,31:17.12
-2,-17,31:17.12
-1,-17,31:17.12
-5,-16,31:17.12
-4,-16,31:17.12
-3,-16,31:17.12
-2,-16,31:17.12
-1,-16,31:17.12
-5,-15,31:17.12
-4,-15,31:17.12
-3,-15,31:17.12
-2,-15,31:17.12
-1,-15,31:17.12
-5,-14,31:17.12
-4,-14,31:17.12
-3,-14,31:17.12
-2,-14,31:17.12
-5,-13,31:17.12
-4,-13,31:17.12
-3,-13,31:17.12
-2,-13,31:17.12
-4,-12,31:17.12
6,-10,31:17.12
7,-10,31:17.12
5,-9,31:17.12
6,-9,31:17.12
7,-9,31:17.12
8,-9,31:17.12
3,-8,31:17.12
4,-8,31:17.12
5,-8,31:17.12
6,-8,31:17.12
7,-8,31:17.12
8,-8,31:17.12
3,-7,31:17.12
4,-7,31:17.12
5,-7,31:17.12
6,-7,31:17.12
7,-7,31:17.12
8,-7,31:17.12
3,-6,31:17.12
4,-6,31:17.12
5,-6,31:17.12
6,-6,31:17.12
7,-6,31:17.12
5,-5,31:17.12
6,-5,31:17.12
-8,-1,31:17.12
-7,-1,31:17.12
-9,0,31:17.12
-8,0,31:17.12
-7,0,31:17.12
-6,0,31:17.12
-10,1,31:17.12
-9,1,31:17.12
-8,1,31:17.12
-7,1,31:17.12
-6,1,31:17.12
-5,1,31:18.12
-4,1,31:18.12
-3,1,31:18.12
-11,2,31:17.12
-10,2,31:17.12
-9,2,31:17.12
-8,2,31:17.12
-7,2,31:17.12
-6,2,31:17.12
-5,2,31:17.12
-4,2,31:18.12
-3,2,31:18.12
-11,3,31:17.12
-10,3,31:17.12
-9,3,31:17.12
-8,3,31:17.12
-7,3,31:17.12
-6,3,31:17.12
-5,3,31:18.12
-4,3,31:18.12
-3,3,31:18.12
-2,3,31:18.12
-1,3,31:18.12
0,3,31:18.12
1,3,31:18.12
2,3,31:18.12
4,3,31:17.12
9,3,31:18.12
-11,4,31:17.12
-10,4,31:17.12
-9,4,31:17.12
-8,4,31:17.12
-7,4,31:18.12
-6,4,31:18.12
-5,4,31:18.12
-4,4,31:18.12
-3,4,31:18.12
-1,4,31:18.12
0,4,31:18.12
3,4,31:17.12
4,4,31:17.12
5,4,31:17.12
6,4,31:17.12
-10,5,31:17.12
-9,5,31:17.12
-8,5,31:17.12
-7,5,31:18.12
-6,5,31:18.12
-5,5,31:17.12
-4,5,31:18.12
-3,5,31:18.12
-2,5,31:18.12
-1,5,31:18.12
0,5,31:18.12
1,5,31:18.12
2,5,31:17.12
3,5,31:17.12
4,5,31:17.12
5,5,31:17.12
6,5,31:17.12
7,5,31:17.12
-8,6,31:17.12
-7,6,31:18.12
-6,6,31:18.12
-5,6,31:18.12
-4,6,31:17.12
-3,6,31:17.12
0,6,31:18.12
1,6,31:18.12
3,6,31:17.12
4,6,31:17.12
5,6,31:17.12
6,6,31:17.12
7,6,31:17.12
8,6,31:17.12
-7,7,31:18.12
-4,7,31:17.12
-3,7,31:17.12
-2,7,31:17.12
-1,7,31:17.12
4,7,31:17.12
5,7,31:17.12
6,7,31:17.12
7,7,31:17.12
8,7,31:18.12
-3,8,31:17.12
-2,8,31:17.12
-1,8,31:17.12
6,8,31:17.12
7,8,31:17.12
8,8,31:18.12
9,8,31:18.12
10,8,31:18.12
-3,9,31:17.12
-2,9,31:17.12
-1,9,31:17.12
7,9,31:17.12
8,9,31:17.12
9,9,31:17.12
10,9,31:17.12
11,9,31:18.12
12,9,31:18.12
-2,10,31:17.12
6,10,31:18.12
8,10,31:17.12
9,10,31:17.12
12,10,31:18.12
12,11,31:18.12
13,11,31:18.12
7,13,31:18.12
7,14,31:18.12
9,14,31:18.12
7,15,31:18.12
-3,-20,32:17.12
-2,-20,32:17.12
-4,-19,32:17.12
-3,-19,32:17.12
-2,-19,32:17.12
-5,-18,32:17.12
-4,-18,32:17.12
-3,-18,32:17.12
-2,-18,32:17.12
-1,-18,32:17.12
-5,-17,32:17.12
-4,-17,32:17.12
-3,-17,32:17.12
-2,-17,32:17.12
-1,-17,32:17.12
-5,-16,32:17.12
-4,-16,32:17.12
-3,-16,32:17.12
-2,-16,32:17.12
-1,-16,32:17.12
-5,-15,32:17.12
-4,-15,32:17.12
-3,-15,32:17.12
-2,-15,32:17.12
-4,-14,32:17.12
-3,-14,32:17.12
-2,-14,32:17.12
9,-11,32:17.12
6,-10,32:17.12
7,-10,32:17.12
8,-10,32:17.12
9,-10,32:17.12
10,-10,32:17.12
5,-9,32:17.12
6,-9,32:17.12
7,-9,32:17.12
8,-9,32:17.12
9,-9,32:17.12
10,-9,32:17.12
4,-8,32:17.12
5,-8,32:17.12
6,-8,32:17.12
7,-8,32:17.12
8,-8,32:17.12
9,-8,32:17.12
4,-7,32:17.12
5,-7,32:17.12
6,-7,32:17.12
7,-7,32:17.12
8,-7,32:17.12
9,-7,32:17.12
5,-6,32:17.12
6,-6,32:17.12
7,-6,32:17.12
8,-6,32:17.12
-7,-2,32:17.12
-8,-1,32:17.12
-7,-1,32:17.12
-9,0,32:17.12
-8,0,32:17.12
-7,0,32:17.12
-6,0,32:17.12
-10,1,32:17.12
-9,1,32:17.12
-8,1,32:17.12
-7,1,32:17.12
-6,1,32:17.12
-5,1,32:18.12
-4,1,32:18.12
10,1,32:18.12
-11,2,32:17.12
-10,2,32:17.12
-9,2,32:17.12
-8,2,32:17.12
-7,2,32:17.12
-6,2,32:17.12
-5,2,32:17.12
8,2,32:18.12
10,2,32:18.12
-12,3,32:17.12
-11,3,32:17.12
-10,3,32:17.12
-9,3,32:17.12
-8,3,32:17.12
-7,3,32:17.12
-6,3,32:18.12
-5,3,32:17.12
-4,3,32:18.12
7,3,32:18.12
8,3,32:18.12
9,3,32:18.12
10,3,32:18.12
11,3,32:18.12
-12,4,32:17.12
-11,4,32:17.12
-10,4,32:17.12
-9,4,32:17.12
-8,4,32:18.12
-7,4,32:18.12
-6,4,32:18.12
-5,4,32:18.12
-4,4,32:18.12
-3,4,32:18.12
3,4,32:17.12
4,4,32:17.12
5,4,32:17.12
6,4,32:17.12
8,4,32:18.12
9,4,32:18.12
10,4,32:18.12
11,4,32:18.12
12,4,32:18.12
-11,5,32:17.12
-10,5,32:17.12
-9,5,32:18.12
-8,5,32:18.12
-7,5,32:17.12
-6,5,32:18.12
-5,5,32:17.12
-4,5,32:17.12
-2,5,32:18.12
-1,5,32:18.12
0,5,32:18.12
3,5,32:17.12
4,5,32:17.12
5,5,32:17.12
6,5,32:17.12
7,5,32:17.12
10,5,32:18.12
12,5,32:18.12
-10,6,32:17.12
-9,6,32:18.12
-8,6,32:17.12
-7,6,32:18.12
-6,6,32:17.12
-5,6,32:18.12
-4,6,32:17.12
0,6,32:18.12
1,6,32:18.12
3,6,32:17.12
4,6,32:17.12
5,6,32:17.12
6,6,32:17.12
7,6,32:17.12
8,6,32:18.12
9,6,32:18.12
10,6,32:18.12
11,6,32:18.12
-7,7,32:17.12
6,7,32:17.12
7,7,32:18.12
8,7,32:18.12
9,7,32:18.12
-3,8,32:17.12
-2,8,32:18.12
-1,8,32:18.12
6,8,32:17.12
7,8,32:17.12
8,8,32:17.12
9,8,32:18.12
10,8,32:17.12
-3,9,32:18.12
-2,9,32:18.12
-1,9,32:17.12
6,9,32:18.12
7,9,32:17.12
8,9,32:17.12
9,9,32:17.12
10,9,32:17.12
11,9,32:18.12
12,9,32:18.12
-3,10,32:17.12
-2,10,32:18.12
-1,10,32:17.12
4,10,32:18.12
5,10,32:18.12
6,10,32:18.12
7,10,32:18.12
8,10,32:18.12
9,10,32:17.12
10,10,32:17.12
11,10,32:18.12
12,10,32:18.12
-3,11,32:18.12
8,11,32:18.12
9,11,32:17.12
10,11,32:17.12
11,11,32:18.12
12,11,32:18.12
7,12,32:18.12
12,12,32:18.12
6,13,32:18.12
7,13,32:18.12
8,13,32:18.12
9,13,32:18.12
10,13,32:18.12
-6,14,32:18.12
-5,14,32:18.12
7,14,32:18.12
9,14,32:18.12
-6,-21,33:18.12
-5,-21,33:18.12
-3,-21,33:17.12
-2,-21,33:17.12
-4,-20,33:17.12
-3,-20,33:17.12
-2,-20,33:17.12
-1,-20,33:17.12
-4,-19,33:18.12
-3,-19,33:18.12
-2,-19,33:17.12
-1,-19,33:17.12
-5,-18,33:17.12
-4,-18,33:17.12
-3,-18,33:17.12
-2,-18,33:17.12
-1,-18,33:17.12
-5,-17,33:17.12
-4,-17,33:17.12
-3,-17,33:17.12
-2,-17,33:17.12
-1,-17,33:17.12
-5,-16,33:17.12
-4,-16,33:17.12
-3,-16,33:17.12
-2,-16,33:17.12
-4,-15,33:17.12
-3,-15,33:17.12
7,-11,33:17.12
8,-11,33:17.12
9,-11,33:17.12
10,-11,33:17.12
6,-10,33:17.12
7,-10,33:17.12
8,-10,33:17.12
9,-10,33:17.12
10,-10,33:17.12
5,-9,33:17.12
6,-9,33:17.12
7,-9,33:17.12
8,-9,33:18.12
9,-9,33:18.12
10,-9,33:17.12
5,-8,33:17.12
6,-8,33:17.12
7,-8,33:17.12
8,-8,33:18.12
9,-8,33:18.12
10,-8,33:18.12
5,-7,33:17.12
6,-7,33:17.12
7,-7,33:17.12
8,-7,33:18.12
9,-7,33:17.12
7,-6,33:17.12
8,-6,33:17.12
-7,-5,33:17.12
-6,-5,33:17.12
-7,-4,33:17.12
-8,-3,33:17.12
-7,-3,33:17.12
-8,-2,33:17.12
-7,-2,33:17.12
-8,-1,33:17.12
-7,-1,33:17.12
-10,0,33:17.12
-9,0,33:17.12
-8,0,33:17.12
-7,0,33:17.12
-6,0,33:17.12
-11,1,33:17.12
-10,1,33:17.12
-9,1,33:17.12
-8,1,33:17.12
-7,1,33:17.12
-6,1,33:17.12
8,1,33:18.12
-12,2,33:17.12
-11,2,33:17.12
-10,2,33:17.12
-9,2,33:17.12
-8,2,33:17.12
-7,2,33:17.12
-6,2,33:18.12
-5,2,33:17.12
7,2,33:18.12
8,2,33:18.12
9,2,33:18.12
-13,3,33:17.12
-12,3,33:17.12
-11,3,33:17.12
-10,3,33:17.12
-9,3,33:17.12
-8,3,33:17.12
-7,3,33:18.12
-6,3,33:18.12
-5,3,33:17.12
6,3,33:17.12
7,3,33:18.12
8,3,33:18.12
9,3,33:18.12
-12,4,33:17.12
-11,4,33:17.12
-10,4,33:17.12
-9,4,33:18.12
-8,4,33:18.12
-7,4,33:17.12
-6,4,33:18.12
-5,4,33:18.12
-4,4,33:18.12
5,4,33:17.12
6,4,33:17.12
7,4,33:18.12
8,4,33:18.12
9,4,33:18.12
10,4,33:18.12
11,4,33:18.12
-12,5,33:17.12
-11,5,33:17.12
-10,5,33:17.12
-9,5,33:18.12
-8,5,33:18.12
-7,5,33:18.12
-6,5,33:18.12
-5,5,33:18.12
-4,5,33:18.12
0,5,33:18.12
4,5,33:17.12
5,5,33:17.12
6,5,33:17.12
7,5,33:18.12
8,5,33:18.12
9,5,33:18.12
11,5,33:18.12
-10,6,33:18.12
-9,6,33:18.12
-8,6,33:18.12
-7,6,33:18.12
-6,6,33:17.12
0,6,33:18.12
6,6,33:17.12
7,6,33:17.12
8,6,33:18.12
9,6,33:18.12
10,6,33:18.12
11,6,33:18.12
-9,7,33:18.12
-8,7,33:18.12
-7,7,33:18.12
-2,7,33:18.12
7,7,33:18.12
8,7,33:18.12
9,7,33:18.12
10,7,33:18.12
-6,8,33:18.12
-5,8,33:18.12
-4,8,33:18.12
-3,8,33:18.12
-2,8,33:18.12
-1,8,33:17.12
7,8,33:18.12
8,8,33:18.12
9,8,33:18.12
10,8,33:18.12
11,8,33:17.12
12,8,33:18.12
16,8,33:18.12
-4,9,33:17.12
-3,9,33:18.12
-2,9,33:18.12
-1,9,33:18.12
0,9,33:17.12
7,9,33:18.12
8,9,33:17.12
9,9,33:17.12
10,9,33:17.12
11,9,33:18.12
12,9,33:18.12
-3,10,33:18.12
-2,10,33:18.12
-1,10,33:18.12
0,10,33:18.12
4,10,33:18.12
5,10,33:18.12
6,10,33:18.12
7,10,33:18.12
8,10,33:17.12
9,10,33:17.12
10,10,33:17.12
11,10,33:18.12
12,10,33:18.12
13,10,33:18.12
-4,11,33:18.12
-3,11,33:18.12
-2,11,33:18.12
-1,11,33:18.12
1,11,33:18.12
6,11,33:18.12
7,11,33:18.12
