[META]
version=2.0
spawnOnBlockType=2
spawnSunlight=True
spawnDarkness=True
spawnWater=False
spawnLava=False
underFill=False
randomRotation=True
dig=True
tree=False
branch=False
needsFoundation=True
rarity=100
collisionPercentage=20
spawnElevationMin=0
spawnElevationMax=200
spawnInBiome=Custom
[DATA]
2,-3,-4:17.0
2,-3,-3:17.0
2,-3,-2:17.0
2,-3,-1:17.0
2,-3,0:17.12
2,-3,1:17.12
2,-3,2:17.12
2,-3,3:17.12
2,-3,4:17.12
-6,-1,4:18.1
-5,-1,4:18.1
-7,0,4:18.1
-6,0,4:18.1
-5,0,4:18.1
-4,0,4:18.1
-8,1,4:18.1
-7,1,4:18.1
-6,1,4:18.1
-5,1,4:17.12
-4,1,4:18.1
-8,2,4:18.1
-7,2,4:18.1
-6,2,4:18.1
-5,2,4:18.1
-7,3,4:18.1
-6,3,4:18.1
2,-3,5:17.12
-5,-2,5:18.1
-4,-2,5:18.1
-3,-2,5:18.1
-2,-2,5:18.1
-6,-1,5:18.1
-5,-1,5:18.1
-4,-1,5:18.1
-3,-1,5:18.1
-2,-1,5:18.1
-1,-1,5:18.1
-7,0,5:80.0
-6,0,5:18.1
-5,0,5:18.1
-4,0,5:18.1
-3,0,5:18.1
-2,0,5:18.1
-1,0,5:18.1
-8,1,5:80.0
-7,1,5:80.0
-6,1,5:80.0
-5,1,5:18.1
-4,1,5:18.1
-3,1,5:18.1
-2,1,5:18.1
0,1,5:18.1
1,1,5:18.1
-8,2,5:80.0
-7,2,5:80.0
-6,2,5:80.0
-5,2,5:80.0
-1,2,5:18.1
0,2,5:18.1
1,2,5:18.1
2,2,5:18.1
-7,3,5:80.0
-6,3,5:80.0
-1,3,5:18.1
0,3,5:17.12
1,3,5:18.1
2,3,5:18.1
6,3,5:18.1
7,3,5:18.1
-1,4,5:18.1
0,4,5:18.1
1,4,5:18.1
2,4,5:18.1
5,4,5:18.1
6,4,5:18.1
7,4,5:18.1
8,4,5:18.1
-1,5,5:18.1
0,5,5:18.1
1,5,5:18.1
2,5,5:18.1
5,5,5:18.1
6,5,5:18.1
7,5,5:18.1
8,5,5:18.1
0,6,5:18.1
1,6,5:18.1
6,6,5:18.1
7,6,5:18.1
-2,-3,6:18.1
-1,-3,6:18.1
0,-3,6:18.1
1,-3,6:18.1
2,-3,6:17.12
8,-3,6:18.1
9,-3,6:18.1
10,-3,6:18.1
-5,-2,6:80.0
-4,-2,6:80.0
-3,-2,6:18.1
-2,-2,6:18.1
-1,-2,6:18.1
0,-2,6:18.1
1,-2,6:18.1
2,-2,6:18.1
3,-2,6:18.1
7,-2,6:18.1
8,-2,6:18.1
9,-2,6:18.1
10,-2,6:18.1
11,-2,6:18.1
-6,-1,6:80.0
-5,-1,6:80.0
-4,-1,6:80.0
-3,-1,6:18.1
-2,-1,6:17.12
-1,-1,6:18.1
0,-1,6:18.1
1,-1,6:18.1
2,-1,6:18.1
3,-1,6:18.1
7,-1,6:18.1
8,-1,6:18.1
9,-1,6:18.1
10,-1,6:18.1
-6,0,6:80.0
-5,0,6:80.0
-4,0,6:80.0
-3,0,6:80.0
-2,0,6:18.1
-1,0,6:18.1
0,0,6:18.1
1,0,6:18.1
2,0,6:18.1
3,0,6:18.1
8,0,6:18.1
9,0,6:18.1
-5,1,6:80.0
-4,1,6:80.0
-3,1,6:80.0
-2,1,6:80.0
-1,1,6:18.1
0,1,6:18.1
1,1,6:18.1
2,1,6:18.1
3,1,6:18.1
5,1,6:18.1
6,1,6:18.1
-1,2,6:18.1
0,2,6:18.1
1,2,6:18.1
2,2,6:18.1
3,2,6:18.1
4,2,6:18.1
5,2,6:18.1
6,2,6:18.1
7,2,6:18.1
-1,3,6:18.1
0,3,6:18.1
1,3,6:18.1
2,3,6:18.1
3,3,6:18.1
4,3,6:18.1
5,3,6:18.1
6,3,6:18.1
7,3,6:18.1
-1,4,6:80.0
0,4,6:18.1
1,4,6:18.1
2,4,6:80.0
4,4,6:18.1
5,4,6:18.1
6,4,6:17.12
7,4,6:18.1
8,4,6:80.0
-1,5,6:80.0
0,5,6:80.0
1,5,6:80.0
2,5,6:80.0
5,5,6:18.1
6,5,6:18.1
7,5,6:80.0
8,5,6:80.0
0,6,6:80.0
1,6,6:80.0
6,6,6:80.0
7,6,6:80.0
0,-10,7:18.1
1,-10,7:18.1
-1,-9,7:18.1
0,-9,7:18.1
1,-9,7:18.1
2,-9,7:18.1
6,-9,7:18.1
7,-9,7:18.1
-1,-8,7:18.1
0,-8,7:18.1
1,-8,7:18.1
2,-8,7:18.1
5,-8,7:18.1
6,-8,7:18.1
7,-8,7:18.1
8,-8,7:18.1
0,-7,7:18.1
1,-7,7:18.1
4,-7,7:18.1
5,-7,7:18.1
6,-7,7:18.1
7,-7,7:18.1
8,-7,7:18.1
4,-6,7:18.1
5,-6,7:18.1
6,-6,7:18.1
7,-6,7:18.1
8,-6,7:18.1
5,-5,7:18.1
6,-5,7:18.1
7,-5,7:18.1
6,-4,7:18.1
-2,-3,7:80.0
-1,-3,7:80.0
0,-3,7:80.0
1,-3,7:18.1
2,-3,7:17.12
6,-3,7:18.1
7,-3,7:18.1
8,-3,7:18.1
9,-3,7:80.0
10,-3,7:80.0
-3,-2,7:80.0
-2,-2,7:80.0
-1,-2,7:80.0
0,-2,7:80.0
1,-2,7:18.1
2,-2,7:18.1
3,-2,7:18.1
4,-2,7:18.1
5,-2,7:18.1
6,-2,7:18.1
7,-2,7:18.1
8,-2,7:17.12
9,-2,7:18.1
10,-2,7:80.0
11,-2,7:80.0
-3,-1,7:80.0
-2,-1,7:80.0
-1,-1,7:80.0
0,-1,7:18.1
1,-1,7:18.1
2,-1,7:18.1
3,-1,7:18.1
4,-1,7:18.1
5,-1,7:18.1
6,-1,7:18.1
7,-1,7:18.1
8,-1,7:18.1
9,-1,7:18.1
10,-1,7:80.0
-2,0,7:80.0
-1,0,7:18.1
0,0,7:18.1
1,0,7:17.12
2,0,7:18.1
3,0,7:18.1
4,0,7:18.1
5,0,7:18.1
6,0,7:18.1
7,0,7:18.1
8,0,7:18.1
9,0,7:80.0
-1,1,7:18.1
0,1,7:18.1
1,1,7:18.1
2,1,7:18.1
3,1,7:18.1
4,1,7:18.1
5,1,7:17.12
6,1,7:18.1
-1,2,7:80.0
0,2,7:18.1
1,2,7:18.1
2,2,7:80.0
3,2,7:80.0
4,2,7:18.1
5,2,7:18.1
6,2,7:18.1
7,2,7:80.0
-1,3,7:80.0
0,3,7:80.0
1,3,7:80.0
2,3,7:80.0
3,3,7:80.0
4,3,7:80.0
5,3,7:18.1
6,3,7:18.1
7,3,7:80.0
0,4,7:80.0
1,4,7:80.0
4,4,7:80.0
5,4,7:80.0
6,4,7:80.0
7,4,7:80.0
5,5,7:80.0
6,5,7:80.0
0,-10,8:80.0
1,-10,8:80.0
-1,-9,8:80.0
0,-9,8:18.1
1,-9,8:18.1
2,-9,8:80.0
6,-9,8:80.0
7,-9,8:80.0
-1,-8,8:18.1
0,-8,8:17.12
1,-8,8:18.1
2,-8,8:18.1
5,-8,8:18.1
6,-8,8:18.1
7,-8,8:80.0
8,-8,8:80.0
-1,-7,8:18.1
0,-7,8:18.1
1,-7,8:18.1
2,-7,8:18.1
4,-7,8:18.1
5,-7,8:18.1
6,-7,8:17.12
7,-7,8:18.1
8,-7,8:80.0
-5,-6,8:18.1
-4,-6,8:18.1
-3,-6,8:18.1
-1,-6,8:18.1
0,-6,8:18.1
1,-6,8:18.1
2,-6,8:18.1
3,-6,8:18.1
4,-6,8:18.1
5,-6,8:18.1
6,-6,8:18.1
7,-6,8:18.1
8,-6,8:80.0
-6,-5,8:18.1
-5,-5,8:18.1
-4,-5,8:18.1
-3,-5,8:18.1
-2,-5,8:18.1
0,-5,8:18.1
1,-5,8:18.1
3,-5,8:18.1
4,-5,8:18.1
5,-5,8:18.1
6,-5,8:18.1
7,-5,8:80.0
-6,-4,8:18.1
-5,-4,8:18.1
-4,-4,8:18.1
-3,-4,8:17.12
-2,-4,8:18.1
3,-4,8:18.1
4,-4,8:18.1
5,-4,8:18.1
6,-4,8:80.0
-5,-3,8:18.1
-4,-3,8:18.1
-3,-3,8:18.1
1,-3,8:80.0
2,-3,8:17.12
3,-3,8:18.1
4,-3,8:18.1
5,-3,8:18.1
6,-3,8:18.1
7,-3,8:80.0
8,-3,8:80.0
1,-2,8:80.0
2,-2,8:18.1
3,-2,8:18.1
4,-2,8:17.12
5,-2,8:18.1
6,-2,8:18.1
7,-2,8:18.1
8,-2,8:80.0
9,-2,8:80.0
0,-1,8:80.0
1,-1,8:80.0
2,-1,8:18.1
3,-1,8:18.1
4,-1,8:18.1
5,-1,8:18.1
6,-1,8:18.1
7,-1,8:80.0
8,-1,8:80.0
9,-1,8:80.0
-1,0,8:80.0
0,0,8:80.0
1,0,8:80.0
2,0,8:80.0
3,0,8:80.0
4,0,8:18.1
5,0,8:18.1
6,0,8:80.0
7,0,8:80.0
8,0,8:80.0
-1,1,8:80.0
0,1,8:80.0
1,1,8:80.0
2,1,8:80.0
3,1,8:80.0
4,1,8:80.0
5,1,8:80.0
6,1,8:80.0
0,2,8:80.0
1,2,8:80.0
4,2,8:80.0
5,2,8:80.0
6,2,8:80.0
5,3,8:80.0
6,3,8:80.0
0,-9,9:80.0
1,-9,9:80.0
-1,-8,9:80.0
0,-8,9:80.0
1,-8,9:80.0
2,-8,9:80.0
5,-8,9:80.0
6,-8,9:80.0
-1,-7,9:80.0
0,-7,9:18.1
1,-7,9:18.1
2,-7,9:80.0
4,-7,9:80.0
5,-7,9:80.0
6,-7,9:80.0
7,-7,9:80.0
-5,-6,9:80.0
-4,-6,9:80.0
-3,-6,9:80.0
-1,-6,9:80.0
0,-6,9:18.1
1,-6,9:18.1
2,-6,9:80.0
3,-6,9:80.0
4,-6,9:80.0
5,-6,9:18.1
6,-6,9:18.1
7,-6,9:80.0
-6,-5,9:80.0
-5,-5,9:80.0
-4,-5,9:18.1
-3,-5,9:80.0
-2,-5,9:80.0
-1,-5,9:18.1
0,-5,9:18.1
1,-5,9:18.1
2,-5,9:18.1
3,-5,9:17.12
4,-5,9:18.1
5,-5,9:18.1
6,-5,9:80.0
-6,-4,9:80.0
-5,-4,9:80.0
-4,-4,9:18.1
-3,-4,9:18.1
-2,-4,9:18.1
-1,-4,9:18.1
0,-4,9:17.12
1,-4,9:18.1
2,-4,9:18.1
3,-4,9:18.1
4,-4,9:18.1
5,-4,9:80.0
-5,-3,9:80.0
-4,-3,9:18.1
-3,-3,9:18.1
-2,-3,9:18.1
-1,-3,9:18.1
0,-3,9:18.1
1,-3,9:18.1
2,-3,9:17.12
3,-3,9:80.0
4,-3,9:80.0
5,-3,9:80.0
6,-3,9:80.0
-3,-2,9:18.1
-2,-2,9:18.1
-1,-2,9:18.1
0,-2,9:18.1
1,-2,9:18.1
2,-2,9:80.0
3,-2,9:80.0
4,-2,9:80.0
5,-2,9:80.0
6,-2,9:80.0
7,-2,9:80.0
-3,-1,9:18.1
-2,-1,9:18.1
-1,-1,9:18.1
0,-1,9:18.1
1,-1,9:18.1
2,-1,9:80.0
3,-1,9:80.0
4,-1,9:80.0
5,-1,9:80.0
6,-1,9:80.0
-4,0,9:18.1
-3,0,9:18.1
-2,0,9:18.1
-1,0,9:18.1
0,0,9:18.1
4,0,9:80.0
5,0,9:80.0
-5,1,9:18.1
-4,1,9:18.1
-3,1,9:18.1
-2,1,9:18.1
-1,1,9:18.1
0,1,9:18.1
-5,2,9:18.1
-4,2,9:18.1
-3,2,9:18.1
-2,2,9:18.1
-1,2,9:18.1
-4,3,9:18.1
-3,3,9:18.1
-2,3,9:18.1
1,3,9:18.1
2,3,9:18.1
0,4,9:18.1
1,4,9:18.1
2,4,9:18.1
3,4,9:18.1
0,5,9:18.1
1,5,9:18.1
2,5,9:18.1
3,5,9:18.1
1,6,9:18.1
2,6,9:18.1
0,-7,10:80.0
1,-7,10:80.0
0,-6,10:80.0
1,-6,10:80.0
5,-6,10:80.0
6,-6,10:80.0
-4,-5,10:80.0
-1,-5,10:80.0
0,-5,10:80.0
1,-5,10:80.0
2,-5,10:80.0
3,-5,10:80.0
4,-5,10:80.0
5,-5,10:80.0
-4,-4,10:80.0
-3,-4,10:80.0
-2,-4,10:80.0
-1,-4,10:80.0
0,-4,10:18.1
1,-4,10:18.1
2,-4,10:80.0
3,-4,10:80.0
4,-4,10:80.0
-4,-3,10:80.0
-3,-3,10:80.0
-2,-3,10:80.0
-1,-3,10:18.1
0,-3,10:18.1
1,-3,10:18.1
2,-3,10:17.12
-3,-2,10:80.0
-2,-2,10:18.1
-1,-2,10:18.1
0,-2,10:17.12
1,-2,10:18.1
2,-2,10:18.1
3,-2,10:18.1
-3,-1,10:80.0
-2,-1,10:18.1
-1,-1,10:18.1
0,-1,10:18.1
1,-1,10:18.1
2,-1,10:18.1
3,-1,10:18.1
5,-1,10:18.1
6,-1,10:18.1
-4,0,10:80.0
-3,0,10:80.0
-2,0,10:18.1
-1,0,10:18.1
0,0,10:18.1
1,0,10:18.1
2,0,10:18.1
3,0,10:18.1
4,0,10:18.1
5,0,10:18.1
6,0,10:18.1
7,0,10:18.1
-5,1,10:80.0
-4,1,10:80.0
-3,1,10:17.12
-2,1,10:18.1
-1,1,10:18.1
0,1,10:18.1
1,1,10:18.1
2,1,10:18.1
3,1,10:18.1
4,1,10:18.1
5,1,10:18.1
6,1,10:18.1
7,1,10:18.1
8,1,10:18.1
-5,2,10:80.0
-4,2,10:80.0
-3,2,10:18.1
-2,2,10:18.1
-1,2,10:80.0
0,2,10:18.1
1,2,10:18.1
2,2,10:18.1
3,2,10:18.1
4,2,10:18.1
5,2,10:18.1
6,2,10:18.1
7,2,10:18.1
8,2,10:18.1
-4,3,10:80.0
-3,3,10:80.0
-2,3,10:80.0
0,3,10:18.1
1,3,10:18.1
2,3,10:18.1
3,3,10:18.1
5,3,10:18.1
6,3,10:18.1
7,3,10:18.1
0,4,10:18.1
1,4,10:18.1
2,4,10:17.12
3,4,10:18.1
0,5,10:80.0
1,5,10:18.1
2,5,10:18.1
3,5,10:80.0
1,6,10:80.0
2,6,10:80.0
2,-8,11:18.1
3,-8,11:18.1
1,-7,11:18.1
2,-7,11:18.1
3,-7,11:18.1
4,-7,11:18.1
1,-6,11:18.1
2,-6,11:18.1
3,-6,11:18.1
4,-6,11:18.1
1,-5,11:18.1
2,-5,11:18.1
3,-5,11:18.1
4,-5,11:18.1
6,-5,11:18.1
7,-5,11:18.1
8,-5,11:18.1
0,-4,11:80.0
1,-4,11:18.1
2,-4,11:18.1
5,-4,11:18.1
6,-4,11:18.1
7,-4,11:17.12
8,-4,11:18.1
9,-4,11:18.1
-1,-3,11:80.0
0,-3,11:80.0
1,-3,11:80.0
2,-3,11:17.12
3,-3,11:18.1
4,-3,11:18.1
5,-3,11:18.1
6,-3,11:18.1
7,-3,11:18.1
8,-3,11:18.1
9,-3,11:18.1
-2,-2,11:80.0
-1,-2,11:80.0
0,-2,11:80.0
1,-2,11:18.1
2,-2,11:18.1
3,-2,11:18.1
4,-2,11:18.1
5,-2,11:18.1
6,-2,11:18.1
7,-2,11:18.1
8,-2,11:18.1
-2,-1,11:80.0
-1,-1,11:80.0
0,-1,11:18.1
1,-1,11:18.1
2,-1,11:18.1
3,-1,11:18.1
4,-1,11:18.1
5,-1,11:18.1
6,-1,11:18.1
-2,0,11:80.0
-1,0,11:80.0
0,0,11:18.1
1,0,11:18.1
2,0,11:17.12
3,0,11:18.1
4,0,11:18.1
5,0,11:18.1
6,0,11:18.1
7,0,11:18.1
-3,1,11:80.0
-2,1,11:80.0
-1,1,11:80.0
0,1,11:18.1
1,1,11:18.1
2,1,11:18.1
3,1,11:18.1
4,1,11:18.1
5,1,11:18.1
6,1,11:17.12
7,1,11:18.1
8,1,11:18.1
-3,2,11:80.0
-2,2,11:80.0
0,2,11:18.1
1,2,11:18.1
2,2,11:18.1
3,2,11:18.1
4,2,11:18.1
5,2,11:18.1
6,2,11:18.1
7,2,11:18.1
8,2,11:18.1
0,3,11:80.0
1,3,11:18.1
2,3,11:18.1
3,3,11:80.0
5,3,11:80.0
6,3,11:18.1
7,3,11:18.1
0,4,11:80.0
1,4,11:80.0
2,4,11:80.0
3,4,11:80.0
1,5,11:80.0
2,5,11:80.0
-1,-8,12:18.1
0,-8,12:18.1
2,-8,12:80.0
3,-8,12:80.0
-2,-7,12:18.1
-1,-7,12:18.1
0,-7,12:18.1
1,-7,12:18.1
2,-7,12:80.0
3,-7,12:80.0
4,-7,12:80.0
-2,-6,12:18.1
-1,-6,12:18.1
0,-6,12:18.1
1,-6,12:18.1
2,-6,12:17.12
3,-6,12:18.1
4,-6,12:80.0
-2,-5,12:18.1
-1,-5,12:18.1
0,-5,12:18.1
1,-5,12:18.1
2,-5,12:18.1
3,-5,12:18.1
4,-5,12:18.1
5,-5,12:18.1
6,-5,12:80.0
7,-5,12:80.0
8,-5,12:80.0
-1,-4,12:18.1
0,-4,12:18.1
1,-4,12:80.0
2,-4,12:18.1
3,-4,12:18.1
4,-4,12:18.1
5,-4,12:18.1
6,-4,12:18.1
7,-4,12:80.0
8,-4,12:80.0
9,-4,12:80.0
2,-3,12:17.12
3,-3,12:18.1
4,-3,12:17.12
5,-3,12:18.1
6,-3,12:18.1
7,-3,12:80.0
8,-3,12:80.0
9,-3,12:80.0
1,-2,12:18.1
2,-2,12:18.1
3,-2,12:18.1
4,-2,12:18.1
5,-2,12:18.1
6,-2,12:80.0
7,-2,12:80.0
8,-2,12:80.0
0,-1,12:80.0
1,-1,12:80.0
2,-1,12:18.1
3,-1,12:18.1
4,-1,12:18.1
5,-1,12:18.1
6,-1,12:80.0
0,0,12:80.0
1,0,12:80.0
2,0,12:80.0
3,0,12:18.1
4,0,12:18.1
5,0,12:80.0
6,0,12:80.0
7,0,12:80.0
0,1,12:80.0
1,1,12:80.0
2,1,12:80.0
3,1,12:80.0
4,1,12:80.0
5,1,12:80.0
6,1,12:80.0
7,1,12:80.0
8,1,12:80.0
0,2,12:80.0
1,2,12:80.0
2,2,12:80.0
3,2,12:80.0
4,2,12:80.0
5,2,12:80.0
6,2,12:80.0
7,2,12:80.0
8,2,12:80.0
1,3,12:80.0
2,3,12:80.0
6,3,12:80.0
7,3,12:80.0
-1,-8,13:80.0
0,-8,13:80.0
-2,-7,13:80.0
-1,-7,13:80.0
0,-7,13:80.0
1,-7,13:80.0
-2,-6,13:80.0
-1,-6,13:18.1
0,-6,13:17.12
1,-6,13:80.0
2,-6,13:80.0
3,-6,13:80.0
-2,-5,13:80.0
-1,-5,13:18.1
0,-5,13:18.1
1,-5,13:18.1
2,-5,13:18.1
3,-5,13:80.0
4,-5,13:80.0
5,-5,13:80.0
-2,-4,13:18.1
-1,-4,13:18.1
0,-4,13:18.1
1,-4,13:18.1
2,-4,13:18.1
3,-4,13:18.1
4,-4,13:80.0
5,-4,13:80.0
6,-4,13:80.0
-3,-3,13:18.1
-2,-3,13:18.1
0,-3,13:18.1
1,-3,13:18.1
2,-3,13:17.12
3,-3,13:18.1
4,-3,13:80.0
5,-3,13:80.0
6,-3,13:80.0
-4,-2,13:18.1
-3,-2,13:18.1
-2,-2,13:18.1
1,-2,13:80.0
2,-2,13:80.0
3,-2,13:80.0
4,-2,13:80.0
5,-2,13:80.0
-3,-1,13:18.1
-2,-1,13:18.1
-1,-1,13:18.1
0,-1,13:18.1
2,-1,13:80.0
3,-1,13:80.0
4,-1,13:80.0
5,-1,13:80.0
-1,0,13:18.1
0,0,13:18.1
3,0,13:80.0
4,0,13:80.0
-2,1,13:18.1
-1,1,13:18.1
0,1,13:18.1
1,1,13:18.1
-2,2,13:18.1
-1,2,13:18.1
0,2,13:18.1
1,2,13:18.1
-1,3,13:18.1
0,3,13:18.1
-1,-6,14:80.0
0,-6,14:80.0
-1,-5,14:80.0
0,-5,14:80.0
1,-5,14:80.0
2,-5,14:80.0
-2,-4,14:80.0
-1,-4,14:18.1
0,-4,14:18.1
1,-4,14:80.0
2,-4,14:80.0
3,-4,14:80.0
-3,-3,14:80.0
-2,-3,14:18.1
-1,-3,14:18.1
0,-3,14:18.1
1,-3,14:18.1
2,-3,14:17.12
3,-3,14:80.0
-4,-2,14:80.0
-3,-2,14:80.0
-2,-2,14:18.1
-1,-2,14:17.12
0,-2,14:18.1
1,-2,14:18.1
2,-2,14:18.1
5,-2,14:18.1
6,-2,14:18.1
-3,-1,14:80.0
-2,-1,14:80.0
-1,-1,14:18.1
0,-1,14:18.1
1,-1,14:18.1
2,-1,14:18.1
4,-1,14:18.1
5,-1,14:17.12
6,-1,14:18.1
7,-1,14:18.1
-1,0,14:80.0
0,0,14:18.1
1,0,14:18.1
2,0,14:18.1
3,0,14:18.1
4,0,14:18.1
5,0,14:18.1
6,0,14:18.1
7,0,14:18.1
-2,1,14:80.0
-1,1,14:80.0
0,1,14:17.12
1,1,14:18.1
2,1,14:18.1
3,1,14:18.1
4,1,14:18.1
5,1,14:18.1
6,1,14:18.1
-2,2,14:80.0
-1,2,14:80.0
0,2,14:18.1
1,2,14:18.1
2,2,14:18.1
3,2,14:18.1
4,2,14:18.1
5,2,14:18.1
-1,3,14:80.0
0,3,14:80.0
2,3,14:18.1
3,3,14:18.1
4,3,14:18.1
5,3,14:18.1
4,4,14:18.1
4,-5,15:18.1
5,-5,15:18.1
-1,-4,15:80.0
0,-4,15:80.0
3,-4,15:18.1
4,-4,15:18.1
5,-4,15:18.1
6,-4,15:18.1
-2,-3,15:80.0
-1,-3,15:80.0
0,-3,15:80.0
1,-3,15:80.0
2,-3,15:17.12
3,-3,15:18.1
4,-3,15:18.1
5,-3,15:18.1
6,-3,15:18.1
7,-3,15:18.1
-2,-2,15:80.0
-1,-2,15:80.0
0,-2,15:80.0
1,-2,15:18.1
2,-2,15:18.1
3,-2,15:18.1
4,-2,15:18.1
5,-2,15:18.1
6,-2,15:18.1
-1,-1,15:80.0
0,-1,15:80.0
1,-1,15:18.1
2,-1,15:18.1
3,-1,15:18.1
4,-1,15:18.1
5,-1,15:18.1
6,-1,15:18.1
7,-1,15:18.1
0,0,15:80.0
1,0,15:80.0
2,0,15:18.1
3,0,15:18.1
4,0,15:18.1
5,0,15:18.1
6,0,15:18.1
7,0,15:18.1
0,1,15:80.0
1,1,15:80.0
2,1,15:80.0
3,1,15:18.1
4,1,15:17.12
5,1,15:18.1
6,1,15:18.1
0,2,15:80.0
1,2,15:80.0
2,2,15:80.0
3,2,15:80.0
4,2,15:80.0
5,2,15:80.0
2,3,15:80.0
3,3,15:80.0
4,3,15:80.0
5,3,15:80.0
4,4,15:80.0
2,-7,16:18.1
1,-6,16:18.1
2,-6,16:18.1
3,-6,16:18.1
4,-6,16:18.1
-1,-5,16:18.1
0,-5,16:18.1
1,-5,16:18.1
2,-5,16:18.1
3,-5,16:18.1
4,-5,16:18.1
5,-5,16:80.0
-2,-4,16:18.1
-1,-4,16:18.1
0,-4,16:18.1
1,-4,16:18.1
2,-4,16:18.1
3,-4,16:18.1
4,-4,16:18.1
5,-4,16:18.1
6,-4,16:80.0
-2,-3,16:18.1
-1,-3,16:18.1
0,-3,16:18.1
1,-3,16:18.1
2,-3,16:17.12
3,-3,16:18.1
4,-3,16:17.12
5,-3,16:18.1
6,-3,16:80.0
7,-3,16:80.0
-1,-2,16:18.1
0,-2,16:18.1
1,-2,16:80.0
2,-2,16:18.1
3,-2,16:18.1
4,-2,16:18.1
5,-2,16:18.1
6,-2,16:80.0
1,-1,16:80.0
2,-1,16:80.0
3,-1,16:18.1
4,-1,16:18.1
5,-1,16:18.1
6,-1,16:18.1
7,-1,16:80.0
2,0,16:80.0
3,0,16:80.0
4,0,16:80.0
5,0,16:18.1
6,0,16:80.0
7,0,16:80.0
3,1,16:80.0
4,1,16:80.0
5,1,16:80.0
6,1,16:80.0
2,-7,17:80.0
1,-6,17:80.0
2,-6,17:18.1
3,-6,17:18.1
4,-6,17:80.0
-1,-5,17:18.1
0,-5,17:18.1
1,-5,17:18.1
2,-5,17:18.1
3,-5,17:18.1
4,-5,17:80.0
-2,-4,17:18.1
-1,-4,17:18.1
0,-4,17:17.12
1,-4,17:18.1
2,-4,17:17.12
3,-4,17:18.1
4,-4,17:18.1
5,-4,17:80.0
-2,-3,17:18.1
-1,-3,17:18.1
0,-3,17:18.1
1,-3,17:18.1
2,-3,17:17.12
3,-3,17:18.1
4,-3,17:18.1
5,-3,17:80.0
-2,-2,17:18.1
-1,-2,17:18.1
0,-2,17:18.1
1,-2,17:18.1
2,-2,17:18.1
3,-2,17:18.1
4,-2,17:80.0
5,-2,17:80.0
-2,-1,17:18.1
-1,-1,17:18.1
0,-1,17:18.1
1,-1,17:18.1
3,-1,17:80.0
4,-1,17:80.0
5,-1,17:80.0
6,-1,17:80.0
-1,0,17:18.1
0,0,17:18.1
1,0,17:18.1
5,0,17:80.0
2,-6,18:80.0
3,-6,18:80.0
-1,-5,18:80.0
0,-5,18:80.0
1,-5,18:80.0
2,-5,18:80.0
3,-5,18:80.0
-2,-4,18:80.0
-1,-4,18:80.0
0,-4,18:18.1
1,-4,18:18.1
2,-4,18:80.0
3,-4,18:80.0
4,-4,18:80.0
-2,-3,18:80.0
-1,-3,18:18.1
0,-3,18:18.1
1,-3,18:18.1
2,-3,18:17.12
3,-3,18:80.0
4,-3,18:80.0
-2,-2,18:80.0
-1,-2,18:18.1
0,-2,18:18.1
1,-2,18:18.1
2,-2,18:18.1
3,-2,18:80.0
-2,-1,18:80.0
-1,-1,18:80.0
0,-1,18:18.1
1,-1,18:17.12
2,-1,18:18.1
3,-1,18:18.1
4,-1,18:18.1
5,-1,18:18.1
-1,0,18:80.0
0,0,18:18.1
1,0,18:18.1
2,0,18:18.1
3,0,18:18.1
4,0,18:18.1
0,1,18:18.1
1,1,18:18.1
2,1,18:18.1
3,1,18:18.1
1,2,18:18.1
2,2,18:18.1
0,-4,19:80.0
1,-4,19:80.0
-1,-3,19:80.0
0,-3,19:80.0
1,-3,19:80.0
2,-3,19:17.12
3,-3,19:18.1
4,-3,19:18.1
-1,-2,19:80.0
0,-2,19:80.0
1,-2,19:18.1
2,-2,19:18.1
3,-2,19:18.1
4,-2,19:18.1
5,-2,19:18.1
0,-1,19:80.0
1,-1,19:18.1
2,-1,19:18.1
3,-1,19:18.1
4,-1,19:80.0
5,-1,19:18.1
0,0,19:80.0
1,0,19:80.0
2,0,19:18.1
3,0,19:18.1
4,0,19:80.0
0,1,19:80.0
1,1,19:80.0
2,1,19:80.0
3,1,19:80.0
1,2,19:80.0
2,2,19:80.0
1,-5,20:18.1
2,-5,20:18.1
3,-5,20:18.1
4,-5,20:18.1
0,-4,20:18.1
1,-4,20:18.1
2,-4,20:18.1
3,-4,20:18.1
4,-4,20:18.1
5,-4,20:18.1
0,-3,20:18.1
1,-3,20:18.1
2,-3,20:17.12
3,-3,20:18.1
4,-3,20:17.12
5,-3,20:18.1
0,-2,20:18.1
1,-2,20:18.1
2,-2,20:18.1
3,-2,20:18.1
4,-2,20:18.1
5,-2,20:80.0
1,-1,20:80.0
2,-1,20:18.1
3,-1,20:18.1
4,-1,20:18.1
5,-1,20:80.0
2,0,20:80.0
3,0,20:80.0
1,-5,21:80.0
2,-5,21:80.0
3,-5,21:80.0
4,-5,21:80.0
0,-4,21:18.1
1,-4,21:18.1
2,-4,21:18.1
3,-4,21:80.0
4,-4,21:80.0
5,-4,21:80.0
-1,-3,21:18.1
0,-3,21:18.1
1,-3,21:18.1
2,-3,21:17.12
3,-3,21:18.1
4,-3,21:80.0
5,-3,21:80.0
-1,-2,21:18.1
0,-2,21:18.1
1,-2,21:18.1
2,-2,21:18.1
3,-2,21:18.1
4,-2,21:80.0
0,-1,21:18.1
1,-1,21:18.1
2,-1,21:18.1
3,-1,21:80.0
4,-1,21:80.0
0,-4,22:80.0
1,-4,22:18.1
2,-4,22:18.1
-1,-3,22:80.0
0,-3,22:18.1
1,-3,22:18.1
2,-3,22:17.12
3,-3,22:18.1
-1,-2,22:80.0
0,-2,22:18.1
1,-2,22:18.1
2,-2,22:18.1
3,-2,22:18.1
0,-1,22:18.1
1,-1,22:18.1
2,-1,22:18.1
3,-1,22:18.1
1,0,22:18.1
2,0,22:18.1
1,-4,23:80.0
2,-4,23:80.0
0,-3,23:80.0
1,-3,23:80.0
2,-3,23:18.1
3,-3,23:18.1
0,-2,23:80.0
1,-2,23:18.1
2,-2,23:18.1
3,-2,23:18.1
4,-2,23:18.1
0,-1,23:80.0
1,-1,23:18.1
2,-1,23:18.1
3,-1,23:18.1
1,0,23:80.0
2,0,23:18.1
2,-3,24:80.0
3,-3,24:80.0
1,-2,24:80.0
2,-2,24:18.1
3,-2,24:18.1
4,-2,24:80.0
1,-1,24:80.0
2,-1,24:18.1
3,-1,24:80.0
2,0,24:80.0
2,-2,25:18.1
3,-2,25:80.0
2,-1,25:80.0
2,-2,26:80.0
