[META]
version=2.0
spawnOnBlockType=2
spawnSunlight=True
spawnDarkness=True
spawnWater=False
spawnLava=False
underFill=False
randomRotation=True
dig=True
tree=False
branch=False
needsFoundation=True
rarity=100
collisionPercentage=20
spawnElevationMin=0
spawnElevationMax=200
spawnInBiome=Custom
[DATA]
1,-4,-4:17.12
2,-4,-4:17.12
1,-3,-4:17.12
2,-3,-4:17.12
1,-4,-3:17.12
2,-4,-3:17.12
1,-3,-3:17.12
2,-3,-3:17.12
1,-4,-2:17.12
2,-4,-2:17.12
1,-3,-2:17.12
2,-3,-2:17.12
1,-4,-1:17.12
2,-4,-1:17.12
1,-3,-1:17.12
2,-3,-1:17.12
1,-4,0:17.12
2,-4,0:17.12
1,-3,0:17.12
2,-3,0:17.12
1,-4,1:17.12
2,-4,1:17.12
1,-3,1:17.12
2,-3,1:17.12
1,-4,2:17.12
2,-4,2:17.12
1,-3,2:17.12
2,-3,2:17.12
1,-4,3:17.12
2,-4,3:17.12
1,-3,3:17.12
2,-3,3:17.12
1,-4,4:17.12
2,-4,4:17.12
1,-3,4:17.12
2,-3,4:17.12
1,-4,5:17.12
2,-4,5:17.12
1,-3,5:17.12
2,-3,5:17.12
1,-4,6:17.12
2,-4,6:17.12
1,-3,6:17.12
2,-3,6:17.12
1,-4,7:17.12
2,-4,7:17.12
1,-3,7:17.12
2,-3,7:17.12
1,-4,8:17.12
2,-4,8:17.12
1,-3,8:17.12
2,-3,8:17.12
1,-4,9:17.12
2,-4,9:17.12
1,-3,9:17.12
2,-3,9:17.12
1,-4,10:17.12
2,-4,10:17.12
1,-3,10:17.12
2,-3,10:17.12
-10,1,10:18.1
-9,1,10:18.1
-8,1,10:18.1
-7,1,10:18.1
-11,2,10:18.1
-10,2,10:18.1
-9,2,10:18.1
-8,2,10:18.1
-7,2,10:18.1
-6,2,10:18.1
-11,3,10:18.1
-10,3,10:18.1
-9,3,10:18.1
-8,3,10:17.12
-7,3,10:18.1
-6,3,10:18.1
-10,4,10:18.1
-9,4,10:18.1
-8,4,10:18.1
-7,4,10:18.1
1,-4,11:17.12
2,-4,11:17.12
1,-3,11:17.12
2,-3,11:17.12
-5,-1,11:18.1
-4,-1,11:18.1
-3,-1,11:18.1
-7,0,11:18.1
-6,0,11:18.1
-5,0,11:18.1
-4,0,11:18.1
-3,0,11:18.1
-2,0,11:18.1
-10,1,11:80.0
-9,1,11:80.0
-8,1,11:18.1
-7,1,11:18.1
-6,1,11:18.1
-5,1,11:17.12
-4,1,11:18.1
-3,1,11:18.1
-2,1,11:18.1
-11,2,11:80.0
-10,2,11:80.0
-9,2,11:80.0
-8,2,11:18.1
-7,2,11:18.1
-6,2,11:18.1
-5,2,11:18.1
-4,2,11:18.1
-3,2,11:18.1
-11,3,11:80.0
-10,3,11:80.0
-9,3,11:80.0
-8,3,11:80.0
-7,3,11:18.1
-6,3,11:18.1
-5,3,11:18.1
-4,3,11:18.1
-10,4,11:80.0
-9,4,11:80.0
-8,4,11:80.0
-7,4,11:80.0
0,6,11:18.1
1,6,11:18.1
-1,7,11:18.1
0,7,11:18.1
1,7,11:18.1
2,7,11:18.1
-1,8,11:18.1
0,8,11:18.1
1,8,11:18.1
2,8,11:18.1
-1,9,11:18.1
0,9,11:18.1
1,9,11:18.1
0,10,11:18.1
1,-4,12:17.12
2,-4,12:17.12
-2,-3,12:18.1
-1,-3,12:18.1
1,-3,12:17.12
2,-3,12:17.12
-4,-2,12:18.1
-3,-2,12:18.1
-2,-2,12:18.1
-5,-1,12:18.1
-4,-1,12:18.1
-3,-1,12:18.1
-2,-1,12:17.12
-1,-1,12:18.1
-7,0,12:80.0
-6,0,12:80.0
-5,0,12:18.1
-4,0,12:18.1
-3,0,12:18.1
-2,0,12:18.1
-1,0,12:18.1
-8,1,12:80.0
-7,1,12:80.0
-6,1,12:80.0
-5,1,12:80.0
-4,1,12:18.1
-3,1,12:18.1
-2,1,12:18.1
-8,2,12:80.0
-7,2,12:80.0
-6,2,12:80.0
-5,2,12:80.0
-4,2,12:80.0
-3,2,12:80.0
-7,3,12:80.0
-6,3,12:80.0
-5,3,12:80.0
-4,3,12:80.0
11,3,12:18.1
0,4,12:18.1
1,4,12:18.1
11,4,12:18.1
-1,5,12:18.1
0,5,12:18.1
1,5,12:18.1
2,5,12:18.1
8,5,12:18.1
9,5,12:18.1
10,5,12:17.12
11,5,12:18.1
12,5,12:18.1
-1,6,12:18.1
0,6,12:18.1
1,6,12:18.1
2,6,12:18.1
9,6,12:18.1
10,6,12:18.1
11,6,12:18.1
12,6,12:18.1
-1,7,12:18.1
0,7,12:17.12
1,7,12:18.1
2,7,12:18.1
10,7,12:18.1
11,7,12:18.1
-1,8,12:80.0
0,8,12:18.1
1,8,12:18.1
2,8,12:80.0
-1,9,12:80.0
0,9,12:80.0
1,9,12:80.0
0,10,12:80.0
13,-7,13:18.1
14,-7,13:18.1
11,-6,13:18.1
12,-6,13:18.1
13,-6,13:18.1
14,-6,13:18.1
15,-6,13:18.1
10,-5,13:18.1
11,-5,13:18.1
12,-5,13:18.1
13,-5,13:17.12
14,-5,13:18.1
15,-5,13:18.1
0,-4,13:18.1
1,-4,13:18.1
2,-4,13:18.1
10,-4,13:18.1
11,-4,13:18.1
12,-4,13:18.1
13,-4,13:18.1
14,-4,13:18.1
-2,-3,13:80.0
-1,-3,13:18.1
0,-3,13:18.1
1,-3,13:17.12
2,-3,13:17.12
11,-3,13:18.1
12,-3,13:18.1
13,-3,13:18.1
-4,-2,13:80.0
-3,-2,13:80.0
-2,-2,13:18.1
-1,-2,13:18.1
0,-2,13:18.1
-5,-1,13:80.0
-4,-1,13:80.0
-3,-1,13:80.0
-2,-1,13:18.1
-1,-1,13:18.1
0,-1,13:18.1
5,-1,13:18.1
6,-1,13:18.1
-5,0,13:80.0
-4,0,13:80.0
-3,0,13:80.0
-2,0,13:80.0
-1,0,13:18.1
0,0,13:18.1
1,0,13:18.1
2,0,13:18.1
4,0,13:18.1
5,0,13:18.1
6,0,13:18.1
7,0,13:18.1
8,0,13:18.1
-4,1,13:80.0
-3,1,13:80.0
-2,1,13:80.0
0,1,13:18.1
1,1,13:18.1
2,1,13:18.1
3,1,13:18.1
5,1,13:18.1
6,1,13:18.1
7,1,13:18.1
8,1,13:18.1
9,1,13:18.1
0,2,13:18.1
1,2,13:18.1
2,2,13:18.1
3,2,13:18.1
5,2,13:18.1
6,2,13:18.1
7,2,13:18.1
8,2,13:17.12
9,2,13:18.1
0,3,13:18.1
1,3,13:18.1
2,3,13:17.12
3,3,13:18.1
6,3,13:18.1
7,3,13:18.1
8,3,13:18.1
9,3,13:18.1
10,3,13:18.1
11,3,13:80.0
0,4,13:80.0
1,4,13:18.1
2,4,13:18.1
7,4,13:18.1
8,4,13:18.1
9,4,13:18.1
10,4,13:18.1
11,4,13:80.0
-1,5,13:80.0
0,5,13:80.0
1,5,13:80.0
2,5,13:80.0
8,5,13:18.1
9,5,13:18.1
10,5,13:80.0
11,5,13:80.0
12,5,13:80.0
-1,6,13:80.0
0,6,13:80.0
1,6,13:80.0
2,6,13:80.0
9,6,13:80.0
10,6,13:80.0
11,6,13:80.0
12,6,13:80.0
-1,7,13:80.0
0,7,13:80.0
1,7,13:80.0
2,7,13:80.0
10,7,13:80.0
11,7,13:80.0
0,8,13:80.0
1,8,13:80.0
6,-14,14:18.1
7,-14,14:18.1
5,-13,14:18.1
6,-13,14:18.1
7,-13,14:18.1
8,-13,14:18.1
4,-12,14:18.1
5,-12,14:18.1
6,-12,14:17.12
7,-12,14:18.1
8,-12,14:18.1
4,-11,14:18.1
5,-11,14:18.1
6,-11,14:18.1
7,-11,14:18.1
5,-10,14:18.1
6,-10,14:18.1
13,-7,14:80.0
14,-7,14:80.0
8,-6,14:18.1
9,-6,14:18.1
10,-6,14:18.1
11,-6,14:18.1
12,-6,14:80.0
13,-6,14:80.0
14,-6,14:80.0
15,-6,14:80.0
7,-5,14:18.1
8,-5,14:18.1
9,-5,14:17.12
10,-5,14:18.1
11,-5,14:18.1
12,-5,14:18.1
13,-5,14:80.0
14,-5,14:80.0
15,-5,14:80.0
0,-4,14:80.0
1,-4,14:18.1
2,-4,14:18.1
7,-4,14:18.1
8,-4,14:18.1
9,-4,14:18.1
10,-4,14:18.1
11,-4,14:18.1
12,-4,14:18.1
13,-4,14:80.0
14,-4,14:80.0
-1,-3,14:80.0
0,-3,14:18.1
1,-3,14:17.12
2,-3,14:17.12
3,-3,14:18.1
8,-3,14:18.1
9,-3,14:18.1
10,-3,14:18.1
11,-3,14:18.1
12,-3,14:80.0
13,-3,14:80.0
-2,-2,14:80.0
-1,-2,14:80.0
0,-2,14:18.1
1,-2,14:18.1
2,-2,14:18.1
3,-2,14:18.1
-2,-1,14:80.0
-1,-1,14:80.0
0,-1,14:18.1
1,-1,14:17.12
2,-1,14:18.1
3,-1,14:18.1
4,-1,14:18.1
5,-1,14:18.1
6,-1,14:18.1
-1,0,14:80.0
0,0,14:18.1
1,0,14:18.1
2,0,14:18.1
3,0,14:18.1
4,0,14:18.1
5,0,14:17.12
6,0,14:18.1
7,0,14:18.1
8,0,14:80.0
0,1,14:80.0
1,1,14:18.1
2,1,14:18.1
3,1,14:80.0
4,1,14:18.1
5,1,14:18.1
6,1,14:18.1
7,1,14:18.1
8,1,14:80.0
9,1,14:80.0
0,2,14:80.0
1,2,14:80.0
2,2,14:80.0
3,2,14:80.0
5,2,14:18.1
6,2,14:18.1
7,2,14:80.0
8,2,14:80.0
9,2,14:80.0
0,3,14:80.0
1,3,14:80.0
2,3,14:80.0
3,3,14:80.0
6,3,14:80.0
7,3,14:80.0
8,3,14:80.0
9,3,14:80.0
10,3,14:80.0
1,4,14:80.0
2,4,14:80.0
7,4,14:80.0
8,4,14:80.0
9,4,14:80.0
10,4,14:80.0
8,5,14:80.0
9,5,14:80.0
-3,-14,15:18.1
-2,-14,15:18.1
6,-14,15:80.0
7,-14,15:80.0
-4,-13,15:18.1
-3,-13,15:18.1
-2,-13,15:18.1
-1,-13,15:18.1
5,-13,15:80.0
6,-13,15:80.0
7,-13,15:80.0
8,-13,15:80.0
-4,-12,15:18.1
-3,-12,15:18.1
-2,-12,15:17.12
-1,-12,15:18.1
4,-12,15:80.0
5,-12,15:18.1
6,-12,15:18.1
7,-12,15:80.0
8,-12,15:80.0
-4,-11,15:18.1
-3,-11,15:18.1
-2,-11,15:18.1
-1,-11,15:18.1
4,-11,15:18.1
5,-11,15:18.1
6,-11,15:18.1
7,-11,15:18.1
-3,-10,15:18.1
-2,-10,15:18.1
3,-10,15:18.1
4,-10,15:18.1
5,-10,15:17.12
6,-10,15:18.1
7,-10,15:18.1
3,-9,15:18.1
4,-9,15:18.1
5,-9,15:18.1
6,-9,15:18.1
7,-9,15:18.1
3,-8,15:18.1
4,-8,15:18.1
5,-8,15:18.1
6,-8,15:18.1
4,-7,15:18.1
5,-7,15:18.1
5,-6,15:18.1
6,-6,15:18.1
7,-6,15:18.1
8,-6,15:80.0
9,-6,15:80.0
10,-6,15:80.0
11,-6,15:80.0
6,-5,15:18.1
7,-5,15:18.1
8,-5,15:18.1
9,-5,15:80.0
10,-5,15:80.0
11,-5,15:80.0
12,-5,15:80.0
1,-4,15:17.12
2,-4,15:17.12
6,-4,15:17.12
7,-4,15:18.1
8,-4,15:18.1
9,-4,15:80.0
10,-4,15:80.0
11,-4,15:80.0
12,-4,15:80.0
0,-3,15:18.1
1,-3,15:18.1
2,-3,15:17.12
3,-3,15:18.1
4,-3,15:18.1
5,-3,15:18.1
6,-3,15:18.1
7,-3,15:18.1
8,-3,15:18.1
9,-3,15:80.0
10,-3,15:80.0
11,-3,15:80.0
0,-2,15:18.1
1,-2,15:18.1
2,-2,15:18.1
3,-2,15:18.1
4,-2,15:18.1
5,-2,15:18.1
6,-2,15:18.1
7,-2,15:18.1
0,-1,15:80.0
1,-1,15:80.0
2,-1,15:18.1
3,-1,15:18.1
4,-1,15:18.1
5,-1,15:18.1
6,-1,15:80.0
0,0,15:80.0
1,0,15:80.0
2,0,15:80.0
3,0,15:18.1
4,0,15:18.1
5,0,15:80.0
6,0,15:80.0
7,0,15:80.0
1,1,15:80.0
2,1,15:80.0
4,1,15:80.0
5,1,15:80.0
6,1,15:80.0
7,1,15:80.0
5,2,15:80.0
6,2,15:80.0
-3,-14,16:80.0
-2,-14,16:80.0
-4,-13,16:80.0
-3,-13,16:80.0
-2,-13,16:80.0
-1,-13,16:80.0
-4,-12,16:80.0
-3,-12,16:18.1
-2,-12,16:18.1
-1,-12,16:18.1
5,-12,16:80.0
6,-12,16:80.0
-4,-11,16:18.1
-3,-11,16:18.1
-2,-11,16:18.1
-1,-11,16:18.1
0,-11,16:18.1
4,-11,16:80.0
5,-11,16:80.0
6,-11,16:80.0
7,-11,16:80.0
-4,-10,16:18.1
-3,-10,16:18.1
-2,-10,16:17.12
-1,-10,16:18.1
0,-10,16:18.1
3,-10,16:80.0
4,-10,16:80.0
5,-10,16:80.0
6,-10,16:80.0
7,-10,16:80.0
-3,-9,16:18.1
-2,-9,16:18.1
-1,-9,16:18.1
0,-9,16:18.1
3,-9,16:18.1
4,-9,16:18.1
5,-9,16:80.0
6,-9,16:80.0
7,-9,16:80.0
-3,-8,16:18.1
-2,-8,16:18.1
-1,-8,16:18.1
0,-8,16:18.1
1,-8,16:18.1
2,-8,16:18.1
3,-8,16:18.1
4,-8,16:18.1
5,-8,16:18.1
6,-8,16:80.0
-2,-7,16:18.1
-1,-7,16:18.1
0,-7,16:18.1
1,-7,16:18.1
2,-7,16:18.1
3,-7,16:18.1
4,-7,16:17.12
5,-7,16:18.1
6,-7,16:18.1
-8,-6,16:18.1
-7,-6,16:18.1
1,-6,16:18.1
2,-6,16:18.1
3,-6,16:18.1
4,-6,16:18.1
5,-6,16:18.1
6,-6,16:18.1
7,-6,16:80.0
-9,-5,16:18.1
-8,-5,16:18.1
-7,-5,16:17.12
-6,-5,16:18.1
1,-5,16:18.1
2,-5,16:18.1
3,-5,16:18.1
4,-5,16:18.1
5,-5,16:18.1
6,-5,16:80.0
7,-5,16:80.0
8,-5,16:80.0
-9,-4,16:18.1
-8,-4,16:18.1
-7,-4,16:18.1
-6,-4,16:18.1
0,-4,16:18.1
1,-4,16:17.12
2,-4,16:17.12
3,-4,16:18.1
4,-4,16:18.1
5,-4,16:18.1
6,-4,16:18.1
7,-4,16:80.0
8,-4,16:80.0
-8,-3,16:18.1
-7,-3,16:18.1
0,-3,16:18.1
1,-3,16:17.12
2,-3,16:17.12
3,-3,16:18.1
4,-3,16:18.1
5,-3,16:18.1
6,-3,16:18.1
7,-3,16:80.0
8,-3,16:80.0
0,-2,16:80.0
1,-2,16:18.1
2,-2,16:18.1
3,-2,16:18.1
4,-2,16:18.1
5,-2,16:18.1
6,-2,16:80.0
7,-2,16:80.0
2,-1,16:80.0
3,-1,16:18.1
4,-1,16:18.1
5,-1,16:80.0
3,0,16:80.0
4,0,16:80.0
-3,-12,17:80.0
-2,-12,17:80.0
-1,-12,17:80.0
-4,-11,17:80.0
-3,-11,17:80.0
-2,-11,17:80.0
-1,-11,17:80.0
0,-11,17:80.0
-4,-10,17:80.0
-3,-10,17:80.0
-2,-10,17:80.0
-1,-10,17:80.0
0,-10,17:80.0
-3,-9,17:80.0
-2,-9,17:80.0
-1,-9,17:18.1
0,-9,17:18.1
3,-9,17:80.0
4,-9,17:80.0
-3,-8,17:80.0
-2,-8,17:18.1
-1,-8,17:18.1
0,-8,17:18.1
1,-8,17:18.1
2,-8,17:80.0
3,-8,17:80.0
4,-8,17:80.0
5,-8,17:80.0
-2,-7,17:18.1
-1,-7,17:18.1
0,-7,17:17.12
1,-7,17:18.1
2,-7,17:18.1
3,-7,17:80.0
4,-7,17:80.0
5,-7,17:80.0
6,-7,17:80.0
-8,-6,17:80.0
-7,-6,17:18.1
-6,-6,17:18.1
-5,-6,17:18.1
-1,-6,17:18.1
0,-6,17:18.1
1,-6,17:18.1
2,-6,17:18.1
3,-6,17:18.1
4,-6,17:80.0
5,-6,17:80.0
6,-6,17:80.0
-9,-5,17:80.0
-8,-5,17:18.1
-7,-5,17:18.1
-6,-5,17:18.1
-5,-5,17:18.1
-4,-5,17:18.1
-3,-5,17:18.1
0,-5,17:18.1
1,-5,17:18.1
2,-5,17:18.1
3,-5,17:18.1
4,-5,17:18.1
5,-5,17:80.0
-9,-4,17:80.0
-8,-4,17:18.1
-7,-4,17:18.1
-6,-4,17:18.1
-5,-4,17:17.12
-4,-4,17:18.1
-3,-4,17:18.1
-2,-4,17:18.1
0,-4,17:18.1
1,-4,17:17.12
2,-4,17:17.12
3,-4,17:18.1
4,-4,17:18.1
5,-4,17:80.0
6,-4,17:80.0
-8,-3,17:80.0
-7,-3,17:18.1
-6,-3,17:18.1
-5,-3,17:18.1
-4,-3,17:18.1
-3,-3,17:18.1
-2,-3,17:18.1
0,-3,17:18.1
1,-3,17:17.12
2,-3,17:17.12
3,-3,17:18.1
4,-3,17:18.1
5,-3,17:80.0
6,-3,17:80.0
-5,-2,17:18.1
-4,-2,17:18.1
-3,-2,17:18.1
-1,-2,17:18.1
0,-2,17:18.1
1,-2,17:18.1
2,-2,17:18.1
3,-2,17:18.1
4,-2,17:80.0
5,-2,17:80.0
0,-1,17:18.1
3,-1,17:80.0
4,-1,17:80.0
-5,2,17:18.1
-4,2,17:18.1
-6,3,17:18.1
-5,3,17:18.1
-4,3,17:18.1
-3,3,17:18.1
-6,4,17:18.1
-5,4,17:18.1
-4,4,17:18.1
-3,4,17:18.1
-5,5,17:18.1
-4,5,17:18.1
-1,-9,18:80.0
0,-9,18:80.0
-2,-8,18:80.0
-1,-8,18:80.0
0,-8,18:80.0
1,-8,18:80.0
-2,-7,18:80.0
-1,-7,18:80.0
0,-7,18:80.0
1,-7,18:80.0
2,-7,18:80.0
-7,-6,18:80.0
-6,-6,18:80.0
-5,-6,18:80.0
-1,-6,18:80.0
0,-6,18:80.0
1,-6,18:18.1
2,-6,18:18.1
3,-6,18:80.0
-8,-5,18:80.0
-7,-5,18:80.0
-6,-5,18:80.0
-5,-5,18:80.0
-4,-5,18:80.0
-3,-5,18:18.1
-2,-5,18:18.1
-1,-5,18:18.1
0,-5,18:18.1
1,-5,18:18.1
2,-5,18:18.1
3,-5,18:18.1
4,-5,18:80.0
-8,-4,18:80.0
-7,-4,18:80.0
-6,-4,18:80.0
-5,-4,18:80.0
-4,-4,18:18.1
-3,-4,18:18.1
-2,-4,18:18.1
-1,-4,18:18.1
0,-4,18:18.1
1,-4,18:17.12
2,-4,18:17.12
3,-4,18:18.1
4,-4,18:80.0
-7,-3,18:80.0
-6,-3,18:80.0
-5,-3,18:80.0
-4,-3,18:18.1
-3,-3,18:18.1
-2,-3,18:17.12
-1,-3,18:18.1
0,-3,18:18.1
1,-3,18:17.12
2,-3,18:17.12
3,-3,18:18.1
4,-3,18:80.0
-5,-2,18:80.0
-4,-2,18:80.0
-3,-2,18:18.1
-2,-2,18:18.1
-1,-2,18:18.1
0,-2,18:18.1
1,-2,18:18.1
2,-2,18:18.1
3,-2,18:18.1
-2,-1,18:18.1
-1,-1,18:18.1
0,-1,18:18.1
1,-1,18:18.1
-3,0,18:18.1
-2,0,18:18.1
-1,0,18:18.1
0,0,18:18.1
1,0,18:18.1
-4,1,18:18.1
-3,1,18:18.1
-2,1,18:18.1
-1,1,18:18.1
0,1,18:18.1
-5,2,18:18.1
-4,2,18:18.1
-3,2,18:18.1
-2,2,18:18.1
-1,2,18:18.1
-6,3,18:80.0
-5,3,18:18.1
-4,3,18:17.12
-3,3,18:18.1
-2,3,18:18.1
-6,4,18:80.0
-5,4,18:80.0
-4,4,18:18.1
-3,4,18:18.1
3,4,18:18.1
4,4,18:18.1
-5,5,18:80.0
-4,5,18:80.0
2,5,18:18.1
3,5,18:18.1
4,5,18:18.1
5,5,18:18.1
2,6,18:18.1
3,6,18:18.1
4,6,18:18.1
5,6,18:18.1
2,7,18:18.1
3,7,18:18.1
4,7,18:18.1
5,7,18:18.1
3,8,18:18.1
4,8,18:18.1
1,-6,19:80.0
2,-6,19:80.0
-3,-5,19:80.0
-2,-5,19:80.0
-1,-5,19:80.0
0,-5,19:18.1
1,-5,19:18.1
2,-5,19:18.1
3,-5,19:80.0
-4,-4,19:80.0
-3,-4,19:80.0
-2,-4,19:80.0
-1,-4,19:18.1
0,-4,19:18.1
1,-4,19:17.12
2,-4,19:17.12
3,-4,19:18.1
-4,-3,19:80.0
-3,-3,19:80.0
-2,-3,19:80.0
-1,-3,19:18.1
0,-3,19:18.1
1,-3,19:17.12
2,-3,19:17.12
3,-3,19:18.1
-3,-2,19:80.0
-2,-2,19:18.1
-1,-2,19:18.1
0,-2,19:18.1
1,-2,19:18.1
2,-2,19:18.1
3,-2,19:18.1
-3,-1,19:18.1
-2,-1,19:18.1
-1,-1,19:18.1
0,-1,19:18.1
1,-1,19:18.1
2,-1,19:18.1
9,-1,19:18.1
10,-1,19:18.1
-3,0,19:18.1
-2,0,19:18.1
-1,0,19:17.12
0,0,19:18.1
1,0,19:18.1
2,0,19:18.1
8,0,19:18.1
9,0,19:18.1
10,0,19:18.1
11,0,19:18.1
-4,1,19:80.0
-3,1,19:80.0
-2,1,19:18.1
-1,1,19:18.1
0,1,19:18.1
8,1,19:18.1
9,1,19:18.1
10,1,19:18.1
11,1,19:18.1
-5,2,19:80.0
-4,2,19:80.0
-3,2,19:80.0
-2,2,19:80.0
-1,2,19:80.0
3,2,19:18.1
4,2,19:18.1
5,2,19:18.1
9,2,19:18.1
10,2,19:18.1
-5,3,19:80.0
-4,3,19:80.0
-3,3,19:80.0
-2,3,19:80.0
2,3,19:18.1
3,3,19:18.1
4,3,19:17.12
5,3,19:18.1
-4,4,19:80.0
-3,4,19:80.0
2,4,19:18.1
3,4,19:18.1
4,4,19:18.1
5,4,19:18.1
2,5,19:18.1
3,5,19:18.1
4,5,19:18.1
5,5,19:18.1
2,6,19:80.0
3,6,19:17.12
4,6,19:18.1
5,6,19:80.0
2,7,19:80.0
3,7,19:80.0
4,7,19:80.0
5,7,19:80.0
3,8,19:80.0
4,8,19:80.0
9,-8,20:18.1
10,-8,20:18.1
8,-7,20:18.1
9,-7,20:18.1
10,-7,20:18.1
11,-7,20:18.1
8,-6,20:18.1
9,-6,20:18.1
10,-6,20:18.1
11,-6,20:18.1
0,-5,20:80.0
1,-5,20:80.0
2,-5,20:80.0
9,-5,20:18.1
10,-5,20:18.1
-1,-4,20:80.0
0,-4,20:18.1
1,-4,20:18.1
2,-4,20:18.1
3,-4,20:80.0
-1,-3,20:18.1
0,-3,20:18.1
1,-3,20:17.12
2,-3,20:17.12
3,-3,20:18.1
4,-3,20:18.1
5,-3,20:18.1
6,-3,20:18.1
-2,-2,20:80.0
-1,-2,20:18.1
0,-2,20:18.1
1,-2,20:18.1
2,-2,20:18.1
3,-2,20:18.1
4,-2,20:18.1
5,-2,20:18.1
6,-2,20:18.1
7,-2,20:18.1
8,-2,20:18.1
9,-2,20:18.1
-3,-1,20:80.0
-2,-1,20:80.0
-1,-1,20:80.0
0,-1,20:18.1
1,-1,20:18.1
2,-1,20:18.1
3,-1,20:18.1
4,-1,20:18.1
5,-1,20:18.1
6,-1,20:18.1
7,-1,20:18.1
8,-1,20:18.1
9,-1,20:18.1
10,-1,20:18.1
-3,0,20:80.0
-2,0,20:80.0
-1,0,20:80.0
0,0,20:80.0
1,0,20:18.1
2,0,20:18.1
3,0,20:18.1
4,0,20:18.1
5,0,20:18.1
6,0,20:18.1
7,0,20:18.1
8,0,20:18.1
9,0,20:17.12
10,0,20:18.1
11,0,20:80.0
-2,1,20:80.0
-1,1,20:80.0
0,1,20:80.0
1,1,20:18.1
2,1,20:18.1
3,1,20:18.1
4,1,20:18.1
6,1,20:18.1
7,1,20:18.1
8,1,20:18.1
9,1,20:18.1
10,1,20:18.1
11,1,20:80.0
2,2,20:18.1
3,2,20:18.1
4,2,20:80.0
5,2,20:80.0
8,2,20:18.1
9,2,20:18.1
10,2,20:80.0
2,3,20:80.0
3,3,20:80.0
4,3,20:80.0
5,3,20:80.0
2,4,20:80.0
3,4,20:80.0
4,4,20:80.0
5,4,20:80.0
2,5,20:80.0
3,5,20:80.0
4,5,20:80.0
5,5,20:80.0
3,6,20:80.0
4,6,20:80.0
3,-12,21:18.1
4,-12,21:18.1
2,-11,21:18.1
3,-11,21:18.1
4,-11,21:18.1
5,-11,21:18.1
2,-10,21:18.1
3,-10,21:18.1
4,-10,21:18.1
5,-10,21:18.1
3,-9,21:18.1
4,-9,21:18.1
7,-8,21:18.1
8,-8,21:18.1
9,-8,21:18.1
10,-8,21:80.0
5,-7,21:18.1
6,-7,21:18.1
7,-7,21:18.1
8,-7,21:18.1
9,-7,21:18.1
10,-7,21:18.1
11,-7,21:80.0
5,-6,21:18.1
6,-6,21:18.1
7,-6,21:18.1
8,-6,21:18.1
9,-6,21:17.12
10,-6,21:18.1
11,-6,21:80.0
5,-5,21:18.1
6,-5,21:18.1
7,-5,21:18.1
8,-5,21:18.1
9,-5,21:18.1
10,-5,21:80.0
0,-4,21:80.0
1,-4,21:18.1
2,-4,21:18.1
3,-4,21:18.1
5,-4,21:18.1
7,-4,21:18.1
8,-4,21:18.1
-1,-3,21:80.0
0,-3,21:80.0
1,-3,21:18.1
2,-3,21:17.12
3,-3,21:18.1
4,-3,21:18.1
5,-3,21:18.1
6,-3,21:18.1
-1,-2,21:80.0
0,-2,21:80.0
1,-2,21:18.1
2,-2,21:18.1
3,-2,21:18.1
4,-2,21:80.0
5,-2,21:17.12
6,-2,21:18.1
7,-2,21:18.1
8,-2,21:80.0
9,-2,21:80.0
0,-1,21:80.0
1,-1,21:18.1
2,-1,21:18.1
3,-1,21:17.12
4,-1,21:18.1
5,-1,21:18.1
6,-1,21:18.1
7,-1,21:18.1
8,-1,21:80.0
9,-1,21:80.0
10,-1,21:80.0
1,0,21:80.0
2,0,21:18.1
3,0,21:18.1
4,0,21:80.0
5,0,21:18.1
6,0,21:18.1
7,0,21:80.0
8,0,21:80.0
9,0,21:80.0
10,0,21:80.0
1,1,21:80.0
2,1,21:80.0
3,1,21:80.0
4,1,21:80.0
6,1,21:80.0
7,1,21:80.0
8,1,21:80.0
9,1,21:80.0
10,1,21:80.0
2,2,21:80.0
3,2,21:80.0
8,2,21:80.0
9,2,21:80.0
2,-12,22:18.1
3,-12,22:18.1
4,-12,22:80.0
1,-11,22:18.1
2,-11,22:18.1
3,-11,22:17.12
4,-11,22:18.1
5,-11,22:80.0
-4,-10,22:18.1
-3,-10,22:18.1
1,-10,22:18.1
2,-10,22:18.1
3,-10,22:18.1
4,-10,22:18.1
5,-10,22:80.0
-5,-9,22:18.1
-4,-9,22:18.1
-3,-9,22:18.1
-2,-9,22:18.1
1,-9,22:18.1
2,-9,22:18.1
3,-9,22:18.1
4,-9,22:18.1
-5,-8,22:18.1
-4,-8,22:18.1
-3,-8,22:18.1
-2,-8,22:18.1
4,-8,22:18.1
7,-8,22:80.0
8,-8,22:80.0
9,-8,22:80.0
-4,-7,22:18.1
-3,-7,22:18.1
5,-7,22:18.1
6,-7,22:80.0
7,-7,22:80.0
8,-7,22:80.0
9,-7,22:80.0
10,-7,22:80.0
5,-6,22:18.1
6,-6,22:18.1
7,-6,22:18.1
8,-6,22:80.0
9,-6,22:80.0
10,-6,22:80.0
5,-5,22:17.12
6,-5,22:18.1
7,-5,22:18.1
8,-5,22:80.0
9,-5,22:80.0
1,-4,22:18.1
2,-4,22:18.1
3,-4,22:18.1
5,-4,22:18.1
6,-4,22:18.1
7,-4,22:18.1
8,-4,22:80.0
1,-3,22:18.1
2,-3,22:17.12
3,-3,22:18.1
4,-3,22:18.1
5,-3,22:18.1
6,-3,22:18.1
1,-2,22:18.1
2,-2,22:18.1
3,-2,22:18.1
4,-2,22:18.1
5,-2,22:80.0
6,-2,22:80.0
7,-2,22:80.0
1,-1,22:80.0
2,-1,22:18.1
3,-1,22:18.1
4,-1,22:80.0
5,-1,22:80.0
6,-1,22:80.0
7,-1,22:80.0
2,0,22:80.0
3,0,22:80.0
5,0,22:80.0
6,0,22:80.0
2,-12,23:80.0
3,-12,23:80.0
1,-11,23:80.0
2,-11,23:80.0
3,-11,23:80.0
4,-11,23:80.0
-4,-10,23:80.0
-3,-10,23:80.0
1,-10,23:80.0
2,-10,23:80.0
3,-10,23:80.0
4,-10,23:80.0
-5,-9,23:80.0
-4,-9,23:18.1
-3,-9,23:18.1
-2,-9,23:18.1
1,-9,23:80.0
2,-9,23:80.0
3,-9,23:80.0
4,-9,23:80.0
-5,-8,23:18.1
-4,-8,23:17.12
-3,-8,23:18.1
-2,-8,23:18.1
-1,-8,23:18.1
2,-8,23:18.1
3,-8,23:18.1
4,-8,23:80.0
-5,-7,23:18.1
-4,-7,23:18.1
-3,-7,23:18.1
-2,-7,23:18.1
-1,-7,23:18.1
0,-7,23:18.1
1,-7,23:18.1
2,-7,23:17.12
3,-7,23:18.1
4,-7,23:18.1
5,-7,23:80.0
-4,-6,23:18.1
-3,-6,23:18.1
-2,-6,23:18.1
1,-6,23:18.1
2,-6,23:18.1
3,-6,23:18.1
4,-6,23:18.1
5,-6,23:80.0
6,-6,23:80.0
7,-6,23:80.0
-2,-5,23:18.1
1,-5,23:18.1
2,-5,23:18.1
3,-5,23:18.1
4,-5,23:18.1
5,-5,23:80.0
6,-5,23:80.0
7,-5,23:80.0
1,-4,23:18.1
2,-4,23:17.12
3,-4,23:18.1
4,-4,23:18.1
5,-4,23:80.0
6,-4,23:80.0
7,-4,23:80.0
-6,-3,23:18.1
-5,-3,23:18.1
1,-3,23:18.1
2,-3,23:17.12
3,-3,23:18.1
4,-3,23:18.1
5,-3,23:80.0
6,-3,23:80.0
-7,-2,23:18.1
-6,-2,23:18.1
-5,-2,23:18.1
-4,-2,23:18.1
1,-2,23:80.0
2,-2,23:18.1
3,-2,23:18.1
4,-2,23:80.0
-7,-1,23:18.1
-6,-1,23:18.1
-5,-1,23:18.1
-4,-1,23:18.1
2,-1,23:80.0
3,-1,23:80.0
-6,0,23:18.1
-5,0,23:18.1
-4,-9,24:80.0
-3,-9,24:80.0
-2,-9,24:80.0
-5,-8,24:80.0
-4,-8,24:80.0
-3,-8,24:80.0
-2,-8,24:80.0
-1,-8,24:80.0
2,-8,24:80.0
3,-8,24:80.0
-5,-7,24:80.0
-4,-7,24:80.0
-3,-7,24:80.0
-2,-7,24:80.0
-1,-7,24:18.1
0,-7,24:18.1
1,-7,24:80.0
2,-7,24:80.0
3,-7,24:80.0
4,-7,24:80.0
-4,-6,24:80.0
-3,-6,24:80.0
-2,-6,24:18.1
-1,-6,24:17.12
0,-6,24:18.1
1,-6,24:18.1
2,-6,24:80.0
3,-6,24:80.0
4,-6,24:80.0
-2,-5,24:18.1
-1,-5,24:18.1
0,-5,24:18.1
1,-5,24:18.1
2,-5,24:18.1
3,-5,24:18.1
4,-5,24:80.0
-4,-4,24:18.1
-3,-4,24:18.1
-2,-4,24:18.1
-1,-4,24:18.1
0,-4,24:18.1
1,-4,24:17.12
2,-4,24:17.12
3,-4,24:80.0
4,-4,24:18.1
-6,-3,24:80.0
-5,-3,24:18.1
-4,-3,24:18.1
-3,-3,24:18.1
-2,-3,24:18.1
1,-3,24:18.1
2,-3,24:17.12
3,-3,24:18.1
4,-3,24:18.1
-7,-2,24:80.0
-6,-2,24:18.1
-5,-2,24:17.12
-4,-2,24:18.1
-3,-2,24:18.1
-2,-2,24:18.1
2,-2,24:18.1
3,-2,24:80.0
-7,-1,24:80.0
-6,-1,24:18.1
-5,-1,24:18.1
-4,-1,24:18.1
-3,-1,24:18.1
-2,-1,24:18.1
-6,0,24:80.0
-5,0,24:18.1
-4,0,24:18.1
-3,0,24:18.1
-1,-7,25:80.0
0,-7,25:80.0
-2,-6,25:80.0
-1,-6,25:80.0
0,-6,25:80.0
1,-6,25:80.0
-2,-5,25:80.0
-1,-5,25:80.0
0,-5,25:80.0
1,-5,25:18.1
2,-5,25:18.1
3,-5,25:80.0
-4,-4,25:80.0
-3,-4,25:80.0
-2,-4,25:18.1
-1,-4,25:18.1
0,-4,25:18.1
1,-4,25:17.12
2,-4,25:17.12
3,-4,25:18.1
4,-4,25:80.0
-5,-3,25:80.0
-4,-3,25:80.0
-3,-3,25:18.1
-2,-3,25:18.1
-1,-3,25:17.12
0,-3,25:18.1
1,-3,25:17.12
2,-3,25:17.12
3,-3,25:18.1
4,-3,25:80.0
-6,-2,25:80.0
-5,-2,25:80.0
-4,-2,25:80.0
-3,-2,25:18.1
-2,-2,25:18.1
-1,-2,25:18.1
0,-2,25:18.1
1,-2,25:18.1
2,-2,25:18.1
-6,-1,25:80.0
-5,-1,25:80.0
-4,-1,25:80.0
-3,-1,25:80.0
-2,-1,25:18.1
-1,-1,25:18.1
0,-1,25:18.1
-5,0,25:80.0
-4,0,25:80.0
-3,0,25:80.0
-1,0,25:18.1
0,0,25:18.1
-2,1,25:18.1
-1,1,25:18.1
0,1,25:18.1
1,1,25:18.1
-2,2,25:18.1
-1,2,25:18.1
0,2,25:18.1
1,2,25:18.1
-2,3,25:18.1
-1,3,25:18.1
0,3,25:17.12
1,3,25:18.1
-2,4,25:18.1
-1,4,25:18.1
0,4,25:18.1
1,4,25:18.1
-1,5,25:18.1
0,5,25:18.1
1,-5,26:80.0
2,-5,26:80.0
-2,-4,26:80.0
-1,-4,26:80.0
0,-4,26:80.0
1,-4,26:18.1
2,-4,26:18.1
3,-4,26:80.0
-3,-3,26:80.0
-2,-3,26:80.0
-1,-3,26:80.0
0,-3,26:18.1
1,-3,26:17.12
2,-3,26:17.12
3,-3,26:80.0
-3,-2,26:80.0
-2,-2,26:80.0
-1,-2,26:18.1
0,-2,26:18.1
1,-2,26:18.1
2,-2,26:18.1
3,-2,26:18.1
-2,-1,26:80.0
-1,-1,26:18.1
0,-1,26:18.1
1,-1,26:18.1
2,-1,26:18.1
3,-1,26:18.1
4,-1,26:18.1
5,-1,26:18.1
-1,0,26:18.1
0,0,26:18.1
1,0,26:17.12
2,0,26:18.1
3,0,26:18.1
4,0,26:18.1
5,0,26:18.1
6,0,26:18.1
-2,1,26:80.0
-1,1,26:80.0
0,1,26:18.1
1,1,26:18.1
2,1,26:18.1
3,1,26:18.1
4,1,26:18.1
5,1,26:18.1
6,1,26:18.1
-2,2,26:80.0
-1,2,26:80.0
0,2,26:80.0
1,2,26:80.0
3,2,26:18.1
4,2,26:17.12
5,2,26:18.1
6,2,26:18.1
-2,3,26:80.0
-1,3,26:80.0
0,3,26:80.0
1,3,26:80.0
3,3,26:18.1
4,3,26:18.1
5,3,26:18.1
6,3,26:18.1
-2,4,26:80.0
-1,4,26:80.0
0,4,26:80.0
1,4,26:80.0
4,4,26:18.1
5,4,26:18.1
-1,5,26:80.0
0,5,26:80.0
0,-4,27:18.1
1,-4,27:17.12
2,-4,27:17.12
6,-4,27:18.1
7,-4,27:18.1
8,-4,27:18.1
0,-3,27:18.1
1,-3,27:18.1
2,-3,27:17.12
5,-3,27:18.1
6,-3,27:18.1
7,-3,27:17.12
8,-3,27:18.1
9,-3,27:18.1
-1,-2,27:80.0
0,-2,27:18.1
1,-2,27:18.1
2,-2,27:18.1
3,-2,27:18.1
4,-2,27:18.1
5,-2,27:18.1
6,-2,27:18.1
7,-2,27:18.1
8,-2,27:18.1
9,-2,27:18.1
-1,-1,27:80.0
0,-1,27:80.0
1,-1,27:18.1
2,-1,27:18.1
3,-1,27:18.1
4,-1,27:18.1
5,-1,27:18.1
6,-1,27:18.1
7,-1,27:18.1
8,-1,27:18.1
-1,0,27:80.0
0,0,27:80.0
1,0,27:80.0
2,0,27:18.1
3,0,27:18.1
4,0,27:18.1
5,0,27:18.1
6,0,27:80.0
0,1,27:80.0
1,1,27:80.0
2,1,27:80.0
3,1,27:18.1
4,1,27:18.1
5,1,27:80.0
6,1,27:80.0
3,2,27:80.0
4,2,27:80.0
5,2,27:80.0
6,2,27:80.0
3,3,27:80.0
4,3,27:80.0
5,3,27:80.0
6,3,27:80.0
4,4,27:80.0
5,4,27:80.0
4,-8,28:18.1
5,-8,28:18.1
6,-8,28:18.1
3,-7,28:18.1
4,-7,28:18.1
5,-7,28:18.1
6,-7,28:18.1
7,-7,28:18.1
3,-6,28:18.1
4,-6,28:18.1
5,-6,28:18.1
6,-6,28:18.1
7,-6,28:18.1
3,-5,28:18.1
4,-5,28:18.1
5,-5,28:18.1
6,-5,28:18.1
0,-4,28:80.0
1,-4,28:17.12
2,-4,28:17.12
3,-4,28:18.1
4,-4,28:18.1
5,-4,28:18.1
6,-4,28:80.0
7,-4,28:80.0
8,-4,28:80.0
0,-3,28:18.1
1,-3,28:17.12
2,-3,28:17.12
3,-3,28:18.1
4,-3,28:18.1
5,-3,28:18.1
6,-3,28:18.1
7,-3,28:80.0
8,-3,28:80.0
9,-3,28:80.0
0,-2,28:80.0
1,-2,28:18.1
2,-2,28:18.1
3,-2,28:18.1
4,-2,28:17.12
5,-2,28:18.1
6,-2,28:18.1
7,-2,28:80.0
8,-2,28:80.0
9,-2,28:80.0
1,-1,28:80.0
2,-1,28:80.0
3,-1,28:18.1
4,-1,28:18.1
5,-1,28:18.1
6,-1,28:80.0
7,-1,28:80.0
8,-1,28:80.0
2,0,28:80.0
3,0,28:80.0
4,0,28:80.0
5,0,28:80.0
3,1,28:80.0
4,1,28:80.0
1,-9,29:18.1
2,-9,29:18.1
0,-8,29:18.1
1,-8,29:18.1
2,-8,29:18.1
3,-8,29:18.1
4,-8,29:80.0
5,-8,29:80.0
6,-8,29:80.0
0,-7,29:18.1
1,-7,29:17.12
2,-7,29:18.1
3,-7,29:18.1
4,-7,29:18.1
5,-7,29:80.0
6,-7,29:80.0
7,-7,29:80.0
0,-6,29:18.1
1,-6,29:18.1
2,-6,29:18.1
3,-6,29:18.1
4,-6,29:18.1
5,-6,29:17.12
6,-6,29:80.0
7,-6,29:80.0
0,-5,29:18.1
1,-5,29:18.1
2,-5,29:18.1
3,-5,29:18.1
4,-5,29:18.1
5,-5,29:18.1
6,-5,29:80.0
1,-4,29:17.12
2,-4,29:17.12
3,-4,29:18.1
4,-4,29:18.1
5,-4,29:18.1
0,-3,29:80.0
1,-3,29:17.12
2,-3,29:17.12
3,-3,29:18.1
4,-3,29:18.1
5,-3,29:80.0
6,-3,29:80.0
1,-2,29:80.0
2,-2,29:18.1
3,-2,29:18.1
4,-2,29:80.0
5,-2,29:80.0
6,-2,29:80.0
3,-1,29:80.0
4,-1,29:80.0
5,-1,29:80.0
1,-9,30:80.0
2,-9,30:80.0
0,-8,30:80.0
1,-8,30:80.0
2,-8,30:80.0
3,-8,30:80.0
0,-7,30:80.0
1,-7,30:18.1
2,-7,30:18.1
3,-7,30:80.0
4,-7,30:80.0
-3,-6,30:18.1
-2,-6,30:18.1
-1,-6,30:18.1
0,-6,30:18.1
1,-6,30:18.1
2,-6,30:18.1
3,-6,30:18.1
4,-6,30:80.0
5,-6,30:80.0
-4,-5,30:18.1
-3,-5,30:18.1
-2,-5,30:17.12
-1,-5,30:18.1
0,-5,30:18.1
1,-5,30:18.1
2,-5,30:18.1
3,-5,30:18.1
4,-5,30:80.0
5,-5,30:80.0
-4,-4,30:18.1
-3,-4,30:18.1
-2,-4,30:18.1
-1,-4,30:18.1
0,-4,30:18.1
1,-4,30:17.12
2,-4,30:17.12
3,-4,30:18.1
4,-4,30:80.0
5,-4,30:80.0
-3,-3,30:18.1
-2,-3,30:18.1
-1,-3,30:18.1
0,-3,30:18.1
1,-3,30:17.12
2,-3,30:17.12
3,-3,30:18.1
4,-3,30:80.0
2,-2,30:18.1
3,-2,30:18.1
1,-7,31:80.0
2,-7,31:80.0
-3,-6,31:80.0
-2,-6,31:80.0
-1,-6,31:18.1
0,-6,31:18.1
1,-6,31:80.0
2,-6,31:80.0
3,-6,31:80.0
-4,-5,31:80.0
-3,-5,31:80.0
-2,-5,31:18.1
-1,-5,31:18.1
0,-5,31:18.1
1,-5,31:18.1
2,-5,31:18.1
3,-5,31:80.0
-4,-4,31:80.0
-3,-4,31:80.0
-2,-4,31:18.1
-1,-4,31:18.1
0,-4,31:18.1
1,-4,31:17.12
2,-4,31:17.12
3,-4,31:18.1
-3,-3,31:80.0
-2,-3,31:18.1
-1,-3,31:18.1
0,-3,31:18.1
1,-3,31:17.12
2,-3,31:17.12
3,-3,31:18.1
-3,-2,31:18.1
-2,-2,31:18.1
-1,-2,31:17.12
0,-2,31:18.1
1,-2,31:18.1
2,-2,31:18.1
3,-2,31:80.0
-3,-1,31:18.1
-2,-1,31:18.1
-1,-1,31:18.1
0,-1,31:18.1
1,-1,31:18.1
2,-1,31:18.1
-2,0,31:18.1
-1,0,31:18.1
0,0,31:18.1
1,0,31:18.1
-1,-6,32:80.0
0,-6,32:80.0
-2,-5,32:80.0
-1,-5,32:80.0
0,-5,32:80.0
1,-5,32:80.0
2,-5,32:80.0
-2,-4,32:80.0
-1,-4,32:80.0
0,-4,32:18.1
1,-4,32:18.1
2,-4,32:18.1
3,-4,32:80.0
-2,-3,32:80.0
-1,-3,32:18.1
0,-3,32:18.1
1,-3,32:17.12
2,-3,32:17.12
3,-3,32:80.0
-3,-2,32:80.0
-2,-2,32:80.0
-1,-2,32:18.1
0,-2,32:18.1
1,-2,32:18.1
2,-2,32:18.1
3,-2,32:18.1
-3,-1,32:80.0
-2,-1,32:80.0
-1,-1,32:18.1
0,-1,32:18.1
1,-1,32:18.1
2,-1,32:18.1
3,-1,32:18.1
-2,0,32:80.0
-1,0,32:80.0
0,0,32:18.1
1,0,32:18.1
2,0,32:17.12
3,0,32:18.1
0,1,32:18.1
1,1,32:18.1
2,1,32:18.1
3,1,32:18.1
1,2,32:18.1
2,2,32:18.1
0,-4,33:80.0
1,-4,33:18.1
2,-4,33:18.1
-1,-3,33:80.0
0,-3,33:18.1
1,-3,33:17.12
2,-3,33:17.12
-1,-2,33:80.0
0,-2,33:18.1
1,-2,33:18.1
2,-2,33:18.1
3,-2,33:18.1
4,-2,33:18.1
5,-2,33:18.1
6,-2,33:18.1
-1,-1,33:80.0
0,-1,33:18.1
1,-1,33:18.1
2,-1,33:18.1
3,-1,33:18.1
4,-1,33:18.1
5,-1,33:18.1
6,-1,33:18.1
0,0,33:80.0
1,0,33:18.1
2,0,33:18.1
3,0,33:18.1
4,0,33:18.1
5,0,33:18.1
0,1,33:80.0
1,1,33:80.0
2,1,33:80.0
3,1,33:80.0
4,1,33:18.1
1,2,33:80.0
2,2,33:80.0
5,-5,34:18.1
1,-4,34:80.0
2,-4,34:18.1
3,-4,34:18.1
4,-4,34:18.1
5,-4,34:18.1
6,-4,34:18.1
0,-3,34:80.0
1,-3,34:18.1
2,-3,34:17.12
3,-3,34:18.1
4,-3,34:18.1
5,-3,34:18.1
6,-3,34:18.1
0,-2,34:80.0
1,-2,34:18.1
2,-2,34:18.1
3,-2,34:18.1
4,-2,34:17.12
5,-2,34:18.1
6,-2,34:80.0
0,-1,34:80.0
1,-1,34:80.0
2,-1,34:18.1
3,-1,34:18.1
4,-1,34:18.1
5,-1,34:18.1
6,-1,34:80.0
1,0,34:80.0
2,0,34:80.0
3,0,34:18.1
4,0,34:18.1
5,0,34:80.0
4,1,34:80.0
3,-7,35:18.1
4,-7,35:18.1
2,-6,35:18.1
3,-6,35:17.12
4,-6,35:18.1
5,-6,35:18.1
1,-5,35:18.1
2,-5,35:18.1
3,-5,35:18.1
4,-5,35:18.1
5,-5,35:18.1
1,-4,35:18.1
2,-4,35:17.12
3,-4,35:18.1
4,-4,35:18.1
5,-4,35:18.1
6,-4,35:80.0
1,-3,35:18.1
2,-3,35:17.12
3,-3,35:18.1
4,-3,35:18.1
5,-3,35:18.1
6,-3,35:80.0
1,-2,35:80.0
2,-2,35:18.1
3,-2,35:18.1
4,-2,35:18.1
5,-2,35:18.1
2,-1,35:80.0
3,-1,35:18.1
4,-1,35:18.1
5,-1,35:80.0
3,0,35:80.0
4,0,35:80.0
3,-7,36:80.0
4,-7,36:80.0
1,-6,36:18.1
2,-6,36:18.1
3,-6,36:18.1
4,-6,36:80.0
5,-6,36:80.0
0,-5,36:18.1
1,-5,36:18.1
2,-5,36:18.1
3,-5,36:18.1
4,-5,36:18.1
5,-5,36:80.0
0,-4,36:18.1
1,-4,36:17.12
2,-4,36:17.12
3,-4,36:18.1
4,-4,36:18.1
5,-4,36:80.0
0,-3,36:18.1
1,-3,36:17.12
2,-3,36:17.12
3,-3,36:18.1
4,-3,36:18.1
5,-3,36:80.0
1,-2,36:18.1
2,-2,36:18.1
3,-2,36:18.1
4,-2,36:80.0
5,-2,36:80.0
3,-1,36:80.0
4,-1,36:80.0
1,-6,37:18.1
2,-6,37:18.1
3,-6,37:80.0
0,-5,37:18.1
1,-5,37:18.1
2,-5,37:18.1
3,-5,37:18.1
4,-5,37:80.0
-1,-4,37:18.1
0,-4,37:18.1
1,-4,37:17.12
2,-4,37:17.12
3,-4,37:18.1
4,-4,37:80.0
-1,-3,37:18.1
0,-3,37:18.1
1,-3,37:17.12
2,-3,37:17.12
3,-3,37:18.1
4,-3,37:80.0
0,-2,37:18.1
1,-2,37:18.1
2,-2,37:18.1
3,-2,37:80.0
1,-6,38:80.0
2,-6,38:80.0
0,-5,38:18.1
1,-5,38:18.1
2,-5,38:18.1
3,-5,38:80.0
-1,-4,38:18.1
0,-4,38:18.1
1,-4,38:17.12
2,-4,38:18.1
3,-4,38:18.1
-1,-3,38:18.1
0,-3,38:18.1
1,-3,38:18.1
2,-3,38:18.1
3,-3,38:18.1
0,-2,38:18.1
1,-2,38:18.1
2,-2,38:18.1
3,-2,38:18.1
1,-1,38:18.1
2,-1,38:18.1
0,-5,39:80.0
1,-5,39:80.0
2,-5,39:80.0
-1,-4,39:80.0
0,-4,39:80.0
1,-4,39:18.1
2,-4,39:18.1
3,-4,39:18.1
-1,-3,39:80.0
0,-3,39:18.1
1,-3,39:18.1
2,-3,39:18.1
3,-3,39:18.1
4,-3,39:18.1
0,-2,39:18.1
1,-2,39:18.1
2,-2,39:18.1
3,-2,39:18.1
4,-2,39:18.1
1,-1,39:18.1
2,-1,39:18.1
3,-1,39:18.1
1,-4,40:18.1
2,-4,40:18.1
3,-4,40:18.1
0,-3,40:18.1
1,-3,40:18.1
2,-3,40:17.12
3,-3,40:18.1
4,-3,40:18.1
0,-2,40:18.1
1,-2,40:18.1
2,-2,40:18.1
3,-2,40:18.1
4,-2,40:18.1
1,-1,40:18.1
2,-1,40:18.1
3,-1,40:18.1
1,-5,41:18.1
2,-5,41:18.1
0,-4,41:18.1
1,-4,41:18.1
2,-4,41:18.1
3,-4,41:18.1
0,-3,41:18.1
1,-3,41:18.1
2,-3,41:17.12
3,-3,41:18.1
4,-3,41:18.1
0,-2,41:80.0
1,-2,41:18.1
2,-2,41:18.1
3,-2,41:18.1
4,-2,41:18.1
1,-1,41:80.0
2,-1,41:18.1
3,-1,41:18.1
1,-5,42:80.0
2,-5,42:80.0
0,-4,42:80.0
1,-4,42:80.0
2,-4,42:80.0
3,-4,42:80.0
0,-3,42:80.0
1,-3,42:80.0
2,-3,42:18.1
3,-3,42:80.0
4,-3,42:80.0
1,-2,42:80.0
2,-2,42:80.0
3,-2,42:80.0
4,-2,42:80.0
2,-1,42:80.0
3,-1,42:80.0
2,-3,43:18.1
2,-3,44:80.0
