[META]
version=2.0
spawnOnBlockType=2
spawnSunlight=True
spawnDarkness=True
spawnWater=False
spawnLava=False
underFill=False
randomRotation=True
dig=True
tree=False
branch=False
needsFoundation=True
rarity=100
collisionPercentage=20
spawnElevationMin=0
spawnElevationMax=200
spawnInBiome=Custom
[DATA]
0,-3,-4:17.12
1,-3,-4:17.12
0,-2,-4:17.12
1,-2,-4:17.12
0,-3,-3:17.12
1,-3,-3:17.12
0,-2,-3:17.12
1,-2,-3:17.12
0,-3,-2:17.12
1,-3,-2:17.12
0,-2,-2:17.12
1,-2,-2:17.12
0,-3,-1:17.12
1,-3,-1:17.12
0,-2,-1:17.12
1,-2,-1:17.12
0,-3,0:17.12
1,-3,0:17.12
0,-2,0:17.12
1,-2,0:17.12
0,-3,1:17.12
1,-3,1:17.12
0,-2,1:17.12
1,-2,1:17.12
0,-3,2:17.12
1,-3,2:17.12
0,-2,2:17.12
1,-2,2:17.12
0,-3,3:17.12
1,-3,3:17.12
0,-2,3:17.12
1,-2,3:17.12
0,-3,4:17.12
1,-3,4:17.12
0,-2,4:17.12
1,-2,4:17.12
0,-3,5:17.12
1,-3,5:17.12
0,-2,5:17.12
1,-2,5:17.12
0,-3,6:17.12
1,-3,6:17.12
0,-2,6:17.12
1,-2,6:17.12
0,-3,7:17.12
1,-3,7:17.12
0,-2,7:17.12
1,-2,7:17.12
0,-3,8:17.12
1,-3,8:17.12
0,-2,8:17.12
1,-2,8:17.12
0,-3,9:17.12
1,-3,9:17.12
0,-2,9:17.12
1,-2,9:17.12
0,-3,10:17.12
1,-3,10:17.12
0,-2,10:17.12
1,-2,10:17.12
-11,2,10:18.1
-10,2,10:18.1
-9,2,10:18.1
-8,2,10:18.1
-12,3,10:18.1
-11,3,10:18.1
-10,3,10:18.1
-9,3,10:18.1
-8,3,10:18.1
-7,3,10:18.1
-12,4,10:18.1
-11,4,10:18.1
-10,4,10:18.1
-9,4,10:17.12
-8,4,10:18.1
-7,4,10:18.1
-11,5,10:18.1
-10,5,10:18.1
-9,5,10:18.1
-8,5,10:18.1
0,-3,11:17.12
1,-3,11:17.12
0,-2,11:17.12
1,-2,11:17.12
-6,0,11:18.1
-5,0,11:18.1
-4,0,11:18.1
-8,1,11:18.1
-7,1,11:18.1
-6,1,11:18.1
-5,1,11:18.1
-4,1,11:18.1
-3,1,11:18.1
-9,2,11:18.1
-8,2,11:18.1
-7,2,11:18.1
-6,2,11:17.12
-5,2,11:18.1
-4,2,11:18.1
-3,2,11:18.1
-9,3,11:18.1
-8,3,11:18.1
-7,3,11:18.1
-6,3,11:18.1
-5,3,11:18.1
-4,3,11:18.1
-8,4,11:18.1
-7,4,11:18.1
-6,4,11:18.1
-5,4,11:18.1
-1,7,11:18.1
0,7,11:18.1
-2,8,11:18.1
-1,8,11:18.1
0,8,11:18.1
1,8,11:18.1
-2,9,11:18.1
-1,9,11:18.1
0,9,11:18.1
1,9,11:18.1
-2,10,11:18.1
-1,10,11:18.1
0,10,11:18.1
-1,11,11:18.1
0,-3,12:17.12
1,-3,12:17.12
-3,-2,12:18.1
-2,-2,12:18.1
0,-2,12:17.12
1,-2,12:17.12
-5,-1,12:18.1
-4,-1,12:18.1
-3,-1,12:18.1
-6,0,12:18.1
-5,0,12:18.1
-4,0,12:18.1
-3,0,12:17.12
-2,0,12:18.1
-6,1,12:18.1
-5,1,12:18.1
-4,1,12:18.1
-3,1,12:18.1
-2,1,12:18.1
-5,2,12:18.1
-4,2,12:18.1
-3,2,12:18.1
10,4,12:18.1
-1,5,12:18.1
0,5,12:18.1
10,5,12:18.1
-2,6,12:18.1
-1,6,12:18.1
0,6,12:18.1
1,6,12:18.1
7,6,12:18.1
8,6,12:18.1
9,6,12:17.12
10,6,12:18.1
11,6,12:18.1
-2,7,12:18.1
-1,7,12:18.1
0,7,12:18.1
1,7,12:18.1
8,7,12:18.1
9,7,12:18.1
10,7,12:18.1
11,7,12:18.1
-2,8,12:18.1
-1,8,12:17.12
0,8,12:18.1
1,8,12:18.1
9,8,12:18.1
10,8,12:18.1
-1,9,12:18.1
0,9,12:18.1
12,-6,13:18.1
13,-6,13:18.1
10,-5,13:18.1
11,-5,13:18.1
12,-5,13:18.1
13,-5,13:18.1
14,-5,13:18.1
9,-4,13:18.1
10,-4,13:18.1
11,-4,13:18.1
12,-4,13:17.12
13,-4,13:18.1
14,-4,13:18.1
-1,-3,13:18.1
0,-3,13:18.1
1,-3,13:18.1
9,-3,13:18.1
10,-3,13:18.1
11,-3,13:18.1
12,-3,13:18.1
13,-3,13:18.1
-2,-2,13:18.1
-1,-2,13:18.1
0,-2,13:17.12
1,-2,13:17.12
10,-2,13:18.1
11,-2,13:18.1
12,-2,13:18.1
-3,-1,13:18.1
-2,-1,13:18.1
-1,-1,13:18.1
-3,0,13:18.1
-2,0,13:18.1
-1,0,13:18.1
4,0,13:18.1
5,0,13:18.1
-2,1,13:18.1
-1,1,13:18.1
0,1,13:18.1
1,1,13:18.1
3,1,13:18.1
4,1,13:18.1
5,1,13:18.1
6,1,13:18.1
7,1,13:18.1
-1,2,13:18.1
0,2,13:18.1
1,2,13:18.1
2,2,13:18.1
4,2,13:18.1
5,2,13:18.1
6,2,13:18.1
7,2,13:18.1
8,2,13:18.1
-1,3,13:18.1
0,3,13:18.1
1,3,13:18.1
2,3,13:18.1
4,3,13:18.1
5,3,13:18.1
6,3,13:18.1
7,3,13:17.12
8,3,13:18.1
-1,4,13:18.1
0,4,13:18.1
1,4,13:17.12
2,4,13:18.1
5,4,13:18.1
6,4,13:18.1
7,4,13:18.1
8,4,13:18.1
9,4,13:18.1
0,5,13:18.1
1,5,13:18.1
6,5,13:18.1
7,5,13:18.1
8,5,13:18.1
9,5,13:18.1
7,6,13:18.1
8,6,13:18.1
5,-13,14:18.1
6,-13,14:18.1
4,-12,14:18.1
5,-12,14:18.1
6,-12,14:18.1
7,-12,14:18.1
3,-11,14:18.1
4,-11,14:18.1
5,-11,14:17.12
6,-11,14:18.1
7,-11,14:18.1
3,-10,14:18.1
4,-10,14:18.1
5,-10,14:18.1
6,-10,14:18.1
4,-9,14:18.1
5,-9,14:18.1
7,-5,14:18.1
8,-5,14:18.1
9,-5,14:18.1
10,-5,14:18.1
6,-4,14:18.1
7,-4,14:18.1
8,-4,14:17.12
9,-4,14:18.1
10,-4,14:18.1
11,-4,14:18.1
0,-3,14:18.1
1,-3,14:18.1
6,-3,14:18.1
7,-3,14:18.1
8,-3,14:18.1
9,-3,14:18.1
10,-3,14:18.1
11,-3,14:18.1
-1,-2,14:18.1
0,-2,14:17.12
1,-2,14:17.12
2,-2,14:18.1
7,-2,14:18.1
8,-2,14:18.1
9,-2,14:18.1
10,-2,14:18.1
-1,-1,14:18.1
0,-1,14:18.1
1,-1,14:18.1
2,-1,14:18.1
-1,0,14:18.1
0,0,14:17.12
1,0,14:18.1
2,0,14:18.1
3,0,14:18.1
4,0,14:18.1
5,0,14:18.1
-1,1,14:18.1
0,1,14:18.1
1,1,14:18.1
2,1,14:18.1
3,1,14:18.1
4,1,14:17.12
5,1,14:18.1
6,1,14:18.1
0,2,14:18.1
1,2,14:18.1
3,2,14:18.1
4,2,14:18.1
5,2,14:18.1
6,2,14:18.1
4,3,14:18.1
5,3,14:18.1
-4,-13,15:18.1
-3,-13,15:18.1
-5,-12,15:18.1
-4,-12,15:18.1
-3,-12,15:18.1
-2,-12,15:18.1
-5,-11,15:18.1
-4,-11,15:18.1
-3,-11,15:17.12
-2,-11,15:18.1
4,-11,15:18.1
5,-11,15:18.1
-5,-10,15:18.1
-4,-10,15:18.1
-3,-10,15:18.1
-2,-10,15:18.1
3,-10,15:18.1
4,-10,15:18.1
5,-10,15:18.1
6,-10,15:18.1
-4,-9,15:18.1
-3,-9,15:18.1
2,-9,15:18.1
3,-9,15:18.1
4,-9,15:17.12
5,-9,15:18.1
6,-9,15:18.1
2,-8,15:18.1
3,-8,15:18.1
4,-8,15:18.1
5,-8,15:18.1
6,-8,15:18.1
2,-7,15:18.1
3,-7,15:18.1
4,-7,15:18.1
5,-7,15:18.1
3,-6,15:18.1
4,-6,15:18.1
4,-5,15:18.1
5,-5,15:18.1
6,-5,15:18.1
5,-4,15:18.1
6,-4,15:18.1
7,-4,15:18.1
0,-3,15:17.12
1,-3,15:17.12
5,-3,15:17.12
6,-3,15:18.1
7,-3,15:18.1
-1,-2,15:18.1
0,-2,15:18.1
1,-2,15:17.12
2,-2,15:18.1
3,-2,15:18.1
4,-2,15:18.1
5,-2,15:18.1
6,-2,15:18.1
7,-2,15:18.1
-1,-1,15:18.1
0,-1,15:18.1
1,-1,15:18.1
2,-1,15:18.1
3,-1,15:18.1
4,-1,15:18.1
5,-1,15:18.1
6,-1,15:18.1
1,0,15:18.1
2,0,15:18.1
3,0,15:18.1
4,0,15:18.1
2,1,15:18.1
3,1,15:18.1
-4,-11,16:18.1
-3,-11,16:18.1
-2,-11,16:18.1
-5,-10,16:18.1
-4,-10,16:18.1
-3,-10,16:18.1
-2,-10,16:18.1
-1,-10,16:18.1
-5,-9,16:18.1
-4,-9,16:18.1
-3,-9,16:17.12
-2,-9,16:18.1
-1,-9,16:18.1
-4,-8,16:18.1
-3,-8,16:18.1
-2,-8,16:18.1
-1,-8,16:18.1
2,-8,16:18.1
3,-8,16:18.1
-4,-7,16:18.1
-3,-7,16:18.1
-2,-7,16:18.1
-1,-7,16:18.1
0,-7,16:18.1
1,-7,16:18.1
2,-7,16:18.1
3,-7,16:18.1
4,-7,16:18.1
-3,-6,16:18.1
-2,-6,16:18.1
-1,-6,16:18.1
0,-6,16:18.1
1,-6,16:18.1
2,-6,16:18.1
3,-6,16:17.12
4,-6,16:18.1
5,-6,16:18.1
-9,-5,16:18.1
-8,-5,16:18.1
0,-5,16:18.1
1,-5,16:18.1
2,-5,16:18.1
3,-5,16:18.1
4,-5,16:18.1
5,-5,16:18.1
-10,-4,16:18.1
-9,-4,16:18.1
-8,-4,16:17.12
-7,-4,16:18.1
0,-4,16:18.1
1,-4,16:18.1
2,-4,16:18.1
3,-4,16:18.1
4,-4,16:18.1
-10,-3,16:18.1
-9,-3,16:18.1
-8,-3,16:18.1
-7,-3,16:18.1
-1,-3,16:18.1
0,-3,16:17.12
1,-3,16:17.12
2,-3,16:18.1
3,-3,16:18.1
4,-3,16:18.1
5,-3,16:18.1
-9,-2,16:18.1
-8,-2,16:18.1
-1,-2,16:18.1
0,-2,16:17.12
1,-2,16:17.12
2,-2,16:18.1
3,-2,16:18.1
4,-2,16:18.1
5,-2,16:18.1
0,-1,16:18.1
1,-1,16:18.1
2,-1,16:18.1
3,-1,16:18.1
4,-1,16:18.1
2,0,16:18.1
3,0,16:18.1
-2,-8,17:18.1
-1,-8,17:18.1
-3,-7,17:18.1
-2,-7,17:18.1
-1,-7,17:18.1
0,-7,17:18.1
-3,-6,17:18.1
-2,-6,17:18.1
-1,-6,17:17.12
0,-6,17:18.1
1,-6,17:18.1
-8,-5,17:18.1
-7,-5,17:18.1
-6,-5,17:18.1
-2,-5,17:18.1
-1,-5,17:18.1
0,-5,17:18.1
1,-5,17:18.1
2,-5,17:18.1
-9,-4,17:18.1
-8,-4,17:18.1
-7,-4,17:18.1
-6,-4,17:18.1
-5,-4,17:18.1
-4,-4,17:18.1
-1,-4,17:18.1
0,-4,17:18.1
1,-4,17:18.1
2,-4,17:18.1
3,-4,17:18.1
-9,-3,17:18.1
-8,-3,17:18.1
-7,-3,17:18.1
-6,-3,17:17.12
-5,-3,17:18.1
-4,-3,17:18.1
-3,-3,17:18.1
-1,-3,17:18.1
0,-3,17:17.12
1,-3,17:17.12
2,-3,17:18.1
3,-3,17:18.1
-8,-2,17:18.1
-7,-2,17:18.1
-6,-2,17:18.1
-5,-2,17:18.1
-4,-2,17:18.1
-3,-2,17:18.1
-1,-2,17:18.1
0,-2,17:17.12
1,-2,17:17.12
2,-2,17:18.1
3,-2,17:18.1
-6,-1,17:18.1
-5,-1,17:18.1
-4,-1,17:18.1
-2,-1,17:18.1
-1,-1,17:18.1
0,-1,17:18.1
1,-1,17:18.1
2,-1,17:18.1
-1,0,17:18.1
-6,3,17:18.1
-5,3,17:18.1
-7,4,17:18.1
-6,4,17:18.1
-5,4,17:18.1
-4,4,17:18.1
-7,5,17:18.1
-6,5,17:18.1
-5,5,17:18.1
-4,5,17:18.1
-6,6,17:18.1
-5,6,17:18.1
0,-5,18:18.1
1,-5,18:18.1
-4,-4,18:18.1
-3,-4,18:18.1
-2,-4,18:18.1
-1,-4,18:18.1
0,-4,18:18.1
1,-4,18:18.1
2,-4,18:18.1
-5,-3,18:18.1
-4,-3,18:18.1
-3,-3,18:18.1
-2,-3,18:18.1
-1,-3,18:18.1
0,-3,18:17.12
1,-3,18:17.12
2,-3,18:18.1
-5,-2,18:18.1
-4,-2,18:18.1
-3,-2,18:17.12
-2,-2,18:18.1
-1,-2,18:18.1
0,-2,18:17.12
1,-2,18:17.12
2,-2,18:18.1
-4,-1,18:18.1
-3,-1,18:18.1
-2,-1,18:18.1
-1,-1,18:18.1
0,-1,18:18.1
1,-1,18:18.1
2,-1,18:18.1
-3,0,18:18.1
-2,0,18:18.1
-1,0,18:18.1
0,0,18:18.1
-4,1,18:18.1
-3,1,18:18.1
-2,1,18:18.1
-1,1,18:18.1
0,1,18:18.1
-5,2,18:18.1
-4,2,18:18.1
-3,2,18:18.1
-2,2,18:18.1
-1,2,18:18.1
-6,3,18:18.1
-5,3,18:18.1
-4,3,18:18.1
-3,3,18:18.1
-2,3,18:18.1
-6,4,18:18.1
-5,4,18:17.12
-4,4,18:18.1
-3,4,18:18.1
-5,5,18:18.1
-4,5,18:18.1
2,5,18:18.1
3,5,18:18.1
1,6,18:18.1
2,6,18:18.1
3,6,18:18.1
4,6,18:18.1
1,7,18:18.1
2,7,18:18.1
3,7,18:18.1
4,7,18:18.1
1,8,18:18.1
2,8,18:18.1
3,8,18:18.1
4,8,18:18.1
2,9,18:18.1
3,9,18:18.1
-1,-4,19:18.1
0,-4,19:18.1
1,-4,19:18.1
-2,-3,19:18.1
-1,-3,19:18.1
0,-3,19:17.12
1,-3,19:17.12
2,-3,19:18.1
-2,-2,19:18.1
-1,-2,19:18.1
0,-2,19:17.12
1,-2,19:17.12
2,-2,19:18.1
-3,-1,19:18.1
-2,-1,19:18.1
-1,-1,19:18.1
0,-1,19:18.1
1,-1,19:18.1
2,-1,19:18.1
-4,0,19:18.1
-3,0,19:18.1
-2,0,19:18.1
-1,0,19:18.1
0,0,19:18.1
1,0,19:18.1
8,0,19:18.1
9,0,19:18.1
-4,1,19:18.1
-3,1,19:18.1
-2,1,19:17.12
-1,1,19:18.1
0,1,19:18.1
1,1,19:18.1
7,1,19:18.1
8,1,19:18.1
9,1,19:18.1
10,1,19:18.1
-3,2,19:18.1
-2,2,19:18.1
-1,2,19:18.1
7,2,19:18.1
8,2,19:18.1
9,2,19:18.1
10,2,19:18.1
2,3,19:18.1
3,3,19:18.1
4,3,19:18.1
8,3,19:18.1
9,3,19:18.1
1,4,19:18.1
2,4,19:18.1
3,4,19:17.12
4,4,19:18.1
1,5,19:18.1
2,5,19:18.1
3,5,19:18.1
4,5,19:18.1
1,6,19:18.1
2,6,19:18.1
3,6,19:18.1
4,6,19:18.1
2,7,19:17.12
3,7,19:18.1
8,-7,20:18.1
9,-7,20:18.1
7,-6,20:18.1
8,-6,20:18.1
9,-6,20:18.1
10,-6,20:18.1
7,-5,20:18.1
8,-5,20:18.1
9,-5,20:18.1
10,-5,20:18.1
8,-4,20:18.1
9,-4,20:18.1
-1,-3,20:18.1
0,-3,20:18.1
1,-3,20:18.1
-2,-2,20:18.1
-1,-2,20:18.1
0,-2,20:17.12
1,-2,20:17.12
2,-2,20:18.1
3,-2,20:18.1
4,-2,20:18.1
5,-2,20:18.1
-2,-1,20:18.1
-1,-1,20:18.1
0,-1,20:18.1
1,-1,20:18.1
2,-1,20:18.1
3,-1,20:18.1
4,-1,20:18.1
5,-1,20:18.1
6,-1,20:18.1
7,-1,20:18.1
8,-1,20:18.1
-1,0,20:18.1
0,0,20:18.1
1,0,20:18.1
2,0,20:18.1
3,0,20:18.1
4,0,20:18.1
5,0,20:18.1
6,0,20:18.1
7,0,20:18.1
8,0,20:18.1
9,0,20:18.1
0,1,20:18.1
1,1,20:18.1
2,1,20:18.1
3,1,20:18.1
4,1,20:18.1
5,1,20:18.1
6,1,20:18.1
7,1,20:18.1
8,1,20:17.12
9,1,20:18.1
0,2,20:18.1
1,2,20:18.1
2,2,20:18.1
3,2,20:18.1
5,2,20:18.1
6,2,20:18.1
7,2,20:18.1
8,2,20:18.1
9,2,20:18.1
1,3,20:18.1
2,3,20:18.1
7,3,20:18.1
8,3,20:18.1
2,-11,21:18.1
3,-11,21:18.1
1,-10,21:18.1
2,-10,21:18.1
3,-10,21:18.1
4,-10,21:18.1
1,-9,21:18.1
2,-9,21:18.1
3,-9,21:18.1
4,-9,21:18.1
2,-8,21:18.1
3,-8,21:18.1
6,-7,21:18.1
7,-7,21:18.1
8,-7,21:18.1
4,-6,21:18.1
5,-6,21:18.1
6,-6,21:18.1
7,-6,21:18.1
8,-6,21:18.1
9,-6,21:18.1
4,-5,21:18.1
5,-5,21:18.1
6,-5,21:18.1
7,-5,21:18.1
8,-5,21:17.12
9,-5,21:18.1
4,-4,21:18.1
5,-4,21:18.1
6,-4,21:18.1
7,-4,21:18.1
8,-4,21:18.1
0,-3,21:18.1
1,-3,21:18.1
2,-3,21:18.1
4,-3,21:18.1
6,-3,21:18.1
7,-3,21:18.1
0,-2,21:18.1
1,-2,21:17.12
2,-2,21:18.1
3,-2,21:18.1
4,-2,21:18.1
5,-2,21:18.1
0,-1,21:18.1
1,-1,21:18.1
2,-1,21:18.1
4,-1,21:17.12
5,-1,21:18.1
6,-1,21:18.1
0,0,21:18.1
1,0,21:18.1
2,0,21:17.12
3,0,21:18.1
4,0,21:18.1
5,0,21:18.1
6,0,21:18.1
1,1,21:18.1
2,1,21:18.1
4,1,21:18.1
5,1,21:18.1
1,-11,22:18.1
2,-11,22:18.1
0,-10,22:18.1
1,-10,22:18.1
2,-10,22:17.12
3,-10,22:18.1
-5,-9,22:18.1
-4,-9,22:18.1
0,-9,22:18.1
1,-9,22:18.1
2,-9,22:18.1
3,-9,22:18.1
-6,-8,22:18.1
-5,-8,22:18.1
-4,-8,22:18.1
-3,-8,22:18.1
0,-8,22:18.1
1,-8,22:18.1
2,-8,22:18.1
3,-8,22:18.1
-6,-7,22:18.1
-5,-7,22:18.1
-4,-7,22:18.1
-3,-7,22:18.1
3,-7,22:18.1
-5,-6,22:18.1
-4,-6,22:18.1
4,-6,22:18.1
4,-5,22:18.1
5,-5,22:18.1
6,-5,22:18.1
4,-4,22:17.12
5,-4,22:18.1
6,-4,22:18.1
0,-3,22:18.1
1,-3,22:18.1
2,-3,22:18.1
4,-3,22:18.1
5,-3,22:18.1
6,-3,22:18.1
0,-2,22:18.1
1,-2,22:17.12
2,-2,22:18.1
3,-2,22:18.1
4,-2,22:18.1
5,-2,22:18.1
0,-1,22:18.1
1,-1,22:18.1
2,-1,22:18.1
3,-1,22:18.1
1,0,22:18.1
2,0,22:18.1
-5,-8,23:18.1
-4,-8,23:18.1
-3,-8,23:18.1
-6,-7,23:18.1
-5,-7,23:17.12
-4,-7,23:18.1
-3,-7,23:18.1
-2,-7,23:18.1
1,-7,23:18.1
2,-7,23:18.1
-6,-6,23:18.1
-5,-6,23:18.1
-4,-6,23:18.1
-3,-6,23:18.1
-2,-6,23:18.1
-1,-6,23:18.1
0,-6,23:18.1
1,-6,23:17.12
2,-6,23:18.1
3,-6,23:18.1
-5,-5,23:18.1
-4,-5,23:18.1
-3,-5,23:18.1
0,-5,23:18.1
1,-5,23:18.1
2,-5,23:18.1
3,-5,23:18.1
-3,-4,23:18.1
0,-4,23:18.1
1,-4,23:18.1
2,-4,23:18.1
3,-4,23:18.1
0,-3,23:18.1
1,-3,23:17.12
2,-3,23:18.1
3,-3,23:18.1
-7,-2,23:18.1
-6,-2,23:18.1
0,-2,23:18.1
1,-2,23:17.12
2,-2,23:18.1
3,-2,23:18.1
-8,-1,23:18.1
-7,-1,23:18.1
-6,-1,23:18.1
-5,-1,23:18.1
1,-1,23:18.1
2,-1,23:18.1
-8,0,23:18.1
-7,0,23:18.1
-6,0,23:18.1
-5,0,23:18.1
-7,1,23:18.1
-6,1,23:18.1
-2,-6,24:18.1
-1,-6,24:18.1
-3,-5,24:18.1
-2,-5,24:17.12
-1,-5,24:18.1
0,-5,24:18.1
-3,-4,24:18.1
-2,-4,24:18.1
-1,-4,24:18.1
0,-4,24:18.1
1,-4,24:18.1
2,-4,24:18.1
-5,-3,24:18.1
-4,-3,24:18.1
-3,-3,24:18.1
-2,-3,24:18.1
-1,-3,24:18.1
0,-3,24:17.12
1,-3,24:17.12
3,-3,24:18.1
-6,-2,24:18.1
-5,-2,24:18.1
-4,-2,24:18.1
-3,-2,24:18.1
0,-2,24:18.1
1,-2,24:17.12
2,-2,24:18.1
3,-2,24:18.1
-7,-1,24:18.1
-6,-1,24:17.12
-5,-1,24:18.1
-4,-1,24:18.1
-3,-1,24:18.1
1,-1,24:18.1
-7,0,24:18.1
-6,0,24:18.1
-5,0,24:18.1
-4,0,24:18.1
-3,0,24:18.1
-6,1,24:18.1
-5,1,24:18.1
-4,1,24:18.1
0,-4,25:18.1
1,-4,25:18.1
-3,-3,25:18.1
-2,-3,25:18.1
-1,-3,25:18.1
0,-3,25:17.12
1,-3,25:17.12
2,-3,25:18.1
-4,-2,25:18.1
-3,-2,25:18.1
-2,-2,25:17.12
-1,-2,25:18.1
0,-2,25:17.12
1,-2,25:17.12
2,-2,25:18.1
-4,-1,25:18.1
-3,-1,25:18.1
-2,-1,25:18.1
-1,-1,25:18.1
0,-1,25:18.1
1,-1,25:18.1
-3,0,25:18.1
-2,0,25:18.1
-1,0,25:18.1
-2,1,25:18.1
-1,1,25:18.1
-3,2,25:18.1
-2,2,25:18.1
-1,2,25:18.1
0,2,25:18.1
-3,3,25:18.1
-2,3,25:18.1
-1,3,25:18.1
0,3,25:18.1
-3,4,25:18.1
-2,4,25:18.1
-1,4,25:17.12
0,4,25:18.1
-3,5,25:18.1
-2,5,25:18.1
-1,5,25:18.1
0,5,25:18.1
-2,6,25:18.1
-1,6,25:18.1
0,-3,26:18.1
1,-3,26:18.1
-1,-2,26:18.1
0,-2,26:17.12
1,-2,26:17.12
-2,-1,26:18.1
-1,-1,26:18.1
0,-1,26:18.1
1,-1,26:18.1
2,-1,26:18.1
-2,0,26:18.1
-1,0,26:18.1
0,0,26:18.1
1,0,26:18.1
2,0,26:18.1
3,0,26:18.1
4,0,26:18.1
-2,1,26:18.1
-1,1,26:18.1
0,1,26:17.12
1,1,26:18.1
2,1,26:18.1
3,1,26:18.1
4,1,26:18.1
5,1,26:18.1
-1,2,26:18.1
0,2,26:18.1
1,2,26:18.1
2,2,26:18.1
3,2,26:18.1
4,2,26:18.1
5,2,26:18.1
2,3,26:18.1
3,3,26:17.12
4,3,26:18.1
5,3,26:18.1
2,4,26:18.1
3,4,26:18.1
4,4,26:18.1
5,4,26:18.1
3,5,26:18.1
4,5,26:18.1
-1,-3,27:18.1
0,-3,27:17.12
1,-3,27:17.12
5,-3,27:18.1
6,-3,27:18.1
7,-3,27:18.1
-1,-2,27:18.1
0,-2,27:18.1
1,-2,27:17.12
4,-2,27:18.1
5,-2,27:18.1
6,-2,27:17.12
7,-2,27:18.1
8,-2,27:18.1
-1,-1,27:18.1
0,-1,27:18.1
1,-1,27:18.1
2,-1,27:18.1
3,-1,27:18.1
4,-1,27:18.1
5,-1,27:18.1
6,-1,27:18.1
7,-1,27:18.1
8,-1,27:18.1
0,0,27:18.1
1,0,27:18.1
2,0,27:18.1
3,0,27:18.1
4,0,27:18.1
5,0,27:18.1
6,0,27:18.1
7,0,27:18.1
1,1,27:18.1
2,1,27:18.1
3,1,27:18.1
4,1,27:18.1
2,2,27:18.1
3,2,27:18.1
3,-7,28:18.1
4,-7,28:18.1
5,-7,28:18.1
2,-6,28:18.1
3,-6,28:18.1
4,-6,28:18.1
5,-6,28:18.1
6,-6,28:18.1
2,-5,28:18.1
3,-5,28:18.1
4,-5,28:18.1
5,-5,28:18.1
6,-5,28:18.1
2,-4,28:18.1
3,-4,28:18.1
4,-4,28:18.1
5,-4,28:18.1
0,-3,28:17.12
1,-3,28:17.12
2,-3,28:18.1
3,-3,28:18.1
4,-3,28:18.1
-1,-2,28:18.1
0,-2,28:17.12
1,-2,28:17.12
2,-2,28:18.1
3,-2,28:18.1
4,-2,28:18.1
5,-2,28:18.1
0,-1,28:18.1
1,-1,28:18.1
2,-1,28:18.1
3,-1,28:17.12
4,-1,28:18.1
5,-1,28:18.1
2,0,28:18.1
3,0,28:18.1
4,0,28:18.1
0,-8,29:18.1
1,-8,29:18.1
-1,-7,29:18.1
0,-7,29:18.1
1,-7,29:18.1
2,-7,29:18.1
-1,-6,29:18.1
0,-6,29:17.12
1,-6,29:18.1
2,-6,29:18.1
3,-6,29:18.1
-1,-5,29:18.1
0,-5,29:18.1
1,-5,29:18.1
2,-5,29:18.1
3,-5,29:18.1
4,-5,29:17.12
-1,-4,29:18.1
0,-4,29:18.1
1,-4,29:18.1
2,-4,29:18.1
3,-4,29:18.1
4,-4,29:18.1
0,-3,29:17.12
1,-3,29:17.12
2,-3,29:18.1
3,-3,29:18.1
4,-3,29:18.1
0,-2,29:17.12
1,-2,29:17.12
2,-2,29:18.1
3,-2,29:18.1
1,-1,29:18.1
2,-1,29:18.1
0,-6,30:18.1
1,-6,30:18.1
-4,-5,30:18.1
-3,-5,30:18.1
-2,-5,30:18.1
-1,-5,30:18.1
0,-5,30:18.1
1,-5,30:18.1
2,-5,30:18.1
-5,-4,30:18.1
-4,-4,30:18.1
-3,-4,30:17.12
-2,-4,30:18.1
-1,-4,30:18.1
0,-4,30:18.1
1,-4,30:18.1
2,-4,30:18.1
-5,-3,30:18.1
-4,-3,30:18.1
-3,-3,30:18.1
-2,-3,30:18.1
-1,-3,30:18.1
0,-3,30:17.12
1,-3,30:17.12
2,-3,30:18.1
-4,-2,30:18.1
-3,-2,30:18.1
-2,-2,30:18.1
-1,-2,30:18.1
0,-2,30:17.12
1,-2,30:17.12
2,-2,30:18.1
1,-1,30:18.1
2,-1,30:18.1
-2,-5,31:18.1
-1,-5,31:18.1
-3,-4,31:18.1
-2,-4,31:18.1
-1,-4,31:18.1
0,-4,31:18.1
1,-4,31:18.1
-3,-3,31:18.1
-2,-3,31:18.1
-1,-3,31:18.1
0,-3,31:17.12
1,-3,31:17.12
2,-3,31:18.1
-3,-2,31:18.1
-2,-2,31:18.1
-1,-2,31:18.1
0,-2,31:17.12
1,-2,31:17.12
2,-2,31:18.1
-4,-1,31:18.1
-3,-1,31:18.1
-2,-1,31:17.12
-1,-1,31:18.1
0,-1,31:18.1
1,-1,31:18.1
-4,0,31:18.1
-3,0,31:18.1
-2,0,31:18.1
-1,0,31:18.1
0,0,31:18.1
1,0,31:18.1
-3,1,31:18.1
-2,1,31:18.1
-1,1,31:18.1
0,1,31:18.1
-1,-3,32:18.1
0,-3,32:18.1
1,-3,32:18.1
-2,-2,32:18.1
-1,-2,32:18.1
0,-2,32:17.12
1,-2,32:17.12
-2,-1,32:18.1
-1,-1,32:18.1
0,-1,32:18.1
1,-1,32:18.1
2,-1,32:18.1
-2,0,32:18.1
-1,0,32:18.1
0,0,32:18.1
1,0,32:18.1
2,0,32:18.1
-1,1,32:18.1
0,1,32:18.1
1,1,32:17.12
2,1,32:18.1
-1,2,32:18.1
0,2,32:18.1
1,2,32:18.1
2,2,32:18.1
0,3,32:18.1
1,3,32:18.1
0,-3,33:18.1
1,-3,33:18.1
-1,-2,33:18.1
0,-2,33:17.12
1,-2,33:17.12
-1,-1,33:18.1
0,-1,33:18.1
1,-1,33:18.1
2,-1,33:18.1
3,-1,33:18.1
4,-1,33:18.1
5,-1,33:18.1
-1,0,33:18.1
0,0,33:18.1
1,0,33:18.1
2,0,33:18.1
3,0,33:18.1
4,0,33:18.1
5,0,33:18.1
0,1,33:18.1
1,1,33:18.1
2,1,33:18.1
3,1,33:18.1
4,1,33:18.1
3,2,33:18.1
4,-4,34:18.1
1,-3,34:18.1
2,-3,34:18.1
3,-3,34:18.1
4,-3,34:18.1
5,-3,34:18.1
0,-2,34:18.1
1,-2,34:17.12
2,-2,34:18.1
3,-2,34:18.1
4,-2,34:18.1
5,-2,34:18.1
0,-1,34:18.1
1,-1,34:18.1
2,-1,34:18.1
3,-1,34:17.12
4,-1,34:18.1
1,0,34:18.1
2,0,34:18.1
3,0,34:18.1
4,0,34:18.1
2,1,34:18.1
3,1,34:18.1
2,-6,35:18.1
3,-6,35:18.1
1,-5,35:18.1
2,-5,35:17.12
3,-5,35:18.1
4,-5,35:18.1
0,-4,35:18.1
1,-4,35:18.1
2,-4,35:18.1
3,-4,35:18.1
4,-4,35:18.1
0,-3,35:18.1
1,-3,35:17.12
2,-3,35:18.1
3,-3,35:18.1
4,-3,35:18.1
0,-2,35:18.1
1,-2,35:17.12
2,-2,35:18.1
3,-2,35:18.1
4,-2,35:18.1
1,-1,35:18.1
2,-1,35:18.1
3,-1,35:18.1
4,-1,35:18.1
2,0,35:18.1
3,0,35:18.1
0,-5,36:18.1
1,-5,36:18.1
2,-5,36:18.1
-1,-4,36:18.1
0,-4,36:18.1
1,-4,36:18.1
2,-4,36:18.1
3,-4,36:18.1
-1,-3,36:18.1
0,-3,36:17.12
1,-3,36:17.12
2,-3,36:18.1
3,-3,36:18.1
-1,-2,36:18.1
0,-2,36:17.12
1,-2,36:17.12
2,-2,36:18.1
3,-2,36:18.1
0,-1,36:18.1
1,-1,36:18.1
2,-1,36:18.1
0,-5,37:18.1
1,-5,37:18.1
-1,-4,37:18.1
0,-4,37:18.1
1,-4,37:18.1
2,-4,37:18.1
-2,-3,37:18.1
-1,-3,37:18.1
0,-3,37:17.12
1,-3,37:17.12
2,-3,37:18.1
-2,-2,37:18.1
-1,-2,37:18.1
0,-2,37:17.12
1,-2,37:17.12
2,-2,37:18.1
-1,-1,37:18.1
0,-1,37:18.1
1,-1,37:18.1
-1,-4,38:18.1
0,-4,38:18.1
1,-4,38:18.1
-2,-3,38:18.1
-1,-3,38:18.1
0,-3,38:17.12
1,-3,38:18.1
2,-3,38:18.1
-2,-2,38:18.1
-1,-2,38:18.1
0,-2,38:18.1
1,-2,38:18.1
2,-2,38:18.1
-1,-1,38:18.1
0,-1,38:18.1
1,-1,38:18.1
2,-1,38:18.1
0,0,38:18.1
1,0,38:18.1
0,-3,39:18.1
1,-3,39:18.1
2,-3,39:18.1
-1,-2,39:18.1
0,-2,39:18.1
1,-2,39:18.1
2,-2,39:18.1
3,-2,39:18.1
-1,-1,39:18.1
0,-1,39:18.1
1,-1,39:18.1
2,-1,39:18.1
3,-1,39:18.1
0,0,39:18.1
1,0,39:18.1
2,0,39:18.1
0,-3,40:18.1
1,-3,40:18.1
2,-3,40:18.1
-1,-2,40:18.1
0,-2,40:18.1
1,-2,40:17.12
2,-2,40:18.1
3,-2,40:18.1
-1,-1,40:18.1
0,-1,40:18.1
1,-1,40:18.1
2,-1,40:18.1
3,-1,40:18.1
0,0,40:18.1
1,0,40:18.1
2,0,40:18.1
0,-4,41:18.1
1,-4,41:18.1
-1,-3,41:18.1
0,-3,41:18.1
1,-3,41:18.1
2,-3,41:18.1
-1,-2,41:18.1
0,-2,41:18.1
1,-2,41:17.12
2,-2,41:18.1
3,-2,41:18.1
0,-1,41:18.1
1,-1,41:18.1
2,-1,41:18.1
3,-1,41:18.1
1,0,41:18.1
2,0,41:18.1
1,-2,42:18.1
1,-2,43:18.1
