[META]
version=2.0
spawnOnBlockType=2
spawnSunlight=True
spawnDarkness=True
spawnWater=False
spawnLava=False
underFill=False
randomRotation=True
dig=True
tree=False
branch=False
needsFoundation=True
rarity=100
collisionPercentage=20
spawnElevationMin=0
spawnElevationMax=200
spawnInBiome=Custom
[DATA]
-1,-4,-4:17.12
0,-4,-4:17.12
-1,-3,-4:17.12
0,-3,-4:17.12
-2,-2,-4:17.12
-1,-2,-4:17.12
0,-2,-4:17.12
1,-2,-4:17.12
-3,-1,-4:17.12
-2,-1,-4:17.12
-1,-1,-4:17.12
0,-1,-4:17.12
1,-1,-4:17.12
2,-1,-4:17.12
3,-1,-4:17.12
-3,0,-4:17.12
-2,0,-4:17.12
-1,0,-4:17.12
0,0,-4:17.12
1,0,-4:17.12
2,0,-4:17.12
3,0,-4:17.12
-2,1,-4:17.12
-1,1,-4:17.12
0,1,-4:17.12
1,1,-4:17.12
2,1,-4:17.12
-1,2,-4:17.12
0,2,-4:17.12
-1,-5,-3:17.12
0,-5,-3:17.0
-2,-4,-3:17.12
-1,-4,-3:17.12
0,-4,-3:17.12
1,-4,-3:17.12
-2,-3,-3:17.12
-1,-3,-3:17.12
0,-3,-3:17.12
1,-3,-3:17.12
-3,-2,-3:17.12
-2,-2,-3:17.12
-1,-2,-3:17.12
0,-2,-3:17.12
1,-2,-3:17.12
2,-2,-3:17.12
3,-2,-3:17.12
-4,-1,-3:17.12
-3,-1,-3:17.12
-2,-1,-3:17.12
-1,-1,-3:17.12
0,-1,-3:17.12
1,-1,-3:17.12
2,-1,-3:17.12
3,-1,-3:17.12
4,-1,-3:17.12
-4,0,-3:17.12
-3,0,-3:17.12
-2,0,-3:17.12
-1,0,-3:17.12
0,0,-3:17.12
1,0,-3:17.12
2,0,-3:17.12
3,0,-3:17.12
4,0,-3:17.12
-3,1,-3:17.12
-2,1,-3:17.12
-1,1,-3:17.12
0,1,-3:17.12
1,1,-3:17.12
2,1,-3:17.12
3,1,-3:17.12
-2,2,-3:17.12
-1,2,-3:17.12
0,2,-3:17.12
1,2,-3:17.12
-1,3,-3:17.12
0,3,-3:17.12
-1,-5,-2:17.12
0,-5,-2:17.12
-2,-4,-2:17.12
-1,-4,-2:17.12
0,-4,-2:17.12
1,-4,-2:17.12
-2,-3,-2:17.12
-1,-3,-2:17.12
0,-3,-2:17.12
1,-3,-2:17.12
-3,-2,-2:17.12
-2,-2,-2:17.12
-1,-2,-2:17.12
0,-2,-2:17.12
1,-2,-2:17.12
2,-2,-2:17.12
3,-2,-2:17.12
-4,-1,-2:17.12
-3,-1,-2:17.12
-2,-1,-2:17.12
-1,-1,-2:17.12
0,-1,-2:17.12
1,-1,-2:17.12
2,-1,-2:17.12
3,-1,-2:17.12
4,-1,-2:17.12
-4,0,-2:17.12
-3,0,-2:17.12
-2,0,-2:17.12
-1,0,-2:17.12
0,0,-2:17.12
1,0,-2:17.12
2,0,-2:17.12
3,0,-2:17.12
4,0,-2:17.12
-3,1,-2:17.12
-2,1,-2:17.12
-1,1,-2:17.12
0,1,-2:17.12
1,1,-2:17.12
2,1,-2:17.12
3,1,-2:17.12
-2,2,-2:17.12
-1,2,-2:17.12
0,2,-2:17.12
1,2,-2:17.12
-1,3,-2:17.12
0,3,-2:17.12
-1,-5,-1:17.12
0,-5,-1:17.12
-2,-4,-1:17.12
-1,-4,-1:17.12
0,-4,-1:17.12
1,-4,-1:17.12
-2,-3,-1:17.12
-1,-3,-1:17.12
0,-3,-1:17.12
1,-3,-1:17.12
-3,-2,-1:17.12
-2,-2,-1:17.12
-1,-2,-1:17.12
0,-2,-1:17.12
1,-2,-1:17.12
2,-2,-1:17.12
3,-2,-1:17.12
-4,-1,-1:17.12
-3,-1,-1:17.12
-2,-1,-1:17.12
-1,-1,-1:17.12
0,-1,-1:17.12
1,-1,-1:17.12
2,-1,-1:17.12
3,-1,-1:17.12
4,-1,-1:17.12
-4,0,-1:17.12
-3,0,-1:17.12
-2,0,-1:17.12
-1,0,-1:17.12
0,0,-1:17.12
1,0,-1:17.12
2,0,-1:17.12
3,0,-1:17.12
4,0,-1:17.12
-3,1,-1:17.12
-2,1,-1:17.12
-1,1,-1:17.12
0,1,-1:17.12
1,1,-1:17.12
2,1,-1:17.12
3,1,-1:17.12
-2,2,-1:17.12
-1,2,-1:17.12
0,2,-1:17.12
1,2,-1:17.12
-1,3,-1:17.12
0,3,-1:17.12
-2,-4,0:17.12
-1,-4,0:17.12
0,-4,0:17.12
1,-4,0:17.12
-2,-3,0:17.12
-1,-3,0:17.12
0,-3,0:17.12
1,-3,0:17.12
-3,-2,0:17.12
-2,-2,0:17.12
-1,-2,0:17.12
0,-2,0:17.12
1,-2,0:17.12
2,-2,0:17.12
3,-2,0:17.12
-3,-1,0:17.12
-2,-1,0:17.12
-1,-1,0:17.12
0,-1,0:17.12
1,-1,0:17.12
2,-1,0:17.12
3,-1,0:17.12
-3,0,0:17.12
-2,0,0:17.12
-1,0,0:17.12
0,0,0:17.12
1,0,0:17.12
2,0,0:17.12
3,0,0:17.12
-3,1,0:17.12
-2,1,0:17.12
-1,1,0:17.12
0,1,0:17.12
1,1,0:17.12
2,1,0:17.12
3,1,0:17.12
-2,2,0:17.12
-1,2,0:17.12
0,2,0:17.12
1,2,0:17.12
-2,-3,1:17.12
-1,-3,1:17.12
0,-3,1:17.12
1,-3,1:17.12
-2,-2,1:17.12
-1,-2,1:17.12
0,-2,1:17.12
1,-2,1:17.12
2,-2,1:17.12
-3,-1,1:17.12
-2,-1,1:17.12
-1,-1,1:17.12
0,-1,1:17.12
1,-1,1:17.12
2,-1,1:17.12
-3,0,1:17.12
-2,0,1:17.12
-1,0,1:17.12
0,0,1:17.12
1,0,1:17.12
2,0,1:17.12
-2,1,1:17.12
-1,1,1:17.12
0,1,1:17.12
1,1,1:17.12
2,1,1:17.12
-1,2,1:17.12
0,2,1:17.12
-1,-3,2:17.12
0,-3,2:17.12
-2,-2,2:17.12
-1,-2,2:17.12
0,-2,2:17.12
1,-2,2:17.12
-3,-1,2:17.12
-2,-1,2:17.12
-1,-1,2:17.12
0,-1,2:17.12
1,-1,2:17.12
2,-1,2:17.12
-3,0,2:17.12
-2,0,2:17.12
-1,0,2:17.12
0,0,2:17.12
1,0,2:17.12
2,0,2:17.12
-2,1,2:17.12
-1,1,2:17.12
0,1,2:17.12
1,1,2:17.12
-1,2,2:17.12
0,2,2:17.12
-1,-3,3:17.12
0,-3,3:17.12
-2,-2,3:17.12
-1,-2,3:17.12
0,-2,3:17.12
1,-2,3:17.12
-3,-1,3:17.12
-2,-1,3:17.12
-1,-1,3:17.12
0,-1,3:17.12
1,-1,3:17.12
2,-1,3:17.12
-3,0,3:17.12
-2,0,3:17.12
-1,0,3:17.12
0,0,3:17.12
1,0,3:17.12
2,0,3:17.12
-2,1,3:17.12
-1,1,3:17.12
0,1,3:17.12
1,1,3:17.12
-1,2,3:17.12
0,2,3:17.12
-1,-3,4:17.12
0,-3,4:17.12
-2,-2,4:17.12
-1,-2,4:17.12
0,-2,4:17.12
1,-2,4:17.12
-3,-1,4:17.12
-2,-1,4:17.12
-1,-1,4:17.12
0,-1,4:17.12
1,-1,4:17.12
2,-1,4:17.12
-3,0,4:17.12
-2,0,4:17.12
-1,0,4:17.12
0,0,4:17.12
1,0,4:17.12
2,0,4:17.12
-2,1,4:17.12
-1,1,4:17.12
0,1,4:17.12
1,1,4:17.12
-1,2,4:17.12
0,2,4:17.12
-1,-3,5:17.12
0,-3,5:17.12
-2,-2,5:17.12
-1,-2,5:17.12
0,-2,5:17.12
1,-2,5:17.12
-3,-1,5:17.12
-2,-1,5:17.12
-1,-1,5:17.12
0,-1,5:17.12
1,-1,5:17.12
2,-1,5:17.12
-3,0,5:17.12
-2,0,5:17.12
-1,0,5:17.12
0,0,5:17.12
1,0,5:17.12
2,0,5:17.12
-2,1,5:17.12
-1,1,5:17.12
0,1,5:17.12
1,1,5:17.12
-1,2,5:17.12
0,2,5:17.12
-1,-3,6:17.12
0,-3,6:17.12
-2,-2,6:17.12
-1,-2,6:17.12
0,-2,6:17.12
1,-2,6:17.12
-3,-1,6:17.12
-2,-1,6:17.12
-1,-1,6:17.12
0,-1,6:17.12
1,-1,6:17.12
2,-1,6:17.12
-3,0,6:17.12
-2,0,6:17.12
-1,0,6:17.12
0,0,6:17.12
1,0,6:17.12
2,0,6:17.12
-2,1,6:17.12
-1,1,6:17.12
0,1,6:17.12
1,1,6:17.12
-1,2,6:17.12
0,2,6:17.12
-1,-3,7:17.12
0,-3,7:17.12
-2,-2,7:17.12
-1,-2,7:17.12
0,-2,7:17.12
1,-2,7:17.12
-3,-1,7:17.12
-2,-1,7:17.12
-1,-1,7:17.12
0,-1,7:17.12
1,-1,7:17.12
2,-1,7:17.12
-3,0,7:17.12
-2,0,7:17.12
-1,0,7:17.12
0,0,7:17.12
1,0,7:17.12
2,0,7:17.12
-2,1,7:17.12
-1,1,7:17.12
0,1,7:17.12
1,1,7:17.12
-1,2,7:17.12
0,2,7:17.12
-1,-3,8:17.12
0,-3,8:17.12
-2,-2,8:17.12
-1,-2,8:17.12
0,-2,8:17.12
1,-2,8:17.12
-3,-1,8:17.12
-2,-1,8:17.12
-1,-1,8:17.12
0,-1,8:17.12
1,-1,8:17.12
2,-1,8:17.12
-3,0,8:17.12
-2,0,8:17.12
-1,0,8:17.12
0,0,8:17.12
1,0,8:17.12
2,0,8:17.12
-2,1,8:17.12
-1,1,8:17.12
0,1,8:17.12
1,1,8:17.12
-1,2,8:17.12
0,2,8:17.12
-1,-3,9:17.12
0,-3,9:17.12
-2,-2,9:17.12
-1,-2,9:17.12
0,-2,9:17.12
1,-2,9:17.12
-3,-1,9:17.12
-2,-1,9:17.12
-1,-1,9:17.12
0,-1,9:17.12
1,-1,9:17.12
2,-1,9:17.12
-3,0,9:17.12
-2,0,9:17.12
-1,0,9:17.12
0,0,9:17.12
1,0,9:17.12
2,0,9:17.12
-2,1,9:17.12
-1,1,9:17.12
0,1,9:17.12
1,1,9:17.12
-1,2,9:17.12
0,2,9:17.12
-1,-3,10:17.12
0,-3,10:17.12
-2,-2,10:17.12
-1,-2,10:17.12
0,-2,10:17.12
1,-2,10:17.12
-3,-1,10:17.12
-2,-1,10:17.12
-1,-1,10:17.12
0,-1,10:17.12
1,-1,10:17.12
2,-1,10:17.12
-3,0,10:17.12
-2,0,10:17.12
-1,0,10:17.12
0,0,10:17.12
1,0,10:17.12
2,0,10:17.12
-2,1,10:17.12
-1,1,10:17.12
0,1,10:17.12
1,1,10:17.12
-1,2,10:17.12
0,2,10:17.12
-1,-3,11:17.12
0,-3,11:17.12
-2,-2,11:17.12
-1,-2,11:17.12
0,-2,11:17.12
1,-2,11:17.12
-3,-1,11:17.12
-2,-1,11:17.12
-1,-1,11:17.12
0,-1,11:17.12
1,-1,11:17.12
2,-1,11:17.12
-3,0,11:17.12
-2,0,11:17.12
-1,0,11:17.12
0,0,11:17.12
1,0,11:17.12
2,0,11:17.12
-2,1,11:17.12
-1,1,11:17.12
0,1,11:17.12
1,1,11:17.12
-1,2,11:17.12
0,2,11:17.12
-1,-3,12:17.12
0,-3,12:17.12
-2,-2,12:17.12
-1,-2,12:17.12
0,-2,12:17.12
1,-2,12:17.12
-3,-1,12:17.12
-2,-1,12:17.12
-1,-1,12:17.12
0,-1,12:17.12
1,-1,12:17.12
2,-1,12:17.12
-3,0,12:17.12
-2,0,12:17.12
-1,0,12:17.12
0,0,12:17.12
1,0,12:17.12
2,0,12:17.12
-2,1,12:17.12
-1,1,12:17.12
0,1,12:17.12
1,1,12:17.12
-1,2,12:17.12
0,2,12:17.12
-1,3,12:17.12
0,3,12:17.12
-1,4,12:17.12
0,4,12:17.12
-1,-3,13:17.12
0,-3,13:17.12
-2,-2,13:17.12
-1,-2,13:17.12
0,-2,13:17.12
1,-2,13:17.12
-3,-1,13:17.12
-2,-1,13:17.12
-1,-1,13:17.12
0,-1,13:17.12
1,-1,13:17.12
2,-1,13:17.12
-3,0,13:17.12
-2,0,13:17.12
-1,0,13:17.12
0,0,13:17.12
1,0,13:17.12
2,0,13:17.12
-2,1,13:17.12
-1,1,13:17.12
0,1,13:17.12
1,1,13:17.12
-2,2,13:17.12
-1,2,13:17.12
0,2,13:17.12
1,2,13:17.12
-2,3,13:17.12
-1,3,13:17.12
0,3,13:17.12
1,3,13:17.12
-2,4,13:17.12
-1,4,13:17.12
0,4,13:17.12
1,4,13:17.12
-2,5,13:17.12
-1,5,13:17.12
0,5,13:17.12
-2,6,13:17.12
-1,6,13:17.12
0,6,13:18.0
-2,7,13:18.0
-1,7,13:18.0
0,7,13:18.0
-2,8,13:18.0
-1,8,13:18.0
0,8,13:18.0
-1,-3,14:17.12
0,-3,14:17.12
-2,-2,14:17.12
-1,-2,14:17.12
0,-2,14:17.12
1,-2,14:17.12
3,-2,14:18.0
4,-2,14:18.0
5,-2,14:18.0
6,-2,14:18.0
7,-2,14:18.0
-3,-1,14:17.12
-2,-1,14:17.12
-1,-1,14:17.12
0,-1,14:17.12
1,-1,14:17.12
2,-1,14:17.12
3,-1,14:18.0
4,-1,14:18.0
5,-1,14:18.0
6,-1,14:18.0
7,-1,14:18.0
8,-1,14:18.0
-3,0,14:17.12
-2,0,14:17.12
-1,0,14:17.12
0,0,14:17.12
1,0,14:17.12
2,0,14:17.12
3,0,14:18.0
4,0,14:18.0
5,0,14:18.0
6,0,14:18.0
7,0,14:18.0
8,0,14:18.0
-2,1,14:17.12
-1,1,14:17.12
0,1,14:17.12
1,1,14:17.12
3,1,14:18.0
4,1,14:18.0
5,1,14:18.0
6,1,14:18.0
7,1,14:18.0
8,1,14:18.0
-2,2,14:17.12
-1,2,14:17.12
0,2,14:17.12
1,2,14:17.12
5,2,14:18.0
6,2,14:18.0
7,2,14:18.0
-2,3,14:17.12
-1,3,14:17.12
0,3,14:17.12
1,3,14:17.12
-3,4,14:17.12
-2,4,14:17.12
-1,4,14:17.12
0,4,14:17.12
1,4,14:18.0
-3,5,14:17.12
-2,5,14:17.12
-1,5,14:17.12
0,5,14:18.0
1,5,14:18.0
2,5,14:18.0
-3,6,14:18.0
-2,6,14:18.0
-1,6,14:18.0
0,6,14:18.0
1,6,14:18.0
2,6,14:18.0
-3,7,14:18.0
-2,7,14:18.0
-1,7,14:18.0
0,7,14:18.0
1,7,14:18.0
2,7,14:18.0
-2,8,14:18.0
-1,8,14:18.0
0,8,14:17.8
1,8,14:18.0
2,8,14:18.0
-3,9,14:18.0
-1,9,14:18.0
0,9,14:18.0
1,9,14:18.0
-1,10,14:18.0
0,10,14:18.0
-1,-3,15:17.12
0,-3,15:17.12
4,-3,15:18.0
5,-3,15:18.0
6,-3,15:18.0
7,-3,15:18.0
-2,-2,15:17.12
-1,-2,15:17.12
0,-2,15:17.12
1,-2,15:17.12
2,-2,15:18.0
3,-2,15:18.0
4,-2,15:18.0
5,-2,15:18.0
6,-2,15:18.0
7,-2,15:18.0
8,-2,15:18.0
-3,-1,15:17.12
-2,-1,15:17.12
-1,-1,15:17.12
0,-1,15:17.12
1,-1,15:17.12
2,-1,15:17.12
3,-1,15:18.0
4,-1,15:18.0
5,-1,15:18.0
6,-1,15:18.0
7,-1,15:18.0
8,-1,15:18.0
9,-1,15:18.0
-3,0,15:17.12
-2,0,15:17.12
-1,0,15:17.12
0,0,15:17.12
1,0,15:17.12
2,0,15:17.12
4,0,15:18.0
5,0,15:18.0
6,0,15:18.0
7,0,15:18.0
8,0,15:18.0
9,0,15:18.0
-2,1,15:17.12
-1,1,15:17.12
0,1,15:17.12
1,1,15:17.12
4,1,15:18.0
5,1,15:18.0
6,1,15:18.0
7,1,15:18.0
8,1,15:18.0
9,1,15:18.0
-2,2,15:18.0
-1,2,15:17.12
0,2,15:17.12
1,2,15:18.0
3,2,15:18.0
4,2,15:18.0
5,2,15:18.0
6,2,15:18.0
7,2,15:17.8
8,2,15:18.0
9,2,15:18.0
-3,3,15:18.0
-1,3,15:18.0
2,3,15:18.0
6,3,15:18.0
7,3,15:18.0
8,3,15:18.0
-4,4,15:18.0
-3,4,15:18.0
-2,4,15:18.0
-1,4,15:18.0
0,4,15:18.0
1,4,15:18.0
2,4,15:18.0
-4,5,15:18.0
-3,5,15:18.0
-2,5,15:18.0
-1,5,15:18.0
0,5,15:18.0
1,5,15:18.0
2,5,15:18.0
-4,6,15:18.0
-3,6,15:17.4
-2,6,15:18.0
-1,6,15:18.0
0,6,15:18.0
1,6,15:17.4
2,6,15:18.0
-4,7,15:18.0
-3,7,15:18.0
-2,7,15:18.0
-1,7,15:18.0
0,7,15:18.0
1,7,15:18.0
2,7,15:18.0
-4,8,15:18.0
-3,8,15:18.0
-2,8,15:18.0
-1,8,15:18.0
0,8,15:18.0
1,8,15:18.0
2,8,15:18.0
-3,9,15:18.0
-2,9,15:18.0
-1,9,15:18.0
0,9,15:18.0
1,9,15:18.0
2,9,15:18.0
-3,10,15:18.0
-2,10,15:18.0
-1,10,15:18.0
0,10,15:18.0
1,10,15:18.0
2,10,15:18.0
3,-4,16:18.0
4,-4,16:18.0
5,-4,16:18.0
-1,-3,16:17.12
0,-3,16:17.12
1,-3,16:18.0
2,-3,16:18.0
3,-3,16:18.0
4,-3,16:18.0
5,-3,16:18.0
6,-3,16:18.0
7,-3,16:18.0
8,-3,16:18.0
9,-3,16:18.0
-3,-2,16:17.12
-2,-2,16:17.12
-1,-2,16:17.12
0,-2,16:17.12
1,-2,16:17.12
2,-2,16:18.0
3,-2,16:18.0
4,-2,16:18.0
5,-2,16:18.0
6,-2,16:17.8
7,-2,16:18.0
8,-2,16:18.0
9,-2,16:18.0
10,-2,16:18.0
-4,-1,16:17.12
-3,-1,16:17.12
-2,-1,16:17.12
-1,-1,16:17.12
0,-1,16:17.12
1,-1,16:17.12
2,-1,16:17.12
4,-1,16:18.0
5,-1,16:18.0
6,-1,16:18.0
7,-1,16:18.0
8,-1,16:18.0
9,-1,16:17.0
10,-1,16:18.0
-4,0,16:17.12
-3,0,16:17.12
-2,0,16:17.12
-1,0,16:17.12
0,0,16:17.12
1,0,16:17.12
2,0,16:17.12
3,0,16:18.0
4,0,16:18.0
5,0,16:18.0
6,0,16:18.0
7,0,16:18.0
8,0,16:18.0
9,0,16:18.0
10,0,16:18.0
-3,1,16:17.12
-2,1,16:17.12
-1,1,16:17.12
0,1,16:17.12
1,1,16:17.12
2,1,16:18.0
4,1,16:18.0
5,1,16:18.0
6,1,16:18.0
7,1,16:18.0
8,1,16:18.0
9,1,16:18.0
10,1,16:18.0
-2,2,16:18.0
-1,2,16:17.12
0,2,16:17.12
1,2,16:18.0
2,2,16:18.0
3,2,16:18.0
4,2,16:17.8
5,2,16:18.0
6,2,16:18.0
7,2,16:18.0
8,2,16:18.0
9,2,16:18.0
-4,3,16:18.0
-3,3,16:18.0
-2,3,16:18.0
-1,3,16:18.0
0,3,16:18.0
2,3,16:18.0
3,3,16:18.0
4,3,16:18.0
5,3,16:18.0
6,3,16:18.0
7,3,16:18.0
8,3,16:18.0
-4,4,16:18.0
-3,4,16:18.0
-2,4,16:18.0
-1,4,16:18.0
0,4,16:18.0
1,4,16:18.0
2,4,16:18.0
3,4,16:18.0
-4,5,16:18.0
-3,5,16:18.0
-2,5,16:18.0
-1,5,16:18.0
0,5,16:18.0
1,5,16:18.0
2,5,16:18.0
3,5,16:18.0
-4,6,16:18.0
-3,6,16:18.0
-2,6,16:18.0
-1,6,16:18.0
0,6,16:18.0
1,6,16:18.0
2,6,16:18.0
3,6,16:18.0
-5,7,16:18.0
-4,7,16:18.0
-3,7,16:18.0
-2,7,16:18.0
-1,7,16:18.0
0,7,16:18.0
1,7,16:18.0
2,7,16:18.0
3,7,16:18.0
-5,8,16:18.0
-4,8,16:18.0
-3,8,16:18.0
-2,8,16:18.0
-1,8,16:18.0
0,8,16:18.0
1,8,16:18.0
2,8,16:18.0
3,8,16:18.0
-4,9,16:18.0
-3,9,16:18.0
-2,9,16:18.0
-1,9,16:18.0
0,9,16:18.0
1,9,16:17.8
2,9,16:18.0
-3,10,16:18.0
-2,10,16:18.0
-1,10,16:18.0
0,10,16:18.0
1,10,16:18.0
2,10,16:18.0
-2,11,16:18.0
-1,11,16:18.0
1,-4,17:18.0
2,-4,17:18.0
3,-4,17:18.0
4,-4,17:18.0
5,-4,17:18.0
6,-4,17:18.0
7,-4,17:18.0
-6,-3,17:18.0
-5,-3,17:18.0
-1,-3,17:17.12
0,-3,17:17.12
1,-3,17:18.0
2,-3,17:18.0
3,-3,17:18.0
4,-3,17:18.0
5,-3,17:18.0
6,-3,17:18.0
7,-3,17:18.0
8,-3,17:18.0
9,-3,17:18.0
-7,-2,17:18.0
-6,-2,17:18.0
-5,-2,17:18.0
-4,-2,17:17.12
-3,-2,17:17.12
-2,-2,17:17.12
-1,-2,17:17.12
0,-2,17:17.12
1,-2,17:17.12
2,-2,17:18.0
3,-2,17:18.0
4,-2,17:18.0
5,-2,17:18.0
6,-2,17:18.0
7,-2,17:18.0
8,-2,17:18.0
9,-2,17:18.0
10,-2,17:18.0
-8,-1,17:18.0
-7,-1,17:18.0
-6,-1,17:18.0
-5,-1,17:17.12
-4,-1,17:17.12
-3,-1,17:17.12
-2,-1,17:17.12
-1,-1,17:17.12
0,-1,17:17.12
1,-1,17:17.12
2,-1,17:17.12
3,-1,17:18.0
4,-1,17:18.0
5,-1,17:18.0
6,-1,17:18.0
7,-1,17:18.0
8,-1,17:18.0
9,-1,17:18.0
10,-1,17:18.0
11,-1,17:18.0
-8,0,17:18.0
-7,0,17:18.0
-6,0,17:18.0
-5,0,17:17.12
-4,0,17:17.12
-3,0,17:17.12
-2,0,17:17.12
-1,0,17:17.12
0,0,17:17.12
1,0,17:17.12
2,0,17:17.12
3,0,17:18.0
4,0,17:18.0
5,0,17:18.0
6,0,17:18.0
7,0,17:18.0
8,0,17:18.0
9,0,17:18.0
10,0,17:18.0
11,0,17:18.0
-7,1,17:18.0
-6,1,17:18.0
-5,1,17:18.0
-4,1,17:18.0
-3,1,17:17.12
-2,1,17:17.12
-1,1,17:17.12
0,1,17:17.12
1,1,17:17.12
2,1,17:18.0
3,1,17:18.0
4,1,17:18.0
5,1,17:18.0
6,1,17:18.0
7,1,17:18.0
8,1,17:18.0
9,1,17:18.0
10,1,17:18.0
-3,2,17:18.0
-2,2,17:18.0
-1,2,17:17.12
0,2,17:17.12
1,2,17:18.0
2,2,17:18.0
3,2,17:18.0
4,2,17:18.0
5,2,17:18.0
6,2,17:18.0
7,2,17:18.0
8,2,17:18.0
9,2,17:18.0
-4,3,17:18.0
-3,3,17:17.4
-2,3,17:18.0
-1,3,17:17.8
0,3,17:18.0
1,3,17:18.0
2,3,17:18.0
3,3,17:18.0
4,3,17:18.0
5,3,17:18.0
6,3,17:18.0
7,3,17:18.0
8,3,17:18.0
-4,4,17:18.0
-3,4,17:18.0
-2,4,17:18.0
-1,4,17:17.8
0,4,17:18.0
1,4,17:18.0
2,4,17:18.0
3,4,17:18.0
4,4,17:18.0
5,4,17:18.0
6,4,17:18.0
7,4,17:18.0
-4,5,17:18.0
-3,5,17:18.0
-2,5,17:18.0
-1,5,17:17.8
0,5,17:18.0
1,5,17:18.0
2,5,17:18.0
3,5,17:18.0
-5,6,17:18.0
-4,6,17:18.0
-3,6,17:18.0
-2,6,17:18.0
-1,6,17:17.8
0,6,17:18.0
1,6,17:18.0
2,6,17:18.0
3,6,17:18.0
-5,7,17:18.0
-4,7,17:18.0
-3,7,17:18.0
-2,7,17:18.0
-1,7,17:17.8
0,7,17:18.0
1,7,17:18.0
2,7,17:18.0
3,7,17:18.0
-5,8,17:18.0
-4,8,17:17.4
-3,8,17:18.0
-2,8,17:18.0
-1,8,17:18.0
0,8,17:18.0
1,8,17:18.0
2,8,17:18.0
3,8,17:18.0
-4,9,17:18.0
-3,9,17:18.0
-2,9,17:18.0
-1,9,17:18.0
0,9,17:18.0
1,9,17:18.0
-4,10,17:18.0
-3,10,17:18.0
-2,10,17:18.0
-1,10,17:18.0
0,10,17:18.0
1,10,17:18.0
2,10,17:18.0
-2,11,17:18.0
-1,11,17:18.0
0,11,17:18.0
0,-10,18:18.0
-1,-9,18:18.0
0,-9,18:18.0
1,-9,18:18.0
-2,-8,18:18.0
-1,-8,18:18.0
0,-8,18:18.0
1,-8,18:18.0
2,-8,18:18.0
-2,-7,18:18.0
-1,-7,18:18.0
0,-7,18:18.0
1,-7,18:18.0
2,-7,18:18.0
-2,-6,18:18.0
-1,-6,18:17.12
0,-6,18:17.12
1,-6,18:18.0
2,-6,18:18.0
3,-6,18:18.0
-2,-5,18:18.0
-1,-5,18:17.12
0,-5,18:17.12
1,-5,18:18.0
2,-5,18:18.0
3,-5,18:18.0
4,-5,18:18.0
-2,-4,18:18.0
-1,-4,18:17.12
0,-4,18:17.12
1,-4,18:18.0
2,-4,18:18.0
3,-4,18:17.8
4,-4,18:18.0
5,-4,18:18.0
6,-4,18:18.0
7,-4,18:18.0
8,-4,18:18.0
-8,-3,18:18.0
-7,-3,18:18.0
-6,-3,18:18.0
-5,-3,18:18.0
-4,-3,18:18.0
-2,-3,18:18.0
-1,-3,18:17.12
0,-3,18:17.12
1,-3,18:18.0
2,-3,18:18.0
3,-3,18:18.0
4,-3,18:18.0
5,-3,18:18.0
6,-3,18:18.0
7,-3,18:18.0
8,-3,18:18.0
9,-3,18:18.0
-10,-2,18:18.0
-9,-2,18:18.0
-8,-2,18:18.0
-7,-2,18:18.0
-6,-2,18:18.0
-5,-2,18:18.0
-4,-2,18:18.0
-3,-2,18:18.0
-2,-2,18:17.12
-1,-2,18:17.12
0,-2,18:17.12
1,-2,18:17.12
2,-2,18:18.0
3,-2,18:18.0
4,-2,18:18.0
5,-2,18:18.0
6,-2,18:18.0
7,-2,18:18.0
8,-2,18:18.0
9,-2,18:18.0
10,-2,18:18.0
-10,-1,18:18.0
-9,-1,18:18.0
-8,-1,18:18.0
-7,-1,18:18.0
-6,-1,18:18.0
-5,-1,18:18.0
-4,-1,18:18.0
-3,-1,18:17.12
-2,-1,18:17.12
-1,-1,18:17.12
0,-1,18:17.12
1,-1,18:17.12
2,-1,18:17.12
3,-1,18:18.0
4,-1,18:18.0
5,-1,18:18.0
6,-1,18:18.0
7,-1,18:18.0
8,-1,18:18.0
9,-1,18:18.0
10,-1,18:18.0
11,-1,18:18.0
-10,0,18:18.0
-9,0,18:18.0
-8,0,18:18.0
-7,0,18:17.4
-6,0,18:18.0
-5,0,18:18.0
-4,0,18:18.0
-3,0,18:17.12
-2,0,18:17.12
-1,0,18:17.12
0,0,18:17.12
1,0,18:17.12
2,0,18:17.12
3,0,18:17.4
4,0,18:17.4
5,0,18:17.4
6,0,18:17.4
7,0,18:17.4
8,0,18:18.0
9,0,18:18.0
10,0,18:18.0
11,0,18:18.0
-9,1,18:18.0
-8,1,18:18.0
-7,1,18:18.0
-6,1,18:18.0
-5,1,18:18.0
-4,1,18:18.0
-3,1,18:18.0
-2,1,18:17.12
-1,1,18:17.12
0,1,18:17.12
1,1,18:17.12
2,1,18:18.0
3,1,18:18.0
4,1,18:18.0
5,1,18:18.0
6,1,18:18.0
7,1,18:18.0
8,1,18:18.0
9,1,18:18.0
10,1,18:18.0
-9,2,18:18.0
-8,2,18:18.0
-7,2,18:18.0
-4,2,18:18.0
-3,2,18:18.0
-2,2,18:18.0
-1,2,18:17.12
0,2,18:17.12
1,2,18:18.0
2,2,18:18.0
3,2,18:18.0
4,2,18:18.0
5,2,18:18.0
6,2,18:18.0
7,2,18:18.0
8,2,18:18.0
9,2,18:18.0
-4,3,18:18.0
-3,3,18:18.0
-2,3,18:18.0
-1,3,18:18.0
0,3,18:18.0
1,3,18:18.0
2,3,18:18.0
3,3,18:18.0
4,3,18:18.0
5,3,18:18.0
6,3,18:18.0
7,3,18:18.0
8,3,18:18.0
9,3,18:18.0
-4,4,18:18.0
-3,4,18:18.0
-2,4,18:18.0
-1,4,18:18.0
0,4,18:18.0
1,4,18:18.0
2,4,18:18.0
3,4,18:18.0
4,4,18:18.0
5,4,18:18.0
6,4,18:18.0
7,4,18:18.0
8,4,18:18.0
-4,5,18:18.0
-3,5,18:18.0
-2,5,18:18.0
-1,5,18:18.0
0,5,18:18.0
1,5,18:18.0
2,5,18:18.0
3,5,18:18.0
-5,6,18:18.0
-4,6,18:18.0
-3,6,18:18.0
-2,6,18:18.0
-1,6,18:18.0
0,6,18:18.0
1,6,18:18.0
2,6,18:18.0
3,6,18:18.0
-5,7,18:18.0
-4,7,18:18.0
-3,7,18:18.0
-2,7,18:18.0
-1,7,18:18.0
0,7,18:18.0
1,7,18:18.0
2,7,18:18.0
3,7,18:18.0
-4,8,18:18.0
-3,8,18:18.0
-2,8,18:18.0
-1,8,18:18.0
0,8,18:18.0
1,8,18:18.0
3,8,18:18.0
-4,9,18:18.0
-3,9,18:18.0
-2,9,18:18.0
-1,9,18:18.0
0,9,18:18.0
1,9,18:18.0
2,9,18:18.0
-4,10,18:18.0
-3,10,18:18.0
-2,10,18:18.0
-1,10,18:17.0
0,10,18:18.0
1,10,18:18.0
2,10,18:18.0
-1,11,18:18.0
-2,-10,19:18.0
-1,-10,19:18.0
0,-10,19:18.0
1,-10,19:18.0
2,-10,19:18.0
-3,-9,19:18.0
-2,-9,19:18.0
-1,-9,19:18.0
0,-9,19:18.0
1,-9,19:17.8
2,-9,19:18.0
3,-9,19:18.0
-3,-8,19:18.0
-2,-8,19:18.0
-1,-8,19:18.0
0,-8,19:18.0
1,-8,19:18.0
2,-8,19:18.0
3,-8,19:18.0
-3,-7,19:18.0
-2,-7,19:18.0
-1,-7,19:18.0
0,-7,19:18.0
1,-7,19:18.0
2,-7,19:18.0
3,-7,19:18.0
-3,-6,19:18.0
-2,-6,19:18.0
-1,-6,19:18.0
0,-6,19:18.0
1,-6,19:18.0
2,-6,19:18.0
3,-6,19:18.0
4,-6,19:18.0
-2,-5,19:18.0
-1,-5,19:18.0
0,-5,19:18.0
1,-5,19:18.0
2,-5,19:18.0
3,-5,19:18.0
4,-5,19:18.0
5,-5,19:18.0
-8,-4,19:18.0
-7,-4,19:18.0
-6,-4,19:18.0
-2,-4,19:18.0
-1,-4,19:18.0
0,-4,19:18.0
1,-4,19:18.0
2,-4,19:18.0
3,-4,19:18.0
4,-4,19:18.0
5,-4,19:18.0
6,-4,19:18.0
7,-4,19:18.0
8,-4,19:18.0
-10,-3,19:18.0
-9,-3,19:18.0
-8,-3,19:18.0
-7,-3,19:17.8
-6,-3,19:18.0
-5,-3,19:18.0
-4,-3,19:18.0
-3,-3,19:18.0
-2,-3,19:18.0
-1,-3,19:17.12
0,-3,19:17.12
1,-3,19:18.0
2,-3,19:18.0
3,-3,19:18.0
4,-3,19:18.0
5,-3,19:18.0
6,-3,19:17.8
7,-3,19:18.0
8,-3,19:18.0
9,-3,19:18.0
-11,-2,19:18.0
-10,-2,19:18.0
-9,-2,19:18.0
-8,-2,19:18.0
-7,-2,19:18.0
-6,-2,19:18.0
-5,-2,19:18.0
-4,-2,19:18.0
-3,-2,19:18.0
-2,-2,19:17.12
-1,-2,19:17.12
0,-2,19:17.12
1,-2,19:17.12
2,-2,19:18.0
3,-2,19:18.0
4,-2,19:18.0
5,-2,19:18.0
6,-2,19:18.0
7,-2,19:18.0
8,-2,19:18.0
9,-2,19:18.0
-11,-1,19:18.0
-10,-1,19:18.0
-9,-1,19:18.0
-8,-1,19:18.0
-7,-1,19:18.0
-6,-1,19:18.0
-5,-1,19:18.0
-4,-1,19:18.0
-3,-1,19:17.12
-2,-1,19:17.12
-1,-1,19:17.12
0,-1,19:17.12
1,-1,19:17.12
2,-1,19:17.12
3,-1,19:18.0
4,-1,19:18.0
5,-1,19:18.0
6,-1,19:18.0
7,-1,19:18.0
8,-1,19:18.0
9,-1,19:18.0
10,-1,19:18.0
-11,0,19:18.0
-10,0,19:18.0
-9,0,19:18.0
-8,0,19:18.0
-7,0,19:18.0
-6,0,19:18.0
-5,0,19:18.0
-4,0,19:18.0
-3,0,19:17.12
-2,0,19:17.12
-1,0,19:17.12
0,0,19:17.12
1,0,19:17.12
2,0,19:17.12
3,0,19:18.0
4,0,19:18.0
5,0,19:18.0
6,0,19:18.0
7,0,19:18.0
8,0,19:18.0
9,0,19:18.0
10,0,19:18.0
-11,1,19:18.0
-10,1,19:18.0
-9,1,19:18.0
-8,1,19:18.0
-7,1,19:18.0
-6,1,19:18.0
-5,1,19:18.0
-4,1,19:18.0
-3,1,19:18.0
-2,1,19:17.12
-1,1,19:17.12
0,1,19:17.12
1,1,19:17.12
2,1,19:18.0
3,1,19:18.0
4,1,19:18.0
5,1,19:18.0
6,1,19:18.0
7,1,19:18.0
8,1,19:18.0
9,1,19:18.0
10,1,19:18.0
-10,2,19:18.0
-9,2,19:18.0
-8,2,19:18.0
-7,2,19:18.0
-6,2,19:18.0
-5,2,19:18.0
-4,2,19:18.0
-3,2,19:18.0
-2,2,19:18.0
-1,2,19:17.12
0,2,19:17.12
1,2,19:18.0
2,2,19:18.0
3,2,19:18.0
4,2,19:18.0
5,2,19:18.0
6,2,19:18.0
7,2,19:18.0
8,2,19:18.0
9,2,19:18.0
-4,3,19:18.0
-3,3,19:18.0
-2,3,19:18.0
-1,3,19:18.0
0,3,19:18.0
1,3,19:18.0
2,3,19:18.0
3,3,19:18.0
4,3,19:18.0
5,3,19:18.0
6,3,19:17.8
7,3,19:18.0
8,3,19:18.0
9,3,19:18.0
-3,4,19:18.0
-2,4,19:18.0
-1,4,19:18.0
0,4,19:18.0
1,4,19:18.0
2,4,19:18.0
3,4,19:18.0
4,4,19:18.0
5,4,19:18.0
6,4,19:18.0
7,4,19:18.0
8,4,19:18.0
-3,5,19:18.0
-2,5,19:18.0
-1,5,19:18.0
0,5,19:18.0
1,5,19:18.0
2,5,19:18.0
3,5,19:17.0
4,5,19:18.0
-4,6,19:18.0
-3,6,19:18.0
-2,6,19:18.0
-1,6,19:18.0
0,6,19:18.0
1,6,19:18.0
2,6,19:18.0
3,6,19:18.0
-4,7,19:18.0
-3,7,19:18.0
-2,7,19:18.0
-1,7,19:18.0
0,7,19:18.0
1,7,19:18.0
3,7,19:18.0
-4,8,19:18.0
-3,8,19:18.0
-2,8,19:18.0
-1,8,19:18.0
0,8,19:18.0
1,8,19:17.0
2,8,19:18.0
-4,9,19:18.0
-3,9,19:18.0
-2,9,19:18.0
-1,9,19:18.0
0,9,19:18.0
1,9,19:18.0
-2,10,19:18.0
-1,10,19:18.0
0,10,19:18.0
1,10,19:18.0
-2,-11,20:18.0
-1,-11,20:18.0
0,-11,20:18.0
1,-11,20:18.0
2,-11,20:18.0
-3,-10,20:18.0
-2,-10,20:17.0
-1,-10,20:18.0
0,-10,20:18.0
1,-10,20:18.0
2,-10,20:18.0
3,-10,20:18.0
-3,-9,20:18.0
-2,-9,20:18.0
-1,-9,20:18.0
0,-9,20:18.0
1,-9,20:18.0
2,-9,20:18.0
3,-9,20:18.0
-4,-8,20:18.0
-3,-8,20:18.0
-2,-8,20:18.0
-1,-8,20:18.0
0,-8,20:18.0
1,-8,20:18.0
2,-8,20:18.0
3,-8,20:17.4
4,-8,20:18.0
-4,-7,20:18.0
-3,-7,20:17.4
-2,-7,20:18.0
-1,-7,20:18.0
0,-7,20:18.0
1,-7,20:18.0
2,-7,20:18.0
3,-7,20:18.0
4,-7,20:18.0
-4,-6,20:18.0
-3,-6,20:18.0
-2,-6,20:18.0
-1,-6,20:18.0
0,-6,20:18.0
1,-6,20:18.0
2,-6,20:18.0
3,-6,20:18.0
4,-6,20:18.0
5,-6,20:18.0
-9,-5,20:18.0
-8,-5,20:18.0
-3,-5,20:18.0
-2,-5,20:18.0
-1,-5,20:18.0
0,-5,20:18.0
1,-5,20:18.0
2,-5,20:18.0
3,-5,20:18.0
4,-5,20:18.0
5,-5,20:18.0
-9,-4,20:18.0
-8,-4,20:18.0
-7,-4,20:18.0
-6,-4,20:18.0
-5,-4,20:18.0
-3,-4,20:18.0
-2,-4,20:18.0
-1,-4,20:18.0
0,-4,20:18.0
1,-4,20:18.0
2,-4,20:18.0
3,-4,20:18.0
4,-4,20:18.0
5,-4,20:18.0
6,-4,20:18.0
7,-4,20:18.0
-11,-3,20:18.0
-10,-3,20:18.0
-9,-3,20:17.4
-8,-3,20:18.0
-7,-3,20:18.0
-6,-3,20:18.0
-5,-3,20:18.0
-4,-3,20:18.0
-3,-3,20:18.0
-2,-3,20:18.0
-1,-3,20:17.12
0,-3,20:17.12
1,-3,20:18.0
2,-3,20:18.0
3,-3,20:18.0
4,-3,20:18.0
5,-3,20:18.0
6,-3,20:18.0
7,-3,20:18.0
8,-3,20:18.0
9,-3,20:18.0
-11,-2,20:18.0
-10,-2,20:17.4
-9,-2,20:18.0
-8,-2,20:18.0
-7,-2,20:18.0
-6,-2,20:18.0
-5,-2,20:18.0
-4,-2,20:18.0
-3,-2,20:18.0
-2,-2,20:17.12
-1,-2,20:17.12
0,-2,20:17.12
1,-2,20:17.12
2,-2,20:18.0
3,-2,20:18.0
4,-2,20:18.0
5,-2,20:18.0
6,-2,20:18.0
7,-2,20:18.0
8,-2,20:17.4
9,-2,20:18.0
-12,-1,20:18.0
-11,-1,20:18.0
-10,-1,20:18.0
-9,-1,20:18.0
-8,-1,20:18.0
-7,-1,20:18.0
-6,-1,20:18.0
-5,-1,20:18.0
-4,-1,20:18.0
-3,-1,20:17.12
-2,-1,20:17.12
-1,-1,20:17.12
0,-1,20:17.12
1,-1,20:17.12
2,-1,20:17.12
3,-1,20:18.0
4,-1,20:18.0
5,-1,20:18.0
6,-1,20:18.0
7,-1,20:18.0
8,-1,20:18.0
9,-1,20:18.0
-12,0,20:18.0
-11,0,20:18.0
-10,0,20:18.0
-9,0,20:18.0
-8,0,20:18.0
-7,0,20:18.0
-6,0,20:18.0
-5,0,20:18.0
-4,0,20:18.0
-3,0,20:17.12
-2,0,20:17.12
-1,0,20:17.12
0,0,20:17.12
1,0,20:17.12
2,0,20:17.12
3,0,20:18.0
4,0,20:18.0
5,0,20:18.0
6,0,20:18.0
7,0,20:18.0
8,0,20:18.0
9,0,20:18.0
10,0,20:18.0
-11,1,20:18.0
-10,1,20:18.0
-9,1,20:18.0
-8,1,20:18.0
-7,1,20:18.0
-6,1,20:18.0
-5,1,20:18.0
-4,1,20:18.0
-3,1,20:18.0
-2,1,20:17.12
-1,1,20:17.12
0,1,20:17.12
1,1,20:17.12
2,1,20:18.0
3,1,20:18.0
4,1,20:18.0
5,1,20:18.0
6,1,20:18.0
7,1,20:18.0
8,1,20:18.0
9,1,20:18.0
10,1,20:18.0
-10,2,20:18.0
-9,2,20:17.8
-8,2,20:18.0
-7,2,20:18.0
-6,2,20:18.0
-5,2,20:18.0
-4,2,20:18.0
-3,2,20:18.0
-2,2,20:18.0
-1,2,20:17.12
0,2,20:17.12
1,2,20:18.0
2,2,20:18.0
3,2,20:18.0
4,2,20:18.0
5,2,20:18.0
6,2,20:18.0
7,2,20:18.0
8,2,20:18.0
9,2,20:18.0
10,2,20:18.0
-9,3,20:18.0
-8,3,20:18.0
-7,3,20:18.0
-6,3,20:18.0
-4,3,20:18.0
-3,3,20:18.0
-2,3,20:18.0
-1,3,20:18.0
0,3,20:18.0
1,3,20:18.0
2,3,20:18.0
3,3,20:18.0
4,3,20:18.0
5,3,20:18.0
6,3,20:18.0
7,3,20:18.0
8,3,20:18.0
9,3,20:18.0
-3,4,20:18.0
-2,4,20:18.0
-1,4,20:18.0
0,4,20:18.0
1,4,20:18.0
2,4,20:18.0
3,4,20:18.0
4,4,20:18.0
5,4,20:18.0
6,4,20:18.0
7,4,20:18.0
-2,5,20:18.0
-1,5,20:18.0
0,5,20:18.0
1,5,20:18.0
2,5,20:18.0
3,5,20:18.0
4,5,20:18.0
5,5,20:18.0
-2,6,20:18.0
-1,6,20:18.0
0,6,20:18.0
1,6,20:18.0
2,6,20:18.0
3,6,20:18.0
-2,7,20:18.0
-1,7,20:18.0
0,7,20:18.0
1,7,20:18.0
2,7,20:18.0
-3,8,20:18.0
-2,8,20:18.0
-1,8,20:18.0
0,8,20:18.0
1,8,20:18.0
2,8,20:18.0
-2,9,20:18.0
-1,9,20:18.0
0,9,20:18.0
1,9,20:18.0
-2,10,20:18.0
-1,10,20:18.0
0,10,20:18.0
1,-12,21:18.0
-3,-11,21:18.0
-2,-11,21:18.0
-1,-11,21:18.0
0,-11,21:18.0
1,-11,21:18.0
2,-11,21:18.0
3,-11,21:18.0
-3,-10,21:18.0
-2,-10,21:18.0
-1,-10,21:18.0
0,-10,21:18.0
1,-10,21:18.0
2,-10,21:18.0
3,-10,21:18.0
-4,-9,21:18.0
-3,-9,21:18.0
-2,-9,21:18.0
-1,-9,21:18.0
0,-9,21:18.0
1,-9,21:18.0
2,-9,21:18.0
3,-9,21:18.0
4,-9,21:18.0
-4,-8,21:18.0
-3,-8,21:18.0
-2,-8,21:18.0
-1,-8,21:18.0
0,-8,21:18.0
1,-8,21:18.0
2,-8,21:18.0
3,-8,21:18.0
4,-8,21:18.0
-4,-7,21:18.0
-3,-7,21:18.0
-2,-7,21:18.0
-1,-7,21:18.0
0,-7,21:18.0
1,-7,21:18.0
2,-7,21:18.0
3,-7,21:18.0
4,-7,21:18.0
5,-7,21:18.0
-4,-6,21:18.0
-3,-6,21:18.0
-2,-6,21:18.0
-1,-6,21:18.0
0,-6,21:18.0
1,-6,21:18.0
2,-6,21:18.0
3,-6,21:18.0
4,-6,21:18.0
5,-6,21:18.0
-9,-5,21:18.0
-8,-5,21:18.0
-7,-5,21:18.0
-4,-5,21:18.0
-3,-5,21:18.0
-2,-5,21:18.0
-1,-5,21:18.0
0,-5,21:18.0
1,-5,21:18.0
2,-5,21:18.0
3,-5,21:18.0
5,-5,21:18.0
6,-5,21:18.0
-10,-4,21:18.0
-9,-4,21:18.0
-8,-4,21:18.0
-7,-4,21:18.0
-6,-4,21:18.0
-5,-4,21:18.0
-4,-4,21:18.0
-3,-4,21:18.0
-2,-4,21:18.0
-1,-4,21:18.0
0,-4,21:18.0
1,-4,21:18.0
2,-4,21:18.0
3,-4,21:18.0
4,-4,21:18.0
5,-4,21:18.0
6,-4,21:18.0
-11,-3,21:18.0
-10,-3,21:18.0
-9,-3,21:18.0
-8,-3,21:18.0
-7,-3,21:18.0
-6,-3,21:18.0
-5,-3,21:18.0
-4,-3,21:18.0
-3,-3,21:18.0
-2,-3,21:18.0
-1,-3,21:17.12
0,-3,21:17.12
1,-3,21:18.0
2,-3,21:18.0
3,-3,21:18.0
4,-3,21:18.0
5,-3,21:18.0
6,-3,21:18.0
7,-3,21:18.0
8,-3,21:18.0
-12,-2,21:18.0
-11,-2,21:18.0
-10,-2,21:18.0
-9,-2,21:18.0
-8,-2,21:18.0
-7,-2,21:18.0
-6,-2,21:18.0
-5,-2,21:18.0
-4,-2,21:18.0
-3,-2,21:18.0
-2,-2,21:17.12
-1,-2,21:17.12
0,-2,21:17.12
1,-2,21:17.12
2,-2,21:18.0
3,-2,21:18.0
4,-2,21:18.0
5,-2,21:18.0
6,-2,21:18.0
7,-2,21:18.0
8,-2,21:18.0
9,-2,21:18.0
-12,-1,21:18.0
-11,-1,21:17.4
-10,-1,21:18.0
-9,-1,21:18.0
-8,-1,21:17.4
-7,-1,21:17.4
-6,-1,21:17.4
-5,-1,21:17.4
-4,-1,21:17.4
-3,-1,21:17.12
-2,-1,21:17.12
-1,-1,21:17.12
0,-1,21:17.12
1,-1,21:17.12
2,-1,21:17.12
3,-1,21:18.0
4,-1,21:18.0
5,-1,21:18.0
6,-1,21:18.0
7,-1,21:18.0
8,-1,21:18.0
9,-1,21:18.0
-12,0,21:18.0
-11,0,21:18.0
-10,0,21:18.0
-9,0,21:18.0
-8,0,21:18.0
-7,0,21:18.0
-6,0,21:18.0
-5,0,21:18.0
-4,0,21:18.0
-3,0,21:17.12
-2,0,21:17.12
-1,0,21:17.12
0,0,21:17.12
1,0,21:17.12
2,0,21:17.12
3,0,21:18.0
4,0,21:18.0
5,0,21:18.0
6,0,21:18.0
7,0,21:18.0
8,0,21:18.0
9,0,21:18.0
10,0,21:18.0
-11,1,21:18.0
-10,1,21:18.0
-9,1,21:18.0
-8,1,21:18.0
-7,1,21:18.0
-6,1,21:18.0
-5,1,21:18.0
-4,1,21:18.0
-3,1,21:18.0
-2,1,21:17.12
-1,1,21:17.12
0,1,21:17.12
1,1,21:17.12
2,1,21:18.0
3,1,21:18.0
4,1,21:18.0
5,1,21:18.0
6,1,21:18.0
7,1,21:18.0
8,1,21:17.0
9,1,21:18.0
10,1,21:18.0
-11,2,21:18.0
-10,2,21:18.0
-9,2,21:18.0
-8,2,21:18.0
-7,2,21:18.0
-6,2,21:18.0
-5,2,21:18.0
-4,2,21:18.0
-3,2,21:18.0
-2,2,21:18.0
-1,2,21:17.12
0,2,21:17.12
1,2,21:18.0
2,2,21:18.0
3,2,21:18.0
4,2,21:18.0
5,2,21:18.0
6,2,21:18.0
7,2,21:18.0
8,2,21:18.0
9,2,21:18.0
-10,3,21:18.0
-9,3,21:18.0
-8,3,21:18.0
-7,3,21:18.0
-6,3,21:18.0
-5,3,21:18.0
-4,3,21:18.0
-3,3,21:18.0
-2,3,21:18.0
-1,3,21:18.0
0,3,21:18.0
1,3,21:18.0
2,3,21:18.0
3,3,21:18.0
4,3,21:18.0
5,3,21:18.0
6,3,21:18.0
7,3,21:18.0
8,3,21:18.0
-4,4,21:18.0
-3,4,21:18.0
-2,4,21:18.0
-1,4,21:18.0
0,4,21:18.0
1,4,21:18.0
2,4,21:18.0
3,4,21:18.0
4,4,21:18.0
5,4,21:18.0
6,4,21:18.0
-3,5,21:18.0
-2,5,21:18.0
-1,5,21:18.0
0,5,21:18.0
1,5,21:18.0
2,5,21:18.0
3,5,21:18.0
4,5,21:18.0
5,5,21:18.0
-1,6,21:18.0
0,6,21:18.0
1,6,21:18.0
2,6,21:18.0
3,6,21:18.0
-1,7,21:18.0
0,7,21:18.0
0,-12,22:18.0
1,-12,22:18.0
-3,-11,22:18.0
-2,-11,22:18.0
-1,-11,22:18.0
0,-11,22:18.0
1,-11,22:18.0
2,-11,22:18.0
3,-11,22:18.0
-3,-10,22:18.0
-2,-10,22:17.0
-1,-10,22:18.0
0,-10,22:18.0
1,-10,22:18.0
2,-10,22:18.0
3,-10,22:18.0
-4,-9,22:18.0
-3,-9,22:18.0
-2,-9,22:18.0
-1,-9,22:18.0
0,-9,22:18.0
1,-9,22:18.0
2,-9,22:18.0
3,-9,22:18.0
4,-9,22:18.0
-4,-8,22:18.0
-3,-8,22:18.0
-2,-8,22:18.0
-1,-8,22:18.0
0,-8,22:17.8
1,-8,22:18.0
2,-8,22:18.0
3,-8,22:18.0
4,-8,22:18.0
-4,-7,22:18.0
-3,-7,22:18.0
-2,-7,22:18.0
-1,-7,22:18.0
0,-7,22:17.8
1,-7,22:18.0
2,-7,22:18.0
3,-7,22:18.0
4,-7,22:18.0
5,-7,22:18.0
-4,-6,22:18.0
-3,-6,22:18.0
-2,-6,22:18.0
-1,-6,22:18.0
0,-6,22:17.8
1,-6,22:18.0
2,-6,22:18.0
3,-6,22:18.0
4,-6,22:18.0
5,-6,22:18.0
-8,-5,22:18.0
-7,-5,22:18.0
-4,-5,22:18.0
-3,-5,22:17.4
-2,-5,22:18.0
-1,-5,22:18.0
0,-5,22:17.8
1,-5,22:18.0
2,-5,22:18.0
3,-5,22:18.0
4,-5,22:18.0
5,-5,22:17.4
6,-5,22:18.0
-10,-4,22:18.0
-9,-4,22:18.0
-8,-4,22:18.0
-7,-4,22:18.0
-6,-4,22:18.0
-5,-4,22:18.0
-4,-4,22:18.0
-3,-4,22:18.0
-2,-4,22:18.0
-1,-4,22:18.0
0,-4,22:17.8
1,-4,22:18.0
2,-4,22:18.0
3,-4,22:18.0
4,-4,22:18.0
5,-4,22:18.0
6,-4,22:18.0
-11,-3,22:18.0
-10,-3,22:18.0
-9,-3,22:18.0
-8,-3,22:18.0
-7,-3,22:18.0
-6,-3,22:18.0
-5,-3,22:18.0
-4,-3,22:18.0
-3,-3,22:18.0
-2,-3,22:18.0
-1,-3,22:17.12
0,-3,22:17.12
1,-3,22:18.0
2,-3,22:18.0
3,-3,22:18.0
4,-3,22:18.0
5,-3,22:18.0
6,-3,22:18.0
-12,-2,22:18.0
-11,-2,22:18.0
-10,-2,22:18.0
-9,-2,22:18.0
-8,-2,22:18.0
-7,-2,22:18.0
-6,-2,22:18.0
-5,-2,22:18.0
-4,-2,22:18.0
-3,-2,22:18.0
-2,-2,22:17.12
-1,-2,22:17.12
0,-2,22:17.12
1,-2,22:17.12
2,-2,22:18.0
3,-2,22:18.0
4,-2,22:18.0
5,-2,22:18.0
6,-2,22:18.0
-12,-1,22:18.0
-11,-1,22:18.0
-10,-1,22:18.0
-9,-1,22:18.0
-8,-1,22:18.0
-7,-1,22:18.0
-6,-1,22:18.0
-5,-1,22:18.0
-4,-1,22:18.0
-3,-1,22:17.12
-2,-1,22:17.12
-1,-1,22:17.12
0,-1,22:17.12
1,-1,22:17.12
2,-1,22:17.12
3,-1,22:18.0
4,-1,22:18.0
5,-1,22:18.0
6,-1,22:18.0
7,-1,22:18.0
-11,0,22:18.0
-10,0,22:18.0
-9,0,22:18.0
-8,0,22:18.0
-7,0,22:18.0
-6,0,22:18.0
-5,0,22:18.0
-4,0,22:18.0
-3,0,22:17.12
-2,0,22:17.12
-1,0,22:17.12
0,0,22:17.12
1,0,22:17.12
2,0,22:17.12
3,0,22:18.0
4,0,22:18.0
5,0,22:18.0
6,0,22:18.0
7,0,22:18.0
8,0,22:18.0
-11,1,22:18.0
-10,1,22:18.0
-9,1,22:18.0
-8,1,22:18.0
-7,1,22:18.0
-6,1,22:18.0
-5,1,22:18.0
-4,1,22:18.0
-3,1,22:18.0
-2,1,22:17.12
-1,1,22:17.12
0,1,22:17.12
1,1,22:17.12
2,1,22:18.0
3,1,22:18.0
4,1,22:18.0
5,1,22:18.0
6,1,22:18.0
7,1,22:18.0
8,1,22:18.0
-11,2,22:18.0
-10,2,22:18.0
-9,2,22:18.0
-8,2,22:18.0
-7,2,22:18.0
-6,2,22:18.0
-5,2,22:18.0
-4,2,22:18.0
-3,2,22:18.0
-2,2,22:18.0
-1,2,22:17.12
0,2,22:17.12
1,2,22:18.0
2,2,22:18.0
3,2,22:18.0
4,2,22:18.0
6,2,22:18.0
7,2,22:18.0
8,2,22:18.0
-9,3,22:18.0
-8,3,22:18.0
-7,3,22:18.0
-6,3,22:18.0
-5,3,22:18.0
-4,3,22:18.0
-3,3,22:18.0
-2,3,22:18.0
-1,3,22:18.0
0,3,22:18.0
1,3,22:18.0
2,3,22:18.0
3,3,22:18.0
4,3,22:18.0
5,3,22:18.0
6,3,22:18.0
-5,4,22:18.0
-4,4,22:18.0
-3,4,22:17.8
-2,4,22:18.0
-1,4,22:18.0
0,4,22:18.0
1,4,22:18.0
2,4,22:18.0
3,4,22:17.8
4,4,22:18.0
-3,5,22:18.0
-2,5,22:18.0
-1,5,22:18.0
0,5,22:18.0
1,5,22:18.0
2,5,22:18.0
3,5,22:18.0
4,5,22:18.0
-1,-12,23:18.0
0,-12,23:18.0
-3,-11,23:18.0
-2,-11,23:18.0
-1,-11,23:18.0
0,-11,23:17.8
1,-11,23:18.0
2,-11,23:18.0
3,-11,23:18.0
-3,-10,23:18.0
-2,-10,23:18.0
-1,-10,23:18.0
0,-10,23:18.0
1,-10,23:18.0
2,-10,23:18.0
3,-10,23:18.0
-4,-9,23:18.0
-3,-9,23:18.0
-2,-9,23:18.0
-1,-9,23:18.0
0,-9,23:18.0
1,-9,23:18.0
2,-9,23:18.0
3,-9,23:17.4
4,-9,23:18.0
-4,-8,23:18.0
-3,-8,23:18.0
-2,-8,23:18.0
-1,-8,23:18.0
0,-8,23:18.0
1,-8,23:18.0
2,-8,23:18.0
3,-8,23:18.0
4,-8,23:18.0
-4,-7,23:18.0
-3,-7,23:18.0
-2,-7,23:18.0
-1,-7,23:18.0
0,-7,23:18.0
1,-7,23:18.0
2,-7,23:18.0
3,-7,23:18.0
4,-7,23:18.0
5,-7,23:18.0
-4,-6,23:18.0
-3,-6,23:18.0
-2,-6,23:18.0
-1,-6,23:18.0
0,-6,23:18.0
1,-6,23:18.0
2,-6,23:18.0
3,-6,23:18.0
4,-6,23:18.0
5,-6,23:18.0
-4,-5,23:18.0
-3,-5,23:18.0
-2,-5,23:18.0
-1,-5,23:18.0
0,-5,23:18.0
1,-5,23:18.0
2,-5,23:18.0
3,-5,23:18.0
4,-5,23:18.0
5,-5,23:18.0
6,-5,23:18.0
-9,-4,23:18.0
-8,-4,23:18.0
-7,-4,23:18.0
-6,-4,23:18.0
-5,-4,23:18.0
-4,-4,23:18.0
-3,-4,23:18.0
-2,-4,23:18.0
-1,-4,23:18.0
0,-4,23:18.0
1,-4,23:18.0
2,-4,23:18.0
3,-4,23:18.0
4,-4,23:18.0
5,-4,23:18.0
6,-4,23:18.0
-11,-3,23:18.0
-10,-3,23:18.0
-9,-3,23:18.0
-8,-3,23:17.0
-7,-3,23:18.0
-6,-3,23:18.0
-5,-3,23:18.0
-4,-3,23:18.0
-3,-3,23:18.0
-2,-3,23:18.0
-1,-3,23:18.0
0,-3,23:18.0
1,-3,23:18.0
2,-3,23:18.0
3,-3,23:18.0
4,-3,23:18.0
5,-3,23:18.0
6,-3,23:18.0
-11,-2,23:18.0
-10,-2,23:18.0
-9,-2,23:18.0
-8,-2,23:18.0
-7,-2,23:18.0
-6,-2,23:18.0
-5,-2,23:18.0
-4,-2,23:18.0
-3,-2,23:18.0
-2,-2,23:18.0
-1,-2,23:18.0
0,-2,23:18.0
1,-2,23:18.0
2,-2,23:18.0
3,-2,23:18.0
4,-2,23:18.0
5,-2,23:18.0
-11,-1,23:18.0
-10,-1,23:17.0
-9,-1,23:18.0
-8,-1,23:18.0
-7,-1,23:18.0
-6,-1,23:18.0
-5,-1,23:18.0
-4,-1,23:18.0
-3,-1,23:18.0
-2,-1,23:18.0
-1,-1,23:18.0
0,-1,23:18.0
1,-1,23:18.0
2,-1,23:18.0
3,-1,23:18.0
4,-1,23:18.0
5,-1,23:18.0
-11,0,23:18.0
-10,0,23:18.0
-9,0,23:18.0
-8,0,23:18.0
-7,0,23:18.0
-6,0,23:18.0
-5,0,23:18.0
-4,0,23:18.0
-3,0,23:18.0
-2,0,23:18.0
-1,0,23:18.0
0,0,23:18.0
1,0,23:18.0
2,0,23:18.0
3,0,23:18.0
4,0,23:18.0
5,0,23:18.0
-11,1,23:18.0
-10,1,23:18.0
-9,1,23:18.0
-8,1,23:17.0
-7,1,23:18.0
-6,1,23:18.0
-5,1,23:18.0
-4,1,23:18.0
-3,1,23:18.0
-2,1,23:18.0
-1,1,23:18.0
0,1,23:18.0
1,1,23:18.0
2,1,23:18.0
3,1,23:18.0
4,1,23:18.0
5,1,23:18.0
6,1,23:18.0
-10,2,23:18.0
-9,2,23:18.0
-8,2,23:18.0
-7,2,23:18.0
-6,2,23:18.0
-5,2,23:18.0
-4,2,23:18.0
-3,2,23:18.0
-2,2,23:18.0
-1,2,23:18.0
0,2,23:18.0
1,2,23:18.0
2,2,23:18.0
3,2,23:18.0
4,2,23:18.0
5,2,23:18.0
-5,3,23:18.0
-4,3,23:18.0
-3,3,23:18.0
-2,3,23:18.0
-1,3,23:18.0
0,3,23:18.0
1,3,23:18.0
2,3,23:18.0
3,3,23:18.0
4,3,23:18.0
5,3,23:18.0
-5,4,23:18.0
-4,4,23:18.0
-3,4,23:18.0
-2,4,23:18.0
-1,4,23:18.0
0,4,23:18.0
1,4,23:18.0
2,4,23:18.0
3,4,23:18.0
4,4,23:18.0
-3,5,23:18.0
-2,5,23:18.0
-1,5,23:18.0
0,5,23:18.0
1,5,23:18.0
2,5,23:18.0
3,5,23:18.0
4,5,23:18.0
-2,-11,24:18.0
-1,-11,24:18.0
0,-11,24:18.0
1,-11,24:18.0
2,-11,24:18.0
-3,-10,24:18.0
-2,-10,24:18.0
-1,-10,24:18.0
0,-10,24:18.0
1,-10,24:18.0
2,-10,24:18.0
3,-10,24:18.0
-3,-9,24:18.0
-2,-9,24:18.0
-1,-9,24:18.0
0,-9,24:18.0
1,-9,24:18.0
2,-9,24:18.0
3,-9,24:18.0
-4,-8,24:18.0
-3,-8,24:17.0
-2,-8,24:18.0
-1,-8,24:18.0
0,-8,24:18.0
1,-8,24:18.0
2,-8,24:18.0
3,-8,24:18.0
4,-8,24:18.0
-4,-7,24:18.0
-3,-7,24:18.0
-2,-7,24:18.0
-1,-7,24:18.0
0,-7,24:18.0
1,-7,24:18.0
2,-7,24:18.0
3,-7,24:18.0
4,-7,24:18.0
-4,-6,24:18.0
-3,-6,24:18.0
-2,-6,24:18.0
-1,-6,24:18.0
0,-6,24:18.0
1,-6,24:18.0
2,-6,24:18.0
3,-6,24:18.0
4,-6,24:18.0
5,-6,24:18.0
-3,-5,24:18.0
-2,-5,24:18.0
-1,-5,24:18.0
0,-5,24:18.0
1,-5,24:18.0
2,-5,24:18.0
3,-5,24:18.0
4,-5,24:18.0
5,-5,24:18.0
-8,-4,24:18.0
-7,-4,24:18.0
-5,-4,24:18.0
-4,-4,24:18.0
-3,-4,24:18.0
-2,-4,24:18.0
-1,-4,24:18.0
0,-4,24:18.0
1,-4,24:18.0
2,-4,24:18.0
3,-4,24:18.0
4,-4,24:18.0
5,-4,24:17.4
6,-4,24:18.0
-10,-3,24:18.0
-9,-3,24:18.0
-8,-3,24:18.0
-7,-3,24:18.0
-6,-3,24:18.0
-5,-3,24:18.0
-4,-3,24:18.0
-3,-3,24:18.0
-2,-3,24:17.4
-1,-3,24:18.0
0,-3,24:18.0
1,-3,24:18.0
2,-3,24:18.0
3,-3,24:18.0
4,-3,24:18.0
5,-3,24:18.0
-11,-2,24:18.0
-10,-2,24:18.0
-9,-2,24:18.0
-8,-2,24:18.0
-7,-2,24:18.0
-6,-2,24:18.0
-5,-2,24:18.0
-4,-2,24:18.0
-3,-2,24:18.0
-2,-2,24:18.0
-1,-2,24:18.0
0,-2,24:18.0
1,-2,24:18.0
2,-2,24:18.0
3,-2,24:18.0
4,-2,24:18.0
5,-2,24:18.0
-11,-1,24:18.0
-10,-1,24:18.0
-9,-1,24:18.0
-8,-1,24:18.0
-7,-1,24:18.0
-6,-1,24:18.0
-5,-1,24:17.4
-4,-1,24:18.0
-3,-1,24:18.0
-2,-1,24:18.0
-1,-1,24:18.0
0,-1,24:18.0
1,-1,24:18.0
2,-1,24:18.0
3,-1,24:18.0
4,-1,24:18.0
-11,0,24:18.0
-10,0,24:18.0
-9,0,24:18.0
-8,0,24:18.0
-7,0,24:18.0
-6,0,24:18.0
-5,0,24:18.0
-4,0,24:18.0
-3,0,24:18.0
-2,0,24:18.0
-1,0,24:18.0
0,0,24:18.0
1,0,24:18.0
2,0,24:18.0
3,0,24:18.0
4,0,24:18.0
-10,1,24:18.0
-9,1,24:18.0
-8,1,24:18.0
-7,1,24:18.0
-6,1,24:18.0
-5,1,24:18.0
-4,1,24:18.0
-3,1,24:18.0
-2,1,24:18.0
-1,1,24:18.0
0,1,24:18.0
1,1,24:18.0
2,1,24:18.0
3,1,24:17.4
4,1,24:18.0
5,1,24:18.0
-9,2,24:18.0
-8,2,24:18.0
-7,2,24:18.0
-5,2,24:18.0
-4,2,24:17.4
-3,2,24:18.0
-2,2,24:18.0
-1,2,24:18.0
0,2,24:18.0
1,2,24:18.0
2,2,24:18.0
3,2,24:18.0
4,2,24:18.0
5,2,24:18.0
-5,3,24:18.0
-4,3,24:18.0
-3,3,24:18.0
-2,3,24:18.0
-1,3,24:18.0
0,3,24:17.0
1,3,24:18.0
2,3,24:18.0
3,3,24:18.0
4,3,24:18.0
5,3,24:18.0
-4,4,24:18.0
-3,4,24:18.0
-2,4,24:18.0
-1,4,24:18.0
0,4,24:18.0
1,4,24:18.0
2,4,24:18.0
3,4,24:18.0
4,4,24:18.0
-2,5,24:18.0
2,5,24:18.0
3,5,24:18.0
-1,-11,25:18.0
0,-11,25:18.0
1,-11,25:18.0
-2,-10,25:18.0
-1,-10,25:18.0
0,-10,25:18.0
1,-10,25:18.0
2,-10,25:18.0
-3,-9,25:18.0
-2,-9,25:18.0
-1,-9,25:18.0
0,-9,25:18.0
1,-9,25:18.0
2,-9,25:18.0
3,-9,25:18.0
-3,-8,25:18.0
-2,-8,25:18.0
-1,-8,25:17.0
0,-8,25:18.0
1,-8,25:18.0
2,-8,25:18.0
3,-8,25:18.0
-3,-7,25:18.0
-2,-7,25:18.0
-1,-7,25:18.0
0,-7,25:18.0
1,-7,25:18.0
2,-7,25:18.0
3,-7,25:18.0
-2,-6,25:18.0
-1,-6,25:18.0
0,-6,25:18.0
1,-6,25:18.0
2,-6,25:18.0
3,-6,25:18.0
4,-6,25:18.0
-1,-5,25:18.0
0,-5,25:18.0
1,-5,25:18.0
2,-5,25:18.0
3,-5,25:17.0
4,-5,25:18.0
5,-5,25:18.0
-1,-4,25:18.0
0,-4,25:18.0
1,-4,25:18.0
2,-4,25:18.0
3,-4,25:18.0
4,-4,25:18.0
5,-4,25:18.0
-3,-3,25:18.0
-2,-3,25:18.0
-1,-3,25:18.0
0,-3,25:18.0
1,-3,25:18.0
2,-3,25:18.0
3,-3,25:18.0
4,-3,25:18.0
5,-3,25:18.0
-7,-2,25:18.0
-6,-2,25:18.0
-5,-2,25:18.0
-4,-2,25:18.0
-3,-2,25:18.0
-2,-2,25:18.0
-1,-2,25:18.0
0,-2,25:18.0
1,-2,25:18.0
2,-2,25:18.0
3,-2,25:18.0
4,-2,25:18.0
-8,-1,25:18.0
-7,-1,25:18.0
-6,-1,25:18.0
-5,-1,25:18.0
-4,-1,25:18.0
-3,-1,25:18.0
-2,-1,25:18.0
-1,-1,25:18.0
0,-1,25:18.0
1,-1,25:18.0
2,-1,25:18.0
3,-1,25:18.0
-7,0,25:18.0
-6,0,25:18.0
-5,0,25:18.0
-4,0,25:18.0
-3,0,25:18.0
-2,0,25:17.0
-1,0,25:18.0
0,0,25:18.0
1,0,25:18.0
2,0,25:18.0
-5,1,25:18.0
-4,1,25:18.0
-3,1,25:18.0
-2,1,25:18.0
-1,1,25:18.0
0,1,25:18.0
1,1,25:18.0
2,1,25:18.0
3,1,25:18.0
-5,2,25:18.0
-4,2,25:18.0
-3,2,25:18.0
-2,2,25:18.0
-1,2,25:18.0
0,2,25:18.0
1,2,25:18.0
2,2,25:18.0
3,2,25:18.0
-4,3,25:18.0
-3,3,25:18.0
-2,3,25:18.0
-1,3,25:18.0
0,3,25:18.0
1,3,25:18.0
2,3,25:18.0
-3,4,25:18.0
-2,4,25:18.0
-1,4,25:18.0
0,-9,26:18.0
1,-9,26:18.0
-1,-8,26:18.0
0,-8,26:18.0
1,-8,26:18.0
0,-7,26:18.0
1,-7,26:18.0
0,-6,26:18.0
1,-6,26:18.0
2,-6,26:18.0
0,-5,26:18.0
1,-5,26:18.0
2,-5,26:18.0
3,-5,26:18.0
1,-4,26:18.0
2,-4,26:18.0
3,-4,26:18.0
2,-3,26:18.0
3,-3,26:18.0
-3,-1,26:18.0
-2,-1,26:18.0
-1,-1,26:18.0
-4,0,26:18.0
-3,0,26:18.0
-2,0,26:18.0
-1,0,26:18.0
0,0,26:18.0
-4,1,26:18.0
-3,1,26:18.0
-2,1,26:18.0
-1,1,26:18.0
0,1,26:18.0
-3,2,26:18.0
-2,2,26:18.0
-1,2,26:18.0
