[META]
version=2.0
spawnOnBlockType=2
spawnSunlight=True
spawnDarkness=True
spawnWater=False
spawnLava=False
underFill=False
randomRotation=True
dig=True
tree=False
branch=False
needsFoundation=True
rarity=100
collisionPercentage=20
spawnElevationMin=0
spawnElevationMax=200
spawnInBiome=Custom
[DATA]
-1,-2,-4:17.2
0,-2,-4:17.2
-1,-1,-4:17.2
0,-1,-4:17.14
-1,0,-4:17.2
0,0,-4:17.14
-1,-3,-3:17.14
0,-3,-3:17.2
-1,-2,-3:17.2
0,-2,-3:17.2
-2,-1,-3:17.2
-1,-1,-3:17.2
0,-1,-3:17.2
1,-1,-3:17.14
-2,0,-3:17.14
-1,0,-3:17.2
0,0,-3:17.2
1,0,-3:17.14
-1,1,-3:17.2
-1,-3,-2:17.2
0,-3,-2:17.2
-1,-2,-2:17.2
0,-2,-2:17.2
-2,-1,-2:17.2
-1,-1,-2:17.2
0,-1,-2:17.14
1,-1,-2:17.14
-2,0,-2:17.14
-1,0,-2:17.14
0,0,-2:17.2
1,0,-2:17.14
-1,1,-2:17.2
-1,-3,-1:17.2
0,-3,-1:17.2
-1,-2,-1:17.2
0,-2,-1:17.14
-2,-1,-1:17.2
-1,-1,-1:17.2
0,-1,-1:17.14
1,-1,-1:17.2
-2,0,-1:17.14
-1,0,-1:17.14
0,0,-1:17.2
1,0,-1:17.2
-1,1,-1:17.2
-1,-3,0:17.14
0,-3,0:17.14
-1,-2,0:17.14
0,-2,0:17.14
-2,-1,0:17.14
-1,-1,0:17.2
0,-1,0:17.14
1,-1,0:17.14
-2,0,0:17.14
-1,0,0:17.14
0,0,0:17.14
1,0,0:17.14
-1,1,0:17.14
-1,-2,1:17.14
0,-2,1:17.14
-1,-1,1:17.14
0,-1,1:17.2
-1,0,1:17.2
0,0,1:17.2
-1,-1,2:17.2
0,-1,2:17.2
-1,0,2:17.2
0,0,2:17.2
-1,-1,3:17.2
0,-1,3:17.1
-1,0,3:17.1
0,0,3:17.2
-1,-1,4:17.14
0,-1,4:17.2
-1,0,4:17.2
0,0,4:17.2
-1,-1,5:17.14
0,-1,5:17.2
-1,0,5:17.1
0,0,5:17.2
-1,-1,6:17.1
0,-1,6:17.2
-1,0,6:17.2
0,0,6:17.2
-1,-1,7:17.1
0,-1,7:17.2
-1,0,7:17.2
0,0,7:17.2
-1,-1,8:17.2
0,-1,8:17.2
-1,0,8:17.2
0,0,8:17.2
-1,-1,9:17.14
0,-1,9:17.2
-1,0,9:17.14
0,0,9:17.2
-1,-1,10:17.2
0,-1,10:17.1
-1,0,10:17.2
0,0,10:17.2
-1,-1,11:17.14
0,-1,11:17.2
-1,0,11:17.2
0,0,11:17.2
-1,-1,12:17.14
0,-1,12:17.2
-1,0,12:17.14
0,0,12:17.2
-1,-1,13:17.1
0,-1,13:17.2
-1,0,13:17.2
0,0,13:17.1
-4,-5,14:18.2
-3,-5,14:18.2
-2,-5,14:18.2
-4,-4,14:18.2
-3,-4,14:18.2
-2,-4,14:18.2
-1,-4,14:18.2
1,-4,14:18.2
2,-4,14:18.2
3,-4,14:18.2
-4,-3,14:18.2
-3,-3,14:18.2
-2,-3,14:18.2
-1,-3,14:18.2
0,-3,14:18.2
1,-3,14:18.2
2,-3,14:18.2
3,-3,14:18.2
1,-2,14:18.2
2,-2,14:18.2
3,-2,14:18.2
-1,-1,14:17.2
0,-1,14:17.2
1,-1,14:18.2
2,-1,14:18.2
3,-1,14:18.2
4,-1,14:18.2
-4,0,14:18.2
-3,0,14:18.2
-2,0,14:18.2
-1,0,14:17.2
0,0,14:17.2
1,0,14:18.2
2,0,14:18.2
3,0,14:18.2
4,0,14:18.2
-5,1,14:18.2
-4,1,14:18.2
-3,1,14:18.2
-2,1,14:18.2
-1,1,14:18.2
0,1,14:18.2
1,1,14:18.2
2,1,14:18.2
3,1,14:18.2
4,1,14:18.2
5,1,14:18.2
-6,2,14:18.2
-5,2,14:18.2
-4,2,14:18.2
-3,2,14:18.2
-2,2,14:18.2
-1,2,14:18.2
0,2,14:18.2
1,2,14:18.2
2,2,14:18.2
3,2,14:18.2
4,2,14:18.2
5,2,14:18.2
-5,3,14:18.2
-4,3,14:18.2
-3,3,14:18.2
-2,3,14:18.2
-1,3,14:18.2
0,3,14:18.2
1,3,14:18.2
2,3,14:18.2
3,3,14:18.2
4,3,14:18.2
5,3,14:18.2
-4,4,14:18.2
-3,4,14:18.2
-2,4,14:18.2
-1,4,14:18.2
0,4,14:18.2
1,4,14:18.2
2,4,14:18.2
3,4,14:18.2
4,4,14:18.2
-3,5,14:18.2
-2,5,14:18.2
2,5,14:18.2
3,5,14:18.2
4,5,14:18.2
-4,-7,15:18.2
-3,-7,15:18.2
-2,-7,15:18.2
-1,-7,15:18.2
-5,-6,15:18.2
-4,-6,15:18.2
-3,-6,15:18.2
-2,-6,15:18.2
-1,-6,15:18.2
0,-6,15:18.2
1,-6,15:18.2
2,-6,15:18.2
3,-6,15:18.2
-6,-5,15:18.2
-5,-5,15:18.2
-4,-5,15:18.2
-3,-5,15:18.2
-2,-5,15:18.2
-1,-5,15:18.2
0,-5,15:18.2
1,-5,15:18.2
2,-5,15:18.2
3,-5,15:18.2
4,-5,15:18.2
-6,-4,15:18.2
-5,-4,15:18.2
-4,-4,15:18.2
-3,-4,15:17.2
-2,-4,15:18.2
-1,-4,15:18.2
0,-4,15:18.2
1,-4,15:18.2
2,-4,15:18.2
3,-4,15:18.2
4,-4,15:18.2
5,-4,15:18.2
-6,-3,15:18.2
-5,-3,15:18.2
-4,-3,15:18.2
-3,-3,15:18.2
-2,-3,15:18.2
-1,-3,15:18.2
0,-3,15:18.2
1,-3,15:18.2
2,-3,15:17.2
3,-3,15:18.2
4,-3,15:18.2
5,-3,15:18.2
-6,-2,15:18.2
-5,-2,15:18.2
-4,-2,15:18.2
-3,-2,15:18.2
-2,-2,15:18.2
-1,-2,15:18.2
0,-2,15:18.2
1,-2,15:18.2
2,-2,15:18.2
3,-2,15:18.2
4,-2,15:18.2
5,-2,15:18.2
-5,-1,15:18.2
-4,-1,15:18.2
-3,-1,15:18.2
-2,-1,15:18.2
-1,-1,15:18.2
0,-1,15:18.2
1,-1,15:18.2
2,-1,15:18.2
3,-1,15:18.2
4,-1,15:18.2
-4,0,15:18.2
-3,0,15:18.2
-2,0,15:18.2
-1,0,15:18.2
0,0,15:18.2
1,0,15:18.2
2,0,15:18.2
3,0,15:18.2
4,0,15:18.2
5,0,15:18.2
-5,1,15:18.2
-4,1,15:18.2
-3,1,15:18.2
-2,1,15:18.2
-1,1,15:18.2
0,1,15:18.2
1,1,15:18.2
2,1,15:18.2
3,1,15:18.2
4,1,15:18.2
5,1,15:18.2
6,1,15:18.2
-6,2,15:18.2
-5,2,15:18.2
-4,2,15:18.2
-3,2,15:17.2
-2,2,15:18.2
-1,2,15:18.2
0,2,15:18.2
1,2,15:18.2
2,2,15:18.2
3,2,15:18.2
4,2,15:18.2
5,2,15:18.2
6,2,15:18.2
-6,3,15:18.2
-5,3,15:18.2
-4,3,15:18.2
-3,3,15:18.2
-2,3,15:18.2
-1,3,15:18.2
0,3,15:18.2
1,3,15:18.2
2,3,15:18.2
3,3,15:17.2
4,3,15:18.2
5,3,15:18.2
6,3,15:18.2
7,3,15:18.2
-5,4,15:18.2
-4,4,15:18.2
-3,4,15:18.2
-2,4,15:18.2
-1,4,15:18.2
0,4,15:18.2
1,4,15:18.2
2,4,15:18.2
3,4,15:18.2
4,4,15:18.2
5,4,15:18.2
6,4,15:18.2
-4,5,15:18.2
-3,5,15:18.2
-2,5,15:18.2
-1,5,15:18.2
1,5,15:18.2
2,5,15:18.2
3,5,15:18.2
4,5,15:18.2
5,5,15:18.2
-3,6,15:18.2
-2,6,15:18.2
2,6,15:18.2
3,6,15:18.2
4,6,15:18.2
3,7,15:18.2
4,7,15:18.2
-3,-8,16:18.2
-2,-8,16:18.2
-5,-7,16:18.2
-4,-7,16:18.2
-3,-7,16:18.2
-2,-7,16:18.2
-1,-7,16:18.2
0,-7,16:18.2
-6,-6,16:18.2
-5,-6,16:18.2
-4,-6,16:18.2
-3,-6,16:18.2
-2,-6,16:18.2
-1,-6,16:17.2
0,-6,16:18.2
1,-6,16:18.2
2,-6,16:18.2
3,-6,16:18.2
-6,-5,16:18.2
-5,-5,16:18.2
-4,-5,16:18.2
-3,-5,16:18.2
-2,-5,16:18.2
-1,-5,16:18.2
0,-5,16:18.2
2,-5,16:18.2
3,-5,16:18.2
-7,-4,16:18.2
-6,-4,16:18.2
-5,-4,16:18.2
-4,-4,16:18.2
-3,-4,16:18.2
-2,-4,16:18.2
-1,-4,16:18.2
0,-4,16:18.2
1,-4,16:18.2
2,-4,16:18.2
3,-4,16:18.2
4,-4,16:18.2
-7,-3,16:18.2
-6,-3,16:18.2
-5,-3,16:17.6
-4,-3,16:18.2
-3,-3,16:18.2
-2,-3,16:18.2
-1,-3,16:18.2
0,-3,16:18.2
1,-3,16:18.2
2,-3,16:18.2
3,-3,16:18.2
4,-3,16:18.2
5,-3,16:18.2
-7,-2,16:18.2
-6,-2,16:18.2
-5,-2,16:18.2
-4,-2,16:18.2
-3,-2,16:18.2
-2,-2,16:18.2
-1,-2,16:18.2
0,-2,16:18.2
1,-2,16:18.2
2,-2,16:18.2
3,-2,16:18.2
4,-2,16:18.2
-7,-1,16:18.2
-6,-1,16:18.2
-5,-1,16:18.2
-4,-1,16:18.2
-3,-1,16:18.2
-2,-1,16:17.2
-1,-1,16:18.2
0,-1,16:18.2
1,-1,16:18.2
2,-1,16:18.2
3,-1,16:18.2
4,-1,16:18.2
5,-1,16:18.2
-6,0,16:18.2
-5,0,16:18.2
-4,0,16:18.2
-3,0,16:18.2
-2,0,16:18.2
-1,0,16:18.2
0,0,16:18.2
1,0,16:18.2
2,0,16:18.2
3,0,16:18.2
4,0,16:18.2
5,0,16:18.2
6,0,16:18.2
-5,1,16:18.2
-4,1,16:18.2
-3,1,16:18.2
-2,1,16:18.2
-1,1,16:18.2
0,1,16:18.2
1,1,16:18.2
2,1,16:18.2
3,1,16:17.2
4,1,16:18.2
5,1,16:18.2
6,1,16:18.2
-4,2,16:18.2
-3,2,16:18.2
-2,2,16:18.2
-1,2,16:18.2
0,2,16:18.2
1,2,16:18.2
2,2,16:18.2
3,2,16:18.2
4,2,16:18.2
5,2,16:18.2
6,2,16:18.2
-4,3,16:18.2
-3,3,16:18.2
-2,3,16:17.10
-1,3,16:18.2
0,3,16:18.2
1,3,16:18.2
2,3,16:17.2
3,3,16:18.2
4,3,16:18.2
5,3,16:18.2
6,3,16:18.2
-4,4,16:18.2
-3,4,16:18.2
-2,4,16:18.2
-1,4,16:18.2
0,4,16:18.2
1,4,16:18.2
2,4,16:18.2
3,4,16:18.2
4,4,16:18.2
5,4,16:18.2
6,4,16:18.2
-4,5,16:18.2
-3,5,16:18.2
-2,5,16:18.2
-1,5,16:18.2
0,5,16:18.2
1,5,16:18.2
2,5,16:18.2
3,5,16:18.2
4,5,16:17.2
5,5,16:18.2
-3,6,16:18.2
-2,6,16:18.2
-1,6,16:18.2
1,6,16:18.2
2,6,16:18.2
3,6,16:18.2
4,6,16:18.2
2,7,16:18.2
3,7,16:18.2
-3,-7,17:18.2
-2,-7,17:18.2
-1,-7,17:18.2
0,-7,17:18.2
-4,-6,17:18.2
-3,-6,17:18.2
-2,-6,17:18.2
-1,-6,17:18.2
0,-6,17:18.2
1,-6,17:18.2
2,-6,17:18.2
-6,-5,17:18.2
-5,-5,17:18.2
-4,-5,17:17.10
-3,-5,17:18.2
-2,-5,17:18.2
-1,-5,17:18.2
0,-5,17:18.2
1,-5,17:18.2
2,-5,17:18.2
-6,-4,17:18.2
-5,-4,17:18.2
-4,-4,17:18.2
-3,-4,17:18.2
-2,-4,17:18.2
-1,-4,17:18.2
0,-4,17:18.2
1,-4,17:17.2
2,-4,17:18.2
3,-4,17:18.2
4,-4,17:18.2
-8,-3,17:18.2
-7,-3,17:18.2
-6,-3,17:18.2
-5,-3,17:18.2
-4,-3,17:18.2
-3,-3,17:18.2
-2,-3,17:18.2
-1,-3,17:17.2
0,-3,17:18.2
1,-3,17:18.2
2,-3,17:18.2
3,-3,17:18.2
4,-3,17:18.2
-8,-2,17:18.2
-7,-2,17:18.2
-6,-2,17:18.2
-5,-2,17:18.2
-4,-2,17:18.2
-3,-2,17:18.2
-2,-2,17:18.2
-1,-2,17:18.2
0,-2,17:18.2
1,-2,17:18.2
2,-2,17:18.2
3,-2,17:18.2
-7,-1,17:18.2
-6,-1,17:18.2
-5,-1,17:18.2
-4,-1,17:18.2
-3,-1,17:18.2
-2,-1,17:18.2
-1,-1,17:18.2
0,-1,17:18.2
1,-1,17:18.2
2,-1,17:18.2
3,-1,17:18.2
4,-1,17:18.2
-6,0,17:18.2
-5,0,17:18.2
-4,0,17:18.2
-3,0,17:18.2
-2,0,17:18.2
-1,0,17:18.2
0,0,17:18.2
1,0,17:18.2
2,0,17:18.2
3,0,17:18.2
4,0,17:18.2
-5,1,17:18.2
-4,1,17:18.2
-3,1,17:18.2
-2,1,17:18.2
-1,1,17:18.2
0,1,17:18.2
1,1,17:18.2
2,1,17:18.2
3,1,17:18.2
-5,2,17:18.2
-4,2,17:18.2
-3,2,17:18.2
-2,2,17:18.2
-1,2,17:18.2
0,2,17:18.2
1,2,17:18.2
2,2,17:18.2
3,2,17:18.2
4,2,17:18.2
-4,3,17:18.2
-3,3,17:18.2
-2,3,17:18.2
-1,3,17:17.2
0,3,17:18.2
1,3,17:18.2
2,3,17:18.2
3,3,17:17.2
4,3,17:17.2
5,3,17:18.2
-3,4,17:18.2
-2,4,17:18.2
-1,4,17:18.2
0,4,17:18.2
1,4,17:18.2
2,4,17:18.2
3,4,17:18.2
4,4,17:18.2
5,4,17:18.2
-3,5,17:18.2
-2,5,17:18.2
-1,5,17:18.2
1,5,17:18.2
2,5,17:18.2
3,5,17:18.2
4,5,17:18.2
5,5,17:18.2
-2,6,17:18.2
2,6,17:18.2
3,6,17:18.2
-3,-6,18:18.2
-2,-6,18:18.2
-4,-5,18:18.2
-3,-5,18:18.2
-2,-5,18:18.2
-1,-5,18:18.2
-5,-4,18:18.2
-4,-4,18:18.2
-3,-4,18:18.2
-2,-4,18:18.2
-1,-4,18:18.2
0,-4,18:18.2
-7,-3,18:18.2
-6,-3,18:18.2
-5,-3,18:18.2
-4,-3,18:18.2
-3,-3,18:18.2
-2,-3,18:18.2
-1,-3,18:18.2
0,-3,18:18.2
1,-3,18:18.2
2,-3,18:18.2
-8,-2,18:18.2
-7,-2,18:18.2
-6,-2,18:18.2
-5,-2,18:17.6
-4,-2,18:18.2
-3,-2,18:18.2
-2,-2,18:18.2
-1,-2,18:18.2
0,-2,18:18.2
1,-2,18:18.2
2,-2,18:18.2
3,-2,18:18.2
-8,-1,18:18.2
-7,-1,18:18.2
-6,-1,18:18.2
-5,-1,18:18.2
-4,-1,18:18.2
-3,-1,18:18.2
-2,-1,18:18.2
-1,-1,18:18.2
0,-1,18:18.2
1,-1,18:17.6
2,-1,18:18.2
3,-1,18:18.2
-7,0,18:18.2
-6,0,18:18.2
-5,0,18:18.2
-4,0,18:18.2
-3,0,18:18.2
-2,0,18:18.2
-1,0,18:18.2
0,0,18:18.2
1,0,18:18.2
2,0,18:18.2
-6,1,18:18.2
-5,1,18:18.2
-4,1,18:18.2
-3,1,18:18.2
-2,1,18:18.2
-1,1,18:18.2
0,1,18:18.2
1,1,18:18.2
-5,2,18:18.2
-4,2,18:18.2
-3,2,18:18.2
1,3,18:18.2
2,3,18:18.2
3,3,18:18.2
1,4,18:18.2
2,4,18:18.2
3,4,18:18.2
2,5,18:18.2
-5,-4,19:18.2
-4,-4,19:18.2
-3,-4,19:18.2
-6,-3,19:18.2
-5,-3,19:18.2
-4,-3,19:18.2
-3,-3,19:18.2
-2,-3,19:18.2
-1,-3,19:18.2
0,-3,19:18.2
-7,-2,19:18.2
-6,-2,19:18.2
-5,-2,19:18.2
-4,-2,19:18.2
-3,-2,19:18.2
-2,-2,19:18.2
-1,-2,19:18.2
0,-2,19:18.2
1,-2,19:18.2
-7,-1,19:18.2
-6,-1,19:18.2
-5,-1,19:18.2
-4,-1,19:17.6
-3,-1,19:18.2
-2,-1,19:18.2
-1,-1,19:18.2
0,-1,19:18.2
1,-1,19:18.2
-6,0,19:18.2
-5,0,19:18.2
-4,0,19:18.2
-3,0,19:18.2
-2,0,19:18.2
-1,0,19:18.2
-5,1,19:18.2
-4,1,19:18.2
-5,-2,20:18.2
-4,-2,20:18.2
-1,-2,20:18.2
-5,-1,20:18.2
-4,-1,20:18.2
