[META]
version=2.0
spawnOnBlockType=2
spawnSunlight=True
spawnDarkness=True
spawnWater=False
spawnLava=False
underFill=False
randomRotation=True
dig=True
tree=False
branch=False
needsFoundation=True
rarity=100
collisionPercentage=20
spawnElevationMin=0
spawnElevationMax=200
spawnInBiome=Custom
[DATA]
-1,-2,-4:17.14
0,-2,-4:17.14
-1,-1,-4:17.14
0,-1,-4:17.14
1,-1,-4:17.14
-1,0,-4:17.14
0,0,-4:17.14
1,0,-4:17.14
-1,-3,-3:17.14
0,-3,-3:17.14
-1,-2,-3:17.14
0,-2,-3:17.14
-2,-1,-3:17.14
-1,-1,-3:17.14
0,-1,-3:17.14
1,-1,-3:17.14
2,-1,-3:17.14
-2,0,-3:17.14
-1,0,-3:17.14
0,0,-3:17.14
1,0,-3:17.14
2,0,-3:17.14
-1,1,-3:17.14
0,1,-3:17.14
-1,-3,-2:17.14
0,-3,-2:17.14
-1,-2,-2:17.14
0,-2,-2:17.14
-2,-1,-2:17.14
-1,-1,-2:17.14
0,-1,-2:17.14
1,-1,-2:17.14
2,-1,-2:17.14
-2,0,-2:17.14
-1,0,-2:17.14
0,0,-2:17.14
1,0,-2:17.14
2,0,-2:17.14
-1,1,-2:17.14
0,1,-2:17.14
-1,-3,-1:17.14
0,-3,-1:17.14
-1,-2,-1:17.14
0,-2,-1:17.14
-2,-1,-1:17.14
-1,-1,-1:17.14
0,-1,-1:17.14
1,-1,-1:17.14
2,-1,-1:17.14
-2,0,-1:17.14
-1,0,-1:17.14
0,0,-1:17.14
1,0,-1:17.14
2,0,-1:17.14
-1,1,-1:17.14
0,1,-1:17.14
-1,-3,0:17.14
0,-3,0:17.14
-1,-2,0:17.14
0,-2,0:17.14
-2,-1,0:17.14
-1,-1,0:17.14
0,-1,0:17.14
1,-1,0:17.14
2,-1,0:17.14
-2,0,0:17.14
-1,0,0:17.14
0,0,0:17.14
1,0,0:17.14
2,0,0:17.14
-1,1,0:17.14
0,1,0:17.14
-1,-2,1:17.14
0,-2,1:17.14
-1,-1,1:17.14
0,-1,1:17.14
1,-1,1:17.14
-1,0,1:17.14
0,0,1:17.14
1,0,1:17.14
-1,-1,2:17.14
0,-1,2:17.14
-1,0,2:17.14
0,0,2:17.14
-1,-1,3:17.1
0,-1,3:17.14
-1,0,3:17.14
0,0,3:17.14
-1,-1,4:17.14
0,-1,4:17.14
-1,0,4:17.14
0,0,4:17.14
-1,-1,5:17.14
0,-1,5:17.14
-1,0,5:17.14
0,0,5:17.14
-1,-1,6:17.14
0,-1,6:17.14
-1,0,6:17.14
0,0,6:17.14
-1,-1,7:17.14
0,-1,7:17.14
-1,0,7:17.14
0,0,7:17.14
-1,-1,8:17.14
0,-1,8:17.14
-1,0,8:17.14
0,0,8:17.14
-1,-1,9:17.14
0,-1,9:17.14
-1,0,9:17.14
0,0,9:17.14
-1,-5,10:18.2
0,-5,10:18.2
1,-5,10:18.2
-1,-4,10:18.2
0,-4,10:18.2
1,-4,10:18.2
-1,-3,10:18.2
0,-3,10:18.2
-1,-1,10:17.14
0,-1,10:17.14
-1,0,10:17.14
0,0,10:17.14
-3,2,10:18.2
-2,2,10:18.2
-3,3,10:18.2
-2,3,10:18.2
-1,-6,11:18.2
0,-6,11:18.2
1,-6,11:18.2
-2,-5,11:18.2
-1,-5,11:18.2
0,-5,11:18.2
1,-5,11:18.2
2,-5,11:18.2
-3,-4,11:18.2
-2,-4,11:18.2
-1,-4,11:17.14
0,-4,11:18.2
1,-4,11:18.2
2,-4,11:18.2
-3,-3,11:18.2
-2,-3,11:18.2
-1,-3,11:18.2
0,-3,11:18.2
1,-3,11:18.2
2,-3,11:18.2
-2,-2,11:18.2
-1,-2,11:18.2
0,-2,11:18.2
1,-2,11:18.2
-1,-1,11:17.14
0,-1,11:17.14
-3,0,11:18.2
-2,0,11:18.2
-1,0,11:17.14
0,0,11:17.14
-4,1,11:18.2
-3,1,11:18.2
-2,1,11:18.2
-1,1,11:18.2
-5,2,11:18.2
-4,2,11:18.2
-3,2,11:18.2
-2,2,11:18.2
-1,2,11:18.2
0,2,11:18.2
-5,3,11:18.2
-4,3,11:18.2
-3,3,11:17.14
-2,3,11:18.2
-1,3,11:18.2
0,3,11:18.2
-4,4,11:18.2
-3,4,11:18.2
-2,4,11:18.2
-1,4,11:18.2
-3,5,11:18.2
-2,5,11:18.2
-2,-6,12:18.2
-1,-6,12:18.2
0,-6,12:18.2
1,-6,12:18.2
2,-6,12:18.2
-3,-5,12:18.2
-2,-5,12:18.2
-1,-5,12:18.2
0,-5,12:18.2
1,-5,12:18.2
2,-5,12:18.2
3,-5,12:18.2
-3,-4,12:18.2
-2,-4,12:18.2
-1,-4,12:18.2
0,-4,12:18.2
1,-4,12:18.2
2,-4,12:17.14
3,-4,12:18.2
-4,-3,12:18.2
-3,-3,12:18.2
-2,-3,12:18.2
-1,-3,12:18.2
0,-3,12:18.2
1,-3,12:18.2
2,-3,12:18.2
3,-3,12:18.2
-6,-2,12:18.2
-5,-2,12:18.2
-4,-2,12:18.2
-3,-2,12:18.2
-2,-2,12:18.2
-1,-2,12:18.2
0,-2,12:18.2
1,-2,12:18.2
-6,-1,12:18.2
-5,-1,12:18.2
-4,-1,12:18.2
-3,-1,12:18.2
-2,-1,12:18.2
-1,-1,12:18.2
0,-1,12:17.14
-6,0,12:18.2
-5,0,12:18.2
-4,0,12:18.2
-3,0,12:18.2
-2,0,12:18.2
-1,0,12:18.2
0,0,12:17.14
1,0,12:18.2
2,0,12:18.2
3,0,12:18.2
-6,1,12:18.2
-5,1,12:18.2
-4,1,12:18.2
-3,1,12:18.2
-2,1,12:18.2
-1,1,12:18.2
0,1,12:18.2
1,1,12:18.2
2,1,12:18.2
3,1,12:18.2
4,1,12:18.2
5,1,12:18.2
-5,2,12:18.2
-4,2,12:18.2
-3,2,12:18.2
-2,2,12:18.2
-1,2,12:18.2
0,2,12:18.2
1,2,12:18.2
2,2,12:18.2
3,2,12:18.2
4,2,12:18.2
5,2,12:18.2
6,2,12:18.2
-5,3,12:18.2
-4,3,12:18.2
-3,3,12:18.2
-2,3,12:18.2
-1,3,12:18.2
0,3,12:18.2
1,3,12:18.2
2,3,12:18.2
3,3,12:18.2
4,3,12:18.2
5,3,12:18.2
6,3,12:18.2
-4,4,12:18.2
-3,4,12:18.2
-2,4,12:18.2
-1,4,12:18.2
0,4,12:18.2
1,4,12:18.2
2,4,12:18.2
3,4,12:18.2
4,4,12:18.2
5,4,12:18.2
-4,5,12:18.2
-3,5,12:18.2
-2,5,12:18.2
-1,5,12:18.2
3,5,12:18.2
4,5,12:18.2
-3,6,12:18.2
0,-7,13:18.2
1,-7,13:18.2
-2,-6,13:18.2
-1,-6,13:18.2
0,-6,13:18.2
1,-6,13:18.2
2,-6,13:18.2
3,-6,13:18.2
-3,-5,13:18.2
-1,-5,13:17.14
0,-5,13:18.2
1,-5,13:18.2
2,-5,13:18.2
3,-5,13:18.2
-4,-4,13:18.2
-3,-4,13:18.2
-2,-4,13:18.2
-1,-4,13:18.2
0,-4,13:18.2
1,-4,13:18.2
2,-4,13:18.2
3,-4,13:18.2
-6,-3,13:18.2
-5,-3,13:18.2
-4,-3,13:18.2
-3,-3,13:18.2
-2,-3,13:18.2
-1,-3,13:18.2
0,-3,13:18.2
1,-3,13:18.2
2,-3,13:18.2
3,-3,13:18.2
-7,-2,13:18.2
-6,-2,13:18.2
-5,-2,13:18.2
-4,-2,13:18.2
-3,-2,13:18.2
-2,-2,13:18.2
-1,-2,13:18.2
0,-2,13:18.2
1,-2,13:18.2
2,-2,13:18.2
3,-2,13:18.2
-7,-1,13:18.2
-6,-1,13:18.2
-5,-1,13:17.14
-4,-1,13:18.2
-3,-1,13:18.2
-2,-1,13:18.2
-1,-1,13:18.2
0,-1,13:17.14
1,-1,13:18.2
2,-1,13:18.2
3,-1,13:18.2
-7,0,13:18.2
-6,0,13:18.2
-5,0,13:18.2
-4,0,13:18.2
-3,0,13:18.2
-2,0,13:18.2
-1,0,13:18.2
0,0,13:17.14
1,0,13:18.2
2,0,13:18.2
3,0,13:18.2
4,0,13:18.2
5,0,13:18.2
-6,1,13:18.2
-5,1,13:18.2
-4,1,13:18.2
-3,1,13:18.2
-2,1,13:18.2
-1,1,13:18.2
0,1,13:18.2
1,1,13:18.2
2,1,13:18.2
3,1,13:18.2
4,1,13:18.2
5,1,13:18.2
6,1,13:18.2
-6,2,13:18.2
-5,2,13:18.2
-4,2,13:18.2
-3,2,13:18.2
-2,2,13:18.2
-1,2,13:18.2
0,2,13:18.2
1,2,13:18.2
2,2,13:18.2
3,2,13:18.2
4,2,13:17.14
5,2,13:18.2
6,2,13:18.2
7,2,13:18.2
-5,3,13:18.2
-4,3,13:18.2
-3,3,13:18.2
-2,3,13:18.2
-1,3,13:18.2
0,3,13:17.14
1,3,13:18.2
2,3,13:18.2
3,3,13:18.2
4,3,13:18.2
5,3,13:18.2
6,3,13:18.2
7,3,13:18.2
-4,4,13:18.2
-3,4,13:18.2
-2,4,13:18.2
-1,4,13:18.2
0,4,13:18.2
1,4,13:18.2
2,4,13:18.2
3,4,13:18.2
4,4,13:18.2
5,4,13:18.2
6,4,13:18.2
-3,5,13:18.2
-2,5,13:18.2
-1,5,13:18.2
1,5,13:18.2
2,5,13:18.2
3,5,13:18.2
4,5,13:18.2
5,5,13:18.2
-2,6,13:18.2
3,6,13:18.2
4,6,13:18.2
-1,-6,14:18.2
0,-6,14:18.2
1,-6,14:18.2
2,-6,14:18.2
3,-6,14:18.2
-2,-5,14:18.2
-1,-5,14:18.2
0,-5,14:18.2
1,-5,14:18.2
2,-5,14:18.2
3,-5,14:18.2
4,-5,14:18.2
-2,-4,14:18.2
0,-4,14:18.2
1,-4,14:18.2
2,-4,14:18.2
3,-4,14:18.2
4,-4,14:18.2
-5,-3,14:18.2
-4,-3,14:18.2
-3,-3,14:18.2
-2,-3,14:18.2
-1,-3,14:18.2
0,-3,14:18.2
1,-3,14:18.2
2,-3,14:18.2
3,-3,14:18.2
-6,-2,14:18.2
-5,-2,14:18.2
-4,-2,14:18.2
-3,-2,14:18.2
-2,-2,14:18.2
-1,-2,14:18.2
0,-2,14:18.2
1,-2,14:18.2
2,-2,14:18.2
3,-2,14:18.2
-6,-1,14:18.2
-5,-1,14:18.2
-4,-1,14:18.2
-3,-1,14:18.2
-2,-1,14:18.2
-1,-1,14:18.2
0,-1,14:18.2
1,-1,14:18.2
2,-1,14:18.2
3,-1,14:18.2
4,-1,14:18.2
-6,0,14:18.2
-5,0,14:18.2
-4,0,14:18.2
-3,0,14:18.2
-2,0,14:18.2
-1,0,14:18.2
0,0,14:17.14
1,0,14:18.2
2,0,14:18.2
3,0,14:18.2
4,0,14:18.2
5,0,14:18.2
-6,1,14:18.2
-5,1,14:18.2
-4,1,14:18.2
-3,1,14:18.2
-2,1,14:18.2
-1,1,14:18.2
0,1,14:18.2
1,1,14:18.2
2,1,14:18.2
3,1,14:18.2
4,1,14:18.2
5,1,14:18.2
6,1,14:18.2
-5,2,14:18.2
-4,2,14:18.2
-3,2,14:18.2
-2,2,14:18.2
-1,2,14:18.2
0,2,14:18.2
1,2,14:18.2
2,2,14:18.2
3,2,14:18.2
4,2,14:18.2
5,2,14:18.2
6,2,14:18.2
7,2,14:18.2
-4,3,14:18.2
-3,3,14:18.2
-2,3,14:17.14
-1,3,14:18.2
0,3,14:18.2
1,3,14:18.2
2,3,14:18.2
3,3,14:18.2
4,3,14:18.2
5,3,14:18.2
6,3,14:18.2
-3,4,14:18.2
-2,4,14:18.2
-1,4,14:18.2
0,4,14:18.2
1,4,14:18.2
2,4,14:18.2
3,4,14:18.2
4,4,14:18.2
5,4,14:18.2
6,4,14:18.2
1,5,14:18.2
3,5,14:18.2
4,5,14:18.2
5,5,14:18.2
2,6,14:18.2
3,6,14:18.2
4,6,14:18.2
1,-6,15:18.2
2,-6,15:18.2
3,-6,15:18.2
0,-5,15:18.2
1,-5,15:18.2
2,-5,15:18.2
3,-5,15:18.2
4,-5,15:18.2
-1,-4,15:18.2
0,-4,15:18.2
1,-4,15:18.2
2,-4,15:17.14
3,-4,15:18.2
-1,-3,15:18.2
0,-3,15:17.14
1,-3,15:18.2
2,-3,15:18.2
3,-3,15:18.2
-4,-2,15:18.2
-3,-2,15:18.2
-2,-2,15:18.2
-1,-2,15:18.2
0,-2,15:18.2
1,-2,15:18.2
2,-2,15:18.2
3,-2,15:18.2
4,-2,15:18.2
-5,-1,15:18.2
-4,-1,15:18.2
-3,-1,15:18.2
-2,-1,15:18.2
-1,-1,15:18.2
0,-1,15:18.2
1,-1,15:18.2
2,-1,15:18.2
3,-1,15:18.2
4,-1,15:18.2
5,-1,15:18.2
-6,0,15:18.2
-5,0,15:18.2
-4,0,15:18.2
-3,0,15:18.2
-2,0,15:18.2
-1,0,15:18.2
0,0,15:17.14
1,0,15:18.2
2,0,15:17.14
3,0,15:18.2
4,0,15:18.2
5,0,15:18.2
6,0,15:18.2
-6,1,15:18.2
-5,1,15:18.2
-4,1,15:18.2
-3,1,15:18.2
-2,1,15:18.2
-1,1,15:18.2
0,1,15:18.2
1,1,15:18.2
2,1,15:18.2
3,1,15:18.2
4,1,15:18.2
5,1,15:18.2
6,1,15:18.2
-5,2,15:18.2
-4,2,15:18.2
-3,2,15:18.2
-2,2,15:18.2
-1,2,15:18.2
0,2,15:18.2
1,2,15:18.2
2,2,15:18.2
3,2,15:18.2
4,2,15:18.2
5,2,15:18.2
6,2,15:18.2
7,2,15:18.2
-4,3,15:18.2
-3,3,15:18.2
-2,3,15:18.2
-1,3,15:18.2
0,3,15:18.2
1,3,15:18.2
2,3,15:18.2
3,3,15:18.2
4,3,15:18.2
5,3,15:18.2
6,3,15:18.2
1,4,15:18.2
2,4,15:18.2
3,4,15:17.14
4,4,15:18.2
5,4,15:18.2
6,4,15:18.2
2,5,15:18.2
3,5,15:18.2
4,5,15:18.2
5,5,15:18.2
2,-5,16:18.2
3,-5,16:18.2
0,-4,16:18.2
1,-4,16:18.2
2,-4,16:18.2
3,-4,16:18.2
0,-3,16:18.2
1,-3,16:18.2
0,-2,16:18.2
1,-2,16:18.2
2,-2,16:18.2
3,-2,16:18.2
-4,-1,16:18.2
-3,-1,16:18.2
-2,-1,16:18.2
-1,-1,16:18.2
0,-1,16:18.2
1,-1,16:18.2
2,-1,16:18.2
3,-1,16:18.2
4,-1,16:18.2
-5,0,16:18.2
-4,0,16:17.14
-3,0,16:18.2
-2,0,16:18.2
-1,0,16:18.2
0,0,16:18.2
1,0,16:18.2
2,0,16:18.2
3,0,16:18.2
4,0,16:18.2
5,0,16:18.2
-5,1,16:18.2
-4,1,16:18.2
-3,1,16:18.2
-2,1,16:18.2
-1,1,16:18.2
0,1,16:18.2
1,1,16:18.2
2,1,16:18.2
3,1,16:18.2
4,1,16:18.2
5,1,16:18.2
6,1,16:18.2
-4,2,16:18.2
-3,2,16:18.2
-2,2,16:18.2
-1,2,16:18.2
0,2,16:18.2
1,2,16:18.2
2,2,16:18.2
3,2,16:18.2
4,2,16:18.2
5,2,16:17.14
6,2,16:18.2
-3,3,16:18.2
-2,3,16:18.2
-1,3,16:18.2
2,3,16:18.2
3,3,16:18.2
4,3,16:18.2
5,3,16:18.2
6,3,16:18.2
2,4,16:18.2
3,4,16:18.2
4,4,16:18.2
5,4,16:18.2
-1,-5,17:18.2
0,-5,17:18.2
-2,-4,17:18.2
-1,-4,17:18.2
0,-4,17:18.2
1,-4,17:18.2
-2,-3,17:18.2
-1,-3,17:18.2
0,-3,17:18.2
1,-3,17:18.2
2,-3,17:18.2
-1,-2,17:18.2
0,-2,17:18.2
1,-2,17:18.2
2,-2,17:18.2
-3,-1,17:18.2
-2,-1,17:18.2
-1,-1,17:17.14
0,-1,17:18.2
1,-1,17:18.2
-4,0,17:18.2
-3,0,17:18.2
-2,0,17:18.2
-1,0,17:18.2
0,0,17:18.2
-4,1,17:18.2
-3,1,17:18.2
-2,1,17:17.14
-1,1,17:18.2
3,1,17:18.2
4,1,17:18.2
-3,2,17:18.2
-2,2,17:18.2
-1,2,17:18.2
3,2,17:18.2
4,2,17:18.2
5,2,17:18.2
4,3,17:18.2
-1,-6,18:18.2
0,-6,18:18.2
1,-6,18:18.2
-2,-5,18:18.2
-1,-5,18:18.2
0,-5,18:18.2
1,-5,18:18.2
2,-5,18:18.2
-2,-4,18:18.2
-1,-4,18:18.2
0,-4,18:18.2
1,-4,18:18.2
2,-4,18:18.2
-2,-3,18:18.2
-1,-3,18:18.2
0,-3,18:18.2
1,-3,18:18.2
2,-3,18:18.2
3,-3,18:18.2
-2,-2,18:18.2
-1,-2,18:18.2
0,-2,18:18.2
1,-2,18:18.2
2,-2,18:18.2
3,-2,18:18.2
-2,-1,18:18.2
-1,-1,18:18.2
0,-1,18:18.2
1,-1,18:18.2
2,-1,18:18.2
-3,0,18:18.2
-2,0,18:18.2
-1,0,18:18.2
0,0,18:18.2
1,0,18:18.2
-3,1,18:18.2
-2,1,18:18.2
-1,1,18:18.2
-2,2,18:18.2
-1,-6,19:18.2
0,-6,19:18.2
1,-6,19:18.2
-2,-5,19:18.2
-1,-5,19:18.2
0,-5,19:17.14
1,-5,19:18.2
2,-5,19:18.2
-3,-4,19:18.2
-2,-4,19:18.2
-1,-4,19:18.2
0,-4,19:18.2
1,-4,19:18.2
2,-4,19:18.2
3,-4,19:18.2
-3,-3,19:18.2
-2,-3,19:18.2
-1,-3,19:18.2
0,-3,19:18.2
1,-3,19:18.2
2,-3,19:18.2
3,-3,19:18.2
-2,-2,19:18.2
-1,-2,19:17.14
0,-2,19:18.2
1,-2,19:17.14
2,-2,19:18.2
3,-2,19:18.2
-1,-1,19:18.2
0,-1,19:18.2
1,-1,19:18.2
2,-1,19:18.2
-1,0,19:18.2
0,0,19:18.2
1,0,19:18.2
0,-5,20:18.2
1,-5,20:18.2
-1,-4,20:18.2
0,-4,20:18.2
1,-4,20:18.2
2,-4,20:18.2
-1,-3,20:18.2
0,-3,20:18.2
1,-3,20:18.2
2,-3,20:18.2
0,-2,20:18.2
1,-2,20:18.2
2,-2,20:18.2
0,-1,20:18.2
