[META]
version=2.0
spawnOnBlockType=2
spawnSunlight=True
spawnDarkness=True
spawnWater=False
spawnLava=False
underFill=False
randomRotation=True
dig=True
tree=False
branch=False
needsFoundation=True
rarity=100
collisionPercentage=20
spawnElevationMin=0
spawnElevationMax=200
spawnInBiome=Custom
[DATA]
-3,-2,-4:17.14
-2,-2,-4:17.14
-3,-1,-4:17.14
-2,-1,-4:17.14
-1,-1,-4:17.14
-3,0,-4:17.14
-2,0,-4:17.14
-1,0,-4:17.14
-3,-3,-3:17.14
-2,-3,-3:17.14
-3,-2,-3:17.14
-2,-2,-3:17.14
-4,-1,-3:17.14
-3,-1,-3:17.14
-2,-1,-3:17.14
-1,-1,-3:17.14
0,-1,-3:17.14
-4,0,-3:17.14
-3,0,-3:17.14
-2,0,-3:17.14
-1,0,-3:17.14
0,0,-3:17.14
-3,1,-3:17.14
-2,1,-3:17.14
-3,-3,-2:17.14
-2,-3,-2:17.14
-3,-2,-2:17.14
-2,-2,-2:17.14
-4,-1,-2:17.14
-1,-1,-2:17.14
0,-1,-2:17.14
-4,0,-2:17.14
-1,0,-2:17.14
0,0,-2:17.14
-3,1,-2:17.14
-2,1,-2:17.14
-3,-3,-1:17.14
-2,-3,-1:17.14
-3,-2,-1:17.14
-2,-2,-1:17.14
-4,-1,-1:17.14
-1,-1,-1:17.14
0,-1,-1:17.14
-4,0,-1:17.14
-1,0,-1:17.14
0,0,-1:17.14
-3,1,-1:17.14
-2,1,-1:17.14
-3,-3,0:17.14
-2,-3,0:17.14
-3,-2,0:17.14
-2,-2,0:17.14
-4,-1,0:17.14
-1,-1,0:17.14
0,-1,0:17.14
-4,0,0:17.14
-1,0,0:17.14
0,0,0:17.14
-3,1,0:17.14
-2,1,0:17.14
-3,-2,1:17.14
-2,-2,1:17.14
-3,-1,1:17.14
-2,-1,1:17.14
-1,-1,1:17.14
-3,0,1:17.14
-2,0,1:17.14
-1,0,1:17.14
-3,-1,2:17.14
-2,-1,2:17.1
-3,0,2:17.14
-2,0,2:17.14
-3,-1,3:17.14
-2,-1,3:17.14
-3,0,3:17.14
-2,0,3:17.14
-3,-1,4:17.14
-2,-1,4:17.14
-3,0,4:17.14
-2,0,4:17.14
-3,-1,5:17.1
-2,-1,5:17.14
-3,0,5:17.14
-2,0,5:17.14
-3,-1,6:17.14
-2,-1,6:17.14
-3,0,6:17.14
-2,0,6:17.1
-3,-1,7:17.14
-2,-1,7:17.2
-3,0,7:17.2
-2,0,7:17.2
-3,-1,8:17.14
-2,-1,8:17.1
-3,0,8:17.1
-2,0,8:17.2
-3,-1,9:17.14
-2,-1,9:17.14
-3,0,9:17.1
-2,0,9:17.14
-3,-1,10:17.14
-2,-1,10:17.14
-3,0,10:17.14
-2,0,10:17.14
-3,-1,11:17.14
-2,-1,11:17.1
-3,0,11:17.14
-2,0,11:17.1
-3,-1,12:17.14
-2,-1,12:17.14
-3,0,12:17.14
-2,0,12:17.14
-3,-1,13:17.14
-2,-1,13:17.14
-3,0,13:17.14
-2,0,13:17.14
-3,-1,14:17.14
-2,-1,14:17.14
-3,0,14:17.14
-2,0,14:17.1
-3,-1,15:17.14
-2,-1,15:17.14
-3,0,15:17.1
-2,0,15:17.14
-3,-1,16:17.14
-2,-1,16:17.14
-3,0,16:17.14
-2,0,16:17.14
-2,-5,17:18.2
-1,-5,17:18.2
0,-5,17:18.2
-2,-4,17:18.2
-1,-4,17:18.2
0,-4,17:18.2
-2,-3,17:18.2
-1,-3,17:18.2
0,-3,17:18.2
1,-3,17:18.2
2,-3,17:18.2
3,-3,17:18.2
-2,-2,17:18.2
-1,-2,17:18.2
0,-2,17:18.2
1,-2,17:18.2
2,-2,17:18.2
3,-2,17:18.2
4,-2,17:18.2
-3,-1,17:17.14
-2,-1,17:17.14
-1,-1,17:18.2
0,-1,17:18.2
1,-1,17:18.2
2,-1,17:18.2
3,-1,17:18.2
4,-1,17:18.2
-3,0,17:17.1
-2,0,17:17.14
-1,0,17:18.2
0,0,17:18.2
1,0,17:18.2
2,0,17:18.2
3,0,17:18.2
4,0,17:18.2
-1,1,17:18.2
0,1,17:18.2
1,1,17:18.2
2,1,17:18.2
3,1,17:18.2
4,1,17:18.2
0,2,17:18.2
1,2,17:18.2
2,2,17:18.2
3,2,17:18.2
-1,-6,18:18.2
0,-6,18:18.2
-2,-5,18:18.2
-1,-5,18:17.14
0,-5,18:18.2
1,-5,18:18.2
-3,-4,18:18.2
-2,-4,18:18.2
-1,-4,18:18.2
0,-4,18:18.2
1,-4,18:18.2
2,-4,18:18.2
-3,-3,18:18.2
-2,-3,18:18.2
-1,-3,18:18.2
0,-3,18:17.14
1,-3,18:18.2
2,-3,18:17.14
3,-3,18:18.2
4,-3,18:18.2
-2,-2,18:18.2
-1,-2,18:18.2
0,-2,18:18.2
1,-2,18:18.2
2,-2,18:18.2
3,-2,18:18.2
4,-2,18:18.2
-3,-1,18:17.1
-2,-1,18:17.14
-1,-1,18:18.2
0,-1,18:18.2
1,-1,18:18.2
2,-1,18:18.2
3,-1,18:18.2
4,-1,18:18.2
5,-1,18:18.2
-3,0,18:18.2
-2,0,18:17.14
-1,0,18:18.2
0,0,18:18.2
1,0,18:17.2
2,0,18:18.2
3,0,18:17.2
4,0,18:18.2
5,0,18:18.2
-3,1,18:18.2
-2,1,18:18.2
-1,1,18:18.2
0,1,18:18.2
1,1,18:18.2
2,1,18:18.2
3,1,18:18.2
4,1,18:18.2
-3,2,18:18.2
-2,2,18:18.2
-1,2,18:18.2
0,2,18:18.2
1,2,18:18.2
2,2,18:18.2
3,2,18:18.2
4,2,18:18.2
-4,3,18:18.2
-3,3,18:18.2
-2,3,18:18.2
-1,3,18:18.2
0,3,18:18.2
1,3,18:18.2
2,3,18:18.2
-4,4,18:18.2
-3,4,18:18.2
-2,4,18:18.2
-1,4,18:18.2
0,4,18:18.2
1,4,18:18.2
2,4,18:18.2
-3,5,18:18.2
-2,5,18:18.2
-1,5,18:18.2
0,5,18:18.2
1,5,18:18.2
-1,-6,19:18.2
-2,-5,19:18.2
-1,-5,19:18.2
0,-5,19:18.2
1,-5,19:18.2
-3,-4,19:18.2
-2,-4,19:18.2
-1,-4,19:18.2
0,-4,19:18.2
1,-4,19:18.2
2,-4,19:18.2
-5,-3,19:18.2
-4,-3,19:18.2
-3,-3,19:18.2
-2,-3,19:18.2
-1,-3,19:18.2
0,-3,19:18.2
1,-3,19:18.2
2,-3,19:18.2
-6,-2,19:18.2
-5,-2,19:18.2
-4,-2,19:18.2
-3,-2,19:18.2
-2,-2,19:18.2
-1,-2,19:18.2
0,-2,19:18.2
1,-2,19:18.2
2,-2,19:18.2
3,-2,19:18.2
4,-2,19:18.2
-5,-1,19:18.2
-4,-1,19:18.2
-3,-1,19:17.14
-2,-1,19:17.14
-1,-1,19:18.2
0,-1,19:18.2
1,-1,19:18.2
2,-1,19:17.14
3,-1,19:18.2
4,-1,19:18.2
-3,0,19:18.2
-2,0,19:17.14
-1,0,19:18.2
0,0,19:18.2
1,0,19:18.2
2,0,19:18.2
3,0,19:18.2
4,0,19:18.2
5,0,19:18.2
-4,1,19:18.2
-3,1,19:18.2
-2,1,19:18.2
-1,1,19:18.2
0,1,19:18.2
1,1,19:18.2
2,1,19:18.2
3,1,19:18.2
4,1,19:18.2
-4,2,19:18.2
-3,2,19:18.2
-2,2,19:18.2
-1,2,19:18.2
0,2,19:18.2
1,2,19:18.2
2,2,19:18.2
3,2,19:18.2
4,2,19:18.2
-4,3,19:18.2
-3,3,19:18.2
-2,3,19:17.14
-1,3,19:18.2
0,3,19:18.2
1,3,19:18.2
2,3,19:17.14
3,3,19:18.2
-4,4,19:18.2
-3,4,19:18.2
-2,4,19:18.2
-1,4,19:18.2
0,4,19:18.2
1,4,19:18.2
2,4,19:18.2
-4,5,19:18.2
-3,5,19:18.2
-2,5,19:18.2
-1,5,19:17.2
0,5,19:18.2
1,5,19:18.2
2,5,19:18.2
-3,6,19:18.2
-2,6,19:18.2
-1,6,19:18.2
0,6,19:18.2
-2,-5,20:18.2
-1,-5,20:18.2
0,-5,20:18.2
-5,-4,20:18.2
-4,-4,20:18.2
-3,-4,20:18.2
-2,-4,20:18.2
-1,-4,20:18.2
0,-4,20:18.2
1,-4,20:18.2
-6,-3,20:18.2
-5,-3,20:18.2
-4,-3,20:18.2
-3,-3,20:18.2
-2,-3,20:18.2
-1,-3,20:18.2
0,-3,20:18.2
1,-3,20:18.2
2,-3,20:18.2
-7,-2,20:18.2
-6,-2,20:18.2
-5,-2,20:18.2
-4,-2,20:18.2
-3,-2,20:18.2
-2,-2,20:18.2
-1,-2,20:18.2
0,-2,20:18.2
1,-2,20:18.2
2,-2,20:18.2
3,-2,20:18.2
-6,-1,20:18.2
-5,-1,20:18.2
-4,-1,20:18.2
-3,-1,20:17.14
-2,-1,20:17.14
-1,-1,20:18.2
0,-1,20:18.2
1,-1,20:18.2
2,-1,20:18.2
3,-1,20:18.2
4,-1,20:18.2
-6,0,20:18.2
-5,0,20:18.2
-4,0,20:18.2
-3,0,20:17.14
-2,0,20:17.14
-1,0,20:18.2
0,0,20:18.2
1,0,20:18.2
2,0,20:18.2
3,0,20:18.2
4,0,20:18.2
-4,1,20:18.2
-3,1,20:18.2
-2,1,20:18.2
-1,1,20:18.2
0,1,20:18.2
1,1,20:18.2
2,1,20:17.14
3,1,20:18.2
4,1,20:18.2
-4,2,20:18.2
-3,2,20:17.14
-2,2,20:18.2
-1,2,20:18.2
0,2,20:18.2
1,2,20:18.2
2,2,20:18.2
3,2,20:18.2
-5,3,20:18.2
-4,3,20:18.2
-3,3,20:18.2
-2,3,20:18.2
-1,3,20:18.2
0,3,20:18.2
1,3,20:18.2
2,3,20:18.2
3,3,20:18.2
-5,4,20:18.2
-4,4,20:17.14
-3,4,20:18.2
-2,4,20:18.2
-1,4,20:18.2
0,4,20:18.2
1,4,20:18.2
2,4,20:18.2
3,4,20:18.2
-4,5,20:18.2
-3,5,20:18.2
-2,5,20:18.2
-1,5,20:17.2
0,5,20:18.2
1,5,20:18.2
2,5,20:18.2
-4,6,20:18.2
-3,6,20:18.2
-2,6,20:18.2
-1,6,20:18.2
0,6,20:18.2
1,6,20:18.2
-2,7,20:18.2
-1,7,20:18.2
-6,-4,21:18.2
-5,-4,21:18.2
-4,-4,21:18.2
-3,-4,21:18.2
-2,-4,21:18.2
-1,-4,21:18.2
-7,-3,21:18.2
-6,-3,21:18.2
-5,-3,21:18.2
-4,-3,21:18.2
-3,-3,21:18.2
-2,-3,21:18.2
-1,-3,21:18.2
0,-3,21:18.2
-7,-2,21:18.2
-6,-2,21:18.2
-5,-2,21:18.2
-4,-2,21:18.2
-3,-2,21:18.2
-2,-2,21:18.2
-1,-2,21:18.2
0,-2,21:18.2
-7,-1,21:18.2
-6,-1,21:18.2
-5,-1,21:17.14
-4,-1,21:18.2
-3,-1,21:18.2
-2,-1,21:18.2
-1,-1,21:18.2
0,-1,21:18.2
1,-1,21:18.2
-6,0,21:18.2
-5,0,21:18.2
-4,0,21:18.2
-3,0,21:18.2
-2,0,21:18.2
-1,0,21:18.2
0,0,21:18.2
1,0,21:18.2
2,0,21:18.2
-4,1,21:18.2
-3,1,21:18.2
-2,1,21:18.2
-1,1,21:18.2
0,1,21:18.2
1,1,21:18.2
2,1,21:18.2
-4,2,21:18.2
-3,2,21:18.2
-2,2,21:18.2
-1,2,21:18.2
0,2,21:18.2
1,2,21:18.2
2,2,21:18.2
-4,3,21:18.2
-3,3,21:18.2
-2,3,21:18.2
-1,3,21:18.2
0,3,21:18.2
1,3,21:18.2
2,3,21:18.2
-4,4,21:18.2
-3,4,21:18.2
-2,4,21:18.2
-1,4,21:18.2
0,4,21:18.2
1,4,21:18.2
-4,5,21:18.2
-3,5,21:18.2
-2,5,21:18.2
-1,5,21:18.2
0,5,21:18.2
1,5,21:18.2
-3,6,21:18.2
-2,6,21:18.2
-1,6,21:18.2
0,6,21:18.2
-6,-4,22:18.2
-5,-4,22:18.2
-4,-4,22:18.2
-3,-4,22:18.2
-7,-3,22:18.2
-6,-3,22:18.2
-5,-3,22:18.2
-4,-3,22:17.14
-3,-3,22:18.2
-2,-3,22:18.2
-7,-2,22:18.2
-6,-2,22:18.2
-5,-2,22:18.2
-4,-2,22:18.2
-3,-2,22:18.2
-2,-2,22:18.2
-1,-2,22:18.2
-7,-1,22:18.2
-6,-1,22:18.2
-5,-1,22:18.2
-4,-1,22:18.2
-3,-1,22:18.2
-2,-1,22:18.2
-1,-1,22:18.2
0,-1,22:18.2
-6,0,22:18.2
-5,0,22:18.2
-4,0,22:18.2
-3,0,22:18.2
-2,0,22:18.2
-1,0,22:18.2
0,0,22:18.2
-4,1,22:18.2
-3,1,22:18.2
-2,1,22:18.2
-1,1,22:18.2
0,1,22:18.2
1,1,22:18.2
-4,2,22:18.2
-3,2,22:18.2
-2,2,22:18.2
-1,2,22:17.14
0,2,22:18.2
1,2,22:18.2
-3,3,22:18.2
-2,3,22:18.2
-1,3,22:18.2
0,3,22:18.2
-1,4,22:18.2
0,4,22:18.2
-6,-3,23:18.2
-5,-3,23:18.2
-4,-3,23:18.2
-3,-3,23:18.2
-2,-3,23:18.2
-6,-2,23:18.2
-5,-2,23:18.2
-4,-2,23:18.2
-3,-2,23:18.2
-2,-2,23:18.2
-1,-2,23:18.2
-6,-1,23:18.2
-5,-1,23:18.2
-4,-1,23:18.2
-3,-1,23:17.2
-2,-1,23:18.2
-1,-1,23:18.2
0,-1,23:18.2
-5,0,23:18.2
-4,0,23:18.2
-3,0,23:18.2
-2,0,23:18.2
-1,0,23:18.2
0,0,23:18.2
-4,1,23:18.2
-3,1,23:18.2
-2,1,23:18.2
-1,1,23:18.2
0,1,23:18.2
-3,2,23:18.2
-2,2,23:18.2
-1,2,23:18.2
-4,-2,24:18.2
-3,-2,24:18.2
-2,-2,24:18.2
-4,-1,24:18.2
-3,-1,24:18.2
-2,-1,24:18.2
-1,-1,24:18.2
-4,0,24:18.2
-3,0,24:18.2
-2,0,24:18.2
-1,0,24:18.2
-2,1,24:18.2
-1,1,24:18.2
