[META]
version=2.0
spawnOnBlockType=2
spawnSunlight=True
spawnDarkness=True
spawnWater=False
spawnLava=False
underFill=False
randomRotation=True
dig=True
tree=False
branch=False
needsFoundation=True
rarity=100
collisionPercentage=20
spawnElevationMin=0
spawnElevationMax=200
spawnInBiome=Custom
[DATA]
-3,-6,-4:17.15
-2,-6,-4:17.15
-3,-5,-4:17.15
-2,-5,-4:17.15
-3,-7,-3:17.15
-2,-7,-3:17.15
-4,-6,-3:17.15
-1,-6,-3:17.15
-4,-5,-3:17.15
-1,-5,-3:17.15
-3,-4,-3:17.15
-2,-4,-3:17.15
-3,-7,-2:17.15
-2,-7,-2:17.15
-4,-6,-2:17.15
-1,-6,-2:17.15
-4,-5,-2:17.15
-1,-5,-2:17.15
-3,-4,-2:17.15
-2,-4,-2:17.15
-3,-7,-1:17.15
-2,-7,-1:17.15
-4,-6,-1:17.15
-1,-6,-1:17.15
-4,-5,-1:17.15
-1,-5,-1:17.15
-3,-4,-1:17.15
-2,-4,-1:17.15
-3,-6,0:17.15
-2,-6,0:17.15
-4,-5,0:17.15
-1,-5,0:17.15
-4,-4,0:17.15
-1,-4,0:17.15
-3,-3,0:17.15
-2,-3,0:17.15
-3,-6,1:17.15
-2,-6,1:17.15
-4,-5,1:17.15
-1,-5,1:17.15
-4,-4,1:17.15
-1,-4,1:17.15
-3,-3,1:17.15
-2,-3,1:17.15
-3,-6,2:17.15
-2,-6,2:17.15
-4,-5,2:17.15
-1,-5,2:17.15
-4,-4,2:17.15
-1,-4,2:17.15
-3,-3,2:17.15
-2,-3,2:17.15
-3,-6,3:17.15
-2,-6,3:17.15
-4,-5,3:17.15
-1,-5,3:17.15
-4,-4,3:17.15
-1,-4,3:17.15
-3,-3,3:17.15
-2,-3,3:17.15
-3,-6,4:17.15
-2,-6,4:17.15
-4,-5,4:17.15
-1,-5,4:17.15
-4,-4,4:17.15
-1,-4,4:17.15
-3,-3,4:17.15
-2,-3,4:17.15
-3,-6,5:17.15
-2,-6,5:17.15
-4,-5,5:17.15
-1,-5,5:17.15
-4,-4,5:17.15
-1,-4,5:17.15
-3,-3,5:17.15
-2,-3,5:17.15
-3,-5,6:17.15
-2,-5,6:17.15
-4,-4,6:17.15
-1,-4,6:17.15
-4,-3,6:17.15
-1,-3,6:17.15
-3,-2,6:17.15
-2,-2,6:17.15
-3,-5,7:17.15
-2,-5,7:17.15
-4,-4,7:17.15
-1,-4,7:17.15
-4,-3,7:17.15
-1,-3,7:17.15
-3,-2,7:17.15
-2,-2,7:17.15
-3,-5,8:17.15
-2,-5,8:17.15
-4,-4,8:17.15
-1,-4,8:17.15
-4,-3,8:17.15
-1,-3,8:17.15
-3,-2,8:17.15
-2,-2,8:17.15
-3,-5,9:17.15
-2,-5,9:17.15
-4,-4,9:17.15
-1,-4,9:17.15
-4,-3,9:17.15
-1,-3,9:17.15
-3,-2,9:17.15
-2,-2,9:17.15
4,-6,10:18.3
5,-5,10:18.3
-3,-4,10:17.15
-2,-4,10:17.15
-4,-3,10:17.15
-1,-3,10:17.15
-4,-2,10:17.15
-1,-2,10:17.15
-3,-1,10:17.15
-2,-1,10:17.15
-1,8,10:18.3
0,8,10:18.3
3,-6,11:18.3
4,-6,11:18.3
5,-5,11:18.3
-3,-4,11:17.15
-2,-4,11:17.15
5,-4,11:18.3
-4,-3,11:17.15
-1,-3,11:17.15
-4,-2,11:17.15
-1,-2,11:17.15
-8,-1,11:18.3
-3,-1,11:17.15
-2,-1,11:17.15
-8,0,11:18.3
7,0,11:18.12
-7,5,11:18.3
5,5,11:18.3
-6,6,11:18.3
4,6,11:18.3
-2,8,11:18.3
-1,8,11:18.3
0,8,11:18.3
1,8,11:18.3
-1,-8,12:18.3
0,-8,12:18.3
-6,-6,12:18.3
3,-6,12:18.3
4,-6,12:18.3
-7,-5,12:18.3
4,-5,12:17.15
5,-5,12:18.3
5,-4,12:18.3
-3,-3,12:17.15
-2,-3,12:17.15
-8,-2,12:18.3
-4,-2,12:17.15
-1,-2,12:17.15
-8,-1,12:18.3
-4,-1,12:17.15
-1,-1,12:17.15
7,-1,12:18.3
-8,0,12:18.3
-3,0,12:17.15
-2,0,12:17.15
7,0,12:18.3
-8,1,12:18.3
7,1,12:18.3
-7,4,12:18.3
5,4,12:18.3
-7,5,12:18.3
5,5,12:18.3
-6,6,12:18.3
-5,6,12:18.3
3,6,12:18.3
4,6,12:18.3
-1,7,12:17.15
-2,8,12:18.3
-1,8,12:18.3
0,8,12:18.3
1,8,12:18.3
-2,-8,13:18.3
-1,-8,13:18.3
0,-8,13:18.3
1,-8,13:18.3
-6,-6,13:18.3
-5,-6,13:18.3
3,-6,13:18.3
4,-6,13:18.3
-7,-5,13:18.3
4,-5,13:17.15
5,-5,13:18.3
-7,-4,13:18.3
5,-4,13:18.3
-2,-3,13:17.15
-1,-3,13:17.15
-8,-2,13:18.3
-3,-2,13:17.15
0,-2,13:17.15
7,-2,13:18.3
-8,-1,13:18.3
-3,-1,13:17.15
0,-1,13:17.15
7,-1,13:18.3
-8,0,13:18.3
-2,0,13:17.15
-1,0,13:17.15
7,0,13:18.3
-8,1,13:18.3
7,1,13:18.3
-7,4,13:18.3
5,4,13:18.3
-7,5,13:18.3
5,5,13:18.3
-6,6,13:18.3
-5,6,13:18.3
3,6,13:18.3
4,6,13:18.3
-1,7,13:17.15
-2,8,13:18.3
-1,8,13:18.3
0,8,13:18.3
1,8,13:18.3
-2,-8,14:18.3
-1,-8,14:18.3
0,-8,14:18.3
1,-8,14:18.3
-6,-6,14:18.3
-5,-6,14:18.3
3,-6,14:18.3
4,-6,14:18.3
-7,-5,14:18.3
4,-5,14:17.15
5,-5,14:18.3
-7,-4,14:18.3
5,-4,14:18.3
-8,-2,14:18.3
-2,-2,14:17.15
-1,-2,14:17.15
0,-2,14:18.3
7,-2,14:18.3
-8,-1,14:17.15
-3,-1,14:17.15
-2,-1,14:17.15
-1,-1,14:17.15
0,-1,14:17.15
1,-1,14:18.3
7,-1,14:18.3
-8,0,14:18.3
-3,0,14:17.15
-2,0,14:17.15
-1,0,14:17.15
0,0,14:17.15
6,0,14:17.15
7,0,14:18.3
-8,1,14:18.3
-2,1,14:17.15
-1,1,14:18.3
0,1,14:18.3
7,1,14:18.3
-7,4,14:18.3
5,4,14:18.3
-7,5,14:18.3
-6,5,14:17.15
4,5,14:17.15
5,5,14:18.3
-6,6,14:18.3
-5,6,14:18.3
3,6,14:18.3
4,6,14:18.3
-1,7,14:17.15
-2,8,14:18.3
-1,8,14:18.3
0,8,14:18.3
1,8,14:18.3
-2,-8,15:18.3
-1,-8,15:17.15
0,-8,15:18.3
1,-8,15:18.3
-6,-6,15:18.3
-5,-6,15:18.3
3,-6,15:18.3
4,-6,15:18.3
-7,-5,15:18.3
-6,-5,15:17.15
4,-5,15:17.15
5,-5,15:18.3
-7,-4,15:18.3
5,-4,15:18.3
-8,-2,15:18.3
-2,-2,15:17.15
-1,-2,15:17.15
0,-2,15:18.3
7,-2,15:18.3
-8,-1,15:18.3
-7,-1,15:17.15
-3,-1,15:17.15
-2,-1,15:17.15
-1,-1,15:17.15
0,-1,15:17.15
1,-1,15:18.3
7,-1,15:18.3
-8,0,15:18.3
-3,0,15:17.15
-2,0,15:17.15
-1,0,15:17.15
0,0,15:17.15
6,0,15:17.15
7,0,15:18.3
-8,1,15:18.3
-3,1,15:18.3
-2,1,15:18.3
-1,1,15:18.3
0,1,15:18.3
7,1,15:18.3
-7,4,15:18.3
5,4,15:18.3
-7,5,15:18.3
-6,5,15:17.15
4,5,15:17.15
5,5,15:18.3
-6,6,15:18.3
-5,6,15:18.3
3,6,15:18.3
4,6,15:18.3
0,7,15:17.15
-2,8,15:18.3
-1,8,15:18.3
0,8,15:18.3
1,8,15:18.3
-2,-8,16:18.3
-1,-8,16:18.3
0,-8,16:18.3
1,-8,16:18.3
-1,-7,16:17.15
-6,-6,16:18.3
-5,-6,16:18.3
-7,-5,16:18.3
-6,-5,16:17.15
3,-5,16:18.3
4,-5,16:18.3
-7,-4,16:18.3
1,-4,16:18.3
2,-4,16:18.3
3,-4,16:18.3
4,-4,16:18.3
1,-3,16:18.3
2,-3,16:17.15
3,-3,16:18.3
-8,-2,16:18.3
-2,-2,16:18.3
0,-2,16:18.3
1,-2,16:18.3
2,-2,16:18.3
3,-2,16:18.3
7,-2,16:18.3
-8,-1,16:18.3
-3,-1,16:18.3
-2,-1,16:18.3
-1,-1,16:18.3
0,-1,16:18.3
1,-1,16:18.3
7,-1,16:18.3
-8,0,16:18.3
-7,0,16:17.15
-3,0,16:18.3
-2,0,16:18.3
-1,0,16:17.15
0,0,16:18.3
6,0,16:17.15
7,0,16:18.3
-8,1,16:18.3
-3,1,16:18.3
-2,1,16:17.15
-1,1,16:18.3
0,1,16:18.3
7,1,16:18.3
-7,4,16:18.3
5,4,16:18.3
-7,5,16:18.3
-6,5,16:17.15
4,5,16:17.15
5,5,16:18.3
-6,6,16:18.3
-5,6,16:18.3
3,6,16:18.3
4,6,16:18.3
0,7,16:17.15
-2,8,16:18.3
-1,8,16:18.3
0,8,16:18.3
1,8,16:18.3
-2,-8,17:18.3
-1,-8,17:18.3
0,-8,17:18.3
1,-8,17:18.3
-1,-7,17:17.15
-6,-6,17:18.3
-5,-6,17:18.3
-7,-5,17:18.3
-6,-5,17:17.15
-7,-4,17:18.3
-8,-2,17:18.3
-2,-2,17:18.3
7,-2,17:18.3
-8,-1,17:18.3
-4,-1,17:18.3
-3,-1,17:18.3
-2,-1,17:17.15
-1,-1,17:18.3
0,-1,17:18.3
6,-1,17:17.15
7,-1,17:18.3
-8,0,17:18.3
-7,0,17:17.15
-4,0,17:18.3
-3,0,17:18.3
0,0,17:18.3
7,0,17:18.3
-8,1,17:18.3
-3,1,17:18.3
0,1,17:17.15
1,1,17:18.3
7,1,17:18.3
-5,2,17:18.3
-4,2,17:18.3
-3,2,17:18.3
-2,2,17:18.3
-1,2,17:18.3
0,2,17:18.3
1,2,17:18.3
-6,3,17:18.3
-5,3,17:18.3
-4,3,17:18.3
-3,3,17:18.3
-1,3,17:18.3
0,3,17:18.3
-6,4,17:18.3
-5,4,17:17.15
-4,4,17:18.3
-3,4,17:18.3
5,4,17:18.3
-6,5,17:18.3
-5,5,17:18.3
-4,5,17:18.3
4,5,17:17.15
5,5,17:18.3
3,6,17:18.3
4,6,17:18.3
-2,7,17:18.3
-1,7,17:18.3
0,7,17:18.3
1,7,17:18.3
-2,-8,18:18.3
-1,-8,18:18.3
0,-8,18:18.3
1,-8,18:18.3
0,-7,18:17.15
-6,-5,18:18.3
-5,-5,18:18.3
-4,-5,18:18.3
-6,-4,18:18.3
-5,-4,18:18.3
-4,-4,18:18.3
-3,-4,18:18.3
-6,-3,18:18.3
-5,-3,18:18.3
-4,-3,18:17.15
-3,-3,18:18.3
-7,-2,18:18.3
-6,-2,18:18.3
-5,-2,18:18.3
-4,-2,18:18.3
-3,-2,18:18.3
-2,-2,18:18.3
-1,-2,18:18.3
0,-2,18:18.3
7,-2,18:18.3
-7,-1,18:18.3
-6,-1,18:17.15
-5,-1,18:18.3
-3,-1,18:18.3
-1,-1,18:18.3
0,-1,18:17.15
1,-1,18:18.3
6,-1,18:17.15
7,-1,18:18.3
-7,0,18:18.3
-6,0,18:18.3
-5,0,18:18.3
0,0,18:18.3
1,0,18:18.3
7,0,18:18.3
-7,1,18:18.3
-6,1,18:18.3
1,1,18:18.3
7,1,18:18.3
0,2,18:18.3
1,2,18:18.3
2,2,18:18.3
3,2,18:18.3
1,3,18:18.3
2,3,18:17.15
3,3,18:18.3
4,3,18:18.3
-1,4,18:18.3
0,4,18:18.3
1,4,18:18.3
2,4,18:18.3
3,4,18:18.3
4,4,18:18.3
-2,5,18:18.3
-1,5,18:18.3
0,5,18:17.15
1,5,18:18.3
2,5,18:18.3
3,5,18:18.3
4,5,18:18.3
-2,6,18:18.3
-1,6,18:18.3
0,6,18:18.3
1,6,18:18.3
-2,-7,19:18.3
-1,-7,19:18.3
0,-7,19:18.3
1,-7,19:18.3
-1,-3,19:18.3
0,-3,19:18.3
-1,-2,19:18.3
0,-2,19:18.3
6,-2,19:18.3
1,-1,19:18.3
2,-1,19:18.3
6,-1,19:18.3
1,0,19:18.3
2,0,19:18.3
6,0,19:18.3
6,1,19:18.3
-2,-6,20:18.3
-1,-6,20:17.15
0,-6,20:18.3
1,-6,20:18.3
-2,-5,20:18.3
-1,-5,20:18.3
0,-5,20:18.3
1,-5,20:18.3
-1,-4,20:18.3
0,-4,20:18.3
4,-2,20:18.3
5,-2,20:18.3
3,-1,20:18.3
4,-1,20:18.3
5,-1,20:18.3
3,0,20:18.3
4,0,20:18.3
5,0,20:17.15
4,1,20:18.3
5,1,20:18.3
