[META]
version=2.0
spawnOnBlockType=2
spawnSunlight=True
spawnDarkness=True
spawnWater=False
spawnLava=False
underFill=False
randomRotation=True
dig=True
tree=False
branch=False
needsFoundation=True
rarity=100
collisionPercentage=20
spawnElevationMin=0
spawnElevationMax=200
spawnInBiome=Custom
[DATA]
-1,-1,-4:17.15
0,-1,-4:17.15
-1,0,-4:17.15
0,0,-4:17.15
-1,-2,-3:17.15
0,-2,-3:17.15
-2,-1,-3:17.15
1,-1,-3:17.15
-2,0,-3:17.15
1,0,-3:17.15
-1,1,-3:17.15
0,1,-3:17.15
-1,-2,-2:17.15
0,-2,-2:17.15
-2,-1,-2:17.15
1,-1,-2:17.15
-2,0,-2:17.15
1,0,-2:17.15
-1,1,-2:17.15
0,1,-2:17.15
-1,-2,-1:17.15
0,-2,-1:17.15
-2,-1,-1:17.15
1,-1,-1:17.15
-2,0,-1:17.15
0,0,-1:17.15
1,0,-1:17.15
-1,1,-1:17.15
0,1,-1:17.15
-2,-3,0:17.15
-1,-3,0:17.15
-3,-2,0:17.15
-2,-2,0:17.15
0,-2,0:17.15
-3,-1,0:17.15
0,-1,0:17.15
-2,0,0:17.15
-1,0,0:17.15
-2,-3,1:17.15
-1,-3,1:17.15
-3,-2,1:17.15
0,-2,1:17.15
-3,-1,1:17.15
0,-1,1:17.15
-2,0,1:17.15
-1,0,1:17.15
-2,-3,2:17.15
-1,-3,2:17.15
-3,-2,2:17.15
0,-2,2:17.15
-3,-1,2:17.15
0,-1,2:17.15
-2,0,2:17.15
-1,0,2:17.15
-2,-3,3:17.15
-1,-3,3:17.15
-3,-2,3:17.15
0,-2,3:17.15
-3,-1,3:17.15
0,-1,3:17.15
-2,0,3:17.15
-1,0,3:17.15
-2,-3,4:17.15
-1,-3,4:17.15
-3,-2,4:17.15
0,-2,4:17.15
-3,-1,4:17.15
0,-1,4:17.15
-2,0,4:17.15
-1,0,4:17.15
-3,-3,5:17.15
-2,-3,5:17.15
-4,-2,5:17.15
-1,-2,5:17.15
-4,-1,5:17.15
-1,-1,5:17.15
-3,0,5:17.15
-2,0,5:17.15
4,-6,6:18.3
5,-5,6:18.3
-3,-3,6:17.15
-2,-3,6:17.15
-4,-2,6:17.15
-1,-2,6:17.15
-4,-1,6:17.15
-1,-1,6:17.15
-3,0,6:17.15
-2,0,6:17.15
-1,8,6:18.3
0,8,6:18.3
3,-6,7:18.3
4,-6,7:18.3
5,-5,7:18.3
5,-4,7:18.3
-3,-3,7:17.15
-2,-3,7:17.15
-4,-2,7:17.15
-1,-2,7:17.15
-8,-1,7:18.3
-4,-1,7:17.15
-1,-1,7:17.15
-8,0,7:18.3
-3,0,7:17.15
-2,0,7:17.15
7,0,7:18.12
-7,5,7:18.3
5,5,7:18.3
-6,6,7:18.3
4,6,7:18.3
-2,8,7:18.3
-1,8,7:18.3
0,8,7:18.3
1,8,7:18.3
-1,-8,8:18.3
0,-8,8:18.3
-6,-6,8:18.3
3,-6,8:18.3
4,-6,8:18.3
-7,-5,8:18.3
4,-5,8:17.15
5,-5,8:18.3
5,-4,8:18.3
-3,-3,8:17.15
-2,-3,8:17.15
-8,-2,8:18.3
-4,-2,8:17.15
-1,-2,8:17.15
-8,-1,8:18.3
-4,-1,8:17.15
-1,-1,8:17.15
7,-1,8:18.3
-8,0,8:18.3
-3,0,8:17.15
-2,0,8:17.15
7,0,8:18.3
-8,1,8:18.3
7,1,8:18.3
-7,4,8:18.3
5,4,8:18.3
-7,5,8:18.3
5,5,8:18.3
-6,6,8:18.3
-5,6,8:18.3
3,6,8:18.3
4,6,8:18.3
-1,7,8:17.15
-2,8,8:18.3
-1,8,8:18.3
0,8,8:18.3
1,8,8:18.3
-2,-8,9:18.3
-1,-8,9:18.3
0,-8,9:18.3
1,-8,9:18.3
-6,-6,9:18.3
-5,-6,9:18.3
3,-6,9:18.3
4,-6,9:18.3
-7,-5,9:18.3
4,-5,9:17.15
5,-5,9:18.3
-7,-4,9:18.3
5,-4,9:18.3
-2,-3,9:17.15
-1,-3,9:17.15
-8,-2,9:18.3
-3,-2,9:17.15
0,-2,9:17.15
7,-2,9:18.3
-8,-1,9:18.3
-3,-1,9:17.15
0,-1,9:17.15
7,-1,9:18.3
-8,0,9:18.3
-2,0,9:17.15
-1,0,9:17.15
7,0,9:18.3
-8,1,9:18.3
7,1,9:18.3
-7,4,9:18.3
5,4,9:18.3
-7,5,9:18.3
5,5,9:18.3
-6,6,9:18.3
-5,6,9:18.3
3,6,9:18.3
4,6,9:18.3
-1,7,9:17.15
-2,8,9:18.3
-1,8,9:18.3
0,8,9:18.3
1,8,9:18.3
-2,-8,10:18.3
-1,-8,10:18.3
0,-8,10:18.3
1,-8,10:18.3
-6,-6,10:18.3
-5,-6,10:18.3
3,-6,10:18.3
4,-6,10:18.3
-7,-5,10:18.3
4,-5,10:17.15
5,-5,10:18.3
-7,-4,10:18.3
5,-4,10:18.3
-8,-2,10:18.3
-2,-2,10:17.15
-1,-2,10:17.15
0,-2,10:18.3
7,-2,10:18.3
-8,-1,10:17.15
-3,-1,10:17.15
-2,-1,10:17.15
-1,-1,10:17.15
0,-1,10:17.15
1,-1,10:18.3
7,-1,10:18.3
-8,0,10:18.3
-3,0,10:17.15
-2,0,10:17.15
-1,0,10:17.15
0,0,10:17.15
6,0,10:17.15
7,0,10:18.3
-8,1,10:18.3
-2,1,10:17.15
-1,1,10:18.3
0,1,10:18.3
7,1,10:18.3
-7,4,10:18.3
5,4,10:18.3
-7,5,10:18.3
-6,5,10:17.15
4,5,10:17.15
5,5,10:18.3
-6,6,10:18.3
-5,6,10:18.3
3,6,10:18.3
4,6,10:18.3
-1,7,10:17.15
-2,8,10:18.3
-1,8,10:18.3
0,8,10:18.3
1,8,10:18.3
-2,-8,11:18.3
-1,-8,11:17.15
0,-8,11:18.3
1,-8,11:18.3
-6,-6,11:18.3
-5,-6,11:18.3
3,-6,11:18.3
4,-6,11:18.3
-7,-5,11:18.3
-6,-5,11:17.15
4,-5,11:17.15
5,-5,11:18.3
-7,-4,11:18.3
5,-4,11:18.3
-8,-2,11:18.3
-2,-2,11:17.15
-1,-2,11:17.15
0,-2,11:18.3
7,-2,11:18.3
-8,-1,11:18.3
-7,-1,11:17.15
-3,-1,11:17.15
-2,-1,11:17.15
-1,-1,11:17.15
0,-1,11:17.15
1,-1,11:18.3
7,-1,11:18.3
-8,0,11:18.3
-3,0,11:17.15
-2,0,11:17.15
-1,0,11:17.15
0,0,11:17.15
6,0,11:17.15
7,0,11:18.3
-8,1,11:18.3
-3,1,11:18.3
-2,1,11:18.3
-1,1,11:18.3
0,1,11:18.3
7,1,11:18.3
-7,4,11:18.3
5,4,11:18.3
-7,5,11:18.3
-6,5,11:17.15
4,5,11:17.15
5,5,11:18.3
-6,6,11:18.3
-5,6,11:18.3
3,6,11:18.3
4,6,11:18.3
0,7,11:17.15
-2,8,11:18.3
-1,8,11:18.3
0,8,11:18.3
1,8,11:18.3
-2,-8,12:18.3
-1,-8,12:18.3
0,-8,12:18.3
1,-8,12:18.3
-1,-7,12:17.15
-6,-6,12:18.3
-5,-6,12:18.3
-7,-5,12:18.3
-6,-5,12:17.15
3,-5,12:18.3
4,-5,12:18.3
-7,-4,12:18.3
1,-4,12:18.3
2,-4,12:18.3
3,-4,12:18.3
4,-4,12:18.3
1,-3,12:18.3
2,-3,12:17.15
3,-3,12:18.3
-8,-2,12:18.3
-2,-2,12:18.3
0,-2,12:18.3
1,-2,12:18.3
2,-2,12:18.3
3,-2,12:18.3
7,-2,12:18.3
-8,-1,12:18.3
-3,-1,12:18.3
-2,-1,12:18.3
-1,-1,12:18.3
0,-1,12:18.3
1,-1,12:18.3
7,-1,12:18.3
-8,0,12:18.3
-7,0,12:17.15
-3,0,12:18.3
-2,0,12:18.3
-1,0,12:17.15
0,0,12:18.3
6,0,12:17.15
7,0,12:18.3
-8,1,12:18.3
-3,1,12:18.3
-2,1,12:17.15
-1,1,12:18.3
0,1,12:18.3
7,1,12:18.3
-7,4,12:18.3
5,4,12:18.3
-7,5,12:18.3
-6,5,12:17.15
4,5,12:17.15
5,5,12:18.3
-6,6,12:18.3
-5,6,12:18.3
3,6,12:18.3
4,6,12:18.3
0,7,12:17.15
-2,8,12:18.3
-1,8,12:18.3
0,8,12:18.3
1,8,12:18.3
-2,-8,13:18.3
-1,-8,13:18.3
0,-8,13:18.3
1,-8,13:18.3
-1,-7,13:17.15
-6,-6,13:18.3
-5,-6,13:18.3
-7,-5,13:18.3
-6,-5,13:17.15
-7,-4,13:18.3
-8,-2,13:18.3
-2,-2,13:18.3
7,-2,13:18.3
-8,-1,13:18.3
-4,-1,13:18.3
-3,-1,13:18.3
-2,-1,13:17.15
-1,-1,13:18.3
0,-1,13:18.3
6,-1,13:17.15
7,-1,13:18.3
-8,0,13:18.3
-7,0,13:17.15
-4,0,13:18.3
-3,0,13:18.3
0,0,13:18.3
7,0,13:18.3
-8,1,13:18.3
-3,1,13:18.3
0,1,13:17.15
1,1,13:18.3
7,1,13:18.3
-5,2,13:18.3
-4,2,13:18.3
-3,2,13:18.3
-2,2,13:18.3
-1,2,13:18.3
0,2,13:18.3
1,2,13:18.3
-6,3,13:18.3
-5,3,13:18.3
-4,3,13:18.3
-3,3,13:18.3
-1,3,13:18.3
0,3,13:18.3
-6,4,13:18.3
-5,4,13:17.15
-4,4,13:18.3
-3,4,13:18.3
5,4,13:18.3
-6,5,13:18.3
-5,5,13:18.3
-4,5,13:18.3
4,5,13:17.15
5,5,13:18.3
3,6,13:18.3
4,6,13:18.3
-2,7,13:18.3
-1,7,13:18.3
0,7,13:18.3
1,7,13:18.3
-2,-8,14:18.3
-1,-8,14:18.3
0,-8,14:18.3
1,-8,14:18.3
0,-7,14:17.15
-6,-5,14:18.3
-5,-5,14:18.3
-4,-5,14:18.3
-6,-4,14:18.3
-5,-4,14:18.3
-4,-4,14:18.3
-3,-4,14:18.3
-6,-3,14:18.3
-5,-3,14:18.3
-4,-3,14:17.15
-3,-3,14:18.3
-7,-2,14:18.3
-6,-2,14:18.3
-5,-2,14:18.3
-4,-2,14:18.3
-3,-2,14:18.3
-2,-2,14:18.3
-1,-2,14:18.3
0,-2,14:18.3
7,-2,14:18.3
-7,-1,14:18.3
-6,-1,14:17.15
-5,-1,14:18.3
-3,-1,14:18.3
-1,-1,14:18.3
0,-1,14:17.15
1,-1,14:18.3
6,-1,14:17.15
7,-1,14:18.3
-7,0,14:18.3
-6,0,14:18.3
-5,0,14:18.3
0,0,14:18.3
1,0,14:18.3
7,0,14:18.3
-7,1,14:18.3
-6,1,14:18.3
1,1,14:18.3
7,1,14:18.3
0,2,14:18.3
1,2,14:18.3
2,2,14:18.3
3,2,14:18.3
1,3,14:18.3
2,3,14:17.15
3,3,14:18.3
4,3,14:18.3
-1,4,14:18.3
0,4,14:18.3
1,4,14:18.3
2,4,14:18.3
3,4,14:18.3
4,4,14:18.3
-2,5,14:18.3
-1,5,14:18.3
0,5,14:17.15
1,5,14:18.3
2,5,14:18.3
3,5,14:18.3
4,5,14:18.3
-2,6,14:18.3
-1,6,14:18.3
0,6,14:18.3
1,6,14:18.3
-2,-7,15:18.3
-1,-7,15:18.3
0,-7,15:18.3
1,-7,15:18.3
-1,-3,15:18.3
0,-3,15:18.3
-1,-2,15:18.3
0,-2,15:18.3
6,-2,15:18.3
1,-1,15:18.3
2,-1,15:18.3
6,-1,15:18.3
1,0,15:18.3
2,0,15:18.3
6,0,15:18.3
6,1,15:18.3
-2,-6,16:18.3
-1,-6,16:17.15
0,-6,16:18.3
1,-6,16:18.3
-2,-5,16:18.3
-1,-5,16:18.3
0,-5,16:18.3
1,-5,16:18.3
-1,-4,16:18.3
0,-4,16:18.3
4,-2,16:18.3
5,-2,16:18.3
3,-1,16:18.3
4,-1,16:18.3
5,-1,16:18.3
3,0,16:18.3
4,0,16:18.3
5,0,16:17.15
4,1,16:18.3
5,1,16:18.3
