[META]
version=2.0
spawnOnBlockType=2
spawnSunlight=True
spawnDarkness=True
spawnWater=False
spawnLava=False
underFill=False
randomRotation=True
dig=True
tree=False
branch=False
needsFoundation=True
rarity=100
collisionPercentage=20
spawnElevationMin=0
spawnElevationMax=200
spawnInBiome=Custom
[DATA]
-7,-5,-4:17.15
-6,-5,-4:17.15
-7,-4,-4:17.15
-6,-4,-4:17.15
-7,-6,-3:17.15
-6,-6,-3:17.15
-8,-5,-3:17.15
-5,-5,-3:17.15
-8,-4,-3:17.15
-5,-4,-3:17.15
-7,-3,-3:17.15
-6,-3,-3:17.15
-7,-6,-2:17.15
-6,-6,-2:17.15
-8,-5,-2:17.15
-5,-5,-2:17.15
-8,-4,-2:17.15
-5,-4,-2:17.15
-7,-3,-2:17.15
-6,-3,-2:17.15
-7,-6,-1:17.15
-6,-6,-1:17.15
-8,-5,-1:17.15
-5,-5,-1:17.15
-8,-4,-1:17.15
-5,-4,-1:17.15
-7,-3,-1:17.15
-6,-3,-1:17.15
-6,-6,0:17.15
-5,-6,0:17.15
-7,-5,0:17.15
-4,-5,0:17.15
-7,-4,0:17.15
-4,-4,0:17.15
-6,-3,0:17.15
-5,-3,0:17.15
-6,-6,1:17.15
-5,-6,1:17.15
-7,-5,1:17.15
-4,-5,1:17.15
-7,-4,1:17.15
-4,-4,1:17.15
-6,-3,1:17.15
-5,-3,1:17.15
-6,-6,2:17.15
-5,-6,2:17.15
-7,-5,2:17.15
-4,-5,2:17.15
-7,-4,2:17.15
-4,-4,2:17.15
-6,-3,2:17.15
-5,-3,2:17.15
-6,-6,3:17.15
-5,-6,3:17.15
-7,-5,3:17.15
-6,-5,3:17.15
-4,-5,3:17.15
-7,-4,3:17.15
-4,-4,3:17.15
-6,-3,3:17.15
-5,-3,3:17.15
-5,-5,4:17.15
-4,-5,4:17.15
-6,-4,4:17.15
-3,-4,4:17.15
-6,-3,4:17.15
-4,-3,4:17.15
-3,-3,4:17.15
-5,-2,4:17.15
-4,-2,4:17.15
-5,-5,5:17.15
-4,-5,5:17.15
-6,-4,5:17.15
-3,-4,5:17.15
-6,-3,5:17.15
-3,-3,5:17.15
-5,-2,5:17.15
-4,-2,5:17.15
-5,-5,6:17.15
-4,-5,6:17.15
-6,-4,6:17.15
-3,-4,6:17.15
-6,-3,6:17.15
-3,-3,6:17.15
-5,-2,6:17.15
-4,-2,6:17.15
-4,-5,7:17.15
-3,-5,7:17.15
-5,-4,7:17.15
-2,-4,7:17.15
-5,-3,7:17.15
-2,-3,7:17.15
-4,-2,7:17.15
-3,-2,7:17.15
-4,-5,8:17.15
-3,-5,8:17.15
-5,-4,8:17.15
-2,-4,8:17.15
-5,-3,8:17.15
-2,-3,8:17.15
-4,-2,8:17.15
-3,-2,8:17.15
-4,-5,9:17.15
-3,-5,9:17.15
-5,-4,9:17.15
-4,-4,9:17.15
-2,-4,9:17.15
-5,-3,9:17.15
-2,-3,9:17.15
-4,-2,9:17.15
-3,-2,9:17.15
-3,-4,10:17.15
-2,-4,10:17.15
-4,-3,10:17.15
-2,-3,10:17.15
-1,-3,10:17.15
-4,-2,10:17.15
-2,-2,10:17.15
-1,-2,10:17.15
-3,-1,10:17.15
-2,-1,10:17.15
-3,-4,11:17.15
-2,-4,11:17.15
-4,-3,11:17.15
-1,-3,11:17.15
-4,-2,11:17.15
-1,-2,11:17.15
-3,-1,11:17.15
-2,-1,11:17.15
5,-6,12:18.3
6,-5,12:18.3
-2,-4,12:17.15
-1,-4,12:17.15
-3,-3,12:17.15
0,-3,12:17.15
-3,-2,12:17.15
0,-2,12:17.15
-2,-1,12:17.15
-1,-1,12:17.15
0,8,12:18.3
1,8,12:18.3
4,-6,13:18.3
5,-6,13:18.3
6,-5,13:18.3
-2,-4,13:17.15
-1,-4,13:17.15
6,-4,13:18.3
-3,-3,13:17.15
0,-3,13:17.15
-3,-2,13:17.15
0,-2,13:17.15
-7,-1,13:18.3
-2,-1,13:17.15
-1,-1,13:17.15
-7,0,13:18.3
8,0,13:18.12
-6,5,13:18.3
6,5,13:18.3
-5,6,13:18.3
5,6,13:18.3
-1,8,13:18.3
0,8,13:18.3
1,8,13:18.3
2,8,13:18.3
0,-8,14:18.3
1,-8,14:18.3
-5,-6,14:18.3
4,-6,14:18.3
5,-6,14:18.3
-6,-5,14:18.3
5,-5,14:17.15
6,-5,14:18.3
6,-4,14:18.3
-2,-3,14:17.15
-1,-3,14:17.15
-7,-2,14:18.3
-3,-2,14:17.15
0,-2,14:17.15
-7,-1,14:18.3
-3,-1,14:17.15
0,-1,14:17.15
8,-1,14:18.3
-7,0,14:18.3
-2,0,14:17.15
-1,0,14:17.15
8,0,14:18.3
-7,1,14:18.3
8,1,14:18.3
-6,4,14:18.3
6,4,14:18.3
-6,5,14:18.3
6,5,14:18.3
-5,6,14:18.3
-4,6,14:18.3
4,6,14:18.3
5,6,14:18.3
0,7,14:17.15
-1,8,14:18.3
0,8,14:18.3
1,8,14:18.3
2,8,14:18.3
-1,-8,15:18.3
0,-8,15:18.3
1,-8,15:18.3
2,-8,15:18.3
-5,-6,15:18.3
-4,-6,15:18.3
4,-6,15:18.3
5,-6,15:18.3
-6,-5,15:18.3
5,-5,15:17.15
6,-5,15:18.3
-6,-4,15:18.3
6,-4,15:18.3
-1,-3,15:17.15
0,-3,15:17.15
-7,-2,15:18.3
-2,-2,15:17.15
1,-2,15:17.15
8,-2,15:18.3
-7,-1,15:18.3
-2,-1,15:17.15
1,-1,15:17.15
8,-1,15:18.3
-7,0,15:18.3
-1,0,15:17.15
0,0,15:17.15
8,0,15:18.3
-7,1,15:18.3
8,1,15:18.3
-6,4,15:18.3
6,4,15:18.3
-6,5,15:18.3
6,5,15:18.3
-5,6,15:18.3
-4,6,15:18.3
4,6,15:18.3
5,6,15:18.3
0,7,15:17.15
-1,8,15:18.3
0,8,15:18.3
1,8,15:18.3
2,8,15:18.3
-1,-8,16:18.3
0,-8,16:18.3
1,-8,16:18.3
2,-8,16:18.3
-5,-6,16:18.3
-4,-6,16:18.3
4,-6,16:18.3
5,-6,16:18.3
-6,-5,16:18.3
5,-5,16:17.15
6,-5,16:18.3
-6,-4,16:18.3
6,-4,16:18.3
-7,-2,16:18.3
-1,-2,16:17.15
0,-2,16:17.15
1,-2,16:18.3
8,-2,16:18.3
-7,-1,16:17.15
-2,-1,16:17.15
-1,-1,16:17.15
0,-1,16:17.15
1,-1,16:17.15
2,-1,16:18.3
8,-1,16:18.3
-7,0,16:18.3
-2,0,16:17.15
-1,0,16:17.15
0,0,16:17.15
1,0,16:17.15
7,0,16:17.15
8,0,16:18.3
-7,1,16:18.3
-1,1,16:17.15
0,1,16:18.3
1,1,16:18.3
8,1,16:18.3
-6,4,16:18.3
6,4,16:18.3
-6,5,16:18.3
-5,5,16:17.15
5,5,16:17.15
6,5,16:18.3
-5,6,16:18.3
-4,6,16:18.3
4,6,16:18.3
5,6,16:18.3
0,7,16:17.15
-1,8,16:18.3
0,8,16:18.3
1,8,16:18.3
2,8,16:18.3
-1,-8,17:18.3
0,-8,17:17.15
1,-8,17:18.3
2,-8,17:18.3
-5,-6,17:18.3
-4,-6,17:18.3
4,-6,17:18.3
5,-6,17:18.3
-6,-5,17:18.3
-5,-5,17:17.15
5,-5,17:17.15
6,-5,17:18.3
-6,-4,17:18.3
6,-4,17:18.3
-7,-2,17:18.3
-1,-2,17:17.15
0,-2,17:17.15
1,-2,17:18.3
8,-2,17:18.3
-7,-1,17:18.3
-6,-1,17:17.15
-2,-1,17:17.15
-1,-1,17:17.15
0,-1,17:17.15
1,-1,17:17.15
2,-1,17:18.3
8,-1,17:18.3
-7,0,17:18.3
-2,0,17:17.15
-1,0,17:17.15
0,0,17:17.15
1,0,17:17.15
7,0,17:17.15
8,0,17:18.3
-7,1,17:18.3
-2,1,17:18.3
-1,1,17:18.3
0,1,17:18.3
1,1,17:18.3
8,1,17:18.3
-6,4,17:18.3
6,4,17:18.3
-6,5,17:18.3
-5,5,17:17.15
5,5,17:17.15
6,5,17:18.3
-5,6,17:18.3
-4,6,17:18.3
4,6,17:18.3
5,6,17:18.3
1,7,17:17.15
-1,8,17:18.3
0,8,17:18.3
1,8,17:18.3
2,8,17:18.3
-1,-8,18:18.3
0,-8,18:18.3
1,-8,18:18.3
2,-8,18:18.3
0,-7,18:17.15
-5,-6,18:18.3
-4,-6,18:18.3
-6,-5,18:18.3
-5,-5,18:17.15
4,-5,18:18.3
5,-5,18:18.3
-6,-4,18:18.3
2,-4,18:18.3
3,-4,18:18.3
4,-4,18:18.3
5,-4,18:18.3
2,-3,18:18.3
3,-3,18:17.15
4,-3,18:18.3
-7,-2,18:18.3
-1,-2,18:18.3
1,-2,18:18.3
2,-2,18:18.3
3,-2,18:18.3
4,-2,18:18.3
8,-2,18:18.3
-7,-1,18:18.3
-2,-1,18:18.3
-1,-1,18:18.3
0,-1,18:18.3
1,-1,18:18.3
2,-1,18:18.3
8,-1,18:18.3
-7,0,18:18.3
-6,0,18:17.15
-2,0,18:18.3
-1,0,18:18.3
0,0,18:17.15
1,0,18:18.3
7,0,18:17.15
8,0,18:18.3
-7,1,18:18.3
-2,1,18:18.3
-1,1,18:17.15
0,1,18:18.3
1,1,18:18.3
8,1,18:18.3
-6,4,18:18.3
6,4,18:18.3
-6,5,18:18.3
-5,5,18:17.15
5,5,18:17.15
6,5,18:18.3
-5,6,18:18.3
-4,6,18:18.3
4,6,18:18.3
5,6,18:18.3
1,7,18:17.15
-1,8,18:18.3
0,8,18:18.3
1,8,18:18.3
2,8,18:18.3
-1,-8,19:18.3
0,-8,19:18.3
1,-8,19:18.3
2,-8,19:18.3
0,-7,19:17.15
-5,-6,19:18.3
-4,-6,19:18.3
-6,-5,19:18.3
-5,-5,19:17.15
-6,-4,19:18.3
-7,-2,19:18.3
-1,-2,19:18.3
8,-2,19:18.3
-7,-1,19:18.3
-3,-1,19:18.3
-2,-1,19:18.3
-1,-1,19:17.15
0,-1,19:18.3
1,-1,19:18.3
7,-1,19:17.15
8,-1,19:18.3
-7,0,19:18.3
-6,0,19:17.15
-3,0,19:18.3
-2,0,19:18.3
1,0,19:18.3
8,0,19:18.3
-7,1,19:18.3
-2,1,19:18.3
1,1,19:17.15
2,1,19:18.3
8,1,19:18.3
-4,2,19:18.3
-3,2,19:18.3
-2,2,19:18.3
-1,2,19:18.3
0,2,19:18.3
1,2,19:18.3
2,2,19:18.3
-5,3,19:18.3
-4,3,19:18.3
-3,3,19:18.3
-2,3,19:18.3
0,3,19:18.3
1,3,19:18.3
-5,4,19:18.3
-4,4,19:17.15
-3,4,19:18.3
-2,4,19:18.3
6,4,19:18.3
-5,5,19:18.3
-4,5,19:18.3
-3,5,19:18.3
5,5,19:17.15
6,5,19:18.3
4,6,19:18.3
5,6,19:18.3
-1,7,19:18.3
0,7,19:18.3
1,7,19:18.3
2,7,19:18.3
-1,-8,20:18.3
0,-8,20:18.3
1,-8,20:18.3
2,-8,20:18.3
1,-7,20:17.15
-5,-5,20:18.3
-4,-5,20:18.3
-3,-5,20:18.3
-5,-4,20:18.3
-4,-4,20:18.3
-3,-4,20:18.3
-2,-4,20:18.3
-5,-3,20:18.3
-4,-3,20:18.3
-3,-3,20:17.15
-2,-3,20:18.3
-6,-2,20:18.3
-5,-2,20:18.3
-4,-2,20:18.3
-3,-2,20:18.3
-2,-2,20:18.3
-1,-2,20:18.3
0,-2,20:18.3
1,-2,20:18.3
8,-2,20:18.3
-6,-1,20:18.3
-5,-1,20:17.15
-4,-1,20:18.3
-2,-1,20:18.3
0,-1,20:18.3
1,-1,20:17.15
2,-1,20:18.3
7,-1,20:17.15
8,-1,20:18.3
-6,0,20:18.3
-5,0,20:18.3
-4,0,20:18.3
1,0,20:18.3
2,0,20:18.3
8,0,20:18.3
-6,1,20:18.3
-5,1,20:18.3
2,1,20:18.3
8,1,20:18.3
1,2,20:18.3
2,2,20:18.3
3,2,20:18.3
4,2,20:18.3
2,3,20:18.3
3,3,20:17.15
4,3,20:18.3
5,3,20:18.3
0,4,20:18.3
1,4,20:18.3
2,4,20:18.3
3,4,20:18.3
4,4,20:18.3
5,4,20:18.3
-1,5,20:18.3
0,5,20:18.3
1,5,20:17.15
2,5,20:18.3
3,5,20:18.3
4,5,20:18.3
5,5,20:18.3
-1,6,20:18.3
0,6,20:18.3
1,6,20:18.3
2,6,20:18.3
-1,-7,21:18.3
0,-7,21:18.3
1,-7,21:18.3
2,-7,21:18.3
0,-3,21:18.3
1,-3,21:18.3
0,-2,21:18.3
1,-2,21:18.3
7,-2,21:18.3
2,-1,21:18.3
3,-1,21:18.3
7,-1,21:18.3
2,0,21:18.3
3,0,21:18.3
7,0,21:18.3
7,1,21:18.3
-1,-6,22:18.3
0,-6,22:17.15
1,-6,22:18.3
2,-6,22:18.3
-1,-5,22:18.3
0,-5,22:18.3
1,-5,22:18.3
2,-5,22:18.3
0,-4,22:18.3
1,-4,22:18.3
5,-2,22:18.3
6,-2,22:18.3
4,-1,22:18.3
5,-1,22:18.3
6,-1,22:18.3
4,0,22:18.3
5,0,22:18.3
6,0,22:17.15
5,1,22:18.3
6,1,22:18.3
