[META]
version=2.0
spawnOnBlockType=2
spawnSunlight=True
spawnDarkness=True
spawnWater=False
spawnLava=False
underFill=False
randomRotation=True
dig=True
tree=False
branch=False
needsFoundation=True
rarity=100
collisionPercentage=20
spawnElevationMin=0
spawnElevationMax=200
spawnInBiome=Custom
[DATA]
1,-2,-4:1.0
2,-2,-4:1.0
3,-2,-4:1.0
1,-1,-4:1.0
2,-1,-4:1.0
3,-1,-4:1.0
1,0,-4:1.0
2,0,-4:1.0
3,0,-4:1.0
1,-3,-3:1.0
2,-3,-3:1.0
3,-3,-3:1.0
-1,-2,-3:1.0
0,-2,-3:1.0
1,-2,-3:1.0
2,-2,-3:1.0
3,-2,-3:1.0
4,-2,-3:1.0
-1,-1,-3:1.0
0,-1,-3:1.0
1,-1,-3:1.0
2,-1,-3:1.0
3,-1,-3:1.0
4,-1,-3:1.0
-1,0,-3:1.0
0,0,-3:1.0
1,0,-3:1.0
2,0,-3:1.0
3,0,-3:1.0
4,0,-3:1.0
1,1,-3:1.0
2,1,-3:1.0
3,1,-3:1.0
0,-3,-2:1.0
1,-3,-2:1.0
2,-3,-2:1.0
3,-3,-2:1.0
-2,-2,-2:1.0
-1,-2,-2:1.0
0,-2,-2:1.0
1,-2,-2:1.0
2,-2,-2:1.0
3,-2,-2:1.0
4,-2,-2:1.0
-2,-1,-2:1.0
-1,-1,-2:1.0
0,-1,-2:1.0
1,-1,-2:1.0
2,-1,-2:1.0
3,-1,-2:1.0
4,-1,-2:1.0
-2,0,-2:1.0
-1,0,-2:1.0
0,0,-2:1.0
1,0,-2:1.0
2,0,-2:1.0
3,0,-2:1.0
4,0,-2:1.0
-1,1,-2:1.0
0,1,-2:1.0
1,1,-2:1.0
2,1,-2:1.0
3,1,-2:1.0
-1,-3,-1:1.0
0,-3,-1:1.0
1,-3,-1:1.0
2,-3,-1:1.0
3,-3,-1:1.0
-2,-2,-1:1.0
-1,-2,-1:1.0
0,-2,-1:1.0
1,-2,-1:1.0
2,-2,-1:1.0
3,-2,-1:1.0
4,-2,-1:1.0
-2,-1,-1:1.0
-1,-1,-1:1.0
0,-1,-1:1.0
1,-1,-1:1.0
2,-1,-1:1.0
3,-1,-1:1.0
4,-1,-1:1.0
-2,0,-1:1.0
-1,0,-1:1.0
0,0,-1:1.0
1,0,-1:1.0
2,0,-1:1.0
3,0,-1:1.0
4,0,-1:1.0
-1,1,-1:1.0
0,1,-1:1.0
1,1,-1:1.0
2,1,-1:1.0
3,1,-1:1.0
-2,-3,0:1.0
-1,-3,0:1.0
0,-3,0:1.0
1,-3,0:1.0
2,-3,0:1.0
-2,-2,0:1.0
-1,-2,0:1.0
0,-2,0:1.0
1,-2,0:1.0
2,-2,0:1.0
3,-2,0:1.0
-2,-1,0:1.0
-1,-1,0:1.0
0,-1,0:1.0
1,-1,0:1.0
2,-1,0:1.0
3,-1,0:1.0
-2,0,0:1.0
-1,0,0:1.0
0,0,0:1.0
1,0,0:1.0
2,0,0:1.0
3,0,0:1.0
-1,1,0:1.0
0,1,0:1.0
1,1,0:1.0
2,1,0:1.0
-2,-3,1:1.0
-1,-3,1:1.0
0,-3,1:1.0
1,-3,1:1.0
2,-3,1:1.0
-2,-2,1:1.0
-1,-2,1:1.0
0,-2,1:1.0
1,-2,1:1.0
2,-2,1:1.0
3,-2,1:1.0
-2,-1,1:1.0
-1,-1,1:1.0
0,-1,1:1.0
1,-1,1:1.0
2,-1,1:1.0
3,-1,1:1.0
-2,0,1:1.0
-1,0,1:1.0
0,0,1:1.0
1,0,1:1.0
2,0,1:1.0
3,0,1:1.0
-1,1,1:1.0
0,1,1:1.0
1,1,1:1.0
2,1,1:1.0
-1,-3,2:1.0
0,-3,2:1.0
1,-3,2:1.0
-2,-2,2:1.0
-1,-2,2:1.0
0,-2,2:1.0
1,-2,2:1.0
2,-2,2:1.0
-2,-1,2:1.0
-1,-1,2:1.0
0,-1,2:1.0
1,-1,2:1.0
2,-1,2:1.0
-2,0,2:1.0
-1,0,2:1.0
0,0,2:1.0
1,0,2:1.0
2,0,2:1.0
-1,1,2:1.0
0,1,2:1.0
1,1,2:1.0
-1,-2,3:1.0
0,-2,3:1.0
1,-2,3:1.0
-1,-1,3:1.0
0,-1,3:1.0
1,-1,3:1.0
-1,0,3:1.0
0,0,3:1.0
1,0,3:1.0
